File: AIME_journal_files/AIME_data/calibDATA_loadcell/date_30:1:2018/MTSdata_date_1.30/radhen_10cyc_black_20deg_1mms_50N.txt
""
"Test Method","Radhen_Load_Cntrl_Cmprsn_250N_12-7.msm"
"Sample I. D.","Sample1.mss"
"Specimen Number","15"

"TheCycle_Output ()","_Time (s)","_Load (N)","_Extension (mm)","RealTimeDepth (mm)","CycleNumber ()"

0,0.160,0.01,0.0000,0.00000,0.000
1,0.300,0.01,0.0756,0.07560,1.000
1,0.430,0.00,0.2058,0.20580,1.000
1,0.560,0.00,0.3357,0.33570,1.000
1,0.690,0.01,0.4659,0.46590,1.000
1,0.820,0.01,0.5959,0.59590,1.000
1,0.950,0.01,0.7259,0.72590,1.000
1,1.080,0.00,0.8559,0.85590,1.000
1,1.210,0.00,0.9857,0.98570,1.000
1,1.340,0.00,1.1157,1.11570,1.000
1,1.470,0.01,1.2459,1.24590,1.000
1,1.600,0.00,1.3759,1.37590,1.000
1,1.730,0.00,1.5059,1.50590,1.000
1,1.860,0.00,1.6357,1.63570,1.000
1,1.990,0.00,1.7658,1.76580,1.000
1,2.120,0.00,1.8960,1.89600,1.000
1,2.250,0.00,2.0259,2.02590,1.000
1,2.380,0.00,2.1558,2.15580,1.000
1,2.510,0.00,2.2859,2.28590,1.000
1,2.640,0.00,2.4157,2.41570,1.000
1,2.770,0.00,2.5460,2.54600,1.000
1,2.900,0.00,2.6757,2.67570,1.000
1,3.030,0.00,2.8058,2.80580,1.000
1,3.160,0.00,2.9360,2.93600,1.000
1,3.290,0.01,3.0657,3.06570,1.000
1,3.420,0.15,3.1958,3.19580,1.000
1,3.550,0.41,3.3260,3.32600,1.000
1,3.680,0.82,3.4559,3.45590,1.000
1,3.810,1.38,3.5859,3.58590,1.000
1,3.940,2.13,3.7158,3.71580,1.000
1,4.070,3.11,3.8458,3.84580,1.000
1,4.200,4.31,3.9758,3.97580,1.000
1,4.330,5.83,4.1060,4.10600,1.000
1,4.460,7.62,4.2357,4.23570,1.000
1,4.590,9.75,4.3658,4.36580,1.000
1,4.720,12.24,4.4960,4.49600,1.000
1,4.850,15.10,4.6260,4.62600,1.000
1,4.980,18.38,4.7558,4.75580,1.000
1,5.110,22.10,4.8858,4.88580,1.000
1,5.240,26.42,5.0159,5.01590,1.000
1,5.370,31.60,5.1458,5.14580,1.000
1,5.500,37.82,5.2758,5.27580,1.000
1,5.630,45.17,5.4058,5.40580,1.000
1,5.770,53.76,5.5282,5.52820,1.000
1,5.900,39.52,5.4207,5.42070,1.000
1,6.030,28.26,5.2907,5.29070,1.000
1,6.160,20.95,5.1606,5.16060,1.000
1,6.290,15.78,5.0308,5.03080,1.000
1,6.420,12.02,4.9007,4.90070,1.000
1,6.550,9.27,4.7707,4.77070,1.000
1,6.680,7.19,4.6406,4.64060,1.000
1,6.810,5.68,4.5107,4.51070,1.000
1,6.940,4.49,4.3807,4.38070,1.000
1,7.070,3.42,4.2505,4.25050,1.000
1,7.200,2.53,4.1205,4.12050,1.000
1,7.330,1.90,3.9905,3.99050,1.000
1,7.460,1.38,3.8606,3.86060,1.000
1,7.590,0.90,3.7306,3.73060,1.000
1,7.720,0.56,3.6003,3.60030,1.000
1,7.850,0.30,3.4705,3.47050,1.000
1,7.980,0.13,3.3406,3.34060,1.000
1,8.110,0.02,3.2106,3.21060,1.000
1,8.240,0.00,3.0803,3.08030,1.000
1,8.370,0.00,2.9503,2.95030,1.000
1,8.500,0.00,2.8204,2.82040,1.000
1,8.630,0.00,2.6905,2.69050,1.000
1,8.760,0.00,2.5603,2.56030,1.000
1,8.890,0.00,2.4303,2.43030,1.000
1,9.020,0.00,2.3003,2.30030,1.000
1,9.150,0.00,2.1707,2.17070,1.000
1,9.280,0.00,2.0403,2.04030,1.000
1,9.410,0.01,1.9104,1.91040,1.000
1,9.540,0.00,1.7803,1.78030,1.000
1,9.670,0.00,1.6503,1.65030,1.000
1,9.800,0.00,1.5203,1.52030,1.000
1,9.930,0.00,1.3903,1.39030,1.000
1,10.060,0.00,1.2604,1.26040,1.000
1,10.190,0.00,1.1303,1.13030,1.000
1,10.320,0.01,1.0001,1.00010,1.000
1,10.450,0.00,0.8702,0.87020,1.000
1,10.580,0.01,0.7403,0.74030,1.000
1,10.710,0.00,0.6104,0.61040,1.000
1,10.840,0.00,0.4802,0.48020,1.000
1,10.970,0.00,0.3502,0.35020,1.000
1,11.100,0.01,0.2203,0.22030,1.000
1,11.230,0.00,0.0904,0.09040,1.000
1,11.380,0.01,-0.0505,-0.05050,1.000
1,11.510,0.00,0.0002,0.00020,1.000
1,11.640,0.00,-0.0003,-0.00030,1.000
1,11.770,0.00,-0.0002,-0.00020,1.000
1,11.900,0.01,-0.0002,-0.00020,1.000
1,12.030,0.01,-0.0002,-0.00020,1.000
1,12.160,0.00,-0.0002,-0.00020,1.000
1,12.290,0.00,-0.0002,-0.00020,1.000
1,12.420,0.01,-0.0002,-0.00020,1.000
1,12.550,0.01,-0.0002,-0.00020,1.000
1,12.680,0.00,-0.0002,-0.00020,1.000
1,12.810,0.00,-0.0002,-0.00020,1.000
1,12.940,0.01,-0.0002,-0.00020,1.000
1,13.070,0.00,-0.0002,-0.00020,1.000
1,13.200,-0.01,-0.0002,-0.00020,1.000
1,13.330,0.00,-0.0002,-0.00020,1.000
1,13.460,-0.01,-0.0002,-0.00020,1.000
1,13.590,-0.01,-0.0002,-0.00020,1.000
1,13.720,0.00,-0.0002,-0.00020,1.000
1,13.850,0.01,-0.0002,-0.00020,1.000
1,13.980,0.00,-0.0002,-0.00020,1.000
1,14.110,0.01,-0.0002,-0.00020,1.000
1,14.240,0.00,-0.0002,-0.00020,1.000
1,14.370,0.01,-0.0002,-0.00020,1.000
1,14.520,0.00,-0.0002,-0.00020,1.000
1,14.650,0.00,-0.0002,-0.00020,1.000
1,14.780,0.00,-0.0002,-0.00020,1.000
1,14.910,0.01,-0.0002,-0.00020,1.000
1,15.040,0.01,-0.0002,-0.00020,1.000
1,15.170,0.01,-0.0002,-0.00020,1.000
1,15.300,-0.01,-0.0002,-0.00020,1.000
1,15.430,0.01,-0.0002,-0.00020,1.000
1,15.560,0.01,-0.0002,-0.00020,1.000
1,15.690,0.00,-0.0001,-0.00010,1.000
1,15.820,0.00,-0.0001,-0.00010,1.000
1,15.950,-0.01,-0.0001,-0.00010,1.000
1,16.080,0.02,-0.0001,-0.00010,1.000
1,16.210,0.01,-0.0001,-0.00010,1.000
1,16.340,0.00,-0.0001,-0.00010,1.000
1,16.470,0.00,-0.0001,-0.00010,1.000
1,16.600,0.00,-0.0001,-0.00010,1.000
1,16.730,0.01,-0.0001,-0.00010,1.000
1,16.860,0.01,-0.0001,-0.00010,1.000
1,16.990,0.01,-0.0001,-0.00010,1.000
1,17.120,0.01,-0.0001,-0.00010,1.000
1,17.250,0.01,-0.0001,-0.00010,1.000
1,17.380,0.00,-0.0001,-0.00010,1.000
2,17.610,0.00,0.0156,0.01560,2.000
2,17.740,-0.01,0.1457,0.14570,2.000
2,17.870,0.00,0.2755,0.27550,2.000
2,18.000,0.00,0.4057,0.40570,2.000
2,18.130,0.00,0.5359,0.53590,2.000
2,18.260,0.00,0.6657,0.66570,2.000
2,18.390,0.01,0.7956,0.79560,2.000
2,18.520,0.00,0.9258,0.92580,2.000
2,18.650,0.00,1.0557,1.05570,2.000
2,18.780,0.00,1.1857,1.18570,2.000
2,18.910,0.00,1.3157,1.31570,2.000
2,19.040,-0.01,1.4459,1.44590,2.000
2,19.170,-0.01,1.5758,1.57580,2.000
2,19.300,-0.01,1.7058,1.70580,2.000
2,19.430,0.00,1.8356,1.83560,2.000
2,19.560,0.00,1.9659,1.96590,2.000
2,19.690,0.00,2.0959,2.09590,2.000
2,19.820,-0.01,2.2260,2.22600,2.000
2,19.950,0.00,2.3555,2.35550,2.000
2,20.080,0.00,2.4858,2.48580,2.000
2,20.210,0.00,2.6158,2.61580,2.000
2,20.340,0.00,2.7457,2.74570,2.000
2,20.470,-0.01,2.8757,2.87570,2.000
2,20.600,0.00,3.0058,3.00580,2.000
2,20.730,0.07,3.1359,3.13590,2.000
2,20.860,0.26,3.2659,3.26590,2.000
2,20.990,0.59,3.3957,3.39570,2.000
2,21.120,1.08,3.5259,3.52590,2.000
2,21.250,1.71,3.6557,3.65570,2.000
2,21.380,2.59,3.7859,3.78590,2.000
2,21.510,3.69,3.9157,3.91570,2.000
2,21.640,5.05,4.0458,4.04580,2.000
2,21.770,6.72,4.1760,4.17600,2.000
2,21.900,8.70,4.3059,4.30590,2.000
2,22.030,11.04,4.4358,4.43580,2.000
2,22.160,13.72,4.5659,4.56590,2.000
2,22.290,16.78,4.6960,4.69600,2.000
2,22.420,20.31,4.8259,4.82590,2.000
2,22.550,24.37,4.9557,4.95570,2.000
2,22.680,29.11,5.0859,5.08590,2.000
2,22.810,34.83,5.2158,5.21580,2.000
2,22.940,41.68,5.3459,5.34590,2.000
2,23.070,49.85,5.4758,5.47580,2.000
2,23.210,47.46,5.4803,5.48030,2.000
2,23.340,33.04,5.3507,5.35070,2.000
2,23.470,24.07,5.2207,5.22070,2.000
2,23.600,18.02,5.0908,5.09080,2.000
2,23.730,13.63,4.9605,4.96050,2.000
2,23.860,10.43,4.8306,4.83060,2.000
2,23.990,8.07,4.7006,4.70060,2.000
2,24.120,6.31,4.5707,4.57070,2.000
2,24.250,4.99,4.4405,4.44050,2.000
2,24.380,3.90,4.3104,4.31040,2.000
2,24.510,2.90,4.1806,4.18060,2.000
2,24.640,2.13,4.0506,4.05060,2.000
2,24.770,1.59,3.9203,3.92030,2.000
2,24.900,1.09,3.7905,3.79050,2.000
2,25.030,0.68,3.6605,3.66050,2.000
2,25.160,0.39,3.5305,3.53050,2.000
2,25.290,0.18,3.4004,3.40040,2.000
2,25.420,0.05,3.2705,3.27050,2.000
2,25.550,0.00,3.1404,3.14040,2.000
2,25.680,0.00,3.0104,3.01040,2.000
2,25.810,-0.01,2.8803,2.88030,2.000
2,25.940,-0.01,2.7503,2.75030,2.000
2,26.070,0.00,2.6204,2.62040,2.000
2,26.200,0.00,2.4905,2.49050,2.000
2,26.330,0.00,2.3601,2.36010,2.000
2,26.460,0.00,2.2304,2.23040,2.000
2,26.590,0.00,2.1004,2.10040,2.000
2,26.720,0.00,1.9704,1.97040,2.000
2,26.850,0.00,1.8402,1.84020,2.000
2,26.980,0.00,1.7101,1.71010,2.000
2,27.110,0.00,1.5803,1.58030,2.000
2,27.240,-0.01,1.4503,1.45030,2.000
2,27.370,-0.01,1.3203,1.32030,2.000
2,27.500,0.00,1.1903,1.19030,2.000
2,27.630,0.00,1.0601,1.06010,2.000
2,27.760,-0.01,0.9303,0.93030,2.000
2,27.890,0.00,0.8002,0.80020,2.000
2,28.020,0.00,0.6703,0.67030,2.000
2,28.150,-0.01,0.5403,0.54030,2.000
2,28.280,0.00,0.4103,0.41030,2.000
2,28.410,-0.01,0.2802,0.28020,2.000
2,28.540,-0.01,0.1503,0.15030,2.000
2,28.670,0.00,0.0203,0.02030,2.000
2,28.820,0.00,-0.0147,-0.01470,2.000
2,28.950,0.00,-0.0003,-0.00030,2.000
2,29.080,0.00,-0.0003,-0.00030,2.000
2,29.210,0.00,-0.0003,-0.00030,2.000
2,29.340,0.00,-0.0003,-0.00030,2.000
2,29.470,-0.01,-0.0003,-0.00030,2.000
2,29.600,0.00,-0.0003,-0.00030,2.000
2,29.730,-0.01,-0.0003,-0.00030,2.000
2,29.860,0.00,-0.0003,-0.00030,2.000
2,29.990,0.00,-0.0003,-0.00030,2.000
2,30.120,0.00,-0.0003,-0.00030,2.000
2,30.250,0.00,-0.0003,-0.00030,2.000
2,30.380,0.00,-0.0003,-0.00030,2.000
2,30.510,0.00,-0.0002,-0.00020,2.000
2,30.640,0.00,-0.0002,-0.00020,2.000
2,30.770,0.00,-0.0002,-0.00020,2.000
2,30.900,0.00,-0.0002,-0.00020,2.000
2,31.030,0.00,-0.0002,-0.00020,2.000
2,31.160,0.00,-0.0002,-0.00020,2.000
2,31.290,0.00,-0.0002,-0.00020,2.000
2,31.420,0.00,-0.0002,-0.00020,2.000
2,31.550,0.00,-0.0002,-0.00020,2.000
2,31.680,0.00,-0.0002,-0.00020,2.000
2,31.820,0.00,-0.0002,-0.00020,2.000
2,31.950,0.00,-0.0002,-0.00020,2.000
2,32.080,0.00,-0.0002,-0.00020,2.000
2,32.210,-0.01,-0.0002,-0.00020,2.000
2,32.340,-0.01,-0.0002,-0.00020,2.000
2,32.470,0.00,-0.0002,-0.00020,2.000
2,32.600,0.00,-0.0002,-0.00020,2.000
2,32.730,0.00,-0.0002,-0.00020,2.000
2,32.860,0.00,-0.0002,-0.00020,2.000
2,32.990,0.00,-0.0002,-0.00020,2.000
2,33.120,0.00,-0.0002,-0.00020,2.000
2,33.250,0.00,-0.0001,-0.00010,2.000
2,33.380,-0.01,-0.0001,-0.00010,2.000
2,33.510,0.00,-0.0001,-0.00010,2.000
2,33.640,0.00,-0.0001,-0.00010,2.000
2,33.770,0.00,-0.0001,-0.00010,2.000
2,33.900,0.00,-0.0001,-0.00010,2.000
2,34.030,0.00,-0.0001,-0.00010,2.000
2,34.160,0.00,-0.0001,-0.00010,2.000
2,34.290,0.00,-0.0001,-0.00010,2.000
2,34.420,-0.01,-0.0001,-0.00010,2.000
2,34.550,0.00,-0.0001,-0.00010,2.000
2,34.680,0.00,-0.0001,-0.00010,2.000
2,34.810,0.00,-0.0001,-0.00010,2.000
3,35.030,0.00,0.0558,0.05580,3.000
3,35.160,-0.01,0.1857,0.18570,3.000
3,35.290,0.00,0.3156,0.31560,3.000
3,35.420,0.00,0.4457,0.44570,3.000
3,35.550,-0.01,0.5758,0.57580,3.000
3,35.680,-0.01,0.7058,0.70580,3.000
3,35.810,-0.01,0.8357,0.83570,3.000
3,35.940,-0.01,0.9658,0.96580,3.000
3,36.070,-0.01,1.0959,1.09590,3.000
3,36.200,-0.01,1.2257,1.22570,3.000
3,36.330,0.00,1.3557,1.35570,3.000
3,36.460,-0.01,1.4859,1.48590,3.000
3,36.590,-0.01,1.6159,1.61590,3.000
3,36.720,0.00,1.7458,1.74580,3.000
3,36.850,0.00,1.8757,1.87570,3.000
3,36.980,0.00,2.0059,2.00590,3.000
3,37.110,0.00,2.1359,2.13590,3.000
3,37.240,-0.01,2.2660,2.26600,3.000
3,37.370,0.00,2.3955,2.39550,3.000
3,37.500,-0.01,2.5259,2.52590,3.000
3,37.630,-0.01,2.6558,2.65580,3.000
3,37.760,-0.01,2.7859,2.78590,3.000
3,37.890,-0.01,2.9158,2.91580,3.000
3,38.020,-0.01,3.0457,3.04570,3.000
3,38.150,0.09,3.1758,3.17580,3.000
3,38.280,0.33,3.3060,3.30600,3.000
3,38.410,0.70,3.4358,3.43580,3.000
3,38.540,1.24,3.5657,3.56570,3.000
3,38.670,1.94,3.6958,3.69580,3.000
3,38.800,2.86,3.8259,3.82590,3.000
3,38.930,4.02,3.9556,3.95560,3.000
3,39.060,5.47,4.0859,4.08590,3.000
3,39.190,7.23,4.2159,4.21590,3.000
3,39.320,9.31,4.3459,4.34590,3.000
3,39.450,11.75,4.4759,4.47590,3.000
3,39.580,14.53,4.6059,4.60590,3.000
3,39.710,17.71,4.7358,4.73580,3.000
3,39.840,21.38,4.8658,4.86580,3.000
3,39.970,25.61,4.9958,4.99580,3.000
3,40.100,30.64,5.1258,5.12580,3.000
3,40.230,36.69,5.2558,5.25580,3.000
3,40.360,43.93,5.3860,5.38600,3.000
3,40.500,53.48,5.5221,5.52210,3.000
3,40.630,42.15,5.4405,5.44050,3.000
3,40.760,29.86,5.3107,5.31070,3.000
3,40.890,21.99,5.1807,5.18070,3.000
3,41.020,16.51,5.0507,5.05070,3.000
3,41.150,12.52,4.9204,4.92040,3.000
3,41.280,9.63,4.7906,4.79060,3.000
3,41.410,7.45,4.6607,4.66070,3.000
3,41.540,5.86,4.5307,4.53070,3.000
3,41.670,4.62,4.4005,4.40050,3.000
3,41.800,3.56,4.2705,4.27050,3.000
3,41.930,2.64,4.1406,4.14060,3.000
3,42.060,1.94,4.0106,4.01060,3.000
3,42.190,1.42,3.8804,3.88040,3.000
3,42.320,0.94,3.7505,3.75050,3.000
3,42.450,0.58,3.6205,3.62050,3.000
3,42.580,0.30,3.4906,3.49060,3.000
3,42.710,0.12,3.3605,3.36050,3.000
3,42.840,0.02,3.2305,3.23050,3.000
3,42.970,-0.01,3.1004,3.10040,3.000
3,43.100,0.00,2.9704,2.97040,3.000
3,43.230,-0.01,2.8403,2.84030,3.000
3,43.360,-0.01,2.7103,2.71030,3.000
3,43.490,-0.01,2.5805,2.58050,3.000
3,43.620,-0.01,2.4504,2.45040,3.000
3,43.750,-0.01,2.3201,2.32010,3.000
3,43.880,-0.01,2.1905,2.19050,3.000
3,44.010,-0.01,2.0605,2.06050,3.000
3,44.140,-0.01,1.9305,1.93050,3.000
3,44.270,0.00,1.8002,1.80020,3.000
3,44.400,-0.01,1.6702,1.67020,3.000
3,44.530,0.00,1.5402,1.54020,3.000
3,44.660,-0.01,1.4103,1.41030,3.000
3,44.790,-0.01,1.2804,1.28040,3.000
3,44.920,-0.02,1.1503,1.15030,3.000
3,45.050,-0.01,1.0204,1.02040,3.000
3,45.180,-0.01,0.8904,0.89040,3.000
3,45.310,-0.01,0.7602,0.76020,3.000
3,45.440,-0.01,0.6303,0.63030,3.000
3,45.570,-0.01,0.5003,0.50030,3.000
3,45.700,0.00,0.3703,0.37030,3.000
3,45.830,-0.01,0.2401,0.24010,3.000
3,45.960,0.00,0.1103,0.11030,3.000
3,46.110,-0.01,-0.0392,-0.03919,3.000
3,46.240,-0.01,0.0006,0.00060,3.000
3,46.370,0.00,-0.0003,-0.00030,3.000
3,46.500,-0.01,-0.0003,-0.00030,3.000
3,46.630,0.00,-0.0003,-0.00030,3.000
3,46.760,-0.01,-0.0003,-0.00030,3.000
3,46.890,0.00,-0.0003,-0.00030,3.000
3,47.020,-0.01,-0.0003,-0.00030,3.000
3,47.150,-0.01,-0.0003,-0.00030,3.000
3,47.280,0.00,-0.0003,-0.00030,3.000
3,47.410,-0.01,-0.0003,-0.00030,3.000
3,47.540,-0.01,-0.0003,-0.00030,3.000
3,47.670,0.00,-0.0002,-0.00020,3.000
3,47.800,-0.01,-0.0002,-0.00020,3.000
3,47.930,-0.01,-0.0002,-0.00020,3.000
3,48.060,0.00,-0.0002,-0.00020,3.000
3,48.190,0.00,-0.0002,-0.00020,3.000
3,48.320,0.00,-0.0002,-0.00020,3.000
3,48.450,0.00,-0.0002,-0.00020,3.000
3,48.580,-0.01,-0.0002,-0.00020,3.000
3,48.710,-0.01,-0.0002,-0.00020,3.000
3,48.840,-0.01,-0.0002,-0.00020,3.000
3,48.970,0.00,-0.0002,-0.00020,3.000
3,49.100,-0.01,-0.0002,-0.00020,3.000
3,49.250,-0.01,-0.0002,-0.00020,3.000
3,49.380,-0.01,-0.0002,-0.00020,3.000
3,49.510,-0.01,-0.0002,-0.00020,3.000
3,49.640,0.00,-0.0002,-0.00020,3.000
3,49.770,-0.01,-0.0002,-0.00020,3.000
3,49.900,-0.01,-0.0002,-0.00020,3.000
3,50.030,-0.01,-0.0002,-0.00020,3.000
3,50.160,-0.01,-0.0002,-0.00020,3.000
3,50.290,0.00,-0.0002,-0.00020,3.000
3,50.420,0.00,-0.0001,-0.00010,3.000
3,50.550,-0.01,-0.0001,-0.00010,3.000
3,50.680,0.00,-0.0001,-0.00010,3.000
3,50.810,-0.01,-0.0001,-0.00010,3.000
3,50.940,-0.01,-0.0001,-0.00010,3.000
3,51.070,0.00,-0.0001,-0.00010,3.000
3,51.200,0.00,-0.0001,-0.00010,3.000
3,51.330,0.00,-0.0001,-0.00010,3.000
3,51.460,0.00,-0.0001,-0.00010,3.000
3,51.590,0.00,-0.0001,-0.00010,3.000
3,51.720,0.00,-0.0001,-0.00010,3.000
3,51.850,-0.01,-0.0001,-0.00010,3.000
3,51.980,0.00,-0.0001,-0.00010,3.000
3,52.110,0.00,-0.0001,-0.00010,3.000
4,52.340,0.01,0.0000,0.00000,4.000
4,52.470,0.01,0.1157,0.11570,4.000
4,52.600,0.00,0.2457,0.24570,4.000
4,52.730,0.01,0.3758,0.37580,4.000
4,52.860,0.01,0.5058,0.50580,4.000
4,52.990,0.01,0.6356,0.63560,4.000
4,53.120,0.01,0.7658,0.76580,4.000
4,53.250,0.01,0.8957,0.89570,4.000
4,53.380,0.01,1.0257,1.02570,4.000
4,53.510,0.01,1.1556,1.15560,4.000
4,53.640,0.00,1.2858,1.28580,4.000
4,53.770,0.00,1.4159,1.41590,4.000
4,53.900,0.01,1.5457,1.54570,4.000
4,54.030,0.01,1.6756,1.67560,4.000
4,54.160,0.01,1.8058,1.80580,4.000
4,54.290,0.01,1.9359,1.93590,4.000
4,54.420,0.01,2.0659,2.06590,4.000
4,54.550,0.01,2.1958,2.19580,4.000
4,54.680,0.01,2.3256,2.32560,4.000
4,54.810,0.01,2.4558,2.45580,4.000
4,54.940,0.01,2.5859,2.58590,4.000
4,55.070,0.01,2.7158,2.71580,4.000
4,55.200,0.01,2.8458,2.84580,4.000
4,55.330,0.01,2.9758,2.97580,4.000
4,55.460,0.04,3.1059,3.10590,4.000
4,55.590,0.20,3.2357,3.23570,4.000
4,55.720,0.49,3.3659,3.36590,4.000
4,55.850,0.94,3.4958,3.49580,4.000
4,55.980,1.54,3.6258,3.62580,4.000
4,56.110,2.34,3.7558,3.75580,4.000
4,56.240,3.37,3.8858,3.88580,4.000
4,56.370,4.64,4.0158,4.01580,4.000
4,56.500,6.23,4.1460,4.14600,4.000
4,56.630,8.14,4.2757,4.27570,4.000
4,56.760,10.37,4.4058,4.40580,4.000
4,56.890,12.95,4.5358,4.53580,4.000
4,57.020,15.89,4.6659,4.66590,4.000
4,57.150,19.30,4.7957,4.79570,4.000
4,57.280,23.19,4.9257,4.92570,4.000
4,57.410,27.70,5.0559,5.05590,4.000
4,57.540,33.19,5.1859,5.18590,4.000
4,57.670,39.76,5.3157,5.31570,4.000
4,57.800,47.74,5.4457,5.44570,4.000
4,57.940,52.16,5.5126,5.51260,4.000
4,58.070,35.87,5.3827,5.38270,4.000
4,58.200,25.94,5.2527,5.25270,4.000
4,58.330,19.33,5.1225,5.12250,4.000
4,58.460,14.57,4.9926,4.99260,4.000
4,58.590,11.10,4.8626,4.86260,4.000
4,58.720,8.58,4.7327,4.73270,4.000
4,58.850,6.68,4.6025,4.60250,4.000
4,58.980,5.27,4.4726,4.47260,4.000
4,59.110,4.14,4.3425,4.34250,4.000
4,59.240,3.12,4.2126,4.21260,4.000
4,59.370,2.30,4.0825,4.08250,4.000
4,59.500,1.72,3.9525,3.95250,4.000
4,59.630,1.20,3.8226,3.82260,4.000
4,59.760,0.77,3.6925,3.69250,4.000
4,59.890,0.45,3.5623,3.56230,4.000
4,60.020,0.23,3.4325,3.43250,4.000
4,60.150,0.08,3.3026,3.30260,4.000
4,60.280,0.00,3.1726,3.17260,4.000
4,60.410,0.01,3.0422,3.04220,4.000
4,60.540,0.01,2.9124,2.91240,4.000
4,60.670,0.00,2.7824,2.78240,4.000
4,60.800,0.00,2.6524,2.65240,4.000
4,60.930,0.00,2.5223,2.52230,4.000
4,61.060,0.00,2.3922,2.39220,4.000
4,61.190,0.01,2.2625,2.26250,4.000
4,61.320,0.01,2.1326,2.13260,4.000
4,61.450,0.00,2.0022,2.00220,4.000
4,61.580,0.01,1.8723,1.87230,4.000
4,61.710,0.01,1.7423,1.74230,4.000
4,61.840,0.01,1.6124,1.61240,4.000
4,61.970,0.01,1.4822,1.48220,4.000
4,62.100,0.01,1.3523,1.35230,4.000
4,62.230,0.01,1.2224,1.22240,4.000
4,62.360,0.01,1.0923,1.09230,4.000
4,62.490,0.01,0.9622,0.96220,4.000
4,62.620,0.01,0.8321,0.83210,4.000
4,62.750,0.01,0.7024,0.70240,4.000
4,62.880,0.01,0.5725,0.57250,4.000
4,63.010,0.01,0.4422,0.44220,4.000
4,63.140,0.01,0.3121,0.31210,4.000
4,63.270,0.01,0.1822,0.18220,4.000
4,63.400,0.00,0.0524,0.05240,4.000
4,63.550,0.01,-0.0408,-0.04080,4.000
4,63.680,0.01,-0.0003,-0.00030,4.000
4,63.810,0.01,-0.0003,-0.00030,4.000
4,63.940,0.01,-0.0003,-0.00030,4.000
4,64.070,0.01,-0.0003,-0.00030,4.000
4,64.200,0.01,-0.0003,-0.00030,4.000
4,64.330,0.01,-0.0003,-0.00030,4.000
4,64.460,0.01,-0.0003,-0.00030,4.000
4,64.590,0.01,-0.0003,-0.00030,4.000
4,64.720,0.01,-0.0003,-0.00030,4.000
4,64.850,0.02,-0.0003,-0.00030,4.000
4,64.980,0.01,-0.0003,-0.00030,4.000
4,65.110,0.01,-0.0003,-0.00030,4.000
4,65.240,0.00,-0.0002,-0.00020,4.000
4,65.370,0.01,-0.0002,-0.00020,4.000
4,65.500,0.01,-0.0002,-0.00020,4.000
4,65.630,0.01,-0.0002,-0.00020,4.000
4,65.760,0.01,-0.0002,-0.00020,4.000
4,65.890,0.01,-0.0002,-0.00020,4.000
4,66.020,0.01,-0.0002,-0.00020,4.000
4,66.150,0.01,-0.0002,-0.00020,4.000
4,66.280,0.01,-0.0002,-0.00020,4.000
4,66.410,0.01,-0.0002,-0.00020,4.000
4,66.540,0.01,-0.0002,-0.00020,4.000
4,66.680,0.01,-0.0002,-0.00020,4.000
4,66.810,0.01,-0.0002,-0.00020,4.000
4,66.940,0.01,-0.0002,-0.00020,4.000
4,67.070,0.01,-0.0002,-0.00020,4.000
4,67.200,0.01,-0.0002,-0.00020,4.000
4,67.330,0.00,-0.0002,-0.00020,4.000
4,67.460,0.01,-0.0002,-0.00020,4.000
4,67.590,0.01,-0.0002,-0.00020,4.000
4,67.720,0.01,-0.0002,-0.00020,4.000
4,67.850,0.01,-0.0002,-0.00020,4.000
4,67.980,0.01,-0.0001,-0.00010,4.000
4,68.110,0.01,-0.0001,-0.00010,4.000
4,68.240,0.01,-0.0001,-0.00010,4.000
4,68.370,0.01,-0.0001,-0.00010,4.000
4,68.500,0.01,-0.0001,-0.00010,4.000
4,68.630,0.00,-0.0001,-0.00010,4.000
4,68.760,0.01,-0.0001,-0.00010,4.000
4,68.890,0.01,-0.0001,-0.00010,4.000
4,69.020,0.01,-0.0001,-0.00010,4.000
4,69.150,0.01,-0.0001,-0.00010,4.000
4,69.280,0.01,-0.0001,-0.00010,4.000
4,69.410,0.00,-0.0001,-0.00010,4.000
4,69.540,0.01,-0.0001,-0.00010,4.000
5,69.770,0.01,0.0357,0.03570,5.000
5,69.900,0.01,0.1657,0.16570,5.000
5,70.030,0.00,0.2958,0.29580,5.000
5,70.160,0.01,0.4257,0.42570,5.000
5,70.290,0.01,0.5557,0.55570,5.000
5,70.420,0.01,0.6857,0.68570,5.000
5,70.550,0.01,0.8158,0.81580,5.000
5,70.680,0.01,0.9458,0.94580,5.000
5,70.810,0.02,1.0756,1.07560,5.000
5,70.940,0.01,1.2057,1.20570,5.000
5,71.070,0.01,1.3358,1.33580,5.000
5,71.200,0.01,1.4659,1.46590,5.000
5,71.330,0.01,1.5956,1.59560,5.000
5,71.460,0.01,1.7257,1.72570,5.000
5,71.590,0.01,1.8559,1.85590,5.000
5,71.720,0.01,1.9858,1.98580,5.000
5,71.850,0.01,2.1159,2.11590,5.000
5,71.980,0.01,2.2459,2.24590,5.000
5,72.110,0.01,2.3757,2.37570,5.000
5,72.240,0.00,2.5059,2.50590,5.000
5,72.370,0.00,2.6357,2.63570,5.000
5,72.500,0.01,2.7658,2.76580,5.000
5,72.630,0.00,2.8959,2.89590,5.000
5,72.760,0.01,3.0258,3.02580,5.000
5,72.890,0.08,3.1557,3.15570,5.000
5,73.020,0.29,3.2859,3.28590,5.000
5,73.150,0.65,3.4159,3.41590,5.000
5,73.280,1.15,3.5459,3.54590,5.000
5,73.410,1.83,3.6758,3.67580,5.000
5,73.540,2.71,3.8057,3.80570,5.000
5,73.670,3.84,3.9359,3.93590,5.000
5,73.800,5.23,4.0660,4.06600,5.000
5,73.930,6.95,4.1958,4.19580,5.000
5,74.060,8.98,4.3257,4.32570,5.000
5,74.190,11.36,4.4559,4.45590,5.000
5,74.320,14.09,4.5860,4.58600,5.000
5,74.450,17.22,4.7158,4.71580,5.000
5,74.580,20.82,4.8458,4.84580,5.000
5,74.710,24.94,4.9759,4.97590,5.000
5,74.840,29.84,5.1059,5.10590,5.000
5,74.970,35.76,5.2358,5.23580,5.000
5,75.100,42.88,5.3657,5.36570,5.000
5,75.250,53.04,5.5122,5.51220,5.000
5,75.380,41.85,5.4306,5.43060,5.000
5,75.510,29.72,5.3008,5.30080,5.000
5,75.640,21.93,5.1707,5.17070,5.000
5,75.770,16.46,5.0406,5.04060,5.000
5,75.900,12.47,4.9106,4.91060,5.000
5,76.030,9.57,4.7806,4.78060,5.000
5,76.160,7.40,4.6506,4.65060,5.000
5,76.290,5.81,4.5205,4.52050,5.000
5,76.420,4.58,4.3906,4.39060,5.000
5,76.550,3.52,4.2605,4.26050,5.000
5,76.680,2.60,4.1306,4.13060,5.000
5,76.810,1.93,4.0005,4.00050,5.000
5,76.940,1.40,3.8705,3.87050,5.000
5,77.070,0.93,3.7406,3.74060,5.000
5,77.200,0.57,3.6105,3.61050,5.000
5,77.330,0.31,3.4804,3.48040,5.000
5,77.460,0.13,3.3506,3.35060,5.000
5,77.590,0.04,3.2205,3.22050,5.000
5,77.720,0.01,3.0904,3.09040,5.000
5,77.850,0.01,2.9602,2.96020,5.000
5,77.980,0.01,2.8303,2.83030,5.000
5,78.110,0.01,2.7003,2.70030,5.000
5,78.240,0.01,2.5704,2.57040,5.000
5,78.370,0.01,2.4401,2.44010,5.000
5,78.500,0.01,2.3103,2.31030,5.000
5,78.630,0.01,2.1805,2.18050,5.000
5,78.760,0.02,2.0505,2.05050,5.000
5,78.890,0.01,1.9203,1.92030,5.000
5,79.020,0.01,1.7903,1.79030,5.000
5,79.150,0.01,1.6604,1.66040,5.000
5,79.280,0.01,1.5304,1.53040,5.000
5,79.410,0.01,1.4002,1.40020,5.000
5,79.540,0.02,1.2703,1.27030,5.000
5,79.670,0.01,1.1403,1.14030,5.000
5,79.800,0.02,1.0103,1.01030,5.000
5,79.930,0.01,0.8802,0.88020,5.000
5,80.060,0.02,0.7502,0.75020,5.000
5,80.190,0.01,0.6203,0.62030,5.000
5,80.320,0.01,0.4904,0.49040,5.000
5,80.450,0.01,0.3601,0.36010,5.000
5,80.580,0.01,0.2302,0.23020,5.000
5,80.710,0.02,0.1003,0.10030,5.000
5,80.850,0.01,-0.0397,-0.03970,5.000
5,80.980,0.01,0.0003,0.00030,5.000
5,81.110,0.01,-0.0003,-0.00030,5.000
5,81.240,0.01,-0.0003,-0.00030,5.000
5,81.370,0.01,-0.0003,-0.00030,5.000
5,81.500,0.02,-0.0003,-0.00030,5.000
5,81.630,0.01,-0.0003,-0.00030,5.000
5,81.760,0.02,-0.0003,-0.00030,5.000
5,81.890,0.02,-0.0003,-0.00030,5.000
5,82.020,0.02,-0.0003,-0.00030,5.000
5,82.150,0.01,-0.0003,-0.00030,5.000
5,82.280,0.01,-0.0003,-0.00030,5.000
5,82.410,0.01,-0.0003,-0.00030,5.000
5,82.540,0.01,-0.0003,-0.00030,5.000
5,82.670,0.01,-0.0003,-0.00030,5.000
5,82.800,0.00,-0.0002,-0.00020,5.000
5,82.930,0.01,-0.0002,-0.00020,5.000
5,83.060,0.02,-0.0002,-0.00020,5.000
5,83.190,0.00,-0.0002,-0.00020,5.000
5,83.320,0.01,-0.0002,-0.00020,5.000
5,83.450,0.02,-0.0002,-0.00020,5.000
5,83.580,0.02,-0.0002,-0.00020,5.000
5,83.710,0.01,-0.0002,-0.00020,5.000
5,83.840,0.01,-0.0002,-0.00020,5.000
5,83.990,0.02,-0.0002,-0.00020,5.000
5,84.120,0.01,-0.0002,-0.00020,5.000
5,84.250,0.00,-0.0002,-0.00020,5.000
5,84.380,0.01,-0.0002,-0.00020,5.000
5,84.510,0.01,-0.0002,-0.00020,5.000
5,84.640,0.01,-0.0002,-0.00020,5.000
5,84.770,0.02,-0.0002,-0.00020,5.000
5,84.900,0.01,-0.0002,-0.00020,5.000
5,85.030,0.02,-0.0002,-0.00020,5.000
5,85.160,0.01,-0.0002,-0.00020,5.000
5,85.290,0.01,-0.0002,-0.00020,5.000
5,85.420,0.01,-0.0002,-0.00020,5.000
5,85.550,0.01,-0.0001,-0.00010,5.000
5,85.680,0.01,-0.0001,-0.00010,5.000
5,85.810,0.01,-0.0001,-0.00010,5.000
5,85.940,0.01,-0.0001,-0.00010,5.000
5,86.070,0.02,-0.0001,-0.00010,5.000
5,86.200,0.02,-0.0001,-0.00010,5.000
5,86.330,0.01,-0.0001,-0.00010,5.000
5,86.460,0.01,-0.0001,-0.00010,5.000
5,86.590,0.01,-0.0001,-0.00010,5.000
5,86.720,0.01,-0.0001,-0.00010,5.000
5,86.850,0.01,-0.0001,-0.00010,5.000
6,87.070,0.01,0.0027,0.00270,6.000
6,87.200,0.01,0.1257,0.12570,6.000
6,87.330,0.00,0.2558,0.25580,6.000
6,87.460,0.01,0.3857,0.38570,6.000
6,87.590,0.00,0.5157,0.51570,6.000
6,87.720,0.01,0.6457,0.64570,6.000
6,87.850,0.01,0.7758,0.77580,6.000
6,87.980,0.01,0.9057,0.90570,6.000
6,88.110,0.01,1.0356,1.03560,6.000
6,88.240,0.01,1.1657,1.16570,6.000
6,88.370,0.01,1.2959,1.29590,6.000
6,88.500,0.00,1.4260,1.42600,6.000
6,88.630,0.01,1.5557,1.55570,6.000
6,88.760,0.00,1.6858,1.68580,6.000
6,88.890,0.01,1.8158,1.81580,6.000
6,89.020,0.01,1.9459,1.94590,6.000
6,89.150,0.01,2.0758,2.07580,6.000
6,89.280,0.00,2.2059,2.20590,6.000
6,89.410,0.01,2.3358,2.33580,6.000
6,89.540,0.01,2.4659,2.46590,6.000
6,89.670,0.01,2.5957,2.59570,6.000
6,89.800,0.01,2.7258,2.72580,6.000
6,89.930,0.01,2.8559,2.85590,6.000
6,90.060,0.01,2.9858,2.98580,6.000
6,90.190,0.05,3.1157,3.11570,6.000
6,90.320,0.21,3.2458,3.24580,6.000
6,90.450,0.53,3.3760,3.37600,6.000
6,90.580,0.99,3.5060,3.50600,6.000
6,90.710,1.61,3.6357,3.63570,6.000
6,90.840,2.43,3.7658,3.76580,6.000
6,90.970,3.49,3.8958,3.89580,6.000
6,91.100,4.80,4.0259,4.02590,6.000
6,91.230,6.43,4.1559,4.15590,6.000
6,91.360,8.36,4.2856,4.28560,6.000
6,91.490,10.63,4.4158,4.41580,6.000
6,91.620,13.25,4.5460,4.54600,6.000
6,91.750,16.24,4.6758,4.67580,6.000
6,91.880,19.67,4.8058,4.80580,6.000
6,92.010,23.61,4.9359,4.93590,6.000
6,92.140,28.20,5.0661,5.06610,6.000
6,92.270,33.79,5.1959,5.19590,6.000
6,92.400,40.48,5.3257,5.32570,6.000
6,92.530,48.55,5.4558,5.45580,6.000
6,92.670,51.20,5.5025,5.50250,6.000
6,92.800,35.13,5.3726,5.37260,6.000
6,92.930,25.47,5.2426,5.24260,6.000
6,93.060,19.03,5.1127,5.11270,6.000
6,93.190,14.36,4.9827,4.98270,6.000
6,93.320,10.97,4.8525,4.85250,6.000
6,93.450,8.47,4.7225,4.72250,6.000
6,93.580,6.57,4.5926,4.59260,6.000
6,93.710,5.20,4.4626,4.46260,6.000
6,93.840,4.09,4.3326,4.33260,6.000
6,93.970,3.06,4.2024,4.20240,6.000
6,94.100,2.26,4.0726,4.07260,6.000
6,94.230,1.68,3.9425,3.94250,6.000
6,94.360,1.17,3.8126,3.81260,6.000
6,94.490,0.75,3.6824,3.68240,6.000
6,94.620,0.44,3.5525,3.55250,6.000
6,94.750,0.21,3.4225,3.42250,6.000
6,94.880,0.08,3.2925,3.29250,6.000
6,95.010,0.00,3.1623,3.16230,6.000
6,95.140,0.01,3.0324,3.03240,6.000
6,95.270,0.00,2.9025,2.90250,6.000
6,95.400,0.01,2.7724,2.77240,6.000
6,95.530,0.01,2.6422,2.64220,6.000
6,95.660,0.00,2.5124,2.51240,6.000
6,95.790,-0.01,2.3823,2.38230,6.000
6,95.920,0.01,2.2525,2.25250,6.000
6,96.050,0.00,2.1225,2.12250,6.000
6,96.180,0.00,1.9924,1.99240,6.000
6,96.310,0.00,1.8623,1.86230,6.000
6,96.440,0.01,1.7324,1.73240,6.000
6,96.570,0.01,1.6022,1.60220,6.000
6,96.700,0.02,1.4723,1.47230,6.000
6,96.830,0.01,1.3425,1.34250,6.000
6,96.960,0.00,1.2125,1.21250,6.000
6,97.090,0.01,1.0822,1.08220,6.000
6,97.220,0.01,0.9522,0.95220,6.000
6,97.350,0.00,0.8224,0.82240,6.000
6,97.480,0.01,0.6924,0.69240,6.000
6,97.610,0.01,0.5622,0.56220,6.000
6,97.740,0.01,0.4322,0.43220,6.000
6,97.870,0.02,0.3023,0.30230,6.000
6,98.000,0.01,0.1723,0.17230,6.000
6,98.130,0.00,0.0422,0.04220,6.000
6,98.280,0.00,-0.0345,-0.03450,6.000
6,98.410,0.01,-0.0003,-0.00030,6.000
6,98.540,0.00,-0.0003,-0.00030,6.000
6,98.670,0.01,-0.0003,-0.00030,6.000
6,98.800,0.00,-0.0003,-0.00030,6.000
6,98.930,0.01,-0.0003,-0.00030,6.000
6,99.060,0.01,-0.0003,-0.00030,6.000
6,99.190,0.00,-0.0003,-0.00030,6.000
6,99.320,0.01,-0.0003,-0.00030,6.000
6,99.450,0.00,-0.0003,-0.00030,6.000
6,99.580,0.01,-0.0003,-0.00030,6.000
6,99.710,0.01,-0.0003,-0.00030,6.000
6,99.840,-0.01,-0.0003,-0.00030,6.000
6,99.970,-0.01,-0.0003,-0.00030,6.000
6,100.100,0.00,-0.0003,-0.00030,6.000
6,100.230,0.01,-0.0003,-0.00030,6.000
6,100.360,0.00,-0.0003,-0.00030,6.000
6,100.490,0.01,-0.0003,-0.00030,6.000
6,100.620,0.00,-0.0002,-0.00020,6.000
6,100.750,0.01,-0.0002,-0.00020,6.000
6,100.880,0.01,-0.0002,-0.00020,6.000
6,101.010,0.02,-0.0002,-0.00020,6.000
6,101.140,0.01,-0.0002,-0.00020,6.000
6,101.270,0.01,-0.0002,-0.00020,6.000
6,101.410,0.00,-0.0002,-0.00020,6.000
6,101.540,0.01,-0.0002,-0.00020,6.000
6,101.670,0.00,-0.0002,-0.00020,6.000
6,101.800,0.01,-0.0002,-0.00020,6.000
6,101.930,0.01,-0.0002,-0.00020,6.000
6,102.060,0.01,-0.0002,-0.00020,6.000
6,102.190,0.01,-0.0002,-0.00020,6.000
6,102.320,0.01,-0.0002,-0.00020,6.000
6,102.450,0.01,-0.0002,-0.00020,6.000
6,102.580,0.01,-0.0002,-0.00020,6.000
6,102.710,0.01,-0.0002,-0.00020,6.000
6,102.840,0.01,-0.0002,-0.00020,6.000
6,102.970,0.01,-0.0002,-0.00020,6.000
6,103.100,0.01,-0.0002,-0.00020,6.000
6,103.230,0.02,-0.0002,-0.00020,6.000
6,103.360,0.02,-0.0001,-0.00010,6.000
6,103.490,0.01,-0.0001,-0.00010,6.000
6,103.620,0.01,-0.0001,-0.00010,6.000
6,103.750,0.00,-0.0001,-0.00010,6.000
6,103.880,0.01,-0.0001,-0.00010,6.000
6,104.010,0.01,-0.0001,-0.00010,6.000
6,104.140,0.00,-0.0001,-0.00010,6.000
6,104.270,0.01,-0.0001,-0.00010,6.000
7,104.500,0.00,0.0356,0.03560,7.000
7,104.630,0.00,0.1656,0.16560,7.000
7,104.760,0.01,0.2958,0.29580,7.000
7,104.890,0.01,0.4257,0.42570,7.000
7,105.020,0.01,0.5557,0.55570,7.000
7,105.150,0.00,0.6857,0.68570,7.000
7,105.280,0.01,0.8158,0.81580,7.000
7,105.410,0.00,0.9458,0.94580,7.000
7,105.540,0.01,1.0755,1.07550,7.000
7,105.670,0.02,1.2058,1.20580,7.000
7,105.800,0.00,1.3358,1.33580,7.000
7,105.930,0.00,1.4660,1.46600,7.000
7,106.060,0.01,1.5957,1.59570,7.000
7,106.190,0.01,1.7257,1.72570,7.000
7,106.320,0.01,1.8559,1.85590,7.000
7,106.450,0.01,1.9859,1.98590,7.000
7,106.580,0.00,2.1158,2.11580,7.000
7,106.710,0.01,2.2459,2.24590,7.000
7,106.840,0.00,2.3757,2.37570,7.000
7,106.970,0.01,2.5059,2.50590,7.000
7,107.100,0.01,2.6359,2.63590,7.000
7,107.230,0.01,2.7657,2.76570,7.000
7,107.360,0.00,2.8958,2.89580,7.000
7,107.490,0.00,3.0258,3.02580,7.000
7,107.620,0.10,3.1557,3.15570,7.000
7,107.750,0.30,3.2858,3.28580,7.000
7,107.880,0.64,3.4160,3.41600,7.000
7,108.010,1.16,3.5460,3.54600,7.000
7,108.140,1.82,3.6757,3.67570,7.000
7,108.270,2.71,3.8058,3.80580,7.000
7,108.400,3.83,3.9358,3.93580,7.000
7,108.530,5.22,4.0660,4.06600,7.000
7,108.660,6.94,4.1958,4.19580,7.000
7,108.790,8.97,4.3258,4.32580,7.000
7,108.920,11.34,4.4559,4.45590,7.000
7,109.050,14.07,4.5860,4.58600,7.000
7,109.180,17.18,4.7158,4.71580,7.000
7,109.310,20.77,4.8457,4.84570,7.000
7,109.440,24.88,4.9758,4.97580,7.000
7,109.570,29.73,5.1060,5.10600,7.000
7,109.700,35.62,5.2359,5.23590,7.000
7,109.830,42.71,5.3658,5.36580,7.000
7,109.960,51.37,5.4958,5.49580,7.000
7,110.100,45.05,5.4626,5.46260,7.000
7,110.230,31.65,5.3326,5.33260,7.000
7,110.360,23.18,5.2026,5.20260,7.000
7,110.490,17.34,5.0727,5.07270,7.000
7,110.620,13.11,4.9426,4.94260,7.000
7,110.750,10.04,4.8126,4.81260,7.000
7,110.880,7.76,4.6825,4.68250,7.000
7,111.010,6.09,4.5526,4.55260,7.000
7,111.140,4.81,4.4226,4.42260,7.000
7,111.270,3.73,4.2925,4.29250,7.000
7,111.400,2.77,4.1625,4.16250,7.000
7,111.530,2.04,4.0326,4.03260,7.000
7,111.660,1.51,3.9025,3.90250,7.000
7,111.790,1.01,3.7725,3.77250,7.000
7,111.920,0.63,3.6422,3.64220,7.000
7,112.050,0.36,3.5126,3.51260,7.000
7,112.180,0.16,3.3826,3.38260,7.000
7,112.310,0.05,3.2526,3.25260,7.000
7,112.440,0.01,3.1223,3.12230,7.000
7,112.570,0.00,2.9924,2.99240,7.000
7,112.700,0.00,2.8625,2.86250,7.000
7,112.830,0.00,2.7323,2.73230,7.000
7,112.960,0.01,2.6023,2.60230,7.000
7,113.090,0.01,2.4724,2.47240,7.000
7,113.220,0.01,2.3422,2.34220,7.000
7,113.350,0.01,2.2125,2.21250,7.000
7,113.480,0.01,2.0823,2.08230,7.000
7,113.610,0.01,1.9524,1.95240,7.000
7,113.740,0.01,1.8224,1.82240,7.000
7,113.870,0.01,1.6924,1.69240,7.000
7,114.000,0.01,1.5621,1.56210,7.000
7,114.130,0.01,1.4324,1.43240,7.000
7,114.260,0.01,1.3025,1.30250,7.000
7,114.390,0.01,1.1723,1.17230,7.000
7,114.520,0.02,1.0421,1.04210,7.000
7,114.650,0.02,0.9122,0.91220,7.000
7,114.780,0.01,0.7822,0.78220,7.000
7,114.910,0.01,0.6524,0.65240,7.000
7,115.040,0.02,0.5223,0.52230,7.000
7,115.170,0.01,0.3922,0.39220,7.000
7,115.300,0.01,0.2622,0.26220,7.000
7,115.430,0.01,0.1323,0.13230,7.000
7,115.560,0.02,0.0022,0.00220,7.000
7,115.710,0.00,-0.0020,-0.00200,7.000
7,115.840,0.01,-0.0003,-0.00030,7.000
7,115.970,0.00,-0.0003,-0.00030,7.000
7,116.100,0.01,-0.0003,-0.00030,7.000
7,116.230,0.00,-0.0003,-0.00030,7.000
7,116.360,0.02,-0.0003,-0.00030,7.000
7,116.490,0.01,-0.0003,-0.00030,7.000
7,116.620,0.01,-0.0003,-0.00030,7.000
7,116.750,0.01,-0.0003,-0.00030,7.000
7,116.880,0.01,-0.0003,-0.00030,7.000
7,117.010,0.02,-0.0003,-0.00030,7.000
7,117.140,0.00,-0.0003,-0.00030,7.000
7,117.270,0.00,-0.0003,-0.00030,7.000
7,117.400,0.01,-0.0003,-0.00030,7.000
7,117.530,0.01,-0.0003,-0.00030,7.000
7,117.660,0.01,-0.0003,-0.00030,7.000
7,117.790,0.01,-0.0002,-0.00020,7.000
7,117.920,0.00,-0.0002,-0.00020,7.000
7,118.050,-0.01,-0.0002,-0.00020,7.000
7,118.180,0.01,-0.0002,-0.00020,7.000
7,118.310,0.01,-0.0002,-0.00020,7.000
7,118.440,0.00,-0.0002,-0.00020,7.000
7,118.570,0.01,-0.0002,-0.00020,7.000
7,118.710,-0.01,-0.0002,-0.00020,7.000
7,118.840,0.01,-0.0002,-0.00020,7.000
7,118.970,0.01,-0.0002,-0.00020,7.000
7,119.100,0.00,-0.0002,-0.00020,7.000
7,119.230,0.02,-0.0002,-0.00020,7.000
7,119.360,0.01,-0.0002,-0.00020,7.000
7,119.490,0.01,-0.0002,-0.00020,7.000
7,119.620,0.01,-0.0002,-0.00020,7.000
7,119.750,0.00,-0.0002,-0.00020,7.000
7,119.880,0.00,-0.0002,-0.00020,7.000
7,120.010,0.01,-0.0002,-0.00020,7.000
7,120.140,0.02,-0.0002,-0.00020,7.000
7,120.270,0.02,-0.0002,-0.00020,7.000
7,120.400,0.01,-0.0002,-0.00020,7.000
7,120.530,0.01,-0.0001,-0.00010,7.000
7,120.660,0.01,-0.0001,-0.00010,7.000
7,120.790,0.01,-0.0001,-0.00010,7.000
7,120.920,0.01,-0.0001,-0.00010,7.000
7,121.050,0.01,-0.0001,-0.00010,7.000
7,121.180,0.01,-0.0001,-0.00010,7.000
7,121.310,0.01,-0.0001,-0.00010,7.000
7,121.440,0.01,-0.0001,-0.00010,7.000
7,121.570,0.01,-0.0001,-0.00010,7.000
7,121.790,0.01,0.0000,0.00000,7.000
8,121.930,0.00,0.0757,0.07570,8.000
8,122.060,-0.01,0.2056,0.20560,8.000
8,122.190,0.00,0.3357,0.33570,8.000
8,122.320,0.01,0.4658,0.46580,8.000
8,122.450,0.00,0.5958,0.59580,8.000
8,122.580,0.01,0.7258,0.72580,8.000
8,122.710,0.00,0.8557,0.85570,8.000
8,122.840,0.01,0.9858,0.98580,8.000
8,122.970,0.00,1.1157,1.11570,8.000
8,123.100,0.00,1.2459,1.24590,8.000
8,123.230,0.00,1.3759,1.37590,8.000
8,123.360,0.00,1.5059,1.50590,8.000
8,123.490,0.00,1.6357,1.63570,8.000
8,123.620,0.01,1.7657,1.76570,8.000
8,123.750,0.00,1.8958,1.89580,8.000
8,123.880,0.01,2.0259,2.02590,8.000
8,124.010,0.01,2.1559,2.15590,8.000
8,124.140,0.00,2.2858,2.28580,8.000
8,124.270,0.01,2.4158,2.41580,8.000
8,124.400,0.00,2.5459,2.54590,8.000
8,124.530,0.01,2.6758,2.67580,8.000
8,124.660,0.00,2.8058,2.80580,8.000
8,124.790,0.01,2.9358,2.93580,8.000
8,124.920,0.01,3.0658,3.06580,8.000
8,125.050,0.13,3.1957,3.19570,8.000
8,125.180,0.38,3.3258,3.32580,8.000
8,125.310,0.78,3.4559,3.45590,8.000
8,125.440,1.33,3.5859,3.58590,8.000
8,125.570,2.05,3.7158,3.71580,8.000
8,125.700,3.00,3.8457,3.84570,8.000
8,125.830,4.21,3.9759,3.97590,8.000
8,125.960,5.70,4.1060,4.10600,8.000
8,126.090,7.51,4.2358,4.23580,8.000
8,126.220,9.65,4.3657,4.36570,8.000
8,126.350,12.14,4.4959,4.49590,8.000
8,126.480,14.97,4.6259,4.62590,8.000
8,126.610,18.22,4.7558,4.75580,8.000
8,126.740,21.95,4.8857,4.88570,8.000
8,126.870,26.23,5.0159,5.01590,8.000
8,127.000,31.39,5.1459,5.14590,8.000
8,127.130,37.59,5.2759,5.27590,8.000
8,127.260,45.12,5.4058,5.40580,8.000
8,127.400,54.44,5.5292,5.52920,8.000
8,127.530,40.09,5.4228,5.42280,8.000
8,127.660,28.60,5.2926,5.29260,8.000
8,127.790,21.16,5.1625,5.16250,8.000
8,127.920,15.87,5.0328,5.03280,8.000
8,128.050,12.05,4.9027,4.90270,8.000
8,128.180,9.26,4.7726,4.77260,8.000
8,128.310,7.17,4.6425,4.64250,8.000
8,128.440,5.65,4.5127,4.51270,8.000
8,128.570,4.46,4.3826,4.38260,8.000
8,128.700,3.41,4.2525,4.25250,8.000
8,128.830,2.49,4.1225,4.12250,8.000
8,128.960,1.88,3.9925,3.99250,8.000
8,129.090,1.35,3.8626,3.86260,8.000
8,129.220,0.86,3.7325,3.73250,8.000
8,129.350,0.52,3.6023,3.60230,8.000
8,129.480,0.28,3.4726,3.47260,8.000
8,129.610,0.11,3.3427,3.34270,8.000
8,129.740,0.01,3.2125,3.21250,8.000
8,129.870,0.00,3.0823,3.08230,8.000
8,130.000,-0.01,2.9522,2.95220,8.000
8,130.130,0.00,2.8224,2.82240,8.000
8,130.260,0.01,2.6923,2.69230,8.000
8,130.390,0.00,2.5623,2.56230,8.000
8,130.520,0.00,2.4323,2.43230,8.000
8,130.650,0.00,2.3023,2.30230,8.000
8,130.780,0.00,2.1725,2.17250,8.000
8,130.910,0.00,2.0422,2.04220,8.000
8,131.040,0.00,1.9123,1.91230,8.000
8,131.170,0.01,1.7824,1.78240,8.000
8,131.300,0.01,1.6523,1.65230,8.000
8,131.430,0.01,1.5223,1.52230,8.000
8,131.560,-0.01,1.3924,1.39240,8.000
8,131.690,0.00,1.2625,1.26250,8.000
8,131.820,0.00,1.1323,1.13230,8.000
8,131.950,0.00,1.0023,1.00230,8.000
8,132.080,0.00,0.8722,0.87220,8.000
8,132.210,0.00,0.7423,0.74230,8.000
8,132.340,0.02,0.6124,0.61240,8.000
8,132.470,0.00,0.4822,0.48220,8.000
8,132.600,0.00,0.3522,0.35220,8.000
8,132.730,0.00,0.2222,0.22220,8.000
8,132.860,0.01,0.0924,0.09240,8.000
8,133.010,0.01,-0.0491,-0.04910,8.000
8,133.140,0.01,-0.0004,-0.00040,8.000
8,133.270,0.00,-0.0003,-0.00030,8.000
8,133.400,0.00,-0.0003,-0.00030,8.000
8,133.530,0.01,-0.0003,-0.00030,8.000
8,133.660,0.00,-0.0003,-0.00030,8.000
8,133.790,0.01,-0.0003,-0.00030,8.000
8,133.920,0.00,-0.0003,-0.00030,8.000
8,134.050,0.00,-0.0003,-0.00030,8.000
8,134.180,0.00,-0.0003,-0.00030,8.000
8,134.310,0.00,-0.0003,-0.00030,8.000
8,134.440,-0.01,-0.0003,-0.00030,8.000
8,134.570,-0.01,-0.0003,-0.00030,8.000
8,134.700,0.02,-0.0003,-0.00030,8.000
8,134.830,0.00,-0.0003,-0.00030,8.000
8,134.960,0.00,-0.0003,-0.00030,8.000
8,135.090,0.00,-0.0003,-0.00030,8.000
8,135.220,0.01,-0.0003,-0.00030,8.000
8,135.350,0.00,-0.0003,-0.00030,8.000
8,135.480,-0.01,-0.0002,-0.00020,8.000
8,135.610,-0.01,-0.0002,-0.00020,8.000
8,135.740,0.00,-0.0002,-0.00020,8.000
8,135.870,0.00,-0.0002,-0.00020,8.000
8,136.000,0.00,-0.0002,-0.00020,8.000
8,136.150,0.01,-0.0002,-0.00020,8.000
8,136.280,0.02,-0.0002,-0.00020,8.000
8,136.410,-0.01,-0.0002,-0.00020,8.000
8,136.540,0.00,-0.0002,-0.00020,8.000
8,136.670,0.00,-0.0002,-0.00020,8.000
8,136.800,0.01,-0.0002,-0.00020,8.000
8,136.930,0.00,-0.0002,-0.00020,8.000
8,137.060,0.00,-0.0002,-0.00020,8.000
8,137.190,0.01,-0.0002,-0.00020,8.000
8,137.320,0.01,-0.0002,-0.00020,8.000
8,137.450,0.02,-0.0002,-0.00020,8.000
8,137.580,0.00,-0.0002,-0.00020,8.000
8,137.710,-0.01,-0.0002,-0.00020,8.000
8,137.840,0.00,-0.0002,-0.00020,8.000
8,137.970,0.01,-0.0002,-0.00020,8.000
8,138.100,0.00,-0.0001,-0.00010,8.000
8,138.230,0.00,-0.0001,-0.00010,8.000
8,138.360,0.00,-0.0001,-0.00010,8.000
8,138.490,0.00,-0.0001,-0.00010,8.000
8,138.620,0.00,-0.0001,-0.00010,8.000
8,138.750,0.01,-0.0001,-0.00010,8.000
8,138.880,-0.01,-0.0001,-0.00010,8.000
8,139.010,0.00,-0.0001,-0.00010,8.000
9,139.240,-0.01,0.0078,0.00780,9.000
9,139.370,-0.01,0.1358,0.13580,9.000
9,139.500,-0.02,0.2657,0.26570,9.000
9,139.630,-0.01,0.3955,0.39550,9.000
9,139.760,-0.02,0.5257,0.52570,9.000
9,139.890,-0.01,0.6559,0.65590,9.000
9,140.020,-0.01,0.7858,0.78580,9.000
9,140.150,-0.03,0.9156,0.91560,9.000
9,140.280,-0.01,1.0456,1.04560,9.000
9,140.410,0.00,1.1758,1.17580,9.000
9,140.540,-0.01,1.3059,1.30590,9.000
9,140.670,-0.01,1.4357,1.43570,9.000
9,140.800,0.00,1.5658,1.56580,9.000
9,140.930,-0.02,1.6957,1.69570,9.000
9,141.060,0.00,1.8258,1.82580,9.000
9,141.190,-0.01,1.9558,1.95580,9.000
9,141.320,-0.01,2.0857,2.08570,9.000
9,141.450,-0.02,2.2160,2.21600,9.000
9,141.580,-0.01,2.3457,2.34570,9.000
9,141.710,-0.03,2.4758,2.47580,9.000
9,141.840,-0.01,2.6059,2.60590,9.000
9,141.970,0.00,2.7358,2.73580,9.000
9,142.100,-0.01,2.8660,2.86600,9.000
9,142.230,-0.02,2.9958,2.99580,9.000
9,142.360,0.05,3.1258,3.12580,9.000
9,142.490,0.21,3.2559,3.25590,9.000
9,142.620,0.53,3.3860,3.38600,9.000
9,142.750,0.99,3.5158,3.51580,9.000
9,142.880,1.62,3.6457,3.64570,9.000
9,143.010,2.45,3.7758,3.77580,9.000
9,143.140,3.51,3.9058,3.90580,9.000
9,143.270,4.84,4.0359,4.03590,9.000
9,143.400,6.49,4.1657,4.16570,9.000
9,143.530,8.43,4.2959,4.29590,9.000
9,143.660,10.72,4.4259,4.42590,9.000
9,143.790,13.36,4.5560,4.55600,9.000
9,143.920,16.37,4.6858,4.68580,9.000
9,144.050,19.82,4.8158,4.81580,9.000
9,144.180,23.78,4.9459,4.94590,9.000
9,144.310,28.43,5.0760,5.07600,9.000
9,144.440,34.04,5.2057,5.20570,9.000
9,144.570,40.79,5.3359,5.33590,9.000
9,144.700,49.04,5.4659,5.46590,9.000
9,144.840,49.49,5.4925,5.49250,9.000
9,144.970,34.09,5.3626,5.36260,9.000
9,145.100,24.75,5.2327,5.23270,9.000
9,145.230,18.47,5.1027,5.10270,9.000
9,145.360,13.93,4.9726,4.97260,9.000
9,145.490,10.62,4.8425,4.84250,9.000
9,145.620,8.19,4.7125,4.71250,9.000
9,145.750,6.41,4.5827,4.58270,9.000
9,145.880,5.05,4.4527,4.45270,9.000
9,146.010,3.96,4.3224,4.32240,9.000
9,146.140,2.94,4.1926,4.19260,9.000
9,146.270,2.15,4.0626,4.06260,9.000
9,146.400,1.60,3.9325,3.93250,9.000
9,146.530,1.09,3.8025,3.80250,9.000
9,146.660,0.68,3.6725,3.67250,9.000
9,146.790,0.39,3.5425,3.54250,9.000
9,146.920,0.17,3.4126,3.41260,9.000
9,147.050,0.05,3.2824,3.28240,9.000
9,147.180,-0.01,3.1525,3.15250,9.000
9,147.310,-0.01,3.0224,3.02240,9.000
9,147.440,-0.01,2.8924,2.89240,9.000
9,147.570,-0.01,2.7622,2.76220,9.000
9,147.700,-0.01,2.6324,2.63240,9.000
9,147.830,-0.01,2.5025,2.50250,9.000
9,147.960,-0.01,2.3722,2.37220,9.000
9,148.090,-0.01,2.2423,2.24230,9.000
9,148.220,-0.01,2.1125,2.11250,9.000
9,148.350,-0.01,1.9825,1.98250,9.000
9,148.480,-0.01,1.8523,1.85230,9.000
9,148.610,-0.01,1.7222,1.72220,9.000
9,148.740,-0.01,1.5923,1.59230,9.000
9,148.870,-0.02,1.4623,1.46230,9.000
9,149.000,-0.01,1.3324,1.33240,9.000
9,149.130,-0.01,1.2022,1.20220,9.000
9,149.260,-0.01,1.0722,1.07220,9.000
9,149.390,-0.01,0.9424,0.94240,9.000
9,149.520,-0.01,0.8123,0.81230,9.000
9,149.650,-0.01,0.6821,0.68210,9.000
9,149.780,-0.01,0.5523,0.55230,9.000
9,149.910,-0.01,0.4223,0.42230,9.000
9,150.040,-0.02,0.2924,0.29240,9.000
9,150.170,-0.02,0.1622,0.16220,9.000
9,150.300,-0.01,0.0323,0.03230,9.000
9,150.450,-0.01,-0.0263,-0.02630,9.000
9,150.580,-0.02,-0.0003,-0.00030,9.000
9,150.710,-0.01,-0.0003,-0.00030,9.000
9,150.840,-0.01,-0.0003,-0.00030,9.000
9,150.970,-0.01,-0.0003,-0.00030,9.000
9,151.100,-0.01,-0.0003,-0.00030,9.000
9,151.230,-0.01,-0.0003,-0.00030,9.000
9,151.360,-0.02,-0.0003,-0.00030,9.000
9,151.490,0.00,-0.0003,-0.00030,9.000
9,151.620,-0.02,-0.0003,-0.00030,9.000
9,151.750,-0.01,-0.0003,-0.00030,9.000
9,151.880,-0.01,-0.0003,-0.00030,9.000
9,152.010,0.00,-0.0003,-0.00030,9.000
9,152.140,0.00,-0.0002,-0.00020,9.000
9,152.270,-0.01,-0.0002,-0.00020,9.000
9,152.400,-0.01,-0.0002,-0.00020,9.000
9,152.530,-0.01,-0.0002,-0.00020,9.000
9,152.660,-0.01,-0.0002,-0.00020,9.000
9,152.790,-0.01,-0.0002,-0.00020,9.000
9,152.920,-0.01,-0.0002,-0.00020,9.000
9,153.050,-0.01,-0.0002,-0.00020,9.000
9,153.180,-0.01,-0.0002,-0.00020,9.000
9,153.310,-0.01,-0.0002,-0.00020,9.000
9,153.460,-0.01,-0.0002,-0.00020,9.000
9,153.590,-0.01,-0.0002,-0.00020,9.000
9,153.720,-0.02,-0.0002,-0.00020,9.000
9,153.850,-0.01,-0.0002,-0.00020,9.000
9,153.980,-0.02,-0.0002,-0.00020,9.000
9,154.110,-0.01,-0.0002,-0.00020,9.000
9,154.240,-0.03,-0.0002,-0.00020,9.000
9,154.370,-0.01,-0.0002,-0.00020,9.000
9,154.500,-0.02,-0.0002,-0.00020,9.000
9,154.630,-0.01,-0.0002,-0.00020,9.000
9,154.760,-0.01,-0.0002,-0.00020,9.000
9,154.890,-0.01,-0.0001,-0.00010,9.000
9,155.020,-0.01,-0.0001,-0.00010,9.000
9,155.150,0.00,-0.0001,-0.00010,9.000
9,155.280,-0.01,-0.0001,-0.00010,9.000
9,155.410,-0.01,-0.0001,-0.00010,9.000
9,155.540,-0.01,-0.0001,-0.00010,9.000
9,155.670,-0.01,-0.0001,-0.00010,9.000
9,155.800,-0.01,-0.0001,-0.00010,9.000
9,155.930,-0.01,-0.0001,-0.00010,9.000
9,156.060,-0.02,-0.0001,-0.00010,9.000
9,156.190,0.00,-0.0001,-0.00010,9.000
9,156.320,-0.01,-0.0001,-0.00010,9.000
9,156.450,0.00,-0.0001,-0.00010,9.000
10,156.680,0.01,0.0657,0.06570,10.000
10,156.810,-0.01,0.1956,0.19560,10.000
10,156.940,-0.02,0.3257,0.32570,10.000
10,157.070,-0.01,0.4558,0.45580,10.000
10,157.200,-0.02,0.5859,0.58590,10.000
10,157.330,-0.01,0.7157,0.71570,10.000
10,157.460,-0.02,0.8457,0.84570,10.000
10,157.590,-0.01,0.9757,0.97570,10.000
10,157.720,-0.01,1.1058,1.10580,10.000
10,157.850,-0.02,1.2357,1.23570,10.000
10,157.980,-0.01,1.3657,1.36570,10.000
10,158.110,0.00,1.4959,1.49590,10.000
10,158.240,0.00,1.6258,1.62580,10.000
10,158.370,-0.01,1.7557,1.75570,10.000
10,158.500,-0.01,1.8857,1.88570,10.000
10,158.630,-0.01,2.0159,2.01590,10.000
10,158.760,-0.01,2.1460,2.14600,10.000
10,158.890,-0.01,2.2758,2.27580,10.000
10,159.020,0.00,2.4057,2.40570,10.000
10,159.150,0.00,2.5358,2.53580,10.000
10,159.280,-0.01,2.6659,2.66590,10.000
10,159.410,-0.01,2.7958,2.79580,10.000
10,159.540,-0.02,2.9258,2.92580,10.000
10,159.670,-0.01,3.0557,3.05570,10.000
10,159.800,0.11,3.1859,3.18590,10.000
10,159.930,0.35,3.3159,3.31590,10.000
10,160.060,0.73,3.4458,3.44580,10.000
10,160.190,1.27,3.5757,3.57570,10.000
10,160.320,1.97,3.7059,3.70590,10.000
10,160.450,2.94,3.8357,3.83570,10.000
10,160.580,4.11,3.9658,3.96580,10.000
10,160.710,5.59,4.0959,4.09590,10.000
10,160.840,7.38,4.2258,4.22580,10.000
10,160.970,9.49,4.3558,4.35580,10.000
10,161.100,11.95,4.4858,4.48580,10.000
10,161.230,14.76,4.6159,4.61590,10.000
10,161.360,17.97,4.7459,4.74590,10.000
10,161.490,21.67,4.8759,4.87590,10.000
10,161.620,25.91,5.0058,5.00580,10.000
10,161.750,30.98,5.1358,5.13580,10.000
10,161.880,37.10,5.2659,5.26590,10.000
10,162.010,44.53,5.3958,5.39580,10.000
10,162.150,54.41,5.5272,5.52720,10.000
10,162.280,41.34,5.4327,5.43270,10.000
10,162.410,29.41,5.3027,5.30270,10.000
10,162.540,21.70,5.1725,5.17250,10.000
10,162.670,16.29,5.0426,5.04260,10.000
10,162.800,12.32,4.9127,4.91270,10.000
10,162.930,9.46,4.7827,4.78270,10.000
10,163.060,7.32,4.6527,4.65270,10.000
10,163.190,5.76,4.5226,4.52260,10.000
10,163.320,4.52,4.3926,4.39260,10.000
10,163.450,3.47,4.2626,4.26260,10.000
10,163.580,2.56,4.1327,4.13270,10.000
10,163.710,1.90,4.0024,4.00240,10.000
10,163.840,1.36,3.8726,3.87260,10.000
10,163.970,0.89,3.7425,3.74250,10.000
10,164.100,0.54,3.6124,3.61240,10.000
10,164.230,0.28,3.4824,3.48240,10.000
10,164.360,0.11,3.3526,3.35260,10.000
10,164.490,0.01,3.2226,3.22260,10.000
10,164.620,-0.01,3.0924,3.09240,10.000
10,164.750,-0.01,2.9622,2.96220,10.000
10,164.880,-0.01,2.8324,2.83240,10.000
10,165.010,-0.01,2.7024,2.70240,10.000
10,165.140,-0.02,2.5724,2.57240,10.000
10,165.270,-0.02,2.4422,2.44220,10.000
10,165.400,-0.01,2.3123,2.31230,10.000
10,165.530,-0.01,2.1825,2.18250,10.000
10,165.660,-0.01,2.0524,2.05240,10.000
10,165.790,-0.01,1.9222,1.92220,10.000
10,165.920,-0.01,1.7923,1.79230,10.000
10,166.050,-0.02,1.6624,1.66240,10.000
10,166.180,-0.01,1.5323,1.53230,10.000
10,166.310,-0.01,1.4023,1.40230,10.000
10,166.440,-0.01,1.2724,1.27240,10.000
10,166.570,-0.02,1.1424,1.14240,10.000
10,166.700,-0.01,1.0123,1.01230,10.000
10,166.830,-0.01,0.8821,0.88210,10.000
10,166.960,-0.01,0.7523,0.75230,10.000
10,167.090,-0.01,0.6224,0.62240,10.000
10,167.220,-0.01,0.4924,0.49240,10.000
10,167.350,-0.01,0.3622,0.36220,10.000
10,167.480,0.00,0.2321,0.23210,10.000
10,167.610,0.00,0.1023,0.10230,10.000
10,167.760,-0.02,-0.0445,-0.04450,10.000
10,167.890,-0.01,-0.0004,-0.00040,10.000
10,168.020,-0.02,-0.0004,-0.00040,10.000
10,168.150,-0.01,-0.0004,-0.00040,10.000
10,168.280,-0.01,-0.0004,-0.00040,10.000
10,168.410,-0.03,-0.0004,-0.00040,10.000
10,168.540,-0.01,-0.0003,-0.00030,10.000
10,168.670,-0.01,-0.0003,-0.00030,10.000
10,168.800,-0.01,-0.0003,-0.00030,10.000
10,168.930,-0.01,-0.0003,-0.00030,10.000
10,169.060,-0.02,-0.0003,-0.00030,10.000
10,169.190,0.00,-0.0003,-0.00030,10.000
10,169.320,-0.02,-0.0003,-0.00030,10.000
10,169.450,-0.02,-0.0003,-0.00030,10.000
10,169.580,-0.01,-0.0003,-0.00030,10.000
10,169.710,-0.01,-0.0003,-0.00030,10.000
10,169.840,-0.01,-0.0003,-0.00030,10.000
10,169.970,-0.02,-0.0003,-0.00030,10.000
10,170.100,-0.01,-0.0003,-0.00030,10.000
10,170.230,-0.01,-0.0002,-0.00020,10.000
10,170.360,-0.02,-0.0002,-0.00020,10.000
10,170.490,-0.02,-0.0002,-0.00020,10.000
10,170.620,-0.02,-0.0002,-0.00020,10.000
10,170.750,-0.02,-0.0002,-0.00020,10.000
10,170.900,0.00,-0.0002,-0.00020,10.000
10,171.030,-0.03,-0.0002,-0.00020,10.000
10,171.160,-0.01,-0.0002,-0.00020,10.000
10,171.290,-0.01,-0.0002,-0.00020,10.000
10,171.420,-0.02,-0.0002,-0.00020,10.000
10,171.550,-0.03,-0.0002,-0.00020,10.000
10,171.680,-0.01,-0.0002,-0.00020,10.000
10,171.810,-0.01,-0.0002,-0.00020,10.000
10,171.940,-0.01,-0.0002,-0.00020,10.000
10,172.070,0.00,-0.0002,-0.00020,10.000
10,172.200,-0.02,-0.0002,-0.00020,10.000
10,172.330,-0.01,-0.0002,-0.00020,10.000
10,172.460,-0.01,-0.0002,-0.00020,10.000
10,172.590,0.00,-0.0002,-0.00020,10.000
10,172.720,-0.01,-0.0002,-0.00020,10.000
10,172.850,-0.01,-0.0001,-0.00010,10.000
10,172.980,0.00,-0.0001,-0.00010,10.000
10,173.110,0.00,-0.0001,-0.00010,10.000
10,173.240,-0.01,-0.0001,-0.00010,10.000
10,173.370,-0.03,-0.0001,-0.00010,10.000
10,173.500,0.00,-0.0001,-0.00010,10.000
10,173.630,0.00,-0.0001,-0.00010,10.000
10,173.760,-0.01,-0.0001,-0.00010,10.000
10,173.830,-0.02,-0.0001,-0.00010,10.000