File: scripts/black/MTS/radhen_black_20degree.txt
""
"Test Method","Radhen_Load_Cntrl_Cmprsn_250N_12-7.msm"
"Sample I. D.","Sample1.mss"
"Specimen Number","8"

"TheCycle_Output ()","_Time (s)","_Load (N)","_Extension (mm)","RealTimeDepth (mm)","CycleNumber ()"

1,0.250,0.00,0.0122,0.01220,1.000
1,0.350,0.00,0.1114,0.11140,1.000
1,0.450,0.00,0.2116,0.21160,1.000
1,0.550,0.00,0.3117,0.31170,1.000
1,0.650,0.00,0.4118,0.41180,1.000
1,0.750,0.00,0.5117,0.51170,1.000
1,0.850,0.00,0.6119,0.61190,1.000
1,0.950,0.00,0.7118,0.71180,1.000
1,1.050,0.00,0.8118,0.81180,1.000
1,1.150,0.00,0.9118,0.91180,1.000
1,1.250,-0.01,1.0119,1.01190,1.000
1,1.350,0.00,1.1116,1.11160,1.000
1,1.450,-0.01,1.2118,1.21180,1.000
1,1.550,0.00,1.3117,1.31170,1.000
1,1.650,0.00,1.4117,1.41170,1.000
1,1.750,0.00,1.5117,1.51170,1.000
1,1.850,-0.01,1.6119,1.61190,1.000
1,1.950,-0.01,1.7118,1.71180,1.000
1,2.050,-0.01,1.8119,1.81190,1.000
1,2.150,0.00,1.9117,1.91170,1.000
1,2.250,0.00,2.0118,2.01180,1.000
1,2.350,0.00,2.1117,2.11170,1.000
1,2.450,0.00,2.2118,2.21180,1.000
1,2.550,0.00,2.3117,2.31170,1.000
1,2.650,0.00,2.4117,2.41170,1.000
1,2.750,0.00,2.5119,2.51190,1.000
1,2.850,0.00,2.6119,2.61190,1.000
1,2.950,0.00,2.7119,2.71190,1.000
1,3.050,0.00,2.8118,2.81180,1.000
1,3.150,0.00,2.9118,2.91180,1.000
1,3.250,0.00,3.0118,3.01180,1.000
1,3.350,0.00,3.1118,3.11180,1.000
1,3.450,0.00,3.2119,3.21190,1.000
1,3.550,0.00,3.3118,3.31180,1.000
1,3.650,-0.01,3.4118,3.41180,1.000
1,3.750,0.00,3.5118,3.51180,1.000
1,3.850,-0.01,3.6118,3.61180,1.000
1,3.950,0.00,3.7118,3.71180,1.000
1,4.050,0.00,3.8119,3.81190,1.000
1,4.150,-0.01,3.9120,3.91200,1.000
1,4.250,0.00,4.0119,4.01190,1.000
1,4.350,0.00,4.1119,4.11190,1.000
1,4.450,0.00,4.2120,4.21200,1.000
1,4.550,0.00,4.3119,4.31190,1.000
1,4.650,-0.01,4.4118,4.41180,1.000
1,4.750,0.00,4.5120,4.51200,1.000
1,4.850,-0.01,4.6118,4.61180,1.000
1,4.950,-0.01,4.7120,4.71200,1.000
1,5.050,0.00,4.8120,4.81200,1.000
1,5.150,0.00,4.9119,4.91190,1.000
1,5.250,0.00,5.0118,5.01180,1.000
1,5.350,0.00,5.1120,5.11200,1.000
1,5.450,0.00,5.2119,5.21190,1.000
1,5.550,-0.01,5.3120,5.31200,1.000
1,5.650,0.00,5.4120,5.41200,1.000
1,5.750,0.00,5.5122,5.51220,1.000
1,5.850,0.00,5.6119,5.61190,1.000
1,5.950,0.00,5.7120,5.71200,1.000
1,6.050,0.00,5.8118,5.81180,1.000
1,6.150,0.00,5.9118,5.91180,1.000
1,6.250,0.00,6.0119,6.01190,1.000
1,6.350,0.00,6.1121,6.11210,1.000
1,6.450,0.00,6.2118,6.21180,1.000
1,6.550,-0.01,6.3120,6.31200,1.000
1,6.650,0.00,6.4120,6.41200,1.000
1,6.750,0.02,6.5121,6.51210,1.000
1,6.850,0.11,6.6119,6.61190,1.000
1,6.950,0.27,6.7121,6.71210,1.000
1,7.050,0.50,6.8118,6.81180,1.000
1,7.150,0.84,6.9119,6.91190,1.000
1,7.250,1.27,7.0118,7.01180,1.000
1,7.350,1.79,7.1120,7.11200,1.000
1,7.450,2.42,7.2118,7.21180,1.000
1,7.550,3.18,7.3120,7.31200,1.000
1,7.650,4.11,7.4119,7.41190,1.000
1,7.750,5.18,7.5121,7.51210,1.000
1,7.850,6.42,7.6118,7.61180,1.000
1,7.950,7.87,7.7121,7.71210,1.000
1,8.050,9.55,7.8119,7.81190,1.000
1,8.150,11.49,7.9120,7.91200,1.000
1,8.250,13.75,8.0117,8.01170,1.000
1,8.350,16.37,8.1119,8.11190,1.000
1,8.450,19.38,8.2118,8.21180,1.000
1,8.550,22.79,8.3119,8.31190,1.000
1,8.650,26.65,8.4117,8.41170,1.000
1,8.750,30.96,8.5119,8.51190,1.000
1,8.850,35.97,8.6119,8.61190,1.000
1,8.950,41.78,8.7120,8.71200,1.000
1,9.050,48.29,8.8118,8.81180,1.000
1,9.200,47.76,8.8368,8.83680,1.000
1,9.300,35.95,8.7368,8.73680,1.000
1,9.400,28.34,8.6369,8.63690,1.000
1,9.500,22.90,8.5368,8.53680,1.000
1,9.600,18.68,8.4368,8.43680,1.000
1,9.700,15.31,8.3366,8.33660,1.000
1,9.800,12.58,8.2368,8.23680,1.000
1,9.900,10.34,8.1367,8.13670,1.000
1,10.000,8.48,8.0367,8.03670,1.000
1,10.100,6.96,7.9366,7.93660,1.000
1,10.200,5.72,7.8366,7.83660,1.000
1,10.300,4.70,7.7367,7.73670,1.000
1,10.400,3.80,7.6367,7.63670,1.000
1,10.500,3.03,7.5366,7.53660,1.000
1,10.600,2.39,7.4366,7.43660,1.000
1,10.700,1.88,7.3366,7.33660,1.000
1,10.800,1.50,7.2366,7.23660,1.000
1,10.900,1.07,7.1366,7.13660,1.000
1,11.000,0.72,7.0366,7.03660,1.000
1,11.100,0.46,6.9364,6.93640,1.000
1,11.200,0.25,6.8364,6.83640,1.000
1,11.300,0.11,6.7364,6.73640,1.000
1,11.400,0.02,6.6366,6.63660,1.000
1,11.500,-0.01,6.5367,6.53670,1.000
1,11.600,-0.01,6.4366,6.43660,1.000
1,11.700,-0.01,6.3365,6.33650,1.000
1,11.800,-0.01,6.2365,6.23650,1.000
1,11.900,-0.01,6.1365,6.13650,1.000
1,12.000,0.00,6.0365,6.03650,1.000
1,12.100,0.00,5.9363,5.93630,1.000
1,12.200,0.00,5.8364,5.83640,1.000
1,12.300,0.00,5.7364,5.73640,1.000
1,12.400,0.00,5.6364,5.63640,1.000
1,12.500,0.00,5.5365,5.53650,1.000
1,12.600,0.00,5.4365,5.43650,1.000
1,12.700,-0.01,5.3364,5.33640,1.000
1,12.800,-0.01,5.2364,5.23640,1.000
1,12.900,0.00,5.1364,5.13640,1.000
1,13.000,0.00,5.0363,5.03630,1.000
1,13.100,0.00,4.9364,4.93640,1.000
1,13.200,-0.01,4.8363,4.83630,1.000
1,13.300,0.00,4.7364,4.73640,1.000
1,13.400,0.00,4.6364,4.63640,1.000
1,13.500,0.00,4.5365,4.53650,1.000
1,13.600,-0.01,4.4362,4.43620,1.000
1,13.700,0.00,4.3362,4.33620,1.000
1,13.800,-0.01,4.2364,4.23640,1.000
1,13.900,-0.01,4.1365,4.13650,1.000
1,14.000,0.00,4.0363,4.03630,1.000
1,14.100,0.00,3.9365,3.93650,1.000
1,14.200,-0.01,3.8364,3.83640,1.000
1,14.300,0.00,3.7363,3.73630,1.000
1,14.400,-0.01,3.6363,3.63630,1.000
1,14.500,0.00,3.5363,3.53630,1.000
1,14.600,-0.01,3.4362,3.43620,1.000
1,14.700,0.00,3.3363,3.33630,1.000
1,14.800,-0.01,3.2362,3.23620,1.000
1,14.900,0.00,3.1363,3.13630,1.000
1,15.000,-0.01,3.0361,3.03610,1.000
1,15.100,-0.01,2.9363,2.93630,1.000
1,15.200,-0.01,2.8361,2.83610,1.000
1,15.300,0.00,2.7363,2.73630,1.000
1,15.400,-0.01,2.6361,2.63610,1.000
1,15.500,0.00,2.5363,2.53630,1.000
1,15.600,0.00,2.4362,2.43620,1.000
1,15.700,0.00,2.3362,2.33620,1.000
1,15.800,0.00,2.2360,2.23600,1.000
1,15.900,0.00,2.1363,2.13630,1.000
1,16.000,-0.01,2.0361,2.03610,1.000
1,16.100,0.00,1.9363,1.93630,1.000
1,16.200,0.00,1.8361,1.83610,1.000
1,16.300,0.00,1.7363,1.73630,1.000
1,16.400,-0.01,1.6360,1.63600,1.000
1,16.500,-0.01,1.5362,1.53620,1.000
1,16.600,-0.01,1.4360,1.43600,1.000
1,16.700,0.00,1.3362,1.33620,1.000
1,16.800,-0.01,1.2360,1.23600,1.000
1,16.900,-0.01,1.1361,1.13610,1.000
1,17.000,-0.01,1.0360,1.03600,1.000
1,17.100,-0.01,0.9362,0.93620,1.000
1,17.200,0.00,0.8360,0.83600,1.000
1,17.300,0.00,0.7363,0.73630,1.000
1,17.400,0.00,0.6360,0.63600,1.000
1,17.500,0.00,0.5363,0.53630,1.000
1,17.600,0.00,0.4360,0.43600,1.000
1,17.700,0.00,0.3362,0.33620,1.000
1,17.800,0.00,0.2359,0.23590,1.000
1,17.900,0.00,0.1360,0.13600,1.000
1,18.000,0.00,0.0360,0.03600,1.000
1,18.150,0.00,-0.0094,-0.00940,1.000
1,18.250,0.00,-0.0004,-0.00040,1.000
1,18.350,0.00,-0.0004,-0.00040,1.000
1,18.450,0.00,-0.0004,-0.00040,1.000
1,18.550,0.00,-0.0004,-0.00040,1.000
1,18.650,0.00,-0.0004,-0.00040,1.000
1,18.750,-0.01,-0.0004,-0.00040,1.000
1,18.850,0.00,-0.0004,-0.00040,1.000
1,18.950,0.00,-0.0004,-0.00040,1.000
1,19.050,0.00,-0.0004,-0.00040,1.000
1,19.150,-0.01,-0.0004,-0.00040,1.000
1,19.250,0.00,-0.0004,-0.00040,1.000
1,19.350,0.00,-0.0004,-0.00040,1.000
1,19.450,0.00,-0.0004,-0.00040,1.000
1,19.550,0.00,-0.0004,-0.00040,1.000
1,19.650,0.00,-0.0004,-0.00040,1.000
1,19.750,0.00,-0.0004,-0.00040,1.000
1,19.850,-0.01,-0.0004,-0.00040,1.000
1,19.950,-0.01,-0.0004,-0.00040,1.000
1,20.050,0.00,-0.0003,-0.00030,1.000
1,20.150,0.00,-0.0003,-0.00030,1.000
1,20.250,0.00,-0.0003,-0.00030,1.000
1,20.350,0.00,-0.0003,-0.00030,1.000
1,20.450,0.00,-0.0003,-0.00030,1.000
1,20.550,0.00,-0.0003,-0.00030,1.000
1,20.650,0.00,-0.0003,-0.00030,1.000
1,20.750,0.00,-0.0003,-0.00030,1.000
1,20.850,0.00,-0.0003,-0.00030,1.000
1,20.950,0.00,-0.0003,-0.00030,1.000
1,21.050,0.00,-0.0003,-0.00030,1.000
1,21.200,0.00,-0.0003,-0.00030,1.000
1,21.300,-0.01,-0.0003,-0.00030,1.000
1,21.400,0.00,-0.0003,-0.00030,1.000
1,21.500,0.00,-0.0003,-0.00030,1.000
1,21.600,0.00,-0.0003,-0.00030,1.000
1,21.700,0.00,-0.0003,-0.00030,1.000
1,21.800,0.00,-0.0003,-0.00030,1.000
1,21.900,0.00,-0.0002,-0.00020,1.000
1,22.000,0.00,-0.0002,-0.00020,1.000
1,22.100,0.00,-0.0002,-0.00020,1.000
2,22.400,0.00,0.1014,0.10150,2.000
2,22.500,0.00,0.2015,0.20160,2.000
2,22.600,0.00,0.3018,0.30190,2.000
2,22.700,0.00,0.4015,0.40160,2.000
2,22.800,0.00,0.5017,0.50180,2.000
2,22.900,0.00,0.6016,0.60170,2.000
2,23.000,0.00,0.7018,0.70190,2.000
2,23.100,0.00,0.8017,0.80180,2.000
2,23.200,0.01,0.9018,0.90190,2.000
2,23.300,0.00,1.0017,1.00180,2.000
2,23.400,0.00,1.1016,1.10170,2.000
2,23.500,0.00,1.2016,1.20170,2.000
2,23.600,0.01,1.3018,1.30190,2.000
2,23.700,0.00,1.4016,1.40170,2.000
2,23.800,0.00,1.5017,1.50180,2.000
2,23.900,0.00,1.6017,1.60180,2.000
2,24.000,0.00,1.7019,1.70200,2.000
2,24.100,0.00,1.8016,1.80170,2.000
2,24.200,0.00,1.9018,1.90190,2.000
2,24.300,0.00,2.0016,2.00170,2.000
2,24.400,0.00,2.1019,2.10200,2.000
2,24.500,0.00,2.2017,2.20180,2.000
2,24.600,0.00,2.3017,2.30180,2.000
2,24.700,0.00,2.4016,2.40170,2.000
2,24.800,0.00,2.5018,2.50190,2.000
2,24.900,0.00,2.6017,2.60180,2.000
2,25.000,0.00,2.7018,2.70190,2.000
2,25.100,0.00,2.8016,2.80170,2.000
2,25.200,0.00,2.9019,2.90200,2.000
2,25.300,0.00,3.0017,3.00180,2.000
2,25.400,0.00,3.1018,3.10190,2.000
2,25.500,0.00,3.2018,3.20190,2.000
2,25.600,0.00,3.3018,3.30190,2.000
2,25.700,0.00,3.4018,3.40190,2.000
2,25.800,0.00,3.5018,3.50190,2.000
2,25.900,0.00,3.6016,3.60170,2.000
2,26.000,0.00,3.7018,3.70190,2.000
2,26.100,0.00,3.8018,3.80190,2.000
2,26.200,0.00,3.9019,3.90200,2.000
2,26.300,0.00,4.0017,4.00180,2.000
2,26.400,0.00,4.1019,4.10200,2.000
2,26.500,0.00,4.2019,4.20200,2.000
2,26.600,0.00,4.3019,4.30200,2.000
2,26.700,0.00,4.4017,4.40180,2.000
2,26.800,0.00,4.5020,4.50210,2.000
2,26.900,0.00,4.6019,4.60200,2.000
2,27.000,0.00,4.7020,4.70210,2.000
2,27.100,0.00,4.8018,4.80190,2.000
2,27.200,0.00,4.9018,4.90190,2.000
2,27.300,0.00,5.0018,5.00190,2.000
2,27.400,0.00,5.1019,5.10200,2.000
2,27.500,0.00,5.2018,5.20190,2.000
2,27.600,0.00,5.3020,5.30210,2.000
2,27.700,0.00,5.4019,5.40200,2.000
2,27.800,0.00,5.5020,5.50210,2.000
2,27.900,0.00,5.6019,5.60200,2.000
2,28.000,0.00,5.7020,5.70210,2.000
2,28.100,0.00,5.8019,5.80200,2.000
2,28.200,0.00,5.9019,5.90200,2.000
2,28.300,0.00,6.0018,6.00190,2.000
2,28.400,0.00,6.1020,6.10210,2.000
2,28.500,0.00,6.2019,6.20200,2.000
2,28.600,0.00,6.3020,6.30210,2.000
2,28.700,0.00,6.4020,6.40210,2.000
2,28.800,0.00,6.5020,6.50210,2.000
2,28.900,0.07,6.6020,6.60210,2.000
2,29.000,0.20,6.7020,6.70210,2.000
2,29.100,0.40,6.8019,6.80200,2.000
2,29.200,0.68,6.9018,6.90190,2.000
2,29.300,1.06,7.0019,7.00200,2.000
2,29.400,1.54,7.1020,7.10210,2.000
2,29.500,2.14,7.2018,7.20190,2.000
2,29.600,2.85,7.3019,7.30200,2.000
2,29.700,3.69,7.4020,7.40210,2.000
2,29.800,4.68,7.5020,7.50210,2.000
2,29.900,5.84,7.6019,7.60200,2.000
2,30.000,7.20,7.7018,7.70190,2.000
2,30.100,8.77,7.8018,7.80190,2.000
2,30.200,10.59,7.9020,7.90210,2.000
2,30.300,12.67,8.0018,8.00190,2.000
2,30.400,15.06,8.1019,8.10200,2.000
2,30.500,17.75,8.2020,8.20210,2.000
2,30.600,20.77,8.3019,8.30200,2.000
2,30.700,24.22,8.4020,8.40210,2.000
2,30.800,28.16,8.5018,8.50190,2.000
2,30.900,32.80,8.6020,8.60210,2.000
2,31.000,38.47,8.7019,8.70200,2.000
2,31.100,45.36,8.8018,8.80190,2.000
2,31.250,52.49,8.8860,8.88610,2.000
2,31.350,39.27,8.7868,8.78690,2.000
2,31.450,30.62,8.6867,8.68680,2.000
2,31.550,24.56,8.5868,8.58690,2.000
2,31.650,19.98,8.4867,8.48680,2.000
2,31.750,16.34,8.3868,8.38690,2.000
2,31.850,13.42,8.2866,8.28670,2.000
2,31.950,11.03,8.1868,8.18690,2.000
2,32.050,9.06,8.0865,8.08660,2.000
2,32.150,7.44,7.9866,7.98670,2.000
2,32.250,6.12,7.8866,7.88670,2.000
2,32.350,5.02,7.7868,7.78690,2.000
2,32.450,4.09,7.6866,7.68670,2.000
2,32.550,3.29,7.5867,7.58680,2.000
2,32.650,2.62,7.4865,7.48660,2.000
2,32.750,2.07,7.3867,7.38680,2.000
2,32.850,1.66,7.2865,7.28660,2.000
2,32.950,1.22,7.1866,7.18670,2.000
2,33.050,0.84,7.0864,7.08650,2.000
2,33.150,0.55,6.9865,6.98660,2.000
2,33.250,0.33,6.8863,6.88640,2.000
2,33.350,0.16,6.7866,6.78670,2.000
2,33.450,0.06,6.6864,6.68650,2.000
2,33.550,0.00,6.5865,6.58660,2.000
2,33.650,-0.01,6.4864,6.48650,2.000
2,33.750,0.00,6.3865,6.38660,2.000
2,33.850,0.00,6.2864,6.28650,2.000
2,33.950,0.00,6.1865,6.18660,2.000
2,34.050,0.00,6.0864,6.08650,2.000
2,34.150,0.00,5.9865,5.98660,2.000
2,34.250,0.00,5.8862,5.88630,2.000
2,34.350,0.00,5.7864,5.78650,2.000
2,34.450,0.00,5.6863,5.68640,2.000
2,34.550,0.00,5.5864,5.58650,2.000
2,34.650,0.00,5.4865,5.48660,2.000
2,34.750,0.00,5.3866,5.38670,2.000
2,34.850,0.00,5.2863,5.28640,2.000
2,34.950,0.00,5.1864,5.18650,2.000
2,35.050,0.00,5.0862,5.08630,2.000
2,35.150,0.00,4.9863,4.98640,2.000
2,35.250,0.00,4.8863,4.88640,2.000
2,35.350,0.00,4.7865,4.78660,2.000
2,35.450,0.00,4.6862,4.68630,2.000
2,35.550,0.00,4.5865,4.58660,2.000
2,35.650,0.00,4.4862,4.48630,2.000
2,35.750,0.00,4.3863,4.38640,2.000
2,35.850,0.00,4.2862,4.28630,2.000
2,35.950,0.00,4.1865,4.18660,2.000
2,36.050,0.00,4.0862,4.08630,2.000
2,36.150,0.00,3.9863,3.98640,2.000
2,36.250,0.00,3.8862,3.88630,2.000
2,36.350,0.00,3.7863,3.78640,2.000
2,36.450,0.00,3.6862,3.68630,2.000
2,36.550,0.00,3.5864,3.58650,2.000
2,36.650,0.00,3.4861,3.48620,2.000
2,36.750,0.00,3.3863,3.38640,2.000
2,36.850,0.00,3.2862,3.28630,2.000
2,36.950,0.00,3.1863,3.18640,2.000
2,37.050,0.00,3.0862,3.08630,2.000
2,37.150,0.00,2.9863,2.98640,2.000
2,37.250,0.00,2.8862,2.88630,2.000
2,37.350,0.00,2.7863,2.78640,2.000
2,37.450,0.00,2.6862,2.68630,2.000
2,37.550,0.00,2.5862,2.58630,2.000
2,37.650,0.00,2.4862,2.48630,2.000
2,37.750,0.00,2.3862,2.38630,2.000
2,37.850,0.00,2.2861,2.28620,2.000
2,37.950,0.00,2.1863,2.18640,2.000
2,38.050,0.00,2.0861,2.08620,2.000
2,38.150,0.00,1.9862,1.98630,2.000
2,38.250,0.00,1.8861,1.88620,2.000
2,38.350,0.00,1.7862,1.78630,2.000
2,38.450,0.00,1.6863,1.68640,2.000
2,38.550,0.00,1.5862,1.58630,2.000
2,38.650,0.00,1.4861,1.48620,2.000
2,38.750,0.00,1.3862,1.38630,2.000
2,38.850,0.00,1.2862,1.28630,2.000
2,38.950,0.00,1.1862,1.18630,2.000
2,39.050,0.00,1.0861,1.08620,2.000
2,39.150,0.00,0.9862,0.98630,2.000
2,39.250,0.00,0.8861,0.88620,2.000
2,39.350,0.00,0.7861,0.78620,2.000
2,39.450,0.00,0.6863,0.68640,2.000
2,39.550,0.00,0.5862,0.58630,2.000
2,39.650,0.00,0.4861,0.48620,2.000
2,39.750,0.00,0.3862,0.38630,2.000
2,39.850,0.00,0.2862,0.28630,2.000
2,39.950,0.00,0.1861,0.18620,2.000
2,40.050,0.00,0.0861,0.08620,2.000
2,40.200,0.00,-0.0443,-0.04420,2.000
2,40.300,0.00,-0.0005,-0.00040,2.000
2,40.400,0.00,-0.0004,-0.00030,2.000
2,40.500,0.00,-0.0004,-0.00030,2.000
2,40.600,0.00,-0.0004,-0.00030,2.000
2,40.700,0.00,-0.0004,-0.00030,2.000
2,40.800,0.00,-0.0004,-0.00030,2.000
2,40.900,0.00,-0.0004,-0.00030,2.000
2,41.000,0.01,-0.0004,-0.00030,2.000
2,41.100,0.00,-0.0004,-0.00030,2.000
2,41.200,0.00,-0.0004,-0.00030,2.000
2,41.300,0.00,-0.0004,-0.00030,2.000
2,41.400,0.00,-0.0004,-0.00030,2.000
2,41.500,0.00,-0.0004,-0.00030,2.000
2,41.600,0.00,-0.0004,-0.00030,2.000
2,41.700,0.00,-0.0004,-0.00030,2.000
2,41.800,0.00,-0.0004,-0.00030,2.000
2,41.900,0.00,-0.0004,-0.00030,2.000
2,42.000,-0.01,-0.0004,-0.00030,2.000
2,42.100,0.00,-0.0003,-0.00020,2.000
2,42.200,0.00,-0.0003,-0.00020,2.000
2,42.300,0.00,-0.0003,-0.00020,2.000
2,42.400,0.00,-0.0003,-0.00020,2.000
2,42.500,0.00,-0.0003,-0.00020,2.000
2,42.600,0.00,-0.0003,-0.00020,2.000
2,42.700,0.00,-0.0003,-0.00020,2.000
2,42.800,0.00,-0.0003,-0.00020,2.000
2,42.900,0.00,-0.0003,-0.00020,2.000
2,43.000,0.00,-0.0003,-0.00020,2.000
2,43.100,0.00,-0.0003,-0.00020,2.000
2,43.200,0.00,-0.0003,-0.00020,2.000
2,43.350,0.00,-0.0003,-0.00020,2.000
2,43.450,0.00,-0.0003,-0.00020,2.000
2,43.550,0.00,-0.0003,-0.00020,2.000
2,43.650,0.00,-0.0003,-0.00020,2.000
2,43.750,0.00,-0.0003,-0.00020,2.000
2,43.850,0.00,-0.0002,-0.00010,2.000
2,43.950,0.00,-0.0002,-0.00010,2.000
2,44.050,0.00,-0.0002,-0.00010,2.000
2,44.150,0.00,-0.0002,-0.00010,2.000
3,44.450,0.00,0.0214,0.02150,3.000
3,44.550,0.00,0.1213,0.12140,3.000
3,44.650,0.00,0.2216,0.22170,3.000
3,44.750,-0.01,0.3216,0.32170,3.000
3,44.850,0.00,0.4216,0.42170,3.000
3,44.950,0.00,0.5215,0.52160,3.000
3,45.050,0.00,0.6218,0.62190,3.000
3,45.150,-0.01,0.7216,0.72170,3.000
3,45.250,0.00,0.8218,0.82190,3.000
3,45.350,0.00,0.9217,0.92180,3.000
3,45.450,-0.01,1.0219,1.02200,3.000
3,45.550,-0.01,1.1215,1.12160,3.000
3,45.650,0.00,1.2218,1.22190,3.000
3,45.750,0.00,1.3217,1.32180,3.000
3,45.850,0.00,1.4217,1.42180,3.000
3,45.950,-0.01,1.5216,1.52170,3.000
3,46.050,0.00,1.6218,1.62190,3.000
3,46.150,-0.01,1.7217,1.72180,3.000
3,46.250,0.00,1.8218,1.82190,3.000
3,46.350,0.00,1.9216,1.92170,3.000
3,46.450,0.00,2.0217,2.02180,3.000
3,46.550,-0.01,2.1216,2.12170,3.000
3,46.650,0.00,2.2218,2.22190,3.000
3,46.750,0.00,2.3216,2.32170,3.000
3,46.850,0.00,2.4218,2.42190,3.000
3,46.950,0.00,2.5216,2.52170,3.000
3,47.050,0.00,2.6218,2.62190,3.000
3,47.150,-0.01,2.7217,2.72180,3.000
3,47.250,0.00,2.8218,2.82190,3.000
3,47.350,0.00,2.9217,2.92180,3.000
3,47.450,0.00,3.0218,3.02190,3.000
3,47.550,0.00,3.1217,3.12180,3.000
3,47.650,0.00,3.2219,3.22200,3.000
3,47.750,0.00,3.3217,3.32180,3.000
3,47.850,0.00,3.4218,3.42190,3.000
3,47.950,0.00,3.5216,3.52170,3.000
3,48.050,-0.01,3.6218,3.62190,3.000
3,48.150,-0.01,3.7216,3.72170,3.000
3,48.250,0.00,3.8218,3.82190,3.000
3,48.350,-0.01,3.9217,3.92180,3.000
3,48.450,0.00,4.0218,4.02190,3.000
3,48.550,0.00,4.1218,4.12190,3.000
3,48.650,0.00,4.2219,4.22200,3.000
3,48.750,-0.01,4.3217,4.32180,3.000
3,48.850,0.00,4.4219,4.42200,3.000
3,48.950,0.00,4.5218,4.52190,3.000
3,49.050,-0.01,4.6219,4.62200,3.000
3,49.150,-0.01,4.7218,4.72190,3.000
3,49.250,0.00,4.8220,4.82210,3.000
3,49.350,0.00,4.9219,4.92200,3.000
3,49.450,0.00,5.0219,5.02200,3.000
3,49.550,0.00,5.1218,5.12190,3.000
3,49.650,0.00,5.2219,5.22200,3.000
3,49.750,-0.01,5.3219,5.32200,3.000
3,49.850,0.00,5.4220,5.42210,3.000
3,49.950,0.00,5.5220,5.52210,3.000
3,50.050,0.00,5.6220,5.62210,3.000
3,50.150,0.00,5.7220,5.72210,3.000
3,50.250,-0.01,5.8219,5.82200,3.000
3,50.350,0.00,5.9218,5.92190,3.000
3,50.450,0.00,6.0219,6.02200,3.000
3,50.550,0.00,6.1219,6.12200,3.000
3,50.650,0.00,6.2219,6.22200,3.000
3,50.750,0.00,6.3218,6.32190,3.000
3,50.850,-0.01,6.4219,6.42200,3.000
3,50.950,0.00,6.5219,6.52200,3.000
3,51.050,0.08,6.6220,6.62210,3.000
3,51.150,0.22,6.7219,6.72200,3.000
3,51.250,0.43,6.8219,6.82200,3.000
3,51.350,0.74,6.9219,6.92200,3.000
3,51.450,1.13,7.0219,7.02200,3.000
3,51.550,1.62,7.1219,7.12200,3.000
3,51.650,2.23,7.2218,7.22190,3.000
3,51.750,2.97,7.3219,7.32200,3.000
3,51.850,3.84,7.4220,7.42210,3.000
3,51.950,4.85,7.5219,7.52200,3.000
3,52.050,6.04,7.6218,7.62190,3.000
3,52.150,7.44,7.7219,7.72200,3.000
3,52.250,9.05,7.8219,7.82200,3.000
3,52.350,10.91,7.9220,7.92210,3.000
3,52.450,13.02,8.0218,8.02190,3.000
3,52.550,15.44,8.1218,8.12190,3.000
3,52.650,18.15,8.2219,8.22200,3.000
3,52.750,21.21,8.3220,8.32210,3.000
3,52.850,24.69,8.4219,8.42200,3.000
3,52.950,28.68,8.5219,8.52200,3.000
3,53.050,33.40,8.6219,8.62200,3.000
3,53.150,39.17,8.7220,8.72210,3.000
3,53.250,46.20,8.8218,8.82190,3.000
3,53.400,53.67,8.9043,8.90440,3.000
3,53.500,40.00,8.8047,8.80480,3.000
3,53.600,31.15,8.7048,8.70490,3.000
3,53.700,24.93,8.6047,8.60480,3.000
3,53.800,20.26,8.5047,8.50480,3.000
3,53.900,16.58,8.4047,8.40480,3.000
3,54.000,13.61,8.3047,8.30480,3.000
3,54.100,11.19,8.2046,8.20470,3.000
3,54.200,9.21,8.1047,8.10480,3.000
3,54.300,7.57,8.0046,8.00470,3.000
3,54.400,6.22,7.9048,7.90490,3.000
3,54.500,5.13,7.8046,7.80470,3.000
3,54.600,4.17,7.7047,7.70480,3.000
3,54.700,3.38,7.6045,7.60460,3.000
3,54.800,2.69,7.5047,7.50480,3.000
3,54.900,2.14,7.4046,7.40470,3.000
3,55.000,1.73,7.3045,7.30460,3.000
3,55.100,1.26,7.2046,7.20470,3.000
3,55.200,0.88,7.1046,7.10470,3.000
3,55.300,0.58,7.0044,7.00450,3.000
3,55.400,0.35,6.9045,6.90460,3.000
3,55.500,0.18,6.8044,6.80450,3.000
3,55.600,0.07,6.7045,6.70460,3.000
3,55.700,0.00,6.6044,6.60450,3.000
3,55.800,-0.01,6.5045,6.50460,3.000
3,55.900,-0.01,6.4045,6.40460,3.000
3,56.000,-0.01,6.3045,6.30460,3.000
3,56.100,0.00,6.2044,6.20450,3.000
3,56.200,-0.01,6.1045,6.10460,3.000
3,56.300,-0.01,6.0044,6.00450,3.000
3,56.400,-0.01,5.9044,5.90450,3.000
3,56.500,-0.01,5.8043,5.80440,3.000
3,56.600,0.00,5.7045,5.70460,3.000
3,56.700,0.00,5.6043,5.60440,3.000
3,56.800,0.00,5.5046,5.50470,3.000
3,56.900,0.00,5.4044,5.40450,3.000
3,57.000,0.00,5.3045,5.30460,3.000
3,57.100,-0.01,5.2044,5.20450,3.000
3,57.200,0.00,5.1044,5.10450,3.000
3,57.300,0.00,5.0043,5.00440,3.000
3,57.400,0.00,4.9045,4.90460,3.000
3,57.500,0.00,4.8044,4.80450,3.000
3,57.600,0.00,4.7045,4.70460,3.000
3,57.700,0.00,4.6043,4.60440,3.000
3,57.800,-0.01,4.5044,4.50450,3.000
3,57.900,-0.01,4.4042,4.40430,3.000
3,58.000,-0.01,4.3043,4.30440,3.000
3,58.100,0.00,4.2043,4.20440,3.000
3,58.200,-0.01,4.1044,4.10450,3.000
3,58.300,0.00,4.0042,4.00430,3.000
3,58.400,0.00,3.9045,3.90460,3.000
3,58.500,0.00,3.8042,3.80430,3.000
3,58.600,-0.01,3.7043,3.70440,3.000
3,58.700,-0.01,3.6042,3.60430,3.000
3,58.800,0.00,3.5042,3.50430,3.000
3,58.900,0.00,3.4041,3.40420,3.000
3,59.000,0.00,3.3043,3.30440,3.000
3,59.100,0.00,3.2041,3.20420,3.000
3,59.200,0.00,3.1042,3.10430,3.000
3,59.300,-0.01,3.0041,3.00420,3.000
3,59.400,0.00,2.9044,2.90450,3.000
3,59.500,0.00,2.8040,2.80410,3.000
3,59.600,0.00,2.7042,2.70430,3.000
3,59.700,-0.01,2.6041,2.60420,3.000
3,59.800,-0.01,2.5043,2.50440,3.000
3,59.900,-0.01,2.4041,2.40420,3.000
3,60.000,-0.01,2.3042,2.30430,3.000
3,60.100,-0.01,2.2040,2.20410,3.000
3,60.200,0.00,2.1042,2.10430,3.000
3,60.300,-0.01,2.0041,2.00420,3.000
3,60.400,0.00,1.9042,1.90430,3.000
3,60.500,-0.01,1.8041,1.80420,3.000
3,60.600,0.00,1.7043,1.70440,3.000
3,60.700,0.00,1.6041,1.60420,3.000
3,60.800,-0.01,1.5041,1.50420,3.000
3,60.900,0.00,1.4041,1.40420,3.000
3,61.000,0.00,1.3041,1.30420,3.000
3,61.100,0.00,1.2040,1.20410,3.000
3,61.200,0.00,1.1040,1.10410,3.000
3,61.300,0.00,1.0041,1.00420,3.000
3,61.400,-0.01,0.9043,0.90440,3.000
3,61.500,0.00,0.8040,0.80410,3.000
3,61.600,0.00,0.7043,0.70440,3.000
3,61.700,0.00,0.6041,0.60420,3.000
3,61.800,0.00,0.5041,0.50420,3.000
3,61.900,-0.01,0.4040,0.40410,3.000
3,62.000,-0.01,0.3042,0.30430,3.000
3,62.100,0.00,0.2040,0.20410,3.000
3,62.200,0.00,0.1041,0.10420,3.000
3,62.300,-0.01,0.0041,0.00420,3.000
3,62.450,-0.01,-0.0045,-0.00440,3.000
3,62.550,-0.01,-0.0004,-0.00030,3.000
3,62.650,0.00,-0.0004,-0.00030,3.000
3,62.750,0.00,-0.0004,-0.00030,3.000
3,62.850,0.00,-0.0004,-0.00030,3.000
3,62.950,-0.01,-0.0004,-0.00030,3.000
3,63.050,0.00,-0.0004,-0.00030,3.000
3,63.150,-0.01,-0.0004,-0.00030,3.000
3,63.250,0.00,-0.0004,-0.00030,3.000
3,63.350,0.00,-0.0004,-0.00030,3.000
3,63.450,-0.01,-0.0004,-0.00030,3.000
3,63.550,0.00,-0.0004,-0.00030,3.000
3,63.650,-0.01,-0.0004,-0.00030,3.000
3,63.750,0.00,-0.0004,-0.00030,3.000
3,63.850,0.00,-0.0004,-0.00030,3.000
3,63.950,-0.01,-0.0004,-0.00030,3.000
3,64.050,-0.01,-0.0004,-0.00030,3.000
3,64.150,0.00,-0.0004,-0.00030,3.000
3,64.250,0.00,-0.0004,-0.00030,3.000
3,64.350,0.00,-0.0004,-0.00030,3.000
3,64.450,0.00,-0.0004,-0.00030,3.000
3,64.550,0.00,-0.0003,-0.00020,3.000
3,64.650,0.00,-0.0003,-0.00020,3.000
3,64.750,0.00,-0.0003,-0.00020,3.000
3,64.850,-0.01,-0.0003,-0.00020,3.000
3,64.950,0.00,-0.0003,-0.00020,3.000
3,65.050,-0.01,-0.0003,-0.00020,3.000
3,65.150,0.00,-0.0003,-0.00020,3.000
3,65.250,0.00,-0.0003,-0.00020,3.000
3,65.350,-0.01,-0.0003,-0.00020,3.000
3,65.500,0.00,-0.0003,-0.00020,3.000
3,65.600,0.00,-0.0003,-0.00020,3.000
3,65.700,0.00,-0.0003,-0.00020,3.000
3,65.800,-0.01,-0.0003,-0.00020,3.000
3,65.900,0.00,-0.0003,-0.00020,3.000
3,66.000,-0.01,-0.0003,-0.00020,3.000
3,66.100,-0.01,-0.0003,-0.00020,3.000
3,66.200,-0.01,-0.0003,-0.00020,3.000
3,66.300,0.00,-0.0002,-0.00010,3.000
4,66.600,0.00,0.0224,0.02250,4.000
4,66.700,-0.01,0.1224,0.12250,4.000
4,66.800,0.00,0.2227,0.22280,4.000
4,66.900,-0.01,0.3226,0.32270,4.000
4,67.000,-0.01,0.4228,0.42290,4.000
4,67.100,-0.01,0.5227,0.52280,4.000
4,67.200,0.00,0.6227,0.62280,4.000
4,67.300,-0.01,0.7227,0.72280,4.000
4,67.400,-0.01,0.8227,0.82280,4.000
4,67.500,-0.01,0.9227,0.92280,4.000
4,67.600,0.00,1.0227,1.02280,4.000
4,67.700,-0.01,1.1226,1.12270,4.000
4,67.800,-0.01,1.2229,1.22300,4.000
4,67.900,0.00,1.3226,1.32270,4.000
4,68.000,-0.01,1.4228,1.42290,4.000
4,68.100,-0.01,1.5227,1.52280,4.000
4,68.200,0.00,1.6229,1.62300,4.000
4,68.300,-0.01,1.7228,1.72290,4.000
4,68.400,-0.01,1.8228,1.82290,4.000
4,68.500,-0.01,1.9226,1.92270,4.000
4,68.600,0.00,2.0227,2.02280,4.000
4,68.700,0.00,2.1226,2.12270,4.000
4,68.800,0.00,2.2228,2.22290,4.000
4,68.900,-0.01,2.3226,2.32270,4.000
4,69.000,0.00,2.4228,2.42290,4.000
4,69.100,-0.01,2.5227,2.52280,4.000
4,69.200,0.00,2.6229,2.62300,4.000
4,69.300,-0.01,2.7226,2.72270,4.000
4,69.400,0.00,2.8228,2.82290,4.000
4,69.500,0.00,2.9227,2.92280,4.000
4,69.600,0.00,3.0228,3.02290,4.000
4,69.700,0.00,3.1227,3.12280,4.000
4,69.800,0.00,3.2228,3.22290,4.000
4,69.900,-0.01,3.3228,3.32290,4.000
4,70.000,0.00,3.4229,3.42300,4.000
4,70.100,0.00,3.5226,3.52270,4.000
4,70.200,0.00,3.6227,3.62280,4.000
4,70.300,-0.01,3.7226,3.72270,4.000
4,70.400,0.00,3.8229,3.82300,4.000
4,70.500,-0.01,3.9227,3.92280,4.000
4,70.600,-0.01,4.0227,4.02280,4.000
4,70.700,-0.01,4.1229,4.12300,4.000
4,70.800,0.00,4.2230,4.22310,4.000
4,70.900,-0.01,4.3227,4.32280,4.000
4,71.000,-0.01,4.4228,4.42290,4.000
4,71.100,0.00,4.5228,4.52290,4.000
4,71.200,-0.01,4.6228,4.62290,4.000
4,71.300,0.00,4.7228,4.72290,4.000
4,71.400,0.00,4.8229,4.82300,4.000
4,71.500,0.00,4.9228,4.92290,4.000
4,71.600,0.00,5.0229,5.02300,4.000
4,71.700,0.00,5.1228,5.12290,4.000
4,71.800,-0.01,5.2229,5.22300,4.000
4,71.900,0.00,5.3229,5.32300,4.000
4,72.000,0.00,5.4230,5.42310,4.000
4,72.100,0.00,5.5230,5.52310,4.000
4,72.200,0.00,5.6230,5.62310,4.000
4,72.300,0.00,5.7229,5.72300,4.000
4,72.400,0.00,5.8229,5.82300,4.000
4,72.500,0.00,5.9228,5.92290,4.000
4,72.600,0.00,6.0228,6.02290,4.000
4,72.700,-0.01,6.1229,6.12300,4.000
4,72.800,0.00,6.2229,6.22300,4.000
4,72.900,0.00,6.3229,6.32300,4.000
4,73.000,-0.01,6.4229,6.42300,4.000
4,73.100,0.00,6.5230,6.52310,4.000
4,73.200,0.08,6.6230,6.62310,4.000
4,73.300,0.21,6.7230,6.72310,4.000
4,73.400,0.42,6.8228,6.82290,4.000
4,73.500,0.72,6.9230,6.92310,4.000
4,73.600,1.11,7.0230,7.02310,4.000
4,73.700,1.60,7.1229,7.12300,4.000
4,73.800,2.20,7.2228,7.22290,4.000
4,73.900,2.94,7.3229,7.32300,4.000
4,74.000,3.80,7.4230,7.42310,4.000
4,74.100,4.80,7.5229,7.52300,4.000
4,74.200,5.98,7.6228,7.62290,4.000
4,74.300,7.37,7.7229,7.72300,4.000
4,74.400,8.98,7.8229,7.82300,4.000
4,74.500,10.82,7.9229,7.92300,4.000
4,74.600,12.92,8.0229,8.02300,4.000
4,74.700,15.31,8.1229,8.12300,4.000
4,74.800,18.00,8.2229,8.22300,4.000
4,74.900,21.02,8.3229,8.32300,4.000
4,75.000,24.47,8.4229,8.42300,4.000
4,75.100,28.41,8.5230,8.52310,4.000
4,75.200,33.04,8.6228,8.62290,4.000
4,75.300,38.69,8.7229,8.72300,4.000
4,75.400,45.51,8.8228,8.82290,4.000
4,75.550,53.19,8.9071,8.90720,4.000
4,75.650,39.79,8.8077,8.80780,4.000
4,75.750,31.00,8.7078,8.70790,4.000
4,75.850,24.83,8.6078,8.60790,4.000
4,75.950,20.18,8.5078,8.50790,4.000
4,76.050,16.50,8.4078,8.40790,4.000
4,76.150,13.55,8.3077,8.30780,4.000
4,76.250,11.13,8.2077,8.20780,4.000
4,76.350,9.17,8.1076,8.10770,4.000
4,76.450,7.54,8.0076,8.00770,4.000
4,76.550,6.19,7.9077,7.90780,4.000
4,76.650,5.11,7.8076,7.80770,4.000
4,76.750,4.14,7.7077,7.70780,4.000
4,76.850,3.37,7.6074,7.60750,4.000
4,76.950,2.68,7.5077,7.50780,4.000
4,77.050,2.13,7.4076,7.40770,4.000
4,77.150,1.71,7.3076,7.30770,4.000
4,77.250,1.25,7.2075,7.20760,4.000
4,77.350,0.87,7.1076,7.10770,4.000
4,77.450,0.58,7.0075,7.00760,4.000
4,77.550,0.35,6.9076,6.90770,4.000
4,77.650,0.18,6.8074,6.80750,4.000
4,77.750,0.07,6.7075,6.70760,4.000
4,77.850,0.00,6.6074,6.60750,4.000
4,77.950,-0.01,6.5076,6.50770,4.000
4,78.050,-0.01,6.4075,6.40760,4.000
4,78.150,0.00,6.3075,6.30760,4.000
4,78.250,-0.01,6.2074,6.20750,4.000
4,78.350,0.00,6.1076,6.10770,4.000
4,78.450,-0.01,6.0073,6.00740,4.000
4,78.550,-0.01,5.9074,5.90750,4.000
4,78.650,0.00,5.8073,5.80740,4.000
4,78.750,-0.01,5.7074,5.70750,4.000
4,78.850,-0.01,5.6073,5.60740,4.000
4,78.950,-0.01,5.5076,5.50770,4.000
4,79.050,-0.01,5.4074,5.40750,4.000
4,79.150,0.00,5.3075,5.30760,4.000
4,79.250,-0.01,5.2074,5.20750,4.000
4,79.350,-0.01,5.1075,5.10760,4.000
4,79.450,-0.01,5.0071,5.00720,4.000
4,79.550,0.00,4.9074,4.90750,4.000
4,79.650,-0.01,4.8073,4.80740,4.000
4,79.750,0.00,4.7074,4.70750,4.000
4,79.850,0.00,4.6072,4.60730,4.000
4,79.950,0.00,4.5075,4.50760,4.000
4,80.050,0.00,4.4072,4.40730,4.000
4,80.150,0.00,4.3073,4.30740,4.000
4,80.250,-0.01,4.2073,4.20740,4.000
4,80.350,0.00,4.1074,4.10750,4.000
4,80.450,-0.01,4.0072,4.00730,4.000
4,80.550,0.00,3.9075,3.90760,4.000
4,80.650,0.00,3.8072,3.80730,4.000
4,80.750,0.00,3.7073,3.70740,4.000
4,80.850,0.00,3.6072,3.60730,4.000
4,80.950,-0.01,3.5072,3.50730,4.000
4,81.050,-0.01,3.4071,3.40720,4.000
4,81.150,-0.01,3.3073,3.30740,4.000
4,81.250,-0.01,3.2071,3.20720,4.000
4,81.350,-0.01,3.1073,3.10740,4.000
4,81.450,-0.01,3.0071,3.00720,4.000
4,81.550,0.00,2.9073,2.90740,4.000
4,81.650,-0.01,2.8071,2.80720,4.000
4,81.750,-0.01,2.7073,2.70740,4.000
4,81.850,-0.01,2.6071,2.60720,4.000
4,81.950,-0.01,2.5072,2.50730,4.000
4,82.050,-0.01,2.4071,2.40720,4.000
4,82.150,-0.01,2.3072,2.30730,4.000
4,82.250,-0.01,2.2071,2.20720,4.000
4,82.350,0.00,2.1071,2.10720,4.000
4,82.450,0.00,2.0071,2.00720,4.000
4,82.550,-0.01,1.9073,1.90740,4.000
4,82.650,-0.01,1.8070,1.80710,4.000
4,82.750,-0.01,1.7072,1.70730,4.000
4,82.850,0.00,1.6071,1.60720,4.000
4,82.950,0.00,1.5071,1.50720,4.000
4,83.050,0.00,1.4070,1.40710,4.000
4,83.150,0.00,1.3072,1.30730,4.000
4,83.250,-0.01,1.2071,1.20720,4.000
4,83.350,-0.01,1.1071,1.10720,4.000
4,83.450,0.00,1.0071,1.00720,4.000
4,83.550,-0.01,0.9072,0.90730,4.000
4,83.650,0.00,0.8071,0.80720,4.000
4,83.750,0.00,0.7073,0.70740,4.000
4,83.850,0.00,0.6071,0.60720,4.000
4,83.950,0.00,0.5072,0.50730,4.000
4,84.050,-0.01,0.4072,0.40730,4.000
4,84.150,-0.01,0.3071,0.30720,4.000
4,84.250,-0.01,0.2071,0.20720,4.000
4,84.350,0.00,0.1071,0.10720,4.000
4,84.450,0.00,0.0071,0.00720,4.000
4,84.600,0.00,-0.0003,-0.00020,4.000
4,84.700,-0.01,-0.0004,-0.00030,4.000
4,84.800,0.00,-0.0004,-0.00030,4.000
4,84.900,0.00,-0.0004,-0.00030,4.000
4,85.000,0.00,-0.0004,-0.00030,4.000
4,85.100,0.00,-0.0004,-0.00030,4.000
4,85.200,0.00,-0.0004,-0.00030,4.000
4,85.300,0.00,-0.0004,-0.00030,4.000
4,85.400,0.00,-0.0004,-0.00030,4.000
4,85.500,0.00,-0.0004,-0.00030,4.000
4,85.600,-0.01,-0.0004,-0.00030,4.000
4,85.700,-0.01,-0.0004,-0.00030,4.000
4,85.800,0.00,-0.0004,-0.00030,4.000
4,85.900,0.00,-0.0004,-0.00030,4.000
4,86.000,0.00,-0.0004,-0.00030,4.000
4,86.100,0.00,-0.0004,-0.00030,4.000
4,86.200,-0.01,-0.0004,-0.00030,4.000
4,86.300,-0.01,-0.0004,-0.00030,4.000
4,86.400,-0.01,-0.0004,-0.00030,4.000
4,86.500,0.00,-0.0004,-0.00030,4.000
4,86.600,0.00,-0.0003,-0.00020,4.000
4,86.700,0.00,-0.0003,-0.00020,4.000
4,86.800,0.00,-0.0003,-0.00020,4.000
4,86.900,0.00,-0.0003,-0.00020,4.000
4,87.000,0.00,-0.0003,-0.00020,4.000
4,87.100,-0.01,-0.0003,-0.00020,4.000
4,87.200,0.00,-0.0003,-0.00020,4.000
4,87.300,-0.01,-0.0003,-0.00020,4.000
4,87.400,0.00,-0.0003,-0.00020,4.000
4,87.500,0.00,-0.0003,-0.00020,4.000
4,87.650,0.00,-0.0003,-0.00020,4.000
4,87.750,0.00,-0.0003,-0.00020,4.000
4,87.850,0.00,-0.0003,-0.00020,4.000
4,87.950,0.00,-0.0003,-0.00020,4.000
4,88.050,-0.01,-0.0003,-0.00020,4.000
4,88.150,-0.01,-0.0003,-0.00020,4.000
4,88.250,0.00,-0.0003,-0.00020,4.000
4,88.350,-0.01,-0.0003,-0.00020,4.000
4,88.450,-0.01,-0.0002,-0.00010,4.000
5,88.750,0.01,0.0214,0.02150,5.000
5,88.850,0.00,0.1214,0.12150,5.000
5,88.950,0.00,0.2216,0.22170,5.000
5,89.050,0.00,0.3215,0.32160,5.000
5,89.150,0.00,0.4216,0.42170,5.000
5,89.250,0.00,0.5215,0.52160,5.000
5,89.350,0.00,0.6217,0.62180,5.000
5,89.450,0.00,0.7216,0.72170,5.000
5,89.550,0.00,0.8217,0.82180,5.000
5,89.650,0.00,0.9216,0.92170,5.000
5,89.750,0.00,1.0217,1.02180,5.000
5,89.850,0.00,1.1215,1.12160,5.000
5,89.950,0.00,1.2217,1.22180,5.000
5,90.050,0.00,1.3216,1.32170,5.000
5,90.150,0.00,1.4217,1.42180,5.000
5,90.250,0.00,1.5217,1.52180,5.000
5,90.350,0.00,1.6217,1.62180,5.000
5,90.450,0.00,1.7216,1.72170,5.000
5,90.550,0.00,1.8218,1.82190,5.000
5,90.650,0.00,1.9217,1.92180,5.000
5,90.750,0.00,2.0217,2.02180,5.000
5,90.850,0.00,2.1217,2.12180,5.000
5,90.950,0.00,2.2217,2.22180,5.000
5,91.050,0.00,2.3216,2.32170,5.000
5,91.150,0.00,2.4217,2.42180,5.000
5,91.250,0.00,2.5216,2.52170,5.000
5,91.350,0.00,2.6217,2.62180,5.000
5,91.450,0.00,2.7217,2.72180,5.000
5,91.550,0.00,2.8218,2.82190,5.000
5,91.650,0.00,2.9218,2.92190,5.000
5,91.750,0.00,3.0218,3.02190,5.000
5,91.850,0.00,3.1216,3.12170,5.000
5,91.950,0.00,3.2219,3.22200,5.000
5,92.050,0.00,3.3217,3.32180,5.000
5,92.150,0.00,3.4218,3.42190,5.000
5,92.250,0.00,3.5216,3.52170,5.000
5,92.350,0.00,3.6218,3.62190,5.000
5,92.450,0.00,3.7216,3.72170,5.000
5,92.550,0.00,3.8219,3.82200,5.000
5,92.650,0.00,3.9218,3.92190,5.000
5,92.750,0.00,4.0217,4.02180,5.000
5,92.850,0.00,4.1219,4.12200,5.000
5,92.950,0.00,4.2220,4.22210,5.000
5,93.050,0.00,4.3217,4.32180,5.000
5,93.150,0.00,4.4218,4.42190,5.000
5,93.250,0.00,4.5218,4.52190,5.000
5,93.350,0.00,4.6219,4.62200,5.000
5,93.450,0.00,4.7220,4.72210,5.000
5,93.550,0.00,4.8220,4.82210,5.000
5,93.650,0.00,4.9218,4.92190,5.000
5,93.750,0.00,5.0219,5.02200,5.000
5,93.850,0.00,5.1219,5.12200,5.000
5,93.950,0.00,5.2219,5.22200,5.000
5,94.050,0.00,5.3220,5.32210,5.000
5,94.150,0.00,5.4220,5.42210,5.000
5,94.250,0.00,5.5219,5.52200,5.000
5,94.350,0.00,5.6220,5.62210,5.000
5,94.450,0.00,5.7220,5.72210,5.000
5,94.550,0.00,5.8219,5.82200,5.000
5,94.650,0.00,5.9219,5.92200,5.000
5,94.750,0.00,6.0218,6.02190,5.000
5,94.850,0.00,6.1220,6.12210,5.000
5,94.950,0.00,6.2219,6.22200,5.000
5,95.050,0.00,6.3220,6.32210,5.000
5,95.150,0.00,6.4219,6.42200,5.000
5,95.250,0.01,6.5221,6.52220,5.000
5,95.350,0.08,6.6220,6.62210,5.000
5,95.450,0.22,6.7219,6.72200,5.000
5,95.550,0.43,6.8218,6.82190,5.000
5,95.650,0.73,6.9219,6.92200,5.000
5,95.750,1.12,7.0218,7.02190,5.000
5,95.850,1.61,7.1219,7.12200,5.000
5,95.950,2.22,7.2218,7.22190,5.000
5,96.050,2.95,7.3219,7.32200,5.000
5,96.150,3.82,7.4220,7.42210,5.000
5,96.250,4.82,7.5220,7.52210,5.000
5,96.350,6.01,7.6218,7.62190,5.000
5,96.450,7.39,7.7219,7.72200,5.000
5,96.550,8.99,7.8219,7.82200,5.000
5,96.650,10.83,7.9219,7.92200,5.000
5,96.750,12.94,8.0218,8.02190,5.000
5,96.850,15.32,8.1219,8.12200,5.000
5,96.950,18.03,8.2219,8.22200,5.000
5,97.050,21.04,8.3219,8.32200,5.000
5,97.150,24.48,8.4218,8.42190,5.000
5,97.250,28.43,8.5220,8.52210,5.000
5,97.350,33.07,8.6219,8.62200,5.000
5,97.450,38.67,8.7220,8.72210,5.000
5,97.550,45.51,8.8217,8.82180,5.000
5,97.700,53.28,8.9060,8.90610,5.000
5,97.800,39.85,8.8067,8.80680,5.000
5,97.900,31.03,8.7068,8.70690,5.000
5,98.000,24.85,8.6067,8.60680,5.000
5,98.100,20.20,8.5067,8.50680,5.000
5,98.200,16.51,8.4067,8.40680,5.000
5,98.300,13.55,8.3067,8.30680,5.000
5,98.400,11.14,8.2068,8.20690,5.000
5,98.500,9.18,8.1067,8.10680,5.000
5,98.600,7.55,8.0065,8.00660,5.000
5,98.700,6.20,7.9067,7.90680,5.000
5,98.800,5.11,7.8067,7.80680,5.000
5,98.900,4.14,7.7067,7.70680,5.000
5,99.000,3.37,7.6065,7.60660,5.000
5,99.100,2.69,7.5067,7.50680,5.000
5,99.200,2.13,7.4066,7.40670,5.000
5,99.300,1.71,7.3066,7.30670,5.000
5,99.400,1.26,7.2066,7.20670,5.000
5,99.500,0.88,7.1065,7.10660,5.000
5,99.600,0.58,7.0065,7.00660,5.000
5,99.700,0.35,6.9065,6.90660,5.000
5,99.800,0.18,6.8064,6.80650,5.000
5,99.900,0.08,6.7064,6.70650,5.000
5,100.000,0.00,6.6064,6.60650,5.000
5,100.100,0.00,6.5065,6.50660,5.000
5,100.200,0.00,6.4065,6.40660,5.000
5,100.300,-0.01,6.3065,6.30660,5.000
5,100.400,0.00,6.2064,6.20650,5.000
5,100.500,0.00,6.1065,6.10660,5.000
5,100.600,0.00,6.0063,6.00640,5.000
5,100.700,-0.01,5.9064,5.90650,5.000
5,100.800,0.00,5.8064,5.80650,5.000
5,100.900,0.00,5.7064,5.70650,5.000
5,101.000,0.00,5.6064,5.60650,5.000
5,101.100,0.00,5.5065,5.50660,5.000
5,101.200,0.00,5.4065,5.40660,5.000
5,101.300,0.00,5.3064,5.30650,5.000
5,101.400,0.00,5.2063,5.20640,5.000
5,101.500,0.00,5.1065,5.10660,5.000
5,101.600,0.00,5.0063,5.00640,5.000
5,101.700,0.00,4.9063,4.90640,5.000
5,101.800,0.00,4.8063,4.80640,5.000
5,101.900,0.00,4.7065,4.70660,5.000
5,102.000,0.01,4.6062,4.60630,5.000
5,102.100,0.00,4.5065,4.50660,5.000
5,102.200,0.00,4.4061,4.40620,5.000
5,102.300,0.00,4.3063,4.30640,5.000
5,102.400,0.00,4.2063,4.20640,5.000
5,102.500,0.00,4.1065,4.10660,5.000
5,102.600,0.00,4.0062,4.00630,5.000
5,102.700,0.00,3.9064,3.90650,5.000
5,102.800,0.00,3.8062,3.80630,5.000
5,102.900,0.00,3.7063,3.70640,5.000
5,103.000,0.01,3.6061,3.60620,5.000
5,103.100,0.00,3.5062,3.50630,5.000
5,103.200,0.00,3.4061,3.40620,5.000
5,103.300,0.00,3.3064,3.30650,5.000
5,103.400,0.00,3.2062,3.20630,5.000
5,103.500,0.00,3.1063,3.10640,5.000
5,103.600,0.00,3.0061,3.00620,5.000
5,103.700,0.00,2.9063,2.90640,5.000
5,103.800,0.00,2.8061,2.80620,5.000
5,103.900,-0.01,2.7062,2.70630,5.000
5,104.000,0.00,2.6062,2.60630,5.000
5,104.100,0.00,2.5063,2.50640,5.000
5,104.200,0.00,2.4061,2.40620,5.000
5,104.300,0.00,2.3063,2.30640,5.000
5,104.400,0.00,2.2061,2.20620,5.000
5,104.500,0.00,2.1063,2.10640,5.000
5,104.600,0.00,2.0061,2.00620,5.000
5,104.700,0.00,1.9063,1.90640,5.000
5,104.800,0.00,1.8060,1.80610,5.000
5,104.900,0.00,1.7062,1.70630,5.000
5,105.000,0.00,1.6060,1.60610,5.000
5,105.100,0.00,1.5062,1.50630,5.000
5,105.200,0.00,1.4061,1.40620,5.000
5,105.300,0.00,1.3062,1.30630,5.000
5,105.400,0.00,1.2060,1.20610,5.000
5,105.500,0.00,1.1060,1.10610,5.000
5,105.600,0.00,1.0060,1.00610,5.000
5,105.700,0.01,0.9062,0.90630,5.000
5,105.800,0.00,0.8061,0.80620,5.000
5,105.900,0.00,0.7063,0.70640,5.000
5,106.000,0.00,0.6060,0.60610,5.000
5,106.100,0.00,0.5063,0.50640,5.000
5,106.200,0.00,0.4060,0.40610,5.000
5,106.300,0.00,0.3061,0.30620,5.000
5,106.400,0.00,0.2060,0.20610,5.000
5,106.500,0.00,0.1060,0.10610,5.000
5,106.600,0.00,0.0061,0.00620,5.000
5,106.750,0.00,-0.0002,-0.00010,5.000
5,106.850,0.01,-0.0004,-0.00030,5.000
5,106.950,0.00,-0.0004,-0.00030,5.000
5,107.050,0.00,-0.0004,-0.00030,5.000
5,107.150,0.00,-0.0004,-0.00030,5.000
5,107.250,0.00,-0.0004,-0.00030,5.000
5,107.350,0.00,-0.0004,-0.00030,5.000
5,107.450,0.00,-0.0004,-0.00030,5.000
5,107.550,0.00,-0.0004,-0.00030,5.000
5,107.650,0.00,-0.0004,-0.00030,5.000
5,107.750,0.00,-0.0004,-0.00030,5.000
5,107.850,0.00,-0.0004,-0.00030,5.000
5,107.950,0.00,-0.0004,-0.00030,5.000
5,108.050,0.00,-0.0004,-0.00030,5.000
5,108.150,0.00,-0.0004,-0.00030,5.000
5,108.250,0.00,-0.0004,-0.00030,5.000
5,108.350,0.00,-0.0004,-0.00030,5.000
5,108.450,0.00,-0.0004,-0.00030,5.000
5,108.550,0.00,-0.0004,-0.00030,5.000
5,108.650,0.00,-0.0003,-0.00020,5.000
5,108.750,0.00,-0.0003,-0.00020,5.000
5,108.850,0.00,-0.0003,-0.00020,5.000
5,108.950,0.00,-0.0003,-0.00020,5.000
5,109.050,0.00,-0.0003,-0.00020,5.000
5,109.150,0.00,-0.0003,-0.00020,5.000
5,109.250,0.00,-0.0003,-0.00020,5.000
5,109.350,0.00,-0.0003,-0.00020,5.000
5,109.450,0.00,-0.0003,-0.00020,5.000
5,109.550,0.00,-0.0003,-0.00020,5.000
5,109.650,0.00,-0.0003,-0.00020,5.000
5,109.800,0.00,-0.0003,-0.00020,5.000
5,109.900,0.00,-0.0003,-0.00020,5.000
5,110.000,0.00,-0.0003,-0.00020,5.000
5,110.100,0.00,-0.0003,-0.00020,5.000
5,110.200,0.00,-0.0003,-0.00020,5.000
5,110.300,0.00,-0.0003,-0.00020,5.000
5,110.400,0.00,-0.0002,-0.00010,5.000
5,110.500,0.00,-0.0002,-0.00010,5.000
5,110.600,0.00,-0.0002,-0.00010,5.000
5,110.650,0.00,-0.0002,-0.00010,5.000