File: scripts/black/MTS/radhen_black_-20degree.txt
""
"Test Method","Radhen_Load_Cntrl_Cmprsn_250N_12-7.msm"
"Sample I. D.","Sample1.mss"
"Specimen Number","7"

"TheCycle_Output ()","_Time (s)","_Load (N)","_Extension (mm)","RealTimeDepth (mm)","CycleNumber ()"

1,0.200,0.00,0.0000,0.00000,1.000
1,0.300,0.00,0.0693,0.06930,1.000
1,0.400,0.00,0.1694,0.16940,1.000
1,0.500,0.00,0.2695,0.26950,1.000
1,0.600,0.00,0.3693,0.36930,1.000
1,0.700,0.00,0.4695,0.46950,1.000
1,0.800,0.00,0.5694,0.56940,1.000
1,0.900,0.00,0.6696,0.66960,1.000
1,1.000,0.00,0.7694,0.76940,1.000
1,1.100,0.00,0.8696,0.86960,1.000
1,1.200,0.00,0.9694,0.96940,1.000
1,1.300,0.00,1.0696,1.06960,1.000
1,1.400,0.00,1.1694,1.16940,1.000
1,1.500,0.00,1.2695,1.26950,1.000
1,1.600,0.00,1.3695,1.36950,1.000
1,1.700,0.00,1.4697,1.46970,1.000
1,1.800,0.00,1.5695,1.56950,1.000
1,1.900,0.00,1.6696,1.66960,1.000
1,2.000,0.00,1.7695,1.76950,1.000
1,2.100,0.00,1.8697,1.86970,1.000
1,2.200,0.00,1.9695,1.96950,1.000
1,2.300,0.00,2.0695,2.06950,1.000
1,2.400,0.00,2.1696,2.16960,1.000
1,2.500,0.00,2.2696,2.26960,1.000
1,2.600,0.00,2.3696,2.36960,1.000
1,2.700,0.00,2.4696,2.46960,1.000
1,2.800,0.00,2.5695,2.56950,1.000
1,2.900,0.00,2.6696,2.66960,1.000
1,3.000,0.00,2.7696,2.76960,1.000
1,3.100,0.00,2.8696,2.86960,1.000
1,3.200,0.00,2.9696,2.96960,1.000
1,3.300,0.00,3.0697,3.06970,1.000
1,3.400,0.00,3.1698,3.16980,1.000
1,3.500,-0.01,3.2697,3.26970,1.000
1,3.600,0.00,3.3696,3.36960,1.000
1,3.700,0.00,3.4698,3.46980,1.000
1,3.800,0.00,3.5698,3.56980,1.000
1,3.900,0.00,3.6697,3.66970,1.000
1,4.000,0.00,3.7698,3.76980,1.000
1,4.100,0.00,3.8697,3.86970,1.000
1,4.200,0.00,3.9698,3.96980,1.000
1,4.300,0.00,4.0698,4.06980,1.000
1,4.400,0.00,4.1697,4.16970,1.000
1,4.500,0.00,4.2699,4.26990,1.000
1,4.600,0.00,4.3700,4.37000,1.000
1,4.700,0.00,4.4698,4.46980,1.000
1,4.800,0.00,4.5697,4.56970,1.000
1,4.900,0.00,4.6697,4.66970,1.000
1,5.000,0.00,4.7699,4.76990,1.000
1,5.100,0.00,4.8697,4.86970,1.000
1,5.200,0.00,4.9697,4.96970,1.000
1,5.300,0.00,5.0697,5.06970,1.000
1,5.400,0.00,5.1698,5.16980,1.000
1,5.500,0.00,5.2697,5.26970,1.000
1,5.600,0.01,5.3700,5.37000,1.000
1,5.700,0.09,5.4698,5.46980,1.000
1,5.800,0.26,5.5700,5.57000,1.000
1,5.900,0.52,5.6698,5.66980,1.000
1,6.000,0.86,5.7697,5.76970,1.000
1,6.100,1.31,5.8697,5.86970,1.000
1,6.200,1.87,5.9699,5.96990,1.000
1,6.300,2.56,6.0698,6.06980,1.000
1,6.400,3.41,6.1699,6.16990,1.000
1,6.500,4.42,6.2697,6.26970,1.000
1,6.600,5.60,6.3699,6.36990,1.000
1,6.700,6.98,6.4697,6.46970,1.000
1,6.800,8.58,6.5699,6.56990,1.000
1,6.900,10.47,6.6698,6.66980,1.000
1,7.000,12.68,6.7700,6.77000,1.000
1,7.100,15.22,6.8698,6.86980,1.000
1,7.200,18.19,6.9698,6.96980,1.000
1,7.300,21.61,7.0696,7.06960,1.000
1,7.400,25.51,7.1699,7.16990,1.000
1,7.500,29.90,7.2697,7.26970,1.000
1,7.600,34.64,7.3700,7.37000,1.000
1,7.700,39.38,7.4698,7.46980,1.000
1,7.800,42.13,7.5700,7.57000,1.000
1,7.900,44.33,7.6697,7.66970,1.000
1,8.000,50.20,7.7698,7.76980,1.000
1,8.150,44.71,7.7566,7.75660,1.000
1,8.250,33.40,7.6567,7.65670,1.000
1,8.350,26.07,7.5567,7.55670,1.000
1,8.450,20.72,7.4567,7.45670,1.000
1,8.550,16.67,7.3566,7.35660,1.000
1,8.650,13.42,7.2566,7.25660,1.000
1,8.750,10.87,7.1566,7.15660,1.000
1,8.850,8.81,7.0566,7.05660,1.000
1,8.950,7.12,6.9566,6.95660,1.000
1,9.050,5.76,6.8566,6.85660,1.000
1,9.150,4.63,6.7567,6.75670,1.000
1,9.250,3.68,6.6566,6.65660,1.000
1,9.350,2.90,6.5566,6.55660,1.000
1,9.450,2.25,6.4565,6.45650,1.000
1,9.550,1.70,6.3566,6.35660,1.000
1,9.650,1.25,6.2565,6.25650,1.000
1,9.750,0.89,6.1565,6.15650,1.000
1,9.850,0.60,6.0565,6.05650,1.000
1,9.950,0.37,5.9566,5.95660,1.000
1,10.050,0.20,5.8563,5.85630,1.000
1,10.150,0.09,5.7565,5.75650,1.000
1,10.250,0.01,5.6565,5.65650,1.000
1,10.350,-0.01,5.5565,5.55650,1.000
1,10.450,0.00,5.4566,5.45660,1.000
1,10.550,0.00,5.3566,5.35660,1.000
1,10.650,0.00,5.2565,5.25650,1.000
1,10.750,0.00,5.1565,5.15650,1.000
1,10.850,0.00,5.0564,5.05640,1.000
1,10.950,0.00,4.9564,4.95640,1.000
1,11.050,0.00,4.8563,4.85630,1.000
1,11.150,0.00,4.7565,4.75650,1.000
1,11.250,0.00,4.6564,4.65640,1.000
1,11.350,0.00,4.5564,4.55640,1.000
1,11.450,0.00,4.4564,4.45640,1.000
1,11.550,-0.01,4.3566,4.35660,1.000
1,11.650,0.00,4.2562,4.25620,1.000
1,11.750,0.00,4.1565,4.15650,1.000
1,11.850,0.00,4.0563,4.05630,1.000
1,11.950,0.00,3.9564,3.95640,1.000
1,12.050,0.00,3.8563,3.85630,1.000
1,12.150,0.00,3.7564,3.75640,1.000
1,12.250,0.00,3.6563,3.65630,1.000
1,12.350,0.00,3.5565,3.55650,1.000
1,12.450,0.00,3.4564,3.45640,1.000
1,12.550,0.00,3.3564,3.35640,1.000
1,12.650,0.00,3.2562,3.25620,1.000
1,12.750,0.00,3.1566,3.15660,1.000
1,12.850,0.00,3.0561,3.05610,1.000
1,12.950,0.00,2.9563,2.95630,1.000
1,13.050,0.00,2.8563,2.85630,1.000
1,13.150,0.00,2.7564,2.75640,1.000
1,13.250,0.00,2.6562,2.65620,1.000
1,13.350,0.00,2.5563,2.55630,1.000
1,13.450,0.00,2.4562,2.45620,1.000
1,13.550,0.00,2.3563,2.35630,1.000
1,13.650,0.00,2.2562,2.25620,1.000
1,13.750,0.01,2.1564,2.15640,1.000
1,13.850,0.00,2.0561,2.05610,1.000
1,13.950,0.00,1.9564,1.95640,1.000
1,14.050,0.00,1.8562,1.85620,1.000
1,14.150,0.00,1.7563,1.75630,1.000
1,14.250,0.00,1.6561,1.65610,1.000
1,14.350,0.00,1.5562,1.55620,1.000
1,14.450,0.00,1.4562,1.45620,1.000
1,14.550,0.00,1.3562,1.35620,1.000
1,14.650,0.00,1.2560,1.25600,1.000
1,14.750,0.00,1.1562,1.15620,1.000
1,14.850,0.00,1.0560,1.05600,1.000
1,14.950,0.00,0.9562,0.95620,1.000
1,15.050,0.00,0.8561,0.85610,1.000
1,15.150,0.00,0.7562,0.75620,1.000
1,15.250,0.00,0.6561,0.65610,1.000
1,15.350,0.00,0.5562,0.55620,1.000
1,15.450,0.00,0.4560,0.45600,1.000
1,15.550,0.00,0.3562,0.35620,1.000
1,15.650,0.00,0.2561,0.25610,1.000
1,15.750,0.00,0.1561,0.15610,1.000
1,15.850,0.00,0.0558,0.05580,1.000
1,16.000,0.00,-0.0494,-0.04940,1.000
1,16.100,0.00,-0.0004,-0.00040,1.000
1,16.200,0.00,-0.0004,-0.00040,1.000
1,16.300,0.00,-0.0004,-0.00040,1.000
1,16.400,0.00,-0.0004,-0.00040,1.000
1,16.500,0.00,-0.0004,-0.00040,1.000
1,16.600,0.00,-0.0004,-0.00040,1.000
1,16.700,0.00,-0.0004,-0.00040,1.000
1,16.800,0.00,-0.0004,-0.00040,1.000
1,16.900,0.00,-0.0004,-0.00040,1.000
1,17.000,0.00,-0.0004,-0.00040,1.000
1,17.100,0.00,-0.0004,-0.00040,1.000
1,17.200,0.00,-0.0004,-0.00040,1.000
1,17.300,0.00,-0.0004,-0.00040,1.000
1,17.400,0.00,-0.0003,-0.00030,1.000
1,17.500,0.00,-0.0003,-0.00030,1.000
1,17.600,0.00,-0.0003,-0.00030,1.000
1,17.700,0.00,-0.0003,-0.00030,1.000
1,17.800,0.01,-0.0003,-0.00030,1.000
1,17.900,0.00,-0.0003,-0.00030,1.000
1,18.000,0.00,-0.0003,-0.00030,1.000
1,18.100,0.00,-0.0003,-0.00030,1.000
1,18.200,0.00,-0.0003,-0.00030,1.000
1,18.300,0.00,-0.0003,-0.00030,1.000
1,18.400,0.00,-0.0003,-0.00030,1.000
1,18.500,0.00,-0.0003,-0.00030,1.000
1,18.600,0.00,-0.0003,-0.00030,1.000
1,18.700,0.00,-0.0003,-0.00030,1.000
1,18.800,0.00,-0.0003,-0.00030,1.000
1,18.900,0.00,-0.0003,-0.00030,1.000
1,19.050,0.01,-0.0003,-0.00030,1.000
1,19.150,0.00,-0.0002,-0.00020,1.000
1,19.250,0.00,-0.0002,-0.00020,1.000
1,19.350,0.00,-0.0002,-0.00020,1.000
1,19.450,0.00,-0.0002,-0.00020,1.000
1,19.550,0.00,-0.0002,-0.00020,1.000
1,19.650,0.00,-0.0002,-0.00020,1.000
1,19.750,0.00,-0.0002,-0.00020,1.000
1,19.850,0.00,-0.0002,-0.00020,1.000
1,19.950,0.00,-0.0002,-0.00020,1.000
2,20.200,0.00,0.0696,0.06970,2.000
2,20.300,0.00,0.1695,0.16960,2.000
2,20.400,0.00,0.2696,0.26970,2.000
2,20.500,0.00,0.3695,0.36960,2.000
2,20.600,0.00,0.4696,0.46970,2.000
2,20.700,0.00,0.5695,0.56960,2.000
2,20.800,0.00,0.6698,0.66990,2.000
2,20.900,0.00,0.7696,0.76970,2.000
2,21.000,0.00,0.8698,0.86990,2.000
2,21.100,0.00,0.9696,0.96970,2.000
2,21.200,0.00,1.0696,1.06970,2.000
2,21.300,0.00,1.1696,1.16970,2.000
2,21.400,0.00,1.2697,1.26980,2.000
2,21.500,0.00,1.3697,1.36980,2.000
2,21.600,0.00,1.4697,1.46980,2.000
2,21.700,0.00,1.5696,1.56970,2.000
2,21.800,0.00,1.6697,1.66980,2.000
2,21.900,0.00,1.7696,1.76970,2.000
2,22.000,0.00,1.8698,1.86990,2.000
2,22.100,0.00,1.9696,1.96970,2.000
2,22.200,0.01,2.0696,2.06970,2.000
2,22.300,0.01,2.1697,2.16980,2.000
2,22.400,0.00,2.2698,2.26990,2.000
2,22.500,0.00,2.3696,2.36970,2.000
2,22.600,0.00,2.4698,2.46990,2.000
2,22.700,0.00,2.5696,2.56970,2.000
2,22.800,0.01,2.6696,2.66970,2.000
2,22.900,0.00,2.7697,2.76980,2.000
2,23.000,0.00,2.8698,2.86990,2.000
2,23.100,0.00,2.9697,2.96980,2.000
2,23.200,0.00,3.0698,3.06990,2.000
2,23.300,0.00,3.1699,3.17000,2.000
2,23.400,0.00,3.2697,3.26980,2.000
2,23.500,0.00,3.3698,3.36990,2.000
2,23.600,0.00,3.4697,3.46980,2.000
2,23.700,0.00,3.5700,3.57010,2.000
2,23.800,0.00,3.6698,3.66990,2.000
2,23.900,0.00,3.7699,3.77000,2.000
2,24.000,0.00,3.8698,3.86990,2.000
2,24.100,0.00,3.9697,3.96980,2.000
2,24.200,0.00,4.0698,4.06990,2.000
2,24.300,0.00,4.1698,4.16990,2.000
2,24.400,0.00,4.2698,4.26990,2.000
2,24.500,0.00,4.3700,4.37010,2.000
2,24.600,0.00,4.4699,4.47000,2.000
2,24.700,0.01,4.5699,4.57000,2.000
2,24.800,0.00,4.6699,4.67000,2.000
2,24.900,0.00,4.7700,4.77010,2.000
2,25.000,0.00,4.8698,4.86990,2.000
2,25.100,0.00,4.9698,4.96990,2.000
2,25.200,0.00,5.0699,5.07000,2.000
2,25.300,0.00,5.1699,5.17000,2.000
2,25.400,0.00,5.2699,5.27000,2.000
2,25.500,0.00,5.3700,5.37010,2.000
2,25.600,0.00,5.4699,5.47000,2.000
2,25.700,0.04,5.5701,5.57020,2.000
2,25.800,0.17,5.6700,5.67010,2.000
2,25.900,0.39,5.7700,5.77010,2.000
2,26.000,0.68,5.8698,5.86990,2.000
2,26.100,1.08,5.9699,5.97000,2.000
2,26.200,1.58,6.0698,6.06990,2.000
2,26.300,2.20,6.1699,6.17000,2.000
2,26.400,2.95,6.2699,6.27000,2.000
2,26.500,3.85,6.3700,6.37010,2.000
2,26.600,4.91,6.4698,6.46990,2.000
2,26.700,6.15,6.5699,6.57000,2.000
2,26.800,7.60,6.6698,6.66990,2.000
2,26.900,9.26,6.7700,6.77010,2.000
2,27.000,11.18,6.8698,6.86990,2.000
2,27.100,13.38,6.9699,6.97000,2.000
2,27.200,15.90,7.0698,7.06990,2.000
2,27.300,18.79,7.1699,7.17000,2.000
2,27.400,22.12,7.2698,7.26990,2.000
2,27.500,25.97,7.3700,7.37010,2.000
2,27.600,30.45,7.4698,7.46990,2.000
2,27.700,35.69,7.5699,7.57000,2.000
2,27.800,41.98,7.6698,7.66990,2.000
2,27.900,49.30,7.7699,7.77000,2.000
2,28.050,45.20,7.7587,7.75880,2.000
2,28.150,33.82,7.6587,7.65880,2.000
2,28.250,26.38,7.5587,7.55880,2.000
2,28.350,21.00,7.4586,7.45870,2.000
2,28.450,16.86,7.3587,7.35880,2.000
2,28.550,13.58,7.2587,7.25880,2.000
2,28.650,10.99,7.1588,7.15890,2.000
2,28.750,8.90,7.0586,7.05870,2.000
2,28.850,7.25,6.9586,6.95870,2.000
2,28.950,5.87,6.8586,6.85870,2.000
2,29.050,4.71,6.7586,6.75870,2.000
2,29.150,3.75,6.6586,6.65870,2.000
2,29.250,2.95,6.5586,6.55870,2.000
2,29.350,2.28,6.4585,6.45860,2.000
2,29.450,1.73,6.3587,6.35880,2.000
2,29.550,1.27,6.2584,6.25850,2.000
2,29.650,0.90,6.1586,6.15870,2.000
2,29.750,0.61,6.0585,6.05860,2.000
2,29.850,0.37,5.9586,5.95870,2.000
2,29.950,0.20,5.8584,5.85850,2.000
2,30.050,0.08,5.7585,5.75860,2.000
2,30.150,0.01,5.6585,5.65860,2.000
2,30.250,0.00,5.5585,5.55860,2.000
2,30.350,-0.01,5.4585,5.45860,2.000
2,30.450,0.00,5.3586,5.35870,2.000
2,30.550,0.00,5.2584,5.25850,2.000
2,30.650,0.00,5.1585,5.15860,2.000
2,30.750,0.00,5.0583,5.05840,2.000
2,30.850,0.00,4.9585,4.95860,2.000
2,30.950,0.00,4.8583,4.85840,2.000
2,31.050,0.00,4.7586,4.75870,2.000
2,31.150,0.00,4.6584,4.65850,2.000
2,31.250,0.00,4.5585,4.55860,2.000
2,31.350,0.00,4.4583,4.45840,2.000
2,31.450,0.00,4.3585,4.35860,2.000
2,31.550,0.00,4.2584,4.25850,2.000
2,31.650,0.00,4.1584,4.15850,2.000
2,31.750,0.01,4.0583,4.05840,2.000
2,31.850,0.00,3.9584,3.95850,2.000
2,31.950,0.00,3.8583,3.85840,2.000
2,32.050,0.00,3.7585,3.75860,2.000
2,32.150,0.00,3.6584,3.65850,2.000
2,32.250,0.00,3.5584,3.55850,2.000
2,32.350,0.00,3.4583,3.45840,2.000
2,32.450,0.01,3.3583,3.35840,2.000
2,32.550,0.00,3.2582,3.25830,2.000
2,32.650,0.00,3.1586,3.15870,2.000
2,32.750,0.00,3.0583,3.05840,2.000
2,32.850,0.00,2.9584,2.95850,2.000
2,32.950,0.00,2.8583,2.85840,2.000
2,33.050,0.00,2.7585,2.75860,2.000
2,33.150,0.00,2.6581,2.65820,2.000
2,33.250,0.00,2.5583,2.55840,2.000
2,33.350,0.00,2.4581,2.45820,2.000
2,33.450,0.00,2.3584,2.35850,2.000
2,33.550,0.00,2.2582,2.25830,2.000
2,33.650,0.00,2.1583,2.15840,2.000
2,33.750,0.00,2.0581,2.05820,2.000
2,33.850,0.00,1.9582,1.95830,2.000
2,33.950,0.00,1.8581,1.85820,2.000
2,34.050,0.00,1.7583,1.75840,2.000
2,34.150,0.00,1.6581,1.65820,2.000
2,34.250,0.00,1.5583,1.55840,2.000
2,34.350,0.00,1.4582,1.45830,2.000
2,34.450,0.00,1.3582,1.35830,2.000
2,34.550,0.00,1.2581,1.25820,2.000
2,34.650,0.00,1.1583,1.15840,2.000
2,34.750,0.00,1.0581,1.05820,2.000
2,34.850,0.00,0.9582,0.95830,2.000
2,34.950,0.00,0.8580,0.85810,2.000
2,35.050,0.00,0.7582,0.75830,2.000
2,35.150,0.00,0.6581,0.65820,2.000
2,35.250,0.00,0.5582,0.55830,2.000
2,35.350,0.00,0.4580,0.45810,2.000
2,35.450,0.00,0.3582,0.35830,2.000
2,35.550,0.00,0.2581,0.25820,2.000
2,35.650,0.00,0.1581,0.15820,2.000
2,35.750,0.00,0.0579,0.05800,2.000
2,35.900,0.00,-0.0297,-0.02960,2.000
2,36.000,0.00,-0.0003,-0.00020,2.000
2,36.100,0.00,-0.0003,-0.00020,2.000
2,36.200,0.00,-0.0003,-0.00020,2.000
2,36.300,0.00,-0.0003,-0.00020,2.000
2,36.400,0.00,-0.0003,-0.00020,2.000
2,36.500,0.00,-0.0003,-0.00020,2.000
2,36.600,0.00,-0.0003,-0.00020,2.000
2,36.700,0.01,-0.0003,-0.00020,2.000
2,36.800,0.01,-0.0003,-0.00020,2.000
2,36.900,0.00,-0.0003,-0.00020,2.000
2,37.000,0.01,-0.0003,-0.00020,2.000
2,37.100,0.00,-0.0003,-0.00020,2.000
2,37.200,0.00,-0.0003,-0.00020,2.000
2,37.300,0.00,-0.0003,-0.00020,2.000
2,37.400,0.00,-0.0003,-0.00020,2.000
2,37.500,0.00,-0.0003,-0.00020,2.000
2,37.600,0.00,-0.0003,-0.00020,2.000
2,37.700,0.00,-0.0003,-0.00020,2.000
2,37.800,0.01,-0.0003,-0.00020,2.000
2,37.900,0.00,-0.0003,-0.00020,2.000
2,38.000,0.00,-0.0003,-0.00020,2.000
2,38.100,0.00,-0.0003,-0.00020,2.000
2,38.200,0.00,-0.0003,-0.00020,2.000
2,38.300,0.00,-0.0003,-0.00020,2.000
2,38.400,0.00,-0.0003,-0.00020,2.000
2,38.500,0.00,-0.0003,-0.00020,2.000
2,38.600,0.00,-0.0003,-0.00020,2.000
2,38.700,0.00,-0.0002,-0.00010,2.000
2,38.800,0.00,-0.0002,-0.00010,2.000
2,38.950,0.00,-0.0002,-0.00010,2.000
2,39.050,0.00,-0.0002,-0.00010,2.000
2,39.150,0.00,-0.0002,-0.00010,2.000
2,39.250,0.00,-0.0002,-0.00010,2.000
2,39.350,0.00,-0.0002,-0.00010,2.000
2,39.450,0.00,-0.0002,-0.00010,2.000
2,39.550,0.00,-0.0002,-0.00010,2.000
2,39.650,0.00,-0.0002,-0.00010,2.000
2,39.750,0.00,-0.0002,-0.00010,2.000
2,39.850,0.00,-0.0002,-0.00010,2.000
3,40.100,0.00,0.0297,0.02980,3.000
3,40.200,0.00,0.1294,0.12950,3.000
3,40.300,0.00,0.2296,0.22970,3.000
3,40.400,0.00,0.3295,0.32960,3.000
3,40.500,0.00,0.4296,0.42970,3.000
3,40.600,0.00,0.5295,0.52960,3.000
3,40.700,0.00,0.6297,0.62980,3.000
3,40.800,0.00,0.7296,0.72970,3.000
3,40.900,0.00,0.8297,0.82980,3.000
3,41.000,0.00,0.9296,0.92970,3.000
3,41.100,0.00,1.0296,1.02970,3.000
3,41.200,0.00,1.1296,1.12970,3.000
3,41.300,0.00,1.2296,1.22970,3.000
3,41.400,0.00,1.3295,1.32960,3.000
3,41.500,0.00,1.4297,1.42980,3.000
3,41.600,0.00,1.5298,1.52990,3.000
3,41.700,0.00,1.6296,1.62970,3.000
3,41.800,0.00,1.7296,1.72970,3.000
3,41.900,-0.01,1.8297,1.82980,3.000
3,42.000,0.00,1.9296,1.92970,3.000
3,42.100,0.00,2.0297,2.02980,3.000
3,42.200,-0.01,2.1297,2.12980,3.000
3,42.300,0.00,2.2296,2.22970,3.000
3,42.400,0.00,2.3297,2.32980,3.000
3,42.500,-0.01,2.4297,2.42980,3.000
3,42.600,0.00,2.5297,2.52980,3.000
3,42.700,-0.01,2.6297,2.62980,3.000
3,42.800,0.00,2.7298,2.72990,3.000
3,42.900,0.00,2.8297,2.82980,3.000
3,43.000,-0.01,2.9297,2.92980,3.000
3,43.100,0.00,3.0298,3.02990,3.000
3,43.200,0.00,3.1299,3.13000,3.000
3,43.300,-0.01,3.2298,3.22990,3.000
3,43.400,0.00,3.3297,3.32980,3.000
3,43.500,0.00,3.4298,3.42990,3.000
3,43.600,0.00,3.5298,3.52990,3.000
3,43.700,0.00,3.6299,3.63000,3.000
3,43.800,0.00,3.7298,3.72990,3.000
3,43.900,-0.01,3.8298,3.82990,3.000
3,44.000,0.00,3.9298,3.92990,3.000
3,44.100,0.00,4.0298,4.02990,3.000
3,44.200,0.00,4.1299,4.13000,3.000
3,44.300,0.00,4.2298,4.22990,3.000
3,44.400,0.00,4.3299,4.33000,3.000
3,44.500,-0.01,4.4299,4.43000,3.000
3,44.600,0.00,4.5299,4.53000,3.000
3,44.700,0.00,4.6297,4.62980,3.000
3,44.800,-0.01,4.7300,4.73010,3.000
3,44.900,0.00,4.8297,4.82980,3.000
3,45.000,0.00,4.9299,4.93000,3.000
3,45.100,0.00,5.0299,5.03000,3.000
3,45.200,0.00,5.1300,5.13010,3.000
3,45.300,0.00,5.2298,5.22990,3.000
3,45.400,0.00,5.3300,5.33010,3.000
3,45.500,0.00,5.4298,5.42990,3.000
3,45.600,0.01,5.5299,5.53000,3.000
3,45.700,0.10,5.6300,5.63010,3.000
3,45.800,0.28,5.7301,5.73020,3.000
3,45.900,0.54,5.8298,5.82990,3.000
3,46.000,0.89,5.9299,5.93000,3.000
3,46.100,1.34,6.0297,6.02980,3.000
3,46.200,1.91,6.1298,6.12990,3.000
3,46.300,2.59,6.2298,6.22990,3.000
3,46.400,3.42,6.3300,6.33010,3.000
3,46.500,4.40,6.4298,6.42990,3.000
3,46.600,5.56,6.5300,6.53010,3.000
3,46.700,6.91,6.6298,6.62990,3.000
3,46.800,8.48,6.7299,6.73000,3.000
3,46.900,10.28,6.8298,6.82990,3.000
3,47.000,12.32,6.9298,6.92990,3.000
3,47.100,14.66,7.0297,7.02980,3.000
3,47.200,17.35,7.1299,7.13000,3.000
3,47.300,20.43,7.2299,7.23000,3.000
3,47.400,23.96,7.3299,7.33000,3.000
3,47.500,28.05,7.4297,7.42980,3.000
3,47.600,32.82,7.5300,7.53010,3.000
3,47.700,38.50,7.6299,7.63000,3.000
3,47.800,45.30,7.7299,7.73000,3.000
3,47.950,54.33,7.8340,7.83410,3.000
3,48.050,40.73,7.7386,7.73870,3.000
3,48.150,31.09,7.6387,7.63880,3.000
3,48.250,24.48,7.5386,7.53870,3.000
3,48.350,19.53,7.4386,7.43870,3.000
3,48.450,15.70,7.3386,7.33870,3.000
3,48.550,12.67,7.2387,7.23880,3.000
3,48.650,10.26,7.1387,7.13880,3.000
3,48.750,8.37,7.0386,7.03870,3.000
3,48.850,6.80,6.9387,6.93880,3.000
3,48.950,5.49,6.8387,6.83880,3.000
3,49.050,4.41,6.7387,6.73880,3.000
3,49.150,3.50,6.6387,6.63880,3.000
3,49.250,2.74,6.5386,6.53870,3.000
3,49.350,2.11,6.4386,6.43870,3.000
3,49.450,1.59,6.3386,6.33870,3.000
3,49.550,1.16,6.2386,6.23870,3.000
3,49.650,0.81,6.1385,6.13860,3.000
3,49.750,0.54,6.0386,6.03870,3.000
3,49.850,0.32,5.9385,5.93860,3.000
3,49.950,0.16,5.8385,5.83860,3.000
3,50.050,0.06,5.7384,5.73850,3.000
3,50.150,-0.01,5.6385,5.63860,3.000
3,50.250,-0.01,5.5385,5.53860,3.000
3,50.350,0.00,5.4386,5.43870,3.000
3,50.450,-0.01,5.3386,5.33870,3.000
3,50.550,0.00,5.2385,5.23860,3.000
3,50.650,-0.01,5.1385,5.13860,3.000
3,50.750,-0.01,5.0385,5.03860,3.000
3,50.850,0.00,4.9383,4.93840,3.000
3,50.950,-0.01,4.8384,4.83850,3.000
3,51.050,-0.01,4.7384,4.73850,3.000
3,51.150,0.00,4.6384,4.63850,3.000
3,51.250,0.00,4.5382,4.53830,3.000
3,51.350,0.00,4.4385,4.43860,3.000
3,51.450,0.00,4.3384,4.33850,3.000
3,51.550,-0.01,4.2384,4.23850,3.000
3,51.650,-0.01,4.1382,4.13830,3.000
3,51.750,-0.01,4.0385,4.03860,3.000
3,51.850,0.00,3.9383,3.93840,3.000
3,51.950,0.01,3.8384,3.83850,3.000
3,52.050,0.00,3.7384,3.73850,3.000
3,52.150,0.00,3.6384,3.63850,3.000
3,52.250,0.00,3.5383,3.53840,3.000
3,52.350,0.00,3.4384,3.43850,3.000
3,52.450,0.00,3.3382,3.33830,3.000
3,52.550,0.00,3.2384,3.23850,3.000
3,52.650,0.00,3.1383,3.13840,3.000
3,52.750,0.00,3.0384,3.03850,3.000
3,52.850,0.00,2.9382,2.93830,3.000
3,52.950,-0.01,2.8385,2.83860,3.000
3,53.050,-0.01,2.7382,2.73830,3.000
3,53.150,-0.01,2.6383,2.63840,3.000
3,53.250,0.00,2.5381,2.53820,3.000
3,53.350,0.00,2.4384,2.43850,3.000
3,53.450,0.00,2.3381,2.33820,3.000
3,53.550,0.00,2.2383,2.23840,3.000
3,53.650,-0.01,2.1382,2.13830,3.000
3,53.750,0.00,2.0382,2.03830,3.000
3,53.850,0.00,1.9381,1.93820,3.000
3,53.950,0.00,1.8383,1.83840,3.000
3,54.050,0.00,1.7381,1.73820,3.000
3,54.150,0.00,1.6383,1.63840,3.000
3,54.250,0.00,1.5380,1.53810,3.000
3,54.350,0.00,1.4383,1.43840,3.000
3,54.450,0.00,1.3380,1.33810,3.000
3,54.550,0.00,1.2382,1.23830,3.000
3,54.650,0.00,1.1382,1.13830,3.000
3,54.750,-0.01,1.0383,1.03840,3.000
3,54.850,0.00,0.9381,0.93820,3.000
3,54.950,-0.01,0.8382,0.83830,3.000
3,55.050,-0.01,0.7380,0.73810,3.000
3,55.150,0.00,0.6382,0.63830,3.000
3,55.250,0.00,0.5381,0.53820,3.000
3,55.350,0.00,0.4382,0.43830,3.000
3,55.450,0.00,0.3380,0.33810,3.000
3,55.550,0.00,0.2383,0.23840,3.000
3,55.650,0.00,0.1380,0.13810,3.000
3,55.750,-0.01,0.0381,0.03820,3.000
3,55.850,0.00,-0.0412,-0.04110,3.000
3,55.950,0.00,-0.0003,-0.00020,3.000
3,56.050,0.00,-0.0003,-0.00020,3.000
3,56.150,0.00,-0.0003,-0.00020,3.000
3,56.250,0.00,-0.0003,-0.00020,3.000
3,56.350,0.00,-0.0003,-0.00020,3.000
3,56.450,0.00,-0.0003,-0.00020,3.000
3,56.550,0.00,-0.0003,-0.00020,3.000
3,56.650,-0.01,-0.0003,-0.00020,3.000
3,56.750,0.00,-0.0003,-0.00020,3.000
3,56.850,-0.01,-0.0003,-0.00020,3.000
3,56.950,0.00,-0.0003,-0.00020,3.000
3,57.050,0.00,-0.0003,-0.00020,3.000
3,57.150,0.00,-0.0003,-0.00020,3.000
3,57.250,0.00,-0.0003,-0.00020,3.000
3,57.350,0.00,-0.0003,-0.00020,3.000
3,57.450,0.00,-0.0003,-0.00020,3.000
3,57.550,-0.01,-0.0003,-0.00020,3.000
3,57.650,0.00,-0.0003,-0.00020,3.000
3,57.750,0.00,-0.0003,-0.00020,3.000
3,57.850,0.00,-0.0003,-0.00020,3.000
3,57.950,-0.01,-0.0003,-0.00020,3.000
3,58.050,0.00,-0.0003,-0.00020,3.000
3,58.150,0.00,-0.0003,-0.00020,3.000
3,58.250,-0.01,-0.0003,-0.00020,3.000
3,58.350,0.00,-0.0003,-0.00020,3.000
3,58.450,0.00,-0.0002,-0.00010,3.000
3,58.550,0.00,-0.0002,-0.00010,3.000
3,58.650,0.00,-0.0002,-0.00010,3.000
3,58.750,0.00,-0.0002,-0.00010,3.000
3,58.850,0.00,-0.0002,-0.00010,3.000
3,59.000,0.00,-0.0002,-0.00010,3.000
3,59.100,0.00,-0.0002,-0.00010,3.000
3,59.200,0.00,-0.0002,-0.00010,3.000
3,59.300,0.00,-0.0002,-0.00010,3.000
3,59.400,0.00,-0.0002,-0.00010,3.000
3,59.500,0.00,-0.0002,-0.00010,3.000
3,59.600,-0.01,-0.0002,-0.00010,3.000
3,59.700,-0.01,-0.0002,-0.00010,3.000
3,59.800,0.00,-0.0002,-0.00010,3.000
4,60.000,0.00,-0.0001,0.00000,4.000
4,60.100,0.00,0.0695,0.06960,4.000
4,60.200,0.00,0.1695,0.16960,4.000
4,60.300,0.00,0.2696,0.26970,4.000
4,60.400,0.00,0.3696,0.36970,4.000
4,60.500,-0.01,0.4695,0.46960,4.000
4,60.600,0.00,0.5695,0.56960,4.000
4,60.700,-0.01,0.6697,0.66980,4.000
4,60.800,0.00,0.7696,0.76970,4.000
4,60.900,0.00,0.8697,0.86980,4.000
4,61.000,0.00,0.9695,0.96960,4.000
4,61.100,0.00,1.0697,1.06980,4.000
4,61.200,0.00,1.1696,1.16970,4.000
4,61.300,-0.01,1.2696,1.26970,4.000
4,61.400,0.00,1.3696,1.36970,4.000
4,61.500,-0.01,1.4696,1.46970,4.000
4,61.600,0.00,1.5697,1.56980,4.000
4,61.700,0.00,1.6697,1.66980,4.000
4,61.800,0.00,1.7697,1.76980,4.000
4,61.900,0.00,1.8697,1.86980,4.000
4,62.000,-0.01,1.9697,1.96980,4.000
4,62.100,-0.01,2.0697,2.06980,4.000
4,62.200,0.00,2.1698,2.16990,4.000
4,62.300,0.00,2.2698,2.26990,4.000
4,62.400,0.00,2.3698,2.36990,4.000
4,62.500,-0.01,2.4697,2.46980,4.000
4,62.600,-0.01,2.5697,2.56980,4.000
4,62.700,-0.01,2.6697,2.66980,4.000
4,62.800,0.00,2.7698,2.76990,4.000
4,62.900,-0.01,2.8697,2.86980,4.000
4,63.000,0.00,2.9698,2.96990,4.000
4,63.100,0.00,3.0698,3.06990,4.000
4,63.200,-0.01,3.1698,3.16990,4.000
4,63.300,0.00,3.2696,3.26970,4.000
4,63.400,0.00,3.3698,3.36990,4.000
4,63.500,-0.01,3.4698,3.46990,4.000
4,63.600,0.00,3.5698,3.56990,4.000
4,63.700,-0.01,3.6698,3.66990,4.000
4,63.800,-0.01,3.7698,3.76990,4.000
4,63.900,0.00,3.8697,3.86980,4.000
4,64.000,0.00,3.9698,3.96990,4.000
4,64.100,0.00,4.0698,4.06990,4.000
4,64.200,0.00,4.1700,4.17010,4.000
4,64.300,0.00,4.2698,4.26990,4.000
4,64.400,0.00,4.3700,4.37010,4.000
4,64.500,0.00,4.4698,4.46990,4.000
4,64.600,0.00,4.5698,4.56990,4.000
4,64.700,-0.01,4.6697,4.66980,4.000
4,64.800,0.00,4.7699,4.77000,4.000
4,64.900,0.00,4.8697,4.86980,4.000
4,65.000,0.00,4.9699,4.97000,4.000
4,65.100,-0.01,5.0697,5.06980,4.000
4,65.200,0.00,5.1699,5.17000,4.000
4,65.300,-0.01,5.2697,5.26980,4.000
4,65.400,0.00,5.3700,5.37010,4.000
4,65.500,0.00,5.4699,5.47000,4.000
4,65.600,0.03,5.5701,5.57020,4.000
4,65.700,0.15,5.6699,5.67000,4.000
4,65.800,0.36,5.7699,5.77000,4.000
4,65.900,0.65,5.8697,5.86980,4.000
4,66.000,1.04,5.9700,5.97010,4.000
4,66.100,1.53,6.0698,6.06990,4.000
4,66.200,2.13,6.1699,6.17000,4.000
4,66.300,2.87,6.2698,6.26990,4.000
4,66.400,3.75,6.3700,6.37010,4.000
4,66.500,4.80,6.4697,6.46980,4.000
4,66.600,6.03,6.5699,6.57000,4.000
4,66.700,7.45,6.6698,6.66990,4.000
4,66.800,9.08,6.7699,6.77000,4.000
4,66.900,10.96,6.8698,6.86990,4.000
4,67.000,13.10,6.9698,6.96990,4.000
4,67.100,15.53,7.0698,7.06990,4.000
4,67.200,18.33,7.1700,7.17010,4.000
4,67.300,21.52,7.2697,7.26980,4.000
4,67.400,25.21,7.3699,7.37000,4.000
4,67.500,29.49,7.4698,7.46990,4.000
4,67.600,34.48,7.5700,7.57010,4.000
4,67.700,40.42,7.6698,7.66990,4.000
4,67.800,47.62,7.7699,7.77000,4.000
4,67.950,48.89,7.7987,7.79880,4.000
4,68.050,36.02,7.6986,7.69870,4.000
4,68.150,27.95,7.5987,7.59880,4.000
4,68.250,22.13,7.4987,7.49880,4.000
4,68.350,17.74,7.3986,7.39870,4.000
4,68.450,14.28,7.2987,7.29880,4.000
4,68.550,11.54,7.1987,7.19880,4.000
4,68.650,9.35,7.0986,7.09870,4.000
4,68.750,7.66,6.9986,6.99870,4.000
4,68.850,6.20,6.8987,6.89880,4.000
4,68.950,4.98,6.7986,6.79870,4.000
4,69.050,3.98,6.6987,6.69880,4.000
4,69.150,3.15,6.5986,6.59870,4.000
4,69.250,2.45,6.4985,6.49860,4.000
4,69.350,1.86,6.3986,6.39870,4.000
4,69.450,1.38,6.2986,6.29870,4.000
4,69.550,0.99,6.1985,6.19860,4.000
4,69.650,0.67,6.0985,6.09860,4.000
4,69.750,0.43,5.9985,5.99860,4.000
4,69.850,0.23,5.8983,5.89840,4.000
4,69.950,0.11,5.7985,5.79860,4.000
4,70.050,0.03,5.6985,5.69860,4.000
4,70.150,-0.01,5.5986,5.59870,4.000
4,70.250,-0.01,5.4986,5.49870,4.000
4,70.350,0.00,5.3986,5.39870,4.000
4,70.450,0.00,5.2985,5.29860,4.000
4,70.550,0.00,5.1985,5.19860,4.000
4,70.650,-0.01,5.0983,5.09840,4.000
4,70.750,0.00,4.9985,4.99860,4.000
4,70.850,0.00,4.8982,4.89830,4.000
4,70.950,-0.01,4.7984,4.79850,4.000
4,71.050,0.00,4.6984,4.69850,4.000
4,71.150,0.00,4.5984,4.59850,4.000
4,71.250,0.00,4.4983,4.49840,4.000
4,71.350,0.00,4.3985,4.39860,4.000
4,71.450,0.00,4.2983,4.29840,4.000
4,71.550,0.00,4.1984,4.19850,4.000
4,71.650,0.00,4.0984,4.09850,4.000
4,71.750,0.00,3.9983,3.99840,4.000
4,71.850,0.00,3.8983,3.89840,4.000
4,71.950,0.00,3.7985,3.79860,4.000
4,72.050,-0.01,3.6982,3.69830,4.000
4,72.150,0.00,3.5985,3.59860,4.000
4,72.250,0.00,3.4984,3.49850,4.000
4,72.350,-0.01,3.3984,3.39850,4.000
4,72.450,-0.01,3.2981,3.29820,4.000
4,72.550,0.00,3.1985,3.19860,4.000
4,72.650,0.00,3.0983,3.09840,4.000
4,72.750,0.00,2.9984,2.99850,4.000
4,72.850,0.00,2.8983,2.89840,4.000
4,72.950,0.00,2.7984,2.79850,4.000
4,73.050,0.00,2.6982,2.69830,4.000
4,73.150,0.00,2.5984,2.59850,4.000
4,73.250,0.00,2.4981,2.49820,4.000
4,73.350,0.00,2.3983,2.39840,4.000
4,73.450,-0.01,2.2981,2.29820,4.000
4,73.550,-0.01,2.1984,2.19850,4.000
4,73.650,0.00,2.0981,2.09820,4.000
4,73.750,0.00,1.9983,1.99840,4.000
4,73.850,-0.01,1.8982,1.89830,4.000
4,73.950,0.00,1.7983,1.79840,4.000
4,74.050,-0.01,1.6981,1.69820,4.000
4,74.150,0.00,1.5982,1.59830,4.000
4,74.250,0.00,1.4982,1.49830,4.000
4,74.350,0.00,1.3982,1.39830,4.000
4,74.450,0.00,1.2980,1.29810,4.000
4,74.550,-0.01,1.1983,1.19840,4.000
4,74.650,0.00,1.0980,1.09810,4.000
4,74.750,0.00,0.9982,0.99830,4.000
4,74.850,0.00,0.8981,0.89820,4.000
4,74.950,-0.01,0.7983,0.79840,4.000
4,75.050,0.00,0.6981,0.69820,4.000
4,75.150,0.00,0.5982,0.59830,4.000
4,75.250,-0.01,0.4981,0.49820,4.000
4,75.350,0.00,0.3982,0.39830,4.000
4,75.450,0.00,0.2981,0.29820,4.000
4,75.550,-0.01,0.1983,0.19840,4.000
4,75.650,0.00,0.0979,0.09800,4.000
4,75.750,0.00,-0.0018,-0.00170,4.000
4,75.900,0.00,-0.0011,-0.00100,4.000
4,76.000,0.00,-0.0003,-0.00020,4.000
4,76.100,0.00,-0.0003,-0.00020,4.000
4,76.200,-0.01,-0.0003,-0.00020,4.000
4,76.300,0.00,-0.0003,-0.00020,4.000
4,76.400,0.00,-0.0003,-0.00020,4.000
4,76.500,0.00,-0.0003,-0.00020,4.000
4,76.600,0.00,-0.0003,-0.00020,4.000
4,76.700,-0.01,-0.0003,-0.00020,4.000
4,76.800,0.00,-0.0003,-0.00020,4.000
4,76.900,0.00,-0.0003,-0.00020,4.000
4,77.000,0.00,-0.0003,-0.00020,4.000
4,77.100,0.00,-0.0003,-0.00020,4.000
4,77.200,0.00,-0.0003,-0.00020,4.000
4,77.300,0.00,-0.0003,-0.00020,4.000
4,77.400,0.00,-0.0003,-0.00020,4.000
4,77.500,0.00,-0.0003,-0.00020,4.000
4,77.600,0.00,-0.0003,-0.00020,4.000
4,77.700,0.00,-0.0003,-0.00020,4.000
4,77.800,-0.01,-0.0003,-0.00020,4.000
4,77.900,-0.01,-0.0003,-0.00020,4.000
4,78.000,-0.01,-0.0003,-0.00020,4.000
4,78.100,-0.01,-0.0003,-0.00020,4.000
4,78.200,0.00,-0.0003,-0.00020,4.000
4,78.300,0.00,-0.0003,-0.00020,4.000
4,78.400,0.00,-0.0002,-0.00010,4.000
4,78.500,-0.01,-0.0002,-0.00010,4.000
4,78.600,0.00,-0.0002,-0.00010,4.000
4,78.700,0.00,-0.0002,-0.00010,4.000
4,78.800,0.00,-0.0002,-0.00010,4.000
4,78.950,0.00,-0.0002,-0.00010,4.000
4,79.050,0.00,-0.0002,-0.00010,4.000
4,79.150,0.00,-0.0002,-0.00010,4.000
4,79.250,0.00,-0.0002,-0.00010,4.000
4,79.350,0.00,-0.0002,-0.00010,4.000
4,79.450,0.00,-0.0002,-0.00010,4.000
4,79.550,0.00,-0.0002,-0.00010,4.000
4,79.650,0.00,-0.0002,-0.00010,4.000
4,79.750,0.00,-0.0002,-0.00010,4.000
5,79.950,0.00,-0.0001,0.00000,5.000
5,80.050,0.00,0.0695,0.06960,5.000
5,80.150,0.00,0.1696,0.16970,5.000
5,80.250,0.00,0.2695,0.26960,5.000
5,80.350,0.00,0.3695,0.36960,5.000
5,80.450,0.00,0.4697,0.46980,5.000
5,80.550,0.00,0.5696,0.56970,5.000
5,80.650,0.00,0.6696,0.66970,5.000
5,80.750,0.00,0.7696,0.76970,5.000
5,80.850,0.00,0.8696,0.86970,5.000
5,80.950,0.00,0.9696,0.96970,5.000
5,81.050,0.00,1.0697,1.06980,5.000
5,81.150,0.00,1.1697,1.16980,5.000
5,81.250,0.00,1.2696,1.26970,5.000
5,81.350,0.00,1.3697,1.36980,5.000
5,81.450,-0.01,1.4697,1.46980,5.000
5,81.550,0.00,1.5698,1.56990,5.000
5,81.650,0.00,1.6696,1.66970,5.000
5,81.750,0.00,1.7696,1.76970,5.000
5,81.850,0.00,1.8697,1.86980,5.000
5,81.950,0.00,1.9696,1.96970,5.000
5,82.050,0.00,2.0696,2.06970,5.000
5,82.150,0.00,2.1698,2.16990,5.000
5,82.250,0.00,2.2697,2.26980,5.000
5,82.350,0.00,2.3698,2.36990,5.000
5,82.450,0.00,2.4697,2.46980,5.000
5,82.550,0.00,2.5698,2.56990,5.000
5,82.650,0.00,2.6696,2.66970,5.000
5,82.750,0.00,2.7699,2.77000,5.000
5,82.850,0.00,2.8697,2.86980,5.000
5,82.950,0.00,2.9699,2.97000,5.000
5,83.050,0.00,3.0697,3.06980,5.000
5,83.150,0.00,3.1699,3.17000,5.000
5,83.250,0.00,3.2697,3.26980,5.000
5,83.350,0.00,3.3697,3.36980,5.000
5,83.450,0.00,3.4698,3.46990,5.000
5,83.550,0.00,3.5700,3.57010,5.000
5,83.650,0.00,3.6699,3.67000,5.000
5,83.750,0.00,3.7700,3.77010,5.000
5,83.850,0.00,3.8698,3.86990,5.000
5,83.950,0.00,3.9699,3.97000,5.000
5,84.050,0.00,4.0698,4.06990,5.000
5,84.150,0.00,4.1698,4.16990,5.000
5,84.250,0.00,4.2697,4.26980,5.000
5,84.350,0.00,4.3701,4.37020,5.000
5,84.450,0.00,4.4699,4.47000,5.000
5,84.550,0.00,4.5699,4.57000,5.000
5,84.650,0.00,4.6698,4.66990,5.000
5,84.750,0.00,4.7699,4.77000,5.000
5,84.850,0.00,4.8697,4.86980,5.000
5,84.950,0.00,4.9699,4.97000,5.000
5,85.050,0.00,5.0698,5.06990,5.000
5,85.150,0.00,5.1698,5.16990,5.000
5,85.250,0.00,5.2697,5.26980,5.000
5,85.350,0.00,5.3700,5.37010,5.000
5,85.450,0.00,5.4698,5.46990,5.000
5,85.550,0.04,5.5700,5.57010,5.000
5,85.650,0.16,5.6699,5.67000,5.000
5,85.750,0.36,5.7698,5.76990,5.000
5,85.850,0.65,5.8697,5.86980,5.000
5,85.950,1.04,5.9700,5.97010,5.000
5,86.050,1.53,6.0698,6.06990,5.000
5,86.150,2.13,6.1699,6.17000,5.000
5,86.250,2.86,6.2698,6.26990,5.000
5,86.350,3.74,6.3700,6.37010,5.000
5,86.450,4.79,6.4698,6.46990,5.000
5,86.550,6.00,6.5699,6.57000,5.000
5,86.650,7.41,6.6699,6.67000,5.000
5,86.750,9.03,6.7698,6.76990,5.000
5,86.850,10.91,6.8699,6.87000,5.000
5,86.950,13.03,6.9698,6.96990,5.000
5,87.050,15.46,7.0697,7.06980,5.000
5,87.150,18.24,7.1700,7.17010,5.000
5,87.250,21.40,7.2698,7.26990,5.000
5,87.350,25.04,7.3700,7.37010,5.000
5,87.450,29.27,7.4698,7.46990,5.000
5,87.550,34.22,7.5700,7.57010,5.000
5,87.650,40.10,7.6698,7.66990,5.000
5,87.750,47.27,7.7698,7.76990,5.000
5,87.900,51.85,7.8242,7.82430,5.000
5,88.000,37.86,7.7246,7.72470,5.000
5,88.100,29.18,7.6247,7.62480,5.000
5,88.200,23.04,7.5247,7.52480,5.000
5,88.300,18.43,7.4247,7.42480,5.000
5,88.400,14.84,7.3247,7.32480,5.000
5,88.500,11.98,7.2247,7.22480,5.000
5,88.600,9.73,7.1247,7.12480,5.000
5,88.700,7.95,7.0246,7.02470,5.000
5,88.800,6.44,6.9246,6.92470,5.000
5,88.900,5.19,6.8245,6.82460,5.000
5,89.000,4.15,6.7247,6.72480,5.000
5,89.100,3.29,6.6246,6.62470,5.000
5,89.200,2.57,6.5246,6.52470,5.000
5,89.300,1.98,6.4246,6.42470,5.000
5,89.400,1.47,6.3246,6.32470,5.000
5,89.500,1.07,6.2244,6.22450,5.000
5,89.600,0.74,6.1245,6.12460,5.000
5,89.700,0.48,6.0244,6.02450,5.000
5,89.800,0.27,5.9245,5.92460,5.000
5,89.900,0.13,5.8242,5.82430,5.000
5,90.000,0.04,5.7245,5.72460,5.000
5,90.100,-0.01,5.6245,5.62460,5.000
5,90.200,-0.01,5.5245,5.52460,5.000
5,90.300,0.00,5.4245,5.42460,5.000
5,90.400,0.00,5.3246,5.32470,5.000
5,90.500,-0.01,5.2243,5.22440,5.000
5,90.600,0.00,5.1245,5.12460,5.000
5,90.700,0.00,5.0244,5.02450,5.000
5,90.800,0.00,4.9244,4.92450,5.000
5,90.900,0.00,4.8243,4.82440,5.000
5,91.000,0.00,4.7245,4.72460,5.000
5,91.100,0.00,4.6242,4.62430,5.000
5,91.200,0.00,4.5245,4.52460,5.000
5,91.300,0.00,4.4244,4.42450,5.000
5,91.400,0.00,4.3246,4.32470,5.000
5,91.500,0.00,4.2243,4.22440,5.000
5,91.600,0.00,4.1244,4.12450,5.000
5,91.700,0.00,4.0243,4.02440,5.000
5,91.800,0.00,3.9243,3.92440,5.000
5,91.900,0.00,3.8244,3.82450,5.000
5,92.000,0.00,3.7244,3.72450,5.000
5,92.100,0.00,3.6243,3.62440,5.000
5,92.200,0.00,3.5244,3.52450,5.000
5,92.300,0.00,3.4242,3.42430,5.000
5,92.400,0.00,3.3243,3.32440,5.000
5,92.500,0.00,3.2243,3.22440,5.000
5,92.600,0.00,3.1244,3.12450,5.000
5,92.700,0.00,3.0243,3.02440,5.000
5,92.800,0.00,2.9244,2.92450,5.000
5,92.900,0.00,2.8243,2.82440,5.000
5,93.000,0.00,2.7243,2.72440,5.000
5,93.100,-0.01,2.6241,2.62420,5.000
5,93.200,0.00,2.5244,2.52450,5.000
5,93.300,0.00,2.4242,2.42430,5.000
5,93.400,-0.01,2.3243,2.32440,5.000
5,93.500,0.00,2.2241,2.22420,5.000
5,93.600,0.00,2.1243,2.12440,5.000
5,93.700,0.00,2.0240,2.02410,5.000
5,93.800,0.00,1.9243,1.92440,5.000
5,93.900,0.00,1.8242,1.82430,5.000
5,94.000,0.00,1.7242,1.72430,5.000
5,94.100,0.00,1.6241,1.62420,5.000
5,94.200,0.00,1.5242,1.52430,5.000
5,94.300,0.00,1.4241,1.42420,5.000
5,94.400,0.00,1.3241,1.32420,5.000
5,94.500,0.00,1.2240,1.22410,5.000
5,94.600,0.00,1.1242,1.12430,5.000
5,94.700,0.00,1.0240,1.02410,5.000
5,94.800,0.00,0.9243,0.92440,5.000
5,94.900,0.00,0.8241,0.82420,5.000
5,95.000,0.00,0.7243,0.72440,5.000
5,95.100,0.00,0.6241,0.62420,5.000
5,95.200,0.00,0.5242,0.52430,5.000
5,95.300,0.00,0.4240,0.42410,5.000
5,95.400,0.00,0.3241,0.32420,5.000
5,95.500,0.00,0.2242,0.22430,5.000
5,95.600,0.00,0.1241,0.12420,5.000
5,95.700,0.00,0.0240,0.02410,5.000
5,95.850,0.00,-0.0084,-0.00830,5.000
5,95.950,0.00,-0.0003,-0.00020,5.000
5,96.050,0.00,-0.0003,-0.00020,5.000
5,96.150,0.00,-0.0003,-0.00020,5.000
5,96.250,0.00,-0.0003,-0.00020,5.000
5,96.350,0.00,-0.0003,-0.00020,5.000
5,96.450,0.00,-0.0003,-0.00020,5.000
5,96.550,0.00,-0.0003,-0.00020,5.000
5,96.650,0.00,-0.0003,-0.00020,5.000
5,96.750,0.00,-0.0003,-0.00020,5.000
5,96.850,0.00,-0.0003,-0.00020,5.000
5,96.950,0.00,-0.0003,-0.00020,5.000
5,97.050,0.00,-0.0003,-0.00020,5.000
5,97.150,0.00,-0.0003,-0.00020,5.000
5,97.250,0.00,-0.0003,-0.00020,5.000
5,97.350,0.00,-0.0003,-0.00020,5.000
5,97.450,0.00,-0.0003,-0.00020,5.000
5,97.550,0.00,-0.0003,-0.00020,5.000
5,97.650,0.00,-0.0003,-0.00020,5.000
5,97.750,0.00,-0.0003,-0.00020,5.000
5,97.850,0.00,-0.0003,-0.00020,5.000
5,97.950,-0.01,-0.0002,-0.00010,5.000
5,98.050,0.00,-0.0002,-0.00010,5.000
5,98.150,0.00,-0.0002,-0.00010,5.000
5,98.250,0.00,-0.0002,-0.00010,5.000
5,98.350,0.00,-0.0002,-0.00010,5.000
5,98.450,0.00,-0.0002,-0.00010,5.000
5,98.550,0.00,-0.0002,-0.00010,5.000
5,98.650,0.00,-0.0002,-0.00010,5.000
5,98.750,0.00,-0.0002,-0.00010,5.000
5,98.900,0.00,-0.0002,-0.00010,5.000
5,99.000,0.00,-0.0002,-0.00010,5.000
5,99.100,-0.01,-0.0002,-0.00010,5.000
5,99.200,0.00,-0.0002,-0.00010,5.000
5,99.300,0.00,-0.0002,-0.00010,5.000
5,99.400,0.00,-0.0002,-0.00010,5.000
5,99.500,-0.01,-0.0002,-0.00010,5.000
5,99.600,0.00,-0.0002,-0.00010,5.000
5,99.700,0.00,-0.0002,-0.00010,5.000
5,99.750,0.00,-0.0002,-0.00010,5.000