File: calibDATA_loadcell/date_02:15:2018/Instron_02.15.2018/1_1N_3_1mm.s_0_0.txt
""
"Test Method","Radhen_Load_Cntrl_Cmprsn_250N_12-7.msm"
"Sample I. D.","Sample1.mss"
"Specimen Number","10"

"TheCycle_Output ()","_Time (s)","_Load (N)","_Extension (mm)","RealTimeDepth (mm)","CycleNumber ()"

1,0.267,0.01,0.0572,0.05720,1.000
1,0.333,0.01,0.1239,0.12387,1.000
1,0.400,0.01,0.1907,0.19070,1.000
1,0.467,0.01,0.2574,0.25737,1.000
1,0.533,0.01,0.3240,0.32403,1.000
1,0.600,0.01,0.3909,0.39090,1.000
1,0.667,0.01,0.4574,0.45737,1.000
1,0.733,0.01,0.5240,0.52400,1.000
1,0.800,0.00,0.5909,0.59090,1.000
1,0.867,0.00,0.6574,0.65743,1.000
1,0.933,0.01,0.7240,0.72403,1.000
1,1.000,0.01,0.7910,0.79100,1.000
1,1.067,0.01,0.8575,0.85753,1.000
1,1.133,0.00,0.9240,0.92403,1.000
1,1.200,0.01,0.9908,0.99080,1.000
1,1.267,0.01,1.0574,1.05737,1.000
1,1.333,0.01,1.1241,1.12407,1.000
1,1.400,0.01,1.1907,1.19070,1.000
1,1.467,0.01,1.2573,1.25733,1.000
1,1.533,0.01,1.3240,1.32403,1.000
1,1.600,0.00,1.3909,1.39090,1.000
1,1.667,0.01,1.4574,1.45743,1.000
1,1.733,0.01,1.5241,1.52407,1.000
1,1.800,0.01,1.5909,1.59090,1.000
1,1.867,0.02,1.6575,1.65747,1.000
1,1.933,0.05,1.7242,1.72417,1.000
1,2.000,0.09,1.7909,1.79090,1.000
1,2.067,0.17,1.8574,1.85740,1.000
1,2.133,0.28,1.9241,1.92413,1.000
1,2.200,0.42,1.9910,1.99100,1.000
1,2.267,0.60,2.0575,2.05753,1.000
1,2.333,0.80,2.1243,2.12427,1.000
1,2.400,1.03,2.1909,2.19090,1.000
1,2.533,1.03,2.1781,2.17813,1.000
1,2.600,0.75,2.1117,2.11170,1.000
1,2.667,0.54,2.0449,2.04487,1.000
1,2.733,0.35,1.9782,1.97823,1.000
1,2.800,0.22,1.9116,1.91160,1.000
1,2.867,0.12,1.8448,1.84477,1.000
1,2.933,0.05,1.7782,1.77820,1.000
1,3.000,0.03,1.7117,1.71170,1.000
1,3.067,0.01,1.6448,1.64483,1.000
1,3.133,0.01,1.5782,1.57817,1.000
1,3.200,0.01,1.5116,1.51160,1.000
1,3.267,0.01,1.4448,1.44480,1.000
1,3.333,0.01,1.3783,1.37830,1.000
1,3.400,0.01,1.3116,1.31160,1.000
1,3.467,0.01,1.2447,1.24473,1.000
1,3.533,0.01,1.1782,1.17817,1.000
1,3.600,0.00,1.1116,1.11160,1.000
1,3.667,0.01,1.0447,1.04470,1.000
1,3.733,0.01,0.9781,0.97810,1.000
1,3.800,0.01,0.9116,0.91160,1.000
1,3.867,0.01,0.8448,0.84480,1.000
1,3.933,0.01,0.7782,0.77820,1.000
1,4.000,0.01,0.7115,0.71150,1.000
1,4.067,0.01,0.6448,0.64477,1.000
1,4.133,0.01,0.5781,0.57810,1.000
1,4.200,0.01,0.5115,0.51150,1.000
1,4.267,0.01,0.4447,0.44470,1.000
1,4.333,0.01,0.3782,0.37817,1.000
1,4.400,0.01,0.3115,0.31150,1.000
1,4.467,0.01,0.2447,0.24470,1.000
1,4.533,0.01,0.1781,0.17807,1.000
1,4.600,0.01,0.1114,0.11140,1.000
1,4.667,0.01,0.0446,0.04460,1.000
1,4.867,0.01,-0.0001,-0.00013,1.000
1,4.933,0.01,-0.0002,-0.00020,1.000
1,5.000,0.01,-0.0002,-0.00020,1.000
1,5.067,0.01,-0.0002,-0.00020,1.000
1,5.133,0.01,-0.0002,-0.00020,1.000
1,5.200,0.01,-0.0002,-0.00020,1.000
1,5.267,0.01,-0.0002,-0.00020,1.000
1,5.333,0.00,-0.0002,-0.00020,1.000
1,5.400,0.01,-0.0002,-0.00020,1.000
1,5.467,0.01,-0.0002,-0.00020,1.000
1,5.533,0.00,-0.0002,-0.00020,1.000
1,5.600,0.00,-0.0002,-0.00020,1.000
1,5.667,0.01,-0.0002,-0.00020,1.000
1,5.733,0.01,-0.0002,-0.00020,1.000
1,5.800,0.01,-0.0002,-0.00020,1.000
1,5.867,0.01,-0.0002,-0.00020,1.000
1,5.933,0.01,-0.0002,-0.00020,1.000
1,6.000,0.00,-0.0002,-0.00020,1.000
1,6.067,0.01,-0.0002,-0.00020,1.000
1,6.133,0.00,-0.0002,-0.00020,1.000
1,6.200,0.01,-0.0001,-0.00010,1.000
1,6.267,0.00,-0.0001,-0.00010,1.000
1,6.333,0.01,-0.0001,-0.00010,1.000
1,6.400,0.00,-0.0001,-0.00010,1.000
1,6.467,0.01,-0.0001,-0.00010,1.000
1,6.533,0.01,-0.0001,-0.00010,1.000
1,6.600,0.01,-0.0001,-0.00010,1.000
1,6.667,0.01,-0.0001,-0.00010,1.000
1,6.733,0.01,-0.0001,-0.00010,1.000
1,6.800,0.00,-0.0001,-0.00010,1.000
1,6.867,0.01,-0.0001,-0.00010,1.000
1,6.933,0.01,-0.0001,-0.00010,1.000
1,7.000,0.00,-0.0001,-0.00010,1.000
1,7.067,0.01,-0.0001,-0.00010,1.000
1,7.133,0.01,-0.0001,-0.00010,1.000
1,7.200,0.01,-0.0001,-0.00010,1.000
1,7.267,0.01,-0.0001,-0.00010,1.000
1,7.333,0.00,-0.0001,-0.00010,1.000
1,7.400,0.01,-0.0001,-0.00010,1.000
1,7.467,0.00,-0.0001,-0.00010,1.000
1,7.533,0.00,-0.0001,-0.00010,1.000
1,7.600,0.00,-0.0001,-0.00010,1.000
1,7.667,0.00,-0.0001,-0.00010,1.000
1,7.733,0.00,-0.0001,-0.00010,1.000
1,7.800,0.01,-0.0001,-0.00010,1.000
1,7.933,0.01,-0.0001,-0.00010,1.000
1,8.000,0.00,-0.0001,-0.00010,1.000
1,8.067,0.01,-0.0001,-0.00010,1.000
1,8.133,0.00,-0.0001,-0.00010,1.000
1,8.200,0.01,-0.0001,-0.00010,1.000
1,8.267,0.01,-0.0001,-0.00010,1.000
1,8.333,0.00,-0.0001,-0.00010,1.000
1,8.400,0.00,-0.0001,-0.00010,1.000
1,8.467,0.00,-0.0001,-0.00010,1.000
1,8.533,0.00,-0.0001,-0.00010,1.000
1,8.600,0.00,-0.0001,-0.00010,1.000
1,8.667,0.00,-0.0001,-0.00010,1.000
1,8.733,0.00,-0.0001,-0.00010,1.000
1,8.800,0.01,-0.0001,-0.00010,1.000
2,9.000,0.00,0.0507,0.05070,2.000
2,9.067,0.00,0.1173,0.11727,2.000
2,9.133,0.00,0.1840,0.18400,2.000
2,9.200,0.00,0.2507,0.25070,2.000
2,9.267,0.00,0.3174,0.31737,2.000
2,9.333,0.00,0.3841,0.38410,2.000
2,9.400,0.00,0.4506,0.45060,2.000
2,9.467,0.00,0.5174,0.51737,2.000
2,9.533,0.00,0.5841,0.58407,2.000
2,9.600,0.00,0.6507,0.65070,2.000
2,9.667,0.00,0.7175,0.71747,2.000
2,9.733,0.00,0.7842,0.78423,2.000
2,9.800,0.00,0.8507,0.85070,2.000
2,9.867,0.00,0.9175,0.91750,2.000
2,9.933,0.00,0.9840,0.98403,2.000
2,10.000,0.00,1.0507,1.05070,2.000
2,10.067,0.00,1.1175,1.11747,2.000
2,10.133,0.00,1.1841,1.18410,2.000
2,10.200,0.00,1.2506,1.25060,2.000
2,10.267,0.00,1.3174,1.31740,2.000
2,10.333,0.00,1.3842,1.38417,2.000
2,10.400,0.00,1.4506,1.45060,2.000
2,10.467,0.00,1.5175,1.51747,2.000
2,10.533,0.00,1.5841,1.58413,2.000
2,10.600,0.01,1.6507,1.65070,2.000
2,10.667,0.04,1.7176,1.71757,2.000
2,10.733,0.08,1.7841,1.78413,2.000
2,10.800,0.15,1.8506,1.85060,2.000
2,10.867,0.26,1.9175,1.91747,2.000
2,10.933,0.39,1.9842,1.98417,2.000
2,11.000,0.57,2.0508,2.05080,2.000
2,11.067,0.77,2.1176,2.11763,2.000
2,11.133,1.00,2.1843,2.18427,2.000
2,11.267,1.06,2.1848,2.18483,2.000
2,11.333,0.77,2.1183,2.11827,2.000
2,11.400,0.54,2.0515,2.05150,2.000
2,11.467,0.36,1.9849,1.98490,2.000
2,11.533,0.22,1.9182,1.91820,2.000
2,11.600,0.12,1.8513,1.85130,2.000
2,11.667,0.05,1.7849,1.78487,2.000
2,11.733,0.02,1.7183,1.71827,2.000
2,11.800,0.01,1.6515,1.65150,2.000
2,11.867,0.00,1.5849,1.58493,2.000
2,11.933,0.00,1.5182,1.51817,2.000
2,12.000,0.00,1.4513,1.45130,2.000
2,12.067,0.00,1.3849,1.38490,2.000
2,12.133,0.00,1.3182,1.31817,2.000
2,12.200,0.00,1.2513,1.25130,2.000
2,12.267,0.00,1.1849,1.18487,2.000
2,12.333,0.00,1.1181,1.11807,2.000
2,12.400,0.00,1.0512,1.05120,2.000
2,12.467,0.00,0.9848,0.98480,2.000
2,12.533,0.00,0.9181,0.91807,2.000
2,12.600,0.00,0.8514,0.85140,2.000
2,12.667,0.00,0.7849,0.78493,2.000
2,12.733,0.00,0.7182,0.71817,2.000
2,12.800,0.00,0.6515,0.65150,2.000
2,12.867,0.00,0.5848,0.58483,2.000
2,12.933,0.00,0.5181,0.51810,2.000
2,13.000,0.00,0.4515,0.45150,2.000
2,13.067,0.00,0.3848,0.38483,2.000
2,13.133,0.00,0.3180,0.31800,2.000
2,13.200,0.00,0.2513,0.25130,2.000
2,13.267,0.00,0.1847,0.18473,2.000
2,13.333,0.00,0.1180,0.11797,2.000
2,13.400,0.00,0.0514,0.05140,2.000
2,13.467,0.00,-0.0152,-0.01520,2.000
2,13.600,0.00,-0.0006,-0.00060,2.000
2,13.667,0.00,-0.0002,-0.00020,2.000
2,13.733,0.00,-0.0002,-0.00020,2.000
2,13.800,0.00,-0.0002,-0.00020,2.000
2,13.867,0.00,-0.0002,-0.00020,2.000
2,13.933,0.00,-0.0002,-0.00020,2.000
2,14.000,0.00,-0.0002,-0.00020,2.000
2,14.067,0.00,-0.0002,-0.00020,2.000
2,14.133,0.00,-0.0002,-0.00020,2.000
2,14.200,0.00,-0.0002,-0.00020,2.000
2,14.267,0.00,-0.0002,-0.00020,2.000
2,14.333,0.00,-0.0002,-0.00020,2.000
2,14.400,0.00,-0.0002,-0.00020,2.000
2,14.467,0.00,-0.0002,-0.00020,2.000
2,14.533,0.00,-0.0002,-0.00020,2.000
2,14.600,0.00,-0.0002,-0.00020,2.000
2,14.667,0.00,-0.0002,-0.00020,2.000
2,14.733,0.00,-0.0002,-0.00020,2.000
2,14.800,0.00,-0.0002,-0.00020,2.000
2,14.867,0.00,-0.0002,-0.00020,2.000
2,14.933,0.00,-0.0002,-0.00020,2.000
2,15.000,0.00,-0.0002,-0.00020,2.000
2,15.067,0.00,-0.0001,-0.00010,2.000
2,15.133,0.00,-0.0001,-0.00010,2.000
2,15.200,0.00,-0.0001,-0.00010,2.000
2,15.267,0.00,-0.0001,-0.00010,2.000
2,15.333,0.00,-0.0001,-0.00010,2.000
2,15.400,0.00,-0.0001,-0.00010,2.000
2,15.467,0.00,-0.0001,-0.00010,2.000
2,15.533,0.00,-0.0001,-0.00010,2.000
2,15.600,0.00,-0.0001,-0.00010,2.000
2,15.667,0.00,-0.0001,-0.00010,2.000
2,15.733,0.00,-0.0001,-0.00010,2.000
2,15.800,0.00,-0.0001,-0.00010,2.000
2,15.867,0.00,-0.0001,-0.00010,2.000
2,15.933,0.00,-0.0001,-0.00010,2.000
2,16.000,0.00,-0.0001,-0.00010,2.000
2,16.067,0.00,-0.0001,-0.00010,2.000
2,16.133,0.00,-0.0001,-0.00010,2.000
2,16.200,0.00,-0.0001,-0.00010,2.000
2,16.267,0.00,-0.0001,-0.00010,2.000
2,16.333,0.00,-0.0001,-0.00010,2.000
2,16.400,0.00,-0.0001,-0.00010,2.000
2,16.467,0.00,-0.0001,-0.00010,2.000
2,16.533,0.00,-0.0001,-0.00010,2.000
2,16.667,0.00,-0.0001,-0.00010,2.000
2,16.733,0.00,-0.0001,-0.00010,2.000
2,16.800,-0.01,-0.0001,-0.00010,2.000
2,16.867,0.00,-0.0001,-0.00010,2.000
2,16.933,0.00,-0.0001,-0.00010,2.000
2,17.000,0.00,-0.0001,-0.00010,2.000
2,17.067,0.00,-0.0001,-0.00010,2.000
2,17.133,0.00,-0.0001,-0.00010,2.000
2,17.200,0.00,-0.0001,-0.00010,2.000
2,17.267,0.00,-0.0001,-0.00010,2.000
2,17.333,0.00,-0.0001,-0.00010,2.000
2,17.400,0.00,-0.0001,-0.00010,2.000
2,17.467,0.00,-0.0001,-0.00010,2.000
2,17.533,0.00,-0.0001,-0.00010,2.000
3,17.800,0.00,0.1006,0.10060,3.000
3,17.867,0.00,0.1672,0.16723,3.000
3,17.933,0.01,0.2340,0.23403,3.000
3,18.000,0.00,0.3007,0.30070,3.000
3,18.067,0.00,0.3674,0.36740,3.000
3,18.133,0.00,0.4341,0.43413,3.000
3,18.200,0.01,0.5007,0.50070,3.000
3,18.267,0.00,0.5673,0.56727,3.000
3,18.333,0.00,0.6341,0.63407,3.000
3,18.400,0.00,0.7008,0.70080,3.000
3,18.467,0.00,0.7674,0.76740,3.000
3,18.533,0.00,0.8342,0.83423,3.000
3,18.600,0.01,0.9009,0.90090,3.000
3,18.667,0.00,0.9674,0.96737,3.000
3,18.733,0.00,1.0341,1.03413,3.000
3,18.800,0.01,1.1007,1.10070,3.000
3,18.867,0.01,1.1673,1.16730,3.000
3,18.933,0.00,1.2341,1.23407,3.000
3,19.000,0.00,1.3008,1.30080,3.000
3,19.067,0.00,1.3674,1.36743,3.000
3,19.133,0.00,1.4341,1.43413,3.000
3,19.200,0.00,1.5008,1.50080,3.000
3,19.267,0.00,1.5674,1.56743,3.000
3,19.333,0.01,1.6343,1.63427,3.000
3,19.400,0.04,1.7009,1.70090,3.000
3,19.467,0.07,1.7674,1.76737,3.000
3,19.533,0.13,1.8341,1.83407,3.000
3,19.600,0.23,1.9008,1.90080,3.000
3,19.667,0.36,1.9674,1.96743,3.000
3,19.733,0.53,2.0342,2.03420,3.000
3,19.800,0.72,2.1009,2.10090,3.000
3,19.867,0.95,2.1675,2.16750,3.000
3,20.000,1.26,2.2276,2.22760,3.000
3,20.067,0.94,2.1608,2.16083,3.000
3,20.133,0.69,2.0941,2.09413,3.000
3,20.200,0.48,2.0277,2.02770,3.000
3,20.267,0.31,1.9609,1.96087,3.000
3,20.333,0.19,1.8941,1.89407,3.000
3,20.400,0.09,1.8276,1.82760,3.000
3,20.467,0.04,1.7609,1.76087,3.000
3,20.533,0.02,1.6942,1.69417,3.000
3,20.600,0.01,1.6277,1.62770,3.000
3,20.667,0.01,1.5608,1.56080,3.000
3,20.733,0.01,1.4941,1.49413,3.000
3,20.800,0.01,1.4276,1.42760,3.000
3,20.867,0.01,1.3608,1.36083,3.000
3,20.933,0.00,1.2941,1.29407,3.000
3,21.000,0.01,1.2274,1.22740,3.000
3,21.067,0.00,1.1607,1.16073,3.000
3,21.133,0.00,1.0941,1.09410,3.000
3,21.200,0.01,1.0274,1.02740,3.000
3,21.267,0.00,0.9607,0.96067,3.000
3,21.333,0.00,0.8941,0.89410,3.000
3,21.400,0.00,0.8275,0.82750,3.000
3,21.467,0.00,0.7609,0.76087,3.000
3,21.533,0.01,0.6941,0.69413,3.000
3,21.600,0.00,0.6275,0.62750,3.000
3,21.667,0.00,0.5607,0.56070,3.000
3,21.733,0.00,0.4941,0.49410,3.000
3,21.800,0.00,0.4276,0.42760,3.000
3,21.867,0.01,0.3608,0.36077,3.000
3,21.933,0.00,0.2941,0.29410,3.000
3,22.000,0.01,0.2274,0.22740,3.000
3,22.067,0.00,0.1607,0.16067,3.000
3,22.133,0.00,0.0940,0.09400,3.000
3,22.200,0.00,0.0275,0.02750,3.000
3,22.333,0.01,-0.0392,-0.03923,3.000
3,22.400,0.00,-0.0002,-0.00020,3.000
3,22.467,0.00,-0.0002,-0.00020,3.000
3,22.533,0.00,-0.0002,-0.00020,3.000
3,22.600,0.00,-0.0002,-0.00020,3.000
3,22.667,0.00,-0.0002,-0.00020,3.000
3,22.733,0.00,-0.0002,-0.00020,3.000
3,22.800,0.00,-0.0002,-0.00020,3.000
3,22.867,0.00,-0.0002,-0.00020,3.000
3,22.933,0.01,-0.0002,-0.00020,3.000
3,23.000,0.00,-0.0002,-0.00020,3.000
3,23.067,0.00,-0.0002,-0.00020,3.000
3,23.133,0.00,-0.0002,-0.00020,3.000
3,23.200,0.00,-0.0002,-0.00020,3.000
3,23.267,0.01,-0.0002,-0.00020,3.000
3,23.333,0.01,-0.0002,-0.00020,3.000
3,23.400,0.01,-0.0002,-0.00020,3.000
3,23.467,0.01,-0.0002,-0.00020,3.000
3,23.533,0.01,-0.0002,-0.00020,3.000
3,23.600,0.01,-0.0002,-0.00020,3.000
3,23.667,0.01,-0.0002,-0.00020,3.000
3,23.733,0.00,-0.0002,-0.00020,3.000
3,23.800,0.00,-0.0002,-0.00020,3.000
3,23.867,0.01,-0.0001,-0.00010,3.000
3,23.933,0.00,-0.0001,-0.00010,3.000
3,24.000,0.01,-0.0001,-0.00010,3.000
3,24.067,0.01,-0.0001,-0.00010,3.000
3,24.133,0.01,-0.0001,-0.00010,3.000
3,24.200,0.01,-0.0001,-0.00010,3.000
3,24.267,0.00,-0.0001,-0.00010,3.000
3,24.333,0.00,-0.0001,-0.00010,3.000
3,24.400,0.01,-0.0001,-0.00010,3.000
3,24.467,0.01,-0.0001,-0.00010,3.000
3,24.533,0.01,-0.0001,-0.00010,3.000
3,24.600,0.01,-0.0001,-0.00010,3.000
3,24.667,0.00,-0.0001,-0.00010,3.000
3,24.733,0.00,-0.0001,-0.00010,3.000
3,24.800,0.01,-0.0001,-0.00010,3.000
3,24.867,0.00,-0.0001,-0.00010,3.000
3,24.933,0.00,-0.0001,-0.00010,3.000
3,25.000,0.01,-0.0001,-0.00010,3.000
3,25.067,0.00,-0.0001,-0.00010,3.000
3,25.133,0.00,-0.0001,-0.00010,3.000
3,25.200,0.01,-0.0001,-0.00010,3.000
3,25.267,0.00,-0.0001,-0.00010,3.000
3,25.467,0.01,-0.0001,-0.00010,3.000
3,25.533,0.00,-0.0001,-0.00010,3.000
3,25.600,0.00,-0.0001,-0.00010,3.000
3,25.667,0.00,-0.0001,-0.00010,3.000
3,25.733,0.00,-0.0001,-0.00010,3.000
3,25.800,0.01,-0.0001,-0.00010,3.000
3,25.867,0.00,-0.0001,-0.00010,3.000
3,25.933,0.01,-0.0001,-0.00010,3.000
3,26.000,0.01,-0.0001,-0.00010,3.000
3,26.067,0.00,-0.0001,-0.00010,3.000
3,26.133,0.00,-0.0001,-0.00010,3.000
3,26.200,0.01,-0.0001,-0.00010,3.000
3,26.267,0.00,-0.0001,-0.00010,3.000
3,26.333,0.00,-0.0001,-0.00010,3.000
4,26.533,0.00,0.0630,0.06300,4.000
4,26.600,0.00,0.1296,0.12960,4.000
4,26.667,-0.01,0.1964,0.19640,4.000
4,26.733,0.00,0.2631,0.26313,4.000
4,26.800,-0.01,0.3297,0.32970,4.000
4,26.867,0.00,0.3964,0.39643,4.000
4,26.933,-0.01,0.4631,0.46310,4.000
4,27.000,-0.01,0.5297,0.52970,4.000
4,27.067,-0.01,0.5964,0.59640,4.000
4,27.133,-0.01,0.6631,0.66310,4.000
4,27.200,0.00,0.7296,0.72960,4.000
4,27.267,-0.01,0.7965,0.79650,4.000
4,27.333,-0.01,0.8632,0.86320,4.000
4,27.400,-0.01,0.9296,0.92960,4.000
4,27.467,0.00,0.9964,0.99640,4.000
4,27.533,0.00,1.0631,1.06307,4.000
4,27.600,-0.01,1.1297,1.12970,4.000
4,27.667,-0.01,1.1964,1.19643,4.000
4,27.733,0.00,1.2631,1.26310,4.000
4,27.800,0.00,1.3297,1.32970,4.000
4,27.867,-0.01,1.3966,1.39657,4.000
4,27.933,-0.01,1.4631,1.46313,4.000
4,28.000,0.00,1.5297,1.52970,4.000
4,28.067,0.00,1.5965,1.59650,4.000
4,28.133,0.01,1.6632,1.66317,4.000
4,28.200,0.04,1.7297,1.72970,4.000
4,28.267,0.08,1.7965,1.79647,4.000
4,28.333,0.16,1.8631,1.86313,4.000
4,28.400,0.28,1.9297,1.92970,4.000
4,28.467,0.42,1.9966,1.99660,4.000
4,28.533,0.60,2.0632,2.06320,4.000
4,28.600,0.81,2.1298,2.12980,4.000
4,28.667,1.05,2.1966,2.19663,4.000
4,28.800,1.07,2.1904,2.19040,4.000
4,28.867,0.79,2.1239,2.12387,4.000
4,28.933,0.56,2.0572,2.05717,4.000
4,29.000,0.37,1.9907,1.99070,4.000
4,29.067,0.22,1.9239,1.92387,4.000
4,29.133,0.12,1.8570,1.85703,4.000
4,29.200,0.05,1.7905,1.79050,4.000
4,29.267,0.02,1.7239,1.72390,4.000
4,29.333,0.00,1.6572,1.65723,4.000
4,29.400,-0.01,1.5906,1.59060,4.000
4,29.467,-0.01,1.5237,1.52373,4.000
4,29.533,-0.01,1.4571,1.45710,4.000
4,29.600,0.00,1.3907,1.39070,4.000
4,29.667,0.00,1.3238,1.32380,4.000
4,29.733,0.00,1.2571,1.25713,4.000
4,29.800,-0.01,1.1905,1.19050,4.000
4,29.867,-0.01,1.1237,1.12370,4.000
4,29.933,-0.01,1.0571,1.05707,4.000
4,30.000,-0.01,0.9904,0.99040,4.000
4,30.067,-0.01,0.9237,0.92373,4.000
4,30.133,0.00,0.8572,0.85720,4.000
4,30.200,-0.01,0.7905,0.79050,4.000
4,30.267,0.00,0.7238,0.72383,4.000
4,30.333,-0.01,0.6571,0.65713,4.000
4,30.400,0.00,0.5905,0.59050,4.000
4,30.467,-0.01,0.5236,0.52363,4.000
4,30.533,-0.01,0.4571,0.45707,4.000
4,30.600,-0.01,0.3904,0.39040,4.000
4,30.667,-0.01,0.3237,0.32370,4.000
4,30.733,-0.01,0.2570,0.25703,4.000
4,30.800,0.00,0.1905,0.19050,4.000
4,30.867,-0.01,0.1237,0.12367,4.000
4,30.933,-0.01,0.0570,0.05703,4.000
4,31.000,0.00,-0.0095,-0.00950,4.000
4,31.133,0.00,-0.0147,-0.01470,4.000
4,31.200,-0.01,-0.0002,-0.00020,4.000
4,31.267,-0.01,-0.0002,-0.00020,4.000
4,31.333,-0.01,-0.0002,-0.00020,4.000
4,31.400,-0.01,-0.0002,-0.00020,4.000
4,31.467,0.00,-0.0002,-0.00020,4.000
4,31.533,-0.01,-0.0002,-0.00020,4.000
4,31.600,-0.01,-0.0002,-0.00020,4.000
4,31.667,-0.01,-0.0002,-0.00020,4.000
4,31.733,-0.01,-0.0002,-0.00020,4.000
4,31.800,-0.01,-0.0002,-0.00020,4.000
4,31.867,-0.01,-0.0002,-0.00020,4.000
4,31.933,-0.01,-0.0002,-0.00020,4.000
4,32.000,-0.01,-0.0002,-0.00020,4.000
4,32.067,0.00,-0.0002,-0.00020,4.000
4,32.133,0.00,-0.0002,-0.00020,4.000
4,32.200,-0.01,-0.0002,-0.00020,4.000
4,32.267,-0.01,-0.0002,-0.00020,4.000
4,32.333,-0.01,-0.0002,-0.00020,4.000
4,32.400,0.00,-0.0002,-0.00020,4.000
4,32.467,-0.01,-0.0002,-0.00020,4.000
4,32.533,-0.01,-0.0002,-0.00020,4.000
4,32.600,-0.01,-0.0002,-0.00020,4.000
4,32.667,-0.01,-0.0002,-0.00020,4.000
4,32.733,-0.01,-0.0001,-0.00010,4.000
4,32.800,-0.01,-0.0001,-0.00010,4.000
4,32.867,-0.01,-0.0001,-0.00010,4.000
4,32.933,-0.01,-0.0001,-0.00010,4.000
4,33.000,0.00,-0.0001,-0.00010,4.000
4,33.067,-0.01,-0.0001,-0.00010,4.000
4,33.133,0.00,-0.0001,-0.00010,4.000
4,33.200,-0.01,-0.0001,-0.00010,4.000
4,33.267,0.00,-0.0001,-0.00010,4.000
4,33.333,0.00,-0.0001,-0.00010,4.000
4,33.400,0.00,-0.0001,-0.00010,4.000
4,33.467,-0.01,-0.0001,-0.00010,4.000
4,33.533,-0.01,-0.0001,-0.00010,4.000
4,33.600,-0.01,-0.0001,-0.00010,4.000
4,33.667,0.00,-0.0001,-0.00010,4.000
4,33.733,0.00,-0.0001,-0.00010,4.000
4,33.800,0.00,-0.0001,-0.00010,4.000
4,33.867,-0.01,-0.0001,-0.00010,4.000
4,33.933,-0.01,-0.0001,-0.00010,4.000
4,34.000,-0.01,-0.0001,-0.00010,4.000
4,34.067,-0.01,-0.0001,-0.00010,4.000
4,34.200,-0.01,-0.0001,-0.00010,4.000
4,34.267,-0.01,-0.0001,-0.00010,4.000
4,34.333,-0.01,-0.0001,-0.00010,4.000
4,34.400,0.00,-0.0001,-0.00010,4.000
4,34.467,0.00,-0.0001,-0.00010,4.000
4,34.533,0.00,-0.0001,-0.00010,4.000
4,34.600,-0.01,-0.0001,-0.00010,4.000
4,34.667,0.00,-0.0001,-0.00010,4.000
4,34.733,0.00,-0.0001,-0.00010,4.000
4,34.800,0.00,-0.0001,-0.00010,4.000
4,34.867,0.00,-0.0001,-0.00010,4.000
4,34.933,-0.01,-0.0001,-0.00010,4.000
4,35.000,0.00,-0.0001,-0.00010,4.000
4,35.067,0.00,-0.0001,-0.00010,4.000
5,35.333,-0.01,0.0730,0.07303,5.000
5,35.400,0.00,0.1396,0.13960,5.000
5,35.467,0.00,0.2063,0.20627,5.000
5,35.533,0.00,0.2732,0.27317,5.000
5,35.600,0.00,0.3397,0.33970,5.000
5,35.667,-0.01,0.4064,0.40637,5.000
5,35.733,0.00,0.4731,0.47310,5.000
5,35.800,0.00,0.5398,0.53980,5.000
5,35.867,0.00,0.6063,0.60630,5.000
5,35.933,0.00,0.6732,0.67317,5.000
5,36.000,-0.01,0.7397,0.73970,5.000
5,36.067,0.00,0.8065,0.80647,5.000
5,36.133,0.00,0.8732,0.87323,5.000
5,36.200,0.00,0.9398,0.93980,5.000
5,36.267,0.00,1.0063,1.00630,5.000
5,36.333,0.00,1.0731,1.07310,5.000
5,36.400,0.00,1.1397,1.13970,5.000
5,36.467,0.00,1.2064,1.20637,5.000
5,36.533,0.00,1.2731,1.27313,5.000
5,36.600,0.00,1.3398,1.33980,5.000
5,36.667,0.00,1.4064,1.40640,5.000
5,36.733,0.00,1.4731,1.47313,5.000
5,36.800,0.00,1.5397,1.53970,5.000
5,36.867,0.00,1.6065,1.60647,5.000
5,36.933,0.02,1.6732,1.67323,5.000
5,37.000,0.05,1.7399,1.73990,5.000
5,37.067,0.09,1.8064,1.80640,5.000
5,37.133,0.18,1.8731,1.87313,5.000
5,37.200,0.30,1.9397,1.93970,5.000
5,37.267,0.45,2.0065,2.00647,5.000
5,37.333,0.63,2.0733,2.07327,5.000
5,37.400,0.85,2.1399,2.13990,5.000
5,37.600,0.97,2.1664,2.16640,5.000
5,37.667,0.70,2.0998,2.09983,5.000
5,37.733,0.49,2.0333,2.03327,5.000
5,37.800,0.32,1.9665,1.96650,5.000
5,37.867,0.19,1.8998,1.89980,5.000
5,37.933,0.09,1.8332,1.83320,5.000
5,38.000,0.04,1.7665,1.76650,5.000
5,38.067,0.01,1.6999,1.69987,5.000
5,38.133,0.00,1.6333,1.63327,5.000
5,38.200,0.00,1.5664,1.56640,5.000
5,38.267,0.00,1.4998,1.49977,5.000
5,38.333,0.00,1.4333,1.43330,5.000
5,38.400,0.00,1.3665,1.36650,5.000
5,38.467,0.00,1.2998,1.29977,5.000
5,38.533,0.00,1.2331,1.23313,5.000
5,38.600,0.00,1.1664,1.16640,5.000
5,38.667,0.00,1.0998,1.09983,5.000
5,38.733,0.00,1.0331,1.03307,5.000
5,38.800,-0.01,0.9664,0.96640,5.000
5,38.867,0.00,0.8998,0.89980,5.000
5,38.933,0.00,0.8333,0.83327,5.000
5,39.000,-0.01,0.7665,0.76650,5.000
5,39.067,-0.01,0.6998,0.69980,5.000
5,39.133,0.00,0.6332,0.63317,5.000
5,39.200,0.00,0.5663,0.56630,5.000
5,39.267,0.00,0.4998,0.49977,5.000
5,39.333,-0.01,0.4332,0.43320,5.000
5,39.400,0.00,0.3663,0.36630,5.000
5,39.467,0.00,0.2998,0.29977,5.000
5,39.533,-0.01,0.2331,0.23307,5.000
5,39.600,-0.01,0.1664,0.16640,5.000
5,39.667,0.00,0.0997,0.09970,5.000
5,39.733,0.00,0.0331,0.03307,5.000
5,39.867,0.00,-0.0274,-0.02737,5.000
5,39.933,0.00,-0.0002,-0.00020,5.000
5,40.000,-0.01,-0.0002,-0.00020,5.000
5,40.067,0.00,-0.0001,-0.00010,5.000
5,40.133,-0.01,-0.0001,-0.00010,5.000
5,40.200,0.00,-0.0001,-0.00010,5.000
5,40.267,0.00,-0.0001,-0.00010,5.000
5,40.333,-0.01,-0.0001,-0.00010,5.000
5,40.400,0.00,-0.0001,-0.00010,5.000
5,40.467,0.00,-0.0001,-0.00010,5.000
5,40.533,0.00,-0.0001,-0.00010,5.000
5,40.600,0.00,-0.0001,-0.00010,5.000
5,40.667,0.00,-0.0001,-0.00010,5.000
5,40.733,0.00,-0.0001,-0.00010,5.000
5,40.800,-0.01,-0.0001,-0.00010,5.000
5,40.867,0.00,-0.0001,-0.00010,5.000
5,40.933,0.00,-0.0001,-0.00010,5.000
5,41.000,-0.01,-0.0001,-0.00010,5.000
5,41.067,-0.01,-0.0001,-0.00010,5.000
5,41.133,0.00,-0.0001,-0.00010,5.000
5,41.200,0.00,-0.0001,-0.00010,5.000
5,41.267,0.00,-0.0001,-0.00010,5.000
5,41.333,-0.01,-0.0001,-0.00010,5.000
5,41.400,0.00,-0.0001,-0.00010,5.000
5,41.467,0.00,-0.0001,-0.00010,5.000
5,41.533,-0.01,-0.0001,-0.00010,5.000
5,41.600,0.00,-0.0001,-0.00010,5.000
5,41.667,0.00,-0.0001,-0.00010,5.000
5,41.733,0.00,-0.0001,-0.00010,5.000
5,41.800,0.00,-0.0001,-0.00010,5.000
5,41.867,-0.01,-0.0001,-0.00010,5.000
5,41.933,-0.01,-0.0001,-0.00010,5.000
5,42.000,-0.01,-0.0001,-0.00010,5.000
5,42.067,0.00,-0.0001,-0.00010,5.000
5,42.133,-0.01,-0.0001,-0.00010,5.000
5,42.200,0.00,-0.0001,-0.00010,5.000
5,42.267,0.00,-0.0001,-0.00010,5.000
5,42.333,0.00,-0.0001,-0.00010,5.000
5,42.400,0.00,-0.0001,-0.00010,5.000
5,42.467,0.00,-0.0001,-0.00010,5.000
5,42.533,0.00,-0.0001,-0.00010,5.000
5,42.600,0.00,-0.0001,-0.00010,5.000
5,42.667,0.00,-0.0001,-0.00010,5.000
5,42.733,0.00,-0.0001,-0.00010,5.000
5,42.800,0.00,-0.0001,-0.00010,5.000
5,43.000,-0.01,-0.0001,-0.00010,5.000
5,43.067,0.00,-0.0001,-0.00010,5.000
5,43.133,-0.01,-0.0001,-0.00010,5.000
5,43.200,-0.01,-0.0001,-0.00010,5.000
5,43.267,0.00,-0.0001,-0.00010,5.000
5,43.333,0.00,-0.0001,-0.00010,5.000
5,43.400,0.00,-0.0001,-0.00010,5.000
5,43.467,0.00,-0.0001,-0.00010,5.000
5,43.533,0.00,-0.0001,-0.00010,5.000
5,43.600,0.00,-0.0001,-0.00010,5.000
5,43.667,0.00,-0.0001,-0.00010,5.000
5,43.733,-0.01,-0.0001,-0.00010,5.000
5,43.800,0.00,-0.0001,-0.00010,5.000
5,43.867,-0.01,-0.0001,-0.00010,5.000
6,44.067,0.00,0.0563,0.05627,6.000
6,44.133,0.00,0.1229,0.12290,6.000
6,44.200,0.00,0.1896,0.18960,6.000
6,44.267,0.00,0.2564,0.25640,6.000
6,44.333,0.00,0.3230,0.32303,6.000
6,44.400,0.00,0.3899,0.38990,6.000
6,44.467,0.00,0.4564,0.45637,6.000
6,44.533,0.00,0.5230,0.52300,6.000
6,44.600,0.00,0.5897,0.58970,6.000
6,44.667,0.00,0.6564,0.65640,6.000
6,44.733,0.00,0.7231,0.72310,6.000
6,44.800,0.00,0.7900,0.79000,6.000
6,44.867,0.00,0.8565,0.85650,6.000
6,44.933,0.00,0.9231,0.92307,6.000
6,45.000,0.00,0.9897,0.98970,6.000
6,45.067,0.00,1.0563,1.05633,6.000
6,45.133,0.00,1.1231,1.12307,6.000
6,45.200,0.00,1.1897,1.18970,6.000
6,45.267,0.00,1.2564,1.25637,6.000
6,45.333,0.00,1.3231,1.32310,6.000
6,45.400,0.00,1.3898,1.38980,6.000
6,45.467,0.00,1.4564,1.45637,6.000
6,45.533,0.00,1.5231,1.52310,6.000
6,45.600,0.01,1.5899,1.58990,6.000
6,45.667,0.02,1.6564,1.65643,6.000
6,45.733,0.04,1.7232,1.72317,6.000
6,45.800,0.09,1.7898,1.78980,6.000
6,45.867,0.16,1.8564,1.85637,6.000
6,45.933,0.28,1.9231,1.92313,6.000
6,46.000,0.42,1.9898,1.98980,6.000
6,46.067,0.59,2.0564,2.05643,6.000
6,46.133,0.80,2.1232,2.12317,6.000
6,46.200,1.03,2.1899,2.18990,6.000
6,46.333,1.03,2.1770,2.17697,6.000
6,46.400,0.75,2.1107,2.11070,6.000
6,46.467,0.53,2.0439,2.04387,6.000
6,46.533,0.35,1.9772,1.97720,6.000
6,46.600,0.21,1.9105,1.91050,6.000
6,46.667,0.12,1.8437,1.84373,6.000
6,46.733,0.05,1.7771,1.77710,6.000
6,46.800,0.02,1.7106,1.71060,6.000
6,46.867,0.01,1.6438,1.64383,6.000
6,46.933,0.00,1.5771,1.57713,6.000
6,47.000,0.01,1.5104,1.51040,6.000
6,47.067,0.00,1.4438,1.44377,6.000
6,47.133,0.01,1.3772,1.37717,6.000
6,47.200,0.00,1.3106,1.31060,6.000
6,47.267,0.00,1.2437,1.24367,6.000
6,47.333,0.00,1.1770,1.17703,6.000
6,47.400,0.00,1.1105,1.11050,6.000
6,47.467,0.00,1.0437,1.04367,6.000
6,47.533,0.00,0.9771,0.97710,6.000
6,47.600,0.01,0.9105,0.91050,6.000
6,47.667,0.00,0.8438,0.84380,6.000
6,47.733,0.00,0.7772,0.77720,6.000
6,47.800,0.01,0.7106,0.71060,6.000
6,47.867,0.00,0.6437,0.64373,6.000
6,47.933,0.00,0.5770,0.57703,6.000
6,48.000,0.00,0.5106,0.51060,6.000
6,48.067,0.00,0.4437,0.44370,6.000
6,48.133,0.00,0.3771,0.37710,6.000
6,48.200,0.00,0.3104,0.31040,6.000
6,48.267,0.00,0.2437,0.24370,6.000
6,48.333,0.00,0.1770,0.17700,6.000
6,48.400,0.00,0.1104,0.11040,6.000
6,48.467,0.00,0.0436,0.04360,6.000
6,48.667,0.00,0.0004,0.00040,6.000
6,48.733,0.00,-0.0002,-0.00017,6.000
6,48.800,0.00,-0.0001,-0.00010,6.000
6,48.867,0.00,-0.0001,-0.00010,6.000
6,48.933,0.00,-0.0001,-0.00010,6.000
6,49.000,0.00,-0.0001,-0.00010,6.000
6,49.067,0.00,-0.0001,-0.00010,6.000
6,49.133,0.00,-0.0001,-0.00010,6.000
6,49.200,0.00,-0.0001,-0.00010,6.000
6,49.267,0.00,-0.0001,-0.00010,6.000
6,49.333,0.00,-0.0001,-0.00010,6.000
6,49.400,0.00,-0.0001,-0.00010,6.000
6,49.467,0.00,-0.0001,-0.00010,6.000
6,49.533,0.00,-0.0001,-0.00010,6.000
6,49.600,0.00,-0.0001,-0.00010,6.000
6,49.667,0.00,-0.0001,-0.00010,6.000
6,49.733,0.00,-0.0001,-0.00010,6.000
6,49.800,0.00,-0.0001,-0.00010,6.000
6,49.867,0.00,-0.0001,-0.00010,6.000
6,49.933,0.00,-0.0001,-0.00010,6.000
6,50.000,0.00,-0.0001,-0.00010,6.000
6,50.067,0.01,-0.0001,-0.00010,6.000
6,50.133,0.00,-0.0001,-0.00010,6.000
6,50.200,0.00,-0.0001,-0.00010,6.000
6,50.267,0.00,-0.0001,-0.00010,6.000
6,50.333,0.00,-0.0001,-0.00010,6.000
6,50.400,0.00,-0.0001,-0.00010,6.000
6,50.467,0.00,-0.0001,-0.00010,6.000
6,50.533,0.00,-0.0001,-0.00010,6.000
6,50.600,0.00,-0.0001,-0.00010,6.000
6,50.667,0.00,-0.0001,-0.00010,6.000
6,50.733,0.00,-0.0001,-0.00010,6.000
6,50.800,0.00,-0.0001,-0.00010,6.000
6,50.867,0.00,-0.0001,-0.00010,6.000
6,50.933,0.00,-0.0001,-0.00010,6.000
6,51.000,0.00,-0.0001,-0.00010,6.000
6,51.067,0.00,-0.0001,-0.00010,6.000
6,51.133,0.00,-0.0001,-0.00010,6.000
6,51.200,0.00,-0.0001,-0.00010,6.000
6,51.267,0.00,-0.0001,-0.00010,6.000
6,51.333,0.00,-0.0001,-0.00010,6.000
6,51.400,0.00,-0.0001,-0.00010,6.000
6,51.467,0.00,-0.0001,-0.00010,6.000
6,51.533,0.00,-0.0001,-0.00010,6.000
6,51.600,0.00,-0.0001,-0.00010,6.000
6,51.733,0.00,-0.0001,-0.00010,6.000
6,51.800,0.00,-0.0001,-0.00010,6.000
6,51.867,0.00,-0.0001,-0.00010,6.000
6,51.933,0.00,-0.0001,-0.00010,6.000
6,52.000,0.00,-0.0001,-0.00010,6.000
6,52.067,0.00,-0.0001,-0.00010,6.000
6,52.133,0.00,-0.0001,-0.00010,6.000
6,52.200,0.00,-0.0001,-0.00010,6.000
6,52.267,0.00,-0.0001,-0.00010,6.000
6,52.333,0.00,-0.0001,-0.00010,6.000
6,52.400,0.00,-0.0001,-0.00010,6.000
6,52.467,0.00,-0.0001,-0.00010,6.000
6,52.533,0.00,-0.0001,-0.00010,6.000
6,52.600,0.01,-0.0001,-0.00010,6.000
7,52.867,0.00,0.1063,0.10630,7.000
7,52.933,0.00,0.1729,0.17287,7.000
7,53.000,0.00,0.2396,0.23960,7.000
7,53.067,0.00,0.3064,0.30640,7.000
7,53.133,0.00,0.3730,0.37300,7.000
7,53.200,0.00,0.4397,0.43970,7.000
7,53.267,0.00,0.5064,0.50637,7.000
7,53.333,0.00,0.5729,0.57293,7.000
7,53.400,0.00,0.6397,0.63970,7.000
7,53.467,0.00,0.7065,0.70650,7.000
7,53.533,0.00,0.7730,0.77303,7.000
7,53.600,0.00,0.8399,0.83990,7.000
7,53.667,0.00,0.9065,0.90653,7.000
7,53.733,0.00,0.9729,0.97290,7.000
7,53.800,0.00,1.0397,1.03970,7.000
7,53.867,0.00,1.1064,1.10640,7.000
7,53.933,0.00,1.1730,1.17297,7.000
7,54.000,0.00,1.2397,1.23970,7.000
7,54.067,-0.01,1.3064,1.30643,7.000
7,54.133,0.00,1.3731,1.37310,7.000
7,54.200,0.00,1.4398,1.43980,7.000
7,54.267,0.00,1.5064,1.50640,7.000
7,54.333,0.00,1.5730,1.57303,7.000
7,54.400,0.01,1.6398,1.63980,7.000
7,54.467,0.03,1.7065,1.70653,7.000
7,54.533,0.07,1.7730,1.77303,7.000
7,54.600,0.14,1.8398,1.83980,7.000
7,54.667,0.24,1.9064,1.90640,7.000
7,54.733,0.37,1.9730,1.97303,7.000
7,54.800,0.54,2.0399,2.03990,7.000
7,54.867,0.74,2.1065,2.10653,7.000
7,54.933,0.97,2.1732,2.17320,7.000
7,55.067,1.11,2.1938,2.19383,7.000
7,55.133,0.81,2.1272,2.12717,7.000
7,55.200,0.58,2.0605,2.06050,7.000
7,55.267,0.39,1.9940,1.99397,7.000
7,55.333,0.24,1.9271,1.92710,7.000
7,55.400,0.13,1.8605,1.86050,7.000
7,55.467,0.06,1.7939,1.79390,7.000
7,55.533,0.02,1.7272,1.72720,7.000
7,55.600,0.00,1.6605,1.66050,7.000
7,55.667,0.00,1.5939,1.59387,7.000
7,55.733,0.00,1.5270,1.52703,7.000
7,55.800,0.00,1.4605,1.46050,7.000
7,55.867,0.00,1.3939,1.39390,7.000
7,55.933,0.00,1.3271,1.32707,7.000
7,56.000,0.00,1.2604,1.26040,7.000
7,56.067,-0.01,1.1938,1.19380,7.000
7,56.133,0.00,1.1270,1.12700,7.000
7,56.200,0.00,1.0605,1.06050,7.000
7,56.267,0.00,0.9937,0.99370,7.000
7,56.333,-0.01,0.9270,0.92700,7.000
7,56.400,-0.01,0.8606,0.86060,7.000
7,56.467,0.00,0.7939,0.79387,7.000
7,56.533,0.00,0.7271,0.72707,7.000
7,56.600,0.00,0.6605,0.66050,7.000
7,56.667,0.00,0.5937,0.59373,7.000
7,56.733,0.00,0.5269,0.52693,7.000
7,56.800,0.00,0.4606,0.46060,7.000
7,56.867,0.00,0.3937,0.39373,7.000
7,56.933,0.00,0.3269,0.32693,7.000
7,57.000,0.00,0.2605,0.26050,7.000
7,57.067,-0.01,0.1937,0.19373,7.000
7,57.133,0.00,0.1270,0.12697,7.000
7,57.200,0.00,0.0605,0.06050,7.000
7,57.267,0.00,-0.0062,-0.00623,7.000
7,57.400,0.00,-0.0043,-0.00430,7.000
7,57.467,0.00,-0.0001,-0.00010,7.000
7,57.533,0.00,-0.0001,-0.00010,7.000
7,57.600,0.00,-0.0001,-0.00010,7.000
7,57.667,0.00,-0.0001,-0.00010,7.000
7,57.733,0.00,-0.0001,-0.00010,7.000
7,57.800,0.00,-0.0001,-0.00010,7.000
7,57.867,0.00,-0.0001,-0.00010,7.000
7,57.933,0.00,-0.0001,-0.00010,7.000
7,58.000,0.00,-0.0001,-0.00010,7.000
7,58.067,0.00,-0.0001,-0.00010,7.000
7,58.133,0.00,-0.0001,-0.00010,7.000
7,58.200,0.00,-0.0001,-0.00010,7.000
7,58.267,0.00,-0.0001,-0.00010,7.000
7,58.333,0.00,-0.0001,-0.00010,7.000
7,58.400,0.00,-0.0001,-0.00010,7.000
7,58.467,0.00,-0.0001,-0.00010,7.000
7,58.533,0.00,-0.0001,-0.00010,7.000
7,58.600,-0.01,-0.0001,-0.00010,7.000
7,58.667,0.00,-0.0001,-0.00010,7.000
7,58.733,0.00,-0.0001,-0.00010,7.000
7,58.800,0.00,-0.0001,-0.00010,7.000
7,58.867,0.00,-0.0001,-0.00010,7.000
7,58.933,0.00,-0.0001,-0.00010,7.000
7,59.000,0.00,-0.0001,-0.00010,7.000
7,59.067,0.00,-0.0001,-0.00010,7.000
7,59.133,0.00,-0.0001,-0.00010,7.000
7,59.200,0.00,-0.0001,-0.00010,7.000
7,59.267,0.00,-0.0001,-0.00010,7.000
7,59.333,0.00,-0.0001,-0.00010,7.000
7,59.400,0.00,-0.0001,-0.00010,7.000
7,59.467,-0.01,-0.0001,-0.00010,7.000
7,59.533,-0.01,-0.0001,-0.00010,7.000
7,59.600,0.00,-0.0001,-0.00010,7.000
7,59.667,0.00,-0.0001,-0.00010,7.000
7,59.733,-0.01,-0.0001,-0.00010,7.000
7,59.800,-0.01,-0.0001,-0.00010,7.000
7,59.867,0.00,-0.0001,-0.00010,7.000
7,59.933,0.00,-0.0001,-0.00010,7.000
7,60.000,0.00,-0.0001,-0.00010,7.000
7,60.067,0.00,-0.0001,-0.00010,7.000
7,60.133,0.00,-0.0001,-0.00010,7.000
7,60.200,0.00,-0.0001,-0.00010,7.000
7,60.267,0.00,-0.0001,-0.00010,7.000
7,60.333,0.00,-0.0001,-0.00010,7.000
7,60.467,0.00,-0.0001,-0.00010,7.000
7,60.533,0.00,-0.0001,-0.00010,7.000
7,60.600,0.00,-0.0001,-0.00010,7.000
7,60.667,0.00,-0.0001,-0.00010,7.000
7,60.733,0.00,-0.0001,-0.00010,7.000
7,60.800,0.00,-0.0001,-0.00010,7.000
7,60.867,0.00,-0.0001,-0.00010,7.000
7,60.933,0.00,-0.0001,-0.00010,7.000
7,61.000,0.00,-0.0001,-0.00010,7.000
7,61.067,-0.01,-0.0001,-0.00010,7.000
7,61.133,-0.01,-0.0001,-0.00010,7.000
7,61.200,-0.01,-0.0001,-0.00010,7.000
7,61.267,0.00,-0.0001,-0.00010,7.000
7,61.333,0.00,-0.0001,-0.00010,7.000
8,61.600,0.00,0.0895,0.08950,8.000
8,61.667,0.00,0.1563,0.15627,8.000
8,61.733,0.00,0.2230,0.22303,8.000
8,61.800,0.00,0.2896,0.28960,8.000
8,61.867,0.00,0.3564,0.35637,8.000
8,61.933,0.00,0.4231,0.42310,8.000
8,62.000,0.00,0.4896,0.48960,8.000
8,62.067,0.00,0.5563,0.55633,8.000
8,62.133,0.00,0.6231,0.62307,8.000
8,62.200,0.00,0.6897,0.68970,8.000
8,62.267,0.00,0.7565,0.75650,8.000
8,62.333,0.00,0.8231,0.82313,8.000
8,62.400,0.00,0.8896,0.88960,8.000
8,62.467,0.00,0.9564,0.95643,8.000
8,62.533,0.00,1.0230,1.02297,8.000
8,62.600,-0.01,1.0896,1.08960,8.000
8,62.667,0.00,1.1564,1.15640,8.000
8,62.733,0.00,1.2230,1.22297,8.000
8,62.800,0.00,1.2896,1.28960,8.000
8,62.867,0.00,1.3565,1.35647,8.000
8,62.933,-0.01,1.4230,1.42303,8.000
8,63.000,0.00,1.4896,1.48960,8.000
8,63.067,0.00,1.5564,1.55643,8.000
8,63.133,0.00,1.6232,1.62320,8.000
8,63.200,0.02,1.6897,1.68970,8.000
8,63.267,0.06,1.7565,1.75653,8.000
8,63.333,0.12,1.8231,1.82310,8.000
8,63.400,0.22,1.8896,1.88960,8.000
8,63.467,0.34,1.9565,1.95653,8.000
8,63.533,0.50,2.0232,2.02317,8.000
8,63.600,0.69,2.0898,2.08980,8.000
8,63.667,0.91,2.1566,2.15660,8.000
8,63.800,1.19,2.2108,2.21080,8.000
8,63.867,0.88,2.1438,2.14380,8.000
8,63.933,0.64,2.0773,2.07730,8.000
8,64.000,0.44,2.0104,2.01040,8.000
8,64.067,0.27,1.9438,1.94383,8.000
8,64.133,0.16,1.8772,1.87717,8.000
8,64.200,0.07,1.8104,1.81040,8.000
8,64.267,0.03,1.7439,1.74387,8.000
8,64.333,0.01,1.6773,1.67727,8.000
8,64.400,0.00,1.6104,1.61040,8.000
8,64.467,0.00,1.5438,1.54380,8.000
8,64.533,0.00,1.4772,1.47720,8.000
8,64.600,0.00,1.4104,1.41040,8.000
8,64.667,0.00,1.3438,1.34383,8.000
8,64.733,0.00,1.2772,1.27717,8.000
8,64.800,0.00,1.2103,1.21030,8.000
8,64.867,0.00,1.1438,1.14383,8.000
8,64.933,0.00,1.0770,1.07703,8.000
8,65.000,0.00,1.0103,1.01030,8.000
8,65.067,0.00,0.9438,0.94377,8.000
8,65.133,0.00,0.8771,0.87713,8.000
8,65.200,0.00,0.8105,0.81050,8.000
8,65.267,-0.01,0.7439,0.74387,8.000
8,65.333,0.00,0.6771,0.67707,8.000
8,65.400,0.00,0.6102,0.61020,8.000
8,65.467,-0.01,0.5437,0.54373,8.000
8,65.533,0.00,0.4771,0.47710,8.000
8,65.600,-0.01,0.4103,0.41030,8.000
8,65.667,0.00,0.3438,0.34377,8.000
8,65.733,0.00,0.2771,0.27707,8.000
8,65.800,0.00,0.2103,0.21030,8.000
8,65.867,0.00,0.1438,0.14377,8.000
8,65.933,0.00,0.0771,0.07707,8.000
8,66.000,0.00,0.0102,0.01020,8.000
8,66.133,0.00,-0.0368,-0.03677,8.000
8,66.200,0.00,-0.0005,-0.00050,8.000
8,66.267,0.00,-0.0001,-0.00013,8.000
8,66.333,0.00,-0.0001,-0.00010,8.000
8,66.400,-0.01,-0.0001,-0.00010,8.000
8,66.467,0.00,-0.0001,-0.00010,8.000
8,66.533,0.00,-0.0001,-0.00010,8.000
8,66.600,0.00,-0.0001,-0.00010,8.000
8,66.667,0.00,-0.0001,-0.00010,8.000
8,66.733,0.00,-0.0001,-0.00010,8.000
8,66.800,0.00,-0.0001,-0.00010,8.000
8,66.867,0.00,-0.0001,-0.00010,8.000
8,66.933,0.00,-0.0001,-0.00010,8.000
8,67.000,0.00,-0.0001,-0.00010,8.000
8,67.067,0.00,-0.0001,-0.00010,8.000
8,67.133,0.00,-0.0001,-0.00010,8.000
8,67.200,0.00,-0.0001,-0.00010,8.000
8,67.267,0.00,-0.0001,-0.00010,8.000
8,67.333,0.00,-0.0001,-0.00010,8.000
8,67.400,0.00,-0.0001,-0.00010,8.000
8,67.467,0.00,-0.0001,-0.00010,8.000
8,67.533,0.00,-0.0001,-0.00010,8.000
8,67.600,-0.01,-0.0001,-0.00010,8.000
8,67.667,0.00,-0.0001,-0.00010,8.000
8,67.733,-0.01,-0.0001,-0.00010,8.000
8,67.800,0.00,-0.0001,-0.00010,8.000
8,67.867,0.00,-0.0001,-0.00010,8.000
8,67.933,0.00,-0.0001,-0.00010,8.000
8,68.000,0.00,-0.0001,-0.00010,8.000
8,68.067,-0.01,-0.0001,-0.00010,8.000
8,68.133,0.00,-0.0001,-0.00010,8.000
8,68.200,-0.01,-0.0001,-0.00010,8.000
8,68.267,0.00,-0.0001,-0.00010,8.000
8,68.333,0.00,-0.0001,-0.00010,8.000
8,68.400,0.00,-0.0001,-0.00010,8.000
8,68.467,-0.01,-0.0001,-0.00010,8.000
8,68.533,0.00,-0.0001,-0.00010,8.000
8,68.600,0.00,-0.0001,-0.00010,8.000
8,68.667,-0.01,-0.0001,-0.00010,8.000
8,68.733,0.00,-0.0001,-0.00010,8.000
8,68.800,0.00,-0.0001,-0.00010,8.000
8,68.867,0.00,-0.0001,-0.00010,8.000
8,68.933,0.00,-0.0001,-0.00010,8.000
8,69.000,0.00,-0.0001,-0.00010,8.000
8,69.067,0.00,-0.0001,-0.00010,8.000
8,69.200,0.00,-0.0001,-0.00010,8.000
8,69.267,0.00,-0.0001,-0.00010,8.000
8,69.333,0.00,-0.0001,-0.00010,8.000
8,69.400,-0.01,-0.0001,-0.00010,8.000
8,69.467,0.00,-0.0001,-0.00010,8.000
8,69.533,0.00,-0.0001,-0.00010,8.000
8,69.600,0.00,-0.0001,-0.00010,8.000
8,69.667,-0.01,-0.0001,-0.00010,8.000
8,69.733,0.00,-0.0001,-0.00010,8.000
8,69.800,-0.01,-0.0001,-0.00010,8.000
8,69.867,0.00,-0.0001,-0.00010,8.000
8,69.933,0.00,-0.0001,-0.00010,8.000
8,70.000,0.00,-0.0001,-0.00010,8.000
8,70.067,0.00,-0.0001,-0.00010,8.000
8,70.133,0.00,-0.0001,-0.00010,8.000
9,70.333,0.00,0.0629,0.06290,9.000
9,70.400,-0.01,0.1295,0.12950,9.000
9,70.467,0.00,0.1964,0.19637,9.000
9,70.533,0.00,0.2631,0.26307,9.000
9,70.600,-0.01,0.3296,0.32960,9.000
9,70.667,-0.01,0.3964,0.39643,9.000
9,70.733,0.00,0.4631,0.46310,9.000
9,70.800,0.00,0.5296,0.52960,9.000
9,70.867,-0.01,0.5964,0.59640,9.000
9,70.933,-0.01,0.6631,0.66310,9.000
9,71.000,0.00,0.7297,0.72970,9.000
9,71.067,0.00,0.7966,0.79657,9.000
9,71.133,0.00,0.8632,0.86320,9.000
9,71.200,0.00,0.9296,0.92960,9.000
9,71.267,0.00,0.9964,0.99637,9.000
9,71.333,0.00,1.0630,1.06303,9.000
9,71.400,0.00,1.1296,1.12960,9.000
9,71.467,0.00,1.1963,1.19633,9.000
9,71.533,0.00,1.2630,1.26303,9.000
9,71.600,-0.01,1.3296,1.32960,9.000
9,71.667,0.00,1.3965,1.39650,9.000
9,71.733,0.00,1.4631,1.46310,9.000
9,71.800,-0.01,1.5297,1.52970,9.000
9,71.867,0.00,1.5965,1.59647,9.000
9,71.933,0.01,1.6631,1.66313,9.000
9,72.000,0.04,1.7297,1.72970,9.000
9,72.067,0.09,1.7965,1.79650,9.000
9,72.133,0.17,1.8631,1.86307,9.000
9,72.200,0.29,1.9297,1.92970,9.000
9,72.267,0.43,1.9965,1.99650,9.000
9,72.333,0.61,2.0632,2.06317,9.000
9,72.400,0.82,2.1298,2.12980,9.000
9,72.467,1.06,2.1966,2.19657,9.000
9,72.600,1.09,2.1904,2.19040,9.000
9,72.667,0.80,2.1239,2.12387,9.000
9,72.733,0.57,2.0572,2.05717,9.000
9,72.800,0.38,1.9907,1.99070,9.000
9,72.867,0.23,1.9238,1.92383,9.000
9,72.933,0.13,1.8571,1.85707,9.000
9,73.000,0.06,1.7906,1.79060,9.000
9,73.067,0.02,1.7238,1.72380,9.000
9,73.133,0.00,1.6572,1.65717,9.000
9,73.200,0.00,1.5906,1.59060,9.000
9,73.267,0.00,1.5237,1.52373,9.000
9,73.333,0.00,1.4571,1.45707,9.000
9,73.400,-0.01,1.3906,1.39060,9.000
9,73.467,0.00,1.3238,1.32380,9.000
9,73.533,0.00,1.2570,1.25703,9.000
9,73.600,0.00,1.1905,1.19050,9.000
9,73.667,-0.01,1.1237,1.12370,9.000
9,73.733,0.00,1.0570,1.05700,9.000
9,73.800,0.00,0.9904,0.99040,9.000
9,73.867,0.00,0.9237,0.92370,9.000
9,73.933,-0.01,0.8571,0.85707,9.000
9,74.000,-0.01,0.7905,0.79050,9.000
9,74.067,0.00,0.7237,0.72373,9.000
9,74.133,0.00,0.6571,0.65710,9.000
9,74.200,0.00,0.5905,0.59050,9.000
9,74.267,-0.01,0.5236,0.52363,9.000
9,74.333,0.00,0.4570,0.45703,9.000
9,74.400,-0.01,0.3904,0.39040,9.000
9,74.467,-0.01,0.3237,0.32367,9.000
9,74.533,-0.01,0.2571,0.25710,9.000
9,74.600,0.00,0.1905,0.19050,9.000
9,74.667,0.00,0.1237,0.12367,9.000
9,74.733,0.00,0.0569,0.05693,9.000
9,74.800,0.00,-0.0095,-0.00950,9.000
9,74.933,0.00,-0.0147,-0.01473,9.000
9,75.000,0.00,-0.0001,-0.00010,9.000
9,75.067,0.00,-0.0001,-0.00010,9.000
9,75.133,0.00,-0.0002,-0.00020,9.000
9,75.200,0.00,-0.0001,-0.00010,9.000
9,75.267,-0.01,-0.0001,-0.00010,9.000
9,75.333,0.00,-0.0001,-0.00010,9.000
9,75.400,0.00,-0.0001,-0.00010,9.000
9,75.467,0.00,-0.0001,-0.00010,9.000
9,75.533,0.00,-0.0001,-0.00010,9.000
9,75.600,0.00,-0.0001,-0.00010,9.000
9,75.667,0.00,-0.0001,-0.00010,9.000
9,75.733,0.00,-0.0001,-0.00010,9.000
9,75.800,0.00,-0.0001,-0.00010,9.000
9,75.867,0.00,-0.0001,-0.00010,9.000
9,75.933,0.00,-0.0001,-0.00010,9.000
9,76.000,0.00,-0.0001,-0.00010,9.000
9,76.067,0.00,-0.0001,-0.00010,9.000
9,76.133,0.00,-0.0001,-0.00010,9.000
9,76.200,0.00,-0.0001,-0.00010,9.000
9,76.267,0.00,-0.0001,-0.00010,9.000
9,76.333,0.00,-0.0001,-0.00010,9.000
9,76.400,-0.01,-0.0001,-0.00010,9.000
9,76.467,0.00,-0.0001,-0.00010,9.000
9,76.533,0.00,-0.0001,-0.00010,9.000
9,76.600,0.00,-0.0001,-0.00010,9.000
9,76.667,0.00,-0.0001,-0.00010,9.000
9,76.733,0.00,-0.0001,-0.00010,9.000
9,76.800,0.00,-0.0001,-0.00010,9.000
9,76.867,0.00,-0.0001,-0.00010,9.000
9,76.933,0.00,-0.0001,-0.00010,9.000
9,77.000,0.00,-0.0001,-0.00010,9.000
9,77.067,0.00,-0.0001,-0.00010,9.000
9,77.133,-0.01,-0.0001,-0.00010,9.000
9,77.200,0.00,-0.0001,-0.00010,9.000
9,77.267,0.00,-0.0001,-0.00010,9.000
9,77.333,0.00,-0.0001,-0.00010,9.000
9,77.400,-0.01,-0.0001,-0.00010,9.000
9,77.467,0.00,-0.0001,-0.00010,9.000
9,77.533,0.00,-0.0001,-0.00010,9.000
9,77.600,-0.01,-0.0001,-0.00010,9.000
9,77.667,0.00,-0.0001,-0.00010,9.000
9,77.733,0.00,-0.0001,-0.00010,9.000
9,77.800,0.00,-0.0001,-0.00010,9.000
9,77.867,0.00,-0.0001,-0.00010,9.000
9,78.000,0.00,-0.0001,-0.00010,9.000
9,78.067,0.00,-0.0001,-0.00010,9.000
9,78.133,0.00,-0.0001,-0.00010,9.000
9,78.200,-0.01,-0.0001,-0.00010,9.000
9,78.267,0.00,-0.0001,-0.00010,9.000
9,78.333,0.00,-0.0001,-0.00010,9.000
9,78.400,-0.01,-0.0001,-0.00010,9.000
9,78.467,0.00,-0.0001,-0.00010,9.000
9,78.533,0.00,-0.0001,-0.00010,9.000
9,78.600,-0.01,-0.0001,-0.00010,9.000
9,78.667,0.00,-0.0001,-0.00010,9.000
9,78.733,0.00,-0.0001,-0.00010,9.000
9,78.800,0.00,-0.0001,-0.00010,9.000
9,78.867,-0.01,-0.0001,-0.00010,9.000
10,79.133,0.00,0.0629,0.06290,10.000
10,79.200,0.00,0.1295,0.12950,10.000
10,79.267,0.00,0.1963,0.19633,10.000
10,79.333,0.00,0.2631,0.26307,10.000
10,79.400,0.00,0.3296,0.32960,10.000
10,79.467,0.00,0.3964,0.39643,10.000
10,79.533,0.00,0.4631,0.46307,10.000
10,79.600,0.00,0.5295,0.52950,10.000
10,79.667,0.00,0.5964,0.59640,10.000
10,79.733,0.00,0.6631,0.66313,10.000
10,79.800,0.00,0.7296,0.72960,10.000
10,79.867,0.00,0.7965,0.79650,10.000
10,79.933,0.00,0.8631,0.86313,10.000
10,80.000,0.00,0.9296,0.92960,10.000
10,80.067,0.00,0.9964,0.99637,10.000
10,80.133,0.00,1.0631,1.06307,10.000
10,80.200,0.00,1.1296,1.12960,10.000
10,80.267,0.00,1.1964,1.19643,10.000
10,80.333,0.00,1.2631,1.26307,10.000
10,80.400,0.00,1.3297,1.32970,10.000
10,80.467,0.00,1.3965,1.39647,10.000
10,80.533,0.00,1.4631,1.46307,10.000
10,80.600,0.00,1.5297,1.52970,10.000
10,80.667,0.00,1.5965,1.59650,10.000
10,80.733,0.02,1.6632,1.66317,10.000
10,80.800,0.05,1.7297,1.72970,10.000
10,80.867,0.09,1.7964,1.79643,10.000
10,80.933,0.18,1.8630,1.86303,10.000
10,81.000,0.29,1.9296,1.92960,10.000
10,81.067,0.44,1.9965,1.99650,10.000
10,81.133,0.62,2.0632,2.06317,10.000
10,81.200,0.83,2.1298,2.12980,10.000
10,81.267,1.07,2.1965,2.19653,10.000
10,81.400,1.03,2.1764,2.17640,10.000
10,81.467,0.75,2.1099,2.10990,10.000
10,81.533,0.53,2.0433,2.04327,10.000
10,81.600,0.35,1.9764,1.97640,10.000
10,81.667,0.21,1.9098,1.90983,10.000
10,81.733,0.11,1.8431,1.84313,10.000
10,81.800,0.05,1.7764,1.77640,10.000
10,81.867,0.02,1.7100,1.71000,10.000
10,81.933,0.00,1.6432,1.64320,10.000
10,82.000,0.00,1.5764,1.57640,10.000
10,82.067,0.00,1.5098,1.50983,10.000
10,82.133,0.00,1.4432,1.44317,10.000
10,82.200,0.00,1.3764,1.37640,10.000
10,82.267,0.00,1.3098,1.30983,10.000
10,82.333,0.00,1.2431,1.24310,10.000
10,82.400,0.00,1.1763,1.17630,10.000
10,82.467,0.00,1.1098,1.10980,10.000
10,82.533,0.00,1.0430,1.04297,10.000
10,82.600,0.00,0.9762,0.97620,10.000
10,82.667,0.00,0.9098,0.90980,10.000
10,82.733,0.00,0.8431,0.84313,10.000
10,82.800,0.00,0.7765,0.77650,10.000
10,82.867,0.00,0.7098,0.70983,10.000
10,82.933,0.00,0.6431,0.64307,10.000
10,83.000,0.00,0.5763,0.57630,10.000
10,83.067,0.00,0.5097,0.50973,10.000
10,83.133,0.00,0.4430,0.44303,10.000
10,83.200,0.00,0.3764,0.37640,10.000
10,83.267,0.00,0.3098,0.30980,10.000
10,83.333,0.00,0.2430,0.24300,10.000
10,83.400,0.00,0.1764,0.17640,10.000
10,83.467,0.00,0.1098,0.10977,10.000
10,83.533,-0.01,0.0430,0.04297,10.000
10,83.600,0.00,-0.0235,-0.02350,10.000
10,83.733,0.00,-0.0011,-0.00113,10.000
10,83.800,0.00,-0.0002,-0.00020,10.000
10,83.867,0.00,-0.0002,-0.00020,10.000
10,83.933,0.00,-0.0002,-0.00020,10.000
10,84.000,0.00,-0.0002,-0.00020,10.000
10,84.067,0.00,-0.0002,-0.00020,10.000
10,84.133,0.00,-0.0002,-0.00020,10.000
10,84.200,0.00,-0.0002,-0.00020,10.000
10,84.267,0.00,-0.0002,-0.00020,10.000
10,84.333,0.00,-0.0002,-0.00020,10.000
10,84.400,0.00,-0.0002,-0.00020,10.000
10,84.467,0.00,-0.0002,-0.00020,10.000
10,84.533,0.00,-0.0002,-0.00020,10.000
10,84.600,0.00,-0.0002,-0.00020,10.000
10,84.667,0.00,-0.0002,-0.00020,10.000
10,84.733,0.00,-0.0002,-0.00020,10.000
10,84.800,0.00,-0.0002,-0.00020,10.000
10,84.867,0.00,-0.0002,-0.00020,10.000
10,84.933,0.00,-0.0002,-0.00020,10.000
10,85.000,0.00,-0.0002,-0.00020,10.000
10,85.067,0.00,-0.0002,-0.00020,10.000
10,85.133,0.00,-0.0002,-0.00020,10.000
10,85.200,0.00,-0.0001,-0.00010,10.000
10,85.267,0.00,-0.0001,-0.00010,10.000
10,85.333,0.00,-0.0001,-0.00010,10.000
10,85.400,0.00,-0.0001,-0.00010,10.000
10,85.467,0.00,-0.0001,-0.00010,10.000
10,85.533,0.00,-0.0001,-0.00010,10.000
10,85.600,0.00,-0.0001,-0.00010,10.000
10,85.667,0.00,-0.0001,-0.00010,10.000
10,85.733,0.00,-0.0001,-0.00010,10.000
10,85.800,0.00,-0.0001,-0.00010,10.000
10,85.867,0.00,-0.0001,-0.00010,10.000
10,85.933,0.00,-0.0001,-0.00010,10.000
10,86.000,0.00,-0.0001,-0.00010,10.000
10,86.067,0.00,-0.0001,-0.00010,10.000
10,86.133,0.00,-0.0001,-0.00010,10.000
10,86.200,0.00,-0.0001,-0.00010,10.000
10,86.267,0.00,-0.0001,-0.00010,10.000
10,86.333,0.00,-0.0001,-0.00010,10.000
10,86.400,0.00,-0.0001,-0.00010,10.000
10,86.467,0.00,-0.0001,-0.00010,10.000
10,86.533,0.00,-0.0001,-0.00010,10.000
10,86.600,0.00,-0.0001,-0.00010,10.000
10,86.667,0.00,-0.0001,-0.00010,10.000
10,86.800,0.00,-0.0001,-0.00010,10.000
10,86.867,0.00,-0.0001,-0.00010,10.000
10,86.933,0.00,-0.0001,-0.00010,10.000
10,87.000,0.00,-0.0001,-0.00010,10.000
10,87.067,0.00,-0.0001,-0.00010,10.000
10,87.133,-0.01,-0.0001,-0.00010,10.000
10,87.200,0.00,-0.0001,-0.00010,10.000
10,87.267,0.00,-0.0001,-0.00010,10.000
10,87.333,0.00,-0.0001,-0.00010,10.000
10,87.400,0.00,-0.0001,-0.00010,10.000
10,87.467,0.00,-0.0001,-0.00010,10.000
10,87.533,0.00,-0.0001,-0.00010,10.000
10,87.600,0.00,-0.0001,-0.00010,10.000
10,87.667,0.00,-0.0001,-0.00010,10.000