File: calibDATA_loadcell/date_02:15:2018/Instron_02.15.2018/1_1N_4__1mm.s_0_0.txt
""
"Test Method","Radhen_Load_Cntrl_Cmprsn_250N_12-7.msm"
"Sample I. D.","Sample1.mss"
"Specimen Number","13"

"TheCycle_Output ()","_Time (s)","_Load (N)","_Extension (mm)","RealTimeDepth (mm)","CycleNumber ()"

1,0.200,0.01,0.0000,0.00000,1.000
1,0.267,0.00,0.0513,0.05130,1.000
1,0.333,0.00,0.1178,0.11783,1.000
1,0.400,0.00,0.1847,0.18470,1.000
1,0.467,0.01,0.2514,0.25143,1.000
1,0.533,0.00,0.3181,0.31813,1.000
1,0.600,0.00,0.3848,0.38480,1.000
1,0.667,0.00,0.4514,0.45143,1.000
1,0.733,0.00,0.5182,0.51817,1.000
1,0.800,-0.01,0.5848,0.58480,1.000
1,0.867,0.00,0.6514,0.65143,1.000
1,0.933,0.00,0.7181,0.71813,1.000
1,1.000,0.00,0.7848,0.78480,1.000
1,1.067,0.00,0.8515,0.85150,1.000
1,1.133,0.00,0.9181,0.91813,1.000
1,1.200,0.00,0.9848,0.98480,1.000
1,1.267,0.00,1.0514,1.05143,1.000
1,1.333,0.00,1.1182,1.11820,1.000
1,1.400,0.00,1.1850,1.18500,1.000
1,1.467,0.01,1.2515,1.25147,1.000
1,1.533,0.00,1.3181,1.31813,1.000
1,1.600,0.01,1.3848,1.38480,1.000
1,1.667,0.00,1.4514,1.45137,1.000
1,1.733,0.00,1.5181,1.51807,1.000
1,1.800,0.00,1.5847,1.58470,1.000
1,1.867,0.00,1.6515,1.65150,1.000
1,1.933,0.00,1.7183,1.71827,1.000
1,2.000,0.01,1.7849,1.78490,1.000
1,2.067,0.00,1.8514,1.85140,1.000
1,2.133,0.01,1.9183,1.91827,1.000
1,2.200,0.03,1.9849,1.98490,1.000
1,2.267,0.05,2.0516,2.05160,1.000
1,2.333,0.11,2.1182,2.11820,1.000
1,2.400,0.20,2.1849,2.18490,1.000
1,2.467,0.32,2.2515,2.25147,1.000
1,2.533,0.47,2.3183,2.31827,1.000
1,2.600,0.65,2.3850,2.38500,1.000
1,2.667,0.86,2.4515,2.45153,1.000
1,2.800,1.19,2.5244,2.52440,1.000
1,2.867,0.90,2.4589,2.45893,1.000
1,2.933,0.66,2.3924,2.39237,1.000
1,3.000,0.46,2.3256,2.32560,1.000
1,3.067,0.29,2.2589,2.25893,1.000
1,3.133,0.18,2.1922,2.19220,1.000
1,3.200,0.09,2.1255,2.12550,1.000
1,3.267,0.04,2.0589,2.05893,1.000
1,3.333,0.02,1.9923,1.99233,1.000
1,3.400,0.00,1.9255,1.92550,1.000
1,3.467,0.00,1.8589,1.85887,1.000
1,3.533,0.00,1.7922,1.79223,1.000
1,3.600,0.00,1.7256,1.72560,1.000
1,3.667,0.00,1.6589,1.65893,1.000
1,3.733,0.00,1.5921,1.59213,1.000
1,3.800,0.01,1.5255,1.52550,1.000
1,3.867,0.00,1.4588,1.45880,1.000
1,3.933,0.00,1.3922,1.39217,1.000
1,4.000,0.01,1.3255,1.32550,1.000
1,4.067,0.00,1.2589,1.25893,1.000
1,4.133,0.00,1.1923,1.19230,1.000
1,4.200,0.01,1.1255,1.12550,1.000
1,4.267,0.01,1.0589,1.05893,1.000
1,4.333,0.01,0.9922,0.99223,1.000
1,4.400,0.00,0.9254,0.92540,1.000
1,4.467,0.00,0.8589,0.85890,1.000
1,4.533,0.01,0.7922,0.79220,1.000
1,4.600,0.01,0.7255,0.72550,1.000
1,4.667,0.00,0.6589,0.65887,1.000
1,4.733,0.00,0.5922,0.59220,1.000
1,4.800,0.00,0.5254,0.52540,1.000
1,4.867,0.00,0.4589,0.45890,1.000
1,4.933,0.00,0.3921,0.39210,1.000
1,5.000,0.00,0.3253,0.32530,1.000
1,5.067,0.01,0.2589,0.25890,1.000
1,5.133,0.00,0.1920,0.19203,1.000
1,5.200,0.00,0.1252,0.12520,1.000
1,5.267,0.00,0.0586,0.05860,1.000
1,5.333,0.00,-0.0079,-0.00790,1.000
1,5.467,0.00,-0.0009,-0.00090,1.000
1,5.533,0.00,-0.0002,-0.00020,1.000
1,5.600,0.00,-0.0002,-0.00020,1.000
1,5.667,0.00,-0.0002,-0.00020,1.000
1,5.733,0.01,-0.0002,-0.00020,1.000
1,5.800,0.01,-0.0002,-0.00020,1.000
1,5.867,0.00,-0.0002,-0.00020,1.000
1,5.933,0.00,-0.0002,-0.00020,1.000
1,6.000,0.00,-0.0002,-0.00020,1.000
1,6.067,0.00,-0.0002,-0.00020,1.000
1,6.133,0.01,-0.0002,-0.00020,1.000
1,6.200,0.01,-0.0002,-0.00020,1.000
1,6.267,0.00,-0.0002,-0.00020,1.000
1,6.333,0.00,-0.0002,-0.00020,1.000
1,6.400,0.00,-0.0002,-0.00020,1.000
1,6.467,0.00,-0.0002,-0.00020,1.000
1,6.533,0.00,-0.0002,-0.00020,1.000
1,6.600,0.00,-0.0002,-0.00020,1.000
1,6.667,0.00,-0.0002,-0.00020,1.000
1,6.733,0.00,-0.0002,-0.00020,1.000
1,6.800,0.00,-0.0002,-0.00020,1.000
1,6.867,0.00,-0.0002,-0.00020,1.000
1,6.933,0.00,-0.0002,-0.00017,1.000
1,7.000,0.00,-0.0001,-0.00010,1.000
1,7.067,0.00,-0.0001,-0.00010,1.000
1,7.133,0.01,-0.0001,-0.00010,1.000
1,7.200,0.00,-0.0001,-0.00010,1.000
1,7.267,0.01,-0.0001,-0.00010,1.000
1,7.333,0.01,-0.0001,-0.00010,1.000
1,7.400,0.00,-0.0001,-0.00010,1.000
1,7.467,0.00,-0.0001,-0.00010,1.000
1,7.533,0.00,-0.0001,-0.00010,1.000
1,7.600,0.01,-0.0001,-0.00010,1.000
1,7.667,0.00,-0.0001,-0.00010,1.000
1,7.733,0.00,-0.0001,-0.00010,1.000
1,7.800,0.00,-0.0001,-0.00010,1.000
1,7.867,0.00,-0.0001,-0.00010,1.000
1,7.933,0.00,-0.0001,-0.00010,1.000
1,8.000,0.00,-0.0001,-0.00010,1.000
1,8.067,0.00,-0.0001,-0.00010,1.000
1,8.133,0.01,-0.0001,-0.00010,1.000
1,8.200,0.01,-0.0001,-0.00010,1.000
1,8.267,0.00,-0.0001,-0.00010,1.000
1,8.333,0.00,-0.0001,-0.00010,1.000
1,8.400,0.00,-0.0001,-0.00010,1.000
1,8.533,0.00,-0.0001,-0.00010,1.000
1,8.600,0.00,-0.0001,-0.00010,1.000
1,8.667,0.00,-0.0001,-0.00010,1.000
1,8.733,0.00,-0.0001,-0.00010,1.000
1,8.800,0.00,-0.0001,-0.00010,1.000
1,8.867,0.00,-0.0001,-0.00010,1.000
1,8.933,0.00,-0.0001,-0.00010,1.000
1,9.000,0.00,-0.0001,-0.00010,1.000
1,9.067,0.00,-0.0001,-0.00010,1.000
1,9.133,0.00,-0.0001,-0.00010,1.000
1,9.200,0.00,-0.0001,-0.00010,1.000
1,9.267,0.01,-0.0001,-0.00010,1.000
1,9.333,0.00,-0.0001,-0.00010,1.000
1,9.400,0.00,-0.0001,-0.00010,1.000
2,9.667,0.00,0.0812,0.08120,2.000
2,9.733,0.00,0.1480,0.14797,2.000
2,9.800,0.01,0.2146,0.21460,2.000
2,9.867,-0.01,0.2814,0.28137,2.000
2,9.933,-0.01,0.3481,0.34813,2.000
2,10.000,0.00,0.4148,0.41480,2.000
2,10.067,0.00,0.4814,0.48137,2.000
2,10.133,0.00,0.5481,0.54813,2.000
2,10.200,0.00,0.6147,0.61470,2.000
2,10.267,-0.01,0.6814,0.68137,2.000
2,10.333,0.00,0.7482,0.74817,2.000
2,10.400,-0.01,0.8148,0.81480,2.000
2,10.467,0.00,0.8813,0.88133,2.000
2,10.533,0.00,0.9481,0.94813,2.000
2,10.600,0.00,1.0147,1.01470,2.000
2,10.667,-0.01,1.0814,1.08140,2.000
2,10.733,0.00,1.1483,1.14830,2.000
2,10.800,-0.01,1.2148,1.21480,2.000
2,10.867,0.00,1.2815,1.28147,2.000
2,10.933,-0.01,1.3481,1.34810,2.000
2,11.000,-0.01,1.4147,1.41470,2.000
2,11.067,0.00,1.4814,1.48140,2.000
2,11.133,0.00,1.5480,1.54803,2.000
2,11.200,0.00,1.6147,1.61470,2.000
2,11.267,0.00,1.6814,1.68140,2.000
2,11.333,-0.01,1.7482,1.74823,2.000
2,11.400,0.00,1.8147,1.81470,2.000
2,11.467,0.00,1.8814,1.88143,2.000
2,11.533,0.01,1.9482,1.94820,2.000
2,11.600,0.03,2.0148,2.01480,2.000
2,11.667,0.07,2.0815,2.08153,2.000
2,11.733,0.14,2.1482,2.14820,2.000
2,11.800,0.24,2.2147,2.21470,2.000
2,11.867,0.38,2.2814,2.28143,2.000
2,11.933,0.54,2.3482,2.34823,2.000
2,12.000,0.74,2.4148,2.41480,2.000
2,12.067,0.95,2.4816,2.48157,2.000
2,12.200,1.07,2.4956,2.49560,2.000
2,12.267,0.78,2.4290,2.42897,2.000
2,12.333,0.56,2.3622,2.36223,2.000
2,12.400,0.38,2.2955,2.29550,2.000
2,12.467,0.23,2.2289,2.22887,2.000
2,12.533,0.13,2.1621,2.16210,2.000
2,12.600,0.06,2.0954,2.09540,2.000
2,12.667,0.02,2.0290,2.02900,2.000
2,12.733,0.01,1.9623,1.96227,2.000
2,12.800,0.00,1.8956,1.89560,2.000
2,12.867,0.00,1.8289,1.82893,2.000
2,12.933,0.00,1.7622,1.76223,2.000
2,13.000,0.00,1.6955,1.69550,2.000
2,13.067,0.00,1.6289,1.62887,2.000
2,13.133,0.00,1.5620,1.56203,2.000
2,13.200,0.00,1.4955,1.49550,2.000
2,13.267,0.00,1.4289,1.42890,2.000
2,13.333,0.00,1.3621,1.36207,2.000
2,13.400,0.00,1.2954,1.29540,2.000
2,13.467,0.00,1.2289,1.22893,2.000
2,13.533,0.00,1.1622,1.16220,2.000
2,13.600,0.00,1.0955,1.09550,2.000
2,13.667,0.00,1.0289,1.02893,2.000
2,13.733,0.00,0.9620,0.96203,2.000
2,13.800,0.00,0.8954,0.89540,2.000
2,13.867,0.00,0.8289,0.82890,2.000
2,13.933,0.00,0.7620,0.76203,2.000
2,14.000,0.00,0.6954,0.69540,2.000
2,14.067,0.00,0.6288,0.62883,2.000
2,14.133,0.00,0.5621,0.56207,2.000
2,14.200,0.00,0.4954,0.49540,2.000
2,14.267,0.00,0.4288,0.42880,2.000
2,14.333,0.00,0.3620,0.36203,2.000
2,14.400,-0.01,0.2954,0.29540,2.000
2,14.467,0.00,0.2288,0.22880,2.000
2,14.533,0.00,0.1619,0.16193,2.000
2,14.600,-0.01,0.0954,0.09540,2.000
2,14.667,0.00,0.0287,0.02873,2.000
2,14.800,0.00,-0.0255,-0.02550,2.000
2,14.867,0.00,-0.0002,-0.00020,2.000
2,14.933,0.00,-0.0002,-0.00020,2.000
2,15.000,0.00,-0.0002,-0.00020,2.000
2,15.067,0.00,-0.0002,-0.00020,2.000
2,15.133,0.00,-0.0002,-0.00020,2.000
2,15.200,0.00,-0.0002,-0.00020,2.000
2,15.267,0.00,-0.0002,-0.00020,2.000
2,15.333,0.00,-0.0002,-0.00020,2.000
2,15.400,0.00,-0.0002,-0.00020,2.000
2,15.467,0.00,-0.0002,-0.00020,2.000
2,15.533,0.00,-0.0002,-0.00020,2.000
2,15.600,0.01,-0.0002,-0.00020,2.000
2,15.667,0.00,-0.0002,-0.00020,2.000
2,15.733,0.00,-0.0002,-0.00020,2.000
2,15.800,-0.01,-0.0002,-0.00020,2.000
2,15.867,0.00,-0.0002,-0.00020,2.000
2,15.933,0.00,-0.0002,-0.00020,2.000
2,16.000,0.00,-0.0002,-0.00020,2.000
2,16.067,0.00,-0.0002,-0.00020,2.000
2,16.133,0.00,-0.0002,-0.00020,2.000
2,16.200,0.00,-0.0002,-0.00020,2.000
2,16.267,0.00,-0.0002,-0.00020,2.000
2,16.333,-0.01,-0.0002,-0.00020,2.000
2,16.400,-0.01,-0.0002,-0.00020,2.000
2,16.467,-0.01,-0.0002,-0.00020,2.000
2,16.533,-0.01,-0.0002,-0.00020,2.000
2,16.600,0.00,-0.0002,-0.00020,2.000
2,16.667,0.00,-0.0002,-0.00020,2.000
2,16.733,0.00,-0.0002,-0.00020,2.000
2,16.800,0.00,-0.0002,-0.00020,2.000
2,16.867,-0.01,-0.0002,-0.00020,2.000
2,16.933,0.00,-0.0002,-0.00020,2.000
2,17.000,0.00,-0.0002,-0.00020,2.000
2,17.067,-0.01,-0.0002,-0.00020,2.000
2,17.133,0.00,-0.0001,-0.00010,2.000
2,17.200,-0.01,-0.0001,-0.00010,2.000
2,17.267,-0.01,-0.0001,-0.00010,2.000
2,17.333,0.00,-0.0001,-0.00010,2.000
2,17.400,-0.01,-0.0001,-0.00010,2.000
2,17.467,0.00,-0.0001,-0.00010,2.000
2,17.533,0.00,-0.0001,-0.00010,2.000
2,17.600,-0.01,-0.0001,-0.00010,2.000
2,17.667,0.00,-0.0001,-0.00010,2.000
2,17.733,0.00,-0.0001,-0.00010,2.000
2,17.800,0.00,-0.0001,-0.00010,2.000
2,17.867,0.00,-0.0001,-0.00010,2.000
2,17.933,-0.01,-0.0001,-0.00010,2.000
2,18.000,0.00,-0.0001,-0.00010,2.000
2,18.067,-0.01,-0.0001,-0.00010,2.000
2,18.133,0.00,-0.0001,-0.00010,2.000
2,18.200,0.00,-0.0001,-0.00010,2.000
2,18.267,0.00,-0.0001,-0.00010,2.000
2,18.333,0.00,-0.0001,-0.00010,2.000
2,18.400,-0.01,-0.0001,-0.00010,2.000
2,18.467,0.00,-0.0001,-0.00010,2.000
2,18.533,0.00,-0.0001,-0.00010,2.000
2,18.600,0.00,-0.0001,-0.00010,2.000
2,18.667,-0.01,-0.0001,-0.00010,2.000
2,18.733,0.00,-0.0001,-0.00010,2.000
2,18.800,0.00,-0.0001,-0.00010,2.000
3,19.000,0.00,0.0556,0.05560,3.000
3,19.067,0.00,0.1222,0.12217,3.000
3,19.133,0.00,0.1890,0.18900,3.000
3,19.200,0.00,0.2556,0.25560,3.000
3,19.267,0.00,0.3224,0.32237,3.000
3,19.333,0.00,0.3891,0.38910,3.000
3,19.400,0.00,0.4558,0.45580,3.000
3,19.467,0.00,0.5224,0.52240,3.000
3,19.533,0.00,0.5891,0.58913,3.000
3,19.600,0.00,0.6558,0.65580,3.000
3,19.667,0.00,0.7224,0.72240,3.000
3,19.733,0.00,0.7892,0.78920,3.000
3,19.800,0.00,0.8558,0.85580,3.000
3,19.867,0.00,0.9223,0.92230,3.000
3,19.933,0.00,0.9892,0.98917,3.000
3,20.000,0.00,1.0558,1.05580,3.000
3,20.067,0.00,1.1225,1.12253,3.000
3,20.133,0.00,1.1893,1.18927,3.000
3,20.200,0.00,1.2558,1.25580,3.000
3,20.267,0.00,1.3224,1.32237,3.000
3,20.333,0.00,1.3891,1.38910,3.000
3,20.400,0.00,1.4557,1.45570,3.000
3,20.467,0.00,1.5223,1.52233,3.000
3,20.533,-0.01,1.5891,1.58907,3.000
3,20.600,0.00,1.6558,1.65580,3.000
3,20.667,0.00,1.7225,1.72247,3.000
3,20.733,-0.01,1.7892,1.78920,3.000
3,20.800,0.00,1.8556,1.85560,3.000
3,20.867,0.01,1.9225,1.92247,3.000
3,20.933,0.03,1.9892,1.98920,3.000
3,21.000,0.05,2.0559,2.05590,3.000
3,21.067,0.11,2.1225,2.12247,3.000
3,21.133,0.20,2.1892,2.18917,3.000
3,21.200,0.32,2.2558,2.25580,3.000
3,21.267,0.48,2.3225,2.32250,3.000
3,21.333,0.66,2.3893,2.38927,3.000
3,21.400,0.87,2.4559,2.45590,3.000
3,21.600,0.97,2.4765,2.47650,3.000
3,21.667,0.71,2.4099,2.40990,3.000
3,21.733,0.50,2.3434,2.34337,3.000
3,21.800,0.33,2.2766,2.27660,3.000
3,21.867,0.20,2.2097,2.20973,3.000
3,21.933,0.10,2.1432,2.14320,3.000
3,22.000,0.05,2.0767,2.07670,3.000
3,22.067,0.02,2.0099,2.00987,3.000
3,22.133,0.00,1.9433,1.94327,3.000
3,22.200,0.00,1.8765,1.87650,3.000
3,22.267,0.00,1.8097,1.80973,3.000
3,22.333,0.00,1.7433,1.74327,3.000
3,22.400,0.00,1.6766,1.67660,3.000
3,22.467,0.00,1.6098,1.60977,3.000
3,22.533,0.00,1.5432,1.54317,3.000
3,22.600,0.00,1.4765,1.47650,3.000
3,22.667,-0.01,1.4097,1.40973,3.000
3,22.733,0.00,1.3431,1.34310,3.000
3,22.800,0.00,1.2764,1.27640,3.000
3,22.867,0.00,1.2098,1.20983,3.000
3,22.933,0.00,1.1433,1.14330,3.000
3,23.000,0.00,1.0765,1.07650,3.000
3,23.067,0.00,1.0098,1.00977,3.000
3,23.133,0.00,0.9431,0.94313,3.000
3,23.200,0.00,0.8765,0.87650,3.000
3,23.267,0.00,0.8097,0.80973,3.000
3,23.333,0.00,0.7432,0.74317,3.000
3,23.400,0.00,0.6764,0.67640,3.000
3,23.467,0.00,0.6097,0.60973,3.000
3,23.533,0.00,0.5432,0.54320,3.000
3,23.600,0.00,0.4764,0.47640,3.000
3,23.667,0.00,0.4097,0.40973,3.000
3,23.733,0.00,0.3431,0.34310,3.000
3,23.800,-0.01,0.2764,0.27640,3.000
3,23.867,0.00,0.2096,0.20963,3.000
3,23.933,0.00,0.1430,0.14303,3.000
3,24.000,0.00,0.0762,0.07620,3.000
3,24.067,0.00,0.0096,0.00963,3.000
3,24.200,0.00,-0.0233,-0.02330,3.000
3,24.267,0.00,-0.0003,-0.00027,3.000
3,24.333,0.00,-0.0002,-0.00020,3.000
3,24.400,0.00,-0.0002,-0.00020,3.000
3,24.467,0.00,-0.0002,-0.00020,3.000
3,24.533,0.00,-0.0002,-0.00020,3.000
3,24.600,0.00,-0.0002,-0.00020,3.000
3,24.667,0.00,-0.0002,-0.00020,3.000
3,24.733,0.00,-0.0002,-0.00020,3.000
3,24.800,0.00,-0.0002,-0.00020,3.000
3,24.867,-0.01,-0.0002,-0.00020,3.000
3,24.933,0.00,-0.0002,-0.00020,3.000
3,25.000,-0.01,-0.0002,-0.00020,3.000
3,25.067,-0.01,-0.0002,-0.00020,3.000
3,25.133,0.00,-0.0002,-0.00020,3.000
3,25.200,0.00,-0.0002,-0.00020,3.000
3,25.267,0.00,-0.0002,-0.00020,3.000
3,25.333,-0.01,-0.0002,-0.00020,3.000
3,25.400,0.00,-0.0002,-0.00020,3.000
3,25.467,-0.01,-0.0002,-0.00020,3.000
3,25.533,-0.01,-0.0002,-0.00020,3.000
3,25.600,-0.01,-0.0002,-0.00020,3.000
3,25.667,-0.01,-0.0002,-0.00020,3.000
3,25.733,-0.01,-0.0002,-0.00020,3.000
3,25.800,0.00,-0.0002,-0.00020,3.000
3,25.867,0.00,-0.0002,-0.00020,3.000
3,25.933,0.00,-0.0002,-0.00020,3.000
3,26.000,0.00,-0.0002,-0.00020,3.000
3,26.067,-0.01,-0.0002,-0.00020,3.000
3,26.133,0.00,-0.0002,-0.00020,3.000
3,26.200,0.00,-0.0002,-0.00020,3.000
3,26.267,0.00,-0.0002,-0.00020,3.000
3,26.333,-0.01,-0.0002,-0.00020,3.000
3,26.400,-0.01,-0.0002,-0.00020,3.000
3,26.467,0.00,-0.0002,-0.00020,3.000
3,26.533,0.00,-0.0002,-0.00020,3.000
3,26.600,0.00,-0.0002,-0.00020,3.000
3,26.667,-0.01,-0.0002,-0.00020,3.000
3,26.733,0.00,-0.0002,-0.00020,3.000
3,26.800,0.00,-0.0001,-0.00010,3.000
3,26.867,-0.01,-0.0001,-0.00010,3.000
3,26.933,0.00,-0.0001,-0.00010,3.000
3,27.000,0.00,-0.0001,-0.00010,3.000
3,27.067,0.00,-0.0001,-0.00010,3.000
3,27.133,0.00,-0.0001,-0.00010,3.000
3,27.267,0.00,-0.0001,-0.00010,3.000
3,27.333,0.00,-0.0001,-0.00010,3.000
3,27.400,0.00,-0.0001,-0.00010,3.000
3,27.467,0.00,-0.0001,-0.00010,3.000
3,27.533,0.00,-0.0001,-0.00010,3.000
3,27.600,0.00,-0.0001,-0.00010,3.000
3,27.667,0.00,-0.0001,-0.00010,3.000
3,27.733,0.00,-0.0001,-0.00010,3.000
3,27.800,0.00,-0.0001,-0.00010,3.000
3,27.867,0.00,-0.0001,-0.00010,3.000
3,27.933,-0.01,-0.0001,-0.00010,3.000
3,28.000,0.00,-0.0001,-0.00010,3.000
3,28.067,0.00,-0.0001,-0.00010,3.000
3,28.133,0.00,-0.0001,-0.00010,3.000
3,28.200,0.00,-0.0001,-0.00010,3.000
4,28.400,0.00,0.0486,0.04870,4.000
4,28.467,0.00,0.1152,0.11530,4.000
4,28.533,0.00,0.1819,0.18203,4.000
4,28.600,0.01,0.2486,0.24870,4.000
4,28.667,0.00,0.3155,0.31557,4.000
4,28.733,0.00,0.3821,0.38220,4.000
4,28.800,0.00,0.4486,0.44870,4.000
4,28.867,0.00,0.5154,0.51550,4.000
4,28.933,0.00,0.5822,0.58227,4.000
4,29.000,0.00,0.6486,0.64870,4.000
4,29.067,0.01,0.7154,0.71553,4.000
4,29.133,0.00,0.7821,0.78220,4.000
4,29.200,0.00,0.8488,0.84890,4.000
4,29.267,0.00,0.9154,0.91553,4.000
4,29.333,0.00,0.9821,0.98223,4.000
4,29.400,0.00,1.0487,1.04880,4.000
4,29.467,0.00,1.1156,1.11570,4.000
4,29.533,0.01,1.1822,1.18233,4.000
4,29.600,0.00,1.2487,1.24880,4.000
4,29.667,0.00,1.3155,1.31557,4.000
4,29.733,0.00,1.3821,1.38223,4.000
4,29.800,0.01,1.4486,1.44870,4.000
4,29.867,0.00,1.5154,1.51553,4.000
4,29.933,0.00,1.5820,1.58210,4.000
4,30.000,0.01,1.6487,1.64880,4.000
4,30.067,0.00,1.7155,1.71563,4.000
4,30.133,0.01,1.7821,1.78220,4.000
4,30.200,0.00,1.8487,1.84880,4.000
4,30.267,0.01,1.9155,1.91563,4.000
4,30.333,0.03,1.9822,1.98233,4.000
4,30.400,0.06,2.0488,2.04890,4.000
4,30.467,0.11,2.1155,2.11563,4.000
4,30.533,0.20,2.1821,2.18217,4.000
4,30.600,0.32,2.2488,2.24890,4.000
4,30.667,0.47,2.3155,2.31560,4.000
4,30.733,0.65,2.3822,2.38233,4.000
4,30.800,0.86,2.4488,2.44890,4.000
4,30.867,1.10,2.5156,2.51570,4.000
4,31.000,1.04,2.4895,2.48960,4.000
4,31.067,0.77,2.4229,2.42303,4.000
4,31.133,0.55,2.3563,2.35640,4.000
4,31.200,0.37,2.2894,2.28950,4.000
4,31.267,0.23,2.2228,2.22290,4.000
4,31.333,0.13,2.1562,2.15627,4.000
4,31.400,0.07,2.0894,2.08950,4.000
4,31.467,0.03,2.0229,2.02300,4.000
4,31.533,0.01,1.9563,1.95637,4.000
4,31.600,0.00,1.8893,1.88940,4.000
4,31.667,0.01,1.8228,1.82293,4.000
4,31.733,0.01,1.7563,1.75637,4.000
4,31.800,0.00,1.6894,1.68950,4.000
4,31.867,0.00,1.6228,1.62290,4.000
4,31.933,0.01,1.5561,1.55620,4.000
4,32.000,0.00,1.4893,1.48940,4.000
4,32.067,0.00,1.4228,1.42293,4.000
4,32.133,0.00,1.3561,1.35617,4.000
4,32.200,0.00,1.2892,1.28930,4.000
4,32.267,0.00,1.2229,1.22303,4.000
4,32.333,0.00,1.1562,1.15633,4.000
4,32.400,0.00,1.0894,1.08950,4.000
4,32.467,0.00,1.0228,1.02290,4.000
4,32.533,0.00,0.9560,0.95613,4.000
4,32.600,0.01,0.8893,0.88940,4.000
4,32.667,0.00,0.8228,0.82293,4.000
4,32.733,0.00,0.7561,0.75620,4.000
4,32.800,0.00,0.6894,0.68950,4.000
4,32.867,0.00,0.6228,0.62287,4.000
4,32.933,0.00,0.5561,0.55620,4.000
4,33.000,0.01,0.4893,0.48940,4.000
4,33.067,0.00,0.4228,0.42290,4.000
4,33.133,0.00,0.3561,0.35623,4.000
4,33.200,0.00,0.2893,0.28940,4.000
4,33.267,0.00,0.2228,0.22290,4.000
4,33.333,0.00,0.1560,0.15610,4.000
4,33.400,0.00,0.0892,0.08930,4.000
4,33.467,0.00,0.0228,0.02287,4.000
4,33.600,0.00,-0.0111,-0.01100,4.000
4,33.667,0.01,-0.0002,-0.00010,4.000
4,33.733,0.00,-0.0002,-0.00010,4.000
4,33.800,0.00,-0.0002,-0.00010,4.000
4,33.867,0.00,-0.0002,-0.00010,4.000
4,33.933,0.00,-0.0002,-0.00010,4.000
4,34.000,0.01,-0.0002,-0.00010,4.000
4,34.067,0.00,-0.0002,-0.00010,4.000
4,34.133,0.00,-0.0002,-0.00010,4.000
4,34.200,0.00,-0.0002,-0.00010,4.000
4,34.267,0.00,-0.0002,-0.00010,4.000
4,34.333,0.00,-0.0002,-0.00010,4.000
4,34.400,0.00,-0.0002,-0.00010,4.000
4,34.467,0.00,-0.0002,-0.00010,4.000
4,34.533,0.00,-0.0002,-0.00010,4.000
4,34.600,0.00,-0.0002,-0.00010,4.000
4,34.667,0.00,-0.0002,-0.00010,4.000
4,34.733,0.00,-0.0002,-0.00010,4.000
4,34.800,0.00,-0.0002,-0.00010,4.000
4,34.867,0.00,-0.0002,-0.00010,4.000
4,34.933,0.00,-0.0002,-0.00010,4.000
4,35.000,0.00,-0.0002,-0.00010,4.000
4,35.067,0.00,-0.0002,-0.00010,4.000
4,35.133,0.00,-0.0002,-0.00010,4.000
4,35.200,0.01,-0.0002,-0.00010,4.000
4,35.267,0.00,-0.0002,-0.00010,4.000
4,35.333,0.01,-0.0002,-0.00010,4.000
4,35.400,0.00,-0.0002,-0.00010,4.000
4,35.467,0.00,-0.0002,-0.00010,4.000
4,35.533,0.00,-0.0002,-0.00010,4.000
4,35.600,0.00,-0.0002,-0.00010,4.000
4,35.667,0.00,-0.0001,0.00000,4.000
4,35.733,0.01,-0.0001,0.00000,4.000
4,35.800,0.00,-0.0001,0.00000,4.000
4,35.867,0.00,-0.0001,0.00000,4.000
4,35.933,0.00,-0.0001,0.00000,4.000
4,36.000,0.00,-0.0001,0.00000,4.000
4,36.067,0.00,-0.0001,0.00000,4.000
4,36.133,0.00,-0.0001,0.00000,4.000
4,36.200,0.00,-0.0001,0.00000,4.000
4,36.267,0.00,-0.0001,0.00000,4.000
4,36.333,0.01,-0.0001,0.00000,4.000
4,36.400,0.00,-0.0001,0.00000,4.000
4,36.467,0.00,-0.0001,0.00000,4.000
4,36.533,0.00,-0.0001,0.00000,4.000
4,36.600,0.00,-0.0001,0.00000,4.000
4,36.667,0.00,-0.0001,0.00000,4.000
4,36.733,0.00,-0.0001,0.00000,4.000
4,36.800,0.00,-0.0001,0.00000,4.000
4,36.867,0.00,-0.0001,0.00000,4.000
4,36.933,0.01,-0.0001,0.00000,4.000
4,37.000,0.00,-0.0001,0.00000,4.000
4,37.067,0.01,-0.0001,0.00000,4.000
4,37.133,0.01,-0.0001,0.00000,4.000
4,37.200,0.00,-0.0001,0.00000,4.000
4,37.267,0.00,-0.0001,0.00000,4.000
4,37.333,0.00,-0.0001,0.00000,4.000
4,37.400,0.00,-0.0001,0.00000,4.000
4,37.467,0.00,-0.0001,0.00000,4.000
4,37.533,0.00,-0.0001,0.00000,4.000
5,37.867,0.00,0.0852,0.08517,5.000
5,37.933,-0.01,0.1520,0.15197,5.000
5,38.000,-0.01,0.2187,0.21870,5.000
5,38.067,0.00,0.2853,0.28533,5.000
5,38.133,-0.01,0.3522,0.35217,5.000
5,38.200,-0.01,0.4188,0.41880,5.000
5,38.267,-0.01,0.4854,0.48537,5.000
5,38.333,0.00,0.5522,0.55217,5.000
5,38.400,0.00,0.6188,0.61880,5.000
5,38.467,-0.01,0.6854,0.68537,5.000
5,38.533,0.00,0.7522,0.75217,5.000
5,38.600,0.01,0.8187,0.81870,5.000
5,38.667,0.01,0.8853,0.88533,5.000
5,38.733,0.00,0.9521,0.95213,5.000
5,38.800,0.00,1.0189,1.01890,5.000
5,38.867,-0.01,1.0855,1.08547,5.000
5,38.933,0.00,1.1523,1.15230,5.000
5,39.000,-0.01,1.2189,1.21890,5.000
5,39.067,-0.01,1.2854,1.28543,5.000
5,39.133,-0.01,1.3521,1.35210,5.000
5,39.200,-0.01,1.4188,1.41880,5.000
5,39.267,-0.01,1.4853,1.48533,5.000
5,39.333,-0.01,1.5521,1.55210,5.000
5,39.400,-0.01,1.6187,1.61870,5.000
5,39.467,-0.01,1.6855,1.68547,5.000
5,39.533,-0.01,1.7522,1.75223,5.000
5,39.600,-0.01,1.8187,1.81870,5.000
5,39.667,0.00,1.8854,1.88543,5.000
5,39.733,0.01,1.9523,1.95230,5.000
5,39.800,0.03,2.0189,2.01890,5.000
5,39.867,0.07,2.0855,2.08550,5.000
5,39.933,0.14,2.1522,2.15217,5.000
5,40.000,0.25,2.2187,2.21870,5.000
5,40.067,0.39,2.2854,2.28543,5.000
5,40.133,0.56,2.3523,2.35227,5.000
5,40.200,0.75,2.4189,2.41890,5.000
5,40.267,0.98,2.4856,2.48557,5.000
5,40.400,1.09,2.4996,2.49960,5.000
5,40.467,0.80,2.4330,2.43297,5.000
5,40.533,0.57,2.3662,2.36620,5.000
5,40.600,0.39,2.2995,2.29950,5.000
5,40.667,0.24,2.2328,2.23283,5.000
5,40.733,0.13,2.1660,2.16603,5.000
5,40.800,0.06,2.0996,2.09960,5.000
5,40.867,0.02,2.0330,2.03303,5.000
5,40.933,0.00,1.9662,1.96620,5.000
5,41.000,-0.01,1.8996,1.89960,5.000
5,41.067,0.00,1.8329,1.83287,5.000
5,41.133,0.00,1.7661,1.76610,5.000
5,41.200,-0.01,1.6995,1.69950,5.000
5,41.267,0.00,1.6329,1.63287,5.000
5,41.333,0.00,1.5660,1.56603,5.000
5,41.400,-0.01,1.4995,1.49950,5.000
5,41.467,0.00,1.4329,1.43287,5.000
5,41.533,-0.01,1.3659,1.36590,5.000
5,41.600,-0.01,1.2995,1.29950,5.000
5,41.667,-0.01,1.2329,1.23290,5.000
5,41.733,-0.01,1.1661,1.16613,5.000
5,41.800,-0.01,1.0995,1.09950,5.000
5,41.867,-0.01,1.0329,1.03290,5.000
5,41.933,-0.01,0.9660,0.96600,5.000
5,42.000,0.00,0.8995,0.89950,5.000
5,42.067,-0.01,0.8328,0.83283,5.000
5,42.133,-0.01,0.7661,0.76610,5.000
5,42.200,-0.01,0.6995,0.69950,5.000
5,42.267,-0.01,0.6328,0.63280,5.000
5,42.333,-0.01,0.5660,0.56603,5.000
5,42.400,-0.01,0.4995,0.49950,5.000
5,42.467,-0.01,0.4328,0.43277,5.000
5,42.533,-0.01,0.3660,0.36603,5.000
5,42.600,-0.01,0.2995,0.29950,5.000
5,42.667,0.00,0.2327,0.23273,5.000
5,42.733,-0.01,0.1660,0.16597,5.000
5,42.800,-0.01,0.0994,0.09940,5.000
5,42.867,-0.01,0.0327,0.03267,5.000
5,43.000,-0.01,-0.0215,-0.02150,5.000
5,43.067,-0.01,-0.0002,-0.00020,5.000
5,43.133,-0.01,-0.0002,-0.00020,5.000
5,43.200,-0.01,-0.0002,-0.00020,5.000
5,43.267,-0.01,-0.0002,-0.00020,5.000
5,43.333,-0.01,-0.0002,-0.00020,5.000
5,43.400,-0.01,-0.0002,-0.00020,5.000
5,43.467,-0.01,-0.0002,-0.00020,5.000
5,43.533,-0.01,-0.0002,-0.00020,5.000
5,43.600,-0.01,-0.0002,-0.00020,5.000
5,43.667,-0.01,-0.0002,-0.00020,5.000
5,43.733,-0.01,-0.0002,-0.00020,5.000
5,43.800,-0.01,-0.0002,-0.00020,5.000
5,43.867,-0.01,-0.0002,-0.00020,5.000
5,43.933,-0.01,-0.0002,-0.00020,5.000
5,44.000,-0.01,-0.0002,-0.00020,5.000
5,44.067,-0.01,-0.0002,-0.00020,5.000
5,44.133,0.00,-0.0002,-0.00020,5.000
5,44.200,-0.01,-0.0002,-0.00020,5.000
5,44.267,-0.01,-0.0002,-0.00020,5.000
5,44.333,-0.01,-0.0002,-0.00020,5.000
5,44.400,0.00,-0.0002,-0.00020,5.000
5,44.467,-0.01,-0.0002,-0.00020,5.000
5,44.533,-0.01,-0.0002,-0.00020,5.000
5,44.600,0.00,-0.0002,-0.00020,5.000
5,44.667,-0.01,-0.0002,-0.00020,5.000
5,44.733,-0.01,-0.0002,-0.00020,5.000
5,44.800,-0.01,-0.0002,-0.00020,5.000
5,44.867,-0.01,-0.0002,-0.00020,5.000
5,44.933,-0.01,-0.0001,-0.00010,5.000
5,45.000,-0.01,-0.0001,-0.00010,5.000
5,45.067,-0.01,-0.0001,-0.00010,5.000
5,45.133,-0.01,-0.0001,-0.00010,5.000
5,45.200,0.00,-0.0001,-0.00010,5.000
5,45.267,-0.01,-0.0001,-0.00010,5.000
5,45.333,-0.01,-0.0001,-0.00010,5.000
5,45.400,0.00,-0.0001,-0.00010,5.000
5,45.467,-0.01,-0.0001,-0.00010,5.000
5,45.533,0.00,-0.0001,-0.00010,5.000
5,45.600,-0.01,-0.0001,-0.00010,5.000
5,45.667,-0.01,-0.0001,-0.00010,5.000
5,45.733,-0.01,-0.0001,-0.00010,5.000
5,45.800,-0.01,-0.0001,-0.00010,5.000
5,45.867,-0.01,-0.0001,-0.00010,5.000
5,45.933,-0.01,-0.0001,-0.00010,5.000
5,46.067,-0.01,-0.0001,-0.00010,5.000
5,46.133,0.00,-0.0001,-0.00010,5.000
5,46.200,0.00,-0.0001,-0.00010,5.000
5,46.267,0.00,-0.0001,-0.00010,5.000
5,46.333,0.00,-0.0001,-0.00010,5.000
5,46.400,-0.01,-0.0001,-0.00010,5.000
5,46.467,0.00,-0.0001,-0.00010,5.000
5,46.533,0.00,-0.0001,-0.00010,5.000
5,46.600,-0.01,-0.0001,-0.00010,5.000
5,46.667,-0.01,-0.0001,-0.00010,5.000
5,46.733,-0.01,-0.0001,-0.00010,5.000
5,46.800,0.00,-0.0001,-0.00010,5.000
5,46.867,0.00,-0.0001,-0.00010,5.000
5,46.933,-0.01,-0.0001,-0.00010,5.000
6,47.267,0.01,0.1123,0.11227,6.000
6,47.333,0.00,0.1789,0.17893,6.000
6,47.400,0.01,0.2456,0.24560,6.000
6,47.467,0.01,0.3124,0.31243,6.000
6,47.533,0.00,0.3790,0.37903,6.000
6,47.600,0.00,0.4457,0.44570,6.000
6,47.667,0.01,0.5125,0.51247,6.000
6,47.733,0.01,0.5790,0.57903,6.000
6,47.800,0.01,0.6456,0.64560,6.000
6,47.867,0.01,0.7125,0.71247,6.000
6,47.933,0.00,0.7791,0.77910,6.000
6,48.000,0.00,0.8457,0.84570,6.000
6,48.067,0.01,0.9124,0.91240,6.000
6,48.133,0.01,0.9791,0.97907,6.000
6,48.200,0.01,1.0457,1.04570,6.000
6,48.267,0.00,1.1126,1.11257,6.000
6,48.333,0.01,1.1792,1.17923,6.000
6,48.400,0.01,1.2457,1.24570,6.000
6,48.467,0.00,1.3124,1.31243,6.000
6,48.533,0.01,1.3790,1.37900,6.000
6,48.600,0.01,1.4456,1.44560,6.000
6,48.667,0.01,1.5125,1.51250,6.000
6,48.733,0.00,1.5790,1.57903,6.000
6,48.800,0.00,1.6457,1.64570,6.000
6,48.867,0.00,1.7125,1.71253,6.000
6,48.933,0.01,1.7791,1.77913,6.000
6,49.000,0.01,1.8457,1.84570,6.000
6,49.067,0.01,1.9125,1.91253,6.000
6,49.133,0.03,1.9792,1.97920,6.000
6,49.200,0.06,2.0459,2.04590,6.000
6,49.267,0.10,2.1126,2.11257,6.000
6,49.333,0.19,2.1790,2.17903,6.000
6,49.400,0.31,2.2457,2.24570,6.000
6,49.467,0.46,2.3125,2.31250,6.000
6,49.533,0.64,2.3791,2.37910,6.000
6,49.600,0.85,2.4458,2.44580,6.000
6,49.800,0.95,2.4665,2.46650,6.000
6,49.867,0.69,2.4000,2.39997,6.000
6,49.933,0.49,2.3332,2.33317,6.000
6,50.000,0.32,2.2666,2.26660,6.000
6,50.067,0.19,2.1997,2.19973,6.000
6,50.133,0.10,2.1331,2.13310,6.000
6,50.200,0.04,2.0667,2.06670,6.000
6,50.267,0.02,1.9999,1.99990,6.000
6,50.333,0.00,1.9332,1.93317,6.000
6,50.400,0.00,1.8666,1.86660,6.000
6,50.467,0.01,1.7998,1.79983,6.000
6,50.533,0.00,1.7332,1.73320,6.000
6,50.600,0.00,1.6666,1.66660,6.000
6,50.667,0.00,1.5997,1.59973,6.000
6,50.733,0.00,1.5331,1.53307,6.000
6,50.800,0.00,1.4666,1.46660,6.000
6,50.867,0.00,1.3997,1.39970,6.000
6,50.933,0.01,1.3330,1.33303,6.000
6,51.000,0.00,1.2666,1.26660,6.000
6,51.067,0.01,1.1999,1.19987,6.000
6,51.133,0.01,1.1332,1.13320,6.000
6,51.200,0.00,1.0666,1.06660,6.000
6,51.267,0.01,0.9997,0.99973,6.000
6,51.333,0.00,0.9330,0.93303,6.000
6,51.400,0.01,0.8664,0.86640,6.000
6,51.467,0.01,0.7998,0.79977,6.000
6,51.533,0.00,0.7331,0.73310,6.000
6,51.600,0.01,0.6664,0.66640,6.000
6,51.667,0.01,0.5997,0.59970,6.000
6,51.733,0.00,0.5330,0.53300,6.000
6,51.800,0.01,0.4665,0.46650,6.000
6,51.867,0.01,0.3998,0.39977,6.000
6,51.933,0.00,0.3330,0.33303,6.000
6,52.000,0.00,0.2665,0.26650,6.000
6,52.067,0.01,0.1997,0.19970,6.000
6,52.133,0.00,0.1329,0.13290,6.000
6,52.200,0.00,0.0664,0.06640,6.000
6,52.267,0.00,-0.0003,-0.00030,6.000
6,52.400,-0.01,-0.0020,-0.00200,6.000
6,52.467,0.00,-0.0002,-0.00020,6.000
6,52.533,0.00,-0.0002,-0.00020,6.000
6,52.600,0.00,-0.0002,-0.00020,6.000
6,52.667,0.00,-0.0002,-0.00020,6.000
6,52.733,0.00,-0.0002,-0.00020,6.000
6,52.800,0.00,-0.0002,-0.00020,6.000
6,52.867,0.01,-0.0002,-0.00020,6.000
6,52.933,0.00,-0.0002,-0.00020,6.000
6,53.000,0.01,-0.0002,-0.00020,6.000
6,53.067,0.00,-0.0002,-0.00020,6.000
6,53.133,0.00,-0.0002,-0.00020,6.000
6,53.200,0.01,-0.0002,-0.00020,6.000
6,53.267,0.00,-0.0002,-0.00020,6.000
6,53.333,0.00,-0.0002,-0.00020,6.000
6,53.400,0.00,-0.0002,-0.00020,6.000
6,53.467,0.00,-0.0002,-0.00020,6.000
6,53.533,0.01,-0.0002,-0.00020,6.000
6,53.600,0.00,-0.0002,-0.00020,6.000
6,53.667,0.00,-0.0002,-0.00020,6.000
6,53.733,0.01,-0.0002,-0.00020,6.000
6,53.800,0.01,-0.0002,-0.00020,6.000
6,53.867,0.00,-0.0002,-0.00020,6.000
6,53.933,0.00,-0.0002,-0.00020,6.000
6,54.000,0.00,-0.0002,-0.00020,6.000
6,54.067,0.01,-0.0001,-0.00010,6.000
6,54.133,0.00,-0.0001,-0.00010,6.000
6,54.200,0.00,-0.0001,-0.00010,6.000
6,54.267,0.00,-0.0001,-0.00010,6.000
6,54.333,0.01,-0.0001,-0.00010,6.000
6,54.400,0.00,-0.0001,-0.00010,6.000
6,54.467,0.00,-0.0001,-0.00010,6.000
6,54.533,0.00,-0.0001,-0.00010,6.000
6,54.600,0.00,-0.0001,-0.00010,6.000
6,54.667,0.00,-0.0001,-0.00010,6.000
6,54.733,0.00,-0.0001,-0.00010,6.000
6,54.800,0.00,-0.0001,-0.00010,6.000
6,54.867,0.01,-0.0001,-0.00010,6.000
6,54.933,0.00,-0.0001,-0.00010,6.000
6,55.000,0.00,-0.0001,-0.00010,6.000
6,55.067,0.00,-0.0001,-0.00010,6.000
6,55.133,0.00,-0.0001,-0.00010,6.000
6,55.200,0.00,-0.0001,-0.00010,6.000
6,55.267,0.00,-0.0001,-0.00010,6.000
6,55.333,0.01,-0.0001,-0.00010,6.000
6,55.467,0.00,-0.0001,-0.00010,6.000
6,55.533,0.00,-0.0001,-0.00010,6.000
6,55.600,0.00,-0.0001,-0.00010,6.000
6,55.667,0.00,-0.0001,-0.00010,6.000
6,55.733,0.00,-0.0001,-0.00010,6.000
6,55.800,0.01,-0.0001,-0.00010,6.000
6,55.867,0.00,-0.0001,-0.00010,6.000
6,55.933,0.00,-0.0001,-0.00010,6.000
6,56.000,0.00,-0.0001,-0.00010,6.000
6,56.067,0.01,-0.0001,-0.00010,6.000
6,56.133,0.00,-0.0001,-0.00010,6.000
6,56.200,-0.01,-0.0001,-0.00010,6.000
6,56.267,0.00,-0.0001,-0.00010,6.000
6,56.333,0.00,-0.0001,-0.00010,6.000
7,56.600,0.01,0.0687,0.06870,7.000
7,56.667,0.01,0.1352,0.13523,7.000
7,56.733,0.01,0.2020,0.20200,7.000
7,56.800,0.01,0.2688,0.26880,7.000
7,56.867,0.00,0.3354,0.33543,7.000
7,56.933,0.00,0.4020,0.40203,7.000
7,57.000,0.00,0.4688,0.46880,7.000
7,57.067,0.00,0.5354,0.53540,7.000
7,57.133,0.00,0.6021,0.60210,7.000
7,57.200,0.00,0.6689,0.66890,7.000
7,57.267,0.00,0.7354,0.73543,7.000
7,57.333,0.00,0.8021,0.80210,7.000
7,57.400,0.00,0.8688,0.86880,7.000
7,57.467,0.00,0.9354,0.93540,7.000
7,57.533,0.00,1.0021,1.00213,7.000
7,57.600,0.00,1.0689,1.06890,7.000
7,57.667,0.00,1.1355,1.13550,7.000
7,57.733,0.00,1.2022,1.20220,7.000
7,57.800,0.01,1.2689,1.26890,7.000
7,57.867,-0.01,1.3353,1.33533,7.000
7,57.933,0.00,1.4020,1.40203,7.000
7,58.000,0.00,1.4687,1.46870,7.000
7,58.067,0.00,1.5353,1.53533,7.000
7,58.133,0.00,1.6021,1.60213,7.000
7,58.200,0.00,1.6689,1.66890,7.000
7,58.267,0.00,1.7354,1.73543,7.000
7,58.333,0.00,1.8022,1.80217,7.000
7,58.400,0.01,1.8688,1.86880,7.000
7,58.467,0.01,1.9354,1.93543,7.000
7,58.533,0.03,2.0022,2.00220,7.000
7,58.600,0.07,2.0690,2.06900,7.000
7,58.667,0.12,2.1354,2.13543,7.000
7,58.733,0.22,2.2021,2.20210,7.000
7,58.800,0.35,2.2689,2.26890,7.000
7,58.867,0.52,2.3354,2.33540,7.000
7,58.933,0.71,2.4023,2.40227,7.000
7,59.000,0.93,2.4690,2.46900,7.000
7,59.133,1.09,2.4959,2.49593,7.000
7,59.200,0.80,2.4297,2.42970,7.000
7,59.267,0.58,2.3629,2.36290,7.000
7,59.333,0.39,2.2962,2.29620,7.000
7,59.400,0.25,2.2295,2.22950,7.000
7,59.467,0.14,2.1628,2.16283,7.000
7,59.533,0.06,2.0961,2.09613,7.000
7,59.600,0.02,2.0297,2.02970,7.000
7,59.667,0.01,1.9629,1.96290,7.000
7,59.733,0.00,1.8961,1.89613,7.000
7,59.800,-0.01,1.8295,1.82950,7.000
7,59.867,0.00,1.7629,1.76287,7.000
7,59.933,0.00,1.6962,1.69617,7.000
7,60.000,0.01,1.6295,1.62950,7.000
7,60.067,0.00,1.5628,1.56277,7.000
7,60.133,0.00,1.4960,1.49603,7.000
7,60.200,0.00,1.4295,1.42950,7.000
7,60.267,0.00,1.3626,1.36263,7.000
7,60.333,0.00,1.2960,1.29600,7.000
7,60.400,0.01,1.2296,1.22960,7.000
7,60.467,0.00,1.1628,1.16280,7.000
7,60.533,0.00,1.0962,1.09620,7.000
7,60.600,0.00,1.0296,1.02960,7.000
7,60.667,0.00,0.9627,0.96270,7.000
7,60.733,0.00,0.8961,0.89610,7.000
7,60.800,0.00,0.8295,0.82950,7.000
7,60.867,0.00,0.7628,0.76277,7.000
7,60.933,0.00,0.6961,0.69607,7.000
7,61.000,0.01,0.6295,0.62950,7.000
7,61.067,0.00,0.5627,0.56267,7.000
7,61.133,0.00,0.4961,0.49607,7.000
7,61.200,0.01,0.4295,0.42950,7.000
7,61.267,0.00,0.3627,0.36267,7.000
7,61.333,0.00,0.2961,0.29610,7.000
7,61.400,-0.01,0.2294,0.22940,7.000
7,61.467,-0.01,0.1626,0.16260,7.000
7,61.533,-0.01,0.0959,0.09593,7.000
7,61.600,0.00,0.0294,0.02940,7.000
7,61.733,0.01,-0.0181,-0.01807,7.000
7,61.800,0.00,-0.0002,-0.00020,7.000
7,61.867,-0.01,-0.0002,-0.00020,7.000
7,61.933,0.00,-0.0002,-0.00020,7.000
7,62.000,0.01,-0.0002,-0.00020,7.000
7,62.067,0.00,-0.0002,-0.00020,7.000
7,62.133,0.00,-0.0002,-0.00020,7.000
7,62.200,-0.01,-0.0002,-0.00020,7.000
7,62.267,-0.01,-0.0002,-0.00020,7.000
7,62.333,0.01,-0.0002,-0.00020,7.000
7,62.400,0.00,-0.0002,-0.00020,7.000
7,62.467,0.00,-0.0002,-0.00020,7.000
7,62.533,0.00,-0.0002,-0.00020,7.000
7,62.600,0.00,-0.0002,-0.00020,7.000
7,62.667,0.00,-0.0002,-0.00020,7.000
7,62.733,0.00,-0.0002,-0.00020,7.000
7,62.800,0.00,-0.0002,-0.00020,7.000
7,62.867,0.00,-0.0002,-0.00020,7.000
7,62.933,0.00,-0.0002,-0.00020,7.000
7,63.000,0.00,-0.0002,-0.00020,7.000
7,63.067,0.00,-0.0002,-0.00020,7.000
7,63.133,0.00,-0.0002,-0.00020,7.000
7,63.200,0.00,-0.0002,-0.00020,7.000
7,63.267,0.00,-0.0002,-0.00020,7.000
7,63.333,0.00,-0.0001,-0.00010,7.000
7,63.400,0.01,-0.0001,-0.00010,7.000
7,63.467,0.00,-0.0001,-0.00010,7.000
7,63.533,0.00,-0.0001,-0.00010,7.000
7,63.600,0.01,-0.0001,-0.00010,7.000
7,63.667,0.00,-0.0001,-0.00010,7.000
7,63.733,0.00,-0.0001,-0.00010,7.000
7,63.800,0.00,-0.0001,-0.00010,7.000
7,63.867,0.01,-0.0001,-0.00010,7.000
7,63.933,0.00,-0.0001,-0.00010,7.000
7,64.000,0.01,-0.0001,-0.00010,7.000
7,64.067,0.00,-0.0001,-0.00010,7.000
7,64.133,0.00,-0.0001,-0.00010,7.000
7,64.200,0.00,-0.0001,-0.00010,7.000
7,64.267,0.00,-0.0001,-0.00010,7.000
7,64.333,0.00,-0.0001,-0.00010,7.000
7,64.400,0.00,-0.0001,-0.00010,7.000
7,64.467,0.00,-0.0001,-0.00010,7.000
7,64.533,0.00,-0.0001,-0.00010,7.000
7,64.600,0.00,-0.0001,-0.00010,7.000
7,64.667,0.00,-0.0001,-0.00010,7.000
7,64.800,0.00,-0.0001,-0.00010,7.000
7,64.867,0.00,-0.0001,-0.00010,7.000
7,64.933,0.00,-0.0001,-0.00010,7.000
7,65.000,0.01,-0.0001,-0.00010,7.000
7,65.067,0.00,-0.0001,-0.00010,7.000
7,65.133,0.00,-0.0001,-0.00010,7.000
7,65.200,0.01,-0.0001,-0.00010,7.000
7,65.267,0.00,-0.0001,-0.00010,7.000
7,65.333,0.00,-0.0001,-0.00010,7.000
7,65.400,0.00,-0.0001,-0.00010,7.000
7,65.467,0.00,-0.0001,-0.00010,7.000
7,65.533,0.00,-0.0001,-0.00010,7.000
7,65.600,0.00,-0.0001,-0.00010,7.000
7,65.667,0.00,-0.0001,-0.00010,7.000
7,65.733,0.00,-0.0001,-0.00010,7.000
8,66.000,-0.01,0.1045,0.10450,8.000
8,66.067,-0.01,0.1712,0.17117,8.000
8,66.133,-0.01,0.2381,0.23807,8.000
8,66.200,-0.01,0.3047,0.30470,8.000
8,66.267,-0.01,0.3713,0.37133,8.000
8,66.333,-0.01,0.4381,0.43807,8.000
8,66.400,-0.01,0.5048,0.50480,8.000
8,66.467,-0.01,0.5714,0.57140,8.000
8,66.533,-0.01,0.6382,0.63817,8.000
8,66.600,-0.01,0.7047,0.70470,8.000
8,66.667,0.00,0.7714,0.77140,8.000
8,66.733,0.00,0.8381,0.83810,8.000
8,66.800,0.00,0.9048,0.90480,8.000
8,66.867,-0.01,0.9713,0.97133,8.000
8,66.933,-0.01,1.0381,1.03813,8.000
8,67.000,-0.01,1.1049,1.10490,8.000
8,67.067,0.00,1.1715,1.17150,8.000
8,67.133,-0.01,1.2382,1.23820,8.000
8,67.200,-0.01,1.3047,1.30470,8.000
8,67.267,-0.01,1.3713,1.37127,8.000
8,67.333,0.00,1.4381,1.43810,8.000
8,67.400,-0.01,1.5048,1.50480,8.000
8,67.467,0.00,1.5713,1.57130,8.000
8,67.533,-0.01,1.6382,1.63817,8.000
8,67.600,-0.01,1.7048,1.70480,8.000
8,67.667,0.00,1.7714,1.77140,8.000
8,67.733,-0.01,1.8382,1.83820,8.000
8,67.800,0.00,1.9048,1.90480,8.000
8,67.867,0.02,1.9715,1.97147,8.000
8,67.933,0.04,2.0383,2.03830,8.000
8,68.000,0.09,2.1049,2.10490,8.000
8,68.067,0.17,2.1714,2.17137,8.000
8,68.133,0.29,2.2382,2.23820,8.000
8,68.200,0.44,2.3048,2.30480,8.000
8,68.267,0.61,2.3715,2.37150,8.000
8,68.333,0.82,2.4383,2.43830,8.000
8,68.400,1.05,2.5049,2.50490,8.000
8,68.533,1.05,2.4920,2.49200,8.000
8,68.600,0.77,2.4256,2.42560,8.000
8,68.667,0.55,2.3590,2.35897,8.000
8,68.733,0.37,2.2921,2.29213,8.000
8,68.800,0.22,2.2255,2.22550,8.000
8,68.867,0.12,2.1589,2.15887,8.000
8,68.933,0.05,2.0921,2.09210,8.000
8,69.000,0.02,2.0257,2.02570,8.000
8,69.067,0.00,1.9590,1.95897,8.000
8,69.133,0.00,1.8921,1.89210,8.000
8,69.200,0.00,1.8255,1.82550,8.000
8,69.267,0.00,1.7588,1.75883,8.000
8,69.333,0.00,1.6921,1.69210,8.000
8,69.400,-0.01,1.6254,1.62540,8.000
8,69.467,0.00,1.5588,1.55880,8.000
8,69.533,0.00,1.4921,1.49210,8.000
8,69.600,-0.01,1.4255,1.42550,8.000
8,69.667,-0.01,1.3588,1.35877,8.000
8,69.733,0.00,1.2921,1.29207,8.000
8,69.800,0.00,1.2257,1.22570,8.000
8,69.867,0.00,1.1589,1.15890,8.000
8,69.933,0.00,1.0922,1.09217,8.000
8,70.000,0.00,1.0255,1.02550,8.000
8,70.067,-0.01,0.9588,0.95880,8.000
8,70.133,-0.01,0.8920,0.89197,8.000
8,70.200,0.00,0.8255,0.82550,8.000
8,70.267,0.00,0.7588,0.75883,8.000
8,70.333,0.00,0.6921,0.69210,8.000
8,70.400,0.00,0.6256,0.62560,8.000
8,70.467,0.00,0.5588,0.55877,8.000
8,70.533,-0.01,0.4921,0.49207,8.000
8,70.600,0.00,0.4254,0.42540,8.000
8,70.667,0.00,0.3587,0.35873,8.000
8,70.733,0.00,0.2920,0.29200,8.000
8,70.800,-0.01,0.2255,0.22550,8.000
8,70.867,-0.01,0.1586,0.15863,8.000
8,70.933,-0.01,0.0919,0.09187,8.000
8,71.000,0.00,0.0253,0.02530,8.000
8,71.133,-0.01,-0.0412,-0.04123,8.000
8,71.200,-0.01,0.0001,0.00010,8.000
8,71.267,-0.01,-0.0002,-0.00020,8.000
8,71.333,-0.01,-0.0002,-0.00020,8.000
8,71.400,0.00,-0.0002,-0.00020,8.000
8,71.467,-0.01,-0.0002,-0.00020,8.000
8,71.533,-0.01,-0.0002,-0.00020,8.000
8,71.600,0.00,-0.0002,-0.00020,8.000
8,71.667,0.00,-0.0002,-0.00020,8.000
8,71.733,0.00,-0.0002,-0.00020,8.000
8,71.800,0.00,-0.0002,-0.00020,8.000
8,71.867,0.00,-0.0002,-0.00020,8.000
8,71.933,0.00,-0.0002,-0.00020,8.000
8,72.000,-0.01,-0.0002,-0.00020,8.000
8,72.067,0.00,-0.0002,-0.00020,8.000
8,72.133,-0.01,-0.0002,-0.00020,8.000
8,72.200,0.00,-0.0002,-0.00020,8.000
8,72.267,0.00,-0.0002,-0.00020,8.000
8,72.333,0.00,-0.0002,-0.00020,8.000
8,72.400,0.00,-0.0002,-0.00020,8.000
8,72.467,0.00,-0.0002,-0.00020,8.000
8,72.533,-0.01,-0.0002,-0.00020,8.000
8,72.600,0.00,-0.0002,-0.00020,8.000
8,72.667,0.00,-0.0002,-0.00020,8.000
8,72.733,0.00,-0.0002,-0.00020,8.000
8,72.800,-0.01,-0.0001,-0.00010,8.000
8,72.867,-0.01,-0.0001,-0.00010,8.000
8,72.933,0.00,-0.0001,-0.00010,8.000
8,73.000,0.01,-0.0001,-0.00010,8.000
8,73.067,-0.01,-0.0001,-0.00010,8.000
8,73.133,-0.01,-0.0001,-0.00010,8.000
8,73.200,-0.01,-0.0001,-0.00010,8.000
8,73.267,-0.01,-0.0001,-0.00010,8.000
8,73.333,-0.01,-0.0001,-0.00010,8.000
8,73.400,-0.01,-0.0001,-0.00010,8.000
8,73.467,0.00,-0.0001,-0.00010,8.000
8,73.533,0.00,-0.0001,-0.00010,8.000
8,73.600,-0.01,-0.0001,-0.00010,8.000
8,73.667,-0.01,-0.0001,-0.00010,8.000
8,73.733,-0.01,-0.0001,-0.00010,8.000
8,73.800,-0.01,-0.0001,-0.00010,8.000
8,73.867,0.00,-0.0001,-0.00010,8.000
8,73.933,-0.01,-0.0001,-0.00010,8.000
8,74.000,0.00,-0.0001,-0.00010,8.000
8,74.067,0.00,-0.0001,-0.00010,8.000
8,74.267,-0.01,-0.0001,-0.00010,8.000
8,74.333,0.00,-0.0001,-0.00010,8.000
8,74.400,-0.01,-0.0001,-0.00010,8.000
8,74.467,-0.01,-0.0001,-0.00010,8.000
8,74.533,0.00,-0.0001,-0.00010,8.000
8,74.600,-0.01,-0.0001,-0.00010,8.000
8,74.667,-0.01,-0.0001,-0.00010,8.000
8,74.733,0.00,-0.0001,-0.00010,8.000
8,74.800,-0.01,-0.0001,-0.00010,8.000
8,74.867,-0.01,-0.0001,-0.00010,8.000
8,74.933,-0.01,-0.0001,-0.00010,8.000
8,75.000,0.00,-0.0001,-0.00010,8.000
8,75.067,-0.01,-0.0001,-0.00010,8.000
8,75.133,-0.01,-0.0001,-0.00010,8.000
9,75.400,0.00,0.1045,0.10450,9.000
9,75.467,0.00,0.1712,0.17117,9.000
9,75.533,0.00,0.2380,0.23803,9.000
9,75.600,0.00,0.3047,0.30470,9.000
9,75.667,0.00,0.3713,0.37133,9.000
9,75.733,0.00,0.4381,0.43807,9.000
9,75.800,0.00,0.5047,0.50470,9.000
9,75.867,0.00,0.5713,0.57133,9.000
9,75.933,0.00,0.6381,0.63810,9.000
9,76.000,0.00,0.7047,0.70470,9.000
9,76.067,0.00,0.7714,0.77140,9.000
9,76.133,0.00,0.8381,0.83813,9.000
9,76.200,0.00,0.9047,0.90470,9.000
9,76.267,0.00,0.9714,0.97137,9.000
9,76.333,0.00,1.0381,1.03810,9.000
9,76.400,0.00,1.1048,1.10480,9.000
9,76.467,0.00,1.1715,1.17153,9.000
9,76.533,0.00,1.2382,1.23820,9.000
9,76.600,0.00,1.3048,1.30480,9.000
9,76.667,0.00,1.3712,1.37123,9.000
9,76.733,0.00,1.4381,1.43807,9.000
9,76.800,0.00,1.5047,1.50470,9.000
9,76.867,0.00,1.5713,1.57133,9.000
9,76.933,0.00,1.6382,1.63820,9.000
9,77.000,-0.01,1.7049,1.70490,9.000
9,77.067,0.00,1.7714,1.77143,9.000
9,77.133,0.01,1.8381,1.83813,9.000
9,77.200,0.00,1.9049,1.90490,9.000
9,77.267,0.02,1.9714,1.97140,9.000
9,77.333,0.05,2.0383,2.03830,9.000
9,77.400,0.10,2.1048,2.10480,9.000
9,77.467,0.18,2.1713,2.17133,9.000
9,77.533,0.29,2.2382,2.23817,9.000
9,77.600,0.44,2.3049,2.30490,9.000
9,77.667,0.62,2.3714,2.37140,9.000
9,77.733,0.82,2.4382,2.43823,9.000
9,77.800,1.05,2.5049,2.50490,9.000
9,77.933,1.06,2.4920,2.49203,9.000
9,78.000,0.78,2.4256,2.42560,9.000
9,78.067,0.56,2.3590,2.35897,9.000
9,78.133,0.37,2.2921,2.29210,9.000
9,78.200,0.21,2.2255,2.22550,9.000
9,78.267,0.13,2.1588,2.15880,9.000
9,78.333,0.06,2.0921,2.09210,9.000
9,78.400,0.03,2.0256,2.02560,9.000
9,78.467,0.00,1.9589,1.95890,9.000
9,78.533,0.00,1.8920,1.89203,9.000
9,78.600,0.00,1.8256,1.82560,9.000
9,78.667,0.00,1.7589,1.75890,9.000
9,78.733,0.01,1.6921,1.69210,9.000
9,78.800,0.01,1.6256,1.62560,9.000
9,78.867,0.00,1.5588,1.55880,9.000
9,78.933,0.00,1.4921,1.49207,9.000
9,79.000,-0.01,1.4256,1.42560,9.000
9,79.067,0.00,1.3587,1.35870,9.000
9,79.133,0.00,1.2921,1.29210,9.000
9,79.200,-0.01,1.2255,1.22550,9.000
9,79.267,0.00,1.1589,1.15890,9.000
9,79.333,0.00,1.0921,1.09213,9.000
9,79.400,0.01,1.0255,1.02550,9.000
9,79.467,0.00,0.9587,0.95873,9.000
9,79.533,0.00,0.8920,0.89203,9.000
9,79.600,0.00,0.8256,0.82560,9.000
9,79.667,0.00,0.7588,0.75877,9.000
9,79.733,0.00,0.6921,0.69207,9.000
9,79.800,0.00,0.6255,0.62550,9.000
9,79.867,0.00,0.5588,0.55877,9.000
9,79.933,0.00,0.4920,0.49203,9.000
9,80.000,0.00,0.4254,0.42540,9.000
9,80.067,0.00,0.3588,0.35877,9.000
9,80.133,0.00,0.2920,0.29203,9.000
9,80.200,0.00,0.2255,0.22550,9.000
9,80.267,0.00,0.1587,0.15867,9.000
9,80.333,0.00,0.0918,0.09180,9.000
9,80.400,0.00,0.0255,0.02550,9.000
9,80.533,0.00,-0.0412,-0.04120,9.000
9,80.600,0.00,0.0000,0.00000,9.000
9,80.667,0.00,-0.0002,-0.00020,9.000
9,80.733,0.00,-0.0002,-0.00020,9.000
9,80.800,-0.01,-0.0002,-0.00020,9.000
9,80.867,0.00,-0.0002,-0.00020,9.000
9,80.933,0.00,-0.0002,-0.00020,9.000
9,81.000,0.00,-0.0002,-0.00020,9.000
9,81.067,0.01,-0.0002,-0.00020,9.000
9,81.133,0.00,-0.0002,-0.00020,9.000
9,81.200,0.01,-0.0002,-0.00020,9.000
9,81.267,0.00,-0.0002,-0.00020,9.000
9,81.333,0.00,-0.0002,-0.00020,9.000
9,81.400,0.00,-0.0002,-0.00020,9.000
9,81.467,0.00,-0.0002,-0.00020,9.000
9,81.533,0.00,-0.0002,-0.00020,9.000
9,81.600,0.01,-0.0002,-0.00020,9.000
9,81.667,0.00,-0.0002,-0.00020,9.000
9,81.733,0.00,-0.0002,-0.00020,9.000
9,81.800,0.01,-0.0002,-0.00020,9.000
9,81.867,0.00,-0.0002,-0.00020,9.000
9,81.933,0.00,-0.0002,-0.00020,9.000
9,82.000,0.01,-0.0002,-0.00020,9.000
9,82.067,0.01,-0.0001,-0.00010,9.000
9,82.133,0.00,-0.0001,-0.00010,9.000
9,82.200,-0.01,-0.0001,-0.00010,9.000
9,82.267,-0.01,-0.0001,-0.00010,9.000
9,82.333,0.00,-0.0001,-0.00010,9.000
9,82.400,0.00,-0.0001,-0.00010,9.000
9,82.467,0.00,-0.0001,-0.00010,9.000
9,82.533,0.01,-0.0001,-0.00010,9.000
9,82.600,0.01,-0.0001,-0.00010,9.000
9,82.667,0.00,-0.0001,-0.00010,9.000
9,82.733,0.00,-0.0001,-0.00010,9.000
9,82.800,0.00,-0.0001,-0.00010,9.000
9,82.867,0.00,-0.0001,-0.00010,9.000
9,82.933,0.00,-0.0001,-0.00010,9.000
9,83.000,0.00,-0.0001,-0.00010,9.000
9,83.067,0.00,-0.0001,-0.00010,9.000
9,83.133,0.00,-0.0001,-0.00010,9.000
9,83.200,0.00,-0.0001,-0.00010,9.000
9,83.267,0.00,-0.0001,-0.00010,9.000
9,83.333,0.00,-0.0001,-0.00010,9.000
9,83.400,0.00,-0.0001,-0.00010,9.000
9,83.467,0.00,-0.0001,-0.00010,9.000
9,83.667,0.00,-0.0001,-0.00010,9.000
9,83.733,0.00,-0.0001,-0.00010,9.000
9,83.800,0.00,-0.0001,-0.00010,9.000
9,83.867,0.00,-0.0001,-0.00010,9.000
9,83.933,0.01,-0.0001,-0.00010,9.000
9,84.000,0.00,-0.0001,-0.00010,9.000
9,84.067,0.00,-0.0001,-0.00010,9.000
9,84.133,0.00,-0.0001,-0.00010,9.000
9,84.200,0.00,-0.0001,-0.00010,9.000
9,84.267,0.01,-0.0001,-0.00010,9.000
9,84.333,0.01,-0.0001,-0.00010,9.000
9,84.400,0.00,-0.0001,-0.00010,9.000
9,84.467,0.00,-0.0001,-0.00010,9.000
9,84.533,0.00,-0.0001,-0.00010,9.000
10,84.800,-0.01,0.1146,0.11460,10.000
10,84.867,0.00,0.1813,0.18127,10.000
10,84.933,-0.01,0.2479,0.24793,10.000
10,85.000,0.00,0.3149,0.31490,10.000
10,85.067,-0.01,0.3813,0.38130,10.000
10,85.133,-0.01,0.4480,0.44797,10.000
10,85.200,0.00,0.5148,0.51480,10.000
10,85.267,-0.01,0.5815,0.58147,10.000
10,85.333,-0.01,0.6480,0.64803,10.000
10,85.400,-0.01,0.7149,0.71490,10.000
10,85.467,-0.02,0.7814,0.78140,10.000
10,85.533,0.00,0.8480,0.84797,10.000
10,85.600,-0.01,0.9148,0.91480,10.000
10,85.667,-0.01,0.9814,0.98143,10.000
10,85.733,-0.02,1.0481,1.04807,10.000
10,85.800,-0.01,1.1148,1.11480,10.000
10,85.867,-0.01,1.1815,1.18150,10.000
10,85.933,-0.01,1.2482,1.24817,10.000
10,86.000,-0.02,1.3148,1.31480,10.000
10,86.067,-0.01,1.3813,1.38127,10.000
10,86.133,-0.01,1.4480,1.44800,10.000
10,86.200,-0.01,1.5148,1.51480,10.000
10,86.267,-0.01,1.5814,1.58137,10.000
10,86.333,0.00,1.6481,1.64807,10.000
10,86.400,-0.01,1.7149,1.71490,10.000
10,86.467,-0.01,1.7814,1.78140,10.000
10,86.533,-0.01,1.8481,1.84807,10.000
10,86.600,0.00,1.9149,1.91490,10.000
10,86.667,0.02,1.9815,1.98147,10.000
10,86.733,0.05,2.0482,2.04817,10.000
10,86.800,0.10,2.1148,2.11480,10.000
10,86.867,0.19,2.1814,2.18140,10.000
10,86.933,0.31,2.2481,2.24810,10.000
10,87.000,0.46,2.3149,2.31490,10.000
10,87.067,0.64,2.3815,2.38150,10.000
10,87.133,0.84,2.4482,2.44823,10.000
10,87.200,1.10,2.5149,2.51490,10.000
10,87.333,1.01,2.4822,2.48220,10.000
10,87.400,0.75,2.4154,2.41540,10.000
10,87.467,0.52,2.3490,2.34900,10.000
10,87.533,0.35,2.2822,2.28220,10.000
10,87.600,0.21,2.2153,2.21530,10.000
10,87.667,0.10,2.1489,2.14890,10.000
10,87.733,0.05,2.0823,2.08227,10.000
10,87.800,0.01,2.0155,2.01550,10.000
10,87.867,0.00,1.9489,1.94893,10.000
10,87.933,-0.01,1.8822,1.88220,10.000
10,88.000,-0.01,1.8154,1.81540,10.000
10,88.067,-0.01,1.7489,1.74890,10.000
10,88.133,-0.01,1.6822,1.68220,10.000
10,88.200,0.00,1.6153,1.61530,10.000
10,88.267,-0.01,1.5488,1.54883,10.000
10,88.333,-0.01,1.4822,1.48217,10.000
10,88.400,-0.01,1.4154,1.41540,10.000
10,88.467,-0.01,1.3487,1.34873,10.000
10,88.533,-0.01,1.2821,1.28213,10.000
10,88.600,-0.01,1.2155,1.21550,10.000
10,88.667,-0.01,1.1490,1.14897,10.000
10,88.733,-0.01,1.0821,1.08213,10.000
10,88.800,-0.01,1.0154,1.01540,10.000
10,88.867,-0.01,0.9488,0.94883,10.000
10,88.933,-0.01,0.8820,0.88197,10.000
10,89.000,-0.01,0.8155,0.81550,10.000
10,89.067,-0.01,0.7488,0.74877,10.000
10,89.133,-0.01,0.6821,0.68210,10.000
10,89.200,0.00,0.6154,0.61540,10.000
10,89.267,-0.01,0.5488,0.54877,10.000
10,89.333,0.00,0.4821,0.48210,10.000
10,89.400,-0.01,0.4153,0.41530,10.000
10,89.467,0.00,0.3489,0.34887,10.000
10,89.533,-0.01,0.2821,0.28210,10.000
10,89.600,-0.01,0.2153,0.21530,10.000
10,89.667,0.00,0.1487,0.14873,10.000
10,89.733,-0.01,0.0818,0.08183,10.000
10,89.800,-0.01,0.0154,0.01540,10.000
10,89.933,-0.01,-0.0339,-0.03387,10.000
10,90.000,-0.01,-0.0003,-0.00030,10.000
10,90.067,-0.01,-0.0002,-0.00020,10.000
10,90.133,-0.01,-0.0002,-0.00020,10.000
10,90.200,-0.01,-0.0002,-0.00020,10.000
10,90.267,-0.01,-0.0002,-0.00020,10.000
10,90.333,-0.01,-0.0002,-0.00020,10.000
10,90.400,-0.01,-0.0002,-0.00020,10.000
10,90.467,-0.01,-0.0002,-0.00020,10.000
10,90.533,-0.01,-0.0002,-0.00020,10.000
10,90.600,-0.01,-0.0002,-0.00020,10.000
10,90.667,0.00,-0.0002,-0.00020,10.000
10,90.733,-0.01,-0.0002,-0.00020,10.000
10,90.800,-0.01,-0.0002,-0.00020,10.000
10,90.867,-0.01,-0.0002,-0.00020,10.000
10,90.933,-0.01,-0.0002,-0.00020,10.000
10,91.000,-0.01,-0.0002,-0.00020,10.000
10,91.067,-0.01,-0.0002,-0.00020,10.000
10,91.133,-0.01,-0.0002,-0.00020,10.000
10,91.200,0.00,-0.0002,-0.00020,10.000
10,91.267,-0.01,-0.0002,-0.00020,10.000
10,91.333,0.00,-0.0002,-0.00020,10.000
10,91.400,-0.01,-0.0002,-0.00020,10.000
10,91.467,0.00,-0.0002,-0.00020,10.000
10,91.533,-0.01,-0.0002,-0.00020,10.000
10,91.600,-0.01,-0.0002,-0.00020,10.000
10,91.667,0.00,-0.0002,-0.00020,10.000
10,91.733,-0.01,-0.0002,-0.00020,10.000
10,91.800,-0.01,-0.0002,-0.00020,10.000
10,91.867,-0.01,-0.0002,-0.00020,10.000
10,91.933,-0.01,-0.0002,-0.00020,10.000
10,92.000,-0.01,-0.0001,-0.00010,10.000
10,92.067,-0.01,-0.0001,-0.00010,10.000
10,92.133,-0.01,-0.0001,-0.00010,10.000
10,92.200,-0.01,-0.0001,-0.00010,10.000
10,92.267,-0.01,-0.0001,-0.00010,10.000
10,92.333,0.00,-0.0001,-0.00010,10.000
10,92.400,-0.01,-0.0001,-0.00010,10.000
10,92.467,-0.01,-0.0001,-0.00010,10.000
10,92.533,-0.01,-0.0001,-0.00010,10.000
10,92.600,-0.01,-0.0001,-0.00010,10.000
10,92.667,-0.01,-0.0001,-0.00010,10.000
10,92.733,-0.01,-0.0001,-0.00010,10.000
10,92.800,-0.01,-0.0001,-0.00010,10.000
10,92.867,-0.01,-0.0001,-0.00010,10.000
10,93.000,-0.01,-0.0001,-0.00010,10.000
10,93.067,-0.01,-0.0001,-0.00010,10.000
10,93.133,0.00,-0.0001,-0.00010,10.000
10,93.200,-0.01,-0.0001,-0.00010,10.000
10,93.267,-0.01,-0.0001,-0.00010,10.000
10,93.333,-0.01,-0.0001,-0.00010,10.000
10,93.400,0.00,-0.0001,-0.00010,10.000
10,93.467,-0.01,-0.0001,-0.00010,10.000
10,93.533,-0.02,-0.0001,-0.00010,10.000
10,93.600,-0.01,-0.0001,-0.00010,10.000
10,93.667,-0.01,-0.0001,-0.00010,10.000
10,93.733,-0.01,-0.0001,-0.00010,10.000
10,93.800,-0.01,-0.0001,-0.00010,10.000
10,93.867,-0.01,-0.0001,-0.00010,10.000
10,93.933,-0.01,-0.0001,-0.00010,10.000