File: calibDATA_loadcell/date_02:15:2018/Instron_02.15.2018/1_1N_1__1mm.s_0_0.txt
""
"Test Method","Radhen_Load_Cntrl_Cmprsn_250N_12-7.msm"
"Sample I. D.","Sample1.mss"
"Specimen Number","3"

"TheCycle_Output ()","_Time (s)","_Load (N)","_Extension (mm)","RealTimeDepth (mm)","CycleNumber ()"

1,0.200,0.00,0.0000,0.00010,1.000
1,0.400,0.00,0.1676,0.16760,1.000
1,0.533,0.00,0.3010,0.30100,1.000
1,0.667,0.00,0.4344,0.43443,1.000
1,0.800,0.00,0.5678,0.56780,1.000
1,0.933,0.00,0.7010,0.70103,1.000
1,1.067,0.00,0.8344,0.83443,1.000
1,1.200,0.00,0.9678,0.96780,1.000
1,1.333,0.00,1.1012,1.10123,1.000
1,1.467,0.00,1.2345,1.23447,1.000
1,1.600,0.00,1.3678,1.36780,1.000
1,1.733,0.00,1.5011,1.50107,1.000
1,1.867,0.00,1.6344,1.63437,1.000
1,2.000,0.00,1.7678,1.76780,1.000
1,2.133,0.00,1.9011,1.90110,1.000
1,2.267,0.00,2.0344,2.03440,1.000
1,2.400,0.00,2.1679,2.16790,1.000
1,2.533,0.00,2.3012,2.30117,1.000
1,2.667,0.00,2.4344,2.43443,1.000
1,2.800,0.00,2.5678,2.56780,1.000
1,2.933,0.00,2.7012,2.70123,1.000
1,3.067,0.00,2.8345,2.83447,1.000
1,3.200,0.00,2.9679,2.96790,1.000
1,3.333,0.00,3.1011,3.10110,1.000
1,3.467,0.00,3.2344,3.23437,1.000
1,3.600,0.00,3.3679,3.36790,1.000
1,3.733,0.00,3.5011,3.50110,1.000
1,3.867,0.00,3.6344,3.63440,1.000
1,4.000,0.00,3.7679,3.76790,1.000
1,4.133,0.00,3.9012,3.90123,1.000
1,4.267,0.00,4.0344,4.03443,1.000
1,4.400,0.00,4.1679,4.16790,1.000
1,4.533,0.00,4.3011,4.30113,1.000
1,4.667,0.00,4.4345,4.43450,1.000
1,4.800,0.00,4.5679,4.56790,1.000
1,4.933,0.00,4.7012,4.70120,1.000
1,5.067,0.00,4.8345,4.83447,1.000
1,5.200,0.00,4.9680,4.96800,1.000
1,5.333,0.00,5.1013,5.10127,1.000
1,5.467,0.00,5.2345,5.23450,1.000
1,5.600,0.00,5.3679,5.36790,1.000
1,5.733,0.00,5.5013,5.50127,1.000
1,5.867,0.00,5.6346,5.63457,1.000
1,6.000,0.01,5.7678,5.76780,1.000
1,6.133,0.01,5.9013,5.90127,1.000
1,6.267,0.05,6.0345,6.03450,1.000
1,6.400,0.17,6.1679,6.16790,1.000
1,6.533,0.41,6.3013,6.30133,1.000
1,6.667,0.79,6.4346,6.43457,1.000
1,6.867,1.00,6.4819,6.48193,1.000
1,7.000,0.52,6.3486,6.34860,1.000
1,7.133,0.21,6.2155,6.21550,1.000
1,7.267,0.07,6.0819,6.08190,1.000
1,7.400,0.01,5.9487,5.94870,1.000
1,7.533,0.00,5.8153,5.81527,1.000
1,7.667,0.00,5.6819,5.68187,1.000
1,7.800,0.00,5.5485,5.54850,1.000
1,7.933,0.00,5.4154,5.41540,1.000
1,8.067,0.00,5.2820,5.28203,1.000
1,8.200,0.00,5.1486,5.14860,1.000
1,8.333,0.00,5.0153,5.01527,1.000
1,8.467,0.00,4.8819,4.88193,1.000
1,8.600,0.00,4.7485,4.74850,1.000
1,8.733,0.00,4.6153,4.61527,1.000
1,8.867,0.00,4.4819,4.48190,1.000
1,9.000,0.00,4.3484,4.34840,1.000
1,9.133,0.00,4.2152,4.21517,1.000
1,9.267,0.00,4.0818,4.08180,1.000
1,9.400,0.00,3.9484,3.94840,1.000
1,9.533,0.00,3.8152,3.81517,1.000
1,9.667,0.00,3.6819,3.68187,1.000
1,9.800,0.00,3.5482,3.54820,1.000
1,9.933,0.00,3.4151,3.41507,1.000
1,10.067,0.00,3.2818,3.28177,1.000
1,10.200,-0.01,3.1482,3.14820,1.000
1,10.333,0.00,3.0150,3.01503,1.000
1,10.467,0.00,2.8818,2.88177,1.000
1,10.600,0.00,2.7483,2.74830,1.000
1,10.733,0.00,2.6151,2.61507,1.000
1,10.867,0.00,2.4816,2.48163,1.000
1,11.000,0.00,2.3483,2.34830,1.000
1,11.133,0.00,2.2149,2.21493,1.000
1,11.267,0.00,2.0817,2.08170,1.000
1,11.400,-0.01,1.9481,1.94810,1.000
1,11.533,0.00,1.8150,1.81497,1.000
1,11.667,0.00,1.6817,1.68170,1.000
1,11.800,0.00,1.5481,1.54810,1.000
1,11.933,0.00,1.4149,1.41490,1.000
1,12.067,0.00,1.2815,1.28153,1.000
1,12.200,0.00,1.1483,1.14830,1.000
1,12.333,0.00,1.0150,1.01497,1.000
1,12.467,0.00,0.8816,0.88163,1.000
1,12.600,0.00,0.7482,0.74820,1.000
1,12.733,0.00,0.6149,0.61487,1.000
1,12.867,0.00,0.4817,0.48167,1.000
1,13.000,0.00,0.3481,0.34810,1.000
1,13.133,0.00,0.2149,0.21490,1.000
1,13.267,0.00,0.0815,0.08153,1.000
1,13.467,0.00,-0.0084,-0.00840,1.000
1,13.600,0.00,-0.0003,-0.00030,1.000
1,13.733,0.00,-0.0003,-0.00030,1.000
1,13.867,0.00,-0.0003,-0.00030,1.000
1,14.000,0.00,-0.0003,-0.00030,1.000
1,14.133,0.00,-0.0003,-0.00030,1.000
1,14.267,0.00,-0.0003,-0.00030,1.000
1,14.400,0.00,-0.0003,-0.00030,1.000
1,14.533,0.00,-0.0003,-0.00030,1.000
1,14.667,0.00,-0.0003,-0.00030,1.000
1,14.800,0.00,-0.0003,-0.00030,1.000
1,14.933,0.00,-0.0003,-0.00030,1.000
1,15.067,0.00,-0.0003,-0.00030,1.000
1,15.200,0.00,-0.0003,-0.00030,1.000
1,15.333,0.00,-0.0003,-0.00030,1.000
1,15.467,0.00,-0.0003,-0.00030,1.000
1,15.600,0.00,-0.0002,-0.00020,1.000
1,15.733,0.00,-0.0002,-0.00020,1.000
1,15.867,0.00,-0.0002,-0.00020,1.000
1,16.000,0.00,-0.0002,-0.00020,1.000
1,16.133,0.00,-0.0002,-0.00020,1.000
1,16.267,0.00,-0.0002,-0.00020,1.000
1,16.400,0.00,-0.0002,-0.00020,1.000
1,16.600,0.00,-0.0002,-0.00020,1.000
1,16.733,0.00,-0.0002,-0.00020,1.000
1,16.867,0.00,-0.0002,-0.00020,1.000
1,17.000,0.00,-0.0002,-0.00020,1.000
1,17.133,0.00,-0.0002,-0.00020,1.000
1,17.267,0.00,-0.0002,-0.00020,1.000
1,17.400,0.00,-0.0002,-0.00020,1.000
2,17.800,0.00,0.1717,0.17180,2.000
2,17.933,0.00,0.3048,0.30493,2.000
2,18.067,0.00,0.4384,0.43850,2.000
2,18.200,0.00,0.5717,0.57180,2.000
2,18.333,0.00,0.7049,0.70500,2.000
2,18.467,0.00,0.8383,0.83840,2.000
2,18.600,0.00,0.9719,0.97200,2.000
2,18.733,0.00,1.1051,1.10523,2.000
2,18.867,0.00,1.2384,1.23850,2.000
2,19.000,0.00,1.3718,1.37190,2.000
2,19.133,0.00,1.5049,1.50503,2.000
2,19.267,0.00,1.6383,1.63843,2.000
2,19.400,-0.01,1.7718,1.77190,2.000
2,19.533,0.00,1.9050,1.90513,2.000
2,19.667,-0.01,2.0384,2.03850,2.000
2,19.800,0.00,2.1717,2.17180,2.000
2,19.933,-0.01,2.3050,2.30513,2.000
2,20.067,0.00,2.4384,2.43850,2.000
2,20.200,0.00,2.5719,2.57200,2.000
2,20.333,0.00,2.7051,2.70517,2.000
2,20.467,-0.01,2.8385,2.83857,2.000
2,20.600,0.00,2.9718,2.97190,2.000
2,20.733,-0.01,3.1050,3.10510,2.000
2,20.867,-0.01,3.2384,3.23850,2.000
2,21.000,0.00,3.3719,3.37200,2.000
2,21.133,0.00,3.5050,3.50513,2.000
2,21.267,-0.01,3.6384,3.63853,2.000
2,21.400,0.00,3.7720,3.77210,2.000
2,21.533,-0.01,3.9051,3.90517,2.000
2,21.667,0.00,4.0384,4.03850,2.000
2,21.800,0.00,4.1718,4.17190,2.000
2,21.933,-0.01,4.3052,4.30527,2.000
2,22.067,0.00,4.4385,4.43860,2.000
2,22.200,0.00,4.5719,4.57200,2.000
2,22.333,0.00,4.7052,4.70530,2.000
2,22.467,0.00,4.8385,4.83857,2.000
2,22.600,0.00,4.9719,4.97200,2.000
2,22.733,0.00,5.1052,5.10527,2.000
2,22.867,0.00,5.2385,5.23860,2.000
2,23.000,0.00,5.3720,5.37210,2.000
2,23.133,0.00,5.5052,5.50530,2.000
2,23.267,0.00,5.6385,5.63863,2.000
2,23.400,0.00,5.7718,5.77190,2.000
2,23.533,0.00,5.9052,5.90530,2.000
2,23.667,0.05,6.0384,6.03850,2.000
2,23.800,0.17,6.1719,6.17200,2.000
2,23.933,0.42,6.3053,6.30537,2.000
2,24.067,0.80,6.4384,6.43850,2.000
2,24.267,1.10,6.5059,6.50597,2.000
2,24.400,0.58,6.3726,6.37270,2.000
2,24.533,0.25,6.2393,6.23940,2.000
2,24.667,0.08,6.1060,6.10610,2.000
2,24.800,0.02,5.9727,5.97280,2.000
2,24.933,-0.01,5.8392,5.83930,2.000
2,25.067,0.00,5.7059,5.70603,2.000
2,25.200,0.00,5.5726,5.57270,2.000
2,25.333,-0.01,5.4392,5.43933,2.000
2,25.467,0.00,5.3059,5.30603,2.000
2,25.600,0.00,5.1726,5.17270,2.000
2,25.733,-0.01,5.0391,5.03920,2.000
2,25.867,-0.01,4.9059,4.90603,2.000
2,26.000,-0.01,4.7725,4.77260,2.000
2,26.133,0.00,4.6391,4.63920,2.000
2,26.267,-0.01,4.5058,4.50593,2.000
2,26.400,0.00,4.3725,4.37260,2.000
2,26.533,-0.01,4.2391,4.23920,2.000
2,26.667,-0.01,4.1057,4.10583,2.000
2,26.800,-0.01,3.9725,3.97260,2.000
2,26.933,-0.01,3.8391,3.83920,2.000
2,27.067,-0.01,3.7058,3.70587,2.000
2,27.200,0.00,3.5725,3.57260,2.000
2,27.333,0.00,3.4390,3.43913,2.000
2,27.467,-0.01,3.3057,3.30577,2.000
2,27.600,-0.01,3.1724,3.17250,2.000
2,27.733,0.00,3.0389,3.03903,2.000
2,27.867,0.00,2.9056,2.90573,2.000
2,28.000,0.00,2.7725,2.77260,2.000
2,28.133,-0.01,2.6391,2.63920,2.000
2,28.267,-0.01,2.5056,2.50573,2.000
2,28.400,0.00,2.3724,2.37250,2.000
2,28.533,-0.01,2.2389,2.23903,2.000
2,28.667,0.00,2.1056,2.10567,2.000
2,28.800,0.00,1.9723,1.97240,2.000
2,28.933,0.00,1.8390,1.83907,2.000
2,29.067,0.00,1.7056,1.70567,2.000
2,29.200,0.00,1.5724,1.57250,2.000
2,29.333,-0.01,1.4389,1.43900,2.000
2,29.467,0.00,1.3054,1.30553,2.000
2,29.600,-0.01,1.1724,1.17250,2.000
2,29.733,0.00,1.0390,1.03910,2.000
2,29.867,-0.01,0.9055,0.90563,2.000
2,30.000,-0.01,0.7724,0.77250,2.000
2,30.133,0.00,0.6389,0.63900,2.000
2,30.267,-0.01,0.5055,0.50563,2.000
2,30.400,-0.01,0.3723,0.37240,2.000
2,30.533,0.00,0.2389,0.23903,2.000
2,30.667,-0.01,0.1055,0.10557,2.000
2,30.800,-0.01,-0.0279,-0.02780,2.000
2,31.000,-0.01,-0.0004,-0.00030,2.000
2,31.133,-0.01,-0.0004,-0.00030,2.000
2,31.267,0.00,-0.0004,-0.00030,2.000
2,31.400,0.00,-0.0004,-0.00030,2.000
2,31.533,-0.01,-0.0004,-0.00030,2.000
2,31.667,-0.01,-0.0003,-0.00020,2.000
2,31.800,0.00,-0.0003,-0.00020,2.000
2,31.933,0.00,-0.0003,-0.00020,2.000
2,32.067,0.00,-0.0003,-0.00020,2.000
2,32.200,-0.01,-0.0003,-0.00020,2.000
2,32.333,0.00,-0.0003,-0.00020,2.000
2,32.467,-0.01,-0.0003,-0.00020,2.000
2,32.600,-0.01,-0.0003,-0.00020,2.000
2,32.733,-0.01,-0.0003,-0.00020,2.000
2,32.867,-0.01,-0.0003,-0.00020,2.000
2,33.000,-0.01,-0.0003,-0.00020,2.000
2,33.133,-0.01,-0.0003,-0.00020,2.000
2,33.267,-0.01,-0.0003,-0.00020,2.000
2,33.400,-0.01,-0.0002,-0.00010,2.000
2,33.533,-0.01,-0.0002,-0.00010,2.000
2,33.667,0.00,-0.0002,-0.00010,2.000
2,33.800,0.00,-0.0002,-0.00010,2.000
2,34.000,-0.01,-0.0002,-0.00010,2.000
2,34.133,0.00,-0.0002,-0.00010,2.000
2,34.267,-0.01,-0.0002,-0.00010,2.000
2,34.400,-0.01,-0.0002,-0.00010,2.000
2,34.533,-0.01,-0.0002,-0.00010,2.000
2,34.667,-0.01,-0.0002,-0.00010,2.000
2,34.800,-0.01,-0.0002,-0.00010,2.000
3,35.133,0.01,0.0548,0.05493,3.000
3,35.267,0.00,0.1882,0.18827,3.000
3,35.400,0.00,0.3216,0.32170,3.000
3,35.533,0.00,0.4551,0.45523,3.000
3,35.667,0.01,0.5882,0.58827,3.000
3,35.800,0.00,0.7217,0.72180,3.000
3,35.933,0.00,0.8551,0.85517,3.000
3,36.067,0.01,0.9884,0.98847,3.000
3,36.200,0.00,1.1219,1.12200,3.000
3,36.333,0.00,1.2551,1.25520,3.000
3,36.467,0.00,1.3882,1.38833,3.000
3,36.600,0.00,1.5216,1.52170,3.000
3,36.733,0.01,1.6551,1.65517,3.000
3,36.867,0.00,1.7884,1.78847,3.000
3,37.000,0.00,1.9217,1.92180,3.000
3,37.133,0.00,2.0552,2.05527,3.000
3,37.267,0.00,2.1883,2.18843,3.000
3,37.400,0.00,2.3217,2.32180,3.000
3,37.533,0.00,2.4552,2.45527,3.000
3,37.667,0.00,2.5883,2.58843,3.000
3,37.800,0.00,2.7218,2.72190,3.000
3,37.933,0.01,2.8553,2.85537,3.000
3,38.067,0.01,2.9884,2.98850,3.000
3,38.200,0.01,3.1217,3.12180,3.000
3,38.333,0.00,3.2552,3.25527,3.000
3,38.467,0.01,3.3884,3.38853,3.000
3,38.600,0.00,3.5216,3.52170,3.000
3,38.733,0.01,3.6552,3.65530,3.000
3,38.867,0.01,3.7885,3.78857,3.000
3,39.000,0.01,3.9217,3.92180,3.000
3,39.133,0.01,4.0551,4.05523,3.000
3,39.267,0.00,4.1884,4.18850,3.000
3,39.400,0.00,4.3217,4.32180,3.000
3,39.533,0.00,4.4552,4.45533,3.000
3,39.667,0.00,4.5885,4.58860,3.000
3,39.800,0.00,4.7219,4.72200,3.000
3,39.933,0.01,4.8552,4.85530,3.000
3,40.067,0.01,4.9885,4.98863,3.000
3,40.200,0.01,5.1218,5.12190,3.000
3,40.333,0.00,5.2553,5.25540,3.000
3,40.467,0.00,5.3886,5.38873,3.000
3,40.600,0.00,5.5218,5.52190,3.000
3,40.733,0.00,5.6552,5.65530,3.000
3,40.867,0.00,5.7885,5.78857,3.000
3,41.000,0.02,5.9217,5.92180,3.000
3,41.133,0.07,6.0552,6.05530,3.000
3,41.267,0.20,6.1886,6.18873,3.000
3,41.400,0.47,6.3218,6.32190,3.000
3,41.533,0.87,6.4553,6.45537,3.000
3,41.733,0.87,6.4493,6.44937,3.000
3,41.867,0.43,6.3159,6.31600,3.000
3,42.000,0.17,6.1827,6.18280,3.000
3,42.133,0.05,6.0493,6.04940,3.000
3,42.267,0.01,5.9159,5.91603,3.000
3,42.400,0.00,5.7825,5.78260,3.000
3,42.533,0.00,5.6493,5.64940,3.000
3,42.667,0.00,5.5158,5.51593,3.000
3,42.800,0.00,5.3827,5.38280,3.000
3,42.933,0.00,5.2493,5.24943,3.000
3,43.067,0.00,5.1158,5.11590,3.000
3,43.200,0.00,4.9826,4.98270,3.000
3,43.333,0.01,4.8492,4.84927,3.000
3,43.467,0.00,4.7157,4.71583,3.000
3,43.600,0.00,4.5825,4.58260,3.000
3,43.733,0.00,4.4492,4.44933,3.000
3,43.867,0.00,4.3157,4.31580,3.000
3,44.000,0.00,4.1825,4.18260,3.000
3,44.133,0.00,4.0492,4.04927,3.000
3,44.267,0.00,3.9158,3.91587,3.000
3,44.400,0.01,3.7824,3.78250,3.000
3,44.533,0.00,3.6492,3.64927,3.000
3,44.667,0.00,3.5156,3.51570,3.000
3,44.800,0.00,3.3824,3.38250,3.000
3,44.933,0.00,3.2491,3.24917,3.000
3,45.067,0.00,3.1156,3.11567,3.000
3,45.200,0.01,2.9824,2.98250,3.000
3,45.333,0.01,2.8491,2.84920,3.000
3,45.467,0.00,2.7156,2.71570,3.000
3,45.600,0.00,2.5824,2.58250,3.000
3,45.733,0.00,2.4490,2.44910,3.000
3,45.867,0.00,2.3156,2.31567,3.000
3,46.000,0.00,2.1823,2.18240,3.000
3,46.133,0.00,2.0490,2.04910,3.000
3,46.267,0.01,1.9156,1.91567,3.000
3,46.400,0.00,1.7823,1.78240,3.000
3,46.533,0.00,1.6490,1.64913,3.000
3,46.667,0.00,1.5155,1.51560,3.000
3,46.800,0.01,1.3821,1.38220,3.000
3,46.933,0.00,1.2489,1.24900,3.000
3,47.067,0.00,1.1157,1.11577,3.000
3,47.200,0.01,0.9823,0.98240,3.000
3,47.333,0.00,0.8490,0.84907,3.000
3,47.467,0.00,0.7156,0.71567,3.000
3,47.600,0.00,0.5821,0.58220,3.000
3,47.733,0.00,0.4490,0.44913,3.000
3,47.867,0.00,0.3155,0.31560,3.000
3,48.000,0.00,0.1821,0.18220,3.000
3,48.133,0.00,0.0489,0.04897,3.000
3,48.400,0.00,-0.0003,-0.00020,3.000
3,48.533,0.01,-0.0003,-0.00020,3.000
3,48.667,0.00,-0.0003,-0.00020,3.000
3,48.800,0.00,-0.0003,-0.00020,3.000
3,48.933,0.00,-0.0003,-0.00020,3.000
3,49.067,0.00,-0.0003,-0.00020,3.000
3,49.200,0.00,-0.0003,-0.00020,3.000
3,49.333,0.00,-0.0003,-0.00020,3.000
3,49.467,0.00,-0.0003,-0.00020,3.000
3,49.600,0.00,-0.0003,-0.00020,3.000
3,49.733,0.00,-0.0003,-0.00020,3.000
3,49.867,0.00,-0.0003,-0.00020,3.000
3,50.000,0.00,-0.0003,-0.00020,3.000
3,50.133,0.00,-0.0003,-0.00020,3.000
3,50.267,0.00,-0.0003,-0.00020,3.000
3,50.400,0.01,-0.0003,-0.00020,3.000
3,50.533,0.00,-0.0003,-0.00020,3.000
3,50.667,0.00,-0.0002,-0.00010,3.000
3,50.800,0.00,-0.0002,-0.00010,3.000
3,50.933,0.00,-0.0002,-0.00010,3.000
3,51.067,0.00,-0.0002,-0.00010,3.000
3,51.200,0.00,-0.0002,-0.00010,3.000
3,51.400,0.00,-0.0002,-0.00010,3.000
3,51.533,0.00,-0.0002,-0.00010,3.000
3,51.667,0.00,-0.0002,-0.00010,3.000
3,51.800,0.00,-0.0002,-0.00010,3.000
3,51.933,0.00,-0.0002,-0.00010,3.000
3,52.067,0.00,-0.0002,-0.00010,3.000
3,52.200,0.00,-0.0002,-0.00010,3.000
4,52.533,0.00,0.0519,0.05197,4.000
4,52.667,0.00,0.1852,0.18527,4.000
4,52.800,0.00,0.3186,0.31870,4.000
4,52.933,0.00,0.4521,0.45220,4.000
4,53.067,0.00,0.5852,0.58530,4.000
4,53.200,0.00,0.7187,0.71880,4.000
4,53.333,0.00,0.8521,0.85220,4.000
4,53.467,0.00,0.9853,0.98543,4.000
4,53.600,0.00,1.1187,1.11880,4.000
4,53.733,0.00,1.2521,1.25223,4.000
4,53.867,0.00,1.3852,1.38533,4.000
4,54.000,0.00,1.5187,1.51880,4.000
4,54.133,0.00,1.6521,1.65220,4.000
4,54.267,0.00,1.7854,1.78550,4.000
4,54.400,0.00,1.9186,1.91870,4.000
4,54.533,0.00,2.0521,2.05223,4.000
4,54.667,0.00,2.1854,2.18547,4.000
4,54.800,-0.01,2.3186,2.31870,4.000
4,54.933,0.00,2.4522,2.45227,4.000
4,55.067,0.00,2.5854,2.58547,4.000
4,55.200,0.00,2.7188,2.71890,4.000
4,55.333,0.00,2.8522,2.85233,4.000
4,55.467,0.00,2.9855,2.98557,4.000
4,55.600,0.00,3.1187,3.11880,4.000
4,55.733,0.00,3.2522,3.25230,4.000
4,55.867,0.00,3.3854,3.38550,4.000
4,56.000,0.00,3.5187,3.51880,4.000
4,56.133,0.00,3.6522,3.65227,4.000
4,56.267,0.00,3.7854,3.78553,4.000
4,56.400,0.00,3.9188,3.91890,4.000
4,56.533,0.00,4.0521,4.05220,4.000
4,56.667,0.00,4.1854,4.18553,4.000
4,56.800,0.00,4.3186,4.31870,4.000
4,56.933,0.00,4.4522,4.45233,4.000
4,57.067,0.00,4.5855,4.58560,4.000
4,57.200,0.00,4.7187,4.71880,4.000
4,57.333,0.00,4.8522,4.85233,4.000
4,57.467,0.00,4.9855,4.98563,4.000
4,57.600,0.00,5.1187,5.11880,4.000
4,57.733,0.00,5.2523,5.25240,4.000
4,57.867,0.00,5.3857,5.38577,4.000
4,58.000,0.00,5.5188,5.51890,4.000
4,58.133,0.00,5.6523,5.65237,4.000
4,58.267,0.00,5.7855,5.78557,4.000
4,58.400,0.01,5.9188,5.91890,4.000
4,58.533,0.06,6.0522,6.05233,4.000
4,58.667,0.19,6.1857,6.18577,4.000
4,58.800,0.46,6.3188,6.31890,4.000
4,58.933,0.85,6.4522,6.45230,4.000
4,59.067,1.23,6.5321,6.53217,4.000
4,59.200,0.68,6.4014,6.40150,4.000
4,59.333,0.32,6.2684,6.26853,4.000
4,59.467,0.11,6.1350,6.13507,4.000
4,59.600,0.02,6.0016,6.00170,4.000
4,59.733,0.00,5.8683,5.86837,4.000
4,59.867,0.00,5.7349,5.73500,4.000
4,60.000,0.00,5.6016,5.60170,4.000
4,60.133,0.00,5.4682,5.46833,4.000
4,60.267,0.00,5.3350,5.33513,4.000
4,60.400,0.00,5.2015,5.20160,4.000
4,60.533,0.00,5.0681,5.06823,4.000
4,60.667,0.00,4.9349,4.93497,4.000
4,60.800,-0.01,4.8014,4.80150,4.000
4,60.933,0.00,4.6682,4.66827,4.000
4,61.067,0.00,4.5350,4.53510,4.000
4,61.200,0.00,4.4014,4.40150,4.000
4,61.333,0.00,4.2681,4.26820,4.000
4,61.467,0.00,4.1349,4.13500,4.000
4,61.600,-0.01,4.0014,4.00150,4.000
4,61.733,0.00,3.8680,3.86813,4.000
4,61.867,0.00,3.7349,3.73500,4.000
4,62.000,0.00,3.6015,3.60160,4.000
4,62.133,0.00,3.4679,3.46803,4.000
4,62.267,0.00,3.3348,3.33490,4.000
4,62.400,0.00,3.2013,3.20140,4.000
4,62.533,0.00,3.0679,3.06797,4.000
4,62.667,0.00,2.9347,2.93483,4.000
4,62.800,0.00,2.8012,2.80130,4.000
4,62.933,0.00,2.6680,2.66810,4.000
4,63.067,0.00,2.5347,2.53483,4.000
4,63.200,0.00,2.4013,2.40140,4.000
4,63.333,0.00,2.2679,2.26800,4.000
4,63.467,0.00,2.1346,2.13473,4.000
4,63.600,0.00,2.0013,2.00140,4.000
4,63.733,0.00,1.8678,1.86793,4.000
4,63.867,0.00,1.7346,1.73473,4.000
4,64.000,0.00,1.6013,1.60140,4.000
4,64.133,0.00,1.4678,1.46793,4.000
4,64.267,0.00,1.3345,1.33460,4.000
4,64.400,0.00,1.2014,1.20150,4.000
4,64.533,0.00,1.0679,1.06797,4.000
4,64.667,0.00,0.9346,0.93473,4.000
4,64.800,-0.01,0.8013,0.80140,4.000
4,64.933,0.00,0.6677,0.66783,4.000
4,65.067,0.00,0.5346,0.53470,4.000
4,65.200,0.00,0.4012,0.40130,4.000
4,65.333,0.00,0.2678,0.26790,4.000
4,65.467,0.00,0.1345,0.13463,4.000
4,65.600,-0.01,0.0013,0.00140,4.000
4,65.800,-0.01,-0.0004,-0.00030,4.000
4,65.933,0.00,-0.0004,-0.00030,4.000
4,66.067,0.00,-0.0004,-0.00030,4.000
4,66.200,0.00,-0.0004,-0.00030,4.000
4,66.333,0.00,-0.0004,-0.00030,4.000
4,66.467,0.00,-0.0004,-0.00030,4.000
4,66.600,-0.01,-0.0004,-0.00030,4.000
4,66.733,0.00,-0.0003,-0.00020,4.000
4,66.867,-0.01,-0.0003,-0.00020,4.000
4,67.000,0.00,-0.0003,-0.00020,4.000
4,67.133,0.00,-0.0003,-0.00020,4.000
4,67.267,0.00,-0.0003,-0.00020,4.000
4,67.400,-0.01,-0.0003,-0.00020,4.000
4,67.533,0.00,-0.0003,-0.00020,4.000
4,67.667,0.00,-0.0003,-0.00020,4.000
4,67.800,0.00,-0.0003,-0.00020,4.000
4,67.933,0.00,-0.0003,-0.00020,4.000
4,68.067,0.00,-0.0003,-0.00020,4.000
4,68.200,0.00,-0.0003,-0.00020,4.000
4,68.333,0.00,-0.0003,-0.00020,4.000
4,68.467,0.00,-0.0002,-0.00010,4.000
4,68.600,-0.01,-0.0002,-0.00010,4.000
4,68.800,0.00,-0.0002,-0.00010,4.000
4,68.933,0.00,-0.0002,-0.00010,4.000
4,69.067,0.00,-0.0002,-0.00010,4.000
4,69.200,0.00,-0.0002,-0.00010,4.000
4,69.333,0.00,-0.0002,-0.00010,4.000
4,69.467,0.00,-0.0002,-0.00010,4.000
4,69.600,0.00,-0.0002,-0.00010,4.000
5,70.000,-0.01,0.0715,0.07160,5.000
5,70.133,0.00,0.2049,0.20500,5.000
5,70.267,-0.01,0.3383,0.33840,5.000
5,70.400,0.00,0.4716,0.47170,5.000
5,70.533,0.00,0.6050,0.60510,5.000
5,70.667,0.00,0.7384,0.73853,5.000
5,70.800,-0.01,0.8716,0.87170,5.000
5,70.933,0.00,1.0052,1.00527,5.000
5,71.067,-0.01,1.1386,1.13867,5.000
5,71.200,0.00,1.2715,1.27160,5.000
5,71.333,0.00,1.4050,1.40510,5.000
5,71.467,0.00,1.5384,1.53850,5.000
5,71.600,0.00,1.6716,1.67170,5.000
5,71.733,0.00,1.8051,1.80520,5.000
5,71.867,0.00,1.9385,1.93857,5.000
5,72.000,0.00,2.0717,2.07180,5.000
5,72.133,0.00,2.2051,2.20517,5.000
5,72.267,0.00,2.3385,2.33857,5.000
5,72.400,-0.01,2.4717,2.47180,5.000
5,72.533,0.00,2.6051,2.60520,5.000
5,72.667,0.00,2.7385,2.73860,5.000
5,72.800,0.00,2.8719,2.87200,5.000
5,72.933,0.00,3.0051,3.00523,5.000
5,73.067,0.00,3.1384,3.13853,5.000
5,73.200,0.00,3.2717,3.27180,5.000
5,73.333,0.00,3.4051,3.40523,5.000
5,73.467,0.00,3.5385,3.53857,5.000
5,73.600,0.00,3.6718,3.67190,5.000
5,73.733,0.00,3.8051,3.80523,5.000
5,73.867,0.00,3.9385,3.93860,5.000
5,74.000,0.00,4.0717,4.07180,5.000
5,74.133,0.00,4.2051,4.20523,5.000
5,74.267,-0.01,4.3385,4.33857,5.000
5,74.400,0.00,4.4719,4.47200,5.000
5,74.533,-0.01,4.6052,4.60530,5.000
5,74.667,0.00,4.7386,4.73870,5.000
5,74.800,-0.01,4.8718,4.87190,5.000
5,74.933,0.00,5.0052,5.00527,5.000
5,75.067,0.00,5.1386,5.13870,5.000
5,75.200,-0.01,5.2719,5.27200,5.000
5,75.333,0.00,5.4053,5.40537,5.000
5,75.467,0.00,5.5385,5.53863,5.000
5,75.600,0.00,5.6719,5.67200,5.000
5,75.733,0.00,5.8050,5.80513,5.000
5,75.867,0.01,5.9386,5.93867,5.000
5,76.000,0.07,6.0718,6.07190,5.000
5,76.133,0.22,6.2052,6.20530,5.000
5,76.267,0.51,6.3386,6.33870,5.000
5,76.400,0.92,6.4719,6.47200,5.000
5,76.600,0.95,6.4727,6.47280,5.000
5,76.733,0.48,6.3393,6.33940,5.000
5,76.867,0.19,6.2059,6.20603,5.000
5,77.000,0.05,6.0726,6.07270,5.000
5,77.133,0.01,5.9394,5.93947,5.000
5,77.267,-0.01,5.8058,5.80590,5.000
5,77.400,-0.01,5.6726,5.67270,5.000
5,77.533,0.00,5.5392,5.53933,5.000
5,77.667,0.00,5.4059,5.40603,5.000
5,77.800,0.00,5.2727,5.27280,5.000
5,77.933,-0.01,5.1392,5.13933,5.000
5,78.067,0.00,5.0058,5.00590,5.000
5,78.200,0.00,4.8725,4.87260,5.000
5,78.333,0.00,4.7393,4.73937,5.000
5,78.467,0.00,4.6058,4.60590,5.000
5,78.600,0.00,4.4725,4.47260,5.000
5,78.733,0.00,4.3391,4.33920,5.000
5,78.867,0.00,4.2058,4.20590,5.000
5,79.000,0.00,4.0724,4.07250,5.000
5,79.133,-0.01,3.9392,3.93933,5.000
5,79.267,-0.01,3.8058,3.80587,5.000
5,79.400,0.00,3.6724,3.67250,5.000
5,79.533,0.00,3.5390,3.53913,5.000
5,79.667,0.00,3.4057,3.40583,5.000
5,79.800,-0.01,3.2723,3.27240,5.000
5,79.933,0.00,3.1389,3.13903,5.000
5,80.067,-0.01,3.0057,3.00577,5.000
5,80.200,0.00,2.8723,2.87240,5.000
5,80.333,0.00,2.7391,2.73923,5.000
5,80.467,0.00,2.6057,2.60580,5.000
5,80.600,0.00,2.4723,2.47240,5.000
5,80.733,0.00,2.3390,2.33913,5.000
5,80.867,0.00,2.2056,2.20573,5.000
5,81.000,-0.01,2.0722,2.07230,5.000
5,81.133,0.00,1.9389,1.93903,5.000
5,81.267,-0.01,1.8056,1.80573,5.000
5,81.400,0.00,1.6721,1.67220,5.000
5,81.533,0.00,1.5389,1.53903,5.000
5,81.667,-0.01,1.4056,1.40570,5.000
5,81.800,0.00,1.2721,1.27220,5.000
5,81.933,-0.01,1.1391,1.13917,5.000
5,82.067,0.00,1.0056,1.00573,5.000
5,82.200,-0.01,0.8722,0.87230,5.000
5,82.333,-0.01,0.7390,0.73907,5.000
5,82.467,0.00,0.6055,0.60563,5.000
5,82.600,0.00,0.4722,0.47230,5.000
5,82.733,0.00,0.3389,0.33897,5.000
5,82.867,0.00,0.2056,0.20567,5.000
5,83.000,0.00,0.0720,0.07210,5.000
5,83.200,0.00,-0.0275,-0.02740,5.000
5,83.333,0.00,-0.0004,-0.00030,5.000
5,83.467,0.00,-0.0004,-0.00030,5.000
5,83.600,-0.01,-0.0004,-0.00030,5.000
5,83.733,0.00,-0.0004,-0.00030,5.000
5,83.867,0.00,-0.0004,-0.00030,5.000
5,84.000,0.00,-0.0004,-0.00030,5.000
5,84.133,-0.01,-0.0004,-0.00030,5.000
5,84.267,0.00,-0.0004,-0.00030,5.000
5,84.400,0.00,-0.0003,-0.00020,5.000
5,84.533,-0.01,-0.0003,-0.00020,5.000
5,84.667,0.00,-0.0003,-0.00020,5.000
5,84.800,-0.01,-0.0003,-0.00020,5.000
5,84.933,0.00,-0.0003,-0.00020,5.000
5,85.067,0.00,-0.0003,-0.00020,5.000
5,85.200,0.00,-0.0003,-0.00020,5.000
5,85.333,0.00,-0.0003,-0.00020,5.000
5,85.467,0.00,-0.0003,-0.00020,5.000
5,85.600,0.00,-0.0003,-0.00020,5.000
5,85.733,0.00,-0.0003,-0.00020,5.000
5,85.867,0.00,-0.0003,-0.00020,5.000
5,86.000,0.00,-0.0003,-0.00020,5.000
5,86.133,0.00,-0.0002,-0.00010,5.000
5,86.333,0.00,-0.0002,-0.00010,5.000
5,86.467,0.00,-0.0002,-0.00010,5.000
5,86.600,0.00,-0.0002,-0.00010,5.000
5,86.733,0.00,-0.0002,-0.00010,5.000
5,86.867,0.00,-0.0002,-0.00010,5.000
5,87.000,0.00,-0.0002,-0.00010,5.000
5,87.133,0.00,-0.0002,-0.00010,5.000
6,87.467,0.00,0.0982,0.09830,6.000
6,87.600,0.00,0.2316,0.23170,6.000
6,87.733,0.00,0.3650,0.36513,6.000
6,87.867,0.00,0.4985,0.49857,6.000
6,88.000,0.00,0.6315,0.63160,6.000
6,88.133,0.00,0.7651,0.76523,6.000
6,88.267,0.00,0.8985,0.89857,6.000
6,88.400,0.00,1.0317,1.03180,6.000
6,88.533,0.00,1.1652,1.16527,6.000
6,88.667,0.00,1.2983,1.29843,6.000
6,88.800,0.00,1.4315,1.43160,6.000
6,88.933,0.00,1.5650,1.56513,6.000
6,89.067,0.00,1.6985,1.69863,6.000
6,89.200,0.00,1.8317,1.83180,6.000
6,89.333,0.00,1.9651,1.96523,6.000
6,89.467,0.00,2.0985,2.09860,6.000
6,89.600,0.00,2.2316,2.23170,6.000
6,89.733,0.00,2.3652,2.36527,6.000
6,89.867,0.00,2.4986,2.49867,6.000
6,90.000,0.00,2.6318,2.63190,6.000
6,90.133,0.00,2.7652,2.76527,6.000
6,90.267,0.00,2.8986,2.89873,6.000
6,90.400,0.00,3.0317,3.03180,6.000
6,90.533,0.00,3.1650,3.16510,6.000
6,90.667,0.00,3.2985,3.29860,6.000
6,90.800,0.00,3.4317,3.43180,6.000
6,90.933,0.00,3.5650,3.56510,6.000
6,91.067,0.00,3.6986,3.69870,6.000
6,91.200,0.00,3.8318,3.83190,6.000
6,91.333,0.00,3.9652,3.96527,6.000
6,91.467,0.00,4.0986,4.09867,6.000
6,91.600,0.00,4.2317,4.23180,6.000
6,91.733,0.00,4.3651,4.36517,6.000
6,91.867,0.00,4.4985,4.49860,6.000
6,92.000,0.00,4.6318,4.63190,6.000
6,92.133,0.00,4.7651,4.76523,6.000
6,92.267,0.00,4.8986,4.89870,6.000
6,92.400,0.00,5.0319,5.03200,6.000
6,92.533,0.00,5.1652,5.16530,6.000
6,92.667,0.00,5.2986,5.29870,6.000
6,92.800,0.00,5.4320,5.43210,6.000
6,92.933,0.00,5.5651,5.56520,6.000
6,93.067,0.00,5.6986,5.69867,6.000
6,93.200,0.00,5.8318,5.83190,6.000
6,93.333,0.03,5.9652,5.96527,6.000
6,93.467,0.09,6.0986,6.09867,6.000
6,93.600,0.27,6.2321,6.23220,6.000
6,93.733,0.58,6.3651,6.36520,6.000
6,93.867,1.02,6.4986,6.49873,6.000
6,94.067,0.84,6.4459,6.44597,6.000
6,94.200,0.41,6.3126,6.31270,6.000
6,94.333,0.16,6.1794,6.17947,6.000
6,94.467,0.04,6.0458,6.04590,6.000
6,94.600,0.00,5.9127,5.91280,6.000
6,94.733,0.00,5.7792,5.77930,6.000
6,94.867,0.00,5.6459,5.64597,6.000
6,95.000,0.00,5.5125,5.51260,6.000
6,95.133,0.00,5.3793,5.37937,6.000
6,95.267,0.00,5.2459,5.24597,6.000
6,95.400,0.00,5.1125,5.11260,6.000
6,95.533,0.00,4.9793,4.97937,6.000
6,95.667,0.00,4.8458,4.84587,6.000
6,95.800,0.00,4.7125,4.71260,6.000
6,95.933,0.00,4.5793,4.57937,6.000
6,96.067,0.00,4.4458,4.44590,6.000
6,96.200,0.00,4.3125,4.31260,6.000
6,96.333,0.00,4.1791,4.17923,6.000
6,96.467,0.00,4.0458,4.04587,6.000
6,96.600,0.00,3.9125,3.91260,6.000
6,96.733,0.00,3.7791,3.77923,6.000
6,96.867,0.00,3.6458,3.64593,6.000
6,97.000,0.00,3.5123,3.51240,6.000
6,97.133,0.00,3.3791,3.37920,6.000
6,97.267,0.00,3.2457,3.24577,6.000
6,97.400,0.00,3.1122,3.11230,6.000
6,97.533,0.00,2.9790,2.97913,6.000
6,97.667,0.00,2.8456,2.84573,6.000
6,97.800,0.00,2.7124,2.71250,6.000
6,97.933,0.00,2.5791,2.57917,6.000
6,98.067,0.00,2.4456,2.44570,6.000
6,98.200,0.00,2.3122,2.31230,6.000
6,98.333,0.00,2.1790,2.17913,6.000
6,98.467,0.00,2.0456,2.04573,6.000
6,98.600,0.00,1.9122,1.91230,6.000
6,98.733,0.00,1.7790,1.77910,6.000
6,98.867,0.00,1.6456,1.64573,6.000
6,99.000,0.00,1.5122,1.51230,6.000
6,99.133,0.00,1.3789,1.37897,6.000
6,99.267,0.00,1.2455,1.24563,6.000
6,99.400,0.00,1.1123,1.11240,6.000
6,99.533,0.00,0.9789,0.97903,6.000
6,99.667,0.00,0.8456,0.84570,6.000
6,99.800,0.00,0.7121,0.71220,6.000
6,99.933,0.00,0.5789,0.57903,6.000
6,100.067,0.00,0.4457,0.44577,6.000
6,100.200,0.00,0.3122,0.31230,6.000
6,100.333,0.00,0.1790,0.17907,6.000
6,100.467,0.00,0.0455,0.04563,6.000
6,100.667,0.00,-0.0052,-0.00513,6.000
6,100.800,0.00,-0.0004,-0.00030,6.000
6,100.933,0.00,-0.0004,-0.00030,6.000
6,101.067,0.00,-0.0004,-0.00030,6.000
6,101.200,0.00,-0.0004,-0.00030,6.000
6,101.333,0.00,-0.0004,-0.00030,6.000
6,101.467,0.00,-0.0004,-0.00030,6.000
6,101.600,0.00,-0.0004,-0.00030,6.000
6,101.733,0.00,-0.0004,-0.00030,6.000
6,101.867,0.00,-0.0004,-0.00030,6.000
6,102.000,0.00,-0.0004,-0.00030,6.000
6,102.133,0.00,-0.0003,-0.00020,6.000
6,102.267,0.00,-0.0003,-0.00020,6.000
6,102.400,0.00,-0.0003,-0.00020,6.000
6,102.533,0.00,-0.0003,-0.00020,6.000
6,102.667,0.00,-0.0003,-0.00020,6.000
6,102.800,0.00,-0.0003,-0.00020,6.000
6,102.933,0.00,-0.0003,-0.00020,6.000
6,103.067,0.00,-0.0003,-0.00020,6.000
6,103.200,0.00,-0.0003,-0.00020,6.000
6,103.333,0.00,-0.0003,-0.00020,6.000
6,103.467,0.00,-0.0003,-0.00020,6.000
6,103.600,0.00,-0.0003,-0.00020,6.000
6,103.800,0.00,-0.0003,-0.00020,6.000
6,103.933,0.00,-0.0002,-0.00010,6.000
6,104.067,0.00,-0.0002,-0.00010,6.000
6,104.200,0.00,-0.0002,-0.00010,6.000
6,104.333,0.00,-0.0002,-0.00010,6.000
6,104.467,0.00,-0.0002,-0.00010,6.000
6,104.600,0.00,-0.0002,-0.00010,6.000
7,104.933,0.00,0.1249,0.12497,7.000
7,105.067,0.00,0.2584,0.25847,7.000
7,105.200,0.00,0.3916,0.39170,7.000
7,105.333,0.00,0.5250,0.52513,7.000
7,105.467,0.00,0.6584,0.65847,7.000
7,105.600,0.00,0.7917,0.79180,7.000
7,105.733,0.00,0.9252,0.92527,7.000
7,105.867,0.00,1.0586,1.05873,7.000
7,106.000,0.00,1.1917,1.19180,7.000
7,106.133,0.00,1.3250,1.32513,7.000
7,106.267,0.00,1.4585,1.45857,7.000
7,106.400,0.00,1.5917,1.59180,7.000
7,106.533,0.00,1.7251,1.72520,7.000
7,106.667,0.00,1.8585,1.85860,7.000
7,106.800,0.00,1.9917,1.99180,7.000
7,106.933,0.00,2.1251,2.12517,7.000
7,107.067,0.00,2.2585,2.25860,7.000
7,107.200,0.00,2.3917,2.39180,7.000
7,107.333,0.00,2.5251,2.52520,7.000
7,107.467,0.00,2.6585,2.65860,7.000
7,107.600,0.00,2.7918,2.79190,7.000
7,107.733,0.00,2.9251,2.92520,7.000
7,107.867,0.00,3.0585,3.05860,7.000
7,108.000,0.00,3.1917,3.19180,7.000
7,108.133,0.00,3.3251,3.32517,7.000
7,108.267,0.00,3.4585,3.45860,7.000
7,108.400,0.00,3.5917,3.59180,7.000
7,108.533,0.00,3.7252,3.72527,7.000
7,108.667,0.00,3.8586,3.85867,7.000
7,108.800,0.00,3.9919,3.99200,7.000
7,108.933,0.00,4.1252,4.12527,7.000
7,109.067,0.00,4.2585,4.25863,7.000
7,109.200,0.00,4.3918,4.39190,7.000
7,109.333,0.00,4.5252,4.52530,7.000
7,109.467,0.00,4.6586,4.65867,7.000
7,109.600,0.00,4.7918,4.79190,7.000
7,109.733,0.00,4.9252,4.92527,7.000
7,109.867,0.00,5.0586,5.05867,7.000
7,110.000,0.00,5.1919,5.19200,7.000
7,110.133,0.00,5.3252,5.32533,7.000
7,110.267,0.00,5.4587,5.45880,7.000
7,110.400,0.00,5.5918,5.59190,7.000
7,110.533,0.00,5.7251,5.72523,7.000
7,110.667,0.00,5.8585,5.85863,7.000
7,110.800,0.04,5.9920,5.99210,7.000
7,110.933,0.12,6.1252,6.12527,7.000
7,111.067,0.33,6.2587,6.25877,7.000
7,111.200,0.66,6.3919,6.39200,7.000
7,111.467,1.01,6.4858,6.48593,7.000
7,111.600,0.53,6.3527,6.35280,7.000
7,111.733,0.22,6.2195,6.21957,7.000
7,111.867,0.07,6.0858,6.08593,7.000
7,112.000,0.01,5.9526,5.95270,7.000
7,112.133,-0.01,5.8193,5.81940,7.000
7,112.267,0.00,5.6859,5.68603,7.000
7,112.400,0.00,5.5526,5.55270,7.000
7,112.533,0.00,5.4194,5.41953,7.000
7,112.667,0.00,5.2859,5.28600,7.000
7,112.800,0.00,5.1526,5.15270,7.000
7,112.933,0.00,5.0193,5.01937,7.000
7,113.067,0.00,4.8858,4.88590,7.000
7,113.200,0.00,4.7526,4.75270,7.000
7,113.333,0.00,4.6192,4.61933,7.000
7,113.467,0.00,4.4858,4.48593,7.000
7,113.600,0.00,4.3524,4.35250,7.000
7,113.733,0.00,4.2192,4.21930,7.000
7,113.867,0.00,4.0857,4.08580,7.000
7,114.000,0.00,3.9525,3.95260,7.000
7,114.133,0.00,3.8192,3.81927,7.000
7,114.267,0.00,3.6858,3.68590,7.000
7,114.400,0.00,3.5523,3.55240,7.000
7,114.533,0.00,3.4191,3.41917,7.000
7,114.667,0.00,3.2857,3.28580,7.000
7,114.800,0.00,3.1522,3.15230,7.000
7,114.933,0.00,3.0191,3.01917,7.000
7,115.067,0.00,2.8857,2.88577,7.000
7,115.200,0.00,2.7524,2.75250,7.000
7,115.333,0.00,2.6191,2.61923,7.000
7,115.467,0.00,2.4856,2.48573,7.000
7,115.600,0.00,2.3523,2.35240,7.000
7,115.733,0.00,2.2189,2.21903,7.000
7,115.867,0.00,2.0857,2.08580,7.000
7,116.000,0.00,1.9521,1.95220,7.000
7,116.133,0.00,1.8190,1.81910,7.000
7,116.267,0.00,1.6856,1.68573,7.000
7,116.400,0.00,1.5522,1.55230,7.000
7,116.533,0.00,1.4189,1.41900,7.000
7,116.667,0.00,1.2855,1.28557,7.000
7,116.800,0.00,1.1522,1.15230,7.000
7,116.933,0.00,1.0190,1.01910,7.000
7,117.067,0.00,0.8856,0.88567,7.000
7,117.200,0.00,0.7521,0.75220,7.000
7,117.333,-0.01,0.6189,0.61900,7.000
7,117.467,0.00,0.4857,0.48577,7.000
7,117.600,0.00,0.3521,0.35220,7.000
7,117.733,0.00,0.2190,0.21907,7.000
7,117.867,0.00,0.0856,0.08570,7.000
7,118.067,0.00,-0.0417,-0.04157,7.000
7,118.200,0.00,-0.0004,-0.00030,7.000
7,118.333,0.00,-0.0004,-0.00030,7.000
7,118.467,-0.01,-0.0004,-0.00030,7.000
7,118.600,0.00,-0.0004,-0.00030,7.000
7,118.733,-0.01,-0.0004,-0.00030,7.000
7,118.867,0.00,-0.0004,-0.00030,7.000
7,119.000,0.00,-0.0004,-0.00030,7.000
7,119.133,0.00,-0.0004,-0.00030,7.000
7,119.267,0.00,-0.0004,-0.00030,7.000
7,119.400,0.00,-0.0004,-0.00030,7.000
7,119.533,0.00,-0.0003,-0.00020,7.000
7,119.667,0.00,-0.0003,-0.00020,7.000
7,119.800,0.00,-0.0003,-0.00020,7.000
7,119.933,0.00,-0.0003,-0.00020,7.000
7,120.067,0.00,-0.0003,-0.00020,7.000
7,120.200,0.00,-0.0003,-0.00020,7.000
7,120.333,0.00,-0.0003,-0.00020,7.000
7,120.467,0.00,-0.0003,-0.00020,7.000
7,120.600,0.00,-0.0003,-0.00020,7.000
7,120.733,0.00,-0.0003,-0.00020,7.000
7,120.867,0.00,-0.0003,-0.00020,7.000
7,121.000,0.00,-0.0003,-0.00020,7.000
7,121.267,0.00,-0.0002,-0.00010,7.000
7,121.400,0.00,-0.0002,-0.00010,7.000
7,121.533,0.00,-0.0002,-0.00010,7.000
7,121.667,0.00,-0.0002,-0.00010,7.000
7,121.800,0.00,-0.0002,-0.00010,7.000
7,121.933,0.00,-0.0002,-0.00010,7.000
7,122.067,0.00,-0.0002,-0.00010,7.000
8,122.400,0.00,0.1515,0.15160,8.000
8,122.533,0.01,0.2849,0.28503,8.000
8,122.667,0.00,0.4185,0.41857,8.000
8,122.800,0.00,0.5516,0.55170,8.000
8,122.933,0.00,0.6850,0.68513,8.000
8,123.067,0.00,0.8184,0.81850,8.000
8,123.200,0.00,0.9516,0.95170,8.000
8,123.333,0.00,1.0851,1.08523,8.000
8,123.467,0.00,1.2185,1.21857,8.000
8,123.600,0.00,1.3516,1.35170,8.000
8,123.733,0.00,1.4850,1.48510,8.000
8,123.867,0.00,1.6185,1.61857,8.000
8,124.000,0.00,1.7516,1.75170,8.000
8,124.133,0.00,1.8850,1.88510,8.000
8,124.267,0.00,2.0185,2.01860,8.000
8,124.400,0.00,2.1517,2.15180,8.000
8,124.533,0.01,2.2851,2.28517,8.000
8,124.667,0.00,2.4185,2.41863,8.000
8,124.800,0.01,2.5518,2.55190,8.000
8,124.933,0.00,2.6851,2.68523,8.000
8,125.067,0.00,2.8185,2.81860,8.000
8,125.200,0.00,2.9518,2.95190,8.000
8,125.333,0.00,3.0850,3.08510,8.000
8,125.467,0.01,3.2185,3.21857,8.000
8,125.600,0.00,3.3517,3.35180,8.000
8,125.733,0.00,3.4851,3.48517,8.000
8,125.867,0.00,3.6185,3.61863,8.000
8,126.000,0.01,3.7518,3.75190,8.000
8,126.133,0.01,3.8851,3.88523,8.000
8,126.267,0.00,4.0185,4.01860,8.000
8,126.400,0.01,4.1518,4.15190,8.000
8,126.533,0.01,4.2851,4.28517,8.000
8,126.667,0.01,4.4185,4.41857,8.000
8,126.800,0.01,4.5519,4.55200,8.000
8,126.933,0.00,4.6852,4.68527,8.000
8,127.067,0.01,4.8186,4.81873,8.000
8,127.200,0.00,4.9520,4.95210,8.000
8,127.333,0.01,5.0852,5.08527,8.000
8,127.467,0.01,5.2186,5.21873,8.000
8,127.600,0.00,5.3520,5.35210,8.000
8,127.733,0.01,5.4852,5.48527,8.000
8,127.867,0.00,5.6186,5.61873,8.000
8,128.000,0.01,5.7519,5.75200,8.000
8,128.133,0.01,5.8852,5.88527,8.000
8,128.267,0.05,6.0186,6.01870,8.000
8,128.400,0.15,6.1519,6.15200,8.000
8,128.533,0.39,6.2852,6.28533,8.000
8,128.667,0.75,6.4185,6.41863,8.000
8,128.867,1.13,6.5060,6.50607,8.000
8,129.000,0.59,6.3725,6.37260,8.000
8,129.133,0.26,6.2394,6.23947,8.000
8,129.267,0.09,6.1060,6.10613,8.000
8,129.400,0.02,5.9725,5.97260,8.000
8,129.533,0.00,5.8392,5.83927,8.000
8,129.667,0.00,5.7060,5.70607,8.000
8,129.800,0.01,5.5725,5.57260,8.000
8,129.933,0.00,5.4392,5.43930,8.000
8,130.067,0.01,5.3060,5.30610,8.000
8,130.200,0.01,5.1725,5.17260,8.000
8,130.333,0.01,5.0391,5.03923,8.000
8,130.467,0.00,4.9060,4.90607,8.000
8,130.600,0.00,4.7725,4.77260,8.000
8,130.733,0.00,4.6391,4.63920,8.000
8,130.867,0.01,4.5059,4.50603,8.000
8,131.000,0.00,4.3725,4.37260,8.000
8,131.133,0.00,4.2391,4.23917,8.000
8,131.267,0.00,4.1058,4.10593,8.000
8,131.400,0.00,3.9726,3.97270,8.000
8,131.533,0.00,3.8391,3.83917,8.000
8,131.667,0.00,3.7059,3.70600,8.000
8,131.800,0.00,3.5724,3.57250,8.000
8,131.933,0.00,3.4389,3.43903,8.000
8,132.067,0.01,3.3057,3.30583,8.000
8,132.200,0.00,3.1724,3.17250,8.000
8,132.333,0.00,3.0389,3.03900,8.000
8,132.467,0.00,2.9057,2.90583,8.000
8,132.600,0.00,2.7724,2.77250,8.000
8,132.733,0.00,2.6390,2.63907,8.000
8,132.867,0.00,2.5056,2.50573,8.000
8,133.000,0.00,2.3725,2.37260,8.000
8,133.133,0.01,2.2388,2.23893,8.000
8,133.267,0.01,2.1056,2.10573,8.000
8,133.400,0.00,1.9723,1.97240,8.000
8,133.533,0.00,1.8389,1.83897,8.000
8,133.667,0.01,1.7056,1.70573,8.000
8,133.800,0.00,1.5723,1.57240,8.000
8,133.933,0.00,1.4388,1.43890,8.000
8,134.067,0.00,1.3054,1.30553,8.000
8,134.200,0.00,1.1724,1.17250,8.000
8,134.333,0.00,1.0390,1.03907,8.000
8,134.467,0.00,0.9056,0.90570,8.000
8,134.600,0.00,0.7724,0.77250,8.000
8,134.733,0.00,0.6388,0.63887,8.000
8,134.867,0.01,0.5056,0.50567,8.000
8,135.000,0.01,0.3723,0.37240,8.000
8,135.133,0.00,0.2389,0.23897,8.000
8,135.267,0.00,0.1055,0.10563,8.000
8,135.400,0.00,-0.0277,-0.02760,8.000
8,135.533,0.00,-0.0002,-0.00007,8.000
8,135.667,0.00,-0.0004,-0.00030,8.000
8,135.800,0.00,-0.0004,-0.00030,8.000
8,135.933,0.00,-0.0004,-0.00030,8.000
8,136.067,0.00,-0.0004,-0.00030,8.000
8,136.200,0.00,-0.0004,-0.00030,8.000
8,136.333,0.00,-0.0004,-0.00030,8.000
8,136.467,0.00,-0.0004,-0.00030,8.000
8,136.600,0.00,-0.0004,-0.00030,8.000
8,136.733,0.00,-0.0003,-0.00020,8.000
8,136.867,0.00,-0.0003,-0.00020,8.000
8,137.000,0.00,-0.0003,-0.00020,8.000
8,137.133,0.00,-0.0003,-0.00020,8.000
8,137.267,0.00,-0.0003,-0.00020,8.000
8,137.400,0.00,-0.0003,-0.00020,8.000
8,137.533,0.00,-0.0003,-0.00020,8.000
8,137.667,0.00,-0.0003,-0.00020,8.000
8,137.800,0.00,-0.0003,-0.00020,8.000
8,137.933,0.00,-0.0003,-0.00020,8.000
8,138.067,0.00,-0.0003,-0.00020,8.000
8,138.200,0.00,-0.0003,-0.00020,8.000
8,138.333,0.00,-0.0003,-0.00020,8.000
8,138.600,0.00,-0.0002,-0.00010,8.000
8,138.733,0.01,-0.0002,-0.00010,8.000
8,138.867,0.00,-0.0002,-0.00010,8.000
8,139.000,0.00,-0.0002,-0.00010,8.000
8,139.133,0.00,-0.0002,-0.00010,8.000
8,139.267,0.00,-0.0002,-0.00010,8.000
8,139.400,0.00,-0.0002,-0.00010,8.000
9,139.733,0.00,0.0718,0.07190,9.000
9,139.867,0.00,0.2053,0.20540,9.000
9,140.000,0.00,0.3387,0.33880,9.000
9,140.133,0.00,0.4721,0.47217,9.000
9,140.267,0.00,0.6053,0.60543,9.000
9,140.400,0.01,0.7388,0.73890,9.000
9,140.533,0.00,0.8720,0.87207,9.000
9,140.667,0.00,1.0055,1.00557,9.000
9,140.800,0.00,1.1390,1.13910,9.000
9,140.933,0.00,1.2720,1.27207,9.000
9,141.067,0.01,1.4053,1.40543,9.000
9,141.200,0.00,1.5389,1.53900,9.000
9,141.333,0.00,1.6720,1.67210,9.000
9,141.467,0.00,1.8054,1.80547,9.000
9,141.600,0.00,1.9388,1.93890,9.000
9,141.733,0.00,2.0721,2.07220,9.000
9,141.867,0.00,2.2054,2.20547,9.000
9,142.000,0.00,2.3389,2.33900,9.000
9,142.133,0.00,2.4721,2.47217,9.000
9,142.267,0.00,2.6054,2.60553,9.000
9,142.400,0.00,2.7388,2.73890,9.000
9,142.533,0.00,2.8722,2.87227,9.000
9,142.667,0.00,3.0054,3.00553,9.000
9,142.800,0.00,3.1387,3.13880,9.000
9,142.933,0.00,3.2721,3.27220,9.000
9,143.067,0.00,3.4054,3.40553,9.000
9,143.200,0.00,3.5387,3.53880,9.000
9,143.333,0.00,3.6722,3.67227,9.000
9,143.467,0.00,3.8054,3.80553,9.000
9,143.600,0.00,3.9389,3.93900,9.000
9,143.733,0.00,4.0722,4.07227,9.000
9,143.867,0.00,4.2054,4.20553,9.000
9,144.000,0.00,4.3388,4.33890,9.000
9,144.133,0.00,4.4723,4.47240,9.000
9,144.267,0.01,4.6055,4.60557,9.000
9,144.400,0.00,4.7389,4.73900,9.000
9,144.533,0.00,4.8723,4.87237,9.000
9,144.667,0.01,5.0055,5.00563,9.000
9,144.800,0.00,5.1388,5.13890,9.000
9,144.933,0.00,5.2724,5.27247,9.000
9,145.067,0.00,5.4056,5.40567,9.000
9,145.200,0.00,5.5389,5.53900,9.000
9,145.333,0.00,5.6723,5.67237,9.000
9,145.467,0.00,5.8054,5.80550,9.000
9,145.600,0.02,5.9388,5.93890,9.000
9,145.733,0.08,6.0722,6.07233,9.000
9,145.867,0.23,6.2055,6.20563,9.000
9,146.000,0.52,6.3389,6.33900,9.000
9,146.133,0.94,6.4723,6.47240,9.000
9,146.333,0.86,6.4462,6.44630,9.000
9,146.467,0.43,6.3130,6.31307,9.000
9,146.600,0.17,6.1798,6.17990,9.000
9,146.733,0.05,6.0461,6.04623,9.000
9,146.867,0.01,5.9130,5.91307,9.000
9,147.000,0.01,5.7795,5.77960,9.000
9,147.133,0.00,5.6462,5.64627,9.000
9,147.267,0.00,5.5129,5.51297,9.000
9,147.400,0.00,5.3797,5.37980,9.000
9,147.533,0.01,5.2462,5.24630,9.000
9,147.667,0.00,5.1128,5.11293,9.000
9,147.800,0.00,4.9797,4.97980,9.000
9,147.933,0.00,4.8461,4.84623,9.000
9,148.067,0.00,4.7129,4.71297,9.000
9,148.200,0.00,4.5796,4.57970,9.000
9,148.333,0.00,4.4461,4.44617,9.000
9,148.467,0.00,4.3128,4.31287,9.000
9,148.600,0.00,4.1795,4.17960,9.000
9,148.733,0.00,4.0460,4.04613,9.000
9,148.867,0.00,3.9127,3.91283,9.000
9,149.000,0.00,3.7796,3.77970,9.000
9,149.133,0.00,3.6461,3.64620,9.000
9,149.267,0.00,3.5126,3.51273,9.000
9,149.400,0.00,3.3794,3.37950,9.000
9,149.533,0.00,3.2460,3.24610,9.000
9,149.667,0.00,3.1126,3.11273,9.000
9,149.800,0.00,2.9795,2.97960,9.000
9,149.933,0.00,2.8460,2.84610,9.000
9,150.067,0.00,2.7127,2.71280,9.000
9,150.200,0.01,2.5794,2.57950,9.000
9,150.333,0.00,2.4460,2.44610,9.000
9,150.467,0.00,2.3126,2.31273,9.000
9,150.600,0.00,2.1794,2.17950,9.000
9,150.733,0.00,2.0460,2.04607,9.000
9,150.867,0.00,1.9126,1.91267,9.000
9,151.000,0.00,1.7794,1.77950,9.000
9,151.133,0.00,1.6459,1.64600,9.000
9,151.267,0.00,1.5125,1.51263,9.000
9,151.400,0.01,1.3793,1.37940,9.000
9,151.533,0.00,1.2459,1.24597,9.000
9,151.667,0.00,1.1127,1.11277,9.000
9,151.800,0.01,0.9794,0.97950,9.000
9,151.933,0.00,0.8459,0.84603,9.000
9,152.067,0.00,0.7125,0.71263,9.000
9,152.200,0.00,0.5792,0.57930,9.000
9,152.333,0.00,0.4459,0.44603,9.000
9,152.467,0.00,0.3125,0.31260,9.000
9,152.600,0.00,0.1793,0.17940,9.000
9,152.733,0.00,0.0458,0.04593,9.000
9,152.867,0.00,-0.0324,-0.03227,9.000
9,153.000,0.00,-0.0004,-0.00030,9.000
9,153.133,0.00,-0.0004,-0.00030,9.000
9,153.267,0.00,-0.0004,-0.00030,9.000
9,153.400,0.00,-0.0004,-0.00030,9.000
9,153.533,0.00,-0.0004,-0.00030,9.000
9,153.667,0.00,-0.0004,-0.00030,9.000
9,153.800,0.00,-0.0004,-0.00030,9.000
9,153.933,0.00,-0.0004,-0.00030,9.000
9,154.067,0.00,-0.0004,-0.00030,9.000
9,154.200,0.00,-0.0004,-0.00030,9.000
9,154.333,0.00,-0.0003,-0.00020,9.000
9,154.467,0.00,-0.0003,-0.00020,9.000
9,154.600,-0.01,-0.0003,-0.00020,9.000
9,154.733,0.00,-0.0003,-0.00020,9.000
9,154.867,0.00,-0.0003,-0.00020,9.000
9,155.000,0.00,-0.0003,-0.00020,9.000
9,155.133,0.00,-0.0003,-0.00020,9.000
9,155.267,0.00,-0.0003,-0.00020,9.000
9,155.400,0.00,-0.0003,-0.00020,9.000
9,155.533,0.00,-0.0003,-0.00020,9.000
9,155.667,0.00,-0.0003,-0.00020,9.000
9,155.800,0.00,-0.0003,-0.00020,9.000
9,156.067,0.00,-0.0003,-0.00020,9.000
9,156.200,0.00,-0.0002,-0.00010,9.000
9,156.333,0.00,-0.0002,-0.00010,9.000
9,156.467,0.00,-0.0002,-0.00010,9.000
9,156.600,0.00,-0.0002,-0.00010,9.000
9,156.733,0.00,-0.0002,-0.00010,9.000
9,156.867,0.00,-0.0002,-0.00010,9.000
10,157.200,0.00,0.1417,0.14180,10.000
10,157.333,0.00,0.2749,0.27503,10.000
10,157.467,0.00,0.4084,0.40847,10.000
10,157.600,0.00,0.5418,0.54190,10.000
10,157.733,-0.01,0.6749,0.67503,10.000
10,157.867,0.00,0.8084,0.80850,10.000
10,158.000,0.00,0.9419,0.94200,10.000
10,158.133,0.00,1.0752,1.07527,10.000
10,158.267,0.00,1.2085,1.20863,10.000
10,158.400,0.00,1.3417,1.34180,10.000
10,158.533,0.00,1.4749,1.47503,10.000
10,158.667,0.00,1.6084,1.60850,10.000
10,158.800,0.00,1.7419,1.74200,10.000
10,158.933,0.00,1.8751,1.87517,10.000
10,159.067,0.00,2.0084,2.00853,10.000
10,159.200,0.00,2.1419,2.14200,10.000
10,159.333,0.00,2.2750,2.27513,10.000
10,159.467,0.00,2.4084,2.40850,10.000
10,159.600,0.00,2.5419,2.54200,10.000
10,159.733,0.00,2.6752,2.67527,10.000
10,159.867,0.00,2.8085,2.80860,10.000
10,160.000,0.00,2.9419,2.94200,10.000
10,160.133,0.00,3.0750,3.07513,10.000
10,160.267,0.00,3.2084,3.20853,10.000
10,160.400,0.00,3.3418,3.34190,10.000
10,160.533,0.00,3.4750,3.47510,10.000
10,160.667,0.00,3.6084,3.60853,10.000
10,160.800,0.00,3.7419,3.74200,10.000
10,160.933,0.00,3.8752,3.87527,10.000
10,161.067,0.00,4.0084,4.00853,10.000
10,161.200,0.00,4.1419,4.14200,10.000
10,161.333,0.00,4.2751,4.27523,10.000
10,161.467,0.00,4.4084,4.40847,10.000
10,161.600,0.00,4.5420,4.54210,10.000
10,161.733,0.00,4.6752,4.67533,10.000
10,161.867,0.00,4.8085,4.80857,10.000
10,162.000,0.00,4.9420,4.94210,10.000
10,162.133,0.00,5.0752,5.07530,10.000
10,162.267,0.00,5.2085,5.20857,10.000
10,162.400,0.00,5.3420,5.34210,10.000
10,162.533,0.00,5.4753,5.47537,10.000
10,162.667,0.00,5.6085,5.60860,10.000
10,162.800,0.00,5.7419,5.74200,10.000
10,162.933,0.00,5.8752,5.87533,10.000
10,163.067,0.04,6.0085,6.00860,10.000
10,163.200,0.13,6.1419,6.14200,10.000
10,163.333,0.36,6.2753,6.27543,10.000
10,163.467,0.71,6.4085,6.40863,10.000
10,163.667,1.09,6.4959,6.49597,10.000
10,163.800,0.56,6.3626,6.36270,10.000
10,163.933,0.24,6.2295,6.22957,10.000
10,164.067,0.07,6.0960,6.09607,10.000
10,164.200,0.01,5.9625,5.96260,10.000
10,164.333,0.00,5.8293,5.82940,10.000
10,164.467,0.00,5.6959,5.69603,10.000
10,164.600,0.00,5.5625,5.56260,10.000
10,164.733,0.00,5.4294,5.42947,10.000
10,164.867,0.00,5.2959,5.29603,10.000
10,165.000,0.00,5.1624,5.16250,10.000
10,165.133,0.00,5.0293,5.02937,10.000
10,165.267,0.00,4.8959,4.89603,10.000
10,165.400,0.00,4.7625,4.76260,10.000
10,165.533,0.00,4.6292,4.62930,10.000
10,165.667,0.00,4.4959,4.49597,10.000
10,165.800,0.00,4.3623,4.36240,10.000
10,165.933,0.00,4.2292,4.22927,10.000
10,166.067,0.00,4.0958,4.09590,10.000
10,166.200,0.00,3.9623,3.96240,10.000
10,166.333,0.00,3.8292,3.82927,10.000
10,166.467,0.00,3.6959,3.69600,10.000
10,166.600,0.00,3.5623,3.56240,10.000
10,166.733,0.00,3.4291,3.42920,10.000
10,166.867,0.00,3.2958,3.29590,10.000
10,167.000,0.00,3.1622,3.16230,10.000
10,167.133,0.00,3.0291,3.02917,10.000
10,167.267,0.00,2.8957,2.89583,10.000
10,167.400,0.00,2.7623,2.76240,10.000
10,167.533,0.00,2.6291,2.62920,10.000
10,167.667,0.00,2.4957,2.49583,10.000
10,167.800,0.00,2.3622,2.36230,10.000
10,167.933,0.00,2.2290,2.22907,10.000
10,168.067,0.00,2.0956,2.09573,10.000
10,168.200,0.00,1.9622,1.96230,10.000
10,168.333,0.00,1.8289,1.82903,10.000
10,168.467,0.00,1.6957,1.69577,10.000
10,168.600,0.00,1.5621,1.56220,10.000
10,168.733,0.00,1.4289,1.42897,10.000
10,168.867,0.00,1.2955,1.29560,10.000
10,169.000,0.00,1.1623,1.16240,10.000
10,169.133,0.00,1.0289,1.02903,10.000
10,169.267,0.00,0.8957,0.89577,10.000
10,169.400,0.00,0.7622,0.76230,10.000
10,169.533,0.00,0.6289,0.62897,10.000
10,169.667,0.00,0.4957,0.49583,10.000
10,169.800,0.00,0.3622,0.36230,10.000
10,169.933,0.00,0.2288,0.22893,10.000
10,170.067,0.00,0.0955,0.09563,10.000
10,170.267,0.00,-0.0316,-0.03150,10.000
10,170.400,0.00,-0.0004,-0.00030,10.000
10,170.533,0.00,-0.0004,-0.00030,10.000
10,170.667,0.00,-0.0004,-0.00030,10.000
10,170.800,0.00,-0.0004,-0.00030,10.000
10,170.933,0.00,-0.0004,-0.00030,10.000
10,171.067,0.00,-0.0004,-0.00030,10.000
10,171.200,0.00,-0.0004,-0.00030,10.000
10,171.333,0.00,-0.0004,-0.00030,10.000
10,171.467,0.00,-0.0004,-0.00030,10.000
10,171.600,-0.01,-0.0004,-0.00030,10.000
10,171.733,0.00,-0.0003,-0.00020,10.000
10,171.867,0.00,-0.0003,-0.00020,10.000
10,172.000,-0.01,-0.0003,-0.00020,10.000
10,172.133,0.00,-0.0003,-0.00020,10.000
10,172.267,0.00,-0.0003,-0.00020,10.000
10,172.400,0.00,-0.0003,-0.00020,10.000
10,172.533,0.00,-0.0003,-0.00020,10.000
10,172.667,0.00,-0.0003,-0.00020,10.000
10,172.800,0.00,-0.0003,-0.00020,10.000
10,172.933,0.00,-0.0003,-0.00020,10.000
10,173.067,0.00,-0.0003,-0.00020,10.000
10,173.200,0.00,-0.0003,-0.00020,10.000
10,173.467,0.00,-0.0003,-0.00020,10.000
10,173.600,0.00,-0.0002,-0.00010,10.000
10,173.733,-0.01,-0.0002,-0.00010,10.000
10,173.867,0.00,-0.0002,-0.00010,10.000
10,174.000,0.00,-0.0002,-0.00010,10.000
10,174.133,0.00,-0.0002,-0.00010,10.000
10,174.267,0.00,-0.0002,-0.00010,10.000