File: calibDATA_loadcell/date_02:15:2018/Instron_02.15.2018/1_1N_2__1mm.s_0_0.txt
""
"Test Method","Radhen_Load_Cntrl_Cmprsn_250N_12-7.msm"
"Sample I. D.","Sample1.mss"
"Specimen Number","6"

"TheCycle_Output ()","_Time (s)","_Load (N)","_Extension (mm)","RealTimeDepth (mm)","CycleNumber ()"

1,0.267,0.01,0.0553,0.05530,1.000
1,0.333,0.00,0.1218,0.12183,1.000
1,0.400,0.01,0.1887,0.18870,1.000
1,0.467,0.01,0.2555,0.25553,1.000
1,0.533,0.00,0.3221,0.32207,1.000
1,0.600,0.01,0.3889,0.38890,1.000
1,0.667,0.00,0.4555,0.45547,1.000
1,0.733,0.00,0.5222,0.52217,1.000
1,0.800,0.01,0.5889,0.58890,1.000
1,0.867,0.00,0.6555,0.65547,1.000
1,0.933,0.01,0.7222,0.72217,1.000
1,1.000,0.00,0.7888,0.78880,1.000
1,1.067,0.00,0.8555,0.85550,1.000
1,1.133,0.00,0.9222,0.92217,1.000
1,1.200,0.01,0.9888,0.98880,1.000
1,1.267,0.01,1.0556,1.05557,1.000
1,1.333,0.00,1.1222,1.12223,1.000
1,1.400,0.01,1.1891,1.18910,1.000
1,1.467,0.00,1.2556,1.25557,1.000
1,1.533,0.00,1.3221,1.32207,1.000
1,1.600,0.01,1.3888,1.38880,1.000
1,1.667,0.00,1.4555,1.45547,1.000
1,1.733,0.00,1.5221,1.52207,1.000
1,1.800,0.00,1.5889,1.58890,1.000
1,1.867,0.01,1.6555,1.65550,1.000
1,1.933,0.03,1.7222,1.72223,1.000
1,2.000,0.06,1.7889,1.78890,1.000
1,2.067,0.10,1.8555,1.85547,1.000
1,2.133,0.17,1.9222,1.92220,1.000
1,2.200,0.28,1.9890,1.98900,1.000
1,2.267,0.42,2.0555,2.05553,1.000
1,2.333,0.60,2.1222,2.12223,1.000
1,2.400,0.79,2.1888,2.18880,1.000
1,2.467,1.02,2.2555,2.25553,1.000
1,2.600,1.04,2.2492,2.24920,1.000
1,2.667,0.77,2.1829,2.18290,1.000
1,2.733,0.55,2.1163,2.11633,1.000
1,2.800,0.37,2.0495,2.04950,1.000
1,2.867,0.23,1.9831,1.98307,1.000
1,2.933,0.13,1.9163,1.91630,1.000
1,3.000,0.07,1.8494,1.84940,1.000
1,3.067,0.04,1.7830,1.78300,1.000
1,3.133,0.02,1.7163,1.71633,1.000
1,3.200,0.01,1.6496,1.64960,1.000
1,3.267,0.00,1.5829,1.58290,1.000
1,3.333,0.00,1.5162,1.51620,1.000
1,3.400,0.00,1.4494,1.44940,1.000
1,3.467,0.00,1.3829,1.38293,1.000
1,3.533,0.00,1.3161,1.31613,1.000
1,3.600,0.00,1.2495,1.24950,1.000
1,3.667,0.00,1.1830,1.18297,1.000
1,3.733,0.00,1.1163,1.11630,1.000
1,3.800,0.00,1.0496,1.04960,1.000
1,3.867,0.00,0.9830,0.98297,1.000
1,3.933,0.00,0.9162,0.91620,1.000
1,4.000,0.00,0.8494,0.84940,1.000
1,4.067,0.00,0.7830,0.78297,1.000
1,4.133,0.00,0.7161,0.71613,1.000
1,4.200,0.00,0.6494,0.64940,1.000
1,4.267,0.00,0.5829,0.58290,1.000
1,4.333,0.00,0.5162,0.51617,1.000
1,4.400,0.00,0.4494,0.44940,1.000
1,4.467,0.01,0.3829,0.38287,1.000
1,4.533,0.00,0.3161,0.31613,1.000
1,4.600,0.00,0.2493,0.24930,1.000
1,4.667,0.00,0.1829,0.18287,1.000
1,4.733,0.00,0.1160,0.11600,1.000
1,4.800,0.00,0.0492,0.04920,1.000
1,5.000,0.01,-0.0002,-0.00020,1.000
1,5.067,0.00,-0.0002,-0.00020,1.000
1,5.133,0.00,-0.0002,-0.00020,1.000
1,5.200,0.00,-0.0002,-0.00020,1.000
1,5.267,0.01,-0.0002,-0.00020,1.000
1,5.333,0.00,-0.0002,-0.00020,1.000
1,5.400,0.00,-0.0002,-0.00020,1.000
1,5.467,0.01,-0.0002,-0.00020,1.000
1,5.533,0.00,-0.0002,-0.00020,1.000
1,5.600,0.00,-0.0002,-0.00020,1.000
1,5.667,0.00,-0.0002,-0.00020,1.000
1,5.733,0.00,-0.0002,-0.00020,1.000
1,5.800,0.01,-0.0002,-0.00020,1.000
1,5.867,0.01,-0.0002,-0.00020,1.000
1,5.933,0.00,-0.0002,-0.00020,1.000
1,6.000,0.00,-0.0002,-0.00020,1.000
1,6.067,0.00,-0.0002,-0.00020,1.000
1,6.133,0.01,-0.0002,-0.00020,1.000
1,6.200,0.00,-0.0002,-0.00020,1.000
1,6.267,0.01,-0.0002,-0.00020,1.000
1,6.333,0.01,-0.0002,-0.00020,1.000
1,6.400,0.01,-0.0001,-0.00010,1.000
1,6.467,0.01,-0.0001,-0.00010,1.000
1,6.533,0.00,-0.0001,-0.00010,1.000
1,6.600,0.01,-0.0001,-0.00010,1.000
1,6.667,0.01,-0.0001,-0.00010,1.000
1,6.733,0.00,-0.0001,-0.00010,1.000
1,6.800,0.01,-0.0001,-0.00010,1.000
1,6.867,0.01,-0.0001,-0.00010,1.000
1,6.933,0.01,-0.0001,-0.00010,1.000
1,7.000,0.00,-0.0001,-0.00010,1.000
1,7.067,0.01,-0.0001,-0.00010,1.000
1,7.133,0.00,-0.0001,-0.00010,1.000
1,7.200,0.01,-0.0001,-0.00010,1.000
1,7.267,0.01,-0.0001,-0.00010,1.000
1,7.333,0.00,-0.0001,-0.00010,1.000
1,7.400,0.01,-0.0001,-0.00010,1.000
1,7.467,0.01,-0.0001,-0.00010,1.000
1,7.533,0.01,-0.0001,-0.00010,1.000
1,7.600,0.01,-0.0001,-0.00010,1.000
1,7.667,0.01,-0.0001,-0.00010,1.000
1,7.733,0.00,-0.0001,-0.00010,1.000
1,7.800,0.01,-0.0001,-0.00010,1.000
1,7.867,0.00,-0.0001,-0.00010,1.000
1,7.933,0.01,-0.0001,-0.00010,1.000
1,8.067,0.00,-0.0001,-0.00010,1.000
1,8.133,0.00,-0.0001,-0.00010,1.000
1,8.200,0.01,-0.0001,-0.00010,1.000
1,8.267,0.00,-0.0001,-0.00010,1.000
1,8.333,0.00,-0.0001,-0.00010,1.000
1,8.400,0.00,-0.0001,-0.00010,1.000
1,8.467,0.00,-0.0001,-0.00010,1.000
1,8.533,0.01,-0.0001,-0.00010,1.000
1,8.600,0.00,-0.0001,-0.00010,1.000
1,8.667,0.00,-0.0001,-0.00010,1.000
1,8.733,0.01,-0.0001,-0.00010,1.000
1,8.800,0.00,-0.0001,-0.00010,1.000
1,8.867,0.01,-0.0001,-0.00010,1.000
1,8.933,0.00,-0.0001,-0.00010,1.000
2,9.200,0.00,0.0896,0.08960,2.000
2,9.267,0.00,0.1562,0.15623,2.000
2,9.333,0.00,0.2231,0.22310,2.000
2,9.400,0.00,0.2896,0.28960,2.000
2,9.467,-0.01,0.3564,0.35643,2.000
2,9.533,-0.01,0.4232,0.42320,2.000
2,9.600,-0.01,0.4897,0.48970,2.000
2,9.667,-0.01,0.5565,0.55647,2.000
2,9.733,-0.01,0.6232,0.62317,2.000
2,9.800,0.00,0.6898,0.68980,2.000
2,9.867,0.00,0.7565,0.75647,2.000
2,9.933,-0.01,0.8231,0.82313,2.000
2,10.000,-0.01,0.8896,0.88960,2.000
2,10.067,0.00,0.9564,0.95643,2.000
2,10.133,0.00,1.0232,1.02317,2.000
2,10.200,0.00,1.0898,1.08980,2.000
2,10.267,-0.01,1.1565,1.15653,2.000
2,10.333,0.00,1.2232,1.22320,2.000
2,10.400,0.00,1.2898,1.28980,2.000
2,10.467,-0.01,1.3564,1.35637,2.000
2,10.533,0.00,1.4231,1.42313,2.000
2,10.600,-0.01,1.4897,1.48970,2.000
2,10.667,0.00,1.5563,1.55633,2.000
2,10.733,0.00,1.6231,1.62313,2.000
2,10.800,0.02,1.6897,1.68970,2.000
2,10.867,0.04,1.7565,1.75650,2.000
2,10.933,0.07,1.8232,1.82323,2.000
2,11.000,0.13,1.8898,1.88980,2.000
2,11.067,0.22,1.9566,1.95660,2.000
2,11.133,0.34,2.0232,2.02323,2.000
2,11.200,0.50,2.0897,2.08970,2.000
2,11.267,0.69,2.1564,2.15643,2.000
2,11.333,0.90,2.2232,2.22317,2.000
2,11.467,1.19,2.2836,2.28363,2.000
2,11.533,0.89,2.2172,2.21717,2.000
2,11.600,0.65,2.1505,2.15050,2.000
2,11.667,0.45,2.0839,2.08387,2.000
2,11.733,0.29,2.0173,2.01727,2.000
2,11.800,0.17,1.9507,1.95070,2.000
2,11.867,0.09,1.8839,1.88387,2.000
2,11.933,0.05,1.8171,1.81713,2.000
2,12.000,0.02,1.7507,1.75070,2.000
2,12.067,0.00,1.6840,1.68397,2.000
2,12.133,0.00,1.6172,1.61723,2.000
2,12.200,0.00,1.5506,1.55060,2.000
2,12.267,-0.01,1.4838,1.48380,2.000
2,12.333,0.00,1.4172,1.41720,2.000
2,12.400,0.00,1.3506,1.35060,2.000
2,12.467,0.00,1.2838,1.28380,2.000
2,12.533,0.00,1.2172,1.21723,2.000
2,12.600,0.00,1.1507,1.15070,2.000
2,12.667,0.00,1.0839,1.08390,2.000
2,12.733,0.00,1.0172,1.01723,2.000
2,12.800,0.00,0.9505,0.95050,2.000
2,12.867,0.00,0.8837,0.88367,2.000
2,12.933,0.00,0.8172,0.81717,2.000
2,13.000,0.00,0.7506,0.75060,2.000
2,13.067,-0.01,0.6838,0.68380,2.000
2,13.133,0.00,0.6171,0.61713,2.000
2,13.200,0.00,0.5505,0.55050,2.000
2,13.267,0.00,0.4837,0.48370,2.000
2,13.333,0.00,0.4171,0.41713,2.000
2,13.400,-0.01,0.3506,0.35060,2.000
2,13.467,0.00,0.2837,0.28370,2.000
2,13.533,0.00,0.2171,0.21707,2.000
2,13.600,0.00,0.1503,0.15030,2.000
2,13.667,0.00,0.0835,0.08353,2.000
2,13.733,0.00,0.0171,0.01707,2.000
2,13.867,0.00,-0.0230,-0.02303,2.000
2,13.933,0.00,-0.0002,-0.00017,2.000
2,14.000,0.00,-0.0002,-0.00020,2.000
2,14.067,0.00,-0.0002,-0.00020,2.000
2,14.133,0.00,-0.0002,-0.00020,2.000
2,14.200,0.00,-0.0002,-0.00020,2.000
2,14.267,-0.01,-0.0002,-0.00020,2.000
2,14.333,0.00,-0.0002,-0.00020,2.000
2,14.400,-0.01,-0.0002,-0.00020,2.000
2,14.467,0.00,-0.0002,-0.00020,2.000
2,14.533,0.00,-0.0002,-0.00020,2.000
2,14.600,0.00,-0.0002,-0.00020,2.000
2,14.667,0.00,-0.0002,-0.00020,2.000
2,14.733,0.00,-0.0002,-0.00020,2.000
2,14.800,0.00,-0.0002,-0.00020,2.000
2,14.867,0.00,-0.0002,-0.00020,2.000
2,14.933,0.00,-0.0002,-0.00020,2.000
2,15.000,0.00,-0.0002,-0.00020,2.000
2,15.067,-0.01,-0.0002,-0.00020,2.000
2,15.133,0.00,-0.0002,-0.00020,2.000
2,15.200,-0.01,-0.0002,-0.00020,2.000
2,15.267,-0.01,-0.0002,-0.00020,2.000
2,15.333,-0.01,-0.0002,-0.00020,2.000
2,15.400,0.00,-0.0002,-0.00020,2.000
2,15.467,-0.01,-0.0001,-0.00010,2.000
2,15.533,0.00,-0.0001,-0.00010,2.000
2,15.600,-0.01,-0.0001,-0.00010,2.000
2,15.667,0.00,-0.0001,-0.00010,2.000
2,15.733,0.00,-0.0001,-0.00010,2.000
2,15.800,0.00,-0.0001,-0.00010,2.000
2,15.867,0.00,-0.0001,-0.00010,2.000
2,15.933,0.00,-0.0001,-0.00010,2.000
2,16.000,0.00,-0.0001,-0.00010,2.000
2,16.067,0.00,-0.0001,-0.00010,2.000
2,16.133,0.00,-0.0001,-0.00010,2.000
2,16.200,0.00,-0.0001,-0.00010,2.000
2,16.267,0.00,-0.0001,-0.00010,2.000
2,16.333,0.00,-0.0001,-0.00010,2.000
2,16.400,0.00,-0.0001,-0.00010,2.000
2,16.467,-0.01,-0.0001,-0.00010,2.000
2,16.533,-0.01,-0.0001,-0.00010,2.000
2,16.600,0.00,-0.0001,-0.00010,2.000
2,16.667,0.00,-0.0001,-0.00010,2.000
2,16.733,0.00,-0.0001,-0.00010,2.000
2,16.800,0.00,-0.0001,-0.00010,2.000
2,16.933,0.00,-0.0001,-0.00010,2.000
2,17.000,-0.01,-0.0001,-0.00010,2.000
2,17.067,0.00,-0.0001,-0.00010,2.000
2,17.133,0.00,-0.0001,-0.00010,2.000
2,17.200,-0.01,-0.0001,-0.00010,2.000
2,17.267,0.00,-0.0001,-0.00010,2.000
2,17.333,0.00,-0.0001,-0.00010,2.000
2,17.400,0.00,-0.0001,-0.00010,2.000
2,17.467,0.00,-0.0001,-0.00010,2.000
2,17.533,-0.01,-0.0001,-0.00010,2.000
2,17.600,0.00,-0.0001,-0.00010,2.000
2,17.667,0.00,-0.0001,-0.00010,2.000
2,17.733,-0.01,-0.0001,-0.00010,2.000
2,17.800,0.00,-0.0001,-0.00010,2.000
3,18.000,0.00,0.0000,0.00000,3.000
3,18.067,0.01,0.0462,0.04620,3.000
3,18.133,0.01,0.1129,0.11293,3.000
3,18.200,0.01,0.1797,0.17970,3.000
3,18.267,0.01,0.2463,0.24633,3.000
3,18.333,0.01,0.3131,0.31313,3.000
3,18.400,0.01,0.3798,0.37980,3.000
3,18.467,0.00,0.4464,0.44637,3.000
3,18.533,0.01,0.5131,0.51310,3.000
3,18.600,0.01,0.5798,0.57980,3.000
3,18.667,0.01,0.6464,0.64643,3.000
3,18.733,0.01,0.7132,0.71317,3.000
3,18.800,0.01,0.7799,0.77990,3.000
3,18.867,0.00,0.8464,0.84637,3.000
3,18.933,0.01,0.9131,0.91313,3.000
3,19.000,0.01,0.9798,0.97980,3.000
3,19.067,0.01,1.0465,1.04647,3.000
3,19.133,0.01,1.1132,1.11320,3.000
3,19.200,0.00,1.1798,1.17980,3.000
3,19.267,0.01,1.2464,1.24643,3.000
3,19.333,0.01,1.3131,1.31307,3.000
3,19.400,0.01,1.3798,1.37980,3.000
3,19.467,0.00,1.4464,1.44637,3.000
3,19.533,0.01,1.5130,1.51303,3.000
3,19.600,0.01,1.5797,1.57970,3.000
3,19.667,0.01,1.6464,1.64640,3.000
3,19.733,0.03,1.7132,1.71320,3.000
3,19.800,0.06,1.7798,1.77980,3.000
3,19.867,0.10,1.8464,1.84640,3.000
3,19.933,0.17,1.9132,1.91317,3.000
3,20.000,0.27,1.9798,1.97980,3.000
3,20.067,0.41,2.0466,2.04657,3.000
3,20.133,0.58,2.1132,2.11320,3.000
3,20.200,0.77,2.1797,2.17970,3.000
3,20.267,0.99,2.2464,2.24643,3.000
3,20.400,1.10,2.2606,2.26060,3.000
3,20.467,0.82,2.1938,2.19383,3.000
3,20.533,0.59,2.1271,2.12713,3.000
3,20.600,0.41,2.0607,2.06070,3.000
3,20.667,0.26,1.9939,1.99393,3.000
3,20.733,0.15,1.9272,1.92717,3.000
3,20.800,0.09,1.8605,1.86050,3.000
3,20.867,0.05,1.7939,1.79393,3.000
3,20.933,0.02,1.7272,1.72720,3.000
3,21.000,0.01,1.6606,1.66060,3.000
3,21.067,0.00,1.5938,1.59383,3.000
3,21.133,0.01,1.5270,1.52703,3.000
3,21.200,0.01,1.4606,1.46060,3.000
3,21.267,0.01,1.3939,1.39387,3.000
3,21.333,0.01,1.3271,1.32707,3.000
3,21.400,0.00,1.2606,1.26060,3.000
3,21.467,0.01,1.1939,1.19393,3.000
3,21.533,0.01,1.1272,1.12717,3.000
3,21.600,0.01,1.0606,1.06060,3.000
3,21.667,0.01,0.9938,0.99383,3.000
3,21.733,0.01,0.9270,0.92703,3.000
3,21.800,0.01,0.8605,0.86050,3.000
3,21.867,0.00,0.7938,0.79380,3.000
3,21.933,0.01,0.7271,0.72710,3.000
3,22.000,0.01,0.6606,0.66060,3.000
3,22.067,0.01,0.5938,0.59377,3.000
3,22.133,0.01,0.5271,0.52707,3.000
3,22.200,0.01,0.4605,0.46050,3.000
3,22.267,0.00,0.3938,0.39383,3.000
3,22.333,0.01,0.3271,0.32707,3.000
3,22.400,0.01,0.2605,0.26050,3.000
3,22.467,0.01,0.1937,0.19367,3.000
3,22.533,0.01,0.1270,0.12697,3.000
3,22.600,0.01,0.0603,0.06030,3.000
3,22.667,0.01,-0.0063,-0.00630,3.000
3,22.800,0.00,-0.0254,-0.02540,3.000
3,22.867,0.01,-0.0002,-0.00023,3.000
3,22.933,0.00,-0.0002,-0.00020,3.000
3,23.000,0.01,-0.0002,-0.00020,3.000
3,23.067,0.00,-0.0002,-0.00020,3.000
3,23.133,0.01,-0.0002,-0.00020,3.000
3,23.200,0.01,-0.0002,-0.00020,3.000
3,23.267,0.01,-0.0002,-0.00020,3.000
3,23.333,0.00,-0.0002,-0.00020,3.000
3,23.400,0.01,-0.0002,-0.00020,3.000
3,23.467,0.01,-0.0002,-0.00020,3.000
3,23.533,0.01,-0.0002,-0.00020,3.000
3,23.600,0.01,-0.0002,-0.00020,3.000
3,23.667,0.01,-0.0002,-0.00020,3.000
3,23.733,0.01,-0.0002,-0.00020,3.000
3,23.800,0.01,-0.0002,-0.00020,3.000
3,23.867,0.00,-0.0002,-0.00020,3.000
3,23.933,0.01,-0.0002,-0.00020,3.000
3,24.000,0.01,-0.0002,-0.00020,3.000
3,24.067,0.01,-0.0002,-0.00020,3.000
3,24.133,0.00,-0.0002,-0.00020,3.000
3,24.200,0.01,-0.0002,-0.00020,3.000
3,24.267,0.01,-0.0002,-0.00020,3.000
3,24.333,0.00,-0.0002,-0.00020,3.000
3,24.400,0.01,-0.0002,-0.00020,3.000
3,24.467,0.00,-0.0002,-0.00020,3.000
3,24.533,0.01,-0.0002,-0.00020,3.000
3,24.600,0.00,-0.0002,-0.00020,3.000
3,24.667,0.01,-0.0002,-0.00020,3.000
3,24.733,0.01,-0.0002,-0.00020,3.000
3,24.800,0.01,-0.0001,-0.00010,3.000
3,24.867,0.01,-0.0001,-0.00010,3.000
3,24.933,0.00,-0.0001,-0.00010,3.000
3,25.000,0.01,-0.0001,-0.00010,3.000
3,25.067,0.00,-0.0001,-0.00010,3.000
3,25.133,0.01,-0.0001,-0.00010,3.000
3,25.200,0.01,-0.0001,-0.00010,3.000
3,25.267,0.01,-0.0001,-0.00010,3.000
3,25.333,0.00,-0.0001,-0.00010,3.000
3,25.400,0.00,-0.0001,-0.00010,3.000
3,25.467,0.01,-0.0001,-0.00010,3.000
3,25.533,0.01,-0.0001,-0.00010,3.000
3,25.600,0.01,-0.0001,-0.00010,3.000
3,25.667,0.00,-0.0001,-0.00010,3.000
3,25.733,0.01,-0.0001,-0.00010,3.000
3,25.867,0.00,-0.0001,-0.00010,3.000
3,25.933,0.01,-0.0001,-0.00010,3.000
3,26.000,0.01,-0.0001,-0.00010,3.000
3,26.067,0.00,-0.0001,-0.00010,3.000
3,26.133,0.01,-0.0001,-0.00010,3.000
3,26.200,0.01,-0.0001,-0.00010,3.000
3,26.267,0.00,-0.0001,-0.00010,3.000
3,26.333,0.01,-0.0001,-0.00010,3.000
3,26.400,0.00,-0.0001,-0.00010,3.000
3,26.467,0.00,-0.0001,-0.00010,3.000
3,26.533,0.01,-0.0001,-0.00010,3.000
3,26.600,0.01,-0.0001,-0.00010,3.000
3,26.667,0.01,-0.0001,-0.00010,3.000
3,26.733,0.00,-0.0001,-0.00010,3.000
4,27.000,0.00,0.0596,0.05960,4.000
4,27.067,0.00,0.1262,0.12620,4.000
4,27.133,0.00,0.1930,0.19300,4.000
4,27.200,0.00,0.2598,0.25980,4.000
4,27.267,0.00,0.3264,0.32637,4.000
4,27.333,0.00,0.3931,0.39313,4.000
4,27.400,0.00,0.4597,0.45970,4.000
4,27.467,0.00,0.5264,0.52637,4.000
4,27.533,0.00,0.5932,0.59317,4.000
4,27.600,0.00,0.6598,0.65980,4.000
4,27.667,0.00,0.7264,0.72637,4.000
4,27.733,0.00,0.7931,0.79310,4.000
4,27.800,0.00,0.8597,0.85970,4.000
4,27.867,0.00,0.9263,0.92633,4.000
4,27.933,0.00,0.9932,0.99320,4.000
4,28.000,0.00,1.0599,1.05990,4.000
4,28.067,0.00,1.1265,1.12647,4.000
4,28.133,0.00,1.1933,1.19327,4.000
4,28.200,-0.01,1.2599,1.25990,4.000
4,28.267,0.00,1.3263,1.32630,4.000
4,28.333,0.00,1.3931,1.39313,4.000
4,28.400,0.00,1.4597,1.45970,4.000
4,28.467,0.00,1.5263,1.52630,4.000
4,28.533,0.00,1.5932,1.59317,4.000
4,28.600,0.00,1.6598,1.65980,4.000
4,28.667,0.03,1.7264,1.72640,4.000
4,28.733,0.06,1.7932,1.79317,4.000
4,28.800,0.10,1.8599,1.85990,4.000
4,28.867,0.17,1.9264,1.92640,4.000
4,28.933,0.29,1.9933,1.99330,4.000
4,29.000,0.43,2.0598,2.05980,4.000
4,29.067,0.61,2.1264,2.12637,4.000
4,29.133,0.81,2.1931,2.19313,4.000
4,29.200,1.03,2.2597,2.25970,4.000
4,29.333,1.12,2.2673,2.26730,4.000
4,29.400,0.83,2.2003,2.20030,4.000
4,29.467,0.60,2.1338,2.13383,4.000
4,29.533,0.41,2.0673,2.06730,4.000
4,29.600,0.26,2.0005,2.00050,4.000
4,29.667,0.15,1.9339,1.93390,4.000
4,29.733,0.08,1.8673,1.86727,4.000
4,29.800,0.04,1.8005,1.80050,4.000
4,29.867,0.01,1.7339,1.73387,4.000
4,29.933,0.00,1.6673,1.66733,4.000
4,30.000,0.00,1.6005,1.60050,4.000
4,30.067,-0.01,1.5337,1.53373,4.000
4,30.133,0.00,1.4672,1.46723,4.000
4,30.200,0.00,1.4004,1.40040,4.000
4,30.267,0.00,1.3337,1.33370,4.000
4,30.333,0.00,1.2673,1.26727,4.000
4,30.400,0.00,1.2005,1.20050,4.000
4,30.467,0.00,1.1338,1.13380,4.000
4,30.533,0.00,1.0673,1.06727,4.000
4,30.600,0.00,1.0005,1.00050,4.000
4,30.667,0.00,0.9337,0.93373,4.000
4,30.733,0.00,0.8672,0.86717,4.000
4,30.800,0.00,0.8004,0.80040,4.000
4,30.867,0.00,0.7338,0.73383,4.000
4,30.933,0.00,0.6672,0.66717,4.000
4,31.000,0.00,0.6005,0.60050,4.000
4,31.067,0.00,0.5338,0.53377,4.000
4,31.133,0.00,0.4672,0.46717,4.000
4,31.200,0.00,0.4004,0.40040,4.000
4,31.267,0.00,0.3338,0.33377,4.000
4,31.333,0.00,0.2672,0.26717,4.000
4,31.400,0.00,0.2003,0.20030,4.000
4,31.467,0.00,0.1337,0.13367,4.000
4,31.533,0.00,0.0670,0.06700,4.000
4,31.600,0.00,0.0003,0.00030,4.000
4,31.733,0.00,-0.0253,-0.02527,4.000
4,31.800,0.00,-0.0002,-0.00020,4.000
4,31.867,0.00,-0.0002,-0.00020,4.000
4,31.933,0.00,-0.0002,-0.00020,4.000
4,32.000,0.00,-0.0002,-0.00020,4.000
4,32.067,0.00,-0.0002,-0.00020,4.000
4,32.133,0.00,-0.0002,-0.00020,4.000
4,32.200,0.00,-0.0002,-0.00020,4.000
4,32.267,0.00,-0.0002,-0.00020,4.000
4,32.333,0.00,-0.0002,-0.00020,4.000
4,32.400,0.00,-0.0002,-0.00020,4.000
4,32.467,0.00,-0.0002,-0.00020,4.000
4,32.533,0.00,-0.0002,-0.00020,4.000
4,32.600,0.00,-0.0002,-0.00020,4.000
4,32.667,0.00,-0.0002,-0.00020,4.000
4,32.733,0.00,-0.0002,-0.00020,4.000
4,32.800,0.00,-0.0002,-0.00020,4.000
4,32.867,0.00,-0.0002,-0.00020,4.000
4,32.933,0.00,-0.0002,-0.00020,4.000
4,33.000,0.00,-0.0002,-0.00020,4.000
4,33.067,0.00,-0.0002,-0.00020,4.000
4,33.133,0.00,-0.0002,-0.00020,4.000
4,33.200,0.00,-0.0002,-0.00020,4.000
4,33.267,0.00,-0.0002,-0.00020,4.000
4,33.333,0.00,-0.0002,-0.00020,4.000
4,33.400,0.00,-0.0002,-0.00020,4.000
4,33.467,0.00,-0.0002,-0.00020,4.000
4,33.533,0.00,-0.0002,-0.00020,4.000
4,33.600,0.00,-0.0002,-0.00020,4.000
4,33.667,0.00,-0.0002,-0.00020,4.000
4,33.733,0.00,-0.0002,-0.00020,4.000
4,33.800,0.00,-0.0002,-0.00020,4.000
4,33.867,0.00,-0.0002,-0.00020,4.000
4,33.933,0.00,-0.0002,-0.00020,4.000
4,34.000,0.00,-0.0002,-0.00020,4.000
4,34.067,0.00,-0.0002,-0.00020,4.000
4,34.133,0.00,-0.0002,-0.00020,4.000
4,34.200,0.00,-0.0002,-0.00020,4.000
4,34.267,0.00,-0.0002,-0.00020,4.000
4,34.333,0.00,-0.0002,-0.00020,4.000
4,34.400,0.00,-0.0002,-0.00020,4.000
4,34.467,0.00,-0.0002,-0.00020,4.000
4,34.533,0.00,-0.0002,-0.00020,4.000
4,34.600,0.00,-0.0001,-0.00010,4.000
4,34.667,0.00,-0.0001,-0.00010,4.000
4,34.800,0.00,-0.0001,-0.00010,4.000
4,34.867,0.00,-0.0001,-0.00010,4.000
4,34.933,0.00,-0.0001,-0.00010,4.000
4,35.000,0.00,-0.0001,-0.00010,4.000
4,35.067,0.00,-0.0001,-0.00010,4.000
4,35.133,0.00,-0.0001,-0.00010,4.000
4,35.200,0.00,-0.0001,-0.00010,4.000
4,35.267,0.00,-0.0001,-0.00010,4.000
4,35.333,0.00,-0.0001,-0.00010,4.000
4,35.400,0.00,-0.0001,-0.00010,4.000
4,35.467,0.00,-0.0001,-0.00010,4.000
4,35.533,0.00,-0.0001,-0.00010,4.000
4,35.600,0.00,-0.0001,-0.00010,4.000
4,35.667,0.00,-0.0001,-0.00010,4.000
5,36.000,0.00,0.0875,0.08760,5.000
5,36.067,0.00,0.1543,0.15440,5.000
5,36.133,0.00,0.2211,0.22117,5.000
5,36.200,0.00,0.2876,0.28770,5.000
5,36.267,0.00,0.3544,0.35453,5.000
5,36.333,0.00,0.4211,0.42120,5.000
5,36.400,0.00,0.4877,0.48780,5.000
5,36.467,0.00,0.5545,0.55463,5.000
5,36.533,0.00,0.6212,0.62130,5.000
5,36.600,0.00,0.6876,0.68770,5.000
5,36.667,0.00,0.7546,0.75467,5.000
5,36.733,0.00,0.8211,0.82120,5.000
5,36.800,0.00,0.8876,0.88770,5.000
5,36.867,0.00,0.9545,0.95460,5.000
5,36.933,0.00,1.0212,1.02133,5.000
5,37.000,0.00,1.0878,1.08790,5.000
5,37.067,0.00,1.1546,1.15473,5.000
5,37.133,0.00,1.2212,1.22133,5.000
5,37.200,0.00,1.2877,1.28780,5.000
5,37.267,0.00,1.3544,1.35453,5.000
5,37.333,0.00,1.4211,1.42120,5.000
5,37.400,0.00,1.4877,1.48780,5.000
5,37.467,0.00,1.5544,1.55450,5.000
5,37.533,0.00,1.6212,1.62127,5.000
5,37.600,0.02,1.6878,1.68790,5.000
5,37.667,0.04,1.7546,1.75467,5.000
5,37.733,0.07,1.8211,1.82123,5.000
5,37.800,0.13,1.8877,1.88780,5.000
5,37.867,0.22,1.9546,1.95473,5.000
5,37.933,0.35,2.0212,2.02127,5.000
5,38.000,0.50,2.0877,2.08780,5.000
5,38.067,0.69,2.1545,2.15460,5.000
5,38.133,0.90,2.2212,2.22127,5.000
5,38.267,1.20,2.2835,2.28357,5.000
5,38.333,0.91,2.2172,2.21727,5.000
5,38.400,0.66,2.1506,2.15070,5.000
5,38.467,0.47,2.0838,2.08393,5.000
5,38.533,0.30,2.0173,2.01740,5.000
5,38.600,0.18,1.9506,1.95070,5.000
5,38.667,0.09,1.8839,1.88400,5.000
5,38.733,0.05,1.8172,1.81727,5.000
5,38.800,0.02,1.7506,1.75070,5.000
5,38.867,0.00,1.6839,1.68397,5.000
5,38.933,0.00,1.6172,1.61730,5.000
5,39.000,0.00,1.5505,1.55060,5.000
5,39.067,0.00,1.4838,1.48387,5.000
5,39.133,0.00,1.4172,1.41727,5.000
5,39.200,0.00,1.3505,1.35060,5.000
5,39.267,0.00,1.2838,1.28390,5.000
5,39.333,0.00,1.2172,1.21733,5.000
5,39.400,0.00,1.1506,1.15070,5.000
5,39.467,0.00,1.0839,1.08397,5.000
5,39.533,0.00,1.0172,1.01730,5.000
5,39.600,0.00,0.9504,0.95050,5.000
5,39.667,0.00,0.8838,0.88387,5.000
5,39.733,0.00,0.8171,0.81720,5.000
5,39.800,0.00,0.7505,0.75060,5.000
5,39.867,0.00,0.6837,0.68383,5.000
5,39.933,0.00,0.6171,0.61723,5.000
5,40.000,0.00,0.5505,0.55060,5.000
5,40.067,0.00,0.4838,0.48387,5.000
5,40.133,0.00,0.4171,0.41723,5.000
5,40.200,0.00,0.3504,0.35050,5.000
5,40.267,0.00,0.2837,0.28380,5.000
5,40.333,0.00,0.2171,0.21717,5.000
5,40.400,0.00,0.1503,0.15040,5.000
5,40.467,0.00,0.0836,0.08367,5.000
5,40.533,0.00,0.0170,0.01710,5.000
5,40.667,0.00,-0.0230,-0.02287,5.000
5,40.733,-0.01,-0.0001,0.00000,5.000
5,40.800,0.00,-0.0002,-0.00010,5.000
5,40.867,0.00,-0.0002,-0.00010,5.000
5,40.933,0.00,-0.0002,-0.00010,5.000
5,41.000,0.00,-0.0001,0.00000,5.000
5,41.067,0.00,-0.0001,0.00000,5.000
5,41.133,0.00,-0.0002,-0.00007,5.000
5,41.200,0.00,-0.0001,0.00000,5.000
5,41.267,0.00,-0.0001,0.00000,5.000
5,41.333,0.00,-0.0001,0.00000,5.000
5,41.400,0.00,-0.0001,0.00000,5.000
5,41.467,0.00,-0.0001,0.00000,5.000
5,41.533,0.00,-0.0001,0.00000,5.000
5,41.600,-0.01,-0.0001,0.00000,5.000
5,41.667,0.00,-0.0001,0.00000,5.000
5,41.733,0.00,-0.0001,0.00000,5.000
5,41.800,0.00,-0.0001,0.00000,5.000
5,41.867,0.00,-0.0001,0.00000,5.000
5,41.933,0.00,-0.0001,0.00000,5.000
5,42.000,0.00,-0.0001,0.00000,5.000
5,42.067,0.00,-0.0001,0.00000,5.000
5,42.133,0.00,-0.0001,0.00000,5.000
5,42.200,0.00,-0.0001,0.00000,5.000
5,42.267,0.00,-0.0001,0.00000,5.000
5,42.333,0.00,-0.0001,0.00000,5.000
5,42.400,0.00,-0.0001,0.00000,5.000
5,42.467,0.00,-0.0001,0.00000,5.000
5,42.533,0.00,-0.0001,0.00000,5.000
5,42.600,0.00,-0.0001,0.00000,5.000
5,42.667,0.00,-0.0001,0.00000,5.000
5,42.733,0.00,-0.0001,0.00000,5.000
5,42.800,0.00,-0.0001,0.00000,5.000
5,42.867,0.00,-0.0001,0.00000,5.000
5,42.933,0.00,-0.0001,0.00000,5.000
5,43.000,0.00,-0.0001,0.00000,5.000
5,43.067,0.00,-0.0001,0.00000,5.000
5,43.133,-0.01,-0.0001,0.00000,5.000
5,43.200,0.00,-0.0001,0.00000,5.000
5,43.267,0.00,-0.0001,0.00000,5.000
5,43.333,0.00,-0.0001,0.00000,5.000
5,43.400,0.00,-0.0001,0.00000,5.000
5,43.467,0.00,-0.0001,0.00000,5.000
5,43.533,0.00,-0.0001,0.00000,5.000
5,43.600,0.00,-0.0001,0.00000,5.000
5,43.800,0.00,-0.0001,0.00000,5.000
5,43.867,0.00,-0.0001,0.00000,5.000
5,43.933,0.00,-0.0001,0.00000,5.000
5,44.000,0.00,-0.0001,0.00000,5.000
5,44.067,0.00,-0.0001,0.00000,5.000
5,44.133,0.00,-0.0001,0.00000,5.000
5,44.200,0.00,-0.0001,0.00000,5.000
5,44.267,0.00,-0.0001,0.00000,5.000
5,44.333,0.00,-0.0001,0.00000,5.000
5,44.400,0.00,-0.0001,0.00000,5.000
5,44.467,0.00,-0.0001,0.00000,5.000
5,44.533,0.00,-0.0001,0.00000,5.000
5,44.600,0.00,-0.0001,0.00000,5.000
5,44.667,-0.01,-0.0001,0.00000,5.000
6,44.933,0.00,0.1019,0.10203,6.000
6,45.000,-0.01,0.1685,0.16860,6.000
6,45.067,0.00,0.2353,0.23543,6.000
6,45.133,0.00,0.3021,0.30223,6.000
6,45.200,0.00,0.3687,0.36880,6.000
6,45.267,0.00,0.4354,0.43553,6.000
6,45.333,0.00,0.5021,0.50223,6.000
6,45.400,0.00,0.5686,0.56870,6.000
6,45.467,0.00,0.6354,0.63553,6.000
6,45.533,0.00,0.7022,0.70227,6.000
6,45.600,0.00,0.7687,0.76880,6.000
6,45.667,0.00,0.8355,0.83557,6.000
6,45.733,0.00,0.9021,0.90220,6.000
6,45.800,0.00,0.9687,0.96880,6.000
6,45.867,0.00,1.0355,1.03563,6.000
6,45.933,0.00,1.1022,1.10227,6.000
6,46.000,0.00,1.1688,1.16890,6.000
6,46.067,0.00,1.2355,1.23563,6.000
6,46.133,0.00,1.3021,1.30223,6.000
6,46.200,0.00,1.3686,1.36870,6.000
6,46.267,0.00,1.4354,1.43553,6.000
6,46.333,0.00,1.5021,1.50217,6.000
6,46.400,0.00,1.5686,1.56870,6.000
6,46.467,0.00,1.6355,1.63557,6.000
6,46.533,0.02,1.7021,1.70220,6.000
6,46.600,0.05,1.7688,1.76890,6.000
6,46.667,0.08,1.8355,1.83563,6.000
6,46.733,0.14,1.9022,1.90227,6.000
6,46.800,0.24,1.9688,1.96890,6.000
6,46.867,0.38,2.0356,2.03573,6.000
6,46.933,0.54,2.1021,2.10220,6.000
6,47.000,0.73,2.1687,2.16880,6.000
6,47.067,0.95,2.2355,2.23563,6.000
6,47.200,1.06,2.2495,2.24960,6.000
6,47.267,0.78,2.1828,2.18287,6.000
6,47.333,0.56,2.1162,2.11630,6.000
6,47.400,0.38,2.0495,2.04960,6.000
6,47.467,0.23,1.9830,1.98310,6.000
6,47.533,0.13,1.9162,1.91633,6.000
6,47.600,0.07,1.8495,1.84960,6.000
6,47.667,0.03,1.7829,1.78297,6.000
6,47.733,0.01,1.7163,1.71637,6.000
6,47.800,0.00,1.6494,1.64950,6.000
6,47.867,0.00,1.5828,1.58290,6.000
6,47.933,0.00,1.5162,1.51627,6.000
6,48.000,0.00,1.4493,1.44940,6.000
6,48.067,0.00,1.3828,1.38290,6.000
6,48.133,0.00,1.3161,1.31620,6.000
6,48.200,0.00,1.2495,1.24960,6.000
6,48.267,0.00,1.1830,1.18307,6.000
6,48.333,0.00,1.1162,1.11633,6.000
6,48.400,0.00,1.0494,1.04950,6.000
6,48.467,0.00,0.9829,0.98300,6.000
6,48.533,0.00,0.9161,0.91617,6.000
6,48.600,0.00,0.8493,0.84940,6.000
6,48.667,0.00,0.7829,0.78297,6.000
6,48.733,0.00,0.7162,0.71627,6.000
6,48.800,0.00,0.6493,0.64940,6.000
6,48.867,0.00,0.5828,0.58293,6.000
6,48.933,0.00,0.5162,0.51627,6.000
6,49.000,0.00,0.4493,0.44940,6.000
6,49.067,0.00,0.3828,0.38293,6.000
6,49.133,0.00,0.3162,0.31627,6.000
6,49.200,0.00,0.2494,0.24950,6.000
6,49.267,0.00,0.1827,0.18283,6.000
6,49.333,0.00,0.1159,0.11603,6.000
6,49.400,0.00,0.0491,0.04920,6.000
6,49.600,0.00,-0.0002,-0.00010,6.000
6,49.667,0.00,-0.0002,-0.00010,6.000
6,49.733,0.00,-0.0002,-0.00010,6.000
6,49.800,0.00,-0.0002,-0.00010,6.000
6,49.867,0.00,-0.0002,-0.00010,6.000
6,49.933,0.00,-0.0002,-0.00010,6.000
6,50.000,-0.01,-0.0002,-0.00010,6.000
6,50.067,0.00,-0.0002,-0.00010,6.000
6,50.133,0.00,-0.0002,-0.00010,6.000
6,50.200,0.00,-0.0002,-0.00010,6.000
6,50.267,0.00,-0.0002,-0.00010,6.000
6,50.333,0.00,-0.0002,-0.00010,6.000
6,50.400,0.00,-0.0002,-0.00010,6.000
6,50.467,0.00,-0.0002,-0.00010,6.000
6,50.533,0.00,-0.0002,-0.00010,6.000
6,50.600,-0.01,-0.0002,-0.00010,6.000
6,50.667,0.00,-0.0002,-0.00010,6.000
6,50.733,0.00,-0.0002,-0.00010,6.000
6,50.800,0.00,-0.0002,-0.00010,6.000
6,50.867,0.00,-0.0002,-0.00010,6.000
6,50.933,0.00,-0.0002,-0.00010,6.000
6,51.000,0.00,-0.0002,-0.00010,6.000
6,51.067,0.00,-0.0002,-0.00010,6.000
6,51.133,0.00,-0.0002,-0.00010,6.000
6,51.200,0.00,-0.0002,-0.00010,6.000
6,51.267,0.00,-0.0002,-0.00010,6.000
6,51.333,0.00,-0.0002,-0.00010,6.000
6,51.400,0.00,-0.0002,-0.00010,6.000
6,51.467,0.00,-0.0002,-0.00010,6.000
6,51.533,0.00,-0.0002,-0.00010,6.000
6,51.600,0.00,-0.0002,-0.00010,6.000
6,51.667,0.00,-0.0002,-0.00010,6.000
6,51.733,0.00,-0.0002,-0.00010,6.000
6,51.800,0.00,-0.0002,-0.00010,6.000
6,51.867,0.00,-0.0002,-0.00010,6.000
6,51.933,0.00,-0.0002,-0.00010,6.000
6,52.000,0.00,-0.0002,-0.00010,6.000
6,52.067,0.00,-0.0001,0.00000,6.000
6,52.133,0.00,-0.0001,0.00000,6.000
6,52.200,0.00,-0.0001,0.00000,6.000
6,52.267,0.00,-0.0001,0.00000,6.000
6,52.333,0.00,-0.0001,0.00000,6.000
6,52.400,0.00,-0.0001,0.00000,6.000
6,52.467,0.00,-0.0001,0.00000,6.000
6,52.533,0.00,-0.0001,0.00000,6.000
6,52.667,0.00,-0.0001,0.00000,6.000
6,52.733,0.00,-0.0001,0.00000,6.000
6,52.800,0.00,-0.0001,0.00000,6.000
6,52.867,0.00,-0.0001,0.00000,6.000
6,52.933,0.00,-0.0001,0.00000,6.000
6,53.000,-0.01,-0.0001,0.00000,6.000
6,53.067,0.00,-0.0001,0.00000,6.000
6,53.133,0.00,-0.0001,0.00000,6.000
6,53.200,0.00,-0.0001,0.00000,6.000
6,53.267,0.00,-0.0001,0.00000,6.000
6,53.333,0.00,-0.0001,0.00000,6.000
6,53.400,0.00,-0.0001,0.00000,6.000
6,53.467,0.00,-0.0001,0.00000,6.000
6,53.533,0.00,-0.0001,0.00000,6.000
7,53.800,0.00,0.0785,0.07850,7.000
7,53.867,0.00,0.1453,0.14530,7.000
7,53.933,0.00,0.2120,0.21203,7.000
7,54.000,0.00,0.2787,0.27870,7.000
7,54.067,0.00,0.3455,0.34550,7.000
7,54.133,0.00,0.4120,0.41203,7.000
7,54.200,0.00,0.4787,0.47870,7.000
7,54.267,0.00,0.5455,0.54547,7.000
7,54.333,0.00,0.6121,0.61207,7.000
7,54.400,0.00,0.6787,0.67870,7.000
7,54.467,0.00,0.7455,0.74553,7.000
7,54.533,0.00,0.8120,0.81200,7.000
7,54.600,0.00,0.8787,0.87870,7.000
7,54.667,0.00,0.9455,0.94550,7.000
7,54.733,0.00,1.0121,1.01207,7.000
7,54.800,0.00,1.0789,1.07890,7.000
7,54.867,0.00,1.1456,1.14563,7.000
7,54.933,0.00,1.2121,1.21213,7.000
7,55.000,0.00,1.2789,1.27890,7.000
7,55.067,0.00,1.3454,1.34543,7.000
7,55.133,0.00,1.4120,1.41200,7.000
7,55.200,0.00,1.4787,1.47870,7.000
7,55.267,0.00,1.5454,1.54540,7.000
7,55.333,0.00,1.6120,1.61203,7.000
7,55.400,0.02,1.6789,1.67890,7.000
7,55.467,0.04,1.7456,1.74557,7.000
7,55.533,0.07,1.8121,1.81207,7.000
7,55.600,0.12,1.8789,1.87890,7.000
7,55.667,0.20,1.9455,1.94550,7.000
7,55.733,0.33,2.0122,2.01217,7.000
7,55.800,0.49,2.0788,2.07880,7.000
7,55.867,0.66,2.1454,2.14540,7.000
7,55.933,0.88,2.2121,2.21207,7.000
7,56.067,1.15,2.2727,2.27270,7.000
7,56.133,0.87,2.2061,2.20607,7.000
7,56.200,0.63,2.1394,2.13940,7.000
7,56.267,0.44,2.0729,2.07293,7.000
7,56.333,0.28,2.0062,2.00623,7.000
7,56.400,0.16,1.9395,1.93950,7.000
7,56.467,0.08,1.8729,1.87290,7.000
7,56.533,0.05,1.8061,1.80607,7.000
7,56.600,0.02,1.7396,1.73960,7.000
7,56.667,0.00,1.6729,1.67293,7.000
7,56.733,0.00,1.6061,1.60607,7.000
7,56.800,0.00,1.5395,1.53950,7.000
7,56.867,0.00,1.4729,1.47290,7.000
7,56.933,0.00,1.4060,1.40600,7.000
7,57.000,0.00,1.3395,1.33950,7.000
7,57.067,0.00,1.2729,1.27290,7.000
7,57.133,0.00,1.2061,1.20613,7.000
7,57.200,0.00,1.1396,1.13960,7.000
7,57.267,0.00,1.0730,1.07297,7.000
7,57.333,0.00,1.0061,1.00610,7.000
7,57.400,0.00,0.9394,0.93940,7.000
7,57.467,0.00,0.8728,0.87280,7.000
7,57.533,0.00,0.8061,0.80610,7.000
7,57.600,0.00,0.7396,0.73960,7.000
7,57.667,0.00,0.6729,0.67290,7.000
7,57.733,0.00,0.6061,0.60610,7.000
7,57.800,0.00,0.5394,0.53940,7.000
7,57.867,0.00,0.4728,0.47283,7.000
7,57.933,0.00,0.4061,0.40613,7.000
7,58.000,0.00,0.3395,0.33950,7.000
7,58.067,0.00,0.2728,0.27283,7.000
7,58.133,0.00,0.2059,0.20593,7.000
7,58.200,0.00,0.1394,0.13940,7.000
7,58.267,0.00,0.0727,0.07267,7.000
7,58.333,0.00,0.0060,0.00600,7.000
7,58.467,0.00,-0.0026,-0.00260,7.000
7,58.533,0.00,-0.0002,-0.00020,7.000
7,58.600,0.00,-0.0002,-0.00020,7.000
7,58.667,0.00,-0.0002,-0.00020,7.000
7,58.733,0.00,-0.0002,-0.00020,7.000
7,58.800,0.00,-0.0002,-0.00020,7.000
7,58.867,0.00,-0.0002,-0.00020,7.000
7,58.933,0.00,-0.0002,-0.00020,7.000
7,59.000,0.00,-0.0002,-0.00020,7.000
7,59.067,0.00,-0.0002,-0.00020,7.000
7,59.133,0.00,-0.0002,-0.00020,7.000
7,59.200,0.00,-0.0002,-0.00020,7.000
7,59.267,0.00,-0.0002,-0.00020,7.000
7,59.333,0.00,-0.0002,-0.00020,7.000
7,59.400,0.00,-0.0002,-0.00020,7.000
7,59.467,0.00,-0.0002,-0.00020,7.000
7,59.533,0.00,-0.0002,-0.00020,7.000
7,59.600,0.00,-0.0002,-0.00020,7.000
7,59.667,0.00,-0.0002,-0.00020,7.000
7,59.733,0.00,-0.0002,-0.00020,7.000
7,59.800,0.00,-0.0002,-0.00020,7.000
7,59.867,0.00,-0.0002,-0.00020,7.000
7,59.933,0.00,-0.0002,-0.00020,7.000
7,60.000,0.00,-0.0002,-0.00020,7.000
7,60.067,0.00,-0.0002,-0.00020,7.000
7,60.133,0.00,-0.0002,-0.00020,7.000
7,60.200,0.00,-0.0002,-0.00020,7.000
7,60.267,0.00,-0.0002,-0.00020,7.000
7,60.333,0.00,-0.0002,-0.00020,7.000
7,60.400,0.00,-0.0002,-0.00020,7.000
7,60.467,0.00,-0.0002,-0.00020,7.000
7,60.533,0.00,-0.0001,-0.00010,7.000
7,60.600,0.00,-0.0001,-0.00010,7.000
7,60.667,0.00,-0.0001,-0.00010,7.000
7,60.733,0.00,-0.0001,-0.00010,7.000
7,60.800,0.00,-0.0001,-0.00010,7.000
7,60.867,0.00,-0.0001,-0.00010,7.000
7,60.933,0.00,-0.0001,-0.00010,7.000
7,61.000,0.00,-0.0001,-0.00010,7.000
7,61.067,0.00,-0.0001,-0.00010,7.000
7,61.133,0.00,-0.0001,-0.00010,7.000
7,61.200,0.00,-0.0001,-0.00010,7.000
7,61.267,0.00,-0.0001,-0.00010,7.000
7,61.333,0.00,-0.0001,-0.00010,7.000
7,61.400,0.00,-0.0001,-0.00010,7.000
7,61.533,0.00,-0.0001,-0.00010,7.000
7,61.600,-0.01,-0.0001,-0.00010,7.000
7,61.667,0.00,-0.0001,-0.00010,7.000
7,61.733,0.00,-0.0001,-0.00010,7.000
7,61.800,0.00,-0.0001,-0.00010,7.000
7,61.867,0.00,-0.0001,-0.00010,7.000
7,61.933,0.00,-0.0001,-0.00010,7.000
7,62.000,0.00,-0.0001,-0.00010,7.000
7,62.067,0.00,-0.0001,-0.00010,7.000
7,62.133,0.00,-0.0001,-0.00010,7.000
7,62.200,0.00,-0.0001,-0.00010,7.000
7,62.267,0.00,-0.0001,-0.00010,7.000
7,62.333,0.00,-0.0001,-0.00010,7.000
7,62.400,0.00,-0.0001,-0.00010,7.000
8,62.667,0.00,0.0643,0.06443,8.000
8,62.733,0.00,0.1309,0.13097,8.000
8,62.800,0.00,0.1977,0.19780,8.000
8,62.867,0.00,0.2645,0.26457,8.000
8,62.933,-0.01,0.3310,0.33113,8.000
8,63.000,0.00,0.3977,0.39780,8.000
8,63.067,0.00,0.4644,0.46453,8.000
8,63.133,0.00,0.5310,0.53113,8.000
8,63.200,0.00,0.5978,0.59790,8.000
8,63.267,-0.01,0.6645,0.66460,8.000
8,63.333,0.00,0.7310,0.73113,8.000
8,63.400,-0.01,0.7979,0.79800,8.000
8,63.467,0.00,0.8644,0.86453,8.000
8,63.533,0.00,0.9310,0.93110,8.000
8,63.600,-0.01,0.9979,0.99800,8.000
8,63.667,-0.01,1.0645,1.06460,8.000
8,63.733,0.00,1.1311,1.13120,8.000
8,63.800,-0.01,1.1979,1.19800,8.000
8,63.867,-0.01,1.2645,1.26460,8.000
8,63.933,0.00,1.3310,1.33107,8.000
8,64.000,0.00,1.3978,1.39790,8.000
8,64.067,-0.01,1.4645,1.46457,8.000
8,64.133,0.00,1.5310,1.53107,8.000
8,64.200,0.00,1.5979,1.59800,8.000
8,64.267,0.01,1.6645,1.66463,8.000
8,64.333,0.02,1.7311,1.73120,8.000
8,64.400,0.06,1.7979,1.79800,8.000
8,64.467,0.11,1.8645,1.86463,8.000
8,64.533,0.18,1.9311,1.93123,8.000
8,64.600,0.30,1.9980,1.99810,8.000
8,64.667,0.44,2.0645,2.06463,8.000
8,64.733,0.62,2.1311,2.13117,8.000
8,64.800,0.82,2.1978,2.19790,8.000
8,64.867,1.06,2.2645,2.26457,8.000
8,65.000,1.09,2.2602,2.26030,8.000
8,65.067,0.81,2.1939,2.19397,8.000
8,65.133,0.58,2.1271,2.12720,8.000
8,65.200,0.40,2.0606,2.06070,8.000
8,65.267,0.25,1.9940,1.99410,8.000
8,65.333,0.14,1.9272,1.92727,8.000
8,65.400,0.07,1.8606,1.86070,8.000
8,65.467,0.03,1.7939,1.79400,8.000
8,65.533,0.01,1.7271,1.72723,8.000
8,65.600,0.00,1.6605,1.66060,8.000
8,65.667,0.00,1.5938,1.59393,8.000
8,65.733,0.00,1.5270,1.52710,8.000
8,65.800,-0.01,1.4605,1.46060,8.000
8,65.867,-0.01,1.3939,1.39397,8.000
8,65.933,0.00,1.3270,1.32713,8.000
8,66.000,-0.01,1.2605,1.26060,8.000
8,66.067,0.00,1.1940,1.19407,8.000
8,66.133,-0.01,1.1272,1.12730,8.000
8,66.200,0.00,1.0607,1.06080,8.000
8,66.267,0.00,0.9939,0.99397,8.000
8,66.333,-0.01,0.9270,0.92713,8.000
8,66.400,-0.01,0.8604,0.86050,8.000
8,66.467,0.00,0.7939,0.79397,8.000
8,66.533,0.00,0.7271,0.72717,8.000
8,66.600,-0.01,0.6605,0.66060,8.000
8,66.667,0.00,0.5939,0.59397,8.000
8,66.733,0.00,0.5271,0.52717,8.000
8,66.800,-0.01,0.4606,0.46070,8.000
8,66.867,-0.01,0.3939,0.39397,8.000
8,66.933,0.00,0.3271,0.32720,8.000
8,67.000,0.00,0.2605,0.26060,8.000
8,67.067,0.00,0.1938,0.19387,8.000
8,67.133,0.00,0.1269,0.12700,8.000
8,67.200,-0.01,0.0604,0.06050,8.000
8,67.267,0.00,-0.0063,-0.00617,8.000
8,67.400,-0.01,-0.0172,-0.01710,8.000
8,67.467,0.00,-0.0002,-0.00007,8.000
8,67.533,-0.01,-0.0002,-0.00010,8.000
8,67.600,-0.01,-0.0002,-0.00010,8.000
8,67.667,0.00,-0.0002,-0.00010,8.000
8,67.733,0.00,-0.0002,-0.00010,8.000
8,67.800,0.00,-0.0002,-0.00010,8.000
8,67.867,-0.01,-0.0002,-0.00010,8.000
8,67.933,0.00,-0.0002,-0.00010,8.000
8,68.000,-0.01,-0.0002,-0.00010,8.000
8,68.067,0.00,-0.0002,-0.00010,8.000
8,68.133,0.00,-0.0002,-0.00010,8.000
8,68.200,0.00,-0.0002,-0.00010,8.000
8,68.267,-0.01,-0.0002,-0.00010,8.000
8,68.333,0.00,-0.0002,-0.00010,8.000
8,68.400,0.00,-0.0002,-0.00010,8.000
8,68.467,0.00,-0.0002,-0.00010,8.000
8,68.533,0.00,-0.0002,-0.00010,8.000
8,68.600,-0.01,-0.0002,-0.00010,8.000
8,68.667,0.00,-0.0002,-0.00010,8.000
8,68.733,-0.01,-0.0002,-0.00010,8.000
8,68.800,0.00,-0.0002,-0.00010,8.000
8,68.867,0.00,-0.0002,-0.00010,8.000
8,68.933,-0.01,-0.0002,-0.00010,8.000
8,69.000,0.00,-0.0002,-0.00010,8.000
8,69.067,-0.01,-0.0002,-0.00010,8.000
8,69.133,-0.01,-0.0002,-0.00010,8.000
8,69.200,0.00,-0.0002,-0.00010,8.000
8,69.267,0.00,-0.0002,-0.00010,8.000
8,69.333,-0.01,-0.0002,-0.00010,8.000
8,69.400,-0.01,-0.0002,-0.00010,8.000
8,69.467,0.00,-0.0002,-0.00010,8.000
8,69.533,-0.01,-0.0002,-0.00010,8.000
8,69.600,-0.01,-0.0002,-0.00010,8.000
8,69.667,-0.01,-0.0002,-0.00010,8.000
8,69.733,0.00,-0.0001,0.00000,8.000
8,69.800,0.00,-0.0001,0.00000,8.000
8,69.867,0.00,-0.0001,0.00000,8.000
8,69.933,0.00,-0.0001,0.00000,8.000
8,70.000,0.00,-0.0001,0.00000,8.000
8,70.067,0.00,-0.0001,0.00000,8.000
8,70.133,-0.01,-0.0001,0.00000,8.000
8,70.200,0.00,-0.0001,0.00000,8.000
8,70.267,0.00,-0.0001,0.00000,8.000
8,70.333,0.00,-0.0001,0.00000,8.000
8,70.467,-0.01,-0.0001,0.00000,8.000
8,70.533,-0.01,-0.0001,0.00000,8.000
8,70.600,0.00,-0.0001,0.00000,8.000
8,70.667,-0.01,-0.0001,0.00000,8.000
8,70.733,0.00,-0.0001,0.00000,8.000
8,70.800,-0.01,-0.0001,0.00000,8.000
8,70.867,0.00,-0.0001,0.00000,8.000
8,70.933,0.00,-0.0001,0.00000,8.000
8,71.000,-0.01,-0.0001,0.00000,8.000
8,71.067,-0.01,-0.0001,0.00000,8.000
8,71.133,0.00,-0.0001,0.00000,8.000
8,71.200,-0.01,-0.0001,0.00000,8.000
8,71.267,0.00,-0.0001,0.00000,8.000
8,71.333,0.00,-0.0001,0.00000,8.000
9,71.600,0.01,0.0384,0.03840,9.000
9,71.667,0.00,0.1053,0.10533,9.000
9,71.733,0.00,0.1719,0.17187,9.000
9,71.800,0.01,0.2388,0.23880,9.000
9,71.867,0.01,0.3055,0.30550,9.000
9,71.933,0.01,0.3721,0.37207,9.000
9,72.000,0.01,0.4389,0.43890,9.000
9,72.067,0.00,0.5055,0.50550,9.000
9,72.133,0.00,0.5721,0.57207,9.000
9,72.200,0.01,0.6389,0.63890,9.000
9,72.267,0.00,0.7055,0.70550,9.000
9,72.333,0.00,0.7720,0.77200,9.000
9,72.400,0.00,0.8387,0.83870,9.000
9,72.467,0.01,0.9055,0.90547,9.000
9,72.533,0.01,0.9721,0.97207,9.000
9,72.600,0.01,1.0389,1.03890,9.000
9,72.667,0.00,1.1056,1.10560,9.000
9,72.733,0.01,1.1722,1.17217,9.000
9,72.800,0.01,1.2389,1.23890,9.000
9,72.867,0.01,1.3055,1.30547,9.000
9,72.933,0.01,1.3720,1.37200,9.000
9,73.000,0.00,1.4388,1.43880,9.000
9,73.067,0.01,1.5054,1.50540,9.000
9,73.133,0.00,1.5720,1.57197,9.000
9,73.200,0.01,1.6388,1.63880,9.000
9,73.267,0.03,1.7055,1.70553,9.000
9,73.333,0.06,1.7721,1.77207,9.000
9,73.400,0.09,1.8389,1.83890,9.000
9,73.467,0.15,1.9055,1.90547,9.000
9,73.533,0.25,1.9722,1.97217,9.000
9,73.600,0.40,2.0390,2.03900,9.000
9,73.667,0.56,2.1055,2.10547,9.000
9,73.733,0.75,2.1721,2.17207,9.000
9,73.800,0.97,2.2389,2.23890,9.000
9,73.933,1.14,2.2659,2.26593,9.000
9,74.000,0.85,2.1995,2.19950,9.000
9,74.067,0.62,2.1327,2.13273,9.000
9,74.133,0.42,2.0663,2.06633,9.000
9,74.200,0.27,1.9996,1.99960,9.000
9,74.267,0.16,1.9328,1.93280,9.000
9,74.333,0.09,1.8663,1.86630,9.000
9,74.400,0.05,1.7996,1.79960,9.000
9,74.467,0.02,1.7329,1.73287,9.000
9,74.533,0.01,1.6663,1.66630,9.000
9,74.600,0.01,1.5994,1.59940,9.000
9,74.667,0.00,1.5327,1.53270,9.000
9,74.733,0.00,1.4662,1.46620,9.000
9,74.800,0.01,1.3995,1.39950,9.000
9,74.867,0.00,1.3328,1.33280,9.000
9,74.933,0.01,1.2662,1.26623,9.000
9,75.000,0.00,1.1995,1.19950,9.000
9,75.067,0.01,1.1329,1.13287,9.000
9,75.133,0.00,1.0663,1.06627,9.000
9,75.200,0.01,0.9995,0.99950,9.000
9,75.267,0.00,0.9327,0.93270,9.000
9,75.333,0.01,0.8662,0.86620,9.000
9,75.400,0.00,0.7995,0.79950,9.000
9,75.467,0.00,0.7328,0.73280,9.000
9,75.533,0.00,0.6662,0.66623,9.000
9,75.600,0.00,0.5995,0.59950,9.000
9,75.667,0.00,0.5327,0.53270,9.000
9,75.733,0.01,0.4662,0.46617,9.000
9,75.800,0.01,0.3995,0.39950,9.000
9,75.867,0.00,0.3328,0.33277,9.000
9,75.933,0.01,0.2662,0.26620,9.000
9,76.000,0.00,0.1993,0.19930,9.000
9,76.067,0.01,0.1326,0.13260,9.000
9,76.133,0.01,0.0660,0.06600,9.000
9,76.200,0.00,-0.0006,-0.00060,9.000
9,76.333,0.01,-0.0090,-0.00900,9.000
9,76.400,0.00,-0.0002,-0.00020,9.000
9,76.467,0.01,-0.0002,-0.00020,9.000
9,76.533,0.01,-0.0002,-0.00020,9.000
9,76.600,0.01,-0.0002,-0.00020,9.000
9,76.667,0.01,-0.0002,-0.00020,9.000
9,76.733,0.00,-0.0002,-0.00020,9.000
9,76.800,0.00,-0.0002,-0.00020,9.000
9,76.867,0.00,-0.0002,-0.00020,9.000
9,76.933,0.00,-0.0002,-0.00020,9.000
9,77.000,0.00,-0.0002,-0.00020,9.000
9,77.067,0.00,-0.0002,-0.00020,9.000
9,77.133,0.00,-0.0002,-0.00020,9.000
9,77.200,0.01,-0.0002,-0.00020,9.000
9,77.267,0.01,-0.0002,-0.00020,9.000
9,77.333,0.01,-0.0002,-0.00020,9.000
9,77.400,0.01,-0.0002,-0.00020,9.000
9,77.467,0.01,-0.0002,-0.00020,9.000
9,77.533,0.00,-0.0002,-0.00020,9.000
9,77.600,0.00,-0.0002,-0.00020,9.000
9,77.667,0.01,-0.0002,-0.00020,9.000
9,77.733,0.00,-0.0002,-0.00020,9.000
9,77.800,0.00,-0.0002,-0.00020,9.000
9,77.867,0.01,-0.0002,-0.00020,9.000
9,77.933,0.00,-0.0002,-0.00020,9.000
9,78.000,0.01,-0.0002,-0.00020,9.000
9,78.067,0.01,-0.0002,-0.00020,9.000
9,78.133,0.01,-0.0002,-0.00020,9.000
9,78.200,0.01,-0.0002,-0.00020,9.000
9,78.267,0.01,-0.0002,-0.00020,9.000
9,78.333,0.01,-0.0002,-0.00020,9.000
9,78.400,0.01,-0.0002,-0.00020,9.000
9,78.467,0.00,-0.0002,-0.00020,9.000
9,78.533,0.00,-0.0002,-0.00020,9.000
9,78.600,0.00,-0.0001,-0.00010,9.000
9,78.667,0.00,-0.0001,-0.00010,9.000
9,78.733,0.01,-0.0001,-0.00010,9.000
9,78.800,0.01,-0.0001,-0.00010,9.000
9,78.867,0.00,-0.0001,-0.00010,9.000
9,78.933,0.00,-0.0001,-0.00010,9.000
9,79.000,0.01,-0.0001,-0.00010,9.000
9,79.067,0.00,-0.0001,-0.00010,9.000
9,79.133,0.00,-0.0001,-0.00010,9.000
9,79.200,0.01,-0.0001,-0.00010,9.000
9,79.267,0.01,-0.0001,-0.00010,9.000
9,79.400,0.01,-0.0001,-0.00010,9.000
9,79.467,0.01,-0.0001,-0.00010,9.000
9,79.533,0.00,-0.0001,-0.00010,9.000
9,79.600,0.01,-0.0001,-0.00010,9.000
9,79.667,0.01,-0.0001,-0.00010,9.000
9,79.733,0.01,-0.0001,-0.00010,9.000
9,79.800,0.01,-0.0001,-0.00010,9.000
9,79.867,0.01,-0.0001,-0.00010,9.000
9,79.933,0.01,-0.0001,-0.00010,9.000
9,80.000,0.00,-0.0001,-0.00010,9.000
9,80.067,0.00,-0.0001,-0.00010,9.000
9,80.133,0.01,-0.0001,-0.00010,9.000
9,80.200,0.01,-0.0001,-0.00010,9.000
9,80.267,0.01,-0.0001,-0.00010,9.000
10,80.533,0.00,0.0620,0.06197,10.000
10,80.600,0.00,0.1286,0.12860,10.000
10,80.667,0.00,0.1954,0.19537,10.000
10,80.733,0.00,0.2621,0.26213,10.000
10,80.800,0.01,0.3287,0.32870,10.000
10,80.867,0.00,0.3954,0.39543,10.000
10,80.933,0.00,0.4622,0.46217,10.000
10,81.000,0.00,0.5287,0.52870,10.000
10,81.067,0.00,0.5955,0.59553,10.000
10,81.133,0.00,0.6621,0.66210,10.000
10,81.200,0.00,0.7287,0.72870,10.000
10,81.267,0.00,0.7954,0.79543,10.000
10,81.333,0.00,0.8621,0.86207,10.000
10,81.400,0.00,0.9286,0.92860,10.000
10,81.467,0.00,0.9955,0.99550,10.000
10,81.533,0.00,1.0622,1.06223,10.000
10,81.600,0.00,1.1288,1.12880,10.000
10,81.667,0.00,1.1956,1.19560,10.000
10,81.733,0.00,1.2622,1.26220,10.000
10,81.800,0.01,1.3286,1.32860,10.000
10,81.867,0.00,1.3954,1.39543,10.000
10,81.933,0.00,1.4621,1.46210,10.000
10,82.000,0.00,1.5286,1.52860,10.000
10,82.067,0.00,1.5954,1.59540,10.000
10,82.133,0.01,1.6621,1.66213,10.000
10,82.200,0.03,1.7287,1.72870,10.000
10,82.267,0.07,1.7955,1.79553,10.000
10,82.333,0.11,1.8622,1.86217,10.000
10,82.400,0.19,1.9287,1.92870,10.000
10,82.467,0.30,1.9956,1.99560,10.000
10,82.533,0.45,2.0622,2.06223,10.000
10,82.600,0.62,2.1287,2.12870,10.000
10,82.667,0.83,2.1955,2.19547,10.000
10,82.733,1.06,2.2622,2.26217,10.000
10,82.867,1.03,2.2428,2.24280,10.000
10,82.933,0.76,2.1761,2.17607,10.000
10,83.000,0.54,2.1095,2.10950,10.000
10,83.067,0.37,2.0430,2.04297,10.000
10,83.133,0.23,1.9762,1.97623,10.000
10,83.200,0.13,1.9096,1.90960,10.000
10,83.267,0.07,1.8429,1.84287,10.000
10,83.333,0.04,1.7762,1.77617,10.000
10,83.400,0.02,1.7097,1.70970,10.000
10,83.467,0.00,1.6428,1.64283,10.000
10,83.533,0.00,1.5761,1.57610,10.000
10,83.600,0.00,1.5095,1.50950,10.000
10,83.667,0.00,1.4428,1.44280,10.000
10,83.733,0.00,1.3761,1.37607,10.000
10,83.800,0.00,1.3096,1.30960,10.000
10,83.867,0.00,1.2429,1.24287,10.000
10,83.933,0.00,1.1762,1.17623,10.000
10,84.000,0.00,1.1096,1.10960,10.000
10,84.067,0.00,1.0429,1.04287,10.000
10,84.133,0.00,0.9761,0.97613,10.000
10,84.200,0.00,0.9095,0.90950,10.000
10,84.267,0.00,0.8427,0.84267,10.000
10,84.333,0.00,0.7761,0.77613,10.000
10,84.400,0.00,0.7095,0.70950,10.000
10,84.467,0.00,0.6428,0.64280,10.000
10,84.533,0.00,0.5761,0.57610,10.000
10,84.600,0.00,0.5095,0.50950,10.000
10,84.667,0.00,0.4427,0.44273,10.000
10,84.733,0.00,0.3761,0.37610,10.000
10,84.800,0.00,0.3097,0.30970,10.000
10,84.867,0.00,0.2426,0.24263,10.000
10,84.933,0.00,0.1760,0.17603,10.000
10,85.000,0.00,0.1095,0.10950,10.000
10,85.067,0.00,0.0426,0.04260,10.000
10,85.267,0.00,-0.0002,-0.00023,10.000
10,85.333,0.00,-0.0002,-0.00020,10.000
10,85.400,0.00,-0.0002,-0.00020,10.000
10,85.467,0.00,-0.0002,-0.00020,10.000
10,85.533,0.00,-0.0002,-0.00020,10.000
10,85.600,0.00,-0.0002,-0.00020,10.000
10,85.667,0.00,-0.0002,-0.00020,10.000
10,85.733,0.00,-0.0002,-0.00020,10.000
10,85.800,0.00,-0.0002,-0.00020,10.000
10,85.867,0.00,-0.0002,-0.00020,10.000
10,85.933,0.00,-0.0002,-0.00020,10.000
10,86.000,0.00,-0.0002,-0.00020,10.000
10,86.067,0.00,-0.0002,-0.00020,10.000
10,86.133,0.00,-0.0002,-0.00020,10.000
10,86.200,0.00,-0.0002,-0.00020,10.000
10,86.267,0.00,-0.0002,-0.00020,10.000
10,86.333,0.00,-0.0002,-0.00020,10.000
10,86.400,0.00,-0.0002,-0.00020,10.000
10,86.467,0.00,-0.0002,-0.00020,10.000
10,86.533,0.00,-0.0002,-0.00020,10.000
10,86.600,0.00,-0.0002,-0.00020,10.000
10,86.667,0.00,-0.0002,-0.00020,10.000
10,86.733,0.00,-0.0002,-0.00020,10.000
10,86.800,0.00,-0.0002,-0.00020,10.000
10,86.867,0.00,-0.0002,-0.00020,10.000
10,86.933,0.00,-0.0002,-0.00020,10.000
10,87.000,0.00,-0.0002,-0.00020,10.000
10,87.067,0.00,-0.0002,-0.00020,10.000
10,87.133,0.00,-0.0002,-0.00020,10.000
10,87.200,0.00,-0.0002,-0.00020,10.000
10,87.267,0.00,-0.0002,-0.00020,10.000
10,87.333,0.00,-0.0002,-0.00020,10.000
10,87.400,0.00,-0.0002,-0.00020,10.000
10,87.467,0.00,-0.0001,-0.00010,10.000
10,87.533,0.00,-0.0001,-0.00010,10.000
10,87.600,0.00,-0.0001,-0.00010,10.000
10,87.667,0.00,-0.0001,-0.00010,10.000
10,87.733,0.00,-0.0001,-0.00010,10.000
10,87.800,0.00,-0.0001,-0.00010,10.000
10,87.867,0.00,-0.0001,-0.00010,10.000
10,87.933,0.00,-0.0001,-0.00010,10.000
10,88.000,0.00,-0.0001,-0.00010,10.000
10,88.067,0.00,-0.0001,-0.00010,10.000
10,88.133,0.00,-0.0001,-0.00010,10.000
10,88.200,0.00,-0.0001,-0.00010,10.000
10,88.333,0.00,-0.0001,-0.00010,10.000
10,88.400,0.01,-0.0001,-0.00010,10.000
10,88.467,0.00,-0.0001,-0.00010,10.000
10,88.533,0.00,-0.0001,-0.00010,10.000
10,88.600,0.00,-0.0001,-0.00010,10.000
10,88.667,0.00,-0.0001,-0.00010,10.000
10,88.733,0.00,-0.0001,-0.00010,10.000
10,88.800,0.00,-0.0001,-0.00010,10.000
10,88.867,0.00,-0.0001,-0.00010,10.000
10,88.933,0.00,-0.0001,-0.00010,10.000
10,89.000,0.00,-0.0001,-0.00010,10.000
10,89.067,0.00,-0.0001,-0.00010,10.000
10,89.133,0.00,-0.0001,-0.00010,10.000
10,89.200,0.00,-0.0001,-0.00010,10.000