File: calibDATA_loadcell/date_02:15:2018/Instron_02.15.2018/1_50N_1__1mm.s_0_0.txt
""
"Test Method","Radhen_Load_Cntrl_Cmprsn_250N_12-7.msm"
"Sample I. D.","Sample1.mss"
"Specimen Number","1"

"TheCycle_Output ()","_Time (s)","_Load (N)","_Extension (mm)","RealTimeDepth (mm)","CycleNumber ()"

1,0.267,0.00,0.0622,0.06223,1.000
1,0.467,-0.01,0.2624,0.26243,1.000
1,0.667,0.00,0.4625,0.46253,1.000
1,0.867,0.00,0.6625,0.66250,1.000
1,1.067,0.00,0.8625,0.86250,1.000
1,1.267,0.00,1.0627,1.06267,1.000
1,1.467,0.00,1.2625,1.26250,1.000
1,1.667,-0.01,1.4626,1.46257,1.000
1,1.867,0.00,1.6626,1.66257,1.000
1,2.067,-0.01,1.8626,1.86257,1.000
1,2.267,-0.01,2.0625,2.06253,1.000
1,2.467,-0.01,2.2626,2.26257,1.000
1,2.667,-0.01,2.4626,2.46263,1.000
1,2.867,0.00,2.6627,2.66267,1.000
1,3.067,0.00,2.8627,2.86270,1.000
1,3.267,-0.01,3.0626,3.06260,1.000
1,3.467,-0.01,3.2626,3.26257,1.000
1,3.667,0.00,3.4626,3.46257,1.000
1,3.867,0.00,3.6627,3.66267,1.000
1,4.067,0.00,3.8627,3.86267,1.000
1,4.267,0.00,4.0626,4.06260,1.000
1,4.467,0.00,4.2626,4.26260,1.000
1,4.667,0.00,4.4627,4.46270,1.000
1,4.867,0.00,4.6626,4.66260,1.000
1,5.067,0.00,4.8627,4.86270,1.000
1,5.267,0.00,5.0627,5.06267,1.000
1,5.467,0.00,5.2627,5.26273,1.000
1,5.667,-0.01,5.4628,5.46277,1.000
1,5.867,-0.01,5.6627,5.66270,1.000
1,6.067,0.00,5.8626,5.86257,1.000
1,6.267,0.08,6.0626,6.06263,1.000
1,6.467,0.36,6.2627,6.26270,1.000
1,6.667,0.93,6.4627,6.46267,1.000
1,6.867,1.80,6.6627,6.66273,1.000
1,7.067,2.96,6.8628,6.86283,1.000
1,7.267,4.47,7.0626,7.06257,1.000
1,7.467,6.43,7.2627,7.26267,1.000
1,7.667,8.89,7.4626,7.46260,1.000
1,7.867,11.91,7.6626,7.66257,1.000
1,8.067,15.65,7.8626,7.86257,1.000
1,8.267,20.27,8.0626,8.06263,1.000
1,8.467,25.97,8.2626,8.26257,1.000
1,8.667,33.09,8.4626,8.46263,1.000
1,8.867,42.02,8.6627,8.66270,1.000
1,9.133,49.61,8.8032,8.80323,1.000
1,9.333,34.00,8.6035,8.60347,1.000
1,9.533,24.60,8.4034,8.40343,1.000
1,9.733,17.99,8.2034,8.20340,1.000
1,9.933,13.18,8.0033,8.00330,1.000
1,10.133,9.65,7.8033,7.80330,1.000
1,10.333,6.98,7.6032,7.60323,1.000
1,10.533,4.96,7.4032,7.40323,1.000
1,10.733,3.43,7.2032,7.20320,1.000
1,10.933,2.28,7.0030,7.00303,1.000
1,11.133,1.44,6.8033,6.80327,1.000
1,11.333,0.81,6.6032,6.60317,1.000
1,11.533,0.36,6.4031,6.40313,1.000
1,11.733,0.09,6.2031,6.20313,1.000
1,11.933,0.00,6.0030,6.00300,1.000
1,12.133,-0.01,5.8030,5.80297,1.000
1,12.333,-0.01,5.6030,5.60297,1.000
1,12.533,0.00,5.4030,5.40303,1.000
1,12.733,-0.01,5.2031,5.20307,1.000
1,12.933,0.00,5.0030,5.00303,1.000
1,13.133,-0.01,4.8030,4.80300,1.000
1,13.333,-0.01,4.6030,4.60297,1.000
1,13.533,-0.01,4.4029,4.40293,1.000
1,13.733,-0.01,4.2029,4.20290,1.000
1,13.933,0.00,4.0029,4.00293,1.000
1,14.133,-0.01,3.8029,3.80287,1.000
1,14.333,0.00,3.6029,3.60287,1.000
1,14.533,0.00,3.4029,3.40287,1.000
1,14.733,0.00,3.2028,3.20283,1.000
1,14.933,0.00,3.0029,3.00287,1.000
1,15.133,0.00,2.8029,2.80290,1.000
1,15.333,0.00,2.6029,2.60293,1.000
1,15.533,0.00,2.4028,2.40280,1.000
1,15.733,0.00,2.2028,2.20283,1.000
1,15.933,-0.01,2.0028,2.00283,1.000
1,16.133,0.00,1.8028,1.80277,1.000
1,16.333,-0.01,1.6028,1.60280,1.000
1,16.533,-0.01,1.4028,1.40277,1.000
1,16.733,0.00,1.2029,1.20287,1.000
1,16.933,-0.01,1.0029,1.00287,1.000
1,17.133,0.00,0.8028,0.80283,1.000
1,17.333,0.00,0.6028,0.60277,1.000
1,17.533,-0.01,0.4028,0.40283,1.000
1,17.733,0.00,0.2029,0.20287,1.000
1,17.933,0.00,0.0028,0.00277,1.000
1,18.200,0.00,-0.0005,-0.00050,1.000
1,18.400,0.00,-0.0005,-0.00050,1.000
1,18.600,0.00,-0.0005,-0.00050,1.000
1,18.800,-0.01,-0.0005,-0.00050,1.000
1,19.000,-0.01,-0.0005,-0.00050,1.000
1,19.200,0.00,-0.0004,-0.00040,1.000
1,19.400,0.00,-0.0004,-0.00040,1.000
1,19.600,0.00,-0.0004,-0.00040,1.000
1,19.800,0.00,-0.0004,-0.00040,1.000
1,20.000,-0.01,-0.0004,-0.00040,1.000
1,20.200,-0.01,-0.0004,-0.00040,1.000
1,20.400,0.00,-0.0004,-0.00040,1.000
1,20.600,-0.01,-0.0003,-0.00030,1.000
1,20.800,-0.01,-0.0003,-0.00030,1.000
1,21.000,0.00,-0.0003,-0.00030,1.000
1,21.267,-0.01,-0.0003,-0.00030,1.000
1,21.467,0.00,-0.0003,-0.00030,1.000
1,21.667,0.00,-0.0003,-0.00030,1.000
1,21.867,0.00,-0.0003,-0.00030,1.000
1,22.067,0.00,-0.0003,-0.00030,1.000
2,22.333,0.00,0.1198,0.11990,2.000
2,22.533,0.00,0.3199,0.32003,2.000
2,22.733,0.00,0.5200,0.52007,2.000
2,22.933,0.00,0.7200,0.72010,2.000
2,23.133,0.00,0.9200,0.92013,2.000
2,23.333,0.00,1.1201,1.12017,2.000
2,23.533,0.00,1.3199,1.32000,2.000
2,23.733,0.00,1.5199,1.52003,2.000
2,23.933,0.00,1.7200,1.72007,2.000
2,24.133,0.00,1.9200,1.92013,2.000
2,24.333,0.00,2.1200,2.12010,2.000
2,24.533,0.00,2.3201,2.32020,2.000
2,24.733,0.00,2.5200,2.52013,2.000
2,24.933,0.00,2.7201,2.72020,2.000
2,25.133,0.00,2.9201,2.92017,2.000
2,25.333,0.00,3.1199,3.12003,2.000
2,25.533,0.00,3.3200,3.32013,2.000
2,25.733,0.00,3.5200,3.52007,2.000
2,25.933,0.00,3.7201,3.72017,2.000
2,26.133,0.00,3.9201,3.92023,2.000
2,26.333,0.00,4.1201,4.12023,2.000
2,26.533,0.00,4.3201,4.32020,2.000
2,26.733,0.00,4.5201,4.52023,2.000
2,26.933,0.00,4.7202,4.72030,2.000
2,27.133,0.00,4.9202,4.92027,2.000
2,27.333,0.00,5.1201,5.12023,2.000
2,27.533,0.00,5.3202,5.32033,2.000
2,27.733,0.00,5.5201,5.52023,2.000
2,27.933,0.00,5.7202,5.72033,2.000
2,28.133,0.02,5.9201,5.92023,2.000
2,28.333,0.12,6.1202,6.12033,2.000
2,28.533,0.47,6.3202,6.32030,2.000
2,28.733,1.11,6.5203,6.52037,2.000
2,28.933,2.04,6.7204,6.72047,2.000
2,29.133,3.29,6.9204,6.92050,2.000
2,29.333,4.87,7.1201,7.12020,2.000
2,29.533,6.96,7.3202,7.32033,2.000
2,29.733,9.56,7.5203,7.52037,2.000
2,29.933,12.78,7.7203,7.72040,2.000
2,30.133,16.73,7.9203,7.92037,2.000
2,30.333,21.64,8.1203,8.12037,2.000
2,30.533,27.71,8.3203,8.32037,2.000
2,30.733,35.28,8.5203,8.52040,2.000
2,30.933,44.91,8.7203,8.72037,2.000
2,31.200,45.46,8.7675,8.76760,2.000
2,31.400,31.81,8.5676,8.56770,2.000
2,31.600,23.13,8.3677,8.36780,2.000
2,31.800,16.93,8.1677,8.16780,2.000
2,32.000,12.40,7.9675,7.96760,2.000
2,32.200,9.06,7.7677,7.76780,2.000
2,32.400,6.53,7.5675,7.56760,2.000
2,32.600,4.60,7.3674,7.36750,2.000
2,32.800,3.17,7.1674,7.16750,2.000
2,33.000,2.11,6.9675,6.96760,2.000
2,33.200,1.30,6.7675,6.76760,2.000
2,33.400,0.71,6.5675,6.56760,2.000
2,33.600,0.30,6.3672,6.36730,2.000
2,33.800,0.07,6.1674,6.16750,2.000
2,34.000,0.00,5.9674,5.96750,2.000
2,34.200,0.00,5.7673,5.76740,2.000
2,34.400,-0.01,5.5673,5.56740,2.000
2,34.600,0.00,5.3674,5.36750,2.000
2,34.800,0.00,5.1673,5.16740,2.000
2,35.000,0.00,4.9673,4.96740,2.000
2,35.200,0.00,4.7674,4.76750,2.000
2,35.400,0.00,4.5673,4.56740,2.000
2,35.600,0.00,4.3672,4.36730,2.000
2,35.800,0.01,4.1672,4.16730,2.000
2,36.000,0.00,3.9673,3.96740,2.000
2,36.200,0.00,3.7672,3.76730,2.000
2,36.400,0.00,3.5672,3.56730,2.000
2,36.600,0.00,3.3672,3.36730,2.000
2,36.800,0.00,3.1671,3.16720,2.000
2,37.000,0.00,2.9671,2.96720,2.000
2,37.200,0.00,2.7672,2.76730,2.000
2,37.400,0.00,2.5673,2.56740,2.000
2,37.600,0.00,2.3672,2.36730,2.000
2,37.800,0.00,2.1671,2.16720,2.000
2,38.000,0.00,1.9672,1.96730,2.000
2,38.200,0.00,1.7672,1.76730,2.000
2,38.400,0.00,1.5672,1.56730,2.000
2,38.600,0.00,1.3671,1.36720,2.000
2,38.800,0.00,1.1673,1.16740,2.000
2,39.000,0.01,0.9673,0.96740,2.000
2,39.200,0.00,0.7672,0.76730,2.000
2,39.400,0.00,0.5672,0.56730,2.000
2,39.600,0.00,0.3671,0.36720,2.000
2,39.800,0.00,0.1672,0.16730,2.000
2,40.067,0.00,-0.0267,-0.02657,2.000
2,40.267,0.00,-0.0005,-0.00040,2.000
2,40.467,0.00,-0.0005,-0.00040,2.000
2,40.667,0.00,-0.0005,-0.00040,2.000
2,40.867,0.00,-0.0005,-0.00040,2.000
2,41.067,0.00,-0.0005,-0.00040,2.000
2,41.267,0.00,-0.0004,-0.00030,2.000
2,41.467,0.00,-0.0004,-0.00030,2.000
2,41.667,0.00,-0.0004,-0.00030,2.000
2,41.867,0.00,-0.0004,-0.00030,2.000
2,42.067,0.00,-0.0004,-0.00030,2.000
2,42.267,0.00,-0.0004,-0.00030,2.000
2,42.467,0.00,-0.0004,-0.00030,2.000
2,42.667,0.00,-0.0003,-0.00020,2.000
2,42.867,0.00,-0.0003,-0.00020,2.000
2,43.133,0.00,-0.0003,-0.00020,2.000
2,43.333,0.00,-0.0003,-0.00020,2.000
2,43.533,0.00,-0.0003,-0.00020,2.000
2,43.733,0.00,-0.0003,-0.00020,2.000
2,43.933,0.00,-0.0003,-0.00020,2.000
3,44.400,0.00,0.1765,0.17660,3.000
3,44.600,0.00,0.3768,0.37690,3.000
3,44.800,0.00,0.5766,0.57670,3.000
3,45.000,0.00,0.7767,0.77680,3.000
3,45.200,0.00,0.9769,0.97700,3.000
3,45.400,0.00,1.1769,1.17700,3.000
3,45.600,0.00,1.3766,1.37670,3.000
3,45.800,0.00,1.5768,1.57690,3.000
3,46.000,0.00,1.7768,1.77690,3.000
3,46.200,0.00,1.9768,1.97690,3.000
3,46.400,0.00,2.1768,2.17690,3.000
3,46.600,0.00,2.3767,2.37680,3.000
3,46.800,0.00,2.5768,2.57690,3.000
3,47.000,0.00,2.7768,2.77690,3.000
3,47.200,0.00,2.9768,2.97690,3.000
3,47.400,0.00,3.1767,3.17680,3.000
3,47.600,0.00,3.3768,3.37690,3.000
3,47.800,0.00,3.5768,3.57690,3.000
3,48.000,0.00,3.7768,3.77690,3.000
3,48.200,0.00,3.9768,3.97690,3.000
3,48.400,0.00,4.1768,4.17690,3.000
3,48.600,0.00,4.3767,4.37680,3.000
3,48.800,-0.01,4.5767,4.57680,3.000
3,49.000,0.00,4.7768,4.77690,3.000
3,49.200,-0.01,4.9769,4.97700,3.000
3,49.400,0.00,5.1770,5.17710,3.000
3,49.600,0.00,5.3770,5.37710,3.000
3,49.800,-0.01,5.5768,5.57690,3.000
3,50.000,0.00,5.7767,5.77680,3.000
3,50.200,0.03,5.9767,5.97680,3.000
3,50.400,0.18,6.1770,6.17710,3.000
3,50.600,0.60,6.3769,6.37700,3.000
3,50.800,1.32,6.5769,6.57700,3.000
3,51.000,2.34,6.7769,6.77700,3.000
3,51.200,3.66,6.9769,6.97700,3.000
3,51.400,5.36,7.1768,7.17690,3.000
3,51.600,7.57,7.3768,7.37690,3.000
3,51.800,10.31,7.5769,7.57700,3.000
3,52.000,13.72,7.7768,7.77690,3.000
3,52.200,17.90,7.9768,7.97690,3.000
3,52.400,23.09,8.1768,8.17690,3.000
3,52.600,29.52,8.3769,8.37700,3.000
3,52.800,37.59,8.5769,8.57700,3.000
3,53.000,47.97,8.7768,8.77690,3.000
3,53.267,40.64,8.7111,8.71123,3.000
3,53.467,28.89,8.5111,8.51120,3.000
3,53.667,21.08,8.3111,8.31120,3.000
3,53.867,15.42,8.1111,8.11120,3.000
3,54.067,11.30,7.9110,7.91107,3.000
3,54.267,8.21,7.7109,7.71103,3.000
3,54.467,5.88,7.5110,7.51113,3.000
3,54.667,4.12,7.3109,7.31103,3.000
3,54.867,2.80,7.1108,7.11093,3.000
3,55.067,1.83,6.9110,6.91110,3.000
3,55.267,1.10,6.7110,6.71107,3.000
3,55.467,0.56,6.5109,6.51103,3.000
3,55.667,0.20,6.3108,6.31093,3.000
3,55.867,0.04,6.1109,6.11097,3.000
3,56.067,-0.01,5.9108,5.91090,3.000
3,56.267,0.00,5.7108,5.71090,3.000
3,56.467,0.00,5.5108,5.51090,3.000
3,56.667,0.00,5.3109,5.31100,3.000
3,56.867,0.00,5.1108,5.11090,3.000
3,57.067,0.00,4.9107,4.91083,3.000
3,57.267,0.00,4.7107,4.71083,3.000
3,57.467,0.00,4.5109,4.51097,3.000
3,57.667,-0.01,4.3107,4.31080,3.000
3,57.867,0.00,4.1107,4.11077,3.000
3,58.067,0.00,3.9107,3.91080,3.000
3,58.267,0.00,3.7106,3.71073,3.000
3,58.467,0.00,3.5106,3.51070,3.000
3,58.667,0.00,3.3107,3.31077,3.000
3,58.867,0.00,3.1104,3.11053,3.000
3,59.067,0.00,2.9106,2.91067,3.000
3,59.267,0.00,2.7106,2.71070,3.000
3,59.467,0.00,2.5106,2.51070,3.000
3,59.667,0.00,2.3106,2.31070,3.000
3,59.867,-0.01,2.1106,2.11067,3.000
3,60.067,0.00,1.9105,1.91057,3.000
3,60.267,-0.01,1.7106,1.71067,3.000
3,60.467,0.00,1.5105,1.51057,3.000
3,60.667,0.00,1.3104,1.31050,3.000
3,60.867,0.00,1.1106,1.11067,3.000
3,61.067,0.00,0.9105,0.91063,3.000
3,61.267,0.00,0.7105,0.71060,3.000
3,61.467,-0.01,0.5106,0.51067,3.000
3,61.667,0.00,0.3105,0.31057,3.000
3,61.867,0.00,0.1104,0.11053,3.000
3,62.067,0.00,-0.0345,-0.03440,3.000
3,62.267,0.00,-0.0005,-0.00040,3.000
3,62.467,0.00,-0.0005,-0.00040,3.000
3,62.667,0.00,-0.0005,-0.00040,3.000
3,62.867,0.00,-0.0005,-0.00040,3.000
3,63.067,0.00,-0.0005,-0.00040,3.000
3,63.267,0.00,-0.0005,-0.00040,3.000
3,63.467,0.00,-0.0004,-0.00030,3.000
3,63.667,0.00,-0.0004,-0.00030,3.000
3,63.867,0.00,-0.0004,-0.00030,3.000
3,64.067,0.00,-0.0004,-0.00030,3.000
3,64.267,0.00,-0.0004,-0.00030,3.000
3,64.467,0.00,-0.0004,-0.00030,3.000
3,64.667,0.00,-0.0003,-0.00023,3.000
3,64.867,-0.01,-0.0003,-0.00020,3.000
3,65.200,0.00,-0.0003,-0.00020,3.000
3,65.400,-0.01,-0.0003,-0.00020,3.000
3,65.600,0.00,-0.0003,-0.00020,3.000
3,65.800,0.00,-0.0003,-0.00020,3.000
3,66.000,-0.01,-0.0003,-0.00020,3.000
4,66.333,0.00,0.1119,0.11197,4.000
4,66.533,0.00,0.3119,0.31200,4.000
4,66.733,0.00,0.5120,0.51207,4.000
4,66.933,0.00,0.7120,0.71210,4.000
4,67.133,0.00,0.9121,0.91223,4.000
4,67.333,0.00,1.1122,1.11230,4.000
4,67.533,0.00,1.3120,1.31207,4.000
4,67.733,0.00,1.5120,1.51210,4.000
4,67.933,0.00,1.7121,1.71220,4.000
4,68.133,0.00,1.9121,1.91217,4.000
4,68.333,0.00,2.1121,2.11223,4.000
4,68.533,0.00,2.3122,2.31227,4.000
4,68.733,0.00,2.5122,2.51230,4.000
4,68.933,0.00,2.7122,2.71227,4.000
4,69.133,0.00,2.9122,2.91233,4.000
4,69.333,0.00,3.1121,3.11217,4.000
4,69.533,0.00,3.3122,3.31227,4.000
4,69.733,0.00,3.5121,3.51223,4.000
4,69.933,0.00,3.7122,3.71230,4.000
4,70.133,0.00,3.9122,3.91233,4.000
4,70.333,0.00,4.1122,4.11233,4.000
4,70.533,0.00,4.3121,4.31223,4.000
4,70.733,0.00,4.5123,4.51237,4.000
4,70.933,0.00,4.7122,4.71233,4.000
4,71.133,0.00,4.9123,4.91243,4.000
4,71.333,0.00,5.1122,5.11233,4.000
4,71.533,0.00,5.3123,5.31240,4.000
4,71.733,0.00,5.5123,5.51237,4.000
4,71.933,0.00,5.7122,5.71230,4.000
4,72.133,0.01,5.9123,5.91240,4.000
4,72.333,0.10,6.1123,6.11237,4.000
4,72.533,0.43,6.3123,6.31240,4.000
4,72.733,1.05,6.5123,6.51243,4.000
4,72.933,1.97,6.7123,6.71243,4.000
4,73.133,3.18,6.9125,6.91257,4.000
4,73.333,4.75,7.1122,7.11230,4.000
4,73.533,6.79,7.3122,7.31233,4.000
4,73.733,9.35,7.5123,7.51237,4.000
4,73.933,12.50,7.7123,7.71237,4.000
4,74.133,16.39,7.9123,7.91237,4.000
4,74.333,21.22,8.1123,8.11240,4.000
4,74.533,27.21,8.3122,8.31233,4.000
4,74.733,34.69,8.5123,8.51237,4.000
4,74.933,44.15,8.7123,8.71237,4.000
4,75.267,41.94,8.7330,8.73307,4.000
4,75.467,29.73,8.5329,8.53303,4.000
4,75.667,21.67,8.3330,8.33310,4.000
4,75.867,15.86,8.1330,8.13307,4.000
4,76.067,11.61,7.9329,7.93297,4.000
4,76.267,8.46,7.7328,7.73293,4.000
4,76.467,6.06,7.5329,7.53300,4.000
4,76.667,4.25,7.3328,7.33293,4.000
4,76.867,2.91,7.1327,7.13277,4.000
4,77.067,1.91,6.9329,6.93300,4.000
4,77.267,1.16,6.7328,6.73293,4.000
4,77.467,0.60,6.5328,6.53293,4.000
4,77.667,0.22,6.3327,6.33277,4.000
4,77.867,0.04,6.1328,6.13287,4.000
4,78.067,-0.01,5.9327,5.93283,4.000
4,78.267,0.00,5.7326,5.73267,4.000
4,78.467,0.00,5.5326,5.53273,4.000
4,78.667,0.00,5.3327,5.33280,4.000
4,78.867,0.00,5.1327,5.13277,4.000
4,79.067,0.00,4.9327,4.93280,4.000
4,79.267,0.00,4.7326,4.73270,4.000
4,79.467,0.00,4.5326,4.53273,4.000
4,79.667,0.00,4.3326,4.33267,4.000
4,79.867,0.00,4.1326,4.13270,4.000
4,80.067,0.00,3.9327,3.93277,4.000
4,80.267,0.00,3.7327,3.73277,4.000
4,80.467,0.00,3.5325,3.53263,4.000
4,80.667,0.00,3.3326,3.33267,4.000
4,80.867,0.00,3.1324,3.13253,4.000
4,81.067,0.00,2.9326,2.93267,4.000
4,81.267,0.00,2.7326,2.73267,4.000
4,81.467,0.00,2.5326,2.53267,4.000
4,81.667,0.00,2.3325,2.33260,4.000
4,81.867,0.00,2.1325,2.13257,4.000
4,82.067,0.00,1.9325,1.93257,4.000
4,82.267,0.00,1.7325,1.73260,4.000
4,82.467,-0.01,1.5325,1.53263,4.000
4,82.667,0.00,1.3324,1.33247,4.000
4,82.867,0.00,1.1327,1.13277,4.000
4,83.067,0.00,0.9326,0.93270,4.000
4,83.267,0.00,0.7326,0.73270,4.000
4,83.467,0.00,0.5325,0.53260,4.000
4,83.667,0.00,0.3325,0.33260,4.000
4,83.867,0.00,0.1326,0.13270,4.000
4,84.133,0.00,-0.0094,-0.00933,4.000
4,84.333,0.00,-0.0005,-0.00040,4.000
4,84.533,0.00,-0.0005,-0.00040,4.000
4,84.733,0.00,-0.0005,-0.00040,4.000
4,84.933,0.00,-0.0005,-0.00040,4.000
4,85.133,0.00,-0.0005,-0.00040,4.000
4,85.333,0.00,-0.0005,-0.00040,4.000
4,85.533,0.00,-0.0004,-0.00030,4.000
4,85.733,0.00,-0.0004,-0.00030,4.000
4,85.933,0.00,-0.0004,-0.00030,4.000
4,86.133,0.00,-0.0004,-0.00030,4.000
4,86.333,0.00,-0.0004,-0.00030,4.000
4,86.533,0.00,-0.0004,-0.00030,4.000
4,86.733,0.00,-0.0004,-0.00030,4.000
4,86.933,0.00,-0.0003,-0.00020,4.000
4,87.200,0.00,-0.0003,-0.00020,4.000
4,87.400,0.00,-0.0003,-0.00020,4.000
4,87.600,0.00,-0.0003,-0.00020,4.000
4,87.800,0.00,-0.0003,-0.00020,4.000
4,88.000,0.00,-0.0003,-0.00020,4.000
5,88.400,0.01,0.1264,0.12650,5.000
5,88.600,0.01,0.3266,0.32670,5.000
5,88.800,0.01,0.5266,0.52670,5.000
5,89.000,0.00,0.7266,0.72670,5.000
5,89.200,0.00,0.9268,0.92690,5.000
5,89.400,0.00,1.1268,1.12690,5.000
5,89.600,0.01,1.3266,1.32670,5.000
5,89.800,0.00,1.5266,1.52670,5.000
5,90.000,0.01,1.7268,1.72690,5.000
5,90.200,0.01,1.9266,1.92670,5.000
5,90.400,0.01,2.1266,2.12670,5.000
5,90.600,0.01,2.3267,2.32680,5.000
5,90.800,0.00,2.5268,2.52690,5.000
5,91.000,0.01,2.7266,2.72670,5.000
5,91.200,0.00,2.9268,2.92690,5.000
5,91.400,0.00,3.1267,3.12680,5.000
5,91.600,0.00,3.3266,3.32670,5.000
5,91.800,0.00,3.5267,3.52680,5.000
5,92.000,0.00,3.7268,3.72690,5.000
5,92.200,0.00,3.9268,3.92690,5.000
5,92.400,0.01,4.1267,4.12680,5.000
5,92.600,0.00,4.3267,4.32680,5.000
5,92.800,0.00,4.5268,4.52690,5.000
5,93.000,0.00,4.7269,4.72700,5.000
5,93.200,0.00,4.9269,4.92700,5.000
5,93.400,0.01,5.1267,5.12680,5.000
5,93.600,0.00,5.3269,5.32700,5.000
5,93.800,0.01,5.5268,5.52690,5.000
5,94.000,0.01,5.7268,5.72690,5.000
5,94.200,0.02,5.9269,5.92700,5.000
5,94.400,0.12,6.1268,6.12690,5.000
5,94.600,0.46,6.3269,6.32700,5.000
5,94.800,1.10,6.5269,6.52700,5.000
5,95.000,2.02,6.7269,6.72700,5.000
5,95.200,3.27,6.9270,6.92710,5.000
5,95.400,4.86,7.1268,7.12690,5.000
5,95.600,6.94,7.3268,7.32690,5.000
5,95.800,9.53,7.5268,7.52690,5.000
5,96.000,12.74,7.7269,7.72700,5.000
5,96.200,16.69,7.9269,7.92700,5.000
5,96.400,21.59,8.1269,8.12700,5.000
5,96.600,27.66,8.3270,8.32710,5.000
5,96.800,35.25,8.5269,8.52700,5.000
5,97.000,44.90,8.7269,8.72700,5.000
5,97.267,46.04,8.7809,8.78100,5.000
5,97.467,32.16,8.5810,8.58110,5.000
5,97.667,23.35,8.3810,8.38110,5.000
5,97.867,17.06,8.1810,8.18107,5.000
5,98.067,12.50,7.9809,7.98097,5.000
5,98.267,9.12,7.7809,7.78097,5.000
5,98.467,6.56,7.5808,7.58090,5.000
5,98.667,4.63,7.3808,7.38093,5.000
5,98.867,3.19,7.1807,7.18083,5.000
5,99.067,2.12,6.9808,6.98087,5.000
5,99.267,1.31,6.7809,6.78100,5.000
5,99.467,0.72,6.5808,6.58090,5.000
5,99.667,0.30,6.3807,6.38080,5.000
5,99.867,0.07,6.1808,6.18090,5.000
5,100.067,0.01,5.9807,5.98080,5.000
5,100.267,0.00,5.7807,5.78080,5.000
5,100.467,0.00,5.5807,5.58077,5.000
5,100.667,0.00,5.3808,5.38087,5.000
5,100.867,0.00,5.1808,5.18090,5.000
5,101.067,0.01,4.9807,4.98080,5.000
5,101.267,0.00,4.7807,4.78077,5.000
5,101.467,0.00,4.5807,4.58080,5.000
5,101.667,0.00,4.3807,4.38077,5.000
5,101.867,0.00,4.1807,4.18077,5.000
5,102.067,0.01,3.9807,3.98077,5.000
5,102.267,0.00,3.7807,3.78083,5.000
5,102.467,0.01,3.5806,3.58073,5.000
5,102.667,0.01,3.3807,3.38077,5.000
5,102.867,0.01,3.1805,3.18060,5.000
5,103.067,0.01,2.9806,2.98073,5.000
5,103.267,0.01,2.7806,2.78067,5.000
5,103.467,0.01,2.5807,2.58077,5.000
5,103.667,0.01,2.3806,2.38070,5.000
5,103.867,0.00,2.1806,2.18067,5.000
5,104.067,0.01,1.9806,1.98067,5.000
5,104.267,0.01,1.7806,1.78067,5.000
5,104.467,0.01,1.5805,1.58060,5.000
5,104.667,0.01,1.3805,1.38060,5.000
5,104.867,0.01,1.1806,1.18073,5.000
5,105.067,0.01,0.9806,0.98070,5.000
5,105.267,0.01,0.7806,0.78067,5.000
5,105.467,0.01,0.5805,0.58060,5.000
5,105.667,0.01,0.3805,0.38063,5.000
5,105.867,0.01,0.1806,0.18070,5.000
5,106.067,0.01,-0.0195,-0.01940,5.000
5,106.333,0.01,-0.0005,-0.00040,5.000
5,106.533,0.01,-0.0005,-0.00040,5.000
5,106.733,0.01,-0.0005,-0.00040,5.000
5,106.933,0.01,-0.0005,-0.00040,5.000
5,107.133,0.01,-0.0005,-0.00040,5.000
5,107.333,0.01,-0.0005,-0.00040,5.000
5,107.533,0.01,-0.0004,-0.00030,5.000
5,107.733,0.01,-0.0004,-0.00030,5.000
5,107.933,0.01,-0.0004,-0.00030,5.000
5,108.133,0.01,-0.0004,-0.00030,5.000
5,108.333,0.01,-0.0004,-0.00030,5.000
5,108.533,0.01,-0.0004,-0.00030,5.000
5,108.733,0.00,-0.0004,-0.00030,5.000
5,108.933,0.00,-0.0003,-0.00020,5.000
5,109.133,0.00,-0.0003,-0.00020,5.000
5,109.400,0.00,-0.0003,-0.00020,5.000
5,109.600,0.01,-0.0003,-0.00020,5.000
5,109.800,0.01,-0.0003,-0.00020,5.000
5,110.000,0.01,-0.0003,-0.00020,5.000
6,110.400,0.00,0.0686,0.06880,6.000
6,110.600,0.00,0.2687,0.26890,6.000
6,110.800,0.00,0.4688,0.46900,6.000
6,111.000,0.00,0.6688,0.66900,6.000
6,111.200,0.00,0.8688,0.86900,6.000
6,111.400,0.00,1.0690,1.06920,6.000
6,111.600,0.00,1.2687,1.26890,6.000
6,111.800,0.00,1.4688,1.46900,6.000
6,112.000,0.00,1.6688,1.66900,6.000
6,112.200,0.00,1.8687,1.86890,6.000
6,112.400,0.00,2.0688,2.06900,6.000
6,112.600,0.00,2.2689,2.26910,6.000
6,112.800,0.00,2.4689,2.46910,6.000
6,113.000,0.00,2.6689,2.66910,6.000
6,113.200,0.00,2.8690,2.86920,6.000
6,113.400,0.00,3.0689,3.06910,6.000
6,113.600,0.01,3.2688,3.26900,6.000
6,113.800,0.00,3.4689,3.46910,6.000
6,114.000,0.00,3.6689,3.66910,6.000
6,114.200,0.00,3.8689,3.86910,6.000
6,114.400,0.00,4.0688,4.06900,6.000
6,114.600,0.00,4.2689,4.26910,6.000
6,114.800,0.00,4.4689,4.46910,6.000
6,115.000,0.00,4.6688,4.66900,6.000
6,115.200,0.00,4.8689,4.86910,6.000
6,115.400,0.00,5.0688,5.06900,6.000
6,115.600,0.01,5.2690,5.26920,6.000
6,115.800,0.00,5.4690,5.46920,6.000
6,116.000,0.00,5.6688,5.66900,6.000
6,116.200,0.01,5.8689,5.86910,6.000
6,116.400,0.07,6.0688,6.06900,6.000
6,116.600,0.33,6.2689,6.26910,6.000
6,116.800,0.87,6.4689,6.46910,6.000
6,117.000,1.72,6.6690,6.66920,6.000
6,117.200,2.86,6.8692,6.86940,6.000
6,117.400,4.34,7.0688,7.06900,6.000
6,117.600,6.25,7.2689,7.26910,6.000
6,117.800,8.68,7.4689,7.46910,6.000
6,118.000,11.68,7.6689,7.66910,6.000
6,118.200,15.39,7.8689,7.86910,6.000
6,118.400,19.97,8.0688,8.06900,6.000
6,118.600,25.68,8.2689,8.26910,6.000
6,118.800,32.77,8.4688,8.46900,6.000
6,119.000,41.71,8.6690,8.66920,6.000
6,119.267,52.44,8.8428,8.84297,6.000
6,119.467,35.58,8.6431,8.64330,6.000
6,119.667,25.66,8.4431,8.44333,6.000
6,119.867,18.74,8.2430,8.24323,6.000
6,120.067,13.70,8.0431,8.04327,6.000
6,120.267,10.02,7.8429,7.84313,6.000
6,120.467,7.23,7.6429,7.64313,6.000
6,120.667,5.14,7.4430,7.44320,6.000
6,120.867,3.57,7.2429,7.24310,6.000
6,121.067,2.39,7.0427,7.04293,6.000
6,121.267,1.52,6.8429,6.84313,6.000
6,121.467,0.87,6.6429,6.64310,6.000
6,121.667,0.41,6.4428,6.44300,6.000
6,121.867,0.11,6.2429,6.24307,6.000
6,122.067,0.01,6.0428,6.04297,6.000
6,122.267,0.00,5.8428,5.84300,6.000
6,122.467,0.00,5.6428,5.64297,6.000
6,122.667,0.00,5.4427,5.44293,6.000
6,122.867,0.00,5.2427,5.24293,6.000
6,123.067,0.00,5.0427,5.04287,6.000
6,123.267,0.00,4.8426,4.84283,6.000
6,123.467,0.00,4.6427,4.64293,6.000
6,123.667,0.00,4.4426,4.44283,6.000
6,123.867,-0.01,4.2426,4.24280,6.000
6,124.067,0.00,4.0426,4.04280,6.000
6,124.267,0.00,3.8426,3.84283,6.000
6,124.467,0.00,3.6427,3.64287,6.000
6,124.667,0.00,3.4426,3.44277,6.000
6,124.867,0.00,3.2426,3.24280,6.000
6,125.067,0.00,3.0425,3.04267,6.000
6,125.267,0.00,2.8426,2.84280,6.000
6,125.467,0.00,2.6426,2.64277,6.000
6,125.667,0.00,2.4425,2.44270,6.000
6,125.867,0.00,2.2425,2.24267,6.000
6,126.067,0.00,2.0425,2.04270,6.000
6,126.267,0.00,1.8424,1.84263,6.000
6,126.467,0.00,1.6425,1.64270,6.000
6,126.667,0.00,1.4424,1.44260,6.000
6,126.867,0.00,1.2425,1.24267,6.000
6,127.067,0.00,1.0425,1.04270,6.000
6,127.267,0.00,0.8424,0.84263,6.000
6,127.467,0.00,0.6424,0.64260,6.000
6,127.667,0.00,0.4425,0.44273,6.000
6,127.867,0.00,0.2424,0.24263,6.000
6,128.067,0.00,0.0424,0.04257,6.000
6,128.400,0.00,-0.0005,-0.00030,6.000
6,128.600,0.00,-0.0005,-0.00030,6.000
6,128.800,0.00,-0.0005,-0.00030,6.000
6,129.000,0.00,-0.0005,-0.00030,6.000
6,129.200,0.00,-0.0005,-0.00030,6.000
6,129.400,0.00,-0.0004,-0.00020,6.000
6,129.600,0.00,-0.0004,-0.00020,6.000
6,129.800,0.00,-0.0004,-0.00020,6.000
6,130.000,0.00,-0.0004,-0.00020,6.000
6,130.200,0.00,-0.0004,-0.00020,6.000
6,130.400,0.00,-0.0004,-0.00020,6.000
6,130.600,0.00,-0.0004,-0.00020,6.000
6,130.800,0.00,-0.0003,-0.00010,6.000
6,131.000,0.01,-0.0003,-0.00010,6.000
6,131.200,0.00,-0.0003,-0.00010,6.000
6,131.467,0.00,-0.0003,-0.00010,6.000
6,131.667,0.00,-0.0003,-0.00010,6.000
6,131.867,0.00,-0.0003,-0.00010,6.000
6,132.067,0.00,-0.0003,-0.00010,6.000
7,132.467,0.00,0.1033,0.10347,7.000
7,132.667,0.00,0.3034,0.30357,7.000
7,132.867,0.00,0.5034,0.50360,7.000
7,133.067,0.00,0.7034,0.70360,7.000
7,133.267,0.00,0.9035,0.90367,7.000
7,133.467,0.00,1.1036,1.10377,7.000
7,133.667,0.00,1.3034,1.30357,7.000
7,133.867,0.00,1.5034,1.50360,7.000
7,134.067,0.00,1.7035,1.70370,7.000
7,134.267,0.00,1.9034,1.90363,7.000
7,134.467,0.00,2.1034,2.10363,7.000
7,134.667,0.00,2.3035,2.30367,7.000
7,134.867,0.00,2.5035,2.50367,7.000
7,135.067,0.00,2.7035,2.70367,7.000
7,135.267,0.00,2.9035,2.90373,7.000
7,135.467,0.00,3.1034,3.10357,7.000
7,135.667,0.00,3.3035,3.30373,7.000
7,135.867,0.00,3.5035,3.50367,7.000
7,136.067,0.00,3.7035,3.70373,7.000
7,136.267,0.00,3.9035,3.90370,7.000
7,136.467,0.00,4.1035,4.10370,7.000
7,136.667,0.00,4.3035,4.30370,7.000
7,136.867,0.00,4.5035,4.50373,7.000
7,137.067,0.00,4.7036,4.70377,7.000
7,137.267,0.00,4.9035,4.90367,7.000
7,137.467,0.00,5.1035,5.10367,7.000
7,137.667,0.00,5.3036,5.30377,7.000
7,137.867,0.00,5.5035,5.50370,7.000
7,138.067,0.00,5.7035,5.70373,7.000
7,138.267,0.01,5.9035,5.90370,7.000
7,138.467,0.09,6.1035,6.10367,7.000
7,138.667,0.39,6.3035,6.30373,7.000
7,138.867,0.98,6.5036,6.50377,7.000
7,139.067,1.87,6.7036,6.70380,7.000
7,139.267,3.07,6.9037,6.90387,7.000
7,139.467,4.61,7.1034,7.10357,7.000
7,139.667,6.61,7.3035,7.30373,7.000
7,139.867,9.12,7.5035,7.50373,7.000
7,140.067,12.23,7.7034,7.70363,7.000
7,140.267,16.07,7.9035,7.90367,7.000
7,140.467,20.82,8.1035,8.10373,7.000
7,140.667,26.74,8.3035,8.30370,7.000
7,140.867,34.11,8.5035,8.50373,7.000
7,141.067,43.43,8.7036,8.70380,7.000
7,141.400,41.23,8.7239,8.72410,7.000
7,141.600,29.24,8.5238,8.52400,7.000
7,141.800,21.29,8.3238,8.32400,7.000
7,142.000,15.55,8.1237,8.12390,7.000
7,142.200,11.38,7.9236,7.92380,7.000
7,142.400,8.26,7.7237,7.72390,7.000
7,142.600,5.91,7.5236,7.52380,7.000
7,142.800,4.14,7.3236,7.32380,7.000
7,143.000,2.81,7.1235,7.12370,7.000
7,143.200,1.85,6.9235,6.92370,7.000
7,143.400,1.11,6.7236,6.72380,7.000
7,143.600,0.56,6.5235,6.52370,7.000
7,143.800,0.20,6.3235,6.32370,7.000
7,144.000,0.04,6.1234,6.12360,7.000
7,144.200,0.00,5.9235,5.92370,7.000
7,144.400,0.00,5.7235,5.72370,7.000
7,144.600,0.00,5.5234,5.52360,7.000
7,144.800,0.00,5.3234,5.32360,7.000
7,145.000,0.00,5.1234,5.12360,7.000
7,145.200,0.00,4.9234,4.92360,7.000
7,145.400,0.00,4.7234,4.72360,7.000
7,145.600,0.00,4.5235,4.52370,7.000
7,145.800,0.00,4.3233,4.32350,7.000
7,146.000,0.00,4.1233,4.12350,7.000
7,146.200,0.00,3.9233,3.92350,7.000
7,146.400,0.00,3.7234,3.72360,7.000
7,146.600,0.00,3.5232,3.52340,7.000
7,146.800,0.00,3.3233,3.32350,7.000
7,147.000,0.00,3.1232,3.12340,7.000
7,147.200,0.01,2.9232,2.92340,7.000
7,147.400,0.00,2.7232,2.72340,7.000
7,147.600,0.00,2.5232,2.52340,7.000
7,147.800,0.00,2.3232,2.32340,7.000
7,148.000,0.00,2.1231,2.12330,7.000
7,148.200,0.00,1.9232,1.92340,7.000
7,148.400,0.00,1.7232,1.72340,7.000
7,148.600,0.00,1.5231,1.52330,7.000
7,148.800,0.00,1.3229,1.32310,7.000
7,149.000,0.00,1.1232,1.12340,7.000
7,149.200,0.00,0.9231,0.92330,7.000
7,149.400,0.00,0.7231,0.72330,7.000
7,149.600,0.00,0.5230,0.52320,7.000
7,149.800,0.00,0.3231,0.32330,7.000
7,150.000,0.00,0.1231,0.12330,7.000
7,150.267,0.00,-0.0017,-0.00147,7.000
7,150.467,0.00,-0.0005,-0.00030,7.000
7,150.667,0.00,-0.0005,-0.00030,7.000
7,150.867,0.00,-0.0005,-0.00030,7.000
7,151.067,0.00,-0.0005,-0.00030,7.000
7,151.267,0.00,-0.0005,-0.00030,7.000
7,151.467,0.00,-0.0004,-0.00020,7.000
7,151.667,0.00,-0.0004,-0.00020,7.000
7,151.867,0.00,-0.0004,-0.00020,7.000
7,152.067,0.00,-0.0004,-0.00020,7.000
7,152.267,0.00,-0.0004,-0.00020,7.000
7,152.467,0.00,-0.0004,-0.00020,7.000
7,152.667,0.00,-0.0004,-0.00020,7.000
7,152.867,0.00,-0.0003,-0.00010,7.000
7,153.067,0.00,-0.0003,-0.00010,7.000
7,153.333,0.00,-0.0003,-0.00010,7.000
7,153.533,0.00,-0.0003,-0.00010,7.000
7,153.733,0.00,-0.0003,-0.00010,7.000
7,153.933,0.00,-0.0003,-0.00010,7.000
7,154.133,0.00,-0.0003,-0.00010,7.000
8,154.533,0.00,0.1489,0.14900,8.000
8,154.733,-0.01,0.3490,0.34913,8.000
8,154.933,0.00,0.5491,0.54917,8.000
8,155.133,0.00,0.7491,0.74917,8.000
8,155.333,0.00,0.9491,0.94923,8.000
8,155.533,0.00,1.1492,1.14933,8.000
8,155.733,0.00,1.3490,1.34907,8.000
8,155.933,-0.01,1.5491,1.54920,8.000
8,156.133,0.00,1.7491,1.74923,8.000
8,156.333,-0.01,1.9491,1.94920,8.000
8,156.533,-0.01,2.1491,2.14920,8.000
8,156.733,0.00,2.3492,2.34927,8.000
8,156.933,0.00,2.5492,2.54927,8.000
8,157.133,-0.01,2.7492,2.74933,8.000
8,157.333,0.00,2.9492,2.94930,8.000
8,157.533,0.00,3.1491,3.14920,8.000
8,157.733,0.00,3.3491,3.34923,8.000
8,157.933,0.00,3.5491,3.54920,8.000
8,158.133,0.00,3.7492,3.74933,8.000
8,158.333,0.00,3.9492,3.94930,8.000
8,158.533,0.00,4.1492,4.14930,8.000
8,158.733,-0.01,4.3492,4.34927,8.000
8,158.933,0.00,4.5492,4.54933,8.000
8,159.133,-0.01,4.7492,4.74930,8.000
8,159.333,0.00,4.9492,4.94930,8.000
8,159.533,0.00,5.1492,5.14933,8.000
8,159.733,-0.01,5.3493,5.34937,8.000
8,159.933,0.00,5.5492,5.54927,8.000
8,160.133,-0.01,5.7491,5.74923,8.000
8,160.333,0.01,5.9492,5.94933,8.000
8,160.533,0.12,6.1492,6.14933,8.000
8,160.733,0.49,6.3491,6.34920,8.000
8,160.933,1.15,6.5493,6.54937,8.000
8,161.133,2.11,6.7493,6.74940,8.000
8,161.333,3.38,6.9493,6.94943,8.000
8,161.533,5.00,7.1492,7.14927,8.000
8,161.733,7.12,7.3492,7.34930,8.000
8,161.933,9.75,7.5492,7.54930,8.000
8,162.133,13.01,7.7492,7.74927,8.000
8,162.333,17.03,7.9491,7.94923,8.000
8,162.533,22.02,8.1492,8.14927,8.000
8,162.733,28.23,8.3492,8.34933,8.000
8,162.933,36.00,8.5492,8.54930,8.000
8,163.133,45.91,8.7492,8.74930,8.000
8,163.400,43.68,8.7567,8.75680,8.000
8,163.600,30.74,8.5567,8.55680,8.000
8,163.800,22.34,8.3569,8.35700,8.000
8,164.000,16.32,8.1568,8.15690,8.000
8,164.200,11.94,7.9568,7.95690,8.000
8,164.400,8.68,7.7567,7.75680,8.000
8,164.600,6.22,7.5567,7.55680,8.000
8,164.800,4.37,7.3567,7.35680,8.000
8,165.000,2.99,7.1565,7.15660,8.000
8,165.200,1.98,6.9566,6.95670,8.000
8,165.400,1.20,6.7567,6.75680,8.000
8,165.600,0.63,6.5566,6.55670,8.000
8,165.800,0.24,6.3565,6.35660,8.000
8,166.000,0.04,6.1566,6.15670,8.000
8,166.200,-0.01,5.9565,5.95660,8.000
8,166.400,-0.01,5.7565,5.75660,8.000
8,166.600,-0.01,5.5564,5.55650,8.000
8,166.800,-0.01,5.3565,5.35660,8.000
8,167.000,-0.01,5.1565,5.15660,8.000
8,167.200,-0.01,4.9565,4.95660,8.000
8,167.400,0.00,4.7564,4.75650,8.000
8,167.600,0.00,4.5565,4.55660,8.000
8,167.800,-0.01,4.3564,4.35650,8.000
8,168.000,-0.01,4.1564,4.15650,8.000
8,168.200,0.00,3.9564,3.95650,8.000
8,168.400,-0.01,3.7564,3.75650,8.000
8,168.600,-0.01,3.5564,3.55650,8.000
8,168.800,-0.01,3.3564,3.35650,8.000
8,169.000,-0.01,3.1561,3.15620,8.000
8,169.200,-0.01,2.9564,2.95650,8.000
8,169.400,-0.01,2.7563,2.75640,8.000
8,169.600,0.00,2.5563,2.55640,8.000
8,169.800,-0.01,2.3563,2.35640,8.000
8,170.000,-0.01,2.1562,2.15630,8.000
8,170.200,-0.01,1.9562,1.95630,8.000
8,170.400,0.00,1.7563,1.75640,8.000
8,170.600,-0.01,1.5561,1.55620,8.000
8,170.800,0.00,1.3562,1.35630,8.000
8,171.000,0.00,1.1563,1.15640,8.000
8,171.200,0.00,0.9562,0.95630,8.000
8,171.400,0.00,0.7563,0.75640,8.000
8,171.600,-0.01,0.5562,0.55630,8.000
8,171.800,-0.01,0.3562,0.35630,8.000
8,172.000,-0.01,0.1561,0.15620,8.000
8,172.267,-0.01,-0.0176,-0.01753,8.000
8,172.467,0.00,-0.0005,-0.00040,8.000
8,172.667,0.00,-0.0005,-0.00040,8.000
8,172.867,-0.01,-0.0005,-0.00040,8.000
8,173.067,-0.01,-0.0005,-0.00040,8.000
8,173.267,0.00,-0.0004,-0.00030,8.000
8,173.467,-0.01,-0.0004,-0.00030,8.000
8,173.667,0.00,-0.0004,-0.00030,8.000
8,173.867,0.00,-0.0004,-0.00030,8.000
8,174.067,-0.01,-0.0004,-0.00030,8.000
8,174.267,-0.01,-0.0004,-0.00030,8.000
8,174.467,-0.01,-0.0004,-0.00030,8.000
8,174.667,0.00,-0.0003,-0.00020,8.000
8,174.867,0.00,-0.0003,-0.00020,8.000
8,175.067,-0.01,-0.0003,-0.00020,8.000
8,175.333,-0.01,-0.0003,-0.00020,8.000
8,175.533,-0.01,-0.0003,-0.00020,8.000
8,175.733,-0.01,-0.0003,-0.00020,8.000
8,175.933,-0.01,-0.0003,-0.00020,8.000
8,176.133,0.00,-0.0003,-0.00020,8.000
9,176.467,0.00,0.0520,0.05213,9.000
9,176.667,0.00,0.2522,0.25233,9.000
9,176.867,0.00,0.4523,0.45243,9.000
9,177.067,0.00,0.6523,0.65240,9.000
9,177.267,0.00,0.8523,0.85243,9.000
9,177.467,0.00,1.0524,1.05253,9.000
9,177.667,0.00,1.2524,1.25247,9.000
9,177.867,0.00,1.4523,1.45237,9.000
9,178.067,0.00,1.6524,1.65250,9.000
9,178.267,0.00,1.8523,1.85240,9.000
9,178.467,0.00,2.0524,2.05247,9.000
9,178.667,0.00,2.2524,2.25247,9.000
9,178.867,0.00,2.4523,2.45243,9.000
9,179.067,0.00,2.6524,2.65250,9.000
9,179.267,0.00,2.8525,2.85257,9.000
9,179.467,0.00,3.0523,3.05243,9.000
9,179.667,0.00,3.2524,3.25253,9.000
9,179.867,0.00,3.4524,3.45247,9.000
9,180.067,0.00,3.6525,3.65257,9.000
9,180.267,0.00,3.8524,3.85253,9.000
9,180.467,0.00,4.0524,4.05247,9.000
9,180.667,0.00,4.2524,4.25253,9.000
9,180.867,0.00,4.4524,4.45253,9.000
9,181.067,0.00,4.6524,4.65253,9.000
9,181.267,0.00,4.8525,4.85260,9.000
9,181.467,0.00,5.0525,5.05257,9.000
9,181.667,0.00,5.2525,5.25257,9.000
9,181.867,0.00,5.4525,5.45263,9.000
9,182.067,0.00,5.6525,5.65257,9.000
9,182.267,0.00,5.8526,5.85267,9.000
9,182.467,0.06,6.0525,6.05260,9.000
9,182.667,0.28,6.2527,6.25277,9.000
9,182.867,0.80,6.4526,6.45267,9.000
9,183.067,1.61,6.6526,6.65267,9.000
9,183.267,2.72,6.8527,6.85283,9.000
9,183.467,4.16,7.0525,7.05260,9.000
9,183.667,6.02,7.2525,7.25263,9.000
9,183.867,8.40,7.4525,7.45263,9.000
9,184.067,11.33,7.6526,7.65267,9.000
9,184.267,14.96,7.8526,7.85267,9.000
9,184.467,19.45,8.0525,8.05263,9.000
9,184.667,25.03,8.2526,8.25270,9.000
9,184.867,31.97,8.4526,8.45270,9.000
9,185.067,40.72,8.6526,8.65273,9.000
9,185.333,53.11,8.8526,8.85267,9.000
9,185.533,36.14,8.6534,8.65350,9.000
9,185.733,26.00,8.4534,8.45350,9.000
9,185.933,18.98,8.2534,8.25347,9.000
9,186.133,13.85,8.0533,8.05340,9.000
9,186.333,10.12,7.8533,7.85337,9.000
9,186.533,7.30,7.6532,7.65327,9.000
9,186.733,5.19,7.4532,7.45333,9.000
9,186.933,3.61,7.2532,7.25327,9.000
9,187.133,2.41,7.0530,7.05313,9.000
9,187.333,1.54,6.8533,6.85340,9.000
9,187.533,0.88,6.6532,6.65333,9.000
9,187.733,0.41,6.4532,6.45327,9.000
9,187.933,0.12,6.2531,6.25323,9.000
9,188.133,0.01,6.0530,6.05313,9.000
9,188.333,0.00,5.8530,5.85313,9.000
9,188.533,0.00,5.6529,5.65303,9.000
9,188.733,0.00,5.4530,5.45310,9.000
9,188.933,0.00,5.2531,5.25317,9.000
9,189.133,0.00,5.0529,5.05303,9.000
9,189.333,0.00,4.8529,4.85303,9.000
9,189.533,0.00,4.6530,4.65310,9.000
9,189.733,0.00,4.4530,4.45307,9.000
9,189.933,0.00,4.2529,4.25300,9.000
9,190.133,0.00,4.0529,4.05300,9.000
9,190.333,0.00,3.8529,3.85300,9.000
9,190.533,0.00,3.6529,3.65303,9.000
9,190.733,0.00,3.4528,3.45293,9.000
9,190.933,0.00,3.2528,3.25293,9.000
9,191.133,0.00,3.0528,3.05287,9.000
9,191.333,0.00,2.8529,2.85303,9.000
9,191.533,0.00,2.6528,2.65293,9.000
9,191.733,0.00,2.4528,2.45287,9.000
9,191.933,0.00,2.2528,2.25287,9.000
9,192.133,0.00,2.0528,2.05287,9.000
9,192.333,0.00,1.8528,1.85287,9.000
9,192.533,0.00,1.6528,1.65290,9.000
9,192.733,0.00,1.4527,1.45277,9.000
9,192.933,0.00,1.2527,1.25277,9.000
9,193.133,0.01,1.0528,1.05290,9.000
9,193.333,0.00,0.8528,0.85287,9.000
9,193.533,0.00,0.6527,0.65283,9.000
9,193.733,0.00,0.4528,0.45290,9.000
9,193.933,0.00,0.2528,0.25290,9.000
9,194.133,0.00,0.0528,0.05287,9.000
9,194.400,0.00,-0.0005,-0.00040,9.000
9,194.600,0.00,-0.0005,-0.00040,9.000
9,194.800,0.00,-0.0005,-0.00040,9.000
9,195.000,0.00,-0.0005,-0.00040,9.000
9,195.200,0.00,-0.0004,-0.00030,9.000
9,195.400,0.00,-0.0004,-0.00030,9.000
9,195.600,0.00,-0.0004,-0.00030,9.000
9,195.800,0.00,-0.0004,-0.00030,9.000
9,196.000,0.00,-0.0004,-0.00030,9.000
9,196.200,0.00,-0.0004,-0.00030,9.000
9,196.400,0.00,-0.0004,-0.00030,9.000
9,196.600,0.00,-0.0003,-0.00020,9.000
9,196.800,0.00,-0.0003,-0.00020,9.000
9,197.000,0.00,-0.0003,-0.00020,9.000
9,197.200,0.00,-0.0003,-0.00020,9.000
9,197.467,0.00,-0.0003,-0.00020,9.000
9,197.667,0.00,-0.0003,-0.00020,9.000
9,197.867,0.00,-0.0003,-0.00020,9.000
9,198.067,0.00,-0.0003,-0.00020,9.000
9,198.267,0.00,-0.0002,-0.00013,9.000
10,198.667,0.00,0.2233,0.22340,10.000
10,198.867,0.00,0.4234,0.42350,10.000
10,199.067,0.00,0.6233,0.62340,10.000
10,199.267,0.01,0.8234,0.82350,10.000
10,199.467,0.01,1.0235,1.02357,10.000
10,199.667,0.00,1.2235,1.22360,10.000
10,199.867,0.00,1.4232,1.42333,10.000
10,200.067,0.00,1.6234,1.62353,10.000
10,200.267,0.00,1.8234,1.82347,10.000
10,200.467,0.00,2.0234,2.02350,10.000
10,200.667,0.01,2.2234,2.22347,10.000
10,200.867,0.00,2.4234,2.42350,10.000
10,201.067,0.00,2.6235,2.62360,10.000
10,201.267,0.00,2.8234,2.82353,10.000
10,201.467,0.01,3.0234,3.02353,10.000
10,201.667,0.01,3.2234,3.22347,10.000
10,201.867,0.00,3.4234,3.42347,10.000
10,202.067,0.00,3.6234,3.62353,10.000
10,202.267,0.00,3.8234,3.82353,10.000
10,202.467,0.00,4.0234,4.02350,10.000
10,202.667,0.00,4.2234,4.22347,10.000
10,202.867,0.00,4.4235,4.42357,10.000
10,203.067,0.01,4.6234,4.62353,10.000
10,203.267,0.00,4.8235,4.82363,10.000
10,203.467,0.00,5.0235,5.02363,10.000
10,203.667,0.00,5.2236,5.22370,10.000
10,203.867,0.00,5.4236,5.42373,10.000
10,204.067,0.00,5.6235,5.62357,10.000
10,204.267,0.00,5.8234,5.82353,10.000
10,204.467,0.04,6.0235,6.02360,10.000
10,204.667,0.22,6.2236,6.22367,10.000
10,204.867,0.70,6.4235,6.42360,10.000
10,205.067,1.47,6.6235,6.62363,10.000
10,205.267,2.53,6.8236,6.82373,10.000
10,205.467,3.92,7.0234,7.02350,10.000
10,205.667,5.71,7.2234,7.22353,10.000
10,205.867,8.01,7.4235,7.42360,10.000
10,206.067,10.85,7.6235,7.62357,10.000
10,206.267,14.37,7.8235,7.82363,10.000
10,206.467,18.71,8.0234,8.02353,10.000
10,206.667,24.10,8.2235,8.22360,10.000
10,206.867,30.82,8.4235,8.42360,10.000
10,207.067,39.28,8.6235,8.62363,10.000
10,207.267,50.33,8.8235,8.82357,10.000
10,207.533,38.09,8.6844,8.68453,10.000
10,207.733,27.27,8.4844,8.48450,10.000
10,207.933,19.88,8.2845,8.28457,10.000
10,208.133,14.51,8.0844,8.08453,10.000
10,208.333,10.60,7.8844,7.88447,10.000
10,208.533,7.66,7.6843,7.68437,10.000
10,208.733,5.46,7.4843,7.48440,10.000
10,208.933,3.81,7.2843,7.28437,10.000
10,209.133,2.57,7.0841,7.08423,10.000
10,209.333,1.66,6.8844,6.88447,10.000
10,209.533,0.98,6.6842,6.68433,10.000
10,209.733,0.48,6.4843,6.48437,10.000
10,209.933,0.15,6.2841,6.28423,10.000
10,210.133,0.02,6.0842,6.08427,10.000
10,210.333,0.00,5.8841,5.88423,10.000
10,210.533,0.00,5.6841,5.68423,10.000
10,210.733,0.00,5.4841,5.48423,10.000
10,210.933,0.00,5.2842,5.28430,10.000
10,211.133,0.01,5.0841,5.08420,10.000
10,211.333,0.01,4.8841,4.88420,10.000
10,211.533,0.01,4.6840,4.68410,10.000
10,211.733,0.01,4.4841,4.48420,10.000
10,211.933,0.00,4.2840,4.28410,10.000
10,212.133,0.00,4.0839,4.08403,10.000
10,212.333,0.00,3.8841,3.88417,10.000
10,212.533,0.00,3.6840,3.68413,10.000
10,212.733,0.01,3.4839,3.48397,10.000
10,212.933,0.00,3.2840,3.28407,10.000
10,213.133,0.00,3.0838,3.08390,10.000
10,213.333,0.00,2.8839,2.88403,10.000
10,213.533,0.00,2.6839,2.68403,10.000
10,213.733,0.00,2.4839,2.48397,10.000
10,213.933,0.00,2.2839,2.28400,10.000
10,214.133,0.00,2.0839,2.08400,10.000
10,214.333,0.00,1.8838,1.88390,10.000
10,214.533,0.01,1.6838,1.68393,10.000
10,214.733,0.00,1.4838,1.48387,10.000
10,214.933,0.00,1.2837,1.28383,10.000
10,215.133,0.00,1.0839,1.08397,10.000
10,215.333,0.00,0.8839,0.88397,10.000
10,215.533,0.00,0.6838,0.68387,10.000
10,215.733,0.01,0.4839,0.48397,10.000
10,215.933,0.00,0.2838,0.28387,10.000
10,216.133,0.01,0.0837,0.08377,10.000
10,216.400,0.00,-0.0005,-0.00040,10.000
10,216.600,0.01,-0.0005,-0.00040,10.000
10,216.800,0.00,-0.0005,-0.00040,10.000
10,217.000,0.00,-0.0004,-0.00030,10.000
10,217.200,0.01,-0.0004,-0.00030,10.000
10,217.400,0.00,-0.0004,-0.00030,10.000
10,217.600,0.00,-0.0004,-0.00030,10.000
10,217.800,0.01,-0.0004,-0.00030,10.000
10,218.000,0.01,-0.0004,-0.00030,10.000
10,218.200,0.01,-0.0004,-0.00030,10.000
10,218.400,0.01,-0.0003,-0.00020,10.000
10,218.600,0.01,-0.0003,-0.00020,10.000
10,218.800,0.00,-0.0003,-0.00020,10.000
10,219.000,0.00,-0.0003,-0.00020,10.000
10,219.200,0.00,-0.0003,-0.00020,10.000
10,219.467,0.00,-0.0003,-0.00020,10.000
10,219.667,0.00,-0.0003,-0.00020,10.000
10,219.867,0.00,-0.0003,-0.00020,10.000
10,220.067,0.00,-0.0003,-0.00020,10.000
10,220.267,0.01,-0.0002,-0.00010,10.000