File: calibDATA_loadcell/date_02:15:2018/Instron_02.15.2018/1_5N_3_1mm.s_0_0.txt
""
"Test Method","Radhen_Load_Cntrl_Cmprsn_250N_12-7.msm"
"Sample I. D.","Sample1.mss"
"Specimen Number","9"

"TheCycle_Output ()","_Time (s)","_Load (N)","_Extension (mm)","RealTimeDepth (mm)","CycleNumber ()"

1,0.200,0.00,0.0000,0.00000,1.000
1,0.333,0.00,0.1128,0.11277,1.000
1,0.467,0.00,0.2462,0.24620,1.000
1,0.600,0.00,0.3796,0.37960,1.000
1,0.733,0.00,0.5129,0.51293,1.000
1,0.867,0.00,0.6462,0.64623,1.000
1,1.000,0.00,0.7797,0.77970,1.000
1,1.133,0.00,0.9130,0.91297,1.000
1,1.267,0.00,1.0461,1.04613,1.000
1,1.400,0.00,1.1795,1.17950,1.000
1,1.533,0.00,1.3130,1.31303,1.000
1,1.667,0.00,1.4463,1.44627,1.000
1,1.800,0.00,1.5797,1.57970,1.000
1,1.933,0.03,1.7131,1.71307,1.000
1,2.067,0.12,1.8462,1.84623,1.000
1,2.200,0.34,1.9798,1.97980,1.000
1,2.333,0.69,2.1132,2.11317,1.000
1,2.467,1.15,2.2464,2.24643,1.000
1,2.600,1.76,2.3799,2.37990,1.000
1,2.733,2.53,2.5130,2.51300,1.000
1,2.867,3.48,2.6463,2.64633,1.000
1,3.000,4.60,2.7796,2.77960,1.000
1,3.267,4.06,2.7398,2.73983,1.000
1,3.400,2.85,2.6063,2.60630,1.000
1,3.533,1.95,2.4730,2.47300,1.000
1,3.667,1.25,2.3399,2.33987,1.000
1,3.800,0.73,2.2063,2.20630,1.000
1,3.933,0.36,2.0732,2.07323,1.000
1,4.067,0.12,1.9398,1.93980,1.000
1,4.200,0.02,1.8063,1.80630,1.000
1,4.333,0.00,1.6732,1.67320,1.000
1,4.467,0.00,1.5398,1.53980,1.000
1,4.600,0.00,1.4063,1.40630,1.000
1,4.733,0.00,1.2730,1.27300,1.000
1,4.867,0.00,1.1398,1.13980,1.000
1,5.000,0.00,1.0062,1.00620,1.000
1,5.133,0.00,0.8730,0.87303,1.000
1,5.267,0.00,0.7398,0.73983,1.000
1,5.400,0.00,0.6062,0.60620,1.000
1,5.533,0.00,0.4729,0.47293,1.000
1,5.667,0.00,0.3397,0.33973,1.000
1,5.800,0.00,0.2062,0.20620,1.000
1,5.933,0.00,0.0729,0.07293,1.000
1,6.133,0.00,-0.0055,-0.00550,1.000
1,6.267,0.00,-0.0003,-0.00030,1.000
1,6.400,0.00,-0.0003,-0.00030,1.000
1,6.533,0.00,-0.0002,-0.00020,1.000
1,6.667,0.00,-0.0002,-0.00020,1.000
1,6.800,0.00,-0.0002,-0.00020,1.000
1,6.933,0.00,-0.0002,-0.00020,1.000
1,7.067,0.00,-0.0002,-0.00020,1.000
1,7.200,0.00,-0.0002,-0.00020,1.000
1,7.333,0.00,-0.0002,-0.00020,1.000
1,7.467,0.00,-0.0002,-0.00020,1.000
1,7.600,0.00,-0.0002,-0.00020,1.000
1,7.733,0.00,-0.0002,-0.00020,1.000
1,7.867,0.00,-0.0002,-0.00020,1.000
1,8.000,0.00,-0.0002,-0.00020,1.000
1,8.133,0.00,-0.0002,-0.00020,1.000
1,8.267,0.00,-0.0002,-0.00020,1.000
1,8.400,0.00,-0.0002,-0.00020,1.000
1,8.533,0.00,-0.0002,-0.00020,1.000
1,8.667,0.00,-0.0002,-0.00020,1.000
1,8.800,0.00,-0.0002,-0.00020,1.000
1,8.933,0.00,-0.0002,-0.00020,1.000
1,9.067,0.00,-0.0002,-0.00020,1.000
1,9.267,0.00,-0.0002,-0.00020,1.000
1,9.400,0.00,-0.0002,-0.00020,1.000
1,9.533,0.00,-0.0002,-0.00020,1.000
1,9.667,0.00,-0.0002,-0.00020,1.000
1,9.800,0.00,-0.0002,-0.00020,1.000
1,9.933,0.00,-0.0002,-0.00020,1.000
1,10.067,0.00,-0.0002,-0.00020,1.000
2,10.400,-0.01,0.1296,0.12960,2.000
2,10.533,0.00,0.2631,0.26313,2.000
2,10.667,-0.01,0.3963,0.39630,2.000
2,10.800,0.00,0.5296,0.52960,2.000
2,10.933,-0.01,0.6631,0.66310,2.000
2,11.067,-0.01,0.7965,0.79650,2.000
2,11.200,0.00,0.9297,0.92970,2.000
2,11.333,0.00,1.0631,1.06310,2.000
2,11.467,-0.01,1.1963,1.19630,2.000
2,11.600,-0.01,1.3297,1.32970,2.000
2,11.733,-0.01,1.4631,1.46307,2.000
2,11.867,-0.01,1.5964,1.59643,2.000
2,12.000,0.02,1.7298,1.72980,2.000
2,12.133,0.13,1.8631,1.86310,2.000
2,12.267,0.36,1.9965,1.99650,2.000
2,12.400,0.73,2.1298,2.12980,2.000
2,12.533,1.22,2.2632,2.26320,2.000
2,12.667,1.86,2.3965,2.39650,2.000
2,12.800,2.66,2.5296,2.52960,2.000
2,12.933,3.63,2.6632,2.66317,2.000
2,13.067,4.79,2.7965,2.79647,2.000
2,13.267,4.39,2.7638,2.76377,2.000
2,13.400,3.09,2.6306,2.63060,2.000
2,13.533,2.12,2.4970,2.49703,2.000
2,13.667,1.38,2.3638,2.36383,2.000
2,13.800,0.83,2.2306,2.23060,2.000
2,13.933,0.43,2.0973,2.09730,2.000
2,14.067,0.16,1.9638,1.96377,2.000
2,14.200,0.03,1.8305,1.83050,2.000
2,14.333,-0.01,1.6972,1.69720,2.000
2,14.467,0.00,1.5637,1.56373,2.000
2,14.600,0.00,1.4306,1.43060,2.000
2,14.733,0.00,1.2971,1.29713,2.000
2,14.867,0.00,1.1637,1.16370,2.000
2,15.000,0.00,1.0303,1.03030,2.000
2,15.133,-0.01,0.8971,0.89713,2.000
2,15.267,-0.01,0.7637,0.76373,2.000
2,15.400,0.00,0.6305,0.63050,2.000
2,15.533,0.00,0.4971,0.49710,2.000
2,15.667,0.00,0.3637,0.36370,2.000
2,15.800,-0.01,0.2305,0.23050,2.000
2,15.933,-0.01,0.0971,0.09710,2.000
2,16.133,0.00,-0.0363,-0.03630,2.000
2,16.267,0.00,-0.0002,-0.00020,2.000
2,16.400,0.00,-0.0002,-0.00020,2.000
2,16.533,-0.01,-0.0002,-0.00020,2.000
2,16.667,0.00,-0.0002,-0.00020,2.000
2,16.800,0.00,-0.0002,-0.00020,2.000
2,16.933,0.00,-0.0002,-0.00020,2.000
2,17.067,0.00,-0.0002,-0.00020,2.000
2,17.200,0.00,-0.0002,-0.00020,2.000
2,17.333,-0.01,-0.0002,-0.00020,2.000
2,17.467,0.00,-0.0002,-0.00020,2.000
2,17.600,-0.01,-0.0002,-0.00020,2.000
2,17.733,0.00,-0.0002,-0.00020,2.000
2,17.867,0.00,-0.0002,-0.00020,2.000
2,18.000,-0.01,-0.0002,-0.00020,2.000
2,18.133,-0.01,-0.0002,-0.00020,2.000
2,18.267,-0.01,-0.0002,-0.00020,2.000
2,18.400,-0.01,-0.0002,-0.00020,2.000
2,18.533,-0.01,-0.0002,-0.00020,2.000
2,18.667,-0.01,-0.0002,-0.00020,2.000
2,18.800,0.00,-0.0001,-0.00010,2.000
2,18.933,0.00,-0.0001,-0.00010,2.000
2,19.067,0.00,-0.0001,-0.00010,2.000
2,19.267,0.00,-0.0001,-0.00010,2.000
2,19.400,0.00,-0.0001,-0.00010,2.000
2,19.533,-0.01,-0.0001,-0.00010,2.000
2,19.667,0.00,-0.0001,-0.00010,2.000
2,19.800,-0.01,-0.0001,-0.00010,2.000
2,19.933,0.00,-0.0001,-0.00010,2.000
2,20.067,-0.01,-0.0001,-0.00010,2.000
3,20.400,0.00,0.0896,0.08960,3.000
3,20.533,0.00,0.2231,0.22310,3.000
3,20.667,0.00,0.3563,0.35633,3.000
3,20.800,0.00,0.4897,0.48970,3.000
3,20.933,0.00,0.6231,0.62307,3.000
3,21.067,0.00,0.7565,0.75647,3.000
3,21.200,0.00,0.8898,0.88980,3.000
3,21.333,0.00,1.0230,1.02300,3.000
3,21.467,0.00,1.1563,1.15633,3.000
3,21.600,0.00,1.2897,1.28970,3.000
3,21.733,0.00,1.4232,1.42320,3.000
3,21.867,0.00,1.5565,1.55647,3.000
3,22.000,0.01,1.6898,1.68980,3.000
3,22.133,0.09,1.8231,1.82310,3.000
3,22.267,0.28,1.9564,1.95643,3.000
3,22.400,0.62,2.0898,2.08980,3.000
3,22.533,1.07,2.2232,2.22323,3.000
3,22.667,1.66,2.3566,2.35657,3.000
3,22.800,2.42,2.4896,2.48960,3.000
3,22.933,3.34,2.6231,2.62307,3.000
3,23.067,4.46,2.7565,2.75647,3.000
3,23.267,5.13,2.8238,2.82383,3.000
3,23.400,3.62,2.6905,2.69050,3.000
3,23.533,2.53,2.5571,2.55710,3.000
3,23.667,1.69,2.4239,2.42387,3.000
3,23.800,1.07,2.2905,2.29050,3.000
3,23.933,0.61,2.1573,2.15730,3.000
3,24.067,0.27,2.0240,2.02397,3.000
3,24.200,0.07,1.8903,1.89030,3.000
3,24.333,0.01,1.7572,1.75717,3.000
3,24.467,-0.01,1.6240,1.62397,3.000
3,24.600,0.00,1.4904,1.49040,3.000
3,24.733,0.00,1.3571,1.35713,3.000
3,24.867,0.00,1.2238,1.22377,3.000
3,25.000,0.00,1.0904,1.09040,3.000
3,25.133,0.00,0.9570,0.95697,3.000
3,25.267,0.00,0.8239,0.82390,3.000
3,25.400,0.00,0.6904,0.69040,3.000
3,25.533,0.00,0.5569,0.55693,3.000
3,25.667,0.00,0.4238,0.42383,3.000
3,25.800,0.00,0.2904,0.29040,3.000
3,25.933,0.00,0.1570,0.15700,3.000
3,26.067,0.00,0.0238,0.02377,3.000
3,26.267,0.00,-0.0001,-0.00007,3.000
3,26.400,0.00,-0.0002,-0.00020,3.000
3,26.533,0.00,-0.0002,-0.00020,3.000
3,26.667,0.00,-0.0002,-0.00020,3.000
3,26.800,0.00,-0.0002,-0.00020,3.000
3,26.933,0.00,-0.0002,-0.00020,3.000
3,27.067,-0.01,-0.0002,-0.00020,3.000
3,27.200,-0.01,-0.0002,-0.00020,3.000
3,27.333,0.00,-0.0002,-0.00020,3.000
3,27.467,0.00,-0.0002,-0.00020,3.000
3,27.600,0.00,-0.0002,-0.00020,3.000
3,27.733,0.00,-0.0002,-0.00020,3.000
3,27.867,0.00,-0.0002,-0.00020,3.000
3,28.000,-0.01,-0.0002,-0.00020,3.000
3,28.133,0.00,-0.0002,-0.00020,3.000
3,28.267,0.00,-0.0002,-0.00020,3.000
3,28.400,0.00,-0.0002,-0.00020,3.000
3,28.533,0.00,-0.0002,-0.00020,3.000
3,28.667,0.00,-0.0002,-0.00020,3.000
3,28.800,0.00,-0.0002,-0.00020,3.000
3,28.933,0.00,-0.0002,-0.00020,3.000
3,29.067,0.00,-0.0002,-0.00020,3.000
3,29.200,0.00,-0.0002,-0.00020,3.000
3,29.400,0.00,-0.0001,-0.00010,3.000
3,29.533,0.00,-0.0001,-0.00010,3.000
3,29.667,0.00,-0.0001,-0.00010,3.000
3,29.800,0.00,-0.0001,-0.00010,3.000
3,29.933,0.00,-0.0001,-0.00010,3.000
3,30.067,0.00,-0.0001,-0.00010,3.000
3,30.200,0.00,-0.0001,-0.00010,3.000
4,30.533,0.00,0.1530,0.15307,4.000
4,30.667,0.00,0.2863,0.28643,4.000
4,30.800,0.01,0.4197,0.41980,4.000
4,30.933,0.00,0.5531,0.55317,4.000
4,31.067,0.00,0.6864,0.68653,4.000
4,31.200,0.00,0.8198,0.81990,4.000
4,31.333,0.00,0.9531,0.95323,4.000
4,31.467,0.01,1.0864,1.08650,4.000
4,31.600,0.00,1.2198,1.21990,4.000
4,31.733,0.00,1.3533,1.35337,4.000
4,31.867,0.00,1.4864,1.48647,4.000
4,32.000,0.00,1.6198,1.61990,4.000
4,32.133,0.05,1.7531,1.75323,4.000
4,32.267,0.17,1.8864,1.88647,4.000
4,32.400,0.43,2.0199,2.02000,4.000
4,32.533,0.83,2.1533,2.15337,4.000
4,32.667,1.34,2.2865,2.28660,4.000
4,32.800,2.01,2.4199,2.42000,4.000
4,32.933,2.85,2.5531,2.55320,4.000
4,33.067,3.87,2.6864,2.68647,4.000
4,33.200,5.07,2.8197,2.81980,4.000
4,33.400,4.37,2.7604,2.76050,4.000
4,33.533,3.08,2.6272,2.62730,4.000
4,33.667,2.12,2.4937,2.49380,4.000
4,33.800,1.39,2.3606,2.36070,4.000
4,33.933,0.84,2.2273,2.22743,4.000
4,34.067,0.44,2.0939,2.09400,4.000
4,34.200,0.17,1.9605,1.96060,4.000
4,34.333,0.04,1.8271,1.82723,4.000
4,34.467,0.01,1.6938,1.69393,4.000
4,34.600,0.00,1.5605,1.56060,4.000
4,34.733,0.00,1.4272,1.42730,4.000
4,34.867,0.01,1.2937,1.29383,4.000
4,35.000,0.00,1.1603,1.16040,4.000
4,35.133,0.01,1.0270,1.02713,4.000
4,35.267,0.00,0.8938,0.89390,4.000
4,35.400,0.01,0.7604,0.76050,4.000
4,35.533,0.00,0.6271,0.62723,4.000
4,35.667,0.00,0.4937,0.49383,4.000
4,35.800,0.00,0.3603,0.36040,4.000
4,35.933,0.00,0.2271,0.22720,4.000
4,36.067,0.01,0.0937,0.09380,4.000
4,36.267,0.00,-0.0427,-0.04257,4.000
4,36.400,0.01,-0.0002,-0.00010,4.000
4,36.533,0.00,-0.0002,-0.00010,4.000
4,36.667,0.00,-0.0002,-0.00010,4.000
4,36.800,0.01,-0.0002,-0.00010,4.000
4,36.933,0.00,-0.0002,-0.00010,4.000
4,37.067,0.00,-0.0002,-0.00010,4.000
4,37.200,0.00,-0.0002,-0.00010,4.000
4,37.333,0.00,-0.0002,-0.00010,4.000
4,37.467,0.00,-0.0002,-0.00010,4.000
4,37.600,0.00,-0.0002,-0.00010,4.000
4,37.733,0.01,-0.0002,-0.00010,4.000
4,37.867,0.00,-0.0002,-0.00010,4.000
4,38.000,0.00,-0.0002,-0.00010,4.000
4,38.133,0.00,-0.0002,-0.00010,4.000
4,38.267,0.00,-0.0002,-0.00010,4.000
4,38.400,0.01,-0.0002,-0.00010,4.000
4,38.533,0.00,-0.0002,-0.00010,4.000
4,38.667,0.00,-0.0002,-0.00010,4.000
4,38.800,0.00,-0.0001,0.00000,4.000
4,38.933,0.00,-0.0001,0.00000,4.000
4,39.067,0.01,-0.0001,0.00000,4.000
4,39.200,0.00,-0.0001,0.00000,4.000
4,39.400,0.00,-0.0001,0.00000,4.000
4,39.533,0.00,-0.0001,0.00000,4.000
4,39.667,0.00,-0.0001,0.00000,4.000
4,39.800,0.00,-0.0001,0.00000,4.000
4,39.933,0.00,-0.0001,0.00000,4.000
4,40.067,0.00,-0.0001,0.00000,4.000
4,40.200,0.01,-0.0001,0.00000,4.000
5,40.533,-0.01,0.0720,0.07203,5.000
5,40.667,-0.01,0.2053,0.20530,5.000
5,40.800,-0.01,0.3388,0.33880,5.000
5,40.933,-0.01,0.4721,0.47210,5.000
5,41.067,-0.01,0.6053,0.60530,5.000
5,41.200,-0.01,0.7388,0.73880,5.000
5,41.333,-0.01,0.8721,0.87213,5.000
5,41.467,-0.01,1.0053,1.00533,5.000
5,41.600,0.00,1.1387,1.13870,5.000
5,41.733,0.00,1.2720,1.27203,5.000
5,41.867,0.00,1.4054,1.40543,5.000
5,42.000,-0.01,1.5388,1.53880,5.000
5,42.133,0.00,1.6722,1.67223,5.000
5,42.267,0.07,1.8053,1.80533,5.000
5,42.400,0.25,1.9388,1.93880,5.000
5,42.533,0.56,2.0722,2.07223,5.000
5,42.667,1.01,2.2055,2.20550,5.000
5,42.800,1.58,2.3390,2.33900,5.000
5,42.933,2.32,2.4721,2.47210,5.000
5,43.067,3.22,2.6054,2.60543,5.000
5,43.200,4.31,2.7387,2.73870,5.000
5,43.400,5.15,2.8196,2.81960,5.000
5,43.533,3.63,2.6861,2.68613,5.000
5,43.667,2.52,2.5528,2.55283,5.000
5,43.800,1.70,2.4195,2.41950,5.000
5,43.933,1.06,2.2862,2.28617,5.000
5,44.067,0.60,2.1530,2.15300,5.000
5,44.200,0.26,2.0196,2.01960,5.000
5,44.333,0.07,1.8861,1.88607,5.000
5,44.467,0.00,1.7529,1.75287,5.000
5,44.600,-0.01,1.6196,1.61960,5.000
5,44.733,-0.01,1.4860,1.48603,5.000
5,44.867,-0.01,1.3529,1.35290,5.000
5,45.000,0.00,1.2195,1.21950,5.000
5,45.133,-0.01,1.0860,1.08600,5.000
5,45.267,-0.01,0.9527,0.95270,5.000
5,45.400,-0.01,0.8196,0.81960,5.000
5,45.533,-0.01,0.6860,0.68603,5.000
5,45.667,-0.01,0.5527,0.55273,5.000
5,45.800,-0.01,0.4195,0.41950,5.000
5,45.933,0.00,0.2860,0.28597,5.000
5,46.067,0.00,0.1527,0.15270,5.000
5,46.200,-0.01,0.0195,0.01950,5.000
5,46.400,-0.01,-0.0002,-0.00020,5.000
5,46.533,0.00,-0.0002,-0.00020,5.000
5,46.667,-0.01,-0.0002,-0.00020,5.000
5,46.800,-0.01,-0.0002,-0.00020,5.000
5,46.933,-0.01,-0.0002,-0.00020,5.000
5,47.067,-0.01,-0.0002,-0.00020,5.000
5,47.200,0.00,-0.0002,-0.00020,5.000
5,47.333,-0.01,-0.0002,-0.00020,5.000
5,47.467,-0.01,-0.0002,-0.00020,5.000
5,47.600,-0.01,-0.0002,-0.00020,5.000
5,47.733,-0.01,-0.0002,-0.00020,5.000
5,47.867,-0.01,-0.0002,-0.00020,5.000
5,48.000,-0.01,-0.0002,-0.00020,5.000
5,48.133,0.00,-0.0002,-0.00020,5.000
5,48.267,-0.01,-0.0002,-0.00020,5.000
5,48.400,0.00,-0.0002,-0.00020,5.000
5,48.533,-0.01,-0.0002,-0.00020,5.000
5,48.667,-0.01,-0.0002,-0.00020,5.000
5,48.800,0.00,-0.0002,-0.00020,5.000
5,48.933,-0.01,-0.0002,-0.00020,5.000
5,49.067,-0.01,-0.0001,-0.00010,5.000
5,49.200,-0.01,-0.0001,-0.00010,5.000
5,49.400,0.00,-0.0001,-0.00010,5.000
5,49.533,-0.01,-0.0001,-0.00010,5.000
5,49.667,0.00,-0.0001,-0.00010,5.000
5,49.800,-0.01,-0.0001,-0.00010,5.000
5,49.933,-0.01,-0.0001,-0.00010,5.000
5,50.067,-0.01,-0.0001,-0.00010,5.000
5,50.200,0.00,-0.0001,-0.00010,5.000
6,50.533,0.00,0.0530,0.05300,6.000
6,50.667,0.00,0.1864,0.18637,6.000
6,50.800,0.00,0.3196,0.31960,6.000
6,50.933,0.00,0.4530,0.45303,6.000
6,51.067,0.00,0.5865,0.58647,6.000
6,51.200,0.00,0.7197,0.71970,6.000
6,51.333,0.00,0.8532,0.85317,6.000
6,51.467,0.00,0.9864,0.98640,6.000
6,51.600,0.00,1.1196,1.11960,6.000
6,51.733,0.00,1.2530,1.25303,6.000
6,51.867,0.00,1.3865,1.38650,6.000
6,52.000,0.00,1.5197,1.51970,6.000
6,52.133,0.01,1.6532,1.65317,6.000
6,52.267,0.06,1.7865,1.78650,6.000
6,52.400,0.23,1.9198,1.91980,6.000
6,52.533,0.53,2.0532,2.05317,6.000
6,52.667,0.95,2.1866,2.18660,6.000
6,52.800,1.51,2.3200,2.32000,6.000
6,52.933,2.22,2.4530,2.45303,6.000
6,53.067,3.10,2.5865,2.58647,6.000
6,53.200,4.16,2.7199,2.71990,6.000
6,53.400,5.43,2.8407,2.84070,6.000
6,53.533,3.84,2.7073,2.70730,6.000
6,53.667,2.69,2.5737,2.57373,6.000
6,53.800,1.82,2.4405,2.44050,6.000
6,53.933,1.16,2.3073,2.30730,6.000
6,54.067,0.67,2.1739,2.17387,6.000
6,54.200,0.32,2.0406,2.04060,6.000
6,54.333,0.10,1.9072,1.90717,6.000
6,54.467,0.02,1.7737,1.77373,6.000
6,54.600,0.00,1.6405,1.64050,6.000
6,54.733,0.00,1.5071,1.50710,6.000
6,54.867,0.00,1.3738,1.37380,6.000
6,55.000,0.00,1.2403,1.24030,6.000
6,55.133,0.00,1.1072,1.10717,6.000
6,55.267,0.00,0.9737,0.97370,6.000
6,55.400,0.00,0.8404,0.84040,6.000
6,55.533,0.00,0.7072,0.70723,6.000
6,55.667,0.00,0.5737,0.57370,6.000
6,55.800,0.00,0.4403,0.44030,6.000
6,55.933,0.00,0.3071,0.30710,6.000
6,56.067,0.00,0.1737,0.17367,6.000
6,56.200,0.00,0.0403,0.04030,6.000
6,56.467,0.00,-0.0002,-0.00020,6.000
6,56.600,0.00,-0.0002,-0.00020,6.000
6,56.733,0.00,-0.0002,-0.00020,6.000
6,56.867,0.00,-0.0002,-0.00020,6.000
6,57.000,0.00,-0.0002,-0.00020,6.000
6,57.133,0.00,-0.0002,-0.00020,6.000
6,57.267,0.00,-0.0002,-0.00020,6.000
6,57.400,0.00,-0.0002,-0.00020,6.000
6,57.533,0.00,-0.0002,-0.00020,6.000
6,57.667,0.00,-0.0002,-0.00020,6.000
6,57.800,0.00,-0.0002,-0.00020,6.000
6,57.933,0.00,-0.0002,-0.00020,6.000
6,58.067,0.00,-0.0002,-0.00020,6.000
6,58.200,0.00,-0.0002,-0.00020,6.000
6,58.333,0.00,-0.0002,-0.00020,6.000
6,58.467,0.00,-0.0001,-0.00010,6.000
6,58.600,0.00,-0.0001,-0.00010,6.000
6,58.733,0.00,-0.0001,-0.00010,6.000
6,58.867,0.00,-0.0001,-0.00010,6.000
6,59.000,0.00,-0.0001,-0.00010,6.000
6,59.133,0.00,-0.0001,-0.00010,6.000
6,59.267,0.00,-0.0001,-0.00010,6.000
6,59.533,0.00,-0.0001,-0.00010,6.000
6,59.667,0.00,-0.0001,-0.00010,6.000
6,59.800,0.00,-0.0001,-0.00010,6.000
6,59.933,0.00,-0.0001,-0.00010,6.000
6,60.067,0.00,-0.0001,-0.00010,6.000
6,60.200,0.00,-0.0001,-0.00010,6.000
6,60.333,0.00,-0.0001,-0.00010,6.000
7,60.600,-0.01,0.1195,0.11960,7.000
7,60.733,0.00,0.2530,0.25310,7.000
7,60.867,0.00,0.3864,0.38653,7.000
7,61.000,0.00,0.5197,0.51980,7.000
7,61.133,0.00,0.6530,0.65313,7.000
7,61.267,0.00,0.7865,0.78663,7.000
7,61.400,0.00,0.9197,0.91980,7.000
7,61.533,0.00,1.0530,1.05310,7.000
7,61.667,-0.01,1.1863,1.18640,7.000
7,61.800,-0.01,1.3198,1.31990,7.000
7,61.933,0.00,1.4531,1.45317,7.000
7,62.067,-0.01,1.5865,1.58660,7.000
7,62.200,0.02,1.7198,1.71990,7.000
7,62.333,0.12,1.8530,1.85313,7.000
7,62.467,0.36,1.9866,1.98670,7.000
7,62.600,0.72,2.1199,2.12000,7.000
7,62.733,1.21,2.2532,2.25330,7.000
7,62.867,1.85,2.3866,2.38670,7.000
7,63.000,2.64,2.5198,2.51990,7.000
7,63.133,3.61,2.6531,2.65317,7.000
7,63.267,4.76,2.7865,2.78657,7.000
7,63.467,4.56,2.7737,2.77380,7.000
7,63.600,3.22,2.6405,2.64060,7.000
7,63.733,2.22,2.5071,2.50720,7.000
7,63.867,1.46,2.3739,2.37397,7.000
7,64.000,0.89,2.2405,2.24060,7.000
7,64.133,0.48,2.1073,2.10743,7.000
7,64.267,0.19,1.9738,1.97387,7.000
7,64.400,0.04,1.8404,1.84050,7.000
7,64.533,-0.01,1.7072,1.70730,7.000
7,64.667,-0.01,1.5738,1.57393,7.000
7,64.800,-0.01,1.4405,1.44060,7.000
7,64.933,-0.01,1.3071,1.30723,7.000
7,65.067,-0.01,1.1737,1.17380,7.000
7,65.200,0.00,1.0402,1.04030,7.000
7,65.333,0.00,0.9072,0.90727,7.000
7,65.467,-0.01,0.7738,0.77390,7.000
7,65.600,-0.01,0.6403,0.64040,7.000
7,65.733,-0.01,0.5071,0.50720,7.000
7,65.867,0.00,0.3737,0.37383,7.000
7,66.000,-0.01,0.2403,0.24040,7.000
7,66.133,-0.01,0.1071,0.10717,7.000
7,66.267,0.00,-0.0262,-0.02613,7.000
7,66.467,-0.01,-0.0002,-0.00010,7.000
7,66.600,-0.01,-0.0002,-0.00010,7.000
7,66.733,0.00,-0.0002,-0.00010,7.000
7,66.867,-0.01,-0.0002,-0.00010,7.000
7,67.000,0.00,-0.0002,-0.00010,7.000
7,67.133,-0.01,-0.0002,-0.00010,7.000
7,67.267,-0.01,-0.0002,-0.00010,7.000
7,67.400,-0.01,-0.0002,-0.00010,7.000
7,67.533,-0.01,-0.0002,-0.00010,7.000
7,67.667,-0.01,-0.0002,-0.00010,7.000
7,67.800,-0.01,-0.0002,-0.00010,7.000
7,67.933,-0.01,-0.0002,-0.00010,7.000
7,68.067,-0.01,-0.0002,-0.00010,7.000
7,68.200,-0.01,-0.0002,-0.00010,7.000
7,68.333,-0.01,-0.0002,-0.00010,7.000
7,68.467,-0.01,-0.0002,-0.00010,7.000
7,68.600,-0.01,-0.0002,-0.00010,7.000
7,68.733,-0.01,-0.0002,-0.00010,7.000
7,68.867,0.00,-0.0002,-0.00010,7.000
7,69.000,-0.01,-0.0002,-0.00010,7.000
7,69.133,-0.01,-0.0002,-0.00010,7.000
7,69.267,-0.01,-0.0002,-0.00010,7.000
7,69.467,-0.01,-0.0002,-0.00010,7.000
7,69.600,0.00,-0.0001,0.00000,7.000
7,69.733,-0.01,-0.0001,0.00000,7.000
7,69.867,-0.01,-0.0001,0.00000,7.000
7,70.000,-0.01,-0.0001,0.00000,7.000
7,70.133,0.00,-0.0001,0.00000,7.000
7,70.267,0.00,-0.0001,0.00000,7.000
8,70.600,0.00,0.0596,0.05970,8.000
8,70.733,0.00,0.1930,0.19310,8.000
8,70.867,0.00,0.3263,0.32643,8.000
8,71.000,0.00,0.4598,0.45990,8.000
8,71.133,0.00,0.5931,0.59317,8.000
8,71.267,0.00,0.7264,0.72653,8.000
8,71.400,0.00,0.8599,0.86000,8.000
8,71.533,0.00,0.9931,0.99320,8.000
8,71.667,0.00,1.1263,1.12640,8.000
8,71.800,0.00,1.2598,1.25990,8.000
8,71.933,0.00,1.3932,1.39327,8.000
8,72.067,0.00,1.5263,1.52643,8.000
8,72.200,0.01,1.6599,1.66000,8.000
8,72.333,0.07,1.7931,1.79323,8.000
8,72.467,0.24,1.9264,1.92653,8.000
8,72.600,0.55,2.0599,2.06000,8.000
8,72.733,0.98,2.1933,2.19340,8.000
8,72.867,1.55,2.3266,2.32670,8.000
8,73.000,2.28,2.4597,2.45980,8.000
8,73.133,3.18,2.5931,2.59317,8.000
8,73.267,4.25,2.7264,2.72647,8.000
8,73.467,5.38,2.8337,2.83383,8.000
8,73.600,3.81,2.7006,2.70070,8.000
8,73.733,2.66,2.5670,2.56713,8.000
8,73.867,1.79,2.4339,2.43400,8.000
8,74.000,1.14,2.3007,2.30080,8.000
8,74.133,0.66,2.1671,2.16723,8.000
8,74.267,0.30,2.0340,2.03407,8.000
8,74.400,0.09,1.9005,1.90060,8.000
8,74.533,0.01,1.7670,1.76713,8.000
8,74.667,0.00,1.6339,1.63400,8.000
8,74.800,-0.01,1.5004,1.50050,8.000
8,74.933,0.00,1.3670,1.36713,8.000
8,75.067,0.00,1.2337,1.23383,8.000
8,75.200,0.00,1.1004,1.10050,8.000
8,75.333,0.00,0.9669,0.96703,8.000
8,75.467,0.00,0.8338,0.83390,8.000
8,75.600,0.00,0.7006,0.70070,8.000
8,75.733,0.00,0.5669,0.56703,8.000
8,75.867,-0.01,0.4338,0.43390,8.000
8,76.000,0.00,0.3004,0.30050,8.000
8,76.133,0.00,0.1670,0.16707,8.000
8,76.267,0.00,0.0336,0.03373,8.000
8,76.533,0.00,-0.0002,-0.00010,8.000
8,76.667,0.00,-0.0002,-0.00010,8.000
8,76.800,0.00,-0.0002,-0.00010,8.000
8,76.933,0.00,-0.0002,-0.00010,8.000
8,77.067,0.00,-0.0002,-0.00010,8.000
8,77.200,0.00,-0.0002,-0.00010,8.000
8,77.333,0.00,-0.0002,-0.00010,8.000
8,77.467,0.00,-0.0002,-0.00010,8.000
8,77.600,0.00,-0.0002,-0.00010,8.000
8,77.733,0.00,-0.0002,-0.00010,8.000
8,77.867,0.00,-0.0002,-0.00010,8.000
8,78.000,0.00,-0.0002,-0.00010,8.000
8,78.133,0.00,-0.0002,-0.00010,8.000
8,78.267,0.00,-0.0002,-0.00010,8.000
8,78.400,0.00,-0.0002,-0.00010,8.000
8,78.533,0.00,-0.0002,-0.00010,8.000
8,78.667,0.00,-0.0002,-0.00010,8.000
8,78.800,0.00,-0.0002,-0.00010,8.000
8,78.933,0.00,-0.0002,-0.00010,8.000
8,79.067,0.00,-0.0001,0.00000,8.000
8,79.200,0.00,-0.0001,0.00000,8.000
8,79.333,0.00,-0.0001,0.00000,8.000
8,79.533,0.00,-0.0001,0.00000,8.000
8,79.667,0.00,-0.0001,0.00000,8.000
8,79.800,0.00,-0.0001,0.00000,8.000
8,79.933,0.00,-0.0001,0.00000,8.000
8,80.067,0.00,-0.0001,0.00000,8.000
8,80.200,0.00,-0.0001,0.00000,8.000
8,80.333,0.00,-0.0001,0.00000,8.000
9,80.667,0.01,0.0862,0.08623,9.000
9,80.800,0.00,0.2196,0.21960,9.000
9,80.933,0.00,0.3531,0.35313,9.000
9,81.067,0.00,0.4863,0.48633,9.000
9,81.200,0.00,0.6196,0.61960,9.000
9,81.333,0.00,0.7532,0.75317,9.000
9,81.467,0.00,0.8865,0.88647,9.000
9,81.600,0.00,1.0198,1.01980,9.000
9,81.733,0.00,1.1531,1.15307,9.000
9,81.867,0.00,1.2864,1.28637,9.000
9,82.000,0.01,1.4198,1.41980,9.000
9,82.133,0.00,1.5532,1.55320,9.000
9,82.267,0.02,1.6865,1.68647,9.000
9,82.400,0.10,1.8198,1.81980,9.000
9,82.533,0.30,1.9532,1.95320,9.000
9,82.667,0.63,2.0865,2.08647,9.000
9,82.800,1.09,2.2199,2.21990,9.000
9,82.933,1.69,2.3533,2.35333,9.000
9,83.067,2.46,2.4863,2.48633,9.000
9,83.200,3.39,2.6197,2.61970,9.000
9,83.333,4.51,2.7532,2.75317,9.000
9,83.533,5.03,2.8071,2.80707,9.000
9,83.667,3.56,2.6739,2.67393,9.000
9,83.800,2.47,2.5405,2.54050,9.000
9,83.933,1.65,2.4072,2.40720,9.000
9,84.067,1.03,2.2740,2.27397,9.000
9,84.200,0.58,2.1406,2.14060,9.000
9,84.333,0.26,2.0072,2.00720,9.000
9,84.467,0.07,1.8738,1.87383,9.000
9,84.600,0.01,1.7405,1.74050,9.000
9,84.733,0.00,1.6071,1.60707,9.000
9,84.867,0.00,1.4738,1.47380,9.000
9,85.000,0.00,1.3406,1.34060,9.000
9,85.133,0.00,1.2069,1.20690,9.000
9,85.267,0.00,1.0737,1.07373,9.000
9,85.400,0.00,0.9405,0.94050,9.000
9,85.533,0.00,0.8071,0.80713,9.000
9,85.667,0.01,0.6738,0.67380,9.000
9,85.800,0.00,0.5404,0.54040,9.000
9,85.933,0.01,0.4070,0.40697,9.000
9,86.067,0.01,0.2737,0.27373,9.000
9,86.200,0.00,0.1405,0.14050,9.000
9,86.333,0.00,0.0070,0.00700,9.000
9,86.533,0.00,0.0000,-0.00003,9.000
9,86.667,0.00,-0.0002,-0.00020,9.000
9,86.800,0.00,-0.0002,-0.00020,9.000
9,86.933,0.01,-0.0002,-0.00020,9.000
9,87.067,0.01,-0.0002,-0.00020,9.000
9,87.200,0.00,-0.0002,-0.00020,9.000
9,87.333,0.01,-0.0002,-0.00020,9.000
9,87.467,0.00,-0.0002,-0.00020,9.000
9,87.600,0.00,-0.0002,-0.00020,9.000
9,87.733,0.00,-0.0002,-0.00020,9.000
9,87.867,0.00,-0.0002,-0.00020,9.000
9,88.000,0.00,-0.0002,-0.00020,9.000
9,88.133,0.00,-0.0002,-0.00020,9.000
9,88.267,0.00,-0.0002,-0.00020,9.000
9,88.400,0.00,-0.0002,-0.00020,9.000
9,88.533,0.00,-0.0002,-0.00020,9.000
9,88.667,0.00,-0.0002,-0.00020,9.000
9,88.800,0.00,-0.0002,-0.00020,9.000
9,88.933,0.00,-0.0002,-0.00020,9.000
9,89.067,0.00,-0.0002,-0.00020,9.000
9,89.200,0.00,-0.0001,-0.00010,9.000
9,89.333,0.00,-0.0001,-0.00010,9.000
9,89.533,0.00,-0.0001,-0.00010,9.000
9,89.667,0.01,-0.0001,-0.00010,9.000
9,89.800,0.00,-0.0001,-0.00010,9.000
9,89.933,0.00,-0.0001,-0.00010,9.000
9,90.067,0.00,-0.0001,-0.00010,9.000
9,90.200,0.00,-0.0001,-0.00010,9.000
9,90.333,0.00,-0.0001,-0.00010,9.000
9,90.467,0.00,-0.0001,-0.00010,9.000
10,90.733,0.01,0.1229,0.12290,10.000
10,90.867,0.01,0.2564,0.25643,10.000
10,91.000,0.01,0.3899,0.38990,10.000
10,91.133,0.01,0.5230,0.52300,10.000
10,91.267,0.01,0.6564,0.65643,10.000
10,91.400,0.01,0.7900,0.79000,10.000
10,91.533,0.01,0.9231,0.92307,10.000
10,91.667,0.01,1.0564,1.05640,10.000
10,91.800,0.01,1.1897,1.18970,10.000
10,91.933,0.01,1.3230,1.32303,10.000
10,92.067,0.01,1.4564,1.45643,10.000
10,92.200,0.01,1.5899,1.58990,10.000
10,92.333,0.04,1.7232,1.72320,10.000
10,92.467,0.15,1.8563,1.85633,10.000
10,92.600,0.38,1.9899,1.98990,10.000
10,92.733,0.75,2.1233,2.12327,10.000
10,92.867,1.24,2.2565,2.25653,10.000
10,93.000,1.89,2.3898,2.38980,10.000
10,93.133,2.71,2.5231,2.52307,10.000
10,93.267,3.69,2.6564,2.65637,10.000
10,93.400,4.85,2.7899,2.78990,10.000
10,93.600,4.58,2.7703,2.77030,10.000
10,93.733,3.24,2.6373,2.63727,10.000
10,93.867,2.24,2.5038,2.50377,10.000
10,94.000,1.47,2.3705,2.37050,10.000
10,94.133,0.90,2.2373,2.23730,10.000
10,94.267,0.49,2.1039,2.10390,10.000
10,94.400,0.20,1.9705,1.97050,10.000
10,94.533,0.05,1.8371,1.83713,10.000
10,94.667,0.01,1.7039,1.70393,10.000
10,94.800,0.01,1.5704,1.57040,10.000
10,94.933,0.01,1.4371,1.43713,10.000
10,95.067,0.01,1.3038,1.30383,10.000
10,95.200,0.01,1.1702,1.17020,10.000
10,95.333,0.01,1.0370,1.03703,10.000
10,95.467,0.01,0.9038,0.90377,10.000
10,95.600,0.01,0.7704,0.77040,10.000
10,95.733,0.01,0.6371,0.63707,10.000
10,95.867,0.01,0.5038,0.50383,10.000
10,96.000,0.01,0.3703,0.37030,10.000
10,96.133,0.01,0.2371,0.23710,10.000
10,96.267,0.01,0.1038,0.10377,10.000
10,96.400,0.01,-0.0297,-0.02970,10.000
10,96.600,0.01,-0.0002,-0.00020,10.000
10,96.733,0.01,-0.0002,-0.00020,10.000
10,96.867,0.01,-0.0002,-0.00020,10.000
10,97.000,0.01,-0.0002,-0.00020,10.000
10,97.133,0.01,-0.0002,-0.00020,10.000
10,97.267,0.01,-0.0002,-0.00020,10.000
10,97.400,0.01,-0.0002,-0.00020,10.000
10,97.533,0.00,-0.0002,-0.00020,10.000
10,97.667,0.01,-0.0002,-0.00020,10.000
10,97.800,0.01,-0.0002,-0.00020,10.000
10,97.933,0.01,-0.0002,-0.00020,10.000
10,98.067,0.01,-0.0002,-0.00020,10.000
10,98.200,0.01,-0.0002,-0.00020,10.000
10,98.333,0.01,-0.0002,-0.00020,10.000
10,98.467,0.01,-0.0002,-0.00020,10.000
10,98.600,0.01,-0.0002,-0.00020,10.000
10,98.733,0.01,-0.0002,-0.00020,10.000
10,98.867,0.01,-0.0002,-0.00020,10.000
10,99.000,0.00,-0.0002,-0.00020,10.000
10,99.133,0.01,-0.0002,-0.00020,10.000
10,99.267,0.01,-0.0001,-0.00010,10.000
10,99.400,0.01,-0.0001,-0.00010,10.000
10,99.600,0.01,-0.0001,-0.00010,10.000
10,99.733,0.01,-0.0001,-0.00010,10.000
10,99.867,0.01,-0.0001,-0.00010,10.000
10,100.000,0.01,-0.0001,-0.00010,10.000
10,100.133,0.01,-0.0001,-0.00010,10.000
10,100.267,0.01,-0.0001,-0.00010,10.000
10,100.400,0.01,-0.0001,-0.00010,10.000
10,100.467,0.01,-0.0001,-0.00010,10.000