File: calibDATA_loadcell/date_02:15:2018/Instron_02.15.2018/2_10N_0__1mm.s_0_0_hold.txt
""
"Test Method","Radhen_Load_Cntrl_Cmprsn_250N_12-7.msm"
"Sample I. D.","Sample1.mss"
"Specimen Number","32"

"TheCycle_Output ()","_Time (s)","_Load (N)","_Extension (mm)","RealTimeDepth (mm)","CycleNumber ()"

1,0.267,0.00,0.0591,0.05910,1.000
1,0.333,0.00,0.1257,0.12570,1.000
1,0.400,0.00,0.1925,0.19250,1.000
1,0.467,0.00,0.2592,0.25917,1.000
1,0.533,0.00,0.3258,0.32577,1.000
1,0.600,0.00,0.3927,0.39270,1.000
1,0.667,0.00,0.4593,0.45930,1.000
1,0.733,0.00,0.5259,0.52590,1.000
1,0.800,0.00,0.5927,0.59270,1.000
1,0.867,0.00,0.6592,0.65923,1.000
1,0.933,0.00,0.7258,0.72583,1.000
1,1.000,0.00,0.7927,0.79270,1.000
1,1.067,0.00,0.8593,0.85930,1.000
1,1.133,0.00,0.9258,0.92583,1.000
1,1.200,0.00,0.9927,0.99270,1.000
1,1.267,0.00,1.0593,1.05930,1.000
1,1.333,0.00,1.1259,1.12593,1.000
1,1.400,0.00,1.1927,1.19270,1.000
1,1.467,0.00,1.2594,1.25940,1.000
1,1.533,0.00,1.3259,1.32593,1.000
1,1.600,0.00,1.3926,1.39260,1.000
1,1.667,0.00,1.4593,1.45930,1.000
1,1.733,0.00,1.5259,1.52587,1.000
1,1.800,0.00,1.5927,1.59270,1.000
1,1.867,0.00,1.6593,1.65927,1.000
1,1.933,0.00,1.7259,1.72593,1.000
1,2.000,0.00,1.7927,1.79270,1.000
1,2.067,0.00,1.8593,1.85927,1.000
1,2.133,0.00,1.9260,1.92600,1.000
1,2.200,0.00,1.9928,1.99280,1.000
1,2.267,0.00,2.0594,2.05943,1.000
1,2.333,0.00,2.1260,2.12603,1.000
1,2.400,0.00,2.1929,2.19290,1.000
1,2.467,0.00,2.2593,2.25933,1.000
1,2.533,0.00,2.3259,2.32593,1.000
1,2.600,0.00,2.3928,2.39280,1.000
1,2.667,0.00,2.4594,2.45940,1.000
1,2.733,0.00,2.5259,2.52593,1.000
1,2.800,0.00,2.5928,2.59280,1.000
1,2.867,0.00,2.6593,2.65930,1.000
1,2.933,0.00,2.7260,2.72603,1.000
1,3.000,0.00,2.7929,2.79290,1.000
1,3.067,0.00,2.8593,2.85930,1.000
1,3.133,0.00,2.9260,2.92597,1.000
1,3.200,0.00,2.9928,2.99280,1.000
1,3.267,0.00,3.0594,3.05943,1.000
1,3.333,0.00,3.1260,3.12603,1.000
1,3.400,0.00,3.1929,3.19290,1.000
1,3.467,0.00,3.2594,3.25943,1.000
1,3.533,0.00,3.3261,3.32610,1.000
1,3.600,-0.01,3.3928,3.39280,1.000
1,3.667,-0.01,3.4594,3.45940,1.000
1,3.733,0.00,3.5261,3.52607,1.000
1,3.800,0.00,3.5928,3.59280,1.000
1,3.867,0.00,3.6595,3.65950,1.000
1,3.933,0.00,3.7262,3.72620,1.000
1,4.000,0.00,3.7928,3.79280,1.000
1,4.067,0.00,3.8593,3.85933,1.000
1,4.133,0.00,3.9260,3.92600,1.000
1,4.200,0.01,3.9927,3.99270,1.000
1,4.267,0.01,4.0593,4.05933,1.000
1,4.333,0.01,4.1260,4.12600,1.000
1,4.400,0.01,4.1928,4.19280,1.000
1,4.467,0.01,4.2594,4.25943,1.000
1,4.533,0.02,4.3261,4.32610,1.000
1,4.600,0.02,4.3929,4.39290,1.000
1,4.667,0.04,4.4594,4.45943,1.000
1,4.733,0.07,4.5262,4.52620,1.000
1,4.800,0.13,4.5930,4.59300,1.000
1,4.867,0.20,4.6594,4.65943,1.000
1,4.933,0.29,4.7261,4.72613,1.000
1,5.000,0.41,4.7929,4.79290,1.000
1,5.067,0.56,4.8594,4.85943,1.000
1,5.133,0.74,4.9263,4.92627,1.000
1,5.200,0.94,4.9929,4.99290,1.000
1,5.267,1.18,5.0595,5.05953,1.000
1,5.333,1.44,5.1263,5.12627,1.000
1,5.400,1.72,5.1930,5.19300,1.000
1,5.467,2.05,5.2595,5.25947,1.000
1,5.533,2.40,5.3262,5.32617,1.000
1,5.600,2.78,5.3928,5.39280,1.000
1,5.667,3.20,5.4594,5.45943,1.000
1,5.733,3.64,5.5263,5.52627,1.000
1,5.800,4.12,5.5930,5.59300,1.000
1,5.867,4.64,5.6597,5.65973,1.000
1,5.933,5.19,5.7263,5.72630,1.000
1,6.000,5.78,5.7928,5.79280,1.000
1,6.067,6.41,5.8594,5.85937,1.000
1,6.133,7.06,5.9262,5.92620,1.000
1,6.200,7.77,5.9929,5.99290,1.000
1,6.267,8.53,6.0594,6.05937,1.000
1,6.333,9.31,6.1261,6.12613,1.000
1,6.400,10.18,6.1929,6.19290,1.000
1,6.533,10.43,6.2229,6.22290,1.000
1,6.600,10.30,6.2229,6.22290,1.000
1,6.667,10.19,6.2229,6.22290,1.000
1,6.733,10.12,6.2229,6.22290,1.000
1,6.800,10.06,6.2229,6.22290,1.000
1,6.867,10.01,6.2229,6.22290,1.000
1,6.933,9.97,6.2229,6.22290,1.000
1,7.000,9.93,6.2229,6.22290,1.000
1,7.067,9.90,6.2229,6.22290,1.000
1,7.133,9.86,6.2229,6.22290,1.000
1,7.200,9.83,6.2229,6.22290,1.000
1,7.267,9.81,6.2229,6.22290,1.000
1,7.333,9.79,6.2229,6.22290,1.000
1,7.400,9.76,6.2229,6.22290,1.000
1,7.467,9.74,6.2229,6.22290,1.000
1,7.533,9.73,6.2230,6.22300,1.000
1,7.600,9.71,6.2230,6.22300,1.000
1,7.667,9.70,6.2230,6.22300,1.000
1,7.733,9.68,6.2230,6.22300,1.000
1,7.800,9.67,6.2230,6.22300,1.000
1,7.867,9.65,6.2230,6.22300,1.000
1,7.933,9.64,6.2230,6.22300,1.000
1,8.000,9.63,6.2230,6.22300,1.000
1,8.067,9.61,6.2230,6.22300,1.000
1,8.133,9.60,6.2230,6.22300,1.000
1,8.200,9.59,6.2230,6.22300,1.000
1,8.267,9.58,6.2230,6.22300,1.000
1,8.333,9.57,6.2230,6.22300,1.000
1,8.400,9.57,6.2230,6.22300,1.000
1,8.467,9.55,6.2230,6.22300,1.000
1,8.533,9.55,6.2230,6.22300,1.000
1,8.600,9.53,6.2230,6.22300,1.000
1,8.667,9.53,6.2230,6.22300,1.000
1,8.733,9.52,6.2230,6.22300,1.000
1,8.800,9.52,6.2230,6.22300,1.000
1,8.867,9.51,6.2230,6.22300,1.000
1,8.933,9.50,6.2230,6.22300,1.000
1,9.000,9.49,6.2230,6.22300,1.000
1,9.067,9.49,6.2230,6.22300,1.000
1,9.133,9.48,6.2230,6.22300,1.000
1,9.200,9.48,6.2230,6.22300,1.000
1,9.267,9.47,6.2230,6.22300,1.000
1,9.333,9.46,6.2230,6.22300,1.000
1,9.400,9.46,6.2230,6.22300,1.000
1,9.467,9.45,6.2230,6.22300,1.000
1,9.533,9.45,6.2230,6.22300,1.000
1,9.600,9.44,6.2230,6.22300,1.000
1,9.667,9.43,6.2230,6.22300,1.000
1,9.733,9.43,6.2230,6.22300,1.000
1,9.800,9.42,6.2230,6.22300,1.000
1,9.867,9.42,6.2230,6.22300,1.000
1,9.933,9.41,6.2230,6.22300,1.000
1,10.000,9.41,6.2230,6.22300,1.000
1,10.067,9.40,6.2230,6.22300,1.000
1,10.133,9.40,6.2230,6.22300,1.000
1,10.200,9.40,6.2230,6.22300,1.000
1,10.267,9.39,6.2230,6.22300,1.000