File: calibDATA_loadcell/date_02:15:2018/Instron_02.15.2018/2_1N_0__1mm.s_0_0_hold.txt
""
"Test Method","Radhen_Load_Cntrl_Cmprsn_250N_12-7.msm"
"Sample I. D.","Sample1.mss"
"Specimen Number","27"

"TheCycle_Output ()","_Time (s)","_Load (N)","_Extension (mm)","RealTimeDepth (mm)","CycleNumber ()"

1,0.333,0.01,0.1067,0.10673,1.000
1,0.400,0.01,0.1734,0.17340,1.000
1,0.467,0.01,0.2401,0.24010,1.000
1,0.533,0.01,0.3068,0.30683,1.000
1,0.600,0.01,0.3735,0.37350,1.000
1,0.667,0.02,0.4402,0.44017,1.000
1,0.733,0.01,0.5070,0.50700,1.000
1,0.800,0.02,0.5736,0.57360,1.000
1,0.867,0.01,0.6401,0.64013,1.000
1,0.933,0.01,0.7070,0.70697,1.000
1,1.000,0.02,0.7736,0.77360,1.000
1,1.067,0.01,0.8403,0.84027,1.000
1,1.133,0.01,0.9070,0.90700,1.000
1,1.200,0.01,0.9735,0.97350,1.000
1,1.267,0.01,1.0402,1.04020,1.000
1,1.333,0.01,1.1071,1.10710,1.000
1,1.400,0.00,1.1736,1.17360,1.000
1,1.467,0.01,1.2403,1.24033,1.000
1,1.533,0.00,1.3071,1.30707,1.000
1,1.600,0.01,1.3736,1.37360,1.000
1,1.667,0.02,1.4402,1.44020,1.000
1,1.733,0.01,1.5069,1.50693,1.000
1,1.800,0.01,1.5736,1.57360,1.000
1,1.867,0.01,1.6402,1.64017,1.000
1,1.933,0.02,1.7070,1.70697,1.000
1,2.000,0.01,1.7736,1.77360,1.000
1,2.067,0.01,1.8403,1.84027,1.000
1,2.133,0.01,1.9070,1.90697,1.000
1,2.200,0.03,1.9736,1.97360,1.000
1,2.267,0.01,2.0404,2.04040,1.000
1,2.333,0.01,2.1071,2.10710,1.000
1,2.400,0.02,2.1736,2.17360,1.000
1,2.467,0.01,2.2402,2.24023,1.000
1,2.533,0.02,2.3070,2.30700,1.000
1,2.600,0.01,2.3737,2.37370,1.000
1,2.667,0.01,2.4404,2.44040,1.000
1,2.733,0.01,2.5071,2.50710,1.000
1,2.800,0.01,2.5735,2.57350,1.000
1,2.867,0.01,2.6403,2.64027,1.000
1,2.933,0.02,2.7070,2.70703,1.000
1,3.000,0.01,2.7737,2.77370,1.000
1,3.067,0.01,2.8404,2.84037,1.000
1,3.133,0.01,2.9070,2.90703,1.000
1,3.200,0.01,2.9737,2.97370,1.000
1,3.267,0.02,3.0404,3.04037,1.000
1,3.333,0.01,3.1071,3.10710,1.000
1,3.400,0.02,3.1736,3.17360,1.000
1,3.467,0.01,3.2404,3.24043,1.000
1,3.533,0.01,3.3071,3.30710,1.000
1,3.600,0.02,3.3737,3.37370,1.000
1,3.667,0.01,3.4405,3.44047,1.000
1,3.733,0.01,3.5071,3.50713,1.000
1,3.800,0.01,3.5737,3.57370,1.000
1,3.867,0.01,3.6404,3.64043,1.000
1,3.933,0.02,3.7073,3.70730,1.000
1,4.000,0.02,3.7738,3.77380,1.000
1,4.067,0.02,3.8404,3.84040,1.000
1,4.133,0.02,3.9071,3.90707,1.000
1,4.200,0.02,3.9736,3.97360,1.000
1,4.267,0.02,4.0405,4.04047,1.000
1,4.333,0.02,4.1071,4.10713,1.000
1,4.400,0.02,4.1737,4.17370,1.000
1,4.467,0.03,4.2405,4.24053,1.000
1,4.533,0.04,4.3071,4.30713,1.000
1,4.600,0.04,4.3737,4.37370,1.000
1,4.667,0.05,4.4405,4.44047,1.000
1,4.733,0.08,4.5072,4.50723,1.000
1,4.800,0.13,4.5738,4.57380,1.000
1,4.867,0.19,4.6405,4.64047,1.000
1,4.933,0.28,4.7072,4.70717,1.000
1,5.000,0.38,4.7736,4.77360,1.000
1,5.067,0.53,4.8405,4.84047,1.000
1,5.133,0.70,4.9072,4.90717,1.000
1,5.200,0.88,4.9738,4.97380,1.000
1,5.333,1.20,5.0540,5.05397,1.000
1,5.400,1.18,5.0540,5.05400,1.000
1,5.467,1.16,5.0540,5.05400,1.000
1,5.533,1.15,5.0540,5.05400,1.000
1,5.600,1.16,5.0540,5.05400,1.000
1,5.667,1.13,5.0540,5.05400,1.000
1,5.733,1.14,5.0540,5.05400,1.000
1,5.800,1.14,5.0540,5.05400,1.000
1,5.867,1.12,5.0540,5.05400,1.000
1,5.933,1.12,5.0540,5.05400,1.000
1,6.000,1.13,5.0540,5.05400,1.000
1,6.067,1.12,5.0540,5.05400,1.000
1,6.133,1.12,5.0540,5.05400,1.000
1,6.200,1.12,5.0540,5.05400,1.000
1,6.267,1.12,5.0540,5.05400,1.000
1,6.333,1.12,5.0540,5.05400,1.000
1,6.400,1.10,5.0540,5.05400,1.000
1,6.467,1.11,5.0540,5.05400,1.000
1,6.533,1.11,5.0540,5.05400,1.000
1,6.600,1.10,5.0540,5.05400,1.000
1,6.667,1.10,5.0540,5.05400,1.000
1,6.733,1.09,5.0540,5.05400,1.000
1,6.800,1.10,5.0540,5.05400,1.000
1,6.867,1.10,5.0540,5.05400,1.000
1,6.933,1.10,5.0540,5.05400,1.000
1,7.000,1.10,5.0540,5.05400,1.000
1,7.067,1.09,5.0540,5.05400,1.000
1,7.133,1.10,5.0540,5.05400,1.000
1,7.200,1.09,5.0540,5.05400,1.000
1,7.267,1.10,5.0540,5.05400,1.000
1,7.333,1.10,5.0540,5.05400,1.000
1,7.400,1.09,5.0540,5.05400,1.000
1,7.467,1.09,5.0540,5.05400,1.000
1,7.533,1.09,5.0540,5.05400,1.000
1,7.600,1.09,5.0540,5.05400,1.000
1,7.667,1.09,5.0540,5.05400,1.000
1,7.733,1.09,5.0540,5.05400,1.000
1,7.800,1.09,5.0540,5.05400,1.000
1,7.867,1.08,5.0540,5.05400,1.000
1,7.933,1.09,5.0540,5.05400,1.000
1,8.000,1.09,5.0540,5.05400,1.000
1,8.067,1.09,5.0540,5.05400,1.000
1,8.133,1.08,5.0540,5.05400,1.000
1,8.200,1.09,5.0540,5.05400,1.000
1,8.267,1.08,5.0540,5.05400,1.000
1,8.333,1.09,5.0540,5.05400,1.000
1,8.400,1.09,5.0540,5.05400,1.000
1,8.467,1.08,5.0540,5.05400,1.000
1,8.533,1.08,5.0540,5.05400,1.000
1,8.600,1.08,5.0540,5.05400,1.000
1,8.667,1.09,5.0540,5.05400,1.000
1,8.733,1.08,5.0540,5.05400,1.000
1,8.800,1.07,5.0540,5.05400,1.000
1,8.867,1.09,5.0540,5.05400,1.000
1,8.933,1.08,5.0540,5.05400,1.000
1,9.000,1.08,5.0540,5.05400,1.000
1,9.067,1.08,5.0540,5.05400,1.000
1,9.133,1.08,5.0540,5.05400,1.000
1,9.200,1.09,5.0540,5.05400,1.000
1,9.267,1.08,5.0540,5.05400,1.000
1,9.333,1.08,5.0540,5.05400,1.000
1,9.400,1.08,5.0540,5.05400,1.000
1,9.467,1.08,5.0540,5.05400,1.000
1,9.533,1.08,5.0540,5.05400,1.000
1,9.600,1.09,5.0540,5.05400,1.000
1,9.667,1.08,5.0540,5.05400,1.000
1,9.733,1.08,5.0540,5.05400,1.000
1,9.800,1.07,5.0540,5.05400,1.000
1,9.867,1.08,5.0540,5.05400,1.000
1,9.933,1.08,5.0540,5.05400,1.000
1,10.000,1.07,5.0540,5.05400,1.000
1,10.067,1.08,5.0540,5.05400,1.000
1,10.133,1.07,5.0540,5.05400,1.000
1,10.200,1.07,5.0540,5.05400,1.000
1,10.267,1.07,5.0540,5.05400,1.000