File: calibDATA_loadcell/date_02:15:2018/Instron_02.15.2018/2_20N_0__3mm.s_0_0_orientation.txt
""
"Test Method","Radhen_Load_Cntrl_Cmprsn_250N_12-7.msm"
"Sample I. D.","Sample1.mss"
"Specimen Number","46"

"TheCycle_Output ()","_Time (s)","_Load (N)","_Extension (mm)","RealTimeDepth (mm)","CycleNumber ()"

1,0.333,0.00,0.1863,0.18627,1.000
1,0.400,-0.01,0.3866,0.38660,1.000
1,0.467,-0.01,0.5865,0.58653,1.000
1,0.533,0.00,0.7866,0.78663,1.000
1,0.600,0.00,0.9866,0.98660,1.000
1,0.667,0.00,1.1867,1.18670,1.000
1,0.733,0.00,1.3867,1.38667,1.000
1,0.800,-0.01,1.5866,1.58660,1.000
1,0.867,0.00,1.7866,1.78663,1.000
1,0.933,0.00,1.9866,1.98657,1.000
1,1.000,0.01,2.1866,2.18660,1.000
1,1.067,0.02,2.3867,2.38667,1.000
1,1.133,0.10,2.5868,2.58677,1.000
1,1.200,0.37,2.7866,2.78660,1.000
1,1.267,0.90,2.9868,2.98680,1.000
1,1.333,1.69,3.1868,3.18680,1.000
1,1.400,2.77,3.3866,3.38660,1.000
1,1.467,4.15,3.5867,3.58670,1.000
1,1.533,5.88,3.7867,3.78670,1.000
1,1.600,7.99,3.9867,3.98670,1.000
1,1.667,10.55,4.1867,4.18667,1.000
1,1.733,13.60,4.3868,4.38677,1.000
1,1.800,17.24,4.5866,4.58660,1.000
1,2.000,27.28,4.9983,4.99830,1.000
1,2.067,24.60,4.9380,4.93803,1.000
1,2.133,18.83,4.7695,4.76953,1.000
1,2.200,13.41,4.5697,4.56970,1.000
1,2.267,9.61,4.3696,4.36960,1.000
1,2.333,6.84,4.1696,4.16963,1.000
1,2.400,4.84,3.9697,3.96970,1.000
1,2.467,3.38,3.7695,3.76953,1.000
1,2.533,2.27,3.5696,3.56960,1.000
1,2.600,1.42,3.3696,3.36960,1.000
1,2.667,0.79,3.1697,3.16967,1.000
1,2.733,0.35,2.9697,2.96970,1.000
1,2.800,0.08,2.7696,2.76960,1.000
1,2.867,-0.01,2.5696,2.56957,1.000
1,2.933,0.00,2.3696,2.36960,1.000
1,3.000,0.00,2.1696,2.16960,1.000
1,3.067,0.00,1.9695,1.96953,1.000
1,3.133,-0.01,1.7695,1.76950,1.000
1,3.200,0.00,1.5696,1.56960,1.000
1,3.267,0.00,1.3695,1.36947,1.000
1,3.333,0.00,1.1695,1.16950,1.000
1,3.400,0.00,0.9695,0.96950,1.000
1,3.467,0.00,0.7696,0.76963,1.000
1,3.533,0.00,0.5694,0.56940,1.000
1,3.600,0.00,0.3695,0.36950,1.000
1,3.667,0.00,0.1694,0.16937,1.000
1,3.867,0.00,-0.2518,-0.25180,1.000
1,3.933,0.00,-0.1974,-0.19743,1.000
1,4.000,-0.01,-0.0571,-0.05710,1.000
1,4.067,-0.01,0.0000,-0.00003,1.000
1,4.133,0.00,-0.0002,-0.00020,1.000
1,4.200,0.00,-0.0002,-0.00020,1.000
1,4.267,0.00,-0.0002,-0.00020,1.000
1,4.333,-0.01,-0.0002,-0.00020,1.000
1,4.400,0.00,-0.0002,-0.00020,1.000
1,4.467,0.00,-0.0002,-0.00020,1.000
1,4.533,0.00,-0.0002,-0.00020,1.000
1,4.600,0.00,-0.0002,-0.00020,1.000
1,4.667,0.00,-0.0002,-0.00020,1.000
1,4.733,0.00,-0.0002,-0.00020,1.000
1,4.800,0.00,-0.0002,-0.00020,1.000
1,4.867,0.00,-0.0002,-0.00020,1.000
1,4.933,0.00,-0.0002,-0.00020,1.000
1,5.000,0.00,-0.0001,-0.00010,1.000
1,5.067,0.00,-0.0001,-0.00010,1.000
1,5.133,-0.01,-0.0001,-0.00010,1.000
1,5.200,0.00,-0.0001,-0.00010,1.000
1,5.267,0.00,-0.0001,-0.00010,1.000
1,5.333,0.00,-0.0001,-0.00010,1.000
1,5.400,0.00,-0.0001,-0.00010,1.000
1,5.467,0.00,-0.0001,-0.00010,1.000
1,5.533,0.00,-0.0001,-0.00010,1.000
1,5.600,0.00,-0.0001,-0.00010,1.000
1,5.667,0.00,-0.0001,-0.00010,1.000
1,5.733,0.00,-0.0001,-0.00010,1.000
1,5.800,0.00,-0.0001,-0.00010,1.000
1,5.867,0.00,-0.0001,-0.00010,1.000
1,5.933,0.00,-0.0001,-0.00010,1.000
1,6.000,0.00,-0.0001,-0.00010,1.000
1,6.067,0.00,-0.0001,-0.00010,1.000
1,6.133,0.00,-0.0001,-0.00010,1.000
1,6.200,0.00,-0.0001,-0.00010,1.000
1,6.267,0.00,-0.0001,-0.00010,1.000
1,6.333,0.00,-0.0001,-0.00010,1.000
1,6.400,0.00,-0.0001,-0.00010,1.000
1,6.467,0.00,-0.0001,-0.00010,1.000
1,6.533,0.00,-0.0001,-0.00010,1.000
1,6.600,0.00,-0.0001,-0.00010,1.000
1,6.667,0.00,-0.0001,-0.00010,1.000
1,6.733,0.00,-0.0001,-0.00010,1.000
1,6.800,0.00,-0.0001,-0.00010,1.000
1,6.933,0.00,-0.0001,-0.00010,1.000
2,7.200,0.01,0.1217,0.12170,2.000
2,7.267,0.01,0.3166,0.31660,2.000
2,7.333,0.01,0.5165,0.51653,2.000
2,7.400,0.01,0.7167,0.71670,2.000
2,7.467,0.00,0.9166,0.91660,2.000
2,7.533,0.00,1.1167,1.11667,2.000
2,7.600,0.01,1.3167,1.31670,2.000
2,7.667,0.01,1.5166,1.51663,2.000
2,7.733,0.01,1.7167,1.71667,2.000
2,7.800,0.01,1.9166,1.91660,2.000
2,7.867,0.02,2.1167,2.11667,2.000
2,7.933,0.02,2.3166,2.31660,2.000
2,8.000,0.05,2.5166,2.51660,2.000
2,8.067,0.24,2.7167,2.71670,2.000
2,8.133,0.65,2.9167,2.91673,2.000
2,8.200,1.33,3.1168,3.11680,2.000
2,8.267,2.29,3.3167,3.31670,2.000
2,8.333,3.53,3.5167,3.51670,2.000
2,8.400,5.12,3.7166,3.71660,2.000
2,8.467,7.08,3.9167,3.91670,2.000
2,8.533,9.46,4.1167,4.11667,2.000
2,8.600,12.32,4.3166,4.31660,2.000
2,8.667,15.73,4.5167,4.51670,2.000
2,8.733,19.82,4.7167,4.71667,2.000
2,8.867,27.37,5.0003,5.00027,2.000
2,8.933,26.25,4.9840,4.98400,2.000
2,9.000,21.49,4.8570,4.85700,2.000
2,9.067,15.39,4.6576,4.65763,2.000
2,9.133,11.03,4.4576,4.45757,2.000
2,9.200,7.88,4.2578,4.25780,2.000
2,9.267,5.61,4.0575,4.05750,2.000
2,9.333,3.96,3.8576,3.85760,2.000
2,9.400,2.70,3.6577,3.65770,2.000
2,9.467,1.75,3.4575,3.45747,2.000
2,9.533,1.03,3.2575,3.25750,2.000
2,9.600,0.52,3.0577,3.05770,2.000
2,9.667,0.18,2.8576,2.85757,2.000
2,9.733,0.02,2.6575,2.65750,2.000
2,9.800,0.00,2.4577,2.45770,2.000
2,9.867,0.00,2.2576,2.25757,2.000
2,9.933,0.00,2.0574,2.05743,2.000
2,10.000,0.00,1.8574,1.85740,2.000
2,10.067,0.01,1.6576,1.65763,2.000
2,10.133,0.01,1.4574,1.45743,2.000
2,10.200,0.01,1.2576,1.25760,2.000
2,10.267,0.01,1.0577,1.05767,2.000
2,10.333,0.01,0.8574,0.85743,2.000
2,10.400,0.01,0.6574,0.65740,2.000
2,10.467,0.00,0.4576,0.45760,2.000
2,10.533,0.01,0.2574,0.25740,2.000
2,10.600,0.01,0.0575,0.05750,2.000
2,10.733,0.01,-0.2474,-0.24740,2.000
2,10.800,0.01,-0.2470,-0.24700,2.000
2,10.867,0.01,-0.1348,-0.13480,2.000
2,10.933,0.00,-0.0171,-0.01713,2.000
2,11.000,0.01,-0.0002,-0.00020,2.000
2,11.067,0.01,-0.0002,-0.00020,2.000
2,11.133,0.00,-0.0002,-0.00020,2.000
2,11.200,0.01,-0.0002,-0.00020,2.000
2,11.267,0.01,-0.0002,-0.00020,2.000
2,11.333,0.01,-0.0002,-0.00020,2.000
2,11.400,0.01,-0.0002,-0.00020,2.000
2,11.467,0.01,-0.0002,-0.00020,2.000
2,11.533,0.01,-0.0002,-0.00020,2.000
2,11.600,0.01,-0.0002,-0.00020,2.000
2,11.667,0.01,-0.0002,-0.00020,2.000
2,11.733,0.01,-0.0002,-0.00020,2.000
2,11.800,0.01,-0.0002,-0.00020,2.000
2,11.867,0.01,-0.0002,-0.00020,2.000
2,11.933,0.01,-0.0002,-0.00020,2.000
2,12.000,0.01,-0.0002,-0.00020,2.000
2,12.067,0.01,-0.0001,-0.00010,2.000
2,12.133,0.01,-0.0001,-0.00010,2.000
2,12.200,0.00,-0.0001,-0.00010,2.000
2,12.267,0.01,-0.0001,-0.00010,2.000
2,12.333,0.01,-0.0001,-0.00010,2.000
2,12.400,0.01,-0.0001,-0.00010,2.000
2,12.467,0.01,-0.0001,-0.00010,2.000
2,12.533,0.01,-0.0001,-0.00010,2.000
2,12.600,0.00,-0.0001,-0.00010,2.000
2,12.667,0.01,-0.0001,-0.00010,2.000
2,12.733,0.01,-0.0001,-0.00010,2.000
2,12.800,0.00,-0.0001,-0.00010,2.000
2,12.867,0.01,-0.0001,-0.00010,2.000
2,12.933,0.01,-0.0001,-0.00010,2.000
2,13.000,0.01,-0.0001,-0.00010,2.000
2,13.067,0.01,-0.0001,-0.00010,2.000
2,13.133,0.01,-0.0001,-0.00010,2.000
2,13.200,0.01,-0.0001,-0.00010,2.000
2,13.267,0.01,-0.0001,-0.00010,2.000
2,13.333,0.01,-0.0001,-0.00010,2.000
2,13.400,0.01,-0.0001,-0.00010,2.000
2,13.467,0.01,-0.0001,-0.00010,2.000
2,13.533,0.01,-0.0001,-0.00010,2.000
2,13.600,0.01,-0.0001,-0.00010,2.000
2,13.667,0.01,-0.0001,-0.00010,2.000
2,13.800,0.01,-0.0001,-0.00010,2.000
3,14.067,0.00,0.1115,0.11147,3.000
3,14.133,0.00,0.3036,0.30357,3.000
3,14.200,0.00,0.5036,0.50360,3.000
3,14.267,0.00,0.7036,0.70360,3.000
3,14.333,0.00,0.9037,0.90367,3.000
3,14.400,0.00,1.1037,1.10370,3.000
3,14.467,0.00,1.3037,1.30370,3.000
3,14.533,0.00,1.5037,1.50370,3.000
3,14.600,0.00,1.7037,1.70370,3.000
3,14.667,0.00,1.9036,1.90357,3.000
3,14.733,0.00,2.1037,2.10367,3.000
3,14.800,0.01,2.3036,2.30360,3.000
3,14.867,0.04,2.5037,2.50370,3.000
3,14.933,0.20,2.7037,2.70373,3.000
3,15.000,0.59,2.9038,2.90380,3.000
3,15.067,1.25,3.1038,3.10377,3.000
3,15.133,2.19,3.3037,3.30370,3.000
3,15.200,3.42,3.5036,3.50360,3.000
3,15.267,4.99,3.7037,3.70367,3.000
3,15.333,6.92,3.9038,3.90377,3.000
3,15.400,9.27,4.1037,4.10370,3.000
3,15.467,12.10,4.3037,4.30367,3.000
3,15.533,15.46,4.5037,4.50373,3.000
3,15.600,19.50,4.7037,4.70370,3.000
3,15.733,27.09,4.9904,4.99040,3.000
3,15.800,26.07,4.9766,4.97660,3.000
3,15.867,21.39,4.8512,4.85123,3.000
3,15.933,15.33,4.6526,4.65260,3.000
3,16.000,10.99,4.4527,4.45270,3.000
3,16.067,7.86,4.2526,4.25260,3.000
3,16.133,5.58,4.0525,4.05247,3.000
3,16.200,3.93,3.8526,3.85260,3.000
3,16.267,2.67,3.6527,3.65270,3.000
3,16.333,1.72,3.4525,3.45253,3.000
3,16.400,1.00,3.2526,3.25260,3.000
3,16.467,0.50,3.0526,3.05260,3.000
3,16.533,0.16,2.8525,2.85250,3.000
3,16.600,0.01,2.6526,2.65260,3.000
3,16.667,0.00,2.4526,2.45257,3.000
3,16.733,0.00,2.2526,2.25257,3.000
3,16.800,0.00,2.0526,2.05260,3.000
3,16.867,0.00,1.8524,1.85243,3.000
3,16.933,-0.01,1.6525,1.65253,3.000
3,17.000,-0.01,1.4526,1.45260,3.000
3,17.067,0.00,1.2525,1.25250,3.000
3,17.133,-0.01,1.0525,1.05253,3.000
3,17.200,0.00,0.8525,0.85250,3.000
3,17.267,0.00,0.6525,0.65247,3.000
3,17.333,-0.01,0.4525,0.45253,3.000
3,17.400,0.00,0.2526,0.25260,3.000
3,17.467,0.00,0.0525,0.05247,3.000
3,17.600,0.00,-0.2598,-0.25980,3.000
3,17.667,0.00,-0.2643,-0.26433,3.000
3,17.733,0.00,-0.1580,-0.15803,3.000
3,17.800,0.00,-0.0267,-0.02670,3.000
3,17.867,0.00,-0.0002,-0.00020,3.000
3,17.933,0.00,-0.0002,-0.00020,3.000
3,18.000,0.00,-0.0001,-0.00010,3.000
3,18.067,0.00,-0.0001,-0.00010,3.000
3,18.133,0.00,-0.0001,-0.00010,3.000
3,18.200,0.00,-0.0001,-0.00010,3.000
3,18.267,0.00,-0.0001,-0.00010,3.000
3,18.333,0.00,-0.0001,-0.00010,3.000
3,18.400,0.00,-0.0001,-0.00010,3.000
3,18.467,0.00,-0.0001,-0.00010,3.000
3,18.533,0.00,-0.0001,-0.00010,3.000
3,18.600,0.00,-0.0001,-0.00010,3.000
3,18.667,0.00,-0.0001,-0.00010,3.000
3,18.733,0.00,-0.0001,-0.00010,3.000
3,18.800,0.00,-0.0001,-0.00010,3.000
3,18.867,0.00,-0.0001,-0.00010,3.000
3,18.933,0.00,-0.0001,-0.00010,3.000
3,19.000,0.00,-0.0001,-0.00010,3.000
3,19.067,0.00,-0.0001,-0.00010,3.000
3,19.133,0.00,-0.0001,-0.00010,3.000
3,19.200,0.00,-0.0001,-0.00010,3.000
3,19.267,0.00,-0.0001,-0.00010,3.000
3,19.333,0.00,-0.0001,-0.00010,3.000
3,19.400,0.00,-0.0001,-0.00010,3.000
3,19.467,0.00,-0.0001,-0.00010,3.000
3,19.533,0.00,-0.0001,-0.00010,3.000
3,19.600,-0.01,-0.0001,-0.00010,3.000
3,19.667,0.00,-0.0001,-0.00010,3.000
3,19.733,0.00,-0.0001,-0.00010,3.000
3,19.800,0.00,-0.0001,-0.00010,3.000
3,19.867,0.00,-0.0001,-0.00010,3.000
3,19.933,0.00,-0.0001,-0.00010,3.000
3,20.000,0.00,-0.0001,-0.00010,3.000
3,20.067,0.00,-0.0001,-0.00010,3.000
3,20.133,0.00,-0.0001,-0.00010,3.000
3,20.200,0.00,-0.0001,-0.00010,3.000
3,20.267,0.00,-0.0001,-0.00010,3.000
3,20.333,0.00,-0.0001,-0.00010,3.000
3,20.400,0.00,-0.0001,-0.00010,3.000
3,20.467,0.00,-0.0001,-0.00010,3.000
3,20.533,0.00,-0.0001,-0.00010,3.000
3,20.667,0.00,-0.0001,-0.00010,3.000
4,20.933,0.00,0.0527,0.05273,4.000
4,21.000,-0.01,0.2158,0.21580,4.000
4,21.067,-0.01,0.4156,0.41557,4.000
4,21.133,-0.01,0.6155,0.61550,4.000
4,21.200,0.00,0.8155,0.81550,4.000
4,21.267,0.00,1.0157,1.01567,4.000
4,21.333,-0.01,1.2158,1.21577,4.000
4,21.400,0.00,1.4157,1.41570,4.000
4,21.467,-0.01,1.6157,1.61567,4.000
4,21.533,-0.01,1.8156,1.81563,4.000
4,21.600,0.00,2.0157,2.01570,4.000
4,21.667,0.00,2.2156,2.21560,4.000
4,21.733,0.02,2.4156,2.41560,4.000
4,21.800,0.10,2.6158,2.61580,4.000
4,21.867,0.37,2.8156,2.81560,4.000
4,21.933,0.91,3.0157,3.01570,4.000
4,22.000,1.72,3.2157,3.21570,4.000
4,22.067,2.83,3.4156,3.41557,4.000
4,22.133,4.25,3.6157,3.61570,4.000
4,22.200,6.02,3.8157,3.81570,4.000
4,22.267,8.18,4.0156,4.01563,4.000
4,22.333,10.80,4.2156,4.21563,4.000
4,22.400,13.92,4.4158,4.41580,4.000
4,22.467,17.65,4.6157,4.61567,4.000
4,22.600,26.48,4.9668,4.96680,4.000
4,22.667,27.33,5.0059,5.00590,4.000
4,22.733,24.29,4.9348,4.93483,4.000
4,22.800,18.28,4.7587,4.75870,4.000
4,22.867,13.06,4.5587,4.55870,4.000
4,22.933,9.36,4.3587,4.35867,4.000
4,23.000,6.67,4.1585,4.15850,4.000
4,23.067,4.71,3.9585,3.95853,4.000
4,23.133,3.28,3.7586,3.75857,4.000
4,23.200,2.18,3.5586,3.55860,4.000
4,23.267,1.35,3.3585,3.35853,4.000
4,23.333,0.74,3.1587,3.15867,4.000
4,23.400,0.30,2.9587,2.95870,4.000
4,23.467,0.06,2.7585,2.75850,4.000
4,23.533,-0.01,2.5586,2.55860,4.000
4,23.600,-0.01,2.3585,2.35850,4.000
4,23.667,-0.01,2.1585,2.15850,4.000
4,23.733,-0.01,1.9585,1.95850,4.000
4,23.800,-0.01,1.7586,1.75860,4.000
4,23.867,0.00,1.5585,1.55847,4.000
4,23.933,-0.01,1.3585,1.35853,4.000
4,24.000,-0.01,1.1585,1.15850,4.000
4,24.067,-0.01,0.9584,0.95837,4.000
4,24.133,-0.01,0.7586,0.75857,4.000
4,24.200,0.00,0.5584,0.55840,4.000
4,24.267,-0.01,0.3584,0.35843,4.000
4,24.333,-0.01,0.1584,0.15843,4.000
4,24.400,0.00,-0.0413,-0.04130,4.000
4,24.533,-0.01,-0.3110,-0.31097,4.000
4,24.600,-0.01,-0.2856,-0.28560,4.000
4,24.667,-0.01,-0.1485,-0.14853,4.000
4,24.733,0.00,-0.0224,-0.02243,4.000
4,24.800,-0.01,-0.0002,-0.00020,4.000
4,24.867,0.00,-0.0002,-0.00020,4.000
4,24.933,0.00,-0.0001,-0.00010,4.000
4,25.000,0.00,-0.0001,-0.00010,4.000
4,25.067,-0.01,-0.0001,-0.00010,4.000
4,25.133,0.00,-0.0001,-0.00010,4.000
4,25.200,-0.01,-0.0001,-0.00010,4.000
4,25.267,0.00,-0.0001,-0.00010,4.000
4,25.333,-0.01,-0.0001,-0.00010,4.000
4,25.400,-0.01,-0.0001,-0.00010,4.000
4,25.467,0.00,-0.0001,-0.00010,4.000
4,25.533,-0.01,-0.0001,-0.00010,4.000
4,25.600,-0.01,-0.0001,-0.00010,4.000
4,25.667,-0.01,-0.0001,-0.00010,4.000
4,25.733,-0.01,-0.0001,-0.00010,4.000
4,25.800,-0.01,-0.0001,-0.00010,4.000
4,25.867,-0.01,-0.0001,-0.00010,4.000
4,25.933,-0.01,-0.0001,-0.00010,4.000
4,26.000,0.00,-0.0001,-0.00010,4.000
4,26.067,-0.01,-0.0001,-0.00010,4.000
4,26.133,-0.01,-0.0001,-0.00010,4.000
4,26.200,-0.01,-0.0001,-0.00010,4.000
4,26.267,0.00,-0.0001,-0.00010,4.000
4,26.333,-0.01,-0.0001,-0.00010,4.000
4,26.400,-0.01,-0.0001,-0.00010,4.000
4,26.467,-0.01,-0.0001,-0.00010,4.000
4,26.533,-0.01,-0.0001,-0.00010,4.000
4,26.600,0.00,-0.0001,-0.00010,4.000
4,26.667,0.00,-0.0001,-0.00010,4.000
4,26.733,0.00,-0.0001,-0.00010,4.000
4,26.800,0.00,-0.0001,-0.00010,4.000
4,26.867,0.00,-0.0001,-0.00010,4.000
4,26.933,0.00,-0.0001,-0.00010,4.000
4,27.000,0.00,-0.0001,-0.00010,4.000
4,27.067,0.00,-0.0001,-0.00010,4.000
4,27.133,-0.01,-0.0001,-0.00010,4.000
4,27.200,0.00,-0.0001,-0.00010,4.000
4,27.267,0.00,-0.0001,-0.00010,4.000
4,27.333,0.00,-0.0001,-0.00010,4.000
4,27.400,-0.01,-0.0001,-0.00010,4.000
4,27.467,0.00,-0.0001,-0.00010,4.000
4,27.600,-0.01,-0.0001,-0.00010,4.000
5,27.867,0.00,0.1666,0.16657,5.000
5,27.933,0.00,0.3666,0.36660,5.000
5,28.000,0.00,0.5666,0.56660,5.000
5,28.067,0.00,0.7667,0.76670,5.000
5,28.133,0.00,0.9665,0.96653,5.000
5,28.200,0.00,1.1668,1.16680,5.000
5,28.267,0.00,1.3667,1.36667,5.000
5,28.333,0.00,1.5666,1.56660,5.000
5,28.400,0.00,1.7667,1.76670,5.000
5,28.467,0.00,1.9666,1.96660,5.000
5,28.533,0.00,2.1666,2.16663,5.000
5,28.600,0.01,2.3667,2.36670,5.000
5,28.667,0.06,2.5668,2.56677,5.000
5,28.733,0.29,2.7666,2.76663,5.000
5,28.800,0.75,2.9667,2.96670,5.000
5,28.867,1.49,3.1668,3.16680,5.000
5,28.933,2.52,3.3666,3.36660,5.000
5,29.000,3.86,3.5667,3.56670,5.000
5,29.067,5.55,3.7667,3.76670,5.000
5,29.133,7.61,3.9666,3.96657,5.000
5,29.200,10.11,4.1666,4.16660,5.000
5,29.267,13.10,4.3667,4.36670,5.000
5,29.333,16.68,4.5666,4.56663,5.000
5,29.400,20.99,4.7666,4.76660,5.000
5,29.533,28.14,5.0255,5.02553,5.000
5,29.600,26.43,4.9938,4.99380,5.000
5,29.667,21.10,4.8499,4.84987,5.000
5,29.733,15.03,4.6497,4.64967,5.000
5,29.800,10.79,4.4496,4.44960,5.000
5,29.867,7.71,4.2496,4.24957,5.000
5,29.933,5.48,4.0495,4.04953,5.000
5,30.000,3.86,3.8496,3.84960,5.000
5,30.067,2.62,3.6497,3.64970,5.000
5,30.133,1.68,3.4495,3.44947,5.000
5,30.200,0.97,3.2496,3.24960,5.000
5,30.267,0.47,3.0495,3.04953,5.000
5,30.333,0.14,2.8495,2.84953,5.000
5,30.400,0.01,2.6495,2.64950,5.000
5,30.467,0.00,2.4495,2.44953,5.000
5,30.533,0.00,2.2496,2.24960,5.000
5,30.600,-0.01,2.0495,2.04950,5.000
5,30.667,0.00,1.8494,1.84943,5.000
5,30.733,-0.01,1.6496,1.64960,5.000
5,30.800,0.00,1.4496,1.44960,5.000
5,30.867,-0.01,1.2495,1.24950,5.000
5,30.933,0.00,1.0495,1.04950,5.000
5,31.000,0.00,0.8495,0.84950,5.000
5,31.067,0.00,0.6494,0.64940,5.000
5,31.133,0.00,0.4496,0.44960,5.000
5,31.200,0.00,0.2495,0.24950,5.000
5,31.267,0.00,0.0494,0.04940,5.000
5,31.400,0.00,-0.2733,-0.27330,5.000
5,31.467,0.00,-0.2858,-0.28583,5.000
5,31.533,0.00,-0.1880,-0.18803,5.000
5,31.600,-0.01,-0.0415,-0.04150,5.000
5,31.667,0.00,-0.0001,-0.00013,5.000
5,31.733,0.00,-0.0002,-0.00020,5.000
5,31.800,0.00,-0.0001,-0.00010,5.000
5,31.867,0.00,-0.0001,-0.00010,5.000
5,31.933,0.00,-0.0001,-0.00010,5.000
5,32.000,0.00,-0.0001,-0.00010,5.000
5,32.067,0.00,-0.0001,-0.00010,5.000
5,32.133,0.00,-0.0001,-0.00010,5.000
5,32.200,0.00,-0.0001,-0.00010,5.000
5,32.267,0.00,-0.0001,-0.00010,5.000
5,32.333,0.00,-0.0001,-0.00010,5.000
5,32.400,0.00,-0.0001,-0.00010,5.000
5,32.467,0.00,-0.0001,-0.00010,5.000
5,32.533,0.00,-0.0001,-0.00010,5.000
5,32.600,0.00,-0.0001,-0.00010,5.000
5,32.667,-0.01,-0.0001,-0.00010,5.000
5,32.733,0.00,-0.0001,-0.00010,5.000
5,32.800,0.00,-0.0001,-0.00010,5.000
5,32.867,0.00,-0.0001,-0.00010,5.000
5,32.933,0.00,-0.0001,-0.00010,5.000
5,33.000,0.00,-0.0001,-0.00010,5.000
5,33.067,0.00,-0.0001,-0.00010,5.000
5,33.133,0.00,-0.0001,-0.00010,5.000
5,33.200,0.00,-0.0001,-0.00010,5.000
5,33.267,0.00,-0.0001,-0.00010,5.000
5,33.333,0.00,-0.0001,-0.00010,5.000
5,33.400,0.00,-0.0001,-0.00010,5.000
5,33.467,0.00,-0.0001,-0.00010,5.000
5,33.533,0.00,-0.0001,-0.00010,5.000
5,33.600,0.00,-0.0001,-0.00010,5.000
5,33.667,0.00,-0.0001,-0.00010,5.000
5,33.733,0.00,-0.0001,-0.00010,5.000
5,33.800,0.00,-0.0001,-0.00010,5.000
5,33.867,0.00,-0.0001,-0.00010,5.000
5,33.933,0.00,-0.0001,-0.00010,5.000
5,34.000,0.00,-0.0001,-0.00010,5.000
5,34.067,0.00,-0.0001,-0.00010,5.000
5,34.133,0.00,-0.0001,-0.00010,5.000
5,34.200,0.00,-0.0001,-0.00010,5.000
5,34.267,0.00,-0.0001,-0.00010,5.000
5,34.333,0.00,-0.0001,-0.00010,5.000
5,34.467,0.00,-0.0001,-0.00010,5.000
6,34.800,0.00,0.2067,0.20680,6.000
6,34.867,0.00,0.4066,0.40670,6.000
6,34.933,0.00,0.6065,0.60660,6.000
6,35.000,0.00,0.8067,0.80680,6.000
6,35.067,0.00,1.0066,1.00670,6.000
6,35.133,0.00,1.2066,1.20673,6.000
6,35.200,0.00,1.4066,1.40670,6.000
6,35.267,0.00,1.6067,1.60683,6.000
6,35.333,0.00,1.8065,1.80663,6.000
6,35.400,0.00,2.0066,2.00670,6.000
6,35.467,0.01,2.2067,2.20677,6.000
6,35.533,0.02,2.4066,2.40670,6.000
6,35.600,0.09,2.6066,2.60670,6.000
6,35.667,0.36,2.8067,2.80677,6.000
6,35.733,0.88,3.0068,3.00690,6.000
6,35.800,1.67,3.2067,3.20680,6.000
6,35.867,2.75,3.4066,3.40673,6.000
6,35.933,4.15,3.6067,3.60677,6.000
6,36.000,5.92,3.8067,3.80680,6.000
6,36.067,8.07,4.0066,4.00670,6.000
6,36.133,10.66,4.2067,4.20680,6.000
6,36.200,13.75,4.4068,4.40690,6.000
6,36.267,17.48,4.6068,4.60687,6.000
6,36.400,25.76,4.9405,4.94060,6.000
6,36.467,26.05,4.9635,4.96357,6.000
6,36.533,22.62,4.8756,4.87573,6.000
6,36.600,16.68,4.6895,4.68960,6.000
6,36.667,11.94,4.4895,4.48963,6.000
6,36.733,8.53,4.2897,4.28983,6.000
6,36.800,6.05,4.0896,4.08970,6.000
6,36.867,4.25,3.8896,3.88967,6.000
6,36.933,2.91,3.6896,3.68973,6.000
6,37.000,1.89,3.4895,3.48960,6.000
6,37.067,1.12,3.2896,3.28967,6.000
6,37.133,0.58,3.0897,3.08977,6.000
6,37.200,0.21,2.8896,2.88970,6.000
6,37.267,0.02,2.6895,2.68960,6.000
6,37.333,0.00,2.4897,2.48977,6.000
6,37.400,0.00,2.2896,2.28970,6.000
6,37.467,0.00,2.0895,2.08957,6.000
6,37.533,0.00,1.8894,1.88947,6.000
6,37.600,0.00,1.6897,1.68980,6.000
6,37.667,0.00,1.4894,1.48953,6.000
6,37.733,0.00,1.2896,1.28967,6.000
6,37.800,0.00,1.0896,1.08970,6.000
6,37.867,0.00,0.8894,0.88950,6.000
6,37.933,0.00,0.6895,0.68957,6.000
6,38.000,0.00,0.4896,0.48970,6.000
6,38.067,0.00,0.2894,0.28953,6.000
6,38.133,0.00,0.0895,0.08957,6.000
6,38.267,0.00,-0.2295,-0.22937,6.000
6,38.333,0.00,-0.2399,-0.23977,6.000
6,38.400,0.00,-0.1395,-0.13940,6.000
6,38.467,0.00,-0.0184,-0.01830,6.000
6,38.533,0.00,0.0001,0.00017,6.000
6,38.600,0.00,-0.0001,0.00000,6.000
6,38.667,0.00,-0.0001,0.00000,6.000
6,38.733,0.00,-0.0001,0.00000,6.000
6,38.800,0.00,-0.0001,0.00000,6.000
6,38.867,0.00,-0.0001,0.00000,6.000
6,38.933,0.00,-0.0001,0.00000,6.000
6,39.000,0.00,-0.0001,0.00000,6.000
6,39.067,0.00,-0.0001,0.00000,6.000
6,39.133,0.00,-0.0001,0.00000,6.000
6,39.200,0.00,-0.0001,0.00000,6.000
6,39.267,0.00,-0.0001,0.00000,6.000
6,39.333,0.00,-0.0001,0.00000,6.000
6,39.400,0.00,-0.0001,0.00000,6.000
6,39.467,0.00,-0.0001,0.00000,6.000
6,39.533,0.00,-0.0001,0.00000,6.000
6,39.600,0.00,-0.0001,0.00000,6.000
6,39.667,0.00,-0.0001,0.00000,6.000
6,39.733,0.00,-0.0001,0.00000,6.000
6,39.800,0.00,-0.0001,0.00000,6.000
6,39.867,0.00,-0.0001,0.00000,6.000
6,39.933,0.00,-0.0001,0.00000,6.000
6,40.000,0.00,-0.0001,0.00000,6.000
6,40.067,0.00,-0.0001,0.00000,6.000
6,40.133,0.00,-0.0001,0.00000,6.000
6,40.200,0.00,-0.0001,0.00000,6.000
6,40.267,0.00,-0.0001,0.00000,6.000
6,40.333,0.00,-0.0001,0.00000,6.000
6,40.400,0.00,-0.0001,0.00000,6.000
6,40.467,0.00,-0.0001,0.00000,6.000
6,40.533,0.00,-0.0001,0.00000,6.000
6,40.600,0.00,-0.0001,0.00000,6.000
6,40.667,0.00,-0.0001,0.00000,6.000
6,40.733,0.00,-0.0001,0.00000,6.000
6,40.800,0.00,-0.0001,0.00000,6.000
6,40.867,0.00,-0.0001,0.00000,6.000
6,40.933,0.00,-0.0001,0.00000,6.000
6,41.000,0.00,-0.0001,0.00000,6.000
6,41.067,0.00,-0.0001,0.00000,6.000
6,41.133,0.00,-0.0001,0.00000,6.000
6,41.200,0.00,-0.0001,0.00000,6.000
6,41.333,0.00,-0.0001,0.00000,6.000
7,41.667,0.00,0.1469,0.14693,7.000
7,41.733,0.00,0.3456,0.34560,7.000
7,41.800,0.00,0.5455,0.54550,7.000
7,41.867,0.00,0.7456,0.74560,7.000
7,41.933,0.00,0.9456,0.94563,7.000
7,42.000,0.00,1.1456,1.14560,7.000
7,42.067,0.00,1.3456,1.34560,7.000
7,42.133,0.00,1.5456,1.54557,7.000
7,42.200,0.00,1.7457,1.74570,7.000
7,42.267,0.00,1.9455,1.94550,7.000
7,42.333,0.01,2.1456,2.14557,7.000
7,42.400,0.01,2.3456,2.34560,7.000
7,42.467,0.04,2.5456,2.54563,7.000
7,42.533,0.25,2.7457,2.74567,7.000
7,42.600,0.68,2.9458,2.94580,7.000
7,42.667,1.39,3.1458,3.14577,7.000
7,42.733,2.38,3.3457,3.34570,7.000
7,42.800,3.66,3.5456,3.54560,7.000
7,42.867,5.31,3.7456,3.74560,7.000
7,42.933,7.33,3.9457,3.94567,7.000
7,43.000,9.79,4.1457,4.14570,7.000
7,43.067,12.73,4.3456,4.34560,7.000
7,43.133,16.24,4.5457,4.54567,7.000
7,43.333,26.60,4.9768,4.97683,7.000
7,43.400,24.44,4.9284,4.92840,7.000
7,43.467,19.02,4.7685,4.76850,7.000
7,43.533,13.54,4.5687,4.56870,7.000
7,43.600,9.69,4.3686,4.36860,7.000
7,43.667,6.90,4.1685,4.16850,7.000
7,43.733,4.87,3.9686,3.96857,7.000
7,43.800,3.38,3.7685,3.76850,7.000
7,43.867,2.25,3.5687,3.56867,7.000
7,43.933,1.40,3.3686,3.36860,7.000
7,44.000,0.76,3.1686,3.16860,7.000
7,44.067,0.32,2.9686,2.96860,7.000
7,44.133,0.07,2.7685,2.76853,7.000
7,44.200,-0.01,2.5685,2.56850,7.000
7,44.267,0.00,2.3685,2.36850,7.000
7,44.333,0.00,2.1685,2.16850,7.000
7,44.400,0.00,1.9684,1.96840,7.000
7,44.467,0.00,1.7685,1.76850,7.000
7,44.533,0.00,1.5685,1.56850,7.000
7,44.600,0.00,1.3685,1.36850,7.000
7,44.667,0.00,1.1685,1.16850,7.000
7,44.733,0.00,0.9684,0.96840,7.000
7,44.800,0.00,0.7685,0.76850,7.000
7,44.867,0.00,0.5684,0.56840,7.000
7,44.933,0.00,0.3685,0.36853,7.000
7,45.000,0.00,0.1684,0.16840,7.000
7,45.200,0.00,-0.2431,-0.24310,7.000
7,45.267,0.00,-0.1829,-0.18287,7.000
7,45.333,0.00,-0.0456,-0.04560,7.000
7,45.400,0.00,0.0020,0.00200,7.000
7,45.467,0.00,-0.0001,-0.00010,7.000
7,45.533,0.00,-0.0001,-0.00010,7.000
7,45.600,0.00,-0.0001,-0.00010,7.000
7,45.667,0.00,-0.0001,-0.00010,7.000
7,45.733,0.00,-0.0001,-0.00010,7.000
7,45.800,0.00,-0.0001,-0.00010,7.000
7,45.867,0.00,-0.0001,-0.00010,7.000
7,45.933,0.00,-0.0001,-0.00010,7.000
7,46.000,0.00,-0.0001,-0.00010,7.000
7,46.067,0.00,-0.0001,-0.00010,7.000
7,46.133,0.00,-0.0001,-0.00010,7.000
7,46.200,0.00,-0.0001,-0.00010,7.000
7,46.267,0.00,-0.0001,-0.00010,7.000
7,46.333,0.00,-0.0001,-0.00010,7.000
7,46.400,0.00,-0.0001,-0.00010,7.000
7,46.467,0.00,-0.0001,-0.00010,7.000
7,46.533,0.00,-0.0001,-0.00010,7.000
7,46.600,0.00,-0.0001,-0.00010,7.000
7,46.667,0.00,-0.0001,-0.00010,7.000
7,46.733,0.00,-0.0001,-0.00010,7.000
7,46.800,0.00,-0.0001,-0.00010,7.000
7,46.867,0.00,-0.0001,-0.00010,7.000
7,46.933,0.00,-0.0001,-0.00010,7.000
7,47.000,0.00,-0.0001,-0.00010,7.000
7,47.067,0.00,-0.0001,-0.00010,7.000
7,47.133,0.00,-0.0001,-0.00010,7.000
7,47.200,0.00,-0.0001,-0.00010,7.000
7,47.267,0.00,-0.0001,-0.00010,7.000
7,47.333,0.00,-0.0001,-0.00010,7.000
7,47.400,0.00,-0.0001,-0.00010,7.000
7,47.467,0.00,-0.0001,-0.00010,7.000
7,47.533,0.00,-0.0001,-0.00010,7.000
7,47.600,0.00,-0.0001,-0.00010,7.000
7,47.667,0.00,-0.0001,-0.00010,7.000
7,47.733,0.00,-0.0001,-0.00010,7.000
7,47.800,0.00,-0.0001,-0.00010,7.000
7,47.867,0.00,-0.0001,-0.00010,7.000
7,47.933,0.00,-0.0001,-0.00010,7.000
7,48.000,0.00,-0.0001,-0.00010,7.000
7,48.067,0.00,-0.0001,-0.00010,7.000
8,48.400,0.00,0.0000,0.00000,8.000
8,48.467,0.00,0.0291,0.02913,8.000
8,48.533,0.00,0.1656,0.16563,8.000
8,48.600,0.01,0.3656,0.36560,8.000
8,48.667,0.00,0.5656,0.56557,8.000
8,48.733,0.00,0.7656,0.76563,8.000
8,48.800,0.01,0.9655,0.96550,8.000
8,48.867,0.00,1.1657,1.16567,8.000
8,48.933,0.00,1.3656,1.36560,8.000
8,49.000,0.00,1.5657,1.56570,8.000
8,49.067,0.00,1.7658,1.76577,8.000
8,49.133,0.01,1.9655,1.96547,8.000
8,49.200,0.02,2.1656,2.16560,8.000
8,49.267,0.02,2.3656,2.36560,8.000
8,49.333,0.06,2.5657,2.56567,8.000
8,49.400,0.28,2.7656,2.76560,8.000
8,49.467,0.74,2.9658,2.96580,8.000
8,49.533,1.47,3.1658,3.16580,8.000
8,49.600,2.49,3.3657,3.36570,8.000
8,49.667,3.81,3.5657,3.56573,8.000
8,49.733,5.49,3.7656,3.76563,8.000
8,49.800,7.56,3.9656,3.96560,8.000
8,49.867,10.06,4.1656,4.16563,8.000
8,49.933,13.06,4.3656,4.36563,8.000
8,50.000,16.64,4.5656,4.56560,8.000
8,50.200,26.58,4.9773,4.97730,8.000
8,50.267,24.00,4.9171,4.91713,8.000
8,50.333,18.38,4.7484,4.74843,8.000
8,50.400,13.09,4.5488,4.54880,8.000
8,50.467,9.37,4.3487,4.34867,8.000
8,50.533,6.66,4.1485,4.14853,8.000
8,50.600,4.69,3.9485,3.94850,8.000
8,50.667,3.25,3.7486,3.74857,8.000
8,50.733,2.15,3.5485,3.54853,8.000
8,50.800,1.32,3.3485,3.34850,8.000
8,50.867,0.71,3.1487,3.14867,8.000
8,50.933,0.29,2.9486,2.94863,8.000
8,51.000,0.06,2.7485,2.74850,8.000
8,51.067,0.00,2.5486,2.54863,8.000
8,51.133,0.00,2.3485,2.34850,8.000
8,51.200,0.00,2.1484,2.14840,8.000
8,51.267,0.00,1.9485,1.94853,8.000
8,51.333,0.00,1.7486,1.74857,8.000
8,51.400,0.00,1.5484,1.54840,8.000
8,51.467,0.00,1.3486,1.34857,8.000
8,51.533,0.01,1.1485,1.14853,8.000
8,51.600,0.00,0.9484,0.94840,8.000
8,51.667,0.00,0.7486,0.74857,8.000
8,51.733,0.00,0.5484,0.54840,8.000
8,51.800,0.00,0.3484,0.34840,8.000
8,51.867,0.00,0.1484,0.14843,8.000
8,52.000,0.00,-0.2010,-0.20100,8.000
8,52.067,0.01,-0.2385,-0.23847,8.000
8,52.133,0.01,-0.1657,-0.16573,8.000
8,52.200,0.00,-0.0335,-0.03350,8.000
8,52.267,0.00,-0.0002,-0.00017,8.000
8,52.333,0.00,-0.0001,-0.00010,8.000
8,52.400,0.00,-0.0001,-0.00010,8.000
8,52.467,0.00,-0.0001,-0.00010,8.000
8,52.533,0.00,-0.0001,-0.00010,8.000
8,52.600,0.01,-0.0001,-0.00010,8.000
8,52.667,0.01,-0.0001,-0.00010,8.000
8,52.733,0.00,-0.0001,-0.00010,8.000
8,52.800,0.00,-0.0001,-0.00010,8.000
8,52.867,0.00,-0.0001,-0.00010,8.000
8,52.933,0.00,-0.0001,-0.00010,8.000
8,53.000,0.00,-0.0001,-0.00010,8.000
8,53.067,0.00,-0.0001,-0.00010,8.000
8,53.133,0.00,-0.0001,-0.00010,8.000
8,53.200,0.01,-0.0001,-0.00010,8.000
8,53.267,0.00,-0.0001,-0.00010,8.000
8,53.333,0.00,-0.0001,-0.00010,8.000
8,53.400,0.01,-0.0001,-0.00010,8.000
8,53.467,0.00,-0.0001,-0.00010,8.000
8,53.533,0.00,-0.0001,-0.00010,8.000
8,53.600,0.00,-0.0001,-0.00010,8.000
8,53.667,0.00,-0.0001,-0.00010,8.000
8,53.733,0.00,-0.0001,-0.00010,8.000
8,53.800,0.01,-0.0001,-0.00010,8.000
8,53.867,0.01,-0.0001,-0.00010,8.000
8,53.933,0.00,-0.0001,-0.00010,8.000
8,54.000,0.00,-0.0001,-0.00010,8.000
8,54.067,0.00,-0.0001,-0.00010,8.000
8,54.133,0.00,-0.0001,-0.00010,8.000
8,54.200,0.00,-0.0001,-0.00010,8.000
8,54.267,0.00,-0.0001,-0.00010,8.000
8,54.333,0.01,-0.0001,-0.00010,8.000
8,54.400,0.00,-0.0001,-0.00010,8.000
8,54.467,0.00,-0.0001,-0.00010,8.000
8,54.533,0.00,-0.0001,-0.00010,8.000
8,54.600,0.00,-0.0001,-0.00010,8.000
8,54.667,0.00,-0.0001,-0.00010,8.000
8,54.733,0.00,-0.0001,-0.00010,8.000
8,54.800,0.01,-0.0001,-0.00010,8.000
8,54.867,0.00,-0.0001,-0.00010,8.000
8,54.933,0.01,-0.0001,-0.00010,8.000
8,55.000,0.01,-0.0001,-0.00010,8.000
8,55.067,0.01,-0.0001,-0.00010,8.000
9,55.400,0.00,0.1762,0.17620,9.000
9,55.467,-0.01,0.3766,0.37657,9.000
9,55.533,0.00,0.5765,0.57650,9.000
9,55.600,0.00,0.7767,0.77670,9.000
9,55.667,0.00,0.9766,0.97657,9.000
9,55.733,-0.01,1.1766,1.17660,9.000
9,55.800,-0.01,1.3767,1.37670,9.000
9,55.867,-0.01,1.5766,1.57660,9.000
9,55.933,-0.01,1.7767,1.77667,9.000
9,56.000,0.00,1.9767,1.97670,9.000
9,56.067,0.00,2.1766,2.17660,9.000
9,56.133,0.01,2.3766,2.37663,9.000
9,56.200,0.07,2.5768,2.57680,9.000
9,56.267,0.29,2.7767,2.77667,9.000
9,56.333,0.77,2.9767,2.97673,9.000
9,56.400,1.51,3.1768,3.17680,9.000
9,56.467,2.55,3.3766,3.37657,9.000
9,56.533,3.89,3.5767,3.57667,9.000
9,56.600,5.60,3.7768,3.77680,9.000
9,56.667,7.68,3.9767,3.97667,9.000
9,56.733,10.20,4.1766,4.17663,9.000
9,56.800,13.22,4.3767,4.37670,9.000
9,56.867,16.83,4.5767,4.57670,9.000
9,57.000,25.36,4.9278,4.92780,9.000
9,57.067,26.22,4.9669,4.96693,9.000
9,57.133,23.33,4.8958,4.89583,9.000
9,57.200,17.56,4.7197,4.71970,9.000
9,57.267,12.53,4.5196,4.51963,9.000
9,57.333,8.97,4.3196,4.31963,9.000
9,57.400,6.36,4.1194,4.11940,9.000
9,57.467,4.47,3.9195,3.91953,9.000
9,57.533,3.08,3.7195,3.71953,9.000
9,57.600,2.02,3.5195,3.51950,9.000
9,57.667,1.22,3.3195,3.31953,9.000
9,57.733,0.64,3.1196,3.11963,9.000
9,57.800,0.24,2.9195,2.91950,9.000
9,57.867,0.03,2.7195,2.71953,9.000
9,57.933,-0.01,2.5196,2.51957,9.000
9,58.000,-0.01,2.3194,2.31940,9.000
9,58.067,-0.01,2.1195,2.11947,9.000
9,58.133,-0.01,1.9195,1.91947,9.000
9,58.200,-0.01,1.7195,1.71950,9.000
9,58.267,-0.01,1.5195,1.51947,9.000
9,58.333,-0.01,1.3196,1.31957,9.000
9,58.400,-0.01,1.1196,1.11960,9.000
9,58.467,-0.01,0.9194,0.91940,9.000
9,58.533,-0.01,0.7196,0.71957,9.000
9,58.600,-0.01,0.5194,0.51940,9.000
9,58.667,-0.01,0.3194,0.31937,9.000
9,58.733,0.00,0.1195,0.11947,9.000
9,58.867,0.00,-0.2201,-0.22013,9.000
9,58.933,-0.01,-0.2485,-0.24850,9.000
9,59.000,-0.01,-0.1666,-0.16660,9.000
9,59.067,-0.01,-0.0329,-0.03287,9.000
9,59.133,-0.01,-0.0002,-0.00017,9.000
9,59.200,-0.01,-0.0001,-0.00010,9.000
9,59.267,-0.01,-0.0001,-0.00010,9.000
9,59.333,-0.01,-0.0001,-0.00010,9.000
9,59.400,-0.01,-0.0001,-0.00010,9.000
9,59.467,-0.01,-0.0001,-0.00010,9.000
9,59.533,0.00,-0.0001,-0.00010,9.000
9,59.600,-0.01,-0.0001,-0.00010,9.000
9,59.667,-0.01,-0.0001,-0.00010,9.000
9,59.733,-0.01,-0.0001,-0.00010,9.000
9,59.800,-0.01,-0.0001,-0.00010,9.000
9,59.867,-0.01,-0.0001,-0.00010,9.000
9,59.933,-0.01,-0.0001,-0.00010,9.000
9,60.000,-0.01,-0.0001,-0.00010,9.000
9,60.067,-0.01,-0.0001,-0.00010,9.000
9,60.133,-0.01,-0.0001,-0.00010,9.000
9,60.200,-0.01,-0.0001,-0.00010,9.000
9,60.267,-0.01,-0.0001,-0.00010,9.000
9,60.333,0.00,-0.0001,-0.00010,9.000
9,60.400,-0.01,-0.0001,-0.00010,9.000
9,60.467,-0.01,-0.0001,-0.00010,9.000
9,60.533,-0.01,-0.0001,-0.00010,9.000
9,60.600,0.00,-0.0001,-0.00010,9.000
9,60.667,0.00,-0.0001,-0.00010,9.000
9,60.733,-0.01,-0.0001,-0.00010,9.000
9,60.800,-0.01,-0.0001,-0.00010,9.000
9,60.867,-0.01,-0.0001,-0.00010,9.000
9,60.933,-0.01,-0.0001,-0.00010,9.000
9,61.000,-0.01,-0.0001,-0.00010,9.000
9,61.067,-0.01,-0.0001,-0.00010,9.000
9,61.133,0.00,-0.0001,-0.00010,9.000
9,61.200,0.00,-0.0001,-0.00010,9.000
9,61.267,-0.01,-0.0001,-0.00010,9.000
9,61.333,0.00,-0.0001,-0.00010,9.000
9,61.400,-0.01,-0.0001,-0.00010,9.000
9,61.467,-0.01,-0.0001,-0.00010,9.000
9,61.533,-0.01,-0.0001,-0.00010,9.000
9,61.600,-0.01,-0.0001,-0.00010,9.000
9,61.667,-0.01,-0.0001,-0.00010,9.000
9,61.733,0.00,-0.0001,-0.00010,9.000
9,61.800,-0.01,-0.0001,-0.00010,9.000
9,61.933,-0.01,-0.0001,-0.00010,9.000
10,62.267,-0.01,0.1469,0.14690,10.000
10,62.333,-0.01,0.3456,0.34560,10.000
10,62.400,-0.01,0.5456,0.54560,10.000
10,62.467,-0.01,0.7456,0.74560,10.000
10,62.533,-0.01,0.9456,0.94563,10.000
10,62.600,-0.01,1.1457,1.14570,10.000
10,62.667,-0.01,1.3456,1.34560,10.000
10,62.733,-0.01,1.5457,1.54567,10.000
10,62.800,-0.02,1.7457,1.74570,10.000
10,62.867,-0.01,1.9456,1.94560,10.000
10,62.933,-0.01,2.1456,2.14560,10.000
10,63.000,0.00,2.3456,2.34560,10.000
10,63.067,0.04,2.5458,2.54577,10.000
10,63.133,0.24,2.7457,2.74567,10.000
10,63.200,0.67,2.9458,2.94580,10.000
10,63.267,1.37,3.1458,3.14577,10.000
10,63.333,2.37,3.3456,3.34563,10.000
10,63.400,3.67,3.5457,3.54570,10.000
10,63.467,5.32,3.7456,3.74560,10.000
10,63.533,7.34,3.9457,3.94567,10.000
10,63.600,9.79,4.1456,4.14560,10.000
10,63.667,12.72,4.3456,4.34563,10.000
10,63.733,16.24,4.5456,4.54563,10.000
10,63.933,26.62,4.9769,4.97690,10.000
10,64.000,24.44,4.9285,4.92850,10.000
10,64.067,19.04,4.7685,4.76853,10.000
10,64.133,13.55,4.5686,4.56863,10.000
10,64.200,9.69,4.3686,4.36860,10.000
10,64.267,6.89,4.1685,4.16850,10.000
10,64.333,4.86,3.9685,3.96847,10.000
10,64.400,3.37,3.7685,3.76850,10.000
10,64.467,2.24,3.5686,3.56860,10.000
10,64.533,1.39,3.3685,3.36850,10.000
10,64.600,0.75,3.1686,3.16860,10.000
10,64.667,0.31,2.9686,2.96863,10.000
10,64.733,0.06,2.7686,2.76857,10.000
10,64.800,-0.02,2.5686,2.56860,10.000
10,64.867,-0.01,2.3685,2.36850,10.000
10,64.933,-0.01,2.1685,2.16847,10.000
10,65.000,-0.01,1.9685,1.96850,10.000
10,65.067,-0.02,1.7685,1.76853,10.000
10,65.133,-0.01,1.5685,1.56850,10.000
10,65.200,-0.02,1.3685,1.36850,10.000
10,65.267,-0.01,1.1684,1.16840,10.000
10,65.333,-0.01,0.9684,0.96843,10.000
10,65.400,-0.01,0.7686,0.76860,10.000
10,65.467,-0.01,0.5683,0.56833,10.000
10,65.533,-0.01,0.3685,0.36847,10.000
10,65.600,-0.01,0.1685,0.16850,10.000
10,65.667,-0.02,-0.0315,-0.03147,10.000
10,65.800,-0.01,-0.2995,-0.29950,10.000
10,65.867,-0.01,-0.2725,-0.27253,10.000
10,65.933,-0.01,-0.1353,-0.13533,10.000
10,66.000,-0.01,-0.0171,-0.01710,10.000
10,66.067,-0.01,-0.0001,-0.00010,10.000
10,66.133,-0.01,-0.0001,-0.00010,10.000
10,66.200,-0.01,-0.0001,-0.00010,10.000
10,66.267,-0.01,-0.0001,-0.00010,10.000
10,66.333,-0.01,-0.0001,-0.00010,10.000
10,66.400,-0.01,-0.0001,-0.00010,10.000
10,66.467,-0.01,-0.0001,-0.00010,10.000
10,66.533,-0.02,-0.0001,-0.00010,10.000
10,66.600,-0.01,-0.0001,-0.00010,10.000
10,66.667,-0.01,-0.0001,-0.00010,10.000
10,66.733,-0.01,-0.0001,-0.00010,10.000
10,66.800,-0.01,-0.0001,-0.00010,10.000
10,66.867,-0.01,-0.0001,-0.00010,10.000
10,66.933,-0.01,-0.0001,-0.00010,10.000
10,67.000,-0.01,-0.0001,-0.00010,10.000
10,67.067,-0.01,-0.0001,-0.00010,10.000
10,67.133,-0.01,-0.0001,-0.00010,10.000
10,67.200,-0.01,-0.0001,-0.00010,10.000
10,67.267,-0.01,-0.0001,-0.00010,10.000
10,67.333,-0.01,-0.0001,-0.00010,10.000
10,67.400,-0.02,-0.0001,-0.00010,10.000
10,67.467,-0.01,-0.0001,-0.00010,10.000
10,67.533,-0.02,-0.0001,-0.00010,10.000
10,67.600,-0.01,-0.0001,-0.00010,10.000
10,67.667,-0.01,-0.0001,-0.00010,10.000
10,67.733,-0.01,-0.0001,-0.00010,10.000
10,67.800,-0.01,-0.0001,-0.00010,10.000
10,67.867,-0.01,-0.0001,-0.00010,10.000
10,67.933,-0.01,-0.0001,-0.00010,10.000
10,68.000,-0.01,-0.0001,-0.00010,10.000
10,68.067,-0.01,-0.0001,-0.00010,10.000
10,68.133,-0.02,-0.0001,-0.00010,10.000
10,68.200,-0.01,-0.0001,-0.00010,10.000
10,68.267,-0.01,-0.0001,-0.00010,10.000
10,68.333,-0.01,-0.0001,-0.00010,10.000
10,68.400,-0.01,-0.0001,-0.00010,10.000
10,68.467,-0.01,-0.0001,-0.00010,10.000
10,68.533,-0.01,-0.0001,-0.00010,10.000
10,68.600,-0.02,-0.0001,-0.00010,10.000
10,68.667,-0.01,-0.0001,-0.00010,10.000
10,68.733,-0.01,-0.0001,-0.00010,10.000
10,68.867,-0.01,-0.0001,-0.00010,10.000