File: calibDATA_loadcell/date_02:15:2018/Instron_02.15.2018/2_20N_0__3mm.s_0_0.txt
""
"Test Method","Radhen_Load_Cntrl_Cmprsn_250N_12-7.msm"
"Sample I. D.","Sample1.mss"
"Specimen Number","23"

"TheCycle_Output ()","_Time (s)","_Load (N)","_Extension (mm)","RealTimeDepth (mm)","CycleNumber ()"

1,0.333,-0.03,0.1542,0.15420,1.000
1,0.400,-0.02,0.3536,0.35360,1.000
1,0.467,-0.01,0.5535,0.55353,1.000
1,0.533,-0.02,0.7536,0.75357,1.000
1,0.600,-0.01,0.9535,0.95350,1.000
1,0.667,-0.01,1.1537,1.15370,1.000
1,0.733,-0.01,1.3536,1.35363,1.000
1,0.800,-0.01,1.5536,1.55360,1.000
1,0.867,-0.02,1.7535,1.75353,1.000
1,0.933,-0.01,1.9536,1.95363,1.000
1,1.000,-0.02,2.1536,2.15360,1.000
1,1.067,-0.01,2.3535,2.35353,1.000
1,1.133,-0.02,2.5537,2.55367,1.000
1,1.200,-0.01,2.7537,2.75370,1.000
1,1.267,-0.03,2.9536,2.95363,1.000
1,1.333,-0.01,3.1538,3.15377,1.000
1,1.400,0.00,3.3537,3.35370,1.000
1,1.467,-0.02,3.5536,3.55363,1.000
1,1.533,-0.01,3.7538,3.75377,1.000
1,1.600,-0.01,3.9536,3.95360,1.000
1,1.667,-0.01,4.1536,4.15357,1.000
1,1.733,0.01,4.3537,4.35373,1.000
1,1.800,0.08,4.5538,4.55380,1.000
1,1.867,0.28,4.7537,4.75367,1.000
1,1.933,0.75,4.9538,4.95383,1.000
1,2.000,1.47,5.1538,5.15380,1.000
1,2.067,2.48,5.3536,5.35363,1.000
1,2.133,3.78,5.5538,5.55383,1.000
1,2.200,5.41,5.7539,5.75390,1.000
1,2.267,7.40,5.9537,5.95370,1.000
1,2.333,9.83,6.1537,6.15373,1.000
1,2.400,12.75,6.3538,6.35380,1.000
1,2.467,16.23,6.5537,6.55373,1.000
1,2.533,20.44,6.7537,6.75367,1.000
1,2.667,26.82,6.9954,6.99540,1.000
1,2.733,24.89,6.9526,6.95263,1.000
1,2.800,19.62,6.7987,6.79870,1.000
1,2.867,14.01,6.5987,6.59870,1.000
1,2.933,10.06,6.3987,6.39867,1.000
1,3.000,7.17,6.1987,6.19870,1.000
1,3.067,5.07,5.9986,5.99860,1.000
1,3.133,3.54,5.7984,5.79843,1.000
1,3.200,2.37,5.5987,5.59870,1.000
1,3.267,1.49,5.3986,5.39857,1.000
1,3.333,0.83,5.1986,5.19857,1.000
1,3.400,0.39,4.9987,4.99870,1.000
1,3.467,0.09,4.7986,4.79857,1.000
1,3.533,-0.02,4.5985,4.59853,1.000
1,3.600,-0.01,4.3986,4.39860,1.000
1,3.667,-0.02,4.1986,4.19857,1.000
1,3.733,-0.02,3.9985,3.99853,1.000
1,3.800,-0.02,3.7984,3.79840,1.000
1,3.867,-0.01,3.5987,3.59870,1.000
1,3.933,-0.02,3.3986,3.39857,1.000
1,4.000,-0.02,3.1986,3.19860,1.000
1,4.067,-0.02,2.9986,2.99863,1.000
1,4.133,-0.02,2.7986,2.79857,1.000
1,4.200,-0.02,2.5984,2.59840,1.000
1,4.267,-0.02,2.3986,2.39863,1.000
1,4.333,-0.02,2.1985,2.19847,1.000
1,4.400,-0.01,1.9986,1.99860,1.000
1,4.467,-0.03,1.7985,1.79853,1.000
1,4.533,-0.01,1.5985,1.59850,1.000
1,4.600,-0.02,1.3983,1.39830,1.000
1,4.667,-0.02,1.1986,1.19857,1.000
1,4.733,-0.01,0.9985,0.99847,1.000
1,4.800,-0.01,0.7984,0.79840,1.000
1,4.867,-0.02,0.5984,0.59843,1.000
1,4.933,-0.02,0.3984,0.39840,1.000
1,5.000,-0.02,0.1983,0.19830,1.000
1,5.067,-0.02,-0.0016,-0.00160,1.000
1,5.200,-0.01,-0.2510,-0.25100,1.000
1,5.267,-0.02,-0.2123,-0.21230,1.000
1,5.333,-0.02,-0.0753,-0.07533,1.000
1,5.400,-0.01,-0.0012,-0.00120,1.000
1,5.467,-0.01,-0.0001,-0.00010,1.000
1,5.533,-0.01,-0.0001,-0.00010,1.000
1,5.600,-0.02,-0.0001,-0.00010,1.000
1,5.667,-0.02,-0.0001,-0.00010,1.000
1,5.733,-0.01,-0.0001,-0.00010,1.000
1,5.800,-0.01,-0.0001,-0.00010,1.000
1,5.867,-0.01,-0.0001,-0.00010,1.000
1,5.933,-0.01,-0.0001,-0.00010,1.000
1,6.000,-0.03,-0.0001,-0.00010,1.000
1,6.067,-0.01,-0.0001,-0.00010,1.000
1,6.133,-0.02,-0.0001,-0.00010,1.000
1,6.200,-0.03,-0.0001,-0.00010,1.000
1,6.267,-0.02,-0.0001,-0.00010,1.000
1,6.333,-0.02,-0.0001,-0.00010,1.000
1,6.400,-0.01,-0.0001,-0.00010,1.000
1,6.467,-0.02,-0.0001,-0.00010,1.000
1,6.533,-0.01,-0.0001,-0.00010,1.000
1,6.600,-0.02,-0.0001,-0.00010,1.000
1,6.667,-0.01,-0.0001,-0.00010,1.000
1,6.733,-0.02,-0.0001,-0.00010,1.000
1,6.800,-0.02,-0.0001,-0.00010,1.000
1,6.867,-0.02,-0.0001,-0.00010,1.000
1,6.933,-0.02,-0.0001,-0.00010,1.000
1,7.000,0.00,-0.0001,-0.00010,1.000
1,7.067,-0.01,-0.0001,-0.00010,1.000
1,7.133,-0.02,-0.0001,-0.00010,1.000
1,7.200,-0.01,-0.0001,-0.00010,1.000
1,7.267,-0.02,-0.0001,-0.00010,1.000
1,7.333,-0.01,-0.0001,-0.00010,1.000
1,7.400,-0.02,-0.0001,-0.00010,1.000
1,7.467,-0.02,-0.0001,-0.00010,1.000
1,7.533,-0.02,-0.0001,-0.00010,1.000
1,7.600,-0.02,-0.0001,-0.00010,1.000
1,7.667,-0.02,-0.0001,-0.00010,1.000
1,7.733,-0.02,-0.0001,-0.00010,1.000
1,7.800,-0.02,-0.0001,-0.00010,1.000
1,7.867,-0.01,-0.0001,-0.00010,1.000
1,7.933,-0.01,-0.0001,-0.00010,1.000
1,8.000,0.00,-0.0001,-0.00010,1.000
1,8.067,-0.02,-0.0001,-0.00010,1.000
1,8.133,-0.02,-0.0001,-0.00010,1.000
1,8.267,-0.02,-0.0001,-0.00010,1.000
2,8.533,0.00,0.1460,0.14603,2.000
2,8.600,0.00,0.3446,0.34460,2.000
2,8.667,0.01,0.5446,0.54457,2.000
2,8.733,0.00,0.7446,0.74460,2.000
2,8.800,0.01,0.9446,0.94460,2.000
2,8.867,0.01,1.1446,1.14463,2.000
2,8.933,-0.01,1.3446,1.34457,2.000
2,9.000,0.00,1.5446,1.54460,2.000
2,9.067,0.00,1.7446,1.74457,2.000
2,9.133,0.00,1.9447,1.94467,2.000
2,9.200,-0.01,2.1447,2.14470,2.000
2,9.267,0.01,2.3445,2.34453,2.000
2,9.333,0.00,2.5445,2.54450,2.000
2,9.400,0.00,2.7446,2.74460,2.000
2,9.467,0.00,2.9446,2.94463,2.000
2,9.533,0.00,3.1446,3.14463,2.000
2,9.600,0.01,3.3447,3.34470,2.000
2,9.667,0.00,3.5446,3.54457,2.000
2,9.733,0.00,3.7447,3.74470,2.000
2,9.800,0.00,3.9447,3.94470,2.000
2,9.867,0.01,4.1446,4.14457,2.000
2,9.933,0.01,4.3446,4.34460,2.000
2,10.000,0.06,4.5447,4.54470,2.000
2,10.067,0.26,4.7447,4.74467,2.000
2,10.133,0.70,4.9448,4.94480,2.000
2,10.200,1.40,5.1448,5.14480,2.000
2,10.267,2.38,5.3447,5.34467,2.000
2,10.333,3.63,5.5448,5.54477,2.000
2,10.400,5.24,5.7448,5.74480,2.000
2,10.467,7.23,5.9447,5.94470,2.000
2,10.533,9.63,6.1447,6.14467,2.000
2,10.600,12.52,6.3447,6.34470,2.000
2,10.667,15.98,6.5448,6.54477,2.000
2,10.733,20.15,6.7447,6.74467,2.000
2,10.867,27.05,7.0028,7.00283,2.000
2,10.933,25.45,6.9701,6.97010,2.000
2,11.000,20.38,6.8262,6.82620,2.000
2,11.067,14.57,6.6256,6.62560,2.000
2,11.133,10.46,6.4256,6.42563,2.000
2,11.200,7.48,6.2257,6.22570,2.000
2,11.267,5.29,6.0254,6.02543,2.000
2,11.333,3.73,5.8254,5.82540,2.000
2,11.400,2.51,5.6257,5.62570,2.000
2,11.467,1.60,5.4254,5.42540,2.000
2,11.533,0.91,5.2256,5.22557,2.000
2,11.600,0.44,5.0257,5.02570,2.000
2,11.667,0.13,4.8255,4.82550,2.000
2,11.733,0.00,4.6255,4.62550,2.000
2,11.800,0.01,4.4256,4.42560,2.000
2,11.867,-0.01,4.2255,4.22547,2.000
2,11.933,0.00,4.0256,4.02557,2.000
2,12.000,0.00,3.8255,3.82550,2.000
2,12.067,0.00,3.6256,3.62563,2.000
2,12.133,0.00,3.4255,3.42550,2.000
2,12.200,0.01,3.2255,3.22550,2.000
2,12.267,0.01,3.0255,3.02553,2.000
2,12.333,0.00,2.8255,2.82553,2.000
2,12.400,0.00,2.6255,2.62550,2.000
2,12.467,0.00,2.4256,2.42557,2.000
2,12.533,-0.01,2.2254,2.22543,2.000
2,12.600,0.00,2.0257,2.02570,2.000
2,12.667,0.00,1.8254,1.82543,2.000
2,12.733,0.00,1.6254,1.62540,2.000
2,12.800,-0.01,1.4254,1.42540,2.000
2,12.867,0.00,1.2255,1.22547,2.000
2,12.933,0.00,1.0254,1.02537,2.000
2,13.000,0.00,0.8256,0.82560,2.000
2,13.067,0.00,0.6254,0.62540,2.000
2,13.133,0.00,0.4254,0.42540,2.000
2,13.200,0.01,0.2253,0.22530,2.000
2,13.267,0.00,0.0254,0.02537,2.000
2,13.400,0.01,-0.2502,-0.25020,2.000
2,13.467,0.00,-0.2282,-0.22823,2.000
2,13.533,0.00,-0.0982,-0.09823,2.000
2,13.600,0.01,-0.0059,-0.00590,2.000
2,13.667,0.00,-0.0001,-0.00010,2.000
2,13.733,0.00,-0.0001,-0.00010,2.000
2,13.800,0.00,-0.0001,-0.00010,2.000
2,13.867,0.00,-0.0001,-0.00010,2.000
2,13.933,-0.01,-0.0001,-0.00010,2.000
2,14.000,0.00,-0.0001,-0.00010,2.000
2,14.067,0.00,-0.0001,-0.00010,2.000
2,14.133,0.00,-0.0001,-0.00010,2.000
2,14.200,0.00,-0.0001,-0.00010,2.000
2,14.267,-0.01,-0.0001,-0.00010,2.000
2,14.333,0.00,-0.0001,-0.00010,2.000
2,14.400,0.01,-0.0001,-0.00010,2.000
2,14.467,0.00,-0.0001,-0.00010,2.000
2,14.533,0.00,-0.0001,-0.00010,2.000
2,14.600,0.00,-0.0001,-0.00010,2.000
2,14.667,0.00,-0.0001,-0.00010,2.000
2,14.733,0.01,-0.0001,-0.00010,2.000
2,14.800,0.01,-0.0001,-0.00010,2.000
2,14.867,0.00,-0.0001,-0.00010,2.000
2,14.933,0.01,-0.0001,-0.00010,2.000
2,15.000,0.00,-0.0001,-0.00010,2.000
2,15.067,0.00,-0.0001,-0.00010,2.000
2,15.133,0.00,-0.0001,-0.00010,2.000
2,15.200,-0.01,-0.0001,-0.00010,2.000
2,15.267,0.00,-0.0001,-0.00010,2.000
2,15.333,0.00,-0.0001,-0.00010,2.000
2,15.400,0.00,-0.0001,-0.00010,2.000
2,15.467,0.00,-0.0001,-0.00010,2.000
2,15.533,0.00,-0.0001,-0.00010,2.000
2,15.600,0.01,-0.0001,-0.00010,2.000
2,15.667,0.00,-0.0001,-0.00010,2.000
2,15.733,0.00,-0.0001,-0.00010,2.000
2,15.800,-0.01,-0.0001,-0.00010,2.000
2,15.867,0.00,-0.0001,-0.00010,2.000
2,15.933,0.01,-0.0001,-0.00010,2.000
2,16.000,0.00,-0.0001,-0.00010,2.000
2,16.067,0.00,-0.0001,-0.00010,2.000
2,16.133,0.00,-0.0001,-0.00010,2.000
2,16.200,0.00,-0.0001,-0.00010,2.000
2,16.267,0.00,-0.0001,-0.00010,2.000
2,16.333,0.00,-0.0001,-0.00010,2.000
2,16.467,0.00,-0.0001,-0.00010,2.000
3,16.733,0.01,0.0840,0.08403,3.000
3,16.800,0.01,0.2666,0.26660,3.000
3,16.867,0.02,0.4666,0.46660,3.000
3,16.933,0.01,0.6666,0.66660,3.000
3,17.000,0.02,0.8666,0.86660,3.000
3,17.067,0.01,1.0666,1.06657,3.000
3,17.133,0.01,1.2667,1.26667,3.000
3,17.200,0.01,1.4667,1.46670,3.000
3,17.267,0.01,1.6666,1.66657,3.000
3,17.333,0.01,1.8665,1.86653,3.000
3,17.400,0.01,2.0667,2.06670,3.000
3,17.467,0.02,2.2665,2.26653,3.000
3,17.533,0.01,2.4665,2.46653,3.000
3,17.600,0.01,2.6665,2.66650,3.000
3,17.667,0.01,2.8667,2.86667,3.000
3,17.733,0.01,3.0667,3.06667,3.000
3,17.800,0.01,3.2668,3.26680,3.000
3,17.867,0.01,3.4666,3.46657,3.000
3,17.933,0.00,3.6667,3.66673,3.000
3,18.000,0.01,3.8666,3.86660,3.000
3,18.067,0.01,4.0666,4.06657,3.000
3,18.133,0.03,4.2667,4.26667,3.000
3,18.200,0.05,4.4668,4.46680,3.000
3,18.267,0.17,4.6667,4.66670,3.000
3,18.333,0.49,4.8666,4.86663,3.000
3,18.400,1.08,5.0668,5.06680,3.000
3,18.467,1.95,5.2668,5.26677,3.000
3,18.533,3.12,5.4667,5.46667,3.000
3,18.600,4.57,5.6669,5.66690,3.000
3,18.667,6.42,5.8667,5.86667,3.000
3,18.733,8.64,6.0666,6.06660,3.000
3,18.800,11.32,6.2667,6.26670,3.000
3,18.867,14.56,6.4667,6.46670,3.000
3,18.933,18.44,6.6666,6.66663,3.000
3,19.067,26.87,6.9935,6.99347,3.000
3,19.133,27.02,7.0105,7.01050,3.000
3,19.200,23.31,6.9168,6.91680,3.000
3,19.267,17.17,6.7276,6.72763,3.000
3,19.333,12.32,6.5276,6.52760,3.000
3,19.400,8.84,6.3276,6.32760,3.000
3,19.467,6.29,6.1276,6.12760,3.000
3,19.533,4.45,5.9275,5.92753,3.000
3,19.600,3.08,5.7275,5.72750,3.000
3,19.667,2.03,5.5276,5.52760,3.000
3,19.733,1.23,5.3275,5.32750,3.000
3,19.800,0.64,5.1275,5.12750,3.000
3,19.867,0.26,4.9277,4.92770,3.000
3,19.933,0.06,4.7275,4.72747,3.000
3,20.000,0.01,4.5276,4.52760,3.000
3,20.067,0.01,4.3275,4.32753,3.000
3,20.133,0.01,4.1275,4.12747,3.000
3,20.200,0.00,3.9273,3.92730,3.000
3,20.267,0.01,3.7276,3.72763,3.000
3,20.333,0.00,3.5275,3.52750,3.000
3,20.400,0.00,3.3275,3.32750,3.000
3,20.467,0.00,3.1275,3.12753,3.000
3,20.533,0.01,2.9275,2.92747,3.000
3,20.600,0.01,2.7275,2.72750,3.000
3,20.667,0.01,2.5274,2.52743,3.000
3,20.733,0.02,2.3276,2.32760,3.000
3,20.800,0.01,2.1275,2.12750,3.000
3,20.867,0.00,1.9274,1.92743,3.000
3,20.933,0.01,1.7275,1.72753,3.000
3,21.000,0.00,1.5274,1.52740,3.000
3,21.067,0.00,1.3273,1.32733,3.000
3,21.133,0.01,1.1275,1.12753,3.000
3,21.200,0.00,0.9274,0.92740,3.000
3,21.267,0.01,0.7274,0.72740,3.000
3,21.333,0.01,0.5275,0.52747,3.000
3,21.400,0.01,0.3273,0.32730,3.000
3,21.467,0.00,0.1272,0.12723,3.000
3,21.667,0.01,-0.2724,-0.27243,3.000
3,21.733,0.01,-0.2063,-0.20630,3.000
3,21.800,0.01,-0.0593,-0.05930,3.000
3,21.867,0.01,-0.0001,-0.00013,3.000
3,21.933,0.01,-0.0002,-0.00020,3.000
3,22.000,0.02,-0.0002,-0.00020,3.000
3,22.067,0.01,-0.0002,-0.00020,3.000
3,22.133,0.01,-0.0002,-0.00020,3.000
3,22.200,0.01,-0.0002,-0.00020,3.000
3,22.267,0.01,-0.0002,-0.00020,3.000
3,22.333,0.01,-0.0002,-0.00020,3.000
3,22.400,0.01,-0.0002,-0.00020,3.000
3,22.467,0.01,-0.0002,-0.00020,3.000
3,22.533,0.01,-0.0002,-0.00020,3.000
3,22.600,0.01,-0.0002,-0.00020,3.000
3,22.667,0.01,-0.0002,-0.00020,3.000
3,22.733,0.01,-0.0002,-0.00020,3.000
3,22.800,0.02,-0.0002,-0.00020,3.000
3,22.867,0.01,-0.0002,-0.00020,3.000
3,22.933,0.01,-0.0002,-0.00020,3.000
3,23.000,0.01,-0.0001,-0.00010,3.000
3,23.067,0.01,-0.0001,-0.00010,3.000
3,23.133,0.01,-0.0001,-0.00010,3.000
3,23.200,0.02,-0.0001,-0.00010,3.000
3,23.267,0.01,-0.0001,-0.00010,3.000
3,23.333,0.01,-0.0001,-0.00010,3.000
3,23.400,0.01,-0.0001,-0.00010,3.000
3,23.467,0.01,-0.0001,-0.00010,3.000
3,23.533,0.01,-0.0001,-0.00010,3.000
3,23.600,0.01,-0.0001,-0.00010,3.000
3,23.667,0.01,-0.0001,-0.00010,3.000
3,23.733,0.00,-0.0001,-0.00010,3.000
3,23.800,0.02,-0.0001,-0.00010,3.000
3,23.867,0.01,-0.0001,-0.00010,3.000
3,23.933,0.02,-0.0001,-0.00010,3.000
3,24.000,0.02,-0.0001,-0.00010,3.000
3,24.067,0.01,-0.0001,-0.00010,3.000
3,24.133,0.01,-0.0001,-0.00010,3.000
3,24.200,0.00,-0.0001,-0.00010,3.000
3,24.267,0.01,-0.0001,-0.00010,3.000
3,24.333,0.01,-0.0001,-0.00010,3.000
3,24.400,0.02,-0.0001,-0.00010,3.000
3,24.467,0.01,-0.0001,-0.00010,3.000
3,24.533,0.01,-0.0001,-0.00010,3.000
3,24.600,0.01,-0.0001,-0.00010,3.000
4,25.000,-0.03,0.1216,0.12160,4.000
4,25.067,-0.02,0.3166,0.31657,4.000
4,25.133,-0.01,0.5166,0.51657,4.000
4,25.200,0.00,0.7166,0.71660,4.000
4,25.267,-0.02,0.9166,0.91660,4.000
4,25.333,-0.01,1.1168,1.11677,4.000
4,25.400,-0.02,1.3166,1.31660,4.000
4,25.467,-0.02,1.5165,1.51650,4.000
4,25.533,-0.02,1.7166,1.71660,4.000
4,25.600,-0.01,1.9166,1.91660,4.000
4,25.667,-0.01,2.1166,2.11663,4.000
4,25.733,-0.01,2.3167,2.31667,4.000
4,25.800,-0.02,2.5166,2.51660,4.000
4,25.867,-0.01,2.7166,2.71660,4.000
4,25.933,-0.02,2.9166,2.91660,4.000
4,26.000,-0.01,3.1166,3.11660,4.000
4,26.067,-0.02,3.3167,3.31667,4.000
4,26.133,-0.01,3.5166,3.51663,4.000
4,26.200,-0.01,3.7168,3.71680,4.000
4,26.267,-0.01,3.9166,3.91657,4.000
4,26.333,-0.01,4.1166,4.11663,4.000
4,26.400,-0.01,4.3168,4.31680,4.000
4,26.467,0.03,4.5167,4.51670,4.000
4,26.533,0.20,4.7167,4.71667,4.000
4,26.600,0.59,4.9168,4.91680,4.000
4,26.667,1.25,5.1168,5.11677,4.000
4,26.733,2.18,5.3167,5.31670,4.000
4,26.800,3.40,5.5167,5.51670,4.000
4,26.867,4.96,5.7168,5.71680,4.000
4,26.933,6.88,5.9167,5.91667,4.000
4,27.000,9.21,6.1166,6.11660,4.000
4,27.067,12.04,6.3167,6.31667,4.000
4,27.133,15.41,6.5167,6.51670,4.000
4,27.200,19.48,6.7167,6.71670,4.000
4,27.333,27.65,7.0217,7.02173,4.000
4,27.400,27.16,7.0211,7.02110,4.000
4,27.467,22.80,6.9091,6.90907,4.000
4,27.533,16.56,6.7136,6.71357,4.000
4,27.600,11.89,6.5136,6.51360,4.000
4,27.667,8.52,6.3136,6.31357,4.000
4,27.733,6.07,6.1136,6.11357,4.000
4,27.800,4.28,5.9137,5.91370,4.000
4,27.867,2.95,5.7136,5.71363,4.000
4,27.933,1.93,5.5135,5.51350,4.000
4,28.000,1.15,5.3136,5.31360,4.000
4,28.067,0.60,5.1136,5.11360,4.000
4,28.133,0.21,4.9136,4.91360,4.000
4,28.200,0.02,4.7135,4.71350,4.000
4,28.267,-0.02,4.5136,4.51360,4.000
4,28.333,-0.02,4.3136,4.31357,4.000
4,28.400,-0.01,4.1135,4.11350,4.000
4,28.467,-0.01,3.9135,3.91347,4.000
4,28.533,-0.01,3.7135,3.71353,4.000
4,28.600,-0.01,3.5135,3.51350,4.000
4,28.667,-0.01,3.3136,3.31357,4.000
4,28.733,-0.01,3.1135,3.11350,4.000
4,28.800,-0.01,2.9135,2.91350,4.000
4,28.867,-0.01,2.7135,2.71350,4.000
4,28.933,-0.02,2.5135,2.51350,4.000
4,29.000,-0.02,2.3135,2.31350,4.000
4,29.067,-0.01,2.1136,2.11363,4.000
4,29.133,-0.02,1.9134,1.91343,4.000
4,29.200,-0.01,1.7135,1.71350,4.000
4,29.267,-0.02,1.5135,1.51347,4.000
4,29.333,-0.02,1.3133,1.31333,4.000
4,29.400,-0.02,1.1135,1.11350,4.000
4,29.467,-0.01,0.9135,0.91350,4.000
4,29.533,-0.01,0.7134,0.71340,4.000
4,29.600,-0.01,0.5134,0.51340,4.000
4,29.667,-0.02,0.3134,0.31340,4.000
4,29.733,0.00,0.1133,0.11327,4.000
4,29.800,-0.02,-0.0865,-0.08650,4.000
4,29.933,-0.01,-0.2969,-0.29687,4.000
4,30.000,-0.01,-0.2365,-0.23650,4.000
4,30.067,-0.03,-0.0828,-0.08280,4.000
4,30.133,-0.02,-0.0027,-0.00270,4.000
4,30.200,-0.02,-0.0002,-0.00020,4.000
4,30.267,-0.01,-0.0002,-0.00020,4.000
4,30.333,-0.01,-0.0002,-0.00020,4.000
4,30.400,-0.02,-0.0002,-0.00020,4.000
4,30.467,-0.01,-0.0002,-0.00020,4.000
4,30.533,-0.02,-0.0002,-0.00020,4.000
4,30.600,-0.01,-0.0002,-0.00020,4.000
4,30.667,-0.02,-0.0002,-0.00020,4.000
4,30.733,-0.02,-0.0002,-0.00020,4.000
4,30.800,-0.02,-0.0002,-0.00020,4.000
4,30.867,-0.02,-0.0002,-0.00020,4.000
4,30.933,-0.01,-0.0002,-0.00020,4.000
4,31.000,-0.01,-0.0002,-0.00020,4.000
4,31.067,-0.02,-0.0002,-0.00020,4.000
4,31.133,-0.01,-0.0002,-0.00020,4.000
4,31.200,-0.01,-0.0001,-0.00010,4.000
4,31.267,-0.02,-0.0001,-0.00010,4.000
4,31.333,-0.01,-0.0001,-0.00010,4.000
4,31.400,-0.01,-0.0001,-0.00010,4.000
4,31.467,-0.02,-0.0001,-0.00010,4.000
4,31.533,-0.01,-0.0001,-0.00010,4.000
4,31.600,-0.03,-0.0001,-0.00010,4.000
4,31.667,-0.01,-0.0001,-0.00010,4.000
4,31.733,-0.01,-0.0001,-0.00010,4.000
4,31.800,-0.02,-0.0001,-0.00010,4.000
4,31.867,-0.01,-0.0001,-0.00010,4.000
4,31.933,-0.01,-0.0001,-0.00010,4.000
4,32.000,-0.01,-0.0001,-0.00010,4.000
4,32.067,-0.01,-0.0001,-0.00010,4.000
4,32.133,-0.01,-0.0001,-0.00010,4.000
4,32.200,-0.01,-0.0001,-0.00010,4.000
4,32.267,-0.01,-0.0001,-0.00010,4.000
4,32.333,-0.01,-0.0001,-0.00010,4.000
4,32.400,-0.01,-0.0001,-0.00010,4.000
4,32.467,-0.01,-0.0001,-0.00010,4.000
4,32.533,-0.02,-0.0001,-0.00010,4.000
4,32.600,-0.01,-0.0001,-0.00010,4.000
4,32.667,-0.02,-0.0001,-0.00010,4.000
4,32.733,-0.02,-0.0001,-0.00010,4.000
4,32.800,-0.01,-0.0001,-0.00010,4.000
4,32.867,-0.02,-0.0001,-0.00010,4.000
5,33.267,0.01,0.1388,0.13880,5.000
5,33.333,0.03,0.3365,0.33650,5.000
5,33.400,0.02,0.5365,0.53650,5.000
5,33.467,0.02,0.7366,0.73657,5.000
5,33.533,0.02,0.9365,0.93653,5.000
5,33.600,0.02,1.1368,1.13680,5.000
5,33.667,0.01,1.3367,1.33667,5.000
5,33.733,0.01,1.5365,1.53653,5.000
5,33.800,0.01,1.7367,1.73670,5.000
5,33.867,0.02,1.9366,1.93657,5.000
5,33.933,0.01,2.1366,2.13660,5.000
5,34.000,0.01,2.3366,2.33660,5.000
5,34.067,0.02,2.5366,2.53663,5.000
5,34.133,0.02,2.7366,2.73663,5.000
5,34.200,0.01,2.9367,2.93670,5.000
5,34.267,0.01,3.1367,3.13673,5.000
5,34.333,0.01,3.3366,3.33663,5.000
5,34.400,0.02,3.5367,3.53670,5.000
5,34.467,0.01,3.7368,3.73680,5.000
5,34.533,0.01,3.9365,3.93653,5.000
5,34.600,0.02,4.1366,4.13660,5.000
5,34.667,0.03,4.3368,4.33677,5.000
5,34.733,0.06,4.5367,4.53673,5.000
5,34.800,0.25,4.7366,4.73660,5.000
5,34.867,0.66,4.9367,4.93670,5.000
5,34.933,1.34,5.1367,5.13673,5.000
5,35.000,2.31,5.3366,5.33660,5.000
5,35.067,3.57,5.5368,5.53677,5.000
5,35.133,5.16,5.7368,5.73680,5.000
5,35.200,7.12,5.9367,5.93670,5.000
5,35.267,9.50,6.1367,6.13670,5.000
5,35.333,12.38,6.3367,6.33670,5.000
5,35.400,15.83,6.5366,6.53660,5.000
5,35.467,19.97,6.7367,6.73670,5.000
5,35.600,26.61,6.9861,6.98610,5.000
5,35.667,24.83,6.9475,6.94750,5.000
5,35.733,19.71,6.7978,6.79777,5.000
5,35.800,14.08,6.5976,6.59760,5.000
5,35.867,10.11,6.3976,6.39760,5.000
5,35.933,7.21,6.1976,6.19763,5.000
5,36.000,5.11,5.9976,5.99760,5.000
5,36.067,3.57,5.7975,5.79747,5.000
5,36.133,2.39,5.5977,5.59767,5.000
5,36.200,1.50,5.3975,5.39750,5.000
5,36.267,0.83,5.1976,5.19763,5.000
5,36.333,0.38,4.9975,4.99753,5.000
5,36.400,0.13,4.7975,4.79750,5.000
5,36.467,0.02,4.5975,4.59753,5.000
5,36.533,0.00,4.3975,4.39750,5.000
5,36.600,0.01,4.1975,4.19750,5.000
5,36.667,0.01,3.9975,3.99753,5.000
5,36.733,0.02,3.7975,3.79747,5.000
5,36.800,0.01,3.5975,3.59750,5.000
5,36.867,0.01,3.3975,3.39750,5.000
5,36.933,0.01,3.1974,3.19743,5.000
5,37.000,0.01,2.9975,2.99750,5.000
5,37.067,0.02,2.7976,2.79763,5.000
5,37.133,0.01,2.5974,2.59740,5.000
5,37.200,0.01,2.3975,2.39750,5.000
5,37.267,0.02,2.1975,2.19753,5.000
5,37.333,0.01,1.9975,1.99750,5.000
5,37.400,0.01,1.7974,1.79740,5.000
5,37.467,0.01,1.5974,1.59743,5.000
5,37.533,0.01,1.3974,1.39737,5.000
5,37.600,0.02,1.1974,1.19740,5.000
5,37.667,0.01,0.9974,0.99743,5.000
5,37.733,0.01,0.7974,0.79740,5.000
5,37.800,0.02,0.5973,0.59730,5.000
5,37.867,0.01,0.3975,0.39747,5.000
5,37.933,0.01,0.1973,0.19733,5.000
5,38.000,0.02,-0.0027,-0.00270,5.000
5,38.133,0.01,-0.2424,-0.24240,5.000
5,38.200,0.02,-0.1987,-0.19870,5.000
5,38.267,0.01,-0.0617,-0.06170,5.000
5,38.333,0.02,0.0017,0.00173,5.000
5,38.400,0.02,-0.0001,-0.00010,5.000
5,38.467,0.01,-0.0001,-0.00010,5.000
5,38.533,0.01,-0.0001,-0.00010,5.000
5,38.600,0.02,-0.0001,-0.00010,5.000
5,38.667,0.01,-0.0001,-0.00010,5.000
5,38.733,0.01,-0.0001,-0.00010,5.000
5,38.800,0.01,-0.0001,-0.00010,5.000
5,38.867,0.02,-0.0001,-0.00010,5.000
5,38.933,0.02,-0.0001,-0.00010,5.000
5,39.000,0.01,-0.0001,-0.00010,5.000
5,39.067,0.01,-0.0001,-0.00010,5.000
5,39.133,0.02,-0.0001,-0.00010,5.000
5,39.200,0.01,-0.0001,-0.00010,5.000
5,39.267,0.01,-0.0001,-0.00010,5.000
5,39.333,0.01,-0.0001,-0.00010,5.000
5,39.400,0.01,-0.0001,-0.00010,5.000
5,39.467,0.01,-0.0001,-0.00010,5.000
5,39.533,0.01,-0.0001,-0.00010,5.000
5,39.600,0.02,-0.0001,-0.00010,5.000
5,39.667,0.01,-0.0001,-0.00010,5.000
5,39.733,0.01,-0.0001,-0.00010,5.000
5,39.800,0.01,-0.0001,-0.00010,5.000
5,39.867,0.02,-0.0001,-0.00010,5.000
5,39.933,0.01,-0.0001,-0.00010,5.000
5,40.000,0.01,-0.0001,-0.00010,5.000
5,40.067,0.01,-0.0001,-0.00010,5.000
5,40.133,0.01,-0.0001,-0.00010,5.000
5,40.200,0.02,-0.0001,-0.00010,5.000
5,40.267,0.01,-0.0001,-0.00010,5.000
5,40.333,0.01,-0.0001,-0.00010,5.000
5,40.400,0.02,-0.0001,-0.00010,5.000
5,40.467,0.01,-0.0001,-0.00010,5.000
5,40.533,0.02,-0.0001,-0.00010,5.000
5,40.600,0.01,-0.0001,-0.00010,5.000
5,40.667,0.01,-0.0001,-0.00010,5.000
5,40.733,0.01,-0.0001,-0.00010,5.000
5,40.800,0.01,-0.0001,-0.00010,5.000
5,40.867,0.02,-0.0001,-0.00010,5.000
5,40.933,0.02,-0.0001,-0.00010,5.000
5,41.000,0.02,-0.0001,-0.00010,5.000
5,41.067,0.01,-0.0001,-0.00010,5.000
6,41.467,0.00,0.1813,0.18133,6.000
6,41.533,0.00,0.3815,0.38147,6.000
6,41.600,0.00,0.5816,0.58160,6.000
6,41.667,0.00,0.7816,0.78163,6.000
6,41.733,0.00,0.9815,0.98153,6.000
6,41.800,0.00,1.1818,1.18180,6.000
6,41.867,0.00,1.3816,1.38157,6.000
6,41.933,0.00,1.5815,1.58153,6.000
6,42.000,0.00,1.7815,1.78150,6.000
6,42.067,0.00,1.9816,1.98157,6.000
6,42.133,0.00,2.1816,2.18157,6.000
6,42.200,0.00,2.3817,2.38170,6.000
6,42.267,0.00,2.5816,2.58157,6.000
6,42.333,0.00,2.7817,2.78170,6.000
6,42.400,0.00,2.9817,2.98170,6.000
6,42.467,0.00,3.1817,3.18167,6.000
6,42.533,0.00,3.3816,3.38157,6.000
6,42.600,0.00,3.5817,3.58170,6.000
6,42.667,0.00,3.7817,3.78173,6.000
6,42.733,0.00,3.9816,3.98160,6.000
6,42.800,0.01,4.1817,4.18170,6.000
6,42.867,0.02,4.3817,4.38170,6.000
6,42.933,0.08,4.5817,4.58167,6.000
6,43.000,0.30,4.7816,4.78160,6.000
6,43.067,0.77,4.9818,4.98180,6.000
6,43.133,1.51,5.1818,5.18177,6.000
6,43.200,2.55,5.3816,5.38160,6.000
6,43.267,3.87,5.5819,5.58187,6.000
6,43.333,5.55,5.7816,5.78163,6.000
6,43.400,7.59,5.9816,5.98160,6.000
6,43.467,10.09,6.1817,6.18170,6.000
6,43.533,13.09,6.3817,6.38170,6.000
6,43.600,16.68,6.5816,6.58160,6.000
6,43.667,21.00,6.7817,6.78173,6.000
6,43.800,27.02,7.0023,7.00230,6.000
6,43.867,24.64,6.9471,6.94713,6.000
6,43.933,19.07,6.7825,6.78253,6.000
6,44.000,13.63,6.5827,6.58270,6.000
6,44.067,9.77,6.3826,6.38257,6.000
6,44.133,6.96,6.1827,6.18267,6.000
6,44.200,4.92,5.9825,5.98250,6.000
6,44.267,3.43,5.7825,5.78247,6.000
6,44.333,2.29,5.5826,5.58263,6.000
6,44.400,1.42,5.3825,5.38250,6.000
6,44.467,0.77,5.1825,5.18253,6.000
6,44.533,0.33,4.9827,4.98270,6.000
6,44.600,0.09,4.7825,4.78250,6.000
6,44.667,-0.01,4.5826,4.58263,6.000
6,44.733,0.00,4.3826,4.38260,6.000
6,44.800,0.00,4.1825,4.18250,6.000
6,44.867,-0.01,3.9824,3.98243,6.000
6,44.933,0.00,3.7825,3.78250,6.000
6,45.000,0.00,3.5826,3.58260,6.000
6,45.067,0.00,3.3825,3.38250,6.000
6,45.133,0.00,3.1826,3.18260,6.000
6,45.200,0.00,2.9825,2.98250,6.000
6,45.267,0.01,2.7825,2.78250,6.000
6,45.333,0.00,2.5824,2.58243,6.000
6,45.400,0.00,2.3826,2.38260,6.000
6,45.467,0.00,2.1824,2.18237,6.000
6,45.533,-0.01,1.9825,1.98253,6.000
6,45.600,0.01,1.7825,1.78250,6.000
6,45.667,0.01,1.5824,1.58237,6.000
6,45.733,0.00,1.3823,1.38230,6.000
6,45.800,0.00,1.1826,1.18260,6.000
6,45.867,-0.01,0.9824,0.98237,6.000
6,45.933,-0.01,0.7824,0.78240,6.000
6,46.000,0.00,0.5825,0.58250,6.000
6,46.067,0.00,0.3823,0.38233,6.000
6,46.133,0.00,0.1824,0.18237,6.000
6,46.200,0.00,-0.0175,-0.01750,6.000
6,46.333,0.00,-0.2575,-0.25750,6.000
6,46.400,0.00,-0.2138,-0.21380,6.000
6,46.467,0.00,-0.0727,-0.07273,6.000
6,46.533,0.00,0.0007,0.00067,6.000
6,46.600,0.00,-0.0001,-0.00010,6.000
6,46.667,0.00,-0.0001,-0.00010,6.000
6,46.733,0.00,-0.0001,-0.00010,6.000
6,46.800,0.00,-0.0001,-0.00010,6.000
6,46.867,0.00,-0.0001,-0.00010,6.000
6,46.933,0.00,-0.0001,-0.00010,6.000
6,47.000,0.00,-0.0001,-0.00010,6.000
6,47.067,0.00,-0.0001,-0.00010,6.000
6,47.133,0.00,-0.0001,-0.00010,6.000
6,47.200,0.00,-0.0001,-0.00010,6.000
6,47.267,0.00,-0.0001,-0.00010,6.000
6,47.333,0.00,-0.0001,-0.00010,6.000
6,47.400,0.00,-0.0001,-0.00010,6.000
6,47.467,0.00,-0.0001,-0.00010,6.000
6,47.533,0.01,-0.0001,-0.00010,6.000
6,47.600,0.00,-0.0001,-0.00010,6.000
6,47.667,0.00,-0.0001,-0.00010,6.000
6,47.733,0.00,-0.0001,-0.00010,6.000
6,47.800,0.00,-0.0001,-0.00010,6.000
6,47.867,0.00,-0.0001,-0.00010,6.000
6,47.933,0.00,-0.0001,-0.00010,6.000
6,48.000,0.00,-0.0001,-0.00010,6.000
6,48.067,0.00,-0.0001,-0.00010,6.000
6,48.133,0.00,-0.0001,-0.00010,6.000
6,48.200,0.00,-0.0001,-0.00010,6.000
6,48.267,0.00,-0.0001,-0.00010,6.000
6,48.333,0.00,-0.0001,-0.00010,6.000
6,48.400,0.00,-0.0001,-0.00010,6.000
6,48.467,0.00,-0.0001,-0.00010,6.000
6,48.533,0.01,-0.0001,-0.00010,6.000
6,48.600,0.00,-0.0001,-0.00010,6.000
6,48.667,0.00,-0.0001,-0.00010,6.000
6,48.733,0.00,-0.0001,-0.00010,6.000
6,48.800,0.00,-0.0001,-0.00010,6.000
6,48.867,0.00,-0.0001,-0.00010,6.000
6,48.933,0.01,-0.0001,-0.00010,6.000
6,49.000,0.00,-0.0001,-0.00010,6.000
6,49.067,0.00,-0.0001,-0.00010,6.000
6,49.133,0.00,-0.0001,-0.00010,6.000
6,49.200,0.00,-0.0001,-0.00010,6.000
6,49.267,-0.01,-0.0001,-0.00010,6.000
6,49.400,-0.01,-0.0001,-0.00010,6.000
7,49.667,0.00,0.1551,0.15513,7.000
7,49.733,0.00,0.3546,0.35457,7.000
7,49.800,-0.01,0.5546,0.55460,7.000
7,49.867,0.00,0.7546,0.75463,7.000
7,49.933,0.00,0.9547,0.95467,7.000
7,50.000,0.00,1.1547,1.15470,7.000
7,50.067,-0.01,1.3545,1.35447,7.000
7,50.133,0.00,1.5546,1.55457,7.000
7,50.200,-0.01,1.7546,1.75460,7.000
7,50.267,0.00,1.9545,1.95453,7.000
7,50.333,0.00,2.1547,2.15467,7.000
7,50.400,0.00,2.3546,2.35460,7.000
7,50.467,0.00,2.5545,2.55450,7.000
7,50.533,0.00,2.7546,2.75460,7.000
7,50.600,-0.01,2.9545,2.95450,7.000
7,50.667,0.00,3.1547,3.15467,7.000
7,50.733,0.00,3.3547,3.35467,7.000
7,50.800,0.00,3.5547,3.55470,7.000
7,50.867,0.00,3.7547,3.75467,7.000
7,50.933,0.00,3.9545,3.95453,7.000
7,51.000,0.01,4.1546,4.15460,7.000
7,51.067,0.02,4.3546,4.35460,7.000
7,51.133,0.06,4.5547,4.55467,7.000
7,51.200,0.24,4.7547,4.75470,7.000
7,51.267,0.69,4.9548,4.95477,7.000
7,51.333,1.39,5.1548,5.15477,7.000
7,51.400,2.37,5.3547,5.35470,7.000
7,51.467,3.65,5.5547,5.55470,7.000
7,51.533,5.28,5.7547,5.75470,7.000
7,51.600,7.27,5.9548,5.95480,7.000
7,51.667,9.71,6.1546,6.15463,7.000
7,51.733,12.64,6.3546,6.35460,7.000
7,51.800,16.15,6.5548,6.55480,7.000
7,51.867,20.36,6.7547,6.75467,7.000
7,52.000,27.11,7.0040,7.00400,7.000
7,52.067,25.32,6.9655,6.96547,7.000
7,52.133,20.10,6.8158,6.81580,7.000
7,52.200,14.35,6.6156,6.61560,7.000
7,52.267,10.30,6.4156,6.41563,7.000
7,52.333,7.36,6.2156,6.21563,7.000
7,52.400,5.20,6.0155,6.01550,7.000
7,52.467,3.65,5.8154,5.81543,7.000
7,52.533,2.45,5.6157,5.61570,7.000
7,52.600,1.54,5.4154,5.41540,7.000
7,52.667,0.87,5.2156,5.21557,7.000
7,52.733,0.39,5.0156,5.01563,7.000
7,52.800,0.10,4.8155,4.81550,7.000
7,52.867,-0.01,4.6155,4.61550,7.000
7,52.933,0.00,4.4156,4.41557,7.000
7,53.000,-0.01,4.2154,4.21540,7.000
7,53.067,0.00,4.0155,4.01553,7.000
7,53.133,0.00,3.8155,3.81550,7.000
7,53.200,0.00,3.6155,3.61550,7.000
7,53.267,-0.01,3.4155,3.41550,7.000
7,53.333,0.00,3.2155,3.21553,7.000
7,53.400,0.00,3.0155,3.01550,7.000
7,53.467,0.00,2.8155,2.81547,7.000
7,53.533,0.00,2.6154,2.61540,7.000
7,53.600,0.00,2.4156,2.41560,7.000
7,53.667,0.00,2.2154,2.21543,7.000
7,53.733,0.00,2.0156,2.01560,7.000
7,53.800,-0.02,1.8154,1.81540,7.000
7,53.867,0.00,1.6154,1.61537,7.000
7,53.933,-0.01,1.4154,1.41543,7.000
7,54.000,0.00,1.2154,1.21540,7.000
7,54.067,0.01,1.0153,1.01533,7.000
7,54.133,0.00,0.8155,0.81553,7.000
7,54.200,0.00,0.6154,0.61540,7.000
7,54.267,0.00,0.4153,0.41533,7.000
7,54.333,0.00,0.2155,0.21547,7.000
7,54.400,0.00,0.0152,0.01520,7.000
7,54.533,0.00,-0.2541,-0.25407,7.000
7,54.600,0.00,-0.2287,-0.22870,7.000
7,54.667,0.00,-0.0957,-0.09570,7.000
7,54.733,0.00,-0.0040,-0.00397,7.000
7,54.800,0.01,-0.0001,-0.00010,7.000
7,54.867,0.01,-0.0001,-0.00010,7.000
7,54.933,0.00,-0.0001,-0.00010,7.000
7,55.000,0.00,-0.0001,-0.00010,7.000
7,55.067,0.00,-0.0001,-0.00010,7.000
7,55.133,0.00,-0.0001,-0.00010,7.000
7,55.200,-0.01,-0.0001,-0.00010,7.000
7,55.267,0.00,-0.0001,-0.00010,7.000
7,55.333,0.00,-0.0001,-0.00010,7.000
7,55.400,0.00,-0.0001,-0.00010,7.000
7,55.467,0.00,-0.0001,-0.00010,7.000
7,55.533,0.00,-0.0001,-0.00010,7.000
7,55.600,-0.01,-0.0001,-0.00010,7.000
7,55.667,0.00,-0.0001,-0.00010,7.000
7,55.733,0.00,-0.0001,-0.00010,7.000
7,55.800,0.00,-0.0001,-0.00010,7.000
7,55.867,0.00,-0.0001,-0.00010,7.000
7,55.933,0.00,-0.0001,-0.00010,7.000
7,56.000,0.00,-0.0001,-0.00010,7.000
7,56.067,0.00,-0.0001,-0.00010,7.000
7,56.133,0.00,-0.0001,-0.00010,7.000
7,56.200,0.00,-0.0001,-0.00010,7.000
7,56.267,0.00,-0.0001,-0.00010,7.000
7,56.333,0.00,-0.0001,-0.00010,7.000
7,56.400,0.00,-0.0001,-0.00010,7.000
7,56.467,0.00,-0.0001,-0.00010,7.000
7,56.533,0.00,-0.0001,-0.00010,7.000
7,56.600,0.00,-0.0001,-0.00010,7.000
7,56.667,0.00,-0.0001,-0.00010,7.000
7,56.733,0.00,-0.0001,-0.00010,7.000
7,56.800,0.00,-0.0001,-0.00010,7.000
7,56.867,0.00,-0.0001,-0.00010,7.000
7,56.933,0.00,-0.0001,-0.00010,7.000
7,57.000,0.00,-0.0001,-0.00010,7.000
7,57.067,0.00,-0.0001,-0.00010,7.000
7,57.133,0.00,-0.0001,-0.00010,7.000
7,57.200,-0.01,-0.0001,-0.00010,7.000
7,57.267,0.00,-0.0001,-0.00010,7.000
7,57.333,-0.01,-0.0001,-0.00010,7.000
7,57.400,-0.01,-0.0001,-0.00010,7.000
7,57.467,0.00,-0.0001,-0.00010,7.000
7,57.600,0.00,-0.0001,-0.00010,7.000
8,57.867,0.01,0.1388,0.13883,8.000
8,57.933,0.01,0.3365,0.33650,8.000
8,58.000,0.01,0.5365,0.53650,8.000
8,58.067,0.01,0.7366,0.73657,8.000
8,58.133,0.01,0.9366,0.93657,8.000
8,58.200,0.01,1.1367,1.13670,8.000
8,58.267,0.01,1.3366,1.33660,8.000
8,58.333,0.01,1.5365,1.53653,8.000
8,58.400,0.01,1.7365,1.73650,8.000
8,58.467,0.01,1.9365,1.93653,8.000
8,58.533,0.01,2.1365,2.13653,8.000
8,58.600,0.01,2.3366,2.33660,8.000
8,58.667,0.01,2.5366,2.53660,8.000
8,58.733,0.00,2.7366,2.73657,8.000
8,58.800,0.01,2.9367,2.93670,8.000
8,58.867,0.02,3.1367,3.13667,8.000
8,58.933,0.01,3.3367,3.33670,8.000
8,59.000,0.01,3.5366,3.53660,8.000
8,59.067,0.01,3.7367,3.73673,8.000
8,59.133,0.01,3.9365,3.93653,8.000
8,59.200,0.01,4.1366,4.13660,8.000
8,59.267,0.02,4.3367,4.33667,8.000
8,59.333,0.06,4.5367,4.53673,8.000
8,59.400,0.24,4.7366,4.73660,8.000
8,59.467,0.65,4.9368,4.93677,8.000
8,59.533,1.33,5.1368,5.13680,8.000
8,59.600,2.26,5.3366,5.33660,8.000
8,59.667,3.54,5.5368,5.53677,8.000
8,59.733,5.13,5.7368,5.73677,8.000
8,59.800,7.10,5.9367,5.93670,8.000
8,59.867,9.49,6.1367,6.13667,8.000
8,59.933,12.38,6.3367,6.33673,8.000
8,60.000,15.80,6.5365,6.53650,8.000
8,60.067,19.97,6.7367,6.73667,8.000
8,60.200,26.62,6.9861,6.98610,8.000
8,60.267,24.85,6.9475,6.94750,8.000
8,60.333,19.73,6.7978,6.79780,8.000
8,60.400,14.09,6.5976,6.59760,8.000
8,60.467,10.10,6.3976,6.39760,8.000
8,60.533,7.21,6.1976,6.19757,8.000
8,60.600,5.09,5.9975,5.99750,8.000
8,60.667,3.57,5.7974,5.79743,8.000
8,60.733,2.39,5.5977,5.59767,8.000
8,60.800,1.49,5.3975,5.39750,8.000
8,60.867,0.84,5.1976,5.19757,8.000
8,60.933,0.38,4.9976,4.99760,8.000
8,61.000,0.12,4.7976,4.79760,8.000
8,61.067,0.00,4.5975,4.59753,8.000
8,61.133,0.00,4.3975,4.39750,8.000
8,61.200,0.02,4.1975,4.19750,8.000
8,61.267,0.01,3.9975,3.99750,8.000
8,61.333,0.00,3.7974,3.79743,8.000
8,61.400,0.02,3.5975,3.59750,8.000
8,61.467,0.01,3.3975,3.39750,8.000
8,61.533,0.01,3.1974,3.19743,8.000
8,61.600,0.01,2.9975,2.99750,8.000
8,61.667,0.01,2.7976,2.79757,8.000
8,61.733,0.00,2.5973,2.59733,8.000
8,61.800,0.00,2.3976,2.39760,8.000
8,61.867,0.00,2.1975,2.19747,8.000
8,61.933,0.01,1.9974,1.99743,8.000
8,62.000,0.01,1.7974,1.79740,8.000
8,62.067,0.01,1.5974,1.59743,8.000
8,62.133,0.00,1.3974,1.39737,8.000
8,62.200,0.01,1.1975,1.19750,8.000
8,62.267,0.01,0.9975,0.99747,8.000
8,62.333,0.01,0.7974,0.79743,8.000
8,62.400,0.01,0.5974,0.59740,8.000
8,62.467,0.01,0.3974,0.39740,8.000
8,62.533,0.00,0.1974,0.19740,8.000
8,62.600,0.00,-0.0027,-0.00270,8.000
8,62.733,0.02,-0.2424,-0.24243,8.000
8,62.800,0.01,-0.1987,-0.19870,8.000
8,62.867,0.01,-0.0617,-0.06167,8.000
8,62.933,0.01,0.0017,0.00173,8.000
8,63.000,0.01,-0.0001,-0.00010,8.000
8,63.067,0.01,-0.0001,-0.00010,8.000
8,63.133,0.02,-0.0001,-0.00010,8.000
8,63.200,0.00,-0.0001,-0.00010,8.000
8,63.267,0.01,-0.0001,-0.00010,8.000
8,63.333,0.01,-0.0001,-0.00010,8.000
8,63.400,0.00,-0.0001,-0.00010,8.000
8,63.467,0.00,-0.0001,-0.00010,8.000
8,63.533,0.01,-0.0001,-0.00010,8.000
8,63.600,0.01,-0.0001,-0.00010,8.000
8,63.667,0.02,-0.0001,-0.00010,8.000
8,63.733,0.01,-0.0001,-0.00010,8.000
8,63.800,0.01,-0.0001,-0.00010,8.000
8,63.867,0.01,-0.0001,-0.00010,8.000
8,63.933,0.01,-0.0001,-0.00010,8.000
8,64.000,0.01,-0.0001,-0.00010,8.000
8,64.067,0.00,-0.0001,-0.00010,8.000
8,64.133,0.00,-0.0001,-0.00010,8.000
8,64.200,0.00,-0.0001,-0.00010,8.000
8,64.267,0.01,-0.0001,-0.00010,8.000
8,64.333,0.01,-0.0001,-0.00010,8.000
8,64.400,0.01,-0.0001,-0.00010,8.000
8,64.467,0.02,-0.0001,-0.00010,8.000
8,64.533,0.00,-0.0001,-0.00010,8.000
8,64.600,-0.01,-0.0001,-0.00010,8.000
8,64.667,0.01,-0.0001,-0.00010,8.000
8,64.733,0.00,-0.0001,-0.00010,8.000
8,64.800,-0.01,-0.0001,-0.00010,8.000
8,64.867,0.01,-0.0001,-0.00010,8.000
8,64.933,0.01,-0.0001,-0.00010,8.000
8,65.000,0.01,-0.0001,-0.00010,8.000
8,65.067,0.00,-0.0001,-0.00010,8.000
8,65.133,0.02,-0.0001,-0.00010,8.000
8,65.200,0.01,-0.0001,-0.00010,8.000
8,65.267,0.00,-0.0001,-0.00010,8.000
8,65.333,0.01,-0.0001,-0.00010,8.000
8,65.400,0.02,-0.0001,-0.00010,8.000
8,65.467,0.01,-0.0001,-0.00010,8.000
8,65.533,0.02,-0.0001,-0.00010,8.000
8,65.600,0.00,-0.0001,-0.00010,8.000
8,65.667,0.01,-0.0001,-0.00010,8.000
9,66.067,0.02,0.1523,0.15233,9.000
9,66.133,0.02,0.3515,0.35153,9.000
9,66.200,0.02,0.5516,0.55160,9.000
9,66.267,0.01,0.7515,0.75153,9.000
9,66.333,0.01,0.9516,0.95163,9.000
9,66.400,0.02,1.1516,1.15160,9.000
9,66.467,0.01,1.3515,1.35150,9.000
9,66.533,0.02,1.5516,1.55157,9.000
9,66.600,0.01,1.7516,1.75160,9.000
9,66.667,0.01,1.9515,1.95153,9.000
9,66.733,0.01,2.1517,2.15167,9.000
9,66.800,0.01,2.3516,2.35160,9.000
9,66.867,0.02,2.5515,2.55150,9.000
9,66.933,0.02,2.7515,2.75153,9.000
9,67.000,0.01,2.9516,2.95160,9.000
9,67.067,0.01,3.1516,3.15160,9.000
9,67.133,0.01,3.3517,3.35170,9.000
9,67.200,0.01,3.5517,3.55170,9.000
9,67.267,0.01,3.7517,3.75173,9.000
9,67.333,0.01,3.9516,3.95160,9.000
9,67.400,0.02,4.1516,4.15160,9.000
9,67.467,0.03,4.3517,4.35167,9.000
9,67.533,0.06,4.5517,4.55170,9.000
9,67.600,0.27,4.7516,4.75160,9.000
9,67.667,0.69,4.9518,4.95177,9.000
9,67.733,1.38,5.1518,5.15177,9.000
9,67.800,2.36,5.3516,5.35160,9.000
9,67.867,3.64,5.5518,5.55177,9.000
9,67.933,5.26,5.7517,5.75167,9.000
9,68.000,7.25,5.9516,5.95160,9.000
9,68.067,9.68,6.1517,6.15167,9.000
9,68.133,12.61,6.3516,6.35163,9.000
9,68.200,16.10,6.5518,6.55180,9.000
9,68.267,20.31,6.7517,6.75173,9.000
9,68.400,27.88,7.0274,7.02740,9.000
9,68.467,26.61,7.0053,7.00527,9.000
9,68.533,21.67,6.8723,6.87233,9.000
9,68.600,15.56,6.6727,6.67270,9.000
9,68.667,11.19,6.4725,6.47253,9.000
9,68.733,8.01,6.2727,6.27267,9.000
9,68.800,5.69,6.0725,6.07250,9.000
9,68.867,4.02,5.8724,5.87240,9.000
9,68.933,2.74,5.6727,5.67270,9.000
9,69.000,1.77,5.4725,5.47250,9.000
9,69.067,1.04,5.2725,5.27250,9.000
9,69.133,0.52,5.0726,5.07257,9.000
9,69.200,0.18,4.8726,4.87260,9.000
9,69.267,0.03,4.6725,4.67250,9.000
9,69.333,0.01,4.4726,4.47260,9.000
9,69.400,0.01,4.2726,4.27260,9.000
9,69.467,0.02,4.0724,4.07240,9.000
9,69.533,0.01,3.8724,3.87240,9.000
9,69.600,0.01,3.6726,3.67260,9.000
9,69.667,0.01,3.4724,3.47240,9.000
9,69.733,0.01,3.2725,3.27250,9.000
9,69.800,0.02,3.0726,3.07260,9.000
9,69.867,0.01,2.8725,2.87250,9.000
9,69.933,0.01,2.6724,2.67243,9.000
9,70.000,0.01,2.4726,2.47260,9.000
9,70.067,0.01,2.2725,2.27247,9.000
9,70.133,0.01,2.0725,2.07250,9.000
9,70.200,0.01,1.8725,1.87250,9.000
9,70.267,0.01,1.6725,1.67247,9.000
9,70.333,0.01,1.4724,1.47237,9.000
9,70.400,0.01,1.2725,1.27250,9.000
9,70.467,0.01,1.0725,1.07247,9.000
9,70.533,0.01,0.8724,0.87240,9.000
9,70.600,0.01,0.6725,0.67250,9.000
9,70.667,0.01,0.4724,0.47243,9.000
9,70.733,0.02,0.2724,0.27237,9.000
9,70.800,0.01,0.0723,0.07230,9.000
9,70.933,0.01,-0.2608,-0.26080,9.000
9,71.000,0.02,-0.2834,-0.28340,9.000
9,71.067,0.01,-0.1946,-0.19457,9.000
9,71.133,0.02,-0.0473,-0.04730,9.000
9,71.200,0.00,0.0000,0.00000,9.000
9,71.267,0.01,-0.0002,-0.00020,9.000
9,71.333,0.00,-0.0002,-0.00020,9.000
9,71.400,0.01,-0.0002,-0.00020,9.000
9,71.467,0.01,-0.0002,-0.00020,9.000
9,71.533,0.01,-0.0002,-0.00020,9.000
9,71.600,0.02,-0.0002,-0.00020,9.000
9,71.667,0.01,-0.0002,-0.00020,9.000
9,71.733,0.01,-0.0002,-0.00020,9.000
9,71.800,0.01,-0.0002,-0.00020,9.000
9,71.867,0.01,-0.0002,-0.00020,9.000
9,71.933,0.00,-0.0002,-0.00020,9.000
9,72.000,0.00,-0.0002,-0.00020,9.000
9,72.067,0.02,-0.0002,-0.00020,9.000
9,72.133,0.01,-0.0002,-0.00020,9.000
9,72.200,0.01,-0.0002,-0.00020,9.000
9,72.267,0.01,-0.0002,-0.00020,9.000
9,72.333,0.01,-0.0002,-0.00020,9.000
9,72.400,0.01,-0.0002,-0.00020,9.000
9,72.467,0.01,-0.0002,-0.00020,9.000
9,72.533,0.01,-0.0002,-0.00020,9.000
9,72.600,0.01,-0.0002,-0.00020,9.000
9,72.667,0.02,-0.0002,-0.00020,9.000
9,72.733,0.01,-0.0002,-0.00020,9.000
9,72.800,0.01,-0.0002,-0.00020,9.000
9,72.867,0.01,-0.0001,-0.00010,9.000
9,72.933,0.01,-0.0001,-0.00010,9.000
9,73.000,0.02,-0.0001,-0.00010,9.000
9,73.067,0.01,-0.0001,-0.00010,9.000
9,73.133,0.02,-0.0001,-0.00010,9.000
9,73.200,0.01,-0.0001,-0.00010,9.000
9,73.267,0.01,-0.0001,-0.00010,9.000
9,73.333,0.01,-0.0001,-0.00010,9.000
9,73.400,0.03,-0.0001,-0.00010,9.000
9,73.467,0.01,-0.0001,-0.00010,9.000
9,73.533,0.01,-0.0001,-0.00010,9.000
9,73.600,0.01,-0.0001,-0.00010,9.000
9,73.667,0.01,-0.0001,-0.00010,9.000
9,73.733,0.01,-0.0001,-0.00010,9.000
9,73.800,0.01,-0.0001,-0.00010,9.000
9,73.867,0.01,-0.0001,-0.00010,9.000
10,74.333,0.00,0.2015,0.20147,10.000
10,74.400,-0.01,0.4016,0.40160,10.000
10,74.467,0.00,0.6015,0.60153,10.000
10,74.533,0.00,0.8016,0.80163,10.000
10,74.600,-0.01,1.0016,1.00160,10.000
10,74.667,0.00,1.2017,1.20167,10.000
10,74.733,-0.01,1.4016,1.40163,10.000
10,74.800,0.00,1.6015,1.60150,10.000
10,74.867,-0.01,1.8015,1.80150,10.000
10,74.933,0.00,2.0017,2.00170,10.000
10,75.000,0.01,2.2015,2.20150,10.000
10,75.067,0.00,2.4017,2.40167,10.000
10,75.133,-0.01,2.6016,2.60163,10.000
10,75.200,0.00,2.8017,2.80170,10.000
10,75.267,0.00,3.0017,3.00167,10.000
10,75.333,0.00,3.2017,3.20170,10.000
10,75.400,-0.01,3.4017,3.40170,10.000
10,75.467,0.00,3.6016,3.60160,10.000
10,75.533,0.00,3.8017,3.80167,10.000
10,75.600,0.00,4.0017,4.00170,10.000
10,75.667,0.01,4.2016,4.20160,10.000
10,75.733,0.02,4.4017,4.40173,10.000
10,75.800,0.09,4.6017,4.60170,10.000
10,75.867,0.32,4.8017,4.80167,10.000
10,75.933,0.82,5.0018,5.00177,10.000
10,76.000,1.59,5.2019,5.20190,10.000
10,76.067,2.62,5.4016,5.40160,10.000
10,76.133,3.98,5.6018,5.60183,10.000
10,76.200,5.71,5.8018,5.80180,10.000
10,76.267,7.82,6.0017,6.00167,10.000
10,76.333,10.36,6.2017,6.20170,10.000
10,76.400,13.42,6.4017,6.40170,10.000
10,76.467,17.09,6.6017,6.60173,10.000
10,76.533,21.47,6.8017,6.80170,10.000
10,76.667,27.92,7.0319,7.03190,10.000
10,76.733,25.66,6.9826,6.98260,10.000
10,76.800,20.04,6.8223,6.82230,10.000
10,76.867,14.32,6.6227,6.62270,10.000
10,76.933,10.29,6.4226,6.42263,10.000
10,77.000,7.33,6.2225,6.22250,10.000
10,77.067,5.21,6.0225,6.02253,10.000
10,77.133,3.65,5.8225,5.82250,10.000
10,77.200,2.46,5.6227,5.62270,10.000
10,77.267,1.55,5.4225,5.42247,10.000
10,77.333,0.88,5.2226,5.22263,10.000
10,77.400,0.40,5.0226,5.02260,10.000
10,77.467,0.12,4.8225,4.82250,10.000
10,77.533,0.00,4.6226,4.62257,10.000
10,77.600,0.00,4.4225,4.42250,10.000
10,77.667,0.00,4.2225,4.22250,10.000
10,77.733,0.00,4.0226,4.02263,10.000
10,77.800,-0.01,3.8225,3.82250,10.000
10,77.867,0.00,3.6225,3.62253,10.000
10,77.933,-0.01,3.4226,3.42260,10.000
10,78.000,-0.01,3.2225,3.22250,10.000
10,78.067,0.00,3.0225,3.02247,10.000
10,78.133,0.00,2.8226,2.82257,10.000
10,78.200,0.00,2.6224,2.62240,10.000
10,78.267,0.00,2.4226,2.42257,10.000
10,78.333,-0.01,2.2225,2.22250,10.000
10,78.400,0.00,2.0225,2.02250,10.000
10,78.467,-0.01,1.8224,1.82240,10.000
10,78.533,0.00,1.6224,1.62243,10.000
10,78.600,0.00,1.4224,1.42240,10.000
10,78.667,0.00,1.2224,1.22240,10.000
10,78.733,0.00,1.0225,1.02247,10.000
10,78.800,0.00,0.8226,0.82260,10.000
10,78.867,0.00,0.6223,0.62233,10.000
10,78.933,-0.01,0.4225,0.42247,10.000
10,79.000,0.01,0.2224,0.22240,10.000
10,79.067,-0.01,0.0224,0.02237,10.000
10,79.200,0.00,-0.2792,-0.27920,10.000
10,79.267,-0.01,-0.2753,-0.27533,10.000
10,79.333,0.00,-0.1607,-0.16070,10.000
10,79.400,-0.01,-0.0268,-0.02680,10.000
10,79.467,0.00,-0.0001,-0.00013,10.000
10,79.533,0.00,-0.0002,-0.00020,10.000
10,79.600,0.01,-0.0001,-0.00010,10.000
10,79.667,0.00,-0.0001,-0.00010,10.000
10,79.733,-0.01,-0.0001,-0.00010,10.000
10,79.800,0.00,-0.0001,-0.00010,10.000
10,79.867,0.00,-0.0001,-0.00010,10.000
10,79.933,-0.01,-0.0001,-0.00010,10.000
10,80.000,0.00,-0.0001,-0.00010,10.000
10,80.067,-0.01,-0.0001,-0.00010,10.000
10,80.133,0.00,-0.0001,-0.00010,10.000
10,80.200,0.00,-0.0001,-0.00010,10.000
10,80.267,0.00,-0.0001,-0.00010,10.000
10,80.333,0.00,-0.0001,-0.00010,10.000
10,80.400,0.00,-0.0001,-0.00010,10.000
10,80.467,0.00,-0.0001,-0.00010,10.000
10,80.533,-0.01,-0.0001,-0.00010,10.000
10,80.600,-0.01,-0.0001,-0.00010,10.000
10,80.667,0.00,-0.0001,-0.00010,10.000
10,80.733,0.00,-0.0001,-0.00010,10.000
10,80.800,-0.01,-0.0001,-0.00010,10.000
10,80.867,-0.01,-0.0001,-0.00010,10.000
10,80.933,0.00,-0.0001,-0.00010,10.000
10,81.000,0.00,-0.0001,-0.00010,10.000
10,81.067,0.00,-0.0001,-0.00010,10.000
10,81.133,0.00,-0.0001,-0.00010,10.000
10,81.200,0.00,-0.0001,-0.00010,10.000
10,81.267,0.00,-0.0001,-0.00010,10.000
10,81.333,-0.01,-0.0001,-0.00010,10.000
10,81.400,0.00,-0.0001,-0.00010,10.000
10,81.467,0.00,-0.0001,-0.00010,10.000
10,81.533,0.00,-0.0001,-0.00010,10.000
10,81.600,0.00,-0.0001,-0.00010,10.000
10,81.667,0.00,-0.0001,-0.00010,10.000
10,81.733,0.00,-0.0001,-0.00010,10.000
10,81.800,-0.01,-0.0001,-0.00010,10.000
10,81.867,-0.01,-0.0001,-0.00010,10.000
10,81.933,0.00,-0.0001,-0.00010,10.000
10,82.000,0.00,-0.0001,-0.00010,10.000
10,82.067,0.00,-0.0001,-0.00010,10.000
10,82.133,-0.01,-0.0001,-0.00010,10.000
10,82.267,-0.01,-0.0001,-0.00010,10.000