File: calibDATA_loadcell/date_02:15:2018/Instron_02.15.2018/2_20N_0__4mm.s_0_0.txt
""
"Test Method","Radhen_Load_Cntrl_Cmprsn_250N_12-7.msm"
"Sample I. D.","Sample1.mss"
"Specimen Number","24"

"TheCycle_Output ()","_Time (s)","_Load (N)","_Extension (mm)","RealTimeDepth (mm)","CycleNumber ()"

1,0.267,0.01,0.0827,0.08270,1.000
1,0.333,0.02,0.2744,0.27443,1.000
1,0.400,0.01,0.5396,0.53960,1.000
1,0.467,0.02,0.8062,0.80623,1.000
1,0.533,0.01,1.0730,1.07300,1.000
1,0.600,0.02,1.3398,1.33980,1.000
1,0.667,0.02,1.6062,1.60620,1.000
1,0.733,0.01,1.8729,1.87290,1.000
1,0.800,0.02,2.1397,2.13970,1.000
1,0.867,0.02,2.4063,2.40630,1.000
1,0.933,0.02,2.6728,2.67283,1.000
1,1.000,0.02,2.9395,2.93950,1.000
1,1.067,0.02,3.2064,3.20637,1.000
1,1.133,0.01,3.4729,3.47293,1.000
1,1.200,0.02,3.7398,3.73980,1.000
1,1.267,0.02,4.0062,4.00620,1.000
1,1.333,0.03,4.2730,4.27300,1.000
1,1.400,0.06,4.5398,4.53980,1.000
1,1.467,0.38,4.8063,4.80627,1.000
1,1.533,1.12,5.0731,5.07310,1.000
1,1.600,2.36,5.3396,5.33960,1.000
1,1.667,4.12,5.6065,5.60647,1.000
1,1.733,6.50,5.8729,5.87290,1.000
1,1.800,9.59,6.1396,6.13960,1.000
1,1.867,13.57,6.4064,6.40637,1.000
1,1.933,18.64,6.6730,6.67297,1.000
1,2.067,30.74,7.1127,7.11273,1.000
1,2.133,32.74,7.1795,7.17950,1.000
1,2.200,30.21,7.1359,7.13590,1.000
1,2.267,23.75,6.9803,6.98027,1.000
1,2.333,15.91,6.7272,6.72723,1.000
1,2.400,10.28,6.4607,6.46070,1.000
1,2.467,6.60,6.1939,6.19393,1.000
1,2.533,4.20,5.9273,5.92730,1.000
1,2.600,2.57,5.6607,5.66070,1.000
1,2.667,1.41,5.3938,5.39383,1.000
1,2.733,0.65,5.1273,5.12733,1.000
1,2.800,0.18,4.8607,4.86070,1.000
1,2.867,0.02,4.5940,4.59400,1.000
1,2.933,0.02,4.3273,4.32727,1.000
1,3.000,0.02,4.0605,4.06050,1.000
1,3.067,0.02,3.7939,3.79393,1.000
1,3.133,0.02,3.5272,3.52720,1.000
1,3.200,0.01,3.2606,3.26060,1.000
1,3.267,0.02,2.9939,2.99393,1.000
1,3.333,0.02,2.7273,2.72730,1.000
1,3.400,0.01,2.4606,2.46060,1.000
1,3.467,0.01,2.1938,2.19383,1.000
1,3.533,0.01,1.9273,1.92727,1.000
1,3.600,0.02,1.6606,1.66060,1.000
1,3.667,0.01,1.3938,1.39380,1.000
1,3.733,0.02,1.1273,1.12730,1.000
1,3.800,0.02,0.8606,0.86060,1.000
1,3.867,0.02,0.5938,0.59383,1.000
1,3.933,0.02,0.3271,0.32710,1.000
1,4.000,0.01,0.0603,0.06030,1.000
1,4.133,0.02,-0.3643,-0.36433,1.000
1,4.200,0.02,-0.4203,-0.42030,1.000
1,4.267,0.02,-0.3650,-0.36497,1.000
1,4.333,0.03,-0.1987,-0.19870,1.000
1,4.400,0.03,-0.0425,-0.04250,1.000
1,4.467,0.02,0.0019,0.00187,1.000
1,4.533,0.02,-0.0001,-0.00010,1.000
1,4.600,0.00,-0.0001,-0.00010,1.000
1,4.667,0.01,-0.0001,-0.00010,1.000
1,4.733,0.02,-0.0001,-0.00010,1.000
1,4.800,0.03,-0.0001,-0.00010,1.000
1,4.867,0.02,-0.0001,-0.00010,1.000
1,4.933,0.01,-0.0001,-0.00010,1.000
1,5.000,0.02,-0.0001,-0.00010,1.000
1,5.067,0.01,-0.0001,-0.00010,1.000
1,5.133,0.02,-0.0001,-0.00010,1.000
1,5.200,0.02,-0.0001,-0.00010,1.000
1,5.267,0.02,-0.0001,-0.00010,1.000
1,5.333,0.02,-0.0001,-0.00010,1.000
1,5.400,0.01,-0.0001,-0.00010,1.000
1,5.467,0.02,-0.0001,-0.00010,1.000
1,5.533,0.02,-0.0001,-0.00010,1.000
1,5.600,0.02,-0.0001,-0.00010,1.000
1,5.667,0.01,-0.0001,-0.00010,1.000
1,5.733,0.01,-0.0001,-0.00010,1.000
1,5.800,0.03,-0.0001,-0.00010,1.000
1,5.867,0.01,-0.0001,-0.00010,1.000
1,5.933,0.01,-0.0001,-0.00010,1.000
1,6.000,0.02,-0.0001,-0.00010,1.000
1,6.067,0.02,-0.0001,-0.00010,1.000
1,6.133,0.01,-0.0001,-0.00010,1.000
1,6.200,0.02,-0.0001,-0.00010,1.000
1,6.267,0.02,-0.0001,-0.00010,1.000
1,6.333,0.01,-0.0001,-0.00010,1.000
1,6.400,0.02,-0.0001,-0.00010,1.000
1,6.467,0.02,-0.0001,-0.00010,1.000
1,6.533,0.00,-0.0001,-0.00010,1.000
1,6.600,0.02,-0.0001,-0.00010,1.000
1,6.667,0.02,-0.0001,-0.00010,1.000
1,6.733,0.02,-0.0001,-0.00010,1.000
1,6.800,0.02,-0.0001,-0.00010,1.000
1,6.867,0.02,-0.0001,-0.00010,1.000
1,6.933,0.01,-0.0001,-0.00010,1.000
1,7.000,0.02,-0.0001,-0.00010,1.000
1,7.067,0.02,-0.0001,-0.00010,1.000
1,7.200,0.01,-0.0001,-0.00010,1.000
2,7.467,0.00,0.1286,0.12860,2.000
2,7.533,0.00,0.3528,0.35283,2.000
2,7.600,0.00,0.6195,0.61950,2.000
2,7.667,0.00,0.8863,0.88630,2.000
2,7.733,0.00,1.1531,1.15310,2.000
2,7.800,0.01,1.4196,1.41960,2.000
2,7.867,0.00,1.6862,1.68623,2.000
2,7.933,0.00,1.9529,1.95293,2.000
2,8.000,0.01,2.2197,2.21970,2.000
2,8.067,0.00,2.4863,2.48630,2.000
2,8.133,0.00,2.7530,2.75297,2.000
2,8.200,0.00,3.0196,3.01960,2.000
2,8.267,0.00,3.2863,3.28630,2.000
2,8.333,0.00,3.5529,3.55293,2.000
2,8.400,0.00,3.8196,3.81960,2.000
2,8.467,0.01,4.0863,4.08627,2.000
2,8.533,0.02,4.3530,4.35297,2.000
2,8.600,0.09,4.6197,4.61970,2.000
2,8.667,0.49,4.8863,4.88630,2.000
2,8.733,1.36,5.1531,5.15313,2.000
2,8.800,2.72,5.4197,5.41970,2.000
2,8.867,4.65,5.6864,5.68643,2.000
2,8.933,7.24,5.9530,5.95303,2.000
2,9.000,10.59,6.2197,6.21970,2.000
2,9.067,14.87,6.4863,6.48633,2.000
2,9.133,20.33,6.7529,6.75293,2.000
2,9.267,30.80,7.1164,7.11643,2.000
2,9.333,30.84,7.1334,7.13340,2.000
2,9.400,26.56,7.0396,7.03960,2.000
2,9.467,19.39,6.8340,6.83403,2.000
2,9.533,12.54,6.5674,6.56740,2.000
2,9.600,8.05,6.3006,6.30060,2.000
2,9.667,5.13,6.0339,6.03387,2.000
2,9.733,3.18,5.7672,5.76720,2.000
2,9.800,1.82,5.5005,5.50050,2.000
2,9.867,0.89,5.2339,5.23387,2.000
2,9.933,0.31,4.9673,4.96733,2.000
2,10.000,0.03,4.7006,4.70060,2.000
2,10.067,0.00,4.4339,4.43390,2.000
2,10.133,0.00,4.1672,4.16717,2.000
2,10.200,0.00,3.9005,3.90050,2.000
2,10.267,0.00,3.6340,3.63400,2.000
2,10.333,0.00,3.3673,3.36727,2.000
2,10.400,0.00,3.1006,3.10060,2.000
2,10.467,0.00,2.8340,2.83400,2.000
2,10.533,0.00,2.5672,2.56720,2.000
2,10.600,0.00,2.3006,2.30060,2.000
2,10.667,0.00,2.0339,2.03393,2.000
2,10.733,0.00,1.7673,1.76727,2.000
2,10.800,0.00,1.5005,1.50050,2.000
2,10.867,-0.01,1.2339,1.23387,2.000
2,10.933,0.00,0.9672,0.96717,2.000
2,11.000,0.00,0.7004,0.70040,2.000
2,11.067,0.00,0.4338,0.43380,2.000
2,11.133,0.00,0.1671,0.16710,2.000
2,11.333,0.00,-0.4111,-0.41107,2.000
2,11.400,0.00,-0.4006,-0.40060,2.000
2,11.467,0.00,-0.2784,-0.27840,2.000
2,11.533,0.00,-0.0916,-0.09160,2.000
2,11.600,0.00,-0.0024,-0.00240,2.000
2,11.667,0.00,-0.0002,-0.00017,2.000
2,11.733,0.00,-0.0001,-0.00010,2.000
2,11.800,0.00,-0.0001,-0.00010,2.000
2,11.867,0.00,-0.0001,-0.00010,2.000
2,11.933,0.00,-0.0001,-0.00010,2.000
2,12.000,0.00,-0.0001,-0.00010,2.000
2,12.067,0.00,-0.0001,-0.00010,2.000
2,12.133,0.00,-0.0001,-0.00010,2.000
2,12.200,0.00,-0.0001,-0.00010,2.000
2,12.267,0.00,-0.0001,-0.00010,2.000
2,12.333,0.00,-0.0001,-0.00010,2.000
2,12.400,0.00,-0.0001,-0.00010,2.000
2,12.467,0.00,-0.0001,-0.00010,2.000
2,12.533,0.00,-0.0001,-0.00010,2.000
2,12.600,0.00,-0.0001,-0.00010,2.000
2,12.667,0.00,-0.0001,-0.00010,2.000
2,12.733,0.00,-0.0001,-0.00010,2.000
2,12.800,0.00,-0.0001,-0.00010,2.000
2,12.867,0.00,-0.0001,-0.00010,2.000
2,12.933,0.00,-0.0001,-0.00010,2.000
2,13.000,0.01,-0.0001,-0.00010,2.000
2,13.067,0.00,-0.0001,-0.00010,2.000
2,13.133,0.00,-0.0001,-0.00010,2.000
2,13.200,0.00,-0.0001,-0.00010,2.000
2,13.267,0.00,-0.0001,-0.00010,2.000
2,13.333,0.00,-0.0001,-0.00010,2.000
2,13.400,0.01,-0.0001,-0.00010,2.000
2,13.467,0.00,-0.0001,-0.00010,2.000
2,13.533,0.00,-0.0001,-0.00010,2.000
2,13.600,0.00,-0.0001,-0.00010,2.000
2,13.667,0.01,-0.0001,-0.00010,2.000
2,13.733,0.00,-0.0001,-0.00010,2.000
2,13.800,0.00,-0.0001,-0.00010,2.000
2,13.867,0.00,-0.0001,-0.00010,2.000
2,13.933,0.00,-0.0001,-0.00010,2.000
2,14.000,0.00,-0.0001,-0.00010,2.000
2,14.067,0.00,-0.0001,-0.00010,2.000
2,14.133,0.00,-0.0001,-0.00010,2.000
2,14.200,-0.01,-0.0001,-0.00010,2.000
2,14.267,0.00,-0.0001,-0.00010,2.000
3,14.600,0.00,0.1117,0.11170,3.000
3,14.667,-0.01,0.3261,0.32607,3.000
3,14.733,0.00,0.5928,0.59283,3.000
3,14.800,-0.01,0.8596,0.85960,3.000
3,14.867,0.00,1.1263,1.12633,3.000
3,14.933,-0.01,1.3928,1.39283,3.000
3,15.000,0.00,1.6595,1.65950,3.000
3,15.067,-0.01,1.9262,1.92623,3.000
3,15.133,0.00,2.1929,2.19287,3.000
3,15.200,0.00,2.4595,2.45950,3.000
3,15.267,0.00,2.7262,2.72623,3.000
3,15.333,0.00,2.9930,2.99297,3.000
3,15.400,-0.01,3.2597,3.25970,3.000
3,15.467,-0.01,3.5262,3.52623,3.000
3,15.533,-0.01,3.7930,3.79297,3.000
3,15.600,0.00,4.0596,4.05960,3.000
3,15.667,0.01,4.3263,4.32633,3.000
3,15.733,0.07,4.5930,4.59300,3.000
3,15.800,0.42,4.8596,4.85960,3.000
3,15.867,1.23,5.1264,5.12643,3.000
3,15.933,2.54,5.3929,5.39293,3.000
3,16.000,4.40,5.6598,5.65980,3.000
3,16.067,6.92,5.9263,5.92633,3.000
3,16.133,10.19,6.1930,6.19300,3.000
3,16.200,14.36,6.4598,6.45980,3.000
3,16.267,19.70,6.7264,6.72637,3.000
3,16.400,32.27,7.1590,7.15900,3.000
3,16.467,34.10,7.2199,7.21990,3.000
3,16.533,31.24,7.1704,7.17040,3.000
3,16.600,24.34,7.0098,7.00980,3.000
3,16.667,16.22,6.7540,6.75397,3.000
3,16.733,10.49,6.4873,6.48727,3.000
3,16.800,6.73,6.2206,6.22060,3.000
3,16.867,4.29,5.9539,5.95390,3.000
3,16.933,2.62,5.6874,5.68743,3.000
3,17.000,1.44,5.4205,5.42050,3.000
3,17.067,0.65,5.1539,5.15393,3.000
3,17.133,0.17,4.8873,4.88727,3.000
3,17.200,-0.01,4.6206,4.62060,3.000
3,17.267,-0.01,4.3539,4.35387,3.000
3,17.333,-0.01,4.0872,4.08717,3.000
3,17.400,-0.01,3.8205,3.82050,3.000
3,17.467,-0.01,3.5539,3.55387,3.000
3,17.533,0.00,3.2872,3.28723,3.000
3,17.600,-0.01,3.0207,3.02070,3.000
3,17.667,-0.01,2.7539,2.75393,3.000
3,17.733,-0.01,2.4873,2.48727,3.000
3,17.800,0.00,2.2204,2.22040,3.000
3,17.867,-0.01,1.9539,1.95387,3.000
3,17.933,0.00,1.6872,1.68723,3.000
3,18.000,0.00,1.4203,1.42030,3.000
3,18.067,-0.01,1.1539,1.15393,3.000
3,18.133,-0.01,0.8872,0.88720,3.000
3,18.200,-0.01,0.6204,0.62040,3.000
3,18.267,-0.01,0.3538,0.35377,3.000
3,18.333,-0.01,0.0870,0.08697,3.000
3,18.467,0.00,-0.3731,-0.37310,3.000
3,18.533,-0.01,-0.4564,-0.45643,3.000
3,18.600,0.00,-0.4292,-0.42920,3.000
3,18.667,0.00,-0.2906,-0.29060,3.000
3,18.733,0.00,-0.0961,-0.09610,3.000
3,18.800,0.00,-0.0035,-0.00350,3.000
3,18.867,-0.02,-0.0001,-0.00013,3.000
3,18.933,0.00,-0.0001,-0.00010,3.000
3,19.000,0.01,-0.0001,-0.00010,3.000
3,19.067,-0.01,-0.0001,-0.00010,3.000
3,19.133,0.00,-0.0001,-0.00010,3.000
3,19.200,-0.01,-0.0001,-0.00010,3.000
3,19.267,0.00,-0.0001,-0.00010,3.000
3,19.333,-0.01,-0.0001,-0.00010,3.000
3,19.400,-0.01,-0.0001,-0.00010,3.000
3,19.467,0.00,-0.0001,-0.00010,3.000
3,19.533,-0.01,-0.0001,-0.00010,3.000
3,19.600,0.00,-0.0001,-0.00010,3.000
3,19.667,-0.01,-0.0001,-0.00010,3.000
3,19.733,-0.01,-0.0001,-0.00010,3.000
3,19.800,-0.01,-0.0001,-0.00010,3.000
3,19.867,-0.01,-0.0001,-0.00010,3.000
3,19.933,-0.01,-0.0001,-0.00010,3.000
3,20.000,0.01,-0.0001,-0.00010,3.000
3,20.067,-0.02,-0.0001,-0.00010,3.000
3,20.133,-0.01,-0.0001,-0.00010,3.000
3,20.200,-0.01,-0.0001,-0.00010,3.000
3,20.267,-0.01,-0.0001,-0.00010,3.000
3,20.333,0.00,-0.0001,-0.00010,3.000
3,20.400,0.00,-0.0001,-0.00010,3.000
3,20.467,0.01,-0.0001,-0.00010,3.000
3,20.533,0.00,-0.0001,-0.00010,3.000
3,20.600,0.00,-0.0001,-0.00010,3.000
3,20.667,-0.01,-0.0001,-0.00010,3.000
3,20.733,-0.01,-0.0001,-0.00010,3.000
3,20.800,0.00,-0.0001,-0.00010,3.000
3,20.867,-0.01,-0.0001,-0.00010,3.000
3,20.933,-0.01,-0.0001,-0.00010,3.000
3,21.000,-0.02,-0.0001,-0.00010,3.000
3,21.067,-0.01,-0.0001,-0.00010,3.000
3,21.133,0.00,-0.0001,-0.00010,3.000
3,21.200,-0.01,-0.0001,-0.00010,3.000
3,21.267,-0.01,-0.0001,-0.00010,3.000
3,21.333,-0.02,-0.0001,-0.00010,3.000
3,21.400,-0.01,-0.0001,-0.00010,3.000
4,21.800,0.01,0.0749,0.07490,4.000
4,21.867,0.01,0.2610,0.26100,4.000
4,21.933,0.01,0.5249,0.52493,4.000
4,22.000,0.01,0.7917,0.79170,4.000
4,22.067,0.01,1.0583,1.05830,4.000
4,22.133,0.01,1.3249,1.32493,4.000
4,22.200,0.02,1.5916,1.59160,4.000
4,22.267,0.02,1.8582,1.85817,4.000
4,22.333,0.01,2.1249,2.12493,4.000
4,22.400,0.01,2.3917,2.39170,4.000
4,22.467,0.02,2.6582,2.65823,4.000
4,22.533,0.01,2.9249,2.92490,4.000
4,22.600,0.02,3.1915,3.19150,4.000
4,22.667,0.02,3.4584,3.45840,4.000
4,22.733,0.01,3.7251,3.72510,4.000
4,22.800,0.01,3.9915,3.99150,4.000
4,22.867,0.02,4.2584,4.25837,4.000
4,22.933,0.05,4.5251,4.52507,4.000
4,23.000,0.31,4.7915,4.79150,4.000
4,23.067,0.99,5.0584,5.05840,4.000
4,23.133,2.17,5.3250,5.32497,4.000
4,23.200,3.87,5.5916,5.59160,4.000
4,23.267,6.22,5.8582,5.85823,4.000
4,23.333,9.28,6.1249,6.12493,4.000
4,23.400,13.22,6.3917,6.39170,4.000
4,23.467,18.24,6.6583,6.65833,4.000
4,23.600,30.71,7.1122,7.11220,4.000
4,23.667,33.16,7.1898,7.18977,4.000
4,23.733,31.08,7.1568,7.15683,4.000
4,23.800,24.85,7.0131,7.01310,4.000
4,23.867,16.86,6.7659,6.76590,4.000
4,23.933,10.91,6.4993,6.49927,4.000
4,24.000,6.99,6.2328,6.23280,4.000
4,24.067,4.46,5.9659,5.96593,4.000
4,24.133,2.74,5.6994,5.69937,4.000
4,24.200,1.51,5.4326,5.43260,4.000
4,24.267,0.70,5.1660,5.16597,4.000
4,24.333,0.21,4.8993,4.89927,4.000
4,24.400,0.02,4.6326,4.63260,4.000
4,24.467,0.01,4.3660,4.36597,4.000
4,24.533,0.01,4.0992,4.09920,4.000
4,24.600,0.00,3.8325,3.83250,4.000
4,24.667,0.01,3.5658,3.56583,4.000
4,24.733,0.01,3.2993,3.29927,4.000
4,24.800,0.01,3.0327,3.03270,4.000
4,24.867,0.02,2.7659,2.76593,4.000
4,24.933,0.01,2.4993,2.49930,4.000
4,25.000,0.01,2.2326,2.23260,4.000
4,25.067,0.02,1.9659,1.96593,4.000
4,25.133,0.02,1.6992,1.69923,4.000
4,25.200,0.01,1.4325,1.43250,4.000
4,25.267,0.01,1.1660,1.16600,4.000
4,25.333,0.01,0.8992,0.89923,4.000
4,25.400,0.01,0.6324,0.63240,4.000
4,25.467,0.01,0.3658,0.36577,4.000
4,25.533,0.01,0.0990,0.09900,4.000
4,25.667,0.01,-0.3610,-0.36103,4.000
4,25.733,0.01,-0.4444,-0.44443,4.000
4,25.800,0.01,-0.4175,-0.41750,4.000
4,25.867,0.01,-0.2785,-0.27853,4.000
4,25.933,0.01,-0.0888,-0.08880,4.000
4,26.000,0.01,-0.0031,-0.00310,4.000
4,26.067,0.02,-0.0001,-0.00010,4.000
4,26.133,0.01,-0.0002,-0.00020,4.000
4,26.200,0.01,-0.0001,-0.00010,4.000
4,26.267,0.01,-0.0001,-0.00010,4.000
4,26.333,0.01,-0.0001,-0.00010,4.000
4,26.400,0.01,-0.0001,-0.00010,4.000
4,26.467,0.02,-0.0001,-0.00010,4.000
4,26.533,0.01,-0.0001,-0.00010,4.000
4,26.600,0.01,-0.0001,-0.00010,4.000
4,26.667,0.01,-0.0001,-0.00010,4.000
4,26.733,0.01,-0.0001,-0.00010,4.000
4,26.800,0.01,-0.0001,-0.00010,4.000
4,26.867,0.01,-0.0001,-0.00010,4.000
4,26.933,0.01,-0.0001,-0.00010,4.000
4,27.000,0.01,-0.0001,-0.00010,4.000
4,27.067,0.01,-0.0001,-0.00010,4.000
4,27.133,0.01,-0.0001,-0.00010,4.000
4,27.200,0.01,-0.0001,-0.00010,4.000
4,27.267,0.01,-0.0001,-0.00010,4.000
4,27.333,0.01,-0.0001,-0.00010,4.000
4,27.400,0.03,-0.0001,-0.00010,4.000
4,27.467,0.01,-0.0001,-0.00010,4.000
4,27.533,0.01,-0.0001,-0.00010,4.000
4,27.600,0.01,-0.0001,-0.00010,4.000
4,27.667,0.01,-0.0001,-0.00010,4.000
4,27.733,0.02,-0.0001,-0.00010,4.000
4,27.800,0.01,-0.0001,-0.00010,4.000
4,27.867,0.01,-0.0001,-0.00010,4.000
4,27.933,0.01,-0.0001,-0.00010,4.000
4,28.000,0.01,-0.0001,-0.00010,4.000
4,28.067,0.01,-0.0001,-0.00010,4.000
4,28.133,0.01,-0.0001,-0.00010,4.000
4,28.200,0.01,-0.0001,-0.00010,4.000
4,28.267,0.01,-0.0001,-0.00010,4.000
4,28.333,0.02,-0.0001,-0.00010,4.000
4,28.400,0.02,-0.0001,-0.00010,4.000
4,28.467,0.01,-0.0001,-0.00010,4.000
4,28.533,0.01,-0.0001,-0.00010,4.000
4,28.600,0.02,-0.0001,-0.00010,4.000
5,29.000,0.00,0.0770,0.07700,5.000
5,29.067,0.00,0.2646,0.26460,5.000
5,29.133,0.00,0.5290,0.52897,5.000
5,29.200,0.00,0.7956,0.79560,5.000
5,29.267,0.00,1.0623,1.06230,5.000
5,29.333,0.00,1.3290,1.32897,5.000
5,29.400,0.00,1.5955,1.59550,5.000
5,29.467,0.00,1.8622,1.86223,5.000
5,29.533,-0.01,2.1290,2.12900,5.000
5,29.600,0.00,2.3956,2.39560,5.000
5,29.667,0.00,2.6622,2.66217,5.000
5,29.733,0.00,2.9289,2.92887,5.000
5,29.800,0.00,3.1956,3.19560,5.000
5,29.867,0.00,3.4623,3.46233,5.000
5,29.933,0.00,3.7291,3.72913,5.000
5,30.000,0.00,3.9956,3.99560,5.000
5,30.067,0.01,4.2624,4.26237,5.000
5,30.133,0.03,4.5291,4.52913,5.000
5,30.200,0.30,4.7956,4.79560,5.000
5,30.267,0.99,5.0624,5.06243,5.000
5,30.333,2.17,5.3290,5.32900,5.000
5,30.400,3.89,5.5957,5.59570,5.000
5,30.467,6.25,5.8622,5.86217,5.000
5,30.533,9.31,6.1290,6.12897,5.000
5,30.600,13.27,6.3957,6.39570,5.000
5,30.667,18.33,6.6624,6.66237,5.000
5,30.800,30.85,7.1162,7.11620,5.000
5,30.867,33.32,7.1938,7.19377,5.000
5,30.933,31.24,7.1608,7.16080,5.000
5,31.000,24.96,7.0170,7.01700,5.000
5,31.067,16.93,6.7699,6.76993,5.000
5,31.133,10.95,6.5033,6.50330,5.000
5,31.200,7.01,6.2367,6.23670,5.000
5,31.267,4.46,5.9699,5.96993,5.000
5,31.333,2.74,5.7033,5.70333,5.000
5,31.400,1.52,5.4366,5.43660,5.000
5,31.467,0.70,5.1700,5.17003,5.000
5,31.533,0.19,4.9033,4.90330,5.000
5,31.600,0.00,4.6366,4.63660,5.000
5,31.667,-0.01,4.3699,4.36993,5.000
5,31.733,0.00,4.1032,4.10320,5.000
5,31.800,-0.01,3.8365,3.83650,5.000
5,31.867,0.00,3.5699,3.56990,5.000
5,31.933,-0.01,3.3033,3.30330,5.000
5,32.000,0.00,3.0366,3.03660,5.000
5,32.067,-0.01,2.7700,2.76997,5.000
5,32.133,0.00,2.5033,2.50327,5.000
5,32.200,-0.01,2.2365,2.23650,5.000
5,32.267,-0.01,1.9699,1.96987,5.000
5,32.333,0.00,1.7032,1.70323,5.000
5,32.400,0.00,1.4364,1.43640,5.000
5,32.467,-0.01,1.1699,1.16993,5.000
5,32.533,0.00,0.9032,0.90320,5.000
5,32.600,0.00,0.6364,0.63640,5.000
5,32.667,0.00,0.3698,0.36980,5.000
5,32.733,0.00,0.1031,0.10310,5.000
5,32.867,0.00,-0.3570,-0.35697,5.000
5,32.933,0.00,-0.4404,-0.44040,5.000
5,33.000,-0.01,-0.4135,-0.41350,5.000
5,33.067,0.00,-0.2745,-0.27453,5.000
5,33.133,0.00,-0.0866,-0.08660,5.000
5,33.200,0.00,-0.0033,-0.00330,5.000
5,33.267,0.00,-0.0002,-0.00020,5.000
5,33.333,0.00,-0.0002,-0.00020,5.000
5,33.400,-0.01,-0.0002,-0.00020,5.000
5,33.467,0.00,-0.0002,-0.00020,5.000
5,33.533,0.00,-0.0002,-0.00020,5.000
5,33.600,0.00,-0.0002,-0.00020,5.000
5,33.667,0.00,-0.0002,-0.00020,5.000
5,33.733,0.00,-0.0002,-0.00020,5.000
5,33.800,-0.01,-0.0002,-0.00020,5.000
5,33.867,-0.01,-0.0002,-0.00020,5.000
5,33.933,0.00,-0.0002,-0.00020,5.000
5,34.000,0.00,-0.0002,-0.00020,5.000
5,34.067,0.00,-0.0002,-0.00020,5.000
5,34.133,0.00,-0.0002,-0.00020,5.000
5,34.200,0.00,-0.0002,-0.00020,5.000
5,34.267,0.00,-0.0002,-0.00020,5.000
5,34.333,0.00,-0.0002,-0.00020,5.000
5,34.400,0.00,-0.0002,-0.00020,5.000
5,34.467,0.00,-0.0002,-0.00020,5.000
5,34.533,0.00,-0.0002,-0.00020,5.000
5,34.600,0.00,-0.0002,-0.00020,5.000
5,34.667,0.00,-0.0002,-0.00020,5.000
5,34.733,0.00,-0.0002,-0.00020,5.000
5,34.800,0.00,-0.0002,-0.00020,5.000
5,34.867,0.00,-0.0002,-0.00020,5.000
5,34.933,0.00,-0.0002,-0.00020,5.000
5,35.000,0.00,-0.0002,-0.00020,5.000
5,35.067,-0.01,-0.0002,-0.00020,5.000
5,35.133,0.00,-0.0001,-0.00010,5.000
5,35.200,0.00,-0.0001,-0.00010,5.000
5,35.267,0.00,-0.0001,-0.00010,5.000
5,35.333,0.00,-0.0001,-0.00010,5.000
5,35.400,-0.02,-0.0001,-0.00010,5.000
5,35.467,0.00,-0.0001,-0.00010,5.000
5,35.533,0.00,-0.0001,-0.00010,5.000
5,35.600,0.00,-0.0001,-0.00010,5.000
5,35.667,0.00,-0.0001,-0.00010,5.000
5,35.733,0.00,-0.0001,-0.00010,5.000
5,35.800,0.00,-0.0001,-0.00010,5.000
5,35.933,0.00,-0.0001,-0.00010,5.000
6,36.200,0.01,0.1095,0.10960,6.000
6,36.267,0.01,0.3221,0.32217,6.000
6,36.333,0.01,0.5889,0.58897,6.000
6,36.400,0.01,0.8556,0.85570,6.000
6,36.467,0.01,1.1224,1.12247,6.000
6,36.533,0.02,1.3889,1.38897,6.000
6,36.600,0.02,1.6556,1.65570,6.000
6,36.667,0.01,1.9223,1.92237,6.000
6,36.733,0.01,2.1889,2.18897,6.000
6,36.800,0.01,2.4556,2.45570,6.000
6,36.867,0.01,2.7222,2.72233,6.000
6,36.933,0.01,2.9890,2.98910,6.000
6,37.000,0.01,3.2556,3.25570,6.000
6,37.067,0.01,3.5223,3.52240,6.000
6,37.133,0.01,3.7890,3.78913,6.000
6,37.200,0.02,4.0556,4.05570,6.000
6,37.267,0.02,4.3224,4.32247,6.000
6,37.333,0.08,4.5890,4.58910,6.000
6,37.400,0.42,4.8556,4.85570,6.000
6,37.467,1.22,5.1224,5.12253,6.000
6,37.533,2.52,5.3890,5.38910,6.000
6,37.600,4.37,5.6559,5.65600,6.000
6,37.667,6.87,5.9223,5.92243,6.000
6,37.733,10.12,6.1890,6.18910,6.000
6,37.800,14.30,6.4558,6.45590,6.000
6,37.867,19.64,6.7224,6.72247,6.000
6,38.000,31.35,7.1311,7.13120,6.000
6,38.067,32.52,7.1754,7.17550,6.000
6,38.133,29.10,7.1094,7.10950,6.000
6,38.200,22.16,6.9322,6.93230,6.000
6,38.267,14.54,6.6700,6.67010,6.000
6,38.333,9.39,6.4033,6.40340,6.000
6,38.400,6.01,6.1365,6.13660,6.000
6,38.467,3.80,5.8698,5.86987,6.000
6,38.533,2.27,5.6034,5.60347,6.000
6,38.600,1.19,5.3366,5.33670,6.000
6,38.667,0.49,5.0699,5.07003,6.000
6,38.733,0.11,4.8032,4.80333,6.000
6,38.800,0.00,4.5366,4.53670,6.000
6,38.867,0.00,4.2699,4.27003,6.000
6,38.933,0.01,4.0032,4.00330,6.000
6,39.000,0.02,3.7366,3.73670,6.000
6,39.067,0.01,3.4698,3.46993,6.000
6,39.133,0.01,3.2032,3.20330,6.000
6,39.200,0.02,2.9365,2.93660,6.000
6,39.267,0.01,2.6698,2.66990,6.000
6,39.333,0.01,2.4032,2.40330,6.000
6,39.400,0.01,2.1366,2.13670,6.000
6,39.467,0.01,1.8698,1.86987,6.000
6,39.533,0.01,1.6032,1.60327,6.000
6,39.600,0.02,1.3364,1.33650,6.000
6,39.667,0.01,1.0698,1.06993,6.000
6,39.733,0.02,0.8032,0.80327,6.000
6,39.800,0.02,0.5366,0.53670,6.000
6,39.867,0.01,0.2697,0.26983,6.000
6,39.933,0.02,0.0032,0.00327,6.000
6,40.067,0.02,-0.3883,-0.38820,6.000
6,40.133,0.01,-0.4217,-0.42160,6.000
6,40.200,0.00,-0.3447,-0.34460,6.000
6,40.267,0.01,-0.1622,-0.16210,6.000
6,40.333,0.02,-0.0278,-0.02773,6.000
6,40.400,0.01,-0.0002,-0.00010,6.000
6,40.467,0.00,-0.0002,-0.00010,6.000
6,40.533,0.02,-0.0002,-0.00010,6.000
6,40.600,0.01,-0.0002,-0.00010,6.000
6,40.667,0.01,-0.0002,-0.00010,6.000
6,40.733,0.01,-0.0002,-0.00010,6.000
6,40.800,0.00,-0.0002,-0.00010,6.000
6,40.867,0.01,-0.0002,-0.00010,6.000
6,40.933,0.01,-0.0002,-0.00010,6.000
6,41.000,0.01,-0.0002,-0.00010,6.000
6,41.067,0.01,-0.0002,-0.00010,6.000
6,41.133,0.02,-0.0002,-0.00010,6.000
6,41.200,0.02,-0.0002,-0.00010,6.000
6,41.267,0.01,-0.0002,-0.00010,6.000
6,41.333,0.01,-0.0002,-0.00010,6.000
6,41.400,0.02,-0.0002,-0.00010,6.000
6,41.467,0.01,-0.0002,-0.00010,6.000
6,41.533,0.01,-0.0002,-0.00010,6.000
6,41.600,0.01,-0.0002,-0.00010,6.000
6,41.667,0.02,-0.0002,-0.00010,6.000
6,41.733,0.01,-0.0002,-0.00010,6.000
6,41.800,0.02,-0.0002,-0.00010,6.000
6,41.867,0.01,-0.0002,-0.00010,6.000
6,41.933,0.01,-0.0002,-0.00010,6.000
6,42.000,0.02,-0.0002,-0.00010,6.000
6,42.067,0.02,-0.0002,-0.00010,6.000
6,42.133,0.01,-0.0002,-0.00010,6.000
6,42.200,0.01,-0.0001,0.00000,6.000
6,42.267,0.02,-0.0001,0.00000,6.000
6,42.333,0.01,-0.0001,0.00000,6.000
6,42.400,0.02,-0.0001,0.00000,6.000
6,42.467,0.01,-0.0001,0.00000,6.000
6,42.533,0.01,-0.0001,0.00000,6.000
6,42.600,0.01,-0.0001,0.00000,6.000
6,42.667,0.01,-0.0001,0.00000,6.000
6,42.733,0.01,-0.0001,0.00000,6.000
6,42.800,0.01,-0.0001,0.00000,6.000
6,42.867,0.01,-0.0001,0.00000,6.000
6,42.933,0.01,-0.0001,0.00000,6.000
6,43.000,0.00,-0.0001,0.00000,6.000
7,43.400,0.00,0.1945,0.19460,7.000
7,43.467,0.00,0.4463,0.44637,7.000
7,43.533,0.00,0.7129,0.71300,7.000
7,43.600,0.00,0.9796,0.97970,7.000
7,43.667,0.01,1.2464,1.24650,7.000
7,43.733,0.00,1.5129,1.51297,7.000
7,43.800,-0.02,1.7796,1.77970,7.000
7,43.867,0.00,2.0464,2.04647,7.000
7,43.933,0.00,2.3130,2.31307,7.000
7,44.000,0.00,2.5796,2.57970,7.000
7,44.067,0.00,2.8462,2.84633,7.000
7,44.133,-0.01,3.1130,3.11310,7.000
7,44.200,0.00,3.3797,3.37980,7.000
7,44.267,0.01,3.6463,3.64643,7.000
7,44.333,-0.02,3.9129,3.91300,7.000
7,44.400,0.01,4.1797,4.17980,7.000
7,44.467,0.02,4.4463,4.44637,7.000
7,44.533,0.17,4.7130,4.71307,7.000
7,44.600,0.71,4.9799,4.98000,7.000
7,44.667,1.74,5.2464,5.24653,7.000
7,44.733,3.28,5.5130,5.51313,7.000
7,44.800,5.43,5.7795,5.77960,7.000
7,44.867,8.26,6.0463,6.04640,7.000
7,44.933,11.93,6.3130,6.31310,7.000
7,45.000,16.62,6.5798,6.57990,7.000
7,45.133,28.58,7.0461,7.04617,7.000
7,45.200,31.34,7.1351,7.13520,7.000
7,45.267,29.84,7.1132,7.11333,7.000
7,45.333,24.27,6.9802,6.98030,7.000
7,45.400,16.71,6.7408,6.74090,7.000
7,45.467,10.75,6.4740,6.47407,7.000
7,45.533,6.87,6.2073,6.20740,7.000
7,45.600,4.35,5.9406,5.94070,7.000
7,45.667,2.63,5.6741,5.67417,7.000
7,45.733,1.43,5.4072,5.40730,7.000
7,45.800,0.64,5.1406,5.14070,7.000
7,45.867,0.16,4.8740,4.87407,7.000
7,45.933,-0.02,4.6072,4.60733,7.000
7,46.000,0.01,4.3406,4.34070,7.000
7,46.067,0.00,4.0739,4.07397,7.000
7,46.133,0.01,3.8072,3.80733,7.000
7,46.200,-0.01,3.5405,3.54060,7.000
7,46.267,0.00,3.2739,3.27400,7.000
7,46.333,-0.01,3.0073,3.00740,7.000
7,46.400,0.00,2.7407,2.74080,7.000
7,46.467,-0.01,2.4740,2.47410,7.000
7,46.533,0.00,2.2072,2.20727,7.000
7,46.600,-0.02,1.9406,1.94070,7.000
7,46.667,0.00,1.6739,1.67400,7.000
7,46.733,-0.01,1.4071,1.40720,7.000
7,46.800,0.01,1.1406,1.14070,7.000
7,46.867,0.00,0.8738,0.87393,7.000
7,46.933,0.00,0.6071,0.60723,7.000
7,47.000,0.00,0.3403,0.34040,7.000
7,47.067,-0.01,0.0737,0.07380,7.000
7,47.200,0.00,-0.3587,-0.35860,7.000
7,47.267,0.00,-0.4198,-0.41973,7.000
7,47.333,0.00,-0.3704,-0.37030,7.000
7,47.400,0.00,-0.2095,-0.20940,7.000
7,47.467,-0.01,-0.0478,-0.04770,7.000
7,47.533,0.00,0.0022,0.00233,7.000
7,47.600,0.00,-0.0002,-0.00010,7.000
7,47.667,0.00,-0.0001,0.00000,7.000
7,47.733,0.00,-0.0001,0.00000,7.000
7,47.800,0.00,-0.0001,0.00000,7.000
7,47.867,0.00,-0.0001,0.00000,7.000
7,47.933,0.00,-0.0001,0.00000,7.000
7,48.000,-0.01,-0.0001,0.00000,7.000
7,48.067,-0.01,-0.0001,0.00000,7.000
7,48.133,-0.02,-0.0001,0.00000,7.000
7,48.200,0.00,-0.0001,0.00000,7.000
7,48.267,0.00,-0.0001,0.00000,7.000
7,48.333,0.00,-0.0001,0.00000,7.000
7,48.400,0.00,-0.0001,0.00000,7.000
7,48.467,0.00,-0.0001,0.00000,7.000
7,48.533,0.00,-0.0001,0.00000,7.000
7,48.600,0.01,-0.0001,0.00000,7.000
7,48.667,0.00,-0.0001,0.00000,7.000
7,48.733,-0.01,-0.0001,0.00000,7.000
7,48.800,0.00,-0.0001,0.00000,7.000
7,48.867,0.00,-0.0001,0.00000,7.000
7,48.933,0.00,-0.0001,0.00000,7.000
7,49.000,0.00,-0.0001,0.00000,7.000
7,49.067,0.00,-0.0001,0.00000,7.000
7,49.133,0.00,-0.0001,0.00000,7.000
7,49.200,0.00,-0.0001,0.00000,7.000
7,49.267,0.00,-0.0001,0.00000,7.000
7,49.333,0.00,-0.0001,0.00000,7.000
7,49.400,0.00,-0.0001,0.00000,7.000
7,49.467,0.00,-0.0001,0.00000,7.000
7,49.533,-0.01,-0.0001,0.00000,7.000
7,49.600,0.00,-0.0001,0.00000,7.000
7,49.667,0.00,-0.0001,0.00000,7.000
7,49.733,0.00,-0.0001,0.00000,7.000
7,49.800,0.00,-0.0001,0.00000,7.000
7,49.867,0.00,-0.0001,0.00000,7.000
7,49.933,0.00,-0.0001,0.00000,7.000
7,50.000,0.01,-0.0001,0.00000,7.000
7,50.067,-0.01,-0.0001,0.00000,7.000
7,50.133,0.00,-0.0001,0.00000,7.000
7,50.267,0.00,-0.0001,0.00000,7.000
8,50.400,0.00,0.0000,0.00010,8.000
8,50.533,0.00,0.1833,0.18333,8.000
8,50.600,-0.01,0.4317,0.43170,8.000
8,50.667,0.00,0.6982,0.69823,8.000
8,50.733,-0.01,0.9650,0.96497,8.000
8,50.800,-0.01,1.2318,1.23180,8.000
8,50.867,0.00,1.4982,1.49823,8.000
8,50.933,0.00,1.7649,1.76487,8.000
8,51.000,0.00,2.0317,2.03170,8.000
8,51.067,0.00,2.2983,2.29827,8.000
8,51.133,-0.01,2.5649,2.56487,8.000
8,51.200,0.00,2.8316,2.83160,8.000
8,51.267,0.01,3.0983,3.09830,8.000
8,51.333,-0.01,3.3650,3.36497,8.000
8,51.400,0.00,3.6317,3.63170,8.000
8,51.467,0.00,3.8981,3.89813,8.000
8,51.533,0.00,4.1650,4.16497,8.000
8,51.600,0.02,4.4316,4.43160,8.000
8,51.667,0.16,4.6983,4.69830,8.000
8,51.733,0.67,4.9650,4.96503,8.000
8,51.800,1.67,5.2317,5.23170,8.000
8,51.867,3.18,5.4983,5.49830,8.000
8,51.933,5.29,5.7650,5.76500,8.000
8,52.000,8.08,6.0317,6.03170,8.000
8,52.067,11.71,6.2983,6.29833,8.000
8,52.133,16.31,6.5650,6.56500,8.000
8,52.333,31.65,7.1431,7.14313,8.000
8,52.400,30.60,7.1327,7.13270,8.000
8,52.467,25.27,7.0105,7.01047,8.000
8,52.533,17.71,6.7792,6.77917,8.000
8,52.600,11.40,6.5126,6.51260,8.000
8,52.667,7.30,6.2460,6.24603,8.000
8,52.733,4.62,5.9793,5.97927,8.000
8,52.800,2.84,5.7127,5.71270,8.000
8,52.867,1.59,5.4458,5.44577,8.000
8,52.933,0.73,5.1793,5.17930,8.000
8,53.000,0.22,4.9126,4.91260,8.000
8,53.067,0.01,4.6459,4.64593,8.000
8,53.133,0.01,4.3792,4.37923,8.000
8,53.200,0.00,4.1126,4.11260,8.000
8,53.267,0.00,3.8458,3.84583,8.000
8,53.333,0.00,3.5793,3.57927,8.000
8,53.400,0.00,3.3126,3.31260,8.000
8,53.467,0.00,3.0460,3.04597,8.000
8,53.533,0.00,2.7793,2.77933,8.000
8,53.600,0.00,2.5125,2.51250,8.000
8,53.667,-0.01,2.2459,2.24590,8.000
8,53.733,0.00,1.9793,1.97927,8.000
8,53.800,0.00,1.7125,1.71250,8.000
8,53.867,0.00,1.4458,1.44580,8.000
8,53.933,0.00,1.1793,1.17927,8.000
8,54.000,0.01,0.9126,0.91260,8.000
8,54.067,0.00,0.6458,0.64577,8.000
8,54.133,0.01,0.3791,0.37913,8.000
8,54.200,0.00,0.1124,0.11240,8.000
8,54.333,0.00,-0.3343,-0.33433,8.000
8,54.400,0.00,-0.4070,-0.40700,8.000
8,54.467,0.00,-0.3684,-0.36840,8.000
8,54.533,0.00,-0.2185,-0.21853,8.000
8,54.600,0.00,-0.0526,-0.05260,8.000
8,54.667,0.00,0.0015,0.00153,8.000
8,54.733,0.00,-0.0002,-0.00020,8.000
8,54.800,0.00,-0.0002,-0.00020,8.000
8,54.867,0.00,-0.0001,-0.00010,8.000
8,54.933,0.00,-0.0002,-0.00017,8.000
8,55.000,0.00,-0.0002,-0.00020,8.000
8,55.067,0.00,-0.0001,-0.00010,8.000
8,55.133,0.01,-0.0001,-0.00010,8.000
8,55.200,0.00,-0.0001,-0.00010,8.000
8,55.267,0.00,-0.0001,-0.00010,8.000
8,55.333,-0.01,-0.0001,-0.00010,8.000
8,55.400,0.01,-0.0001,-0.00010,8.000
8,55.467,0.00,-0.0001,-0.00010,8.000
8,55.533,0.00,-0.0001,-0.00010,8.000
8,55.600,0.01,-0.0001,-0.00010,8.000
8,55.667,0.00,-0.0001,-0.00010,8.000
8,55.733,-0.01,-0.0001,-0.00010,8.000
8,55.800,0.00,-0.0001,-0.00010,8.000
8,55.867,0.00,-0.0001,-0.00010,8.000
8,55.933,0.00,-0.0001,-0.00010,8.000
8,56.000,0.00,-0.0001,-0.00010,8.000
8,56.067,-0.01,-0.0001,-0.00010,8.000
8,56.133,0.00,-0.0001,-0.00010,8.000
8,56.200,-0.01,-0.0001,-0.00010,8.000
8,56.267,0.00,-0.0001,-0.00010,8.000
8,56.333,0.00,-0.0001,-0.00010,8.000
8,56.400,0.00,-0.0001,-0.00010,8.000
8,56.467,-0.01,-0.0001,-0.00010,8.000
8,56.533,0.00,-0.0001,-0.00010,8.000
8,56.600,0.00,-0.0001,-0.00010,8.000
8,56.667,0.00,-0.0001,-0.00010,8.000
8,56.733,0.00,-0.0001,-0.00010,8.000
8,56.800,0.01,-0.0001,-0.00010,8.000
8,56.867,0.01,-0.0001,-0.00010,8.000
8,56.933,0.01,-0.0001,-0.00010,8.000
8,57.000,0.01,-0.0001,-0.00010,8.000
8,57.067,0.00,-0.0001,-0.00010,8.000
8,57.133,0.00,-0.0001,-0.00010,8.000
8,57.200,0.01,-0.0001,-0.00010,8.000
8,57.267,-0.01,-0.0001,-0.00010,8.000
8,57.400,0.00,-0.0001,-0.00010,8.000
9,57.667,0.00,0.0911,0.09123,9.000
9,57.733,0.00,0.2895,0.28960,9.000
9,57.800,-0.01,0.5555,0.55560,9.000
9,57.867,0.00,0.8223,0.82243,9.000
9,57.933,0.00,1.0890,1.08910,9.000
9,58.000,0.00,1.3557,1.35580,9.000
9,58.067,-0.01,1.6223,1.62237,9.000
9,58.133,0.00,1.8888,1.88893,9.000
9,58.200,0.00,2.1557,2.15580,9.000
9,58.267,0.00,2.4224,2.42247,9.000
9,58.333,-0.01,2.6889,2.68903,9.000
9,58.400,-0.01,2.9556,2.95570,9.000
9,58.467,0.00,3.2224,3.22247,9.000
9,58.533,0.00,3.4890,3.48913,9.000
9,58.600,0.00,3.7557,3.75580,9.000
9,58.667,0.00,4.0223,4.02237,9.000
9,58.733,0.01,4.2890,4.28913,9.000
9,58.800,0.04,4.5556,4.55570,9.000
9,58.867,0.34,4.8223,4.82240,9.000
9,58.933,1.07,5.0891,5.08920,9.000
9,59.000,2.29,5.3556,5.35570,9.000
9,59.067,4.07,5.6225,5.62260,9.000
9,59.133,6.49,5.8889,5.88897,9.000
9,59.200,9.63,6.1556,6.15570,9.000
9,59.267,13.69,6.4224,6.42247,9.000
9,59.333,18.88,6.6890,6.68907,9.000
9,59.467,30.90,7.1176,7.11773,9.000
9,59.533,32.61,7.1759,7.17600,9.000
9,59.600,29.78,7.1240,7.12410,9.000
9,59.667,23.13,6.9601,6.96020,9.000
9,59.733,15.37,6.7032,6.70333,9.000
9,59.800,9.90,6.4366,6.43670,9.000
9,59.867,6.34,6.1700,6.17010,9.000
9,59.933,4.01,5.9032,5.90333,9.000
9,60.000,2.40,5.6366,5.63670,9.000
9,60.067,1.27,5.3699,5.37000,9.000
9,60.133,0.54,5.1033,5.10337,9.000
9,60.200,0.12,4.8365,4.83660,9.000
9,60.267,-0.02,4.5700,4.57013,9.000
9,60.333,-0.01,4.3033,4.30343,9.000
9,60.400,0.00,4.0366,4.03670,9.000
9,60.467,0.00,3.7700,3.77007,9.000
9,60.533,0.00,3.5032,3.50330,9.000
9,60.600,-0.01,3.2366,3.23670,9.000
9,60.667,-0.02,2.9699,2.97000,9.000
9,60.733,-0.01,2.7032,2.70333,9.000
9,60.800,0.00,2.4367,2.43680,9.000
9,60.867,-0.01,2.1699,2.17000,9.000
9,60.933,0.00,1.9032,1.90333,9.000
9,61.000,0.00,1.6364,1.63650,9.000
9,61.067,0.00,1.3698,1.36990,9.000
9,61.133,0.00,1.1033,1.10340,9.000
9,61.200,-0.01,0.8366,0.83670,9.000
9,61.267,-0.01,0.5699,0.57000,9.000
9,61.333,-0.01,0.3031,0.30320,9.000
9,61.400,-0.01,0.0364,0.03650,9.000
9,61.533,0.00,-0.3637,-0.36363,9.000
9,61.600,0.00,-0.4029,-0.40280,9.000
9,61.667,-0.01,-0.3312,-0.33107,9.000
9,61.733,-0.01,-0.1537,-0.15363,9.000
9,61.800,0.00,-0.0241,-0.02400,9.000
9,61.867,-0.01,-0.0003,-0.00020,9.000
9,61.933,0.00,-0.0002,-0.00010,9.000
9,62.000,-0.01,-0.0002,-0.00010,9.000
9,62.067,0.00,-0.0002,-0.00010,9.000
9,62.133,0.00,-0.0002,-0.00010,9.000
9,62.200,0.00,-0.0002,-0.00010,9.000
9,62.267,0.00,-0.0002,-0.00010,9.000
9,62.333,0.00,-0.0002,-0.00010,9.000
9,62.400,-0.01,-0.0002,-0.00010,9.000
9,62.467,0.00,-0.0002,-0.00010,9.000
9,62.533,0.00,-0.0002,-0.00010,9.000
9,62.600,0.00,-0.0002,-0.00010,9.000
9,62.667,-0.01,-0.0002,-0.00010,9.000
9,62.733,-0.01,-0.0002,-0.00010,9.000
9,62.800,0.00,-0.0002,-0.00010,9.000
9,62.867,0.00,-0.0002,-0.00010,9.000
9,62.933,0.00,-0.0002,-0.00010,9.000
9,63.000,-0.02,-0.0002,-0.00010,9.000
9,63.067,-0.01,-0.0002,-0.00010,9.000
9,63.133,-0.01,-0.0002,-0.00010,9.000
9,63.200,0.01,-0.0002,-0.00010,9.000
9,63.267,0.01,-0.0002,-0.00010,9.000
9,63.333,-0.01,-0.0002,-0.00010,9.000
9,63.400,-0.01,-0.0002,-0.00010,9.000
9,63.467,0.00,-0.0002,-0.00010,9.000
9,63.533,0.00,-0.0002,-0.00010,9.000
9,63.600,-0.01,-0.0002,-0.00010,9.000
9,63.667,-0.01,-0.0002,-0.00010,9.000
9,63.733,-0.01,-0.0002,-0.00010,9.000
9,63.800,0.00,-0.0002,-0.00010,9.000
9,63.867,0.00,-0.0002,-0.00010,9.000
9,63.933,0.00,-0.0002,-0.00010,9.000
9,64.000,-0.01,-0.0002,-0.00010,9.000
9,64.067,0.00,-0.0002,-0.00010,9.000
9,64.133,0.00,-0.0002,-0.00010,9.000
9,64.200,0.00,-0.0002,-0.00010,9.000
9,64.267,-0.02,-0.0001,0.00000,9.000
9,64.333,-0.01,-0.0001,0.00000,9.000
9,64.400,0.00,-0.0001,0.00000,9.000
9,64.467,0.00,-0.0001,0.00000,9.000
9,64.600,-0.01,-0.0001,0.00000,9.000
10,64.800,0.00,0.0694,0.06950,10.000
10,64.867,-0.01,0.2503,0.25043,10.000
10,64.933,0.00,0.5129,0.51303,10.000
10,65.000,0.01,0.7796,0.77970,10.000
10,65.067,-0.01,1.0463,1.04640,10.000
10,65.133,0.00,1.3130,1.31310,10.000
10,65.200,0.01,1.5796,1.57970,10.000
10,65.267,0.00,1.8462,1.84630,10.000
10,65.333,0.00,2.1130,2.11310,10.000
10,65.400,0.00,2.3796,2.37970,10.000
10,65.467,0.00,2.6462,2.64630,10.000
10,65.533,0.00,2.9129,2.91300,10.000
10,65.600,0.01,3.1797,3.17980,10.000
10,65.667,0.01,3.4463,3.44643,10.000
10,65.733,0.00,3.7131,3.71320,10.000
10,65.800,0.00,3.9796,3.97970,10.000
10,65.867,0.01,4.2464,4.24647,10.000
10,65.933,0.03,4.5130,4.51313,10.000
10,66.000,0.26,4.7797,4.77980,10.000
10,66.067,0.91,5.0464,5.04653,10.000
10,66.133,2.07,5.3131,5.31317,10.000
10,66.200,3.74,5.5798,5.57990,10.000
10,66.267,6.05,5.8463,5.84643,10.000
10,66.333,9.08,6.1130,6.11307,10.000
10,66.400,12.98,6.3797,6.37980,10.000
10,66.467,17.95,6.6464,6.64650,10.000
10,66.600,30.91,7.1189,7.11900,10.000
10,66.667,34.07,7.2131,7.21317,10.000
10,66.733,32.65,7.1969,7.19703,10.000
10,66.800,26.74,7.0696,7.06970,10.000
10,66.867,18.57,6.8340,6.83413,10.000
10,66.933,12.00,6.5674,6.56753,10.000
10,67.000,7.71,6.3006,6.30070,10.000
10,67.067,4.93,6.0339,6.03397,10.000
10,67.133,3.06,5.7672,5.76733,10.000
10,67.200,1.77,5.5005,5.50060,10.000
10,67.267,0.85,5.2338,5.23393,10.000
10,67.333,0.28,4.9674,4.96747,10.000
10,67.400,0.03,4.7007,4.70080,10.000
10,67.467,-0.01,4.4339,4.43400,10.000
10,67.533,0.00,4.1672,4.16727,10.000
10,67.600,0.00,3.9004,3.90050,10.000
10,67.667,-0.01,3.6339,3.63403,10.000
10,67.733,0.00,3.3671,3.36723,10.000
10,67.800,-0.01,3.1006,3.10070,10.000
10,67.867,0.00,2.8339,2.83403,10.000
10,67.933,0.01,2.5672,2.56727,10.000
10,68.000,0.00,2.3005,2.30060,10.000
10,68.067,-0.01,2.0339,2.03403,10.000
10,68.133,-0.01,1.7672,1.76733,10.000
10,68.200,0.01,1.5003,1.50040,10.000
10,68.267,0.01,1.2338,1.23393,10.000
10,68.333,0.00,0.9671,0.96723,10.000
10,68.400,-0.01,0.7004,0.70050,10.000
10,68.467,0.00,0.4339,0.43397,10.000
10,68.533,0.01,0.1671,0.16717,10.000
10,68.600,-0.02,-0.0995,-0.09940,10.000
10,68.733,0.00,-0.4430,-0.44293,10.000
10,68.800,0.00,-0.4492,-0.44910,10.000
10,68.867,0.00,-0.3438,-0.34367,10.000
10,68.933,0.00,-0.1455,-0.14540,10.000
10,69.000,-0.01,-0.0193,-0.01920,10.000
10,69.067,0.00,-0.0002,-0.00007,10.000
10,69.133,0.00,-0.0002,-0.00010,10.000
10,69.200,0.00,-0.0002,-0.00010,10.000
10,69.267,0.00,-0.0001,0.00000,10.000
10,69.333,0.00,-0.0001,-0.00003,10.000
10,69.400,0.00,-0.0001,0.00000,10.000
10,69.467,-0.01,-0.0001,0.00000,10.000
10,69.533,0.00,-0.0001,0.00000,10.000
10,69.600,0.00,-0.0001,0.00000,10.000
10,69.667,0.00,-0.0001,0.00000,10.000
10,69.733,0.00,-0.0001,0.00000,10.000
10,69.800,-0.01,-0.0001,0.00000,10.000
10,69.867,0.00,-0.0001,0.00000,10.000
10,69.933,0.01,-0.0001,0.00000,10.000
10,70.000,0.01,-0.0001,0.00000,10.000
10,70.067,0.00,-0.0001,0.00000,10.000
10,70.133,0.00,-0.0001,0.00000,10.000
10,70.200,0.00,-0.0001,0.00000,10.000
10,70.267,-0.01,-0.0001,0.00000,10.000
10,70.333,0.00,-0.0001,0.00000,10.000
10,70.400,0.00,-0.0001,0.00000,10.000
10,70.467,0.00,-0.0001,0.00000,10.000
10,70.533,0.00,-0.0001,0.00000,10.000
10,70.600,0.01,-0.0001,0.00000,10.000
10,70.667,0.00,-0.0001,0.00000,10.000
10,70.733,0.00,-0.0001,0.00000,10.000
10,70.800,0.00,-0.0001,0.00000,10.000
10,70.867,0.00,-0.0001,0.00000,10.000
10,70.933,-0.01,-0.0001,0.00000,10.000
10,71.000,0.01,-0.0001,0.00000,10.000
10,71.067,0.00,-0.0001,0.00000,10.000
10,71.133,0.00,-0.0001,0.00000,10.000
10,71.200,0.00,-0.0001,0.00000,10.000
10,71.267,0.00,-0.0001,0.00000,10.000
10,71.333,0.00,-0.0001,0.00000,10.000
10,71.400,0.00,-0.0001,0.00000,10.000
10,71.467,0.00,-0.0001,0.00000,10.000
10,71.533,0.00,-0.0001,0.00000,10.000
10,71.600,0.00,-0.0001,0.00000,10.000
10,71.667,0.00,-0.0001,0.00000,10.000