File: calibDATA_loadcell/date_02:15:2018/Instron_02.15.2018/2_20N_0__1mm.s_0_0.txt
""
"Test Method","Radhen_Load_Cntrl_Cmprsn_250N_12-7.msm"
"Sample I. D.","Sample1.mss"
"Specimen Number","17"

"TheCycle_Output ()","_Time (s)","_Load (N)","_Extension (mm)","RealTimeDepth (mm)","CycleNumber ()"

1,0.200,-0.02,0.0000,0.00000,1.000
1,0.400,-0.02,0.1835,0.18350,1.000
1,0.600,0.00,0.3835,0.38350,1.000
1,0.800,-0.01,0.5835,0.58350,1.000
1,1.000,-0.01,0.7835,0.78350,1.000
1,1.200,-0.02,0.9837,0.98370,1.000
1,1.400,-0.01,1.1836,1.18360,1.000
1,1.600,-0.01,1.3836,1.38360,1.000
1,1.800,-0.02,1.5837,1.58370,1.000
1,2.000,0.00,1.7836,1.78360,1.000
1,2.200,-0.01,1.9837,1.98370,1.000
1,2.400,-0.02,2.1836,2.18360,1.000
1,2.600,-0.01,2.3836,2.38360,1.000
1,2.800,-0.01,2.5836,2.58360,1.000
1,3.000,-0.01,2.7836,2.78360,1.000
1,3.200,-0.01,2.9837,2.98370,1.000
1,3.400,-0.01,3.1837,3.18370,1.000
1,3.600,-0.01,3.3837,3.38370,1.000
1,3.800,-0.02,3.5837,3.58370,1.000
1,4.000,-0.02,3.7837,3.78370,1.000
1,4.200,-0.01,3.9836,3.98360,1.000
1,4.400,-0.01,4.1837,4.18370,1.000
1,4.600,-0.01,4.3837,4.38370,1.000
1,4.800,-0.02,4.5837,4.58370,1.000
1,5.000,-0.03,4.7837,4.78370,1.000
1,5.200,-0.01,4.9838,4.98380,1.000
1,5.400,-0.02,5.1839,5.18390,1.000
1,5.600,-0.02,5.3838,5.38380,1.000
1,5.800,-0.02,5.5839,5.58390,1.000
1,6.000,0.00,5.7838,5.78380,1.000
1,6.200,0.01,5.9838,5.98380,1.000
1,6.400,0.06,6.1838,6.18380,1.000
1,6.600,0.20,6.3839,6.38390,1.000
1,6.800,0.55,6.5839,6.58390,1.000
1,7.000,1.12,6.7841,6.78410,1.000
1,7.200,1.93,6.9840,6.98400,1.000
1,7.400,3.01,7.1841,7.18410,1.000
1,7.600,4.41,7.3841,7.38410,1.000
1,7.800,6.16,7.5839,7.58390,1.000
1,8.000,8.30,7.7840,7.78400,1.000
1,8.200,10.90,7.9841,7.98410,1.000
1,8.400,14.10,8.1839,8.18390,1.000
1,8.600,18.06,8.3840,8.38400,1.000
1,8.867,18.04,8.4181,8.41807,1.000
1,9.067,12.80,8.2180,8.21797,1.000
1,9.267,9.18,8.0180,8.01803,1.000
1,9.467,6.54,7.8180,7.81803,1.000
1,9.667,4.60,7.6178,7.61783,1.000
1,9.867,3.15,7.4180,7.41803,1.000
1,10.067,2.08,7.2181,7.21807,1.000
1,10.267,1.28,7.0179,7.01793,1.000
1,10.467,0.69,6.8179,6.81793,1.000
1,10.667,0.30,6.6179,6.61787,1.000
1,10.867,0.09,6.4180,6.41797,1.000
1,11.067,0.00,6.2178,6.21783,1.000
1,11.267,-0.02,6.0178,6.01780,1.000
1,11.467,-0.01,5.8178,5.81780,1.000
1,11.667,-0.02,5.6178,5.61780,1.000
1,11.867,-0.01,5.4178,5.41780,1.000
1,12.067,-0.01,5.2178,5.21780,1.000
1,12.267,-0.02,5.0177,5.01773,1.000
1,12.467,-0.02,4.8175,4.81753,1.000
1,12.667,-0.02,4.6178,4.61777,1.000
1,12.867,-0.02,4.4177,4.41767,1.000
1,13.067,-0.01,4.2178,4.21777,1.000
1,13.267,-0.01,4.0176,4.01763,1.000
1,13.467,-0.01,3.8176,3.81760,1.000
1,13.667,-0.01,3.6175,3.61747,1.000
1,13.867,-0.01,3.4176,3.41760,1.000
1,14.067,-0.01,3.2176,3.21763,1.000
1,14.267,-0.01,3.0176,3.01760,1.000
1,14.467,-0.01,2.8175,2.81753,1.000
1,14.667,-0.01,2.6176,2.61757,1.000
1,14.867,-0.01,2.4174,2.41743,1.000
1,15.067,-0.01,2.2176,2.21757,1.000
1,15.267,-0.01,2.0175,2.01750,1.000
1,15.467,-0.01,1.8173,1.81733,1.000
1,15.667,-0.01,1.6175,1.61750,1.000
1,15.867,-0.02,1.4176,1.41757,1.000
1,16.067,-0.01,1.2175,1.21747,1.000
1,16.267,-0.01,1.0176,1.01757,1.000
1,16.467,-0.01,0.8174,0.81740,1.000
1,16.667,-0.02,0.6174,0.61743,1.000
1,16.867,-0.01,0.4174,0.41740,1.000
1,17.067,-0.01,0.2175,0.21750,1.000
1,17.267,-0.01,0.0174,0.01740,1.000
1,17.533,-0.02,-0.0003,-0.00030,1.000
1,17.733,-0.02,-0.0003,-0.00030,1.000
1,17.933,-0.01,-0.0003,-0.00030,1.000
1,18.133,-0.01,-0.0003,-0.00030,1.000
1,18.333,-0.01,-0.0003,-0.00030,1.000
1,18.533,-0.02,-0.0003,-0.00030,1.000
1,18.733,-0.01,-0.0003,-0.00030,1.000
1,18.933,-0.01,-0.0003,-0.00030,1.000
1,19.133,-0.01,-0.0003,-0.00030,1.000
1,19.333,-0.01,-0.0003,-0.00030,1.000
1,19.533,-0.02,-0.0003,-0.00030,1.000
1,19.733,-0.01,-0.0002,-0.00020,1.000
1,19.933,-0.02,-0.0002,-0.00020,1.000
1,20.133,-0.01,-0.0002,-0.00020,1.000
1,20.333,-0.01,-0.0002,-0.00020,1.000
1,20.667,-0.02,-0.0002,-0.00020,1.000
1,20.867,-0.02,-0.0002,-0.00020,1.000
1,21.067,-0.02,-0.0002,-0.00020,1.000
1,21.267,-0.02,-0.0002,-0.00020,1.000
2,21.667,0.00,0.0803,0.08037,2.000
2,21.867,0.00,0.2803,0.28037,2.000
2,22.067,0.00,0.4803,0.48037,2.000
2,22.267,0.00,0.6804,0.68047,2.000
2,22.467,0.00,0.8803,0.88043,2.000
2,22.667,0.00,1.0804,1.08047,2.000
2,22.867,0.00,1.2804,1.28050,2.000
2,23.067,0.00,1.4804,1.48053,2.000
2,23.267,0.00,1.6805,1.68060,2.000
2,23.467,0.00,1.8803,1.88043,2.000
2,23.667,0.00,2.0804,2.08050,2.000
2,23.867,0.00,2.2804,2.28047,2.000
2,24.067,0.00,2.4804,2.48050,2.000
2,24.267,0.00,2.6804,2.68047,2.000
2,24.467,0.00,2.8804,2.88053,2.000
2,24.667,0.00,3.0804,3.08053,2.000
2,24.867,0.00,3.2805,3.28057,2.000
2,25.067,0.00,3.4805,3.48063,2.000
2,25.267,0.00,3.6804,3.68050,2.000
2,25.467,0.00,3.8805,3.88060,2.000
2,25.667,-0.01,4.0804,4.08047,2.000
2,25.867,0.00,4.2805,4.28057,2.000
2,26.067,0.00,4.4805,4.48057,2.000
2,26.267,0.00,4.6806,4.68070,2.000
2,26.467,-0.01,4.8804,4.88050,2.000
2,26.667,-0.01,5.0805,5.08060,2.000
2,26.867,0.00,5.2805,5.28060,2.000
2,27.067,-0.01,5.4806,5.48067,2.000
2,27.267,0.00,5.6805,5.68063,2.000
2,27.467,0.00,5.8806,5.88067,2.000
2,27.667,0.03,6.0804,6.08053,2.000
2,27.867,0.10,6.2804,6.28053,2.000
2,28.067,0.32,6.4805,6.48063,2.000
2,28.267,0.74,6.6806,6.68067,2.000
2,28.467,1.41,6.8805,6.88057,2.000
2,28.667,2.34,7.0805,7.08063,2.000
2,28.867,3.55,7.2806,7.28067,2.000
2,29.067,5.12,7.4806,7.48070,2.000
2,29.267,7.06,7.6805,7.68057,2.000
2,29.467,9.48,7.8805,7.88057,2.000
2,29.667,12.39,8.0805,8.08063,2.000
2,29.867,15.94,8.2804,8.28053,2.000
2,30.067,20.35,8.4804,8.48050,2.000
2,30.333,15.75,8.3414,8.34153,2.000
2,30.533,11.28,8.1414,8.14153,2.000
2,30.733,8.08,7.9413,7.94143,2.000
2,30.933,5.72,7.7413,7.74140,2.000
2,31.133,3.99,7.5412,7.54133,2.000
2,31.333,2.71,7.3413,7.34143,2.000
2,31.533,1.75,7.1414,7.14147,2.000
2,31.733,1.03,6.9412,6.94127,2.000
2,31.933,0.52,6.7413,6.74137,2.000
2,32.133,0.21,6.5411,6.54123,2.000
2,32.333,0.06,6.3411,6.34120,2.000
2,32.533,0.01,6.1411,6.14120,2.000
2,32.733,0.00,5.9411,5.94123,2.000
2,32.933,0.00,5.7411,5.74117,2.000
2,33.133,0.00,5.5412,5.54127,2.000
2,33.333,-0.01,5.3411,5.34120,2.000
2,33.533,0.00,5.1411,5.14117,2.000
2,33.733,0.00,4.9410,4.94113,2.000
2,33.933,0.00,4.7410,4.74110,2.000
2,34.133,0.00,4.5410,4.54113,2.000
2,34.333,0.00,4.3410,4.34107,2.000
2,34.533,0.00,4.1409,4.14103,2.000
2,34.733,0.00,3.9410,3.94110,2.000
2,34.933,0.00,3.7408,3.74087,2.000
2,35.133,0.00,3.5408,3.54090,2.000
2,35.333,0.00,3.3410,3.34107,2.000
2,35.533,0.00,3.1409,3.14097,2.000
2,35.733,0.00,2.9409,2.94100,2.000
2,35.933,0.00,2.7408,2.74093,2.000
2,36.133,0.00,2.5407,2.54083,2.000
2,36.333,0.00,2.3408,2.34090,2.000
2,36.533,0.00,2.1408,2.14087,2.000
2,36.733,0.00,1.9407,1.94077,2.000
2,36.933,0.00,1.7408,1.74087,2.000
2,37.133,0.00,1.5408,1.54087,2.000
2,37.333,0.00,1.3408,1.34093,2.000
2,37.533,0.00,1.1407,1.14080,2.000
2,37.733,0.00,0.9407,0.94083,2.000
2,37.933,0.00,0.7408,0.74090,2.000
2,38.133,0.00,0.5407,0.54077,2.000
2,38.333,0.00,0.3407,0.34077,2.000
2,38.533,0.00,0.1408,0.14090,2.000
2,38.800,0.00,-0.0084,-0.00830,2.000
2,39.000,0.00,-0.0003,-0.00020,2.000
2,39.200,0.00,-0.0003,-0.00020,2.000
2,39.400,0.00,-0.0003,-0.00020,2.000
2,39.600,0.00,-0.0003,-0.00020,2.000
2,39.800,0.00,-0.0003,-0.00020,2.000
2,40.000,0.00,-0.0003,-0.00020,2.000
2,40.200,0.00,-0.0003,-0.00020,2.000
2,40.400,0.00,-0.0002,-0.00010,2.000
2,40.600,0.00,-0.0002,-0.00010,2.000
2,40.800,0.00,-0.0002,-0.00010,2.000
2,41.000,0.00,-0.0002,-0.00010,2.000
2,41.200,0.00,-0.0002,-0.00010,2.000
2,41.400,0.00,-0.0002,-0.00010,2.000
2,41.600,0.00,-0.0002,-0.00010,2.000
2,41.867,0.00,-0.0002,-0.00010,2.000
2,42.067,0.00,-0.0002,-0.00010,2.000
2,42.267,0.00,-0.0002,-0.00010,2.000
2,42.467,0.00,-0.0002,-0.00010,2.000
2,42.667,0.00,-0.0002,-0.00010,2.000
3,43.067,0.00,0.1052,0.10530,3.000
3,43.267,-0.01,0.3051,0.30523,3.000
3,43.467,-0.01,0.5051,0.50523,3.000
3,43.667,-0.01,0.7053,0.70537,3.000
3,43.867,-0.01,0.9053,0.90537,3.000
3,44.067,0.00,1.1053,1.10537,3.000
3,44.267,0.00,1.3053,1.30540,3.000
3,44.467,-0.01,1.5053,1.50540,3.000
3,44.667,-0.01,1.7054,1.70547,3.000
3,44.867,-0.01,1.9053,1.90537,3.000
3,45.067,0.00,2.1053,2.10540,3.000
3,45.267,-0.01,2.3054,2.30547,3.000
3,45.467,0.00,2.5053,2.50543,3.000
3,45.667,-0.01,2.7053,2.70540,3.000
3,45.867,0.00,2.9053,2.90543,3.000
3,46.067,-0.01,3.1054,3.10547,3.000
3,46.267,-0.01,3.3054,3.30550,3.000
3,46.467,-0.01,3.5055,3.50557,3.000
3,46.667,-0.01,3.7054,3.70547,3.000
3,46.867,-0.01,3.9054,3.90547,3.000
3,47.067,-0.01,4.1054,4.10550,3.000
3,47.267,-0.01,4.3054,4.30553,3.000
3,47.467,-0.01,4.5054,4.50550,3.000
3,47.667,-0.01,4.7054,4.70553,3.000
3,47.867,-0.01,4.9055,4.90557,3.000
3,48.067,0.00,5.1055,5.10557,3.000
3,48.267,0.00,5.3056,5.30567,3.000
3,48.467,-0.01,5.5055,5.50560,3.000
3,48.667,0.00,5.7055,5.70560,3.000
3,48.867,0.01,5.9055,5.90563,3.000
3,49.067,0.03,6.1054,6.10547,3.000
3,49.267,0.12,6.3054,6.30553,3.000
3,49.467,0.36,6.5056,6.50570,3.000
3,49.667,0.81,6.7056,6.70570,3.000
3,49.867,1.51,6.9056,6.90567,3.000
3,50.067,2.46,7.1057,7.10577,3.000
3,50.267,3.71,7.3058,7.30587,3.000
3,50.467,5.33,7.5056,7.50570,3.000
3,50.667,7.33,7.7055,7.70560,3.000
3,50.867,9.78,7.9056,7.90570,3.000
3,51.067,12.76,8.1056,8.10573,3.000
3,51.267,16.40,8.3055,8.30563,3.000
3,51.533,20.63,8.4862,8.48633,3.000
3,51.733,14.41,8.2862,8.28630,3.000
3,51.933,10.33,8.0863,8.08640,3.000
3,52.133,7.38,7.8863,7.88637,3.000
3,52.333,5.21,7.6861,7.68623,3.000
3,52.533,3.60,7.4863,7.48637,3.000
3,52.733,2.41,7.2863,7.28637,3.000
3,52.933,1.52,7.0862,7.08630,3.000
3,53.133,0.87,6.8861,6.88623,3.000
3,53.333,0.42,6.6861,6.68623,3.000
3,53.533,0.15,6.4861,6.48623,3.000
3,53.733,0.03,6.2860,6.28613,3.000
3,53.933,0.00,6.0861,6.08617,3.000
3,54.133,-0.01,5.8861,5.88623,3.000
3,54.333,-0.01,5.6861,5.68620,3.000
3,54.533,0.00,5.4861,5.48620,3.000
3,54.733,-0.01,5.2861,5.28623,3.000
3,54.933,-0.01,5.0861,5.08620,3.000
3,55.133,-0.01,4.8861,4.88617,3.000
3,55.333,-0.01,4.6862,4.68627,3.000
3,55.533,-0.01,4.4861,4.48620,3.000
3,55.733,-0.01,4.2861,4.28620,3.000
3,55.933,-0.01,4.0860,4.08613,3.000
3,56.133,-0.01,3.8860,3.88613,3.000
3,56.333,0.00,3.6859,3.68603,3.000
3,56.533,-0.01,3.4860,3.48607,3.000
3,56.733,-0.01,3.2861,3.28617,3.000
3,56.933,-0.01,3.0859,3.08603,3.000
3,57.133,0.00,2.8859,2.88603,3.000
3,57.333,-0.01,2.6859,2.68603,3.000
3,57.533,-0.01,2.4859,2.48600,3.000
3,57.733,0.00,2.2859,2.28600,3.000
3,57.933,-0.01,2.0859,2.08597,3.000
3,58.133,-0.01,1.8858,1.88593,3.000
3,58.333,0.00,1.6860,1.68610,3.000
3,58.533,-0.01,1.4859,1.48600,3.000
3,58.733,0.00,1.2859,1.28603,3.000
3,58.933,0.00,1.0858,1.08593,3.000
3,59.133,0.00,0.8859,0.88597,3.000
3,59.333,-0.01,0.6860,0.68607,3.000
3,59.533,0.00,0.4858,0.48590,3.000
3,59.733,0.00,0.2858,0.28590,3.000
3,59.933,-0.01,0.0859,0.08597,3.000
3,60.200,0.00,-0.0003,-0.00020,3.000
3,60.400,-0.01,-0.0003,-0.00020,3.000
3,60.600,0.01,-0.0003,-0.00020,3.000
3,60.800,-0.01,-0.0003,-0.00020,3.000
3,61.000,-0.01,-0.0003,-0.00020,3.000
3,61.200,-0.03,-0.0003,-0.00020,3.000
3,61.400,0.00,-0.0003,-0.00020,3.000
3,61.600,-0.02,-0.0003,-0.00020,3.000
3,61.800,-0.01,-0.0002,-0.00010,3.000
3,62.000,0.00,-0.0002,-0.00010,3.000
3,62.200,-0.01,-0.0002,-0.00010,3.000
3,62.400,0.01,-0.0002,-0.00010,3.000
3,62.600,-0.01,-0.0002,-0.00010,3.000
3,62.800,-0.01,-0.0002,-0.00010,3.000
3,63.000,-0.01,-0.0002,-0.00010,3.000
3,63.267,0.00,-0.0002,-0.00010,3.000
3,63.467,-0.01,-0.0002,-0.00010,3.000
3,63.667,-0.01,-0.0002,-0.00010,3.000
3,63.867,0.00,-0.0002,-0.00010,3.000
3,64.067,0.00,-0.0002,-0.00010,3.000
4,64.533,0.01,0.2169,0.21687,4.000
4,64.733,0.00,0.4168,0.41680,4.000
4,64.933,0.00,0.6168,0.61683,4.000
4,65.133,0.01,0.8169,0.81690,4.000
4,65.333,0.01,1.0170,1.01700,4.000
4,65.533,0.00,1.2170,1.21703,4.000
4,65.733,0.01,1.4171,1.41713,4.000
4,65.933,0.01,1.6171,1.61710,4.000
4,66.133,0.00,1.8170,1.81697,4.000
4,66.333,0.01,2.0170,2.01703,4.000
4,66.533,0.01,2.2171,2.21707,4.000
4,66.733,0.01,2.4170,2.41703,4.000
4,66.933,0.01,2.6171,2.61710,4.000
4,67.133,0.01,2.8171,2.81710,4.000
4,67.333,0.01,3.0171,3.01710,4.000
4,67.533,0.00,3.2172,3.21717,4.000
4,67.733,0.01,3.4172,3.41717,4.000
4,67.933,0.00,3.6171,3.61713,4.000
4,68.133,0.01,3.8171,3.81710,4.000
4,68.333,0.00,4.0171,4.01710,4.000
4,68.533,0.01,4.2173,4.21727,4.000
4,68.733,0.00,4.4171,4.41713,4.000
4,68.933,0.01,4.6173,4.61727,4.000
4,69.133,0.01,4.8172,4.81717,4.000
4,69.333,0.02,5.0172,5.01717,4.000
4,69.533,0.01,5.2172,5.21723,4.000
4,69.733,0.01,5.4173,5.41730,4.000
4,69.933,0.01,5.6173,5.61730,4.000
4,70.133,0.02,5.8173,5.81727,4.000
4,70.333,0.03,6.0172,6.01720,4.000
4,70.533,0.08,6.2172,6.21717,4.000
4,70.733,0.24,6.4173,6.41730,4.000
4,70.933,0.60,6.6172,6.61723,4.000
4,71.133,1.17,6.8174,6.81740,4.000
4,71.333,2.00,7.0173,7.01730,4.000
4,71.533,3.12,7.2174,7.21737,4.000
4,71.733,4.57,7.4174,7.41737,4.000
4,71.933,6.39,7.6172,7.61720,4.000
4,72.133,8.62,7.8173,7.81727,4.000
4,72.333,11.35,8.0173,8.01733,4.000
4,72.533,14.69,8.2172,8.21720,4.000
4,72.733,18.80,8.4173,8.41730,4.000
4,73.000,17.54,8.4046,8.40460,4.000
4,73.200,12.50,8.2045,8.20450,4.000
4,73.400,8.97,8.0045,8.00450,4.000
4,73.600,6.39,7.8045,7.80450,4.000
4,73.800,4.49,7.6043,7.60430,4.000
4,74.000,3.07,7.4045,7.40450,4.000
4,74.200,2.02,7.2045,7.20450,4.000
4,74.400,1.25,7.0044,7.00440,4.000
4,74.600,0.67,6.8045,6.80450,4.000
4,74.800,0.30,6.6045,6.60450,4.000
4,75.000,0.10,6.4044,6.40440,4.000
4,75.200,0.03,6.2044,6.20440,4.000
4,75.400,0.01,6.0044,6.00440,4.000
4,75.600,0.02,5.8044,5.80440,4.000
4,75.800,0.00,5.6045,5.60450,4.000
4,76.000,0.01,5.4044,5.40440,4.000
4,76.200,0.00,5.2045,5.20450,4.000
4,76.400,0.00,5.0045,5.00450,4.000
4,76.600,0.01,4.8042,4.80420,4.000
4,76.800,0.02,4.6044,4.60440,4.000
4,77.000,0.00,4.4043,4.40430,4.000
4,77.200,0.00,4.2045,4.20450,4.000
4,77.400,0.01,4.0043,4.00430,4.000
4,77.600,0.01,3.8043,3.80430,4.000
4,77.800,0.01,3.6042,3.60420,4.000
4,78.000,0.01,3.4044,3.40440,4.000
4,78.200,0.01,3.2043,3.20430,4.000
4,78.400,0.02,3.0043,3.00430,4.000
4,78.600,0.01,2.8043,2.80430,4.000
4,78.800,0.00,2.6043,2.60430,4.000
4,79.000,0.00,2.4042,2.40420,4.000
4,79.200,0.01,2.2043,2.20430,4.000
4,79.400,0.00,2.0042,2.00420,4.000
4,79.600,-0.01,1.8042,1.80420,4.000
4,79.800,0.01,1.6043,1.60430,4.000
4,80.000,0.01,1.4042,1.40420,4.000
4,80.200,0.01,1.2041,1.20410,4.000
4,80.400,0.01,1.0044,1.00440,4.000
4,80.600,0.00,0.8043,0.80430,4.000
4,80.800,0.01,0.6043,0.60430,4.000
4,81.000,0.01,0.4041,0.40410,4.000
4,81.200,0.00,0.2042,0.20420,4.000
4,81.400,0.00,0.0042,0.00420,4.000
4,81.667,0.01,-0.0003,-0.00030,4.000
4,81.867,0.01,-0.0003,-0.00030,4.000
4,82.067,0.01,-0.0003,-0.00030,4.000
4,82.267,0.01,-0.0003,-0.00030,4.000
4,82.467,0.01,-0.0003,-0.00030,4.000
4,82.667,0.01,-0.0003,-0.00030,4.000
4,82.867,0.00,-0.0003,-0.00030,4.000
4,83.067,0.01,-0.0003,-0.00030,4.000
4,83.267,0.01,-0.0003,-0.00030,4.000
4,83.467,0.01,-0.0002,-0.00020,4.000
4,83.667,0.01,-0.0002,-0.00020,4.000
4,83.867,0.01,-0.0002,-0.00020,4.000
4,84.067,0.01,-0.0002,-0.00020,4.000
4,84.267,0.01,-0.0002,-0.00020,4.000
4,84.467,0.01,-0.0002,-0.00020,4.000
4,84.733,0.00,-0.0002,-0.00020,4.000
4,84.933,0.01,-0.0002,-0.00020,4.000
4,85.133,0.01,-0.0002,-0.00020,4.000
4,85.333,0.00,-0.0002,-0.00020,4.000
5,85.800,0.02,0.1033,0.10340,5.000
5,86.000,0.02,0.3035,0.30360,5.000
5,86.200,0.02,0.5034,0.50350,5.000
5,86.400,0.01,0.7035,0.70360,5.000
5,86.600,0.01,0.9035,0.90360,5.000
5,86.800,0.01,1.1035,1.10360,5.000
5,87.000,0.01,1.3036,1.30370,5.000
5,87.200,0.01,1.5038,1.50390,5.000
5,87.400,0.01,1.7037,1.70380,5.000
5,87.600,0.02,1.9036,1.90370,5.000
5,87.800,0.01,2.1036,2.10370,5.000
5,88.000,0.02,2.3037,2.30380,5.000
5,88.200,0.01,2.5036,2.50370,5.000
5,88.400,0.01,2.7037,2.70380,5.000
5,88.600,0.01,2.9037,2.90380,5.000
5,88.800,0.01,3.1037,3.10380,5.000
5,89.000,0.01,3.3039,3.30400,5.000
5,89.200,0.01,3.5039,3.50400,5.000
5,89.400,0.01,3.7036,3.70370,5.000
5,89.600,0.01,3.9038,3.90390,5.000
5,89.800,0.02,4.1037,4.10380,5.000
5,90.000,-0.01,4.3038,4.30390,5.000
5,90.200,0.02,4.5038,4.50390,5.000
5,90.400,0.01,4.7039,4.70400,5.000
5,90.600,0.01,4.9038,4.90390,5.000
5,90.800,0.01,5.1039,5.10400,5.000
5,91.000,0.01,5.3039,5.30400,5.000
5,91.200,0.01,5.5039,5.50400,5.000
5,91.400,0.02,5.7039,5.70400,5.000
5,91.600,0.03,5.9039,5.90400,5.000
5,91.800,0.06,6.1038,6.10390,5.000
5,92.000,0.13,6.3039,6.30400,5.000
5,92.200,0.35,6.5039,6.50400,5.000
5,92.400,0.82,6.7041,6.70420,5.000
5,92.600,1.51,6.9039,6.90400,5.000
5,92.800,2.45,7.1040,7.10410,5.000
5,93.000,3.69,7.3040,7.30410,5.000
5,93.200,5.31,7.5040,7.50410,5.000
5,93.400,7.31,7.7039,7.70400,5.000
5,93.600,9.78,7.9040,7.90410,5.000
5,93.800,12.76,8.1039,8.10400,5.000
5,94.000,16.41,8.3038,8.30390,5.000
5,94.200,20.94,8.5039,8.50400,5.000
5,94.400,16.97,8.3847,8.38480,5.000
5,94.600,12.12,8.1846,8.18470,5.000
5,94.800,8.71,7.9847,7.98480,5.000
5,95.000,6.19,7.7846,7.78470,5.000
5,95.200,4.33,7.5844,7.58450,5.000
5,95.400,2.95,7.3847,7.38480,5.000
5,95.600,1.94,7.1846,7.18470,5.000
5,95.800,1.17,6.9845,6.98460,5.000
5,96.000,0.62,6.7846,6.78470,5.000
5,96.200,0.27,6.5846,6.58470,5.000
5,96.400,0.09,6.3845,6.38460,5.000
5,96.600,0.02,6.1845,6.18460,5.000
5,96.800,0.01,5.9845,5.98460,5.000
5,97.000,0.01,5.7845,5.78460,5.000
5,97.200,0.01,5.5845,5.58460,5.000
5,97.400,0.01,5.3844,5.38450,5.000
5,97.600,0.01,5.1844,5.18450,5.000
5,97.800,0.01,4.9844,4.98450,5.000
5,98.000,0.01,4.7843,4.78440,5.000
5,98.200,0.01,4.5844,4.58450,5.000
5,98.400,0.01,4.3843,4.38440,5.000
5,98.600,0.01,4.1844,4.18450,5.000
5,98.800,0.00,3.9843,3.98440,5.000
5,99.000,0.01,3.7842,3.78430,5.000
5,99.200,0.01,3.5842,3.58430,5.000
5,99.400,0.01,3.3842,3.38430,5.000
5,99.600,0.02,3.1843,3.18440,5.000
5,99.800,0.02,2.9843,2.98440,5.000
5,100.000,0.02,2.7842,2.78430,5.000
5,100.200,0.02,2.5842,2.58430,5.000
5,100.400,0.01,2.3842,2.38430,5.000
5,100.600,0.02,2.1842,2.18430,5.000
5,100.800,0.02,1.9841,1.98420,5.000
5,101.000,0.02,1.7840,1.78410,5.000
5,101.200,0.01,1.5842,1.58430,5.000
5,101.400,0.01,1.3841,1.38420,5.000
5,101.600,0.01,1.1840,1.18410,5.000
5,101.800,0.01,0.9841,0.98420,5.000
5,102.000,0.01,0.7841,0.78420,5.000
5,102.200,0.01,0.5840,0.58410,5.000
5,102.400,0.01,0.3840,0.38410,5.000
5,102.600,0.02,0.1839,0.18400,5.000
5,102.800,0.02,-0.0160,-0.01590,5.000
5,103.067,0.01,-0.0003,-0.00020,5.000
5,103.267,0.01,-0.0003,-0.00020,5.000
5,103.467,0.01,-0.0003,-0.00020,5.000
5,103.667,0.02,-0.0003,-0.00020,5.000
5,103.867,0.01,-0.0003,-0.00020,5.000
5,104.067,0.01,-0.0003,-0.00020,5.000
5,104.267,0.02,-0.0003,-0.00020,5.000
5,104.467,0.01,-0.0003,-0.00020,5.000
5,104.667,0.01,-0.0003,-0.00020,5.000
5,104.867,0.02,-0.0002,-0.00010,5.000
5,105.067,0.01,-0.0002,-0.00010,5.000
5,105.267,0.01,-0.0002,-0.00010,5.000
5,105.467,0.01,-0.0002,-0.00010,5.000
5,105.667,0.01,-0.0002,-0.00010,5.000
5,105.867,0.01,-0.0002,-0.00010,5.000
5,106.133,0.01,-0.0002,-0.00010,5.000
5,106.333,0.01,-0.0002,-0.00010,5.000
5,106.533,0.01,-0.0002,-0.00010,5.000
5,106.733,0.01,-0.0002,-0.00010,5.000
6,107.200,0.01,0.1135,0.11350,6.000
6,107.400,0.00,0.3135,0.31350,6.000
6,107.600,0.00,0.5134,0.51340,6.000
6,107.800,0.00,0.7136,0.71360,6.000
6,108.000,0.02,0.9136,0.91360,6.000
6,108.200,-0.01,1.1135,1.11350,6.000
6,108.400,0.00,1.3137,1.31370,6.000
6,108.600,0.02,1.5137,1.51370,6.000
6,108.800,0.00,1.7137,1.71370,6.000
6,109.000,0.01,1.9136,1.91360,6.000
6,109.200,0.00,2.1137,2.11370,6.000
6,109.400,0.01,2.3137,2.31370,6.000
6,109.600,0.01,2.5136,2.51360,6.000
6,109.800,0.00,2.7137,2.71370,6.000
6,110.000,0.01,2.9136,2.91360,6.000
6,110.200,0.00,3.1136,3.11360,6.000
6,110.400,0.00,3.3138,3.31380,6.000
6,110.600,0.01,3.5136,3.51360,6.000
6,110.800,0.00,3.7136,3.71360,6.000
6,111.000,0.00,3.9138,3.91380,6.000
6,111.200,0.00,4.1137,4.11370,6.000
6,111.400,0.00,4.3137,4.31370,6.000
6,111.600,-0.01,4.5136,4.51360,6.000
6,111.800,0.00,4.7137,4.71370,6.000
6,112.000,0.00,4.9136,4.91360,6.000
6,112.200,0.00,5.1137,5.11370,6.000
6,112.400,0.00,5.3138,5.31380,6.000
6,112.600,0.00,5.5138,5.51380,6.000
6,112.800,0.01,5.7137,5.71370,6.000
6,113.000,0.01,5.9138,5.91380,6.000
6,113.200,0.05,6.1137,6.11370,6.000
6,113.400,0.13,6.3137,6.31370,6.000
6,113.600,0.38,6.5139,6.51390,6.000
6,113.800,0.83,6.7139,6.71390,6.000
6,114.000,1.54,6.9138,6.91380,6.000
6,114.200,2.50,7.1139,7.11390,6.000
6,114.400,3.76,7.3141,7.31410,6.000
6,114.600,5.39,7.5139,7.51390,6.000
6,114.800,7.41,7.7138,7.71380,6.000
6,115.000,9.89,7.9140,7.91400,6.000
6,115.200,12.90,8.1139,8.11390,6.000
6,115.400,16.60,8.3139,8.31390,6.000
6,115.667,21.22,8.5078,8.50777,6.000
6,115.867,14.85,8.3079,8.30793,6.000
6,116.067,10.65,8.1080,8.10803,6.000
6,116.267,7.62,7.9079,7.90793,6.000
6,116.467,5.39,7.7078,7.70783,6.000
6,116.667,3.73,7.5079,7.50790,6.000
6,116.867,2.51,7.3079,7.30793,6.000
6,117.067,1.60,7.1079,7.10793,6.000
6,117.267,0.92,6.9079,6.90787,6.000
6,117.467,0.45,6.7079,6.70790,6.000
6,117.667,0.17,6.5079,6.50790,6.000
6,117.867,0.04,6.3077,6.30773,6.000
6,118.067,0.01,6.1077,6.10770,6.000
6,118.267,0.00,5.9079,5.90787,6.000
6,118.467,0.01,5.7078,5.70777,6.000
6,118.667,0.00,5.5078,5.50783,6.000
6,118.867,0.00,5.3078,5.30780,6.000
6,119.067,-0.01,5.1077,5.10767,6.000
6,119.267,0.01,4.9077,4.90767,6.000
6,119.467,0.00,4.7077,4.70773,6.000
6,119.667,0.00,4.5077,4.50767,6.000
6,119.867,-0.01,4.3077,4.30767,6.000
6,120.067,0.01,4.1076,4.10763,6.000
6,120.267,0.00,3.9076,3.90760,6.000
6,120.467,0.00,3.7075,3.70750,6.000
6,120.667,-0.01,3.5075,3.50753,6.000
6,120.867,0.00,3.3076,3.30760,6.000
6,121.067,-0.01,3.1075,3.10753,6.000
6,121.267,0.00,2.9076,2.90757,6.000
6,121.467,0.00,2.7075,2.70750,6.000
6,121.667,0.00,2.5074,2.50740,6.000
6,121.867,-0.01,2.3075,2.30750,6.000
6,122.067,0.00,2.1074,2.10743,6.000
6,122.267,-0.01,1.9074,1.90740,6.000
6,122.467,0.00,1.7075,1.70753,6.000
6,122.667,0.00,1.5075,1.50747,6.000
6,122.867,0.01,1.3075,1.30750,6.000
6,123.067,0.00,1.1075,1.10747,6.000
6,123.267,0.01,0.9075,0.90750,6.000
6,123.467,0.00,0.7075,0.70750,6.000
6,123.667,0.01,0.5073,0.50733,6.000
6,123.867,0.00,0.3074,0.30737,6.000
6,124.067,0.00,0.1075,0.10747,6.000
6,124.333,0.01,-0.0064,-0.00640,6.000
6,124.533,0.01,-0.0003,-0.00030,6.000
6,124.733,0.00,-0.0003,-0.00030,6.000
6,124.933,0.00,-0.0003,-0.00030,6.000
6,125.133,0.00,-0.0003,-0.00030,6.000
6,125.333,0.00,-0.0003,-0.00030,6.000
6,125.533,0.00,-0.0003,-0.00030,6.000
6,125.733,0.01,-0.0003,-0.00030,6.000
6,125.933,0.00,-0.0003,-0.00030,6.000
6,126.133,0.00,-0.0003,-0.00030,6.000
6,126.333,0.00,-0.0003,-0.00030,6.000
6,126.533,0.01,-0.0003,-0.00030,6.000
6,126.733,0.00,-0.0002,-0.00020,6.000
6,126.933,0.00,-0.0002,-0.00020,6.000
6,127.133,0.00,-0.0002,-0.00020,6.000
6,127.400,0.01,-0.0002,-0.00020,6.000
6,127.600,0.01,-0.0002,-0.00020,6.000
6,127.800,0.00,-0.0002,-0.00020,6.000
6,128.000,0.00,-0.0002,-0.00020,6.000
6,128.200,0.00,-0.0002,-0.00020,6.000
7,128.667,-0.01,0.1713,0.17143,7.000
7,128.867,-0.01,0.3713,0.37137,7.000
7,129.067,-0.01,0.5713,0.57137,7.000
7,129.267,-0.01,0.7713,0.77140,7.000
7,129.467,0.00,0.9714,0.97153,7.000
7,129.667,-0.01,1.1713,1.17140,7.000
7,129.867,0.00,1.3714,1.37153,7.000
7,130.067,-0.01,1.5715,1.57160,7.000
7,130.267,-0.01,1.7714,1.77153,7.000
7,130.467,-0.02,1.9714,1.97147,7.000
7,130.667,-0.01,2.1714,2.17150,7.000
7,130.867,0.00,2.3715,2.37160,7.000
7,131.067,-0.01,2.5714,2.57153,7.000
7,131.267,0.00,2.7714,2.77153,7.000
7,131.467,0.00,2.9714,2.97153,7.000
7,131.667,-0.02,3.1715,3.17160,7.000
7,131.867,-0.01,3.3715,3.37157,7.000
7,132.067,-0.01,3.5714,3.57153,7.000
7,132.267,0.00,3.7714,3.77150,7.000
7,132.467,-0.01,3.9715,3.97160,7.000
7,132.667,0.00,4.1715,4.17160,7.000
7,132.867,0.00,4.3715,4.37157,7.000
7,133.067,-0.01,4.5715,4.57160,7.000
7,133.267,0.00,4.7714,4.77153,7.000
7,133.467,0.00,4.9715,4.97163,7.000
7,133.667,-0.01,5.1715,5.17160,7.000
7,133.867,-0.01,5.3715,5.37163,7.000
7,134.067,-0.01,5.5716,5.57167,7.000
7,134.267,0.01,5.7715,5.77157,7.000
7,134.467,0.01,5.9716,5.97173,7.000
7,134.667,0.05,6.1715,6.17157,7.000
7,134.867,0.17,6.3715,6.37163,7.000
7,135.067,0.48,6.5715,6.57163,7.000
7,135.267,1.00,6.7716,6.77170,7.000
7,135.467,1.77,6.9715,6.97160,7.000
7,135.667,2.81,7.1716,7.17167,7.000
7,135.867,4.18,7.3716,7.37173,7.000
7,136.067,5.91,7.5715,7.57160,7.000
7,136.267,8.09,7.7715,7.77157,7.000
7,136.467,10.71,7.9715,7.97157,7.000
7,136.667,13.90,8.1715,8.17160,7.000
7,136.867,17.82,8.3715,8.37163,7.000
7,137.133,18.57,8.4324,8.43247,7.000
7,137.333,13.16,8.2323,8.23240,7.000
7,137.533,9.45,8.0324,8.03247,7.000
7,137.733,6.72,7.8322,7.83233,7.000
7,137.933,4.71,7.6322,7.63227,7.000
7,138.133,3.23,7.4323,7.43240,7.000
7,138.333,2.13,7.2323,7.23240,7.000
7,138.533,1.31,7.0322,7.03230,7.000
7,138.733,0.71,6.8322,6.83233,7.000
7,138.933,0.32,6.6322,6.63233,7.000
7,139.133,0.09,6.4322,6.43230,7.000
7,139.333,0.01,6.2321,6.23220,7.000
7,139.533,-0.01,6.0320,6.03213,7.000
7,139.733,-0.01,5.8321,5.83217,7.000
7,139.933,0.00,5.6321,5.63217,7.000
7,140.133,-0.01,5.4321,5.43217,7.000
7,140.333,-0.01,5.2321,5.23217,7.000
7,140.533,-0.01,5.0320,5.03210,7.000
7,140.733,-0.01,4.8319,4.83197,7.000
7,140.933,0.00,4.6321,4.63217,7.000
7,141.133,-0.01,4.4319,4.43200,7.000
7,141.333,-0.01,4.2321,4.23217,7.000
7,141.533,-0.01,4.0319,4.03200,7.000
7,141.733,0.00,3.8318,3.83193,7.000
7,141.933,-0.01,3.6318,3.63190,7.000
7,142.133,-0.01,3.4319,3.43200,7.000
7,142.333,0.00,3.2319,3.23197,7.000
7,142.533,0.00,3.0319,3.03200,7.000
7,142.733,0.00,2.8318,2.83190,7.000
7,142.933,-0.01,2.6319,2.63197,7.000
7,143.133,-0.01,2.4317,2.43183,7.000
7,143.333,-0.01,2.2317,2.23183,7.000
7,143.533,-0.01,2.0318,2.03187,7.000
7,143.733,-0.01,1.8317,1.83177,7.000
7,143.933,0.00,1.6318,1.63190,7.000
7,144.133,0.00,1.4318,1.43193,7.000
7,144.333,0.00,1.2317,1.23180,7.000
7,144.533,0.00,1.0319,1.03197,7.000
7,144.733,-0.01,0.8318,0.83187,7.000
7,144.933,0.00,0.6318,0.63187,7.000
7,145.133,0.00,0.4317,0.43177,7.000
7,145.333,-0.01,0.2318,0.23187,7.000
7,145.533,0.00,0.0318,0.03187,7.000
7,145.800,0.00,-0.0003,-0.00020,7.000
7,146.000,-0.01,-0.0003,-0.00020,7.000
7,146.200,-0.01,-0.0003,-0.00020,7.000
7,146.400,0.00,-0.0003,-0.00020,7.000
7,146.600,0.00,-0.0003,-0.00020,7.000
7,146.800,0.00,-0.0003,-0.00020,7.000
7,147.000,0.00,-0.0003,-0.00020,7.000
7,147.200,0.00,-0.0003,-0.00020,7.000
7,147.400,-0.01,-0.0003,-0.00020,7.000
7,147.600,-0.01,-0.0003,-0.00020,7.000
7,147.800,-0.01,-0.0003,-0.00020,7.000
7,148.000,-0.01,-0.0003,-0.00020,7.000
7,148.200,-0.01,-0.0002,-0.00010,7.000
7,148.400,-0.02,-0.0002,-0.00010,7.000
7,148.600,0.01,-0.0002,-0.00010,7.000
7,148.867,-0.01,-0.0002,-0.00010,7.000
7,149.067,0.00,-0.0002,-0.00010,7.000
7,149.267,-0.01,-0.0002,-0.00010,7.000
7,149.467,-0.01,-0.0002,-0.00010,7.000
8,149.800,-0.02,-0.0001,0.00000,8.000
8,150.067,0.00,0.2342,0.23433,8.000
8,150.267,0.01,0.4342,0.43427,8.000
8,150.467,0.00,0.6342,0.63430,8.000
8,150.667,0.00,0.8342,0.83427,8.000
8,150.867,0.01,1.0343,1.03443,8.000
8,151.067,0.00,1.2343,1.23437,8.000
8,151.267,0.00,1.4343,1.43443,8.000
8,151.467,0.01,1.6344,1.63453,8.000
8,151.667,0.00,1.8342,1.83430,8.000
8,151.867,0.00,2.0343,2.03437,8.000
8,152.067,0.00,2.2343,2.23443,8.000
8,152.267,0.00,2.4343,2.43443,8.000
8,152.467,0.00,2.6343,2.63443,8.000
8,152.667,0.01,2.8344,2.83447,8.000
8,152.867,0.01,3.0344,3.03447,8.000
8,153.067,0.01,3.2343,3.23440,8.000
8,153.267,0.01,3.4344,3.43450,8.000
8,153.467,-0.01,3.6343,3.63440,8.000
8,153.667,0.00,3.8344,3.83447,8.000
8,153.867,0.01,4.0343,4.03443,8.000
8,154.067,0.01,4.2345,4.23457,8.000
8,154.267,0.01,4.4344,4.43453,8.000
8,154.467,0.00,4.6345,4.63460,8.000
8,154.667,0.01,4.8343,4.83443,8.000
8,154.867,-0.01,5.0345,5.03460,8.000
8,155.067,0.00,5.2345,5.23460,8.000
8,155.267,0.01,5.4345,5.43460,8.000
8,155.467,0.00,5.6345,5.63460,8.000
8,155.667,0.02,5.8346,5.83467,8.000
8,155.867,0.02,6.0345,6.03463,8.000
8,156.067,0.08,6.2345,6.23457,8.000
8,156.267,0.24,6.4346,6.43470,8.000
8,156.467,0.62,6.6346,6.63467,8.000
8,156.667,1.22,6.8346,6.83467,8.000
8,156.867,2.07,7.0346,7.03467,8.000
8,157.067,3.21,7.2347,7.23477,8.000
8,157.267,4.68,7.4346,7.43473,8.000
8,157.467,6.54,7.6345,7.63457,8.000
8,157.667,8.84,7.8345,7.83463,8.000
8,157.867,11.61,8.0346,8.03470,8.000
8,158.067,15.01,8.2345,8.23460,8.000
8,158.267,19.22,8.4346,8.43470,8.000
8,158.533,16.69,8.3752,8.37533,8.000
8,158.733,11.92,8.1753,8.17540,8.000
8,158.933,8.55,7.9752,7.97533,8.000
8,159.133,6.06,7.7753,7.77537,8.000
8,159.333,4.24,7.5751,7.57523,8.000
8,159.533,2.88,7.3753,7.37540,8.000
8,159.733,1.88,7.1753,7.17537,8.000
8,159.933,1.13,6.9751,6.97523,8.000
8,160.133,0.59,6.7753,6.77540,8.000
8,160.333,0.24,6.5751,6.57523,8.000
8,160.533,0.07,6.3751,6.37523,8.000
8,160.733,0.02,6.1751,6.17520,8.000
8,160.933,-0.01,5.9752,5.97527,8.000
8,161.133,0.00,5.7752,5.77527,8.000
8,161.333,0.00,5.5752,5.57527,8.000
8,161.533,0.00,5.3751,5.37520,8.000
8,161.733,0.00,5.1751,5.17523,8.000
8,161.933,0.00,4.9751,4.97520,8.000
8,162.133,-0.01,4.7750,4.77510,8.000
8,162.333,-0.01,4.5751,4.57517,8.000
8,162.533,0.00,4.3751,4.37520,8.000
8,162.733,0.00,4.1751,4.17520,8.000
8,162.933,-0.01,3.9750,3.97513,8.000
8,163.133,0.01,3.7750,3.77510,8.000
8,163.333,0.00,3.5749,3.57503,8.000
8,163.533,0.00,3.3750,3.37513,8.000
8,163.733,0.01,3.1749,3.17503,8.000
8,163.933,0.00,2.9750,2.97507,8.000
8,164.133,0.01,2.7749,2.77500,8.000
8,164.333,0.00,2.5749,2.57497,8.000
8,164.533,0.01,2.3749,2.37500,8.000
8,164.733,0.00,2.1749,2.17500,8.000
8,164.933,0.00,1.9749,1.97500,8.000
8,165.133,0.01,1.7748,1.77493,8.000
8,165.333,0.00,1.5750,1.57507,8.000
8,165.533,-0.01,1.3750,1.37510,8.000
8,165.733,0.01,1.1748,1.17490,8.000
8,165.933,0.00,0.9750,0.97507,8.000
8,166.133,0.00,0.7749,0.77503,8.000
8,166.333,0.01,0.5748,0.57487,8.000
8,166.533,0.00,0.3748,0.37487,8.000
8,166.733,-0.01,0.1749,0.17500,8.000
8,167.000,0.00,-0.0314,-0.03130,8.000
8,167.200,0.00,-0.0004,-0.00030,8.000
8,167.400,0.00,-0.0004,-0.00030,8.000
8,167.600,0.00,-0.0004,-0.00030,8.000
8,167.800,0.00,-0.0004,-0.00030,8.000
8,168.000,0.00,-0.0004,-0.00030,8.000
8,168.200,0.01,-0.0003,-0.00020,8.000
8,168.400,-0.01,-0.0003,-0.00020,8.000
8,168.600,0.01,-0.0003,-0.00020,8.000
8,168.800,0.01,-0.0003,-0.00020,8.000
8,169.000,0.01,-0.0003,-0.00020,8.000
8,169.200,0.01,-0.0003,-0.00020,8.000
8,169.400,0.01,-0.0003,-0.00020,8.000
8,169.600,0.00,-0.0003,-0.00020,8.000
8,169.800,0.01,-0.0003,-0.00020,8.000
8,170.000,0.00,-0.0002,-0.00010,8.000
8,170.200,-0.01,-0.0002,-0.00010,8.000
8,170.400,0.00,-0.0002,-0.00010,8.000
8,170.600,-0.01,-0.0002,-0.00010,8.000
8,170.800,0.01,-0.0002,-0.00010,8.000
8,171.000,0.00,-0.0002,-0.00010,8.000
9,171.400,0.00,0.2087,0.20880,9.000
9,171.600,0.00,0.4086,0.40870,9.000
9,171.800,-0.02,0.6087,0.60880,9.000
9,172.000,0.00,0.8087,0.80880,9.000
9,172.200,-0.01,1.0087,1.00880,9.000
9,172.400,-0.01,1.2087,1.20880,9.000
9,172.600,-0.01,1.4087,1.40880,9.000
9,172.800,-0.01,1.6087,1.60880,9.000
9,173.000,-0.01,1.8087,1.80880,9.000
9,173.200,-0.01,2.0088,2.00890,9.000
9,173.400,-0.01,2.2089,2.20900,9.000
9,173.600,-0.01,2.4088,2.40890,9.000
9,173.800,-0.01,2.6087,2.60880,9.000
9,174.000,-0.01,2.8088,2.80890,9.000
9,174.200,-0.01,3.0089,3.00900,9.000
9,174.400,-0.01,3.2087,3.20880,9.000
9,174.600,-0.02,3.4088,3.40890,9.000
9,174.800,0.00,3.6088,3.60890,9.000
9,175.000,-0.01,3.8088,3.80890,9.000
9,175.200,-0.01,4.0087,4.00880,9.000
9,175.400,-0.01,4.2088,4.20890,9.000
9,175.600,-0.01,4.4087,4.40880,9.000
9,175.800,0.00,4.6089,4.60900,9.000
9,176.000,-0.01,4.8087,4.80880,9.000
9,176.200,-0.01,5.0088,5.00890,9.000
9,176.400,-0.01,5.2088,5.20890,9.000
9,176.600,-0.01,5.4089,5.40900,9.000
9,176.800,-0.01,5.6089,5.60900,9.000
9,177.000,0.00,5.8087,5.80880,9.000
9,177.200,0.01,6.0088,6.00890,9.000
9,177.400,0.06,6.2089,6.20900,9.000
9,177.600,0.21,6.4088,6.40890,9.000
9,177.800,0.55,6.6088,6.60890,9.000
9,178.000,1.11,6.8089,6.80900,9.000
9,178.200,1.94,7.0088,7.00890,9.000
9,178.400,3.02,7.2089,7.20900,9.000
9,178.600,4.45,7.4089,7.40900,9.000
9,178.800,6.27,7.6088,7.60890,9.000
9,179.000,8.52,7.8088,7.80890,9.000
9,179.200,11.25,8.0089,8.00900,9.000
9,179.400,14.55,8.2088,8.20890,9.000
9,179.600,18.64,8.4089,8.40900,9.000
9,179.867,17.03,8.3831,8.38320,9.000
9,180.067,12.13,8.1830,8.18307,9.000
9,180.267,8.70,7.9830,7.98313,9.000
9,180.467,6.17,7.7830,7.78310,9.000
9,180.667,4.30,7.5829,7.58297,9.000
9,180.867,2.92,7.3830,7.38310,9.000
9,181.067,1.91,7.1830,7.18310,9.000
9,181.267,1.14,6.9829,6.98297,9.000
9,181.467,0.59,6.7829,6.78303,9.000
9,181.667,0.24,6.5829,6.58297,9.000
9,181.867,0.06,6.3829,6.38297,9.000
9,182.067,0.00,6.1828,6.18293,9.000
9,182.267,-0.01,5.9829,5.98297,9.000
9,182.467,-0.01,5.7828,5.78293,9.000
9,182.667,-0.02,5.5829,5.58300,9.000
9,182.867,-0.02,5.3828,5.38287,9.000
9,183.067,-0.01,5.1827,5.18283,9.000
9,183.267,-0.01,4.9828,4.98287,9.000
9,183.467,0.00,4.7826,4.78273,9.000
9,183.667,-0.01,4.5828,4.58290,9.000
9,183.867,-0.01,4.3827,4.38280,9.000
9,184.067,-0.01,4.1828,4.18290,9.000
9,184.267,0.00,3.9827,3.98280,9.000
9,184.467,-0.02,3.7826,3.78273,9.000
9,184.667,0.00,3.5825,3.58263,9.000
9,184.867,-0.01,3.3826,3.38273,9.000
9,185.067,-0.01,3.1826,3.18273,9.000
9,185.267,-0.01,2.9826,2.98273,9.000
9,185.467,-0.01,2.7826,2.78267,9.000
9,185.667,0.00,2.5825,2.58263,9.000
9,185.867,-0.01,2.3826,2.38270,9.000
9,186.067,-0.01,2.1825,2.18263,9.000
9,186.267,-0.01,1.9825,1.98263,9.000
9,186.467,0.00,1.7825,1.78260,9.000
9,186.667,0.00,1.5826,1.58270,9.000
9,186.867,0.00,1.3825,1.38263,9.000
9,187.067,-0.01,1.1825,1.18257,9.000
9,187.267,-0.01,0.9825,0.98263,9.000
9,187.467,-0.01,0.7825,0.78263,9.000
9,187.667,-0.01,0.5824,0.58253,9.000
9,187.867,-0.02,0.3824,0.38250,9.000
9,188.067,-0.01,0.1825,0.18260,9.000
9,188.400,-0.01,-0.0004,-0.00030,9.000
9,188.600,-0.02,-0.0004,-0.00030,9.000
9,188.800,0.00,-0.0004,-0.00030,9.000
9,189.000,0.01,-0.0004,-0.00030,9.000
9,189.200,-0.01,-0.0004,-0.00030,9.000
9,189.400,0.00,-0.0004,-0.00030,9.000
9,189.600,-0.02,-0.0003,-0.00020,9.000
9,189.800,-0.02,-0.0003,-0.00020,9.000
9,190.000,-0.01,-0.0003,-0.00020,9.000
9,190.200,-0.01,-0.0003,-0.00020,9.000
9,190.400,-0.01,-0.0003,-0.00020,9.000
9,190.600,-0.01,-0.0003,-0.00020,9.000
9,190.800,0.00,-0.0003,-0.00020,9.000
9,191.000,-0.01,-0.0003,-0.00020,9.000
9,191.200,-0.01,-0.0003,-0.00020,9.000
9,191.533,-0.01,-0.0002,-0.00010,9.000
9,191.733,-0.01,-0.0002,-0.00010,9.000
9,191.933,-0.01,-0.0002,-0.00010,9.000
9,192.133,-0.01,-0.0002,-0.00010,9.000
9,192.333,-0.02,-0.0002,-0.00010,9.000
10,192.733,-0.01,0.2019,0.20203,10.000
10,192.933,-0.01,0.4019,0.40200,10.000
10,193.133,0.00,0.6019,0.60203,10.000
10,193.333,-0.01,0.8019,0.80203,10.000
10,193.533,-0.01,1.0020,1.00210,10.000
10,193.733,-0.01,1.2020,1.20210,10.000
10,193.933,-0.01,1.4021,1.40217,10.000
10,194.133,-0.01,1.6021,1.60220,10.000
10,194.333,-0.01,1.8019,1.80203,10.000
10,194.533,-0.01,2.0020,2.00210,10.000
10,194.733,-0.01,2.2020,2.20210,10.000
10,194.933,-0.01,2.4020,2.40210,10.000
10,195.133,0.00,2.6020,2.60210,10.000
10,195.333,-0.01,2.8020,2.80210,10.000
10,195.533,-0.01,3.0020,3.00210,10.000
10,195.733,-0.02,3.2021,3.20220,10.000
10,195.933,-0.01,3.4021,3.40217,10.000
10,196.133,-0.01,3.6020,3.60210,10.000
10,196.333,-0.01,3.8021,3.80217,10.000
10,196.533,-0.02,4.0020,4.00210,10.000
10,196.733,-0.03,4.2022,4.20227,10.000
10,196.933,-0.01,4.4021,4.40217,10.000
10,197.133,-0.01,4.6022,4.60227,10.000
10,197.333,-0.01,4.8020,4.80210,10.000
10,197.533,-0.01,5.0021,5.00223,10.000
10,197.733,-0.01,5.2021,5.20223,10.000
10,197.933,-0.01,5.4022,5.40227,10.000
10,198.133,-0.01,5.6021,5.60223,10.000
10,198.333,0.00,5.8021,5.80223,10.000
10,198.533,0.01,6.0022,6.00227,10.000
10,198.733,0.05,6.2021,6.20217,10.000
10,198.933,0.20,6.4022,6.40230,10.000
10,199.133,0.53,6.6022,6.60230,10.000
10,199.333,1.09,6.8022,6.80230,10.000
10,199.533,1.88,7.0022,7.00230,10.000
10,199.733,2.98,7.2024,7.20247,10.000
10,199.933,4.41,7.4024,7.40247,10.000
10,200.133,6.20,7.6022,7.60227,10.000
10,200.333,8.42,7.8022,7.80230,10.000
10,200.533,11.11,8.0023,8.00237,10.000
10,200.733,14.39,8.2022,8.20230,10.000
10,200.933,18.45,8.4022,8.40230,10.000
10,201.200,17.77,8.4115,8.41160,10.000
10,201.400,12.65,8.2115,8.21160,10.000
10,201.600,9.07,8.0115,8.01160,10.000
10,201.800,6.44,7.8115,7.81160,10.000
10,202.000,4.52,7.6114,7.61150,10.000
10,202.200,3.08,7.4115,7.41160,10.000
10,202.400,2.03,7.2115,7.21160,10.000
10,202.600,1.24,7.0115,7.01160,10.000
10,202.800,0.64,6.8115,6.81160,10.000
10,203.000,0.30,6.6113,6.61140,10.000
10,203.200,0.09,6.4114,6.41150,10.000
10,203.400,-0.01,6.2113,6.21140,10.000
10,203.600,0.00,6.0114,6.01150,10.000
10,203.800,0.00,5.8113,5.81140,10.000
10,204.000,-0.02,5.6114,5.61150,10.000
10,204.200,-0.01,5.4114,5.41150,10.000
10,204.400,-0.03,5.2114,5.21150,10.000
10,204.600,-0.02,5.0115,5.01160,10.000
10,204.800,0.00,4.8112,4.81130,10.000
10,205.000,-0.02,4.6114,4.61150,10.000
10,205.200,-0.02,4.4114,4.41150,10.000
10,205.400,-0.02,4.2115,4.21160,10.000
10,205.600,-0.01,4.0114,4.01150,10.000
10,205.800,-0.01,3.8114,3.81150,10.000
10,206.000,-0.02,3.6113,3.61140,10.000
10,206.200,-0.02,3.4114,3.41150,10.000
10,206.400,-0.01,3.2112,3.21130,10.000
10,206.600,-0.01,3.0113,3.01140,10.000
10,206.800,-0.02,2.8112,2.81130,10.000
10,207.000,-0.02,2.6112,2.61130,10.000
10,207.200,-0.01,2.4112,2.41130,10.000
10,207.400,-0.01,2.2113,2.21140,10.000
10,207.600,-0.01,2.0113,2.01140,10.000
10,207.800,-0.01,1.8112,1.81130,10.000
10,208.000,-0.01,1.6113,1.61140,10.000
10,208.200,-0.02,1.4113,1.41140,10.000
10,208.400,-0.01,1.2113,1.21140,10.000
10,208.600,0.00,1.0113,1.01140,10.000
10,208.800,-0.02,0.8112,0.81130,10.000
10,209.000,-0.02,0.6111,0.61120,10.000
10,209.200,-0.01,0.4111,0.41120,10.000
10,209.400,-0.01,0.2112,0.21130,10.000
10,209.600,-0.01,0.0113,0.01140,10.000
10,209.867,-0.02,-0.0004,-0.00030,10.000
10,210.067,-0.02,-0.0004,-0.00030,10.000
10,210.267,-0.01,-0.0004,-0.00030,10.000
10,210.467,-0.01,-0.0004,-0.00030,10.000
10,210.667,-0.01,-0.0004,-0.00030,10.000
10,210.867,-0.01,-0.0004,-0.00030,10.000
10,211.067,-0.01,-0.0004,-0.00030,10.000
10,211.267,-0.01,-0.0003,-0.00020,10.000
10,211.467,-0.01,-0.0003,-0.00020,10.000
10,211.667,-0.02,-0.0003,-0.00020,10.000
10,211.867,-0.01,-0.0003,-0.00020,10.000
10,212.067,-0.01,-0.0003,-0.00020,10.000
10,212.267,-0.01,-0.0003,-0.00020,10.000
10,212.467,-0.01,-0.0003,-0.00020,10.000
10,212.667,-0.01,-0.0003,-0.00020,10.000
10,212.933,-0.01,-0.0002,-0.00010,10.000
10,213.133,-0.01,-0.0002,-0.00010,10.000
10,213.333,-0.01,-0.0002,-0.00010,10.000
10,213.533,-0.01,-0.0002,-0.00010,10.000
10,213.667,-0.02,-0.0002,-0.00010,10.000