File: calibDATA_loadcell/date_02:15:2018/Instron_02.15.2018/2_50N_4__1mm.s_0_0.txt
""
"Test Method","Radhen_Load_Cntrl_Cmprsn_250N_12-7.msm"
"Sample I. D.","Sample1.mss"
"Specimen Number","16"

"TheCycle_Output ()","_Time (s)","_Load (N)","_Extension (mm)","RealTimeDepth (mm)","CycleNumber ()"

1,0.200,0.00,0.0001,0.00010,1.000
1,0.333,0.00,0.1198,0.11980,1.000
1,0.467,0.02,0.2533,0.25333,1.000
1,0.600,0.03,0.3868,0.38680,1.000
1,0.733,0.08,0.5201,0.52010,1.000
1,0.867,0.20,0.6534,0.65337,1.000
1,1.000,0.42,0.7867,0.78670,1.000
1,1.133,0.71,0.9201,0.92010,1.000
1,1.267,1.08,1.0534,1.05340,1.000
1,1.400,1.56,1.1869,1.18690,1.000
1,1.533,2.15,1.3201,1.32013,1.000
1,1.667,2.85,1.4533,1.45330,1.000
1,1.800,3.69,1.5867,1.58670,1.000
1,1.933,4.69,1.7202,1.72017,1.000
1,2.067,5.85,1.8533,1.85333,1.000
1,2.200,7.18,1.9868,1.98680,1.000
1,2.333,8.71,2.1202,2.12017,1.000
1,2.467,10.43,2.2533,2.25333,1.000
1,2.600,12.35,2.3868,2.38680,1.000
1,2.733,14.47,2.5202,2.52023,1.000
1,2.867,16.73,2.6535,2.65350,1.000
1,3.000,18.47,2.7867,2.78670,1.000
1,3.133,18.62,2.9201,2.92010,1.000
1,3.267,18.64,3.0533,3.05333,1.000
1,3.400,18.82,3.1867,3.18670,1.000
1,3.533,17.70,3.3202,3.32017,1.000
1,3.667,18.35,3.4534,3.45337,1.000
1,3.800,20.48,3.5868,3.58680,1.000
1,3.933,24.66,3.7201,3.72013,1.000
1,4.067,29.16,3.8534,3.85343,1.000
1,4.200,34.22,3.9867,3.98670,1.000
1,4.333,40.08,4.1202,4.12017,1.000
1,4.467,46.93,4.2535,4.25347,1.000
1,4.667,48.32,4.3029,4.30287,1.000
1,4.800,37.48,4.1697,4.16970,1.000
1,4.933,30.02,4.0364,4.03640,1.000
1,5.067,24.33,3.9029,3.90290,1.000
1,5.200,19.80,3.7697,3.76970,1.000
1,5.333,16.11,3.6363,3.63630,1.000
1,5.467,13.13,3.5028,3.50277,1.000
1,5.600,10.69,3.3696,3.36960,1.000
1,5.733,8.69,3.2363,3.23633,1.000
1,5.867,7.05,3.1027,3.10273,1.000
1,6.000,5.69,2.9695,2.96950,1.000
1,6.133,4.57,2.8361,2.83613,1.000
1,6.267,3.64,2.7028,2.70283,1.000
1,6.400,2.85,2.5695,2.56950,1.000
1,6.533,2.19,2.4362,2.43623,1.000
1,6.667,1.63,2.3027,2.30270,1.000
1,6.800,1.18,2.1694,2.16940,1.000
1,6.933,0.80,2.0362,2.03620,1.000
1,7.067,0.50,1.9027,1.90270,1.000
1,7.200,0.27,1.7694,1.76940,1.000
1,7.333,0.13,1.6360,1.63603,1.000
1,7.467,0.05,1.5027,1.50267,1.000
1,7.600,0.02,1.3693,1.36930,1.000
1,7.733,0.00,1.2362,1.23617,1.000
1,7.867,0.00,1.1027,1.10273,1.000
1,8.000,0.00,0.9693,0.96930,1.000
1,8.133,-0.01,0.8360,0.83603,1.000
1,8.267,0.00,0.7027,0.70270,1.000
1,8.400,0.00,0.5692,0.56920,1.000
1,8.533,0.00,0.4360,0.43603,1.000
1,8.667,-0.01,0.3027,0.30267,1.000
1,8.800,0.00,0.1691,0.16910,1.000
1,8.933,0.00,0.0358,0.03583,1.000
1,9.133,0.00,-0.0004,-0.00037,1.000
1,9.267,0.00,-0.0002,-0.00020,1.000
1,9.400,0.00,-0.0002,-0.00020,1.000
1,9.533,0.00,-0.0002,-0.00020,1.000
1,9.667,0.00,-0.0002,-0.00020,1.000
1,9.800,0.00,-0.0002,-0.00020,1.000
1,9.933,0.00,-0.0002,-0.00020,1.000
1,10.067,0.00,-0.0002,-0.00020,1.000
1,10.200,-0.02,-0.0002,-0.00020,1.000
1,10.333,0.00,-0.0002,-0.00020,1.000
1,10.467,0.00,-0.0002,-0.00020,1.000
1,10.600,0.00,-0.0002,-0.00020,1.000
1,10.733,0.00,-0.0002,-0.00020,1.000
1,10.867,0.00,-0.0002,-0.00020,1.000
1,11.000,0.00,-0.0002,-0.00020,1.000
1,11.133,-0.01,-0.0002,-0.00020,1.000
1,11.267,0.00,-0.0002,-0.00020,1.000
1,11.400,0.00,-0.0002,-0.00020,1.000
1,11.533,0.00,-0.0002,-0.00020,1.000
1,11.667,0.00,-0.0002,-0.00020,1.000
1,11.800,-0.01,-0.0002,-0.00020,1.000
1,11.933,0.00,-0.0002,-0.00020,1.000
1,12.200,0.00,-0.0001,-0.00010,1.000
1,12.333,-0.01,-0.0001,-0.00010,1.000
1,12.467,-0.01,-0.0001,-0.00010,1.000
1,12.600,-0.01,-0.0001,-0.00010,1.000
1,12.733,-0.01,-0.0001,-0.00010,1.000
1,12.867,0.00,-0.0001,-0.00010,1.000
1,13.000,0.00,-0.0001,-0.00010,1.000
2,13.333,-0.01,0.1007,0.10070,2.000
2,13.467,-0.01,0.2343,0.23430,2.000
2,13.600,-0.01,0.3676,0.36760,2.000
2,13.733,0.00,0.5010,0.50103,2.000
2,13.867,0.00,0.6345,0.63447,2.000
2,14.000,-0.01,0.7676,0.76760,2.000
2,14.133,0.00,0.9009,0.90090,2.000
2,14.267,0.01,1.0344,1.03443,2.000
2,14.400,0.01,1.1678,1.16780,2.000
2,14.533,0.03,1.3010,1.30097,2.000
2,14.667,0.09,1.4344,1.43443,2.000
2,14.800,0.21,1.5676,1.56760,2.000
2,14.933,0.41,1.7010,1.70103,2.000
2,15.067,0.72,1.8344,1.83443,2.000
2,15.200,1.14,1.9678,1.96780,2.000
2,15.333,1.67,2.1010,2.10100,2.000
2,15.467,2.32,2.2344,2.23440,2.000
2,15.600,3.13,2.3679,2.36790,2.000
2,15.733,4.12,2.5011,2.50110,2.000
2,15.867,5.28,2.6346,2.63463,2.000
2,16.000,6.63,2.7678,2.76780,2.000
2,16.133,8.20,2.9010,2.90103,2.000
2,16.267,9.99,3.0345,3.03447,2.000
2,16.400,12.04,3.1678,3.16780,2.000
2,16.533,14.37,3.3010,3.30103,2.000
2,16.667,17.02,3.4345,3.43450,2.000
2,16.800,20.08,3.5678,3.56780,2.000
2,16.933,23.64,3.7010,3.70097,2.000
2,17.067,27.78,3.8345,3.83450,2.000
2,17.200,32.64,3.9679,3.96790,2.000
2,17.333,38.39,4.1011,4.10107,2.000
2,17.467,45.25,4.2345,4.23450,2.000
2,17.667,52.11,4.3417,4.34167,2.000
2,17.800,39.95,4.2087,4.20870,2.000
2,17.933,31.87,4.0754,4.07537,2.000
2,18.067,25.80,3.9418,3.94183,2.000
2,18.200,21.00,3.8087,3.80870,2.000
2,18.333,17.13,3.6753,3.67527,2.000
2,18.467,13.97,3.5418,3.54177,2.000
2,18.600,11.38,3.4086,3.40860,2.000
2,18.733,9.26,3.2752,3.27520,2.000
2,18.867,7.51,3.1417,3.14173,2.000
2,19.000,6.06,3.0085,3.00850,2.000
2,19.133,4.85,2.8751,2.87507,2.000
2,19.267,3.85,2.7418,2.74177,2.000
2,19.400,3.01,2.6084,2.60840,2.000
2,19.533,2.29,2.4752,2.47523,2.000
2,19.667,1.72,2.3418,2.34177,2.000
2,19.800,1.23,2.2084,2.20840,2.000
2,19.933,0.84,2.0751,2.07513,2.000
2,20.067,0.53,1.9417,1.94173,2.000
2,20.200,0.30,1.8083,1.80830,2.000
2,20.333,0.15,1.6751,1.67510,2.000
2,20.467,0.06,1.5416,1.54163,2.000
2,20.600,0.01,1.4083,1.40830,2.000
2,20.733,0.00,1.2751,1.27507,2.000
2,20.867,-0.01,1.1418,1.14177,2.000
2,21.000,0.00,1.0084,1.00840,2.000
2,21.133,0.00,0.8751,0.87507,2.000
2,21.267,-0.01,0.7417,0.74170,2.000
2,21.400,0.00,0.6083,0.60830,2.000
2,21.533,0.00,0.4751,0.47507,2.000
2,21.667,0.00,0.3416,0.34160,2.000
2,21.800,0.00,0.2081,0.20810,2.000
2,21.933,0.00,0.0748,0.07483,2.000
2,22.133,0.00,-0.0181,-0.01807,2.000
2,22.267,-0.01,-0.0002,-0.00020,2.000
2,22.400,0.00,-0.0002,-0.00020,2.000
2,22.533,0.00,-0.0002,-0.00020,2.000
2,22.667,0.00,-0.0002,-0.00020,2.000
2,22.800,-0.01,-0.0002,-0.00020,2.000
2,22.933,0.00,-0.0002,-0.00020,2.000
2,23.067,-0.01,-0.0002,-0.00020,2.000
2,23.200,-0.01,-0.0002,-0.00020,2.000
2,23.333,-0.01,-0.0002,-0.00020,2.000
2,23.467,0.00,-0.0002,-0.00020,2.000
2,23.600,-0.01,-0.0002,-0.00020,2.000
2,23.733,-0.01,-0.0002,-0.00020,2.000
2,23.867,0.00,-0.0002,-0.00020,2.000
2,24.000,0.00,-0.0002,-0.00020,2.000
2,24.133,0.00,-0.0002,-0.00020,2.000
2,24.267,-0.01,-0.0002,-0.00020,2.000
2,24.400,-0.01,-0.0002,-0.00020,2.000
2,24.533,0.00,-0.0002,-0.00020,2.000
2,24.667,-0.01,-0.0002,-0.00020,2.000
2,24.800,0.00,-0.0002,-0.00020,2.000
2,24.933,-0.01,-0.0001,-0.00010,2.000
2,25.067,-0.01,-0.0001,-0.00010,2.000
2,25.267,-0.01,-0.0001,-0.00010,2.000
2,25.400,0.00,-0.0001,-0.00010,2.000
2,25.533,0.00,-0.0001,-0.00010,2.000
2,25.667,0.00,-0.0001,-0.00010,2.000
2,25.800,-0.01,-0.0001,-0.00010,2.000
2,25.933,-0.01,-0.0001,-0.00010,2.000
2,26.067,-0.01,-0.0001,-0.00010,2.000
3,26.467,0.01,0.1552,0.15520,3.000
3,26.600,0.01,0.2885,0.28850,3.000
3,26.733,0.01,0.4220,0.42200,3.000
3,26.867,0.01,0.5555,0.55547,3.000
3,27.000,0.01,0.6886,0.68860,3.000
3,27.133,0.01,0.8220,0.82197,3.000
3,27.267,0.02,0.9554,0.95540,3.000
3,27.400,0.02,1.0887,1.08870,3.000
3,27.533,0.03,1.2221,1.22210,3.000
3,27.667,0.06,1.3554,1.35540,3.000
3,27.800,0.13,1.4886,1.48860,3.000
3,27.933,0.28,1.6220,1.62197,3.000
3,28.067,0.52,1.7555,1.75553,3.000
3,28.200,0.86,1.8888,1.88880,3.000
3,28.333,1.32,2.0221,2.02213,3.000
3,28.467,1.89,2.1554,2.15540,3.000
3,28.600,2.59,2.2888,2.28880,3.000
3,28.733,3.47,2.4222,2.42217,3.000
3,28.867,4.51,2.5556,2.55560,3.000
3,29.000,5.73,2.6888,2.68880,3.000
3,29.133,7.16,2.8219,2.82193,3.000
3,29.267,8.82,2.9554,2.95537,3.000
3,29.400,10.72,3.0887,3.08870,3.000
3,29.533,12.86,3.2221,3.22210,3.000
3,29.667,15.29,3.3554,3.35543,3.000
3,29.800,18.10,3.4887,3.48870,3.000
3,29.933,21.33,3.6220,3.62203,3.000
3,30.067,25.08,3.7554,3.75543,3.000
3,30.200,29.47,3.8888,3.88880,3.000
3,30.333,34.63,4.0221,4.02210,3.000
3,30.467,40.73,4.1555,4.15547,3.000
3,30.600,48.13,4.2888,4.28880,3.000
3,30.800,46.47,4.2896,4.28960,3.000
3,30.933,36.38,4.1563,4.15630,3.000
3,31.067,29.24,4.0229,4.02290,3.000
3,31.200,23.72,3.8895,3.88950,3.000
3,31.333,19.36,3.7563,3.75633,3.000
3,31.467,15.78,3.6228,3.62283,3.000
3,31.600,12.86,3.4895,3.48950,3.000
3,31.733,10.48,3.3562,3.35623,3.000
3,31.867,8.52,3.2228,3.22280,3.000
3,32.000,6.89,3.0895,3.08950,3.000
3,32.133,5.54,2.9561,2.95613,3.000
3,32.267,4.42,2.8227,2.82267,3.000
3,32.400,3.48,2.6895,2.68950,3.000
3,32.533,2.70,2.5562,2.55623,3.000
3,32.667,2.05,2.4227,2.42273,3.000
3,32.800,1.52,2.2894,2.28940,3.000
3,32.933,1.07,2.1561,2.15613,3.000
3,33.067,0.71,2.0228,2.02277,3.000
3,33.200,0.44,1.8893,1.88930,3.000
3,33.333,0.24,1.7562,1.75623,3.000
3,33.467,0.11,1.6226,1.62263,3.000
3,33.600,0.04,1.4893,1.48930,3.000
3,33.733,0.02,1.3560,1.35600,3.000
3,33.867,0.01,1.2228,1.22277,3.000
3,34.000,0.01,1.0894,1.08940,3.000
3,34.133,0.01,0.9560,0.95603,3.000
3,34.267,0.01,0.8227,0.82270,3.000
3,34.400,0.01,0.6892,0.68920,3.000
3,34.533,0.01,0.5560,0.55603,3.000
3,34.667,0.01,0.4227,0.42267,3.000
3,34.800,0.01,0.2892,0.28920,3.000
3,34.933,0.01,0.1559,0.15590,3.000
3,35.067,0.01,0.0226,0.02257,3.000
3,35.267,0.01,-0.0002,-0.00020,3.000
3,35.400,0.01,-0.0002,-0.00020,3.000
3,35.533,0.01,-0.0002,-0.00020,3.000
3,35.667,0.01,-0.0002,-0.00020,3.000
3,35.800,0.00,-0.0002,-0.00020,3.000
3,35.933,0.01,-0.0002,-0.00020,3.000
3,36.067,0.01,-0.0002,-0.00020,3.000
3,36.200,0.00,-0.0002,-0.00020,3.000
3,36.333,0.01,-0.0002,-0.00020,3.000
3,36.467,0.00,-0.0002,-0.00020,3.000
3,36.600,0.01,-0.0002,-0.00020,3.000
3,36.733,0.01,-0.0002,-0.00020,3.000
3,36.867,0.00,-0.0002,-0.00020,3.000
3,37.000,0.01,-0.0002,-0.00020,3.000
3,37.133,0.01,-0.0002,-0.00020,3.000
3,37.267,0.01,-0.0002,-0.00020,3.000
3,37.400,0.00,-0.0002,-0.00020,3.000
3,37.533,0.01,-0.0002,-0.00020,3.000
3,37.667,0.01,-0.0002,-0.00020,3.000
3,37.800,0.01,-0.0002,-0.00020,3.000
3,37.933,0.01,-0.0002,-0.00020,3.000
3,38.067,0.00,-0.0002,-0.00020,3.000
3,38.267,0.01,-0.0001,-0.00010,3.000
3,38.400,0.00,-0.0001,-0.00010,3.000
3,38.533,0.01,-0.0001,-0.00010,3.000
3,38.667,0.00,-0.0001,-0.00010,3.000
3,38.800,0.01,-0.0001,-0.00010,3.000
3,38.933,0.01,-0.0001,-0.00010,3.000
3,39.067,0.01,-0.0001,-0.00010,3.000
4,39.467,0.00,0.0930,0.09303,4.000
4,39.600,0.00,0.2266,0.22660,4.000
4,39.733,0.00,0.3600,0.36000,4.000
4,39.867,0.00,0.4932,0.49320,4.000
4,40.000,-0.01,0.6267,0.62670,4.000
4,40.133,0.00,0.7601,0.76010,4.000
4,40.267,0.00,0.8933,0.89327,4.000
4,40.400,0.01,1.0266,1.02660,4.000
4,40.533,0.01,1.1602,1.16023,4.000
4,40.667,0.03,1.2933,1.29330,4.000
4,40.800,0.08,1.4266,1.42660,4.000
4,40.933,0.18,1.5600,1.56000,4.000
4,41.067,0.37,1.6934,1.69337,4.000
4,41.200,0.66,1.8266,1.82660,4.000
4,41.333,1.06,1.9602,1.96017,4.000
4,41.467,1.58,2.0934,2.09343,4.000
4,41.600,2.22,2.2267,2.22670,4.000
4,41.733,3.00,2.3602,2.36023,4.000
4,41.867,3.96,2.4935,2.49347,4.000
4,42.000,5.09,2.6268,2.62680,4.000
4,42.133,6.42,2.7602,2.76017,4.000
4,42.267,7.96,2.8933,2.89330,4.000
4,42.400,9.75,3.0267,3.02670,4.000
4,42.533,11.77,3.1601,3.16010,4.000
4,42.667,14.05,3.2935,3.29347,4.000
4,42.800,16.67,3.4268,3.42680,4.000
4,42.933,19.68,3.5601,3.56010,4.000
4,43.067,23.18,3.6934,3.69343,4.000
4,43.200,27.26,3.8268,3.82680,4.000
4,43.333,32.01,3.9601,3.96013,4.000
4,43.467,37.64,4.0934,4.09343,4.000
4,43.600,44.37,4.2267,4.22670,4.000
4,43.800,52.49,4.3478,4.34780,4.000
4,43.933,40.28,4.2142,4.21417,4.000
4,44.067,32.08,4.0810,4.08100,4.000
4,44.200,25.96,3.9476,3.94760,4.000
4,44.333,21.11,3.8142,3.81423,4.000
4,44.467,17.21,3.6810,3.68097,4.000
4,44.600,14.03,3.5475,3.54750,4.000
4,44.733,11.44,3.4142,3.41417,4.000
4,44.867,9.30,3.2809,3.28087,4.000
4,45.000,7.53,3.1475,3.14750,4.000
4,45.133,6.06,3.0140,3.01403,4.000
4,45.267,4.86,2.8807,2.88070,4.000
4,45.400,3.85,2.7474,2.74740,4.000
4,45.533,3.01,2.6141,2.61410,4.000
4,45.667,2.29,2.4808,2.48083,4.000
4,45.800,1.72,2.3474,2.34740,4.000
4,45.933,1.24,2.2139,2.21393,4.000
4,46.067,0.83,2.0808,2.08083,4.000
4,46.200,0.53,1.9475,1.94750,4.000
4,46.333,0.30,1.8139,1.81393,4.000
4,46.467,0.15,1.6807,1.68073,4.000
4,46.600,0.06,1.5473,1.54730,4.000
4,46.733,0.01,1.4139,1.41393,4.000
4,46.867,0.00,1.2808,1.28077,4.000
4,47.000,0.00,1.1475,1.14750,4.000
4,47.133,0.00,1.0140,1.01397,4.000
4,47.267,0.00,0.8807,0.88070,4.000
4,47.400,0.00,0.7473,0.74730,4.000
4,47.533,-0.01,0.6139,0.61393,4.000
4,47.667,0.00,0.4808,0.48077,4.000
4,47.800,-0.01,0.3474,0.34740,4.000
4,47.933,-0.01,0.2139,0.21390,4.000
4,48.067,0.00,0.0804,0.08043,4.000
4,48.267,0.00,-0.0087,-0.00873,4.000
4,48.400,-0.01,-0.0002,-0.00020,4.000
4,48.533,0.00,-0.0002,-0.00020,4.000
4,48.667,-0.01,-0.0002,-0.00020,4.000
4,48.800,0.00,-0.0002,-0.00020,4.000
4,48.933,0.00,-0.0002,-0.00020,4.000
4,49.067,0.00,-0.0002,-0.00020,4.000
4,49.200,-0.01,-0.0002,-0.00020,4.000
4,49.333,0.00,-0.0002,-0.00020,4.000
4,49.467,0.00,-0.0002,-0.00020,4.000
4,49.600,-0.01,-0.0002,-0.00020,4.000
4,49.733,-0.01,-0.0002,-0.00020,4.000
4,49.867,0.00,-0.0002,-0.00020,4.000
4,50.000,0.00,-0.0002,-0.00020,4.000
4,50.133,0.00,-0.0002,-0.00020,4.000
4,50.267,0.00,-0.0002,-0.00020,4.000
4,50.400,-0.01,-0.0002,-0.00020,4.000
4,50.533,0.00,-0.0002,-0.00020,4.000
4,50.667,0.00,-0.0002,-0.00020,4.000
4,50.800,-0.01,-0.0002,-0.00020,4.000
4,50.933,0.00,-0.0002,-0.00020,4.000
4,51.067,-0.01,-0.0002,-0.00020,4.000
4,51.200,0.00,-0.0002,-0.00020,4.000
4,51.400,0.00,-0.0001,-0.00010,4.000
4,51.533,-0.01,-0.0001,-0.00010,4.000
4,51.667,0.00,-0.0001,-0.00010,4.000
4,51.800,0.00,-0.0001,-0.00010,4.000
4,51.933,0.00,-0.0001,-0.00010,4.000
4,52.067,-0.01,-0.0001,-0.00010,4.000
4,52.200,0.00,-0.0001,-0.00010,4.000
5,52.467,0.00,0.0353,0.03527,5.000
5,52.600,-0.01,0.1684,0.16840,5.000
5,52.733,0.00,0.3020,0.30197,5.000
5,52.867,-0.01,0.4354,0.43540,5.000
5,53.000,-0.01,0.5686,0.56860,5.000
5,53.133,-0.01,0.7020,0.70203,5.000
5,53.267,0.00,0.8354,0.83537,5.000
5,53.400,0.01,0.9686,0.96860,5.000
5,53.533,0.00,1.1021,1.10207,5.000
5,53.667,0.01,1.2355,1.23550,5.000
5,53.800,0.05,1.3685,1.36850,5.000
5,53.933,0.12,1.5020,1.50200,5.000
5,54.067,0.27,1.6354,1.63543,5.000
5,54.200,0.52,1.7688,1.76880,5.000
5,54.333,0.85,1.9020,1.90200,5.000
5,54.467,1.32,2.0355,2.03553,5.000
5,54.600,1.90,2.1687,2.16870,5.000
5,54.733,2.61,2.3020,2.30197,5.000
5,54.867,3.48,2.4356,2.43557,5.000
5,55.000,4.54,2.5689,2.56890,5.000
5,55.133,5.78,2.7021,2.70213,5.000
5,55.267,7.22,2.8354,2.83540,5.000
5,55.400,8.90,2.9688,2.96880,5.000
5,55.533,10.82,3.1020,3.10200,5.000
5,55.667,12.98,3.2355,3.23547,5.000
5,55.800,15.44,3.3688,3.36880,5.000
5,55.933,18.27,3.5020,3.50197,5.000
5,56.067,21.54,3.6355,3.63547,5.000
5,56.200,25.34,3.7689,3.76890,5.000
5,56.333,29.78,3.9021,3.90210,5.000
5,56.467,35.00,4.0355,4.03553,5.000
5,56.600,41.20,4.1689,4.16890,5.000
5,56.733,48.75,4.3021,4.30207,5.000
5,56.933,45.14,4.2762,4.27623,5.000
5,57.067,35.49,4.1428,4.14283,5.000
5,57.200,28.55,4.0097,4.00970,5.000
5,57.333,23.18,3.8763,3.87633,5.000
5,57.467,18.90,3.7429,3.74290,5.000
5,57.600,15.40,3.6095,3.60950,5.000
5,57.733,12.55,3.4761,3.47613,5.000
5,57.867,10.22,3.3428,3.34283,5.000
5,58.000,8.29,3.2096,3.20960,5.000
5,58.133,6.69,3.0762,3.07620,5.000
5,58.267,5.37,2.9426,2.94263,5.000
5,58.400,4.27,2.8094,2.80940,5.000
5,58.533,3.36,2.6762,2.67623,5.000
5,58.667,2.59,2.5428,2.54280,5.000
5,58.800,1.96,2.4094,2.40940,5.000
5,58.933,1.43,2.2761,2.27610,5.000
5,59.067,1.00,2.1427,2.14267,5.000
5,59.200,0.65,2.0095,2.00950,5.000
5,59.333,0.39,1.8761,1.87610,5.000
5,59.467,0.20,1.7427,1.74270,5.000
5,59.600,0.08,1.6094,1.60940,5.000
5,59.733,0.03,1.4760,1.47600,5.000
5,59.867,0.00,1.3426,1.34257,5.000
5,60.000,0.00,1.2094,1.20940,5.000
5,60.133,0.00,1.0762,1.07617,5.000
5,60.267,-0.01,0.9426,0.94260,5.000
5,60.400,-0.01,0.8093,0.80930,5.000
5,60.533,-0.01,0.6760,0.67603,5.000
5,60.667,-0.01,0.5427,0.54267,5.000
5,60.800,-0.01,0.4093,0.40930,5.000
5,60.933,-0.01,0.2761,0.27607,5.000
5,61.067,-0.01,0.1425,0.14250,5.000
5,61.200,0.00,0.0092,0.00920,5.000
5,61.400,-0.01,-0.0002,-0.00020,5.000
5,61.533,0.00,-0.0002,-0.00020,5.000
5,61.667,-0.01,-0.0002,-0.00020,5.000
5,61.800,-0.01,-0.0002,-0.00020,5.000
5,61.933,-0.01,-0.0002,-0.00020,5.000
5,62.067,-0.01,-0.0002,-0.00020,5.000
5,62.200,-0.01,-0.0002,-0.00020,5.000
5,62.333,0.00,-0.0002,-0.00020,5.000
5,62.467,-0.01,-0.0002,-0.00020,5.000
5,62.600,-0.02,-0.0002,-0.00020,5.000
5,62.733,-0.01,-0.0002,-0.00020,5.000
5,62.867,-0.01,-0.0002,-0.00020,5.000
5,63.000,-0.01,-0.0002,-0.00020,5.000
5,63.133,0.00,-0.0002,-0.00020,5.000
5,63.267,-0.01,-0.0002,-0.00020,5.000
5,63.400,-0.01,-0.0002,-0.00020,5.000
5,63.533,-0.01,-0.0002,-0.00020,5.000
5,63.667,-0.01,-0.0002,-0.00020,5.000
5,63.800,0.00,-0.0002,-0.00020,5.000
5,63.933,-0.01,-0.0002,-0.00020,5.000
5,64.067,-0.01,-0.0002,-0.00020,5.000
5,64.200,-0.01,-0.0001,-0.00010,5.000
5,64.400,-0.01,-0.0001,-0.00010,5.000
5,64.533,0.00,-0.0001,-0.00010,5.000
5,64.667,-0.01,-0.0001,-0.00010,5.000
5,64.800,-0.01,-0.0001,-0.00010,5.000
5,64.933,-0.01,-0.0001,-0.00010,5.000
5,65.067,-0.01,-0.0001,-0.00010,5.000
5,65.200,-0.01,-0.0001,-0.00010,5.000
6,65.533,0.01,0.0597,0.05973,6.000
6,65.667,0.01,0.1933,0.19330,6.000
6,65.800,0.01,0.3267,0.32670,6.000
6,65.933,0.01,0.4600,0.46000,6.000
6,66.067,0.01,0.5934,0.59340,6.000
6,66.200,0.01,0.7266,0.72660,6.000
6,66.333,0.01,0.8600,0.85997,6.000
6,66.467,0.02,0.9934,0.99340,6.000
6,66.600,0.02,1.1267,1.12670,6.000
6,66.733,0.03,1.2600,1.26000,6.000
6,66.867,0.07,1.3933,1.39330,6.000
6,67.000,0.15,1.5266,1.52660,6.000
6,67.133,0.31,1.6600,1.65997,6.000
6,67.267,0.58,1.7934,1.79337,6.000
6,67.400,0.94,1.9268,1.92680,6.000
6,67.533,1.42,2.0601,2.06007,6.000
6,67.667,2.02,2.1934,2.19343,6.000
6,67.800,2.76,2.3268,2.32680,6.000
6,67.933,3.66,2.4601,2.46013,6.000
6,68.067,4.74,2.5935,2.59353,6.000
6,68.200,6.02,2.7270,2.72700,6.000
6,68.333,7.50,2.8599,2.85993,6.000
6,68.467,9.22,2.9935,2.99347,6.000
6,68.600,11.19,3.1268,3.12680,6.000
6,68.733,13.40,3.2601,3.26007,6.000
6,68.867,15.92,3.3935,3.39350,6.000
6,69.000,18.81,3.5268,3.52680,6.000
6,69.133,22.18,3.6600,3.65997,6.000
6,69.267,26.08,3.7934,3.79340,6.000
6,69.400,30.64,3.9268,3.92680,6.000
6,69.533,36.02,4.0601,4.06013,6.000
6,69.667,42.42,4.1934,4.19343,6.000
6,69.800,50.28,4.3270,4.32700,6.000
6,70.000,44.12,4.2675,4.26750,6.000
6,70.133,34.83,4.1343,4.13427,6.000
6,70.267,28.07,4.0010,4.00097,6.000
6,70.400,22.80,3.8675,3.86750,6.000
6,70.533,18.60,3.7342,3.73417,6.000
6,70.667,15.16,3.6009,3.60093,6.000
6,70.800,12.35,3.4674,3.46740,6.000
6,70.933,10.06,3.3342,3.33417,6.000
6,71.067,8.16,3.2009,3.20093,6.000
6,71.200,6.59,3.0675,3.06750,6.000
6,71.333,5.29,2.9340,2.93400,6.000
6,71.467,4.20,2.8008,2.80080,6.000
6,71.600,3.31,2.6675,2.66750,6.000
6,71.733,2.55,2.5341,2.53413,6.000
6,71.867,1.93,2.4009,2.40090,6.000
6,72.000,1.41,2.2673,2.26730,6.000
6,72.133,0.99,2.1340,2.13400,6.000
6,72.267,0.64,2.0009,2.00087,6.000
6,72.400,0.38,1.8674,1.86740,6.000
6,72.533,0.21,1.7341,1.73410,6.000
6,72.667,0.09,1.6008,1.60077,6.000
6,72.800,0.04,1.4674,1.46740,6.000
6,72.933,0.02,1.3338,1.33383,6.000
6,73.067,0.01,1.2008,1.20083,6.000
6,73.200,0.01,1.0674,1.06740,6.000
6,73.333,0.01,0.9338,0.93383,6.000
6,73.467,0.00,0.8007,0.80070,6.000
6,73.600,0.01,0.6674,0.66740,6.000
6,73.733,0.01,0.5339,0.53390,6.000
6,73.867,0.01,0.4007,0.40067,6.000
6,74.000,0.01,0.2674,0.26740,6.000
6,74.133,0.01,0.1338,0.13383,6.000
6,74.267,0.01,0.0006,0.00063,6.000
6,74.467,0.01,-0.0003,-0.00030,6.000
6,74.600,0.01,-0.0002,-0.00020,6.000
6,74.733,0.01,-0.0002,-0.00020,6.000
6,74.867,0.01,-0.0002,-0.00020,6.000
6,75.000,0.01,-0.0002,-0.00020,6.000
6,75.133,0.01,-0.0002,-0.00020,6.000
6,75.267,0.01,-0.0002,-0.00020,6.000
6,75.400,0.01,-0.0002,-0.00020,6.000
6,75.533,0.01,-0.0002,-0.00020,6.000
6,75.667,0.01,-0.0002,-0.00020,6.000
6,75.800,0.01,-0.0002,-0.00020,6.000
6,75.933,0.01,-0.0002,-0.00020,6.000
6,76.067,0.00,-0.0002,-0.00020,6.000
6,76.200,0.01,-0.0002,-0.00020,6.000
6,76.333,0.01,-0.0002,-0.00020,6.000
6,76.467,0.01,-0.0002,-0.00020,6.000
6,76.600,0.00,-0.0002,-0.00020,6.000
6,76.733,0.01,-0.0002,-0.00020,6.000
6,76.867,0.01,-0.0002,-0.00020,6.000
6,77.000,0.01,-0.0002,-0.00020,6.000
6,77.133,0.00,-0.0002,-0.00020,6.000
6,77.267,0.00,-0.0002,-0.00020,6.000
6,77.467,0.01,-0.0002,-0.00020,6.000
6,77.600,0.01,-0.0002,-0.00020,6.000
6,77.733,0.01,-0.0001,-0.00010,6.000
6,77.867,0.01,-0.0001,-0.00010,6.000
6,78.000,0.01,-0.0001,-0.00010,6.000
6,78.133,0.01,-0.0001,-0.00010,6.000
6,78.267,0.00,-0.0001,-0.00010,6.000
7,78.667,0.01,0.1030,0.10300,7.000
7,78.800,0.01,0.2367,0.23670,7.000
7,78.933,0.01,0.3699,0.36990,7.000
7,79.067,0.01,0.5033,0.50327,7.000
7,79.200,0.00,0.6367,0.63670,7.000
7,79.333,0.00,0.7701,0.77007,7.000
7,79.467,0.00,0.9033,0.90330,7.000
7,79.600,0.01,1.0368,1.03680,7.000
7,79.733,0.02,1.1701,1.17010,7.000
7,79.867,0.03,1.3033,1.30330,7.000
7,80.000,0.08,1.4368,1.43680,7.000
7,80.133,0.19,1.5700,1.56997,7.000
7,80.267,0.38,1.7034,1.70337,7.000
7,80.400,0.67,1.8368,1.83680,7.000
7,80.533,1.07,1.9702,1.97020,7.000
7,80.667,1.59,2.1034,2.10337,7.000
7,80.800,2.22,2.2367,2.23670,7.000
7,80.933,3.02,2.3701,2.37013,7.000
7,81.067,3.97,2.5035,2.50347,7.000
7,81.200,5.11,2.6370,2.63700,7.000
7,81.333,6.44,2.7702,2.77020,7.000
7,81.467,8.00,2.9033,2.90333,7.000
7,81.600,9.79,3.0367,3.03670,7.000
7,81.733,11.83,3.1701,3.17013,7.000
7,81.867,14.14,3.3034,3.30340,7.000
7,82.000,16.76,3.4367,3.43670,7.000
7,82.133,19.80,3.5701,3.57010,7.000
7,82.267,23.32,3.7034,3.70340,7.000
7,82.400,27.42,3.8368,3.83680,7.000
7,82.533,32.22,3.9701,3.97013,7.000
7,82.667,37.90,4.1035,4.10347,7.000
7,82.800,44.69,4.2367,4.23670,7.000
7,83.000,53.00,4.3579,4.35790,7.000
7,83.133,40.67,4.2242,4.22420,7.000
7,83.267,32.39,4.0910,4.09097,7.000
7,83.400,26.21,3.9576,3.95760,7.000
7,83.533,21.32,3.8242,3.82420,7.000
7,83.667,17.39,3.6909,3.69093,7.000
7,83.800,14.17,3.5576,3.55760,7.000
7,83.933,11.54,3.4241,3.42410,7.000
7,84.067,9.38,3.2909,3.29087,7.000
7,84.200,7.60,3.1575,3.15750,7.000
7,84.333,6.11,3.0241,3.02407,7.000
7,84.467,4.90,2.8907,2.89070,7.000
7,84.600,3.88,2.7575,2.75750,7.000
7,84.733,3.03,2.6241,2.62413,7.000
7,84.867,2.31,2.4908,2.49083,7.000
7,85.000,1.73,2.3575,2.35750,7.000
7,85.133,1.25,2.2239,2.22393,7.000
7,85.267,0.85,2.0908,2.09077,7.000
7,85.400,0.54,1.9575,1.95750,7.000
7,85.533,0.31,1.8240,1.82403,7.000
7,85.667,0.15,1.6908,1.69077,7.000
7,85.800,0.06,1.5573,1.55730,7.000
7,85.933,0.02,1.4240,1.42400,7.000
7,86.067,0.01,1.2907,1.29067,7.000
7,86.200,0.00,1.1576,1.15760,7.000
7,86.333,0.00,1.0240,1.02403,7.000
7,86.467,0.00,0.8906,0.89060,7.000
7,86.600,0.00,0.7574,0.75740,7.000
7,86.733,0.00,0.6240,0.62400,7.000
7,86.867,0.00,0.4906,0.49063,7.000
7,87.000,0.00,0.3573,0.35730,7.000
7,87.133,0.00,0.2239,0.22393,7.000
7,87.267,0.00,0.0904,0.09043,7.000
7,87.467,0.00,-0.0364,-0.03637,7.000
7,87.600,0.00,-0.0002,-0.00020,7.000
7,87.733,0.00,-0.0002,-0.00020,7.000
7,87.867,0.00,-0.0002,-0.00020,7.000
7,88.000,0.01,-0.0002,-0.00020,7.000
7,88.133,0.00,-0.0002,-0.00020,7.000
7,88.267,0.00,-0.0002,-0.00020,7.000
7,88.400,0.00,-0.0002,-0.00020,7.000
7,88.533,0.00,-0.0002,-0.00020,7.000
7,88.667,0.00,-0.0002,-0.00020,7.000
7,88.800,0.00,-0.0002,-0.00020,7.000
7,88.933,0.00,-0.0002,-0.00020,7.000
7,89.067,0.00,-0.0002,-0.00020,7.000
7,89.200,0.00,-0.0002,-0.00020,7.000
7,89.333,0.00,-0.0002,-0.00020,7.000
7,89.467,0.00,-0.0002,-0.00020,7.000
7,89.600,0.00,-0.0002,-0.00020,7.000
7,89.733,0.00,-0.0002,-0.00020,7.000
7,89.867,0.00,-0.0002,-0.00020,7.000
7,90.000,0.00,-0.0002,-0.00020,7.000
7,90.133,0.00,-0.0002,-0.00020,7.000
7,90.267,-0.01,-0.0002,-0.00020,7.000
7,90.400,0.00,-0.0002,-0.00020,7.000
7,90.667,0.00,-0.0001,-0.00010,7.000
7,90.800,0.00,-0.0001,-0.00010,7.000
7,90.933,0.00,-0.0001,-0.00010,7.000
7,91.067,0.00,-0.0001,-0.00010,7.000
7,91.200,0.00,-0.0001,-0.00010,7.000
7,91.333,0.00,-0.0001,-0.00010,7.000
7,91.467,0.00,-0.0001,-0.00010,7.000
8,91.800,0.00,0.1665,0.16650,8.000
8,91.933,-0.01,0.2999,0.29990,8.000
8,92.067,0.00,0.4334,0.43340,8.000
8,92.200,-0.01,0.5667,0.56670,8.000
8,92.333,-0.01,0.6999,0.69990,8.000
8,92.467,0.00,0.8334,0.83343,8.000
8,92.600,0.01,0.9667,0.96670,8.000
8,92.733,0.01,1.1000,1.10003,8.000
8,92.867,0.02,1.2335,1.23353,8.000
8,93.000,0.04,1.3667,1.36670,8.000
8,93.133,0.12,1.4999,1.49993,8.000
8,93.267,0.26,1.6334,1.63337,8.000
8,93.400,0.49,1.7668,1.76680,8.000
8,93.533,0.83,1.9000,1.90000,8.000
8,93.667,1.28,2.0335,2.03347,8.000
8,93.800,1.86,2.1669,2.16690,8.000
8,93.933,2.56,2.3000,2.30000,8.000
8,94.067,3.43,2.4336,2.43357,8.000
8,94.200,4.46,2.5670,2.56700,8.000
8,94.333,5.70,2.7001,2.70013,8.000
8,94.467,7.13,2.8334,2.83340,8.000
8,94.600,8.80,2.9669,2.96690,8.000
8,94.733,10.71,3.1001,3.10007,8.000
8,94.867,12.85,3.2335,3.23347,8.000
8,95.000,15.30,3.3669,3.36690,8.000
8,95.133,18.11,3.5000,3.50000,8.000
8,95.267,21.37,3.6334,3.63340,8.000
8,95.400,25.13,3.7669,3.76690,8.000
8,95.533,29.55,3.9001,3.90007,8.000
8,95.667,34.74,4.0335,4.03350,8.000
8,95.800,40.88,4.1669,4.16690,8.000
8,95.933,48.39,4.3001,4.30010,8.000
8,96.133,46.35,4.2942,4.29423,8.000
8,96.267,36.33,4.1610,4.16100,8.000
8,96.400,29.22,4.0276,4.02760,8.000
8,96.533,23.70,3.8942,3.89423,8.000
8,96.667,19.31,3.7610,3.76100,8.000
8,96.800,15.75,3.6275,3.62750,8.000
8,96.933,12.81,3.4941,3.49413,8.000
8,97.067,10.44,3.3609,3.36093,8.000
8,97.200,8.47,3.2275,3.22750,8.000
8,97.333,6.84,3.0941,3.09410,8.000
8,97.467,5.49,2.9608,2.96080,8.000
8,97.600,4.37,2.8274,2.82740,8.000
8,97.733,3.43,2.6942,2.69417,8.000
8,97.867,2.66,2.5609,2.56087,8.000
8,98.000,2.02,2.4274,2.42740,8.000
8,98.133,1.48,2.2940,2.29403,8.000
8,98.267,1.04,2.1607,2.16073,8.000
8,98.400,0.68,2.0274,2.02740,8.000
8,98.533,0.41,1.8940,1.89403,8.000
8,98.667,0.22,1.7608,1.76083,8.000
8,98.800,0.10,1.6273,1.62730,8.000
8,98.933,0.03,1.4939,1.49387,8.000
8,99.067,0.00,1.3606,1.36063,8.000
8,99.200,0.00,1.2274,1.22740,8.000
8,99.333,0.00,1.0940,1.09400,8.000
8,99.467,-0.01,0.9607,0.96073,8.000
8,99.600,0.00,0.8274,0.82740,8.000
8,99.733,-0.01,0.6939,0.69393,8.000
8,99.867,0.00,0.5607,0.56073,8.000
8,100.000,-0.01,0.4274,0.42740,8.000
8,100.133,-0.01,0.2939,0.29390,8.000
8,100.267,-0.01,0.1606,0.16057,8.000
8,100.400,-0.01,0.0273,0.02730,8.000
8,100.600,-0.01,-0.0002,-0.00020,8.000
8,100.733,0.00,-0.0002,-0.00020,8.000
8,100.867,-0.01,-0.0002,-0.00020,8.000
8,101.000,-0.01,-0.0002,-0.00020,8.000
8,101.133,-0.01,-0.0002,-0.00020,8.000
8,101.267,0.00,-0.0002,-0.00020,8.000
8,101.400,0.00,-0.0002,-0.00020,8.000
8,101.533,0.00,-0.0002,-0.00020,8.000
8,101.667,0.00,-0.0002,-0.00020,8.000
8,101.800,-0.01,-0.0002,-0.00020,8.000
8,101.933,-0.01,-0.0002,-0.00020,8.000
8,102.067,0.00,-0.0002,-0.00020,8.000
8,102.200,-0.01,-0.0002,-0.00020,8.000
8,102.333,0.00,-0.0002,-0.00020,8.000
8,102.467,0.00,-0.0002,-0.00020,8.000
8,102.600,0.00,-0.0002,-0.00020,8.000
8,102.733,-0.01,-0.0002,-0.00020,8.000
8,102.867,-0.01,-0.0002,-0.00020,8.000
8,103.000,0.00,-0.0002,-0.00020,8.000
8,103.133,0.00,-0.0002,-0.00020,8.000
8,103.267,-0.01,-0.0002,-0.00020,8.000
8,103.400,-0.01,-0.0002,-0.00020,8.000
8,103.667,-0.01,-0.0001,-0.00010,8.000
8,103.800,0.00,-0.0001,-0.00010,8.000
8,103.933,-0.01,-0.0001,-0.00010,8.000
8,104.067,-0.01,-0.0001,-0.00010,8.000
8,104.200,-0.01,-0.0001,-0.00010,8.000
8,104.333,0.00,-0.0001,-0.00010,8.000
8,104.467,-0.01,-0.0001,-0.00010,8.000
9,104.800,0.00,0.0785,0.07850,9.000
9,104.933,0.00,0.2119,0.21187,9.000
9,105.067,0.00,0.3453,0.34533,9.000
9,105.200,0.00,0.4788,0.47880,9.000
9,105.333,0.00,0.6120,0.61197,9.000
9,105.467,0.00,0.7453,0.74527,9.000
9,105.600,0.00,0.8788,0.87880,9.000
9,105.733,0.01,1.0120,1.01200,9.000
9,105.867,0.01,1.1455,1.14547,9.000
9,106.000,0.03,1.2789,1.27890,9.000
9,106.133,0.06,1.4119,1.41190,9.000
9,106.267,0.16,1.5453,1.54527,9.000
9,106.400,0.32,1.6788,1.67880,9.000
9,106.533,0.59,1.8121,1.81210,9.000
9,106.667,0.97,1.9454,1.94537,9.000
9,106.800,1.46,2.0788,2.07880,9.000
9,106.933,2.07,2.2121,2.21207,9.000
9,107.067,2.82,2.3454,2.34543,9.000
9,107.200,3.76,2.4789,2.47890,9.000
9,107.333,4.85,2.6122,2.61220,9.000
9,107.467,6.16,2.7454,2.74543,9.000
9,107.600,7.68,2.8788,2.87880,9.000
9,107.733,9.43,3.0121,3.01210,9.000
9,107.867,11.43,3.1453,3.14533,9.000
9,108.000,13.66,3.2789,3.27890,9.000
9,108.133,16.23,3.4121,3.41213,9.000
9,108.267,19.19,3.5453,3.54533,9.000
9,108.400,22.62,3.6789,3.67890,9.000
9,108.533,26.61,3.8122,3.81217,9.000
9,108.667,31.27,3.9454,3.94543,9.000
9,108.800,36.77,4.0789,4.07890,9.000
9,108.933,43.36,4.2122,4.21217,9.000
9,109.067,51.49,4.3455,4.34547,9.000
9,109.267,42.86,4.2529,4.25293,9.000
9,109.400,33.98,4.1197,4.11970,9.000
9,109.533,27.42,3.9862,3.98620,9.000
9,109.667,22.29,3.8529,3.85293,9.000
9,109.800,18.17,3.7197,3.71970,9.000
9,109.933,14.80,3.5861,3.58610,9.000
9,110.067,12.04,3.4528,3.45280,9.000
9,110.200,9.79,3.3197,3.31970,9.000
9,110.333,7.93,3.1861,3.18610,9.000
9,110.467,6.39,3.0528,3.05280,9.000
9,110.600,5.12,2.9194,2.91940,9.000
9,110.733,4.06,2.7861,2.78607,9.000
9,110.867,3.18,2.6529,2.65287,9.000
9,111.000,2.44,2.5196,2.51960,9.000
9,111.133,1.84,2.3861,2.38607,9.000
9,111.267,1.33,2.2527,2.25270,9.000
9,111.400,0.91,2.1194,2.11940,9.000
9,111.533,0.59,1.9860,1.98603,9.000
9,111.667,0.35,1.8528,1.85277,9.000
9,111.800,0.18,1.7196,1.71960,9.000
9,111.933,0.07,1.5859,1.58590,9.000
9,112.067,0.02,1.4526,1.45263,9.000
9,112.200,0.01,1.3194,1.31940,9.000
9,112.333,0.00,1.1861,1.18607,9.000
9,112.467,0.00,1.0527,1.05267,9.000
9,112.600,0.00,0.9193,0.91930,9.000
9,112.733,0.00,0.7860,0.78597,9.000
9,112.867,0.00,0.6525,0.65253,9.000
9,113.000,0.00,0.5195,0.51950,9.000
9,113.133,0.00,0.3860,0.38597,9.000
9,113.267,0.00,0.2526,0.25260,9.000
9,113.400,0.00,0.1192,0.11920,9.000
9,113.533,0.00,-0.0140,-0.01400,9.000
9,113.733,0.00,-0.0002,-0.00020,9.000
9,113.867,0.00,-0.0002,-0.00020,9.000
9,114.000,0.00,-0.0002,-0.00020,9.000
9,114.133,0.00,-0.0002,-0.00020,9.000
9,114.267,0.00,-0.0002,-0.00020,9.000
9,114.400,0.00,-0.0002,-0.00020,9.000
9,114.533,0.00,-0.0002,-0.00020,9.000
9,114.667,0.00,-0.0002,-0.00020,9.000
9,114.800,0.00,-0.0002,-0.00020,9.000
9,114.933,0.00,-0.0002,-0.00020,9.000
9,115.067,0.00,-0.0002,-0.00020,9.000
9,115.200,0.00,-0.0002,-0.00020,9.000
9,115.333,0.00,-0.0002,-0.00020,9.000
9,115.467,0.00,-0.0002,-0.00020,9.000
9,115.600,0.00,-0.0002,-0.00020,9.000
9,115.733,0.00,-0.0002,-0.00020,9.000
9,115.867,0.00,-0.0002,-0.00020,9.000
9,116.000,0.00,-0.0002,-0.00020,9.000
9,116.133,0.00,-0.0002,-0.00020,9.000
9,116.267,0.00,-0.0002,-0.00020,9.000
9,116.400,0.00,-0.0001,-0.00010,9.000
9,116.533,0.00,-0.0001,-0.00010,9.000
9,116.733,0.00,-0.0001,-0.00010,9.000
9,116.867,0.00,-0.0001,-0.00010,9.000
9,117.000,0.00,-0.0001,-0.00010,9.000
9,117.133,0.00,-0.0001,-0.00010,9.000
9,117.267,0.00,-0.0001,-0.00010,9.000
9,117.400,0.00,-0.0001,-0.00010,9.000
9,117.533,0.00,-0.0001,-0.00010,9.000
10,117.867,0.00,0.0631,0.06310,10.000
10,118.000,0.00,0.1966,0.19660,10.000
10,118.133,0.00,0.3300,0.32997,10.000
10,118.267,0.00,0.4633,0.46327,10.000
10,118.400,0.00,0.5968,0.59680,10.000
10,118.533,0.00,0.7300,0.73000,10.000
10,118.667,0.00,0.8633,0.86333,10.000
10,118.800,0.01,0.9968,0.99680,10.000
10,118.933,0.01,1.1302,1.13017,10.000
10,119.067,0.02,1.2634,1.26340,10.000
10,119.200,0.06,1.3966,1.39660,10.000
10,119.333,0.14,1.5300,1.52997,10.000
10,119.467,0.29,1.6633,1.66333,10.000
10,119.600,0.54,1.7968,1.79680,10.000
10,119.733,0.90,1.9301,1.93013,10.000
10,119.867,1.38,2.0634,2.06340,10.000
10,120.000,1.99,2.1967,2.19670,10.000
10,120.133,2.72,2.3302,2.33017,10.000
10,120.267,3.61,2.4634,2.46343,10.000
10,120.400,4.69,2.5970,2.59700,10.000
10,120.533,5.97,2.7303,2.73027,10.000
10,120.667,7.47,2.8633,2.86333,10.000
10,120.800,9.19,2.9968,2.99680,10.000
10,120.933,11.16,3.1302,3.13017,10.000
10,121.067,13.38,3.2634,3.26343,10.000
10,121.200,15.89,3.3968,3.39680,10.000
10,121.333,18.81,3.5301,3.53010,10.000
10,121.467,22.18,3.6634,3.66343,10.000
10,121.600,26.09,3.7968,3.79680,10.000
10,121.733,30.65,3.9302,3.93017,10.000
10,121.867,36.06,4.0635,4.06347,10.000
10,122.000,42.47,4.1968,4.19680,10.000
10,122.133,50.38,4.3302,4.33023,10.000
10,122.333,43.81,4.2641,4.26413,10.000
10,122.467,34.62,4.1309,4.13093,10.000
10,122.600,27.91,3.9976,3.99760,10.000
10,122.733,22.69,3.8642,3.86420,10.000
10,122.867,18.48,3.7309,3.73093,10.000
10,123.000,15.07,3.5977,3.59770,10.000
10,123.133,12.26,3.4641,3.46410,10.000
10,123.267,9.97,3.3309,3.33087,10.000
10,123.400,8.07,3.1976,3.19760,10.000
10,123.533,6.51,3.0641,3.06410,10.000
10,123.667,5.21,2.9307,2.93073,10.000
10,123.800,4.13,2.7974,2.79740,10.000
10,123.933,3.25,2.6641,2.66410,10.000
10,124.067,2.49,2.5308,2.53080,10.000
10,124.200,1.88,2.3976,2.39760,10.000
10,124.333,1.36,2.2640,2.26400,10.000
10,124.467,0.94,2.1307,2.13073,10.000
10,124.600,0.61,1.9976,1.99760,10.000
10,124.733,0.37,1.8640,1.86397,10.000
10,124.867,0.19,1.7308,1.73080,10.000
10,125.000,0.08,1.5973,1.59730,10.000
10,125.133,0.03,1.4640,1.46400,10.000
10,125.267,0.02,1.3306,1.33057,10.000
10,125.400,0.00,1.1974,1.19740,10.000
10,125.533,0.01,1.0641,1.06407,10.000
10,125.667,0.00,0.9306,0.93060,10.000
10,125.800,0.00,0.7975,0.79750,10.000
10,125.933,-0.01,0.6640,0.66397,10.000
10,126.067,0.01,0.5307,0.53067,10.000
10,126.200,0.01,0.3973,0.39730,10.000
10,126.333,0.00,0.2640,0.26397,10.000
10,126.467,0.00,0.1305,0.13047,10.000
10,126.600,0.00,-0.0026,-0.00260,10.000
10,126.800,0.00,-0.0002,-0.00020,10.000
10,126.933,0.00,-0.0002,-0.00020,10.000
10,127.067,0.00,-0.0002,-0.00020,10.000
10,127.200,-0.02,-0.0002,-0.00020,10.000
10,127.333,0.00,-0.0002,-0.00020,10.000
10,127.467,0.00,-0.0002,-0.00020,10.000
10,127.600,0.00,-0.0002,-0.00020,10.000
10,127.733,0.00,-0.0002,-0.00020,10.000
10,127.867,0.00,-0.0002,-0.00020,10.000
10,128.000,0.00,-0.0002,-0.00020,10.000
10,128.133,0.00,-0.0002,-0.00020,10.000
10,128.267,0.00,-0.0002,-0.00020,10.000
10,128.400,0.01,-0.0002,-0.00020,10.000
10,128.533,0.00,-0.0002,-0.00020,10.000
10,128.667,0.00,-0.0002,-0.00020,10.000
10,128.800,-0.01,-0.0002,-0.00020,10.000
10,128.933,0.00,-0.0002,-0.00020,10.000
10,129.067,0.01,-0.0002,-0.00020,10.000
10,129.200,0.00,-0.0002,-0.00020,10.000
10,129.333,0.00,-0.0002,-0.00020,10.000
10,129.467,0.00,-0.0002,-0.00020,10.000
10,129.600,0.00,-0.0001,-0.00010,10.000
10,129.800,0.00,-0.0001,-0.00010,10.000
10,129.933,0.00,-0.0001,-0.00010,10.000
10,130.067,0.00,-0.0001,-0.00010,10.000
10,130.200,-0.01,-0.0001,-0.00010,10.000
10,130.333,0.01,-0.0001,-0.00010,10.000
10,130.467,0.00,-0.0001,-0.00010,10.000
10,130.600,0.00,-0.0001,-0.00010,10.000
10,130.667,0.00,-0.0001,-0.00010,10.000