File: calibDATA_loadcell/date_02:15:2018/Instron_02.15.2018/2_50N_0__1mm.s_0_0_hold.txt
""
"Test Method","Radhen_Load_Cntrl_Cmprsn_250N_12-7.msm"
"Sample I. D.","Sample1.mss"
"Specimen Number","37"

"TheCycle_Output ()","_Time (s)","_Load (N)","_Extension (mm)","RealTimeDepth (mm)","CycleNumber ()"

1,0.267,0.00,0.0580,0.05803,1.000
1,0.333,0.00,0.1246,0.12463,1.000
1,0.400,-0.01,0.1916,0.19160,1.000
1,0.467,0.00,0.2581,0.25813,1.000
1,0.533,0.00,0.3247,0.32473,1.000
1,0.600,-0.01,0.3916,0.39160,1.000
1,0.667,0.00,0.4581,0.45813,1.000
1,0.733,0.00,0.5248,0.52483,1.000
1,0.800,0.00,0.5916,0.59160,1.000
1,0.867,0.00,0.6582,0.65823,1.000
1,0.933,-0.01,0.7248,0.72483,1.000
1,1.000,-0.02,0.7917,0.79170,1.000
1,1.067,0.00,0.8582,0.85820,1.000
1,1.133,-0.01,0.9248,0.92483,1.000
1,1.200,0.00,0.9915,0.99150,1.000
1,1.267,-0.01,1.0582,1.05820,1.000
1,1.333,-0.01,1.1250,1.12497,1.000
1,1.400,0.00,1.1917,1.19170,1.000
1,1.467,-0.01,1.2583,1.25830,1.000
1,1.533,0.00,1.3250,1.32497,1.000
1,1.600,0.00,1.3917,1.39170,1.000
1,1.667,0.00,1.4581,1.45813,1.000
1,1.733,0.00,1.5248,1.52483,1.000
1,1.800,-0.01,1.5916,1.59160,1.000
1,1.867,-0.01,1.6583,1.65830,1.000
1,1.933,-0.01,1.7249,1.72493,1.000
1,2.000,0.00,1.7917,1.79170,1.000
1,2.067,-0.01,1.8582,1.85817,1.000
1,2.133,-0.01,1.9249,1.92493,1.000
1,2.200,-0.01,1.9918,1.99180,1.000
1,2.267,0.00,2.0583,2.05833,1.000
1,2.333,0.00,2.1249,2.12493,1.000
1,2.400,0.00,2.1917,2.19170,1.000
1,2.467,-0.01,2.2583,2.25830,1.000
1,2.533,0.00,2.3250,2.32497,1.000
1,2.600,0.00,2.3917,2.39170,1.000
1,2.667,0.01,2.4583,2.45827,1.000
1,2.733,-0.01,2.5249,2.52490,1.000
1,2.800,-0.02,2.5916,2.59160,1.000
1,2.867,-0.01,2.6583,2.65827,1.000
1,2.933,-0.01,2.7250,2.72497,1.000
1,3.000,0.00,2.7919,2.79190,1.000
1,3.067,-0.01,2.8583,2.85833,1.000
1,3.133,0.00,2.9250,2.92497,1.000
1,3.200,0.01,2.9917,2.99170,1.000
1,3.267,0.00,3.0583,3.05833,1.000
1,3.333,0.00,3.1251,3.12513,1.000
1,3.400,-0.01,3.1918,3.19180,1.000
1,3.467,-0.01,3.2584,3.25843,1.000
1,3.533,-0.01,3.3251,3.32513,1.000
1,3.600,0.00,3.3917,3.39170,1.000
1,3.667,0.00,3.4584,3.45837,1.000
1,3.733,0.00,3.5251,3.52507,1.000
1,3.800,-0.01,3.5918,3.59180,1.000
1,3.867,0.00,3.6585,3.65850,1.000
1,3.933,-0.01,3.7252,3.72523,1.000
1,4.000,0.00,3.7919,3.79190,1.000
1,4.067,-0.01,3.8583,3.85833,1.000
1,4.133,0.00,3.9250,3.92500,1.000
1,4.200,0.00,3.9918,3.99180,1.000
1,4.267,0.00,4.0583,4.05833,1.000
1,4.333,0.01,4.1251,4.12507,1.000
1,4.400,0.00,4.1918,4.19180,1.000
1,4.467,0.01,4.2584,4.25840,1.000
1,4.533,0.01,4.3252,4.32517,1.000
1,4.600,0.02,4.3917,4.39170,1.000
1,4.667,0.03,4.4584,4.45837,1.000
1,4.733,0.07,4.5252,4.52523,1.000
1,4.800,0.11,4.5918,4.59180,1.000
1,4.867,0.18,4.6584,4.65843,1.000
1,4.933,0.27,4.7251,4.72513,1.000
1,5.000,0.40,4.7918,4.79180,1.000
1,5.067,0.53,4.8584,4.85837,1.000
1,5.133,0.71,4.9252,4.92520,1.000
1,5.200,0.91,4.9920,4.99200,1.000
1,5.267,1.14,5.0585,5.05853,1.000
1,5.333,1.40,5.1253,5.12530,1.000
1,5.400,1.68,5.1920,5.19200,1.000
1,5.467,1.99,5.2585,5.25847,1.000
1,5.533,2.34,5.3252,5.32523,1.000
1,5.600,2.73,5.3918,5.39180,1.000
1,5.667,3.13,5.4584,5.45843,1.000
1,5.733,3.57,5.5252,5.52523,1.000
1,5.800,4.06,5.5920,5.59200,1.000
1,5.867,4.56,5.6586,5.65863,1.000
1,5.933,5.12,5.7253,5.72527,1.000
1,6.000,5.70,5.7918,5.79180,1.000
1,6.067,6.33,5.8583,5.85833,1.000
1,6.133,6.99,5.9251,5.92513,1.000
1,6.200,7.71,5.9918,5.99180,1.000
1,6.267,8.46,6.0584,6.05840,1.000
1,6.333,9.27,6.1252,6.12520,1.000
1,6.400,10.12,6.1918,6.19180,1.000
1,6.467,11.03,6.2584,6.25843,1.000
1,6.533,11.99,6.3252,6.32520,1.000
1,6.600,13.02,6.3918,6.39180,1.000
1,6.667,14.09,6.4585,6.45847,1.000
1,6.733,15.22,6.5252,6.52520,1.000
1,6.800,16.44,6.5918,6.59180,1.000
1,6.867,17.72,6.6585,6.65850,1.000
1,6.933,19.09,6.7252,6.72517,1.000
1,7.000,20.53,6.7919,6.79190,1.000
1,7.067,22.07,6.8585,6.85850,1.000
1,7.133,23.69,6.9253,6.92533,1.000
1,7.200,25.43,6.9918,6.99180,1.000
1,7.267,27.25,7.0585,7.05847,1.000
1,7.333,29.20,7.1252,7.12520,1.000
1,7.400,31.26,7.1918,7.19180,1.000
1,7.467,33.47,7.2584,7.25840,1.000
1,7.533,35.81,7.3252,7.32520,1.000
1,7.600,38.29,7.3918,7.39180,1.000
1,7.667,40.97,7.4584,7.45843,1.000
1,7.733,43.83,7.5252,7.52520,1.000
1,7.800,46.93,7.5918,7.59180,1.000
1,7.867,50.27,7.6584,7.65843,1.000
1,8.000,51.08,7.7020,7.70200,1.000
1,8.067,50.18,7.7020,7.70200,1.000
1,8.133,49.58,7.7020,7.70200,1.000
1,8.200,49.13,7.7020,7.70200,1.000
1,8.267,48.77,7.7020,7.70200,1.000
1,8.333,48.47,7.7020,7.70200,1.000
1,8.400,48.23,7.7020,7.70200,1.000
1,8.467,48.00,7.7020,7.70200,1.000
1,8.533,47.81,7.7020,7.70200,1.000
1,8.600,47.64,7.7020,7.70200,1.000
1,8.667,47.49,7.7020,7.70200,1.000
1,8.733,47.34,7.7020,7.70200,1.000
1,8.800,47.21,7.7020,7.70200,1.000
1,8.867,47.09,7.7020,7.70200,1.000
1,8.933,46.98,7.7020,7.70200,1.000
1,9.000,46.88,7.7020,7.70200,1.000
1,9.067,46.78,7.7020,7.70200,1.000
1,9.133,46.69,7.7020,7.70200,1.000
1,9.200,46.60,7.7020,7.70200,1.000
1,9.267,46.52,7.7020,7.70200,1.000
1,9.333,46.45,7.7020,7.70200,1.000
1,9.400,46.37,7.7020,7.70200,1.000
1,9.467,46.30,7.7020,7.70200,1.000
1,9.533,46.24,7.7020,7.70200,1.000
1,9.600,46.17,7.7020,7.70200,1.000
1,9.667,46.11,7.7020,7.70200,1.000
1,9.733,46.05,7.7020,7.70200,1.000
1,9.800,45.99,7.7020,7.70200,1.000
1,9.867,45.94,7.7020,7.70200,1.000
1,9.933,45.89,7.7020,7.70200,1.000
1,10.000,45.84,7.7020,7.70200,1.000
1,10.067,45.79,7.7020,7.70200,1.000
1,10.133,45.75,7.7020,7.70200,1.000
1,10.200,45.70,7.7020,7.70200,1.000
1,10.267,45.66,7.7020,7.70200,1.000
1,10.333,45.61,7.7020,7.70200,1.000
1,10.400,45.57,7.7020,7.70200,1.000
1,10.467,45.53,7.7020,7.70200,1.000
1,10.533,45.49,7.7020,7.70200,1.000
1,10.600,45.45,7.7020,7.70200,1.000
1,10.667,45.41,7.7020,7.70200,1.000
1,10.733,45.38,7.7020,7.70200,1.000
1,10.800,45.35,7.7020,7.70200,1.000
1,10.867,45.31,7.7020,7.70200,1.000
1,10.933,45.27,7.7020,7.70200,1.000
1,11.000,45.24,7.7020,7.70200,1.000
1,11.067,45.21,7.7020,7.70200,1.000
1,11.133,45.18,7.7020,7.70200,1.000
1,11.200,45.14,7.7020,7.70200,1.000
1,11.267,45.12,7.7020,7.70200,1.000
1,11.333,45.09,7.7020,7.70200,1.000
1,11.400,45.06,7.7020,7.70200,1.000
1,11.467,45.03,7.7020,7.70200,1.000
1,11.533,44.99,7.7020,7.70200,1.000
1,11.600,44.97,7.7020,7.70200,1.000
1,11.667,44.94,7.7020,7.70200,1.000
1,11.733,44.91,7.7020,7.70200,1.000
1,11.800,44.89,7.7020,7.70200,1.000
1,11.867,44.86,7.7020,7.70200,1.000
1,11.933,44.84,7.7020,7.70200,1.000
1,12.000,44.81,7.7020,7.70200,1.000
1,12.067,44.79,7.7020,7.70200,1.000
1,12.133,44.77,7.7020,7.70200,1.000
1,12.200,44.74,7.7020,7.70200,1.000
1,12.267,44.72,7.7020,7.70200,1.000
1,12.333,44.70,7.7020,7.70200,1.000
1,12.400,44.67,7.7020,7.70200,1.000
1,12.467,44.65,7.7020,7.70200,1.000
1,12.533,44.63,7.7020,7.70200,1.000
1,12.600,44.61,7.7020,7.70200,1.000
1,12.667,44.59,7.7020,7.70200,1.000
1,12.733,44.57,7.7020,7.70200,1.000
1,12.800,44.55,7.7020,7.70200,1.000
1,12.867,44.52,7.7020,7.70200,1.000
1,12.933,44.51,7.7020,7.70200,1.000
1,13.000,44.49,7.7020,7.70200,1.000
1,13.067,44.47,7.7020,7.70200,1.000
1,13.133,44.45,7.7020,7.70200,1.000
1,13.200,44.43,7.7020,7.70200,1.000
1,13.267,44.41,7.7020,7.70200,1.000
1,13.333,44.39,7.7020,7.70200,1.000
1,13.400,44.38,7.7020,7.70200,1.000
1,13.467,44.36,7.7020,7.70200,1.000
1,13.533,44.34,7.7020,7.70200,1.000
1,13.600,44.32,7.7020,7.70200,1.000
1,13.667,44.31,7.7020,7.70200,1.000
1,13.733,44.29,7.7020,7.70200,1.000
1,13.800,44.26,7.7020,7.70200,1.000
1,13.867,44.26,7.7020,7.70200,1.000
1,13.933,44.25,7.7020,7.70200,1.000
1,14.000,44.23,7.7020,7.70200,1.000
1,14.067,44.22,7.7020,7.70200,1.000
1,14.133,44.20,7.7020,7.70200,1.000