File: calibDATA_loadcell/date_02:15:2018/Instron_02.15.2018/2_5N_0__1mm.s_0_0_hold.txt
""
"Test Method","Radhen_Load_Cntrl_Cmprsn_250N_12-7.msm"
"Sample I. D.","Sample1.mss"
"Specimen Number","31"

"TheCycle_Output ()","_Time (s)","_Load (N)","_Extension (mm)","RealTimeDepth (mm)","CycleNumber ()"

1,0.267,-0.01,0.0550,0.05503,1.000
1,0.333,0.00,0.1216,0.12163,1.000
1,0.400,-0.02,0.1885,0.18850,1.000
1,0.467,0.00,0.2552,0.25517,1.000
1,0.533,0.00,0.3217,0.32173,1.000
1,0.600,0.00,0.3886,0.38860,1.000
1,0.667,0.00,0.4552,0.45520,1.000
1,0.733,-0.01,0.5219,0.52187,1.000
1,0.800,-0.01,0.5887,0.58870,1.000
1,0.867,-0.01,0.6552,0.65520,1.000
1,0.933,0.00,0.7218,0.72183,1.000
1,1.000,-0.01,0.7887,0.78870,1.000
1,1.067,0.00,0.8553,0.85527,1.000
1,1.133,0.00,0.9219,0.92190,1.000
1,1.200,0.00,0.9886,0.98860,1.000
1,1.267,0.00,1.0552,1.05517,1.000
1,1.333,-0.01,1.1220,1.12197,1.000
1,1.400,-0.01,1.1888,1.18880,1.000
1,1.467,0.00,1.2553,1.25527,1.000
1,1.533,0.00,1.3220,1.32197,1.000
1,1.600,-0.01,1.3887,1.38870,1.000
1,1.667,-0.01,1.4552,1.45517,1.000
1,1.733,0.00,1.5218,1.52180,1.000
1,1.800,0.00,1.5887,1.58870,1.000
1,1.867,0.00,1.6553,1.65530,1.000
1,1.933,0.00,1.7219,1.72190,1.000
1,2.000,0.00,1.7887,1.78870,1.000
1,2.067,0.00,1.8551,1.85513,1.000
1,2.133,0.00,1.9219,1.92187,1.000
1,2.200,0.00,1.9888,1.98880,1.000
1,2.267,0.00,2.0553,2.05533,1.000
1,2.333,-0.01,2.1220,2.12203,1.000
1,2.400,-0.01,2.1888,2.18880,1.000
1,2.467,-0.01,2.2553,2.25527,1.000
1,2.533,0.00,2.3220,2.32197,1.000
1,2.600,-0.01,2.3887,2.38870,1.000
1,2.667,0.00,2.4553,2.45533,1.000
1,2.733,-0.01,2.5220,2.52197,1.000
1,2.800,0.00,2.5887,2.58870,1.000
1,2.867,0.00,2.6553,2.65527,1.000
1,2.933,0.00,2.7220,2.72203,1.000
1,3.000,0.00,2.7888,2.78880,1.000
1,3.067,-0.01,2.8553,2.85527,1.000
1,3.133,0.00,2.9220,2.92200,1.000
1,3.200,-0.01,2.9888,2.98880,1.000
1,3.267,0.00,3.0554,3.05537,1.000
1,3.333,-0.01,3.1221,3.12210,1.000
1,3.400,0.00,3.1888,3.18880,1.000
1,3.467,0.00,3.2554,3.25540,1.000
1,3.533,0.00,3.3221,3.32210,1.000
1,3.600,0.00,3.3888,3.38880,1.000
1,3.667,0.00,3.4553,3.45533,1.000
1,3.733,0.00,3.5221,3.52207,1.000
1,3.800,-0.01,3.5887,3.58870,1.000
1,3.867,-0.01,3.6554,3.65540,1.000
1,3.933,0.00,3.7222,3.72220,1.000
1,4.000,-0.01,3.7889,3.78890,1.000
1,4.067,0.00,3.8553,3.85533,1.000
1,4.133,0.00,3.9221,3.92207,1.000
1,4.200,0.01,3.9888,3.98880,1.000
1,4.267,0.00,4.0553,4.05530,1.000
1,4.333,0.01,4.1221,4.12207,1.000
1,4.400,0.01,4.1887,4.18870,1.000
1,4.467,0.01,4.2554,4.25543,1.000
1,4.533,0.01,4.3222,4.32217,1.000
1,4.600,0.03,4.3888,4.38880,1.000
1,4.667,0.03,4.4554,4.45543,1.000
1,4.733,0.07,4.5222,4.52223,1.000
1,4.800,0.12,4.5888,4.58880,1.000
1,4.867,0.19,4.6554,4.65537,1.000
1,4.933,0.28,4.7221,4.72213,1.000
1,5.000,0.40,4.7887,4.78870,1.000
1,5.067,0.55,4.8554,4.85537,1.000
1,5.133,0.72,4.9223,4.92227,1.000
1,5.200,0.93,4.9889,4.98890,1.000
1,5.267,1.16,5.0554,5.05543,1.000
1,5.333,1.42,5.1223,5.12227,1.000
1,5.400,1.71,5.1890,5.18900,1.000
1,5.467,2.04,5.2554,5.25543,1.000
1,5.533,2.38,5.3222,5.32220,1.000
1,5.600,2.77,5.3888,5.38880,1.000
1,5.667,3.19,5.4554,5.45537,1.000
1,5.733,3.63,5.5222,5.52223,1.000
1,5.800,4.12,5.5890,5.58900,1.000
1,5.867,4.64,5.6557,5.65567,1.000
1,6.067,5.44,5.7550,5.75500,1.000
1,6.133,5.37,5.7550,5.75500,1.000
1,6.200,5.33,5.7550,5.75500,1.000
1,6.267,5.29,5.7550,5.75500,1.000
1,6.333,5.25,5.7550,5.75500,1.000
1,6.400,5.23,5.7550,5.75500,1.000
1,6.467,5.21,5.7550,5.75500,1.000
1,6.533,5.19,5.7550,5.75500,1.000
1,6.600,5.17,5.7550,5.75500,1.000
1,6.667,5.15,5.7550,5.75500,1.000
1,6.733,5.14,5.7550,5.75500,1.000
1,6.800,5.12,5.7550,5.75500,1.000
1,6.867,5.12,5.7550,5.75500,1.000
1,6.933,5.10,5.7550,5.75500,1.000
1,7.000,5.09,5.7550,5.75500,1.000
1,7.067,5.08,5.7550,5.75500,1.000
1,7.133,5.07,5.7550,5.75500,1.000
1,7.200,5.07,5.7550,5.75500,1.000
1,7.267,5.06,5.7550,5.75500,1.000
1,7.333,5.05,5.7550,5.75500,1.000
1,7.400,5.05,5.7550,5.75500,1.000
1,7.467,5.04,5.7550,5.75500,1.000
1,7.533,5.03,5.7550,5.75500,1.000
1,7.600,5.02,5.7550,5.75500,1.000
1,7.667,5.02,5.7550,5.75500,1.000
1,7.733,5.01,5.7550,5.75500,1.000
1,7.800,5.01,5.7550,5.75500,1.000
1,7.867,5.00,5.7550,5.75500,1.000
1,7.933,5.00,5.7550,5.75500,1.000
1,8.000,5.00,5.7550,5.75500,1.000
1,8.067,4.99,5.7550,5.75500,1.000
1,8.133,4.98,5.7550,5.75500,1.000
1,8.200,4.98,5.7550,5.75500,1.000
1,8.267,4.97,5.7550,5.75500,1.000
1,8.333,4.97,5.7550,5.75500,1.000
1,8.400,4.97,5.7550,5.75500,1.000
1,8.467,4.96,5.7550,5.75500,1.000
1,8.533,4.96,5.7550,5.75500,1.000
1,8.600,4.96,5.7550,5.75500,1.000
1,8.667,4.95,5.7550,5.75500,1.000
1,8.733,4.95,5.7550,5.75500,1.000
1,8.800,4.95,5.7550,5.75500,1.000
1,8.867,4.94,5.7550,5.75500,1.000
1,8.933,4.94,5.7550,5.75500,1.000
1,9.000,4.93,5.7550,5.75500,1.000
1,9.067,4.93,5.7550,5.75500,1.000
1,9.133,4.93,5.7550,5.75500,1.000
1,9.200,4.93,5.7550,5.75500,1.000
1,9.267,4.92,5.7550,5.75500,1.000
1,9.333,4.92,5.7550,5.75500,1.000
1,9.400,4.92,5.7550,5.75500,1.000
1,9.467,4.92,5.7550,5.75500,1.000
1,9.533,4.91,5.7550,5.75500,1.000
1,9.600,4.91,5.7550,5.75500,1.000
1,9.667,4.91,5.7550,5.75500,1.000
1,9.733,4.91,5.7550,5.75500,1.000
1,9.800,4.91,5.7550,5.75500,1.000
1,9.867,4.90,5.7550,5.75500,1.000
1,9.933,4.90,5.7550,5.75500,1.000
1,10.000,4.90,5.7550,5.75500,1.000
1,10.067,4.89,5.7550,5.75500,1.000