File: calibDATA_loadcell/date_02:15:2018/Instron_02.15.2018/2_5N_0__3mm.s_0_0.txt
""
"Test Method","Radhen_Load_Cntrl_Cmprsn_250N_12-7.msm"
"Sample I. D.","Sample1.mss"
"Specimen Number","45"

"TheCycle_Output ()","_Time (s)","_Load (N)","_Extension (mm)","RealTimeDepth (mm)","CycleNumber ()"

1,0.200,0.01,0.0000,0.00000,1.000
1,0.267,0.01,0.0619,0.06190,1.000
1,0.333,0.02,0.2316,0.23160,1.000
1,0.400,0.01,0.4318,0.43180,1.000
1,0.467,0.02,0.6315,0.63153,1.000
1,0.533,0.01,0.8316,0.83160,1.000
1,0.600,0.02,1.0318,1.03180,1.000
1,0.667,0.01,1.2318,1.23177,1.000
1,0.733,0.01,1.4316,1.43160,1.000
1,0.800,0.01,1.6318,1.63180,1.000
1,0.867,0.02,1.8316,1.83157,1.000
1,0.933,0.02,2.0316,2.03163,1.000
1,1.000,0.02,2.2317,2.23170,1.000
1,1.067,0.04,2.4317,2.43173,1.000
1,1.133,0.17,2.6316,2.63163,1.000
1,1.200,0.49,2.8317,2.83170,1.000
1,1.267,1.09,3.0318,3.03180,1.000
1,1.333,1.94,3.2317,3.23170,1.000
1,1.400,3.08,3.4316,3.43160,1.000
1,1.467,4.54,3.6319,3.63187,1.000
1,1.600,7.82,3.9522,3.95220,1.000
1,1.667,7.96,3.9633,3.96327,1.000
1,1.733,6.71,3.8638,3.86377,1.000
1,1.800,4.60,3.6728,3.67280,1.000
1,1.867,2.95,3.4724,3.47243,1.000
1,1.933,1.76,3.2726,3.27260,1.000
1,2.000,0.92,3.0726,3.07260,1.000
1,2.067,0.38,2.8725,2.87253,1.000
1,2.133,0.09,2.6726,2.67263,1.000
1,2.200,0.01,2.4726,2.47260,1.000
1,2.267,0.01,2.2726,2.27260,1.000
1,2.333,0.01,2.0726,2.07260,1.000
1,2.400,0.01,1.8725,1.87250,1.000
1,2.467,0.01,1.6726,1.67257,1.000
1,2.533,0.01,1.4725,1.47250,1.000
1,2.600,0.01,1.2726,1.27260,1.000
1,2.667,0.01,1.0725,1.07253,1.000
1,2.733,0.01,0.8725,0.87253,1.000
1,2.800,0.01,0.6725,0.67250,1.000
1,2.867,0.01,0.4725,0.47253,1.000
1,2.933,0.01,0.2725,0.27250,1.000
1,3.000,0.01,0.0726,0.07260,1.000
1,3.133,0.01,-0.2410,-0.24103,1.000
1,3.200,0.01,-0.2472,-0.24720,1.000
1,3.267,0.01,-0.1416,-0.14163,1.000
1,3.333,0.01,-0.0185,-0.01850,1.000
1,3.400,0.01,-0.0002,-0.00020,1.000
1,3.467,0.01,-0.0001,-0.00010,1.000
1,3.533,0.01,-0.0001,-0.00010,1.000
1,3.600,0.02,0.0000,0.00000,1.000
1,3.667,0.02,0.0000,0.00000,1.000
1,3.733,0.01,-0.0001,-0.00010,1.000
1,3.800,0.02,0.0000,0.00000,1.000
1,3.867,0.01,0.0000,0.00000,1.000
1,3.933,0.02,0.0000,0.00000,1.000
1,4.000,0.02,0.0000,0.00000,1.000
1,4.067,0.02,0.0000,0.00000,1.000
1,4.133,0.01,0.0000,0.00000,1.000
1,4.200,0.02,0.0000,0.00000,1.000
1,4.267,0.01,0.0000,0.00000,1.000
1,4.333,0.02,0.0000,0.00000,1.000
1,4.400,0.01,0.0000,0.00000,1.000
1,4.467,0.01,0.0000,0.00000,1.000
1,4.533,0.01,0.0000,0.00000,1.000
1,4.600,0.01,0.0000,0.00000,1.000
1,4.667,0.02,0.0000,0.00000,1.000
1,4.733,0.02,0.0000,0.00000,1.000
1,4.800,0.01,0.0000,0.00000,1.000
1,4.867,0.01,0.0000,0.00000,1.000
1,4.933,0.01,0.0000,0.00000,1.000
1,5.000,0.01,0.0000,0.00000,1.000
1,5.067,0.01,0.0000,0.00000,1.000
1,5.133,0.01,0.0000,0.00000,1.000
1,5.200,0.01,0.0000,0.00000,1.000
1,5.267,0.01,0.0000,0.00000,1.000
1,5.333,0.01,0.0000,0.00000,1.000
1,5.400,0.01,0.0000,0.00000,1.000
1,5.467,0.01,0.0000,0.00000,1.000
1,5.533,0.01,0.0000,0.00000,1.000
1,5.600,0.01,0.0000,0.00000,1.000
1,5.667,0.01,0.0000,0.00000,1.000
1,5.733,0.01,0.0000,0.00000,1.000
1,5.800,0.01,0.0000,0.00000,1.000
1,5.867,0.01,0.0000,0.00000,1.000
1,5.933,0.01,0.0000,0.00000,1.000
1,6.000,0.01,0.0000,0.00000,1.000
1,6.067,0.02,0.0000,0.00000,1.000
1,6.200,0.01,0.0000,0.00000,1.000
2,6.467,0.00,0.0999,0.09990,2.000
2,6.533,0.00,0.2886,0.28860,2.000
2,6.600,0.00,0.4886,0.48860,2.000
2,6.667,0.00,0.6885,0.68853,2.000
2,6.733,0.00,0.8886,0.88857,2.000
2,6.800,0.00,1.0886,1.08860,2.000
2,6.867,0.00,1.2886,1.28863,2.000
2,6.933,0.00,1.4886,1.48863,2.000
2,7.000,0.00,1.6889,1.68890,2.000
2,7.067,0.00,1.8886,1.88860,2.000
2,7.133,0.01,2.0887,2.08867,2.000
2,7.200,0.01,2.2886,2.28860,2.000
2,7.267,0.04,2.4887,2.48873,2.000
2,7.333,0.20,2.6886,2.68860,2.000
2,7.400,0.58,2.8887,2.88870,2.000
2,7.467,1.24,3.0887,3.08870,2.000
2,7.533,2.17,3.2887,3.28870,2.000
2,7.600,3.39,3.4886,3.48860,2.000
2,7.667,4.95,3.6888,3.68880,2.000
2,7.800,7.65,3.9380,3.93800,2.000
2,7.867,7.17,3.8994,3.89943,2.000
2,7.933,5.48,3.7498,3.74983,2.000
2,8.000,3.54,3.5495,3.54950,2.000
2,8.067,2.17,3.3496,3.34957,2.000
2,8.133,1.20,3.1497,3.14970,2.000
2,8.200,0.54,2.9497,2.94970,2.000
2,8.267,0.16,2.7494,2.74943,2.000
2,8.333,0.01,2.5497,2.54967,2.000
2,8.400,0.00,2.3496,2.34960,2.000
2,8.467,0.00,2.1496,2.14957,2.000
2,8.533,0.00,1.9495,1.94953,2.000
2,8.600,0.00,1.7496,1.74960,2.000
2,8.667,0.00,1.5494,1.54940,2.000
2,8.733,0.00,1.3495,1.34950,2.000
2,8.800,0.00,1.1496,1.14960,2.000
2,8.867,0.00,0.9494,0.94940,2.000
2,8.933,0.00,0.7496,0.74957,2.000
2,9.000,0.00,0.5495,0.54950,2.000
2,9.067,0.00,0.3494,0.34943,2.000
2,9.133,0.00,0.1495,0.14947,2.000
2,9.200,0.00,-0.0505,-0.05050,2.000
2,9.333,0.00,-0.2607,-0.26067,2.000
2,9.400,0.00,-0.2006,-0.20060,2.000
2,9.467,0.00,-0.0574,-0.05737,2.000
2,9.533,0.00,-0.0001,-0.00007,2.000
2,9.600,0.00,-0.0002,-0.00020,2.000
2,9.667,0.00,-0.0002,-0.00020,2.000
2,9.733,0.00,-0.0002,-0.00020,2.000
2,9.800,0.00,-0.0002,-0.00020,2.000
2,9.867,0.00,-0.0002,-0.00020,2.000
2,9.933,0.00,-0.0002,-0.00020,2.000
2,10.000,0.00,-0.0002,-0.00020,2.000
2,10.067,-0.01,-0.0002,-0.00020,2.000
2,10.133,0.00,-0.0002,-0.00020,2.000
2,10.200,0.00,-0.0002,-0.00020,2.000
2,10.267,0.00,-0.0002,-0.00020,2.000
2,10.333,0.00,-0.0002,-0.00020,2.000
2,10.400,0.00,-0.0002,-0.00020,2.000
2,10.467,0.00,-0.0002,-0.00020,2.000
2,10.533,0.00,-0.0002,-0.00020,2.000
2,10.600,-0.01,-0.0002,-0.00020,2.000
2,10.667,0.00,-0.0002,-0.00020,2.000
2,10.733,0.00,-0.0002,-0.00020,2.000
2,10.800,0.00,-0.0002,-0.00020,2.000
2,10.867,0.00,-0.0002,-0.00020,2.000
2,10.933,0.00,-0.0001,-0.00010,2.000
2,11.000,0.00,-0.0001,-0.00010,2.000
2,11.067,0.00,-0.0001,-0.00010,2.000
2,11.133,0.00,-0.0001,-0.00010,2.000
2,11.200,0.00,-0.0001,-0.00010,2.000
2,11.267,0.00,-0.0001,-0.00010,2.000
2,11.333,0.00,-0.0001,-0.00010,2.000
2,11.400,0.00,-0.0001,-0.00010,2.000
2,11.467,0.00,-0.0001,-0.00010,2.000
2,11.533,0.00,-0.0001,-0.00010,2.000
2,11.600,0.00,-0.0001,-0.00010,2.000
2,11.667,0.00,-0.0001,-0.00010,2.000
2,11.733,0.00,-0.0001,-0.00010,2.000
2,11.800,0.00,-0.0001,-0.00010,2.000
2,11.867,0.00,-0.0001,-0.00010,2.000
2,11.933,0.00,-0.0001,-0.00010,2.000
2,12.000,0.00,-0.0001,-0.00010,2.000
2,12.067,0.00,-0.0001,-0.00010,2.000
2,12.133,0.00,-0.0001,-0.00010,2.000
2,12.200,-0.01,-0.0001,-0.00010,2.000
2,12.267,0.00,-0.0001,-0.00010,2.000
3,12.667,0.00,0.1785,0.17847,3.000
3,12.733,0.00,0.3787,0.37867,3.000
3,12.800,-0.01,0.5785,0.57850,3.000
3,12.867,0.00,0.7787,0.77873,3.000
3,12.933,0.00,0.9786,0.97863,3.000
3,13.000,-0.01,1.1786,1.17860,3.000
3,13.067,-0.01,1.3787,1.37870,3.000
3,13.133,0.00,1.5787,1.57870,3.000
3,13.200,0.01,1.7786,1.77860,3.000
3,13.267,0.00,1.9786,1.97863,3.000
3,13.333,0.00,2.1787,2.17867,3.000
3,13.400,0.02,2.3787,2.37870,3.000
3,13.467,0.08,2.5787,2.57867,3.000
3,13.533,0.34,2.7786,2.77863,3.000
3,13.600,0.83,2.9788,2.97880,3.000
3,13.667,1.60,3.1788,3.17883,3.000
3,13.733,2.67,3.3787,3.37873,3.000
3,13.800,4.05,3.5788,3.57880,3.000
3,13.933,7.33,3.9118,3.91177,3.000
3,14.000,7.63,3.9345,3.93450,3.000
3,14.067,6.54,3.8456,3.84563,3.000
3,14.133,4.53,3.6596,3.65963,3.000
3,14.200,2.87,3.4595,3.45950,3.000
3,14.267,1.69,3.2596,3.25963,3.000
3,14.333,0.87,3.0596,3.05957,3.000
3,14.400,0.34,2.8594,2.85940,3.000
3,14.467,0.06,2.6596,2.65957,3.000
3,14.533,0.00,2.4596,2.45960,3.000
3,14.600,0.00,2.2595,2.25950,3.000
3,14.667,0.00,2.0596,2.05960,3.000
3,14.733,0.00,1.8595,1.85947,3.000
3,14.800,0.00,1.6595,1.65950,3.000
3,14.867,0.00,1.4595,1.45950,3.000
3,14.933,0.00,1.2595,1.25953,3.000
3,15.000,0.00,1.0595,1.05950,3.000
3,15.067,0.00,0.8595,0.85953,3.000
3,15.133,-0.01,0.6595,0.65950,3.000
3,15.200,0.00,0.4596,0.45960,3.000
3,15.267,-0.01,0.2595,0.25950,3.000
3,15.333,-0.01,0.0595,0.05950,3.000
3,15.467,0.00,-0.2469,-0.24693,3.000
3,15.533,0.00,-0.2473,-0.24733,3.000
3,15.600,-0.01,-0.1366,-0.13660,3.000
3,15.667,0.00,-0.0177,-0.01773,3.000
3,15.733,-0.01,-0.0002,-0.00020,3.000
3,15.800,0.00,-0.0002,-0.00020,3.000
3,15.867,0.00,-0.0001,-0.00010,3.000
3,15.933,0.00,-0.0001,-0.00010,3.000
3,16.000,0.00,-0.0001,-0.00010,3.000
3,16.067,0.00,-0.0001,-0.00010,3.000
3,16.133,0.00,-0.0001,-0.00010,3.000
3,16.200,0.00,-0.0001,-0.00010,3.000
3,16.267,0.00,-0.0001,-0.00010,3.000
3,16.333,0.00,-0.0001,-0.00010,3.000
3,16.400,0.00,-0.0001,-0.00010,3.000
3,16.467,0.00,-0.0001,-0.00010,3.000
3,16.533,0.00,-0.0001,-0.00010,3.000
3,16.600,0.00,-0.0001,-0.00010,3.000
3,16.667,0.00,-0.0001,-0.00010,3.000
3,16.733,-0.01,-0.0001,-0.00010,3.000
3,16.800,0.00,-0.0001,-0.00010,3.000
3,16.867,0.00,-0.0001,-0.00010,3.000
3,16.933,0.01,-0.0001,-0.00010,3.000
3,17.000,0.00,-0.0001,-0.00010,3.000
3,17.067,0.00,-0.0001,-0.00010,3.000
3,17.133,0.00,-0.0001,-0.00010,3.000
3,17.200,0.00,-0.0001,-0.00010,3.000
3,17.267,0.00,-0.0001,-0.00010,3.000
3,17.333,0.00,-0.0001,-0.00010,3.000
3,17.400,0.00,-0.0001,-0.00010,3.000
3,17.467,0.00,-0.0001,-0.00010,3.000
3,17.533,0.00,-0.0001,-0.00010,3.000
3,17.600,0.00,-0.0001,-0.00010,3.000
3,17.667,0.00,-0.0001,-0.00010,3.000
3,17.733,0.01,-0.0001,-0.00010,3.000
3,17.800,0.00,-0.0001,-0.00010,3.000
3,17.867,0.00,-0.0001,-0.00010,3.000
3,17.933,0.00,-0.0001,-0.00010,3.000
3,18.000,0.00,-0.0001,-0.00010,3.000
3,18.067,0.00,-0.0001,-0.00010,3.000
3,18.133,0.00,-0.0001,-0.00010,3.000
3,18.200,0.01,-0.0001,-0.00010,3.000
3,18.267,0.00,-0.0001,-0.00010,3.000
3,18.333,0.01,-0.0001,-0.00010,3.000
3,18.400,-0.01,-0.0001,-0.00010,3.000
3,18.533,-0.01,-0.0001,-0.00010,3.000
4,18.800,0.02,0.0412,0.04130,4.000
4,18.867,0.02,0.1935,0.19357,4.000
4,18.933,0.02,0.3936,0.39370,4.000
4,19.000,0.02,0.5937,0.59380,4.000
4,19.067,0.01,0.7937,0.79380,4.000
4,19.133,0.01,0.9936,0.99370,4.000
4,19.200,0.02,1.1937,1.19380,4.000
4,19.267,0.02,1.3937,1.39377,4.000
4,19.333,0.01,1.5936,1.59373,4.000
4,19.400,0.02,1.7936,1.79370,4.000
4,19.467,0.01,1.9937,1.99377,4.000
4,19.533,0.02,2.1936,2.19373,4.000
4,19.600,0.03,2.3937,2.39380,4.000
4,19.667,0.11,2.5937,2.59383,4.000
4,19.733,0.37,2.7936,2.79373,4.000
4,19.800,0.89,2.9938,2.99390,4.000
4,19.867,1.69,3.1938,3.19390,4.000
4,19.933,2.78,3.3936,3.39370,4.000
4,20.000,4.18,3.5937,3.59380,4.000
4,20.200,8.21,3.9830,3.98310,4.000
4,20.267,7.27,3.9112,3.91127,4.000
4,20.333,5.23,3.7346,3.73473,4.000
4,20.400,3.36,3.5346,3.53470,4.000
4,20.467,2.06,3.3346,3.33467,4.000
4,20.533,1.13,3.1346,3.13470,4.000
4,20.600,0.49,2.9347,2.93480,4.000
4,20.667,0.15,2.7346,2.73470,4.000
4,20.733,0.03,2.5346,2.53473,4.000
4,20.800,0.02,2.3345,2.33460,4.000
4,20.867,0.01,2.1346,2.13467,4.000
4,20.933,0.02,1.9344,1.93450,4.000
4,21.000,0.02,1.7346,1.73470,4.000
4,21.067,0.02,1.5345,1.53463,4.000
4,21.133,0.02,1.3345,1.33460,4.000
4,21.200,0.01,1.1345,1.13460,4.000
4,21.267,0.01,0.9345,0.93460,4.000
4,21.333,0.02,0.7345,0.73463,4.000
4,21.400,0.01,0.5344,0.53450,4.000
4,21.467,0.02,0.3345,0.33463,4.000
4,21.533,0.01,0.1345,0.13457,4.000
4,21.600,0.02,-0.0655,-0.06540,4.000
4,21.733,0.02,-0.2757,-0.27557,4.000
4,21.800,0.02,-0.2154,-0.21530,4.000
4,21.867,0.02,-0.0676,-0.06750,4.000
4,21.933,0.02,-0.0007,-0.00057,4.000
4,22.000,0.02,-0.0001,0.00000,4.000
4,22.067,0.01,-0.0001,0.00000,4.000
4,22.133,0.02,-0.0001,0.00000,4.000
4,22.200,0.02,-0.0001,0.00000,4.000
4,22.267,0.01,-0.0001,0.00000,4.000
4,22.333,0.02,-0.0001,0.00000,4.000
4,22.400,0.02,-0.0001,0.00000,4.000
4,22.467,0.02,-0.0001,0.00000,4.000
4,22.533,0.01,-0.0001,0.00000,4.000
4,22.600,0.02,-0.0001,0.00000,4.000
4,22.667,0.02,-0.0001,0.00000,4.000
4,22.733,0.02,-0.0001,0.00000,4.000
4,22.800,0.02,-0.0001,0.00000,4.000
4,22.867,0.01,-0.0001,0.00000,4.000
4,22.933,0.02,-0.0001,0.00000,4.000
4,23.000,0.02,-0.0001,0.00000,4.000
4,23.067,0.02,-0.0001,0.00000,4.000
4,23.133,0.02,-0.0001,0.00000,4.000
4,23.200,0.02,-0.0001,0.00000,4.000
4,23.267,0.02,-0.0001,0.00000,4.000
4,23.333,0.01,-0.0001,0.00000,4.000
4,23.400,0.01,-0.0001,0.00000,4.000
4,23.467,0.02,-0.0001,0.00000,4.000
4,23.533,0.02,-0.0001,0.00000,4.000
4,23.600,0.02,-0.0001,0.00000,4.000
4,23.667,0.02,-0.0001,0.00000,4.000
4,23.733,0.02,-0.0001,0.00000,4.000
4,23.800,0.01,-0.0001,0.00000,4.000
4,23.867,0.01,-0.0001,0.00000,4.000
4,23.933,0.02,-0.0001,0.00000,4.000
4,24.000,0.01,-0.0001,0.00000,4.000
4,24.067,0.02,-0.0001,0.00000,4.000
4,24.133,0.01,-0.0001,0.00000,4.000
4,24.200,0.02,-0.0001,0.00000,4.000
4,24.267,0.02,-0.0001,0.00000,4.000
4,24.333,0.01,-0.0001,0.00000,4.000
4,24.400,0.02,-0.0001,0.00000,4.000
4,24.467,0.02,-0.0001,0.00000,4.000
4,24.533,0.01,-0.0001,0.00000,4.000
4,24.600,0.02,-0.0001,0.00000,4.000
4,24.667,0.01,-0.0001,0.00000,4.000
4,24.800,0.01,-0.0001,0.00000,4.000
5,25.067,0.00,0.1814,0.18140,5.000
5,25.133,0.00,0.3816,0.38163,5.000
5,25.200,0.00,0.5815,0.58150,5.000
5,25.267,-0.01,0.7817,0.78170,5.000
5,25.333,0.00,0.9816,0.98163,5.000
5,25.400,0.00,1.1817,1.18170,5.000
5,25.467,0.00,1.3817,1.38167,5.000
5,25.533,0.00,1.5817,1.58167,5.000
5,25.600,-0.02,1.7816,1.78160,5.000
5,25.667,0.00,1.9817,1.98167,5.000
5,25.733,0.01,2.1817,2.18173,5.000
5,25.800,0.02,2.3816,2.38160,5.000
5,25.867,0.08,2.5817,2.58167,5.000
5,25.933,0.33,2.7817,2.78173,5.000
5,26.000,0.83,2.9818,2.98180,5.000
5,26.067,1.60,3.1818,3.18180,5.000
5,26.133,2.67,3.3817,3.38173,5.000
5,26.200,4.04,3.5818,3.58180,5.000
5,26.400,8.03,3.9708,3.97080,5.000
5,26.467,7.11,3.8992,3.89917,5.000
5,26.533,5.09,3.7227,3.72270,5.000
5,26.600,3.26,3.5225,3.52250,5.000
5,26.667,1.98,3.3226,3.32257,5.000
5,26.733,1.07,3.1226,3.12260,5.000
5,26.800,0.46,2.9227,2.92270,5.000
5,26.867,0.12,2.7225,2.72247,5.000
5,26.933,0.00,2.5226,2.52260,5.000
5,27.000,0.00,2.3226,2.32260,5.000
5,27.067,0.00,2.1225,2.12247,5.000
5,27.133,0.00,1.9225,1.92247,5.000
5,27.200,0.00,1.7227,1.72270,5.000
5,27.267,0.00,1.5225,1.52253,5.000
5,27.333,0.00,1.3226,1.32260,5.000
5,27.400,0.00,1.1227,1.12270,5.000
5,27.467,0.00,0.9225,0.92247,5.000
5,27.533,0.00,0.7225,0.72247,5.000
5,27.600,0.00,0.5225,0.52250,5.000
5,27.667,0.00,0.3225,0.32250,5.000
5,27.733,0.00,0.1225,0.12247,5.000
5,27.800,0.00,-0.0774,-0.07740,5.000
5,27.933,0.00,-0.2878,-0.28777,5.000
5,28.000,0.00,-0.2275,-0.22750,5.000
5,28.067,0.00,-0.0762,-0.07623,5.000
5,28.133,0.00,-0.0017,-0.00170,5.000
5,28.200,0.00,-0.0002,-0.00020,5.000
5,28.267,0.00,-0.0002,-0.00020,5.000
5,28.333,0.00,-0.0002,-0.00017,5.000
5,28.400,0.00,-0.0001,-0.00010,5.000
5,28.467,0.00,-0.0001,-0.00010,5.000
5,28.533,-0.01,-0.0001,-0.00010,5.000
5,28.600,0.00,-0.0001,-0.00010,5.000
5,28.667,0.00,-0.0001,-0.00010,5.000
5,28.733,0.00,-0.0001,-0.00010,5.000
5,28.800,0.00,-0.0001,-0.00010,5.000
5,28.867,0.00,-0.0001,-0.00010,5.000
5,28.933,0.00,-0.0001,-0.00010,5.000
5,29.000,0.00,-0.0001,-0.00010,5.000
5,29.067,-0.01,-0.0001,-0.00010,5.000
5,29.133,0.00,-0.0001,-0.00010,5.000
5,29.200,0.00,-0.0001,-0.00010,5.000
5,29.267,0.00,-0.0001,-0.00010,5.000
5,29.333,0.00,-0.0001,-0.00010,5.000
5,29.400,0.00,-0.0001,-0.00010,5.000
5,29.467,0.00,-0.0001,-0.00010,5.000
5,29.533,0.00,-0.0001,-0.00010,5.000
5,29.600,-0.01,-0.0001,-0.00010,5.000
5,29.667,0.00,-0.0001,-0.00010,5.000
5,29.733,0.00,-0.0001,-0.00010,5.000
5,29.800,-0.01,-0.0001,-0.00010,5.000
5,29.867,0.00,-0.0001,-0.00010,5.000
5,29.933,0.00,-0.0001,-0.00010,5.000
5,30.000,0.00,-0.0001,-0.00010,5.000
5,30.067,0.00,-0.0001,-0.00010,5.000
5,30.133,-0.01,-0.0001,-0.00010,5.000
5,30.200,0.00,-0.0001,-0.00010,5.000
5,30.267,0.00,-0.0001,-0.00010,5.000
5,30.333,0.00,-0.0001,-0.00010,5.000
5,30.400,0.00,-0.0001,-0.00010,5.000
5,30.467,-0.01,-0.0001,-0.00010,5.000
5,30.533,0.00,-0.0001,-0.00010,5.000
5,30.600,0.00,-0.0001,-0.00010,5.000
5,30.667,0.00,-0.0001,-0.00010,5.000
5,30.733,0.00,-0.0001,-0.00010,5.000
5,30.800,0.00,-0.0001,-0.00010,5.000
5,30.867,0.00,-0.0001,-0.00010,5.000
5,31.000,-0.01,-0.0001,-0.00010,5.000
6,31.267,0.01,0.1525,0.15247,6.000
6,31.333,0.02,0.3515,0.35153,6.000
6,31.400,0.02,0.5516,0.55160,6.000
6,31.467,0.02,0.7517,0.75167,6.000
6,31.533,0.02,0.9515,0.95153,6.000
6,31.600,0.02,1.1516,1.15160,6.000
6,31.667,0.02,1.3517,1.35167,6.000
6,31.733,0.02,1.5516,1.55163,6.000
6,31.800,0.02,1.7517,1.75170,6.000
6,31.867,0.02,1.9516,1.95157,6.000
6,31.933,0.03,2.1516,2.15160,6.000
6,32.000,0.03,2.3517,2.35170,6.000
6,32.067,0.08,2.5518,2.55180,6.000
6,32.133,0.30,2.7517,2.75167,6.000
6,32.200,0.75,2.9517,2.95170,6.000
6,32.267,1.49,3.1518,3.15180,6.000
6,32.333,2.51,3.3517,3.35167,6.000
6,32.400,3.82,3.5517,3.55170,6.000
6,32.467,5.49,3.7517,3.75170,6.000
6,32.600,8.02,3.9722,3.97220,6.000
6,32.667,7.33,3.9171,3.91707,6.000
6,32.733,5.42,3.7525,3.75253,6.000
6,32.800,3.50,3.5526,3.55260,6.000
6,32.867,2.16,3.3525,3.35253,6.000
6,32.933,1.19,3.1527,3.15270,6.000
6,33.000,0.55,2.9526,2.95260,6.000
6,33.067,0.18,2.7525,2.75253,6.000
6,33.133,0.03,2.5527,2.55273,6.000
6,33.200,0.01,2.3525,2.35250,6.000
6,33.267,0.01,2.1525,2.15250,6.000
6,33.333,0.02,1.9526,1.95260,6.000
6,33.400,0.02,1.7526,1.75260,6.000
6,33.467,0.02,1.5525,1.55250,6.000
6,33.533,0.01,1.3525,1.35253,6.000
6,33.600,0.02,1.1526,1.15260,6.000
6,33.667,0.02,0.9524,0.95243,6.000
6,33.733,0.02,0.7526,0.75263,6.000
6,33.800,0.02,0.5525,0.55250,6.000
6,33.867,0.02,0.3525,0.35250,6.000
6,33.933,0.02,0.1525,0.15247,6.000
6,34.133,0.02,-0.2576,-0.25763,6.000
6,34.200,0.02,-0.1976,-0.19760,6.000
6,34.267,0.01,-0.0546,-0.05460,6.000
6,34.333,0.02,0.0020,0.00203,6.000
6,34.400,0.02,-0.0001,-0.00010,6.000
6,34.467,0.02,-0.0001,-0.00010,6.000
6,34.533,0.02,-0.0001,-0.00010,6.000
6,34.600,0.02,-0.0001,-0.00010,6.000
6,34.667,0.02,-0.0001,-0.00010,6.000
6,34.733,0.02,-0.0001,-0.00010,6.000
6,34.800,0.02,-0.0001,-0.00010,6.000
6,34.867,0.02,-0.0001,-0.00010,6.000
6,34.933,0.02,-0.0001,-0.00010,6.000
6,35.000,0.02,-0.0001,-0.00010,6.000
6,35.067,0.02,-0.0001,-0.00010,6.000
6,35.133,0.02,-0.0001,-0.00010,6.000
6,35.200,0.01,-0.0001,-0.00010,6.000
6,35.267,0.02,-0.0001,-0.00010,6.000
6,35.333,0.02,-0.0001,-0.00010,6.000
6,35.400,0.02,-0.0001,-0.00010,6.000
6,35.467,0.02,-0.0001,-0.00010,6.000
6,35.533,0.02,-0.0001,-0.00010,6.000
6,35.600,0.01,-0.0001,-0.00010,6.000
6,35.667,0.02,-0.0001,-0.00010,6.000
6,35.733,0.02,-0.0001,-0.00010,6.000
6,35.800,0.02,-0.0001,-0.00010,6.000
6,35.867,0.02,-0.0001,-0.00010,6.000
6,35.933,0.02,-0.0001,-0.00010,6.000
6,36.000,0.02,-0.0001,-0.00010,6.000
6,36.067,0.01,-0.0001,-0.00010,6.000
6,36.133,0.02,-0.0001,-0.00010,6.000
6,36.200,0.02,-0.0001,-0.00010,6.000
6,36.267,0.02,-0.0001,-0.00010,6.000
6,36.333,0.02,-0.0001,-0.00010,6.000
6,36.400,0.02,-0.0001,-0.00010,6.000
6,36.467,0.02,-0.0001,-0.00010,6.000
6,36.533,0.02,-0.0001,-0.00010,6.000
6,36.600,0.02,-0.0001,-0.00010,6.000
6,36.667,0.02,-0.0001,-0.00010,6.000
6,36.733,0.02,-0.0001,-0.00010,6.000
6,36.800,0.02,-0.0001,-0.00010,6.000
6,36.867,0.02,-0.0001,-0.00010,6.000
6,36.933,0.02,-0.0001,-0.00010,6.000
6,37.000,0.02,-0.0001,-0.00010,6.000
6,37.067,0.02,-0.0001,-0.00010,6.000
6,37.200,0.02,-0.0001,-0.00010,6.000
7,37.467,0.01,0.1524,0.15243,7.000
7,37.533,0.01,0.3516,0.35160,7.000
7,37.600,0.01,0.5515,0.55150,7.000
7,37.667,0.01,0.7517,0.75170,7.000
7,37.733,0.01,0.9516,0.95160,7.000
7,37.800,0.01,1.1517,1.15170,7.000
7,37.867,0.00,1.3517,1.35173,7.000
7,37.933,0.01,1.5516,1.55163,7.000
7,38.000,0.00,1.7517,1.75170,7.000
7,38.067,0.00,1.9517,1.95167,7.000
7,38.133,0.01,2.1515,2.15153,7.000
7,38.200,0.02,2.3517,2.35170,7.000
7,38.267,0.07,2.5518,2.55180,7.000
7,38.333,0.29,2.7516,2.75163,7.000
7,38.400,0.75,2.9517,2.95170,7.000
7,38.467,1.49,3.1519,3.15187,7.000
7,38.533,2.50,3.3516,3.35163,7.000
7,38.600,3.83,3.5516,3.55160,7.000
7,38.800,7.67,3.9409,3.94090,7.000
7,38.867,6.79,3.8692,3.86923,7.000
7,38.933,4.85,3.6927,3.69273,7.000
7,39.000,3.09,3.4925,3.49250,7.000
7,39.067,1.86,3.2925,3.29253,7.000
7,39.133,0.98,3.0926,3.09257,7.000
7,39.200,0.41,2.8927,2.89270,7.000
7,39.267,0.10,2.6925,2.69250,7.000
7,39.333,0.01,2.4926,2.49257,7.000
7,39.400,0.01,2.2926,2.29260,7.000
7,39.467,0.00,2.0925,2.09253,7.000
7,39.533,0.01,1.8924,1.89240,7.000
7,39.600,0.01,1.6926,1.69260,7.000
7,39.667,0.01,1.4924,1.49243,7.000
7,39.733,0.00,1.2924,1.29243,7.000
7,39.800,0.01,1.0927,1.09270,7.000
7,39.867,0.01,0.8925,0.89247,7.000
7,39.933,0.01,0.6925,0.69247,7.000
7,40.000,0.00,0.4925,0.49250,7.000
7,40.067,0.00,0.2925,0.29247,7.000
7,40.133,0.01,0.0924,0.09243,7.000
7,40.267,0.00,-0.2343,-0.23430,7.000
7,40.333,0.01,-0.2513,-0.25127,7.000
7,40.400,0.01,-0.1577,-0.15770,7.000
7,40.467,0.00,-0.0260,-0.02600,7.000
7,40.533,0.01,-0.0004,-0.00037,7.000
7,40.600,0.00,-0.0001,-0.00010,7.000
7,40.667,0.01,-0.0001,-0.00010,7.000
7,40.733,0.01,-0.0001,-0.00010,7.000
7,40.800,0.01,-0.0001,-0.00010,7.000
7,40.867,0.01,-0.0001,-0.00010,7.000
7,40.933,0.00,-0.0001,-0.00010,7.000
7,41.000,0.00,-0.0001,-0.00010,7.000
7,41.067,0.01,-0.0001,-0.00010,7.000
7,41.133,0.01,-0.0001,-0.00010,7.000
7,41.200,0.01,-0.0001,-0.00010,7.000
7,41.267,0.01,-0.0001,-0.00010,7.000
7,41.333,0.00,-0.0001,-0.00010,7.000
7,41.400,0.00,-0.0001,-0.00010,7.000
7,41.467,0.00,-0.0001,-0.00010,7.000
7,41.533,0.00,-0.0001,-0.00010,7.000
7,41.600,0.00,-0.0001,-0.00010,7.000
7,41.667,0.00,-0.0001,-0.00010,7.000
7,41.733,0.01,-0.0001,-0.00010,7.000
7,41.800,0.00,-0.0001,-0.00010,7.000
7,41.867,0.00,-0.0001,-0.00010,7.000
7,41.933,0.01,-0.0001,-0.00010,7.000
7,42.000,0.01,-0.0001,-0.00010,7.000
7,42.067,0.01,-0.0001,-0.00010,7.000
7,42.133,0.01,-0.0001,-0.00010,7.000
7,42.200,0.00,-0.0001,-0.00010,7.000
7,42.267,0.01,-0.0001,-0.00010,7.000
7,42.333,0.01,-0.0001,-0.00010,7.000
7,42.400,0.01,-0.0001,-0.00010,7.000
7,42.467,0.01,-0.0001,-0.00010,7.000
7,42.533,0.00,-0.0001,-0.00010,7.000
7,42.600,0.01,-0.0001,-0.00010,7.000
7,42.667,0.01,-0.0001,-0.00010,7.000
7,42.733,0.01,-0.0001,-0.00010,7.000
7,42.800,0.01,-0.0001,-0.00010,7.000
7,42.867,0.01,-0.0001,-0.00010,7.000
7,42.933,0.01,-0.0001,-0.00010,7.000
7,43.000,0.01,-0.0001,-0.00010,7.000
7,43.067,0.01,-0.0001,-0.00010,7.000
7,43.133,0.00,-0.0001,-0.00010,7.000
7,43.200,0.01,-0.0001,-0.00010,7.000
7,43.267,0.01,-0.0001,-0.00010,7.000
8,43.667,0.01,0.1666,0.16657,8.000
8,43.733,0.00,0.3667,0.36667,8.000
8,43.800,0.00,0.5666,0.56660,8.000
8,43.867,0.00,0.7667,0.76673,8.000
8,43.933,0.00,0.9666,0.96663,8.000
8,44.000,0.00,1.1668,1.16680,8.000
8,44.067,0.00,1.3666,1.36663,8.000
8,44.133,0.00,1.5667,1.56667,8.000
8,44.200,0.00,1.7668,1.76680,8.000
8,44.267,0.00,1.9667,1.96667,8.000
8,44.333,0.01,2.1667,2.16667,8.000
8,44.400,0.02,2.3668,2.36680,8.000
8,44.467,0.07,2.5668,2.56677,8.000
8,44.533,0.30,2.7666,2.76660,8.000
8,44.600,0.78,2.9668,2.96680,8.000
8,44.667,1.54,3.1668,3.16683,8.000
8,44.733,2.59,3.3667,3.36667,8.000
8,44.800,3.94,3.5667,3.56670,8.000
8,45.000,8.08,3.9750,3.97500,8.000
8,45.067,7.29,3.9133,3.91327,8.000
8,45.133,5.33,3.7435,3.74353,8.000
8,45.200,3.43,3.5435,3.54350,8.000
8,45.267,2.10,3.3436,3.34357,8.000
8,45.333,1.15,3.1437,3.14367,8.000
8,45.400,0.51,2.9436,2.94360,8.000
8,45.467,0.15,2.7435,2.74353,8.000
8,45.533,0.01,2.5436,2.54360,8.000
8,45.600,0.00,2.3436,2.34360,8.000
8,45.667,0.00,2.1436,2.14357,8.000
8,45.733,0.00,1.9435,1.94347,8.000
8,45.800,0.00,1.7435,1.74350,8.000
8,45.867,0.00,1.5435,1.54347,8.000
8,45.933,0.01,1.3436,1.34357,8.000
8,46.000,0.00,1.1435,1.14350,8.000
8,46.067,0.00,0.9435,0.94350,8.000
8,46.133,0.00,0.7435,0.74353,8.000
8,46.200,0.00,0.5435,0.54350,8.000
8,46.267,0.00,0.3435,0.34350,8.000
8,46.333,0.00,0.1434,0.14343,8.000
8,46.533,0.00,-0.2759,-0.27587,8.000
8,46.600,0.01,-0.2205,-0.22050,8.000
8,46.667,0.00,-0.0733,-0.07333,8.000
8,46.733,0.00,-0.0013,-0.00130,8.000
8,46.800,0.00,-0.0002,-0.00020,8.000
8,46.867,0.00,-0.0002,-0.00020,8.000
8,46.933,0.00,-0.0002,-0.00020,8.000
8,47.000,0.00,-0.0002,-0.00020,8.000
8,47.067,0.00,-0.0002,-0.00020,8.000
8,47.133,0.00,-0.0002,-0.00020,8.000
8,47.200,0.00,-0.0002,-0.00020,8.000
8,47.267,0.00,-0.0002,-0.00020,8.000
8,47.333,0.00,-0.0002,-0.00020,8.000
8,47.400,0.01,-0.0002,-0.00020,8.000
8,47.467,0.00,-0.0002,-0.00020,8.000
8,47.533,0.01,-0.0002,-0.00020,8.000
8,47.600,0.00,-0.0002,-0.00020,8.000
8,47.667,0.00,-0.0001,-0.00010,8.000
8,47.733,0.00,-0.0001,-0.00010,8.000
8,47.800,0.00,-0.0001,-0.00010,8.000
8,47.867,0.00,-0.0001,-0.00010,8.000
8,47.933,0.00,-0.0001,-0.00010,8.000
8,48.000,0.00,-0.0001,-0.00010,8.000
8,48.067,0.00,-0.0001,-0.00010,8.000
8,48.133,0.00,-0.0001,-0.00010,8.000
8,48.200,0.01,-0.0001,-0.00010,8.000
8,48.267,0.00,-0.0001,-0.00010,8.000
8,48.333,0.01,-0.0001,-0.00010,8.000
8,48.400,0.00,-0.0001,-0.00010,8.000
8,48.467,0.00,-0.0001,-0.00010,8.000
8,48.533,0.01,-0.0001,-0.00010,8.000
8,48.600,0.01,-0.0001,-0.00010,8.000
8,48.667,0.01,-0.0001,-0.00010,8.000
8,48.733,0.00,-0.0001,-0.00010,8.000
8,48.800,0.01,-0.0001,-0.00010,8.000
8,48.867,0.00,-0.0001,-0.00010,8.000
8,48.933,0.00,-0.0001,-0.00010,8.000
8,49.000,0.00,-0.0001,-0.00010,8.000
8,49.067,0.00,-0.0001,-0.00010,8.000
8,49.133,0.00,-0.0001,-0.00010,8.000
8,49.200,0.00,-0.0001,-0.00010,8.000
8,49.267,0.00,-0.0001,-0.00010,8.000
8,49.333,0.01,-0.0001,-0.00010,8.000
8,49.400,0.00,-0.0001,-0.00010,8.000
8,49.467,0.00,-0.0001,-0.00010,8.000
9,49.867,-0.01,0.2115,0.21153,9.000
9,49.933,-0.01,0.4117,0.41173,9.000
9,50.000,-0.01,0.6117,0.61170,9.000
9,50.067,-0.01,0.8116,0.81163,9.000
9,50.133,-0.01,1.0117,1.01170,9.000
9,50.200,-0.02,1.2117,1.21170,9.000
9,50.267,-0.01,1.4117,1.41167,9.000
9,50.333,-0.01,1.6117,1.61173,9.000
9,50.400,-0.02,1.8117,1.81170,9.000
9,50.467,-0.01,2.0117,2.01170,9.000
9,50.533,0.00,2.2118,2.21177,9.000
9,50.600,0.01,2.4117,2.41170,9.000
9,50.667,0.09,2.6117,2.61167,9.000
9,50.733,0.37,2.8117,2.81167,9.000
9,50.800,0.91,3.0118,3.01180,9.000
9,50.867,1.73,3.2118,3.21180,9.000
9,50.933,2.85,3.4117,3.41167,9.000
9,51.000,4.28,3.6119,3.61190,9.000
9,51.133,7.47,3.9251,3.92510,9.000
9,51.200,7.56,3.9312,3.93120,9.000
9,51.267,6.29,3.8260,3.82600,9.000
9,51.333,4.24,3.6327,3.63273,9.000
9,51.400,2.65,3.4324,3.43240,9.000
9,51.467,1.54,3.2326,3.23263,9.000
9,51.533,0.76,3.0327,3.03270,9.000
9,51.600,0.27,2.8326,2.83260,9.000
9,51.667,0.03,2.6325,2.63250,9.000
9,51.733,-0.02,2.4326,2.43260,9.000
9,51.800,-0.01,2.2325,2.23250,9.000
9,51.867,-0.01,2.0325,2.03250,9.000
9,51.933,-0.01,1.8325,1.83250,9.000
9,52.000,-0.01,1.6326,1.63260,9.000
9,52.067,-0.01,1.4325,1.43250,9.000
9,52.133,-0.02,1.2326,1.23260,9.000
9,52.200,-0.01,1.0325,1.03250,9.000
9,52.267,-0.02,0.8325,0.83250,9.000
9,52.333,-0.01,0.6325,0.63250,9.000
9,52.400,-0.01,0.4326,0.43260,9.000
9,52.467,-0.01,0.2324,0.23243,9.000
9,52.533,-0.01,0.0325,0.03253,9.000
9,52.667,-0.01,-0.2510,-0.25097,9.000
9,52.733,-0.01,-0.2347,-0.23473,9.000
9,52.800,-0.01,-0.1079,-0.10790,9.000
9,52.867,-0.01,-0.0072,-0.00723,9.000
9,52.933,-0.01,0.0000,-0.00003,9.000
9,53.000,-0.02,-0.0001,-0.00010,9.000
9,53.067,-0.01,-0.0001,-0.00010,9.000
9,53.133,-0.01,-0.0001,-0.00010,9.000
9,53.200,-0.01,-0.0001,-0.00010,9.000
9,53.267,-0.01,-0.0001,-0.00010,9.000
9,53.333,-0.01,-0.0001,-0.00010,9.000
9,53.400,-0.01,-0.0001,-0.00010,9.000
9,53.467,-0.02,-0.0001,-0.00010,9.000
9,53.533,-0.01,-0.0001,-0.00010,9.000
9,53.600,-0.02,-0.0001,-0.00010,9.000
9,53.667,-0.02,-0.0001,-0.00010,9.000
9,53.733,-0.02,-0.0001,-0.00010,9.000
9,53.800,-0.01,-0.0001,-0.00010,9.000
9,53.867,-0.01,-0.0001,-0.00010,9.000
9,53.933,-0.01,-0.0001,-0.00010,9.000
9,54.000,-0.02,-0.0001,-0.00010,9.000
9,54.067,-0.01,-0.0001,-0.00010,9.000
9,54.133,-0.02,-0.0001,-0.00010,9.000
9,54.200,-0.02,-0.0001,-0.00010,9.000
9,54.267,-0.02,-0.0001,-0.00010,9.000
9,54.333,-0.02,-0.0001,-0.00010,9.000
9,54.400,-0.01,-0.0001,-0.00010,9.000
9,54.467,-0.02,-0.0001,-0.00010,9.000
9,54.533,-0.01,-0.0001,-0.00010,9.000
9,54.600,-0.01,-0.0001,-0.00010,9.000
9,54.667,-0.02,-0.0001,-0.00010,9.000
9,54.733,-0.01,-0.0001,-0.00010,9.000
9,54.800,-0.01,-0.0001,-0.00010,9.000
9,54.867,-0.01,-0.0001,-0.00010,9.000
9,54.933,-0.01,-0.0001,-0.00010,9.000
9,55.000,-0.02,-0.0001,-0.00010,9.000
9,55.067,-0.02,-0.0001,-0.00010,9.000
9,55.133,-0.02,-0.0001,-0.00010,9.000
9,55.200,-0.02,-0.0001,-0.00010,9.000
9,55.267,-0.01,-0.0001,-0.00010,9.000
9,55.333,-0.02,-0.0001,-0.00010,9.000
9,55.400,-0.01,-0.0001,-0.00010,9.000
9,55.467,-0.02,-0.0001,-0.00010,9.000
9,55.533,-0.02,-0.0001,-0.00010,9.000
9,55.600,-0.01,-0.0001,-0.00010,9.000
9,55.733,-0.01,-0.0001,-0.00010,9.000
10,56.000,0.00,0.1216,0.12160,10.000
10,56.067,0.00,0.3166,0.31660,10.000
10,56.133,0.00,0.5165,0.51653,10.000
10,56.200,0.01,0.7167,0.71670,10.000
10,56.267,0.00,0.9167,0.91667,10.000
10,56.333,0.00,1.1167,1.11667,10.000
10,56.400,0.00,1.3168,1.31680,10.000
10,56.467,0.00,1.5167,1.51670,10.000
10,56.533,0.00,1.7168,1.71677,10.000
10,56.600,0.00,1.9166,1.91660,10.000
10,56.667,0.01,2.1166,2.11663,10.000
10,56.733,0.02,2.3166,2.31663,10.000
10,56.800,0.05,2.5167,2.51670,10.000
10,56.867,0.23,2.7167,2.71670,10.000
10,56.933,0.63,2.9167,2.91673,10.000
10,57.000,1.32,3.1167,3.11670,10.000
10,57.067,2.29,3.3167,3.31670,10.000
10,57.133,3.57,3.5167,3.51667,10.000
10,57.200,5.19,3.7167,3.71670,10.000
10,57.333,7.87,3.9564,3.95643,10.000
10,57.400,7.32,3.9130,3.91300,10.000
10,57.467,5.53,3.7576,3.75757,10.000
10,57.533,3.57,3.5577,3.55767,10.000
10,57.600,2.19,3.3574,3.35740,10.000
10,57.667,1.21,3.1577,3.15773,10.000
10,57.733,0.55,2.9577,2.95770,10.000
10,57.800,0.17,2.7575,2.75750,10.000
10,57.867,0.02,2.5576,2.55763,10.000
10,57.933,0.00,2.3576,2.35760,10.000
10,58.000,0.00,2.1575,2.15750,10.000
10,58.067,0.00,1.9574,1.95743,10.000
10,58.133,0.00,1.7577,1.75767,10.000
10,58.200,0.00,1.5577,1.55770,10.000
10,58.267,0.00,1.3575,1.35753,10.000
10,58.333,0.00,1.1576,1.15760,10.000
10,58.400,0.00,0.9575,0.95750,10.000
10,58.467,0.00,0.7575,0.75753,10.000
10,58.533,0.00,0.5575,0.55747,10.000
10,58.600,0.01,0.3575,0.35750,10.000
10,58.667,0.00,0.1574,0.15737,10.000
10,58.867,0.00,-0.2422,-0.24223,10.000
10,58.933,0.00,-0.1763,-0.17627,10.000
10,59.000,0.00,-0.0400,-0.04000,10.000
10,59.067,0.00,0.0009,0.00093,10.000
10,59.133,0.00,-0.0001,-0.00010,10.000
10,59.200,0.00,-0.0001,-0.00010,10.000
10,59.267,0.00,-0.0001,-0.00010,10.000
10,59.333,0.00,-0.0001,-0.00010,10.000
10,59.400,0.00,-0.0001,-0.00010,10.000
10,59.467,0.00,-0.0001,-0.00010,10.000
10,59.533,0.00,-0.0001,-0.00010,10.000
10,59.600,0.00,-0.0001,-0.00010,10.000
10,59.667,0.01,-0.0001,-0.00010,10.000
10,59.733,0.00,-0.0001,-0.00010,10.000
10,59.800,0.01,-0.0001,-0.00010,10.000
10,59.867,0.01,-0.0001,-0.00010,10.000
10,59.933,0.00,-0.0001,-0.00010,10.000
10,60.000,0.01,-0.0001,-0.00010,10.000
10,60.067,0.00,-0.0001,-0.00010,10.000
10,60.133,0.00,-0.0001,-0.00010,10.000
10,60.200,0.01,-0.0001,-0.00010,10.000
10,60.267,0.00,-0.0001,-0.00010,10.000
10,60.333,0.00,-0.0001,-0.00010,10.000
10,60.400,0.00,-0.0001,-0.00010,10.000
10,60.467,0.00,-0.0001,-0.00010,10.000
10,60.533,0.00,-0.0001,-0.00010,10.000
10,60.600,0.00,-0.0001,-0.00010,10.000
10,60.667,0.00,-0.0001,-0.00010,10.000
10,60.733,0.00,-0.0001,-0.00010,10.000
10,60.800,0.00,-0.0001,-0.00010,10.000
10,60.867,0.00,-0.0001,-0.00010,10.000
10,60.933,0.01,-0.0001,-0.00010,10.000
10,61.000,0.00,-0.0001,-0.00010,10.000
10,61.067,0.00,-0.0001,-0.00010,10.000
10,61.133,0.00,-0.0001,-0.00010,10.000
10,61.200,0.00,-0.0001,-0.00010,10.000
10,61.267,0.00,-0.0001,-0.00010,10.000
10,61.333,0.00,-0.0001,-0.00010,10.000
10,61.400,0.01,-0.0001,-0.00010,10.000
10,61.467,0.00,-0.0001,-0.00010,10.000
10,61.533,0.00,-0.0001,-0.00010,10.000
10,61.600,0.00,-0.0001,-0.00010,10.000
10,61.667,0.00,-0.0001,-0.00010,10.000
10,61.733,0.00,-0.0001,-0.00010,10.000