File: calibDATA_loadcell/date_14:12:17/black/MTS/radhen_black_0degree.txt
""
"Test Method","Radhen_Load_Cntrl_Cmprsn_250N_12-7.msm"
"Sample I. D.","Sample1.mss"
"Specimen Number","5"

"TheCycle_Output ()","_Time (s)","_Load (N)","_Extension (mm)","RealTimeDepth (mm)","CycleNumber ()"

1,0.250,0.00,0.0277,0.02770,1.000
1,0.400,-0.01,0.1777,0.17770,1.000
1,0.550,-0.01,0.3277,0.32770,1.000
1,0.700,-0.01,0.4776,0.47760,1.000
1,0.850,-0.01,0.6274,0.62740,1.000
1,1.000,0.00,0.7776,0.77760,1.000
1,1.150,0.00,0.9277,0.92770,1.000
1,1.300,-0.01,1.0777,1.07770,1.000
1,1.450,-0.01,1.2275,1.22750,1.000
1,1.600,-0.01,1.3776,1.37760,1.000
1,1.750,0.00,1.5278,1.52780,1.000
1,1.900,0.00,1.6777,1.67770,1.000
1,2.050,-0.01,1.8276,1.82760,1.000
1,2.200,0.00,1.9779,1.97790,1.000
1,2.350,-0.01,2.1278,2.12780,1.000
1,2.500,-0.01,2.2777,2.27770,1.000
1,2.650,0.00,2.4277,2.42770,1.000
1,2.800,0.00,2.5778,2.57780,1.000
1,2.950,0.00,2.7278,2.72780,1.000
1,3.100,0.00,2.8777,2.87770,1.000
1,3.250,0.00,3.0277,3.02770,1.000
1,3.400,0.00,3.1779,3.17790,1.000
1,3.550,-0.01,3.3278,3.32780,1.000
1,3.700,-0.01,3.4777,3.47770,1.000
1,3.850,-0.01,3.6279,3.62790,1.000
1,4.000,0.00,3.7779,3.77790,1.000
1,4.150,0.00,3.9278,3.92780,1.000
1,4.300,-0.01,4.0777,4.07770,1.000
1,4.450,0.00,4.2279,4.22790,1.000
1,4.600,-0.01,4.3780,4.37800,1.000
1,4.750,-0.01,4.5279,4.52790,1.000
1,4.900,-0.01,4.6779,4.67790,1.000
1,5.050,0.00,4.8278,4.82780,1.000
1,5.200,-0.01,4.9780,4.97800,1.000
1,5.350,0.00,5.1278,5.12780,1.000
1,5.500,-0.01,5.2778,5.27780,1.000
1,5.650,-0.01,5.4280,5.42800,1.000
1,5.800,-0.01,5.5780,5.57800,1.000
1,5.950,-0.01,5.7280,5.72800,1.000
1,6.100,-0.01,5.8779,5.87790,1.000
1,6.250,-0.01,6.0278,6.02780,1.000
1,6.400,-0.01,6.1779,6.17790,1.000
1,6.550,-0.01,6.3279,6.32790,1.000
1,6.700,0.00,6.4777,6.47770,1.000
1,6.850,-0.01,6.6281,6.62810,1.000
1,7.000,-0.01,6.7779,6.77790,1.000
1,7.150,-0.01,6.9279,6.92790,1.000
1,7.300,-0.01,7.0778,7.07780,1.000
1,7.450,-0.01,7.2280,7.22800,1.000
1,7.600,-0.01,7.3779,7.37790,1.000
1,7.750,0.00,7.5278,7.52780,1.000
1,7.900,-0.01,7.6779,7.67790,1.000
1,8.050,-0.01,7.8281,7.82810,1.000
1,8.200,-0.01,7.9779,7.97790,1.000
1,8.350,-0.01,8.1280,8.12800,1.000
1,8.500,0.00,8.2780,8.27800,1.000
1,8.650,0.00,8.4280,8.42800,1.000
1,8.800,-0.01,8.5779,8.57790,1.000
1,8.950,-0.01,8.7279,8.72790,1.000
1,9.100,-0.01,8.8779,8.87790,1.000
1,9.250,0.01,9.0280,9.02800,1.000
1,9.400,0.08,9.1780,9.17800,1.000
1,9.550,0.27,9.3279,9.32790,1.000
1,9.700,0.59,9.4780,9.47800,1.000
1,9.850,1.07,9.6280,9.62800,1.000
1,10.000,1.69,9.7780,9.77800,1.000
1,10.150,2.47,9.9279,9.92790,1.000
1,10.300,3.42,10.0779,10.07790,1.000
1,10.450,4.61,10.2281,10.22810,1.000
1,10.600,6.05,10.3781,10.37810,1.000
1,10.750,7.78,10.5278,10.52780,1.000
1,10.900,9.85,10.6780,10.67800,1.000
1,11.050,12.32,10.8279,10.82790,1.000
1,11.200,15.31,10.9779,10.97790,1.000
1,11.350,18.90,11.1279,11.12790,1.000
1,11.500,23.20,11.2780,11.27800,1.000
1,11.650,28.32,11.4281,11.42810,1.000
1,11.800,34.31,11.5779,11.57790,1.000
1,11.950,41.25,11.7278,11.72780,1.000
1,12.100,49.18,11.8780,11.87800,1.000
1,12.300,42.49,11.8407,11.84070,1.000
1,12.450,31.60,11.6906,11.69060,1.000
1,12.600,24.44,11.5406,11.54060,1.000
1,12.750,19.24,11.3910,11.39100,1.000
1,12.900,15.25,11.2407,11.24070,1.000
1,13.050,12.13,11.0907,11.09070,1.000
1,13.200,9.65,10.9406,10.94060,1.000
1,13.350,7.66,10.7907,10.79070,1.000
1,13.500,6.06,10.6407,10.64070,1.000
1,13.650,4.74,10.4904,10.49040,1.000
1,13.800,3.64,10.3408,10.34080,1.000
1,13.950,2.72,10.1908,10.19080,1.000
1,14.100,1.98,10.0406,10.04060,1.000
1,14.250,1.36,9.8903,9.89030,1.000
1,14.400,0.87,9.7405,9.74050,1.000
1,14.550,0.48,9.5906,9.59060,1.000
1,14.700,0.21,9.4405,9.44050,1.000
1,14.850,0.05,9.2902,9.29020,1.000
1,15.000,0.00,9.1406,9.14060,1.000
1,15.150,0.00,8.9905,8.99050,1.000
1,15.300,-0.01,8.8405,8.84050,1.000
1,15.450,0.00,8.6903,8.69030,1.000
1,15.600,-0.01,8.5405,8.54050,1.000
1,15.750,-0.01,8.3903,8.39030,1.000
1,15.900,-0.01,8.2405,8.24050,1.000
1,16.050,-0.01,8.0903,8.09030,1.000
1,16.200,0.00,7.9404,7.94040,1.000
1,16.350,-0.01,7.7904,7.79040,1.000
1,16.500,-0.01,7.6402,7.64020,1.000
1,16.650,0.00,7.4904,7.49040,1.000
1,16.800,0.00,7.3405,7.34050,1.000
1,16.950,-0.01,7.1903,7.19030,1.000
1,17.100,-0.01,7.0403,7.04030,1.000
1,17.250,0.00,6.8903,6.89030,1.000
1,17.400,0.00,6.7404,6.74040,1.000
1,17.550,-0.01,6.5904,6.59040,1.000
1,17.700,0.00,6.4402,6.44020,1.000
1,17.850,-0.01,6.2903,6.29030,1.000
1,18.000,-0.01,6.1403,6.14030,1.000
1,18.150,0.00,5.9902,5.99020,1.000
1,18.300,0.00,5.8400,5.84000,1.000
1,18.450,-0.01,5.6903,5.69030,1.000
1,18.600,0.00,5.5403,5.54030,1.000
1,18.750,-0.01,5.3902,5.39020,1.000
1,18.900,0.00,5.2401,5.24010,1.000
1,19.050,-0.01,5.0902,5.09020,1.000
1,19.200,0.00,4.9403,4.94030,1.000
1,19.350,0.00,4.7901,4.79010,1.000
1,19.500,-0.01,4.6401,4.64010,1.000
1,19.650,0.00,4.4902,4.49020,1.000
1,19.800,0.00,4.3403,4.34030,1.000
1,19.950,-0.01,4.1901,4.19010,1.000
1,20.100,0.00,4.0401,4.04010,1.000
1,20.250,-0.01,3.8902,3.89020,1.000
1,20.400,0.00,3.7403,3.74030,1.000
1,20.550,-0.01,3.5901,3.59010,1.000
1,20.700,0.00,3.4401,3.44010,1.000
1,20.850,0.00,3.2902,3.29020,1.000
1,21.000,-0.01,3.1402,3.14020,1.000
1,21.150,-0.01,2.9901,2.99010,1.000
1,21.300,-0.01,2.8400,2.84000,1.000
1,21.450,-0.01,2.6902,2.69020,1.000
1,21.600,-0.01,2.5401,2.54010,1.000
1,21.750,-0.01,2.3901,2.39010,1.000
1,21.900,-0.01,2.2400,2.24000,1.000
1,22.050,0.00,2.0903,2.09030,1.000
1,22.200,-0.01,1.9401,1.94010,1.000
1,22.350,-0.01,1.7900,1.79000,1.000
1,22.500,-0.01,1.6401,1.64010,1.000
1,22.650,-0.01,1.4902,1.49020,1.000
1,22.800,-0.01,1.3401,1.34010,1.000
1,22.950,-0.01,1.1900,1.19000,1.000
1,23.100,0.00,1.0402,1.04020,1.000
1,23.250,-0.01,0.8901,0.89010,1.000
1,23.400,-0.01,0.7401,0.74010,1.000
1,23.550,-0.01,0.5900,0.59000,1.000
1,23.700,-0.01,0.4402,0.44020,1.000
1,23.850,-0.01,0.2900,0.29000,1.000
1,24.000,-0.01,0.1401,0.14010,1.000
1,24.150,-0.01,-0.0100,-0.01000,1.000
1,24.350,-0.01,-0.0001,-0.00010,1.000
1,24.500,-0.01,-0.0004,-0.00040,1.000
1,24.650,-0.01,-0.0004,-0.00040,1.000
1,24.800,-0.01,-0.0004,-0.00040,1.000
1,24.950,-0.01,-0.0004,-0.00040,1.000
1,25.100,-0.01,-0.0004,-0.00040,1.000
1,25.250,-0.01,-0.0004,-0.00040,1.000
1,25.400,0.00,-0.0004,-0.00040,1.000
1,25.550,-0.01,-0.0004,-0.00040,1.000
1,25.700,-0.01,-0.0004,-0.00040,1.000
1,25.850,-0.01,-0.0004,-0.00040,1.000
1,26.000,-0.01,-0.0003,-0.00030,1.000
1,26.150,-0.01,-0.0003,-0.00030,1.000
1,26.300,-0.01,-0.0003,-0.00030,1.000
1,26.450,-0.01,-0.0003,-0.00030,1.000
1,26.600,-0.01,-0.0003,-0.00030,1.000
1,26.750,-0.01,-0.0003,-0.00030,1.000
1,26.900,-0.01,-0.0003,-0.00030,1.000
1,27.050,-0.01,-0.0003,-0.00030,1.000
1,27.200,-0.01,-0.0003,-0.00030,1.000
1,27.350,0.00,-0.0003,-0.00030,1.000
1,27.500,-0.01,-0.0003,-0.00030,1.000
1,27.650,0.00,-0.0002,-0.00020,1.000
1,27.800,-0.01,-0.0002,-0.00020,1.000
1,27.950,-0.01,-0.0002,-0.00020,1.000
1,28.100,0.00,-0.0002,-0.00020,1.000
2,28.400,0.00,0.0374,0.03750,2.000
2,28.550,0.00,0.1874,0.18750,2.000
2,28.700,0.00,0.3375,0.33760,2.000
2,28.850,0.00,0.4877,0.48780,2.000
2,29.000,-0.01,0.6375,0.63760,2.000
2,29.150,-0.01,0.7875,0.78760,2.000
2,29.300,0.00,0.9376,0.93770,2.000
2,29.450,-0.01,1.0878,1.08790,2.000
2,29.600,0.00,1.2375,1.23760,2.000
2,29.750,-0.01,1.3874,1.38750,2.000
2,29.900,-0.01,1.5376,1.53770,2.000
2,30.050,0.00,1.6877,1.68780,2.000
2,30.200,-0.01,1.8376,1.83770,2.000
2,30.350,-0.01,1.9876,1.98770,2.000
2,30.500,-0.01,2.1377,2.13780,2.000
2,30.650,0.00,2.2876,2.28770,2.000
2,30.800,0.00,2.4376,2.43770,2.000
2,30.950,0.00,2.5877,2.58780,2.000
2,31.100,-0.01,2.7377,2.73780,2.000
2,31.250,-0.01,2.8876,2.88770,2.000
2,31.400,-0.01,3.0377,3.03780,2.000
2,31.550,0.00,3.1878,3.18790,2.000
2,31.700,-0.01,3.3380,3.33810,2.000
2,31.850,-0.01,3.4877,3.48780,2.000
2,32.000,-0.01,3.6376,3.63770,2.000
2,32.150,-0.01,3.7878,3.78790,2.000
2,32.300,-0.01,3.9379,3.93800,2.000
2,32.450,0.00,4.0878,4.08790,2.000
2,32.600,-0.01,4.2377,4.23780,2.000
2,32.750,-0.01,4.3878,4.38790,2.000
2,32.900,-0.01,4.5380,4.53810,2.000
2,33.050,-0.01,4.6878,4.68790,2.000
2,33.200,-0.01,4.8377,4.83780,2.000
2,33.350,-0.01,4.9880,4.98810,2.000
2,33.500,0.00,5.1378,5.13790,2.000
2,33.650,0.00,5.2878,5.28790,2.000
2,33.800,-0.01,5.4377,5.43780,2.000
2,33.950,-0.01,5.5879,5.58800,2.000
2,34.100,-0.01,5.7378,5.73790,2.000
2,34.250,-0.01,5.8878,5.88790,2.000
2,34.400,-0.01,6.0378,6.03790,2.000
2,34.550,-0.01,6.1879,6.18800,2.000
2,34.700,0.00,6.3378,6.33790,2.000
2,34.850,-0.01,6.4878,6.48790,2.000
2,35.000,-0.01,6.6378,6.63790,2.000
2,35.150,-0.01,6.7879,6.78800,2.000
2,35.300,0.00,6.9379,6.93800,2.000
2,35.450,0.00,7.0878,7.08790,2.000
2,35.600,-0.01,7.2377,7.23780,2.000
2,35.750,-0.01,7.3879,7.38800,2.000
2,35.900,-0.01,7.5378,7.53790,2.000
2,36.050,0.00,7.6878,7.68790,2.000
2,36.200,-0.01,7.8379,7.83800,2.000
2,36.350,0.00,7.9879,7.98800,2.000
2,36.500,0.00,8.1380,8.13810,2.000
2,36.650,-0.01,8.2878,8.28790,2.000
2,36.800,-0.01,8.4379,8.43800,2.000
2,36.950,0.00,8.5880,8.58810,2.000
2,37.100,0.00,8.7379,8.73800,2.000
2,37.250,0.00,8.8879,8.88800,2.000
2,37.400,-0.01,9.0380,9.03810,2.000
2,37.550,0.04,9.1881,9.18820,2.000
2,37.700,0.19,9.3379,9.33800,2.000
2,37.850,0.48,9.4879,9.48800,2.000
2,38.000,0.92,9.6380,9.63810,2.000
2,38.150,1.51,9.7881,9.78820,2.000
2,38.300,2.26,9.9379,9.93800,2.000
2,38.450,3.22,10.0879,10.08800,2.000
2,38.600,4.39,10.2381,10.23820,2.000
2,38.750,5.80,10.3881,10.38820,2.000
2,38.900,7.49,10.5379,10.53800,2.000
2,39.050,9.51,10.6878,10.68790,2.000
2,39.200,11.91,10.8380,10.83810,2.000
2,39.350,14.75,10.9879,10.98800,2.000
2,39.500,18.13,11.1379,11.13800,2.000
2,39.650,22.10,11.2879,11.28800,2.000
2,39.800,26.82,11.4381,11.43820,2.000
2,39.950,32.45,11.5880,11.58810,2.000
2,40.100,39.38,11.7378,11.73790,2.000
2,40.250,48.09,11.8878,11.88790,2.000
2,40.450,42.20,11.8506,11.85070,2.000
2,40.600,31.37,11.7007,11.70080,2.000
2,40.750,24.26,11.5508,11.55090,2.000
2,40.900,19.09,11.4007,11.40080,2.000
2,41.050,15.14,11.2507,11.25080,2.000
2,41.200,12.05,11.1007,11.10080,2.000
2,41.350,9.59,10.9507,10.95080,2.000
2,41.500,7.62,10.8006,10.80070,2.000
2,41.650,6.04,10.6504,10.65050,2.000
2,41.800,4.71,10.5006,10.50070,2.000
2,41.950,3.62,10.3507,10.35080,2.000
2,42.100,2.71,10.2006,10.20070,2.000
2,42.250,1.97,10.0504,10.05050,2.000
2,42.400,1.36,9.9005,9.90060,2.000
2,42.550,0.86,9.7506,9.75070,2.000
2,42.700,0.47,9.6005,9.60060,2.000
2,42.850,0.20,9.4504,9.45050,2.000
2,43.000,0.03,9.3003,9.30040,2.000
2,43.150,0.00,9.1506,9.15070,2.000
2,43.300,-0.01,9.0005,9.00060,2.000
2,43.450,0.00,8.8504,8.85050,2.000
2,43.600,0.00,8.7004,8.70050,2.000
2,43.750,-0.01,8.5505,8.55060,2.000
2,43.900,-0.01,8.4002,8.40030,2.000
2,44.050,-0.01,8.2504,8.25050,2.000
2,44.200,-0.01,8.1005,8.10060,2.000
2,44.350,-0.01,7.9504,7.95050,2.000
2,44.500,-0.01,7.8003,7.80040,2.000
2,44.650,0.00,7.6504,7.65050,2.000
2,44.800,-0.01,7.5005,7.50060,2.000
2,44.950,0.00,7.3504,7.35050,2.000
2,45.100,-0.01,7.2001,7.20020,2.000
2,45.250,0.00,7.0503,7.05040,2.000
2,45.400,-0.01,6.9005,6.90060,2.000
2,45.550,-0.01,6.7502,6.75030,2.000
2,45.700,0.00,6.6003,6.60040,2.000
2,45.850,-0.01,6.4503,6.45040,2.000
2,46.000,-0.01,6.3004,6.30050,2.000
2,46.150,-0.01,6.1502,6.15030,2.000
2,46.300,-0.01,6.0000,6.00010,2.000
2,46.450,-0.01,5.8502,5.85030,2.000
2,46.600,0.00,5.7003,5.70040,2.000
2,46.750,-0.01,5.5503,5.55040,2.000
2,46.900,-0.01,5.4002,5.40030,2.000
2,47.050,-0.01,5.2501,5.25020,2.000
2,47.200,0.00,5.1002,5.10030,2.000
2,47.350,-0.01,4.9502,4.95030,2.000
2,47.500,-0.01,4.8000,4.80010,2.000
2,47.650,-0.01,4.6504,4.65050,2.000
2,47.800,0.00,4.5002,4.50030,2.000
2,47.950,-0.01,4.3502,4.35030,2.000
2,48.100,-0.01,4.2000,4.20010,2.000
2,48.250,-0.01,4.0501,4.05020,2.000
2,48.400,-0.01,3.9003,3.90040,2.000
2,48.550,-0.01,3.7502,3.75030,2.000
2,48.700,0.00,3.6000,3.60010,2.000
2,48.850,-0.01,3.4503,3.45040,2.000
2,49.000,-0.01,3.3003,3.30040,2.000
2,49.150,0.00,3.1502,3.15030,2.000
2,49.300,-0.01,3.0001,3.00020,2.000
2,49.450,-0.01,2.8502,2.85030,2.000
2,49.600,-0.01,2.7001,2.70020,2.000
2,49.750,-0.01,2.5500,2.55010,2.000
2,49.900,0.00,2.4001,2.40020,2.000
2,50.050,-0.01,2.2501,2.25020,2.000
2,50.200,-0.01,2.1002,2.10030,2.000
2,50.350,-0.01,1.9500,1.95010,2.000
2,50.500,-0.01,1.8001,1.80020,2.000
2,50.650,0.00,1.6503,1.65040,2.000
2,50.800,0.00,1.5001,1.50020,2.000
2,50.950,0.00,1.3499,1.35000,2.000
2,51.100,-0.01,1.2001,1.20020,2.000
2,51.250,-0.01,1.0501,1.05020,2.000
2,51.400,-0.01,0.9001,0.90020,2.000
2,51.550,-0.01,0.7500,0.75010,2.000
2,51.700,0.00,0.6000,0.60010,2.000
2,51.850,-0.01,0.4502,0.45030,2.000
2,52.000,-0.01,0.3000,0.30010,2.000
2,52.150,-0.01,0.1501,0.15020,2.000
2,52.300,-0.01,0.0000,0.00010,2.000
2,52.500,0.00,-0.0004,-0.00030,2.000
2,52.650,0.00,-0.0004,-0.00030,2.000
2,52.800,-0.01,-0.0004,-0.00030,2.000
2,52.950,-0.01,-0.0004,-0.00030,2.000
2,53.100,0.00,-0.0004,-0.00030,2.000
2,53.250,-0.01,-0.0004,-0.00030,2.000
2,53.400,-0.01,-0.0004,-0.00030,2.000
2,53.550,-0.01,-0.0004,-0.00030,2.000
2,53.700,-0.01,-0.0004,-0.00030,2.000
2,53.850,-0.01,-0.0004,-0.00030,2.000
2,54.000,-0.01,-0.0004,-0.00030,2.000
2,54.150,-0.01,-0.0004,-0.00030,2.000
2,54.300,-0.01,-0.0004,-0.00030,2.000
2,54.450,-0.01,-0.0003,-0.00020,2.000
2,54.600,0.00,-0.0003,-0.00020,2.000
2,54.750,-0.01,-0.0003,-0.00020,2.000
2,54.900,-0.01,-0.0003,-0.00020,2.000
2,55.050,-0.01,-0.0003,-0.00020,2.000
2,55.200,0.00,-0.0003,-0.00020,2.000
2,55.350,0.00,-0.0003,-0.00020,2.000
2,55.550,-0.01,-0.0003,-0.00020,2.000
2,55.700,0.00,-0.0003,-0.00020,2.000
2,55.850,-0.01,-0.0003,-0.00020,2.000
2,56.000,-0.01,-0.0003,-0.00020,2.000
2,56.150,0.00,-0.0002,-0.00010,2.000
2,56.300,-0.01,-0.0002,-0.00010,2.000
3,56.600,0.00,0.0477,0.04780,3.000
3,56.750,0.00,0.1975,0.19760,3.000
3,56.900,0.00,0.3475,0.34760,3.000
3,57.050,0.00,0.4976,0.49770,3.000
3,57.200,0.00,0.6475,0.64760,3.000
3,57.350,0.00,0.7977,0.79780,3.000
3,57.500,0.00,0.9475,0.94760,3.000
3,57.650,0.00,1.0978,1.09790,3.000
3,57.800,0.00,1.2476,1.24770,3.000
3,57.950,0.00,1.3975,1.39760,3.000
3,58.100,0.00,1.5475,1.54760,3.000
3,58.250,0.00,1.6978,1.69790,3.000
3,58.400,0.00,1.8477,1.84780,3.000
3,58.550,0.00,1.9976,1.99770,3.000
3,58.700,0.00,2.1476,2.14770,3.000
3,58.850,0.00,2.2977,2.29780,3.000
3,59.000,0.00,2.4477,2.44780,3.000
3,59.150,0.00,2.5977,2.59780,3.000
3,59.300,0.00,2.7476,2.74770,3.000
3,59.450,0.00,2.8978,2.89790,3.000
3,59.600,0.00,3.0478,3.04790,3.000
3,59.750,0.00,3.1976,3.19770,3.000
3,59.900,0.00,3.3479,3.34800,3.000
3,60.050,0.00,3.4977,3.49780,3.000
3,60.200,0.00,3.6478,3.64790,3.000
3,60.350,0.00,3.7977,3.79780,3.000
3,60.500,0.00,3.9478,3.94790,3.000
3,60.650,0.00,4.0979,4.09800,3.000
3,60.800,0.00,4.2478,4.24790,3.000
3,60.950,0.00,4.3977,4.39780,3.000
3,61.100,0.00,4.5479,4.54800,3.000
3,61.250,0.00,4.6979,4.69800,3.000
3,61.400,0.00,4.8477,4.84780,3.000
3,61.550,0.00,4.9978,4.99790,3.000
3,61.700,-0.01,5.1478,5.14790,3.000
3,61.850,0.00,5.2979,5.29800,3.000
3,62.000,0.00,5.4478,5.44790,3.000
3,62.150,0.00,5.5979,5.59800,3.000
3,62.300,0.00,5.7480,5.74810,3.000
3,62.450,0.00,5.8978,5.89790,3.000
3,62.600,0.00,6.0478,6.04790,3.000
3,62.750,0.00,6.1977,6.19780,3.000
3,62.900,0.00,6.3479,6.34800,3.000
3,63.050,0.00,6.4978,6.49790,3.000
3,63.200,0.00,6.6479,6.64800,3.000
3,63.350,0.00,6.7978,6.79790,3.000
3,63.500,0.00,6.9480,6.94810,3.000
3,63.650,0.00,7.0979,7.09800,3.000
3,63.800,0.00,7.2478,7.24790,3.000
3,63.950,0.00,7.3980,7.39810,3.000
3,64.100,0.00,7.5480,7.54810,3.000
3,64.250,0.00,7.6979,7.69800,3.000
3,64.400,0.00,7.8479,7.84800,3.000
3,64.550,0.00,7.9978,7.99790,3.000
3,64.700,0.00,8.1480,8.14810,3.000
3,64.850,0.00,8.2979,8.29800,3.000
3,65.000,0.00,8.4479,8.44800,3.000
3,65.150,0.00,8.5979,8.59800,3.000
3,65.300,0.00,8.7481,8.74820,3.000
3,65.450,0.00,8.8979,8.89800,3.000
3,65.600,0.00,9.0478,9.04790,3.000
3,65.750,0.05,9.1979,9.19800,3.000
3,65.900,0.20,9.3480,9.34810,3.000
3,66.050,0.49,9.4979,9.49800,3.000
3,66.200,0.94,9.6478,9.64790,3.000
3,66.350,1.53,9.7980,9.79810,3.000
3,66.500,2.29,9.9480,9.94810,3.000
3,66.650,3.25,10.0979,10.09800,3.000
3,66.800,4.42,10.2479,10.24800,3.000
3,66.950,5.82,10.3982,10.39830,3.000
3,67.100,7.51,10.5479,10.54800,3.000
3,67.250,9.54,10.6980,10.69810,3.000
3,67.400,11.95,10.8478,10.84790,3.000
3,67.550,14.80,10.9980,10.99810,3.000
3,67.700,18.16,11.1479,11.14800,3.000
3,67.850,22.12,11.2978,11.29790,3.000
3,68.000,26.79,11.4479,11.44800,3.000
3,68.150,32.35,11.5979,11.59800,3.000
3,68.300,39.15,11.7479,11.74800,3.000
3,68.450,47.82,11.8978,11.89790,3.000
3,68.600,50.89,11.9464,11.94650,3.000
3,68.750,36.34,11.7967,11.79680,3.000
3,68.900,27.71,11.6467,11.64680,3.000
3,69.050,21.66,11.4966,11.49670,3.000
3,69.200,17.13,11.3468,11.34690,3.000
3,69.350,13.60,11.1968,11.19690,3.000
3,69.500,10.84,11.0467,11.04680,3.000
3,69.650,8.65,10.8965,10.89660,3.000
3,69.800,6.87,10.7466,10.74670,3.000
3,69.950,5.43,10.5966,10.59670,3.000
3,70.100,4.21,10.4467,10.44680,3.000
3,70.250,3.21,10.2965,10.29660,3.000
3,70.400,2.38,10.1467,10.14680,3.000
3,70.550,1.70,9.9965,9.99660,3.000
3,70.700,1.15,9.8464,9.84650,3.000
3,70.850,0.69,9.6964,9.69650,3.000
3,71.000,0.36,9.5465,9.54660,3.000
3,71.150,0.12,9.3965,9.39660,3.000
3,71.300,0.00,9.2464,9.24650,3.000
3,71.450,-0.01,9.0965,9.09660,3.000
3,71.600,0.00,8.9465,8.94660,3.000
3,71.750,0.00,8.7966,8.79670,3.000
3,71.900,0.00,8.6464,8.64650,3.000
3,72.050,0.00,8.4964,8.49650,3.000
3,72.200,0.00,8.3464,8.34650,3.000
3,72.350,0.00,8.1965,8.19660,3.000
3,72.500,0.00,8.0462,8.04630,3.000
3,72.650,0.00,7.8964,7.89650,3.000
3,72.800,0.00,7.7464,7.74650,3.000
3,72.950,0.00,7.5964,7.59650,3.000
3,73.100,0.00,7.4463,7.44640,3.000
3,73.250,0.00,7.2963,7.29640,3.000
3,73.400,0.00,7.1464,7.14650,3.000
3,73.550,0.00,6.9963,6.99640,3.000
3,73.700,0.00,6.8462,6.84630,3.000
3,73.850,0.00,6.6963,6.69640,3.000
3,74.000,0.00,6.5463,6.54640,3.000
3,74.150,0.00,6.3962,6.39630,3.000
3,74.300,0.00,6.2462,6.24630,3.000
3,74.450,0.00,6.0962,6.09630,3.000
3,74.600,0.00,5.9462,5.94630,3.000
3,74.750,0.00,5.7962,5.79630,3.000
3,74.900,0.00,5.6462,5.64630,3.000
3,75.050,0.00,5.4963,5.49640,3.000
3,75.200,0.00,5.3462,5.34630,3.000
3,75.350,0.00,5.1960,5.19610,3.000
3,75.500,0.00,5.0460,5.04610,3.000
3,75.650,0.00,4.8963,4.89640,3.000
3,75.800,0.00,4.7462,4.74630,3.000
3,75.950,0.00,4.5963,4.59640,3.000
3,76.100,0.00,4.4461,4.44620,3.000
3,76.250,0.00,4.2963,4.29640,3.000
3,76.400,0.01,4.1461,4.14620,3.000
3,76.550,0.00,3.9961,3.99620,3.000
3,76.700,0.00,3.8462,3.84630,3.000
3,76.850,0.00,3.6963,3.69640,3.000
3,77.000,0.00,3.5461,3.54620,3.000
3,77.150,0.00,3.3961,3.39620,3.000
3,77.300,0.00,3.2461,3.24620,3.000
3,77.450,-0.01,3.0963,3.09640,3.000
3,77.600,0.00,2.9462,2.94630,3.000
3,77.750,0.00,2.7960,2.79610,3.000
3,77.900,0.00,2.6460,2.64610,3.000
3,78.050,0.00,2.4962,2.49630,3.000
3,78.200,0.00,2.3461,2.34620,3.000
3,78.350,0.00,2.1959,2.19600,3.000
3,78.500,0.00,2.0461,2.04620,3.000
3,78.650,0.00,1.8961,1.89620,3.000
3,78.800,0.00,1.7461,1.74620,3.000
3,78.950,0.00,1.5959,1.59600,3.000
3,79.100,0.00,1.4461,1.44620,3.000
3,79.250,0.00,1.2961,1.29620,3.000
3,79.400,0.00,1.1462,1.14630,3.000
3,79.550,0.00,0.9959,0.99600,3.000
3,79.700,0.00,0.8462,0.84630,3.000
3,79.850,0.00,0.6961,0.69620,3.000
3,80.000,0.00,0.5461,0.54620,3.000
3,80.150,0.00,0.3961,0.39620,3.000
3,80.300,0.00,0.2460,0.24610,3.000
3,80.450,0.00,0.0961,0.09620,3.000
3,80.650,0.00,-0.0247,-0.02460,3.000
3,80.800,0.00,-0.0004,-0.00030,3.000
3,80.950,0.00,-0.0004,-0.00030,3.000
3,81.100,0.00,-0.0004,-0.00030,3.000
3,81.250,0.00,-0.0004,-0.00030,3.000
3,81.400,0.00,-0.0004,-0.00030,3.000
3,81.550,0.00,-0.0004,-0.00030,3.000
3,81.700,0.00,-0.0004,-0.00030,3.000
3,81.850,0.00,-0.0004,-0.00030,3.000
3,82.000,0.00,-0.0004,-0.00030,3.000
3,82.150,0.00,-0.0004,-0.00030,3.000
3,82.300,0.00,-0.0004,-0.00030,3.000
3,82.450,0.00,-0.0004,-0.00030,3.000
3,82.600,0.00,-0.0003,-0.00020,3.000
3,82.750,0.00,-0.0003,-0.00020,3.000
3,82.900,-0.01,-0.0003,-0.00020,3.000
3,83.050,0.00,-0.0003,-0.00020,3.000
3,83.200,0.00,-0.0003,-0.00020,3.000
3,83.350,0.00,-0.0003,-0.00020,3.000
3,83.500,0.00,-0.0003,-0.00020,3.000
3,83.700,0.00,-0.0003,-0.00020,3.000
3,83.850,0.00,-0.0003,-0.00020,3.000
3,84.000,0.00,-0.0003,-0.00020,3.000
3,84.150,0.00,-0.0003,-0.00020,3.000
3,84.300,0.00,-0.0003,-0.00020,3.000
3,84.450,0.00,-0.0002,-0.00010,3.000
3,84.600,0.00,-0.0002,-0.00010,3.000
4,84.900,-0.01,0.0875,0.08760,4.000
4,85.050,-0.01,0.2375,0.23760,4.000
4,85.200,-0.01,0.3875,0.38760,4.000
4,85.350,-0.01,0.5377,0.53780,4.000
4,85.500,-0.01,0.6876,0.68770,4.000
4,85.650,-0.01,0.8376,0.83770,4.000
4,85.800,-0.01,0.9875,0.98760,4.000
4,85.950,-0.01,1.1378,1.13790,4.000
4,86.100,-0.01,1.2876,1.28770,4.000
4,86.250,0.00,1.4375,1.43760,4.000
4,86.400,-0.01,1.5876,1.58770,4.000
4,86.550,-0.01,1.7379,1.73800,4.000
4,86.700,-0.01,1.8876,1.88770,4.000
4,86.850,-0.01,2.0376,2.03770,4.000
4,87.000,-0.01,2.1876,2.18770,4.000
4,87.150,-0.01,2.3377,2.33780,4.000
4,87.300,-0.01,2.4876,2.48770,4.000
4,87.450,-0.01,2.6376,2.63770,4.000
4,87.600,-0.01,2.7876,2.78770,4.000
4,87.750,-0.01,2.9377,2.93780,4.000
4,87.900,-0.02,3.0878,3.08790,4.000
4,88.050,-0.01,3.2376,3.23770,4.000
4,88.200,-0.01,3.3879,3.38800,4.000
4,88.350,-0.01,3.5378,3.53790,4.000
4,88.500,-0.01,3.6877,3.68780,4.000
4,88.650,-0.01,3.8377,3.83780,4.000
4,88.800,-0.01,3.9880,3.98810,4.000
4,88.950,-0.01,4.1378,4.13790,4.000
4,89.100,0.00,4.2878,4.28790,4.000
4,89.250,-0.01,4.4377,4.43780,4.000
4,89.400,-0.01,4.5880,4.58810,4.000
4,89.550,-0.01,4.7378,4.73790,4.000
4,89.700,-0.01,4.8878,4.88790,4.000
4,89.850,-0.01,5.0377,5.03780,4.000
4,90.000,-0.01,5.1879,5.18800,4.000
4,90.150,-0.01,5.3378,5.33790,4.000
4,90.300,-0.01,5.4877,5.48780,4.000
4,90.450,-0.02,5.6380,5.63810,4.000
4,90.600,-0.01,5.7879,5.78800,4.000
4,90.750,-0.01,5.9379,5.93800,4.000
4,90.900,-0.01,6.0877,6.08780,4.000
4,91.050,-0.01,6.2378,6.23790,4.000
4,91.200,-0.01,6.3879,6.38800,4.000
4,91.350,-0.01,6.5377,6.53780,4.000
4,91.500,-0.01,6.6878,6.68790,4.000
4,91.650,-0.01,6.8379,6.83800,4.000
4,91.800,-0.01,6.9878,6.98790,4.000
4,91.950,-0.01,7.1378,7.13790,4.000
4,92.100,-0.01,7.2878,7.28790,4.000
4,92.250,-0.01,7.4379,7.43800,4.000
4,92.400,-0.01,7.5880,7.58810,4.000
4,92.550,-0.01,7.7379,7.73800,4.000
4,92.700,-0.01,7.8878,7.88790,4.000
4,92.850,-0.01,8.0378,8.03790,4.000
4,93.000,-0.01,8.1879,8.18800,4.000
4,93.150,-0.01,8.3379,8.33800,4.000
4,93.300,-0.01,8.4877,8.48780,4.000
4,93.450,-0.01,8.6379,8.63800,4.000
4,93.600,-0.01,8.7880,8.78810,4.000
4,93.750,-0.01,8.9379,8.93800,4.000
4,93.900,0.00,9.0879,9.08800,4.000
4,94.050,0.06,9.2380,9.23810,4.000
4,94.200,0.25,9.3881,9.38820,4.000
4,94.350,0.57,9.5379,9.53800,4.000
4,94.500,1.04,9.6880,9.68810,4.000
4,94.650,1.68,9.8381,9.83820,4.000
4,94.800,2.48,9.9879,9.98800,4.000
4,94.950,3.49,10.1379,10.13800,4.000
4,95.100,4.72,10.2879,10.28800,4.000
4,95.250,6.20,10.4382,10.43830,4.000
4,95.400,7.98,10.5878,10.58790,4.000
4,95.550,10.10,10.7378,10.73790,4.000
4,95.700,12.62,10.8879,10.88800,4.000
4,95.850,15.58,11.0380,11.03810,4.000
4,96.000,19.07,11.1879,11.18800,4.000
4,96.150,23.16,11.3378,11.33790,4.000
4,96.300,28.00,11.4880,11.48810,4.000
4,96.450,33.77,11.6379,11.63800,4.000
4,96.600,40.88,11.7878,11.78790,4.000
4,96.750,50.03,11.9378,11.93790,4.000
4,96.950,40.99,11.8586,11.85870,4.000
4,97.100,30.70,11.7087,11.70880,4.000
4,97.250,23.81,11.5588,11.55890,4.000
4,97.400,18.76,11.4088,11.40890,4.000
4,97.550,14.88,11.2585,11.25860,4.000
4,97.700,11.85,11.1088,11.10890,4.000
4,97.850,9.45,10.9587,10.95880,4.000
4,98.000,7.52,10.8085,10.80860,4.000
4,98.150,5.97,10.6584,10.65850,4.000
4,98.300,4.66,10.5087,10.50880,4.000
4,98.450,3.57,10.3587,10.35880,4.000
4,98.600,2.67,10.2086,10.20870,4.000
4,98.750,1.94,10.0584,10.05850,4.000
4,98.900,1.34,9.9085,9.90860,4.000
4,99.050,0.84,9.7585,9.75860,4.000
4,99.200,0.46,9.6085,9.60860,4.000
4,99.350,0.19,9.4585,9.45860,4.000
4,99.500,0.02,9.3084,9.30850,4.000
4,99.650,-0.01,9.1585,9.15860,4.000
4,99.800,-0.01,9.0084,9.00850,4.000
4,99.950,-0.01,8.8584,8.85850,4.000
4,100.100,-0.01,8.7085,8.70860,4.000
4,100.250,-0.01,8.5585,8.55860,4.000
4,100.400,-0.01,8.4084,8.40850,4.000
4,100.550,-0.01,8.2583,8.25840,4.000
4,100.700,-0.01,8.1086,8.10870,4.000
4,100.850,-0.01,7.9583,7.95840,4.000
4,101.000,-0.01,7.8083,7.80840,4.000
4,101.150,-0.01,7.6584,7.65850,4.000
4,101.300,-0.01,7.5084,7.50850,4.000
4,101.450,-0.01,7.3584,7.35850,4.000
4,101.600,-0.01,7.2082,7.20830,4.000
4,101.750,-0.01,7.0584,7.05850,4.000
4,101.900,-0.01,6.9084,6.90850,4.000
4,102.050,-0.01,6.7582,6.75830,4.000
4,102.200,-0.01,6.6083,6.60840,4.000
4,102.350,-0.01,6.4583,6.45840,4.000
4,102.500,-0.01,6.3083,6.30840,4.000
4,102.650,-0.01,6.1582,6.15830,4.000
4,102.800,-0.01,6.0081,6.00820,4.000
4,102.950,-0.01,5.8583,5.85840,4.000
4,103.100,-0.01,5.7083,5.70840,4.000
4,103.250,-0.01,5.5583,5.55840,4.000
4,103.400,-0.01,5.4081,5.40820,4.000
4,103.550,-0.01,5.2582,5.25830,4.000
4,103.700,-0.01,5.1081,5.10820,4.000
4,103.850,-0.01,4.9582,4.95830,4.000
4,104.000,-0.01,4.8080,4.80810,4.000
4,104.150,-0.01,4.6584,4.65850,4.000
4,104.300,-0.01,4.5083,4.50840,4.000
4,104.450,-0.01,4.3582,4.35830,4.000
4,104.600,-0.01,4.2081,4.20820,4.000
4,104.750,-0.01,4.0583,4.05840,4.000
4,104.900,-0.01,3.9083,3.90840,4.000
4,105.050,-0.01,3.7582,3.75830,4.000
4,105.200,-0.01,3.6081,3.60820,4.000
4,105.350,-0.01,3.4582,3.45830,4.000
4,105.500,-0.01,3.3082,3.30830,4.000
4,105.650,-0.01,3.1580,3.15810,4.000
4,105.800,-0.01,3.0082,3.00830,4.000
4,105.950,-0.01,2.8582,2.85830,4.000
4,106.100,-0.01,2.7081,2.70820,4.000
4,106.250,-0.01,2.5579,2.55800,4.000
4,106.400,-0.01,2.4082,2.40830,4.000
4,106.550,-0.01,2.2582,2.25830,4.000
4,106.700,-0.01,2.1082,2.10830,4.000
4,106.850,-0.01,1.9580,1.95810,4.000
4,107.000,-0.01,1.8081,1.80820,4.000
4,107.150,-0.01,1.6583,1.65840,4.000
4,107.300,-0.01,1.5081,1.50820,4.000
4,107.450,-0.01,1.3580,1.35810,4.000
4,107.600,-0.01,1.2081,1.20820,4.000
4,107.750,-0.01,1.0581,1.05820,4.000
4,107.900,-0.01,0.9081,0.90820,4.000
4,108.050,-0.01,0.7579,0.75800,4.000
4,108.200,-0.02,0.6081,0.60820,4.000
4,108.350,-0.01,0.4582,0.45830,4.000
4,108.500,-0.01,0.3079,0.30800,4.000
4,108.650,-0.01,0.1579,0.15800,4.000
4,108.800,-0.01,0.0081,0.00820,4.000
4,109.000,-0.01,-0.0005,-0.00040,4.000
4,109.150,-0.01,-0.0005,-0.00040,4.000
4,109.300,-0.01,-0.0005,-0.00040,4.000
4,109.450,0.00,-0.0005,-0.00040,4.000
4,109.600,-0.01,-0.0005,-0.00040,4.000
4,109.750,-0.01,-0.0004,-0.00030,4.000
4,109.900,-0.01,-0.0004,-0.00030,4.000
4,110.050,-0.01,-0.0004,-0.00030,4.000
4,110.200,-0.01,-0.0004,-0.00030,4.000
4,110.350,-0.01,-0.0004,-0.00030,4.000
4,110.500,-0.01,-0.0004,-0.00030,4.000
4,110.650,-0.01,-0.0004,-0.00030,4.000
4,110.800,-0.01,-0.0004,-0.00030,4.000
4,110.950,-0.01,-0.0004,-0.00030,4.000
4,111.100,-0.01,-0.0003,-0.00020,4.000
4,111.250,-0.01,-0.0003,-0.00020,4.000
4,111.400,-0.01,-0.0003,-0.00020,4.000
4,111.550,-0.01,-0.0003,-0.00020,4.000
4,111.700,-0.01,-0.0003,-0.00020,4.000
4,111.850,-0.02,-0.0003,-0.00020,4.000
4,112.050,-0.01,-0.0003,-0.00020,4.000
4,112.200,-0.01,-0.0003,-0.00020,4.000
4,112.350,-0.01,-0.0003,-0.00020,4.000
4,112.500,-0.01,-0.0003,-0.00020,4.000
4,112.650,-0.01,-0.0003,-0.00020,4.000
4,112.800,-0.01,-0.0002,-0.00010,4.000
5,113.100,0.00,0.0174,0.01750,5.000
5,113.250,0.00,0.1675,0.16760,5.000
5,113.400,0.00,0.3174,0.31750,5.000
5,113.550,0.01,0.4676,0.46770,5.000
5,113.700,0.00,0.6176,0.61770,5.000
5,113.850,0.00,0.7677,0.76780,5.000
5,114.000,0.00,0.9176,0.91770,5.000
5,114.150,0.00,1.0676,1.06770,5.000
5,114.300,0.00,1.2176,1.21770,5.000
5,114.450,0.01,1.3676,1.36770,5.000
5,114.600,0.00,1.5175,1.51760,5.000
5,114.750,0.01,1.6678,1.66790,5.000
5,114.900,0.00,1.8177,1.81780,5.000
5,115.050,0.00,1.9677,1.96780,5.000
5,115.200,0.00,2.1177,2.11780,5.000
5,115.350,0.01,2.2676,2.26770,5.000
5,115.500,0.00,2.4178,2.41790,5.000
5,115.650,0.00,2.5677,2.56780,5.000
5,115.800,0.00,2.7175,2.71760,5.000
5,115.950,0.00,2.8677,2.86780,5.000
5,116.100,0.00,3.0179,3.01800,5.000
5,116.250,0.00,3.1677,3.16780,5.000
5,116.400,0.01,3.3178,3.31790,5.000
5,116.550,0.00,3.4677,3.46780,5.000
5,116.700,0.00,3.6177,3.61780,5.000
5,116.850,0.01,3.7677,3.76780,5.000
5,117.000,0.00,3.9177,3.91780,5.000
5,117.150,0.00,4.0679,4.06800,5.000
5,117.300,0.00,4.2178,4.21790,5.000
5,117.450,0.00,4.3678,4.36790,5.000
5,117.600,0.00,4.5178,4.51790,5.000
5,117.750,0.01,4.6680,4.66810,5.000
5,117.900,0.00,4.8178,4.81790,5.000
5,118.050,0.00,4.9678,4.96790,5.000
5,118.200,0.00,5.1178,5.11790,5.000
5,118.350,0.00,5.2679,5.26800,5.000
5,118.500,0.01,5.4179,5.41800,5.000
5,118.650,0.01,5.5678,5.56790,5.000
5,118.800,0.01,5.7179,5.71800,5.000
5,118.950,0.00,5.8679,5.86800,5.000
5,119.100,0.00,6.0178,6.01790,5.000
5,119.250,0.01,6.1678,6.16790,5.000
5,119.400,0.01,6.3178,6.31790,5.000
5,119.550,0.01,6.4679,6.46800,5.000
5,119.700,0.00,6.6179,6.61800,5.000
5,119.850,0.00,6.7677,6.76780,5.000
5,120.000,0.00,6.9180,6.91810,5.000
5,120.150,0.01,7.0679,7.06800,5.000
5,120.300,0.00,7.2178,7.21790,5.000
5,120.450,0.00,7.3678,7.36790,5.000
5,120.600,0.00,7.5179,7.51800,5.000
5,120.750,0.00,7.6680,7.66810,5.000
5,120.900,0.00,7.8179,7.81800,5.000
5,121.050,0.00,7.9678,7.96790,5.000
5,121.200,0.00,8.1181,8.11820,5.000
5,121.350,0.00,8.2680,8.26810,5.000
5,121.500,0.00,8.4179,8.41800,5.000
5,121.650,0.00,8.5678,8.56790,5.000
5,121.800,0.00,8.7179,8.71800,5.000
5,121.950,0.01,8.8680,8.86810,5.000
5,122.100,0.01,9.0178,9.01790,5.000
5,122.250,0.04,9.1680,9.16810,5.000
5,122.400,0.16,9.3180,9.31810,5.000
5,122.550,0.41,9.4680,9.46810,5.000
5,122.700,0.81,9.6178,9.61790,5.000
5,122.850,1.38,9.7680,9.76810,5.000
5,123.000,2.08,9.9179,9.91800,5.000
5,123.150,2.99,10.0679,10.06800,5.000
5,123.300,4.11,10.2178,10.21790,5.000
5,123.450,5.46,10.3681,10.36820,5.000
5,123.600,7.09,10.5180,10.51810,5.000
5,123.750,9.02,10.6679,10.66800,5.000
5,123.900,11.33,10.8178,10.81790,5.000
5,124.050,14.07,10.9679,10.96800,5.000
5,124.200,17.28,11.1180,11.11810,5.000
5,124.350,21.04,11.2679,11.26800,5.000
5,124.500,25.48,11.4178,11.41790,5.000
5,124.650,30.74,11.5680,11.56810,5.000
5,124.800,37.09,11.7180,11.71810,5.000
5,124.950,45.11,11.8679,11.86800,5.000
5,125.150,49.81,11.9488,11.94890,5.000
5,125.300,35.79,11.7988,11.79890,5.000
5,125.450,27.34,11.6486,11.64870,5.000
5,125.600,21.40,11.4986,11.49870,5.000
5,125.750,16.93,11.3488,11.34890,5.000
5,125.900,13.45,11.1987,11.19880,5.000
5,126.050,10.73,11.0487,11.04880,5.000
5,126.200,8.57,10.8984,10.89850,5.000
5,126.350,6.82,10.7487,10.74880,5.000
5,126.500,5.38,10.5985,10.59860,5.000
5,126.650,4.18,10.4486,10.44870,5.000
5,126.800,3.18,10.2985,10.29860,5.000
5,126.950,2.36,10.1486,10.14870,5.000
5,127.100,1.69,9.9985,9.99860,5.000
5,127.250,1.13,9.8485,9.84860,5.000
5,127.400,0.68,9.6984,9.69850,5.000
5,127.550,0.35,9.5486,9.54870,5.000
5,127.700,0.12,9.3986,9.39870,5.000
5,127.850,0.00,9.2483,9.24840,5.000
5,128.000,0.00,9.0984,9.09850,5.000
5,128.150,0.00,8.9485,8.94860,5.000
5,128.300,0.00,8.7986,8.79870,5.000
5,128.450,0.00,8.6483,8.64840,5.000
5,128.600,0.01,8.4983,8.49840,5.000
5,128.750,0.00,8.3485,8.34860,5.000
5,128.900,0.00,8.1985,8.19860,5.000
5,129.050,0.00,8.0482,8.04830,5.000
5,129.200,0.00,7.8984,7.89850,5.000
5,129.350,0.00,7.7485,7.74860,5.000
5,129.500,0.00,7.5984,7.59850,5.000
5,129.650,0.00,7.4483,7.44840,5.000
5,129.800,0.00,7.2983,7.29840,5.000
5,129.950,0.00,7.1484,7.14850,5.000
5,130.100,0.00,6.9983,6.99840,5.000
5,130.250,0.01,6.8483,6.84840,5.000
5,130.400,0.00,6.6983,6.69840,5.000
5,130.550,0.00,6.5484,6.54850,5.000
5,130.700,0.00,6.3982,6.39830,5.000
5,130.850,0.00,6.2482,6.24830,5.000
5,131.000,0.00,6.0982,6.09830,5.000
5,131.150,0.00,5.9483,5.94840,5.000
5,131.300,0.00,5.7983,5.79840,5.000
5,131.450,0.01,5.6482,5.64830,5.000
5,131.600,0.01,5.4982,5.49830,5.000
5,131.750,0.00,5.3483,5.34840,5.000
5,131.900,0.01,5.1982,5.19830,5.000
5,132.050,0.00,5.0481,5.04820,5.000
5,132.200,0.00,4.8983,4.89840,5.000
5,132.350,0.00,4.7482,4.74830,5.000
5,132.500,0.01,4.5982,4.59830,5.000
5,132.650,0.00,4.4481,4.44820,5.000
5,132.800,0.00,4.2983,4.29840,5.000
5,132.950,0.00,4.1481,4.14820,5.000
5,133.100,0.00,3.9982,3.99830,5.000
5,133.250,0.00,3.8481,3.84820,5.000
5,133.400,0.00,3.6983,3.69840,5.000
5,133.550,0.01,3.5480,3.54810,5.000
5,133.700,0.00,3.3982,3.39830,5.000
5,133.850,0.00,3.2480,3.24810,5.000
5,134.000,0.01,3.0983,3.09840,5.000
5,134.150,0.01,2.9482,2.94830,5.000
5,134.300,0.00,2.7981,2.79820,5.000
5,134.450,0.01,2.6480,2.64810,5.000
5,134.600,0.01,2.4982,2.49830,5.000
5,134.750,0.01,2.3481,2.34820,5.000
5,134.900,0.00,2.1979,2.19800,5.000
5,135.050,0.00,2.0481,2.04820,5.000
5,135.200,0.00,1.8982,1.89830,5.000
5,135.350,0.01,1.7482,1.74830,5.000
5,135.500,0.00,1.5979,1.59800,5.000
5,135.650,0.00,1.4480,1.44810,5.000
5,135.800,0.01,1.2981,1.29820,5.000
5,135.950,0.00,1.1482,1.14830,5.000
5,136.100,0.01,0.9979,0.99800,5.000
5,136.250,0.00,0.8481,0.84820,5.000
5,136.400,0.00,0.6982,0.69830,5.000
5,136.550,0.00,0.5481,0.54820,5.000
5,136.700,0.00,0.3980,0.39810,5.000
5,136.850,0.01,0.2481,0.24820,5.000
5,137.000,0.00,0.0982,0.09830,5.000
5,137.250,0.01,-0.0005,-0.00040,5.000
5,137.400,0.00,-0.0004,-0.00030,5.000
5,137.550,0.00,-0.0004,-0.00030,5.000
5,137.700,0.01,-0.0004,-0.00030,5.000
5,137.850,0.01,-0.0004,-0.00030,5.000
5,138.000,0.01,-0.0004,-0.00030,5.000
5,138.150,0.01,-0.0004,-0.00030,5.000
5,138.300,0.01,-0.0004,-0.00030,5.000
5,138.450,0.01,-0.0004,-0.00030,5.000
5,138.600,0.01,-0.0004,-0.00030,5.000
5,138.750,0.01,-0.0004,-0.00030,5.000
5,138.900,0.01,-0.0004,-0.00030,5.000
5,139.050,0.01,-0.0003,-0.00020,5.000
5,139.200,0.01,-0.0003,-0.00020,5.000
5,139.350,0.01,-0.0003,-0.00020,5.000
5,139.500,0.01,-0.0003,-0.00020,5.000
5,139.650,0.00,-0.0003,-0.00020,5.000
5,139.800,0.01,-0.0003,-0.00020,5.000
5,139.950,0.01,-0.0003,-0.00020,5.000
5,140.100,0.01,-0.0003,-0.00020,5.000
5,140.300,0.01,-0.0003,-0.00020,5.000
5,140.450,0.01,-0.0003,-0.00020,5.000
5,140.600,0.00,-0.0003,-0.00020,5.000
5,140.750,0.01,-0.0003,-0.00020,5.000
5,140.900,0.01,-0.0002,-0.00010,5.000
5,141.050,0.00,-0.0002,-0.00010,5.000
5,141.150,0.01,-0.0002,-0.00010,5.000