File: AIME_journal_files/AIME_data/calibDATA_loadcell/date_02:22:2018/Instron/1N_0_1_0_0.txt
""
"Test Method","Radhen_Load_Cntrl_Cmprsn_250N_12-7.msm"
"Sample I. D.","Sample1.mss"
"Specimen Number","24"

"TheCycle_Output ()","_Time (s)","_Load (N)","_Extension (mm)","RealTimeDepth (mm)","CycleNumber ()"

1,0.312,0.00,0.0710,0.07100,1.000
1,0.438,0.00,0.1960,0.19605,1.000
1,0.562,0.00,0.3212,0.32120,1.000
1,0.688,0.00,0.4462,0.44622,1.000
1,0.812,0.00,0.5711,0.57112,1.000
1,0.938,0.00,0.6960,0.69600,1.000
1,1.062,0.00,0.8212,0.82122,1.000
1,1.188,0.00,0.9461,0.94610,1.000
1,1.312,0.00,1.0712,1.07120,1.000
1,1.438,0.00,1.1963,1.19628,1.000
1,1.562,0.00,1.3212,1.32120,1.000
1,1.688,0.00,1.4463,1.44628,1.000
1,1.812,0.00,1.5713,1.57128,1.000
1,1.938,0.00,1.6962,1.69618,1.000
1,2.062,0.00,1.8212,1.82120,1.000
1,2.188,0.00,1.9462,1.94618,1.000
1,2.312,0.00,2.0712,2.07122,1.000
1,2.438,0.00,2.1963,2.19628,1.000
1,2.562,0.00,2.3212,2.32125,1.000
1,2.688,0.01,2.4464,2.44640,1.000
1,2.812,0.04,2.5712,2.57125,1.000
1,2.938,0.10,2.6962,2.69622,1.000
1,3.062,0.19,2.8212,2.82120,1.000
1,3.188,0.35,2.9462,2.94622,1.000
1,3.312,0.61,3.0713,3.07130,1.000
1,3.438,0.95,3.1962,3.19620,1.000
1,3.625,0.88,3.1744,3.17445,1.000
1,3.750,0.51,3.0496,3.04960,1.000
1,3.875,0.26,2.9246,2.92455,1.000
1,4.000,0.11,2.7996,2.79960,1.000
1,4.125,0.05,2.6744,2.67445,1.000
1,4.250,0.01,2.5494,2.54940,1.000
1,4.375,0.01,2.4246,2.42455,1.000
1,4.500,0.00,2.2995,2.29950,1.000
1,4.625,0.00,2.1745,2.17450,1.000
1,4.750,0.00,2.0495,2.04950,1.000
1,4.875,0.00,1.9245,1.92445,1.000
1,5.000,-0.01,1.7997,1.79970,1.000
1,5.125,0.00,1.6744,1.67445,1.000
1,5.250,0.00,1.5495,1.54950,1.000
1,5.375,0.00,1.4244,1.42440,1.000
1,5.500,0.00,1.2993,1.29930,1.000
1,5.625,0.00,1.1744,1.17435,1.000
1,5.750,0.00,1.0494,1.04940,1.000
1,5.875,0.00,0.9244,0.92445,1.000
1,6.000,0.00,0.7996,0.79960,1.000
1,6.125,0.00,0.6743,0.67430,1.000
1,6.250,0.00,0.5494,0.54940,1.000
1,6.375,0.00,0.4244,0.42435,1.000
1,6.500,0.00,0.2991,0.29910,1.000
1,6.625,0.00,0.1742,0.17425,1.000
1,6.750,0.01,0.0492,0.04920,1.000
1,7.000,0.00,-0.0001,-0.00010,1.000
1,7.125,0.00,-0.0001,-0.00010,1.000
1,7.250,0.00,-0.0001,-0.00010,1.000
1,7.375,0.00,-0.0001,-0.00010,1.000
1,7.500,0.00,-0.0001,-0.00010,1.000
1,7.625,0.00,-0.0001,-0.00010,1.000
1,7.750,0.00,-0.0001,-0.00010,1.000
1,7.875,0.00,-0.0001,-0.00010,1.000
1,8.000,0.00,-0.0001,-0.00010,1.000
1,8.125,0.00,-0.0001,-0.00010,1.000
1,8.250,0.00,-0.0001,-0.00010,1.000
1,8.375,0.00,-0.0001,-0.00010,1.000
1,8.500,0.00,-0.0001,-0.00010,1.000
1,8.625,0.00,-0.0001,-0.00010,1.000
1,8.750,-0.01,-0.0001,-0.00010,1.000
1,8.875,0.00,-0.0001,-0.00010,1.000
1,9.000,0.00,-0.0001,-0.00010,1.000
1,9.125,0.00,-0.0001,-0.00010,1.000
1,9.250,0.00,-0.0001,-0.00010,1.000
1,9.375,0.00,-0.0001,-0.00010,1.000
1,9.500,0.00,-0.0001,-0.00010,1.000
1,9.625,0.00,-0.0001,-0.00010,1.000
1,9.750,0.00,-0.0001,-0.00010,1.000
1,9.875,0.00,-0.0001,-0.00010,1.000
2,10.188,0.01,0.0960,0.09600,2.000
2,10.312,0.01,0.2210,0.22100,2.000
2,10.438,0.01,0.3461,0.34608,2.000
2,10.562,0.01,0.4712,0.47120,2.000
2,10.688,0.01,0.5960,0.59600,2.000
2,10.812,0.01,0.7212,0.72117,2.000
2,10.938,0.01,0.8463,0.84630,2.000
2,11.062,0.01,0.9712,0.97125,2.000
2,11.188,0.02,1.0961,1.09605,2.000
2,11.312,0.01,1.2211,1.22110,2.000
2,11.438,0.01,1.3461,1.34608,2.000
2,11.562,0.01,1.4712,1.47120,2.000
2,11.688,0.01,1.5963,1.59628,2.000
2,11.812,0.01,1.7213,1.72130,2.000
2,11.938,0.01,1.8463,1.84633,2.000
2,12.062,0.01,1.9712,1.97125,2.000
2,12.188,0.01,2.0962,2.09615,2.000
2,12.312,0.01,2.2211,2.22115,2.000
2,12.438,0.01,2.3462,2.34618,2.000
2,12.562,0.03,2.4712,2.47125,2.000
2,12.688,0.06,2.5962,2.59620,2.000
2,12.812,0.11,2.7212,2.72122,2.000
2,12.938,0.22,2.8464,2.84638,2.000
2,13.062,0.41,2.9713,2.97130,2.000
2,13.188,0.68,3.0963,3.09630,2.000
2,13.312,1.03,3.2212,3.22120,2.000
2,13.500,0.81,3.1493,3.14930,2.000
2,13.625,0.47,3.0245,3.02450,2.000
2,13.750,0.24,2.8995,2.89950,2.000
2,13.875,0.10,2.7745,2.77450,2.000
2,14.000,0.05,2.6494,2.64940,2.000
2,14.125,0.03,2.5246,2.52455,2.000
2,14.250,0.02,2.3997,2.39970,2.000
2,14.375,0.01,2.2745,2.27450,2.000
2,14.500,0.01,2.1495,2.14950,2.000
2,14.625,0.01,2.0244,2.02435,2.000
2,14.750,0.01,1.8993,1.89930,2.000
2,14.875,0.01,1.7745,1.77450,2.000
2,15.000,0.01,1.6494,1.64940,2.000
2,15.125,0.01,1.5245,1.52450,2.000
2,15.250,0.01,1.3996,1.39960,2.000
2,15.375,0.01,1.2744,1.27440,2.000
2,15.500,0.01,1.1493,1.14930,2.000
2,15.625,0.01,1.0243,1.02430,2.000
2,15.750,0.01,0.8993,0.89930,2.000
2,15.875,0.01,0.7744,0.77440,2.000
2,16.000,0.01,0.6493,0.64930,2.000
2,16.125,0.01,0.5244,0.52440,2.000
2,16.250,0.01,0.3993,0.39930,2.000
2,16.375,0.01,0.2744,0.27435,2.000
2,16.500,0.01,0.1493,0.14930,2.000
2,16.625,0.01,0.0242,0.02420,2.000
2,16.812,0.01,0.0001,0.00015,2.000
2,16.938,0.01,-0.0001,-0.00010,2.000
2,17.062,0.02,-0.0001,-0.00010,2.000
2,17.188,0.01,-0.0001,-0.00010,2.000
2,17.312,0.02,-0.0001,-0.00010,2.000
2,17.438,0.02,-0.0001,-0.00010,2.000
2,17.562,0.01,-0.0001,-0.00010,2.000
2,17.688,0.01,-0.0001,-0.00010,2.000
2,17.812,0.01,-0.0001,-0.00010,2.000
2,17.938,0.01,-0.0001,-0.00010,2.000
2,18.062,0.01,-0.0001,-0.00010,2.000
2,18.188,0.01,-0.0001,-0.00010,2.000
2,18.312,0.01,-0.0001,-0.00010,2.000
2,18.438,0.01,-0.0001,-0.00010,2.000
2,18.562,0.01,-0.0001,-0.00010,2.000
2,18.688,0.02,-0.0001,-0.00010,2.000
2,18.812,0.01,-0.0001,-0.00010,2.000
2,18.938,0.01,-0.0001,-0.00010,2.000
2,19.062,0.02,-0.0001,-0.00010,2.000
2,19.188,0.01,-0.0001,-0.00010,2.000
2,19.312,0.01,-0.0001,-0.00010,2.000
2,19.438,0.02,-0.0001,-0.00010,2.000
2,19.562,0.01,-0.0001,-0.00010,2.000
2,19.688,0.01,-0.0001,-0.00010,2.000
3,20.000,0.00,0.0574,0.05740,3.000
3,20.125,0.00,0.1824,0.18245,3.000
3,20.250,0.00,0.3077,0.30770,3.000
3,20.375,0.00,0.4327,0.43270,3.000
3,20.500,0.00,0.5576,0.55760,3.000
3,20.625,0.01,0.6826,0.68255,3.000
3,20.750,0.00,0.8078,0.80780,3.000
3,20.875,0.00,0.9326,0.93265,3.000
3,21.000,0.00,1.0575,1.05750,3.000
3,21.125,0.00,1.1826,1.18265,3.000
3,21.250,0.01,1.3076,1.30760,3.000
3,21.375,0.00,1.4326,1.43265,3.000
3,21.500,0.00,1.5577,1.55770,3.000
3,21.625,0.00,1.6828,1.68275,3.000
3,21.750,0.00,1.8079,1.80790,3.000
3,21.875,0.00,1.9327,1.93270,3.000
3,22.000,0.00,2.0578,2.05780,3.000
3,22.125,0.00,2.1826,2.18265,3.000
3,22.250,0.00,2.3078,2.30780,3.000
3,22.375,0.01,2.4329,2.43285,3.000
3,22.500,0.04,2.5577,2.55770,3.000
3,22.625,0.08,2.6828,2.68275,3.000
3,22.750,0.17,2.8079,2.80790,3.000
3,22.875,0.33,2.9328,2.93285,3.000
3,23.000,0.58,3.0577,3.05770,3.000
3,23.125,0.90,3.1827,3.18270,3.000
3,23.375,0.77,3.1434,3.14335,3.000
3,23.500,0.44,3.0185,3.01850,3.000
3,23.625,0.22,2.8936,2.89355,3.000
3,23.750,0.09,2.7685,2.76850,3.000
3,23.875,0.04,2.6435,2.64350,3.000
3,24.000,0.01,2.5185,2.51850,3.000
3,24.125,0.01,2.3935,2.39345,3.000
3,24.250,0.00,2.2683,2.26830,3.000
3,24.375,0.00,2.1434,2.14335,3.000
3,24.500,0.00,2.0183,2.01830,3.000
3,24.625,0.01,1.8934,1.89345,3.000
3,24.750,0.00,1.7685,1.76850,3.000
3,24.875,0.00,1.6435,1.64350,3.000
3,25.000,0.00,1.5185,1.51850,3.000
3,25.125,0.01,1.3934,1.39340,3.000
3,25.250,0.00,1.2683,1.26830,3.000
3,25.375,0.00,1.1433,1.14325,3.000
3,25.500,0.00,1.0183,1.01830,3.000
3,25.625,0.00,0.8934,0.89340,3.000
3,25.750,0.00,0.7685,0.76850,3.000
3,25.875,0.00,0.6432,0.64325,3.000
3,26.000,0.00,0.5184,0.51840,3.000
3,26.125,0.00,0.3934,0.39335,3.000
3,26.250,0.00,0.2683,0.26830,3.000
3,26.375,0.01,0.1432,0.14320,3.000
3,26.500,0.00,0.0182,0.01820,3.000
3,26.688,0.00,0.0006,0.00058,3.000
3,26.812,0.01,-0.0001,-0.00010,3.000
3,26.938,0.00,-0.0001,-0.00010,3.000
3,27.062,0.01,-0.0001,-0.00010,3.000
3,27.188,-0.01,-0.0001,-0.00010,3.000
3,27.312,0.01,-0.0001,-0.00010,3.000
3,27.438,0.00,-0.0001,-0.00010,3.000
3,27.562,0.00,-0.0001,-0.00010,3.000
3,27.688,0.01,-0.0001,-0.00010,3.000
3,27.812,0.01,-0.0001,-0.00010,3.000
3,27.938,0.00,-0.0001,-0.00010,3.000
3,28.062,0.00,-0.0001,-0.00010,3.000
3,28.188,-0.01,-0.0001,-0.00010,3.000
3,28.312,0.01,-0.0001,-0.00010,3.000
3,28.438,0.00,-0.0001,-0.00010,3.000
3,28.562,0.01,-0.0001,-0.00010,3.000
3,28.688,0.00,-0.0001,-0.00010,3.000
3,28.812,0.00,-0.0001,-0.00010,3.000
3,28.938,0.00,-0.0001,-0.00010,3.000
3,29.062,0.00,-0.0001,-0.00010,3.000
3,29.188,0.00,-0.0001,-0.00010,3.000
3,29.312,0.00,-0.0001,-0.00010,3.000
3,29.438,-0.01,-0.0001,-0.00010,3.000
3,29.562,0.01,-0.0001,-0.00010,3.000
4,29.938,0.02,0.1059,0.10595,4.000
4,30.062,0.02,0.2310,0.23100,4.000
4,30.188,0.02,0.3562,0.35617,4.000
4,30.312,0.02,0.4813,0.48127,4.000
4,30.438,0.01,0.6060,0.60602,4.000
4,30.562,0.02,0.7311,0.73115,4.000
4,30.688,0.03,0.8561,0.85615,4.000
4,30.812,0.02,0.9811,0.98112,4.000
4,30.938,0.01,1.1061,1.10607,4.000
4,31.062,0.02,1.2311,1.23112,4.000
4,31.188,0.02,1.3561,1.35612,4.000
4,31.312,0.02,1.4813,1.48130,4.000
4,31.438,0.01,1.6063,1.60635,4.000
4,31.562,0.02,1.7313,1.73127,4.000
4,31.688,0.02,1.8562,1.85617,4.000
4,31.812,0.02,1.9810,1.98105,4.000
4,31.938,0.02,2.1062,2.10617,4.000
4,32.062,0.02,2.2312,2.23122,4.000
4,32.188,0.03,2.3563,2.35625,4.000
4,32.312,0.04,2.4813,2.48132,4.000
4,32.438,0.08,2.6063,2.60628,4.000
4,32.562,0.13,2.7313,2.73130,4.000
4,32.688,0.24,2.8562,2.85623,4.000
4,32.812,0.41,2.9813,2.98135,4.000
4,32.938,0.71,3.1062,3.10615,4.000
4,33.062,1.07,3.2312,3.23122,4.000
4,33.250,0.84,3.1595,3.15950,4.000
4,33.375,0.49,3.0345,3.03450,4.000
4,33.500,0.26,2.9095,2.90950,4.000
4,33.625,0.11,2.7845,2.78445,4.000
4,33.750,0.05,2.6593,2.65930,4.000
4,33.875,0.04,2.5345,2.53450,4.000
4,34.000,0.03,2.4095,2.40950,4.000
4,34.125,0.01,2.2846,2.28455,4.000
4,34.250,0.01,2.1596,2.15960,4.000
4,34.375,0.02,2.0344,2.03440,4.000
4,34.500,0.02,1.9095,1.90950,4.000
4,34.625,0.02,1.7845,1.78450,4.000
4,34.750,0.02,1.6594,1.65940,4.000
4,34.875,0.02,1.5345,1.53450,4.000
4,35.000,0.02,1.4095,1.40950,4.000
4,35.125,0.02,1.2844,1.28440,4.000
4,35.250,0.01,1.1595,1.15950,4.000
4,35.375,0.01,1.0344,1.03440,4.000
4,35.500,0.01,0.9093,0.90930,4.000
4,35.625,0.02,0.7844,0.78440,4.000
4,35.750,0.01,0.6592,0.65920,4.000
4,35.875,0.02,0.5343,0.53430,4.000
4,36.000,0.01,0.4094,0.40940,4.000
4,36.125,0.01,0.2844,0.28435,4.000
4,36.250,0.01,0.1592,0.15920,4.000
4,36.375,0.02,0.0343,0.03430,4.000
4,36.562,0.01,-0.0001,-0.00010,4.000
4,36.688,0.02,-0.0001,-0.00010,4.000
4,36.812,0.02,-0.0001,-0.00010,4.000
4,36.938,0.01,-0.0001,-0.00010,4.000
4,37.062,0.02,-0.0001,-0.00010,4.000
4,37.188,0.02,-0.0001,-0.00010,4.000
4,37.312,0.01,-0.0001,-0.00010,4.000
4,37.438,0.01,-0.0001,-0.00010,4.000
4,37.562,0.01,-0.0001,-0.00010,4.000
4,37.688,0.01,-0.0001,-0.00010,4.000
4,37.812,0.01,-0.0001,-0.00010,4.000
4,37.938,0.02,-0.0001,-0.00010,4.000
4,38.062,0.01,-0.0001,-0.00010,4.000
4,38.188,0.03,-0.0001,-0.00010,4.000
4,38.312,0.02,-0.0001,-0.00010,4.000
4,38.438,0.02,-0.0001,-0.00010,4.000
4,38.562,0.01,-0.0001,-0.00010,4.000
4,38.688,0.02,-0.0001,-0.00010,4.000
4,38.812,0.02,-0.0001,-0.00010,4.000
4,38.938,0.01,-0.0001,-0.00010,4.000
4,39.062,0.01,-0.0001,-0.00010,4.000
4,39.188,0.02,-0.0001,-0.00010,4.000
4,39.312,0.02,-0.0001,-0.00010,4.000
4,39.438,0.02,-0.0001,-0.00010,4.000
5,39.812,0.02,0.0810,0.08102,5.000
5,39.938,0.03,0.2061,0.20608,5.000
5,40.062,0.02,0.3311,0.33115,5.000
5,40.188,0.02,0.4561,0.45608,5.000
5,40.312,0.02,0.5809,0.58092,5.000
5,40.438,0.02,0.7060,0.70600,5.000
5,40.562,0.02,0.8311,0.83115,5.000
5,40.688,0.02,0.9562,0.95615,5.000
5,40.812,0.02,1.0811,1.08112,5.000
5,40.938,0.03,1.2063,1.20628,5.000
5,41.062,0.02,1.3312,1.33122,5.000
5,41.188,0.02,1.4562,1.45615,5.000
5,41.312,0.02,1.5811,1.58112,5.000
5,41.438,0.02,1.7062,1.70618,5.000
5,41.562,0.02,1.8312,1.83125,5.000
5,41.688,0.03,1.9563,1.95625,5.000
5,41.812,0.03,2.0813,2.08130,5.000
5,41.938,0.02,2.2063,2.20630,5.000
5,42.062,0.02,2.3313,2.33132,5.000
5,42.188,0.04,2.4564,2.45638,5.000
5,42.312,0.07,2.5812,2.58117,5.000
5,42.438,0.12,2.7062,2.70620,5.000
5,42.562,0.22,2.8312,2.83120,5.000
5,42.688,0.39,2.9563,2.95628,5.000
5,42.812,0.66,3.0813,3.08130,5.000
5,42.938,1.00,3.2064,3.20638,5.000
5,43.125,0.81,3.1444,3.14435,5.000
5,43.250,0.47,3.0196,3.01960,5.000
5,43.375,0.25,2.8946,2.89455,5.000
5,43.500,0.11,2.7696,2.76960,5.000
5,43.625,0.05,2.6444,2.64445,5.000
5,43.750,0.04,2.5195,2.51950,5.000
5,43.875,0.03,2.3945,2.39450,5.000
5,44.000,0.02,2.2693,2.26930,5.000
5,44.125,0.02,2.1444,2.14445,5.000
5,44.250,0.02,2.0193,2.01930,5.000
5,44.375,0.02,1.8944,1.89440,5.000
5,44.500,0.03,1.7695,1.76950,5.000
5,44.625,0.02,1.6444,1.64445,5.000
5,44.750,0.02,1.5196,1.51960,5.000
5,44.875,0.02,1.3944,1.39440,5.000
5,45.000,0.02,1.2694,1.26940,5.000
5,45.125,0.02,1.1443,1.14430,5.000
5,45.250,0.02,1.0193,1.01930,5.000
5,45.375,0.02,0.8944,0.89440,5.000
5,45.500,0.02,0.7695,0.76950,5.000
5,45.625,0.02,0.6442,0.64425,5.000
5,45.750,0.03,0.5194,0.51940,5.000
5,45.875,0.02,0.3944,0.39435,5.000
5,46.000,0.03,0.2693,0.26930,5.000
5,46.125,0.02,0.1442,0.14420,5.000
5,46.250,0.03,0.0191,0.01910,5.000
5,46.438,0.02,-0.0001,-0.00010,5.000
5,46.562,0.02,-0.0001,-0.00010,5.000
5,46.688,0.02,-0.0001,-0.00010,5.000
5,46.812,0.03,-0.0001,-0.00010,5.000
5,46.938,0.02,-0.0001,-0.00010,5.000
5,47.062,0.02,-0.0001,-0.00010,5.000
5,47.188,0.02,-0.0001,-0.00010,5.000
5,47.312,0.02,-0.0001,-0.00010,5.000
5,47.438,0.02,-0.0001,-0.00010,5.000
5,47.562,0.02,-0.0001,-0.00010,5.000
5,47.688,0.02,-0.0001,-0.00010,5.000
5,47.812,0.02,-0.0001,-0.00010,5.000
5,47.938,0.02,-0.0001,-0.00010,5.000
5,48.062,0.02,-0.0001,-0.00010,5.000
5,48.188,0.02,-0.0001,-0.00010,5.000
5,48.312,0.02,-0.0001,-0.00010,5.000
5,48.438,0.02,-0.0001,-0.00010,5.000
5,48.562,0.02,-0.0001,-0.00010,5.000
5,48.688,0.02,-0.0001,-0.00010,5.000
5,48.812,0.02,-0.0001,-0.00010,5.000
5,48.938,0.02,-0.0001,-0.00010,5.000
5,49.062,0.03,-0.0001,-0.00010,5.000
5,49.188,0.02,-0.0001,-0.00010,5.000
5,49.312,0.02,-0.0001,-0.00010,5.000
6,49.688,0.00,0.1150,0.11500,6.000
6,49.812,0.00,0.2401,0.24010,6.000
6,49.938,0.00,0.3653,0.36528,6.000
6,50.062,0.00,0.4902,0.49017,6.000
6,50.188,-0.01,0.6149,0.61488,6.000
6,50.312,-0.01,0.7400,0.74002,6.000
6,50.438,0.00,0.8652,0.86518,6.000
6,50.562,0.00,0.9901,0.99012,6.000
6,50.688,-0.01,1.1152,1.11518,6.000
6,50.812,0.00,1.2401,1.24015,6.000
6,50.938,0.00,1.3652,1.36520,6.000
6,51.062,0.00,1.4902,1.49025,6.000
6,51.188,0.00,1.6152,1.61518,6.000
6,51.312,0.00,1.7402,1.74020,6.000
6,51.438,0.00,1.8652,1.86520,6.000
6,51.562,0.00,1.9901,1.99015,6.000
6,51.688,0.00,2.1152,2.11518,6.000
6,51.812,0.00,2.2402,2.24022,6.000
6,51.938,0.00,2.3654,2.36535,6.000
6,52.062,0.02,2.4903,2.49030,6.000
6,52.188,0.05,2.6152,2.61515,6.000
6,52.312,0.12,2.7402,2.74017,6.000
6,52.438,0.23,2.8652,2.86515,6.000
6,52.562,0.44,2.9902,2.99022,6.000
6,52.688,0.72,3.1152,3.11518,6.000
6,52.875,1.20,3.2567,3.25665,6.000
6,53.000,0.75,3.1364,3.13640,6.000
6,53.125,0.43,3.0116,3.01160,6.000
6,53.250,0.22,2.8865,2.88650,6.000
6,53.375,0.09,2.7616,2.76160,6.000
6,53.500,0.03,2.6365,2.63650,6.000
6,53.625,0.01,2.5115,2.51145,6.000
6,53.750,0.01,2.3864,2.38640,6.000
6,53.875,0.00,2.2614,2.26135,6.000
6,54.000,0.00,2.1365,2.13650,6.000
6,54.125,0.00,2.0115,2.01145,6.000
6,54.250,0.00,1.8865,1.88650,6.000
6,54.375,0.00,1.7616,1.76155,6.000
6,54.500,0.00,1.6365,1.63650,6.000
6,54.625,0.00,1.5114,1.51140,6.000
6,54.750,0.00,1.3863,1.38630,6.000
6,54.875,0.00,1.2613,1.26130,6.000
6,55.000,0.00,1.1364,1.13640,6.000
6,55.125,0.00,1.0114,1.01135,6.000
6,55.250,0.00,0.8865,0.88650,6.000
6,55.375,0.00,0.7615,0.76145,6.000
6,55.500,-0.01,0.6362,0.63620,6.000
6,55.625,0.00,0.5114,0.51135,6.000
6,55.750,0.00,0.3863,0.38630,6.000
6,55.875,0.00,0.2613,0.26125,6.000
6,56.000,-0.01,0.1362,0.13620,6.000
6,56.125,0.00,0.0113,0.01130,6.000
6,56.312,0.00,-0.0002,-0.00018,6.000
6,56.438,0.00,-0.0001,-0.00010,6.000
6,56.562,0.00,-0.0001,-0.00010,6.000
6,56.688,0.00,-0.0001,-0.00010,6.000
6,56.812,0.00,-0.0001,-0.00010,6.000
6,56.938,0.00,-0.0001,-0.00010,6.000
6,57.062,0.00,-0.0001,-0.00010,6.000
6,57.188,0.00,-0.0001,-0.00010,6.000
6,57.312,0.01,-0.0001,-0.00010,6.000
6,57.438,0.00,-0.0001,-0.00010,6.000
6,57.562,0.00,-0.0001,-0.00010,6.000
6,57.688,0.00,-0.0001,-0.00010,6.000
6,57.812,0.00,-0.0001,-0.00010,6.000
6,57.938,0.00,-0.0001,-0.00010,6.000
6,58.062,0.00,-0.0001,-0.00010,6.000
6,58.188,0.00,-0.0001,-0.00010,6.000
6,58.312,0.00,-0.0001,-0.00010,6.000
6,58.438,0.00,-0.0001,-0.00010,6.000
6,58.562,-0.01,-0.0001,-0.00010,6.000
6,58.688,0.00,-0.0001,-0.00010,6.000
6,58.812,0.00,-0.0001,-0.00010,6.000
6,58.938,0.00,-0.0001,-0.00010,6.000
6,59.062,-0.01,-0.0001,-0.00010,6.000
6,59.188,0.00,-0.0001,-0.00010,6.000
7,59.562,-0.01,0.1300,0.12997,7.000
7,59.688,0.00,0.2550,0.25498,7.000
7,59.812,0.00,0.3800,0.38005,7.000
7,59.938,0.00,0.5051,0.50510,7.000
7,60.062,0.00,0.6300,0.63000,7.000
7,60.188,0.00,0.7552,0.75518,7.000
7,60.312,0.00,0.8802,0.88022,7.000
7,60.438,0.00,1.0052,1.00520,7.000
7,60.562,0.00,1.1302,1.13025,7.000
7,60.688,0.00,1.2551,1.25508,7.000
7,60.812,0.00,1.3801,1.38010,7.000
7,60.938,-0.01,1.5052,1.50518,7.000
7,61.062,0.00,1.6301,1.63012,7.000
7,61.188,0.00,1.7553,1.75528,7.000
7,61.312,-0.01,1.8803,1.88035,7.000
7,61.438,-0.02,2.0053,2.00528,7.000
7,61.562,0.00,2.1302,2.13020,7.000
7,61.688,0.00,2.2552,2.25522,7.000
7,61.812,0.01,2.3802,2.38020,7.000
7,61.938,0.02,2.5052,2.50522,7.000
7,62.062,0.06,2.6301,2.63012,7.000
7,62.188,0.13,2.7552,2.75520,7.000
7,62.312,0.24,2.8803,2.88030,7.000
7,62.438,0.46,3.0054,3.00537,7.000
7,62.562,0.76,3.1303,3.13030,7.000
7,62.750,1.17,3.2483,3.24830,7.000
7,62.875,0.72,3.1236,3.12355,7.000
7,63.000,0.40,2.9985,2.99850,7.000
7,63.125,0.20,2.8735,2.87345,7.000
7,63.250,0.07,2.7483,2.74830,7.000
7,63.375,0.03,2.6233,2.62330,7.000
7,63.500,0.01,2.4984,2.49840,7.000
7,63.625,0.00,2.3735,2.37350,7.000
7,63.750,0.00,2.2484,2.24840,7.000
7,63.875,0.00,2.1236,2.12355,7.000
7,64.000,-0.01,1.9985,1.99850,7.000
7,64.125,0.00,1.8734,1.87345,7.000
7,64.250,0.00,1.7484,1.74840,7.000
7,64.375,0.00,1.6234,1.62340,7.000
7,64.500,0.00,1.4985,1.49850,7.000
7,64.625,0.00,1.3734,1.37340,7.000
7,64.750,0.00,1.2484,1.24840,7.000
7,64.875,0.00,1.1234,1.12335,7.000
7,65.000,0.00,0.9984,0.99840,7.000
7,65.125,0.01,0.8735,0.87350,7.000
7,65.250,0.00,0.7484,0.74840,7.000
7,65.375,0.00,0.6232,0.62315,7.000
7,65.500,0.00,0.4982,0.49820,7.000
7,65.625,0.00,0.3734,0.37335,7.000
7,65.750,0.00,0.2482,0.24820,7.000
7,65.875,0.00,0.1232,0.12325,7.000
7,66.000,0.00,-0.0017,-0.00170,7.000
7,66.188,0.00,0.0000,-0.00002,7.000
7,66.312,0.00,-0.0001,-0.00010,7.000
7,66.438,0.00,-0.0001,-0.00010,7.000
7,66.562,0.00,-0.0001,-0.00010,7.000
7,66.688,0.00,-0.0001,-0.00010,7.000
7,66.812,0.00,-0.0001,-0.00010,7.000
7,66.938,0.00,-0.0001,-0.00010,7.000
7,67.062,0.00,-0.0001,-0.00010,7.000
7,67.188,0.00,-0.0001,-0.00010,7.000
7,67.312,0.00,-0.0001,-0.00010,7.000
7,67.438,0.00,-0.0001,-0.00010,7.000
7,67.562,0.00,-0.0001,-0.00010,7.000
7,67.688,0.00,-0.0001,-0.00010,7.000
7,67.812,-0.01,-0.0001,-0.00010,7.000
7,67.938,0.00,-0.0001,-0.00010,7.000
7,68.062,0.00,-0.0001,-0.00010,7.000
7,68.188,0.00,-0.0001,-0.00010,7.000
7,68.312,0.00,-0.0001,-0.00010,7.000
7,68.438,-0.01,-0.0001,-0.00010,7.000
7,68.562,0.00,-0.0001,-0.00010,7.000
7,68.688,0.00,-0.0001,-0.00010,7.000
7,68.812,0.00,-0.0001,-0.00010,7.000
7,68.938,-0.01,-0.0001,-0.00010,7.000
7,69.062,0.00,-0.0001,-0.00010,7.000
8,69.438,0.01,0.1250,0.12502,8.000
8,69.562,0.02,0.2501,0.25012,8.000
8,69.688,0.01,0.3751,0.37508,8.000
8,69.812,0.01,0.5000,0.50005,8.000
8,69.938,0.01,0.6250,0.62498,8.000
8,70.062,0.01,0.7501,0.75012,8.000
8,70.188,0.02,0.8752,0.87520,8.000
8,70.312,0.01,1.0001,1.00015,8.000
8,70.438,0.01,1.1252,1.12520,8.000
8,70.562,0.01,1.2502,1.25022,8.000
8,70.688,0.02,1.3752,1.37515,8.000
8,70.812,0.01,1.5002,1.50017,8.000
8,70.938,0.02,1.6252,1.62520,8.000
8,71.062,0.01,1.7502,1.75025,8.000
8,71.188,0.01,1.8754,1.87535,8.000
8,71.312,0.02,2.0001,2.00015,8.000
8,71.438,0.01,2.1253,2.12530,8.000
8,71.562,0.01,2.2503,2.25027,8.000
8,71.688,0.02,2.3752,2.37522,8.000
8,71.812,0.04,2.5002,2.50025,8.000
8,71.938,0.07,2.6250,2.62505,8.000
8,72.062,0.13,2.7502,2.75022,8.000
8,72.188,0.26,2.8753,2.87525,8.000
8,72.312,0.47,3.0004,3.00037,8.000
8,72.438,0.76,3.1253,3.12528,8.000
8,72.625,1.20,3.2504,3.25035,8.000
8,72.750,0.74,3.1264,3.12640,8.000
8,72.875,0.42,3.0016,3.00160,8.000
8,73.000,0.22,2.8764,2.87640,8.000
8,73.125,0.10,2.7514,2.75145,8.000
8,73.250,0.06,2.6263,2.62630,8.000
8,73.375,0.03,2.5015,2.50145,8.000
8,73.500,0.02,2.3765,2.37650,8.000
8,73.625,0.02,2.2515,2.25150,8.000
8,73.750,0.01,2.1265,2.12650,8.000
8,73.875,0.01,2.0015,2.00145,8.000
8,74.000,0.01,1.8765,1.87650,8.000
8,74.125,0.01,1.7515,1.75145,8.000
8,74.250,0.02,1.6263,1.62630,8.000
8,74.375,0.02,1.5015,1.50145,8.000
8,74.500,0.01,1.3762,1.37620,8.000
8,74.625,0.01,1.2514,1.25135,8.000
8,74.750,0.01,1.1265,1.12650,8.000
8,74.875,0.02,1.0014,1.00145,8.000
8,75.000,0.02,0.8765,0.87650,8.000
8,75.125,0.01,0.7514,0.75140,8.000
8,75.250,0.02,0.6261,0.62610,8.000
8,75.375,0.02,0.5013,0.50130,8.000
8,75.500,0.02,0.3763,0.37630,8.000
8,75.625,0.02,0.2513,0.25125,8.000
8,75.750,0.02,0.1263,0.12630,8.000
8,75.875,0.01,0.0013,0.00135,8.000
8,76.062,0.01,-0.0001,-0.00012,8.000
8,76.188,0.02,-0.0001,-0.00010,8.000
8,76.312,0.02,-0.0001,-0.00010,8.000
8,76.438,0.02,-0.0001,-0.00010,8.000
8,76.562,0.01,-0.0001,-0.00010,8.000
8,76.688,0.01,-0.0001,-0.00010,8.000
8,76.812,0.01,-0.0001,-0.00010,8.000
8,76.938,0.01,-0.0001,-0.00010,8.000
8,77.062,0.02,-0.0001,-0.00010,8.000
8,77.188,0.02,-0.0001,-0.00010,8.000
8,77.312,0.02,-0.0001,-0.00010,8.000
8,77.438,0.01,-0.0001,-0.00010,8.000
8,77.562,0.01,-0.0001,-0.00010,8.000
8,77.688,0.02,-0.0001,-0.00010,8.000
8,77.812,0.01,-0.0001,-0.00010,8.000
8,77.938,0.01,-0.0001,-0.00010,8.000
8,78.062,0.01,-0.0001,-0.00010,8.000
8,78.188,0.02,-0.0001,-0.00010,8.000
8,78.312,0.02,-0.0001,-0.00010,8.000
8,78.438,0.01,-0.0001,-0.00010,8.000
8,78.562,0.01,-0.0001,-0.00010,8.000
8,78.688,0.01,-0.0001,-0.00010,8.000
8,78.812,0.01,-0.0001,-0.00010,8.000
8,78.938,0.01,-0.0001,-0.00010,8.000
9,79.312,0.00,0.1100,0.11000,9.000
9,79.438,0.01,0.2350,0.23500,9.000
9,79.562,0.01,0.3601,0.36015,9.000
9,79.688,0.01,0.4852,0.48520,9.000
9,79.812,0.00,0.6100,0.61000,9.000
9,79.938,0.00,0.7350,0.73505,9.000
9,80.062,0.00,0.8601,0.86015,9.000
9,80.188,0.00,0.9851,0.98510,9.000
9,80.312,0.00,1.1100,1.11005,9.000
9,80.438,0.01,1.2352,1.23518,9.000
9,80.562,0.01,1.3601,1.36015,9.000
9,80.688,0.01,1.4852,1.48520,9.000
9,80.812,0.01,1.6103,1.61035,9.000
9,80.938,0.00,1.7353,1.73530,9.000
9,81.062,0.01,1.8602,1.86025,9.000
9,81.188,0.01,1.9851,1.98512,9.000
9,81.312,0.00,2.1101,2.11015,9.000
9,81.438,0.01,2.2353,2.23525,9.000
9,81.562,0.01,2.3602,2.36025,9.000
9,81.688,0.03,2.4853,2.48530,9.000
9,81.812,0.06,2.6102,2.61025,9.000
9,81.938,0.11,2.7352,2.73525,9.000
9,82.062,0.23,2.8603,2.86027,9.000
9,82.188,0.43,2.9853,2.98530,9.000
9,82.312,0.71,3.1102,3.11020,9.000
9,82.438,1.08,3.2352,3.23525,9.000
9,82.625,0.81,3.1534,3.15340,9.000
9,82.750,0.46,3.0284,3.02840,9.000
9,82.875,0.24,2.9035,2.90345,9.000
9,83.000,0.11,2.7785,2.77850,9.000
9,83.125,0.04,2.6535,2.65350,9.000
9,83.250,0.02,2.5285,2.52850,9.000
9,83.375,0.01,2.4036,2.40360,9.000
9,83.500,0.01,2.2785,2.27850,9.000
9,83.625,0.01,2.1535,2.15345,9.000
9,83.750,0.01,2.0284,2.02840,9.000
9,83.875,0.00,1.9034,1.90335,9.000
9,84.000,0.01,1.7785,1.77850,9.000
9,84.125,0.00,1.6534,1.65340,9.000
9,84.250,0.01,1.5285,1.52850,9.000
9,84.375,0.00,1.4035,1.40350,9.000
9,84.500,-0.01,1.2784,1.27840,9.000
9,84.625,0.01,1.1534,1.15335,9.000
9,84.750,0.02,1.0283,1.02830,9.000
9,84.875,0.01,0.9033,0.90330,9.000
9,85.000,0.00,0.7784,0.77840,9.000
9,85.125,0.01,0.6532,0.65320,9.000
9,85.250,0.01,0.5284,0.52840,9.000
9,85.375,0.00,0.4034,0.40345,9.000
9,85.500,0.01,0.2783,0.27830,9.000
9,85.625,0.01,0.1532,0.15320,9.000
9,85.750,0.02,0.0282,0.02820,9.000
9,85.938,0.00,0.0007,0.00068,9.000
9,86.062,0.00,-0.0001,-0.00010,9.000
9,86.188,0.00,-0.0001,-0.00010,9.000
9,86.312,0.00,-0.0001,-0.00010,9.000
9,86.438,0.01,-0.0001,-0.00010,9.000
9,86.562,0.00,-0.0001,-0.00010,9.000
9,86.688,0.01,-0.0001,-0.00010,9.000
9,86.812,0.01,-0.0001,-0.00010,9.000
9,86.938,0.01,-0.0001,-0.00010,9.000
9,87.062,0.00,-0.0001,-0.00010,9.000
9,87.188,0.00,-0.0001,-0.00010,9.000
9,87.312,0.00,-0.0001,-0.00010,9.000
9,87.438,0.00,-0.0001,-0.00010,9.000
9,87.562,0.00,-0.0001,-0.00010,9.000
9,87.688,0.00,-0.0001,-0.00010,9.000
9,87.812,0.01,-0.0001,-0.00010,9.000
9,87.938,0.01,-0.0001,-0.00010,9.000
9,88.062,0.01,-0.0001,-0.00010,9.000
9,88.188,0.01,-0.0001,-0.00010,9.000
9,88.312,0.01,-0.0001,-0.00010,9.000
9,88.438,0.00,-0.0001,-0.00010,9.000
9,88.562,0.01,-0.0001,-0.00010,9.000
9,88.688,0.00,-0.0001,-0.00010,9.000
9,88.812,0.01,-0.0001,-0.00010,9.000
10,89.125,0.01,0.0436,0.04355,10.000
10,89.250,0.01,0.1686,0.16860,10.000
10,89.375,0.01,0.2936,0.29360,10.000
10,89.500,0.02,0.4185,0.41850,10.000
10,89.625,0.01,0.5436,0.54355,10.000
10,89.750,0.01,0.6684,0.66840,10.000
10,89.875,0.01,0.7938,0.79375,10.000
10,90.000,0.02,0.9187,0.91870,10.000
10,90.125,0.02,1.0437,1.04370,10.000
10,90.250,0.02,1.1688,1.16880,10.000
10,90.375,0.01,1.2936,1.29365,10.000
10,90.500,0.02,1.4186,1.41860,10.000
10,90.625,0.01,1.5437,1.54370,10.000
10,90.750,0.01,1.6686,1.66860,10.000
10,90.875,0.01,1.7938,1.79380,10.000
10,91.000,0.02,1.9187,1.91870,10.000
10,91.125,0.01,2.0438,2.04380,10.000
10,91.250,0.02,2.1688,2.16880,10.000
10,91.375,0.02,2.2938,2.29385,10.000
10,91.500,0.02,2.4187,2.41870,10.000
10,91.625,0.05,2.5436,2.54365,10.000
10,91.750,0.09,2.6687,2.66870,10.000
10,91.875,0.17,2.7937,2.79365,10.000
10,92.000,0.33,2.9188,2.91880,10.000
10,92.125,0.56,3.0438,3.04380,10.000
10,92.250,0.88,3.1687,3.16870,10.000
10,92.438,1.11,3.2298,3.22982,10.000
10,92.562,0.67,3.1050,3.10498,10.000
10,92.688,0.38,2.9800,2.98000,10.000
10,92.812,0.19,2.8550,2.85503,10.000
10,92.938,0.07,2.7301,2.73008,10.000
10,93.062,0.03,2.6050,2.60500,10.000
10,93.188,0.02,2.4800,2.48002,10.000
10,93.312,0.01,2.3550,2.35503,10.000
10,93.438,0.01,2.2299,2.22990,10.000
10,93.562,0.01,2.1049,2.10490,10.000
10,93.688,0.02,1.9798,1.97980,10.000
10,93.812,0.01,1.8550,1.85500,10.000
10,93.938,0.01,1.7300,1.73005,10.000
10,94.062,0.01,1.6051,1.60508,10.000
10,94.188,0.02,1.4800,1.47995,10.000
10,94.312,0.01,1.3549,1.35488,10.000
10,94.438,0.02,1.2299,1.22990,10.000
10,94.562,0.02,1.1048,1.10480,10.000
10,94.688,0.02,0.9799,0.97988,10.000
10,94.812,0.01,0.8550,0.85500,10.000
10,94.938,0.01,0.7300,0.72995,10.000
10,95.062,0.02,0.6048,0.60478,10.000
10,95.188,0.02,0.4799,0.47993,10.000
10,95.312,0.01,0.3549,0.35488,10.000
10,95.438,0.01,0.2297,0.22972,10.000
10,95.562,0.01,0.1046,0.10463,10.000
10,95.688,0.01,-0.0202,-0.02022,10.000
10,95.875,0.01,-0.0002,-0.00015,10.000
10,96.000,0.02,-0.0001,-0.00010,10.000
10,96.125,0.01,-0.0001,-0.00010,10.000
10,96.250,0.02,-0.0001,-0.00010,10.000
10,96.375,0.01,-0.0001,-0.00010,10.000
10,96.500,0.02,-0.0001,-0.00010,10.000
10,96.625,0.02,-0.0001,-0.00010,10.000
10,96.750,0.01,-0.0001,-0.00010,10.000
10,96.875,0.01,-0.0001,-0.00010,10.000
10,97.000,0.01,-0.0001,-0.00010,10.000
10,97.125,0.01,-0.0001,-0.00010,10.000
10,97.250,0.01,-0.0001,-0.00010,10.000
10,97.375,0.01,-0.0001,-0.00010,10.000
10,97.500,0.01,-0.0001,-0.00010,10.000
10,97.625,0.01,-0.0001,-0.00010,10.000
10,97.750,0.01,-0.0001,-0.00010,10.000
10,97.875,0.00,-0.0001,-0.00010,10.000
10,98.000,0.01,-0.0001,-0.00010,10.000
10,98.125,0.02,-0.0001,-0.00010,10.000
10,98.250,0.01,-0.0001,-0.00010,10.000
10,98.375,0.01,-0.0001,-0.00010,10.000
10,98.500,0.01,-0.0001,-0.00010,10.000
10,98.625,0.01,-0.0001,-0.00010,10.000
10,98.750,0.01,-0.0001,-0.00010,10.000