File: AIME_journal_files/AIME_data/calibDATA_loadcell/date_02:22:2018/Instron/1N_0_1_4_0.txt
""
"Test Method","Radhen_Load_Cntrl_Cmprsn_250N_12-7.msm"
"Sample I. D.","Sample1.mss"
"Specimen Number","20"

"TheCycle_Output ()","_Time (s)","_Load (N)","_Extension (mm)","RealTimeDepth (mm)","CycleNumber ()"

1,0.312,0.00,0.0800,0.07998,1.000
1,0.438,0.00,0.2052,0.20525,1.000
1,0.562,-0.01,0.3302,0.33025,1.000
1,0.688,-0.01,0.4553,0.45528,1.000
1,0.812,0.00,0.5802,0.58025,1.000
1,0.938,0.00,0.7053,0.70530,1.000
1,1.062,0.00,0.8303,0.83032,1.000
1,1.188,0.00,0.9555,0.95545,1.000
1,1.312,0.00,1.0804,1.08042,1.000
1,1.438,0.00,1.2054,1.20538,1.000
1,1.562,0.00,1.3303,1.33032,1.000
1,1.688,0.00,1.4552,1.45522,1.000
1,1.812,0.00,1.5804,1.58038,1.000
1,1.938,0.01,1.7054,1.70540,1.000
1,2.062,0.00,1.8304,1.83042,1.000
1,2.188,0.02,1.9554,1.95540,1.000
1,2.312,0.05,2.0804,2.08038,1.000
1,2.438,0.08,2.2054,2.20538,1.000
1,2.562,0.14,2.3304,2.33035,1.000
1,2.688,0.25,2.4553,2.45532,1.000
1,2.812,0.43,2.5803,2.58025,1.000
1,2.938,0.71,2.7054,2.70542,1.000
1,3.125,1.14,2.8322,2.83220,1.000
1,3.250,0.69,2.7087,2.70870,1.000
1,3.375,0.39,2.5836,2.58355,1.000
1,3.500,0.21,2.4587,2.45870,1.000
1,3.625,0.10,2.3336,2.33355,1.000
1,3.750,0.06,2.2085,2.20850,1.000
1,3.875,0.03,2.0836,2.08355,1.000
1,4.000,0.00,1.9586,1.95860,1.000
1,4.125,0.00,1.8337,1.83370,1.000
1,4.250,-0.01,1.7086,1.70860,1.000
1,4.375,0.00,1.5836,1.58360,1.000
1,4.500,0.00,1.4584,1.45840,1.000
1,4.625,0.00,1.3334,1.33345,1.000
1,4.750,0.01,1.2085,1.20850,1.000
1,4.875,0.01,1.0835,1.08350,1.000
1,5.000,-0.01,0.9586,0.95860,1.000
1,5.125,0.00,0.8336,0.83355,1.000
1,5.250,0.00,0.7085,0.70850,1.000
1,5.375,0.00,0.5834,0.58345,1.000
1,5.500,-0.01,0.4584,0.45840,1.000
1,5.625,0.00,0.3334,0.33335,1.000
1,5.750,0.00,0.2084,0.20840,1.000
1,5.875,0.00,0.0832,0.08320,1.000
1,6.062,0.00,-0.0107,-0.01073,1.000
1,6.188,0.00,-0.0002,-0.00020,1.000
1,6.312,0.00,-0.0002,-0.00020,1.000
1,6.438,0.00,-0.0002,-0.00020,1.000
1,6.562,0.00,-0.0002,-0.00020,1.000
1,6.688,0.00,-0.0002,-0.00020,1.000
1,6.812,0.00,-0.0002,-0.00020,1.000
1,6.938,0.00,-0.0002,-0.00020,1.000
1,7.062,0.00,-0.0002,-0.00020,1.000
1,7.188,0.00,-0.0002,-0.00020,1.000
1,7.312,0.00,-0.0002,-0.00020,1.000
1,7.438,0.00,-0.0002,-0.00020,1.000
1,7.562,0.00,-0.0002,-0.00020,1.000
1,7.688,0.00,-0.0002,-0.00020,1.000
1,7.812,-0.01,-0.0001,-0.00010,1.000
1,7.938,0.00,-0.0001,-0.00010,1.000
1,8.062,0.00,-0.0001,-0.00010,1.000
1,8.188,-0.01,-0.0001,-0.00010,1.000
1,8.312,0.00,-0.0001,-0.00010,1.000
1,8.438,0.00,-0.0001,-0.00010,1.000
1,8.562,0.01,-0.0001,-0.00010,1.000
1,8.688,0.00,-0.0001,-0.00010,1.000
1,8.812,0.00,-0.0001,-0.00010,1.000
1,8.938,0.00,-0.0001,-0.00010,1.000
2,9.312,-0.01,0.0660,0.06600,2.000
2,9.438,-0.02,0.1913,0.19133,2.000
2,9.562,-0.01,0.3163,0.31627,2.000
2,9.688,-0.02,0.4412,0.44118,2.000
2,9.812,-0.02,0.5661,0.56610,2.000
2,9.938,-0.01,0.6912,0.69120,2.000
2,10.062,-0.01,0.8161,0.81615,2.000
2,10.188,-0.02,0.9413,0.94128,2.000
2,10.312,-0.01,1.0663,1.06632,2.000
2,10.438,-0.02,1.1915,1.19145,2.000
2,10.562,-0.01,1.3163,1.31635,2.000
2,10.688,-0.02,1.4413,1.44125,2.000
2,10.812,-0.01,1.5662,1.56625,2.000
2,10.938,-0.01,1.6913,1.69128,2.000
2,11.062,-0.01,1.8163,1.81630,2.000
2,11.188,0.00,1.9413,1.94130,2.000
2,11.312,0.03,2.0663,2.06630,2.000
2,11.438,0.06,2.1914,2.19135,2.000
2,11.562,0.12,2.3164,2.31640,2.000
2,11.688,0.22,2.4414,2.44140,2.000
2,11.812,0.40,2.5662,2.56622,2.000
2,11.938,0.66,2.6913,2.69133,2.000
2,12.188,0.98,2.7970,2.79700,2.000
2,12.312,0.57,2.6722,2.67215,2.000
2,12.438,0.32,2.5470,2.54700,2.000
2,12.562,0.16,2.4221,2.42208,2.000
2,12.688,0.08,2.2969,2.29695,2.000
2,12.812,0.04,2.1720,2.17195,2.000
2,12.938,0.01,2.0469,2.04695,2.000
2,13.062,-0.01,1.9220,1.92200,2.000
2,13.188,-0.01,1.7970,1.79702,2.000
2,13.312,-0.01,1.6720,1.67203,2.000
2,13.438,-0.01,1.5471,1.54707,2.000
2,13.562,-0.01,1.4220,1.42203,2.000
2,13.688,-0.01,1.2969,1.29695,2.000
2,13.812,-0.02,1.1720,1.17200,2.000
2,13.938,-0.01,1.0470,1.04697,2.000
2,14.062,-0.02,0.9220,0.92200,2.000
2,14.188,-0.01,0.7969,0.79690,2.000
2,14.312,-0.01,0.6719,0.67193,2.000
2,14.438,-0.02,0.5469,0.54692,2.000
2,14.562,-0.01,0.4220,0.42195,2.000
2,14.688,-0.01,0.2969,0.29692,2.000
2,14.812,-0.01,0.1718,0.17175,2.000
2,14.938,-0.02,0.0467,0.04667,2.000
2,15.062,-0.01,-0.0372,-0.03723,2.000
2,15.188,-0.01,-0.0002,-0.00020,2.000
2,15.312,-0.01,-0.0002,-0.00020,2.000
2,15.438,-0.01,-0.0002,-0.00020,2.000
2,15.562,-0.01,-0.0002,-0.00020,2.000
2,15.688,-0.02,-0.0002,-0.00020,2.000
2,15.812,-0.01,-0.0002,-0.00020,2.000
2,15.938,-0.02,-0.0002,-0.00020,2.000
2,16.062,-0.01,-0.0002,-0.00020,2.000
2,16.188,-0.01,-0.0002,-0.00020,2.000
2,16.312,-0.01,-0.0002,-0.00020,2.000
2,16.438,-0.02,-0.0002,-0.00020,2.000
2,16.562,-0.01,-0.0002,-0.00020,2.000
2,16.688,-0.02,-0.0002,-0.00020,2.000
2,16.812,-0.01,-0.0002,-0.00020,2.000
2,16.938,-0.01,-0.0002,-0.00020,2.000
2,17.062,-0.01,-0.0002,-0.00020,2.000
2,17.188,-0.02,-0.0002,-0.00020,2.000
2,17.312,-0.01,-0.0002,-0.00020,2.000
2,17.438,-0.01,-0.0002,-0.00020,2.000
2,17.562,-0.02,-0.0002,-0.00020,2.000
2,17.688,-0.01,-0.0002,-0.00020,2.000
2,17.812,-0.01,-0.0002,-0.00020,2.000
2,17.938,-0.01,-0.0002,-0.00020,2.000
3,18.312,0.00,0.0610,0.06095,3.000
3,18.438,0.00,0.1862,0.18620,3.000
3,18.562,0.00,0.3112,0.31123,3.000
3,18.688,0.00,0.4363,0.43627,3.000
3,18.812,-0.01,0.5612,0.56123,3.000
3,18.938,0.00,0.6861,0.68615,3.000
3,19.062,0.01,0.8112,0.81120,3.000
3,19.188,0.00,0.9362,0.93625,3.000
3,19.312,0.00,1.0613,1.06125,3.000
3,19.438,0.00,1.1864,1.18637,3.000
3,19.562,0.00,1.3113,1.31133,3.000
3,19.688,0.00,1.4364,1.43637,3.000
3,19.812,0.00,1.5613,1.56133,3.000
3,19.938,0.00,1.6862,1.68625,3.000
3,20.062,0.00,1.8112,1.81123,3.000
3,20.188,0.01,1.9363,1.93627,3.000
3,20.312,0.05,2.0612,2.06120,3.000
3,20.438,0.08,2.1862,2.18622,3.000
3,20.562,0.13,2.3113,2.31133,3.000
3,20.688,0.23,2.4364,2.43645,3.000
3,20.812,0.40,2.5613,2.56130,3.000
3,20.938,0.66,2.6864,2.68640,3.000
3,21.062,1.02,2.8113,2.81130,3.000
3,21.250,0.88,2.7696,2.76960,3.000
3,21.375,0.51,2.6446,2.64455,3.000
3,21.500,0.28,2.5195,2.51950,3.000
3,21.625,0.14,2.3946,2.39465,3.000
3,21.750,0.07,2.2696,2.26960,3.000
3,21.875,0.04,2.1445,2.14450,3.000
3,22.000,0.02,2.0195,2.01950,3.000
3,22.125,0.01,1.8945,1.89445,3.000
3,22.250,0.01,1.7694,1.76940,3.000
3,22.375,0.00,1.6444,1.64445,3.000
3,22.500,0.00,1.5195,1.51950,3.000
3,22.625,0.01,1.3944,1.39445,3.000
3,22.750,0.01,1.2696,1.26960,3.000
3,22.875,0.01,1.1445,1.14450,3.000
3,23.000,0.00,1.0195,1.01950,3.000
3,23.125,0.00,0.8944,0.89435,3.000
3,23.250,0.00,0.7693,0.76930,3.000
3,23.375,0.00,0.6444,0.64435,3.000
3,23.500,0.01,0.5194,0.51940,3.000
3,23.625,0.00,0.3944,0.39440,3.000
3,23.750,0.01,0.2695,0.26950,3.000
3,23.875,0.00,0.1444,0.14440,3.000
3,24.000,0.01,0.0192,0.01920,3.000
3,24.188,0.00,-0.0002,-0.00023,3.000
3,24.312,0.00,-0.0002,-0.00020,3.000
3,24.438,-0.01,-0.0002,-0.00020,3.000
3,24.562,0.00,-0.0002,-0.00020,3.000
3,24.688,0.01,-0.0002,-0.00020,3.000
3,24.812,0.01,-0.0002,-0.00020,3.000
3,24.938,0.01,-0.0002,-0.00020,3.000
3,25.062,0.00,-0.0002,-0.00020,3.000
3,25.188,0.00,-0.0002,-0.00020,3.000
3,25.312,0.00,-0.0002,-0.00020,3.000
3,25.438,0.00,-0.0002,-0.00020,3.000
3,25.562,0.00,-0.0002,-0.00020,3.000
3,25.688,0.01,-0.0002,-0.00020,3.000
3,25.812,0.00,-0.0002,-0.00020,3.000
3,25.938,0.00,-0.0002,-0.00020,3.000
3,26.062,0.00,-0.0002,-0.00020,3.000
3,26.188,0.00,-0.0002,-0.00020,3.000
3,26.312,0.00,-0.0002,-0.00020,3.000
3,26.438,0.00,-0.0002,-0.00020,3.000
3,26.562,0.01,-0.0002,-0.00020,3.000
3,26.688,0.00,-0.0002,-0.00020,3.000
3,26.812,-0.01,-0.0002,-0.00020,3.000
3,26.938,-0.01,-0.0002,-0.00020,3.000
3,27.062,0.01,-0.0002,-0.00020,3.000
4,27.438,-0.01,0.1350,0.13500,4.000
4,27.562,-0.01,0.2603,0.26030,4.000
4,27.688,-0.01,0.3852,0.38520,4.000
4,27.812,-0.01,0.5103,0.51030,4.000
4,27.938,-0.01,0.6352,0.63522,4.000
4,28.062,-0.01,0.7602,0.76025,4.000
4,28.188,-0.01,0.8852,0.88522,4.000
4,28.312,-0.01,1.0102,1.01020,4.000
4,28.438,-0.01,1.1353,1.13527,4.000
4,28.562,-0.01,1.2602,1.26025,4.000
4,28.688,-0.01,1.3852,1.38520,4.000
4,28.812,-0.01,1.5103,1.51030,4.000
4,28.938,-0.01,1.6353,1.63530,4.000
4,29.062,-0.01,1.7603,1.76035,4.000
4,29.188,0.00,1.8852,1.88525,4.000
4,29.312,0.02,2.0102,2.01020,4.000
4,29.438,0.05,2.1353,2.13527,4.000
4,29.562,0.10,2.2602,2.26020,4.000
4,29.688,0.17,2.3853,2.38535,4.000
4,29.812,0.31,2.5103,2.51032,4.000
4,29.938,0.54,2.6354,2.63537,4.000
4,30.062,0.85,2.7604,2.76042,4.000
4,30.250,1.15,2.8383,2.83830,4.000
4,30.375,0.68,2.7137,2.71365,4.000
4,30.500,0.38,2.5886,2.58860,4.000
4,30.625,0.20,2.4635,2.46355,4.000
4,30.750,0.09,2.3384,2.33840,4.000
4,30.875,0.04,2.2134,2.21345,4.000
4,31.000,0.01,2.0885,2.08850,4.000
4,31.125,0.00,1.9634,1.96345,4.000
4,31.250,-0.01,1.8386,1.83860,4.000
4,31.375,-0.01,1.7135,1.71350,4.000
4,31.500,-0.01,1.5885,1.58850,4.000
4,31.625,-0.01,1.4635,1.46350,4.000
4,31.750,-0.01,1.3383,1.33830,4.000
4,31.875,-0.01,1.2135,1.21350,4.000
4,32.000,-0.01,1.0884,1.08840,4.000
4,32.125,-0.01,0.9634,0.96345,4.000
4,32.250,-0.01,0.8385,0.83850,4.000
4,32.375,-0.01,0.7134,0.71345,4.000
4,32.500,-0.01,0.5885,0.58850,4.000
4,32.625,-0.01,0.4634,0.46345,4.000
4,32.750,0.00,0.3385,0.33850,4.000
4,32.875,0.00,0.2134,0.21340,4.000
4,33.000,-0.02,0.0880,0.08800,4.000
4,33.188,-0.01,-0.0426,-0.04262,4.000
4,33.312,-0.01,-0.0002,-0.00020,4.000
4,33.438,0.00,-0.0002,-0.00020,4.000
4,33.562,-0.01,-0.0002,-0.00020,4.000
4,33.688,-0.01,-0.0002,-0.00020,4.000
4,33.812,0.00,-0.0002,-0.00020,4.000
4,33.938,-0.01,-0.0002,-0.00020,4.000
4,34.062,-0.01,-0.0002,-0.00020,4.000
4,34.188,-0.01,-0.0002,-0.00020,4.000
4,34.312,0.00,-0.0002,-0.00020,4.000
4,34.438,-0.01,-0.0002,-0.00020,4.000
4,34.562,0.00,-0.0002,-0.00020,4.000
4,34.688,-0.01,-0.0002,-0.00020,4.000
4,34.812,-0.01,-0.0002,-0.00020,4.000
4,34.938,-0.01,-0.0002,-0.00020,4.000
4,35.062,-0.01,-0.0002,-0.00020,4.000
4,35.188,0.00,-0.0002,-0.00020,4.000
4,35.312,0.00,-0.0002,-0.00020,4.000
4,35.438,-0.01,-0.0002,-0.00020,4.000
4,35.562,-0.02,-0.0001,-0.00010,4.000
4,35.688,-0.01,-0.0001,-0.00010,4.000
4,35.812,-0.01,-0.0001,-0.00010,4.000
4,35.938,-0.01,-0.0001,-0.00010,4.000
4,36.062,-0.02,-0.0001,-0.00010,4.000
5,36.500,-0.01,0.0835,0.08360,5.000
5,36.625,-0.01,0.2087,0.20880,5.000
5,36.750,-0.01,0.3337,0.33380,5.000
5,36.875,0.00,0.4587,0.45880,5.000
5,37.000,0.00,0.5836,0.58370,5.000
5,37.125,-0.01,0.7088,0.70885,5.000
5,37.250,0.00,0.8339,0.83400,5.000
5,37.375,0.00,0.9588,0.95890,5.000
5,37.500,0.00,1.0838,1.08390,5.000
5,37.625,0.00,1.2088,1.20890,5.000
5,37.750,0.00,1.3337,1.33380,5.000
5,37.875,-0.01,1.4587,1.45880,5.000
5,38.000,-0.01,1.5838,1.58390,5.000
5,38.125,-0.01,1.7088,1.70890,5.000
5,38.250,-0.01,1.8338,1.83390,5.000
5,38.375,0.01,1.9589,1.95895,5.000
5,38.500,0.04,2.0838,2.08390,5.000
5,38.625,0.07,2.2087,2.20880,5.000
5,38.750,0.13,2.3337,2.33380,5.000
5,38.875,0.26,2.4588,2.45890,5.000
5,39.000,0.43,2.5838,2.58390,5.000
5,39.125,0.71,2.7089,2.70900,5.000
5,39.312,1.16,2.8400,2.84010,5.000
5,39.438,0.69,2.7171,2.71722,5.000
5,39.562,0.40,2.5921,2.59215,5.000
5,39.688,0.20,2.4671,2.46717,5.000
5,39.812,0.10,2.3420,2.34208,5.000
5,39.938,0.05,2.2169,2.21702,5.000
5,40.062,0.02,2.0919,2.09198,5.000
5,40.188,0.00,1.9669,1.96700,5.000
5,40.312,-0.01,1.8420,1.84213,5.000
5,40.438,0.00,1.7170,1.71715,5.000
5,40.562,-0.01,1.5921,1.59218,5.000
5,40.688,0.00,1.4669,1.46705,5.000
5,40.812,-0.02,1.3420,1.34205,5.000
5,40.938,0.00,1.2169,1.21705,5.000
5,41.062,0.00,1.0919,1.09195,5.000
5,41.188,-0.01,0.9669,0.96702,5.000
5,41.312,-0.01,0.8419,0.84203,5.000
5,41.438,-0.01,0.7169,0.71700,5.000
5,41.562,-0.01,0.5919,0.59198,5.000
5,41.688,-0.01,0.4670,0.46710,5.000
5,41.812,0.00,0.3419,0.34198,5.000
5,41.938,0.00,0.2169,0.21705,5.000
5,42.062,0.00,0.0916,0.09173,5.000
5,42.250,0.00,-0.0280,-0.02790,5.000
5,42.375,0.00,-0.0002,-0.00010,5.000
5,42.500,0.00,-0.0002,-0.00010,5.000
5,42.625,-0.01,-0.0002,-0.00010,5.000
5,42.750,-0.01,-0.0002,-0.00010,5.000
5,42.875,-0.01,-0.0002,-0.00010,5.000
5,43.000,0.00,-0.0002,-0.00010,5.000
5,43.125,-0.01,-0.0002,-0.00010,5.000
5,43.250,0.00,-0.0002,-0.00010,5.000
5,43.375,-0.02,-0.0002,-0.00010,5.000
5,43.500,0.00,-0.0002,-0.00010,5.000
5,43.625,0.00,-0.0002,-0.00010,5.000
5,43.750,0.00,-0.0002,-0.00010,5.000
5,43.875,-0.01,-0.0002,-0.00010,5.000
5,44.000,-0.01,-0.0002,-0.00010,5.000
5,44.125,-0.01,-0.0002,-0.00010,5.000
5,44.250,-0.01,-0.0002,-0.00010,5.000
5,44.375,-0.01,-0.0002,-0.00010,5.000
5,44.500,-0.02,-0.0002,-0.00010,5.000
5,44.625,-0.01,-0.0002,-0.00010,5.000
5,44.750,0.00,-0.0002,-0.00010,5.000
5,44.875,0.00,-0.0002,-0.00010,5.000
5,45.000,0.00,-0.0002,-0.00010,5.000
5,45.125,0.00,-0.0002,-0.00005,5.000
5,45.250,0.00,-0.0001,0.00000,5.000
6,45.625,0.01,0.1486,0.14875,6.000
6,45.750,0.02,0.2737,0.27380,6.000
6,45.875,0.01,0.3988,0.39885,6.000
6,46.000,0.02,0.5237,0.52380,6.000
6,46.125,0.02,0.6487,0.64875,6.000
6,46.250,0.00,0.7737,0.77380,6.000
6,46.375,0.02,0.8987,0.89880,6.000
6,46.500,0.02,1.0237,1.02380,6.000
6,46.625,0.02,1.1488,1.14890,6.000
6,46.750,0.00,1.2739,1.27400,6.000
6,46.875,0.02,1.3988,1.39885,6.000
6,47.000,0.02,1.5238,1.52390,6.000
6,47.125,0.02,1.6488,1.64885,6.000
6,47.250,0.01,1.7736,1.77370,6.000
6,47.375,0.03,1.8987,1.89880,6.000
6,47.500,0.06,2.0238,2.02390,6.000
6,47.625,0.09,2.1488,2.14890,6.000
6,47.750,0.13,2.2739,2.27400,6.000
6,47.875,0.22,2.3989,2.39900,6.000
6,48.000,0.36,2.5239,2.52400,6.000
6,48.125,0.59,2.6487,2.64885,6.000
6,48.250,0.91,2.7738,2.77390,6.000
6,48.438,0.86,2.7572,2.75732,6.000
6,48.562,0.50,2.6321,2.63218,6.000
6,48.688,0.28,2.5071,2.50717,6.000
6,48.812,0.15,2.3820,2.38208,6.000
6,48.938,0.09,2.2570,2.25710,6.000
6,49.062,0.04,2.1320,2.13205,6.000
6,49.188,0.03,2.0070,2.00707,6.000
6,49.312,0.02,1.8820,1.88213,6.000
6,49.438,0.02,1.7570,1.75715,6.000
6,49.562,0.02,1.6321,1.63215,6.000
6,49.688,0.02,1.5070,1.50712,6.000
6,49.812,0.01,1.3820,1.38205,6.000
6,49.938,0.02,1.2569,1.25697,6.000
6,50.062,0.02,1.1319,1.13200,6.000
6,50.188,0.02,1.0069,1.00705,6.000
6,50.312,0.02,0.8820,0.88213,6.000
6,50.438,0.03,0.7570,0.75707,6.000
6,50.562,0.02,0.6320,0.63205,6.000
6,50.688,0.02,0.5069,0.50702,6.000
6,50.812,0.02,0.3819,0.38198,6.000
6,50.938,0.01,0.2569,0.25702,6.000
6,51.062,0.02,0.1317,0.13180,6.000
6,51.188,0.02,0.0068,0.00687,6.000
6,51.375,0.02,-0.0003,-0.00020,6.000
6,51.500,0.01,-0.0002,-0.00010,6.000
6,51.625,0.01,-0.0002,-0.00010,6.000
6,51.750,0.01,-0.0002,-0.00010,6.000
6,51.875,0.02,-0.0002,-0.00010,6.000
6,52.000,0.02,-0.0002,-0.00010,6.000
6,52.125,0.01,-0.0002,-0.00010,6.000
6,52.250,0.01,-0.0002,-0.00010,6.000
6,52.375,0.01,-0.0002,-0.00010,6.000
6,52.500,0.02,-0.0002,-0.00010,6.000
6,52.625,0.01,-0.0002,-0.00010,6.000
6,52.750,0.02,-0.0002,-0.00010,6.000
6,52.875,0.01,-0.0002,-0.00010,6.000
6,53.000,0.01,-0.0002,-0.00010,6.000
6,53.125,0.01,-0.0002,-0.00010,6.000
6,53.250,0.02,-0.0002,-0.00010,6.000
6,53.375,0.01,-0.0002,-0.00010,6.000
6,53.500,0.01,-0.0002,-0.00010,6.000
6,53.625,0.01,-0.0002,-0.00010,6.000
6,53.750,0.02,-0.0002,-0.00010,6.000
6,53.875,0.02,-0.0002,-0.00010,6.000
6,54.000,0.02,-0.0002,-0.00010,6.000
6,54.125,0.02,-0.0002,-0.00010,6.000
6,54.250,0.01,-0.0002,-0.00010,6.000
7,54.625,-0.01,0.1436,0.14360,7.000
7,54.750,-0.01,0.2688,0.26880,7.000
7,54.875,-0.01,0.3937,0.39375,7.000
7,55.000,-0.01,0.5188,0.51880,7.000
7,55.125,-0.01,0.6436,0.64365,7.000
7,55.250,-0.01,0.7688,0.76880,7.000
7,55.375,-0.01,0.8937,0.89370,7.000
7,55.500,-0.02,1.0188,1.01880,7.000
7,55.625,-0.01,1.1438,1.14385,7.000
7,55.750,-0.01,1.2688,1.26880,7.000
7,55.875,-0.01,1.3938,1.39380,7.000
7,56.000,-0.02,1.5189,1.51890,7.000
7,56.125,-0.01,1.6438,1.64380,7.000
7,56.250,-0.01,1.7687,1.76870,7.000
7,56.375,-0.01,1.8937,1.89375,7.000
7,56.500,0.02,2.0187,2.01870,7.000
7,56.625,0.05,2.1437,2.14370,7.000
7,56.750,0.10,2.2687,2.26870,7.000
7,56.875,0.18,2.3939,2.39390,7.000
7,57.000,0.32,2.5189,2.51890,7.000
7,57.125,0.55,2.6438,2.64385,7.000
7,57.250,0.87,2.7690,2.76900,7.000
7,57.438,0.96,2.7921,2.79207,7.000
7,57.562,0.55,2.6671,2.66705,7.000
7,57.688,0.30,2.5419,2.54192,7.000
7,57.812,0.15,2.4171,2.41708,7.000
7,57.938,0.07,2.2920,2.29197,7.000
7,58.062,0.03,2.1670,2.16700,7.000
7,58.188,0.01,2.0419,2.04190,7.000
7,58.312,-0.01,1.9171,1.91708,7.000
7,58.438,-0.01,1.7921,1.79210,7.000
7,58.562,-0.02,1.6671,1.66705,7.000
7,58.688,-0.01,1.5419,1.54195,7.000
7,58.812,-0.01,1.4168,1.41683,7.000
7,58.938,-0.01,1.2919,1.29190,7.000
7,59.062,-0.01,1.1670,1.16695,7.000
7,59.188,-0.01,1.0420,1.04205,7.000
7,59.312,-0.01,0.9170,0.91700,7.000
7,59.438,-0.01,0.7920,0.79200,7.000
7,59.562,-0.01,0.6670,0.66695,7.000
7,59.688,-0.01,0.5418,0.54185,7.000
7,59.812,-0.01,0.4168,0.41680,7.000
7,59.938,-0.02,0.2919,0.29190,7.000
7,60.062,0.00,0.1669,0.16688,7.000
7,60.188,-0.01,0.0417,0.04175,7.000
7,60.375,-0.01,-0.0003,-0.00030,7.000
7,60.500,-0.02,-0.0002,-0.00020,7.000
7,60.625,0.00,-0.0002,-0.00020,7.000
7,60.750,-0.01,-0.0002,-0.00020,7.000
7,60.875,-0.01,-0.0002,-0.00020,7.000
7,61.000,-0.01,-0.0002,-0.00020,7.000
7,61.125,-0.01,-0.0002,-0.00020,7.000
7,61.250,-0.01,-0.0002,-0.00020,7.000
7,61.375,-0.01,-0.0002,-0.00020,7.000
7,61.500,-0.01,-0.0002,-0.00020,7.000
7,61.625,-0.01,-0.0002,-0.00020,7.000
7,61.750,-0.01,-0.0002,-0.00020,7.000
7,61.875,-0.01,-0.0002,-0.00020,7.000
7,62.000,-0.01,-0.0002,-0.00020,7.000
7,62.125,-0.01,-0.0002,-0.00020,7.000
7,62.250,-0.02,-0.0002,-0.00020,7.000
7,62.375,-0.01,-0.0002,-0.00020,7.000
7,62.500,-0.01,-0.0001,-0.00010,7.000
7,62.625,-0.02,-0.0001,-0.00010,7.000
7,62.750,-0.01,-0.0001,-0.00010,7.000
7,62.875,-0.01,-0.0001,-0.00010,7.000
7,63.000,-0.01,-0.0001,-0.00010,7.000
7,63.125,-0.01,-0.0001,-0.00010,7.000
7,63.250,-0.01,-0.0001,-0.00010,7.000
8,63.562,-0.01,0.0260,0.02600,8.000
8,63.688,0.00,0.1511,0.15115,8.000
8,63.812,0.00,0.2763,0.27627,8.000
8,63.938,0.00,0.4012,0.40122,8.000
8,64.062,0.01,0.5261,0.52615,8.000
8,64.188,0.00,0.6511,0.65105,8.000
8,64.312,0.00,0.7760,0.77605,8.000
8,64.438,0.00,0.9012,0.90118,8.000
8,64.562,0.00,1.0263,1.02630,8.000
8,64.688,-0.01,1.1514,1.15135,8.000
8,64.812,0.01,1.2764,1.27637,8.000
8,64.938,0.00,1.4012,1.40123,8.000
8,65.062,0.00,1.5262,1.52625,8.000
8,65.188,0.00,1.6512,1.65118,8.000
8,65.312,-0.01,1.7761,1.77615,8.000
8,65.438,0.01,1.9012,1.90120,8.000
8,65.562,0.03,2.0263,2.02627,8.000
8,65.688,0.06,2.1513,2.15132,8.000
8,65.812,0.11,2.2762,2.27625,8.000
8,65.938,0.20,2.4014,2.40145,8.000
8,66.062,0.34,2.5263,2.52627,8.000
8,66.188,0.58,2.6513,2.65130,8.000
8,66.312,0.91,2.7763,2.77630,8.000
8,66.500,0.97,2.7946,2.79460,8.000
8,66.625,0.57,2.6696,2.66955,8.000
8,66.750,0.31,2.5444,2.54440,8.000
8,66.875,0.16,2.4196,2.41955,8.000
8,67.000,0.08,2.2944,2.29440,8.000
8,67.125,0.04,2.1695,2.16950,8.000
8,67.250,0.01,2.0445,2.04450,8.000
8,67.375,0.01,1.9195,1.91950,8.000
8,67.500,-0.01,1.7946,1.79460,8.000
8,67.625,-0.01,1.6694,1.66945,8.000
8,67.750,0.00,1.5445,1.54450,8.000
8,67.875,0.00,1.4194,1.41935,8.000
8,68.000,-0.01,1.2944,1.29440,8.000
8,68.125,0.00,1.1694,1.16940,8.000
8,68.250,0.00,1.0445,1.04450,8.000
8,68.375,-0.01,0.9195,0.91945,8.000
8,68.500,0.00,0.7945,0.79450,8.000
8,68.625,-0.01,0.6694,0.66940,8.000
8,68.750,0.00,0.5445,0.54450,8.000
8,68.875,0.00,0.4194,0.41935,8.000
8,69.000,-0.02,0.2944,0.29440,8.000
8,69.125,-0.01,0.1694,0.16935,8.000
8,69.250,0.00,0.0442,0.04420,8.000
8,69.500,0.00,-0.0002,-0.00020,8.000
8,69.625,0.00,-0.0002,-0.00020,8.000
8,69.750,0.00,-0.0002,-0.00020,8.000
8,69.875,0.00,-0.0002,-0.00020,8.000
8,70.000,-0.01,-0.0002,-0.00020,8.000
8,70.125,-0.01,-0.0002,-0.00020,8.000
8,70.250,0.00,-0.0002,-0.00020,8.000
8,70.375,0.00,-0.0002,-0.00020,8.000
8,70.500,0.00,-0.0002,-0.00020,8.000
8,70.625,0.00,-0.0002,-0.00020,8.000
8,70.750,-0.02,-0.0002,-0.00020,8.000
8,70.875,0.00,-0.0002,-0.00020,8.000
8,71.000,-0.01,-0.0002,-0.00020,8.000
8,71.125,-0.01,-0.0002,-0.00020,8.000
8,71.250,-0.02,-0.0002,-0.00020,8.000
8,71.375,0.00,-0.0002,-0.00020,8.000
8,71.500,0.00,-0.0002,-0.00020,8.000
8,71.625,0.00,-0.0002,-0.00020,8.000
8,71.750,-0.01,-0.0002,-0.00020,8.000
8,71.875,-0.01,-0.0002,-0.00020,8.000
8,72.000,0.00,-0.0002,-0.00020,8.000
8,72.125,-0.01,-0.0002,-0.00020,8.000
8,72.250,-0.01,-0.0001,-0.00010,8.000
8,72.375,-0.01,-0.0001,-0.00010,8.000
9,72.688,0.00,0.0909,0.09090,9.000
9,72.812,-0.01,0.2161,0.21615,9.000
9,72.938,0.00,0.3412,0.34125,9.000
9,73.062,0.00,0.4662,0.46620,9.000
9,73.188,0.01,0.5913,0.59125,9.000
9,73.312,0.01,0.7162,0.71622,9.000
9,73.438,0.00,0.8414,0.84135,9.000
9,73.562,0.00,0.9663,0.96627,9.000
9,73.688,-0.01,1.0912,1.09122,9.000
9,73.812,0.00,1.2163,1.21627,9.000
9,73.938,0.00,1.3412,1.34120,9.000
9,74.062,0.00,1.4663,1.46627,9.000
9,74.188,0.00,1.5912,1.59120,9.000
9,74.312,0.00,1.7162,1.71625,9.000
9,74.438,0.01,1.8413,1.84132,9.000
9,74.562,0.02,1.9662,1.96625,9.000
9,74.688,0.05,2.0912,2.09117,9.000
9,74.812,0.09,2.2162,2.21617,9.000
9,74.938,0.15,2.3413,2.34128,9.000
9,75.062,0.26,2.4663,2.46630,9.000
9,75.188,0.45,2.5912,2.59120,9.000
9,75.312,0.74,2.7165,2.71650,9.000
9,75.500,1.21,2.8518,2.85180,9.000
9,75.625,0.75,2.7297,2.72965,9.000
9,75.750,0.41,2.6045,2.60450,9.000
9,75.875,0.23,2.4796,2.47960,9.000
9,76.000,0.12,2.3546,2.35460,9.000
9,76.125,0.06,2.2295,2.22955,9.000
9,76.250,0.03,2.1044,2.10440,9.000
9,76.375,0.02,1.9794,1.97940,9.000
9,76.500,0.00,1.8544,1.85440,9.000
9,76.625,0.00,1.7294,1.72940,9.000
9,76.750,0.00,1.6044,1.60440,9.000
9,76.875,0.00,1.4795,1.47950,9.000
9,77.000,0.00,1.3545,1.35450,9.000
9,77.125,0.00,1.2296,1.22955,9.000
9,77.250,0.00,1.1045,1.10450,9.000
9,77.375,0.00,0.9794,0.97940,9.000
9,77.500,0.00,0.8544,0.85440,9.000
9,77.625,0.00,0.7294,0.72935,9.000
9,77.750,0.00,0.6044,0.60440,9.000
9,77.875,0.00,0.4794,0.47940,9.000
9,78.000,0.00,0.3545,0.35450,9.000
9,78.125,0.00,0.2295,0.22950,9.000
9,78.250,0.00,0.1042,0.10420,9.000
9,78.500,-0.01,-0.0028,-0.00280,9.000
9,78.625,0.01,-0.0002,-0.00020,9.000
9,78.750,0.01,-0.0001,-0.00010,9.000
9,78.875,0.01,-0.0001,-0.00010,9.000
9,79.000,0.00,-0.0001,-0.00010,9.000
9,79.125,0.00,-0.0001,-0.00010,9.000
9,79.250,0.01,-0.0001,-0.00010,9.000
9,79.375,0.00,-0.0001,-0.00010,9.000
9,79.500,-0.01,-0.0001,-0.00010,9.000
9,79.625,-0.01,-0.0001,-0.00010,9.000
9,79.750,0.00,-0.0001,-0.00010,9.000
9,79.875,0.00,-0.0001,-0.00010,9.000
9,80.000,0.00,-0.0001,-0.00010,9.000
9,80.125,0.00,-0.0001,-0.00010,9.000
9,80.250,0.00,-0.0001,-0.00010,9.000
9,80.375,0.00,-0.0001,-0.00010,9.000
9,80.500,0.00,-0.0001,-0.00010,9.000
9,80.625,0.00,-0.0001,-0.00010,9.000
9,80.750,0.01,-0.0001,-0.00010,9.000
9,80.875,0.00,-0.0001,-0.00010,9.000
9,81.000,-0.01,-0.0001,-0.00010,9.000
9,81.125,0.00,-0.0001,-0.00010,9.000
9,81.250,0.00,-0.0001,-0.00010,9.000
9,81.375,0.00,-0.0001,-0.00010,9.000
10,81.750,-0.01,0.0984,0.09840,10.000
10,81.875,-0.01,0.2238,0.22375,10.000
10,82.000,0.00,0.3487,0.34870,10.000
10,82.125,-0.01,0.4737,0.47370,10.000
10,82.250,-0.01,0.5988,0.59880,10.000
10,82.375,0.00,0.7236,0.72365,10.000
10,82.500,-0.02,0.8486,0.84860,10.000
10,82.625,-0.01,0.9737,0.97370,10.000
10,82.750,0.00,1.0986,1.09860,10.000
10,82.875,0.00,1.2238,1.22375,10.000
10,83.000,0.00,1.3488,1.34880,10.000
10,83.125,0.00,1.4738,1.47375,10.000
10,83.250,0.00,1.5987,1.59870,10.000
10,83.375,-0.01,1.7237,1.72370,10.000
10,83.500,0.00,1.8487,1.84870,10.000
10,83.625,0.02,1.9737,1.97370,10.000
10,83.750,0.03,2.0986,2.09860,10.000
10,83.875,0.08,2.2236,2.22365,10.000
10,84.000,0.16,2.3487,2.34870,10.000
10,84.125,0.27,2.4738,2.47380,10.000
10,84.250,0.47,2.5988,2.59880,10.000
10,84.375,0.75,2.7239,2.72390,10.000
10,84.562,1.16,2.8369,2.83685,10.000
10,84.688,0.68,2.7121,2.71210,10.000
10,84.812,0.39,2.5870,2.58695,10.000
10,84.938,0.20,2.4620,2.46202,10.000
10,85.062,0.10,2.3369,2.33693,10.000
10,85.188,0.04,2.2120,2.21198,10.000
10,85.312,0.03,2.0870,2.08698,10.000
10,85.438,0.00,1.9620,1.96198,10.000
10,85.562,0.00,1.8370,1.83703,10.000
10,85.688,0.00,1.7120,1.71200,10.000
10,85.812,0.00,1.5870,1.58695,10.000
10,85.938,0.00,1.4618,1.46185,10.000
10,86.062,-0.01,1.3368,1.33683,10.000
10,86.188,0.00,1.2120,1.21198,10.000
10,86.312,0.00,1.0870,1.08698,10.000
10,86.438,0.00,0.9620,0.96198,10.000
10,86.562,-0.01,0.8369,0.83693,10.000
10,86.688,-0.01,0.7119,0.71192,10.000
10,86.812,0.00,0.5869,0.58685,10.000
10,86.938,-0.01,0.4618,0.46175,10.000
10,87.062,0.00,0.3367,0.33673,10.000
10,87.188,-0.01,0.2119,0.21188,10.000
10,87.312,0.00,0.0867,0.08670,10.000
10,87.500,0.00,-0.0312,-0.03120,10.000
10,87.625,-0.01,-0.0002,-0.00020,10.000
10,87.750,-0.01,-0.0002,-0.00020,10.000
10,87.875,-0.01,-0.0002,-0.00020,10.000
10,88.000,0.00,-0.0002,-0.00020,10.000
10,88.125,0.00,-0.0002,-0.00020,10.000
10,88.250,-0.02,-0.0002,-0.00020,10.000
10,88.375,-0.01,-0.0002,-0.00020,10.000
10,88.500,-0.01,-0.0002,-0.00020,10.000
10,88.625,-0.01,-0.0002,-0.00020,10.000
10,88.750,-0.01,-0.0002,-0.00020,10.000
10,88.875,-0.01,-0.0002,-0.00020,10.000
10,89.000,0.00,-0.0002,-0.00020,10.000
10,89.125,-0.01,-0.0002,-0.00020,10.000
10,89.250,0.00,-0.0002,-0.00020,10.000
10,89.375,-0.01,-0.0002,-0.00020,10.000
10,89.500,0.00,-0.0002,-0.00020,10.000
10,89.625,0.00,-0.0002,-0.00020,10.000
10,89.750,-0.01,-0.0002,-0.00020,10.000
10,89.875,-0.01,-0.0001,-0.00010,10.000
10,90.000,0.00,-0.0001,-0.00010,10.000
10,90.125,0.00,-0.0001,-0.00010,10.000
10,90.250,0.00,-0.0001,-0.00010,10.000
10,90.375,-0.01,-0.0001,-0.00010,10.000
10,90.500,0.00,-0.0001,-0.00010,10.000