File: AIME_journal_files/AIME_data/calibDATA_loadcell/date_02:22:2018/Instron/1N_0_1_2_0.txt
""
"Test Method","Radhen_Load_Cntrl_Cmprsn_250N_12-7.msm"
"Sample I. D.","Sample1.mss"
"Specimen Number","10"

"TheCycle_Output ()","_Time (s)","_Load (N)","_Extension (mm)","RealTimeDepth (mm)","CycleNumber ()"

1,0.312,0.00,0.0709,0.07090,1.000
1,0.438,0.00,0.1960,0.19605,1.000
1,0.562,0.00,0.3211,0.32107,1.000
1,0.688,0.00,0.4461,0.44610,1.000
1,0.812,0.00,0.5710,0.57100,1.000
1,0.938,0.00,0.6961,0.69610,1.000
1,1.062,0.00,0.8211,0.82108,1.000
1,1.188,0.00,0.9463,0.94625,1.000
1,1.312,0.01,1.0712,1.07120,1.000
1,1.438,0.00,1.1961,1.19610,1.000
1,1.562,0.00,1.3211,1.32112,1.000
1,1.688,0.00,1.4462,1.44615,1.000
1,1.812,0.00,1.5712,1.57115,1.000
1,1.938,0.00,1.6961,1.69608,1.000
1,2.062,0.00,1.8210,1.82098,1.000
1,2.188,0.00,1.9462,1.94615,1.000
1,2.312,0.00,2.0712,2.07115,1.000
1,2.438,0.00,2.1962,2.19625,1.000
1,2.562,0.02,2.3212,2.32122,1.000
1,2.688,0.05,2.4464,2.44640,1.000
1,2.812,0.11,2.5713,2.57133,1.000
1,2.938,0.23,2.6962,2.69622,1.000
1,3.062,0.43,2.8211,2.82112,1.000
1,3.188,0.72,2.9462,2.94620,1.000
1,3.375,1.20,3.0814,3.08145,1.000
1,3.500,0.73,2.9595,2.95950,1.000
1,3.625,0.40,2.8345,2.83445,1.000
1,3.750,0.19,2.7095,2.70950,1.000
1,3.875,0.08,2.5844,2.58445,1.000
1,4.000,0.03,2.4595,2.45950,1.000
1,4.125,0.01,2.3345,2.33450,1.000
1,4.250,0.00,2.2095,2.20950,1.000
1,4.375,0.00,2.0846,2.08455,1.000
1,4.500,0.00,1.9596,1.95960,1.000
1,4.625,0.00,1.8344,1.83440,1.000
1,4.750,0.00,1.7095,1.70950,1.000
1,4.875,0.00,1.5844,1.58440,1.000
1,5.000,0.00,1.4593,1.45930,1.000
1,5.125,0.00,1.3344,1.33435,1.000
1,5.250,0.00,1.2094,1.20940,1.000
1,5.375,0.00,1.0845,1.08445,1.000
1,5.500,0.00,0.9595,0.95950,1.000
1,5.625,0.00,0.8344,0.83445,1.000
1,5.750,0.00,0.7095,0.70950,1.000
1,5.875,0.00,0.5843,0.58430,1.000
1,6.000,0.00,0.4593,0.45930,1.000
1,6.125,0.00,0.3342,0.33420,1.000
1,6.250,0.00,0.2093,0.20930,1.000
1,6.375,0.00,0.0842,0.08425,1.000
1,6.562,0.00,-0.0190,-0.01903,1.000
1,6.688,0.00,-0.0001,-0.00010,1.000
1,6.812,0.00,-0.0001,-0.00010,1.000
1,6.938,0.00,-0.0001,-0.00010,1.000
1,7.062,0.00,-0.0001,-0.00010,1.000
1,7.188,0.00,-0.0001,-0.00010,1.000
1,7.312,0.00,-0.0001,-0.00010,1.000
1,7.438,0.00,-0.0001,-0.00010,1.000
1,7.562,0.00,-0.0001,-0.00010,1.000
1,7.688,0.00,-0.0001,-0.00010,1.000
1,7.812,0.00,-0.0001,-0.00010,1.000
1,7.938,0.00,-0.0001,-0.00010,1.000
1,8.062,0.00,-0.0001,-0.00010,1.000
1,8.188,0.00,-0.0001,-0.00010,1.000
1,8.312,0.00,-0.0001,-0.00010,1.000
1,8.438,0.00,-0.0001,-0.00010,1.000
1,8.562,0.00,-0.0001,-0.00010,1.000
1,8.688,0.00,-0.0001,-0.00010,1.000
1,8.812,0.00,-0.0001,-0.00010,1.000
1,8.938,0.00,-0.0001,-0.00010,1.000
1,9.062,0.00,-0.0001,-0.00010,1.000
1,9.188,0.00,-0.0001,-0.00010,1.000
1,9.312,0.00,-0.0001,-0.00010,1.000
1,9.438,0.00,-0.0001,-0.00010,1.000
2,9.812,-0.01,0.0659,0.06592,2.000
2,9.938,-0.01,0.1911,0.19105,2.000
2,10.062,0.00,0.3161,0.31610,2.000
2,10.188,0.00,0.4412,0.44115,2.000
2,10.312,-0.01,0.5661,0.56615,2.000
2,10.438,0.00,0.6911,0.69113,2.000
2,10.562,0.00,0.8161,0.81610,2.000
2,10.688,0.00,0.9412,0.94118,2.000
2,10.812,0.00,1.0662,1.06620,2.000
2,10.938,0.00,1.1911,1.19108,2.000
2,11.062,0.00,1.3161,1.31612,2.000
2,11.188,-0.01,1.4413,1.44125,2.000
2,11.312,-0.01,1.5662,1.56625,2.000
2,11.438,0.00,1.6912,1.69123,2.000
2,11.562,-0.01,1.8161,1.81610,2.000
2,11.688,0.00,1.9411,1.94110,2.000
2,11.812,0.00,2.0661,2.06612,2.000
2,11.938,-0.01,2.1912,2.19118,2.000
2,12.062,0.01,2.3162,2.31622,2.000
2,12.188,0.04,2.4414,2.44140,2.000
2,12.312,0.10,2.5662,2.56622,2.000
2,12.438,0.22,2.6913,2.69130,2.000
2,12.562,0.42,2.8163,2.81627,2.000
2,12.688,0.70,2.9413,2.94125,2.000
2,12.875,1.18,3.0764,3.07640,2.000
2,13.000,0.72,2.9546,2.95460,2.000
2,13.125,0.39,2.8295,2.82945,2.000
2,13.250,0.18,2.7044,2.70440,2.000
2,13.375,0.06,2.5795,2.57945,2.000
2,13.500,0.02,2.4545,2.45450,2.000
2,13.625,0.01,2.3295,2.32950,2.000
2,13.750,0.00,2.2046,2.20460,2.000
2,13.875,0.00,2.0796,2.07955,2.000
2,14.000,0.00,1.9546,1.95460,2.000
2,14.125,0.00,1.8294,1.82935,2.000
2,14.250,-0.01,1.7044,1.70440,2.000
2,14.375,0.00,1.5793,1.57930,2.000
2,14.500,0.00,1.4544,1.45440,2.000
2,14.625,0.00,1.3294,1.32940,2.000
2,14.750,0.00,1.2045,1.20450,2.000
2,14.875,0.00,1.0795,1.07945,2.000
2,15.000,-0.01,0.9546,0.95460,2.000
2,15.125,0.00,0.8295,0.82945,2.000
2,15.250,0.00,0.7044,0.70440,2.000
2,15.375,0.00,0.5794,0.57935,2.000
2,15.500,0.00,0.4543,0.45430,2.000
2,15.625,0.00,0.3293,0.32930,2.000
2,15.750,0.00,0.2044,0.20440,2.000
2,15.875,0.00,0.0793,0.07930,2.000
2,16.062,0.00,-0.0238,-0.02385,2.000
2,16.188,0.00,-0.0001,-0.00010,2.000
2,16.312,0.00,-0.0001,-0.00010,2.000
2,16.438,0.00,-0.0001,-0.00010,2.000
2,16.562,0.00,-0.0001,-0.00010,2.000
2,16.688,0.00,-0.0001,-0.00010,2.000
2,16.812,0.00,-0.0001,-0.00010,2.000
2,16.938,0.00,-0.0001,-0.00010,2.000
2,17.062,0.00,-0.0001,-0.00010,2.000
2,17.188,-0.01,-0.0001,-0.00010,2.000
2,17.312,-0.01,-0.0001,-0.00010,2.000
2,17.438,0.00,-0.0001,-0.00010,2.000
2,17.562,0.00,-0.0001,-0.00010,2.000
2,17.688,-0.01,-0.0001,-0.00010,2.000
2,17.812,0.00,-0.0001,-0.00010,2.000
2,17.938,0.00,-0.0001,-0.00010,2.000
2,18.062,0.00,-0.0001,-0.00010,2.000
2,18.188,0.00,-0.0001,-0.00010,2.000
2,18.312,-0.01,-0.0001,-0.00010,2.000
2,18.438,-0.01,-0.0001,-0.00010,2.000
2,18.562,-0.01,-0.0001,-0.00010,2.000
2,18.688,-0.01,-0.0001,-0.00010,2.000
2,18.812,0.00,-0.0001,-0.00010,2.000
2,18.938,-0.01,-0.0001,-0.00010,2.000
3,19.312,0.00,0.0511,0.05105,3.000
3,19.438,0.00,0.1759,0.17595,3.000
3,19.562,0.00,0.3010,0.30100,3.000
3,19.688,0.00,0.4261,0.42612,3.000
3,19.812,0.00,0.5511,0.55105,3.000
3,19.938,0.00,0.6761,0.67610,3.000
3,20.062,0.00,0.8012,0.80123,3.000
3,20.188,0.00,0.9263,0.92630,3.000
3,20.312,0.00,1.0512,1.05118,3.000
3,20.438,0.00,1.1760,1.17605,3.000
3,20.562,0.01,1.3011,1.30105,3.000
3,20.688,0.01,1.4261,1.42615,3.000
3,20.812,0.00,1.5511,1.55110,3.000
3,20.938,0.00,1.6763,1.67627,3.000
3,21.062,0.00,1.8012,1.80123,3.000
3,21.188,0.00,1.9262,1.92620,3.000
3,21.312,0.00,2.0512,2.05118,3.000
3,21.438,0.00,2.1762,2.17617,3.000
3,21.562,0.01,2.3011,2.30113,3.000
3,21.688,0.04,2.4262,2.42620,3.000
3,21.812,0.09,2.5512,2.55123,3.000
3,21.938,0.21,2.6762,2.67620,3.000
3,22.062,0.39,2.8013,2.80125,3.000
3,22.188,0.67,2.9264,2.92637,3.000
3,22.312,1.04,3.0515,3.05145,3.000
3,22.500,0.81,2.9795,2.97950,3.000
3,22.625,0.45,2.8545,2.85450,3.000
3,22.750,0.22,2.7296,2.72960,3.000
3,22.875,0.09,2.6045,2.60455,3.000
3,23.000,0.03,2.4796,2.47960,3.000
3,23.125,0.01,2.3545,2.35455,3.000
3,23.250,0.01,2.2294,2.22940,3.000
3,23.375,0.00,2.1044,2.10440,3.000
3,23.500,0.00,1.9793,1.97930,3.000
3,23.625,0.00,1.8544,1.85435,3.000
3,23.750,0.00,1.7294,1.72940,3.000
3,23.875,0.00,1.6045,1.60445,3.000
3,24.000,0.00,1.4794,1.47940,3.000
3,24.125,0.00,1.3544,1.35435,3.000
3,24.250,0.00,1.2293,1.22930,3.000
3,24.375,0.00,1.1043,1.10430,3.000
3,24.500,0.00,0.9794,0.97940,3.000
3,24.625,0.00,0.8544,0.85440,3.000
3,24.750,0.00,0.7294,0.72940,3.000
3,24.875,0.00,0.6044,0.60440,3.000
3,25.000,0.00,0.4795,0.47950,3.000
3,25.125,0.00,0.3544,0.35435,3.000
3,25.250,0.00,0.2293,0.22930,3.000
3,25.375,0.00,0.1042,0.10420,3.000
3,25.500,0.00,-0.0207,-0.02070,3.000
3,25.688,0.00,-0.0001,-0.00010,3.000
3,25.812,0.00,-0.0001,-0.00010,3.000
3,25.938,0.00,-0.0001,-0.00010,3.000
3,26.062,0.00,-0.0001,-0.00010,3.000
3,26.188,0.00,-0.0001,-0.00010,3.000
3,26.312,0.00,-0.0001,-0.00010,3.000
3,26.438,0.00,-0.0001,-0.00010,3.000
3,26.562,0.00,-0.0001,-0.00010,3.000
3,26.688,0.00,-0.0001,-0.00010,3.000
3,26.812,0.00,-0.0001,-0.00010,3.000
3,26.938,0.00,-0.0001,-0.00010,3.000
3,27.062,0.00,-0.0001,-0.00010,3.000
3,27.188,0.00,-0.0001,-0.00010,3.000
3,27.312,0.00,-0.0001,-0.00010,3.000
3,27.438,0.00,-0.0001,-0.00010,3.000
3,27.562,0.00,-0.0001,-0.00010,3.000
3,27.688,0.00,-0.0001,-0.00010,3.000
3,27.812,0.00,-0.0001,-0.00010,3.000
3,27.938,0.00,-0.0001,-0.00010,3.000
3,28.062,0.00,-0.0001,-0.00010,3.000
3,28.188,0.00,-0.0001,-0.00010,3.000
3,28.312,0.00,-0.0001,-0.00010,3.000
3,28.438,0.00,-0.0001,-0.00010,3.000
3,28.562,0.00,-0.0001,-0.00010,3.000
4,28.812,0.00,0.0312,0.03122,4.000
4,28.938,0.00,0.1561,0.15612,4.000
4,29.062,0.00,0.2810,0.28102,4.000
4,29.188,0.00,0.4061,0.40612,4.000
4,29.312,-0.01,0.5311,0.53107,4.000
4,29.438,0.00,0.6560,0.65605,4.000
4,29.562,0.00,0.7811,0.78112,4.000
4,29.688,0.00,0.9062,0.90617,4.000
4,29.812,0.00,1.0313,1.03127,4.000
4,29.938,0.00,1.1561,1.15610,4.000
4,30.062,0.00,1.2812,1.28117,4.000
4,30.188,0.00,1.4062,1.40625,4.000
4,30.312,0.00,1.5312,1.53117,4.000
4,30.438,0.00,1.6562,1.65620,4.000
4,30.562,0.00,1.7811,1.78110,4.000
4,30.688,0.00,1.9062,1.90617,4.000
4,30.812,0.00,2.0312,2.03120,4.000
4,30.938,0.00,2.1562,2.15620,4.000
4,31.062,0.01,2.2813,2.28127,4.000
4,31.188,0.04,2.4064,2.40637,4.000
4,31.312,0.08,2.5313,2.53130,4.000
4,31.438,0.18,2.6562,2.65617,4.000
4,31.562,0.35,2.7812,2.78120,4.000
4,31.688,0.62,2.9062,2.90625,4.000
4,31.812,0.98,3.0313,3.03130,4.000
4,32.000,0.94,3.0196,3.01960,4.000
4,32.125,0.54,2.8946,2.89455,4.000
4,32.250,0.28,2.7695,2.76950,4.000
4,32.375,0.12,2.6445,2.64450,4.000
4,32.500,0.04,2.5196,2.51960,4.000
4,32.625,0.01,2.3945,2.39455,4.000
4,32.750,0.00,2.2693,2.26930,4.000
4,32.875,0.00,2.1444,2.14445,4.000
4,33.000,0.00,2.0194,2.01940,4.000
4,33.125,0.00,1.8944,1.89435,4.000
4,33.250,0.00,1.7694,1.76940,4.000
4,33.375,0.00,1.6445,1.64450,4.000
4,33.500,0.00,1.5195,1.51950,4.000
4,33.625,0.00,1.3944,1.39445,4.000
4,33.750,0.00,1.2694,1.26940,4.000
4,33.875,0.00,1.1442,1.14425,4.000
4,34.000,0.00,1.0194,1.01940,4.000
4,34.125,0.00,0.8944,0.89435,4.000
4,34.250,0.00,0.7695,0.76950,4.000
4,34.375,0.00,0.6444,0.64440,4.000
4,34.500,0.00,0.5194,0.51940,4.000
4,34.625,0.00,0.3944,0.39440,4.000
4,34.750,0.00,0.2693,0.26930,4.000
4,34.875,0.00,0.1442,0.14420,4.000
4,35.000,0.00,0.0192,0.01920,4.000
4,35.188,0.00,-0.0001,-0.00010,4.000
4,35.312,0.00,-0.0001,-0.00010,4.000
4,35.438,0.00,-0.0001,-0.00010,4.000
4,35.562,0.00,-0.0001,-0.00010,4.000
4,35.688,0.00,-0.0001,-0.00010,4.000
4,35.812,0.00,-0.0001,-0.00010,4.000
4,35.938,0.00,-0.0001,-0.00010,4.000
4,36.062,0.00,-0.0001,-0.00010,4.000
4,36.188,0.00,-0.0001,-0.00010,4.000
4,36.312,0.00,-0.0001,-0.00010,4.000
4,36.438,0.00,-0.0001,-0.00010,4.000
4,36.562,0.00,-0.0001,-0.00010,4.000
4,36.688,0.00,-0.0001,-0.00010,4.000
4,36.812,0.00,-0.0001,-0.00010,4.000
4,36.938,0.00,-0.0001,-0.00010,4.000
4,37.062,0.00,-0.0001,-0.00010,4.000
4,37.188,0.00,-0.0001,-0.00010,4.000
4,37.312,0.00,-0.0001,-0.00010,4.000
4,37.438,0.00,-0.0001,-0.00010,4.000
4,37.562,0.00,-0.0001,-0.00010,4.000
4,37.688,0.00,-0.0001,-0.00010,4.000
4,37.812,0.00,-0.0001,-0.00010,4.000
4,37.938,0.00,-0.0001,-0.00010,4.000
4,38.062,0.00,-0.0001,-0.00010,4.000
5,38.438,0.00,0.1109,0.11090,5.000
5,38.562,0.00,0.2360,0.23602,5.000
5,38.688,0.00,0.3612,0.36118,5.000
5,38.812,0.00,0.4861,0.48610,5.000
5,38.938,0.00,0.6111,0.61108,5.000
5,39.062,0.00,0.7361,0.73610,5.000
5,39.188,0.00,0.8611,0.86105,5.000
5,39.312,0.00,0.9862,0.98620,5.000
5,39.438,0.00,1.1112,1.11115,5.000
5,39.562,0.00,1.2362,1.23620,5.000
5,39.688,0.01,1.3613,1.36125,5.000
5,39.812,0.00,1.4862,1.48620,5.000
5,39.938,0.00,1.6113,1.61128,5.000
5,40.062,0.00,1.7362,1.73622,5.000
5,40.188,0.00,1.8611,1.86110,5.000
5,40.312,0.00,1.9861,1.98610,5.000
5,40.438,0.00,2.1113,2.11128,5.000
5,40.562,0.00,2.2363,2.23627,5.000
5,40.688,0.03,2.3613,2.36133,5.000
5,40.812,0.06,2.4863,2.48632,5.000
5,40.938,0.14,2.6113,2.61130,5.000
5,41.062,0.29,2.7363,2.73630,5.000
5,41.188,0.51,2.8612,2.86118,5.000
5,41.312,0.84,2.9862,2.98622,5.000
5,41.500,1.02,3.0342,3.03420,5.000
5,41.625,0.59,2.9095,2.90945,5.000
5,41.750,0.31,2.7844,2.78440,5.000
5,41.875,0.14,2.6594,2.65935,5.000
5,42.000,0.05,2.5346,2.53460,5.000
5,42.125,0.02,2.4096,2.40960,5.000
5,42.250,0.01,2.2845,2.28450,5.000
5,42.375,0.01,2.1596,2.15955,5.000
5,42.500,0.01,2.0344,2.03440,5.000
5,42.625,0.00,1.9094,1.90935,5.000
5,42.750,0.00,1.7843,1.78430,5.000
5,42.875,0.00,1.6594,1.65940,5.000
5,43.000,0.00,1.5344,1.53440,5.000
5,43.125,0.00,1.4094,1.40945,5.000
5,43.250,0.00,1.2844,1.28440,5.000
5,43.375,0.00,1.1594,1.15940,5.000
5,43.500,0.00,1.0345,1.03450,5.000
5,43.625,0.00,0.9094,0.90935,5.000
5,43.750,0.00,0.7843,0.78430,5.000
5,43.875,0.00,0.6594,0.65935,5.000
5,44.000,0.01,0.5343,0.53430,5.000
5,44.125,0.00,0.4094,0.40940,5.000
5,44.250,0.00,0.2844,0.28440,5.000
5,44.375,0.00,0.1594,0.15935,5.000
5,44.500,0.00,0.0344,0.03440,5.000
5,44.688,0.00,0.0004,0.00038,5.000
5,44.812,0.00,-0.0001,-0.00010,5.000
5,44.938,0.01,0.0000,0.00000,5.000
5,45.062,0.00,0.0000,0.00000,5.000
5,45.188,0.00,0.0000,0.00000,5.000
5,45.312,0.00,0.0000,0.00000,5.000
5,45.438,0.00,0.0000,0.00000,5.000
5,45.562,0.00,0.0000,0.00000,5.000
5,45.688,0.00,0.0000,0.00000,5.000
5,45.812,0.00,0.0000,0.00000,5.000
5,45.938,0.00,0.0000,0.00000,5.000
5,46.062,0.00,0.0000,0.00000,5.000
5,46.188,0.00,0.0000,0.00000,5.000
5,46.312,0.00,0.0000,0.00000,5.000
5,46.438,0.00,0.0000,0.00000,5.000
5,46.562,0.00,0.0000,0.00000,5.000
5,46.688,0.00,0.0000,0.00000,5.000
5,46.812,0.00,0.0000,0.00000,5.000
5,46.938,0.00,0.0000,0.00000,5.000
5,47.062,0.00,0.0000,0.00000,5.000
5,47.188,0.00,0.0000,0.00000,5.000
5,47.312,0.00,0.0000,0.00000,5.000
5,47.438,0.00,0.0000,0.00000,5.000
5,47.562,0.00,0.0000,0.00000,5.000
6,47.938,0.00,0.1109,0.11090,6.000
6,48.062,0.00,0.2360,0.23600,6.000
6,48.188,0.00,0.3611,0.36110,6.000
6,48.312,0.00,0.4861,0.48615,6.000
6,48.438,0.00,0.6111,0.61110,6.000
6,48.562,0.00,0.7361,0.73607,6.000
6,48.688,0.00,0.8610,0.86098,6.000
6,48.812,0.00,0.9862,0.98620,6.000
6,48.938,0.00,1.1111,1.11108,6.000
6,49.062,0.00,1.2362,1.23617,6.000
6,49.188,0.00,1.3611,1.36113,6.000
6,49.312,0.00,1.4862,1.48617,6.000
6,49.438,0.00,1.6112,1.61120,6.000
6,49.562,0.00,1.7362,1.73617,6.000
6,49.688,0.00,1.8611,1.86105,6.000
6,49.812,0.00,1.9861,1.98610,6.000
6,49.938,0.00,2.1111,2.11110,6.000
6,50.062,0.00,2.2360,2.23605,6.000
6,50.188,0.02,2.3613,2.36125,6.000
6,50.312,0.06,2.4863,2.48632,6.000
6,50.438,0.13,2.6112,2.61123,6.000
6,50.562,0.28,2.7362,2.73620,6.000
6,50.688,0.51,2.8612,2.86120,6.000
6,50.812,0.83,2.9863,2.98627,6.000
6,51.000,1.02,3.0342,3.03420,6.000
6,51.125,0.59,2.9094,2.90940,6.000
6,51.250,0.31,2.7844,2.78440,6.000
6,51.375,0.13,2.6594,2.65940,6.000
6,51.500,0.05,2.5344,2.53440,6.000
6,51.625,0.02,2.4097,2.40965,6.000
6,51.750,0.00,2.2845,2.28450,6.000
6,51.875,0.00,2.1596,2.15955,6.000
6,52.000,0.00,2.0344,2.03440,6.000
6,52.125,0.00,1.9094,1.90935,6.000
6,52.250,0.00,1.7842,1.78420,6.000
6,52.375,0.00,1.6593,1.65930,6.000
6,52.500,0.00,1.5343,1.53430,6.000
6,52.625,0.00,1.4094,1.40940,6.000
6,52.750,0.00,1.2844,1.28440,6.000
6,52.875,0.00,1.1594,1.15935,6.000
6,53.000,0.00,1.0346,1.03460,6.000
6,53.125,0.00,0.9093,0.90930,6.000
6,53.250,0.00,0.7843,0.78430,6.000
6,53.375,0.00,0.6593,0.65930,6.000
6,53.500,0.00,0.5343,0.53430,6.000
6,53.625,0.00,0.4094,0.40940,6.000
6,53.750,-0.01,0.2844,0.28440,6.000
6,53.875,0.00,0.1594,0.15935,6.000
6,54.000,-0.01,0.0344,0.03440,6.000
6,54.188,-0.01,0.0003,0.00028,6.000
6,54.312,-0.01,-0.0001,-0.00010,6.000
6,54.438,0.00,-0.0001,-0.00010,6.000
6,54.562,0.00,-0.0001,-0.00010,6.000
6,54.688,0.00,-0.0001,-0.00010,6.000
6,54.812,-0.01,-0.0001,-0.00010,6.000
6,54.938,0.00,-0.0001,-0.00010,6.000
6,55.062,-0.01,-0.0001,-0.00010,6.000
6,55.188,0.00,-0.0001,-0.00010,6.000
6,55.312,0.00,-0.0001,-0.00010,6.000
6,55.438,0.00,-0.0001,-0.00010,6.000
6,55.562,0.00,-0.0001,-0.00010,6.000
6,55.688,0.00,-0.0001,-0.00010,6.000
6,55.812,0.00,-0.0001,-0.00010,6.000
6,55.938,0.00,-0.0001,-0.00010,6.000
6,56.062,0.00,-0.0001,-0.00010,6.000
6,56.188,0.00,-0.0001,-0.00010,6.000
6,56.312,0.00,-0.0001,-0.00010,6.000
6,56.438,0.00,-0.0001,-0.00010,6.000
6,56.562,-0.01,-0.0001,-0.00010,6.000
6,56.688,0.00,-0.0001,-0.00010,6.000
6,56.812,0.00,-0.0001,-0.00010,6.000
6,56.938,0.00,-0.0001,-0.00010,6.000
6,57.062,0.00,-0.0001,-0.00010,6.000
7,57.438,0.00,0.1109,0.11090,7.000
7,57.562,0.00,0.2361,0.23610,7.000
7,57.688,0.00,0.3612,0.36115,7.000
7,57.812,-0.01,0.4861,0.48615,7.000
7,57.938,0.00,0.6112,0.61115,7.000
7,58.062,0.00,0.7361,0.73610,7.000
7,58.188,-0.01,0.8612,0.86118,7.000
7,58.312,0.00,0.9862,0.98620,7.000
7,58.438,0.00,1.1111,1.11110,7.000
7,58.562,0.00,1.2362,1.23617,7.000
7,58.688,0.00,1.3612,1.36123,7.000
7,58.812,0.00,1.4862,1.48620,7.000
7,58.938,0.00,1.6112,1.61123,7.000
7,59.062,0.00,1.7362,1.73620,7.000
7,59.188,0.00,1.8610,1.86103,7.000
7,59.312,0.00,1.9861,1.98612,7.000
7,59.438,-0.01,2.1112,2.11120,7.000
7,59.562,0.00,2.2362,2.23625,7.000
7,59.688,0.02,2.3613,2.36133,7.000
7,59.812,0.06,2.4864,2.48637,7.000
7,59.938,0.14,2.6113,2.61128,7.000
7,60.062,0.28,2.7363,2.73632,7.000
7,60.188,0.51,2.8612,2.86118,7.000
7,60.312,0.84,2.9862,2.98620,7.000
7,60.500,1.02,3.0342,3.03420,7.000
7,60.625,0.59,2.9095,2.90945,7.000
7,60.750,0.30,2.7844,2.78440,7.000
7,60.875,0.13,2.6594,2.65940,7.000
7,61.000,0.05,2.5345,2.53450,7.000
7,61.125,0.01,2.4097,2.40965,7.000
7,61.250,0.00,2.2845,2.28450,7.000
7,61.375,0.00,2.1595,2.15950,7.000
7,61.500,0.00,2.0344,2.03440,7.000
7,61.625,0.00,1.9094,1.90935,7.000
7,61.750,0.00,1.7843,1.78430,7.000
7,61.875,0.00,1.6594,1.65940,7.000
7,62.000,0.00,1.5345,1.53450,7.000
7,62.125,-0.01,1.4095,1.40945,7.000
7,62.250,0.00,1.2845,1.28450,7.000
7,62.375,-0.01,1.1594,1.15940,7.000
7,62.500,0.00,1.0345,1.03450,7.000
7,62.625,0.00,0.9094,0.90940,7.000
7,62.750,-0.01,0.7843,0.78430,7.000
7,62.875,0.00,0.6593,0.65930,7.000
7,63.000,0.00,0.5343,0.53430,7.000
7,63.125,0.00,0.4095,0.40945,7.000
7,63.250,0.00,0.2843,0.28430,7.000
7,63.375,0.00,0.1594,0.15935,7.000
7,63.500,0.00,0.0343,0.03430,7.000
7,63.688,0.00,0.0003,0.00030,7.000
7,63.812,0.00,-0.0001,-0.00010,7.000
7,63.938,0.00,-0.0001,-0.00010,7.000
7,64.062,0.00,-0.0001,-0.00010,7.000
7,64.188,0.00,-0.0001,-0.00010,7.000
7,64.312,0.00,-0.0001,-0.00010,7.000
7,64.438,0.00,-0.0001,-0.00010,7.000
7,64.562,0.00,-0.0001,-0.00010,7.000
7,64.688,-0.01,-0.0001,-0.00010,7.000
7,64.812,0.00,-0.0001,-0.00010,7.000
7,64.938,0.00,-0.0001,-0.00010,7.000
7,65.062,0.00,-0.0001,-0.00010,7.000
7,65.188,-0.01,-0.0001,-0.00010,7.000
7,65.312,0.00,-0.0001,-0.00010,7.000
7,65.438,0.00,-0.0001,-0.00010,7.000
7,65.562,-0.01,-0.0001,-0.00010,7.000
7,65.688,0.00,-0.0001,-0.00010,7.000
7,65.812,-0.01,-0.0001,-0.00010,7.000
7,65.938,0.00,-0.0001,-0.00010,7.000
7,66.062,0.00,-0.0001,-0.00010,7.000
7,66.188,-0.01,-0.0001,-0.00010,7.000
7,66.312,0.00,-0.0001,-0.00010,7.000
7,66.438,0.00,-0.0001,-0.00010,7.000
7,66.562,0.00,-0.0001,-0.00010,7.000
8,67.000,0.00,0.1635,0.16350,8.000
8,67.125,0.01,0.2886,0.28855,8.000
8,67.250,0.01,0.4137,0.41370,8.000
8,67.375,0.00,0.5385,0.53850,8.000
8,67.500,0.00,0.6636,0.66360,8.000
8,67.625,0.01,0.7887,0.78865,8.000
8,67.750,0.01,0.9136,0.91360,8.000
8,67.875,0.01,1.0388,1.03880,8.000
8,68.000,0.01,1.1636,1.16360,8.000
8,68.125,0.01,1.2887,1.28865,8.000
8,68.250,0.01,1.4137,1.41370,8.000
8,68.375,0.01,1.5386,1.53865,8.000
8,68.500,0.01,1.6636,1.66360,8.000
8,68.625,0.01,1.7886,1.78860,8.000
8,68.750,0.00,1.9135,1.91350,8.000
8,68.875,0.00,2.0386,2.03865,8.000
8,69.000,0.01,2.1637,2.16370,8.000
8,69.125,0.02,2.2888,2.28875,8.000
8,69.250,0.04,2.4139,2.41390,8.000
8,69.375,0.09,2.5388,2.53880,8.000
8,69.500,0.19,2.6636,2.66360,8.000
8,69.625,0.38,2.7887,2.78870,8.000
8,69.750,0.65,2.9138,2.91380,8.000
8,69.875,1.01,3.0388,3.03880,8.000
8,70.062,0.89,3.0021,3.00205,8.000
8,70.188,0.51,2.8770,2.87695,8.000
8,70.312,0.26,2.7519,2.75193,8.000
8,70.438,0.11,2.6270,2.62695,8.000
8,70.562,0.04,2.5020,2.50203,8.000
8,70.688,0.02,2.3770,2.37702,8.000
8,70.812,0.01,2.2520,2.25195,8.000
8,70.938,0.01,2.1271,2.12708,8.000
8,71.062,0.00,2.0020,2.00198,8.000
8,71.188,0.01,1.8769,1.87690,8.000
8,71.312,0.00,1.7520,1.75195,8.000
8,71.438,0.01,1.6268,1.62683,8.000
8,71.562,0.01,1.5018,1.50175,8.000
8,71.688,0.00,1.3768,1.37685,8.000
8,71.812,0.01,1.2519,1.25190,8.000
8,71.938,0.01,1.1269,1.12692,8.000
8,72.062,0.01,1.0020,1.00198,8.000
8,72.188,0.00,0.8769,0.87690,8.000
8,72.312,0.00,0.7519,0.75190,8.000
8,72.438,0.01,0.6267,0.62672,8.000
8,72.562,0.01,0.5018,0.50175,8.000
8,72.688,0.01,0.3768,0.37685,8.000
8,72.812,0.00,0.2518,0.25183,8.000
8,72.938,0.01,0.1268,0.12680,8.000
8,73.062,0.01,0.0019,0.00185,8.000
8,73.250,0.01,-0.0001,-0.00010,8.000
8,73.375,0.00,-0.0001,-0.00010,8.000
8,73.500,0.00,-0.0001,-0.00010,8.000
8,73.625,0.00,-0.0001,-0.00010,8.000
8,73.750,0.00,-0.0001,-0.00010,8.000
8,73.875,0.01,-0.0001,-0.00010,8.000
8,74.000,0.00,-0.0001,-0.00010,8.000
8,74.125,0.00,-0.0001,-0.00010,8.000
8,74.250,0.01,-0.0001,-0.00010,8.000
8,74.375,0.01,-0.0001,-0.00010,8.000
8,74.500,0.00,-0.0001,-0.00010,8.000
8,74.625,0.01,-0.0001,-0.00010,8.000
8,74.750,0.01,-0.0001,-0.00010,8.000
8,74.875,0.01,-0.0001,-0.00010,8.000
8,75.000,0.01,-0.0001,-0.00010,8.000
8,75.125,0.01,-0.0001,-0.00010,8.000
8,75.250,0.00,-0.0001,-0.00010,8.000
8,75.375,0.01,-0.0001,-0.00010,8.000
8,75.500,0.01,-0.0001,-0.00010,8.000
8,75.625,0.01,-0.0001,-0.00010,8.000
8,75.750,0.01,-0.0001,-0.00010,8.000
8,75.875,0.01,-0.0001,-0.00010,8.000
8,76.000,0.01,-0.0001,-0.00010,8.000
8,76.125,0.00,-0.0001,-0.00010,8.000
9,76.500,0.00,0.1335,0.13350,9.000
9,76.625,0.00,0.2585,0.25850,9.000
9,76.750,-0.01,0.3836,0.38360,9.000
9,76.875,0.00,0.5086,0.50855,9.000
9,77.000,0.00,0.6336,0.63360,9.000
9,77.125,0.00,0.7587,0.75870,9.000
9,77.250,0.00,0.8838,0.88380,9.000
9,77.375,0.00,1.0088,1.00880,9.000
9,77.500,0.00,1.1337,1.13370,9.000
9,77.625,0.00,1.2586,1.25860,9.000
9,77.750,0.00,1.3836,1.38360,9.000
9,77.875,0.00,1.5086,1.50865,9.000
9,78.000,0.00,1.6337,1.63370,9.000
9,78.125,0.00,1.7587,1.75870,9.000
9,78.250,0.00,1.8837,1.88370,9.000
9,78.375,0.00,2.0088,2.00875,9.000
9,78.500,0.00,2.1338,2.13380,9.000
9,78.625,0.00,2.2587,2.25870,9.000
9,78.750,0.03,2.3837,2.38370,9.000
9,78.875,0.07,2.5088,2.50875,9.000
9,79.000,0.16,2.6337,2.63370,9.000
9,79.125,0.32,2.7587,2.75870,9.000
9,79.250,0.57,2.8837,2.88370,9.000
9,79.375,0.91,3.0089,3.00890,9.000
9,79.625,0.77,2.9696,2.96960,9.000
9,79.750,0.43,2.8445,2.84450,9.000
9,79.875,0.20,2.7195,2.71950,9.000
9,80.000,0.08,2.5944,2.59440,9.000
9,80.125,0.03,2.4694,2.46945,9.000
9,80.250,0.01,2.3445,2.34450,9.000
9,80.375,0.00,2.2194,2.21940,9.000
9,80.500,0.00,2.0945,2.09450,9.000
9,80.625,0.00,1.9695,1.96950,9.000
9,80.750,0.00,1.8444,1.84440,9.000
9,80.875,0.00,1.7195,1.71950,9.000
9,81.000,0.00,1.5943,1.59430,9.000
9,81.125,0.00,1.4694,1.46935,9.000
9,81.250,0.00,1.3443,1.34430,9.000
9,81.375,0.00,1.2193,1.21930,9.000
9,81.500,0.00,1.0943,1.09430,9.000
9,81.625,0.00,0.9696,0.96955,9.000
9,81.750,0.00,0.8445,0.84450,9.000
9,81.875,0.00,0.7194,0.71945,9.000
9,82.000,0.00,0.5944,0.59440,9.000
9,82.125,0.00,0.4694,0.46940,9.000
9,82.250,0.00,0.3441,0.34410,9.000
9,82.375,0.00,0.2192,0.21920,9.000
9,82.500,0.00,0.0943,0.09430,9.000
9,82.750,-0.01,-0.0022,-0.00220,9.000
9,82.875,0.00,-0.0001,-0.00010,9.000
9,83.000,0.00,-0.0001,-0.00010,9.000
9,83.125,0.00,-0.0001,-0.00010,9.000
9,83.250,0.00,-0.0001,-0.00010,9.000
9,83.375,0.00,-0.0001,-0.00010,9.000
9,83.500,0.00,-0.0001,-0.00010,9.000
9,83.625,0.00,-0.0001,-0.00010,9.000
9,83.750,0.00,-0.0001,-0.00010,9.000
9,83.875,0.00,-0.0001,-0.00010,9.000
9,84.000,0.00,-0.0001,-0.00010,9.000
9,84.125,0.00,-0.0001,-0.00010,9.000
9,84.250,0.00,-0.0001,-0.00010,9.000
9,84.375,0.00,-0.0001,-0.00010,9.000
9,84.500,0.00,-0.0001,-0.00010,9.000
9,84.625,0.00,-0.0001,-0.00010,9.000
9,84.750,0.00,-0.0001,-0.00010,9.000
9,84.875,0.00,-0.0001,-0.00010,9.000
9,85.000,0.00,-0.0001,-0.00010,9.000
9,85.125,0.00,-0.0001,-0.00010,9.000
9,85.250,0.00,-0.0001,-0.00010,9.000
9,85.375,0.00,-0.0001,-0.00010,9.000
9,85.500,0.00,-0.0001,-0.00010,9.000
9,85.625,0.00,-0.0001,-0.00010,9.000
10,85.938,0.00,0.0501,0.05008,10.000
10,86.062,0.00,0.1750,0.17500,10.000
10,86.188,0.00,0.3000,0.30000,10.000
10,86.312,0.00,0.4250,0.42502,10.000
10,86.438,0.00,0.5501,0.55008,10.000
10,86.562,0.00,0.6752,0.67520,10.000
10,86.688,0.00,0.8003,0.80025,10.000
10,86.812,0.00,0.9252,0.92520,10.000
10,86.938,0.00,1.0503,1.05030,10.000
10,87.062,0.00,1.1751,1.17515,10.000
10,87.188,0.00,1.3000,1.30005,10.000
10,87.312,0.00,1.4251,1.42507,10.000
10,87.438,0.00,1.5501,1.55008,10.000
10,87.562,0.00,1.6753,1.67530,10.000
10,87.688,0.00,1.8001,1.80010,10.000
10,87.812,0.00,1.9252,1.92520,10.000
10,87.938,0.00,2.0502,2.05020,10.000
10,88.062,0.00,2.1753,2.17535,10.000
10,88.188,0.01,2.3002,2.30020,10.000
10,88.312,0.04,2.4253,2.42535,10.000
10,88.438,0.09,2.5502,2.55022,10.000
10,88.562,0.21,2.6751,2.67515,10.000
10,88.688,0.40,2.8002,2.80025,10.000
10,88.812,0.67,2.9253,2.92527,10.000
10,88.938,1.04,3.0505,3.05048,10.000
10,89.125,0.84,2.9885,2.98850,10.000
10,89.250,0.47,2.8633,2.86330,10.000
10,89.375,0.23,2.7385,2.73850,10.000
10,89.500,0.09,2.6135,2.61350,10.000
10,89.625,0.04,2.4887,2.48865,10.000
10,89.750,0.01,2.3635,2.36350,10.000
10,89.875,0.00,2.2385,2.23845,10.000
10,90.000,0.00,2.1135,2.11350,10.000
10,90.125,0.00,1.9884,1.98835,10.000
10,90.250,0.00,1.8633,1.86330,10.000
10,90.375,0.00,1.7384,1.73845,10.000
10,90.500,0.00,1.6134,1.61340,10.000
10,90.625,0.00,1.4886,1.48855,10.000
10,90.750,0.00,1.3634,1.36340,10.000
10,90.875,0.00,1.2384,1.23840,10.000
10,91.000,0.00,1.1133,1.11330,10.000
10,91.125,0.00,0.9884,0.98840,10.000
10,91.250,0.00,0.8633,0.86330,10.000
10,91.375,0.00,0.7384,0.73840,10.000
10,91.500,0.00,0.6133,0.61330,10.000
10,91.625,0.00,0.4884,0.48840,10.000
10,91.750,0.00,0.3634,0.36340,10.000
10,91.875,0.00,0.2384,0.23835,10.000
10,92.000,0.00,0.1132,0.11320,10.000
10,92.125,0.00,-0.0116,-0.01165,10.000
10,92.312,0.00,0.0002,0.00023,10.000
10,92.438,0.00,0.0000,0.00000,10.000
10,92.562,0.00,0.0000,0.00000,10.000
10,92.688,0.00,-0.0001,-0.00010,10.000
10,92.812,0.00,0.0000,-0.00002,10.000
10,92.938,0.00,0.0000,-0.00002,10.000
10,93.062,0.00,0.0000,0.00000,10.000
10,93.188,0.00,0.0000,-0.00002,10.000
10,93.312,0.00,0.0000,0.00000,10.000
10,93.438,0.00,0.0000,0.00000,10.000
10,93.562,0.00,0.0000,0.00000,10.000
10,93.688,0.00,0.0000,0.00000,10.000
10,93.812,0.00,0.0000,0.00000,10.000
10,93.938,0.00,0.0000,0.00000,10.000
10,94.062,0.00,0.0000,0.00000,10.000
10,94.188,0.00,0.0000,0.00000,10.000
10,94.312,0.00,0.0000,0.00000,10.000
10,94.438,0.00,0.0000,0.00000,10.000
10,94.562,0.00,0.0000,0.00000,10.000
10,94.688,0.00,0.0000,0.00000,10.000
10,94.812,0.00,0.0000,0.00000,10.000
10,94.938,0.00,0.0000,0.00000,10.000
10,95.062,0.00,0.0000,0.00000,10.000
10,95.188,0.00,0.0000,0.00000,10.000