File: AIME_journal_files/AIME_data/calibDATA_loadcell/date_02:22:2018/Instron/30N_0_1_2_0.txt
""
"Test Method","Radhen_Load_Cntrl_Cmprsn_250N_12-7.msm"
"Sample I. D.","Sample1.mss"
"Specimen Number","8"

"TheCycle_Output ()","_Time (s)","_Load (N)","_Extension (mm)","RealTimeDepth (mm)","CycleNumber ()"

1,0.312,0.00,0.0711,0.07108,1.000
1,0.438,0.00,0.1960,0.19605,1.000
1,0.562,0.00,0.3211,0.32112,1.000
1,0.688,0.00,0.4462,0.44618,1.000
1,0.812,0.00,0.5712,0.57120,1.000
1,0.938,0.00,0.6963,0.69628,1.000
1,1.062,0.00,0.8214,0.82135,1.000
1,1.188,0.00,0.9464,0.94640,1.000
1,1.312,0.00,1.0714,1.07135,1.000
1,1.438,0.01,1.1962,1.19615,1.000
1,1.562,0.00,1.3211,1.32115,1.000
1,1.688,0.00,1.4462,1.44620,1.000
1,1.812,0.00,1.5712,1.57125,1.000
1,1.938,0.00,1.6963,1.69630,1.000
1,2.062,0.00,1.8213,1.82130,1.000
1,2.188,0.00,1.9463,1.94630,1.000
1,2.312,0.00,2.0714,2.07135,1.000
1,2.438,0.00,2.1962,2.19625,1.000
1,2.562,0.02,2.3212,2.32122,1.000
1,2.688,0.05,2.4464,2.44638,1.000
1,2.812,0.12,2.5713,2.57130,1.000
1,2.938,0.24,2.6963,2.69630,1.000
1,3.062,0.45,2.8213,2.82132,1.000
1,3.188,0.74,2.9464,2.94640,1.000
1,3.312,1.13,3.0715,3.07150,1.000
1,3.438,1.61,3.1964,3.19635,1.000
1,3.562,2.23,3.3213,3.32130,1.000
1,3.688,2.98,3.4462,3.44620,1.000
1,3.812,3.86,3.5713,3.57130,1.000
1,3.938,4.88,3.6964,3.69638,1.000
1,4.062,6.06,3.8213,3.82135,1.000
1,4.188,7.40,3.9464,3.94637,1.000
1,4.312,8.93,4.0714,4.07137,1.000
1,4.438,10.67,4.1964,4.19635,1.000
1,4.562,12.61,4.3214,4.32138,1.000
1,4.688,14.78,4.4462,4.44625,1.000
1,4.812,17.18,4.5712,4.57122,1.000
1,4.938,19.88,4.6963,4.69630,1.000
1,5.062,22.91,4.8214,4.82142,1.000
1,5.188,26.32,4.9465,4.94650,1.000
1,5.312,30.24,5.0714,5.07140,1.000
1,5.500,24.60,4.9997,4.99970,1.000
1,5.625,19.17,4.8748,4.87475,1.000
1,5.750,15.18,4.7497,4.74970,1.000
1,5.875,12.12,4.6248,4.62475,1.000
1,6.000,9.70,4.4998,4.49980,1.000
1,6.125,7.77,4.3747,4.37465,1.000
1,6.250,6.24,4.2496,4.24960,1.000
1,6.375,5.03,4.1246,4.12455,1.000
1,6.500,4.08,3.9996,3.99960,1.000
1,6.625,3.30,3.8747,3.87465,1.000
1,6.750,2.64,3.7496,3.74960,1.000
1,6.875,2.10,3.6247,3.62465,1.000
1,7.000,1.62,3.4995,3.49950,1.000
1,7.125,1.21,3.3746,3.37455,1.000
1,7.250,0.87,3.2494,3.24940,1.000
1,7.375,0.58,3.1244,3.12445,1.000
1,7.500,0.35,2.9996,2.99960,1.000
1,7.625,0.20,2.8745,2.87450,1.000
1,7.750,0.09,2.7495,2.74950,1.000
1,7.875,0.03,2.6244,2.62445,1.000
1,8.000,0.01,2.4996,2.49960,1.000
1,8.125,0.01,2.3745,2.37450,1.000
1,8.250,0.00,2.2493,2.24930,1.000
1,8.375,0.00,2.1244,2.12440,1.000
1,8.500,0.00,1.9994,1.99940,1.000
1,8.625,0.00,1.8743,1.87430,1.000
1,8.750,0.00,1.7495,1.74950,1.000
1,8.875,0.00,1.6244,1.62440,1.000
1,9.000,0.00,1.4994,1.49940,1.000
1,9.125,0.00,1.3744,1.37440,1.000
1,9.250,0.00,1.2494,1.24940,1.000
1,9.375,0.00,1.1243,1.12425,1.000
1,9.500,-0.01,0.9993,0.99930,1.000
1,9.625,0.00,0.8743,0.87430,1.000
1,9.750,0.00,0.7494,0.74940,1.000
1,9.875,0.00,0.6244,0.62435,1.000
1,10.000,0.00,0.4994,0.49940,1.000
1,10.125,0.00,0.3744,0.37440,1.000
1,10.250,0.00,0.2493,0.24930,1.000
1,10.375,0.00,0.1242,0.12420,1.000
1,10.500,0.00,-0.0009,-0.00090,1.000
1,10.688,0.00,-0.0003,-0.00030,1.000
1,10.812,0.00,-0.0003,-0.00030,1.000
1,10.938,0.00,-0.0003,-0.00030,1.000
1,11.062,0.00,-0.0003,-0.00030,1.000
1,11.188,0.00,-0.0003,-0.00030,1.000
1,11.312,0.00,-0.0003,-0.00030,1.000
1,11.438,0.00,-0.0003,-0.00030,1.000
1,11.562,0.00,-0.0003,-0.00030,1.000
1,11.688,0.00,-0.0002,-0.00020,1.000
1,11.812,0.00,-0.0002,-0.00020,1.000
1,11.938,0.00,-0.0002,-0.00020,1.000
1,12.062,0.00,-0.0002,-0.00020,1.000
1,12.188,0.00,-0.0002,-0.00020,1.000
1,12.312,0.00,-0.0002,-0.00020,1.000
1,12.438,0.00,-0.0002,-0.00020,1.000
1,12.562,0.00,-0.0002,-0.00020,1.000
1,12.688,0.00,-0.0002,-0.00020,1.000
1,12.812,0.00,-0.0002,-0.00020,1.000
1,12.938,0.00,-0.0002,-0.00020,1.000
1,13.062,0.00,-0.0002,-0.00020,1.000
1,13.188,0.00,-0.0002,-0.00020,1.000
1,13.312,0.00,-0.0002,-0.00020,1.000
1,13.438,0.00,-0.0002,-0.00020,1.000
1,13.562,0.00,-0.0002,-0.00020,1.000
2,13.875,-0.01,0.0925,0.09265,2.000
2,14.000,-0.01,0.2176,0.21770,2.000
2,14.125,-0.01,0.3426,0.34275,2.000
2,14.250,-0.01,0.4676,0.46770,2.000
2,14.375,-0.01,0.5926,0.59275,2.000
2,14.500,-0.01,0.7177,0.71780,2.000
2,14.625,-0.01,0.8426,0.84270,2.000
2,14.750,-0.01,0.9678,0.96790,2.000
2,14.875,-0.01,1.0926,1.09275,2.000
2,15.000,-0.01,1.2176,1.21770,2.000
2,15.125,-0.01,1.3426,1.34275,2.000
2,15.250,-0.02,1.4677,1.46780,2.000
2,15.375,-0.01,1.5927,1.59280,2.000
2,15.500,-0.01,1.7176,1.71770,2.000
2,15.625,-0.01,1.8425,1.84265,2.000
2,15.750,-0.01,1.9676,1.96770,2.000
2,15.875,-0.01,2.0927,2.09285,2.000
2,16.000,-0.01,2.2178,2.21790,2.000
2,16.125,0.00,2.3429,2.34295,2.000
2,16.250,0.04,2.4679,2.46800,2.000
2,16.375,0.10,2.5928,2.59290,2.000
2,16.500,0.23,2.7179,2.71800,2.000
2,16.625,0.44,2.8427,2.84275,2.000
2,16.750,0.73,2.9677,2.96780,2.000
2,16.875,1.13,3.0928,3.09290,2.000
2,17.000,1.63,3.2178,3.21790,2.000
2,17.125,2.25,3.3429,3.34295,2.000
2,17.250,3.00,3.4677,3.46780,2.000
2,17.375,3.90,3.5929,3.59295,2.000
2,17.500,4.95,3.7179,3.71800,2.000
2,17.625,6.16,3.8428,3.84285,2.000
2,17.750,7.53,3.9677,3.96780,2.000
2,17.875,9.11,4.0928,4.09285,2.000
2,18.000,10.88,4.2177,4.21780,2.000
2,18.125,12.87,4.3429,4.34295,2.000
2,18.250,15.08,4.4679,4.46800,2.000
2,18.375,17.55,4.5929,4.59300,2.000
2,18.500,20.31,4.7178,4.71790,2.000
2,18.625,23.42,4.8429,4.84295,2.000
2,18.750,26.94,4.9677,4.96780,2.000
2,19.000,27.82,5.0586,5.05870,2.000
2,19.125,21.35,4.9336,4.93375,2.000
2,19.250,16.83,4.8086,4.80870,2.000
2,19.375,13.39,4.6836,4.68365,2.000
2,19.500,10.71,4.5587,4.55880,2.000
2,19.625,8.57,4.4336,4.43375,2.000
2,19.750,6.87,4.3088,4.30890,2.000
2,19.875,5.51,4.1836,4.18365,2.000
2,20.000,4.46,4.0585,4.05860,2.000
2,20.125,3.61,3.9335,3.93355,2.000
2,20.250,2.90,3.8084,3.80850,2.000
2,20.375,2.30,3.6836,3.68365,2.000
2,20.500,1.81,3.5585,3.55860,2.000
2,20.625,1.36,3.4335,3.43355,2.000
2,20.750,0.99,3.3086,3.30870,2.000
2,20.875,0.68,3.1835,3.18360,2.000
2,21.000,0.43,3.0586,3.05870,2.000
2,21.125,0.24,2.9335,2.93355,2.000
2,21.250,0.11,2.8082,2.80830,2.000
2,21.375,0.04,2.6834,2.68345,2.000
2,21.500,0.01,2.5584,2.55850,2.000
2,21.625,-0.01,2.4335,2.43360,2.000
2,21.750,-0.01,2.3084,2.30850,2.000
2,21.875,-0.01,2.1834,2.18350,2.000
2,22.000,-0.02,2.0585,2.05860,2.000
2,22.125,-0.01,1.9334,1.93345,2.000
2,22.250,-0.01,1.8083,1.80840,2.000
2,22.375,-0.01,1.6833,1.68340,2.000
2,22.500,-0.01,1.5583,1.55840,2.000
2,22.625,-0.01,1.4334,1.43345,2.000
2,22.750,-0.01,1.3084,1.30850,2.000
2,22.875,-0.01,1.1834,1.18345,2.000
2,23.000,-0.01,1.0585,1.05860,2.000
2,23.125,-0.01,0.9334,0.93350,2.000
2,23.250,-0.01,0.8083,0.80840,2.000
2,23.375,-0.01,0.6832,0.68335,2.000
2,23.500,-0.01,0.5582,0.55830,2.000
2,23.625,-0.01,0.4333,0.43340,2.000
2,23.750,-0.01,0.3082,0.30830,2.000
2,23.875,-0.01,0.1833,0.18340,2.000
2,24.000,-0.02,0.0583,0.05840,2.000
2,24.188,-0.01,-0.0139,-0.01380,2.000
2,24.312,-0.01,-0.0002,-0.00010,2.000
2,24.438,-0.01,-0.0002,-0.00010,2.000
2,24.562,-0.01,-0.0002,-0.00010,2.000
2,24.688,-0.01,-0.0002,-0.00010,2.000
2,24.812,-0.01,-0.0002,-0.00010,2.000
2,24.938,-0.01,-0.0002,-0.00010,2.000
2,25.062,-0.01,-0.0002,-0.00010,2.000
2,25.188,-0.01,-0.0002,-0.00010,2.000
2,25.312,-0.01,-0.0002,-0.00010,2.000
2,25.438,-0.01,-0.0002,-0.00010,2.000
2,25.562,-0.01,-0.0002,-0.00010,2.000
2,25.688,-0.01,-0.0002,-0.00010,2.000
2,25.812,-0.01,-0.0002,-0.00010,2.000
2,25.938,-0.01,-0.0002,-0.00010,2.000
2,26.062,-0.01,-0.0002,-0.00010,2.000
2,26.188,-0.01,-0.0002,-0.00010,2.000
2,26.312,-0.01,-0.0002,-0.00010,2.000
2,26.438,-0.01,-0.0002,-0.00010,2.000
2,26.562,-0.01,-0.0002,-0.00010,2.000
2,26.688,-0.01,-0.0002,-0.00010,2.000
2,26.812,-0.01,-0.0002,-0.00010,2.000
2,26.938,-0.01,-0.0002,-0.00010,2.000
2,27.062,-0.01,-0.0002,-0.00010,2.000
3,27.438,0.01,0.0848,0.08495,3.000
3,27.562,0.01,0.2099,0.21005,3.000
3,27.688,0.01,0.3350,0.33510,3.000
3,27.812,0.01,0.4601,0.46020,3.000
3,27.938,0.01,0.5851,0.58525,3.000
3,28.062,0.01,0.7102,0.71035,3.000
3,28.188,0.01,0.8351,0.83522,3.000
3,28.312,0.00,0.9602,0.96030,3.000
3,28.438,0.01,1.0851,1.08520,3.000
3,28.562,0.01,1.2101,1.21020,3.000
3,28.688,0.00,1.3352,1.33527,3.000
3,28.812,0.01,1.4603,1.46037,3.000
3,28.938,0.01,1.5852,1.58530,3.000
3,29.062,0.01,1.7103,1.71042,3.000
3,29.188,0.01,1.8352,1.83527,3.000
3,29.312,0.01,1.9601,1.96020,3.000
3,29.438,0.01,2.0851,2.08520,3.000
3,29.562,0.01,2.2102,2.21030,3.000
3,29.688,0.02,2.3352,2.33535,3.000
3,29.812,0.05,2.4603,2.46042,3.000
3,29.938,0.11,2.5853,2.58537,3.000
3,30.062,0.23,2.7103,2.71040,3.000
3,30.188,0.43,2.8353,2.83540,3.000
3,30.312,0.72,2.9603,2.96040,3.000
3,30.438,1.11,3.0852,3.08532,3.000
3,30.562,1.60,3.2102,3.21032,3.000
3,30.688,2.21,3.3352,3.33535,3.000
3,30.812,2.96,3.4602,3.46032,3.000
3,30.938,3.84,3.5853,3.58545,3.000
3,31.062,4.88,3.7103,3.71042,3.000
3,31.188,6.08,3.8354,3.83547,3.000
3,31.312,7.44,3.9602,3.96035,3.000
3,31.438,9.01,4.0852,4.08530,3.000
3,31.562,10.78,4.2101,4.21022,3.000
3,31.688,12.75,4.3352,4.33530,3.000
3,31.812,14.95,4.4603,4.46040,3.000
3,31.938,17.41,4.5853,4.58545,3.000
3,32.062,20.14,4.7103,4.71042,3.000
3,32.188,23.24,4.8355,4.83555,3.000
3,32.312,26.74,4.9604,4.96050,3.000
3,32.438,30.76,5.0852,5.08525,3.000
3,32.625,24.63,5.0035,5.00360,3.000
3,32.750,19.21,4.8787,4.87880,3.000
3,32.875,15.23,4.7536,4.75370,3.000
3,33.000,12.16,4.6287,4.62880,3.000
3,33.125,9.74,4.5037,4.50375,3.000
3,33.250,7.79,4.3785,4.37860,3.000
3,33.375,6.25,4.2535,4.25360,3.000
3,33.500,5.04,4.1284,4.12850,3.000
3,33.625,4.07,4.0034,4.00355,3.000
3,33.750,3.29,3.8785,3.87860,3.000
3,33.875,2.64,3.7536,3.75370,3.000
3,34.000,2.09,3.6286,3.62870,3.000
3,34.125,1.61,3.5034,3.50355,3.000
3,34.250,1.21,3.3784,3.37850,3.000
3,34.375,0.86,3.2534,3.25350,3.000
3,34.500,0.57,3.1283,3.12840,3.000
3,34.625,0.35,3.0035,3.00360,3.000
3,34.750,0.19,2.8784,2.87850,3.000
3,34.875,0.09,2.7534,2.75355,3.000
3,35.000,0.03,2.6284,2.62850,3.000
3,35.125,0.02,2.5034,2.50355,3.000
3,35.250,0.01,2.3785,2.37860,3.000
3,35.375,0.01,2.2533,2.25335,3.000
3,35.500,0.01,2.1282,2.12830,3.000
3,35.625,0.00,2.0032,2.00335,3.000
3,35.750,0.01,1.8783,1.87840,3.000
3,35.875,0.01,1.7534,1.75345,3.000
3,36.000,0.01,1.6283,1.62840,3.000
3,36.125,0.01,1.5034,1.50350,3.000
3,36.250,0.01,1.3785,1.37860,3.000
3,36.375,0.01,1.2533,1.25340,3.000
3,36.500,0.01,1.1282,1.12830,3.000
3,36.625,0.01,1.0034,1.00350,3.000
3,36.750,0.01,0.8783,0.87840,3.000
3,36.875,0.01,0.7534,0.75345,3.000
3,37.000,0.00,0.6283,0.62840,3.000
3,37.125,0.01,0.5034,0.50345,3.000
3,37.250,0.01,0.3784,0.37850,3.000
3,37.375,0.00,0.2532,0.25330,3.000
3,37.500,0.01,0.1281,0.12820,3.000
3,37.625,0.01,0.0033,0.00340,3.000
3,37.812,0.01,-0.0003,-0.00020,3.000
3,37.938,0.01,-0.0003,-0.00020,3.000
3,38.062,0.01,-0.0003,-0.00020,3.000
3,38.188,0.01,-0.0003,-0.00020,3.000
3,38.312,0.01,-0.0003,-0.00020,3.000
3,38.438,0.01,-0.0003,-0.00020,3.000
3,38.562,0.01,-0.0003,-0.00020,3.000
3,38.688,0.01,-0.0003,-0.00020,3.000
3,38.812,0.01,-0.0003,-0.00020,3.000
3,38.938,0.00,-0.0003,-0.00020,3.000
3,39.062,0.01,-0.0003,-0.00020,3.000
3,39.188,0.01,-0.0002,-0.00010,3.000
3,39.312,0.01,-0.0002,-0.00010,3.000
3,39.438,0.00,-0.0002,-0.00010,3.000
3,39.562,0.01,-0.0002,-0.00010,3.000
3,39.688,0.01,-0.0002,-0.00010,3.000
3,39.812,0.01,-0.0002,-0.00010,3.000
3,39.938,0.01,-0.0002,-0.00010,3.000
3,40.062,0.01,-0.0002,-0.00010,3.000
3,40.188,0.01,-0.0002,-0.00010,3.000
3,40.312,0.01,-0.0002,-0.00010,3.000
3,40.438,0.01,-0.0002,-0.00010,3.000
3,40.562,0.01,-0.0002,-0.00010,3.000
3,40.688,0.01,-0.0002,-0.00010,3.000
4,41.062,0.00,0.1300,0.13010,4.000
4,41.188,-0.01,0.2550,0.25510,4.000
4,41.312,-0.01,0.3802,0.38030,4.000
4,41.438,0.00,0.5052,0.50528,4.000
4,41.562,0.00,0.6302,0.63027,4.000
4,41.688,0.00,0.7552,0.75525,4.000
4,41.812,-0.01,0.8801,0.88020,4.000
4,41.938,0.00,1.0052,1.00530,4.000
4,42.062,0.00,1.1301,1.13020,4.000
4,42.188,0.00,1.2551,1.25520,4.000
4,42.312,0.00,1.3802,1.38027,4.000
4,42.438,0.00,1.5052,1.50530,4.000
4,42.562,0.00,1.6303,1.63037,4.000
4,42.688,0.00,1.7552,1.75530,4.000
4,42.812,0.00,1.8801,1.88020,4.000
4,42.938,0.00,2.0051,2.00520,4.000
4,43.062,0.00,2.1301,2.13022,4.000
4,43.188,0.00,2.2552,2.25528,4.000
4,43.312,0.02,2.3803,2.38040,4.000
4,43.438,0.05,2.5054,2.50548,4.000
4,43.562,0.13,2.6303,2.63037,4.000
4,43.688,0.27,2.7553,2.75543,4.000
4,43.812,0.51,2.8803,2.88040,4.000
4,43.938,0.83,3.0053,3.00543,4.000
4,44.062,1.25,3.1302,3.13032,4.000
4,44.188,1.78,3.2553,3.25535,4.000
4,44.312,2.44,3.3802,3.38035,4.000
4,44.438,3.24,3.5053,3.50543,4.000
4,44.562,4.17,3.6303,3.63040,4.000
4,44.688,5.27,3.7553,3.75540,4.000
4,44.812,6.52,3.8803,3.88040,4.000
4,44.938,7.96,4.0052,4.00533,4.000
4,45.062,9.60,4.1301,4.13022,4.000
4,45.188,11.43,4.2553,4.25538,4.000
4,45.312,13.49,4.3802,4.38032,4.000
4,45.438,15.79,4.5054,4.50545,4.000
4,45.562,18.34,4.6303,4.63042,4.000
4,45.688,21.20,4.7553,4.75540,4.000
4,45.812,24.44,4.8804,4.88055,4.000
4,45.938,28.12,5.0053,5.00543,4.000
4,46.125,28.60,5.0636,5.06365,4.000
4,46.250,21.80,4.9387,4.93880,4.000
4,46.375,17.16,4.8136,4.81370,4.000
4,46.500,13.66,4.6885,4.68860,4.000
4,46.625,10.92,4.5636,4.56365,4.000
4,46.750,8.72,4.4387,4.43880,4.000
4,46.875,7.00,4.3137,4.31380,4.000
4,47.000,5.61,4.1886,4.18870,4.000
4,47.125,4.52,4.0635,4.06360,4.000
4,47.250,3.66,3.9385,3.93860,4.000
4,47.375,2.93,3.8135,3.81360,4.000
4,47.500,2.33,3.6885,3.68860,4.000
4,47.625,1.81,3.5634,3.56350,4.000
4,47.750,1.38,3.4384,3.43850,4.000
4,47.875,1.01,3.3136,3.31365,4.000
4,48.000,0.69,3.1885,3.18860,4.000
4,48.125,0.44,3.0635,3.06360,4.000
4,48.250,0.25,2.9385,2.93860,4.000
4,48.375,0.12,2.8134,2.81345,4.000
4,48.500,0.04,2.6883,2.68840,4.000
4,48.625,0.01,2.5633,2.56340,4.000
4,48.750,0.00,2.4386,2.43870,4.000
4,48.875,-0.01,2.3134,2.31350,4.000
4,49.000,-0.01,2.1885,2.18860,4.000
4,49.125,-0.01,2.0635,2.06360,4.000
4,49.250,0.00,1.9384,1.93850,4.000
4,49.375,-0.01,1.8133,1.81340,4.000
4,49.500,0.00,1.6882,1.68830,4.000
4,49.625,-0.01,1.5633,1.56335,4.000
4,49.750,-0.01,1.4383,1.43840,4.000
4,49.875,-0.01,1.3133,1.31340,4.000
4,50.000,-0.01,1.1883,1.18840,4.000
4,50.125,-0.01,1.0634,1.06350,4.000
4,50.250,0.00,0.9385,0.93860,4.000
4,50.375,0.00,0.8134,0.81345,4.000
4,50.500,-0.01,0.6882,0.68830,4.000
4,50.625,0.00,0.5632,0.56330,4.000
4,50.750,-0.01,0.4383,0.43840,4.000
4,50.875,-0.01,0.3133,0.31335,4.000
4,51.000,-0.01,0.1883,0.18840,4.000
4,51.125,-0.01,0.0634,0.06345,4.000
4,51.312,-0.01,-0.0050,-0.00490,4.000
4,51.438,0.00,-0.0003,-0.00020,4.000
4,51.562,-0.01,-0.0003,-0.00020,4.000
4,51.688,0.00,-0.0003,-0.00020,4.000
4,51.812,-0.01,-0.0003,-0.00020,4.000
4,51.938,-0.01,-0.0003,-0.00020,4.000
4,52.062,-0.01,-0.0003,-0.00020,4.000
4,52.188,0.00,-0.0003,-0.00020,4.000
4,52.312,0.00,-0.0003,-0.00020,4.000
4,52.438,-0.01,-0.0003,-0.00020,4.000
4,52.562,-0.01,-0.0003,-0.00020,4.000
4,52.688,0.00,-0.0003,-0.00020,4.000
4,52.812,0.00,-0.0002,-0.00010,4.000
4,52.938,0.00,-0.0002,-0.00010,4.000
4,53.062,0.00,-0.0002,-0.00010,4.000
4,53.188,-0.01,-0.0002,-0.00010,4.000
4,53.312,0.00,-0.0002,-0.00010,4.000
4,53.438,-0.01,-0.0002,-0.00010,4.000
4,53.562,0.00,-0.0002,-0.00010,4.000
4,53.688,0.00,-0.0002,-0.00010,4.000
4,53.812,-0.01,-0.0002,-0.00010,4.000
4,53.938,-0.01,-0.0002,-0.00010,4.000
4,54.062,0.00,-0.0002,-0.00010,4.000
4,54.188,0.00,-0.0002,-0.00010,4.000
5,54.562,0.00,0.0610,0.06115,5.000
5,54.688,0.00,0.1862,0.18625,5.000
5,54.812,0.00,0.3111,0.31117,5.000
5,54.938,0.00,0.4361,0.43623,5.000
5,55.062,0.01,0.5610,0.56112,5.000
5,55.188,0.00,0.6861,0.68620,5.000
5,55.312,0.00,0.8111,0.81122,5.000
5,55.438,0.00,0.9363,0.93635,5.000
5,55.562,0.00,1.0611,1.06125,5.000
5,55.688,0.00,1.1862,1.18628,5.000
5,55.812,0.00,1.3112,1.31135,5.000
5,55.938,0.00,1.4362,1.43625,5.000
5,56.062,0.00,1.5611,1.56120,5.000
5,56.188,0.00,1.6862,1.68630,5.000
5,56.312,0.00,1.8111,1.81120,5.000
5,56.438,0.00,1.9363,1.93635,5.000
5,56.562,0.00,2.0612,2.06132,5.000
5,56.688,0.00,2.1862,2.18630,5.000
5,56.812,0.01,2.3113,2.31137,5.000
5,56.938,0.04,2.4363,2.43643,5.000
5,57.062,0.08,2.5613,2.56137,5.000
5,57.188,0.19,2.6862,2.68633,5.000
5,57.312,0.38,2.8112,2.81130,5.000
5,57.438,0.64,2.9363,2.93640,5.000
5,57.562,1.00,3.0614,3.06150,5.000
5,57.688,1.47,3.1864,3.18645,5.000
5,57.812,2.07,3.3114,3.31150,5.000
5,57.938,2.78,3.4363,3.43638,5.000
5,58.062,3.64,3.5613,3.56137,5.000
5,58.188,4.66,3.6863,3.68638,5.000
5,58.312,5.82,3.8112,3.81130,5.000
5,58.438,7.15,3.9363,3.93638,5.000
5,58.562,8.68,4.0613,4.06137,5.000
5,58.688,10.40,4.1863,4.18638,5.000
5,58.812,12.33,4.3114,4.31155,5.000
5,58.938,14.50,4.4364,4.43648,5.000
5,59.062,16.91,4.5613,4.56145,5.000
5,59.188,19.59,4.6862,4.68633,5.000
5,59.312,22.62,4.8112,4.81135,5.000
5,59.438,26.05,4.9363,4.93640,5.000
5,59.562,29.97,5.0612,5.06135,5.000
5,59.750,25.23,5.0095,5.00960,5.000
5,59.875,19.62,4.8847,4.88475,5.000
5,60.000,15.53,4.7596,4.75970,5.000
5,60.125,12.40,4.6347,4.63480,5.000
5,60.250,9.92,4.5098,4.50990,5.000
5,60.375,7.94,4.3847,4.38480,5.000
5,60.500,6.36,4.2596,4.25970,5.000
5,60.625,5.12,4.1344,4.13450,5.000
5,60.750,4.14,4.0094,4.00950,5.000
5,60.875,3.33,3.8846,3.88465,5.000
5,61.000,2.66,3.7596,3.75970,5.000
5,61.125,2.10,3.6346,3.63470,5.000
5,61.250,1.62,3.5095,3.50960,5.000
5,61.375,1.22,3.3845,3.38455,5.000
5,61.500,0.87,3.2593,3.25940,5.000
5,61.625,0.58,3.1344,3.13445,5.000
5,61.750,0.35,3.0093,3.00940,5.000
5,61.875,0.19,2.8844,2.88450,5.000
5,62.000,0.08,2.7595,2.75960,5.000
5,62.125,0.03,2.6345,2.63455,5.000
5,62.250,0.02,2.5095,2.50960,5.000
5,62.375,0.00,2.3846,2.38465,5.000
5,62.500,0.01,2.2594,2.25950,5.000
5,62.625,0.00,2.1344,2.13445,5.000
5,62.750,0.00,2.0092,2.00930,5.000
5,62.875,0.00,1.8843,1.88435,5.000
5,63.000,0.00,1.7594,1.75950,5.000
5,63.125,0.00,1.6344,1.63450,5.000
5,63.250,0.01,1.5093,1.50940,5.000
5,63.375,0.01,1.3844,1.38445,5.000
5,63.500,0.00,1.2594,1.25950,5.000
5,63.625,0.00,1.1343,1.13435,5.000
5,63.750,0.01,1.0094,1.00950,5.000
5,63.875,0.00,0.8842,0.88430,5.000
5,64.000,0.01,0.7594,0.75950,5.000
5,64.125,0.00,0.6343,0.63440,5.000
5,64.250,0.01,0.5094,0.50950,5.000
5,64.375,0.00,0.3844,0.38450,5.000
5,64.500,0.00,0.2592,0.25930,5.000
5,64.625,0.00,0.1342,0.13435,5.000
5,64.750,0.00,0.0092,0.00930,5.000
5,64.938,0.00,-0.0003,-0.00020,5.000
5,65.062,0.00,-0.0003,-0.00020,5.000
5,65.188,0.00,-0.0003,-0.00020,5.000
5,65.312,0.00,-0.0003,-0.00020,5.000
5,65.438,0.00,-0.0003,-0.00020,5.000
5,65.562,0.00,-0.0003,-0.00020,5.000
5,65.688,0.00,-0.0003,-0.00020,5.000
5,65.812,0.00,-0.0003,-0.00020,5.000
5,65.938,0.00,-0.0003,-0.00020,5.000
5,66.062,0.00,-0.0002,-0.00010,5.000
5,66.188,0.00,-0.0002,-0.00010,5.000
5,66.312,0.00,-0.0002,-0.00010,5.000
5,66.438,0.00,-0.0002,-0.00010,5.000
5,66.562,0.00,-0.0002,-0.00010,5.000
5,66.688,0.00,-0.0002,-0.00010,5.000
5,66.812,0.00,-0.0002,-0.00010,5.000
5,66.938,0.00,-0.0002,-0.00010,5.000
5,67.062,0.01,-0.0002,-0.00010,5.000
5,67.188,0.01,-0.0002,-0.00010,5.000
5,67.312,0.00,-0.0002,-0.00010,5.000
5,67.438,0.00,-0.0002,-0.00010,5.000
5,67.562,0.01,-0.0002,-0.00010,5.000
5,67.688,0.00,-0.0002,-0.00010,5.000
5,67.812,0.00,-0.0002,-0.00010,5.000
6,68.188,0.00,0.1249,0.12500,6.000
6,68.312,0.00,0.2499,0.25005,6.000
6,68.438,0.00,0.3751,0.37520,6.000
6,68.562,0.00,0.5001,0.50022,6.000
6,68.688,0.00,0.6252,0.62525,6.000
6,68.812,0.00,0.7502,0.75030,6.000
6,68.938,-0.01,0.8752,0.87525,6.000
6,69.062,0.00,1.0002,1.00030,6.000
6,69.188,0.00,1.1250,1.12512,6.000
6,69.312,0.00,1.2500,1.25015,6.000
6,69.438,0.00,1.3752,1.37528,6.000
6,69.562,0.00,1.5001,1.50025,6.000
6,69.688,0.00,1.6253,1.62538,6.000
6,69.812,0.00,1.7502,1.75032,6.000
6,69.938,0.00,1.8752,1.87530,6.000
6,70.062,0.00,2.0001,2.00020,6.000
6,70.188,0.00,2.1252,2.12525,6.000
6,70.312,0.00,2.2501,2.25022,6.000
6,70.438,0.02,2.3753,2.37535,6.000
6,70.562,0.05,2.5002,2.50035,6.000
6,70.688,0.12,2.6252,2.62532,6.000
6,70.812,0.27,2.7503,2.75037,6.000
6,70.938,0.49,2.8754,2.87548,6.000
6,71.062,0.81,3.0003,3.00040,6.000
6,71.188,1.23,3.1253,3.12535,6.000
6,71.312,1.75,3.2502,3.25030,6.000
6,71.438,2.41,3.3752,3.37528,6.000
6,71.562,3.20,3.5002,3.50030,6.000
6,71.688,4.14,3.6253,3.62540,6.000
6,71.812,5.22,3.7503,3.75037,6.000
6,71.938,6.47,3.8753,3.87543,6.000
6,72.062,7.90,4.0003,4.00037,6.000
6,72.188,9.53,4.1252,4.12528,6.000
6,72.312,11.36,4.2502,4.25030,6.000
6,72.438,13.41,4.3751,4.37525,6.000
6,72.562,15.70,4.5002,4.50035,6.000
6,72.688,18.25,4.6253,4.62538,6.000
6,72.812,21.09,4.7502,4.75035,6.000
6,72.938,24.32,4.8754,4.87555,6.000
6,73.062,27.99,5.0004,5.00047,6.000
6,73.250,30.14,5.0881,5.08820,6.000
6,73.375,22.71,4.9637,4.96375,6.000
6,73.500,17.84,4.8387,4.83880,6.000
6,73.625,14.19,4.7137,4.71375,6.000
6,73.750,11.34,4.5887,4.58880,6.000
6,73.875,9.08,4.4637,4.46375,6.000
6,74.000,7.27,4.3386,4.33870,6.000
6,74.125,5.83,4.2135,4.21360,6.000
6,74.250,4.69,4.0885,4.08860,6.000
6,74.375,3.79,3.9635,3.96360,6.000
6,74.500,3.05,3.8386,3.83870,6.000
6,74.625,2.43,3.7136,3.71370,6.000
6,74.750,1.90,3.5886,3.58870,6.000
6,74.875,1.45,3.4634,3.46355,6.000
6,75.000,1.07,3.3384,3.33850,6.000
6,75.125,0.74,3.2134,3.21345,6.000
6,75.250,0.48,3.0885,3.08860,6.000
6,75.375,0.28,2.9634,2.96355,6.000
6,75.500,0.14,2.8384,2.83850,6.000
6,75.625,0.06,2.7135,2.71360,6.000
6,75.750,0.02,2.5885,2.58860,6.000
6,75.875,0.01,2.4635,2.46365,6.000
6,76.000,0.00,2.3384,2.33850,6.000
6,76.125,0.00,2.2133,2.21340,6.000
6,76.250,0.00,2.0883,2.08840,6.000
6,76.375,0.00,1.9633,1.96340,6.000
6,76.500,-0.01,1.8383,1.83840,6.000
6,76.625,0.00,1.7134,1.71355,6.000
6,76.750,-0.01,1.5885,1.58860,6.000
6,76.875,-0.01,1.4634,1.46350,6.000
6,77.000,-0.01,1.3383,1.33840,6.000
6,77.125,0.00,1.2132,1.21330,6.000
6,77.250,0.00,1.0882,1.08830,6.000
6,77.375,0.00,0.9634,0.96345,6.000
6,77.500,0.00,0.8383,0.83840,6.000
6,77.625,0.00,0.7134,0.71345,6.000
6,77.750,0.00,0.5884,0.58850,6.000
6,77.875,0.00,0.4634,0.46350,6.000
6,78.000,0.00,0.3384,0.33850,6.000
6,78.125,0.00,0.2132,0.21330,6.000
6,78.250,0.00,0.0881,0.08820,6.000
6,78.438,0.00,-0.0428,-0.04272,6.000
6,78.562,0.00,-0.0003,-0.00018,6.000
6,78.688,0.00,-0.0003,-0.00020,6.000
6,78.812,0.00,-0.0002,-0.00010,6.000
6,78.938,0.00,-0.0002,-0.00010,6.000
6,79.062,0.00,-0.0002,-0.00010,6.000
6,79.188,0.00,-0.0002,-0.00010,6.000
6,79.312,0.00,-0.0002,-0.00010,6.000
6,79.438,0.00,-0.0002,-0.00010,6.000
6,79.562,0.00,-0.0002,-0.00010,6.000
6,79.688,0.00,-0.0002,-0.00010,6.000
6,79.812,0.00,-0.0002,-0.00010,6.000
6,79.938,-0.01,-0.0002,-0.00010,6.000
6,80.062,-0.01,-0.0002,-0.00010,6.000
6,80.188,0.00,-0.0002,-0.00010,6.000
6,80.312,0.00,-0.0002,-0.00010,6.000
6,80.438,0.00,-0.0002,-0.00010,6.000
6,80.562,0.00,-0.0002,-0.00010,6.000
6,80.688,0.00,-0.0002,-0.00010,6.000
6,80.812,0.00,-0.0002,-0.00010,6.000
6,80.938,0.00,-0.0002,-0.00010,6.000
6,81.062,0.00,-0.0002,-0.00010,6.000
6,81.188,0.00,-0.0002,-0.00010,6.000
6,81.312,0.00,-0.0002,-0.00010,6.000
6,81.438,0.00,-0.0002,-0.00010,6.000
7,81.750,-0.01,0.1174,0.11750,7.000
7,81.875,-0.01,0.2424,0.24255,7.000
7,82.000,-0.01,0.3675,0.36760,7.000
7,82.125,-0.01,0.4925,0.49260,7.000
7,82.250,-0.01,0.6176,0.61770,7.000
7,82.375,-0.01,0.7427,0.74280,7.000
7,82.500,-0.01,0.8677,0.86780,7.000
7,82.625,-0.01,0.9928,0.99290,7.000
7,82.750,-0.01,1.1177,1.11780,7.000
7,82.875,-0.01,1.2426,1.24265,7.000
7,83.000,0.00,1.3676,1.36770,7.000
7,83.125,-0.01,1.4926,1.49270,7.000
7,83.250,-0.01,1.6176,1.61770,7.000
7,83.375,-0.01,1.7427,1.74280,7.000
7,83.500,-0.01,1.8676,1.86770,7.000
7,83.625,-0.01,1.9927,1.99280,7.000
7,83.750,-0.01,2.1179,2.11800,7.000
7,83.875,0.00,2.2427,2.24280,7.000
7,84.000,0.01,2.3676,2.36770,7.000
7,84.125,0.05,2.4928,2.49285,7.000
7,84.250,0.12,2.6176,2.61770,7.000
7,84.375,0.25,2.7428,2.74285,7.000
7,84.500,0.47,2.8677,2.86780,7.000
7,84.625,0.78,2.9929,2.99300,7.000
7,84.750,1.19,3.1178,3.11790,7.000
7,84.875,1.71,3.2428,3.24285,7.000
7,85.000,2.35,3.3677,3.36780,7.000
7,85.125,3.13,3.4926,3.49275,7.000
7,85.250,4.05,3.6177,3.61780,7.000
7,85.375,5.13,3.7427,3.74280,7.000
7,85.500,6.37,3.8678,3.86790,7.000
7,85.625,7.79,3.9928,3.99295,7.000
7,85.750,9.41,4.1178,4.11790,7.000
7,85.875,11.24,4.2428,4.24290,7.000
7,86.000,13.28,4.3678,4.36790,7.000
7,86.125,15.55,4.4928,4.49290,7.000
7,86.250,18.09,4.6177,4.61780,7.000
7,86.375,20.91,4.7428,4.74285,7.000
7,86.500,24.10,4.8680,4.86810,7.000
7,86.625,27.75,4.9929,4.99295,7.000
7,86.812,30.65,5.0960,5.09613,7.000
7,86.938,23.05,4.9711,4.97118,7.000
7,87.062,18.10,4.8461,4.84623,7.000
7,87.188,14.38,4.7212,4.72125,7.000
7,87.312,11.49,4.5961,4.59623,7.000
7,87.438,9.20,4.4712,4.47130,7.000
7,87.562,7.37,4.3462,4.34633,7.000
7,87.688,5.90,4.2210,4.22108,7.000
7,87.812,4.75,4.0959,4.09603,7.000
7,87.938,3.84,3.9710,3.97108,7.000
7,88.062,3.08,3.8461,3.84618,7.000
7,88.188,2.46,3.7210,3.72110,7.000
7,88.312,1.93,3.5961,3.59618,7.000
7,88.438,1.47,3.4709,3.47103,7.000
7,88.562,1.09,3.3461,3.34615,7.000
7,88.688,0.76,3.2208,3.22093,7.000
7,88.812,0.48,3.0959,3.09595,7.000
7,88.938,0.28,2.9709,2.97100,7.000
7,89.062,0.14,2.8459,2.84595,7.000
7,89.188,0.05,2.7209,2.72098,7.000
7,89.312,0.02,2.5959,2.59600,7.000
7,89.438,0.00,2.4710,2.47115,7.000
7,89.562,-0.01,2.3460,2.34608,7.000
7,89.688,0.00,2.2208,2.22095,7.000
7,89.812,-0.01,2.0959,2.09595,7.000
7,89.938,-0.01,1.9708,1.97090,7.000
7,90.062,-0.01,1.8457,1.84583,7.000
7,90.188,-0.01,1.7209,1.72098,7.000
7,90.312,-0.01,1.5959,1.59598,7.000
7,90.438,-0.01,1.4709,1.47098,7.000
7,90.562,-0.01,1.3459,1.34598,7.000
7,90.688,-0.01,1.2208,1.22090,7.000
7,90.812,-0.01,1.0958,1.09593,7.000
7,90.938,-0.01,0.9708,0.97088,7.000
7,91.062,-0.01,0.8457,0.84580,7.000
7,91.188,-0.01,0.7208,0.72090,7.000
7,91.312,-0.01,0.5958,0.59590,7.000
7,91.438,-0.01,0.4708,0.47090,7.000
7,91.562,-0.01,0.3458,0.34590,7.000
7,91.688,-0.01,0.2209,0.22095,7.000
7,91.812,-0.01,0.0958,0.09585,7.000
7,92.062,-0.01,-0.0003,-0.00020,7.000
7,92.188,-0.01,-0.0002,-0.00010,7.000
7,92.312,-0.01,-0.0002,-0.00010,7.000
7,92.438,-0.01,-0.0002,-0.00010,7.000
7,92.562,-0.01,-0.0002,-0.00010,7.000
7,92.688,-0.01,-0.0002,-0.00010,7.000
7,92.812,-0.01,-0.0002,-0.00010,7.000
7,92.938,-0.01,-0.0002,-0.00010,7.000
7,93.062,-0.01,-0.0002,-0.00010,7.000
7,93.188,-0.01,-0.0002,-0.00010,7.000
7,93.312,-0.01,-0.0002,-0.00010,7.000
7,93.438,-0.01,-0.0002,-0.00010,7.000
7,93.562,0.00,-0.0002,-0.00010,7.000
7,93.688,-0.01,-0.0002,-0.00010,7.000
7,93.812,-0.01,-0.0002,-0.00010,7.000
7,93.938,0.00,-0.0002,-0.00010,7.000
7,94.062,0.00,-0.0002,-0.00010,7.000
7,94.188,-0.01,-0.0002,-0.00010,7.000
7,94.312,-0.01,-0.0002,-0.00010,7.000
7,94.438,0.00,-0.0002,-0.00010,7.000
7,94.562,-0.01,-0.0002,-0.00010,7.000
7,94.688,-0.01,-0.0002,-0.00010,7.000
7,94.812,0.00,-0.0002,-0.00010,7.000
7,94.938,-0.01,-0.0002,-0.00010,7.000
8,95.250,0.01,0.0565,0.05660,8.000
8,95.375,0.01,0.1816,0.18165,8.000
8,95.500,0.01,0.3065,0.30660,8.000
8,95.625,0.01,0.4316,0.43175,8.000
8,95.750,0.01,0.5567,0.55680,8.000
8,95.875,0.01,0.6817,0.68175,8.000
8,96.000,0.01,0.8065,0.80660,8.000
8,96.125,0.01,0.9316,0.93170,8.000
8,96.250,0.01,1.0566,1.05670,8.000
8,96.375,0.01,1.1816,1.18170,8.000
8,96.500,0.01,1.3066,1.30670,8.000
8,96.625,0.01,1.4317,1.43180,8.000
8,96.750,0.00,1.5568,1.55690,8.000
8,96.875,0.01,1.6816,1.68175,8.000
8,97.000,0.00,1.8065,1.80660,8.000
8,97.125,0.01,1.9316,1.93175,8.000
8,97.250,0.01,2.0567,2.05680,8.000
8,97.375,0.01,2.1817,2.18180,8.000
8,97.500,0.01,2.3067,2.30680,8.000
8,97.625,0.04,2.4319,2.43195,8.000
8,97.750,0.09,2.5568,2.55690,8.000
8,97.875,0.19,2.6818,2.68190,8.000
8,98.000,0.36,2.8067,2.80680,8.000
8,98.125,0.63,2.9318,2.93185,8.000
8,98.250,0.99,3.0568,3.05690,8.000
8,98.375,1.45,3.1818,3.18185,8.000
8,98.500,2.03,3.3067,3.30680,8.000
8,98.625,2.75,3.4318,3.43190,8.000
8,98.750,3.61,3.5568,3.55690,8.000
8,98.875,4.61,3.6818,3.68195,8.000
8,99.000,5.77,3.8067,3.80680,8.000
8,99.125,7.10,3.9317,3.93180,8.000
8,99.250,8.63,4.0567,4.05680,8.000
8,99.375,10.35,4.1817,4.18175,8.000
8,99.500,12.28,4.3069,4.30700,8.000
8,99.625,14.44,4.4318,4.43190,8.000
8,99.750,16.85,4.5569,4.55700,8.000
8,99.875,19.53,4.6818,4.68195,8.000
8,100.000,22.54,4.8068,4.80690,8.000
8,100.125,25.97,4.9319,4.93195,8.000
8,100.250,29.89,5.0567,5.05680,8.000
8,100.438,26.20,5.0300,5.03015,8.000
8,100.562,20.31,4.9052,4.90525,8.000
8,100.688,16.06,4.7800,4.78012,8.000
8,100.812,12.82,4.6550,4.65513,8.000
8,100.938,10.26,4.5302,4.53025,8.000
8,101.062,8.20,4.4051,4.40520,8.000
8,101.188,6.58,4.2801,4.28022,8.000
8,101.312,5.29,4.1551,4.15520,8.000
8,101.438,4.26,4.0301,4.03020,8.000
8,101.562,3.44,3.9051,3.90523,8.000
8,101.688,2.75,3.7800,3.78005,8.000
8,101.812,2.18,3.6550,3.65513,8.000
8,101.938,1.69,3.5299,3.52998,8.000
8,102.062,1.27,3.4049,3.40495,8.000
8,102.188,0.92,3.2800,3.28008,8.000
8,102.312,0.62,3.1550,3.15505,8.000
8,102.438,0.38,3.0301,3.03018,8.000
8,102.562,0.21,2.9050,2.90508,8.000
8,102.688,0.10,2.7799,2.77998,8.000
8,102.812,0.04,2.6548,2.65490,8.000
8,102.938,0.02,2.5298,2.52993,8.000
8,103.062,0.01,2.4049,2.40503,8.000
8,103.188,0.01,2.2799,2.27998,8.000
8,103.312,0.01,2.1550,2.15510,8.000
8,103.438,0.00,2.0299,2.03000,8.000
8,103.562,0.01,1.9049,1.90503,8.000
8,103.688,0.01,1.7798,1.77993,8.000
8,103.812,0.01,1.6549,1.65498,8.000
8,103.938,0.01,1.5297,1.52982,8.000
8,104.062,0.01,1.4048,1.40485,8.000
8,104.188,0.01,1.2799,1.27995,8.000
8,104.312,0.01,1.1548,1.15490,8.000
8,104.438,0.00,1.0299,1.03002,8.000
8,104.562,0.01,0.9049,0.90500,8.000
8,104.688,0.01,0.7799,0.78000,8.000
8,104.812,0.01,0.6549,0.65495,8.000
8,104.938,0.01,0.5296,0.52975,8.000
8,105.062,0.01,0.4047,0.40483,8.000
8,105.188,0.01,0.2796,0.27975,8.000
8,105.312,0.01,0.1547,0.15483,8.000
8,105.438,0.01,0.0298,0.02990,8.000
8,105.562,0.01,-0.0468,-0.04668,8.000
8,105.688,0.01,-0.0003,-0.00020,8.000
8,105.812,0.00,-0.0003,-0.00020,8.000
8,105.938,0.01,-0.0003,-0.00020,8.000
8,106.062,0.01,-0.0003,-0.00020,8.000
8,106.188,0.01,-0.0003,-0.00020,8.000
8,106.312,0.01,-0.0003,-0.00020,8.000
8,106.438,0.01,-0.0003,-0.00020,8.000
8,106.562,0.01,-0.0003,-0.00020,8.000
8,106.688,0.01,-0.0002,-0.00010,8.000
8,106.812,0.00,-0.0002,-0.00010,8.000
8,106.938,0.01,-0.0002,-0.00010,8.000
8,107.062,0.01,-0.0002,-0.00010,8.000
8,107.188,0.01,-0.0002,-0.00010,8.000
8,107.312,0.01,-0.0002,-0.00010,8.000
8,107.438,0.01,-0.0002,-0.00010,8.000
8,107.562,0.01,-0.0002,-0.00010,8.000
8,107.688,0.01,-0.0002,-0.00010,8.000
8,107.812,0.01,-0.0002,-0.00010,8.000
8,107.938,0.01,-0.0002,-0.00010,8.000
8,108.062,0.01,-0.0002,-0.00010,8.000
8,108.188,0.01,-0.0002,-0.00010,8.000
8,108.312,0.01,-0.0002,-0.00010,8.000
8,108.438,0.01,-0.0002,-0.00010,8.000
8,108.562,0.01,-0.0002,-0.00010,8.000
9,108.875,0.00,0.1224,0.12255,9.000
9,109.000,0.00,0.2475,0.24760,9.000
9,109.125,0.00,0.3726,0.37270,9.000
9,109.250,0.00,0.4975,0.49760,9.000
9,109.375,0.00,0.6226,0.62270,9.000
9,109.500,0.01,0.7478,0.74790,9.000
9,109.625,0.00,0.8727,0.87280,9.000
9,109.750,0.00,0.9978,0.99790,9.000
9,109.875,0.00,1.1226,1.12270,9.000
9,110.000,0.00,1.2475,1.24760,9.000
9,110.125,0.00,1.3726,1.37265,9.000
9,110.250,0.00,1.4977,1.49780,9.000
9,110.375,0.00,1.6227,1.62280,9.000
9,110.500,0.00,1.7477,1.74780,9.000
9,110.625,0.01,1.8728,1.87285,9.000
9,110.750,0.00,1.9977,1.99780,9.000
9,110.875,0.00,2.1228,2.12285,9.000
9,111.000,0.01,2.2476,2.24770,9.000
9,111.125,0.02,2.3727,2.37280,9.000
9,111.250,0.05,2.4977,2.49780,9.000
9,111.375,0.13,2.6226,2.62275,9.000
9,111.500,0.27,2.7478,2.74790,9.000
9,111.625,0.49,2.8728,2.87290,9.000
9,111.750,0.80,2.9979,2.99800,9.000
9,111.875,1.21,3.1228,3.12295,9.000
9,112.000,1.74,3.2476,3.24770,9.000
9,112.125,2.38,3.3727,3.37280,9.000
9,112.250,3.17,3.4976,3.49770,9.000
9,112.375,4.11,3.6228,3.62285,9.000
9,112.500,5.18,3.7478,3.74790,9.000
9,112.625,6.43,3.8728,3.87295,9.000
9,112.750,7.86,3.9979,3.99800,9.000
9,112.875,9.50,4.1227,4.12280,9.000
9,113.000,11.33,4.2477,4.24780,9.000
9,113.125,13.37,4.3728,4.37285,9.000
9,113.250,15.66,4.4976,4.49770,9.000
9,113.375,18.20,4.6228,4.62290,9.000
9,113.500,21.05,4.7477,4.74780,9.000
9,113.625,24.25,4.8729,4.87300,9.000
9,113.750,27.91,4.9979,4.99800,9.000
9,113.938,30.33,5.0908,5.09085,9.000
9,114.062,22.84,4.9661,4.96623,9.000
9,114.188,17.94,4.8412,4.84128,9.000
9,114.312,14.27,4.7161,4.71620,9.000
9,114.438,11.41,4.5911,4.59122,9.000
9,114.562,9.13,4.4661,4.46620,9.000
9,114.688,7.31,4.3410,4.34115,9.000
9,114.812,5.86,4.2159,4.21603,9.000
9,114.938,4.72,4.0909,4.09102,9.000
9,115.062,3.82,3.9660,3.96613,9.000
9,115.188,3.06,3.8410,3.84115,9.000
9,115.312,2.44,3.7161,3.71615,9.000
9,115.438,1.91,3.5911,3.59120,9.000
9,115.562,1.46,3.4660,3.46605,9.000
9,115.688,1.08,3.3409,3.34098,9.000
9,115.812,0.75,3.2158,3.21593,9.000
9,115.938,0.48,3.0910,3.09108,9.000
9,116.062,0.29,2.9659,2.96598,9.000
9,116.188,0.15,2.8410,2.84108,9.000
9,116.312,0.06,2.7160,2.71610,9.000
9,116.438,0.02,2.5910,2.59108,9.000
9,116.562,0.01,2.4660,2.46610,9.000
9,116.688,0.00,2.3408,2.34095,9.000
9,116.812,0.00,2.2157,2.21583,9.000
9,116.938,0.00,2.0908,2.09093,9.000
9,117.062,0.00,1.9658,1.96588,9.000
9,117.188,0.00,1.8408,1.84088,9.000
9,117.312,0.00,1.7160,1.71608,9.000
9,117.438,0.00,1.5909,1.59100,9.000
9,117.562,0.00,1.4660,1.46605,9.000
9,117.688,0.00,1.3408,1.34093,9.000
9,117.812,0.00,1.2157,1.21583,9.000
9,117.938,0.00,1.0907,1.09078,9.000
9,118.062,0.00,0.9658,0.96593,9.000
9,118.188,0.00,0.8408,0.84090,9.000
9,118.312,0.00,0.7159,0.71600,9.000
9,118.438,0.00,0.5909,0.59098,9.000
9,118.562,0.00,0.4659,0.46598,9.000
9,118.688,0.00,0.3407,0.34082,9.000
9,118.812,0.00,0.2158,0.21585,9.000
9,118.938,0.00,0.0906,0.09075,9.000
9,119.125,0.00,-0.0443,-0.04420,9.000
9,119.250,0.00,-0.0002,-0.00010,9.000
9,119.375,0.00,-0.0002,-0.00010,9.000
9,119.500,0.00,-0.0002,-0.00010,9.000
9,119.625,0.00,-0.0002,-0.00010,9.000
9,119.750,0.00,-0.0002,-0.00010,9.000
9,119.875,0.00,-0.0002,-0.00010,9.000
9,120.000,0.00,-0.0002,-0.00010,9.000
9,120.125,0.00,-0.0002,-0.00010,9.000
9,120.250,0.00,-0.0002,-0.00010,9.000
9,120.375,0.00,-0.0002,-0.00010,9.000
9,120.500,0.00,-0.0002,-0.00010,9.000
9,120.625,0.00,-0.0002,-0.00010,9.000
9,120.750,0.00,-0.0002,-0.00010,9.000
9,120.875,0.00,-0.0002,-0.00010,9.000
9,121.000,0.00,-0.0002,-0.00010,9.000
9,121.125,0.00,-0.0002,-0.00010,9.000
9,121.250,0.00,-0.0002,-0.00010,9.000
9,121.375,0.00,-0.0002,-0.00010,9.000
9,121.500,0.00,-0.0002,-0.00010,9.000
9,121.625,0.00,-0.0002,-0.00010,9.000
9,121.750,0.01,-0.0002,-0.00010,9.000
9,121.875,0.00,-0.0002,-0.00010,9.000
9,122.000,0.00,-0.0002,-0.00010,9.000
9,122.125,0.00,-0.0002,-0.00010,9.000
10,122.438,0.00,0.1060,0.10615,10.000
10,122.562,0.00,0.2310,0.23110,10.000
10,122.688,0.00,0.3560,0.35615,10.000
10,122.812,0.00,0.4811,0.48117,10.000
10,122.938,0.00,0.6060,0.60612,10.000
10,123.062,0.00,0.7311,0.73120,10.000
10,123.188,0.01,0.8561,0.85617,10.000
10,123.312,0.00,0.9813,0.98140,10.000
10,123.438,0.00,1.1062,1.10630,10.000
10,123.562,0.00,1.2312,1.23127,10.000
10,123.688,0.00,1.3562,1.35627,10.000
10,123.812,0.00,1.4812,1.48132,10.000
10,123.938,0.00,1.6062,1.60625,10.000
10,124.062,0.00,1.7311,1.73120,10.000
10,124.188,0.00,1.8561,1.85618,10.000
10,124.312,0.00,1.9811,1.98122,10.000
10,124.438,0.00,2.1063,2.10638,10.000
10,124.562,0.00,2.2312,2.23127,10.000
10,124.688,0.01,2.3563,2.35640,10.000
10,124.812,0.05,2.4813,2.48140,10.000
10,124.938,0.11,2.6062,2.60632,10.000
10,125.062,0.24,2.7311,2.73122,10.000
10,125.188,0.45,2.8562,2.85630,10.000
10,125.312,0.75,2.9813,2.98140,10.000
10,125.438,1.15,3.1064,3.10645,10.000
10,125.562,1.65,3.2313,3.23142,10.000
10,125.688,2.28,3.3564,3.35645,10.000
10,125.812,3.05,3.4812,3.48135,10.000
10,125.938,3.97,3.6062,3.60635,10.000
10,126.062,5.04,3.7312,3.73130,10.000
10,126.188,6.25,3.8562,3.85632,10.000
10,126.312,7.66,3.9813,3.98137,10.000
10,126.438,9.26,4.1061,4.10623,10.000
10,126.562,11.07,4.2312,4.23132,10.000
10,126.688,13.08,4.3564,4.35648,10.000
10,126.812,15.33,4.4814,4.48150,10.000
10,126.938,17.85,4.6063,4.60640,10.000
10,127.062,20.65,4.7313,4.73137,10.000
10,127.188,23.81,4.8563,4.85642,10.000
10,127.312,27.41,4.9813,4.98140,10.000
10,127.500,31.43,5.1082,5.10830,10.000
10,127.625,23.70,4.9846,4.98470,10.000
10,127.750,18.57,4.8595,4.85960,10.000
10,127.875,14.74,4.7345,4.73460,10.000
10,128.000,11.78,4.6096,4.60970,10.000
10,128.125,9.43,4.4847,4.48480,10.000
10,128.250,7.54,4.3596,4.35970,10.000
10,128.375,6.05,4.2346,4.23470,10.000
10,128.500,4.87,4.1096,4.10970,10.000
10,128.625,3.93,3.9846,3.98465,10.000
10,128.750,3.16,3.8594,3.85950,10.000
10,128.875,2.52,3.7344,3.73455,10.000
10,129.000,1.98,3.6094,3.60950,10.000
10,129.125,1.52,3.4844,3.48450,10.000
10,129.250,1.13,3.3596,3.35970,10.000
10,129.375,0.79,3.2344,3.23455,10.000
10,129.500,0.52,3.1096,3.10970,10.000
10,129.625,0.31,2.9845,2.98460,10.000
10,129.750,0.16,2.8594,2.85950,10.000
10,129.875,0.07,2.7344,2.73445,10.000
10,130.000,0.03,2.6094,2.60950,10.000
10,130.125,0.01,2.4845,2.48460,10.000
10,130.250,0.00,2.3595,2.35960,10.000
10,130.375,0.00,2.2344,2.23450,10.000
10,130.500,0.00,2.1095,2.10960,10.000
10,130.625,0.00,1.9844,1.98445,10.000
10,130.750,0.00,1.8592,1.85930,10.000
10,130.875,0.00,1.7343,1.73440,10.000
10,131.000,0.00,1.6093,1.60940,10.000
10,131.125,0.00,1.4843,1.48440,10.000
10,131.250,0.00,1.3593,1.35940,10.000
10,131.375,0.00,1.2343,1.23440,10.000
10,131.500,0.00,1.1094,1.10950,10.000
10,131.625,0.00,0.9844,0.98450,10.000
10,131.750,0.00,0.8594,0.85950,10.000
10,131.875,0.00,0.7343,0.73440,10.000
10,132.000,0.00,0.6091,0.60920,10.000
10,132.125,0.00,0.4843,0.48435,10.000
10,132.250,0.00,0.3592,0.35930,10.000
10,132.375,0.00,0.2342,0.23435,10.000
10,132.500,0.00,0.1092,0.10930,10.000
10,132.750,0.00,0.0000,0.00010,10.000
10,132.875,0.00,-0.0002,-0.00010,10.000
10,133.000,0.00,-0.0002,-0.00010,10.000
10,133.125,0.00,-0.0002,-0.00010,10.000
10,133.250,0.00,-0.0002,-0.00010,10.000
10,133.375,0.00,-0.0002,-0.00010,10.000
10,133.500,0.00,-0.0002,-0.00010,10.000
10,133.625,0.00,-0.0002,-0.00010,10.000
10,133.750,0.00,-0.0002,-0.00010,10.000
10,133.875,0.00,-0.0002,-0.00010,10.000
10,134.000,0.00,-0.0002,-0.00010,10.000
10,134.125,0.00,-0.0002,-0.00010,10.000
10,134.250,0.00,-0.0002,-0.00010,10.000
10,134.375,0.00,-0.0002,-0.00010,10.000
10,134.500,0.00,-0.0002,-0.00010,10.000
10,134.625,0.00,-0.0002,-0.00010,10.000
10,134.750,0.00,-0.0002,-0.00010,10.000
10,134.875,0.00,-0.0002,-0.00010,10.000
10,135.000,0.00,-0.0002,-0.00010,10.000
10,135.125,0.00,-0.0002,-0.00010,10.000
10,135.250,0.00,-0.0002,-0.00010,10.000
10,135.375,0.00,-0.0002,-0.00010,10.000
10,135.500,0.00,-0.0002,-0.00010,10.000
10,135.625,0.00,-0.0002,-0.00010,10.000
10,135.688,0.00,-0.0002,-0.00010,10.000