File: AIME_journal_files/AIME_data/calibDATA_loadcell/date_02:22:2018/Instron/30N_0_1_0_0.txt
""
"Test Method","Radhen_Load_Cntrl_Cmprsn_250N_12-7.msm"
"Sample I. D.","Sample1.mss"
"Specimen Number","22"

"TheCycle_Output ()","_Time (s)","_Load (N)","_Extension (mm)","RealTimeDepth (mm)","CycleNumber ()"

1,0.312,0.02,0.1051,0.10513,1.000
1,0.438,0.02,0.2302,0.23018,1.000
1,0.562,0.01,0.3553,0.35535,1.000
1,0.688,0.01,0.4802,0.48025,1.000
1,0.812,0.01,0.6051,0.60510,1.000
1,0.938,0.01,0.7303,0.73027,1.000
1,1.062,0.01,0.8553,0.85530,1.000
1,1.188,0.02,0.9804,0.98038,1.000
1,1.312,0.01,1.1053,1.10530,1.000
1,1.438,0.01,1.2303,1.23032,1.000
1,1.562,0.02,1.3553,1.35528,1.000
1,1.688,0.02,1.4802,1.48023,1.000
1,1.812,0.01,1.6053,1.60530,1.000
1,1.938,0.00,1.7304,1.73038,1.000
1,2.062,0.02,1.8553,1.85530,1.000
1,2.188,0.02,1.9803,1.98030,1.000
1,2.312,0.01,2.1054,2.10535,1.000
1,2.438,0.02,2.2304,2.23040,1.000
1,2.562,0.02,2.3555,2.35552,1.000
1,2.688,0.04,2.4804,2.48035,1.000
1,2.812,0.08,2.6052,2.60522,1.000
1,2.938,0.15,2.7303,2.73028,1.000
1,3.062,0.28,2.8553,2.85532,1.000
1,3.188,0.48,2.9804,2.98038,1.000
1,3.312,0.76,3.1054,3.10540,1.000
1,3.438,1.14,3.2304,3.23043,1.000
1,3.562,1.61,3.3555,3.35550,1.000
1,3.688,2.18,3.4805,3.48048,1.000
1,3.812,2.87,3.6054,3.60543,1.000
1,3.938,3.66,3.7304,3.73040,1.000
1,4.062,4.58,3.8553,3.85535,1.000
1,4.188,5.63,3.9804,3.98040,1.000
1,4.312,6.80,4.1053,4.10535,1.000
1,4.438,8.08,4.2304,4.23045,1.000
1,4.562,9.48,4.3554,4.35538,1.000
1,4.688,10.99,4.4803,4.48035,1.000
1,4.812,12.69,4.6054,4.60538,1.000
1,4.938,14.82,4.7303,4.73032,1.000
1,5.062,17.18,4.8552,4.85525,1.000
1,5.188,19.85,4.9803,4.98030,1.000
1,5.312,22.79,5.1053,5.10532,1.000
1,5.438,26.03,5.2304,5.23038,1.000
1,5.562,29.61,5.3554,5.35542,1.000
1,5.750,26.39,5.3257,5.32570,1.000
1,5.875,20.96,5.2007,5.20070,1.000
1,6.000,16.87,5.0758,5.07580,1.000
1,6.125,13.77,4.9507,4.95065,1.000
1,6.250,11.29,4.8257,4.82570,1.000
1,6.375,9.47,4.7006,4.70060,1.000
1,6.500,7.90,4.5756,4.57560,1.000
1,6.625,6.55,4.4505,4.45050,1.000
1,6.750,5.39,4.3255,4.32550,1.000
1,6.875,4.40,4.2005,4.20050,1.000
1,7.000,3.57,4.0756,4.07560,1.000
1,7.125,2.90,3.9507,3.95065,1.000
1,7.250,2.33,3.8256,3.82560,1.000
1,7.375,1.84,3.7005,3.70050,1.000
1,7.500,1.42,3.5754,3.57540,1.000
1,7.625,1.05,3.4504,3.45040,1.000
1,7.750,0.75,3.3255,3.32550,1.000
1,7.875,0.50,3.2004,3.20045,1.000
1,8.000,0.31,3.0754,3.07540,1.000
1,8.125,0.17,2.9505,2.95050,1.000
1,8.250,0.07,2.8254,2.82540,1.000
1,8.375,0.04,2.7005,2.70045,1.000
1,8.500,0.02,2.5753,2.57530,1.000
1,8.625,0.02,2.4504,2.45035,1.000
1,8.750,0.01,2.3253,2.32530,1.000
1,8.875,0.01,2.2004,2.20035,1.000
1,9.000,0.02,2.0753,2.07530,1.000
1,9.125,0.01,1.9504,1.95040,1.000
1,9.250,0.01,1.8254,1.82540,1.000
1,9.375,0.02,1.7005,1.70045,1.000
1,9.500,0.02,1.5754,1.57540,1.000
1,9.625,0.01,1.4504,1.45035,1.000
1,9.750,0.02,1.3251,1.32510,1.000
1,9.875,0.02,1.2003,1.20025,1.000
1,10.000,0.01,1.0753,1.07530,1.000
1,10.125,0.01,0.9503,0.95030,1.000
1,10.250,0.01,0.8255,0.82550,1.000
1,10.375,0.01,0.7004,0.70035,1.000
1,10.500,0.02,0.5752,0.57520,1.000
1,10.625,0.02,0.4503,0.45030,1.000
1,10.750,0.01,0.3252,0.32520,1.000
1,10.875,0.01,0.2001,0.20010,1.000
1,11.000,0.01,0.0753,0.07530,1.000
1,11.188,0.02,-0.0174,-0.01742,1.000
1,11.312,0.01,-0.0003,-0.00030,1.000
1,11.438,0.01,-0.0003,-0.00030,1.000
1,11.562,0.02,-0.0003,-0.00030,1.000
1,11.688,0.01,-0.0003,-0.00030,1.000
1,11.812,0.02,-0.0003,-0.00030,1.000
1,11.938,0.01,-0.0003,-0.00030,1.000
1,12.062,0.01,-0.0003,-0.00030,1.000
1,12.188,0.02,-0.0003,-0.00030,1.000
1,12.312,0.02,-0.0003,-0.00030,1.000
1,12.438,0.01,-0.0003,-0.00030,1.000
1,12.562,0.01,-0.0003,-0.00030,1.000
1,12.688,0.01,-0.0003,-0.00030,1.000
1,12.812,0.01,-0.0003,-0.00030,1.000
1,12.938,0.02,-0.0003,-0.00030,1.000
1,13.062,0.01,-0.0002,-0.00020,1.000
1,13.188,0.01,-0.0002,-0.00020,1.000
1,13.312,0.01,-0.0002,-0.00020,1.000
1,13.438,0.01,-0.0002,-0.00020,1.000
1,13.562,0.01,-0.0002,-0.00020,1.000
1,13.688,0.01,-0.0002,-0.00020,1.000
1,13.812,0.01,-0.0002,-0.00020,1.000
1,13.938,0.01,-0.0002,-0.00020,1.000
1,14.062,0.01,-0.0002,-0.00020,1.000
2,14.438,-0.01,0.0890,0.08908,2.000
2,14.562,0.00,0.2140,0.21412,2.000
2,14.688,-0.01,0.3391,0.33923,2.000
2,14.812,0.00,0.4643,0.46440,2.000
2,14.938,0.00,0.5891,0.58920,2.000
2,15.062,-0.01,0.7141,0.71420,2.000
2,15.188,0.00,0.8392,0.83930,2.000
2,15.312,-0.01,0.9641,0.96422,2.000
2,15.438,0.00,1.0892,1.08928,2.000
2,15.562,0.00,1.2141,1.21425,2.000
2,15.688,0.00,1.3391,1.33923,2.000
2,15.812,0.00,1.4643,1.46440,2.000
2,15.938,0.00,1.5894,1.58945,2.000
2,16.062,0.00,1.7144,1.71445,2.000
2,16.188,0.00,1.8392,1.83935,2.000
2,16.312,-0.01,1.9642,1.96428,2.000
2,16.438,0.00,2.0892,2.08930,2.000
2,16.562,0.00,2.2142,2.21425,2.000
2,16.688,0.00,2.3392,2.33930,2.000
2,16.812,0.02,2.4644,2.46450,2.000
2,16.938,0.06,2.5892,2.58935,2.000
2,17.062,0.11,2.7143,2.71438,2.000
2,17.188,0.22,2.8393,2.83940,2.000
2,17.312,0.40,2.9643,2.96440,2.000
2,17.438,0.66,3.0892,3.08930,2.000
2,17.562,1.02,3.2142,3.21425,2.000
2,17.688,1.47,3.3393,3.33942,2.000
2,17.812,2.01,3.4643,3.46443,2.000
2,17.938,2.67,3.5894,3.58947,2.000
2,18.062,3.45,3.7145,3.71458,2.000
2,18.188,4.33,3.8394,3.83955,2.000
2,18.312,5.34,3.9644,3.96448,2.000
2,18.438,6.50,4.0892,4.08932,2.000
2,18.562,7.77,4.2143,4.21440,2.000
2,18.688,9.15,4.3393,4.33937,2.000
2,18.812,10.64,4.4643,4.46435,2.000
2,18.938,12.28,4.5894,4.58947,2.000
2,19.062,14.39,4.7144,4.71445,2.000
2,19.188,16.70,4.8394,4.83950,2.000
2,19.312,19.36,4.9644,4.96445,2.000
2,19.438,22.26,5.0892,5.08935,2.000
2,19.562,25.47,5.2142,5.21433,2.000
2,19.688,29.03,5.3394,5.33947,2.000
2,19.812,31.37,5.4160,5.41607,2.000
2,19.938,24.66,5.2951,5.29520,2.000
2,20.062,19.69,5.1701,5.17022,2.000
2,20.188,15.90,5.0450,5.04510,2.000
2,20.312,13.01,4.9201,4.92022,2.000
2,20.438,10.75,4.7951,4.79520,2.000
2,20.562,9.00,4.6701,4.67020,2.000
2,20.688,7.49,4.5451,4.54520,2.000
2,20.812,6.19,4.4200,4.42012,2.000
2,20.938,5.08,4.2949,4.29503,2.000
2,21.062,4.14,4.1699,4.17002,2.000
2,21.188,3.35,4.0450,4.04508,2.000
2,21.312,2.70,3.9201,3.92020,2.000
2,21.438,2.15,3.7950,3.79510,2.000
2,21.562,1.69,3.6700,3.67010,2.000
2,21.688,1.29,3.5449,3.54503,2.000
2,21.812,0.94,3.4199,3.42005,2.000
2,21.938,0.65,3.2949,3.29503,2.000
2,22.062,0.42,3.1698,3.16992,2.000
2,22.188,0.24,3.0449,3.04498,2.000
2,22.312,0.12,2.9199,2.92002,2.000
2,22.438,0.05,2.7949,2.79500,2.000
2,22.562,0.02,2.6699,2.67000,2.000
2,22.688,0.01,2.5448,2.54493,2.000
2,22.812,0.00,2.4199,2.42005,2.000
2,22.938,0.00,2.2948,2.29493,2.000
2,23.062,-0.01,2.1698,2.16990,2.000
2,23.188,-0.01,2.0448,2.04488,2.000
2,23.312,0.00,1.9197,1.91985,2.000
2,23.438,-0.01,1.7950,1.79508,2.000
2,23.562,-0.01,1.6699,1.67000,2.000
2,23.688,-0.01,1.5450,1.54508,2.000
2,23.812,-0.01,1.4199,1.42005,2.000
2,23.938,-0.01,1.2948,1.29490,2.000
2,24.062,-0.01,1.1697,1.16980,2.000
2,24.188,0.00,1.0447,1.04480,2.000
2,24.312,0.00,0.9198,0.91990,2.000
2,24.438,0.00,0.7950,0.79505,2.000
2,24.562,-0.01,0.6697,0.66983,2.000
2,24.688,0.00,0.5449,0.54495,2.000
2,24.812,-0.01,0.4198,0.41990,2.000
2,24.938,-0.01,0.2947,0.29475,2.000
2,25.062,0.00,0.1696,0.16970,2.000
2,25.188,0.00,0.0446,0.04470,2.000
2,25.375,-0.01,-0.0124,-0.01225,2.000
2,25.500,0.00,-0.0003,-0.00020,2.000
2,25.625,0.00,-0.0003,-0.00020,2.000
2,25.750,0.00,-0.0003,-0.00020,2.000
2,25.875,0.00,-0.0003,-0.00020,2.000
2,26.000,0.00,-0.0003,-0.00020,2.000
2,26.125,0.00,-0.0003,-0.00020,2.000
2,26.250,0.00,-0.0003,-0.00020,2.000
2,26.375,0.00,-0.0003,-0.00020,2.000
2,26.500,0.00,-0.0003,-0.00020,2.000
2,26.625,0.00,-0.0003,-0.00020,2.000
2,26.750,0.00,-0.0003,-0.00020,2.000
2,26.875,-0.01,-0.0003,-0.00020,2.000
2,27.000,0.00,-0.0003,-0.00020,2.000
2,27.125,0.00,-0.0003,-0.00020,2.000
2,27.250,-0.02,-0.0003,-0.00020,2.000
2,27.375,0.00,-0.0003,-0.00020,2.000
2,27.500,0.00,-0.0002,-0.00010,2.000
2,27.625,0.00,-0.0002,-0.00010,2.000
2,27.750,-0.01,-0.0002,-0.00010,2.000
2,27.875,0.00,-0.0002,-0.00010,2.000
2,28.000,0.00,-0.0002,-0.00010,2.000
2,28.125,0.00,-0.0002,-0.00010,2.000
2,28.250,-0.01,-0.0002,-0.00010,2.000
3,28.562,0.00,0.0551,0.05517,3.000
3,28.688,0.00,0.1801,0.18017,3.000
3,28.812,0.00,0.3051,0.30522,3.000
3,28.938,-0.02,0.4303,0.43042,3.000
3,29.062,0.00,0.5551,0.55525,3.000
3,29.188,0.00,0.6800,0.68012,3.000
3,29.312,0.00,0.8052,0.80532,3.000
3,29.438,0.00,0.9301,0.93020,3.000
3,29.562,0.00,1.0551,1.05522,3.000
3,29.688,0.00,1.1802,1.18027,3.000
3,29.812,0.00,1.3052,1.30530,3.000
3,29.938,-0.01,1.4303,1.43037,3.000
3,30.062,-0.01,1.5553,1.55545,3.000
3,30.188,0.00,1.6802,1.68027,3.000
3,30.312,-0.01,1.8052,1.80532,3.000
3,30.438,-0.01,1.9302,1.93027,3.000
3,30.562,-0.01,2.0551,2.05525,3.000
3,30.688,0.00,2.1802,2.18030,3.000
3,30.812,0.00,2.3053,2.30540,3.000
3,30.938,0.01,2.4304,2.43055,3.000
3,31.062,0.04,2.5553,2.55542,3.000
3,31.188,0.08,2.6803,2.68037,3.000
3,31.312,0.16,2.8053,2.80537,3.000
3,31.438,0.33,2.9303,2.93040,3.000
3,31.562,0.56,3.0552,3.05535,3.000
3,31.688,0.90,3.1802,3.18035,3.000
3,31.812,1.30,3.3053,3.30545,3.000
3,31.938,1.81,3.4304,3.43047,3.000
3,32.062,2.44,3.5553,3.55542,3.000
3,32.188,3.18,3.6803,3.68043,3.000
3,32.312,4.05,3.8053,3.80545,3.000
3,32.438,5.04,3.9303,3.93043,3.000
3,32.562,6.16,4.0551,4.05525,3.000
3,32.688,7.40,4.1804,4.18045,3.000
3,32.812,8.76,4.3053,4.30542,3.000
3,32.938,10.22,4.4304,4.43045,3.000
3,33.062,11.83,4.5553,4.55542,3.000
3,33.188,13.81,4.6805,4.68058,3.000
3,33.312,16.05,4.8053,4.80545,3.000
3,33.438,18.62,4.9303,4.93035,3.000
3,33.562,21.45,5.0552,5.05532,3.000
3,33.688,24.60,5.1803,5.18038,3.000
3,33.812,28.06,5.3053,5.30542,3.000
3,34.000,30.19,5.3932,5.39330,3.000
3,34.125,23.49,5.2687,5.26880,3.000
3,34.250,18.81,5.1435,5.14360,3.000
3,34.375,15.22,5.0185,5.01855,3.000
3,34.500,12.47,4.8934,4.89350,3.000
3,34.625,10.35,4.7685,4.76860,3.000
3,34.750,8.66,4.6437,4.64380,3.000
3,34.875,7.19,4.5186,4.51865,3.000
3,35.000,5.93,4.3936,4.39370,3.000
3,35.125,4.86,4.2685,4.26860,3.000
3,35.250,3.95,4.1435,4.14360,3.000
3,35.375,3.19,4.0185,4.01860,3.000
3,35.500,2.56,3.8933,3.89340,3.000
3,35.625,2.03,3.7684,3.76850,3.000
3,35.750,1.59,3.6434,3.64350,3.000
3,35.875,1.19,3.5185,3.51860,3.000
3,36.000,0.86,3.3935,3.39360,3.000
3,36.125,0.58,3.2685,3.26860,3.000
3,36.250,0.37,3.1433,3.14340,3.000
3,36.375,0.20,3.0184,3.01850,3.000
3,36.500,0.09,2.8932,2.89330,3.000
3,36.625,0.04,2.7684,2.76845,3.000
3,36.750,0.01,2.6433,2.64340,3.000
3,36.875,0.01,2.5184,2.51845,3.000
3,37.000,0.00,2.3934,2.39350,3.000
3,37.125,0.00,2.2684,2.26850,3.000
3,37.250,0.00,2.1434,2.14350,3.000
3,37.375,0.00,2.0183,2.01840,3.000
3,37.500,-0.01,1.8932,1.89330,3.000
3,37.625,0.00,1.7683,1.76840,3.000
3,37.750,-0.01,1.6433,1.64340,3.000
3,37.875,0.00,1.5184,1.51845,3.000
3,38.000,-0.01,1.3934,1.39350,3.000
3,38.125,0.00,1.2683,1.26840,3.000
3,38.250,-0.01,1.1433,1.14340,3.000
3,38.375,0.00,1.0183,1.01840,3.000
3,38.500,-0.01,0.8932,0.89330,3.000
3,38.625,0.00,0.7683,0.76840,3.000
3,38.750,0.00,0.6430,0.64310,3.000
3,38.875,0.00,0.5183,0.51840,3.000
3,39.000,0.00,0.3933,0.39340,3.000
3,39.125,0.00,0.2682,0.26835,3.000
3,39.250,0.00,0.1434,0.14350,3.000
3,39.375,0.00,0.0182,0.01830,3.000
3,39.562,0.00,0.0005,0.00058,3.000
3,39.688,0.00,-0.0003,-0.00020,3.000
3,39.812,-0.01,-0.0003,-0.00020,3.000
3,39.938,0.00,-0.0003,-0.00020,3.000
3,40.062,0.00,-0.0003,-0.00020,3.000
3,40.188,-0.01,-0.0003,-0.00020,3.000
3,40.312,0.00,-0.0003,-0.00020,3.000
3,40.438,-0.01,-0.0003,-0.00020,3.000
3,40.562,0.00,-0.0003,-0.00020,3.000
3,40.688,-0.01,-0.0003,-0.00020,3.000
3,40.812,0.00,-0.0003,-0.00020,3.000
3,40.938,0.00,-0.0003,-0.00020,3.000
3,41.062,0.00,-0.0002,-0.00010,3.000
3,41.188,0.00,-0.0002,-0.00010,3.000
3,41.312,0.00,-0.0002,-0.00010,3.000
3,41.438,-0.01,-0.0002,-0.00010,3.000
3,41.562,-0.01,-0.0002,-0.00010,3.000
3,41.688,0.00,-0.0002,-0.00010,3.000
3,41.812,0.00,-0.0002,-0.00010,3.000
3,41.938,0.00,-0.0002,-0.00010,3.000
3,42.062,0.00,-0.0002,-0.00010,3.000
3,42.188,-0.01,-0.0002,-0.00010,3.000
3,42.312,0.00,-0.0002,-0.00010,3.000
3,42.438,-0.01,-0.0002,-0.00010,3.000
4,42.812,0.01,0.1550,0.15515,4.000
4,42.938,0.01,0.2801,0.28015,4.000
4,43.062,0.01,0.4050,0.40515,4.000
4,43.188,0.01,0.5301,0.53018,4.000
4,43.312,0.01,0.6550,0.65510,4.000
4,43.438,0.01,0.7803,0.78035,4.000
4,43.562,0.01,0.9052,0.90532,4.000
4,43.688,0.01,1.0302,1.03025,4.000
4,43.812,0.01,1.1552,1.15535,4.000
4,43.938,0.01,1.2801,1.28023,4.000
4,44.062,0.01,1.4051,1.40522,4.000
4,44.188,0.01,1.5302,1.53025,4.000
4,44.312,0.01,1.6551,1.65525,4.000
4,44.438,0.01,1.7803,1.78043,4.000
4,44.562,0.01,1.9053,1.90537,4.000
4,44.688,0.01,2.0303,2.03038,4.000
4,44.812,0.01,2.1553,2.15537,4.000
4,44.938,0.01,2.2802,2.28033,4.000
4,45.062,0.03,2.4052,2.40532,4.000
4,45.188,0.05,2.5302,2.53025,4.000
4,45.312,0.09,2.6551,2.65522,4.000
4,45.438,0.16,2.7802,2.78028,4.000
4,45.562,0.30,2.9053,2.90542,4.000
4,45.688,0.53,3.0304,3.03048,4.000
4,45.812,0.82,3.1552,3.15532,4.000
4,45.938,1.22,3.2804,3.28053,4.000
4,46.062,1.71,3.4053,3.40542,4.000
4,46.188,2.32,3.5303,3.53040,4.000
4,46.312,3.02,3.6552,3.65535,4.000
4,46.438,3.85,3.7804,3.78045,4.000
4,46.562,4.80,3.9053,3.90545,4.000
4,46.688,5.90,4.0303,4.03040,4.000
4,46.812,7.10,4.1553,4.15542,4.000
4,46.938,8.43,4.2804,4.28050,4.000
4,47.062,9.87,4.4053,4.40545,4.000
4,47.188,11.43,4.5303,4.53038,4.000
4,47.312,13.31,4.6552,4.65532,4.000
4,47.438,15.51,4.7802,4.78030,4.000
4,47.562,18.03,4.9053,4.90537,4.000
4,47.688,20.80,5.0303,5.03038,4.000
4,47.812,23.84,5.1553,5.15540,4.000
4,47.938,27.23,5.2804,5.28050,4.000
4,48.125,31.27,5.4154,5.41550,4.000
4,48.250,24.51,5.2935,5.29360,4.000
4,48.375,19.58,5.1686,5.16870,4.000
4,48.500,15.81,5.0436,5.04370,4.000
4,48.625,12.94,4.9187,4.91875,4.000
4,48.750,10.70,4.7936,4.79370,4.000
4,48.875,8.96,4.6686,4.66870,4.000
4,49.000,7.45,4.5435,4.54360,4.000
4,49.125,6.16,4.4184,4.41850,4.000
4,49.250,5.06,4.2934,4.29350,4.000
4,49.375,4.11,4.1685,4.16855,4.000
4,49.500,3.34,4.0435,4.04360,4.000
4,49.625,2.68,3.9185,3.91860,4.000
4,49.750,2.13,3.7935,3.79360,4.000
4,49.875,1.66,3.6685,3.66860,4.000
4,50.000,1.28,3.5434,3.54350,4.000
4,50.125,0.93,3.4184,3.41850,4.000
4,50.250,0.66,3.2934,3.29350,4.000
4,50.375,0.41,3.1683,3.16840,4.000
4,50.500,0.24,3.0434,3.04350,4.000
4,50.625,0.12,2.9185,2.91855,4.000
4,50.750,0.05,2.7934,2.79350,4.000
4,50.875,0.03,2.6684,2.66845,4.000
4,51.000,0.02,2.5433,2.54340,4.000
4,51.125,0.01,2.4184,2.41845,4.000
4,51.250,0.01,2.2933,2.29340,4.000
4,51.375,0.01,2.1683,2.16840,4.000
4,51.500,0.01,2.0434,2.04350,4.000
4,51.625,0.01,1.9183,1.91840,4.000
4,51.750,0.01,1.7935,1.79360,4.000
4,51.875,0.01,1.6684,1.66850,4.000
4,52.000,0.01,1.5434,1.54350,4.000
4,52.125,0.01,1.4184,1.41845,4.000
4,52.250,0.02,1.2932,1.29330,4.000
4,52.375,0.01,1.1683,1.16835,4.000
4,52.500,0.01,1.0433,1.04340,4.000
4,52.625,0.02,0.9183,0.91840,4.000
4,52.750,0.01,0.7934,0.79350,4.000
4,52.875,0.01,0.6682,0.66830,4.000
4,53.000,0.01,0.5434,0.54350,4.000
4,53.125,0.02,0.4183,0.41840,4.000
4,53.250,0.01,0.2933,0.29340,4.000
4,53.375,0.00,0.1681,0.16820,4.000
4,53.500,0.01,0.0430,0.04310,4.000
4,53.750,0.01,-0.0003,-0.00020,4.000
4,53.875,0.01,-0.0003,-0.00020,4.000
4,54.000,0.01,-0.0003,-0.00020,4.000
4,54.125,0.01,-0.0003,-0.00020,4.000
4,54.250,0.01,-0.0003,-0.00020,4.000
4,54.375,0.01,-0.0003,-0.00020,4.000
4,54.500,0.01,-0.0003,-0.00020,4.000
4,54.625,0.01,-0.0003,-0.00020,4.000
4,54.750,0.01,-0.0003,-0.00020,4.000
4,54.875,0.01,-0.0003,-0.00020,4.000
4,55.000,0.02,-0.0002,-0.00010,4.000
4,55.125,0.01,-0.0002,-0.00010,4.000
4,55.250,0.01,-0.0002,-0.00010,4.000
4,55.375,0.01,-0.0002,-0.00010,4.000
4,55.500,0.02,-0.0002,-0.00010,4.000
4,55.625,0.01,-0.0002,-0.00010,4.000
4,55.750,0.02,-0.0002,-0.00010,4.000
4,55.875,0.01,-0.0002,-0.00010,4.000
4,56.000,0.01,-0.0002,-0.00010,4.000
4,56.125,0.01,-0.0002,-0.00010,4.000
4,56.250,0.01,-0.0002,-0.00010,4.000
4,56.375,0.01,-0.0002,-0.00010,4.000
4,56.500,0.01,-0.0002,-0.00010,4.000
4,56.625,0.01,-0.0002,-0.00010,4.000
5,57.000,0.02,0.1485,0.14860,5.000
5,57.125,0.01,0.2736,0.27370,5.000
5,57.250,0.01,0.3986,0.39870,5.000
5,57.375,0.01,0.5236,0.52370,5.000
5,57.500,0.01,0.6484,0.64850,5.000
5,57.625,0.01,0.7737,0.77380,5.000
5,57.750,0.01,0.8986,0.89870,5.000
5,57.875,0.01,1.0237,1.02385,5.000
5,58.000,0.01,1.1486,1.14870,5.000
5,58.125,0.01,1.2736,1.27375,5.000
5,58.250,0.01,1.3988,1.39890,5.000
5,58.375,0.01,1.5237,1.52380,5.000
5,58.500,0.01,1.6486,1.64870,5.000
5,58.625,0.01,1.7737,1.77380,5.000
5,58.750,0.01,1.8987,1.89880,5.000
5,58.875,0.01,2.0237,2.02380,5.000
5,59.000,0.01,2.1488,2.14890,5.000
5,59.125,0.01,2.2738,2.27390,5.000
5,59.250,0.02,2.3989,2.39900,5.000
5,59.375,0.04,2.5237,2.52385,5.000
5,59.500,0.08,2.6486,2.64870,5.000
5,59.625,0.14,2.7736,2.77375,5.000
5,59.750,0.29,2.8987,2.89880,5.000
5,59.875,0.49,3.0238,3.02390,5.000
5,60.000,0.79,3.1489,3.14900,5.000
5,60.125,1.18,3.2739,3.27400,5.000
5,60.250,1.66,3.3989,3.39900,5.000
5,60.375,2.25,3.5238,3.52395,5.000
5,60.500,2.96,3.6488,3.64890,5.000
5,60.625,3.79,3.7737,3.77385,5.000
5,60.750,4.74,3.8987,3.89880,5.000
5,60.875,5.82,4.0238,4.02390,5.000
5,61.000,7.04,4.1489,4.14900,5.000
5,61.125,8.37,4.2739,4.27400,5.000
5,61.250,9.80,4.3989,4.39900,5.000
5,61.375,11.37,4.5238,4.52390,5.000
5,61.500,13.21,4.6488,4.64890,5.000
5,61.625,15.40,4.7737,4.77385,5.000
5,61.750,17.88,4.8987,4.89880,5.000
5,61.875,20.64,5.0237,5.02380,5.000
5,62.000,23.69,5.1489,5.14900,5.000
5,62.125,27.06,5.2739,5.27400,5.000
5,62.250,30.77,5.3989,5.39900,5.000
5,62.375,27.75,5.3547,5.35475,5.000
5,62.500,21.90,5.2296,5.22970,5.000
5,62.625,17.59,5.1045,5.10455,5.000
5,62.750,14.31,4.9795,4.97960,5.000
5,62.875,11.71,4.8545,4.85460,5.000
5,63.000,9.80,4.7295,4.72960,5.000
5,63.125,8.17,4.6046,4.60470,5.000
5,63.250,6.77,4.4795,4.47960,5.000
5,63.375,5.57,4.3546,4.35465,5.000
5,63.500,4.55,4.2295,4.22960,5.000
5,63.625,3.69,4.1044,4.10450,5.000
5,63.750,2.98,3.9793,3.97940,5.000
5,63.875,2.37,3.8545,3.85455,5.000
5,64.000,1.88,3.7295,3.72960,5.000
5,64.125,1.45,3.6044,3.60455,5.000
5,64.250,1.08,3.4794,3.47950,5.000
5,64.375,0.77,3.3546,3.35465,5.000
5,64.500,0.51,3.2296,3.22970,5.000
5,64.625,0.31,3.1044,3.10450,5.000
5,64.750,0.17,2.9793,2.97940,5.000
5,64.875,0.08,2.8544,2.85445,5.000
5,65.000,0.03,2.7293,2.72940,5.000
5,65.125,0.01,2.6042,2.60435,5.000
5,65.250,0.01,2.4794,2.47950,5.000
5,65.375,0.01,2.3544,2.35450,5.000
5,65.500,0.01,2.2294,2.22950,5.000
5,65.625,0.01,2.1044,2.10450,5.000
5,65.750,0.01,1.9794,1.97950,5.000
5,65.875,0.01,1.8543,1.85440,5.000
5,66.000,0.01,1.7293,1.72940,5.000
5,66.125,0.01,1.6044,1.60445,5.000
5,66.250,0.02,1.4794,1.47950,5.000
5,66.375,0.01,1.3544,1.35445,5.000
5,66.500,0.01,1.2293,1.22940,5.000
5,66.625,0.01,1.1044,1.10445,5.000
5,66.750,0.01,0.9794,0.97950,5.000
5,66.875,0.01,0.8544,0.85445,5.000
5,67.000,0.01,0.7292,0.72930,5.000
5,67.125,0.01,0.6040,0.60415,5.000
5,67.250,-0.01,0.4794,0.47950,5.000
5,67.375,0.01,0.3544,0.35445,5.000
5,67.500,0.01,0.2292,0.22930,5.000
5,67.625,0.01,0.1042,0.10430,5.000
5,67.750,0.01,-0.0207,-0.02060,5.000
5,67.938,0.01,-0.0003,-0.00020,5.000
5,68.062,0.01,-0.0003,-0.00020,5.000
5,68.188,0.01,-0.0003,-0.00020,5.000
5,68.312,0.01,-0.0003,-0.00020,5.000
5,68.438,0.01,-0.0003,-0.00020,5.000
5,68.562,0.01,-0.0003,-0.00020,5.000
5,68.688,0.01,-0.0003,-0.00020,5.000
5,68.812,0.01,-0.0003,-0.00020,5.000
5,68.938,0.01,-0.0003,-0.00020,5.000
5,69.062,0.01,-0.0003,-0.00020,5.000
5,69.188,0.01,-0.0003,-0.00020,5.000
5,69.312,0.01,-0.0003,-0.00020,5.000
5,69.438,0.01,-0.0003,-0.00020,5.000
5,69.562,0.01,-0.0003,-0.00020,5.000
5,69.688,0.01,-0.0003,-0.00020,5.000
5,69.812,0.01,-0.0002,-0.00010,5.000
5,69.938,0.00,-0.0002,-0.00010,5.000
5,70.062,0.01,-0.0002,-0.00010,5.000
5,70.188,0.01,-0.0002,-0.00010,5.000
5,70.312,0.01,-0.0002,-0.00010,5.000
5,70.438,0.01,-0.0002,-0.00010,5.000
5,70.562,0.01,-0.0002,-0.00010,5.000
5,70.688,0.01,-0.0002,-0.00010,5.000
5,70.812,0.01,-0.0002,-0.00010,5.000
6,71.125,0.00,0.1274,0.12755,6.000
6,71.250,-0.01,0.2526,0.25270,6.000
6,71.375,0.00,0.3776,0.37770,6.000
6,71.500,0.00,0.5027,0.50280,6.000
6,71.625,-0.01,0.6275,0.62760,6.000
6,71.750,0.00,0.7527,0.75280,6.000
6,71.875,-0.01,0.8777,0.87780,6.000
6,72.000,-0.01,1.0027,1.00280,6.000
6,72.125,-0.01,1.1276,1.12770,6.000
6,72.250,-0.01,1.2526,1.25270,6.000
6,72.375,-0.01,1.3776,1.37775,6.000
6,72.500,-0.01,1.5027,1.50280,6.000
6,72.625,-0.01,1.6278,1.62790,6.000
6,72.750,-0.01,1.7529,1.75300,6.000
6,72.875,-0.01,1.8778,1.87785,6.000
6,73.000,0.00,2.0026,2.00270,6.000
6,73.125,-0.01,2.1277,2.12780,6.000
6,73.250,0.00,2.2526,2.25270,6.000
6,73.375,0.00,2.3777,2.37780,6.000
6,73.500,0.02,2.5027,2.50280,6.000
6,73.625,0.06,2.6278,2.62785,6.000
6,73.750,0.12,2.7528,2.75290,6.000
6,73.875,0.24,2.8778,2.87790,6.000
6,74.000,0.44,3.0028,3.00290,6.000
6,74.125,0.72,3.1276,3.12775,6.000
6,74.250,1.08,3.2527,3.25280,6.000
6,74.375,1.55,3.3778,3.37790,6.000
6,74.500,2.12,3.5028,3.50290,6.000
6,74.625,2.80,3.6278,3.62790,6.000
6,74.750,3.59,3.7528,3.75290,6.000
6,74.875,4.53,3.8779,3.87800,6.000
6,75.000,5.59,4.0030,4.00310,6.000
6,75.125,6.77,4.1279,4.12795,6.000
6,75.250,8.06,4.2527,4.25280,6.000
6,75.375,9.48,4.3778,4.37785,6.000
6,75.500,11.02,4.5028,4.50290,6.000
6,75.625,12.76,4.6279,4.62795,6.000
6,75.750,14.92,4.7529,4.75300,6.000
6,75.875,17.33,4.8779,4.87795,6.000
6,76.000,20.04,5.0028,5.00290,6.000
6,76.125,23.03,5.1278,5.12790,6.000
6,76.250,26.33,5.2528,5.25290,6.000
6,76.375,29.97,5.3778,5.37790,6.000
6,76.562,26.48,5.3410,5.34113,6.000
6,76.688,21.03,5.2160,5.21612,6.000
6,76.812,16.92,5.0910,5.09113,6.000
6,76.938,13.81,4.9661,4.96622,6.000
6,77.062,11.32,4.8411,4.84123,6.000
6,77.188,9.49,4.7161,4.71620,6.000
6,77.312,7.91,4.5912,4.59125,6.000
6,77.438,6.55,4.4660,4.46608,6.000
6,77.562,5.38,4.3410,4.34108,6.000
6,77.688,4.39,4.2159,4.21600,6.000
6,77.812,3.56,4.0909,4.09103,6.000
6,77.938,2.86,3.9660,3.96608,6.000
6,78.062,2.28,3.8410,3.84113,6.000
6,78.188,1.79,3.7161,3.71618,6.000
6,78.312,1.39,3.5910,3.59110,6.000
6,78.438,1.02,3.4659,3.46602,6.000
6,78.562,0.71,3.3410,3.34108,6.000
6,78.688,0.47,3.2158,3.21588,6.000
6,78.812,0.28,3.0908,3.09093,6.000
6,78.938,0.14,2.9660,2.96610,6.000
6,79.062,0.05,2.8410,2.84108,6.000
6,79.188,0.02,2.7159,2.71602,6.000
6,79.312,0.00,2.5909,2.59098,6.000
6,79.438,0.00,2.4660,2.46610,6.000
6,79.562,-0.01,2.3409,2.34103,6.000
6,79.688,-0.01,2.2158,2.21585,6.000
6,79.812,0.00,2.0908,2.09090,6.000
6,79.938,-0.01,1.9658,1.96585,6.000
6,80.062,-0.01,1.8409,1.84095,6.000
6,80.188,0.00,1.7159,1.71600,6.000
6,80.312,-0.01,1.5909,1.59100,6.000
6,80.438,-0.01,1.4659,1.46602,6.000
6,80.562,-0.01,1.3408,1.34093,6.000
6,80.688,-0.02,1.2157,1.21578,6.000
6,80.812,0.00,1.0907,1.09075,6.000
6,80.938,-0.01,0.9658,0.96588,6.000
6,81.062,0.00,0.8409,0.84095,6.000
6,81.188,-0.01,0.7158,0.71588,6.000
6,81.312,0.00,0.5907,0.59075,6.000
6,81.438,0.00,0.4659,0.46598,6.000
6,81.562,0.00,0.3408,0.34088,6.000
6,81.688,-0.01,0.2156,0.21575,6.000
6,81.812,0.00,0.0907,0.09075,6.000
6,82.062,-0.01,-0.0016,-0.00153,6.000
6,82.188,-0.01,-0.0003,-0.00020,6.000
6,82.312,0.00,-0.0003,-0.00020,6.000
6,82.438,0.00,-0.0003,-0.00020,6.000
6,82.562,0.00,-0.0003,-0.00020,6.000
6,82.688,0.00,-0.0003,-0.00020,6.000
6,82.812,-0.01,-0.0003,-0.00020,6.000
6,82.938,-0.01,-0.0003,-0.00020,6.000
6,83.062,-0.01,-0.0003,-0.00020,6.000
6,83.188,0.00,-0.0002,-0.00010,6.000
6,83.312,-0.01,-0.0002,-0.00010,6.000
6,83.438,-0.01,-0.0002,-0.00010,6.000
6,83.562,0.00,-0.0002,-0.00010,6.000
6,83.688,-0.01,-0.0002,-0.00010,6.000
6,83.812,-0.01,-0.0002,-0.00010,6.000
6,83.938,-0.01,-0.0002,-0.00010,6.000
6,84.062,0.00,-0.0002,-0.00010,6.000
6,84.188,-0.01,-0.0002,-0.00010,6.000
6,84.312,0.00,-0.0002,-0.00010,6.000
6,84.438,-0.01,-0.0002,-0.00010,6.000
6,84.562,-0.01,-0.0002,-0.00010,6.000
6,84.688,-0.01,-0.0002,-0.00010,6.000
6,84.812,-0.01,-0.0002,-0.00010,6.000
6,84.938,-0.01,-0.0002,-0.00010,6.000
7,85.250,-0.01,0.0575,0.05760,7.000
7,85.375,-0.01,0.1825,0.18260,7.000
7,85.500,-0.01,0.3076,0.30770,7.000
7,85.625,-0.01,0.4328,0.43285,7.000
7,85.750,-0.01,0.5576,0.55770,7.000
7,85.875,-0.01,0.6826,0.68265,7.000
7,86.000,-0.01,0.8077,0.80780,7.000
7,86.125,-0.01,0.9327,0.93275,7.000
7,86.250,0.00,1.0577,1.05780,7.000
7,86.375,-0.01,1.1826,1.18275,7.000
7,86.500,0.00,1.3076,1.30770,7.000
7,86.625,-0.01,1.4328,1.43285,7.000
7,86.750,0.00,1.5579,1.55800,7.000
7,86.875,-0.01,1.6827,1.68280,7.000
7,87.000,-0.01,1.8077,1.80780,7.000
7,87.125,-0.01,1.9327,1.93275,7.000
7,87.250,0.00,2.0576,2.05770,7.000
7,87.375,-0.01,2.1827,2.18280,7.000
7,87.500,-0.01,2.3078,2.30790,7.000
7,87.625,0.00,2.4329,2.43300,7.000
7,87.750,0.03,2.5579,2.55800,7.000
7,87.875,0.07,2.6827,2.68280,7.000
7,88.000,0.15,2.8077,2.80780,7.000
7,88.125,0.30,2.9328,2.93290,7.000
7,88.250,0.54,3.0577,3.05780,7.000
7,88.375,0.85,3.1827,3.18280,7.000
7,88.500,1.26,3.3079,3.30800,7.000
7,88.625,1.77,3.4328,3.43295,7.000
7,88.750,2.38,3.5578,3.55790,7.000
7,88.875,3.12,3.6829,3.68300,7.000
7,89.000,3.97,3.8079,3.80800,7.000
7,89.125,4.96,3.9328,3.93290,7.000
7,89.250,6.07,4.0576,4.05770,7.000
7,89.375,7.32,4.1827,4.18280,7.000
7,89.500,8.67,4.3078,4.30790,7.000
7,89.625,10.14,4.4328,4.43290,7.000
7,89.750,11.74,4.5579,4.55800,7.000
7,89.875,13.69,4.6829,4.68300,7.000
7,90.000,15.93,4.8078,4.80790,7.000
7,90.125,18.49,4.9328,4.93290,7.000
7,90.250,21.32,5.0577,5.05780,7.000
7,90.375,24.45,5.1827,5.18280,7.000
7,90.500,27.91,5.3078,5.30790,7.000
7,90.688,31.14,5.4209,5.42095,7.000
7,90.812,24.21,5.2961,5.29615,7.000
7,90.938,19.35,5.1711,5.17118,7.000
7,91.062,15.64,5.0460,5.04613,7.000
7,91.188,12.79,4.9211,4.92120,7.000
7,91.312,10.60,4.7961,4.79620,7.000
7,91.438,8.86,4.6711,4.67122,7.000
7,91.562,7.36,4.5460,4.54610,7.000
7,91.688,6.07,4.4209,4.42098,7.000
7,91.812,4.97,4.2959,4.29603,7.000
7,91.938,4.04,4.1709,4.17105,7.000
7,92.062,3.27,4.0461,4.04618,7.000
7,92.188,2.62,3.9211,3.92118,7.000
7,92.312,2.07,3.7961,3.79618,7.000
7,92.438,1.63,3.6710,3.67113,7.000
7,92.562,1.22,3.5460,3.54605,7.000
7,92.688,0.89,3.4208,3.42095,7.000
7,92.812,0.61,3.2959,3.29603,7.000
7,92.938,0.38,3.1708,3.17095,7.000
7,93.062,0.21,3.0459,3.04598,7.000
7,93.188,0.09,2.9209,2.92100,7.000
7,93.312,0.03,2.7960,2.79605,7.000
7,93.438,0.01,2.6710,2.67105,7.000
7,93.562,0.00,2.5459,2.54595,7.000
7,93.688,0.00,2.4208,2.42095,7.000
7,93.812,0.00,2.2958,2.29590,7.000
7,93.938,-0.01,2.1707,2.17082,7.000
7,94.062,-0.02,2.0458,2.04585,7.000
7,94.188,-0.01,1.9208,1.92085,7.000
7,94.312,-0.01,1.7960,1.79610,7.000
7,94.438,0.00,1.6708,1.67093,7.000
7,94.562,-0.01,1.5459,1.54598,7.000
7,94.688,-0.02,1.4209,1.42100,7.000
7,94.812,0.00,1.2958,1.29588,7.000
7,94.938,-0.01,1.1708,1.17090,7.000
7,95.062,-0.01,1.0457,1.04578,7.000
7,95.188,-0.01,0.9208,0.92088,7.000
7,95.312,-0.01,0.7959,0.79600,7.000
7,95.438,-0.01,0.6707,0.67080,7.000
7,95.562,-0.01,0.5459,0.54595,7.000
7,95.688,0.00,0.4208,0.42090,7.000
7,95.812,-0.01,0.2956,0.29573,7.000
7,95.938,-0.01,0.1707,0.17078,7.000
7,96.062,-0.01,0.0456,0.04573,7.000
7,96.250,-0.01,-0.0052,-0.00510,7.000
7,96.375,-0.01,-0.0003,-0.00020,7.000
7,96.500,-0.01,-0.0002,-0.00010,7.000
7,96.625,-0.01,-0.0002,-0.00010,7.000
7,96.750,-0.01,-0.0002,-0.00010,7.000
7,96.875,-0.01,-0.0002,-0.00010,7.000
7,97.000,-0.01,-0.0002,-0.00010,7.000
7,97.125,-0.01,-0.0002,-0.00010,7.000
7,97.250,-0.01,-0.0002,-0.00010,7.000
7,97.375,-0.01,-0.0002,-0.00010,7.000
7,97.500,0.00,-0.0002,-0.00010,7.000
7,97.625,-0.01,-0.0002,-0.00010,7.000
7,97.750,-0.01,-0.0002,-0.00010,7.000
7,97.875,-0.01,-0.0002,-0.00010,7.000
7,98.000,-0.01,-0.0002,-0.00010,7.000
7,98.125,-0.01,-0.0002,-0.00010,7.000
7,98.250,-0.01,-0.0002,-0.00010,7.000
7,98.375,-0.01,-0.0002,-0.00010,7.000
7,98.500,-0.01,-0.0002,-0.00010,7.000
7,98.625,-0.01,-0.0002,-0.00010,7.000
7,98.750,-0.01,-0.0002,-0.00010,7.000
7,98.875,0.00,-0.0002,-0.00010,7.000
7,99.000,-0.01,-0.0002,-0.00010,7.000
7,99.125,-0.01,-0.0002,-0.00010,7.000
8,99.438,0.02,0.0490,0.04912,8.000
8,99.562,0.02,0.1739,0.17402,8.000
8,99.688,0.02,0.2990,0.29910,8.000
8,99.812,0.03,0.4242,0.42430,8.000
8,99.938,0.03,0.5491,0.54920,8.000
8,100.062,0.02,0.6740,0.67412,8.000
8,100.188,0.02,0.7993,0.79938,8.000
8,100.312,0.03,0.9241,0.92420,8.000
8,100.438,0.02,1.0491,1.04920,8.000
8,100.562,0.03,1.1740,1.17415,8.000
8,100.688,0.02,1.2992,1.29925,8.000
8,100.812,0.02,1.4241,1.42422,8.000
8,100.938,0.03,1.5492,1.54932,8.000
8,101.062,0.02,1.6742,1.67432,8.000
8,101.188,0.02,1.7993,1.79940,8.000
8,101.312,0.01,1.9242,1.92427,8.000
8,101.438,0.02,2.0492,2.04925,8.000
8,101.562,0.03,2.1741,2.17422,8.000
8,101.688,0.02,2.2992,2.29930,8.000
8,101.812,0.04,2.4242,2.42435,8.000
8,101.938,0.06,2.5491,2.54923,8.000
8,102.062,0.10,2.6742,2.67432,8.000
8,102.188,0.17,2.7993,2.79940,8.000
8,102.312,0.33,2.9243,2.92445,8.000
8,102.438,0.54,3.0492,3.04928,8.000
8,102.562,0.85,3.1741,3.17425,8.000
8,102.688,1.25,3.2994,3.29948,8.000
8,102.812,1.75,3.4243,3.42437,8.000
8,102.938,2.36,3.5492,3.54933,8.000
8,103.062,3.08,3.6744,3.67452,8.000
8,103.188,3.92,3.7994,3.79950,8.000
8,103.312,4.88,3.9244,3.92455,8.000
8,103.438,5.99,4.0493,4.04942,8.000
8,103.562,7.21,4.1743,4.17437,8.000
8,103.688,8.56,4.2993,4.29940,8.000
8,103.812,10.02,4.4242,4.42430,8.000
8,103.938,11.62,4.5493,4.54937,8.000
8,104.062,13.53,4.6743,4.67442,8.000
8,104.188,15.73,4.7994,4.79950,8.000
8,104.312,18.26,4.9244,4.92447,8.000
8,104.438,21.07,5.0493,5.04935,8.000
8,104.562,24.16,5.1743,5.17437,8.000
8,104.688,27.57,5.2993,5.29935,8.000
8,104.875,31.40,5.4278,5.42785,8.000
8,105.000,24.52,5.3045,5.30460,8.000
8,105.125,19.59,5.1796,5.17965,8.000
8,105.250,15.82,5.0545,5.05460,8.000
8,105.375,12.95,4.9296,4.92965,8.000
8,105.500,10.72,4.8045,4.80460,8.000
8,105.625,8.97,4.6796,4.67970,8.000
8,105.750,7.46,4.5547,4.55480,8.000
8,105.875,6.16,4.4295,4.42960,8.000
8,106.000,5.06,4.3045,4.30460,8.000
8,106.125,4.12,4.1794,4.17955,8.000
8,106.250,3.34,4.0544,4.05450,8.000
8,106.375,2.68,3.9296,3.92965,8.000
8,106.500,2.13,3.8045,3.80460,8.000
8,106.625,1.68,3.6796,3.67965,8.000
8,106.750,1.28,3.5545,3.55460,8.000
8,106.875,0.93,3.4295,3.42960,8.000
8,107.000,0.64,3.3045,3.30460,8.000
8,107.125,0.42,3.1793,3.17940,8.000
8,107.250,0.25,3.0544,3.05450,8.000
8,107.375,0.13,2.9294,2.92945,8.000
8,107.500,0.06,2.8044,2.80450,8.000
8,107.625,0.04,2.6794,2.67950,8.000
8,107.750,0.04,2.5543,2.55440,8.000
8,107.875,0.03,2.4295,2.42960,8.000
8,108.000,0.02,2.3043,2.30440,8.000
8,108.125,0.01,2.1793,2.17940,8.000
8,108.250,0.02,2.0543,2.05440,8.000
8,108.375,0.01,1.9292,1.92930,8.000
8,108.500,0.01,1.8044,1.80450,8.000
8,108.625,0.02,1.6794,1.67945,8.000
8,108.750,0.01,1.5545,1.55460,8.000
8,108.875,0.01,1.4294,1.42950,8.000
8,109.000,0.02,1.3043,1.30440,8.000
8,109.125,0.02,1.1793,1.17940,8.000
8,109.250,0.02,1.0541,1.05420,8.000
8,109.375,0.03,0.9292,0.92930,8.000
8,109.500,0.02,0.8044,0.80450,8.000
8,109.625,0.02,0.6792,0.67930,8.000
8,109.750,0.02,0.5543,0.55440,8.000
8,109.875,0.02,0.4294,0.42945,8.000
8,110.000,0.02,0.3044,0.30450,8.000
8,110.125,0.02,0.1792,0.17930,8.000
8,110.250,0.02,0.0542,0.05430,8.000
8,110.438,0.02,-0.0189,-0.01875,8.000
8,110.562,0.02,-0.0002,-0.00010,8.000
8,110.688,0.02,-0.0002,-0.00010,8.000
8,110.812,0.02,-0.0002,-0.00010,8.000
8,110.938,0.02,-0.0002,-0.00010,8.000
8,111.062,0.02,-0.0002,-0.00010,8.000
8,111.188,0.02,-0.0002,-0.00010,8.000
8,111.312,0.03,-0.0002,-0.00010,8.000
8,111.438,0.02,-0.0002,-0.00010,8.000
8,111.562,0.02,-0.0002,-0.00010,8.000
8,111.688,0.02,-0.0002,-0.00010,8.000
8,111.812,0.02,-0.0002,-0.00010,8.000
8,111.938,0.02,-0.0002,-0.00010,8.000
8,112.062,0.02,-0.0002,-0.00010,8.000
8,112.188,0.02,-0.0002,-0.00010,8.000
8,112.312,0.02,-0.0002,-0.00010,8.000
8,112.438,0.02,-0.0002,-0.00010,8.000
8,112.562,0.02,-0.0002,-0.00010,8.000
8,112.688,0.02,-0.0002,-0.00010,8.000
8,112.812,0.02,-0.0002,-0.00010,8.000
8,112.938,0.02,-0.0002,-0.00010,8.000
8,113.062,0.02,-0.0002,-0.00010,8.000
8,113.188,0.02,-0.0002,-0.00010,8.000
8,113.312,0.03,-0.0002,-0.00010,8.000
9,113.625,0.00,0.0475,0.04755,9.000
9,113.750,0.01,0.1724,0.17250,9.000
9,113.875,0.01,0.2975,0.29760,9.000
9,114.000,0.01,0.4227,0.42280,9.000
9,114.125,0.01,0.5476,0.54770,9.000
9,114.250,0.01,0.6726,0.67270,9.000
9,114.375,0.00,0.7978,0.79785,9.000
9,114.500,0.02,0.9226,0.92270,9.000
9,114.625,0.01,1.0476,1.04770,9.000
9,114.750,0.01,1.1725,1.17260,9.000
9,114.875,0.01,1.2976,1.29765,9.000
9,115.000,0.00,1.4227,1.42280,9.000
9,115.125,0.01,1.5478,1.54785,9.000
9,115.250,0.01,1.6727,1.67280,9.000
9,115.375,0.01,1.7979,1.79795,9.000
9,115.500,0.01,1.9228,1.92290,9.000
9,115.625,0.00,2.0476,2.04775,9.000
9,115.750,0.01,2.1726,2.17270,9.000
9,115.875,0.01,2.2976,2.29775,9.000
9,116.000,0.02,2.4228,2.42290,9.000
9,116.125,0.04,2.5477,2.54780,9.000
9,116.250,0.08,2.6727,2.67280,9.000
9,116.375,0.15,2.7978,2.79790,9.000
9,116.500,0.30,2.9229,2.92300,9.000
9,116.625,0.52,3.0478,3.04785,9.000
9,116.750,0.83,3.1727,3.17280,9.000
9,116.875,1.22,3.2978,3.29790,9.000
9,117.000,1.71,3.4227,3.42280,9.000
9,117.125,2.32,3.5478,3.54790,9.000
9,117.250,3.04,3.6729,3.67300,9.000
9,117.375,3.87,3.7979,3.79795,9.000
9,117.500,4.83,3.9230,3.92310,9.000
9,117.625,5.93,4.0479,4.04795,9.000
9,117.750,7.15,4.1728,4.17290,9.000
9,117.875,8.49,4.2978,4.29785,9.000
9,118.000,9.94,4.4228,4.42290,9.000
9,118.125,11.54,4.5478,4.54785,9.000
9,118.250,13.42,4.6728,4.67290,9.000
9,118.375,15.64,4.7979,4.79795,9.000
9,118.500,18.15,4.9228,4.92290,9.000
9,118.625,20.93,5.0478,5.04790,9.000
9,118.750,24.01,5.1727,5.17280,9.000
9,118.875,27.43,5.2978,5.29785,9.000
9,119.000,31.18,5.4227,5.42280,9.000
9,119.125,28.11,5.3786,5.37865,9.000
9,119.250,22.17,5.2537,5.25380,9.000
9,119.375,17.79,5.1286,5.12870,9.000
9,119.500,14.46,5.0036,5.00370,9.000
9,119.625,11.84,4.8786,4.87870,9.000
9,119.750,9.90,4.7536,4.75370,9.000
9,119.875,8.26,4.6286,4.62870,9.000
9,120.000,6.84,4.5033,4.50340,9.000
9,120.125,5.64,4.3784,4.37850,9.000
9,120.250,4.61,4.2534,4.25350,9.000
9,120.375,3.74,4.1286,4.12865,9.000
9,120.500,3.02,4.0036,4.00370,9.000
9,120.625,2.41,3.8786,3.87865,9.000
9,120.750,1.91,3.7535,3.75360,9.000
9,120.875,1.48,3.6284,3.62855,9.000
9,121.000,1.09,3.5034,3.50350,9.000
9,121.125,0.78,3.3784,3.37850,9.000
9,121.250,0.52,3.2534,3.25350,9.000
9,121.375,0.32,3.1284,3.12850,9.000
9,121.500,0.18,3.0036,3.00370,9.000
9,121.625,0.08,2.8785,2.87860,9.000
9,121.750,0.03,2.7535,2.75360,9.000
9,121.875,0.02,2.6283,2.62840,9.000
9,122.000,0.02,2.5034,2.50350,9.000
9,122.125,0.00,2.3784,2.37845,9.000
9,122.250,0.00,2.2533,2.25340,9.000
9,122.375,0.01,2.1283,2.12840,9.000
9,122.500,0.01,2.0034,2.00350,9.000
9,122.625,0.00,1.8784,1.87850,9.000
9,122.750,0.00,1.7535,1.75360,9.000
9,122.875,0.01,1.6284,1.62845,9.000
9,123.000,0.01,1.5034,1.50350,9.000
9,123.125,0.01,1.3783,1.37835,9.000
9,123.250,0.01,1.2533,1.25340,9.000
9,123.375,0.00,1.1282,1.12830,9.000
9,123.500,0.01,1.0033,1.00340,9.000
9,123.625,0.00,0.8784,0.87845,9.000
9,123.750,0.00,0.7534,0.75350,9.000
9,123.875,0.00,0.6282,0.62830,9.000
9,124.000,0.00,0.5033,0.50340,9.000
9,124.125,0.01,0.3782,0.37830,9.000
9,124.250,0.00,0.2531,0.25320,9.000
9,124.375,0.00,0.1282,0.12825,9.000
9,124.500,0.01,0.0031,0.00320,9.000
9,124.688,0.01,-0.0007,-0.00055,9.000
9,124.812,0.00,-0.0002,-0.00010,9.000
9,124.938,0.01,-0.0002,-0.00010,9.000
9,125.062,0.00,-0.0002,-0.00010,9.000
9,125.188,0.00,-0.0002,-0.00010,9.000
9,125.312,-0.01,-0.0002,-0.00010,9.000
9,125.438,0.00,-0.0002,-0.00010,9.000
9,125.562,0.00,-0.0002,-0.00010,9.000
9,125.688,0.01,-0.0002,-0.00010,9.000
9,125.812,0.00,-0.0002,-0.00010,9.000
9,125.938,0.01,-0.0002,-0.00010,9.000
9,126.062,0.01,-0.0002,-0.00010,9.000
9,126.188,0.00,-0.0002,-0.00010,9.000
9,126.312,0.00,-0.0002,-0.00010,9.000
9,126.438,0.01,-0.0002,-0.00010,9.000
9,126.562,0.01,-0.0002,-0.00010,9.000
9,126.688,0.01,-0.0002,-0.00010,9.000
9,126.812,0.01,-0.0002,-0.00010,9.000
9,126.938,0.01,-0.0002,-0.00010,9.000
9,127.062,0.02,-0.0002,-0.00010,9.000
9,127.188,0.00,-0.0002,-0.00010,9.000
9,127.312,0.00,-0.0002,-0.00010,9.000
9,127.438,0.01,-0.0002,-0.00010,9.000
9,127.562,0.01,-0.0002,-0.00010,9.000
10,127.875,-0.02,0.0924,0.09250,10.000
10,128.000,-0.01,0.2174,0.21750,10.000
10,128.125,0.00,0.3426,0.34275,10.000
10,128.250,-0.01,0.4678,0.46790,10.000
10,128.375,-0.01,0.5925,0.59260,10.000
10,128.500,-0.02,0.7176,0.71770,10.000
10,128.625,-0.01,0.8427,0.84280,10.000
10,128.750,-0.02,0.9675,0.96760,10.000
10,128.875,-0.02,1.0926,1.09265,10.000
10,129.000,-0.01,1.2176,1.21770,10.000
10,129.125,-0.01,1.3426,1.34270,10.000
10,129.250,-0.01,1.4676,1.46770,10.000
10,129.375,-0.01,1.5928,1.59285,10.000
10,129.500,-0.02,1.7179,1.71800,10.000
10,129.625,-0.01,1.8428,1.84285,10.000
10,129.750,-0.02,1.9676,1.96770,10.000
10,129.875,-0.01,2.0926,2.09275,10.000
10,130.000,-0.02,2.2176,2.21770,10.000
10,130.125,-0.01,2.3427,2.34280,10.000
10,130.250,0.01,2.4679,2.46800,10.000
10,130.375,0.03,2.5927,2.59280,10.000
10,130.500,0.08,2.7177,2.71780,10.000
10,130.625,0.17,2.8427,2.84280,10.000
10,130.750,0.34,2.9679,2.96800,10.000
10,130.875,0.59,3.0927,3.09275,10.000
10,131.000,0.93,3.2177,3.21780,10.000
10,131.125,1.35,3.3429,3.34295,10.000
10,131.250,1.88,3.4677,3.46780,10.000
10,131.375,2.53,3.5928,3.59290,10.000
10,131.500,3.29,3.7178,3.71790,10.000
10,131.625,4.16,3.8429,3.84300,10.000
10,131.750,5.19,3.9679,3.96800,10.000
10,131.875,6.34,4.0928,4.09285,10.000
10,132.000,7.60,4.2177,4.21780,10.000
10,132.125,8.99,4.3427,4.34280,10.000
10,132.250,10.50,4.4678,4.46790,10.000
10,132.375,12.13,4.5928,4.59290,10.000
10,132.500,14.18,4.7178,4.71790,10.000
10,132.625,16.47,4.8429,4.84295,10.000
10,132.750,19.10,4.9678,4.96790,10.000
10,132.875,21.99,5.0928,5.09290,10.000
10,133.000,25.19,5.2177,5.21780,10.000
10,133.125,28.70,5.3428,5.34290,10.000
10,133.375,24.63,5.3046,5.30465,10.000
10,133.500,19.63,5.1795,5.17960,10.000
10,133.625,15.83,5.0546,5.05465,10.000
10,133.750,12.95,4.9295,4.92960,10.000
10,133.875,10.70,4.8046,4.80470,10.000
10,134.000,8.93,4.6797,4.67980,10.000
10,134.125,7.42,4.5546,4.55470,10.000
10,134.250,6.12,4.4295,4.42960,10.000
10,134.375,5.01,4.3044,4.30450,10.000
10,134.500,4.06,4.1793,4.17940,10.000
10,134.625,3.29,4.0544,4.05455,10.000
10,134.750,2.62,3.9295,3.92960,10.000
10,134.875,2.08,3.8045,3.80460,10.000
10,135.000,1.62,3.6796,3.67970,10.000
10,135.125,1.22,3.5545,3.55460,10.000
10,135.250,0.88,3.4294,3.42950,10.000
10,135.375,0.59,3.3044,3.30455,10.000
10,135.500,0.37,3.1792,3.17930,10.000
10,135.625,0.21,3.0544,3.05445,10.000
10,135.750,0.09,2.9295,2.92960,10.000
10,135.875,0.03,2.8044,2.80445,10.000
10,136.000,-0.01,2.6794,2.67950,10.000
10,136.125,0.00,2.5544,2.55445,10.000
10,136.250,-0.01,2.4295,2.42960,10.000
10,136.375,-0.01,2.3044,2.30445,10.000
10,136.500,-0.01,2.1792,2.17930,10.000
10,136.625,-0.02,2.0542,2.05435,10.000
10,136.750,-0.01,1.9292,1.92930,10.000
10,136.875,-0.01,1.8044,1.80450,10.000
10,137.000,-0.01,1.6794,1.67950,10.000
10,137.125,-0.02,1.5544,1.55455,10.000
10,137.250,-0.02,1.4294,1.42950,10.000
10,137.375,-0.02,1.3043,1.30440,10.000
10,137.500,-0.02,1.1792,1.17930,10.000
10,137.625,-0.02,1.0542,1.05430,10.000
10,137.750,-0.01,0.9291,0.92920,10.000
10,137.875,-0.01,0.8044,0.80450,10.000
10,138.000,-0.01,0.6792,0.67930,10.000
10,138.125,-0.01,0.5543,0.55440,10.000
10,138.250,-0.01,0.4293,0.42940,10.000
10,138.375,-0.02,0.3043,0.30435,10.000
10,138.500,-0.02,0.1792,0.17930,10.000
10,138.625,-0.02,0.0542,0.05425,10.000
10,138.812,-0.01,-0.0044,-0.00425,10.000
10,138.938,-0.01,-0.0002,-0.00010,10.000
10,139.062,-0.01,-0.0002,-0.00010,10.000
10,139.188,-0.02,-0.0002,-0.00010,10.000
10,139.312,-0.01,-0.0002,-0.00010,10.000
10,139.438,-0.01,-0.0002,-0.00010,10.000
10,139.562,-0.02,-0.0002,-0.00010,10.000
10,139.688,-0.01,-0.0002,-0.00010,10.000
10,139.812,-0.01,-0.0002,-0.00010,10.000
10,139.938,-0.01,-0.0002,-0.00010,10.000
10,140.062,-0.01,-0.0002,-0.00010,10.000
10,140.188,-0.02,-0.0002,-0.00010,10.000
10,140.312,-0.01,-0.0002,-0.00010,10.000
10,140.438,-0.01,-0.0002,-0.00010,10.000
10,140.562,-0.01,-0.0002,-0.00010,10.000
10,140.688,-0.01,-0.0002,-0.00010,10.000
10,140.812,-0.01,-0.0002,-0.00010,10.000
10,140.938,-0.01,-0.0002,-0.00010,10.000
10,141.062,-0.01,-0.0002,-0.00010,10.000
10,141.188,-0.01,-0.0002,-0.00010,10.000
10,141.312,-0.02,-0.0002,-0.00010,10.000
10,141.438,-0.01,-0.0002,-0.00010,10.000
10,141.562,-0.02,-0.0002,-0.00010,10.000
10,141.688,-0.01,-0.0002,-0.00010,10.000
10,141.750,-0.01,-0.0002,-0.00010,10.000