File: AIME_journal_files/AIME_data/calibDATA_loadcell/date_02:22:2018/Instron/30N_0_1_3_0.txt
""
"Test Method","Radhen_Load_Cntrl_Cmprsn_250N_12-7.msm"
"Sample I. D.","Sample1.mss"
"Specimen Number","13"

"TheCycle_Output ()","_Time (s)","_Load (N)","_Extension (mm)","RealTimeDepth (mm)","CycleNumber ()"

1,0.312,0.01,0.0711,0.07115,1.000
1,0.438,0.01,0.1961,0.19612,1.000
1,0.562,0.01,0.3213,0.32130,1.000
1,0.688,0.01,0.4463,0.44628,1.000
1,0.812,0.00,0.5713,0.57130,1.000
1,0.938,0.00,0.6964,0.69638,1.000
1,1.062,0.00,0.8214,0.82135,1.000
1,1.188,0.01,0.9463,0.94625,1.000
1,1.312,0.01,1.0712,1.07122,1.000
1,1.438,0.01,1.1962,1.19620,1.000
1,1.562,0.01,1.3213,1.32130,1.000
1,1.688,0.00,1.4463,1.44628,1.000
1,1.812,0.00,1.5713,1.57132,1.000
1,1.938,0.02,1.6964,1.69638,1.000
1,2.062,0.05,1.8215,1.82148,1.000
1,2.188,0.10,1.9464,1.94640,1.000
1,2.312,0.21,2.0713,2.07128,1.000
1,2.438,0.41,2.1962,2.19625,1.000
1,2.562,0.69,2.3212,2.32125,1.000
1,2.688,1.07,2.4464,2.44638,1.000
1,2.812,1.54,2.5714,2.57140,1.000
1,2.938,2.14,2.6964,2.69638,1.000
1,3.062,2.87,2.8214,2.82138,1.000
1,3.188,3.79,2.9464,2.94638,1.000
1,3.312,4.87,3.0714,3.07140,1.000
1,3.438,6.15,3.1964,3.19640,1.000
1,3.562,7.64,3.3212,3.32122,1.000
1,3.688,9.34,3.4463,3.44628,1.000
1,3.812,11.27,3.5713,3.57132,1.000
1,3.938,13.41,3.6964,3.69640,1.000
1,4.062,15.79,3.8214,3.82142,1.000
1,4.188,18.43,3.9465,3.94648,1.000
1,4.312,21.39,4.0714,4.07142,1.000
1,4.438,24.71,4.1964,4.19638,1.000
1,4.562,28.42,4.3214,4.32145,1.000
1,4.750,28.86,4.3797,4.37970,1.000
1,4.875,21.94,4.2547,4.25470,1.000
1,5.000,17.17,4.1296,4.12960,1.000
1,5.125,13.55,4.0046,4.00460,1.000
1,5.250,10.72,3.8797,3.87970,1.000
1,5.375,8.50,3.7547,3.75470,1.000
1,5.500,6.76,3.6297,3.62970,1.000
1,5.625,5.38,3.5046,3.50460,1.000
1,5.750,4.29,3.3797,3.37970,1.000
1,5.875,3.40,3.2546,3.25455,1.000
1,6.000,2.69,3.1296,3.12960,1.000
1,6.125,2.10,3.0045,3.00450,1.000
1,6.250,1.60,2.8794,2.87940,1.000
1,6.375,1.18,2.7544,2.75445,1.000
1,6.500,0.83,2.6295,2.62950,1.000
1,6.625,0.55,2.5046,2.50455,1.000
1,6.750,0.34,2.3797,2.37970,1.000
1,6.875,0.17,2.2545,2.25450,1.000
1,7.000,0.06,2.1294,2.12940,1.000
1,7.125,0.03,2.0044,2.00435,1.000
1,7.250,0.02,1.8793,1.87930,1.000
1,7.375,0.01,1.7544,1.75445,1.000
1,7.500,0.01,1.6294,1.62940,1.000
1,7.625,0.00,1.5045,1.50450,1.000
1,7.750,0.00,1.3793,1.37930,1.000
1,7.875,0.00,1.2544,1.25445,1.000
1,8.000,0.00,1.1295,1.12950,1.000
1,8.125,0.01,1.0044,1.00435,1.000
1,8.250,0.01,0.8793,0.87930,1.000
1,8.375,0.00,0.7543,0.75425,1.000
1,8.500,0.00,0.6293,0.62930,1.000
1,8.625,0.00,0.5043,0.50430,1.000
1,8.750,0.00,0.3795,0.37950,1.000
1,8.875,0.00,0.2544,0.25440,1.000
1,9.000,0.00,0.1294,0.12940,1.000
1,9.125,0.00,0.0043,0.00430,1.000
1,9.312,0.00,-0.0003,-0.00030,1.000
1,9.438,0.00,-0.0002,-0.00020,1.000
1,9.562,0.00,-0.0002,-0.00020,1.000
1,9.688,0.01,-0.0002,-0.00020,1.000
1,9.812,0.01,-0.0002,-0.00020,1.000
1,9.938,0.00,-0.0002,-0.00020,1.000
1,10.062,0.01,-0.0002,-0.00020,1.000
1,10.188,0.01,-0.0002,-0.00020,1.000
1,10.312,0.00,-0.0002,-0.00020,1.000
1,10.438,0.00,-0.0002,-0.00020,1.000
1,10.562,0.00,-0.0002,-0.00020,1.000
1,10.688,0.00,-0.0002,-0.00020,1.000
1,10.812,0.00,-0.0002,-0.00020,1.000
1,10.938,0.00,-0.0002,-0.00020,1.000
1,11.062,0.00,-0.0002,-0.00020,1.000
1,11.188,0.00,-0.0002,-0.00020,1.000
1,11.312,0.01,-0.0002,-0.00020,1.000
1,11.438,0.00,-0.0002,-0.00020,1.000
1,11.562,0.00,-0.0002,-0.00020,1.000
1,11.688,0.00,-0.0002,-0.00020,1.000
1,11.812,0.00,-0.0002,-0.00020,1.000
1,11.938,0.01,-0.0002,-0.00020,1.000
1,12.062,0.00,-0.0002,-0.00020,1.000
1,12.188,0.00,-0.0002,-0.00020,1.000
2,12.562,0.00,0.1471,0.14717,2.000
2,12.688,-0.01,0.2721,0.27223,2.000
2,12.812,0.00,0.3972,0.39730,2.000
2,12.938,-0.01,0.5220,0.52210,2.000
2,13.062,0.00,0.6472,0.64730,2.000
2,13.188,0.00,0.7722,0.77228,2.000
2,13.312,0.00,0.8973,0.89737,2.000
2,13.438,0.00,1.0222,1.02233,2.000
2,13.562,-0.01,1.1472,1.14735,2.000
2,13.688,-0.01,1.2721,1.27223,2.000
2,13.812,-0.01,1.3971,1.39722,2.000
2,13.938,-0.01,1.5222,1.52228,2.000
2,14.062,0.00,1.6471,1.64725,2.000
2,14.188,0.02,1.7723,1.77238,2.000
2,14.312,0.05,1.8973,1.89740,2.000
2,14.438,0.13,2.0223,2.02238,2.000
2,14.562,0.28,2.1472,2.14735,2.000
2,14.688,0.52,2.2723,2.27235,2.000
2,14.812,0.85,2.3972,2.39732,2.000
2,14.938,1.27,2.5222,2.52233,2.000
2,15.062,1.81,2.6473,2.64738,2.000
2,15.188,2.48,2.7722,2.77230,2.000
2,15.312,3.31,2.8973,2.89742,2.000
2,15.438,4.32,3.0224,3.02248,2.000
2,15.562,5.52,3.1473,3.14742,2.000
2,15.688,6.92,3.2723,3.27240,2.000
2,15.812,8.55,3.3972,3.39730,2.000
2,15.938,10.38,3.5221,3.52223,2.000
2,16.062,12.46,3.6472,3.64733,2.000
2,16.188,14.75,3.7722,3.77235,2.000
2,16.312,17.31,3.8974,3.89750,2.000
2,16.438,20.15,4.0223,4.02240,2.000
2,16.562,23.35,4.1473,4.14743,2.000
2,16.688,26.93,4.2725,4.27257,2.000
2,16.938,28.09,4.3680,4.36808,2.000
2,17.062,21.48,4.2430,4.24315,2.000
2,17.188,16.82,4.1181,4.11815,2.000
2,17.312,13.28,3.9931,3.99320,2.000
2,17.438,10.51,3.8681,3.86820,2.000
2,17.562,8.33,3.7431,3.74322,2.000
2,17.688,6.63,3.6182,3.61828,2.000
2,17.812,5.27,3.4930,3.49307,2.000
2,17.938,4.19,3.3679,3.36798,2.000
2,18.062,3.32,3.2429,3.24302,2.000
2,18.188,2.62,3.1180,3.11808,2.000
2,18.312,2.04,2.9930,2.99310,2.000
2,18.438,1.54,2.8680,2.86808,2.000
2,18.562,1.12,2.7429,2.74305,2.000
2,18.688,0.78,2.6180,2.61808,2.000
2,18.812,0.51,2.4930,2.49315,2.000
2,18.938,0.30,2.3680,2.36805,2.000
2,19.062,0.14,2.2428,2.24292,2.000
2,19.188,0.05,2.1179,2.11798,2.000
2,19.312,0.02,1.9928,1.99290,2.000
2,19.438,0.01,1.8680,1.86808,2.000
2,19.562,0.00,1.7429,1.74305,2.000
2,19.688,-0.01,1.6179,1.61798,2.000
2,19.812,0.00,1.4929,1.49305,2.000
2,19.938,0.00,1.3678,1.36785,2.000
2,20.062,0.00,1.2427,1.24282,2.000
2,20.188,0.00,1.1178,1.11790,2.000
2,20.312,0.00,0.9927,0.99282,2.000
2,20.438,0.00,0.8678,0.86788,2.000
2,20.562,0.00,0.7428,0.74290,2.000
2,20.688,0.00,0.6179,0.61798,2.000
2,20.812,0.00,0.4928,0.49290,2.000
2,20.938,0.00,0.3679,0.36800,2.000
2,21.062,0.00,0.2428,0.24292,2.000
2,21.188,0.00,0.1177,0.11778,2.000
2,21.312,-0.01,-0.0072,-0.00713,2.000
2,21.500,-0.01,-0.0004,-0.00030,2.000
2,21.625,0.00,-0.0003,-0.00020,2.000
2,21.750,0.00,-0.0003,-0.00020,2.000
2,21.875,0.00,-0.0003,-0.00020,2.000
2,22.000,-0.01,-0.0003,-0.00020,2.000
2,22.125,0.00,-0.0003,-0.00020,2.000
2,22.250,0.00,-0.0003,-0.00020,2.000
2,22.375,0.00,-0.0003,-0.00020,2.000
2,22.500,0.00,-0.0003,-0.00020,2.000
2,22.625,0.00,-0.0003,-0.00020,2.000
2,22.750,-0.01,-0.0003,-0.00020,2.000
2,22.875,0.00,-0.0002,-0.00010,2.000
2,23.000,-0.01,-0.0002,-0.00010,2.000
2,23.125,0.00,-0.0002,-0.00010,2.000
2,23.250,-0.01,-0.0002,-0.00010,2.000
2,23.375,0.00,-0.0002,-0.00010,2.000
2,23.500,0.00,-0.0002,-0.00010,2.000
2,23.625,0.00,-0.0002,-0.00010,2.000
2,23.750,0.00,-0.0002,-0.00010,2.000
2,23.875,0.00,-0.0002,-0.00010,2.000
2,24.000,0.00,-0.0002,-0.00010,2.000
2,24.125,-0.01,-0.0002,-0.00010,2.000
2,24.250,0.00,-0.0002,-0.00010,2.000
2,24.375,0.00,-0.0002,-0.00010,2.000
3,24.750,0.00,0.1446,0.14470,3.000
3,24.875,0.00,0.2696,0.26975,3.000
3,25.000,0.00,0.3946,0.39470,3.000
3,25.125,0.00,0.5196,0.51970,3.000
3,25.250,0.00,0.6446,0.64470,3.000
3,25.375,0.00,0.7696,0.76970,3.000
3,25.500,0.00,0.8946,0.89470,3.000
3,25.625,0.00,1.0198,1.01990,3.000
3,25.750,0.00,1.1447,1.14480,3.000
3,25.875,0.00,1.2697,1.26980,3.000
3,26.000,0.00,1.3946,1.39470,3.000
3,26.125,0.00,1.5197,1.51980,3.000
3,26.250,0.01,1.6446,1.64470,3.000
3,26.375,0.03,1.7698,1.76990,3.000
3,26.500,0.06,1.8948,1.89490,3.000
3,26.625,0.13,2.0198,2.01990,3.000
3,26.750,0.27,2.1448,2.14490,3.000
3,26.875,0.51,2.2698,2.26990,3.000
3,27.000,0.83,2.3948,2.39490,3.000
3,27.125,1.26,2.5197,2.51980,3.000
3,27.250,1.79,2.6446,2.64470,3.000
3,27.375,2.46,2.7698,2.76985,3.000
3,27.500,3.28,2.8948,2.89490,3.000
3,27.625,4.29,3.0198,3.01990,3.000
3,27.750,5.49,3.1449,3.14500,3.000
3,27.875,6.89,3.2698,3.26990,3.000
3,28.000,8.53,3.3947,3.39480,3.000
3,28.125,10.38,3.5197,3.51980,3.000
3,28.250,12.46,3.6448,3.64490,3.000
3,28.375,14.76,3.7697,3.76980,3.000
3,28.500,17.33,3.8948,3.89490,3.000
3,28.625,20.18,4.0198,4.01990,3.000
3,28.750,23.37,4.1449,4.14500,3.000
3,28.875,26.97,4.2699,4.27000,3.000
3,29.000,31.03,4.3948,4.39490,3.000
3,29.125,27.49,4.3526,4.35270,3.000
3,29.250,21.07,4.2276,4.22770,3.000
3,29.375,16.53,4.1027,4.10275,3.000
3,29.500,13.07,3.9776,3.97770,3.000
3,29.625,10.35,3.8526,3.85275,3.000
3,29.750,8.20,3.7275,3.72760,3.000
3,29.875,6.51,3.6025,3.60260,3.000
3,30.000,5.18,3.4774,3.47750,3.000
3,30.125,4.11,3.3525,3.35260,3.000
3,30.250,3.24,3.2276,3.22770,3.000
3,30.375,2.55,3.1026,3.10275,3.000
3,30.500,1.98,2.9775,2.97760,3.000
3,30.625,1.49,2.8524,2.85250,3.000
3,30.750,1.08,2.7274,2.72750,3.000
3,30.875,0.75,2.6024,2.60245,3.000
3,31.000,0.48,2.4774,2.47750,3.000
3,31.125,0.28,2.3525,2.35260,3.000
3,31.250,0.14,2.2275,2.22760,3.000
3,31.375,0.04,2.1025,2.10255,3.000
3,31.500,0.02,1.9775,1.97760,3.000
3,31.625,0.01,1.8525,1.85260,3.000
3,31.750,0.01,1.7275,1.72760,3.000
3,31.875,0.00,1.6023,1.60235,3.000
3,32.000,0.00,1.4773,1.47740,3.000
3,32.125,0.00,1.3523,1.35240,3.000
3,32.250,0.00,1.2273,1.22740,3.000
3,32.375,0.00,1.1024,1.10245,3.000
3,32.500,0.00,0.9774,0.97750,3.000
3,32.625,0.00,0.8524,0.85245,3.000
3,32.750,0.00,0.7273,0.72740,3.000
3,32.875,0.00,0.6023,0.60235,3.000
3,33.000,0.00,0.4772,0.47730,3.000
3,33.125,0.00,0.3524,0.35245,3.000
3,33.250,0.00,0.2273,0.22740,3.000
3,33.375,0.00,0.1023,0.10240,3.000
3,33.500,0.01,-0.0226,-0.02250,3.000
3,33.688,0.00,-0.0003,-0.00020,3.000
3,33.812,0.00,-0.0003,-0.00020,3.000
3,33.938,0.00,-0.0003,-0.00020,3.000
3,34.062,0.00,-0.0003,-0.00020,3.000
3,34.188,0.00,-0.0003,-0.00020,3.000
3,34.312,0.00,-0.0003,-0.00020,3.000
3,34.438,0.00,-0.0003,-0.00020,3.000
3,34.562,0.00,-0.0003,-0.00020,3.000
3,34.688,0.00,-0.0003,-0.00020,3.000
3,34.812,0.00,-0.0003,-0.00020,3.000
3,34.938,0.00,-0.0003,-0.00020,3.000
3,35.062,0.00,-0.0003,-0.00020,3.000
3,35.188,0.00,-0.0003,-0.00020,3.000
3,35.312,0.00,-0.0002,-0.00010,3.000
3,35.438,0.00,-0.0002,-0.00010,3.000
3,35.562,0.00,-0.0002,-0.00010,3.000
3,35.688,0.00,-0.0002,-0.00010,3.000
3,35.812,0.00,-0.0002,-0.00010,3.000
3,35.938,0.00,-0.0002,-0.00010,3.000
3,36.062,0.00,-0.0002,-0.00010,3.000
3,36.188,0.00,-0.0002,-0.00010,3.000
3,36.312,0.00,-0.0002,-0.00010,3.000
3,36.438,0.00,-0.0002,-0.00010,3.000
3,36.562,0.00,-0.0002,-0.00010,3.000
4,36.938,0.01,0.1321,0.13223,4.000
4,37.062,0.01,0.2573,0.25737,4.000
4,37.188,0.01,0.3822,0.38233,4.000
4,37.312,0.01,0.5071,0.50725,4.000
4,37.438,0.01,0.6321,0.63218,4.000
4,37.562,0.01,0.7570,0.75712,4.000
4,37.688,0.01,0.8821,0.88220,4.000
4,37.812,0.01,1.0071,1.00725,4.000
4,37.938,0.01,1.1322,1.13230,4.000
4,38.062,0.01,1.2573,1.25740,4.000
4,38.188,0.01,1.3823,1.38238,4.000
4,38.312,0.01,1.5073,1.50745,4.000
4,38.438,0.01,1.6322,1.63225,4.000
4,38.562,0.03,1.7572,1.75730,4.000
4,38.688,0.06,1.8822,1.88228,4.000
4,38.812,0.12,2.0071,2.00722,4.000
4,38.938,0.26,2.1323,2.13238,4.000
4,39.062,0.48,2.2573,2.25742,4.000
4,39.188,0.79,2.3825,2.38255,4.000
4,39.312,1.20,2.5073,2.50745,4.000
4,39.438,1.72,2.6323,2.63240,4.000
4,39.562,2.37,2.7572,2.75730,4.000
4,39.688,3.18,2.8821,2.88223,4.000
4,39.812,4.17,3.0072,3.00732,4.000
4,39.938,5.35,3.1323,3.13238,4.000
4,40.062,6.73,3.2574,3.25747,4.000
4,40.188,8.33,3.3824,3.38248,4.000
4,40.312,10.16,3.5073,3.50737,4.000
4,40.438,12.22,3.6323,3.63243,4.000
4,40.562,14.49,3.7573,3.75737,4.000
4,40.688,17.03,3.8823,3.88235,4.000
4,40.812,19.85,4.0072,4.00732,4.000
4,40.938,23.00,4.1323,4.13238,4.000
4,41.062,26.54,4.2573,4.25745,4.000
4,41.188,30.53,4.3825,4.38255,4.000
4,41.375,24.49,4.3006,4.30075,4.000
4,41.500,19.03,4.1757,4.17580,4.000
4,41.625,14.98,4.0506,4.05070,4.000
4,41.750,11.86,3.9254,3.92550,4.000
4,41.875,9.41,3.8006,3.80065,4.000
4,42.000,7.46,3.6757,3.67580,4.000
4,42.125,5.92,3.5506,3.55065,4.000
4,42.250,4.71,3.4256,3.42570,4.000
4,42.375,3.73,3.3006,3.30065,4.000
4,42.500,2.94,3.1756,3.17570,4.000
4,42.625,2.30,3.0505,3.05060,4.000
4,42.750,1.76,2.9253,2.92540,4.000
4,42.875,1.32,2.8004,2.80050,4.000
4,43.000,0.94,2.6754,2.67550,4.000
4,43.125,0.64,2.5505,2.55060,4.000
4,43.250,0.40,2.4256,2.42570,4.000
4,43.375,0.22,2.3005,2.30060,4.000
4,43.500,0.09,2.1754,2.17550,4.000
4,43.625,0.04,2.0504,2.05045,4.000
4,43.750,0.02,1.9253,1.92540,4.000
4,43.875,0.02,1.8004,1.80050,4.000
4,44.000,0.02,1.6754,1.67550,4.000
4,44.125,0.01,1.5504,1.55045,4.000
4,44.250,0.01,1.4254,1.42550,4.000
4,44.375,0.01,1.3004,1.30050,4.000
4,44.500,0.01,1.1754,1.17550,4.000
4,44.625,0.01,1.0504,1.05050,4.000
4,44.750,0.01,0.9253,0.92540,4.000
4,44.875,0.01,0.8002,0.80035,4.000
4,45.000,0.01,0.6751,0.67520,4.000
4,45.125,0.01,0.5502,0.55030,4.000
4,45.250,0.01,0.4253,0.42540,4.000
4,45.375,0.01,0.3004,0.30045,4.000
4,45.500,0.01,0.1754,0.17550,4.000
4,45.625,0.01,0.0503,0.05040,4.000
4,45.812,0.01,-0.0021,-0.00195,4.000
4,45.938,0.01,-0.0003,-0.00020,4.000
4,46.062,0.01,-0.0003,-0.00020,4.000
4,46.188,0.01,-0.0003,-0.00020,4.000
4,46.312,0.01,-0.0003,-0.00020,4.000
4,46.438,0.01,-0.0003,-0.00020,4.000
4,46.562,0.01,-0.0003,-0.00020,4.000
4,46.688,0.01,-0.0003,-0.00020,4.000
4,46.812,0.01,-0.0003,-0.00020,4.000
4,46.938,0.01,-0.0003,-0.00020,4.000
4,47.062,0.01,-0.0003,-0.00020,4.000
4,47.188,0.01,-0.0003,-0.00020,4.000
4,47.312,0.01,-0.0003,-0.00020,4.000
4,47.438,0.01,-0.0003,-0.00020,4.000
4,47.562,0.01,-0.0002,-0.00010,4.000
4,47.688,0.01,-0.0002,-0.00010,4.000
4,47.812,0.01,-0.0002,-0.00010,4.000
4,47.938,0.01,-0.0002,-0.00010,4.000
4,48.062,0.01,-0.0002,-0.00010,4.000
4,48.188,0.01,-0.0002,-0.00010,4.000
4,48.312,0.01,-0.0002,-0.00010,4.000
4,48.438,0.01,-0.0002,-0.00010,4.000
4,48.562,0.01,-0.0002,-0.00010,4.000
4,48.688,0.01,-0.0002,-0.00010,4.000
5,49.062,0.00,0.0810,0.08110,5.000
5,49.188,0.00,0.2062,0.20625,5.000
5,49.312,0.00,0.3312,0.33132,5.000
5,49.438,0.00,0.4563,0.45635,5.000
5,49.562,0.00,0.5812,0.58130,5.000
5,49.688,-0.01,0.7063,0.70635,5.000
5,49.812,0.00,0.8312,0.83127,5.000
5,49.938,0.00,0.9562,0.95628,5.000
5,50.062,0.00,1.0811,1.08122,5.000
5,50.188,-0.01,1.2062,1.20628,5.000
5,50.312,-0.01,1.3312,1.33130,5.000
5,50.438,-0.01,1.4563,1.45638,5.000
5,50.562,0.00,1.5812,1.58132,5.000
5,50.688,0.01,1.7063,1.70640,5.000
5,50.812,0.03,1.8313,1.83145,5.000
5,50.938,0.08,1.9562,1.95628,5.000
5,51.062,0.18,2.0811,2.08125,5.000
5,51.188,0.37,2.2062,2.20630,5.000
5,51.312,0.64,2.3313,2.33142,5.000
5,51.438,1.00,2.4563,2.45643,5.000
5,51.562,1.47,2.5813,2.58142,5.000
5,51.688,2.07,2.7064,2.70653,5.000
5,51.812,2.80,2.8313,2.83142,5.000
5,51.938,3.72,2.9563,2.95640,5.000
5,52.062,4.82,3.0813,3.08137,5.000
5,52.188,6.11,3.2062,3.20630,5.000
5,52.312,7.61,3.3312,3.33130,5.000
5,52.438,9.35,3.4563,3.45638,5.000
5,52.562,11.31,3.5812,3.58135,5.000
5,52.688,13.50,3.7064,3.70650,5.000
5,52.812,15.92,3.8313,3.83145,5.000
5,52.938,18.61,3.9563,3.95640,5.000
5,53.062,21.63,4.0813,4.08137,5.000
5,53.188,25.02,4.2063,4.20640,5.000
5,53.312,28.81,4.3313,4.33142,5.000
5,53.500,26.82,4.3396,4.33970,5.000
5,53.625,20.63,4.2146,4.21470,5.000
5,53.750,16.18,4.0895,4.08960,5.000
5,53.875,12.79,3.9645,3.96460,5.000
5,54.000,10.14,3.8397,3.83980,5.000
5,54.125,8.03,3.7147,3.71475,5.000
5,54.250,6.37,3.5895,3.58960,5.000
5,54.375,5.06,3.4646,3.46465,5.000
5,54.500,4.01,3.3396,3.33970,5.000
5,54.625,3.16,3.2145,3.21460,5.000
5,54.750,2.48,3.0895,3.08960,5.000
5,54.875,1.91,2.9644,2.96450,5.000
5,55.000,1.43,2.8394,2.83950,5.000
5,55.125,1.04,2.7144,2.71450,5.000
5,55.250,0.71,2.5895,2.58960,5.000
5,55.375,0.45,2.4645,2.46460,5.000
5,55.500,0.26,2.3395,2.33960,5.000
5,55.625,0.11,2.2145,2.21455,5.000
5,55.750,0.03,2.0894,2.08950,5.000
5,55.875,0.01,1.9643,1.96440,5.000
5,56.000,0.01,1.8393,1.83940,5.000
5,56.125,0.00,1.7144,1.71450,5.000
5,56.250,0.00,1.5894,1.58950,5.000
5,56.375,0.00,1.4645,1.46455,5.000
5,56.500,0.00,1.3394,1.33950,5.000
5,56.625,0.00,1.2144,1.21445,5.000
5,56.750,0.00,1.0894,1.08950,5.000
5,56.875,0.00,0.9643,0.96440,5.000
5,57.000,-0.01,0.8391,0.83920,5.000
5,57.125,0.00,0.7143,0.71435,5.000
5,57.250,0.00,0.5892,0.58930,5.000
5,57.375,0.00,0.4643,0.46440,5.000
5,57.500,0.00,0.3395,0.33960,5.000
5,57.625,0.00,0.2144,0.21445,5.000
5,57.750,0.00,0.0894,0.08950,5.000
5,57.938,0.00,-0.0331,-0.03297,5.000
5,58.062,0.00,-0.0003,-0.00020,5.000
5,58.188,0.00,-0.0003,-0.00020,5.000
5,58.312,0.00,-0.0003,-0.00020,5.000
5,58.438,0.00,-0.0003,-0.00020,5.000
5,58.562,0.00,-0.0003,-0.00020,5.000
5,58.688,0.00,-0.0003,-0.00020,5.000
5,58.812,0.00,-0.0003,-0.00020,5.000
5,58.938,-0.01,-0.0003,-0.00020,5.000
5,59.062,-0.01,-0.0003,-0.00020,5.000
5,59.188,0.00,-0.0003,-0.00020,5.000
5,59.312,0.00,-0.0003,-0.00020,5.000
5,59.438,-0.01,-0.0002,-0.00010,5.000
5,59.562,-0.01,-0.0002,-0.00010,5.000
5,59.688,0.00,-0.0002,-0.00010,5.000
5,59.812,0.00,-0.0002,-0.00010,5.000
5,59.938,0.00,-0.0002,-0.00010,5.000
5,60.062,0.00,-0.0002,-0.00010,5.000
5,60.188,0.00,-0.0002,-0.00010,5.000
5,60.312,-0.01,-0.0002,-0.00010,5.000
5,60.438,0.00,-0.0002,-0.00010,5.000
5,60.562,0.00,-0.0002,-0.00010,5.000
5,60.688,0.00,-0.0002,-0.00010,5.000
5,60.812,-0.01,-0.0002,-0.00010,5.000
6,61.188,0.00,0.0461,0.04623,6.000
6,61.312,0.00,0.1711,0.17120,6.000
6,61.438,0.00,0.2963,0.29638,6.000
6,61.562,0.00,0.4212,0.42135,6.000
6,61.688,0.00,0.5461,0.54620,6.000
6,61.812,0.00,0.6712,0.67127,6.000
6,61.938,0.00,0.7961,0.79622,6.000
6,62.062,0.00,0.9210,0.92115,6.000
6,62.188,-0.01,1.0462,1.04627,6.000
6,62.312,0.00,1.1712,1.17127,6.000
6,62.438,0.00,1.2961,1.29622,6.000
6,62.562,0.00,1.4212,1.42135,6.000
6,62.688,0.00,1.5463,1.54640,6.000
6,62.812,0.01,1.6712,1.67135,6.000
6,62.938,0.03,1.7962,1.79635,6.000
6,63.062,0.07,1.9211,1.92125,6.000
6,63.188,0.14,2.0463,2.04637,6.000
6,63.312,0.30,2.1713,2.17137,6.000
6,63.438,0.55,2.2963,2.29640,6.000
6,63.562,0.89,2.4213,2.42145,6.000
6,63.688,1.33,2.5463,2.54642,6.000
6,63.812,1.88,2.6714,2.67152,6.000
6,63.938,2.57,2.7962,2.79632,6.000
6,64.062,3.43,2.9212,2.92130,6.000
6,64.188,4.48,3.0463,3.04638,6.000
6,64.312,5.72,3.1712,3.17135,6.000
6,64.438,7.16,3.2962,3.29633,6.000
6,64.562,8.82,3.4213,3.42140,6.000
6,64.688,10.73,3.5462,3.54633,6.000
6,64.812,12.85,3.6714,3.67147,6.000
6,64.938,15.20,3.7963,3.79643,6.000
6,65.062,17.82,3.9212,3.92132,6.000
6,65.188,20.74,4.0462,4.04632,6.000
6,65.312,24.01,4.1713,4.17140,6.000
6,65.438,27.68,4.2963,4.29642,6.000
6,65.625,30.35,4.3944,4.39455,6.000
6,65.750,22.82,4.2696,4.26970,6.000
6,65.875,17.82,4.1446,4.14470,6.000
6,66.000,14.05,4.0197,4.01980,6.000
6,66.125,11.13,3.8946,3.89470,6.000
6,66.250,8.82,3.7695,3.76960,6.000
6,66.375,7.01,3.6446,3.64470,6.000
6,66.500,5.56,3.5194,3.51950,6.000
6,66.625,4.42,3.3945,3.39460,6.000
6,66.750,3.49,3.2696,3.26970,6.000
6,66.875,2.75,3.1446,3.14475,6.000
6,67.000,2.15,3.0196,3.01970,6.000
6,67.125,1.62,2.8944,2.89450,6.000
6,67.250,1.20,2.7694,2.76950,6.000
6,67.375,0.84,2.6443,2.64440,6.000
6,67.500,0.55,2.5193,2.51940,6.000
6,67.625,0.33,2.3945,2.39460,6.000
6,67.750,0.17,2.2695,2.26960,6.000
6,67.875,0.06,2.1444,2.14455,6.000
6,68.000,0.02,2.0195,2.01960,6.000
6,68.125,0.01,1.8944,1.89450,6.000
6,68.250,0.00,1.7694,1.76950,6.000
6,68.375,0.00,1.6442,1.64435,6.000
6,68.500,-0.01,1.5193,1.51940,6.000
6,68.625,0.00,1.3943,1.39440,6.000
6,68.750,0.00,1.2694,1.26950,6.000
6,68.875,0.00,1.1444,1.14450,6.000
6,69.000,0.00,1.0195,1.01960,6.000
6,69.125,0.00,0.8944,0.89450,6.000
6,69.250,0.00,0.7694,0.76950,6.000
6,69.375,0.00,0.6442,0.64435,6.000
6,69.500,0.00,0.5192,0.51930,6.000
6,69.625,0.00,0.3943,0.39440,6.000
6,69.750,0.00,0.2693,0.26940,6.000
6,69.875,0.00,0.1444,0.14445,6.000
6,70.000,0.00,0.0193,0.01940,6.000
6,70.188,0.00,-0.0004,-0.00028,6.000
6,70.312,0.00,-0.0003,-0.00020,6.000
6,70.438,0.00,-0.0003,-0.00020,6.000
6,70.562,0.00,-0.0003,-0.00020,6.000
6,70.688,0.00,-0.0003,-0.00020,6.000
6,70.812,0.00,-0.0003,-0.00020,6.000
6,70.938,0.00,-0.0003,-0.00020,6.000
6,71.062,0.00,-0.0003,-0.00020,6.000
6,71.188,0.00,-0.0003,-0.00020,6.000
6,71.312,0.00,-0.0003,-0.00020,6.000
6,71.438,0.00,-0.0003,-0.00020,6.000
6,71.562,0.00,-0.0003,-0.00020,6.000
6,71.688,0.00,-0.0003,-0.00020,6.000
6,71.812,0.00,-0.0003,-0.00020,6.000
6,71.938,0.00,-0.0003,-0.00020,6.000
6,72.062,0.00,-0.0002,-0.00010,6.000
6,72.188,0.00,-0.0002,-0.00010,6.000
6,72.312,0.00,-0.0002,-0.00010,6.000
6,72.438,0.00,-0.0002,-0.00010,6.000
6,72.562,0.00,-0.0002,-0.00010,6.000
6,72.688,0.00,-0.0002,-0.00010,6.000
6,72.812,0.00,-0.0002,-0.00010,6.000
6,72.938,0.00,-0.0002,-0.00010,6.000
6,73.062,0.00,-0.0002,-0.00010,6.000
7,73.500,-0.01,0.1645,0.16460,7.000
7,73.625,0.00,0.2897,0.28980,7.000
7,73.750,0.00,0.4147,0.41480,7.000
7,73.875,0.00,0.5397,0.53980,7.000
7,74.000,0.00,0.6647,0.66480,7.000
7,74.125,0.00,0.7897,0.78980,7.000
7,74.250,0.00,0.9146,0.91470,7.000
7,74.375,0.00,1.0397,1.03980,7.000
7,74.500,0.00,1.1647,1.16480,7.000
7,74.625,-0.01,1.2897,1.28980,7.000
7,74.750,-0.01,1.4148,1.41490,7.000
7,74.875,0.00,1.5398,1.53990,7.000
7,75.000,0.00,1.6648,1.66490,7.000
7,75.125,0.02,1.7899,1.78995,7.000
7,75.250,0.06,1.9147,1.91480,7.000
7,75.375,0.14,2.0397,2.03980,7.000
7,75.500,0.29,2.1648,2.16490,7.000
7,75.625,0.53,2.2898,2.28985,7.000
7,75.750,0.87,2.4148,2.41490,7.000
7,75.875,1.30,2.5398,2.53995,7.000
7,76.000,1.85,2.6649,2.66500,7.000
7,76.125,2.53,2.7898,2.78990,7.000
7,76.250,3.38,2.9148,2.91490,7.000
7,76.375,4.41,3.0398,3.03985,7.000
7,76.500,5.63,3.1647,3.16480,7.000
7,76.625,7.07,3.2898,3.28985,7.000
7,76.750,8.72,3.4147,3.41480,7.000
7,76.875,10.61,3.5398,3.53985,7.000
7,77.000,12.73,3.6648,3.66490,7.000
7,77.125,15.06,3.7899,3.79000,7.000
7,77.250,17.67,3.9149,3.91500,7.000
7,77.375,20.56,4.0398,4.03985,7.000
7,77.500,23.82,4.1647,4.16480,7.000
7,77.625,27.48,4.2899,4.28995,7.000
7,77.812,31.29,4.4122,4.41225,7.000
7,77.938,23.58,4.2880,4.28812,7.000
7,78.062,18.37,4.1631,4.16315,7.000
7,78.188,14.48,4.0381,4.03818,7.000
7,78.312,11.45,3.9132,3.91328,7.000
7,78.438,9.08,3.7882,3.78830,7.000
7,78.562,7.21,3.6631,3.66320,7.000
7,78.688,5.72,3.5380,3.53810,7.000
7,78.812,4.55,3.4130,3.41313,7.000
7,78.938,3.60,3.2879,3.28802,7.000
7,79.062,2.84,3.1630,3.16305,7.000
7,79.188,2.21,3.0379,3.03802,7.000
7,79.312,1.68,2.9130,2.91308,7.000
7,79.438,1.25,2.7880,2.78808,7.000
7,79.562,0.88,2.6630,2.66308,7.000
7,79.688,0.59,2.5379,2.53802,7.000
7,79.812,0.36,2.4130,2.41313,7.000
7,79.938,0.19,2.2879,2.28802,7.000
7,80.062,0.07,2.1628,2.16293,7.000
7,80.188,0.02,2.0379,2.03795,7.000
7,80.312,0.01,1.9129,1.91298,7.000
7,80.438,0.00,1.7880,1.78815,7.000
7,80.562,0.00,1.6629,1.66298,7.000
7,80.688,-0.01,1.5379,1.53802,7.000
7,80.812,0.00,1.4129,1.41298,7.000
7,80.938,-0.01,1.2878,1.28793,7.000
7,81.062,0.00,1.1628,1.16290,7.000
7,81.188,0.00,1.0378,1.03785,7.000
7,81.312,0.00,0.9128,0.91293,7.000
7,81.438,-0.01,0.7878,0.78795,7.000
7,81.562,0.00,0.6628,0.66285,7.000
7,81.688,0.00,0.5378,0.53795,7.000
7,81.812,0.00,0.4129,0.41298,7.000
7,81.938,0.00,0.2878,0.28792,7.000
7,82.062,0.00,0.1627,0.16283,7.000
7,82.188,0.00,0.0377,0.03783,7.000
7,82.375,-0.01,-0.0057,-0.00560,7.000
7,82.500,-0.01,-0.0003,-0.00020,7.000
7,82.625,0.00,-0.0003,-0.00020,7.000
7,82.750,-0.01,-0.0003,-0.00020,7.000
7,82.875,-0.01,-0.0003,-0.00020,7.000
7,83.000,0.00,-0.0003,-0.00020,7.000
7,83.125,0.00,-0.0003,-0.00020,7.000
7,83.250,0.00,-0.0003,-0.00020,7.000
7,83.375,0.00,-0.0003,-0.00020,7.000
7,83.500,0.00,-0.0003,-0.00020,7.000
7,83.625,0.00,-0.0003,-0.00020,7.000
7,83.750,0.00,-0.0003,-0.00020,7.000
7,83.875,0.00,-0.0003,-0.00020,7.000
7,84.000,-0.01,-0.0003,-0.00020,7.000
7,84.125,-0.01,-0.0003,-0.00020,7.000
7,84.250,0.00,-0.0003,-0.00020,7.000
7,84.375,0.00,-0.0002,-0.00010,7.000
7,84.500,0.00,-0.0002,-0.00010,7.000
7,84.625,0.00,-0.0002,-0.00010,7.000
7,84.750,-0.01,-0.0002,-0.00010,7.000
7,84.875,0.00,-0.0002,-0.00010,7.000
7,85.000,0.00,-0.0002,-0.00010,7.000
7,85.125,0.00,-0.0002,-0.00010,7.000
7,85.250,0.00,-0.0002,-0.00010,7.000
8,85.500,-0.01,-0.0001,0.00000,8.000
8,85.625,-0.01,0.0937,0.09375,8.000
8,85.750,0.00,0.2188,0.21890,8.000
8,85.875,-0.01,0.3438,0.34385,8.000
8,86.000,-0.01,0.4687,0.46880,8.000
8,86.125,0.00,0.5936,0.59370,8.000
8,86.250,0.00,0.7186,0.71870,8.000
8,86.375,-0.01,0.8436,0.84370,8.000
8,86.500,0.00,0.9687,0.96880,8.000
8,86.625,-0.01,1.0937,1.09380,8.000
8,86.750,-0.01,1.2187,1.21880,8.000
8,86.875,-0.01,1.3438,1.34385,8.000
8,87.000,-0.01,1.4689,1.46900,8.000
8,87.125,-0.01,1.5937,1.59380,8.000
8,87.250,0.00,1.7186,1.71870,8.000
8,87.375,0.03,1.8438,1.84385,8.000
8,87.500,0.08,1.9687,1.96880,8.000
8,87.625,0.19,2.0938,2.09385,8.000
8,87.750,0.38,2.2187,2.21880,8.000
8,87.875,0.66,2.3439,2.34395,8.000
8,88.000,1.03,2.4689,2.46900,8.000
8,88.125,1.51,2.5938,2.59385,8.000
8,88.250,2.12,2.7187,2.71880,8.000
8,88.375,2.86,2.8437,2.84380,8.000
8,88.500,3.79,2.9687,2.96880,8.000
8,88.625,4.90,3.0938,3.09390,8.000
8,88.750,6.21,3.2188,3.21890,8.000
8,88.875,7.74,3.3438,3.34390,8.000
8,89.000,9.50,3.4688,3.46890,8.000
8,89.125,11.49,3.5938,3.59390,8.000
8,89.250,13.70,3.7189,3.71900,8.000
8,89.375,16.15,3.8438,3.84390,8.000
8,89.500,18.87,3.9687,3.96880,8.000
8,89.625,21.92,4.0938,4.09385,8.000
8,89.750,25.34,4.2188,4.21890,8.000
8,89.875,29.18,4.3439,4.34400,8.000
8,90.062,26.95,4.3471,4.34715,8.000
8,90.188,20.73,4.2222,4.22228,8.000
8,90.312,16.27,4.0971,4.09715,8.000
8,90.438,12.85,3.9721,3.97215,8.000
8,90.562,10.18,3.8471,3.84718,8.000
8,90.688,8.08,3.7222,3.72225,8.000
8,90.812,6.40,3.5971,3.59718,8.000
8,90.938,5.08,3.4721,3.47215,8.000
8,91.062,4.03,3.3470,3.34713,8.000
8,91.188,3.18,3.2221,3.22218,8.000
8,91.312,2.50,3.0971,3.09718,8.000
8,91.438,1.92,2.9720,2.97205,8.000
8,91.562,1.44,2.8468,2.84690,8.000
8,91.688,1.04,2.7220,2.72205,8.000
8,91.812,0.72,2.5969,2.59700,8.000
8,91.938,0.46,2.4720,2.47210,8.000
8,92.062,0.26,2.3470,2.34710,8.000
8,92.188,0.12,2.2220,2.22210,8.000
8,92.312,0.03,2.0970,2.09708,8.000
8,92.438,0.01,1.9718,1.97192,8.000
8,92.562,0.00,1.8470,1.84705,8.000
8,92.688,0.00,1.7218,1.72195,8.000
8,92.812,0.00,1.5968,1.59693,8.000
8,92.938,-0.01,1.4719,1.47198,8.000
8,93.062,-0.01,1.3469,1.34698,8.000
8,93.188,0.00,1.2219,1.22200,8.000
8,93.312,-0.01,1.0969,1.09698,8.000
8,93.438,-0.01,0.9719,0.97200,8.000
8,93.562,0.00,0.8469,0.84695,8.000
8,93.688,0.00,0.7217,0.72182,8.000
8,93.812,0.00,0.5967,0.59678,8.000
8,93.938,0.00,0.4718,0.47188,8.000
8,94.062,0.00,0.3469,0.34703,8.000
8,94.188,0.00,0.2219,0.22202,8.000
8,94.312,-0.01,0.0969,0.09698,8.000
8,94.562,-0.01,-0.0009,-0.00080,8.000
8,94.688,-0.01,-0.0003,-0.00020,8.000
8,94.812,-0.01,-0.0003,-0.00020,8.000
8,94.938,-0.01,-0.0003,-0.00020,8.000
8,95.062,0.00,-0.0003,-0.00020,8.000
8,95.188,-0.01,-0.0003,-0.00020,8.000
8,95.312,-0.01,-0.0003,-0.00020,8.000
8,95.438,0.00,-0.0003,-0.00020,8.000
8,95.562,0.00,-0.0003,-0.00020,8.000
8,95.688,-0.01,-0.0003,-0.00020,8.000
8,95.812,0.00,-0.0003,-0.00020,8.000
8,95.938,0.00,-0.0003,-0.00020,8.000
8,96.062,0.00,-0.0003,-0.00020,8.000
8,96.188,-0.01,-0.0003,-0.00020,8.000
8,96.312,0.00,-0.0002,-0.00010,8.000
8,96.438,0.00,-0.0002,-0.00010,8.000
8,96.562,-0.01,-0.0002,-0.00010,8.000
8,96.688,0.00,-0.0002,-0.00010,8.000
8,96.812,-0.01,-0.0002,-0.00010,8.000
8,96.938,-0.01,-0.0002,-0.00010,8.000
8,97.062,-0.01,-0.0002,-0.00010,8.000
8,97.188,0.00,-0.0002,-0.00010,8.000
8,97.312,0.00,-0.0002,-0.00010,8.000
8,97.438,-0.01,-0.0002,-0.00010,8.000
9,97.750,0.00,0.0546,0.05470,9.000
9,97.875,0.00,0.1796,0.17975,9.000
9,98.000,0.00,0.3048,0.30490,9.000
9,98.125,0.00,0.4296,0.42975,9.000
9,98.250,0.00,0.5546,0.55470,9.000
9,98.375,0.00,0.6796,0.67970,9.000
9,98.500,0.00,0.8045,0.80460,9.000
9,98.625,0.00,0.9297,0.92975,9.000
9,98.750,0.00,1.0547,1.05480,9.000
9,98.875,0.00,1.1797,1.17980,9.000
9,99.000,0.00,1.3047,1.30480,9.000
9,99.125,0.00,1.4298,1.42990,9.000
9,99.250,0.00,1.5547,1.55480,9.000
9,99.375,0.01,1.6796,1.67975,9.000
9,99.500,0.03,1.8047,1.80480,9.000
9,99.625,0.07,1.9298,1.92985,9.000
9,99.750,0.14,2.0548,2.05490,9.000
9,99.875,0.32,2.1798,2.17990,9.000
9,100.000,0.57,2.3049,2.30500,9.000
9,100.125,0.91,2.4299,2.43000,9.000
9,100.250,1.36,2.5549,2.55500,9.000
9,100.375,1.92,2.6797,2.67980,9.000
9,100.500,2.63,2.8046,2.80470,9.000
9,100.625,3.49,2.9297,2.92980,9.000
9,100.750,4.55,3.0548,3.05490,9.000
9,100.875,5.79,3.1798,3.17990,9.000
9,101.000,7.25,3.3047,3.30480,9.000
9,101.125,8.94,3.4298,3.42995,9.000
9,101.250,10.85,3.5548,3.55490,9.000
9,101.375,12.99,3.6798,3.67985,9.000
9,101.500,15.36,3.8047,3.80480,9.000
9,101.625,18.00,3.9298,3.92985,9.000
9,101.750,20.94,4.0547,4.05480,9.000
9,101.875,24.24,4.1798,4.17990,9.000
9,102.000,27.97,4.3049,4.30500,9.000
9,102.188,30.41,4.3978,4.39785,9.000
9,102.312,22.87,4.2732,4.27325,9.000
9,102.438,17.85,4.1481,4.14820,9.000
9,102.562,14.08,4.0232,4.02328,9.000
9,102.688,11.14,3.8981,3.89820,9.000
9,102.812,8.84,3.7731,3.77318,9.000
9,102.938,7.02,3.6481,3.64818,9.000
9,103.062,5.57,3.5230,3.52308,9.000
9,103.188,4.43,3.3980,3.39815,9.000
9,103.312,3.50,3.2731,3.27318,9.000
9,103.438,2.76,3.1481,3.14820,9.000
9,103.562,2.14,3.0231,3.02318,9.000
9,103.688,1.63,2.8980,2.89808,9.000
9,103.812,1.20,2.7729,2.77298,9.000
9,103.938,0.84,2.6478,2.64795,9.000
9,104.062,0.55,2.5229,2.52295,9.000
9,104.188,0.33,2.3980,2.39808,9.000
9,104.312,0.17,2.2730,2.27310,9.000
9,104.438,0.06,2.1480,2.14810,9.000
9,104.562,0.02,2.0230,2.02305,9.000
9,104.688,0.01,1.8980,1.89810,9.000
9,104.812,0.01,1.7730,1.77308,9.000
9,104.938,0.00,1.6478,1.64790,9.000
9,105.062,0.00,1.5228,1.52290,9.000
9,105.188,0.00,1.3978,1.39795,9.000
9,105.312,0.00,1.2728,1.27290,9.000
9,105.438,-0.01,1.1479,1.14798,9.000
9,105.562,-0.01,1.0229,1.02295,9.000
9,105.688,0.00,0.8979,0.89800,9.000
9,105.812,0.00,0.7729,0.77295,9.000
9,105.938,0.00,0.6478,0.64785,9.000
9,106.062,0.00,0.5227,0.52275,9.000
9,106.188,0.00,0.3978,0.39790,9.000
9,106.312,0.00,0.2728,0.27290,9.000
9,106.438,0.00,0.1479,0.14795,9.000
9,106.562,0.00,0.0228,0.02290,9.000
9,106.750,0.00,0.0000,0.00010,9.000
9,106.875,-0.01,-0.0003,-0.00020,9.000
9,107.000,0.00,-0.0003,-0.00020,9.000
9,107.125,0.00,-0.0003,-0.00020,9.000
9,107.250,-0.01,-0.0003,-0.00020,9.000
9,107.375,0.00,-0.0003,-0.00020,9.000
9,107.500,-0.01,-0.0003,-0.00020,9.000
9,107.625,0.00,-0.0003,-0.00020,9.000
9,107.750,-0.01,-0.0003,-0.00020,9.000
9,107.875,-0.01,-0.0003,-0.00020,9.000
9,108.000,0.00,-0.0003,-0.00020,9.000
9,108.125,0.00,-0.0003,-0.00020,9.000
9,108.250,0.00,-0.0003,-0.00020,9.000
9,108.375,0.00,-0.0003,-0.00020,9.000
9,108.500,0.00,-0.0002,-0.00010,9.000
9,108.625,0.00,-0.0002,-0.00010,9.000
9,108.750,0.00,-0.0002,-0.00010,9.000
9,108.875,0.00,-0.0002,-0.00010,9.000
9,109.000,-0.01,-0.0002,-0.00010,9.000
9,109.125,-0.01,-0.0002,-0.00010,9.000
9,109.250,-0.01,-0.0002,-0.00010,9.000
9,109.375,-0.01,-0.0002,-0.00010,9.000
9,109.500,0.00,-0.0002,-0.00010,9.000
9,109.625,-0.01,-0.0002,-0.00010,9.000
10,109.938,0.00,0.0521,0.05218,10.000
10,110.062,0.01,0.1772,0.17730,10.000
10,110.188,0.00,0.3023,0.30238,10.000
10,110.312,0.00,0.4272,0.42727,10.000
10,110.438,0.00,0.5521,0.55220,10.000
10,110.562,0.00,0.6771,0.67720,10.000
10,110.688,0.00,0.8022,0.80225,10.000
10,110.812,0.00,0.9271,0.92722,10.000
10,110.938,0.00,1.0522,1.05235,10.000
10,111.062,0.00,1.1772,1.17730,10.000
10,111.188,0.00,1.3022,1.30232,10.000
10,111.312,0.00,1.4273,1.42740,10.000
10,111.438,0.00,1.5523,1.55240,10.000
10,111.562,0.01,1.6772,1.67727,10.000
10,111.688,0.03,1.8022,1.80235,10.000
10,111.812,0.07,1.9272,1.92727,10.000
10,111.938,0.15,2.0522,2.05235,10.000
10,112.062,0.31,2.1773,2.17740,10.000
10,112.188,0.56,2.3023,2.30240,10.000
10,112.312,0.90,2.4274,2.42755,10.000
10,112.438,1.35,2.5524,2.55248,10.000
10,112.562,1.91,2.6773,2.67737,10.000
10,112.688,2.61,2.8022,2.80225,10.000
10,112.812,3.48,2.9271,2.92722,10.000
10,112.938,4.54,3.0522,3.05232,10.000
10,113.062,5.77,3.1772,3.17735,10.000
10,113.188,7.23,3.3022,3.30232,10.000
10,113.312,8.92,3.4272,3.42735,10.000
10,113.438,10.84,3.5523,3.55238,10.000
10,113.562,12.97,3.6773,3.67745,10.000
10,113.688,15.34,3.8022,3.80235,10.000
10,113.812,17.99,3.9272,3.92730,10.000
10,113.938,20.93,4.0522,4.05230,10.000
10,114.062,24.23,4.1772,4.17735,10.000
10,114.188,27.94,4.3024,4.30247,10.000
10,114.375,30.64,4.4004,4.40050,10.000
10,114.500,23.03,4.2757,4.27580,10.000
10,114.625,17.97,4.1507,4.15075,10.000
10,114.750,14.18,4.0256,4.02570,10.000
10,114.875,11.22,3.9006,3.90070,10.000
10,115.000,8.89,3.7756,3.77570,10.000
10,115.125,7.07,3.6506,3.65065,10.000
10,115.250,5.61,3.5254,3.52550,10.000
10,115.375,4.46,3.4005,3.40060,10.000
10,115.500,3.53,3.2756,3.27570,10.000
10,115.625,2.78,3.1506,3.15070,10.000
10,115.750,2.16,3.0256,3.02570,10.000
10,115.875,1.64,2.9004,2.90050,10.000
10,116.000,1.21,2.7754,2.77550,10.000
10,116.125,0.85,2.6504,2.65045,10.000
10,116.250,0.56,2.5253,2.52540,10.000
10,116.375,0.35,2.4005,2.40055,10.000
10,116.500,0.18,2.2754,2.27550,10.000
10,116.625,0.07,2.1505,2.15055,10.000
10,116.750,0.03,2.0255,2.02560,10.000
10,116.875,0.02,1.9005,1.90055,10.000
10,117.000,0.01,1.7755,1.77560,10.000
10,117.125,0.01,1.6503,1.65040,10.000
10,117.250,0.00,1.5252,1.52530,10.000
10,117.375,0.00,1.4003,1.40040,10.000
10,117.500,0.01,1.2753,1.27540,10.000
10,117.625,0.00,1.1504,1.15045,10.000
10,117.750,0.00,1.0254,1.02550,10.000
10,117.875,0.01,0.9004,0.90050,10.000
10,118.000,0.00,0.7754,0.77550,10.000
10,118.125,0.00,0.6503,0.65040,10.000
10,118.250,0.00,0.5251,0.52520,10.000
10,118.375,0.00,0.4003,0.40040,10.000
10,118.500,0.00,0.2753,0.27540,10.000
10,118.625,0.01,0.1503,0.15040,10.000
10,118.750,0.01,0.0252,0.02530,10.000
10,118.938,0.01,-0.0005,-0.00040,10.000
10,119.062,0.00,-0.0003,-0.00020,10.000
10,119.188,0.00,-0.0003,-0.00020,10.000
10,119.312,0.00,-0.0003,-0.00020,10.000
10,119.438,0.01,-0.0003,-0.00020,10.000
10,119.562,0.00,-0.0003,-0.00020,10.000
10,119.688,0.00,-0.0003,-0.00020,10.000
10,119.812,0.00,-0.0003,-0.00020,10.000
10,119.938,0.00,-0.0003,-0.00020,10.000
10,120.062,0.00,-0.0003,-0.00020,10.000
10,120.188,0.00,-0.0003,-0.00020,10.000
10,120.312,0.00,-0.0003,-0.00020,10.000
10,120.438,0.00,-0.0002,-0.00010,10.000
10,120.562,0.00,-0.0002,-0.00010,10.000
10,120.688,0.00,-0.0002,-0.00010,10.000
10,120.812,0.00,-0.0002,-0.00010,10.000
10,120.938,0.00,-0.0002,-0.00010,10.000
10,121.062,0.00,-0.0002,-0.00010,10.000
10,121.188,0.00,-0.0002,-0.00010,10.000
10,121.312,0.00,-0.0002,-0.00010,10.000
10,121.438,0.01,-0.0002,-0.00010,10.000
10,121.562,0.01,-0.0002,-0.00010,10.000
10,121.688,0.00,-0.0002,-0.00010,10.000
10,121.812,0.00,-0.0002,-0.00010,10.000
10,121.875,0.01,-0.0002,-0.00010,10.000