File: AIME_journal_files/AIME_data/calibDATA_loadcell/date_02:22:2018/Instron/30N_0_1_1_0.txt
""
"Test Method","Radhen_Load_Cntrl_Cmprsn_250N_12-7.msm"
"Sample I. D.","Sample1.mss"
"Specimen Number","5"

"TheCycle_Output ()","_Time (s)","_Load (N)","_Extension (mm)","RealTimeDepth (mm)","CycleNumber ()"

1,0.312,0.00,0.1020,0.10205,1.000
1,0.438,0.00,0.2273,0.22728,1.000
1,0.562,0.01,0.3522,0.35222,1.000
1,0.688,0.00,0.4771,0.47715,1.000
1,0.812,0.00,0.6023,0.60232,1.000
1,0.938,0.00,0.7272,0.72725,1.000
1,1.062,0.01,0.8522,0.85220,1.000
1,1.188,0.00,0.9773,0.97728,1.000
1,1.312,0.00,1.1023,1.10230,1.000
1,1.438,0.00,1.2273,1.22730,1.000
1,1.562,0.01,1.3524,1.35238,1.000
1,1.688,0.00,1.4774,1.47738,1.000
1,1.812,0.00,1.6025,1.60248,1.000
1,1.938,0.01,1.7273,1.72732,1.000
1,2.062,0.00,1.8523,1.85225,1.000
1,2.188,0.00,1.9772,1.97720,1.000
1,2.312,0.00,2.1023,2.10230,1.000
1,2.438,0.00,2.2274,2.22735,1.000
1,2.562,0.00,2.3525,2.35248,1.000
1,2.688,0.00,2.4774,2.47738,1.000
1,2.812,0.00,2.6024,2.60235,1.000
1,2.938,0.00,2.7273,2.72728,1.000
1,3.062,0.00,2.8523,2.85230,1.000
1,3.188,0.00,2.9774,2.97735,1.000
1,3.312,0.01,3.1024,3.10235,1.000
1,3.438,0.03,3.2273,3.22728,1.000
1,3.562,0.05,3.3524,3.35238,1.000
1,3.688,0.09,3.4775,3.47748,1.000
1,3.812,0.18,3.6025,3.60250,1.000
1,3.938,0.34,3.7275,3.72750,1.000
1,4.062,0.58,3.8524,3.85242,1.000
1,4.188,0.91,3.9773,3.97732,1.000
1,4.312,1.36,4.1022,4.10222,1.000
1,4.438,1.93,4.2274,4.22737,1.000
1,4.562,2.62,4.3523,4.35235,1.000
1,4.688,3.45,4.4774,4.47745,1.000
1,4.812,4.45,4.6025,4.60248,1.000
1,4.938,5.60,4.7273,4.72732,1.000
1,5.062,6.97,4.8523,4.85228,1.000
1,5.188,8.52,4.9773,4.97732,1.000
1,5.312,10.29,5.1024,5.10237,1.000
1,5.438,12.30,5.2273,5.22730,1.000
1,5.562,14.54,5.3523,5.35230,1.000
1,5.688,17.06,5.4775,5.47748,1.000
1,5.812,19.89,5.6025,5.60252,1.000
1,5.938,23.07,5.7275,5.72750,1.000
1,6.062,26.64,5.8524,5.85240,1.000
1,6.312,27.55,5.9400,5.94002,1.000
1,6.438,21.12,5.8151,5.81508,1.000
1,6.562,16.57,5.6903,5.69030,1.000
1,6.688,13.11,5.5654,5.56540,1.000
1,6.812,10.45,5.4403,5.44028,1.000
1,6.938,8.35,5.3152,5.31515,1.000
1,7.062,6.72,5.1903,5.19025,1.000
1,7.188,5.42,5.0650,5.06505,1.000
1,7.312,4.36,4.9401,4.94013,1.000
1,7.438,3.50,4.8151,4.81508,1.000
1,7.562,2.78,4.6900,4.69005,1.000
1,7.688,2.18,4.5652,4.56515,1.000
1,7.812,1.66,4.4402,4.44020,1.000
1,7.938,1.24,4.3152,4.31520,1.000
1,8.062,0.89,4.1901,4.19010,1.000
1,8.188,0.59,4.0648,4.06485,1.000
1,8.312,0.37,3.9399,3.93985,1.000
1,8.438,0.20,3.8150,3.81502,1.000
1,8.562,0.08,3.6900,3.69003,1.000
1,8.688,0.03,3.5650,3.56502,1.000
1,8.812,0.01,3.4399,3.43993,1.000
1,8.938,0.01,3.3150,3.31500,1.000
1,9.062,0.00,3.1900,3.18995,1.000
1,9.188,0.01,3.0649,3.06495,1.000
1,9.312,0.00,2.9399,2.93990,1.000
1,9.438,0.00,2.8149,2.81488,1.000
1,9.562,0.00,2.6899,2.68993,1.000
1,9.688,0.00,2.5648,2.56482,1.000
1,9.812,0.00,2.4399,2.43993,1.000
1,9.938,0.00,2.3151,2.31508,1.000
1,10.062,0.00,2.1899,2.18985,1.000
1,10.188,0.00,2.0648,2.06482,1.000
1,10.312,0.00,1.9398,1.93978,1.000
1,10.438,0.00,1.8146,1.81462,1.000
1,10.562,0.00,1.6899,1.68993,1.000
1,10.688,0.00,1.5648,1.56482,1.000
1,10.812,0.00,1.4399,1.43993,1.000
1,10.938,0.00,1.3150,1.31497,1.000
1,11.062,0.00,1.1898,1.18980,1.000
1,11.188,0.00,1.0649,1.06490,1.000
1,11.312,0.00,0.9398,0.93975,1.000
1,11.438,0.00,0.8147,0.81470,1.000
1,11.562,0.00,0.6897,0.68973,1.000
1,11.688,0.00,0.5648,0.56477,1.000
1,11.812,0.00,0.4397,0.43970,1.000
1,11.938,0.00,0.3149,0.31487,1.000
1,12.062,0.01,0.1898,0.18980,1.000
1,12.188,0.01,0.0647,0.06467,1.000
1,12.375,0.01,-0.0135,-0.01345,1.000
1,12.500,0.00,-0.0003,-0.00030,1.000
1,12.625,0.00,-0.0003,-0.00030,1.000
1,12.750,0.00,-0.0003,-0.00030,1.000
1,12.875,0.00,-0.0003,-0.00030,1.000
1,13.000,0.00,-0.0003,-0.00030,1.000
1,13.125,0.00,-0.0003,-0.00030,1.000
1,13.250,0.00,-0.0003,-0.00030,1.000
1,13.375,0.01,-0.0003,-0.00030,1.000
1,13.500,0.00,-0.0003,-0.00030,1.000
1,13.625,0.01,-0.0003,-0.00030,1.000
1,13.750,0.00,-0.0003,-0.00030,1.000
1,13.875,0.00,-0.0003,-0.00030,1.000
1,14.000,0.00,-0.0003,-0.00030,1.000
1,14.125,0.01,-0.0003,-0.00030,1.000
1,14.250,0.00,-0.0003,-0.00030,1.000
1,14.375,0.00,-0.0003,-0.00030,1.000
1,14.500,0.00,-0.0002,-0.00020,1.000
1,14.625,0.00,-0.0002,-0.00020,1.000
1,14.750,0.01,-0.0002,-0.00020,1.000
1,14.875,0.00,-0.0002,-0.00020,1.000
1,15.000,0.00,-0.0002,-0.00020,1.000
1,15.125,0.00,-0.0002,-0.00020,1.000
1,15.250,0.01,-0.0002,-0.00020,1.000
2,15.562,0.01,0.0619,0.06202,2.000
2,15.688,0.01,0.1870,0.18710,2.000
2,15.812,0.01,0.3121,0.31222,2.000
2,15.938,0.01,0.4371,0.43718,2.000
2,16.062,0.01,0.5621,0.56223,2.000
2,16.188,0.01,0.6871,0.68717,2.000
2,16.312,0.01,0.8120,0.81210,2.000
2,16.438,0.01,0.9370,0.93710,2.000
2,16.562,0.01,1.0622,1.06230,2.000
2,16.688,0.01,1.1871,1.18720,2.000
2,16.812,0.01,1.3122,1.31233,2.000
2,16.938,0.01,1.4372,1.43732,2.000
2,17.062,0.01,1.5623,1.56238,2.000
2,17.188,0.01,1.6873,1.68737,2.000
2,17.312,0.01,1.8120,1.81213,2.000
2,17.438,0.01,1.9372,1.93727,2.000
2,17.562,0.01,2.0622,2.06233,2.000
2,17.688,0.01,2.1873,2.18737,2.000
2,17.812,0.01,2.3123,2.31243,2.000
2,17.938,0.01,2.4372,2.43732,2.000
2,18.062,0.01,2.5622,2.56233,2.000
2,18.188,0.01,2.6872,2.68735,2.000
2,18.312,0.01,2.8122,2.81230,2.000
2,18.438,0.01,2.9372,2.93730,2.000
2,18.562,0.01,3.0622,3.06233,2.000
2,18.688,0.03,3.1873,3.18740,2.000
2,18.812,0.04,3.3123,3.31240,2.000
2,18.938,0.08,3.4373,3.43737,2.000
2,19.062,0.14,3.5625,3.56255,2.000
2,19.188,0.27,3.6873,3.68745,2.000
2,19.312,0.48,3.8123,3.81238,2.000
2,19.438,0.77,3.9372,3.93727,2.000
2,19.562,1.17,4.0622,4.06230,2.000
2,19.688,1.68,4.1873,4.18737,2.000
2,19.812,2.32,4.3124,4.31248,2.000
2,19.938,3.10,4.4373,4.43742,2.000
2,20.062,4.02,4.5624,4.56250,2.000
2,20.188,5.13,4.6873,4.68742,2.000
2,20.312,6.42,4.8122,4.81230,2.000
2,20.438,7.91,4.9373,4.93737,2.000
2,20.562,9.61,5.0622,5.06233,2.000
2,20.688,11.54,5.1873,5.18740,2.000
2,20.812,13.71,5.3123,5.31235,2.000
2,20.938,16.15,5.4373,5.43740,2.000
2,21.062,18.89,5.5624,5.56253,2.000
2,21.188,21.97,5.6874,5.68752,2.000
2,21.312,25.43,5.8122,5.81230,2.000
2,21.438,29.35,5.9372,5.93735,2.000
2,21.625,27.02,5.9355,5.93560,2.000
2,21.750,20.84,5.8106,5.81070,2.000
2,21.875,16.37,5.6857,5.68580,2.000
2,22.000,12.98,5.5608,5.56090,2.000
2,22.125,10.35,5.4357,5.43575,2.000
2,22.250,8.29,5.3106,5.31070,2.000
2,22.375,6.67,5.1856,5.18570,2.000
2,22.500,5.36,5.0606,5.06070,2.000
2,22.625,4.32,4.9356,4.93565,2.000
2,22.750,3.46,4.8106,4.81070,2.000
2,22.875,2.75,4.6855,4.68560,2.000
2,23.000,2.14,4.5607,4.56080,2.000
2,23.125,1.63,4.4356,4.43570,2.000
2,23.250,1.22,4.3105,4.31060,2.000
2,23.375,0.86,4.1854,4.18555,2.000
2,23.500,0.57,4.0603,4.06040,2.000
2,23.625,0.36,3.9355,3.93555,2.000
2,23.750,0.19,3.8105,3.81060,2.000
2,23.875,0.07,3.6855,3.68560,2.000
2,24.000,0.02,3.5605,3.56060,2.000
2,24.125,0.01,3.4355,3.43555,2.000
2,24.250,0.01,3.3104,3.31050,2.000
2,24.375,0.00,3.1854,3.18550,2.000
2,24.500,0.01,3.0604,3.06050,2.000
2,24.625,0.01,2.9354,2.93545,2.000
2,24.750,0.00,2.8103,2.81040,2.000
2,24.875,0.01,2.6854,2.68550,2.000
2,25.000,0.01,2.5603,2.56040,2.000
2,25.125,0.01,2.4353,2.43545,2.000
2,25.250,0.01,2.3105,2.31060,2.000
2,25.375,0.01,2.1852,2.18535,2.000
2,25.500,0.01,2.0602,2.06030,2.000
2,25.625,0.01,1.9352,1.93535,2.000
2,25.750,0.01,1.8102,1.81030,2.000
2,25.875,0.01,1.6854,1.68550,2.000
2,26.000,0.01,1.5604,1.56050,2.000
2,26.125,0.01,1.4354,1.43545,2.000
2,26.250,0.01,1.3104,1.31050,2.000
2,26.375,0.01,1.1852,1.18530,2.000
2,26.500,0.01,1.0603,1.06040,2.000
2,26.625,0.01,0.9352,0.93525,2.000
2,26.750,0.01,0.8103,0.81040,2.000
2,26.875,0.01,0.6853,0.68540,2.000
2,27.000,0.01,0.5603,0.56040,2.000
2,27.125,0.01,0.4352,0.43535,2.000
2,27.250,0.01,0.3103,0.31040,2.000
2,27.375,0.01,0.1852,0.18535,2.000
2,27.500,0.01,0.0601,0.06020,2.000
2,27.688,0.01,-0.0324,-0.03228,2.000
2,27.812,0.01,-0.0004,-0.00030,2.000
2,27.938,0.01,-0.0004,-0.00030,2.000
2,28.062,0.01,-0.0004,-0.00030,2.000
2,28.188,0.01,-0.0004,-0.00030,2.000
2,28.312,0.01,-0.0003,-0.00020,2.000
2,28.438,0.01,-0.0003,-0.00020,2.000
2,28.562,0.01,-0.0003,-0.00020,2.000
2,28.688,0.01,-0.0003,-0.00020,2.000
2,28.812,0.01,-0.0003,-0.00020,2.000
2,28.938,0.01,-0.0003,-0.00020,2.000
2,29.062,0.01,-0.0003,-0.00020,2.000
2,29.188,0.01,-0.0003,-0.00020,2.000
2,29.312,0.01,-0.0003,-0.00020,2.000
2,29.438,0.01,-0.0003,-0.00020,2.000
2,29.562,0.01,-0.0003,-0.00020,2.000
2,29.688,0.01,-0.0003,-0.00020,2.000
2,29.812,0.01,-0.0003,-0.00020,2.000
2,29.938,0.01,-0.0003,-0.00020,2.000
2,30.062,0.01,-0.0003,-0.00020,2.000
2,30.188,0.01,-0.0002,-0.00010,2.000
2,30.312,0.01,-0.0002,-0.00010,2.000
2,30.438,0.01,-0.0002,-0.00010,2.000
2,30.562,0.01,-0.0002,-0.00010,2.000
3,30.875,0.00,0.0444,0.04450,3.000
3,31.000,0.00,0.1695,0.16960,3.000
3,31.125,0.00,0.2945,0.29465,3.000
3,31.250,0.00,0.4194,0.41950,3.000
3,31.375,0.00,0.5446,0.54470,3.000
3,31.500,0.00,0.6697,0.66980,3.000
3,31.625,0.00,0.7947,0.79480,3.000
3,31.750,0.00,0.9196,0.91970,3.000
3,31.875,0.00,1.0447,1.04480,3.000
3,32.000,0.00,1.1697,1.16980,3.000
3,32.125,0.00,1.2947,1.29475,3.000
3,32.250,0.00,1.4196,1.41970,3.000
3,32.375,0.00,1.5448,1.54485,3.000
3,32.500,0.00,1.6699,1.67000,3.000
3,32.625,0.00,1.7947,1.79480,3.000
3,32.750,0.00,1.9198,1.91990,3.000
3,32.875,0.00,2.0448,2.04485,3.000
3,33.000,0.00,2.1696,2.16970,3.000
3,33.125,0.00,2.2947,2.29480,3.000
3,33.250,0.00,2.4196,2.41970,3.000
3,33.375,0.00,2.5447,2.54480,3.000
3,33.500,0.00,2.6698,2.66990,3.000
3,33.625,0.00,2.7948,2.79490,3.000
3,33.750,0.00,2.9199,2.92000,3.000
3,33.875,0.00,3.0448,3.04495,3.000
3,34.000,0.01,3.1699,3.17000,3.000
3,34.125,0.03,3.2947,3.29480,3.000
3,34.250,0.06,3.4197,3.41980,3.000
3,34.375,0.12,3.5448,3.54490,3.000
3,34.500,0.23,3.6698,3.66990,3.000
3,34.625,0.43,3.7948,3.79490,3.000
3,34.750,0.70,3.9199,3.92000,3.000
3,34.875,1.09,4.0448,4.04490,3.000
3,35.000,1.59,4.1698,4.16990,3.000
3,35.125,2.21,4.2948,4.29490,3.000
3,35.250,2.97,4.4197,4.41980,3.000
3,35.375,3.88,4.5448,4.54485,3.000
3,35.500,4.97,4.6698,4.66990,3.000
3,35.625,6.23,4.7948,4.79490,3.000
3,35.750,7.70,4.9198,4.91990,3.000
3,35.875,9.38,5.0448,5.04495,3.000
3,36.000,11.30,5.1700,5.17010,3.000
3,36.125,13.45,5.2948,5.29490,3.000
3,36.250,15.88,5.4197,5.41980,3.000
3,36.375,18.58,5.5449,5.54500,3.000
3,36.500,21.61,5.6698,5.66990,3.000
3,36.625,25.03,5.7948,5.79490,3.000
3,36.750,28.89,5.9199,5.92000,3.000
3,36.938,27.31,5.9330,5.93312,3.000
3,37.062,21.01,5.8082,5.80828,3.000
3,37.188,16.49,5.6832,5.68330,3.000
3,37.312,13.05,5.5584,5.55845,3.000
3,37.438,10.39,5.4331,5.43322,3.000
3,37.562,8.31,5.3081,5.30823,3.000
3,37.688,6.68,5.1830,5.18312,3.000
3,37.812,5.36,5.0581,5.05815,3.000
3,37.938,4.31,4.9331,4.93325,3.000
3,38.062,3.44,4.8081,4.80820,3.000
3,38.188,2.73,4.6831,4.68320,3.000
3,38.312,2.12,4.5582,4.55825,3.000
3,38.438,1.62,4.4330,4.43312,3.000
3,38.562,1.20,4.3080,4.30810,3.000
3,38.688,0.84,4.1829,4.18302,3.000
3,38.812,0.56,4.0578,4.05793,3.000
3,38.938,0.34,3.9329,3.93300,3.000
3,39.062,0.18,3.8080,3.80810,3.000
3,39.188,0.07,3.6831,3.68317,3.000
3,39.312,0.02,3.5581,3.55815,3.000
3,39.438,0.01,3.4329,3.43302,3.000
3,39.562,0.00,3.3079,3.30798,3.000
3,39.688,0.00,3.1828,3.18292,3.000
3,39.812,0.00,3.0579,3.05795,3.000
3,39.938,0.00,2.9328,2.93295,3.000
3,40.062,0.00,2.8079,2.80795,3.000
3,40.188,0.00,2.6830,2.68307,3.000
3,40.312,0.00,2.5579,2.55798,3.000
3,40.438,0.00,2.4329,2.43300,3.000
3,40.562,0.00,2.3080,2.30805,3.000
3,40.688,0.00,2.1827,2.18285,3.000
3,40.812,-0.01,2.0578,2.05790,3.000
3,40.938,0.00,1.9328,1.93287,3.000
3,41.062,0.00,1.8077,1.80780,3.000
3,41.188,0.00,1.6830,1.68307,3.000
3,41.312,0.00,1.5579,1.55800,3.000
3,41.438,0.00,1.4329,1.43305,3.000
3,41.562,0.00,1.3078,1.30788,3.000
3,41.688,0.00,1.1827,1.18277,3.000
3,41.812,0.00,1.0577,1.05783,3.000
3,41.938,0.00,0.9326,0.93270,3.000
3,42.062,-0.01,0.8078,0.80788,3.000
3,42.188,0.00,0.6828,0.68292,3.000
3,42.312,0.00,0.5578,0.55785,3.000
3,42.438,0.00,0.4328,0.43290,3.000
3,42.562,0.00,0.3079,0.30795,3.000
3,42.688,0.00,0.1827,0.18277,3.000
3,42.812,0.00,0.0575,0.05763,3.000
3,43.000,-0.01,-0.0105,-0.01040,3.000
3,43.125,0.00,-0.0003,-0.00020,3.000
3,43.250,-0.01,-0.0003,-0.00020,3.000
3,43.375,0.00,-0.0003,-0.00020,3.000
3,43.500,0.00,-0.0003,-0.00020,3.000
3,43.625,0.00,-0.0003,-0.00020,3.000
3,43.750,-0.01,-0.0003,-0.00020,3.000
3,43.875,-0.01,-0.0003,-0.00020,3.000
3,44.000,-0.01,-0.0003,-0.00020,3.000
3,44.125,0.00,-0.0003,-0.00020,3.000
3,44.250,0.00,-0.0003,-0.00020,3.000
3,44.375,-0.01,-0.0003,-0.00020,3.000
3,44.500,0.00,-0.0003,-0.00020,3.000
3,44.625,0.00,-0.0003,-0.00020,3.000
3,44.750,0.00,-0.0003,-0.00020,3.000
3,44.875,0.00,-0.0003,-0.00020,3.000
3,45.000,0.00,-0.0003,-0.00020,3.000
3,45.125,0.00,-0.0002,-0.00010,3.000
3,45.250,0.00,-0.0002,-0.00010,3.000
3,45.375,0.00,-0.0002,-0.00010,3.000
3,45.500,0.00,-0.0002,-0.00010,3.000
3,45.625,0.00,-0.0002,-0.00010,3.000
3,45.750,-0.01,-0.0002,-0.00010,3.000
3,45.875,0.00,-0.0002,-0.00010,3.000
4,46.250,-0.01,0.0884,0.08850,4.000
4,46.375,-0.01,0.2134,0.21355,4.000
4,46.500,-0.01,0.3385,0.33860,4.000
4,46.625,-0.01,0.4634,0.46355,4.000
4,46.750,-0.01,0.5887,0.58880,4.000
4,46.875,-0.02,0.7136,0.71375,4.000
4,47.000,-0.01,0.8387,0.83880,4.000
4,47.125,-0.01,0.9636,0.96370,4.000
4,47.250,-0.01,1.0886,1.08870,4.000
4,47.375,-0.01,1.2136,1.21370,4.000
4,47.500,-0.02,1.3387,1.33880,4.000
4,47.625,-0.01,1.4636,1.46375,4.000
4,47.750,-0.01,1.5887,1.58880,4.000
4,47.875,-0.01,1.7138,1.71390,4.000
4,48.000,-0.01,1.8387,1.83880,4.000
4,48.125,-0.01,1.9637,1.96380,4.000
4,48.250,-0.01,2.0887,2.08880,4.000
4,48.375,-0.01,2.2136,2.21375,4.000
4,48.500,-0.01,2.3388,2.33890,4.000
4,48.625,-0.01,2.4636,2.46370,4.000
4,48.750,-0.01,2.5887,2.58880,4.000
4,48.875,-0.01,2.7137,2.71385,4.000
4,49.000,-0.01,2.8388,2.83890,4.000
4,49.125,-0.01,2.9638,2.96390,4.000
4,49.250,-0.01,3.0888,3.08890,4.000
4,49.375,0.01,3.2137,3.21385,4.000
4,49.500,0.03,3.3386,3.33870,4.000
4,49.625,0.07,3.4637,3.46385,4.000
4,49.750,0.14,3.5889,3.58900,4.000
4,49.875,0.28,3.7139,3.71400,4.000
4,50.000,0.50,3.8388,3.83890,4.000
4,50.125,0.81,3.9638,3.96395,4.000
4,50.250,1.22,4.0889,4.08900,4.000
4,50.375,1.76,4.2138,4.21390,4.000
4,50.500,2.42,4.3388,4.33890,4.000
4,50.625,3.23,4.4637,4.46385,4.000
4,50.750,4.19,4.5887,4.58880,4.000
4,50.875,5.34,4.7137,4.71380,4.000
4,51.000,6.67,4.8388,4.83890,4.000
4,51.125,8.21,4.9639,4.96400,4.000
4,51.250,9.97,5.0889,5.08900,4.000
4,51.375,11.97,5.2139,5.21400,4.000
4,51.500,14.21,5.3388,5.33890,4.000
4,51.625,16.72,5.4638,5.46395,4.000
4,51.750,19.53,5.5889,5.58900,4.000
4,51.875,22.68,5.7138,5.71395,4.000
4,52.000,26.24,5.8388,5.83890,4.000
4,52.125,30.28,5.9638,5.96395,4.000
4,52.312,24.63,5.8872,5.88728,4.000
4,52.438,19.16,5.7622,5.76227,4.000
4,52.562,15.09,5.6373,5.63735,4.000
4,52.688,11.97,5.5123,5.51240,4.000
4,52.812,9.54,5.3870,5.38713,4.000
4,52.938,7.65,5.2621,5.26220,4.000
4,53.062,6.14,5.1371,5.13715,4.000
4,53.188,4.93,5.0121,5.01225,4.000
4,53.312,3.95,4.8871,4.88715,4.000
4,53.438,3.14,4.7620,4.76212,4.000
4,53.562,2.47,4.6370,4.63708,4.000
4,53.688,1.90,4.5120,4.51212,4.000
4,53.812,1.43,4.3871,4.38715,4.000
4,53.938,1.05,4.2619,4.26205,4.000
4,54.062,0.73,4.1369,4.13698,4.000
4,54.188,0.46,4.0119,4.01200,4.000
4,54.312,0.26,3.8870,3.88705,4.000
4,54.438,0.12,3.7620,3.76210,4.000
4,54.562,0.03,3.6371,3.63718,4.000
4,54.688,0.00,3.5119,3.51202,4.000
4,54.812,-0.01,3.3869,3.38700,4.000
4,54.938,-0.01,3.2618,3.26190,4.000
4,55.062,-0.01,3.1370,3.13708,4.000
4,55.188,-0.01,3.0119,3.01200,4.000
4,55.312,-0.01,2.8869,2.88700,4.000
4,55.438,-0.01,2.7620,2.76207,4.000
4,55.562,-0.01,2.6370,2.63705,4.000
4,55.688,-0.01,2.5119,2.51200,4.000
4,55.812,-0.01,2.3869,2.38695,4.000
4,55.938,-0.01,2.2617,2.26185,4.000
4,56.062,-0.01,2.1367,2.13680,4.000
4,56.188,-0.01,2.0118,2.01187,4.000
4,56.312,-0.01,1.8868,1.88690,4.000
4,56.438,-0.01,1.7618,1.76190,4.000
4,56.562,-0.01,1.6371,1.63718,4.000
4,56.688,-0.01,1.5118,1.51195,4.000
4,56.812,-0.01,1.3869,1.38700,4.000
4,56.938,-0.01,1.2617,1.26182,4.000
4,57.062,-0.01,1.1367,1.13675,4.000
4,57.188,-0.01,1.0118,1.01187,4.000
4,57.312,-0.01,0.8867,0.88680,4.000
4,57.438,-0.01,0.7618,0.76190,4.000
4,57.562,-0.01,0.6368,0.63693,4.000
4,57.688,-0.01,0.5118,0.51190,4.000
4,57.812,-0.01,0.3868,0.38685,4.000
4,57.938,-0.01,0.2616,0.26175,4.000
4,58.062,-0.01,0.1366,0.13670,4.000
4,58.188,-0.01,0.0116,0.01167,4.000
4,58.375,-0.01,-0.0003,-0.00020,4.000
4,58.500,-0.01,-0.0003,-0.00020,4.000
4,58.625,-0.01,-0.0003,-0.00020,4.000
4,58.750,-0.02,-0.0003,-0.00020,4.000
4,58.875,-0.01,-0.0003,-0.00020,4.000
4,59.000,-0.01,-0.0003,-0.00020,4.000
4,59.125,-0.01,-0.0003,-0.00020,4.000
4,59.250,-0.01,-0.0003,-0.00020,4.000
4,59.375,-0.01,-0.0003,-0.00020,4.000
4,59.500,-0.01,-0.0003,-0.00020,4.000
4,59.625,-0.01,-0.0003,-0.00020,4.000
4,59.750,-0.01,-0.0003,-0.00020,4.000
4,59.875,-0.01,-0.0003,-0.00020,4.000
4,60.000,-0.01,-0.0003,-0.00020,4.000
4,60.125,-0.01,-0.0003,-0.00020,4.000
4,60.250,-0.01,-0.0003,-0.00020,4.000
4,60.375,-0.01,-0.0003,-0.00020,4.000
4,60.500,-0.01,-0.0002,-0.00010,4.000
4,60.625,-0.01,-0.0002,-0.00010,4.000
4,60.750,0.00,-0.0002,-0.00010,4.000
4,60.875,-0.01,-0.0002,-0.00010,4.000
4,61.000,-0.01,-0.0002,-0.00010,4.000
4,61.125,-0.01,-0.0002,-0.00010,4.000
4,61.250,-0.01,-0.0002,-0.00010,4.000
5,61.625,0.00,0.1424,0.14255,5.000
5,61.750,0.00,0.2676,0.26770,5.000
5,61.875,0.00,0.3926,0.39270,5.000
5,62.000,0.00,0.5176,0.51770,5.000
5,62.125,0.00,0.6427,0.64280,5.000
5,62.250,0.00,0.7677,0.76780,5.000
5,62.375,0.00,0.8925,0.89260,5.000
5,62.500,0.00,1.0177,1.01780,5.000
5,62.625,0.00,1.1426,1.14270,5.000
5,62.750,0.00,1.2677,1.26780,5.000
5,62.875,0.00,1.3927,1.39285,5.000
5,63.000,0.00,1.5178,1.51790,5.000
5,63.125,0.00,1.6429,1.64300,5.000
5,63.250,0.00,1.7677,1.76780,5.000
5,63.375,0.00,1.8926,1.89270,5.000
5,63.500,0.00,2.0176,2.01770,5.000
5,63.625,0.00,2.1426,2.14270,5.000
5,63.750,0.00,2.2678,2.26790,5.000
5,63.875,0.00,2.3927,2.39285,5.000
5,64.000,0.00,2.5177,2.51780,5.000
5,64.125,0.00,2.6428,2.64285,5.000
5,64.250,0.00,2.7679,2.76800,5.000
5,64.375,0.00,2.8928,2.89285,5.000
5,64.500,0.00,3.0177,3.01780,5.000
5,64.625,0.01,3.1428,3.14285,5.000
5,64.750,0.02,3.2676,3.26770,5.000
5,64.875,0.05,3.3928,3.39285,5.000
5,65.000,0.10,3.5179,3.51800,5.000
5,65.125,0.20,3.6429,3.64300,5.000
5,65.250,0.38,3.7679,3.76800,5.000
5,65.375,0.63,3.8928,3.89285,5.000
5,65.500,0.98,4.0177,4.01780,5.000
5,65.625,1.46,4.1426,4.14275,5.000
5,65.750,2.05,4.2677,4.26780,5.000
5,65.875,2.77,4.3928,4.39285,5.000
5,66.000,3.64,4.5178,4.51790,5.000
5,66.125,4.69,4.6428,4.64290,5.000
5,66.250,5.90,4.7678,4.76790,5.000
5,66.375,7.33,4.8928,4.89295,5.000
5,66.500,8.95,5.0178,5.01790,5.000
5,66.625,10.82,5.1428,5.14290,5.000
5,66.750,12.93,5.2678,5.26790,5.000
5,66.875,15.28,5.3928,5.39285,5.000
5,67.000,17.91,5.5179,5.51800,5.000
5,67.125,20.87,5.6430,5.64305,5.000
5,67.250,24.18,5.7678,5.76790,5.000
5,67.375,27.96,5.8929,5.89300,5.000
5,67.562,30.04,5.9758,5.97585,5.000
5,67.688,22.70,5.8512,5.85125,5.000
5,67.812,17.75,5.7262,5.72628,5.000
5,67.938,14.04,5.6014,5.60145,5.000
5,68.062,11.17,5.4763,5.47635,5.000
5,68.188,8.90,5.3511,5.35115,5.000
5,68.312,7.15,5.2261,5.22615,5.000
5,68.438,5.74,5.1011,5.10118,5.000
5,68.562,4.62,4.9761,4.97620,5.000
5,68.688,3.70,4.8511,4.85118,5.000
5,68.812,2.94,4.7260,4.72605,5.000
5,68.938,2.30,4.6011,4.60118,5.000
5,69.062,1.76,4.4761,4.47618,5.000
5,69.188,1.32,4.3510,4.35105,5.000
5,69.312,0.96,4.2260,4.22608,5.000
5,69.438,0.65,4.1008,4.10090,5.000
5,69.562,0.41,3.9759,3.97603,5.000
5,69.688,0.23,3.8510,3.85108,5.000
5,69.812,0.10,3.7260,3.72610,5.000
5,69.938,0.02,3.6011,3.60118,5.000
5,70.062,0.01,3.4760,3.47605,5.000
5,70.188,0.01,3.3509,3.35095,5.000
5,70.312,0.00,3.2259,3.22595,5.000
5,70.438,0.00,3.1010,3.10105,5.000
5,70.562,0.00,2.9759,2.97603,5.000
5,70.688,0.00,2.8509,2.85098,5.000
5,70.812,0.00,2.7259,2.72600,5.000
5,70.938,0.00,2.6010,2.60108,5.000
5,71.062,0.00,2.4758,2.47590,5.000
5,71.188,0.00,2.3508,2.35092,5.000
5,71.312,0.00,2.2258,2.22593,5.000
5,71.438,0.01,2.1008,2.10090,5.000
5,71.562,0.00,1.9758,1.97588,5.000
5,71.688,0.00,1.8508,1.85085,5.000
5,71.812,0.00,1.7258,1.72593,5.000
5,71.938,0.00,1.6010,1.60108,5.000
5,72.062,0.00,1.4759,1.47600,5.000
5,72.188,0.00,1.3509,1.35100,5.000
5,72.312,0.00,1.2257,1.22583,5.000
5,72.438,0.00,1.1007,1.10083,5.000
5,72.562,0.00,0.9757,0.97578,5.000
5,72.688,0.00,0.8508,0.85085,5.000
5,72.812,0.00,0.7258,0.72590,5.000
5,72.938,0.00,0.6009,0.60098,5.000
5,73.062,0.00,0.4758,0.47590,5.000
5,73.188,0.00,0.3508,0.35090,5.000
5,73.312,0.00,0.2257,0.22583,5.000
5,73.438,0.00,0.1006,0.10073,5.000
5,73.688,0.00,-0.0019,-0.00180,5.000
5,73.812,0.00,-0.0003,-0.00020,5.000
5,73.938,0.00,-0.0003,-0.00020,5.000
5,74.062,0.01,-0.0003,-0.00020,5.000
5,74.188,0.00,-0.0003,-0.00020,5.000
5,74.312,0.01,-0.0003,-0.00020,5.000
5,74.438,0.01,-0.0003,-0.00020,5.000
5,74.562,0.00,-0.0003,-0.00020,5.000
5,74.688,0.00,-0.0003,-0.00020,5.000
5,74.812,0.00,-0.0003,-0.00020,5.000
5,74.938,0.00,-0.0003,-0.00020,5.000
5,75.062,0.00,-0.0003,-0.00020,5.000
5,75.188,0.00,-0.0003,-0.00020,5.000
5,75.312,0.00,-0.0003,-0.00020,5.000
5,75.438,-0.01,-0.0002,-0.00010,5.000
5,75.562,0.01,-0.0002,-0.00010,5.000
5,75.688,0.00,-0.0002,-0.00010,5.000
5,75.812,0.00,-0.0002,-0.00010,5.000
5,75.938,0.01,-0.0002,-0.00010,5.000
5,76.062,0.00,-0.0002,-0.00010,5.000
5,76.188,0.01,-0.0002,-0.00010,5.000
5,76.312,0.00,-0.0002,-0.00010,5.000
5,76.438,0.01,-0.0002,-0.00010,5.000
5,76.562,0.00,-0.0002,-0.00010,5.000
6,76.875,-0.01,0.0745,0.07460,6.000
6,77.000,-0.01,0.1996,0.19970,6.000
6,77.125,-0.01,0.3246,0.32470,6.000
6,77.250,-0.01,0.4495,0.44960,6.000
6,77.375,-0.01,0.5746,0.57465,6.000
6,77.500,0.00,0.6996,0.69970,6.000
6,77.625,-0.01,0.8246,0.82465,6.000
6,77.750,-0.01,0.9496,0.94970,6.000
6,77.875,0.00,1.0747,1.07480,6.000
6,78.000,-0.01,1.1996,1.19970,6.000
6,78.125,-0.01,1.3247,1.32480,6.000
6,78.250,-0.01,1.4498,1.44990,6.000
6,78.375,-0.01,1.5747,1.57480,6.000
6,78.500,-0.01,1.6997,1.69980,6.000
6,78.625,-0.01,1.8246,1.82465,6.000
6,78.750,-0.01,1.9496,1.94970,6.000
6,78.875,-0.01,2.0748,2.07485,6.000
6,79.000,-0.01,2.1998,2.19990,6.000
6,79.125,-0.01,2.3248,2.32495,6.000
6,79.250,0.00,2.4496,2.44970,6.000
6,79.375,-0.01,2.5747,2.57480,6.000
6,79.500,-0.01,2.6997,2.69980,6.000
6,79.625,-0.01,2.8247,2.82480,6.000
6,79.750,-0.01,2.9497,2.94980,6.000
6,79.875,-0.01,3.0748,3.07490,6.000
6,80.000,0.01,3.1998,3.19990,6.000
6,80.125,0.02,3.3248,3.32490,6.000
6,80.250,0.06,3.4499,3.45000,6.000
6,80.375,0.13,3.5748,3.57495,6.000
6,80.500,0.26,3.6997,3.69980,6.000
6,80.625,0.47,3.8248,3.82485,6.000
6,80.750,0.76,3.9498,3.94990,6.000
6,80.875,1.17,4.0748,4.07485,6.000
6,81.000,1.70,4.1999,4.20000,6.000
6,81.125,2.34,4.3249,4.32500,6.000
6,81.250,3.13,4.4499,4.45000,6.000
6,81.375,4.08,4.5748,4.57485,6.000
6,81.500,5.20,4.6997,4.69980,6.000
6,81.625,6.51,4.8248,4.82485,6.000
6,81.750,8.02,4.9497,4.94980,6.000
6,81.875,9.76,5.0748,5.07490,6.000
6,82.000,11.73,5.1998,5.19990,6.000
6,82.125,13.94,5.3249,5.32500,6.000
6,82.250,16.43,5.4500,5.45010,6.000
6,82.375,19.21,5.5750,5.57510,6.000
6,82.500,22.33,5.6998,5.69990,6.000
6,82.625,25.85,5.8247,5.82480,6.000
6,82.750,29.84,5.9498,5.94990,6.000
6,82.938,26.35,5.9231,5.92322,6.000
6,83.062,20.37,5.7981,5.79823,6.000
6,83.188,16.02,5.6730,5.67310,6.000
6,83.312,12.71,5.5481,5.54823,6.000
6,83.438,10.11,5.4230,5.42313,6.000
6,83.562,8.09,5.2981,5.29823,6.000
6,83.688,6.49,5.1731,5.17325,6.000
6,83.812,5.22,5.0481,5.04823,6.000
6,83.938,4.18,4.9232,4.92328,6.000
6,84.062,3.33,4.7981,4.79815,6.000
6,84.188,2.63,4.6729,4.67298,6.000
6,84.312,2.04,4.5481,4.54815,6.000
6,84.438,1.55,4.4230,4.42308,6.000
6,84.562,1.14,4.2981,4.29820,6.000
6,84.688,0.80,4.1730,4.17308,6.000
6,84.812,0.52,4.0480,4.04810,6.000
6,84.938,0.31,3.9230,3.92312,6.000
6,85.062,0.15,3.7981,3.79815,6.000
6,85.188,0.05,3.6731,3.67318,6.000
6,85.312,0.01,3.5479,3.54800,6.000
6,85.438,0.00,3.4228,3.42290,6.000
6,85.562,-0.01,3.2978,3.29793,6.000
6,85.688,-0.01,3.1728,3.17292,6.000
6,85.812,-0.01,3.0480,3.04810,6.000
6,85.938,-0.01,2.9230,2.92308,6.000
6,86.062,-0.01,2.7980,2.79805,6.000
6,86.188,0.00,2.6729,2.67295,6.000
6,86.312,-0.01,2.5478,2.54793,6.000
6,86.438,-0.01,2.4227,2.42278,6.000
6,86.562,-0.01,2.2978,2.29793,6.000
6,86.688,-0.01,2.1728,2.17285,6.000
6,86.812,-0.01,2.0478,2.04793,6.000
6,86.938,-0.01,1.9229,1.92298,6.000
6,87.062,-0.01,1.7979,1.79795,6.000
6,87.188,-0.01,1.6731,1.67318,6.000
6,87.312,0.00,1.5478,1.54788,6.000
6,87.438,-0.01,1.4229,1.42298,6.000
6,87.562,-0.01,1.2977,1.29775,6.000
6,87.688,-0.01,1.1728,1.17285,6.000
6,87.812,-0.01,1.0478,1.04793,6.000
6,87.938,-0.01,0.9227,0.92280,6.000
6,88.062,-0.01,0.7979,0.79798,6.000
6,88.188,-0.01,0.6729,0.67300,6.000
6,88.312,-0.01,0.5477,0.54780,6.000
6,88.438,-0.01,0.4226,0.42268,6.000
6,88.562,-0.01,0.2976,0.29773,6.000
6,88.688,-0.01,0.1726,0.17272,6.000
6,88.812,-0.01,0.0477,0.04778,6.000
6,89.000,-0.01,-0.0176,-0.01750,6.000
6,89.125,-0.01,-0.0003,-0.00020,6.000
6,89.250,-0.01,-0.0003,-0.00020,6.000
6,89.375,-0.01,-0.0003,-0.00020,6.000
6,89.500,-0.01,-0.0003,-0.00020,6.000
6,89.625,-0.01,-0.0003,-0.00020,6.000
6,89.750,-0.01,-0.0003,-0.00020,6.000
6,89.875,-0.01,-0.0003,-0.00020,6.000
6,90.000,-0.01,-0.0003,-0.00020,6.000
6,90.125,-0.01,-0.0003,-0.00020,6.000
6,90.250,-0.01,-0.0003,-0.00020,6.000
6,90.375,-0.01,-0.0003,-0.00020,6.000
6,90.500,-0.01,-0.0003,-0.00020,6.000
6,90.625,-0.01,-0.0003,-0.00020,6.000
6,90.750,-0.01,-0.0003,-0.00020,6.000
6,90.875,-0.01,-0.0003,-0.00020,6.000
6,91.000,0.00,-0.0003,-0.00020,6.000
6,91.125,-0.01,-0.0003,-0.00020,6.000
6,91.250,0.00,-0.0002,-0.00010,6.000
6,91.375,-0.01,-0.0002,-0.00010,6.000
6,91.500,-0.01,-0.0002,-0.00010,6.000
6,91.625,-0.01,-0.0002,-0.00010,6.000
6,91.750,-0.01,-0.0002,-0.00010,6.000
6,91.875,-0.01,-0.0002,-0.00010,6.000
7,92.188,-0.01,0.0470,0.04708,7.000
7,92.312,0.00,0.1720,0.17207,7.000
7,92.438,-0.01,0.2970,0.29705,7.000
7,92.562,-0.01,0.4219,0.42202,7.000
7,92.688,-0.01,0.5470,0.54710,7.000
7,92.812,-0.01,0.6722,0.67230,7.000
7,92.938,0.00,0.7972,0.79728,7.000
7,93.062,-0.01,0.9221,0.92220,7.000
7,93.188,0.00,1.0472,1.04733,7.000
7,93.312,0.00,1.1721,1.17220,7.000
7,93.438,0.00,1.2972,1.29728,7.000
7,93.562,-0.01,1.4221,1.42222,7.000
7,93.688,0.00,1.5472,1.54730,7.000
7,93.812,0.00,1.6723,1.67242,7.000
7,93.938,-0.01,1.7972,1.79725,7.000
7,94.062,-0.01,1.9222,1.92232,7.000
7,94.188,0.00,2.0472,2.04733,7.000
7,94.312,0.00,2.1722,2.17230,7.000
7,94.438,0.00,2.2972,2.29735,7.000
7,94.562,0.00,2.4221,2.42222,7.000
7,94.688,0.00,2.5472,2.54728,7.000
7,94.812,-0.01,2.6722,2.67230,7.000
7,94.938,0.00,2.7973,2.79738,7.000
7,95.062,-0.01,2.9222,2.92232,7.000
7,95.188,-0.01,3.0474,3.04748,7.000
7,95.312,0.00,3.1724,3.17247,7.000
7,95.438,0.02,3.2973,3.29740,7.000
7,95.562,0.05,3.4222,3.42232,7.000
7,95.688,0.11,3.5472,3.54733,7.000
7,95.812,0.23,3.6723,3.67242,7.000
7,95.938,0.42,3.7973,3.79740,7.000
7,96.062,0.69,3.9223,3.92242,7.000
7,96.188,1.07,4.0473,4.04740,7.000
7,96.312,1.57,4.1723,4.17245,7.000
7,96.438,2.19,4.2973,4.29738,7.000
7,96.562,2.95,4.4223,4.42237,7.000
7,96.688,3.86,4.5473,4.54740,7.000
7,96.812,4.94,4.6722,4.67232,7.000
7,96.938,6.21,4.7973,4.79738,7.000
7,97.062,7.68,4.9223,4.92245,7.000
7,97.188,9.36,5.0474,5.04748,7.000
7,97.312,11.28,5.1724,5.17255,7.000
7,97.438,13.45,5.2973,5.29743,7.000
7,97.562,15.87,5.4223,5.42240,7.000
7,97.688,18.58,5.5474,5.54750,7.000
7,97.812,21.61,5.6723,5.67242,7.000
7,97.938,25.04,5.7973,5.79738,7.000
7,98.062,28.94,5.9224,5.92250,7.000
7,98.312,24.47,5.8882,5.88830,7.000
7,98.438,19.04,5.7632,5.76328,7.000
7,98.562,15.01,5.6383,5.63835,7.000
7,98.688,11.92,5.5132,5.51328,7.000
7,98.812,9.49,5.3880,5.38805,7.000
7,98.938,7.61,5.2631,5.26320,7.000
7,99.062,6.11,5.1382,5.13825,7.000
7,99.188,4.91,5.0131,5.01320,7.000
7,99.312,3.93,4.8881,4.88823,7.000
7,99.438,3.13,4.7631,4.76320,7.000
7,99.562,2.46,4.6380,4.63810,7.000
7,99.688,1.89,4.5130,4.51305,7.000
7,99.812,1.42,4.3879,4.38803,7.000
7,99.938,1.04,4.2630,4.26310,7.000
7,100.062,0.72,4.1379,4.13795,7.000
7,100.188,0.46,4.0129,4.01303,7.000
7,100.312,0.26,3.8880,3.88810,7.000
7,100.438,0.12,3.7631,3.76318,7.000
7,100.562,0.04,3.6381,3.63815,7.000
7,100.688,0.01,3.5129,3.51300,7.000
7,100.812,0.00,3.3879,3.38800,7.000
7,100.938,0.00,3.2628,3.26290,7.000
7,101.062,-0.01,3.1379,3.13803,7.000
7,101.188,0.00,3.0130,3.01310,7.000
7,101.312,-0.01,2.8878,2.88793,7.000
7,101.438,0.00,2.7629,2.76300,7.000
7,101.562,0.00,2.6380,2.63805,7.000
7,101.688,0.00,2.5128,2.51288,7.000
7,101.812,0.00,2.3878,2.38790,7.000
7,101.938,-0.01,2.2628,2.26290,7.000
7,102.062,-0.01,2.1377,2.13778,7.000
7,102.188,0.00,2.0127,2.01283,7.000
7,102.312,0.00,1.8878,1.88788,7.000
7,102.438,-0.01,1.7628,1.76290,7.000
7,102.562,0.00,1.6381,1.63815,7.000
7,102.688,0.00,1.5128,1.51288,7.000
7,102.812,0.00,1.3879,1.38798,7.000
7,102.938,-0.01,1.2627,1.26278,7.000
7,103.062,-0.01,1.1377,1.13783,7.000
7,103.188,0.00,1.0128,1.01290,7.000
7,103.312,0.00,0.8878,0.88790,7.000
7,103.438,-0.01,0.7628,0.76295,7.000
7,103.562,-0.01,0.6379,0.63798,7.000
7,103.688,-0.01,0.5128,0.51287,7.000
7,103.812,0.00,0.3878,0.38785,7.000
7,103.938,-0.01,0.2626,0.26275,7.000
7,104.062,0.00,0.1376,0.13770,7.000
7,104.188,-0.01,0.0126,0.01268,7.000
7,104.375,-0.01,-0.0004,-0.00025,7.000
7,104.500,0.00,-0.0003,-0.00020,7.000
7,104.625,0.00,-0.0003,-0.00020,7.000
7,104.750,0.00,-0.0003,-0.00020,7.000
7,104.875,-0.01,-0.0003,-0.00020,7.000
7,105.000,0.00,-0.0003,-0.00020,7.000
7,105.125,0.00,-0.0003,-0.00020,7.000
7,105.250,0.00,-0.0003,-0.00020,7.000
7,105.375,0.00,-0.0003,-0.00020,7.000
7,105.500,-0.01,-0.0003,-0.00020,7.000
7,105.625,0.00,-0.0003,-0.00020,7.000
7,105.750,0.00,-0.0003,-0.00020,7.000
7,105.875,0.00,-0.0003,-0.00020,7.000
7,106.000,0.00,-0.0003,-0.00020,7.000
7,106.125,0.00,-0.0003,-0.00020,7.000
7,106.250,0.00,-0.0002,-0.00010,7.000
7,106.375,0.00,-0.0002,-0.00010,7.000
7,106.500,0.00,-0.0002,-0.00010,7.000
7,106.625,0.00,-0.0002,-0.00010,7.000
7,106.750,0.00,-0.0002,-0.00010,7.000
7,106.875,0.00,-0.0002,-0.00010,7.000
7,107.000,0.00,-0.0002,-0.00010,7.000
7,107.125,0.00,-0.0002,-0.00010,7.000
7,107.250,0.00,-0.0002,-0.00010,7.000
8,107.625,0.00,0.1545,0.15460,8.000
8,107.750,0.00,0.2797,0.27980,8.000
8,107.875,0.00,0.4046,0.40465,8.000
8,108.000,0.00,0.5296,0.52970,8.000
8,108.125,0.00,0.6546,0.65470,8.000
8,108.250,0.00,0.7794,0.77950,8.000
8,108.375,0.00,0.9045,0.90460,8.000
8,108.500,0.00,1.0296,1.02970,8.000
8,108.625,0.00,1.1546,1.15470,8.000
8,108.750,0.00,1.2797,1.27980,8.000
8,108.875,0.00,1.4048,1.40485,8.000
8,109.000,0.00,1.5297,1.52980,8.000
8,109.125,0.00,1.6548,1.65490,8.000
8,109.250,0.00,1.7795,1.77960,8.000
8,109.375,0.00,1.9046,1.90470,8.000
8,109.500,0.01,2.0297,2.02980,8.000
8,109.625,0.00,2.1547,2.15480,8.000
8,109.750,0.00,2.2798,2.27990,8.000
8,109.875,0.00,2.4048,2.40490,8.000
8,110.000,0.00,2.5298,2.52990,8.000
8,110.125,0.00,2.6547,2.65480,8.000
8,110.250,0.00,2.7798,2.77990,8.000
8,110.375,0.00,2.9048,2.90485,8.000
8,110.500,0.00,3.0296,3.02970,8.000
8,110.625,0.01,3.1548,3.15490,8.000
8,110.750,0.03,3.2798,3.27990,8.000
8,110.875,0.05,3.4048,3.40490,8.000
8,111.000,0.10,3.5299,3.53000,8.000
8,111.125,0.21,3.6549,3.65500,8.000
8,111.250,0.39,3.7799,3.78000,8.000
8,111.375,0.65,3.9047,3.90480,8.000
8,111.500,1.01,4.0298,4.02990,8.000
8,111.625,1.49,4.1547,4.15480,8.000
8,111.750,2.09,4.2799,4.28000,8.000
8,111.875,2.82,4.4049,4.40495,8.000
8,112.000,3.71,4.5298,4.52990,8.000
8,112.125,4.77,4.6548,4.65490,8.000
8,112.250,6.01,4.7798,4.77990,8.000
8,112.375,7.45,4.9048,4.90490,8.000
8,112.500,9.10,5.0298,5.02990,8.000
8,112.625,10.99,5.1548,5.15495,8.000
8,112.750,13.12,5.2799,5.28000,8.000
8,112.875,15.50,5.4048,5.40490,8.000
8,113.000,18.17,5.5301,5.53020,8.000
8,113.125,21.17,5.6550,5.65505,8.000
8,113.250,24.53,5.7797,5.77980,8.000
8,113.375,28.38,5.9048,5.90485,8.000
8,113.562,29.35,5.9682,5.96825,8.000
8,113.688,22.32,5.8431,5.84320,8.000
8,113.812,17.47,5.7181,5.71818,8.000
8,113.938,13.82,5.5932,5.59325,8.000
8,114.062,11.00,5.4681,5.46820,8.000
8,114.188,8.78,5.3430,5.34315,8.000
8,114.312,7.03,5.2182,5.21830,8.000
8,114.438,5.65,5.0932,5.09328,8.000
8,114.562,4.54,4.9681,4.96823,8.000
8,114.688,3.63,4.8430,4.84315,8.000
8,114.812,2.88,4.7180,4.71813,8.000
8,114.938,2.25,4.5929,4.59302,8.000
8,115.062,1.72,4.4680,4.46805,8.000
8,115.188,1.28,4.3430,4.34315,8.000
8,115.312,0.92,4.2180,4.21810,8.000
8,115.438,0.62,4.0929,4.09302,8.000
8,115.562,0.39,3.9680,3.96810,8.000
8,115.688,0.21,3.8430,3.84310,8.000
8,115.812,0.09,3.7180,3.71808,8.000
8,115.938,0.02,3.5930,3.59305,8.000
8,116.062,0.01,3.4678,3.46793,8.000
8,116.188,0.00,3.3429,3.34298,8.000
8,116.312,0.00,3.2179,3.21795,8.000
8,116.438,0.00,3.0930,3.09308,8.000
8,116.562,0.00,2.9679,2.96798,8.000
8,116.688,0.00,2.8430,2.84305,8.000
8,116.812,0.00,2.7180,2.71805,8.000
8,116.938,0.00,2.5928,2.59288,8.000
8,117.062,0.00,2.4678,2.46785,8.000
8,117.188,0.00,2.3428,2.34285,8.000
8,117.312,0.00,2.2178,2.21790,8.000
8,117.438,0.00,2.0928,2.09288,8.000
8,117.562,0.00,1.9678,1.96793,8.000
8,117.688,0.00,1.8428,1.84290,8.000
8,117.812,0.00,1.7178,1.71790,8.000
8,117.938,0.00,1.5929,1.59303,8.000
8,118.062,0.00,1.4678,1.46793,8.000
8,118.188,0.00,1.3428,1.34285,8.000
8,118.312,0.00,1.2177,1.21783,8.000
8,118.438,0.00,1.0929,1.09295,8.000
8,118.562,0.00,0.9677,0.96783,8.000
8,118.688,0.00,0.8428,0.84288,8.000
8,118.812,0.00,0.7179,0.71798,8.000
8,118.938,0.00,0.5928,0.59292,8.000
8,119.062,0.01,0.4678,0.46785,8.000
8,119.188,0.00,0.3426,0.34275,8.000
8,119.312,0.00,0.2176,0.21773,8.000
8,119.438,0.00,0.0926,0.09268,8.000
8,119.688,0.00,-0.0054,-0.00530,8.000
8,119.812,0.00,-0.0003,-0.00020,8.000
8,119.938,0.00,-0.0003,-0.00020,8.000
8,120.062,0.00,-0.0003,-0.00020,8.000
8,120.188,0.00,-0.0003,-0.00020,8.000
8,120.312,0.00,-0.0003,-0.00020,8.000
8,120.438,0.00,-0.0003,-0.00020,8.000
8,120.562,0.00,-0.0003,-0.00020,8.000
8,120.688,0.00,-0.0003,-0.00020,8.000
8,120.812,0.00,-0.0003,-0.00020,8.000
8,120.938,0.00,-0.0003,-0.00020,8.000
8,121.062,0.01,-0.0003,-0.00020,8.000
8,121.188,0.00,-0.0003,-0.00020,8.000
8,121.312,0.00,-0.0003,-0.00020,8.000
8,121.438,0.00,-0.0003,-0.00020,8.000
8,121.562,0.00,-0.0002,-0.00010,8.000
8,121.688,0.00,-0.0002,-0.00010,8.000
8,121.812,0.00,-0.0002,-0.00010,8.000
8,121.938,0.00,-0.0002,-0.00010,8.000
8,122.062,0.00,-0.0002,-0.00010,8.000
8,122.188,0.00,-0.0002,-0.00010,8.000
8,122.312,0.00,-0.0002,-0.00010,8.000
8,122.438,0.00,-0.0002,-0.00010,8.000
8,122.562,0.00,-0.0002,-0.00010,8.000
9,122.875,0.00,0.0644,0.06450,9.000
9,123.000,0.00,0.1895,0.18960,9.000
9,123.125,0.00,0.3146,0.31470,9.000
9,123.250,0.00,0.4395,0.43960,9.000
9,123.375,-0.01,0.5646,0.56475,9.000
9,123.500,0.00,0.6897,0.68980,9.000
9,123.625,0.00,0.8146,0.81470,9.000
9,123.750,-0.01,0.9396,0.93970,9.000
9,123.875,0.00,1.0646,1.06470,9.000
9,124.000,0.00,1.1896,1.18970,9.000
9,124.125,0.00,1.3147,1.31480,9.000
9,124.250,0.00,1.4398,1.43990,9.000
9,124.375,0.00,1.5648,1.56490,9.000
9,124.500,-0.01,1.6898,1.68990,9.000
9,124.625,-0.01,1.8146,1.81470,9.000
9,124.750,0.00,1.9396,1.93970,9.000
9,124.875,0.00,2.0646,2.06475,9.000
9,125.000,0.00,2.1896,2.18970,9.000
9,125.125,0.00,2.3147,2.31485,9.000
9,125.250,-0.01,2.4396,2.43970,9.000
9,125.375,0.00,2.5647,2.56485,9.000
9,125.500,-0.01,2.6898,2.68990,9.000
9,125.625,-0.01,2.8147,2.81485,9.000
9,125.750,-0.01,2.9396,2.93970,9.000
9,125.875,0.00,3.0647,3.06485,9.000
9,126.000,0.02,3.1897,3.18980,9.000
9,126.125,0.02,3.3147,3.31480,9.000
9,126.250,0.06,3.4398,3.43990,9.000
9,126.375,0.12,3.5649,3.56500,9.000
9,126.500,0.25,3.6899,3.69000,9.000
9,126.625,0.45,3.8148,3.81495,9.000
9,126.750,0.73,3.9397,3.93980,9.000
9,126.875,1.12,4.0647,4.06480,9.000
9,127.000,1.63,4.1897,4.18980,9.000
9,127.125,2.27,4.3148,4.31495,9.000
9,127.250,3.05,4.4399,4.44000,9.000
9,127.375,3.98,4.5648,4.56495,9.000
9,127.500,5.09,4.6899,4.69000,9.000
9,127.625,6.38,4.8148,4.81490,9.000
9,127.750,7.89,4.9399,4.94000,9.000
9,127.875,9.60,5.0648,5.06490,9.000
9,128.000,11.56,5.1898,5.18990,9.000
9,128.125,13.76,5.3148,5.31485,9.000
9,128.250,16.23,5.4398,5.43990,9.000
9,128.375,18.97,5.5650,5.56505,9.000
9,128.500,22.06,5.6900,5.69010,9.000
9,128.625,25.56,5.8148,5.81490,9.000
9,128.750,29.54,5.9398,5.93990,9.000
9,128.938,26.99,5.9332,5.93325,9.000
9,129.062,20.80,5.8080,5.80812,9.000
9,129.188,16.35,5.6832,5.68330,9.000
9,129.312,12.95,5.5582,5.55832,9.000
9,129.438,10.31,5.4330,5.43312,9.000
9,129.562,8.24,5.3080,5.30812,9.000
9,129.688,6.62,5.1831,5.18325,9.000
9,129.812,5.31,5.0581,5.05822,9.000
9,129.938,4.26,4.9332,4.93328,9.000
9,130.062,3.40,4.8080,4.80812,9.000
9,130.188,2.68,4.6830,4.68312,9.000
9,130.312,2.08,4.5580,4.55815,9.000
9,130.438,1.58,4.4329,4.43298,9.000
9,130.562,1.16,4.3080,4.30805,9.000
9,130.688,0.82,4.1829,4.18303,9.000
9,130.812,0.54,4.0579,4.05800,9.000
9,130.938,0.33,3.9330,3.93313,9.000
9,131.062,0.17,3.8080,3.80805,9.000
9,131.188,0.06,3.6831,3.68320,9.000
9,131.312,0.01,3.5580,3.55808,9.000
9,131.438,0.00,3.4328,3.43288,9.000
9,131.562,-0.01,3.3078,3.30790,9.000
9,131.688,-0.01,3.1828,3.18290,9.000
9,131.812,-0.01,3.0580,3.05810,9.000
9,131.938,0.00,2.9329,2.93300,9.000
9,132.062,-0.01,2.8079,2.80802,9.000
9,132.188,-0.01,2.6829,2.68300,9.000
9,132.312,0.00,2.5579,2.55795,9.000
9,132.438,-0.01,2.4328,2.43285,9.000
9,132.562,-0.01,2.3078,2.30793,9.000
9,132.688,-0.01,2.1826,2.18275,9.000
9,132.812,0.00,2.0578,2.05785,9.000
9,132.938,-0.01,1.9328,1.93285,9.000
9,133.062,-0.01,1.8077,1.80782,9.000
9,133.188,-0.01,1.6830,1.68310,9.000
9,133.312,-0.01,1.5579,1.55798,9.000
9,133.438,-0.01,1.4328,1.43293,9.000
9,133.562,0.00,1.3077,1.30780,9.000
9,133.688,-0.01,1.1826,1.18273,9.000
9,133.812,-0.01,1.0578,1.05785,9.000
9,133.938,-0.02,0.9327,0.93282,9.000
9,134.062,-0.01,0.8078,0.80792,9.000
9,134.188,-0.01,0.6828,0.68290,9.000
9,134.312,-0.01,0.5578,0.55790,9.000
9,134.438,-0.01,0.4327,0.43282,9.000
9,134.562,0.00,0.3077,0.30780,9.000
9,134.688,-0.01,0.1826,0.18272,9.000
9,134.812,0.00,0.0575,0.05763,9.000
9,135.000,0.00,-0.0106,-0.01050,9.000
9,135.125,0.00,-0.0003,-0.00020,9.000
9,135.250,0.00,-0.0003,-0.00020,9.000
9,135.375,-0.01,-0.0003,-0.00020,9.000
9,135.500,0.00,-0.0003,-0.00020,9.000
9,135.625,0.00,-0.0003,-0.00020,9.000
9,135.750,0.00,-0.0003,-0.00020,9.000
9,135.875,-0.01,-0.0003,-0.00020,9.000
9,136.000,-0.01,-0.0003,-0.00020,9.000
9,136.125,0.00,-0.0003,-0.00020,9.000
9,136.250,-0.01,-0.0003,-0.00020,9.000
9,136.375,0.00,-0.0002,-0.00015,9.000
9,136.500,0.00,-0.0002,-0.00010,9.000
9,136.625,0.00,-0.0002,-0.00010,9.000
9,136.750,-0.01,-0.0002,-0.00010,9.000
9,136.875,0.00,-0.0002,-0.00010,9.000
9,137.000,-0.01,-0.0002,-0.00010,9.000
9,137.125,0.00,-0.0002,-0.00010,9.000
9,137.250,0.00,-0.0002,-0.00010,9.000
9,137.375,-0.01,-0.0002,-0.00010,9.000
9,137.500,0.00,-0.0002,-0.00010,9.000
9,137.625,0.00,-0.0002,-0.00010,9.000
9,137.750,0.00,-0.0002,-0.00010,9.000
9,137.875,0.00,-0.0002,-0.00010,9.000
10,138.188,0.01,0.0471,0.04715,10.000
10,138.312,0.00,0.1720,0.17212,10.000
10,138.438,0.00,0.2970,0.29708,10.000
10,138.562,0.01,0.4219,0.42200,10.000
10,138.688,0.01,0.5470,0.54710,10.000
10,138.812,0.01,0.6722,0.67228,10.000
10,138.938,0.01,0.7972,0.79728,10.000
10,139.062,0.01,0.9220,0.92215,10.000
10,139.188,0.00,1.0473,1.04738,10.000
10,139.312,0.01,1.1721,1.17220,10.000
10,139.438,0.01,1.2972,1.29725,10.000
10,139.562,0.00,1.4222,1.42228,10.000
10,139.688,0.01,1.5471,1.54720,10.000
10,139.812,0.00,1.6723,1.67235,10.000
10,139.938,0.00,1.7972,1.79728,10.000
10,140.062,0.00,1.9222,1.92232,10.000
10,140.188,0.00,2.0473,2.04738,10.000
10,140.312,0.00,2.1722,2.17233,10.000
10,140.438,0.00,2.2972,2.29735,10.000
10,140.562,0.00,2.4221,2.42220,10.000
10,140.688,0.01,2.5472,2.54728,10.000
10,140.812,0.00,2.6722,2.67230,10.000
10,140.938,0.00,2.7972,2.79735,10.000
10,141.062,0.00,2.9223,2.92240,10.000
10,141.188,0.00,3.0474,3.04748,10.000
10,141.312,0.01,3.1724,3.17248,10.000
10,141.438,0.03,3.2973,3.29740,10.000
10,141.562,0.06,3.4222,3.42230,10.000
10,141.688,0.12,3.5473,3.54740,10.000
10,141.812,0.23,3.6723,3.67243,10.000
10,141.938,0.42,3.7972,3.79733,10.000
10,142.062,0.69,3.9223,3.92240,10.000
10,142.188,1.07,4.0474,4.04745,10.000
10,142.312,1.56,4.1723,4.17240,10.000
10,142.438,2.18,4.2973,4.29743,10.000
10,142.562,2.93,4.4224,4.42245,10.000
10,142.688,3.84,4.5473,4.54740,10.000
10,142.812,4.93,4.6722,4.67230,10.000
10,142.938,6.20,4.7973,4.79738,10.000
10,143.062,7.66,4.9224,4.92248,10.000
10,143.188,9.34,5.0474,5.04745,10.000
10,143.312,11.27,5.1724,5.17250,10.000
10,143.438,13.44,5.2974,5.29748,10.000
10,143.562,15.87,5.4223,5.42240,10.000
10,143.688,18.58,5.5474,5.54745,10.000
10,143.812,21.62,5.6722,5.67235,10.000
10,143.938,25.05,5.7972,5.79730,10.000
10,144.062,28.95,5.9223,5.92243,10.000
10,144.250,27.14,5.9306,5.93070,10.000
10,144.375,20.89,5.8056,5.80570,10.000
10,144.500,16.41,5.6806,5.68070,10.000
10,144.625,13.00,5.5557,5.55580,10.000
10,144.750,10.34,5.4305,5.43060,10.000
10,144.875,8.27,5.3056,5.30570,10.000
10,145.000,6.63,5.1808,5.18090,10.000
10,145.125,5.31,5.0556,5.05575,10.000
10,145.250,4.27,4.9306,4.93070,10.000
10,145.375,3.40,4.8056,4.80565,10.000
10,145.500,2.68,4.6805,4.68060,10.000
10,145.625,2.08,4.5555,4.55560,10.000
10,145.750,1.58,4.4305,4.43060,10.000
10,145.875,1.17,4.3055,4.30560,10.000
10,146.000,0.82,4.1805,4.18060,10.000
10,146.125,0.55,4.0555,4.05555,10.000
10,146.250,0.33,3.9306,3.93070,10.000
10,146.375,0.17,3.8055,3.80560,10.000
10,146.500,0.06,3.6806,3.68070,10.000
10,146.625,0.02,3.5554,3.55555,10.000
10,146.750,0.01,3.4303,3.43040,10.000
10,146.875,0.00,3.3053,3.30540,10.000
10,147.000,0.00,3.1804,3.18050,10.000
10,147.125,0.00,3.0555,3.05560,10.000
10,147.250,0.00,2.9305,2.93060,10.000
10,147.375,0.01,2.8054,2.80550,10.000
10,147.500,0.00,2.6804,2.68050,10.000
10,147.625,0.00,2.5553,2.55540,10.000
10,147.750,0.00,2.4302,2.43030,10.000
10,147.875,0.00,2.3053,2.30540,10.000
10,148.000,0.01,2.1802,2.18030,10.000
10,148.125,0.00,2.0553,2.05540,10.000
10,148.250,0.00,1.9303,1.93040,10.000
10,148.375,0.00,1.8053,1.80540,10.000
10,148.500,0.01,1.6805,1.68060,10.000
10,148.625,0.00,1.5553,1.55540,10.000
10,148.750,0.00,1.4303,1.43040,10.000
10,148.875,0.00,1.3053,1.30540,10.000
10,149.000,0.01,1.1803,1.18040,10.000
10,149.125,0.00,1.0553,1.05540,10.000
10,149.250,0.01,0.9302,0.93030,10.000
10,149.375,0.01,0.8054,0.80545,10.000
10,149.500,0.00,0.6804,0.68050,10.000
10,149.625,0.00,0.5552,0.55535,10.000
10,149.750,0.00,0.4303,0.43040,10.000
10,149.875,0.00,0.3052,0.30525,10.000
10,150.000,0.01,0.1800,0.18010,10.000
10,150.125,0.01,0.0550,0.05515,10.000
10,150.312,0.00,-0.0091,-0.00895,10.000
10,150.438,0.00,-0.0003,-0.00020,10.000
10,150.562,0.00,-0.0003,-0.00020,10.000
10,150.688,0.00,-0.0003,-0.00020,10.000
10,150.812,0.00,-0.0003,-0.00020,10.000
10,150.938,0.00,-0.0003,-0.00020,10.000
10,151.062,0.00,-0.0003,-0.00020,10.000
10,151.188,0.01,-0.0003,-0.00020,10.000
10,151.312,0.01,-0.0003,-0.00020,10.000
10,151.438,0.01,-0.0003,-0.00020,10.000
10,151.562,0.00,-0.0003,-0.00020,10.000
10,151.688,0.01,-0.0002,-0.00010,10.000
10,151.812,0.00,-0.0002,-0.00010,10.000
10,151.938,0.01,-0.0002,-0.00010,10.000
10,152.062,0.01,-0.0002,-0.00010,10.000
10,152.188,0.00,-0.0002,-0.00010,10.000
10,152.312,0.01,-0.0002,-0.00010,10.000
10,152.438,0.00,-0.0002,-0.00010,10.000
10,152.562,0.00,-0.0002,-0.00010,10.000
10,152.688,0.01,-0.0002,-0.00010,10.000
10,152.812,0.01,-0.0002,-0.00010,10.000
10,152.938,0.01,-0.0002,-0.00010,10.000
10,153.062,0.00,-0.0002,-0.00010,10.000
10,153.188,0.01,-0.0002,-0.00010,10.000
10,153.250,0.00,-0.0002,-0.00010,10.000