File: AIME_journal_files/AIME_data/calibDATA_loadcell/date_02:22:2018/Instron/30N_0_1_4_0.txt
""
"Test Method","Radhen_Load_Cntrl_Cmprsn_250N_12-7.msm"
"Sample I. D.","Sample1.mss"
"Specimen Number","18"

"TheCycle_Output ()","_Time (s)","_Load (N)","_Extension (mm)","RealTimeDepth (mm)","CycleNumber ()"

1,0.312,0.00,0.0941,0.09408,1.000
1,0.438,0.01,0.2193,0.21932,1.000
1,0.562,0.01,0.3442,0.34425,1.000
1,0.688,0.00,0.4692,0.46920,1.000
1,0.812,0.01,0.5942,0.59418,1.000
1,0.938,0.01,0.7192,0.71920,1.000
1,1.062,0.00,0.8443,0.84432,1.000
1,1.188,0.01,0.9694,0.96940,1.000
1,1.312,0.01,1.0943,1.09432,1.000
1,1.438,0.01,1.2194,1.21942,1.000
1,1.562,0.01,1.3444,1.34435,1.000
1,1.688,0.00,1.4693,1.46930,1.000
1,1.812,0.00,1.5942,1.59415,1.000
1,1.938,0.00,1.7193,1.71928,1.000
1,2.062,0.00,1.8444,1.84440,1.000
1,2.188,0.03,1.9694,1.96937,1.000
1,2.312,0.05,2.0944,2.09440,1.000
1,2.438,0.09,2.2194,2.21938,1.000
1,2.562,0.16,2.3444,2.34442,1.000
1,2.688,0.27,2.4693,2.46932,1.000
1,2.812,0.47,2.5942,2.59422,1.000
1,2.938,0.75,2.7194,2.71940,1.000
1,3.062,1.14,2.8443,2.84432,1.000
1,3.188,1.63,2.9694,2.96940,1.000
1,3.312,2.25,3.0944,3.09442,1.000
1,3.438,3.01,3.2194,3.21942,1.000
1,3.562,3.94,3.3445,3.34453,1.000
1,3.688,5.06,3.4694,3.46940,1.000
1,3.812,6.36,3.5943,3.59432,1.000
1,3.938,7.90,3.7193,3.71930,1.000
1,4.062,9.68,3.8443,3.84432,1.000
1,4.188,11.72,3.9694,3.96945,1.000
1,4.312,14.00,4.0944,4.09442,1.000
1,4.438,16.59,4.2194,4.21940,1.000
1,4.562,19.52,4.3444,4.34437,1.000
1,4.688,22.80,4.4693,4.46930,1.000
1,4.812,26.52,4.5943,4.59430,1.000
1,5.062,27.72,4.6801,4.68008,1.000
1,5.188,21.36,4.5551,4.55510,1.000
1,5.312,16.80,4.4301,4.43005,1.000
1,5.438,13.29,4.3052,4.30518,1.000
1,5.562,10.58,4.1802,4.18020,1.000
1,5.688,8.42,4.0552,4.05520,1.000
1,5.812,6.69,3.9301,3.93010,1.000
1,5.938,5.31,3.8050,3.80500,1.000
1,6.062,4.22,3.6799,3.67993,1.000
1,6.188,3.33,3.5549,3.55490,1.000
1,6.312,2.60,3.4301,3.43010,1.000
1,6.438,2.02,3.3052,3.30515,1.000
1,6.562,1.53,3.1801,3.18010,1.000
1,6.688,1.13,3.0552,3.05515,1.000
1,6.812,0.80,2.9300,2.93000,1.000
1,6.938,0.53,2.8050,2.80495,1.000
1,7.062,0.32,2.6800,2.68000,1.000
1,7.188,0.17,2.5548,2.55483,1.000
1,7.312,0.09,2.4300,2.43000,1.000
1,7.438,0.05,2.3049,2.30490,1.000
1,7.562,0.02,2.1800,2.17995,1.000
1,7.688,0.01,2.0550,2.05505,1.000
1,7.812,0.01,1.9300,1.92998,1.000
1,7.938,0.00,1.8049,1.80493,1.000
1,8.062,0.00,1.6799,1.67988,1.000
1,8.188,0.00,1.5548,1.55482,1.000
1,8.312,0.00,1.4298,1.42983,1.000
1,8.438,0.00,1.3049,1.30490,1.000
1,8.562,0.00,1.1800,1.18000,1.000
1,8.688,0.01,1.0550,1.05497,1.000
1,8.812,0.00,0.9299,0.92993,1.000
1,8.938,0.00,0.8049,0.80492,1.000
1,9.062,0.00,0.6799,0.67985,1.000
1,9.188,0.00,0.5547,0.55472,1.000
1,9.312,0.00,0.4297,0.42973,1.000
1,9.438,0.00,0.3048,0.30485,1.000
1,9.562,0.00,0.1799,0.17990,1.000
1,9.688,0.00,0.0546,0.05462,1.000
1,9.875,0.00,-0.0065,-0.00650,1.000
1,10.000,0.01,-0.0003,-0.00030,1.000
1,10.125,0.01,-0.0002,-0.00020,1.000
1,10.250,0.00,-0.0002,-0.00020,1.000
1,10.375,0.00,-0.0002,-0.00020,1.000
1,10.500,0.00,-0.0002,-0.00020,1.000
1,10.625,0.01,-0.0002,-0.00020,1.000
1,10.750,0.00,-0.0002,-0.00020,1.000
1,10.875,0.00,-0.0002,-0.00020,1.000
1,11.000,0.00,-0.0002,-0.00020,1.000
1,11.125,0.01,-0.0002,-0.00020,1.000
1,11.250,0.00,-0.0002,-0.00020,1.000
1,11.375,0.00,-0.0002,-0.00020,1.000
1,11.500,0.01,-0.0002,-0.00020,1.000
1,11.625,0.01,-0.0002,-0.00020,1.000
1,11.750,0.00,-0.0002,-0.00020,1.000
1,11.875,0.00,-0.0002,-0.00020,1.000
1,12.000,0.01,-0.0002,-0.00020,1.000
1,12.125,0.00,-0.0002,-0.00020,1.000
1,12.250,0.01,-0.0002,-0.00020,1.000
1,12.375,0.00,-0.0002,-0.00020,1.000
1,12.500,0.00,-0.0002,-0.00020,1.000
1,12.625,0.00,-0.0002,-0.00020,1.000
1,12.750,0.00,-0.0002,-0.00020,1.000
2,13.125,0.01,0.0965,0.09660,2.000
2,13.250,0.01,0.2217,0.22180,2.000
2,13.375,0.00,0.3466,0.34670,2.000
2,13.500,0.01,0.4716,0.47170,2.000
2,13.625,0.01,0.5965,0.59665,2.000
2,13.750,0.00,0.7216,0.72170,2.000
2,13.875,0.01,0.8467,0.84685,2.000
2,14.000,0.01,0.9718,0.97190,2.000
2,14.125,0.01,1.0967,1.09685,2.000
2,14.250,0.01,1.2218,1.22190,2.000
2,14.375,0.00,1.3466,1.34675,2.000
2,14.500,0.01,1.4716,1.47170,2.000
2,14.625,0.01,1.5966,1.59675,2.000
2,14.750,0.00,1.7217,1.72180,2.000
2,14.875,0.01,1.8468,1.84690,2.000
2,15.000,0.02,1.9719,1.97200,2.000
2,15.125,0.05,2.0967,2.09685,2.000
2,15.250,0.09,2.2218,2.22190,2.000
2,15.375,0.15,2.3467,2.34685,2.000
2,15.500,0.25,2.4717,2.47180,2.000
2,15.625,0.45,2.5966,2.59675,2.000
2,15.750,0.72,2.7218,2.72190,2.000
2,15.875,1.10,2.8467,2.84680,2.000
2,16.000,1.59,2.9718,2.97190,2.000
2,16.125,2.20,3.0969,3.09700,2.000
2,16.250,2.97,3.2219,3.22200,2.000
2,16.375,3.91,3.3469,3.34700,2.000
2,16.500,5.02,3.4717,3.47180,2.000
2,16.625,6.34,3.5967,3.59680,2.000
2,16.750,7.88,3.7217,3.72180,2.000
2,16.875,9.69,3.8467,3.84680,2.000
2,17.000,11.73,3.9718,3.97190,2.000
2,17.125,14.04,4.0968,4.09695,2.000
2,17.250,16.64,4.2218,4.22190,2.000
2,17.375,19.60,4.3468,4.34695,2.000
2,17.500,22.92,4.4717,4.47180,2.000
2,17.625,26.69,4.5968,4.59685,2.000
2,17.750,30.99,4.7217,4.72180,2.000
2,17.938,25.01,4.6351,4.63518,2.000
2,18.062,19.50,4.5100,4.51012,2.000
2,18.188,15.39,4.3852,4.38528,2.000
2,18.312,12.21,4.2601,4.26020,2.000
2,18.438,9.72,4.1352,4.13528,2.000
2,18.562,7.74,4.0101,4.01025,2.000
2,18.688,6.14,3.8850,3.88513,2.000
2,18.812,4.87,3.7598,3.75995,2.000
2,18.938,3.85,3.6350,3.63508,2.000
2,19.062,3.03,3.5099,3.50997,2.000
2,19.188,2.37,3.3851,3.38518,2.000
2,19.312,1.83,3.2601,3.26017,2.000
2,19.438,1.37,3.1351,3.13520,2.000
2,19.562,1.01,3.0100,3.01007,2.000
2,19.688,0.69,2.8849,2.88498,2.000
2,19.812,0.44,2.7600,2.76012,2.000
2,19.938,0.26,2.6349,2.63500,2.000
2,20.062,0.14,2.5098,2.50987,2.000
2,20.188,0.08,2.3850,2.38505,2.000
2,20.312,0.04,2.2599,2.26002,2.000
2,20.438,0.02,2.1350,2.13508,2.000
2,20.562,0.02,2.0099,2.00997,2.000
2,20.688,0.01,1.8849,1.88495,2.000
2,20.812,0.01,1.7598,1.75990,2.000
2,20.938,0.01,1.6348,1.63490,2.000
2,21.062,0.01,1.5097,1.50985,2.000
2,21.188,0.01,1.3849,1.38495,2.000
2,21.312,0.01,1.2599,1.26000,2.000
2,21.438,0.00,1.1349,1.13500,2.000
2,21.562,0.01,1.0099,1.01000,2.000
2,21.688,0.01,0.8848,0.88493,2.000
2,21.812,0.01,0.7598,0.75995,2.000
2,21.938,0.01,0.6347,0.63483,2.000
2,22.062,0.01,0.5097,0.50977,2.000
2,22.188,0.01,0.3848,0.38493,2.000
2,22.312,0.01,0.2598,0.25995,2.000
2,22.438,0.01,0.1348,0.13490,2.000
2,22.562,0.00,0.0097,0.00980,2.000
2,22.750,0.00,0.0002,0.00030,2.000
2,22.875,0.01,-0.0003,-0.00020,2.000
2,23.000,0.00,-0.0003,-0.00020,2.000
2,23.125,0.01,-0.0003,-0.00020,2.000
2,23.250,0.00,-0.0003,-0.00020,2.000
2,23.375,0.01,-0.0003,-0.00020,2.000
2,23.500,0.01,-0.0003,-0.00020,2.000
2,23.625,0.01,-0.0003,-0.00020,2.000
2,23.750,0.01,-0.0003,-0.00020,2.000
2,23.875,0.01,-0.0003,-0.00020,2.000
2,24.000,0.00,-0.0003,-0.00020,2.000
2,24.125,0.01,-0.0003,-0.00020,2.000
2,24.250,0.01,-0.0003,-0.00020,2.000
2,24.375,0.01,-0.0003,-0.00020,2.000
2,24.500,0.01,-0.0003,-0.00020,2.000
2,24.625,0.00,-0.0003,-0.00020,2.000
2,24.750,0.01,-0.0003,-0.00020,2.000
2,24.875,0.01,-0.0003,-0.00020,2.000
2,25.000,0.01,-0.0003,-0.00020,2.000
2,25.125,0.00,-0.0002,-0.00010,2.000
2,25.250,0.01,-0.0002,-0.00010,2.000
2,25.375,0.01,-0.0002,-0.00010,2.000
2,25.500,0.01,-0.0002,-0.00010,2.000
2,25.625,0.01,-0.0002,-0.00010,2.000
3,26.000,0.00,0.1514,0.15150,3.000
3,26.125,0.00,0.2766,0.27675,3.000
3,26.250,0.00,0.4016,0.40170,3.000
3,26.375,0.00,0.5267,0.52675,3.000
3,26.500,0.01,0.6518,0.65190,3.000
3,26.625,0.00,0.7768,0.77685,3.000
3,26.750,0.00,0.9017,0.90180,3.000
3,26.875,0.00,1.0267,1.02680,3.000
3,27.000,0.00,1.1516,1.15170,3.000
3,27.125,0.00,1.2768,1.27685,3.000
3,27.250,0.00,1.4016,1.40170,3.000
3,27.375,0.00,1.5266,1.52675,3.000
3,27.500,0.00,1.6517,1.65180,3.000
3,27.625,0.00,1.7768,1.77690,3.000
3,27.750,0.01,1.9019,1.90200,3.000
3,27.875,0.03,2.0267,2.02685,3.000
3,28.000,0.06,2.1516,2.15170,3.000
3,28.125,0.10,2.2767,2.27685,3.000
3,28.250,0.18,2.4017,2.40180,3.000
3,28.375,0.32,2.5267,2.52685,3.000
3,28.500,0.54,2.6519,2.65200,3.000
3,28.625,0.86,2.7769,2.77700,3.000
3,28.750,1.29,2.9018,2.90190,3.000
3,28.875,1.83,3.0268,3.02695,3.000
3,29.000,2.51,3.1519,3.15200,3.000
3,29.125,3.34,3.2768,3.27690,3.000
3,29.250,4.35,3.4018,3.40190,3.000
3,29.375,5.54,3.5268,3.52685,3.000
3,29.500,6.95,3.6519,3.65200,3.000
3,29.625,8.61,3.7768,3.77690,3.000
3,29.750,10.52,3.9018,3.90190,3.000
3,29.875,12.69,4.0269,4.02700,3.000
3,30.000,15.11,4.1519,4.15200,3.000
3,30.125,17.87,4.2768,4.27685,3.000
3,30.250,20.97,4.4017,4.40180,3.000
3,30.375,24.46,4.5267,4.52680,3.000
3,30.500,28.45,4.6518,4.65190,3.000
3,30.688,29.13,4.7051,4.70515,3.000
3,30.812,22.32,4.5801,4.58023,3.000
3,30.938,17.53,4.4551,4.45518,3.000
3,31.062,13.86,4.3302,4.33025,3.000
3,31.188,11.03,4.2050,4.20505,3.000
3,31.312,8.79,4.0800,4.08008,3.000
3,31.438,6.99,3.9551,3.95515,3.000
3,31.562,5.54,3.8300,3.83005,3.000
3,31.688,4.40,3.7051,3.70518,3.000
3,31.812,3.47,3.5801,3.58020,3.000
3,31.938,2.72,3.4551,3.45518,3.000
3,32.062,2.12,3.3301,3.33015,3.000
3,32.188,1.61,3.2049,3.20505,3.000
3,32.312,1.20,3.0799,3.08003,3.000
3,32.438,0.86,2.9548,2.95492,3.000
3,32.562,0.56,2.8299,2.82998,3.000
3,32.688,0.34,2.7051,2.70517,3.000
3,32.812,0.19,2.5799,2.58003,3.000
3,32.938,0.10,2.4551,2.45517,3.000
3,33.062,0.05,2.3300,2.33005,3.000
3,33.188,0.03,2.2048,2.20492,3.000
3,33.312,0.02,2.0798,2.07990,3.000
3,33.438,0.00,1.9548,1.95492,3.000
3,33.562,0.00,1.8298,1.82988,3.000
3,33.688,0.00,1.7049,1.70497,3.000
3,33.812,0.00,1.5799,1.58000,3.000
3,33.938,0.00,1.4549,1.45497,3.000
3,34.062,0.00,1.3299,1.32998,3.000
3,34.188,0.00,1.2049,1.20502,3.000
3,34.312,0.00,1.0797,1.07983,3.000
3,34.438,0.00,0.9549,0.95497,3.000
3,34.562,0.00,0.8298,0.82990,3.000
3,34.688,0.00,0.7048,0.70490,3.000
3,34.812,0.00,0.5798,0.57993,3.000
3,34.938,0.00,0.4548,0.45492,3.000
3,35.062,0.00,0.3298,0.32990,3.000
3,35.188,0.00,0.2048,0.20495,3.000
3,35.312,0.00,0.0797,0.07975,3.000
3,35.500,0.00,-0.0285,-0.02840,3.000
3,35.625,0.00,-0.0003,-0.00020,3.000
3,35.750,0.00,-0.0003,-0.00020,3.000
3,35.875,0.00,-0.0003,-0.00020,3.000
3,36.000,0.00,-0.0003,-0.00020,3.000
3,36.125,0.01,-0.0003,-0.00020,3.000
3,36.250,0.01,-0.0003,-0.00020,3.000
3,36.375,0.00,-0.0003,-0.00020,3.000
3,36.500,0.01,-0.0003,-0.00020,3.000
3,36.625,0.00,-0.0003,-0.00020,3.000
3,36.750,0.00,-0.0003,-0.00020,3.000
3,36.875,0.00,-0.0003,-0.00020,3.000
3,37.000,0.00,-0.0003,-0.00020,3.000
3,37.125,0.01,-0.0003,-0.00020,3.000
3,37.250,0.00,-0.0003,-0.00020,3.000
3,37.375,0.00,-0.0002,-0.00010,3.000
3,37.500,0.00,-0.0002,-0.00010,3.000
3,37.625,0.00,-0.0002,-0.00010,3.000
3,37.750,0.00,-0.0002,-0.00010,3.000
3,37.875,0.00,-0.0002,-0.00010,3.000
3,38.000,0.00,-0.0002,-0.00010,3.000
3,38.125,0.00,-0.0002,-0.00010,3.000
3,38.250,0.00,-0.0002,-0.00010,3.000
3,38.375,0.00,-0.0002,-0.00010,3.000
4,38.750,-0.01,0.0584,0.05850,4.000
4,38.875,0.00,0.1836,0.18375,4.000
4,39.000,-0.01,0.3086,0.30870,4.000
4,39.125,0.00,0.4336,0.43370,4.000
4,39.250,0.00,0.5585,0.55860,4.000
4,39.375,-0.01,0.6837,0.68375,4.000
4,39.500,0.00,0.8087,0.80880,4.000
4,39.625,0.00,0.9338,0.93385,4.000
4,39.750,0.00,1.0589,1.05900,4.000
4,39.875,0.00,1.1838,1.18390,4.000
4,40.000,-0.01,1.3087,1.30880,4.000
4,40.125,-0.01,1.4336,1.43375,4.000
4,40.250,-0.01,1.5586,1.55870,4.000
4,40.375,-0.01,1.6837,1.68380,4.000
4,40.500,0.00,1.8087,1.80880,4.000
4,40.625,0.01,1.9338,1.93395,4.000
4,40.750,0.03,2.0589,2.05900,4.000
4,40.875,0.06,2.1838,2.18385,4.000
4,41.000,0.11,2.3087,2.30880,4.000
4,41.125,0.20,2.4338,2.43385,4.000
4,41.250,0.36,2.5586,2.55870,4.000
4,41.375,0.61,2.6838,2.68390,4.000
4,41.500,0.95,2.8088,2.80890,4.000
4,41.625,1.40,2.9339,2.93395,4.000
4,41.750,1.97,3.0589,3.05900,4.000
4,41.875,2.69,3.1839,3.18400,4.000
4,42.000,3.56,3.3089,3.30900,4.000
4,42.125,4.61,3.4338,3.43385,4.000
4,42.250,5.86,3.5587,3.55880,4.000
4,42.375,7.34,3.6838,3.68385,4.000
4,42.500,9.05,3.8087,3.80880,4.000
4,42.625,11.03,3.9338,3.93395,4.000
4,42.750,13.26,4.0589,4.05900,4.000
4,42.875,15.77,4.1839,4.18395,4.000
4,43.000,18.61,4.3089,4.30900,4.000
4,43.125,21.80,4.4338,4.43385,4.000
4,43.250,25.42,4.5587,4.55880,4.000
4,43.375,29.54,4.6838,4.68385,4.000
4,43.562,26.17,4.6532,4.65325,4.000
4,43.688,20.32,4.5280,4.52812,4.000
4,43.812,16.01,4.4030,4.40313,4.000
4,43.938,12.69,4.2780,4.27815,4.000
4,44.062,10.09,4.1531,4.15320,4.000
4,44.188,8.03,4.0282,4.02827,4.000
4,44.312,6.37,3.9031,3.90320,4.000
4,44.438,5.04,3.7781,3.77820,4.000
4,44.562,3.99,3.6531,3.65315,4.000
4,44.688,3.14,3.5280,3.52810,4.000
4,44.812,2.45,3.4030,3.40308,4.000
4,44.938,1.89,3.2779,3.27802,4.000
4,45.062,1.42,3.1530,3.15310,4.000
4,45.188,1.04,3.0280,3.02810,4.000
4,45.312,0.72,2.9030,2.90308,4.000
4,45.438,0.45,2.7781,2.77825,4.000
4,45.562,0.26,2.6530,2.65308,4.000
4,45.688,0.14,2.5278,2.52787,4.000
4,45.812,0.07,2.4029,2.40300,4.000
4,45.938,0.03,2.2778,2.27792,4.000
4,46.062,0.01,2.1528,2.15293,4.000
4,46.188,0.01,2.0278,2.02795,4.000
4,46.312,0.00,1.9029,1.90295,4.000
4,46.438,0.00,1.7779,1.77800,4.000
4,46.562,-0.01,1.6529,1.65300,4.000
4,46.688,-0.01,1.5278,1.52792,4.000
4,46.812,-0.01,1.4029,1.40295,4.000
4,46.938,0.00,1.2778,1.27792,4.000
4,47.062,-0.01,1.1528,1.15293,4.000
4,47.188,0.00,1.0278,1.02790,4.000
4,47.312,-0.01,0.9029,0.90295,4.000
4,47.438,0.00,0.7778,0.77792,4.000
4,47.562,-0.01,0.6528,0.65293,4.000
4,47.688,0.00,0.5278,0.52792,4.000
4,47.812,0.00,0.4028,0.40285,4.000
4,47.938,-0.01,0.2777,0.27782,4.000
4,48.062,0.00,0.1527,0.15275,4.000
4,48.188,0.00,0.0276,0.02775,4.000
4,48.375,-0.01,-0.0002,-0.00015,4.000
4,48.500,0.00,-0.0003,-0.00020,4.000
4,48.625,-0.01,-0.0003,-0.00020,4.000
4,48.750,0.00,-0.0003,-0.00020,4.000
4,48.875,-0.01,-0.0003,-0.00020,4.000
4,49.000,0.00,-0.0003,-0.00020,4.000
4,49.125,-0.01,-0.0003,-0.00020,4.000
4,49.250,0.00,-0.0003,-0.00020,4.000
4,49.375,-0.01,-0.0003,-0.00020,4.000
4,49.500,-0.01,-0.0003,-0.00020,4.000
4,49.625,-0.01,-0.0003,-0.00020,4.000
4,49.750,-0.01,-0.0003,-0.00020,4.000
4,49.875,0.00,-0.0003,-0.00020,4.000
4,50.000,-0.01,-0.0003,-0.00020,4.000
4,50.125,-0.01,-0.0003,-0.00020,4.000
4,50.250,0.00,-0.0003,-0.00020,4.000
4,50.375,0.00,-0.0003,-0.00020,4.000
4,50.500,-0.01,-0.0003,-0.00020,4.000
4,50.625,0.00,-0.0003,-0.00020,4.000
4,50.750,0.00,-0.0002,-0.00010,4.000
4,50.875,-0.01,-0.0002,-0.00010,4.000
4,51.000,-0.01,-0.0002,-0.00010,4.000
4,51.125,-0.01,-0.0002,-0.00010,4.000
4,51.250,-0.01,-0.0002,-0.00010,4.000
5,51.625,0.00,0.1465,0.14660,5.000
5,51.750,0.00,0.2716,0.27170,5.000
5,51.875,0.00,0.3966,0.39670,5.000
5,52.000,0.00,0.5216,0.52170,5.000
5,52.125,0.00,0.6467,0.64680,5.000
5,52.250,0.00,0.7718,0.77190,5.000
5,52.375,0.00,0.8967,0.89685,5.000
5,52.500,0.00,1.0217,1.02180,5.000
5,52.625,0.00,1.1468,1.14690,5.000
5,52.750,0.00,1.2717,1.27180,5.000
5,52.875,0.00,1.3966,1.39670,5.000
5,53.000,0.00,1.5216,1.52170,5.000
5,53.125,0.00,1.6467,1.64680,5.000
5,53.250,0.00,1.7717,1.77180,5.000
5,53.375,0.01,1.8968,1.89690,5.000
5,53.500,0.03,2.0219,2.02200,5.000
5,53.625,0.06,2.1467,2.14685,5.000
5,53.750,0.10,2.2717,2.27180,5.000
5,53.875,0.18,2.3968,2.39690,5.000
5,54.000,0.31,2.5217,2.52180,5.000
5,54.125,0.53,2.6468,2.64690,5.000
5,54.250,0.84,2.7719,2.77200,5.000
5,54.375,1.26,2.8968,2.89690,5.000
5,54.500,1.79,3.0219,3.02200,5.000
5,54.625,2.46,3.1468,3.14695,5.000
5,54.750,3.29,3.2719,3.27200,5.000
5,54.875,4.29,3.3968,3.39695,5.000
5,55.000,5.48,3.5217,3.52180,5.000
5,55.125,6.88,3.6467,3.64685,5.000
5,55.250,8.51,3.7718,3.77190,5.000
5,55.375,10.42,3.8968,3.89695,5.000
5,55.500,12.56,4.0219,4.02200,5.000
5,55.625,14.99,4.1468,4.14695,5.000
5,55.750,17.73,4.2718,4.27190,5.000
5,55.875,20.82,4.3968,4.39690,5.000
5,56.000,24.30,4.5216,4.52170,5.000
5,56.125,28.26,4.6467,4.64685,5.000
5,56.312,28.55,4.6920,4.69205,5.000
5,56.438,21.92,4.5670,4.56712,5.000
5,56.562,17.22,4.4420,4.44210,5.000
5,56.688,13.62,4.3170,4.31715,5.000
5,56.812,10.83,4.1921,4.19218,5.000
5,56.938,8.62,4.0672,4.06727,5.000
5,57.062,6.84,3.9422,3.94228,5.000
5,57.188,5.42,3.8170,3.81712,5.000
5,57.312,4.30,3.6920,3.69208,5.000
5,57.438,3.39,3.5670,3.56710,5.000
5,57.562,2.65,3.4420,3.44208,5.000
5,57.688,2.05,3.3170,3.31715,5.000
5,57.812,1.56,3.1920,3.19205,5.000
5,57.938,1.15,3.0671,3.06717,5.000
5,58.062,0.82,2.9419,2.94203,5.000
5,58.188,0.53,2.8170,2.81710,5.000
5,58.312,0.32,2.6921,2.69215,5.000
5,58.438,0.17,2.5668,2.56687,5.000
5,58.562,0.09,2.4419,2.44195,5.000
5,58.688,0.04,2.3169,2.31697,5.000
5,58.812,0.02,2.1919,2.19200,5.000
5,58.938,0.01,2.0668,2.06695,5.000
5,59.062,0.00,1.9419,1.94200,5.000
5,59.188,0.00,1.8170,1.81707,5.000
5,59.312,0.00,1.6920,1.69205,5.000
5,59.438,0.00,1.5668,1.56692,5.000
5,59.562,0.00,1.4418,1.44188,5.000
5,59.688,0.00,1.3168,1.31692,5.000
5,59.812,0.00,1.1919,1.19195,5.000
5,59.938,0.00,1.0669,1.06697,5.000
5,60.062,0.00,0.9419,0.94200,5.000
5,60.188,0.00,0.8169,0.81700,5.000
5,60.312,0.00,0.6918,0.69190,5.000
5,60.438,0.00,0.5668,0.56690,5.000
5,60.562,0.00,0.4418,0.44185,5.000
5,60.688,0.00,0.3167,0.31677,5.000
5,60.812,0.00,0.1918,0.19185,5.000
5,60.938,0.00,0.0666,0.06667,5.000
5,61.125,0.00,-0.0120,-0.01190,5.000
5,61.250,0.00,-0.0003,-0.00020,5.000
5,61.375,0.00,-0.0003,-0.00020,5.000
5,61.500,0.00,-0.0003,-0.00020,5.000
5,61.625,0.00,-0.0003,-0.00020,5.000
5,61.750,0.00,-0.0003,-0.00020,5.000
5,61.875,0.00,-0.0003,-0.00020,5.000
5,62.000,0.00,-0.0003,-0.00020,5.000
5,62.125,0.00,-0.0003,-0.00020,5.000
5,62.250,0.00,-0.0003,-0.00020,5.000
5,62.375,0.00,-0.0003,-0.00020,5.000
5,62.500,0.00,-0.0003,-0.00020,5.000
5,62.625,0.00,-0.0003,-0.00020,5.000
5,62.750,0.00,-0.0003,-0.00020,5.000
5,62.875,0.00,-0.0003,-0.00020,5.000
5,63.000,0.00,-0.0003,-0.00020,5.000
5,63.125,0.00,-0.0003,-0.00020,5.000
5,63.250,0.00,-0.0003,-0.00020,5.000
5,63.375,0.00,-0.0002,-0.00010,5.000
5,63.500,0.00,-0.0002,-0.00010,5.000
5,63.625,0.00,-0.0002,-0.00010,5.000
5,63.750,0.01,-0.0002,-0.00010,5.000
5,63.875,0.00,-0.0002,-0.00010,5.000
5,64.000,0.00,-0.0002,-0.00010,5.000
6,64.375,0.00,0.0865,0.08660,6.000
6,64.500,-0.01,0.2118,0.21190,6.000
6,64.625,0.00,0.3368,0.33685,6.000
6,64.750,0.00,0.4617,0.46180,6.000
6,64.875,-0.01,0.5866,0.58675,6.000
6,65.000,0.00,0.7116,0.71170,6.000
6,65.125,-0.01,0.8366,0.83675,6.000
6,65.250,0.00,0.9617,0.96180,6.000
6,65.375,0.00,1.0868,1.08685,6.000
6,65.500,0.00,1.2118,1.21190,6.000
6,65.625,0.00,1.3368,1.33685,6.000
6,65.750,0.00,1.4617,1.46180,6.000
6,65.875,0.00,1.5867,1.58680,6.000
6,66.000,-0.01,1.7117,1.71180,6.000
6,66.125,0.00,1.8368,1.83685,6.000
6,66.250,0.01,1.9617,1.96180,6.000
6,66.375,0.04,2.0866,2.08675,6.000
6,66.500,0.07,2.2118,2.21190,6.000
6,66.625,0.13,2.3368,2.33690,6.000
6,66.750,0.23,2.4619,2.46200,6.000
6,66.875,0.41,2.5868,2.58685,6.000
6,67.000,0.67,2.7119,2.71200,6.000
6,67.125,1.03,2.8368,2.83685,6.000
6,67.250,1.52,2.9617,2.96180,6.000
6,67.375,2.11,3.0868,3.08685,6.000
6,67.500,2.86,3.2119,3.21200,6.000
6,67.625,3.78,3.3369,3.33700,6.000
6,67.750,4.87,3.4619,3.46200,6.000
6,67.875,6.16,3.5868,3.58695,6.000
6,68.000,7.69,3.7119,3.71200,6.000
6,68.125,9.46,3.8368,3.83685,6.000
6,68.250,11.49,3.9617,3.96180,6.000
6,68.375,13.78,4.0868,4.08685,6.000
6,68.500,16.36,4.2118,4.21190,6.000
6,68.625,19.27,4.3368,4.33690,6.000
6,68.750,22.56,4.4618,4.46190,6.000
6,68.875,26.27,4.5868,4.58695,6.000
6,69.000,30.52,4.7118,4.71190,6.000
6,69.188,25.47,4.6450,4.64512,6.000
6,69.312,19.83,4.5200,4.52005,6.000
6,69.438,15.64,4.3952,4.39525,6.000
6,69.562,12.40,4.2701,4.27020,6.000
6,69.688,9.87,4.1451,4.14520,6.000
6,69.812,7.85,4.0202,4.02030,6.000
6,69.938,6.24,3.8950,3.89512,6.000
6,70.062,4.93,3.7700,3.77005,6.000
6,70.188,3.91,3.6449,3.64500,6.000
6,70.312,3.07,3.5199,3.52000,6.000
6,70.438,2.40,3.3950,3.39508,6.000
6,70.562,1.84,3.2700,3.27005,6.000
6,70.688,1.38,3.1450,3.14510,6.000
6,70.812,1.01,3.0201,3.02018,6.000
6,70.938,0.69,2.8949,2.89503,6.000
6,71.062,0.43,2.7701,2.77018,6.000
6,71.188,0.25,2.6448,2.64492,6.000
6,71.312,0.13,2.5198,2.51990,6.000
6,71.438,0.06,2.3949,2.39500,6.000
6,71.562,0.03,2.2699,2.27000,6.000
6,71.688,0.01,2.1449,2.14500,6.000
6,71.812,0.00,2.0199,2.02000,6.000
6,71.938,-0.01,1.8949,1.89500,6.000
6,72.062,-0.01,1.7699,1.76998,6.000
6,72.188,-0.01,1.6448,1.64492,6.000
6,72.312,-0.01,1.5198,1.51985,6.000
6,72.438,-0.01,1.3947,1.39483,6.000
6,72.562,-0.01,1.2699,1.26995,6.000
6,72.688,-0.01,1.1449,1.14498,6.000
6,72.812,0.00,1.0199,1.02003,6.000
6,72.938,-0.01,0.8949,0.89500,6.000
6,73.062,0.00,0.7699,0.76995,6.000
6,73.188,0.00,0.6447,0.64482,6.000
6,73.312,-0.01,0.5197,0.51980,6.000
6,73.438,-0.01,0.3946,0.39475,6.000
6,73.562,-0.01,0.2698,0.26990,6.000
6,73.688,-0.01,0.1448,0.14485,6.000
6,73.812,-0.01,0.0197,0.01980,6.000
6,74.000,0.00,-0.0014,-0.00130,6.000
6,74.125,-0.01,-0.0004,-0.00030,6.000
6,74.250,-0.01,-0.0003,-0.00020,6.000
6,74.375,0.00,-0.0003,-0.00020,6.000
6,74.500,-0.01,-0.0003,-0.00020,6.000
6,74.625,-0.01,-0.0003,-0.00020,6.000
6,74.750,0.00,-0.0003,-0.00020,6.000
6,74.875,0.00,-0.0003,-0.00020,6.000
6,75.000,-0.01,-0.0003,-0.00020,6.000
6,75.125,0.00,-0.0003,-0.00020,6.000
6,75.250,0.00,-0.0003,-0.00020,6.000
6,75.375,-0.01,-0.0003,-0.00020,6.000
6,75.500,0.00,-0.0003,-0.00020,6.000
6,75.625,-0.02,-0.0003,-0.00020,6.000
6,75.750,0.00,-0.0003,-0.00020,6.000
6,75.875,-0.01,-0.0003,-0.00020,6.000
6,76.000,0.00,-0.0003,-0.00020,6.000
6,76.125,0.00,-0.0003,-0.00020,6.000
6,76.250,-0.01,-0.0003,-0.00020,6.000
6,76.375,-0.01,-0.0003,-0.00020,6.000
6,76.500,-0.01,-0.0003,-0.00020,6.000
6,76.625,-0.01,-0.0002,-0.00015,6.000
6,76.750,-0.02,-0.0002,-0.00010,6.000
6,76.875,-0.01,-0.0002,-0.00010,6.000
7,77.188,0.00,0.0789,0.07900,7.000
7,77.312,-0.01,0.2041,0.20425,7.000
7,77.438,0.00,0.3292,0.32930,7.000
7,77.562,-0.01,0.4542,0.45430,7.000
7,77.688,0.00,0.5793,0.57935,7.000
7,77.812,-0.01,0.7042,0.70435,7.000
7,77.938,-0.01,0.8292,0.82932,7.000
7,78.062,-0.01,0.9542,0.95430,7.000
7,78.188,-0.01,1.0792,1.07928,7.000
7,78.312,-0.01,1.2042,1.20435,7.000
7,78.438,-0.01,1.3292,1.32930,7.000
7,78.562,-0.01,1.4543,1.45440,7.000
7,78.688,0.00,1.5793,1.57940,7.000
7,78.812,-0.01,1.7043,1.70445,7.000
7,78.938,-0.01,1.8292,1.82935,7.000
7,79.062,0.01,1.9542,1.95430,7.000
7,79.188,0.04,2.0792,2.07930,7.000
7,79.312,0.07,2.2041,2.20425,7.000
7,79.438,0.12,2.3293,2.32938,7.000
7,79.562,0.22,2.4543,2.45440,7.000
7,79.688,0.39,2.5793,2.57938,7.000
7,79.812,0.65,2.7044,2.70452,7.000
7,79.938,1.01,2.8294,2.82950,7.000
7,80.062,1.48,2.9543,2.95437,7.000
7,80.188,2.07,3.0792,3.07935,7.000
7,80.312,2.80,3.2042,3.20435,7.000
7,80.438,3.71,3.3293,3.32940,7.000
7,80.562,4.79,3.4543,3.45442,7.000
7,80.688,6.07,3.5793,3.57943,7.000
7,80.812,7.58,3.7044,3.70450,7.000
7,80.938,9.34,3.8293,3.82943,7.000
7,81.062,11.36,3.9544,3.95452,7.000
7,81.188,13.63,4.0793,4.07943,7.000
7,81.312,16.20,4.2042,4.20432,7.000
7,81.438,19.09,4.3292,4.32930,7.000
7,81.562,22.34,4.4542,4.45430,7.000
7,81.688,26.03,4.5794,4.57945,7.000
7,81.812,30.24,4.7043,4.70445,7.000
7,82.000,25.96,4.6546,4.65470,7.000
7,82.125,20.19,4.5295,4.52960,7.000
7,82.250,15.92,4.4044,4.40450,7.000
7,82.375,12.62,4.2795,4.27960,7.000
7,82.500,10.03,4.1546,4.15470,7.000
7,82.625,7.99,4.0296,4.02975,7.000
7,82.750,6.34,3.9046,3.90470,7.000
7,82.875,5.02,3.7796,3.77965,7.000
7,83.000,3.98,3.6545,3.65460,7.000
7,83.125,3.13,3.5294,3.52955,7.000
7,83.250,2.45,3.4044,3.40450,7.000
7,83.375,1.88,3.2795,3.27960,7.000
7,83.500,1.41,3.1546,3.15470,7.000
7,83.625,1.04,3.0296,3.02965,7.000
7,83.750,0.71,2.9045,2.90460,7.000
7,83.875,0.45,2.7796,2.77970,7.000
7,84.000,0.26,2.6546,2.65470,7.000
7,84.125,0.14,2.5294,2.52945,7.000
7,84.250,0.07,2.4044,2.40450,7.000
7,84.375,0.03,2.2793,2.27940,7.000
7,84.500,0.01,2.1543,2.15440,7.000
7,84.625,0.01,2.0294,2.02945,7.000
7,84.750,0.00,1.9044,1.90450,7.000
7,84.875,0.00,1.7794,1.77950,7.000
7,85.000,-0.01,1.6545,1.65460,7.000
7,85.125,0.00,1.5294,1.52950,7.000
7,85.250,0.00,1.4042,1.40430,7.000
7,85.375,-0.01,1.2793,1.27940,7.000
7,85.500,-0.01,1.1543,1.15440,7.000
7,85.625,0.00,1.0294,1.02945,7.000
7,85.750,-0.01,0.9044,0.90450,7.000
7,85.875,-0.01,0.7794,0.77950,7.000
7,86.000,-0.01,0.6543,0.65440,7.000
7,86.125,0.00,0.5292,0.52935,7.000
7,86.250,-0.01,0.4042,0.40430,7.000
7,86.375,0.00,0.2793,0.27940,7.000
7,86.500,0.00,0.1542,0.15430,7.000
7,86.625,0.00,0.0292,0.02925,7.000
7,86.875,-0.01,-0.0004,-0.00025,7.000
7,87.000,0.00,-0.0003,-0.00020,7.000
7,87.125,-0.01,-0.0003,-0.00020,7.000
7,87.250,0.00,-0.0003,-0.00020,7.000
7,87.375,0.00,-0.0003,-0.00020,7.000
7,87.500,-0.01,-0.0003,-0.00020,7.000
7,87.625,-0.01,-0.0003,-0.00020,7.000
7,87.750,-0.01,-0.0003,-0.00020,7.000
7,87.875,-0.01,-0.0003,-0.00020,7.000
7,88.000,-0.01,-0.0003,-0.00020,7.000
7,88.125,-0.01,-0.0003,-0.00020,7.000
7,88.250,0.00,-0.0003,-0.00020,7.000
7,88.375,0.00,-0.0003,-0.00020,7.000
7,88.500,-0.01,-0.0003,-0.00020,7.000
7,88.625,0.00,-0.0003,-0.00020,7.000
7,88.750,0.00,-0.0003,-0.00020,7.000
7,88.875,0.00,-0.0003,-0.00020,7.000
7,89.000,0.00,-0.0003,-0.00020,7.000
7,89.125,-0.01,-0.0003,-0.00020,7.000
7,89.250,-0.01,-0.0003,-0.00020,7.000
7,89.375,-0.01,-0.0002,-0.00010,7.000
7,89.500,0.00,-0.0002,-0.00010,7.000
7,89.625,0.00,-0.0002,-0.00010,7.000
7,89.750,-0.01,-0.0002,-0.00010,7.000
8,90.062,-0.01,0.1209,0.12102,8.000
8,90.188,0.00,0.2462,0.24628,8.000
8,90.312,-0.01,0.3713,0.37137,8.000
8,90.438,0.00,0.4962,0.49628,8.000
8,90.562,0.00,0.6212,0.62127,8.000
8,90.688,0.00,0.7462,0.74630,8.000
8,90.812,0.00,0.8711,0.87122,8.000
8,90.938,0.00,0.9962,0.99625,8.000
8,91.062,-0.01,1.1212,1.12132,8.000
8,91.188,0.00,1.2463,1.24638,8.000
8,91.312,0.00,1.3712,1.37130,8.000
8,91.438,0.00,1.4963,1.49638,8.000
8,91.562,0.00,1.6213,1.62140,8.000
8,91.688,0.00,1.7462,1.74635,8.000
8,91.812,0.00,1.8713,1.87140,8.000
8,91.938,0.02,1.9962,1.99630,8.000
8,92.062,0.05,2.1211,2.12122,8.000
8,92.188,0.09,2.2462,2.24635,8.000
8,92.312,0.15,2.3713,2.37142,8.000
8,92.438,0.26,2.4964,2.49645,8.000
8,92.562,0.47,2.6213,2.62140,8.000
8,92.688,0.76,2.7464,2.74655,8.000
8,92.812,1.15,2.8713,2.87145,8.000
8,92.938,1.66,2.9963,2.99635,8.000
8,93.062,2.30,3.1212,3.12132,8.000
8,93.188,3.09,3.2464,3.24645,8.000
8,93.312,4.05,3.3713,3.37145,8.000
8,93.438,5.20,3.4964,3.49645,8.000
8,93.562,6.55,3.6214,3.62147,8.000
8,93.688,8.14,3.7464,3.74648,8.000
8,93.812,9.98,3.8714,3.87147,8.000
8,93.938,12.08,3.9963,3.99643,8.000
8,94.062,14.44,4.1213,4.12137,8.000
8,94.188,17.12,4.2463,4.24640,8.000
8,94.312,20.13,4.3713,4.37137,8.000
8,94.438,23.52,4.4962,4.49630,8.000
8,94.562,27.36,4.6213,4.62142,8.000
8,94.750,30.97,4.7297,4.72980,8.000
8,94.875,23.48,4.6046,4.60465,8.000
8,95.000,18.38,4.4795,4.47960,8.000
8,95.125,14.53,4.3546,4.35470,8.000
8,95.250,11.53,4.2296,4.22970,8.000
8,95.375,9.18,4.1047,4.10475,8.000
8,95.500,7.30,3.9797,3.97980,8.000
8,95.625,5.79,3.8545,3.85460,8.000
8,95.750,4.59,3.7294,3.72950,8.000
8,95.875,3.62,3.6045,3.60455,8.000
8,96.000,2.84,3.4793,3.47940,8.000
8,96.125,2.21,3.3546,3.35465,8.000
8,96.250,1.68,3.2295,3.22960,8.000
8,96.375,1.25,3.1046,3.10465,8.000
8,96.500,0.91,2.9795,2.97960,8.000
8,96.625,0.60,2.8544,2.85455,8.000
8,96.750,0.37,2.7296,2.72970,8.000
8,96.875,0.20,2.6044,2.60445,8.000
8,97.000,0.11,2.4794,2.47950,8.000
8,97.125,0.05,2.3544,2.35445,8.000
8,97.250,0.02,2.2294,2.22950,8.000
8,97.375,0.01,2.1044,2.10450,8.000
8,97.500,-0.01,1.9795,1.97960,8.000
8,97.625,-0.01,1.8544,1.85450,8.000
8,97.750,-0.01,1.7294,1.72950,8.000
8,97.875,-0.01,1.6043,1.60435,8.000
8,98.000,-0.01,1.4792,1.47930,8.000
8,98.125,-0.01,1.3542,1.35435,8.000
8,98.250,-0.01,1.2295,1.22960,8.000
8,98.375,-0.01,1.1044,1.10450,8.000
8,98.500,0.00,0.9795,0.97960,8.000
8,98.625,-0.01,0.8544,0.85450,8.000
8,98.750,-0.01,0.7294,0.72950,8.000
8,98.875,-0.01,0.6042,0.60430,8.000
8,99.000,-0.01,0.4792,0.47930,8.000
8,99.125,-0.01,0.3542,0.35435,8.000
8,99.250,0.00,0.2293,0.22940,8.000
8,99.375,-0.01,0.1042,0.10430,8.000
8,99.500,-0.01,-0.0206,-0.02050,8.000
8,99.688,-0.01,-0.0003,-0.00023,8.000
8,99.812,-0.01,-0.0004,-0.00028,8.000
8,99.938,0.00,-0.0003,-0.00020,8.000
8,100.062,-0.01,-0.0003,-0.00020,8.000
8,100.188,-0.01,-0.0003,-0.00020,8.000
8,100.312,-0.01,-0.0003,-0.00020,8.000
8,100.438,0.00,-0.0003,-0.00020,8.000
8,100.562,-0.01,-0.0003,-0.00020,8.000
8,100.688,0.00,-0.0003,-0.00020,8.000
8,100.812,0.00,-0.0003,-0.00020,8.000
8,100.938,-0.01,-0.0003,-0.00020,8.000
8,101.062,-0.01,-0.0003,-0.00020,8.000
8,101.188,-0.01,-0.0003,-0.00020,8.000
8,101.312,-0.01,-0.0003,-0.00020,8.000
8,101.438,-0.01,-0.0003,-0.00020,8.000
8,101.562,0.00,-0.0003,-0.00020,8.000
8,101.688,-0.01,-0.0003,-0.00020,8.000
8,101.812,-0.01,-0.0003,-0.00020,8.000
8,101.938,0.00,-0.0003,-0.00020,8.000
8,102.062,-0.01,-0.0003,-0.00020,8.000
8,102.188,-0.01,-0.0003,-0.00020,8.000
8,102.312,-0.01,-0.0003,-0.00020,8.000
8,102.438,0.00,-0.0002,-0.00010,8.000
8,102.562,-0.01,-0.0002,-0.00010,8.000
9,102.875,0.00,0.1154,0.11550,9.000
9,103.000,0.00,0.2406,0.24070,9.000
9,103.125,0.00,0.3656,0.36570,9.000
9,103.250,0.00,0.4907,0.49080,9.000
9,103.375,0.00,0.6157,0.61580,9.000
9,103.500,0.00,0.7408,0.74090,9.000
9,103.625,0.00,0.8658,0.86585,9.000
9,103.750,0.00,0.9908,0.99090,9.000
9,103.875,0.00,1.1157,1.11580,9.000
9,104.000,0.00,1.2408,1.24090,9.000
9,104.125,0.00,1.3657,1.36580,9.000
9,104.250,0.00,1.4907,1.49080,9.000
9,104.375,0.00,1.6158,1.61585,9.000
9,104.500,0.00,1.7409,1.74100,9.000
9,104.625,0.00,1.8658,1.86595,9.000
9,104.750,0.02,1.9908,1.99090,9.000
9,104.875,0.05,2.1157,2.11580,9.000
9,105.000,0.09,2.2407,2.24080,9.000
9,105.125,0.15,2.3658,2.36585,9.000
9,105.250,0.26,2.4907,2.49080,9.000
9,105.375,0.46,2.6158,2.61590,9.000
9,105.500,0.74,2.7410,2.74110,9.000
9,105.625,1.14,2.8658,2.86595,9.000
9,105.750,1.64,2.9908,2.99090,9.000
9,105.875,2.27,3.1158,3.11595,9.000
9,106.000,3.05,3.2407,3.24080,9.000
9,106.125,4.01,3.3658,3.36595,9.000
9,106.250,5.14,3.4908,3.49090,9.000
9,106.375,6.49,3.6158,3.61590,9.000
9,106.500,8.06,3.7408,3.74090,9.000
9,106.625,9.89,3.8658,3.86595,9.000
9,106.750,11.98,3.9910,3.99110,9.000
9,106.875,14.33,4.1159,4.11600,9.000
9,107.000,16.99,4.2408,4.24090,9.000
9,107.125,19.99,4.3658,4.36585,9.000
9,107.250,23.37,4.4906,4.49070,9.000
9,107.375,27.19,4.6158,4.61590,9.000
9,107.562,31.43,4.7383,4.73835,9.000
9,107.688,23.90,4.6141,4.61418,9.000
9,107.812,18.71,4.4890,4.48908,9.000
9,107.938,14.78,4.3640,4.36410,9.000
9,108.062,11.74,4.2391,4.23918,9.000
9,108.188,9.34,4.1140,4.11412,9.000
9,108.312,7.43,3.9891,3.98923,9.000
9,108.438,5.90,3.8641,3.86420,9.000
9,108.562,4.68,3.7390,3.73910,9.000
9,108.688,3.70,3.6139,3.61403,9.000
9,108.812,2.90,3.4889,3.48900,9.000
9,108.938,2.26,3.3640,3.36410,9.000
9,109.062,1.73,3.2390,3.23905,9.000
9,109.188,1.29,3.1140,3.11408,9.000
9,109.312,0.93,2.9890,2.98910,9.000
9,109.438,0.62,2.8640,2.86410,9.000
9,109.562,0.39,2.7391,2.73920,9.000
9,109.688,0.22,2.6139,2.61403,9.000
9,109.812,0.12,2.4888,2.48893,9.000
9,109.938,0.06,2.3638,2.36392,9.000
9,110.062,0.03,2.2388,2.23893,9.000
9,110.188,0.02,2.1139,2.11398,9.000
9,110.312,0.01,1.9889,1.98900,9.000
9,110.438,0.00,1.8640,1.86405,9.000
9,110.562,0.00,1.7390,1.73905,9.000
9,110.688,0.00,1.6140,1.61405,9.000
9,110.812,0.00,1.4889,1.48898,9.000
9,110.938,0.00,1.3637,1.36382,9.000
9,111.062,0.00,1.2388,1.23888,9.000
9,111.188,0.00,1.1138,1.11395,9.000
9,111.312,0.00,0.9889,0.98895,9.000
9,111.438,0.00,0.8640,0.86408,9.000
9,111.562,0.00,0.7389,0.73900,9.000
9,111.688,0.00,0.6138,0.61395,9.000
9,111.812,0.00,0.4888,0.48888,9.000
9,111.938,0.00,0.3638,0.36385,9.000
9,112.062,0.01,0.2387,0.23883,9.000
9,112.188,0.00,0.1136,0.11372,9.000
9,112.312,0.00,-0.0113,-0.01122,9.000
9,112.500,0.00,-0.0003,-0.00020,9.000
9,112.625,0.00,-0.0004,-0.00030,9.000
9,112.750,0.00,-0.0004,-0.00030,9.000
9,112.875,0.00,-0.0004,-0.00030,9.000
9,113.000,0.00,-0.0004,-0.00030,9.000
9,113.125,0.00,-0.0004,-0.00030,9.000
9,113.250,0.01,-0.0004,-0.00030,9.000
9,113.375,0.00,-0.0003,-0.00020,9.000
9,113.500,0.00,-0.0003,-0.00020,9.000
9,113.625,0.00,-0.0003,-0.00020,9.000
9,113.750,0.00,-0.0003,-0.00020,9.000
9,113.875,0.00,-0.0003,-0.00020,9.000
9,114.000,0.00,-0.0003,-0.00020,9.000
9,114.125,0.00,-0.0003,-0.00020,9.000
9,114.250,0.00,-0.0003,-0.00020,9.000
9,114.375,0.00,-0.0003,-0.00020,9.000
9,114.500,0.00,-0.0003,-0.00020,9.000
9,114.625,0.00,-0.0003,-0.00020,9.000
9,114.750,0.00,-0.0003,-0.00020,9.000
9,114.875,0.00,-0.0003,-0.00020,9.000
9,115.000,0.00,-0.0003,-0.00020,9.000
9,115.125,0.00,-0.0003,-0.00020,9.000
9,115.250,0.00,-0.0002,-0.00010,9.000
9,115.375,0.00,-0.0002,-0.00010,9.000
10,115.688,0.00,0.1089,0.10902,10.000
10,115.812,0.00,0.2342,0.23430,10.000
10,115.938,-0.01,0.3591,0.35920,10.000
10,116.062,-0.01,0.4841,0.48422,10.000
10,116.188,0.00,0.6092,0.60928,10.000
10,116.312,-0.01,0.7342,0.73430,10.000
10,116.438,-0.01,0.8593,0.85938,10.000
10,116.562,-0.01,0.9843,0.98445,10.000
10,116.688,0.00,1.1092,1.10933,10.000
10,116.812,0.00,1.2343,1.23437,10.000
10,116.938,-0.01,1.3591,1.35923,10.000
10,117.062,-0.01,1.4841,1.48425,10.000
10,117.188,-0.01,1.6092,1.60930,10.000
10,117.312,0.00,1.7343,1.73442,10.000
10,117.438,0.00,1.8593,1.85940,10.000
10,117.562,0.01,1.9843,1.98440,10.000
10,117.688,0.05,2.1093,2.10940,10.000
10,117.812,0.08,2.2343,2.23442,10.000
10,117.938,0.14,2.3592,2.35935,10.000
10,118.062,0.25,2.4842,2.48430,10.000
10,118.188,0.44,2.6092,2.60930,10.000
10,118.312,0.72,2.7344,2.73450,10.000
10,118.438,1.10,2.8593,2.85940,10.000
10,118.562,1.60,2.9843,2.98445,10.000
10,118.688,2.23,3.1094,3.10950,10.000
10,118.812,3.00,3.2344,3.23450,10.000
10,118.938,3.94,3.3594,3.35953,10.000
10,119.062,5.07,3.4842,3.48432,10.000
10,119.188,6.40,3.6093,3.60940,10.000
10,119.312,7.96,3.7343,3.73440,10.000
10,119.438,9.78,3.8593,3.85940,10.000
10,119.562,11.84,3.9844,3.98452,10.000
10,119.688,14.18,4.1094,4.10950,10.000
10,119.812,16.82,4.2344,4.23452,10.000
10,119.938,19.81,4.3593,4.35942,10.000
10,120.062,23.16,4.4842,4.48430,10.000
10,120.188,26.97,4.6093,4.60938,10.000
10,120.375,31.77,4.7445,4.74460,10.000
10,120.500,24.28,4.6227,4.62280,10.000
10,120.625,18.99,4.4975,4.49760,10.000
10,120.750,14.99,4.3725,4.37260,10.000
10,120.875,11.90,4.2475,4.24755,10.000
10,121.000,9.47,4.1225,4.12260,10.000
10,121.125,7.53,3.9976,3.99770,10.000
10,121.250,5.97,3.8725,3.87260,10.000
10,121.375,4.73,3.7476,3.74770,10.000
10,121.500,3.75,3.6226,3.62270,10.000
10,121.625,2.94,3.4975,3.49760,10.000
10,121.750,2.28,3.3725,3.37260,10.000
10,121.875,1.75,3.2474,3.24755,10.000
10,122.000,1.31,3.1225,3.12260,10.000
10,122.125,0.94,2.9974,2.99755,10.000
10,122.250,0.64,2.8726,2.87270,10.000
10,122.375,0.39,2.7476,2.74775,10.000
10,122.500,0.22,2.6225,2.62260,10.000
10,122.625,0.12,2.4974,2.49755,10.000
10,122.750,0.06,2.3724,2.37250,10.000
10,122.875,0.03,2.2474,2.24745,10.000
10,123.000,0.01,2.1222,2.12230,10.000
10,123.125,0.00,1.9973,1.99735,10.000
10,123.250,-0.01,1.8724,1.87250,10.000
10,123.375,-0.01,1.7474,1.74750,10.000
10,123.500,-0.01,1.6224,1.62250,10.000
10,123.625,-0.01,1.4974,1.49750,10.000
10,123.750,0.00,1.3723,1.37240,10.000
10,123.875,-0.01,1.2474,1.24750,10.000
10,124.000,0.00,1.1222,1.12230,10.000
10,124.125,-0.01,0.9973,0.99740,10.000
10,124.250,-0.01,0.8724,0.87250,10.000
10,124.375,0.00,0.7474,0.74750,10.000
10,124.500,0.00,0.6223,0.62240,10.000
10,124.625,0.00,0.4974,0.49745,10.000
10,124.750,0.00,0.3723,0.37240,10.000
10,124.875,0.00,0.2474,0.24745,10.000
10,125.000,-0.01,0.1222,0.12230,10.000
10,125.125,-0.01,-0.0028,-0.00275,10.000
10,125.312,-0.01,-0.0006,-0.00050,10.000
10,125.438,-0.01,-0.0004,-0.00030,10.000
10,125.562,-0.01,-0.0004,-0.00030,10.000
10,125.688,0.00,-0.0004,-0.00030,10.000
10,125.812,-0.01,-0.0004,-0.00030,10.000
10,125.938,0.00,-0.0004,-0.00030,10.000
10,126.062,0.00,-0.0004,-0.00030,10.000
10,126.188,-0.01,-0.0003,-0.00020,10.000
10,126.312,0.00,-0.0003,-0.00020,10.000
10,126.438,0.00,-0.0003,-0.00020,10.000
10,126.562,0.00,-0.0003,-0.00020,10.000
10,126.688,0.00,-0.0003,-0.00020,10.000
10,126.812,0.00,-0.0003,-0.00020,10.000
10,126.938,0.00,-0.0003,-0.00020,10.000
10,127.062,0.00,-0.0003,-0.00020,10.000
10,127.188,-0.01,-0.0003,-0.00020,10.000
10,127.312,0.00,-0.0003,-0.00020,10.000
10,127.438,0.00,-0.0003,-0.00020,10.000
10,127.562,0.00,-0.0003,-0.00020,10.000
10,127.688,0.00,-0.0003,-0.00020,10.000
10,127.812,0.00,-0.0003,-0.00020,10.000
10,127.938,0.00,-0.0003,-0.00020,10.000
10,128.062,0.00,-0.0002,-0.00010,10.000
10,128.188,-0.01,-0.0002,-0.00010,10.000