File: AIME_journal_files/AIME_data/calibDATA_loadcell/date_02:22:2018/Instron/50N_0_1_3_0.txt
""
"Test Method","Radhen_Load_Cntrl_Cmprsn_250N_12-7.msm"
"Sample I. D.","Sample1.mss"
"Specimen Number","12"

"TheCycle_Output ()","_Time (s)","_Load (N)","_Extension (mm)","RealTimeDepth (mm)","CycleNumber ()"

1,0.312,0.00,0.0637,0.06373,1.000
1,0.438,0.00,0.1888,0.18878,1.000
1,0.562,0.00,0.3140,0.31400,1.000
1,0.688,0.00,0.4390,0.43897,1.000
1,0.812,0.00,0.5640,0.56400,1.000
1,0.938,0.00,0.6890,0.68900,1.000
1,1.062,0.00,0.8140,0.81400,1.000
1,1.188,0.00,0.9390,0.93895,1.000
1,1.312,0.00,1.0641,1.06405,1.000
1,1.438,0.00,1.1890,1.18900,1.000
1,1.562,0.00,1.3140,1.31395,1.000
1,1.688,0.00,1.4391,1.43905,1.000
1,1.812,0.00,1.5640,1.56402,1.000
1,1.938,0.02,1.6891,1.68908,1.000
1,2.062,0.06,1.8142,1.81420,1.000
1,2.188,0.12,1.9392,1.93915,1.000
1,2.312,0.27,2.0641,2.06407,1.000
1,2.438,0.50,2.1890,2.18902,1.000
1,2.562,0.80,2.3141,2.31412,1.000
1,2.688,1.21,2.4392,2.43918,1.000
1,2.812,1.72,2.5640,2.56405,1.000
1,2.938,2.36,2.6891,2.68910,1.000
1,3.062,3.15,2.8142,2.81418,1.000
1,3.188,4.11,2.9392,2.93920,1.000
1,3.312,5.25,3.0642,3.06418,1.000
1,3.438,6.58,3.1892,3.18915,1.000
1,3.562,8.12,3.3140,3.31402,1.000
1,3.688,9.88,3.4391,3.43910,1.000
1,3.812,11.88,3.5641,3.56410,1.000
1,3.938,14.12,3.6893,3.68925,1.000
1,4.062,16.63,3.8143,3.81430,1.000
1,4.188,19.46,3.9393,3.93930,1.000
1,4.312,22.66,4.0642,4.06420,1.000
1,4.438,26.25,4.1892,4.18920,1.000
1,4.562,30.33,4.3142,4.31420,1.000
1,4.688,34.97,4.4391,4.43912,1.000
1,4.812,40.26,4.5641,4.56412,1.000
1,4.938,46.20,4.6893,4.68928,1.000
1,5.125,48.94,4.7874,4.78735,1.000
1,5.250,35.11,4.6626,4.66260,1.000
1,5.375,26.84,4.5376,4.53755,1.000
1,5.500,20.95,4.4126,4.41260,1.000
1,5.625,16.52,4.2876,4.28760,1.000
1,5.750,13.10,4.1625,4.16250,1.000
1,5.875,10.47,4.0375,4.03750,1.000
1,6.000,8.42,3.9125,3.91250,1.000
1,6.125,6.86,3.7875,3.78750,1.000
1,6.250,5.63,3.6626,3.66260,1.000
1,6.375,4.62,3.5375,3.53750,1.000
1,6.500,3.80,3.4125,3.41250,1.000
1,6.625,3.13,3.2874,3.28745,1.000
1,6.750,2.53,3.1625,3.16250,1.000
1,6.875,2.01,3.0374,3.03745,1.000
1,7.000,1.56,2.9123,2.91230,1.000
1,7.125,1.17,2.7873,2.78730,1.000
1,7.250,0.83,2.6624,2.66240,1.000
1,7.375,0.57,2.5374,2.53740,1.000
1,7.500,0.36,2.4126,2.41260,1.000
1,7.625,0.19,2.2874,2.28740,1.000
1,7.750,0.08,2.1623,2.16230,1.000
1,7.875,0.03,2.0373,2.03730,1.000
1,8.000,0.01,1.9122,1.91220,1.000
1,8.125,0.01,1.7875,1.78745,1.000
1,8.250,0.00,1.6623,1.66230,1.000
1,8.375,0.00,1.5373,1.53730,1.000
1,8.500,0.00,1.4124,1.41240,1.000
1,8.625,0.00,1.2873,1.28730,1.000
1,8.750,0.00,1.1624,1.16240,1.000
1,8.875,0.00,1.0373,1.03730,1.000
1,9.000,0.01,0.9121,0.91210,1.000
1,9.125,0.00,0.7872,0.78720,1.000
1,9.250,0.00,0.6622,0.66220,1.000
1,9.375,0.00,0.5373,0.53725,1.000
1,9.500,0.00,0.4124,0.41240,1.000
1,9.625,0.00,0.2874,0.28735,1.000
1,9.750,0.00,0.1623,0.16230,1.000
1,9.875,0.00,0.0372,0.03720,1.000
1,10.125,0.00,-0.0002,-0.00020,1.000
1,10.250,0.00,-0.0003,-0.00030,1.000
1,10.375,0.00,-0.0002,-0.00020,1.000
1,10.500,0.00,-0.0002,-0.00020,1.000
1,10.625,0.00,-0.0002,-0.00020,1.000
1,10.750,0.00,-0.0002,-0.00020,1.000
1,10.875,0.00,-0.0002,-0.00020,1.000
1,11.000,0.00,-0.0002,-0.00020,1.000
1,11.125,0.00,-0.0002,-0.00020,1.000
1,11.250,0.00,-0.0002,-0.00020,1.000
1,11.375,0.00,-0.0002,-0.00020,1.000
1,11.500,0.00,-0.0002,-0.00020,1.000
1,11.625,0.00,-0.0002,-0.00020,1.000
1,11.750,0.00,-0.0002,-0.00020,1.000
1,11.875,0.00,-0.0002,-0.00020,1.000
1,12.000,0.00,-0.0002,-0.00020,1.000
1,12.125,0.00,-0.0002,-0.00020,1.000
1,12.250,0.00,-0.0002,-0.00020,1.000
1,12.375,0.00,-0.0002,-0.00020,1.000
1,12.500,0.00,-0.0002,-0.00020,1.000
1,12.625,0.00,-0.0002,-0.00020,1.000
1,12.750,0.00,-0.0002,-0.00020,1.000
1,12.875,0.00,-0.0002,-0.00020,1.000
1,13.000,0.00,-0.0002,-0.00020,1.000
2,13.375,0.00,0.1666,0.16670,2.000
2,13.500,0.00,0.2917,0.29180,2.000
2,13.625,0.00,0.4167,0.41680,2.000
2,13.750,0.01,0.5415,0.54160,2.000
2,13.875,0.00,0.6665,0.66665,2.000
2,14.000,0.00,0.7916,0.79170,2.000
2,14.125,0.00,0.9166,0.91670,2.000
2,14.250,0.00,1.0416,1.04170,2.000
2,14.375,0.00,1.1666,1.16675,2.000
2,14.500,0.00,1.2918,1.29190,2.000
2,14.625,0.00,1.4167,1.41685,2.000
2,14.750,0.01,1.5417,1.54180,2.000
2,14.875,0.01,1.6666,1.66675,2.000
2,15.000,0.04,1.7917,1.79180,2.000
2,15.125,0.08,1.9166,1.91675,2.000
2,15.250,0.17,2.0417,2.04180,2.000
2,15.375,0.35,2.1667,2.16680,2.000
2,15.500,0.61,2.2918,2.29190,2.000
2,15.625,0.96,2.4169,2.41700,2.000
2,15.750,1.41,2.5419,2.54200,2.000
2,15.875,1.98,2.6667,2.66685,2.000
2,16.000,2.69,2.7915,2.79160,2.000
2,16.125,3.56,2.9166,2.91670,2.000
2,16.250,4.61,3.0418,3.04190,2.000
2,16.375,5.85,3.1668,3.16690,2.000
2,16.500,7.30,3.2917,3.29180,2.000
2,16.625,8.97,3.4168,3.41690,2.000
2,16.750,10.88,3.5418,3.54190,2.000
2,16.875,13.01,3.6668,3.66685,2.000
2,17.000,15.37,3.7917,3.79180,2.000
2,17.125,18.02,3.9168,3.91685,2.000
2,17.250,21.01,4.0416,4.04170,2.000
2,17.375,24.34,4.1668,4.16690,2.000
2,17.500,28.09,4.2918,4.29190,2.000
2,17.625,32.36,4.4168,4.41690,2.000
2,17.750,37.33,4.5418,4.54190,2.000
2,17.875,43.22,4.6668,4.66690,2.000
2,18.000,50.40,4.7916,4.79170,2.000
2,18.188,41.06,4.7451,4.74523,2.000
2,18.312,30.71,4.6202,4.62027,2.000
2,18.438,23.78,4.4951,4.49520,2.000
2,18.562,18.68,4.3701,4.37025,2.000
2,18.688,14.78,4.2451,4.24523,2.000
2,18.812,11.78,4.1200,4.12010,2.000
2,18.938,9.44,3.9950,3.99505,2.000
2,19.062,7.64,3.8700,3.87015,2.000
2,19.188,6.25,3.7451,3.74518,2.000
2,19.312,5.14,3.6200,3.62015,2.000
2,19.438,4.23,3.4951,3.49515,2.000
2,19.562,3.48,3.3700,3.37015,2.000
2,19.688,2.86,3.2450,3.24508,2.000
2,19.812,2.29,3.1199,3.12002,2.000
2,19.938,1.80,2.9949,2.99498,2.000
2,20.062,1.37,2.8698,2.86990,2.000
2,20.188,1.00,2.7449,2.74503,2.000
2,20.312,0.71,2.6199,2.62000,2.000
2,20.438,0.47,2.4950,2.49508,2.000
2,20.562,0.28,2.3700,2.37015,2.000
2,20.688,0.13,2.2449,2.24503,2.000
2,20.812,0.04,2.1199,2.11997,2.000
2,20.938,0.02,1.9948,1.99490,2.000
2,21.062,0.01,1.8698,1.86992,2.000
2,21.188,0.01,1.7449,1.74500,2.000
2,21.312,0.00,1.6198,1.61990,2.000
2,21.438,0.00,1.4950,1.49508,2.000
2,21.562,0.00,1.3699,1.36997,2.000
2,21.688,0.00,1.2448,1.24493,2.000
2,21.812,0.00,1.1198,1.11992,2.000
2,21.938,0.00,0.9948,0.99485,2.000
2,22.062,0.00,0.8696,0.86975,2.000
2,22.188,0.00,0.7448,0.74488,2.000
2,22.312,0.00,0.6197,0.61977,2.000
2,22.438,0.00,0.4948,0.49488,2.000
2,22.562,0.00,0.3699,0.37000,2.000
2,22.688,0.00,0.2448,0.24493,2.000
2,22.812,0.00,0.1198,0.11992,2.000
2,22.938,0.00,-0.0052,-0.00510,2.000
2,23.125,0.00,-0.0004,-0.00025,2.000
2,23.250,0.00,-0.0003,-0.00020,2.000
2,23.375,0.00,-0.0003,-0.00020,2.000
2,23.500,0.00,-0.0003,-0.00020,2.000
2,23.625,0.01,-0.0003,-0.00020,2.000
2,23.750,0.00,-0.0003,-0.00020,2.000
2,23.875,0.00,-0.0003,-0.00020,2.000
2,24.000,0.00,-0.0003,-0.00020,2.000
2,24.125,0.00,-0.0003,-0.00020,2.000
2,24.250,0.00,-0.0002,-0.00010,2.000
2,24.375,0.00,-0.0002,-0.00010,2.000
2,24.500,0.00,-0.0002,-0.00010,2.000
2,24.625,0.00,-0.0002,-0.00010,2.000
2,24.750,0.00,-0.0002,-0.00010,2.000
2,24.875,0.00,-0.0002,-0.00010,2.000
2,25.000,0.00,-0.0002,-0.00010,2.000
2,25.125,0.00,-0.0002,-0.00010,2.000
2,25.250,0.01,-0.0002,-0.00010,2.000
2,25.375,0.01,-0.0002,-0.00010,2.000
2,25.500,0.00,-0.0002,-0.00010,2.000
2,25.625,0.00,-0.0002,-0.00010,2.000
2,25.750,0.01,-0.0002,-0.00010,2.000
2,25.875,0.00,-0.0002,-0.00010,2.000
2,26.000,0.00,-0.0002,-0.00010,2.000
3,26.375,0.00,0.1336,0.13365,3.000
3,26.500,0.00,0.2587,0.25880,3.000
3,26.625,0.00,0.3837,0.38380,3.000
3,26.750,0.00,0.5085,0.50860,3.000
3,26.875,0.00,0.6336,0.63370,3.000
3,27.000,0.00,0.7586,0.75870,3.000
3,27.125,0.00,0.8837,0.88380,3.000
3,27.250,0.00,1.0088,1.00890,3.000
3,27.375,0.00,1.1337,1.13380,3.000
3,27.500,0.00,1.2588,1.25890,3.000
3,27.625,0.00,1.3836,1.38375,3.000
3,27.750,0.00,1.5086,1.50870,3.000
3,27.875,0.01,1.6336,1.63370,3.000
3,28.000,0.03,1.7586,1.75870,3.000
3,28.125,0.06,1.8837,1.88380,3.000
3,28.250,0.13,2.0087,2.00880,3.000
3,28.375,0.28,2.1338,2.13390,3.000
3,28.500,0.51,2.2589,2.25900,3.000
3,28.625,0.83,2.3838,2.38390,3.000
3,28.750,1.26,2.5087,2.50880,3.000
3,28.875,1.79,2.6337,2.63380,3.000
3,29.000,2.44,2.7587,2.75880,3.000
3,29.125,3.26,2.8836,2.88375,3.000
3,29.250,4.26,3.0087,3.00880,3.000
3,29.375,5.45,3.1338,3.13390,3.000
3,29.500,6.84,3.2588,3.25890,3.000
3,29.625,8.45,3.3838,3.38390,3.000
3,29.750,10.30,3.5087,3.50880,3.000
3,29.875,12.37,3.6338,3.63385,3.000
3,30.000,14.66,3.7586,3.75870,3.000
3,30.125,17.22,3.8838,3.88385,3.000
3,30.250,20.09,4.0087,4.00880,3.000
3,30.375,23.31,4.1338,4.13390,3.000
3,30.500,26.91,4.2590,4.25910,3.000
3,30.625,30.98,4.3838,4.38395,3.000
3,30.750,35.69,4.5087,4.50880,3.000
3,30.875,41.22,4.6338,4.63385,3.000
3,31.000,47.94,4.7586,4.75870,3.000
3,31.250,39.65,4.7396,4.73970,3.000
3,31.375,29.85,4.6147,4.61480,3.000
3,31.500,23.18,4.4896,4.48970,3.000
3,31.625,18.21,4.3646,4.36470,3.000
3,31.750,14.43,4.2396,4.23970,3.000
3,31.875,11.51,4.1145,4.11460,3.000
3,32.000,9.24,3.9896,3.98970,3.000
3,32.125,7.47,3.8646,3.86475,3.000
3,32.250,6.12,3.7395,3.73960,3.000
3,32.375,5.03,3.6146,3.61465,3.000
3,32.500,4.15,3.4895,3.48960,3.000
3,32.625,3.41,3.3644,3.36455,3.000
3,32.750,2.79,3.2394,3.23950,3.000
3,32.875,2.23,3.1144,3.11455,3.000
3,33.000,1.75,2.9895,2.98960,3.000
3,33.125,1.33,2.8644,2.86445,3.000
3,33.250,0.98,2.7395,2.73960,3.000
3,33.375,0.69,2.6145,2.61455,3.000
3,33.500,0.45,2.4895,2.48960,3.000
3,33.625,0.26,2.3644,2.36455,3.000
3,33.750,0.12,2.2393,2.23940,3.000
3,33.875,0.04,2.1143,2.11440,3.000
3,34.000,0.02,1.9893,1.98940,3.000
3,34.125,0.01,1.8644,1.86450,3.000
3,34.250,0.00,1.7395,1.73960,3.000
3,34.375,0.00,1.6144,1.61445,3.000
3,34.500,0.00,1.4895,1.48960,3.000
3,34.625,0.00,1.3643,1.36440,3.000
3,34.750,0.00,1.2393,1.23940,3.000
3,34.875,0.00,1.1142,1.11435,3.000
3,35.000,0.00,0.9892,0.98930,3.000
3,35.125,0.00,0.8642,0.86430,3.000
3,35.250,0.00,0.7393,0.73940,3.000
3,35.375,0.00,0.6143,0.61440,3.000
3,35.500,0.00,0.4894,0.48950,3.000
3,35.625,0.00,0.3644,0.36445,3.000
3,35.750,0.00,0.2394,0.23950,3.000
3,35.875,0.00,0.1142,0.11435,3.000
3,36.000,0.00,-0.0108,-0.01070,3.000
3,36.188,0.00,-0.0002,-0.00010,3.000
3,36.312,0.00,-0.0002,-0.00010,3.000
3,36.438,0.00,-0.0002,-0.00010,3.000
3,36.562,0.00,-0.0002,-0.00010,3.000
3,36.688,0.00,-0.0002,-0.00010,3.000
3,36.812,0.00,-0.0002,-0.00010,3.000
3,36.938,0.00,-0.0002,-0.00010,3.000
3,37.062,0.00,-0.0002,-0.00010,3.000
3,37.188,0.00,-0.0002,-0.00010,3.000
3,37.312,0.00,-0.0002,-0.00010,3.000
3,37.438,0.00,-0.0002,-0.00010,3.000
3,37.562,0.00,-0.0002,-0.00010,3.000
3,37.688,0.00,-0.0002,-0.00010,3.000
3,37.812,0.00,-0.0002,-0.00010,3.000
3,37.938,0.00,-0.0002,-0.00010,3.000
3,38.062,0.00,-0.0002,-0.00010,3.000
3,38.188,0.00,-0.0002,-0.00010,3.000
3,38.312,0.00,-0.0002,-0.00010,3.000
3,38.438,0.00,-0.0002,-0.00010,3.000
3,38.562,0.00,-0.0002,-0.00010,3.000
3,38.688,0.00,-0.0002,-0.00010,3.000
3,38.812,0.00,-0.0002,-0.00010,3.000
3,38.938,0.00,-0.0002,-0.00010,3.000
3,39.062,0.00,-0.0002,-0.00010,3.000
4,39.438,-0.01,0.1292,0.12925,4.000
4,39.562,0.00,0.2542,0.25435,4.000
4,39.688,0.00,0.3792,0.37930,4.000
4,39.812,0.00,0.5040,0.50412,4.000
4,39.938,-0.01,0.6290,0.62908,4.000
4,40.062,-0.01,0.7541,0.75417,4.000
4,40.188,0.00,0.8790,0.87913,4.000
4,40.312,0.00,1.0041,1.00425,4.000
4,40.438,0.00,1.1292,1.12930,4.000
4,40.562,0.00,1.2542,1.25430,4.000
4,40.688,0.00,1.3791,1.37923,4.000
4,40.812,-0.01,1.5042,1.50427,4.000
4,40.938,0.00,1.6291,1.62918,4.000
4,41.062,0.02,1.7541,1.75425,4.000
4,41.188,0.05,1.8792,1.87933,4.000
4,41.312,0.12,2.0042,2.00430,4.000
4,41.438,0.26,2.1292,2.12930,4.000
4,41.562,0.48,2.2543,2.25440,4.000
4,41.688,0.80,2.3794,2.37950,4.000
4,41.812,1.21,2.5043,2.50437,4.000
4,41.938,1.74,2.6292,2.62933,4.000
4,42.062,2.39,2.7541,2.75422,4.000
4,42.188,3.20,2.8791,2.87920,4.000
4,42.312,4.19,3.0043,3.00440,4.000
4,42.438,5.37,3.1292,3.12933,4.000
4,42.562,6.75,3.2543,3.25440,4.000
4,42.688,8.35,3.3794,3.37945,4.000
4,42.812,10.18,3.5042,3.50435,4.000
4,42.938,12.24,3.6293,3.62940,4.000
4,43.062,14.52,3.7542,3.75430,4.000
4,43.188,17.08,3.8793,3.87938,4.000
4,43.312,19.92,4.0043,4.00440,4.000
4,43.438,23.11,4.1293,4.12938,4.000
4,43.562,26.67,4.2544,4.25450,4.000
4,43.688,30.69,4.3794,4.37948,4.000
4,43.812,35.32,4.5043,4.50437,4.000
4,43.938,40.76,4.6293,4.62935,4.000
4,44.062,47.35,4.7542,4.75435,4.000
4,44.312,38.28,4.7200,4.72010,4.000
4,44.438,28.95,4.5951,4.59517,4.000
4,44.562,22.51,4.4700,4.47010,4.000
4,44.688,17.72,4.3451,4.34520,4.000
4,44.812,14.05,4.2201,4.22023,4.000
4,44.938,11.23,4.0951,4.09522,4.000
4,45.062,9.01,3.9702,3.97025,4.000
4,45.188,7.29,3.8450,3.84515,4.000
4,45.312,5.96,3.7201,3.72018,4.000
4,45.438,4.90,3.5950,3.59507,4.000
4,45.562,4.02,3.4699,3.47003,4.000
4,45.688,3.30,3.3450,3.34507,4.000
4,45.812,2.69,3.2200,3.22008,4.000
4,45.938,2.15,3.0951,3.09525,4.000
4,46.062,1.67,2.9701,2.97018,4.000
4,46.188,1.26,2.8449,2.84500,4.000
4,46.312,0.91,2.7199,2.72000,4.000
4,46.438,0.64,2.5948,2.59490,4.000
4,46.562,0.41,2.4699,2.47003,4.000
4,46.688,0.23,2.3450,2.34507,4.000
4,46.812,0.09,2.2199,2.22003,4.000
4,46.938,0.03,2.0949,2.09502,4.000
4,47.062,0.01,1.9700,1.97005,4.000
4,47.188,0.00,1.8449,1.84505,4.000
4,47.312,0.00,1.7199,1.72003,4.000
4,47.438,-0.01,1.5947,1.59482,4.000
4,47.562,0.00,1.4698,1.46985,4.000
4,47.688,0.00,1.3448,1.34492,4.000
4,47.812,-0.01,1.2199,1.21998,4.000
4,47.938,0.00,1.0949,1.09497,4.000
4,48.062,0.00,0.9698,0.96993,4.000
4,48.188,0.00,0.8449,0.84500,4.000
4,48.312,-0.01,0.7198,0.71988,4.000
4,48.438,0.00,0.5948,0.59487,4.000
4,48.562,0.00,0.4697,0.46980,4.000
4,48.688,0.00,0.3449,0.34497,4.000
4,48.812,0.00,0.2198,0.21985,4.000
4,48.938,0.00,0.0948,0.09487,4.000
4,49.125,-0.01,-0.0403,-0.04020,4.000
4,49.250,0.00,-0.0002,-0.00010,4.000
4,49.375,0.00,-0.0002,-0.00010,4.000
4,49.500,0.00,-0.0002,-0.00010,4.000
4,49.625,0.00,-0.0002,-0.00010,4.000
4,49.750,-0.01,-0.0002,-0.00010,4.000
4,49.875,0.00,-0.0002,-0.00010,4.000
4,50.000,0.00,-0.0002,-0.00010,4.000
4,50.125,0.00,-0.0002,-0.00010,4.000
4,50.250,-0.01,-0.0002,-0.00010,4.000
4,50.375,-0.01,-0.0002,-0.00010,4.000
4,50.500,0.00,-0.0002,-0.00010,4.000
4,50.625,0.00,-0.0002,-0.00010,4.000
4,50.750,0.00,-0.0002,-0.00010,4.000
4,50.875,0.00,-0.0002,-0.00010,4.000
4,51.000,0.00,-0.0002,-0.00010,4.000
4,51.125,0.00,-0.0002,-0.00010,4.000
4,51.250,-0.01,-0.0002,-0.00010,4.000
4,51.375,0.00,-0.0002,-0.00010,4.000
4,51.500,0.00,-0.0002,-0.00010,4.000
4,51.625,0.00,-0.0002,-0.00010,4.000
4,51.750,0.00,-0.0002,-0.00010,4.000
4,51.875,0.00,-0.0002,-0.00010,4.000
4,52.000,0.00,-0.0002,-0.00010,4.000
5,52.375,0.00,0.0475,0.04765,5.000
5,52.500,0.00,0.1727,0.17280,5.000
5,52.625,0.00,0.2977,0.29780,5.000
5,52.750,0.00,0.4226,0.42270,5.000
5,52.875,0.00,0.5475,0.54760,5.000
5,53.000,0.00,0.6726,0.67270,5.000
5,53.125,-0.01,0.7975,0.79765,5.000
5,53.250,0.00,0.9225,0.92260,5.000
5,53.375,0.00,1.0477,1.04785,5.000
5,53.500,-0.01,1.1726,1.17270,5.000
5,53.625,0.00,1.2977,1.29780,5.000
5,53.750,0.00,1.4227,1.42280,5.000
5,53.875,0.00,1.5476,1.54775,5.000
5,54.000,0.01,1.6725,1.67260,5.000
5,54.125,0.03,1.7977,1.79780,5.000
5,54.250,0.07,1.9227,1.92280,5.000
5,54.375,0.15,2.0477,2.04785,5.000
5,54.500,0.32,2.1727,2.17280,5.000
5,54.625,0.58,2.2978,2.29790,5.000
5,54.750,0.92,2.4230,2.42310,5.000
5,54.875,1.37,2.5477,2.54785,5.000
5,55.000,1.94,2.6727,2.67280,5.000
5,55.125,2.64,2.7976,2.79775,5.000
5,55.250,3.51,2.9227,2.92280,5.000
5,55.375,4.56,3.0477,3.04785,5.000
5,55.500,5.81,3.1728,3.17290,5.000
5,55.625,7.25,3.2978,3.29790,5.000
5,55.750,8.94,3.4229,3.42300,5.000
5,55.875,10.85,3.5477,3.54780,5.000
5,56.000,13.00,3.6727,3.67280,5.000
5,56.125,15.37,3.7977,3.79780,5.000
5,56.250,18.02,3.9228,3.92290,5.000
5,56.375,20.97,4.0477,4.04780,5.000
5,56.500,24.27,4.1729,4.17300,5.000
5,56.625,27.98,4.2979,4.29800,5.000
5,56.750,32.18,4.4229,4.42300,5.000
5,56.875,37.07,4.5478,4.54790,5.000
5,57.000,42.85,4.6728,4.67290,5.000
5,57.125,49.95,4.7977,4.79780,5.000
5,57.312,40.99,4.7510,4.75110,5.000
5,57.438,30.67,4.6261,4.62620,5.000
5,57.562,23.74,4.5011,4.50118,5.000
5,57.688,18.66,4.3762,4.37627,5.000
5,57.812,14.78,4.2512,4.25133,5.000
5,57.938,11.78,4.1260,4.12607,5.000
5,58.062,9.45,4.0011,4.00115,5.000
5,58.188,7.62,3.8760,3.87612,5.000
5,58.312,6.22,3.7510,3.75113,5.000
5,58.438,5.11,3.6261,3.62617,5.000
5,58.562,4.19,3.5010,3.50113,5.000
5,58.688,3.44,3.3761,3.37617,5.000
5,58.812,2.82,3.2511,3.25115,5.000
5,58.938,2.25,3.1260,3.12607,5.000
5,59.062,1.77,3.0011,3.00115,5.000
5,59.188,1.35,2.8757,2.87585,5.000
5,59.312,0.98,2.7508,2.75093,5.000
5,59.438,0.69,2.6258,2.62592,5.000
5,59.562,0.46,2.5009,2.50103,5.000
5,59.688,0.26,2.3760,2.37610,5.000
5,59.812,0.12,2.2509,2.25100,5.000
5,59.938,0.04,2.1259,2.12602,5.000
5,60.062,0.02,2.0008,2.00088,5.000
5,60.188,0.01,1.8758,1.87590,5.000
5,60.312,0.00,1.7509,1.75100,5.000
5,60.438,0.00,1.6258,1.62587,5.000
5,60.562,-0.01,1.5009,1.50100,5.000
5,60.688,0.00,1.3758,1.37595,5.000
5,60.812,0.00,1.2508,1.25093,5.000
5,60.938,0.00,1.1259,1.12600,5.000
5,61.062,0.00,1.0008,1.00093,5.000
5,61.188,-0.01,0.8756,0.87575,5.000
5,61.312,0.00,0.7508,0.75085,5.000
5,61.438,-0.01,0.6257,0.62580,5.000
5,61.562,0.00,0.5008,0.50090,5.000
5,61.688,-0.01,0.3759,0.37600,5.000
5,61.812,0.00,0.2508,0.25093,5.000
5,61.938,0.00,0.1258,0.12593,5.000
5,62.062,0.00,0.0008,0.00088,5.000
5,62.250,0.00,-0.0002,-0.00010,5.000
5,62.375,0.00,-0.0003,-0.00020,5.000
5,62.500,-0.01,-0.0002,-0.00010,5.000
5,62.625,0.00,-0.0002,-0.00010,5.000
5,62.750,-0.01,-0.0002,-0.00010,5.000
5,62.875,-0.01,-0.0002,-0.00010,5.000
5,63.000,0.00,-0.0002,-0.00010,5.000
5,63.125,-0.01,-0.0002,-0.00010,5.000
5,63.250,-0.01,-0.0002,-0.00010,5.000
5,63.375,0.00,-0.0002,-0.00010,5.000
5,63.500,0.00,-0.0002,-0.00010,5.000
5,63.625,0.00,-0.0002,-0.00010,5.000
5,63.750,-0.01,-0.0002,-0.00010,5.000
5,63.875,0.00,-0.0002,-0.00010,5.000
5,64.000,0.00,-0.0002,-0.00010,5.000
5,64.125,0.00,-0.0002,-0.00010,5.000
5,64.250,-0.01,-0.0002,-0.00010,5.000
5,64.375,0.00,-0.0002,-0.00010,5.000
5,64.500,0.00,-0.0002,-0.00010,5.000
5,64.625,0.00,-0.0002,-0.00010,5.000
5,64.750,0.00,-0.0002,-0.00010,5.000
5,64.875,-0.01,-0.0002,-0.00010,5.000
5,65.000,-0.01,-0.0002,-0.00010,5.000
5,65.125,-0.01,-0.0002,-0.00010,5.000
6,65.500,0.01,0.1326,0.13270,6.000
6,65.625,0.00,0.2577,0.25780,6.000
6,65.750,0.01,0.3827,0.38280,6.000
6,65.875,0.01,0.5075,0.50760,6.000
6,66.000,0.00,0.6325,0.63260,6.000
6,66.125,0.01,0.7576,0.75765,6.000
6,66.250,0.01,0.8826,0.88270,6.000
6,66.375,0.00,1.0078,1.00785,6.000
6,66.500,0.00,1.1328,1.13290,6.000
6,66.625,0.01,1.2577,1.25780,6.000
6,66.750,0.01,1.3827,1.38280,6.000
6,66.875,0.00,1.5077,1.50780,6.000
6,67.000,0.01,1.6326,1.63270,6.000
6,67.125,0.03,1.7577,1.75780,6.000
6,67.250,0.06,1.8828,1.88290,6.000
6,67.375,0.12,2.0076,2.00775,6.000
6,67.500,0.26,2.1328,2.13290,6.000
6,67.625,0.49,2.2578,2.25790,6.000
6,67.750,0.80,2.3829,2.38300,6.000
6,67.875,1.21,2.5077,2.50785,6.000
6,68.000,1.74,2.6326,2.63270,6.000
6,68.125,2.40,2.7576,2.75775,6.000
6,68.250,3.20,2.8827,2.88280,6.000
6,68.375,4.20,3.0077,3.00785,6.000
6,68.500,5.37,3.1328,3.13290,6.000
6,68.625,6.76,3.2578,3.25790,6.000
6,68.750,8.36,3.3829,3.38300,6.000
6,68.875,10.20,3.5077,3.50780,6.000
6,69.000,12.27,3.6327,3.63280,6.000
6,69.125,14.56,3.7577,3.75775,6.000
6,69.250,17.11,3.8826,3.88270,6.000
6,69.375,19.96,4.0077,4.00785,6.000
6,69.500,23.14,4.1328,4.13290,6.000
6,69.625,26.70,4.2579,4.25800,6.000
6,69.750,30.74,4.3829,4.38300,6.000
6,69.875,35.35,4.5078,4.50785,6.000
6,70.000,40.78,4.6329,4.63300,6.000
6,70.125,47.34,4.7578,4.75785,6.000
6,70.312,46.52,4.8008,4.80088,6.000
6,70.438,33.96,4.6761,4.67618,6.000
6,70.562,26.05,4.5511,4.55118,6.000
6,70.688,20.38,4.4260,4.42610,6.000
6,70.812,16.10,4.3012,4.30130,6.000
6,70.938,12.82,4.1761,4.17623,6.000
6,71.062,10.26,4.0511,4.05120,6.000
6,71.188,8.27,3.9260,3.92613,6.000
6,71.312,6.72,3.8010,3.80110,6.000
6,71.438,5.51,3.6760,3.67610,6.000
6,71.562,4.53,3.5509,3.55100,6.000
6,71.688,3.71,3.4260,3.42610,6.000
6,71.812,3.05,3.3010,3.30105,6.000
6,71.938,2.46,3.1760,3.17610,6.000
6,72.062,1.96,3.0511,3.05118,6.000
6,72.188,1.51,2.9258,2.92595,6.000
6,72.312,1.12,2.8008,2.80090,6.000
6,72.438,0.80,2.6759,2.67598,6.000
6,72.562,0.55,2.5508,2.55090,6.000
6,72.688,0.34,2.4260,2.42608,6.000
6,72.812,0.18,2.3010,2.30110,6.000
6,72.938,0.07,2.1759,2.17600,6.000
6,73.062,0.03,2.0509,2.05098,6.000
6,73.188,0.02,1.9258,1.92588,6.000
6,73.312,0.01,1.8009,1.80100,6.000
6,73.438,0.00,1.6758,1.67590,6.000
6,73.562,0.00,1.5508,1.55093,6.000
6,73.688,0.00,1.4258,1.42595,6.000
6,73.812,0.00,1.3008,1.30093,6.000
6,73.938,0.00,1.1759,1.17598,6.000
6,74.062,0.00,1.0509,1.05100,6.000
6,74.188,0.00,0.9259,0.92598,6.000
6,74.312,0.00,0.8008,0.80090,6.000
6,74.438,0.00,0.6757,0.67582,6.000
6,74.562,0.01,0.5506,0.55073,6.000
6,74.688,0.01,0.4257,0.42580,6.000
6,74.812,0.00,0.3009,0.30098,6.000
6,74.938,0.00,0.1758,0.17590,6.000
6,75.062,0.00,0.0508,0.05090,6.000
6,75.250,0.01,-0.0227,-0.02260,6.000
6,75.375,0.00,-0.0003,-0.00020,6.000
6,75.500,0.00,-0.0003,-0.00020,6.000
6,75.625,0.00,-0.0003,-0.00020,6.000
6,75.750,0.00,-0.0003,-0.00020,6.000
6,75.875,0.00,-0.0003,-0.00020,6.000
6,76.000,0.00,-0.0003,-0.00020,6.000
6,76.125,0.01,-0.0003,-0.00020,6.000
6,76.250,0.00,-0.0003,-0.00020,6.000
6,76.375,0.00,-0.0003,-0.00020,6.000
6,76.500,0.00,-0.0003,-0.00020,6.000
6,76.625,0.01,-0.0003,-0.00020,6.000
6,76.750,0.00,-0.0003,-0.00020,6.000
6,76.875,0.01,-0.0002,-0.00010,6.000
6,77.000,0.01,-0.0002,-0.00010,6.000
6,77.125,0.00,-0.0002,-0.00010,6.000
6,77.250,0.01,-0.0002,-0.00010,6.000
6,77.375,0.01,-0.0002,-0.00010,6.000
6,77.500,0.00,-0.0002,-0.00010,6.000
6,77.625,0.00,-0.0002,-0.00010,6.000
6,77.750,0.00,-0.0002,-0.00010,6.000
6,77.875,0.00,-0.0002,-0.00010,6.000
6,78.000,0.00,-0.0002,-0.00010,6.000
6,78.125,0.00,-0.0002,-0.00010,6.000
7,78.500,0.00,0.0715,0.07160,7.000
7,78.625,0.00,0.1966,0.19665,7.000
7,78.750,0.00,0.3216,0.32170,7.000
7,78.875,0.00,0.4467,0.44675,7.000
7,79.000,0.00,0.5717,0.57180,7.000
7,79.125,0.00,0.6967,0.69680,7.000
7,79.250,0.00,0.8217,0.82180,7.000
7,79.375,0.00,0.9466,0.94675,7.000
7,79.500,0.00,1.0717,1.07180,7.000
7,79.625,0.00,1.1966,1.19665,7.000
7,79.750,0.00,1.3216,1.32170,7.000
7,79.875,0.00,1.4468,1.44685,7.000
7,80.000,0.00,1.5717,1.57180,7.000
7,80.125,0.01,1.6968,1.69690,7.000
7,80.250,0.04,1.8218,1.82190,7.000
7,80.375,0.08,1.9468,1.94685,7.000
7,80.500,0.18,2.0717,2.07180,7.000
7,80.625,0.36,2.1967,2.19680,7.000
7,80.750,0.63,2.3218,2.32190,7.000
7,80.875,0.99,2.4468,2.44690,7.000
7,81.000,1.45,2.5717,2.57180,7.000
7,81.125,2.04,2.6968,2.69690,7.000
7,81.250,2.77,2.8218,2.82190,7.000
7,81.375,3.68,2.9468,2.94685,7.000
7,81.500,4.75,3.0718,3.07190,7.000
7,81.625,6.04,3.1968,3.19685,7.000
7,81.750,7.53,3.3217,3.32180,7.000
7,81.875,9.25,3.4467,3.44680,7.000
7,82.000,11.19,3.5717,3.57180,7.000
7,82.125,13.37,3.6969,3.69695,7.000
7,82.250,15.80,3.8219,3.82200,7.000
7,82.375,18.49,3.9469,3.94695,7.000
7,82.500,21.51,4.0719,4.07200,7.000
7,82.625,24.87,4.1968,4.19690,7.000
7,82.750,28.64,4.3218,4.32190,7.000
7,82.875,32.92,4.4467,4.44680,7.000
7,83.000,37.87,4.5719,4.57200,7.000
7,83.125,43.80,4.6969,4.69700,7.000
7,83.250,51.11,4.8218,4.82190,7.000
7,83.438,40.34,4.7550,4.75510,7.000
7,83.562,30.29,4.6301,4.63023,7.000
7,83.688,23.51,4.5052,4.50525,7.000
7,83.812,18.47,4.3801,4.38023,7.000
7,83.938,14.64,4.2552,4.25530,7.000
7,84.062,11.68,4.1301,4.13023,7.000
7,84.188,9.36,4.0050,4.00508,7.000
7,84.312,7.57,3.8800,3.88013,7.000
7,84.438,6.19,3.7550,3.75515,7.000
7,84.562,5.09,3.6300,3.63010,7.000
7,84.688,4.17,3.5050,3.50510,7.000
7,84.812,3.43,3.3800,3.38005,7.000
7,84.938,2.80,3.2551,3.25520,7.000
7,85.062,2.24,3.1301,3.13015,7.000
7,85.188,1.76,3.0050,3.00505,7.000
7,85.312,1.34,2.8798,2.87985,7.000
7,85.438,0.98,2.7549,2.75498,7.000
7,85.562,0.69,2.6299,2.62995,7.000
7,85.688,0.46,2.5050,2.50505,7.000
7,85.812,0.27,2.3800,2.38013,7.000
7,85.938,0.13,2.2550,2.25510,7.000
7,86.062,0.04,2.1300,2.13005,7.000
7,86.188,0.02,2.0048,2.00485,7.000
7,86.312,0.01,1.8798,1.87985,7.000
7,86.438,0.00,1.7549,1.75500,7.000
7,86.562,0.00,1.6298,1.62990,7.000
7,86.688,0.00,1.5049,1.50495,7.000
7,86.812,0.00,1.3798,1.37993,7.000
7,86.938,0.00,1.2549,1.25500,7.000
7,87.062,0.00,1.1299,1.12998,7.000
7,87.188,0.00,1.0049,1.00498,7.000
7,87.312,0.01,0.8799,0.87995,7.000
7,87.438,0.00,0.7547,0.75478,7.000
7,87.562,0.00,0.6298,0.62988,7.000
7,87.688,0.00,0.5048,0.50487,7.000
7,87.812,0.00,0.3799,0.38000,7.000
7,87.938,0.00,0.2549,0.25500,7.000
7,88.062,0.00,0.1299,0.12998,7.000
7,88.188,0.00,0.0048,0.00490,7.000
7,88.375,0.00,-0.0002,-0.00015,7.000
7,88.500,0.00,-0.0003,-0.00020,7.000
7,88.625,0.00,-0.0003,-0.00020,7.000
7,88.750,0.00,-0.0003,-0.00020,7.000
7,88.875,0.00,-0.0003,-0.00020,7.000
7,89.000,0.00,-0.0003,-0.00020,7.000
7,89.125,0.00,-0.0003,-0.00020,7.000
7,89.250,0.00,-0.0003,-0.00020,7.000
7,89.375,0.00,-0.0003,-0.00020,7.000
7,89.500,0.00,-0.0003,-0.00020,7.000
7,89.625,0.00,-0.0003,-0.00020,7.000
7,89.750,0.00,-0.0003,-0.00020,7.000
7,89.875,0.00,-0.0003,-0.00020,7.000
7,90.000,0.00,-0.0003,-0.00020,7.000
7,90.125,0.00,-0.0002,-0.00010,7.000
7,90.250,0.00,-0.0002,-0.00010,7.000
7,90.375,0.00,-0.0002,-0.00010,7.000
7,90.500,0.00,-0.0002,-0.00010,7.000
7,90.625,0.00,-0.0002,-0.00010,7.000
7,90.750,0.00,-0.0002,-0.00010,7.000
7,90.875,0.00,-0.0002,-0.00010,7.000
7,91.000,0.00,-0.0002,-0.00010,7.000
7,91.125,0.00,-0.0002,-0.00010,7.000
7,91.250,0.00,-0.0002,-0.00010,7.000
8,91.625,0.00,0.1266,0.12670,8.000
8,91.750,0.00,0.2517,0.25180,8.000
8,91.875,0.00,0.3768,0.37685,8.000
8,92.000,0.00,0.5016,0.50170,8.000
8,92.125,0.00,0.6266,0.62670,8.000
8,92.250,0.01,0.7515,0.75160,8.000
8,92.375,0.00,0.8766,0.87665,8.000
8,92.500,0.00,1.0017,1.00180,8.000
8,92.625,0.00,1.1267,1.12680,8.000
8,92.750,0.00,1.2517,1.25180,8.000
8,92.875,0.01,1.3767,1.37680,8.000
8,93.000,0.00,1.5018,1.50190,8.000
8,93.125,0.01,1.6267,1.62680,8.000
8,93.250,0.03,1.7517,1.75180,8.000
8,93.375,0.05,1.8768,1.87685,8.000
8,93.500,0.12,2.0016,2.00170,8.000
8,93.625,0.25,2.1268,2.12685,8.000
8,93.750,0.46,2.2519,2.25200,8.000
8,93.875,0.77,2.3769,2.37700,8.000
8,94.000,1.17,2.5018,2.50190,8.000
8,94.125,1.68,2.6268,2.62690,8.000
8,94.250,2.33,2.7517,2.75180,8.000
8,94.375,3.12,2.8766,2.87675,8.000
8,94.500,4.10,3.0017,3.00180,8.000
8,94.625,5.27,3.1268,3.12685,8.000
8,94.750,6.64,3.2517,3.25180,8.000
8,94.875,8.23,3.3768,3.37690,8.000
8,95.000,10.05,3.5017,3.50180,8.000
8,95.125,12.10,3.6268,3.62695,8.000
8,95.250,14.38,3.7518,3.75190,8.000
8,95.375,16.91,3.8768,3.87690,8.000
8,95.500,19.74,4.0017,4.00180,8.000
8,95.625,22.90,4.1268,4.12685,8.000
8,95.750,26.42,4.2518,4.25190,8.000
8,95.875,30.39,4.3768,4.37695,8.000
8,96.000,34.93,4.5019,4.50200,8.000
8,96.125,40.27,4.6268,4.62695,8.000
8,96.250,46.72,4.7518,4.75190,8.000
8,96.438,49.14,4.8250,4.82515,8.000
8,96.562,35.29,4.7002,4.70033,8.000
8,96.688,27.00,4.5752,4.57528,8.000
8,96.812,21.08,4.4501,4.45015,8.000
8,96.938,16.64,4.3250,4.32515,8.000
8,97.062,13.23,4.2000,4.20013,8.000
8,97.188,10.58,4.0751,4.07518,8.000
8,97.312,8.50,3.9501,3.95023,8.000
8,97.438,6.91,3.8252,3.82525,8.000
8,97.562,5.66,3.7002,3.70028,8.000
8,97.688,4.64,3.5751,3.57518,8.000
8,97.812,3.81,3.4500,3.45008,8.000
8,97.938,3.13,3.3249,3.32502,8.000
8,98.062,2.54,3.1999,3.20003,8.000
8,98.188,2.02,3.0750,3.07508,8.000
8,98.312,1.56,2.9500,2.95008,8.000
8,98.438,1.17,2.8249,2.82500,8.000
8,98.562,0.84,2.7000,2.70010,8.000
8,98.688,0.58,2.5750,2.57508,8.000
8,98.812,0.36,2.4501,2.45015,8.000
8,98.938,0.19,2.3249,2.32502,8.000
8,99.062,0.08,2.1998,2.19990,8.000
8,99.188,0.03,2.0748,2.07495,8.000
8,99.312,0.02,1.9499,1.94998,8.000
8,99.438,0.01,1.8250,1.82508,8.000
8,99.562,0.00,1.6999,1.70000,8.000
8,99.688,0.00,1.5749,1.57500,8.000
8,99.812,0.00,1.4499,1.44998,8.000
8,99.938,0.00,1.3248,1.32488,8.000
8,100.062,0.00,1.1997,1.19983,8.000
8,100.188,0.00,1.0747,1.07482,8.000
8,100.312,0.00,0.9498,0.94985,8.000
8,100.438,0.00,0.8248,0.82488,8.000
8,100.562,0.00,0.6998,0.69985,8.000
8,100.688,0.00,0.5749,0.57498,8.000
8,100.812,0.00,0.4499,0.44998,8.000
8,100.938,0.00,0.3249,0.32502,8.000
8,101.062,0.00,0.1998,0.19985,8.000
8,101.188,0.00,0.0747,0.07480,8.000
8,101.375,0.00,-0.0430,-0.04290,8.000
8,101.500,0.00,-0.0003,-0.00020,8.000
8,101.625,0.00,-0.0003,-0.00020,8.000
8,101.750,0.01,-0.0003,-0.00020,8.000
8,101.875,0.00,-0.0003,-0.00020,8.000
8,102.000,0.00,-0.0003,-0.00020,8.000
8,102.125,0.00,-0.0003,-0.00020,8.000
8,102.250,0.00,-0.0003,-0.00020,8.000
8,102.375,0.00,-0.0003,-0.00020,8.000
8,102.500,0.01,-0.0003,-0.00020,8.000
8,102.625,0.00,-0.0003,-0.00020,8.000
8,102.750,0.00,-0.0003,-0.00020,8.000
8,102.875,0.00,-0.0003,-0.00020,8.000
8,103.000,0.00,-0.0003,-0.00020,8.000
8,103.125,0.00,-0.0002,-0.00015,8.000
8,103.250,0.00,-0.0002,-0.00010,8.000
8,103.375,0.00,-0.0002,-0.00010,8.000
8,103.500,0.00,-0.0002,-0.00010,8.000
8,103.625,0.00,-0.0002,-0.00010,8.000
8,103.750,0.00,-0.0002,-0.00010,8.000
8,103.875,0.00,-0.0002,-0.00010,8.000
8,104.000,0.00,-0.0002,-0.00010,8.000
8,104.125,0.00,-0.0002,-0.00010,8.000
8,104.250,0.00,-0.0002,-0.00010,8.000
9,104.625,0.00,0.0666,0.06665,9.000
9,104.750,0.00,0.1916,0.19170,9.000
9,104.875,0.00,0.3166,0.31675,9.000
9,105.000,0.00,0.4416,0.44170,9.000
9,105.125,0.00,0.5666,0.56670,9.000
9,105.250,0.00,0.6917,0.69180,9.000
9,105.375,0.00,0.8167,0.81680,9.000
9,105.500,0.00,0.9418,0.94190,9.000
9,105.625,0.00,1.0667,1.06680,9.000
9,105.750,0.01,1.1915,1.19160,9.000
9,105.875,0.00,1.3166,1.31675,9.000
9,106.000,0.00,1.4416,1.44170,9.000
9,106.125,0.00,1.5666,1.56675,9.000
9,106.250,0.01,1.6918,1.69190,9.000
9,106.375,0.03,1.8168,1.81695,9.000
9,106.500,0.08,1.9419,1.94200,9.000
9,106.625,0.17,2.0668,2.06690,9.000
9,106.750,0.34,2.1917,2.19180,9.000
9,106.875,0.61,2.3168,2.31685,9.000
9,107.000,0.96,2.4418,2.44190,9.000
9,107.125,1.42,2.5668,2.56685,9.000
9,107.250,1.99,2.6917,2.69180,9.000
9,107.375,2.71,2.8168,2.81690,9.000
9,107.500,3.60,2.9419,2.94200,9.000
9,107.625,4.67,3.0668,3.06695,9.000
9,107.750,5.94,3.1918,3.19190,9.000
9,107.875,7.42,3.3167,3.31680,9.000
9,108.000,9.12,3.4418,3.44190,9.000
9,108.125,11.06,3.5666,3.56675,9.000
9,108.250,13.23,3.6918,3.69190,9.000
9,108.375,15.64,3.8168,3.81690,9.000
9,108.500,18.31,3.9420,3.94210,9.000
9,108.625,21.30,4.0668,4.06690,9.000
9,108.750,24.65,4.1919,4.19200,9.000
9,108.875,28.40,4.3169,4.31695,9.000
9,109.000,32.64,4.4417,4.44180,9.000
9,109.125,37.56,4.5668,4.56690,9.000
9,109.250,43.38,4.6919,4.69200,9.000
9,109.375,50.58,4.8168,4.81690,9.000
9,109.562,41.48,4.7700,4.77008,9.000
9,109.688,31.02,4.6451,4.64520,9.000
9,109.812,24.01,4.5200,4.52005,9.000
9,109.938,18.86,4.3950,4.39510,9.000
9,110.062,14.93,4.2702,4.27028,9.000
9,110.188,11.90,4.1452,4.14528,9.000
9,110.312,9.54,4.0201,4.02020,9.000
9,110.438,7.70,3.8951,3.89523,9.000
9,110.562,6.29,3.7701,3.77018,9.000
9,110.688,5.16,3.6450,3.64505,9.000
9,110.812,4.23,3.5199,3.52000,9.000
9,110.938,3.48,3.3949,3.39500,9.000
9,111.062,2.85,3.2700,3.27005,9.000
9,111.188,2.28,3.1450,3.14510,9.000
9,111.312,1.80,3.0201,3.02020,9.000
9,111.438,1.37,2.8949,2.89500,9.000
9,111.562,1.01,2.7700,2.77005,9.000
9,111.688,0.72,2.6448,2.64495,9.000
9,111.812,0.48,2.5199,2.51998,9.000
9,111.938,0.28,2.3950,2.39505,9.000
9,112.062,0.14,2.2699,2.27003,9.000
9,112.188,0.05,2.1449,2.14500,9.000
9,112.312,0.03,2.0199,2.01995,9.000
9,112.438,0.01,1.8949,1.89500,9.000
9,112.562,0.01,1.7700,1.77005,9.000
9,112.688,0.00,1.6448,1.64485,9.000
9,112.812,0.00,1.5198,1.51993,9.000
9,112.938,0.00,1.3948,1.39490,9.000
9,113.062,0.00,1.2698,1.26985,9.000
9,113.188,0.00,1.1449,1.14495,9.000
9,113.312,0.00,1.0199,1.02000,9.000
9,113.438,0.00,0.8949,0.89498,9.000
9,113.562,0.00,0.7698,0.76990,9.000
9,113.688,0.00,0.6447,0.64485,9.000
9,113.812,0.00,0.5197,0.51980,9.000
9,113.938,0.00,0.3948,0.39485,9.000
9,114.062,0.00,0.2698,0.26990,9.000
9,114.188,0.00,0.1448,0.14488,9.000
9,114.312,0.00,0.0198,0.01990,9.000
9,114.500,0.00,-0.0006,-0.00050,9.000
9,114.625,0.00,-0.0003,-0.00020,9.000
9,114.750,0.00,-0.0003,-0.00020,9.000
9,114.875,0.00,-0.0003,-0.00020,9.000
9,115.000,0.00,-0.0003,-0.00020,9.000
9,115.125,0.00,-0.0003,-0.00020,9.000
9,115.250,0.00,-0.0003,-0.00020,9.000
9,115.375,0.00,-0.0003,-0.00020,9.000
9,115.500,0.00,-0.0003,-0.00020,9.000
9,115.625,0.00,-0.0003,-0.00020,9.000
9,115.750,0.00,-0.0003,-0.00020,9.000
9,115.875,0.00,-0.0003,-0.00020,9.000
9,116.000,0.00,-0.0003,-0.00020,9.000
9,116.125,0.00,-0.0003,-0.00020,9.000
9,116.250,0.01,-0.0003,-0.00020,9.000
9,116.375,0.00,-0.0002,-0.00010,9.000
9,116.500,0.00,-0.0002,-0.00010,9.000
9,116.625,0.00,-0.0002,-0.00010,9.000
9,116.750,0.00,-0.0002,-0.00010,9.000
9,116.875,0.00,-0.0002,-0.00010,9.000
9,117.000,0.00,-0.0002,-0.00010,9.000
9,117.125,0.00,-0.0002,-0.00010,9.000
9,117.250,0.00,-0.0002,-0.00010,9.000
9,117.375,0.00,-0.0002,-0.00010,9.000
10,117.688,0.00,0.0492,0.04930,10.000
10,117.812,0.00,0.1742,0.17427,10.000
10,117.938,0.00,0.2992,0.29930,10.000
10,118.062,0.00,0.4242,0.42432,10.000
10,118.188,0.00,0.5491,0.54915,10.000
10,118.312,0.00,0.6741,0.67420,10.000
10,118.438,0.00,0.7991,0.79918,10.000
10,118.562,0.00,0.9242,0.92430,10.000
10,118.688,0.00,1.0493,1.04938,10.000
10,118.812,0.00,1.1742,1.17430,10.000
10,118.938,0.00,1.2992,1.29930,10.000
10,119.062,0.00,1.4242,1.42435,10.000
10,119.188,0.00,1.5492,1.54930,10.000
10,119.312,0.01,1.6742,1.67435,10.000
10,119.438,0.03,1.7992,1.79925,10.000
10,119.562,0.07,1.9242,1.92430,10.000
10,119.688,0.15,2.0493,2.04943,10.000
10,119.812,0.31,2.1742,2.17435,10.000
10,119.938,0.56,2.2993,2.29943,10.000
10,120.062,0.90,2.4244,2.42447,10.000
10,120.188,1.34,2.5493,2.54943,10.000
10,120.312,1.90,2.6742,2.67430,10.000
10,120.438,2.59,2.7992,2.79930,10.000
10,120.562,3.45,2.9241,2.92425,10.000
10,120.688,4.50,3.0493,3.04938,10.000
10,120.812,5.74,3.1742,3.17435,10.000
10,120.938,7.18,3.2994,3.29945,10.000
10,121.062,8.86,3.4243,3.42440,10.000
10,121.188,10.76,3.5492,3.54933,10.000
10,121.312,12.91,3.6743,3.67445,10.000
10,121.438,15.28,3.7992,3.79935,10.000
10,121.562,17.91,3.9242,3.92432,10.000
10,121.688,20.85,4.0492,4.04935,10.000
10,121.812,24.14,4.1744,4.17447,10.000
10,121.938,27.82,4.2994,4.29955,10.000
10,122.062,31.98,4.4243,4.42445,10.000
10,122.188,36.78,4.5494,4.54947,10.000
10,122.312,42.45,4.6744,4.67447,10.000
10,122.438,49.40,4.7992,4.79930,10.000
10,122.625,42.55,4.7776,4.77770,10.000
10,122.750,31.66,4.6526,4.65270,10.000
10,122.875,24.48,4.5276,4.52765,10.000
10,123.000,19.21,4.4025,4.40260,10.000
10,123.125,15.20,4.2776,4.27765,10.000
10,123.250,12.12,4.1527,4.15280,10.000
10,123.375,9.71,4.0276,4.02770,10.000
10,123.500,7.82,3.9027,3.90280,10.000
10,123.625,6.38,3.7776,3.77770,10.000
10,123.750,5.23,3.6526,3.65270,10.000
10,123.875,4.29,3.5274,3.52750,10.000
10,124.000,3.51,3.4024,3.40250,10.000
10,124.125,2.88,3.2774,3.27750,10.000
10,124.250,2.31,3.1525,3.15260,10.000
10,124.375,1.82,3.0276,3.02765,10.000
10,124.500,1.39,2.9025,2.90260,10.000
10,124.625,1.03,2.7775,2.77755,10.000
10,124.750,0.73,2.6524,2.65250,10.000
10,124.875,0.49,2.5274,2.52750,10.000
10,125.000,0.29,2.4023,2.40240,10.000
10,125.125,0.14,2.2774,2.27745,10.000
10,125.250,0.05,2.1524,2.15250,10.000
10,125.375,0.03,2.0274,2.02750,10.000
10,125.500,0.01,1.9024,1.90250,10.000
10,125.625,0.01,1.7776,1.77765,10.000
10,125.750,0.00,1.6523,1.65240,10.000
10,125.875,0.00,1.5274,1.52745,10.000
10,126.000,0.00,1.4022,1.40230,10.000
10,126.125,0.00,1.2773,1.27740,10.000
10,126.250,0.00,1.1523,1.15240,10.000
10,126.375,0.00,1.0274,1.02745,10.000
10,126.500,0.00,0.9024,0.90250,10.000
10,126.625,0.00,0.7774,0.77745,10.000
10,126.750,0.00,0.6524,0.65250,10.000
10,126.875,0.00,0.5273,0.52735,10.000
10,127.000,0.00,0.4023,0.40240,10.000
10,127.125,0.00,0.2773,0.27735,10.000
10,127.250,0.00,0.1522,0.15230,10.000
10,127.375,0.00,0.0272,0.02730,10.000
10,127.625,0.00,-0.0003,-0.00020,10.000
10,127.750,0.00,-0.0003,-0.00020,10.000
10,127.875,0.00,-0.0003,-0.00020,10.000
10,128.000,0.00,-0.0003,-0.00020,10.000
10,128.125,0.00,-0.0003,-0.00020,10.000
10,128.250,0.00,-0.0003,-0.00020,10.000
10,128.375,0.00,-0.0003,-0.00020,10.000
10,128.500,0.00,-0.0003,-0.00020,10.000
10,128.625,0.00,-0.0003,-0.00020,10.000
10,128.750,0.00,-0.0003,-0.00020,10.000
10,128.875,0.00,-0.0003,-0.00020,10.000
10,129.000,0.00,-0.0003,-0.00020,10.000
10,129.125,0.00,-0.0003,-0.00020,10.000
10,129.250,0.00,-0.0003,-0.00020,10.000
10,129.375,0.00,-0.0003,-0.00020,10.000
10,129.500,0.00,-0.0002,-0.00010,10.000
10,129.625,0.00,-0.0002,-0.00010,10.000
10,129.750,0.00,-0.0002,-0.00010,10.000
10,129.875,0.00,-0.0002,-0.00010,10.000
10,130.000,0.00,-0.0002,-0.00010,10.000
10,130.125,0.00,-0.0002,-0.00010,10.000
10,130.250,0.01,-0.0002,-0.00010,10.000
10,130.375,0.00,-0.0002,-0.00010,10.000
10,130.500,0.00,-0.0002,-0.00010,10.000