File: AIME_journal_files/AIME_data/calibDATA_loadcell/date_02:22:2018/Instron/50N_0_1_4_0.txt
""
"Test Method","Radhen_Load_Cntrl_Cmprsn_250N_12-7.msm"
"Sample I. D.","Sample1.mss"
"Specimen Number","17"

"TheCycle_Output ()","_Time (s)","_Load (N)","_Extension (mm)","RealTimeDepth (mm)","CycleNumber ()"

1,0.312,0.00,0.1040,0.10405,1.000
1,0.438,-0.01,0.2294,0.22938,1.000
1,0.562,0.00,0.3543,0.35435,1.000
1,0.688,0.00,0.4794,0.47940,1.000
1,0.812,-0.01,0.6043,0.60430,1.000
1,0.938,0.00,0.7293,0.72932,1.000
1,1.062,0.00,0.8544,0.85435,1.000
1,1.188,0.00,0.9793,0.97933,1.000
1,1.312,0.00,1.1043,1.10430,1.000
1,1.438,0.00,1.2294,1.22938,1.000
1,1.562,0.00,1.3544,1.35435,1.000
1,1.688,0.00,1.4794,1.47940,1.000
1,1.812,0.00,1.6045,1.60448,1.000
1,1.938,0.00,1.7294,1.72942,1.000
1,2.062,0.00,1.8544,1.85442,1.000
1,2.188,0.03,1.9794,1.97940,1.000
1,2.312,0.06,2.1043,2.10432,1.000
1,2.438,0.11,2.2294,2.22938,1.000
1,2.562,0.19,2.3544,2.35440,1.000
1,2.688,0.32,2.4794,2.47940,1.000
1,2.812,0.54,2.6045,2.60448,1.000
1,2.938,0.84,2.7296,2.72960,1.000
1,3.062,1.25,2.8545,2.85445,1.000
1,3.188,1.78,2.9794,2.97942,1.000
1,3.312,2.41,3.1043,3.10430,1.000
1,3.438,3.20,3.2294,3.22938,1.000
1,3.562,4.15,3.3545,3.35450,1.000
1,3.688,5.29,3.4794,3.47938,1.000
1,3.812,6.63,3.6044,3.60442,1.000
1,3.938,8.20,3.7294,3.72945,1.000
1,4.062,10.03,3.8544,3.85445,1.000
1,4.188,12.11,3.9794,3.97942,1.000
1,4.312,14.46,4.1044,4.10445,1.000
1,4.438,17.11,4.2293,4.22932,1.000
1,4.562,20.12,4.3543,4.35432,1.000
1,4.688,23.53,4.4793,4.47930,1.000
1,4.812,27.43,4.6044,4.60445,1.000
1,4.938,31.93,4.7295,4.72948,1.000
1,5.062,37.17,4.8545,4.85450,1.000
1,5.188,43.29,4.9794,4.97942,1.000
1,5.312,50.50,5.1044,5.10445,1.000
1,5.500,39.74,5.0325,5.03250,1.000
1,5.625,30.21,4.9076,4.90765,1.000
1,5.750,23.59,4.7826,4.78260,1.000
1,5.875,18.63,4.6578,4.65775,1.000
1,6.000,14.84,4.5327,4.53270,1.000
1,6.125,11.92,4.4076,4.40765,1.000
1,6.250,9.62,4.2826,4.28260,1.000
1,6.375,7.82,4.1576,4.15760,1.000
1,6.500,6.38,4.0325,4.03250,1.000
1,6.625,5.20,3.9076,3.90755,1.000
1,6.750,4.28,3.7824,3.78240,1.000
1,6.875,3.50,3.6576,3.65755,1.000
1,7.000,2.84,3.5326,3.53260,1.000
1,7.125,2.29,3.4076,3.40760,1.000
1,7.250,1.81,3.2827,3.28270,1.000
1,7.375,1.38,3.1574,3.15745,1.000
1,7.500,1.02,3.0324,3.03240,1.000
1,7.625,0.71,2.9074,2.90740,1.000
1,7.750,0.47,2.7824,2.78240,1.000
1,7.875,0.28,2.6575,2.65750,1.000
1,8.000,0.15,2.5324,2.53240,1.000
1,8.125,0.08,2.4076,2.40755,1.000
1,8.250,0.04,2.2825,2.28250,1.000
1,8.375,0.01,2.1575,2.15745,1.000
1,8.500,0.01,2.0325,2.03250,1.000
1,8.625,0.00,1.9074,1.90735,1.000
1,8.750,-0.01,1.7822,1.78220,1.000
1,8.875,0.00,1.6573,1.65730,1.000
1,9.000,0.00,1.5324,1.53240,1.000
1,9.125,0.00,1.4074,1.40740,1.000
1,9.250,-0.01,1.2824,1.28240,1.000
1,9.375,0.00,1.1574,1.15740,1.000
1,9.500,-0.01,1.0324,1.03240,1.000
1,9.625,0.00,0.9074,0.90735,1.000
1,9.750,-0.01,0.7822,0.78220,1.000
1,9.875,0.00,0.6573,0.65725,1.000
1,10.000,0.00,0.5322,0.53220,1.000
1,10.125,-0.01,0.4073,0.40730,1.000
1,10.250,-0.01,0.2824,0.28240,1.000
1,10.375,0.00,0.1574,0.15735,1.000
1,10.500,0.00,0.0322,0.03220,1.000
1,10.688,-0.01,0.0004,0.00038,1.000
1,10.812,0.00,-0.0002,-0.00020,1.000
1,10.938,0.00,-0.0002,-0.00020,1.000
1,11.062,0.00,-0.0002,-0.00020,1.000
1,11.188,0.00,-0.0002,-0.00020,1.000
1,11.312,-0.01,-0.0002,-0.00020,1.000
1,11.438,0.00,-0.0002,-0.00020,1.000
1,11.562,0.00,-0.0002,-0.00020,1.000
1,11.688,0.00,-0.0002,-0.00020,1.000
1,11.812,0.00,-0.0002,-0.00020,1.000
1,11.938,0.00,-0.0002,-0.00020,1.000
1,12.062,0.00,-0.0002,-0.00020,1.000
1,12.188,0.00,-0.0002,-0.00020,1.000
1,12.312,0.00,-0.0002,-0.00020,1.000
1,12.438,0.00,-0.0002,-0.00020,1.000
1,12.562,0.00,-0.0002,-0.00020,1.000
1,12.688,0.00,-0.0002,-0.00020,1.000
1,12.812,-0.01,-0.0002,-0.00020,1.000
1,12.938,0.00,-0.0002,-0.00020,1.000
1,13.062,0.00,-0.0002,-0.00020,1.000
1,13.188,0.00,-0.0002,-0.00020,1.000
1,13.312,0.00,-0.0002,-0.00020,1.000
1,13.438,0.00,-0.0002,-0.00020,1.000
1,13.562,0.00,-0.0002,-0.00020,1.000
2,13.875,0.00,0.0664,0.06640,2.000
2,14.000,0.00,0.1916,0.19160,2.000
2,14.125,0.00,0.3167,0.31670,2.000
2,14.250,0.00,0.4417,0.44170,2.000
2,14.375,0.00,0.5666,0.56665,2.000
2,14.500,0.00,0.6917,0.69170,2.000
2,14.625,0.00,0.8166,0.81665,2.000
2,14.750,0.00,0.9415,0.94150,2.000
2,14.875,0.00,1.0666,1.06665,2.000
2,15.000,0.00,1.1917,1.19170,2.000
2,15.125,0.00,1.3167,1.31675,2.000
2,15.250,0.00,1.4417,1.44170,2.000
2,15.375,0.00,1.5667,1.56675,2.000
2,15.500,0.00,1.6919,1.69190,2.000
2,15.625,0.00,1.8167,1.81675,2.000
2,15.750,0.02,1.9416,1.94160,2.000
2,15.875,0.05,2.0666,2.06660,2.000
2,16.000,0.09,2.1917,2.19170,2.000
2,16.125,0.14,2.3168,2.31675,2.000
2,16.250,0.24,2.4419,2.44190,2.000
2,16.375,0.41,2.5668,2.56675,2.000
2,16.500,0.67,2.6919,2.69190,2.000
2,16.625,1.03,2.8168,2.81680,2.000
2,16.750,1.50,2.9417,2.94170,2.000
2,16.875,2.08,3.0668,3.06675,2.000
2,17.000,2.81,3.1917,3.19170,2.000
2,17.125,3.71,3.3169,3.31685,2.000
2,17.250,4.77,3.4419,3.44190,2.000
2,17.375,6.05,3.5668,3.56680,2.000
2,17.500,7.54,3.6919,3.69190,2.000
2,17.625,9.28,3.8168,3.81680,2.000
2,17.750,11.27,3.9417,3.94170,2.000
2,17.875,13.52,4.0668,4.06675,2.000
2,18.000,16.06,4.1917,4.19170,2.000
2,18.125,18.94,4.3168,4.31675,2.000
2,18.250,22.19,4.4418,4.44180,2.000
2,18.375,25.87,4.5669,4.56685,2.000
2,18.500,30.08,4.6919,4.69190,2.000
2,18.625,34.95,4.8168,4.81680,2.000
2,18.750,40.71,4.9419,4.94190,2.000
2,18.875,47.71,5.0668,5.06680,2.000
2,19.062,47.23,5.1098,5.10980,2.000
2,19.188,34.81,4.9852,4.98515,2.000
2,19.312,26.91,4.8601,4.86012,2.000
2,19.438,21.16,4.7352,4.73520,2.000
2,19.562,16.81,4.6102,4.61020,2.000
2,19.688,13.45,4.4851,4.48505,2.000
2,19.812,10.83,4.3601,4.36012,2.000
2,19.938,8.77,4.2350,4.23495,2.000
2,20.062,7.14,4.1099,4.10995,2.000
2,20.188,5.83,3.9850,3.98500,2.000
2,20.312,4.78,3.8600,3.86000,2.000
2,20.438,3.92,3.7350,3.73500,2.000
2,20.562,3.19,3.6100,3.61000,2.000
2,20.688,2.59,3.4850,3.48500,2.000
2,20.812,2.07,3.3600,3.36002,2.000
2,20.938,1.61,3.2349,3.23488,2.000
2,21.062,1.21,3.1099,3.10990,2.000
2,21.188,0.88,2.9849,2.98488,2.000
2,21.312,0.59,2.8598,2.85982,2.000
2,21.438,0.37,2.7351,2.73508,2.000
2,21.562,0.21,2.6099,2.60990,2.000
2,21.688,0.11,2.4849,2.48490,2.000
2,21.812,0.05,2.3599,2.35995,2.000
2,21.938,0.03,2.2349,2.23485,2.000
2,22.062,0.01,2.1098,2.10985,2.000
2,22.188,0.00,1.9848,1.98480,2.000
2,22.312,0.00,1.8597,1.85975,2.000
2,22.438,0.00,1.7349,1.73485,2.000
2,22.562,0.00,1.6098,1.60980,2.000
2,22.688,0.00,1.4849,1.48488,2.000
2,22.812,-0.01,1.3598,1.35985,2.000
2,22.938,0.00,1.2349,1.23485,2.000
2,23.062,0.00,1.1098,1.10982,2.000
2,23.188,0.00,0.9847,0.98473,2.000
2,23.312,0.00,0.8598,0.85980,2.000
2,23.438,0.00,0.7348,0.73483,2.000
2,23.562,0.00,0.6097,0.60972,2.000
2,23.688,0.00,0.4848,0.48480,2.000
2,23.812,0.00,0.3598,0.35980,2.000
2,23.938,0.00,0.2349,0.23490,2.000
2,24.062,0.00,0.1097,0.10968,2.000
2,24.188,0.00,-0.0153,-0.01535,2.000
2,24.375,0.00,-0.0003,-0.00030,2.000
2,24.500,0.00,-0.0002,-0.00020,2.000
2,24.625,0.00,-0.0002,-0.00020,2.000
2,24.750,0.00,-0.0002,-0.00020,2.000
2,24.875,0.00,-0.0002,-0.00020,2.000
2,25.000,0.00,-0.0002,-0.00020,2.000
2,25.125,0.00,-0.0002,-0.00020,2.000
2,25.250,0.00,-0.0002,-0.00020,2.000
2,25.375,0.00,-0.0002,-0.00020,2.000
2,25.500,0.00,-0.0002,-0.00020,2.000
2,25.625,0.00,-0.0002,-0.00020,2.000
2,25.750,0.00,-0.0002,-0.00020,2.000
2,25.875,0.00,-0.0002,-0.00020,2.000
2,26.000,0.00,-0.0002,-0.00020,2.000
2,26.125,0.00,-0.0002,-0.00020,2.000
2,26.250,0.00,-0.0002,-0.00020,2.000
2,26.375,0.00,-0.0002,-0.00020,2.000
2,26.500,0.00,-0.0002,-0.00020,2.000
2,26.625,0.00,-0.0002,-0.00020,2.000
2,26.750,0.00,-0.0002,-0.00020,2.000
2,26.875,0.00,-0.0002,-0.00020,2.000
2,27.000,0.00,-0.0002,-0.00020,2.000
2,27.125,0.00,-0.0002,-0.00020,2.000
2,27.250,0.00,-0.0002,-0.00020,2.000
3,27.562,0.00,0.1140,0.11410,3.000
3,27.688,0.00,0.2392,0.23930,3.000
3,27.812,0.00,0.3641,0.36422,3.000
3,27.938,0.00,0.4892,0.48930,3.000
3,28.062,0.00,0.6141,0.61420,3.000
3,28.188,0.00,0.7390,0.73915,3.000
3,28.312,0.00,0.8641,0.86420,3.000
3,28.438,0.00,0.9891,0.98920,3.000
3,28.562,0.00,1.1142,1.11432,3.000
3,28.688,0.00,1.2393,1.23940,3.000
3,28.812,-0.01,1.3642,1.36430,3.000
3,28.938,0.00,1.4892,1.48932,3.000
3,29.062,0.00,1.6142,1.61435,3.000
3,29.188,0.00,1.7391,1.73925,3.000
3,29.312,0.00,1.8642,1.86427,3.000
3,29.438,0.02,1.9891,1.98920,3.000
3,29.562,0.05,2.1141,2.11425,3.000
3,29.688,0.09,2.2392,2.23935,3.000
3,29.812,0.16,2.3643,2.36440,3.000
3,29.938,0.28,2.4893,2.48945,3.000
3,30.062,0.48,2.6143,2.61437,3.000
3,30.188,0.78,2.7394,2.73950,3.000
3,30.312,1.17,2.8642,2.86430,3.000
3,30.438,1.68,2.9892,2.98930,3.000
3,30.562,2.32,3.1142,3.11432,3.000
3,30.688,3.11,3.2393,3.23937,3.000
3,30.812,4.06,3.3644,3.36452,3.000
3,30.938,5.20,3.4893,3.48940,3.000
3,31.062,6.54,3.6143,3.61440,3.000
3,31.188,8.12,3.7393,3.73940,3.000
3,31.312,9.96,3.8642,3.86435,3.000
3,31.438,12.05,3.9892,3.98932,3.000
3,31.562,14.40,4.1143,4.11437,3.000
3,31.688,17.06,4.2392,4.23930,3.000
3,31.812,20.07,4.3642,4.36435,3.000
3,31.938,23.46,4.4893,4.48937,3.000
3,32.062,27.30,4.6144,4.61447,3.000
3,32.188,31.72,4.7394,4.73948,3.000
3,32.312,36.83,4.8643,4.86445,3.000
3,32.438,42.93,4.9893,4.98935,3.000
3,32.562,50.45,5.1143,5.11440,3.000
3,32.750,41.54,5.0625,5.06260,3.000
3,32.875,31.42,4.9377,4.93775,3.000
3,33.000,24.49,4.8126,4.81270,3.000
3,33.125,19.36,4.6877,4.68775,3.000
3,33.250,15.43,4.5627,4.56280,3.000
3,33.375,12.39,4.4374,4.43755,3.000
3,33.500,10.00,4.3124,4.31250,3.000
3,33.625,8.12,4.1874,4.18755,3.000
3,33.750,6.61,4.0626,4.06270,3.000
3,33.875,5.39,3.9376,3.93765,3.000
3,34.000,4.42,3.8125,3.81260,3.000
3,34.125,3.61,3.6875,3.68760,3.000
3,34.250,2.93,3.5624,3.56250,3.000
3,34.375,2.37,3.4374,3.43750,3.000
3,34.500,1.88,3.3123,3.31240,3.000
3,34.625,1.44,3.1874,3.18750,3.000
3,34.750,1.08,3.0625,3.06260,3.000
3,34.875,0.76,2.9374,2.93750,3.000
3,35.000,0.49,2.8125,2.81260,3.000
3,35.125,0.30,2.6876,2.68770,3.000
3,35.250,0.16,2.5625,2.56260,3.000
3,35.375,0.08,2.4374,2.43750,3.000
3,35.500,0.04,2.3123,2.31240,3.000
3,35.625,0.02,2.1872,2.18735,3.000
3,35.750,0.01,2.0623,2.06240,3.000
3,35.875,0.00,1.9373,1.93740,3.000
3,36.000,0.00,1.8124,1.81250,3.000
3,36.125,-0.01,1.6873,1.68740,3.000
3,36.250,0.00,1.5624,1.56250,3.000
3,36.375,0.00,1.4373,1.43740,3.000
3,36.500,-0.01,1.3123,1.31240,3.000
3,36.625,0.00,1.1873,1.18740,3.000
3,36.750,-0.01,1.0622,1.06230,3.000
3,36.875,0.00,0.9372,0.93735,3.000
3,37.000,0.00,0.8124,0.81250,3.000
3,37.125,0.00,0.6874,0.68745,3.000
3,37.250,0.00,0.5622,0.56230,3.000
3,37.375,0.00,0.4372,0.43735,3.000
3,37.500,0.00,0.3122,0.31230,3.000
3,37.625,0.00,0.1873,0.18740,3.000
3,37.750,0.00,0.0620,0.06210,3.000
3,37.938,0.00,-0.0115,-0.01137,3.000
3,38.062,0.00,-0.0002,-0.00010,3.000
3,38.188,0.00,-0.0002,-0.00010,3.000
3,38.312,0.00,-0.0002,-0.00010,3.000
3,38.438,0.00,-0.0002,-0.00010,3.000
3,38.562,0.00,-0.0002,-0.00010,3.000
3,38.688,0.00,-0.0002,-0.00010,3.000
3,38.812,0.00,-0.0002,-0.00010,3.000
3,38.938,0.00,-0.0002,-0.00010,3.000
3,39.062,0.00,-0.0002,-0.00010,3.000
3,39.188,0.00,-0.0002,-0.00010,3.000
3,39.312,0.00,-0.0002,-0.00010,3.000
3,39.438,0.00,-0.0002,-0.00010,3.000
3,39.562,0.00,-0.0002,-0.00010,3.000
3,39.688,0.00,-0.0002,-0.00010,3.000
3,39.812,0.00,-0.0002,-0.00010,3.000
3,39.938,0.00,-0.0002,-0.00010,3.000
3,40.062,0.00,-0.0002,-0.00010,3.000
3,40.188,0.00,-0.0002,-0.00010,3.000
3,40.312,0.00,-0.0002,-0.00010,3.000
3,40.438,0.00,-0.0002,-0.00010,3.000
3,40.562,-0.01,-0.0002,-0.00010,3.000
3,40.688,0.00,-0.0002,-0.00010,3.000
3,40.812,0.00,-0.0002,-0.00010,3.000
4,41.188,-0.01,0.0860,0.08608,4.000
4,41.312,-0.01,0.2112,0.21127,4.000
4,41.438,0.00,0.3361,0.33618,4.000
4,41.562,-0.01,0.4610,0.46112,4.000
4,41.688,-0.01,0.5860,0.58613,4.000
4,41.812,-0.01,0.7110,0.71115,4.000
4,41.938,-0.01,0.8362,0.83633,4.000
4,42.062,0.00,0.9612,0.96132,4.000
4,42.188,-0.01,1.0863,1.08638,4.000
4,42.312,-0.01,1.2112,1.21132,4.000
4,42.438,-0.01,1.3362,1.33625,4.000
4,42.562,-0.01,1.4611,1.46120,4.000
4,42.688,-0.01,1.5861,1.58620,4.000
4,42.812,-0.01,1.7111,1.71125,4.000
4,42.938,-0.01,1.8362,1.83630,4.000
4,43.062,0.01,1.9613,1.96140,4.000
4,43.188,0.03,2.0863,2.08635,4.000
4,43.312,0.08,2.2113,2.21137,4.000
4,43.438,0.13,2.3362,2.33633,4.000
4,43.562,0.24,2.4612,2.46130,4.000
4,43.688,0.42,2.5862,2.58625,4.000
4,43.812,0.69,2.7112,2.71135,4.000
4,43.938,1.06,2.8363,2.83638,4.000
4,44.062,1.54,2.9613,2.96140,4.000
4,44.188,2.14,3.0864,3.08645,4.000
4,44.312,2.89,3.2113,3.21142,4.000
4,44.438,3.81,3.3364,3.33650,4.000
4,44.562,4.90,3.4613,3.46137,4.000
4,44.688,6.20,3.5863,3.58635,4.000
4,44.812,7.73,3.7112,3.71132,4.000
4,44.938,9.51,3.8362,3.83628,4.000
4,45.062,11.54,3.9612,3.96135,4.000
4,45.188,13.83,4.0862,4.08633,4.000
4,45.312,16.42,4.2114,4.21147,4.000
4,45.438,19.35,4.3363,4.33640,4.000
4,45.562,22.66,4.4612,4.46127,4.000
4,45.688,26.37,4.5862,4.58628,4.000
4,45.812,30.63,4.7112,4.71130,4.000
4,45.938,35.56,4.8362,4.83630,4.000
4,46.062,41.38,4.9612,4.96135,4.000
4,46.188,48.46,5.0864,5.08648,4.000
4,46.375,44.24,5.0866,5.08665,4.000
4,46.500,33.08,4.9616,4.96170,4.000
4,46.625,25.70,4.8366,4.83665,4.000
4,46.750,20.26,4.7115,4.71160,4.000
4,46.875,16.12,4.5866,4.58665,4.000
4,47.000,12.92,4.4616,4.46170,4.000
4,47.125,10.41,4.3366,4.33665,4.000
4,47.250,8.43,4.2115,4.21160,4.000
4,47.375,6.86,4.0866,4.08670,4.000
4,47.500,5.59,3.9615,3.96160,4.000
4,47.625,4.58,3.8364,3.83650,4.000
4,47.750,3.74,3.7113,3.71140,4.000
4,47.875,3.04,3.5864,3.58650,4.000
4,48.000,2.46,3.4616,3.46170,4.000
4,48.125,1.95,3.3366,3.33665,4.000
4,48.250,1.51,3.2115,3.21160,4.000
4,48.375,1.13,3.0865,3.08655,4.000
4,48.500,0.80,2.9614,2.96150,4.000
4,48.625,0.53,2.8364,2.83645,4.000
4,48.750,0.33,2.7114,2.71150,4.000
4,48.875,0.18,2.5863,2.58635,4.000
4,49.000,0.09,2.4613,2.46140,4.000
4,49.125,0.04,2.3364,2.33650,4.000
4,49.250,0.02,2.2113,2.21140,4.000
4,49.375,0.01,2.0864,2.08645,4.000
4,49.500,0.00,1.9614,1.96150,4.000
4,49.625,-0.01,1.8364,1.83645,4.000
4,49.750,-0.01,1.7113,1.71140,4.000
4,49.875,0.00,1.5863,1.58635,4.000
4,50.000,0.00,1.4613,1.46140,4.000
4,50.125,-0.01,1.3363,1.33640,4.000
4,50.250,-0.01,1.2114,1.21150,4.000
4,50.375,-0.01,1.0864,1.08645,4.000
4,50.500,-0.01,0.9614,0.96150,4.000
4,50.625,-0.01,0.8363,0.83640,4.000
4,50.750,0.00,0.7112,0.71130,4.000
4,50.875,-0.01,0.5862,0.58625,4.000
4,51.000,-0.01,0.4611,0.46120,4.000
4,51.125,0.00,0.3362,0.33630,4.000
4,51.250,-0.01,0.2114,0.21150,4.000
4,51.375,-0.01,0.0863,0.08635,4.000
4,51.562,-0.01,-0.0362,-0.03605,4.000
4,51.688,-0.01,-0.0003,-0.00020,4.000
4,51.812,-0.01,-0.0003,-0.00020,4.000
4,51.938,0.00,-0.0003,-0.00020,4.000
4,52.062,-0.01,-0.0003,-0.00020,4.000
4,52.188,-0.01,-0.0003,-0.00020,4.000
4,52.312,-0.01,-0.0003,-0.00020,4.000
4,52.438,0.00,-0.0003,-0.00020,4.000
4,52.562,-0.01,-0.0003,-0.00020,4.000
4,52.688,-0.01,-0.0003,-0.00020,4.000
4,52.812,0.00,-0.0003,-0.00020,4.000
4,52.938,0.00,-0.0002,-0.00010,4.000
4,53.062,0.00,-0.0002,-0.00010,4.000
4,53.188,0.00,-0.0002,-0.00010,4.000
4,53.312,-0.01,-0.0002,-0.00010,4.000
4,53.438,-0.01,-0.0002,-0.00010,4.000
4,53.562,0.00,-0.0002,-0.00010,4.000
4,53.688,0.00,-0.0002,-0.00010,4.000
4,53.812,-0.01,-0.0002,-0.00010,4.000
4,53.938,-0.01,-0.0002,-0.00010,4.000
4,54.062,0.00,-0.0002,-0.00010,4.000
4,54.188,0.00,-0.0002,-0.00010,4.000
4,54.312,0.00,-0.0002,-0.00010,4.000
4,54.438,-0.01,-0.0002,-0.00010,4.000
5,54.812,0.00,0.0840,0.08407,5.000
5,54.938,0.01,0.2092,0.20930,5.000
5,55.062,0.01,0.3342,0.33432,5.000
5,55.188,0.01,0.4591,0.45915,5.000
5,55.312,0.01,0.5840,0.58412,5.000
5,55.438,0.01,0.7091,0.70918,5.000
5,55.562,0.01,0.8342,0.83430,5.000
5,55.688,0.01,0.9591,0.95923,5.000
5,55.812,0.01,1.0843,1.08437,5.000
5,55.938,0.01,1.2093,1.20940,5.000
5,56.062,0.01,1.3342,1.33435,5.000
5,56.188,0.01,1.4591,1.45923,5.000
5,56.312,0.01,1.5841,1.58422,5.000
5,56.438,0.01,1.7091,1.70920,5.000
5,56.562,0.01,1.8342,1.83430,5.000
5,56.688,0.02,1.9592,1.95933,5.000
5,56.812,0.05,2.0843,2.08440,5.000
5,56.938,0.08,2.2093,2.20940,5.000
5,57.062,0.14,2.3343,2.33445,5.000
5,57.188,0.24,2.4592,2.45933,5.000
5,57.312,0.42,2.5842,2.58435,5.000
5,57.438,0.69,2.7093,2.70935,5.000
5,57.562,1.05,2.8342,2.83430,5.000
5,57.688,1.53,2.9593,2.95938,5.000
5,57.812,2.13,3.0843,3.08442,5.000
5,57.938,2.87,3.2094,3.20948,5.000
5,58.062,3.79,3.3344,3.33455,5.000
5,58.188,4.88,3.4593,3.45935,5.000
5,58.312,6.17,3.5842,3.58432,5.000
5,58.438,7.69,3.7092,3.70933,5.000
5,58.562,9.46,3.8342,3.83430,5.000
5,58.688,11.49,3.9593,3.95938,5.000
5,58.812,13.77,4.0843,4.08440,5.000
5,58.938,16.36,4.2093,4.20943,5.000
5,59.062,19.28,4.3343,4.33445,5.000
5,59.188,22.58,4.4592,4.45933,5.000
5,59.312,26.29,4.5843,4.58445,5.000
5,59.438,30.52,4.7093,4.70935,5.000
5,59.562,35.42,4.8342,4.83432,5.000
5,59.688,41.20,4.9593,4.95938,5.000
5,59.812,48.26,5.0843,5.08440,5.000
5,60.000,43.09,5.0726,5.07270,5.000
5,60.125,32.36,4.9476,4.94770,5.000
5,60.250,25.18,4.8226,4.82270,5.000
5,60.375,19.88,4.6977,4.69775,5.000
5,60.500,15.83,4.5727,4.57280,5.000
5,60.625,12.71,4.4476,4.44765,5.000
5,60.750,10.25,4.3226,4.32270,5.000
5,60.875,8.31,4.1975,4.19755,5.000
5,61.000,6.75,4.0725,4.07260,5.000
5,61.125,5.50,3.9475,3.94760,5.000
5,61.250,4.49,3.8225,3.82260,5.000
5,61.375,3.67,3.6975,3.69755,5.000
5,61.500,2.98,3.5725,3.57260,5.000
5,61.625,2.41,3.4475,3.44760,5.000
5,61.750,1.91,3.3226,3.32270,5.000
5,61.875,1.46,3.1974,3.19750,5.000
5,62.000,1.09,3.0724,3.07250,5.000
5,62.125,0.77,2.9473,2.94740,5.000
5,62.250,0.50,2.8224,2.82250,5.000
5,62.375,0.31,2.6976,2.69765,5.000
5,62.500,0.17,2.5724,2.57250,5.000
5,62.625,0.09,2.4475,2.44760,5.000
5,62.750,0.05,2.3224,2.32250,5.000
5,62.875,0.02,2.1974,2.19745,5.000
5,63.000,0.02,2.0722,2.07230,5.000
5,63.125,0.00,1.9473,1.94735,5.000
5,63.250,0.00,1.8223,1.82240,5.000
5,63.375,0.00,1.6973,1.69740,5.000
5,63.500,0.00,1.5724,1.57250,5.000
5,63.625,0.00,1.4474,1.44745,5.000
5,63.750,0.00,1.3223,1.32240,5.000
5,63.875,0.00,1.1974,1.19750,5.000
5,64.000,0.00,1.0722,1.07230,5.000
5,64.125,0.00,0.9472,0.94735,5.000
5,64.250,0.00,0.8223,0.82240,5.000
5,64.375,0.01,0.6972,0.69735,5.000
5,64.500,0.01,0.5723,0.57240,5.000
5,64.625,0.00,0.4473,0.44740,5.000
5,64.750,0.01,0.3224,0.32250,5.000
5,64.875,0.01,0.1974,0.19750,5.000
5,65.000,0.01,0.0722,0.07230,5.000
5,65.188,0.01,-0.0204,-0.02035,5.000
5,65.312,0.00,-0.0003,-0.00020,5.000
5,65.438,0.00,-0.0002,-0.00010,5.000
5,65.562,0.01,-0.0002,-0.00010,5.000
5,65.688,0.00,-0.0002,-0.00010,5.000
5,65.812,0.01,-0.0002,-0.00010,5.000
5,65.938,0.00,-0.0002,-0.00010,5.000
5,66.062,0.00,-0.0002,-0.00010,5.000
5,66.188,0.00,-0.0002,-0.00010,5.000
5,66.312,0.00,-0.0002,-0.00010,5.000
5,66.438,0.01,-0.0002,-0.00010,5.000
5,66.562,0.00,-0.0002,-0.00010,5.000
5,66.688,0.01,-0.0002,-0.00010,5.000
5,66.812,0.01,-0.0002,-0.00010,5.000
5,66.938,0.00,-0.0002,-0.00010,5.000
5,67.062,0.00,-0.0002,-0.00010,5.000
5,67.188,0.00,-0.0002,-0.00010,5.000
5,67.312,0.01,-0.0002,-0.00010,5.000
5,67.438,0.00,-0.0002,-0.00010,5.000
5,67.562,0.00,-0.0002,-0.00010,5.000
5,67.688,0.01,-0.0002,-0.00010,5.000
5,67.812,0.01,-0.0002,-0.00010,5.000
5,67.938,0.00,-0.0002,-0.00010,5.000
5,68.062,0.00,-0.0002,-0.00010,5.000
6,68.438,0.02,0.0760,0.07605,6.000
6,68.562,0.02,0.2011,0.20125,6.000
6,68.688,0.02,0.3262,0.32630,6.000
6,68.812,0.02,0.4511,0.45120,6.000
6,68.938,0.02,0.5760,0.57615,6.000
6,69.062,0.02,0.7011,0.70120,6.000
6,69.188,0.02,0.8261,0.82620,6.000
6,69.312,0.02,0.9511,0.95122,6.000
6,69.438,0.01,1.0762,1.07628,6.000
6,69.562,0.02,1.2013,1.20142,6.000
6,69.688,0.02,1.3262,1.32632,6.000
6,69.812,0.02,1.4512,1.45135,6.000
6,69.938,0.02,1.5762,1.57625,6.000
6,70.062,0.02,1.7012,1.70130,6.000
6,70.188,0.01,1.8262,1.82625,6.000
6,70.312,0.03,1.9511,1.95122,6.000
6,70.438,0.06,2.0762,2.07628,6.000
6,70.562,0.09,2.2011,2.20125,6.000
6,70.688,0.14,2.3262,2.32630,6.000
6,70.812,0.25,2.4513,2.45145,6.000
6,70.938,0.41,2.5762,2.57632,6.000
6,71.062,0.68,2.7014,2.70147,6.000
6,71.188,1.04,2.8262,2.82632,6.000
6,71.312,1.50,2.9512,2.95130,6.000
6,71.438,2.09,3.0763,3.07638,6.000
6,71.562,2.83,3.2012,3.20135,6.000
6,71.688,3.73,3.3265,3.32655,6.000
6,71.812,4.81,3.4514,3.45150,6.000
6,71.938,6.09,3.5764,3.57650,6.000
6,72.062,7.59,3.7013,3.70140,6.000
6,72.188,9.35,3.8263,3.82640,6.000
6,72.312,11.36,3.9512,3.95132,6.000
6,72.438,13.63,4.0763,4.07637,6.000
6,72.562,16.19,4.2013,4.20140,6.000
6,72.688,19.09,4.3263,4.32638,6.000
6,72.812,22.35,4.4513,4.45137,6.000
6,72.938,26.03,4.5763,4.57640,6.000
6,73.062,30.22,4.7013,4.70145,6.000
6,73.188,35.07,4.8263,4.82638,6.000
6,73.312,40.78,4.9513,4.95137,6.000
6,73.438,47.74,5.0763,5.07640,6.000
6,73.625,47.13,5.1144,5.11445,6.000
6,73.750,34.77,4.9896,4.98970,6.000
6,73.875,26.92,4.8646,4.86470,6.000
6,74.000,21.20,4.7396,4.73970,6.000
6,74.125,16.86,4.6148,4.61485,6.000
6,74.250,13.51,4.4895,4.48960,6.000
6,74.375,10.89,4.3646,4.36465,6.000
6,74.500,8.82,4.2394,4.23950,6.000
6,74.625,7.17,4.1144,4.11455,6.000
6,74.750,5.84,3.9896,3.98970,6.000
6,74.875,4.77,3.8644,3.86455,6.000
6,75.000,3.91,3.7396,3.73970,6.000
6,75.125,3.19,3.6145,3.61455,6.000
6,75.250,2.57,3.4895,3.48960,6.000
6,75.375,2.08,3.3646,3.36465,6.000
6,75.500,1.62,3.2395,3.23960,6.000
6,75.625,1.22,3.1144,3.11450,6.000
6,75.750,0.89,2.9893,2.98940,6.000
6,75.875,0.60,2.8643,2.86440,6.000
6,76.000,0.38,2.7395,2.73960,6.000
6,76.125,0.22,2.6144,2.61450,6.000
6,76.250,0.13,2.4894,2.48950,6.000
6,76.375,0.07,2.3644,2.36455,6.000
6,76.500,0.04,2.2393,2.23940,6.000
6,76.625,0.03,2.1143,2.11440,6.000
6,76.750,0.02,1.9892,1.98930,6.000
6,76.875,0.02,1.8643,1.86440,6.000
6,77.000,0.01,1.7393,1.73940,6.000
6,77.125,0.02,1.6144,1.61445,6.000
6,77.250,0.02,1.4893,1.48940,6.000
6,77.375,0.02,1.3644,1.36445,6.000
6,77.500,0.02,1.2394,1.23950,6.000
6,77.625,0.02,1.1143,1.11440,6.000
6,77.750,0.02,0.9892,0.98930,6.000
6,77.875,0.02,0.8643,0.86435,6.000
6,78.000,0.02,0.7392,0.73930,6.000
6,78.125,0.02,0.6143,0.61435,6.000
6,78.250,0.02,0.4892,0.48930,6.000
6,78.375,0.02,0.3642,0.36435,6.000
6,78.500,0.02,0.2394,0.23950,6.000
6,78.625,0.02,0.1142,0.11430,6.000
6,78.750,0.02,-0.0109,-0.01080,6.000
6,78.938,0.02,-0.0003,-0.00020,6.000
6,79.062,0.02,-0.0003,-0.00020,6.000
6,79.188,0.02,-0.0003,-0.00020,6.000
6,79.312,0.02,-0.0003,-0.00020,6.000
6,79.438,0.02,-0.0003,-0.00020,6.000
6,79.562,0.02,-0.0003,-0.00020,6.000
6,79.688,0.02,-0.0003,-0.00020,6.000
6,79.812,0.02,-0.0003,-0.00020,6.000
6,79.938,0.02,-0.0003,-0.00020,6.000
6,80.062,0.01,-0.0003,-0.00020,6.000
6,80.188,0.02,-0.0003,-0.00020,6.000
6,80.312,0.02,-0.0003,-0.00020,6.000
6,80.438,0.02,-0.0003,-0.00020,6.000
6,80.562,0.02,-0.0002,-0.00010,6.000
6,80.688,0.02,-0.0002,-0.00010,6.000
6,80.812,0.02,-0.0002,-0.00010,6.000
6,80.938,0.02,-0.0002,-0.00010,6.000
6,81.062,0.02,-0.0002,-0.00010,6.000
6,81.188,0.02,-0.0002,-0.00010,6.000
6,81.312,0.02,-0.0002,-0.00010,6.000
6,81.438,0.02,-0.0002,-0.00010,6.000
6,81.562,0.02,-0.0002,-0.00010,6.000
6,81.688,0.02,-0.0002,-0.00010,6.000
6,81.812,0.02,-0.0002,-0.00010,6.000
7,82.188,0.00,0.1591,0.15918,7.000
7,82.312,0.00,0.2843,0.28440,7.000
7,82.438,0.00,0.4092,0.40930,7.000
7,82.562,0.00,0.5341,0.53417,7.000
7,82.688,0.00,0.6591,0.65923,7.000
7,82.812,0.00,0.7841,0.78422,7.000
7,82.938,0.00,0.9092,0.90928,7.000
7,83.062,0.00,1.0342,1.03432,7.000
7,83.188,0.00,1.1593,1.15938,7.000
7,83.312,0.00,1.2842,1.28435,7.000
7,83.438,0.00,1.4093,1.40938,7.000
7,83.562,0.00,1.5342,1.53435,7.000
7,83.688,0.00,1.6592,1.65925,7.000
7,83.812,0.00,1.7841,1.78422,7.000
7,83.938,0.01,1.9092,1.90925,7.000
7,84.062,0.03,2.0341,2.03422,7.000
7,84.188,0.06,2.1592,2.15930,7.000
7,84.312,0.10,2.2843,2.28437,7.000
7,84.438,0.18,2.4094,2.40948,7.000
7,84.562,0.32,2.5342,2.53432,7.000
7,84.688,0.56,2.6594,2.65948,7.000
7,84.812,0.88,2.7843,2.78445,7.000
7,84.938,1.31,2.9092,2.90933,7.000
7,85.062,1.85,3.0341,3.03425,7.000
7,85.188,2.54,3.1593,3.15938,7.000
7,85.312,3.38,3.2843,3.28442,7.000
7,85.438,4.39,3.4094,3.40948,7.000
7,85.562,5.60,3.5343,3.53442,7.000
7,85.688,7.03,3.6594,3.65948,7.000
7,85.812,8.70,3.7842,3.78435,7.000
7,85.938,10.63,3.9092,3.90928,7.000
7,86.062,12.81,4.0342,4.03432,7.000
7,86.188,15.27,4.1593,4.15938,7.000
7,86.312,18.05,4.2842,4.28435,7.000
7,86.438,21.19,4.4093,4.40938,7.000
7,86.562,24.71,4.5342,4.53435,7.000
7,86.688,28.72,4.6594,4.65948,7.000
7,86.812,33.33,4.7844,4.78447,7.000
7,86.938,38.70,4.9093,4.90938,7.000
7,87.062,45.17,5.0343,5.03437,7.000
7,87.250,53.32,5.1612,5.16130,7.000
7,87.375,38.55,5.0375,5.03760,7.000
7,87.500,29.50,4.9126,4.91270,7.000
7,87.625,23.12,4.7876,4.78770,7.000
7,87.750,18.32,4.6626,4.66270,7.000
7,87.875,14.63,4.5376,4.53770,7.000
7,88.000,11.77,4.4126,4.41270,7.000
7,88.125,9.51,4.2875,4.28760,7.000
7,88.250,7.72,4.1626,4.16270,7.000
7,88.375,6.28,4.0375,4.03760,7.000
7,88.500,5.12,3.9125,3.91260,7.000
7,88.625,4.20,3.7874,3.78750,7.000
7,88.750,3.42,3.6625,3.66260,7.000
7,88.875,2.78,3.5375,3.53760,7.000
7,89.000,2.23,3.4126,3.41270,7.000
7,89.125,1.75,3.2875,3.28760,7.000
7,89.250,1.34,3.1624,3.16250,7.000
7,89.375,0.99,3.0374,3.03745,7.000
7,89.500,0.68,2.9122,2.91230,7.000
7,89.625,0.43,2.7874,2.78750,7.000
7,89.750,0.25,2.6624,2.66250,7.000
7,89.875,0.14,2.5374,2.53745,7.000
7,90.000,0.07,2.4125,2.41260,7.000
7,90.125,0.03,2.2874,2.28750,7.000
7,90.250,0.02,2.1624,2.16250,7.000
7,90.375,0.01,2.0373,2.03735,7.000
7,90.500,0.00,1.9122,1.91230,7.000
7,90.625,0.00,1.7872,1.78735,7.000
7,90.750,0.00,1.6624,1.66250,7.000
7,90.875,0.00,1.5374,1.53745,7.000
7,91.000,0.00,1.4123,1.41240,7.000
7,91.125,0.00,1.2874,1.28750,7.000
7,91.250,0.00,1.1624,1.16250,7.000
7,91.375,0.00,1.0373,1.03740,7.000
7,91.500,0.00,0.9122,0.91230,7.000
7,91.625,0.00,0.7872,0.78735,7.000
7,91.750,0.00,0.6622,0.66230,7.000
7,91.875,0.00,0.5372,0.53735,7.000
7,92.000,0.00,0.4123,0.41240,7.000
7,92.125,0.00,0.2874,0.28745,7.000
7,92.250,0.00,0.1624,0.16250,7.000
7,92.375,0.00,0.0372,0.03725,7.000
7,92.562,0.00,-0.0076,-0.00745,7.000
7,92.688,0.00,-0.0003,-0.00020,7.000
7,92.812,0.00,-0.0003,-0.00020,7.000
7,92.938,0.00,-0.0003,-0.00020,7.000
7,93.062,0.00,-0.0003,-0.00020,7.000
7,93.188,0.00,-0.0003,-0.00020,7.000
7,93.312,0.00,-0.0003,-0.00020,7.000
7,93.438,0.00,-0.0003,-0.00020,7.000
7,93.562,0.00,-0.0003,-0.00020,7.000
7,93.688,0.00,-0.0003,-0.00020,7.000
7,93.812,0.00,-0.0003,-0.00020,7.000
7,93.938,0.00,-0.0003,-0.00020,7.000
7,94.062,0.00,-0.0003,-0.00020,7.000
7,94.188,0.00,-0.0003,-0.00020,7.000
7,94.312,0.00,-0.0003,-0.00020,7.000
7,94.438,0.00,-0.0002,-0.00010,7.000
7,94.562,0.00,-0.0002,-0.00010,7.000
7,94.688,0.00,-0.0002,-0.00010,7.000
7,94.812,0.00,-0.0002,-0.00010,7.000
7,94.938,0.00,-0.0002,-0.00010,7.000
7,95.062,0.00,-0.0002,-0.00010,7.000
7,95.188,0.00,-0.0002,-0.00010,7.000
7,95.312,0.00,-0.0002,-0.00010,7.000
7,95.438,0.00,-0.0002,-0.00010,7.000
8,95.750,0.01,0.0613,0.06140,8.000
8,95.875,0.00,0.1866,0.18665,8.000
8,96.000,0.01,0.3117,0.31180,8.000
8,96.125,0.01,0.4367,0.43675,8.000
8,96.250,0.00,0.5617,0.56180,8.000
8,96.375,0.00,0.6867,0.68680,8.000
8,96.500,0.01,0.8119,0.81200,8.000
8,96.625,0.01,0.9367,0.93680,8.000
8,96.750,0.01,1.0617,1.06180,8.000
8,96.875,0.01,1.1867,1.18680,8.000
8,97.000,0.01,1.3117,1.31180,8.000
8,97.125,0.00,1.4366,1.43670,8.000
8,97.250,0.00,1.5617,1.56180,8.000
8,97.375,0.01,1.6868,1.68685,8.000
8,97.500,0.00,1.8118,1.81190,8.000
8,97.625,0.02,1.9368,1.93690,8.000
8,97.750,0.04,2.0617,2.06180,8.000
8,97.875,0.08,2.1867,2.18680,8.000
8,98.000,0.12,2.3116,2.31170,8.000
8,98.125,0.21,2.4367,2.43680,8.000
8,98.250,0.37,2.5617,2.56180,8.000
8,98.375,0.62,2.6868,2.68695,8.000
8,98.500,0.96,2.8119,2.81200,8.000
8,98.625,1.42,2.9368,2.93690,8.000
8,98.750,1.99,3.0619,3.06200,8.000
8,98.875,2.70,3.1868,3.18690,8.000
8,99.000,3.58,3.3118,3.31190,8.000
8,99.125,4.64,3.4368,3.43685,8.000
8,99.250,5.89,3.5617,3.56180,8.000
8,99.375,7.37,3.6868,3.68690,8.000
8,99.500,9.10,3.8118,3.81190,8.000
8,99.625,11.09,3.9368,3.93695,8.000
8,99.750,13.32,4.0620,4.06210,8.000
8,99.875,15.85,4.1868,4.18690,8.000
8,100.000,18.72,4.3117,4.31180,8.000
8,100.125,21.94,4.4367,4.43680,8.000
8,100.250,25.57,4.5617,4.56180,8.000
8,100.375,29.68,4.6868,4.68685,8.000
8,100.500,34.42,4.8118,4.81190,8.000
8,100.625,39.99,4.9368,4.93695,8.000
8,100.750,46.72,5.0619,5.06200,8.000
8,100.938,49.92,5.1361,5.13620,8.000
8,101.062,36.26,5.0113,5.01135,8.000
8,101.188,27.97,4.8861,4.88622,8.000
8,101.312,21.99,4.7611,4.76120,8.000
8,101.438,17.46,4.6361,4.63618,8.000
8,101.562,13.96,4.5110,4.51110,8.000
8,101.688,11.24,4.3861,4.38618,8.000
8,101.812,9.08,4.2611,4.26120,8.000
8,101.938,7.37,4.1360,4.13612,8.000
8,102.062,6.01,4.0112,4.01125,8.000
8,102.188,4.90,3.8860,3.88613,8.000
8,102.312,4.02,3.7609,3.76100,8.000
8,102.438,3.27,3.6358,3.63593,8.000
8,102.562,2.66,3.5109,3.51095,8.000
8,102.688,2.13,3.3860,3.38610,8.000
8,102.812,1.66,3.2610,3.26110,8.000
8,102.938,1.26,3.1360,3.13615,8.000
8,103.062,0.92,3.0111,3.01115,8.000
8,103.188,0.63,2.8859,2.88600,8.000
8,103.312,0.40,2.7611,2.76115,8.000
8,103.438,0.23,2.6358,2.63593,8.000
8,103.562,0.12,2.5108,2.51085,8.000
8,103.688,0.06,2.3859,2.38598,8.000
8,103.812,0.03,2.2609,2.26100,8.000
8,103.938,0.02,2.1359,2.13600,8.000
8,104.062,0.01,2.0108,2.01093,8.000
8,104.188,0.00,1.8858,1.88592,8.000
8,104.312,0.00,1.7609,1.76095,8.000
8,104.438,0.01,1.6358,1.63585,8.000
8,104.562,0.01,1.5107,1.51078,8.000
8,104.688,0.01,1.3858,1.38588,8.000
8,104.812,0.01,1.2609,1.26100,8.000
8,104.938,0.01,1.1359,1.13598,8.000
8,105.062,0.01,1.0109,1.01100,8.000
8,105.188,0.01,0.8860,0.88605,8.000
8,105.312,0.01,0.7609,0.76095,8.000
8,105.438,0.01,0.6357,0.63582,8.000
8,105.562,0.01,0.5107,0.51075,8.000
8,105.688,0.01,0.3857,0.38578,8.000
8,105.812,0.01,0.2608,0.26093,8.000
8,105.938,0.00,0.1357,0.13582,8.000
8,106.062,0.00,0.0107,0.01083,8.000
8,106.250,0.01,0.0006,0.00070,8.000
8,106.375,0.00,-0.0003,-0.00020,8.000
8,106.500,0.01,-0.0003,-0.00020,8.000
8,106.625,0.00,-0.0003,-0.00020,8.000
8,106.750,0.00,-0.0003,-0.00020,8.000
8,106.875,0.00,-0.0003,-0.00020,8.000
8,107.000,0.00,-0.0003,-0.00020,8.000
8,107.125,0.00,-0.0003,-0.00020,8.000
8,107.250,0.00,-0.0003,-0.00020,8.000
8,107.375,0.01,-0.0003,-0.00020,8.000
8,107.500,0.01,-0.0003,-0.00020,8.000
8,107.625,0.01,-0.0003,-0.00020,8.000
8,107.750,0.01,-0.0002,-0.00010,8.000
8,107.875,0.01,-0.0002,-0.00010,8.000
8,108.000,0.00,-0.0002,-0.00010,8.000
8,108.125,0.00,-0.0002,-0.00010,8.000
8,108.250,0.00,-0.0002,-0.00010,8.000
8,108.375,0.00,-0.0002,-0.00010,8.000
8,108.500,0.01,-0.0002,-0.00010,8.000
8,108.625,0.01,-0.0002,-0.00010,8.000
8,108.750,0.01,-0.0002,-0.00010,8.000
8,108.875,0.01,-0.0002,-0.00010,8.000
8,109.000,0.00,-0.0002,-0.00010,8.000
8,109.125,0.01,-0.0002,-0.00010,8.000
9,109.500,0.00,0.1415,0.14160,9.000
9,109.625,-0.01,0.2666,0.26675,9.000
9,109.750,0.00,0.3915,0.39160,9.000
9,109.875,0.00,0.5166,0.51665,9.000
9,110.000,0.00,0.6416,0.64170,9.000
9,110.125,0.00,0.7666,0.76675,9.000
9,110.250,-0.01,0.8917,0.89180,9.000
9,110.375,0.00,1.0167,1.01680,9.000
9,110.500,-0.01,1.1417,1.14180,9.000
9,110.625,0.00,1.2667,1.26680,9.000
9,110.750,0.00,1.3916,1.39170,9.000
9,110.875,-0.01,1.5166,1.51670,9.000
9,111.000,0.00,1.6418,1.64190,9.000
9,111.125,0.00,1.7668,1.76685,9.000
9,111.250,0.00,1.8918,1.89190,9.000
9,111.375,0.02,2.0168,2.01685,9.000
9,111.500,0.05,2.1418,2.14190,9.000
9,111.625,0.09,2.2667,2.26680,9.000
9,111.750,0.16,2.3917,2.39180,9.000
9,111.875,0.30,2.5167,2.51680,9.000
9,112.000,0.51,2.6417,2.64180,9.000
9,112.125,0.81,2.7668,2.76695,9.000
9,112.250,1.22,2.8918,2.89190,9.000
9,112.375,1.75,3.0168,3.01695,9.000
9,112.500,2.42,3.1419,3.14200,9.000
9,112.625,3.23,3.2668,3.26690,9.000
9,112.750,4.22,3.3919,3.39200,9.000
9,112.875,5.40,3.5167,3.51680,9.000
9,113.000,6.79,3.6417,3.64180,9.000
9,113.125,8.42,3.7668,3.76685,9.000
9,113.250,10.32,3.8919,3.89200,9.000
9,113.375,12.46,4.0169,4.01705,9.000
9,113.500,14.88,4.1420,4.14210,9.000
9,113.625,17.62,4.2668,4.26685,9.000
9,113.750,20.71,4.3917,4.39180,9.000
9,113.875,24.18,4.5166,4.51675,9.000
9,114.000,28.11,4.6416,4.64170,9.000
9,114.125,32.60,4.7668,4.76695,9.000
9,114.250,37.83,4.8918,4.89190,9.000
9,114.375,44.07,5.0169,5.01700,9.000
9,114.500,51.88,5.1419,5.14200,9.000
9,114.688,40.05,5.0552,5.05528,9.000
9,114.812,30.51,4.9301,4.93018,9.000
9,114.938,23.87,4.8051,4.80515,9.000
9,115.062,18.90,4.6801,4.68020,9.000
9,115.188,15.08,4.5551,4.55518,9.000
9,115.312,12.11,4.4300,4.43005,9.000
9,115.438,9.77,4.3050,4.30510,9.000
9,115.562,7.92,4.1801,4.18015,9.000
9,115.688,6.44,4.0552,4.05528,9.000
9,115.812,5.24,3.9301,3.93018,9.000
9,115.938,4.30,3.8049,3.80502,9.000
9,116.062,3.50,3.6799,3.68000,9.000
9,116.188,2.84,3.5549,3.55500,9.000
9,116.312,2.29,3.4299,3.43003,9.000
9,116.438,1.80,3.3051,3.30518,9.000
9,116.562,1.38,3.1800,3.18010,9.000
9,116.688,1.02,3.0550,3.05510,9.000
9,116.812,0.71,2.9300,2.93005,9.000
9,116.938,0.45,2.8050,2.80505,9.000
9,117.062,0.27,2.6800,2.68008,9.000
9,117.188,0.14,2.5547,2.55482,9.000
9,117.312,0.07,2.4298,2.42988,9.000
9,117.438,0.03,2.3048,2.30495,9.000
9,117.562,0.01,2.1799,2.18000,9.000
9,117.688,0.01,2.0549,2.05500,9.000
9,117.812,-0.01,1.9299,1.92998,9.000
9,117.938,0.00,1.8049,1.80502,9.000
9,118.062,-0.01,1.6798,1.67993,9.000
9,118.188,-0.01,1.5547,1.55478,9.000
9,118.312,-0.01,1.4297,1.42978,9.000
9,118.438,0.00,1.3048,1.30495,9.000
9,118.562,-0.01,1.1799,1.18003,9.000
9,118.688,-0.01,1.0550,1.05505,9.000
9,118.812,-0.01,0.9299,0.92995,9.000
9,118.938,-0.01,0.8049,0.80500,9.000
9,119.062,-0.01,0.6798,0.67988,9.000
9,119.188,-0.01,0.5547,0.55475,9.000
9,119.312,0.00,0.4297,0.42980,9.000
9,119.438,0.00,0.3047,0.30480,9.000
9,119.562,-0.01,0.1798,0.17985,9.000
9,119.688,0.00,0.0546,0.05475,9.000
9,119.875,0.00,-0.0218,-0.02165,9.000
9,120.000,0.00,-0.0003,-0.00020,9.000
9,120.125,0.00,-0.0003,-0.00020,9.000
9,120.250,0.00,-0.0003,-0.00020,9.000
9,120.375,-0.01,-0.0003,-0.00020,9.000
9,120.500,-0.01,-0.0003,-0.00020,9.000
9,120.625,0.00,-0.0003,-0.00020,9.000
9,120.750,-0.01,-0.0003,-0.00020,9.000
9,120.875,0.00,-0.0003,-0.00020,9.000
9,121.000,0.00,-0.0003,-0.00020,9.000
9,121.125,-0.01,-0.0003,-0.00020,9.000
9,121.250,0.00,-0.0003,-0.00020,9.000
9,121.375,-0.01,-0.0003,-0.00020,9.000
9,121.500,0.00,-0.0003,-0.00020,9.000
9,121.625,-0.01,-0.0003,-0.00020,9.000
9,121.750,-0.01,-0.0003,-0.00020,9.000
9,121.875,0.00,-0.0003,-0.00020,9.000
9,122.000,-0.01,-0.0003,-0.00020,9.000
9,122.125,-0.01,-0.0002,-0.00010,9.000
9,122.250,-0.01,-0.0002,-0.00010,9.000
9,122.375,-0.01,-0.0002,-0.00010,9.000
9,122.500,0.00,-0.0002,-0.00010,9.000
9,122.625,-0.01,-0.0002,-0.00010,9.000
9,122.750,-0.01,-0.0002,-0.00010,9.000
10,123.125,0.01,0.0964,0.09655,10.000
10,123.250,0.01,0.2216,0.22170,10.000
10,123.375,0.01,0.3466,0.34670,10.000
10,123.500,0.01,0.4715,0.47160,10.000
10,123.625,0.01,0.5965,0.59665,10.000
10,123.750,0.01,0.7216,0.72170,10.000
10,123.875,0.01,0.8467,0.84680,10.000
10,124.000,0.00,0.9718,0.97190,10.000
10,124.125,0.01,1.0967,1.09685,10.000
10,124.250,0.01,1.2217,1.22180,10.000
10,124.375,0.01,1.3466,1.34675,10.000
10,124.500,0.01,1.4716,1.47170,10.000
10,124.625,0.01,1.5966,1.59675,10.000
10,124.750,0.01,1.7217,1.72180,10.000
10,124.875,0.01,1.8468,1.84690,10.000
10,125.000,0.03,1.9718,1.97190,10.000
10,125.125,0.06,2.0968,2.09690,10.000
10,125.250,0.09,2.2217,2.22180,10.000
10,125.375,0.15,2.3467,2.34685,10.000
10,125.500,0.25,2.4717,2.47180,10.000
10,125.625,0.43,2.5967,2.59680,10.000
10,125.750,0.71,2.7218,2.72190,10.000
10,125.875,1.08,2.8467,2.84685,10.000
10,126.000,1.57,2.9719,2.97200,10.000
10,126.125,2.17,3.0968,3.09695,10.000
10,126.250,2.93,3.2220,3.22210,10.000
10,126.375,3.85,3.3469,3.34700,10.000
10,126.500,4.96,3.4718,3.47190,10.000
10,126.625,6.27,3.5967,3.59680,10.000
10,126.750,7.81,3.7218,3.72190,10.000
10,126.875,9.60,3.8467,3.84680,10.000
10,127.000,11.65,3.9718,3.97190,10.000
10,127.125,13.96,4.0969,4.09700,10.000
10,127.250,16.58,4.2218,4.22190,10.000
10,127.375,19.54,4.3468,4.34690,10.000
10,127.500,22.86,4.4717,4.47180,10.000
10,127.625,26.62,4.5967,4.59685,10.000
10,127.750,30.89,4.7217,4.72180,10.000
10,127.875,35.81,4.8468,4.84690,10.000
10,128.000,41.64,4.9718,4.97190,10.000
10,128.125,48.78,5.0969,5.09700,10.000
10,128.312,44.81,5.1001,5.10020,10.000
10,128.438,33.49,4.9751,4.97522,10.000
10,128.562,26.03,4.8501,4.85020,10.000
10,128.688,20.55,4.7250,4.72512,10.000
10,128.812,16.36,4.6000,4.60012,10.000
10,128.938,13.11,4.4750,4.47508,10.000
10,129.062,10.56,4.3501,4.35020,10.000
10,129.188,8.55,4.2250,4.22515,10.000
10,129.312,6.95,4.1000,4.10013,10.000
10,129.438,5.66,3.9752,3.97525,10.000
10,129.562,4.62,3.8500,3.85008,10.000
10,129.688,3.78,3.7249,3.72503,10.000
10,129.812,3.08,3.5999,3.60000,10.000
10,129.938,2.49,3.4749,3.47498,10.000
10,130.062,1.98,3.3500,3.35005,10.000
10,130.188,1.53,3.2250,3.22508,10.000
10,130.312,1.15,3.1000,3.10013,10.000
10,130.438,0.82,2.9750,2.97510,10.000
10,130.562,0.55,2.8500,2.85005,10.000
10,130.688,0.34,2.7250,2.72510,10.000
10,130.812,0.19,2.5998,2.59990,10.000
10,130.938,0.11,2.4748,2.47490,10.000
10,131.062,0.06,2.3498,2.34993,10.000
10,131.188,0.03,2.2248,2.22490,10.000
10,131.312,0.02,2.0999,2.10000,10.000
10,131.438,0.01,1.9749,1.97500,10.000
10,131.562,0.01,1.8498,1.84992,10.000
10,131.688,0.01,1.7248,1.72490,10.000
10,131.812,0.01,1.5998,1.59995,10.000
10,131.938,0.01,1.4748,1.47485,10.000
10,132.062,0.01,1.3497,1.34982,10.000
10,132.188,0.01,1.2248,1.22490,10.000
10,132.312,0.01,1.0999,1.10000,10.000
10,132.438,0.01,0.9749,0.97498,10.000
10,132.562,0.01,0.8500,0.85005,10.000
10,132.688,0.01,0.7249,0.72498,10.000
10,132.812,0.01,0.5998,0.59985,10.000
10,132.938,0.01,0.4746,0.47475,10.000
10,133.062,0.01,0.3497,0.34982,10.000
10,133.188,0.01,0.2249,0.22498,10.000
10,133.312,0.01,0.0997,0.09980,10.000
10,133.562,0.01,-0.0002,-0.00010,10.000
10,133.688,0.01,-0.0003,-0.00020,10.000
10,133.812,0.01,-0.0003,-0.00020,10.000
10,133.938,0.01,-0.0003,-0.00020,10.000
10,134.062,0.01,-0.0003,-0.00020,10.000
10,134.188,0.01,-0.0003,-0.00020,10.000
10,134.312,0.01,-0.0003,-0.00020,10.000
10,134.438,0.01,-0.0003,-0.00020,10.000
10,134.562,0.01,-0.0003,-0.00020,10.000
10,134.688,0.01,-0.0003,-0.00020,10.000
10,134.812,0.01,-0.0003,-0.00020,10.000
10,134.938,0.01,-0.0003,-0.00020,10.000
10,135.062,0.01,-0.0003,-0.00020,10.000
10,135.188,0.01,-0.0003,-0.00020,10.000
10,135.312,0.01,-0.0003,-0.00020,10.000
10,135.438,0.01,-0.0002,-0.00010,10.000
10,135.562,0.01,-0.0002,-0.00010,10.000
10,135.688,0.01,-0.0002,-0.00010,10.000
10,135.812,0.01,-0.0002,-0.00010,10.000
10,135.938,0.01,-0.0002,-0.00010,10.000
10,136.062,0.00,-0.0002,-0.00010,10.000
10,136.188,0.01,-0.0002,-0.00010,10.000
10,136.312,0.01,-0.0002,-0.00010,10.000
10,136.438,0.01,-0.0002,-0.00010,10.000
10,136.500,0.00,-0.0002,-0.00010,10.000