File: AIME_journal_files/AIME_data/calibDATA_loadcell/date_02:22:2018/Instron/5N_0_1_0_0.txt
""
"Test Method","Radhen_Load_Cntrl_Cmprsn_250N_12-7.msm"
"Sample I. D.","Sample1.mss"
"Specimen Number","23"

"TheCycle_Output ()","_Time (s)","_Load (N)","_Extension (mm)","RealTimeDepth (mm)","CycleNumber ()"

1,0.312,-0.01,0.1070,0.10703,1.000
1,0.438,-0.02,0.2322,0.23218,1.000
1,0.562,-0.02,0.3573,0.35727,1.000
1,0.688,-0.02,0.4823,0.48230,1.000
1,0.812,-0.01,0.6070,0.60705,1.000
1,0.938,-0.02,0.7322,0.73217,1.000
1,1.062,-0.01,0.8572,0.85720,1.000
1,1.188,-0.01,0.9822,0.98225,1.000
1,1.312,-0.01,1.1072,1.10722,1.000
1,1.438,-0.02,1.2323,1.23230,1.000
1,1.562,-0.01,1.3572,1.35722,1.000
1,1.688,-0.02,1.4822,1.48223,1.000
1,1.812,-0.02,1.6073,1.60728,1.000
1,1.938,-0.02,1.7322,1.73225,1.000
1,2.062,-0.01,1.8572,1.85723,1.000
1,2.188,-0.01,1.9822,1.98225,1.000
1,2.312,-0.01,2.1072,2.10725,1.000
1,2.438,-0.02,2.2323,2.23230,1.000
1,2.562,-0.01,2.3574,2.35740,1.000
1,2.688,0.01,2.4824,2.48238,1.000
1,2.812,0.04,2.6072,2.60725,1.000
1,2.938,0.11,2.7323,2.73230,1.000
1,3.062,0.21,2.8572,2.85720,1.000
1,3.188,0.41,2.9823,2.98230,1.000
1,3.312,0.68,3.1072,3.10725,1.000
1,3.438,1.04,3.2324,3.23238,1.000
1,3.562,1.49,3.3574,3.35745,1.000
1,3.688,2.05,3.4824,3.48245,1.000
1,3.812,2.71,3.6074,3.60745,1.000
1,3.938,3.49,3.7324,3.73238,1.000
1,4.062,4.39,3.8573,3.85730,1.000
1,4.250,5.19,3.9451,3.94510,1.000
1,4.375,3.89,3.8205,3.82050,1.000
1,4.500,2.91,3.6956,3.69560,1.000
1,4.625,2.13,3.5706,3.57060,1.000
1,4.750,1.53,3.4455,3.44550,1.000
1,4.875,1.05,3.3207,3.32070,1.000
1,5.000,0.69,3.1956,3.19560,1.000
1,5.125,0.40,3.0706,3.07055,1.000
1,5.250,0.21,2.9456,2.94560,1.000
1,5.375,0.08,2.8204,2.82045,1.000
1,5.500,0.02,2.6954,2.69540,1.000
1,5.625,0.00,2.5704,2.57040,1.000
1,5.750,0.00,2.4456,2.44560,1.000
1,5.875,-0.02,2.3205,2.32050,1.000
1,6.000,-0.02,2.1956,2.19560,1.000
1,6.125,-0.02,2.0705,2.07050,1.000
1,6.250,-0.02,1.9454,1.94540,1.000
1,6.375,-0.01,1.8205,1.82050,1.000
1,6.500,-0.01,1.6954,1.69540,1.000
1,6.625,-0.01,1.5704,1.57045,1.000
1,6.750,-0.01,1.4455,1.44550,1.000
1,6.875,-0.02,1.3204,1.32040,1.000
1,7.000,-0.01,1.1954,1.19540,1.000
1,7.125,-0.02,1.0705,1.07045,1.000
1,7.250,-0.03,0.9454,0.94540,1.000
1,7.375,-0.02,0.8204,0.82045,1.000
1,7.500,-0.01,0.6952,0.69520,1.000
1,7.625,-0.02,0.5702,0.57020,1.000
1,7.750,-0.02,0.4453,0.44530,1.000
1,7.875,-0.02,0.3204,0.32035,1.000
1,8.000,-0.02,0.1952,0.19520,1.000
1,8.125,-0.02,0.0703,0.07025,1.000
1,8.312,-0.01,-0.0129,-0.01293,1.000
1,8.438,-0.01,-0.0002,-0.00020,1.000
1,8.562,-0.01,-0.0002,-0.00020,1.000
1,8.688,-0.01,-0.0002,-0.00020,1.000
1,8.812,0.00,-0.0002,-0.00020,1.000
1,8.938,-0.01,-0.0002,-0.00020,1.000
1,9.062,-0.02,-0.0002,-0.00020,1.000
1,9.188,-0.01,-0.0002,-0.00020,1.000
1,9.312,-0.01,-0.0002,-0.00020,1.000
1,9.438,-0.02,-0.0002,-0.00020,1.000
1,9.562,-0.02,-0.0002,-0.00020,1.000
1,9.688,-0.01,-0.0002,-0.00020,1.000
1,9.812,-0.01,-0.0002,-0.00020,1.000
1,9.938,-0.01,-0.0002,-0.00020,1.000
1,10.062,0.00,-0.0001,-0.00010,1.000
1,10.188,-0.01,-0.0001,-0.00010,1.000
1,10.312,-0.01,-0.0001,-0.00010,1.000
1,10.438,-0.02,-0.0001,-0.00010,1.000
1,10.562,-0.02,-0.0001,-0.00010,1.000
1,10.688,-0.02,-0.0001,-0.00010,1.000
1,10.812,-0.01,-0.0001,-0.00010,1.000
1,10.938,0.00,-0.0001,-0.00010,1.000
1,11.062,-0.01,-0.0001,-0.00010,1.000
1,11.188,-0.02,-0.0001,-0.00010,1.000
2,11.562,-0.01,0.1071,0.10707,2.000
2,11.688,-0.01,0.2321,0.23210,2.000
2,11.812,0.00,0.3572,0.35725,2.000
2,11.938,-0.01,0.4822,0.48220,2.000
2,12.062,-0.01,0.6070,0.60697,2.000
2,12.188,0.00,0.7321,0.73205,2.000
2,12.312,-0.01,0.8572,0.85717,2.000
2,12.438,-0.01,0.9821,0.98210,2.000
2,12.562,0.00,1.1072,1.10720,2.000
2,12.688,-0.01,1.2322,1.23220,2.000
2,12.812,-0.01,1.3572,1.35725,2.000
2,12.938,-0.01,1.4823,1.48230,2.000
2,13.062,-0.01,1.6073,1.60727,2.000
2,13.188,-0.01,1.7323,1.73225,2.000
2,13.312,-0.01,1.8571,1.85715,2.000
2,13.438,0.00,1.9822,1.98218,2.000
2,13.562,0.00,2.1073,2.10727,2.000
2,13.688,-0.01,2.2322,2.23223,2.000
2,13.812,0.00,2.3573,2.35730,2.000
2,13.938,0.01,2.4824,2.48238,2.000
2,14.062,0.04,2.6072,2.60725,2.000
2,14.188,0.09,2.7323,2.73230,2.000
2,14.312,0.20,2.8572,2.85720,2.000
2,14.438,0.39,2.9823,2.98228,2.000
2,14.562,0.66,3.1073,3.10727,2.000
2,14.688,1.02,3.2322,3.23223,2.000
2,14.812,1.48,3.3574,3.35742,2.000
2,14.938,2.02,3.4823,3.48230,2.000
2,15.062,2.69,3.6074,3.60735,2.000
2,15.188,3.48,3.7323,3.73233,2.000
2,15.312,4.39,3.8573,3.85730,2.000
2,15.500,5.23,3.9451,3.94510,2.000
2,15.625,3.90,3.8205,3.82050,2.000
2,15.750,2.93,3.6955,3.69550,2.000
2,15.875,2.16,3.5705,3.57050,2.000
2,16.000,1.54,3.4455,3.44550,2.000
2,16.125,1.05,3.3207,3.32065,2.000
2,16.250,0.68,3.1955,3.19550,2.000
2,16.375,0.40,3.0704,3.07045,2.000
2,16.500,0.20,2.9455,2.94550,2.000
2,16.625,0.09,2.8204,2.82035,2.000
2,16.750,0.03,2.6953,2.69530,2.000
2,16.875,0.00,2.5703,2.57030,2.000
2,17.000,0.00,2.4455,2.44550,2.000
2,17.125,-0.01,2.3205,2.32050,2.000
2,17.250,0.00,2.1955,2.19550,2.000
2,17.375,-0.01,2.0704,2.07045,2.000
2,17.500,-0.02,1.9454,1.94540,2.000
2,17.625,-0.01,1.8204,1.82045,2.000
2,17.750,0.00,1.6954,1.69540,2.000
2,17.875,-0.01,1.5704,1.57040,2.000
2,18.000,-0.02,1.4455,1.44550,2.000
2,18.125,-0.01,1.3204,1.32035,2.000
2,18.250,-0.02,1.1954,1.19540,2.000
2,18.375,-0.01,1.0704,1.07035,2.000
2,18.500,-0.01,0.9454,0.94540,2.000
2,18.625,-0.01,0.8204,0.82045,2.000
2,18.750,0.00,0.6951,0.69510,2.000
2,18.875,-0.01,0.5702,0.57020,2.000
2,19.000,-0.01,0.4453,0.44530,2.000
2,19.125,-0.01,0.3204,0.32035,2.000
2,19.250,0.00,0.1952,0.19520,2.000
2,19.375,-0.01,0.0703,0.07030,2.000
2,19.562,-0.01,-0.0327,-0.03272,2.000
2,19.688,-0.01,-0.0002,-0.00020,2.000
2,19.812,-0.01,-0.0002,-0.00020,2.000
2,19.938,-0.01,-0.0002,-0.00020,2.000
2,20.062,0.00,-0.0002,-0.00020,2.000
2,20.188,-0.01,-0.0002,-0.00020,2.000
2,20.312,-0.01,-0.0002,-0.00020,2.000
2,20.438,-0.01,-0.0002,-0.00020,2.000
2,20.562,-0.01,-0.0002,-0.00020,2.000
2,20.688,-0.01,-0.0002,-0.00020,2.000
2,20.812,-0.01,-0.0002,-0.00020,2.000
2,20.938,-0.01,-0.0002,-0.00020,2.000
2,21.062,-0.01,-0.0002,-0.00020,2.000
2,21.188,0.00,-0.0002,-0.00020,2.000
2,21.312,-0.01,-0.0002,-0.00020,2.000
2,21.438,-0.01,-0.0002,-0.00020,2.000
2,21.562,-0.01,-0.0001,-0.00010,2.000
2,21.688,-0.01,-0.0001,-0.00010,2.000
2,21.812,-0.01,-0.0001,-0.00010,2.000
2,21.938,-0.01,-0.0001,-0.00010,2.000
2,22.062,-0.01,-0.0001,-0.00010,2.000
2,22.188,0.00,-0.0001,-0.00010,2.000
2,22.312,0.00,-0.0001,-0.00010,2.000
2,22.438,-0.01,-0.0001,-0.00010,2.000
3,22.812,0.00,0.0969,0.09693,3.000
3,22.938,-0.01,0.2220,0.22205,3.000
3,23.062,-0.01,0.3472,0.34720,3.000
3,23.188,0.00,0.4722,0.47222,3.000
3,23.312,0.00,0.5971,0.59713,3.000
3,23.438,0.00,0.7222,0.72220,3.000
3,23.562,0.00,0.8473,0.84725,3.000
3,23.688,0.00,0.9721,0.97212,3.000
3,23.812,-0.01,1.0971,1.09710,3.000
3,23.938,-0.01,1.2222,1.22217,3.000
3,24.062,0.00,1.3471,1.34712,3.000
3,24.188,0.01,1.4722,1.47220,3.000
3,24.312,-0.01,1.5972,1.59725,3.000
3,24.438,0.00,1.7223,1.72235,3.000
3,24.562,0.00,1.8473,1.84730,3.000
3,24.688,-0.01,1.9721,1.97215,3.000
3,24.812,0.00,2.0971,2.09715,3.000
3,24.938,0.00,2.2222,2.22220,3.000
3,25.062,0.01,2.3472,2.34725,3.000
3,25.188,0.01,2.4724,2.47237,3.000
3,25.312,0.04,2.5973,2.59727,3.000
3,25.438,0.09,2.7224,2.72237,3.000
3,25.562,0.20,2.8473,2.84730,3.000
3,25.688,0.38,2.9723,2.97232,3.000
3,25.812,0.64,3.0972,3.09720,3.000
3,25.938,0.99,3.2222,3.22220,3.000
3,26.062,1.44,3.3473,3.34732,3.000
3,26.188,1.99,3.4722,3.47225,3.000
3,26.312,2.64,3.5974,3.59740,3.000
3,26.438,3.42,3.7224,3.72245,3.000
3,26.562,4.32,3.8474,3.84740,3.000
3,26.750,5.49,3.9743,3.97430,3.000
3,26.875,4.17,3.8506,3.85055,3.000
3,27.000,3.14,3.7256,3.72560,3.000
3,27.125,2.31,3.6006,3.60065,3.000
3,27.250,1.68,3.4756,3.47560,3.000
3,27.375,1.16,3.3506,3.35055,3.000
3,27.500,0.77,3.2254,3.22540,3.000
3,27.625,0.46,3.1004,3.10040,3.000
3,27.750,0.24,2.9755,2.97550,3.000
3,27.875,0.11,2.8505,2.85045,3.000
3,28.000,0.04,2.7255,2.72550,3.000
3,28.125,0.01,2.6004,2.60045,3.000
3,28.250,0.00,2.4756,2.47560,3.000
3,28.375,0.00,2.3505,2.35050,3.000
3,28.500,0.00,2.2254,2.22540,3.000
3,28.625,0.00,2.1004,2.10040,3.000
3,28.750,0.00,1.9752,1.97520,3.000
3,28.875,-0.01,1.8504,1.85040,3.000
3,29.000,0.00,1.7255,1.72550,3.000
3,29.125,0.00,1.6005,1.60050,3.000
3,29.250,0.00,1.4754,1.47540,3.000
3,29.375,-0.01,1.3504,1.35035,3.000
3,29.500,-0.01,1.2254,1.22540,3.000
3,29.625,0.00,1.1003,1.10030,3.000
3,29.750,0.00,0.9753,0.97530,3.000
3,29.875,0.00,0.8504,0.85040,3.000
3,30.000,0.00,0.7254,0.72540,3.000
3,30.125,0.00,0.6003,0.60025,3.000
3,30.250,0.00,0.4754,0.47540,3.000
3,30.375,0.00,0.3504,0.35035,3.000
3,30.500,0.00,0.2252,0.22520,3.000
3,30.625,0.00,0.1002,0.10020,3.000
3,30.750,0.00,-0.0247,-0.02470,3.000
3,30.938,-0.01,-0.0002,-0.00020,3.000
3,31.062,0.00,-0.0002,-0.00020,3.000
3,31.188,-0.01,-0.0002,-0.00020,3.000
3,31.312,0.00,-0.0002,-0.00020,3.000
3,31.438,0.00,-0.0002,-0.00020,3.000
3,31.562,0.00,-0.0002,-0.00020,3.000
3,31.688,0.00,-0.0002,-0.00020,3.000
3,31.812,0.00,-0.0002,-0.00020,3.000
3,31.938,0.00,-0.0002,-0.00020,3.000
3,32.062,-0.01,-0.0002,-0.00020,3.000
3,32.188,0.00,-0.0002,-0.00020,3.000
3,32.312,0.00,-0.0002,-0.00020,3.000
3,32.438,0.00,-0.0002,-0.00020,3.000
3,32.562,0.00,-0.0002,-0.00020,3.000
3,32.688,-0.01,-0.0001,-0.00010,3.000
3,32.812,-0.01,-0.0001,-0.00010,3.000
3,32.938,0.00,-0.0001,-0.00010,3.000
3,33.062,0.00,-0.0001,-0.00010,3.000
3,33.188,0.00,-0.0001,-0.00010,3.000
3,33.312,0.00,-0.0001,-0.00010,3.000
3,33.438,0.00,-0.0001,-0.00010,3.000
3,33.562,0.00,-0.0001,-0.00010,3.000
3,33.688,0.00,-0.0001,-0.00010,3.000
3,33.812,0.00,-0.0001,-0.00010,3.000
4,34.062,0.00,0.0312,0.03122,4.000
4,34.188,-0.01,0.1561,0.15610,4.000
4,34.312,-0.01,0.2811,0.28115,4.000
4,34.438,-0.01,0.4061,0.40608,4.000
4,34.562,0.00,0.5311,0.53110,4.000
4,34.688,-0.01,0.6559,0.65590,4.000
4,34.812,-0.01,0.7812,0.78122,4.000
4,34.938,0.00,0.9063,0.90625,4.000
4,35.062,-0.01,1.0312,1.03120,4.000
4,35.188,-0.01,1.1562,1.15620,4.000
4,35.312,0.00,1.2812,1.28122,4.000
4,35.438,-0.01,1.4061,1.40613,4.000
4,35.562,-0.01,1.5312,1.53120,4.000
4,35.688,-0.01,1.6562,1.65620,4.000
4,35.812,-0.01,1.7812,1.78117,4.000
4,35.938,-0.01,1.9062,1.90618,4.000
4,36.062,0.00,2.0311,2.03115,4.000
4,36.188,0.00,2.1562,2.15623,4.000
4,36.312,-0.01,2.2812,2.28122,4.000
4,36.438,0.00,2.4064,2.40638,4.000
4,36.562,0.02,2.5312,2.53117,4.000
4,36.688,0.06,2.6561,2.65605,4.000
4,36.812,0.13,2.7811,2.78112,4.000
4,36.938,0.27,2.9063,2.90625,4.000
4,37.062,0.49,3.0313,3.03130,4.000
4,37.188,0.79,3.1562,3.15623,4.000
4,37.312,1.19,3.2814,3.28140,4.000
4,37.438,1.68,3.4064,3.40640,4.000
4,37.562,2.28,3.5313,3.53135,4.000
4,37.688,2.98,3.6563,3.65630,4.000
4,37.812,3.82,3.7813,3.78130,4.000
4,37.938,4.75,3.9063,3.90630,4.000
4,38.125,4.70,3.9044,3.90440,4.000
4,38.250,3.54,3.7796,3.77960,4.000
4,38.375,2.64,3.6546,3.65455,4.000
4,38.500,1.93,3.5296,3.52960,4.000
4,38.625,1.36,3.4046,3.40455,4.000
4,38.750,0.91,3.2797,3.27970,4.000
4,38.875,0.58,3.1545,3.15450,4.000
4,39.000,0.32,3.0295,3.02950,4.000
4,39.125,0.16,2.9044,2.90440,4.000
4,39.250,0.06,2.7794,2.77940,4.000
4,39.375,0.02,2.6544,2.65435,4.000
4,39.500,-0.01,2.5295,2.52950,4.000
4,39.625,-0.01,2.4046,2.40455,4.000
4,39.750,-0.01,2.2796,2.27960,4.000
4,39.875,-0.01,2.1544,2.15445,4.000
4,40.000,0.00,2.0295,2.02950,4.000
4,40.125,-0.02,1.9044,1.90435,4.000
4,40.250,0.00,1.7794,1.77940,4.000
4,40.375,-0.01,1.6544,1.65435,4.000
4,40.500,0.00,1.5294,1.52940,4.000
4,40.625,0.00,1.4044,1.40440,4.000
4,40.750,-0.02,1.2793,1.27930,4.000
4,40.875,0.00,1.1544,1.15440,4.000
4,41.000,0.00,1.0295,1.02950,4.000
4,41.125,-0.01,0.9043,0.90430,4.000
4,41.250,-0.01,0.7794,0.77940,4.000
4,41.375,0.00,0.6542,0.65415,4.000
4,41.500,0.00,0.5293,0.52930,4.000
4,41.625,-0.01,0.4043,0.40430,4.000
4,41.750,0.00,0.2792,0.27920,4.000
4,41.875,-0.01,0.1542,0.15425,4.000
4,42.000,-0.01,0.0292,0.02920,4.000
4,42.188,-0.01,-0.0001,-0.00012,4.000
4,42.312,-0.01,-0.0001,-0.00010,4.000
4,42.438,-0.01,-0.0001,-0.00010,4.000
4,42.562,-0.01,-0.0001,-0.00010,4.000
4,42.688,0.00,-0.0001,-0.00010,4.000
4,42.812,-0.01,-0.0001,-0.00010,4.000
4,42.938,-0.01,-0.0001,-0.00010,4.000
4,43.062,-0.01,-0.0001,-0.00010,4.000
4,43.188,-0.01,-0.0001,-0.00010,4.000
4,43.312,0.00,-0.0001,-0.00010,4.000
4,43.438,0.00,-0.0001,-0.00010,4.000
4,43.562,-0.01,-0.0001,-0.00010,4.000
4,43.688,-0.01,-0.0001,-0.00010,4.000
4,43.812,-0.01,-0.0001,-0.00010,4.000
4,43.938,-0.01,-0.0001,-0.00010,4.000
4,44.062,-0.01,-0.0001,-0.00010,4.000
4,44.188,-0.01,-0.0001,-0.00010,4.000
4,44.312,-0.02,-0.0001,-0.00010,4.000
4,44.438,-0.02,-0.0001,-0.00010,4.000
4,44.562,-0.01,-0.0001,-0.00010,4.000
4,44.688,-0.01,-0.0001,-0.00010,4.000
4,44.812,-0.01,-0.0001,-0.00010,4.000
4,44.938,-0.01,-0.0001,-0.00010,4.000
4,45.062,0.00,-0.0001,-0.00010,4.000
5,45.438,0.00,0.1419,0.14190,5.000
5,45.562,0.00,0.2671,0.26710,5.000
5,45.688,0.00,0.3921,0.39213,5.000
5,45.812,0.01,0.5172,0.51720,5.000
5,45.938,0.00,0.6419,0.64193,5.000
5,46.062,0.01,0.7672,0.76717,5.000
5,46.188,0.00,0.8921,0.89208,5.000
5,46.312,0.01,1.0170,1.01702,5.000
5,46.438,0.00,1.1421,1.14205,5.000
5,46.562,0.00,1.2671,1.26712,5.000
5,46.688,0.01,1.3922,1.39215,5.000
5,46.812,0.01,1.5172,1.51722,5.000
5,46.938,0.01,1.6424,1.64235,5.000
5,47.062,0.01,1.7673,1.76732,5.000
5,47.188,0.00,1.8922,1.89215,5.000
5,47.312,0.00,2.0171,2.01710,5.000
5,47.438,0.01,2.1422,2.14218,5.000
5,47.562,0.00,2.2671,2.26715,5.000
5,47.688,0.01,2.3923,2.39233,5.000
5,47.812,0.03,2.5173,2.51730,5.000
5,47.938,0.07,2.6423,2.64228,5.000
5,48.062,0.13,2.7673,2.76727,5.000
5,48.188,0.27,2.8922,2.89220,5.000
5,48.312,0.47,3.0172,3.01720,5.000
5,48.438,0.77,3.1421,3.14213,5.000
5,48.562,1.15,3.2673,3.26730,5.000
5,48.688,1.63,3.3923,3.39230,5.000
5,48.812,2.22,3.5173,3.51732,5.000
5,48.938,2.92,3.6424,3.64238,5.000
5,49.062,3.74,3.7674,3.76737,5.000
5,49.188,4.67,3.8923,3.89233,5.000
5,49.312,5.45,3.9705,3.97048,5.000
5,49.438,4.17,3.8501,3.85007,5.000
5,49.562,3.14,3.7251,3.72510,5.000
5,49.688,2.33,3.6000,3.60002,5.000
5,49.812,1.67,3.4751,3.47505,5.000
5,49.938,1.17,3.3500,3.35005,5.000
5,50.062,0.78,3.2249,3.22490,5.000
5,50.188,0.48,3.0998,3.09982,5.000
5,50.312,0.26,2.9750,2.97495,5.000
5,50.438,0.12,2.8499,2.84990,5.000
5,50.562,0.05,2.7250,2.72495,5.000
5,50.688,0.02,2.5998,2.59985,5.000
5,50.812,0.01,2.4751,2.47505,5.000
5,50.938,0.02,2.3499,2.34992,5.000
5,51.062,0.01,2.2250,2.22495,5.000
5,51.188,0.01,2.0998,2.09982,5.000
5,51.312,0.01,1.9748,1.97475,5.000
5,51.438,0.00,1.8499,1.84995,5.000
5,51.562,0.01,1.7249,1.72493,5.000
5,51.688,0.01,1.6000,1.59997,5.000
5,51.812,0.01,1.4750,1.47500,5.000
5,51.938,0.00,1.3499,1.34990,5.000
5,52.062,0.01,1.2249,1.22485,5.000
5,52.188,0.01,1.0997,1.09972,5.000
5,52.312,0.01,0.9748,0.97475,5.000
5,52.438,0.01,0.8499,0.84995,5.000
5,52.562,0.00,0.7249,0.72485,5.000
5,52.688,0.01,0.5997,0.59975,5.000
5,52.812,0.00,0.4749,0.47488,5.000
5,52.938,0.01,0.3498,0.34985,5.000
5,53.062,0.01,0.2247,0.22468,5.000
5,53.188,0.00,0.0996,0.09965,5.000
5,53.375,0.01,-0.0353,-0.03525,5.000
5,53.500,0.01,-0.0002,-0.00020,5.000
5,53.625,0.01,-0.0002,-0.00020,5.000
5,53.750,0.01,-0.0002,-0.00020,5.000
5,53.875,0.01,-0.0002,-0.00020,5.000
5,54.000,0.01,-0.0002,-0.00020,5.000
5,54.125,0.00,-0.0002,-0.00020,5.000
5,54.250,0.01,-0.0002,-0.00020,5.000
5,54.375,0.00,-0.0002,-0.00020,5.000
5,54.500,0.01,-0.0002,-0.00020,5.000
5,54.625,0.00,-0.0002,-0.00020,5.000
5,54.750,0.01,-0.0002,-0.00020,5.000
5,54.875,0.00,-0.0002,-0.00020,5.000
5,55.000,0.02,-0.0002,-0.00020,5.000
5,55.125,0.01,-0.0002,-0.00020,5.000
5,55.250,0.00,-0.0002,-0.00020,5.000
5,55.375,0.01,-0.0002,-0.00020,5.000
5,55.500,0.02,-0.0002,-0.00020,5.000
5,55.625,0.01,-0.0001,-0.00010,5.000
5,55.750,0.01,-0.0001,-0.00010,5.000
5,55.875,0.00,-0.0001,-0.00010,5.000
5,56.000,0.01,-0.0001,-0.00010,5.000
5,56.125,0.01,-0.0001,-0.00010,5.000
5,56.250,0.00,-0.0001,-0.00010,5.000
6,56.625,-0.01,0.0435,0.04355,6.000
6,56.750,-0.01,0.1684,0.16840,6.000
6,56.875,0.00,0.2935,0.29350,6.000
6,57.000,0.01,0.4187,0.41870,6.000
6,57.125,0.00,0.5436,0.54360,6.000
6,57.250,-0.01,0.6686,0.66860,6.000
6,57.375,-0.01,0.7937,0.79375,6.000
6,57.500,-0.02,0.9188,0.91880,6.000
6,57.625,-0.01,1.0437,1.04370,6.000
6,57.750,-0.01,1.1686,1.16860,6.000
6,57.875,0.00,1.2936,1.29360,6.000
6,58.000,0.00,1.4186,1.41860,6.000
6,58.125,0.00,1.5437,1.54370,6.000
6,58.250,0.00,1.6687,1.66870,6.000
6,58.375,-0.01,1.7938,1.79385,6.000
6,58.500,-0.01,1.9187,1.91870,6.000
6,58.625,-0.01,2.0437,2.04375,6.000
6,58.750,-0.01,2.1689,2.16890,6.000
6,58.875,0.00,2.2937,2.29375,6.000
6,59.000,-0.01,2.4187,2.41870,6.000
6,59.125,0.03,2.5437,2.54370,6.000
6,59.250,0.07,2.6687,2.66870,6.000
6,59.375,0.15,2.7937,2.79370,6.000
6,59.500,0.29,2.9189,2.91890,6.000
6,59.625,0.52,3.0439,3.04390,6.000
6,59.750,0.84,3.1688,3.16880,6.000
6,59.875,1.23,3.2938,3.29385,6.000
6,60.000,1.75,3.4188,3.41880,6.000
6,60.125,2.35,3.5437,3.54375,6.000
6,60.250,3.07,3.6687,3.66870,6.000
6,60.375,3.92,3.7938,3.79380,6.000
6,60.500,4.89,3.9189,3.91890,6.000
6,60.688,4.59,3.8920,3.89200,6.000
6,60.812,3.45,3.7671,3.76710,6.000
6,60.938,2.57,3.6421,3.64215,6.000
6,61.062,1.87,3.5171,3.51705,6.000
6,61.188,1.31,3.3920,3.39197,6.000
6,61.312,0.88,3.2670,3.26700,6.000
6,61.438,0.56,3.1419,3.14190,6.000
6,61.562,0.31,3.0170,3.01703,6.000
6,61.688,0.15,2.8919,2.89190,6.000
6,61.812,0.06,2.7670,2.76695,6.000
6,61.938,0.02,2.6420,2.64198,6.000
6,62.062,0.01,2.5170,2.51695,6.000
6,62.188,-0.01,2.3920,2.39203,6.000
6,62.312,0.00,2.2669,2.26693,6.000
6,62.438,0.00,2.1419,2.14185,6.000
6,62.562,0.00,2.0168,2.01675,6.000
6,62.688,0.00,1.8919,1.89188,6.000
6,62.812,0.00,1.7670,1.76703,6.000
6,62.938,0.00,1.6420,1.64198,6.000
6,63.062,0.00,1.5170,1.51698,6.000
6,63.188,0.00,1.3919,1.39190,6.000
6,63.312,-0.01,1.2669,1.26685,6.000
6,63.438,-0.01,1.1418,1.14175,6.000
6,63.562,0.00,1.0168,1.01675,6.000
6,63.688,0.00,0.8918,0.89180,6.000
6,63.812,-0.01,0.7669,0.76690,6.000
6,63.938,0.00,0.6417,0.64165,6.000
6,64.062,-0.01,0.5169,0.51688,6.000
6,64.188,0.00,0.3920,0.39195,6.000
6,64.312,0.00,0.2668,0.26678,6.000
6,64.438,0.00,0.1417,0.14170,6.000
6,64.562,0.00,0.0167,0.01665,6.000
6,64.750,0.01,-0.0001,-0.00010,6.000
6,64.875,0.00,-0.0001,-0.00010,6.000
6,65.000,0.00,-0.0001,-0.00010,6.000
6,65.125,0.00,-0.0001,-0.00010,6.000
6,65.250,0.00,-0.0001,-0.00010,6.000
6,65.375,0.00,-0.0001,-0.00010,6.000
6,65.500,0.00,-0.0001,-0.00010,6.000
6,65.625,-0.01,-0.0001,-0.00010,6.000
6,65.750,0.00,-0.0001,-0.00010,6.000
6,65.875,0.00,-0.0001,-0.00010,6.000
6,66.000,-0.01,-0.0001,-0.00010,6.000
6,66.125,0.00,-0.0001,-0.00010,6.000
6,66.250,0.00,-0.0001,-0.00010,6.000
6,66.375,0.00,-0.0001,-0.00010,6.000
6,66.500,-0.01,-0.0001,-0.00010,6.000
6,66.625,0.00,-0.0001,-0.00010,6.000
6,66.750,-0.01,-0.0001,-0.00010,6.000
6,66.875,0.00,-0.0001,-0.00010,6.000
6,67.000,-0.01,-0.0001,-0.00010,6.000
6,67.125,0.00,-0.0001,-0.00010,6.000
6,67.250,-0.01,-0.0001,-0.00010,6.000
6,67.375,0.00,-0.0001,-0.00010,6.000
6,67.500,0.00,-0.0001,-0.00010,6.000
6,67.625,0.00,-0.0001,-0.00010,6.000
7,68.000,0.02,0.1384,0.13840,7.000
7,68.125,0.01,0.2636,0.26355,7.000
7,68.250,0.01,0.3886,0.38860,7.000
7,68.375,0.01,0.5137,0.51365,7.000
7,68.500,0.02,0.6385,0.63850,7.000
7,68.625,0.02,0.7636,0.76365,7.000
7,68.750,0.02,0.8886,0.88860,7.000
7,68.875,0.01,1.0136,1.01355,7.000
7,69.000,0.01,1.1385,1.13850,7.000
7,69.125,0.02,1.2636,1.26360,7.000
7,69.250,0.02,1.3886,1.38860,7.000
7,69.375,0.02,1.5138,1.51375,7.000
7,69.500,0.02,1.6388,1.63880,7.000
7,69.625,0.01,1.7638,1.76385,7.000
7,69.750,0.02,1.8887,1.88870,7.000
7,69.875,0.02,2.0137,2.01365,7.000
7,70.000,0.02,2.1386,2.13860,7.000
7,70.125,0.02,2.2637,2.26365,7.000
7,70.250,0.03,2.3887,2.38870,7.000
7,70.375,0.04,2.5138,2.51375,7.000
7,70.500,0.08,2.6387,2.63870,7.000
7,70.625,0.14,2.7638,2.76375,7.000
7,70.750,0.27,2.8889,2.88890,7.000
7,70.875,0.47,3.0138,3.01380,7.000
7,71.000,0.77,3.1386,3.13860,7.000
7,71.125,1.15,3.2638,3.26375,7.000
7,71.250,1.64,3.3888,3.38880,7.000
7,71.375,2.21,3.5138,3.51375,7.000
7,71.500,2.91,3.6389,3.63890,7.000
7,71.625,3.71,3.7639,3.76390,7.000
7,71.750,4.67,3.8889,3.88890,7.000
7,71.938,5.14,3.9418,3.94185,7.000
7,72.062,3.87,3.8170,3.81703,7.000
7,72.188,2.91,3.6920,3.69200,7.000
7,72.312,2.15,3.5670,3.56703,7.000
7,72.438,1.54,3.4420,3.44200,7.000
7,72.562,1.06,3.3171,3.31710,7.000
7,72.688,0.70,3.1920,3.19200,7.000
7,72.812,0.40,3.0669,3.06690,7.000
7,72.938,0.22,2.9419,2.94190,7.000
7,73.062,0.10,2.8169,2.81690,7.000
7,73.188,0.05,2.6920,2.69195,7.000
7,73.312,0.03,2.5669,2.56690,7.000
7,73.438,0.03,2.4421,2.44208,7.000
7,73.562,0.02,2.3170,2.31695,7.000
7,73.688,0.01,2.1920,2.19198,7.000
7,73.812,0.01,2.0670,2.06695,7.000
7,73.938,0.02,1.9417,1.94172,7.000
7,74.062,0.02,1.8170,1.81698,7.000
7,74.188,0.01,1.6919,1.69188,7.000
7,74.312,0.01,1.5669,1.56688,7.000
7,74.438,0.02,1.4419,1.44192,7.000
7,74.562,0.01,1.3168,1.31683,7.000
7,74.688,0.00,1.1919,1.19190,7.000
7,74.812,0.01,1.0668,1.06680,7.000
7,74.938,0.01,0.9418,0.94175,7.000
7,75.062,0.02,0.8169,0.81690,7.000
7,75.188,0.02,0.6917,0.69170,7.000
7,75.312,0.02,0.5668,0.56678,7.000
7,75.438,0.01,0.4419,0.44188,7.000
7,75.562,0.03,0.3168,0.31680,7.000
7,75.688,0.01,0.1917,0.19172,7.000
7,75.812,0.01,0.0668,0.06675,7.000
7,76.000,0.02,-0.0354,-0.03540,7.000
7,76.125,0.02,-0.0002,-0.00020,7.000
7,76.250,0.02,-0.0002,-0.00020,7.000
7,76.375,0.02,-0.0002,-0.00020,7.000
7,76.500,0.02,-0.0002,-0.00020,7.000
7,76.625,0.02,-0.0002,-0.00020,7.000
7,76.750,0.02,-0.0002,-0.00020,7.000
7,76.875,0.01,-0.0002,-0.00020,7.000
7,77.000,0.01,-0.0002,-0.00020,7.000
7,77.125,0.02,-0.0002,-0.00020,7.000
7,77.250,0.02,-0.0002,-0.00020,7.000
7,77.375,0.02,-0.0002,-0.00020,7.000
7,77.500,0.01,-0.0002,-0.00020,7.000
7,77.625,0.02,-0.0002,-0.00020,7.000
7,77.750,0.02,-0.0002,-0.00020,7.000
7,77.875,0.02,-0.0002,-0.00020,7.000
7,78.000,0.02,-0.0001,-0.00010,7.000
7,78.125,0.01,-0.0001,-0.00010,7.000
7,78.250,0.01,-0.0001,-0.00010,7.000
7,78.375,0.02,-0.0001,-0.00010,7.000
7,78.500,0.01,-0.0001,-0.00010,7.000
7,78.625,0.02,-0.0001,-0.00010,7.000
7,78.750,0.02,-0.0001,-0.00010,7.000
7,78.875,0.01,-0.0001,-0.00010,7.000
7,79.000,0.02,-0.0001,-0.00010,7.000
8,79.312,0.00,0.1110,0.11112,8.000
8,79.438,0.00,0.2361,0.23620,8.000
8,79.562,0.00,0.3612,0.36135,8.000
8,79.688,0.00,0.4862,0.48630,8.000
8,79.812,0.00,0.6110,0.61107,8.000
8,79.938,0.00,0.7360,0.73612,8.000
8,80.062,0.00,0.8610,0.86115,8.000
8,80.188,0.00,0.9862,0.98625,8.000
8,80.312,0.00,1.1112,1.11130,8.000
8,80.438,0.01,1.2361,1.23622,8.000
8,80.562,0.00,1.3612,1.36130,8.000
8,80.688,0.00,1.4863,1.48637,8.000
8,80.812,0.00,1.6113,1.61142,8.000
8,80.938,0.01,1.7362,1.73632,8.000
8,81.062,0.00,1.8611,1.86125,8.000
8,81.188,0.00,1.9861,1.98620,8.000
8,81.312,0.00,2.1112,2.11130,8.000
8,81.438,0.00,2.2362,2.23632,8.000
8,81.562,0.01,2.3613,2.36142,8.000
8,81.688,0.02,2.4863,2.48642,8.000
8,81.812,0.05,2.6112,2.61130,8.000
8,81.938,0.11,2.7362,2.73632,8.000
8,82.062,0.22,2.8612,2.86130,8.000
8,82.188,0.41,2.9863,2.98640,8.000
8,82.312,0.69,3.1111,3.11125,8.000
8,82.438,1.04,3.2363,3.23640,8.000
8,82.562,1.51,3.3614,3.36150,8.000
8,82.688,2.06,3.4863,3.48642,8.000
8,82.812,2.73,3.6114,3.61152,8.000
8,82.938,3.50,3.7364,3.73645,8.000
8,83.062,4.42,3.8613,3.86140,8.000
8,83.250,5.44,3.9697,3.96980,8.000
8,83.375,4.09,3.8446,3.84465,8.000
8,83.500,3.08,3.7196,3.71970,8.000
8,83.625,2.29,3.5945,3.59460,8.000
8,83.750,1.66,3.4694,3.46950,8.000
8,83.875,1.14,3.3446,3.34465,8.000
8,84.000,0.74,3.2195,3.21960,8.000
8,84.125,0.45,3.0945,3.09460,8.000
8,84.250,0.25,2.9696,2.96970,8.000
8,84.375,0.11,2.8445,2.84460,8.000
8,84.500,0.04,2.7195,2.71960,8.000
8,84.625,0.02,2.5944,2.59450,8.000
8,84.750,0.02,2.4695,2.46960,8.000
8,84.875,0.00,2.3444,2.34445,8.000
8,85.000,0.00,2.2194,2.21950,8.000
8,85.125,0.01,2.0944,2.09450,8.000
8,85.250,0.01,1.9692,1.96930,8.000
8,85.375,0.00,1.8445,1.84460,8.000
8,85.500,0.00,1.7195,1.71960,8.000
8,85.625,0.00,1.5944,1.59455,8.000
8,85.750,0.00,1.4694,1.46950,8.000
8,85.875,0.00,1.3443,1.34440,8.000
8,86.000,0.01,1.2192,1.21930,8.000
8,86.125,0.00,1.0943,1.09440,8.000
8,86.250,0.01,0.9693,0.96940,8.000
8,86.375,0.00,0.8444,0.84455,8.000
8,86.500,0.01,0.7193,0.71940,8.000
8,86.625,0.00,0.5943,0.59435,8.000
8,86.750,-0.01,0.4694,0.46950,8.000
8,86.875,0.00,0.3443,0.34440,8.000
8,87.000,0.00,0.2191,0.21920,8.000
8,87.125,0.00,0.0942,0.09425,8.000
8,87.250,0.00,-0.0308,-0.03070,8.000
8,87.375,0.01,-0.0004,-0.00035,8.000
8,87.500,0.00,-0.0002,-0.00010,8.000
8,87.625,0.00,-0.0002,-0.00010,8.000
8,87.750,0.01,-0.0002,-0.00010,8.000
8,87.875,0.00,-0.0002,-0.00010,8.000
8,88.000,0.01,-0.0002,-0.00010,8.000
8,88.125,0.00,-0.0002,-0.00010,8.000
8,88.250,0.00,-0.0002,-0.00010,8.000
8,88.375,0.00,-0.0002,-0.00010,8.000
8,88.500,0.00,-0.0002,-0.00010,8.000
8,88.625,0.00,-0.0002,-0.00010,8.000
8,88.750,0.00,-0.0002,-0.00010,8.000
8,88.875,0.00,-0.0001,0.00000,8.000
8,89.000,-0.01,-0.0001,0.00000,8.000
8,89.125,0.00,-0.0001,0.00000,8.000
8,89.250,0.00,-0.0001,0.00000,8.000
8,89.375,0.00,-0.0001,0.00000,8.000
8,89.500,0.00,-0.0001,0.00000,8.000
8,89.625,0.01,-0.0001,0.00000,8.000
8,89.750,0.00,-0.0001,0.00000,8.000
8,89.875,-0.01,-0.0001,0.00000,8.000
8,90.000,0.01,-0.0001,0.00000,8.000
8,90.125,0.01,-0.0001,0.00000,8.000
8,90.250,-0.01,-0.0001,0.00000,8.000
9,90.562,0.01,0.0659,0.06595,9.000
9,90.688,0.01,0.1910,0.19100,9.000
9,90.812,0.01,0.3160,0.31605,9.000
9,90.938,0.01,0.4412,0.44120,9.000
9,91.062,0.01,0.5661,0.56607,9.000
9,91.188,0.00,0.6910,0.69095,9.000
9,91.312,0.00,0.8161,0.81612,9.000
9,91.438,0.01,0.9411,0.94110,9.000
9,91.562,0.00,1.0661,1.06607,9.000
9,91.688,0.01,1.1912,1.19117,9.000
9,91.812,0.01,1.3162,1.31617,9.000
9,91.938,0.01,1.4412,1.44125,9.000
9,92.062,0.01,1.5663,1.56627,9.000
9,92.188,0.00,1.6912,1.69122,9.000
9,92.312,0.01,1.8162,1.81620,9.000
9,92.438,0.01,1.9411,1.94110,9.000
9,92.562,0.00,2.0662,2.06620,9.000
9,92.688,0.01,2.1911,2.19112,9.000
9,92.812,0.02,2.3163,2.31630,9.000
9,92.938,0.02,2.4414,2.44138,9.000
9,93.062,0.05,2.5662,2.56620,9.000
9,93.188,0.09,2.6912,2.69122,9.000
9,93.312,0.17,2.8162,2.81622,9.000
9,93.438,0.34,2.9412,2.94118,9.000
9,93.562,0.57,3.0662,3.06620,9.000
9,93.688,0.91,3.1912,3.19125,9.000
9,93.812,1.33,3.3164,3.31640,9.000
9,93.938,1.86,3.4414,3.44135,9.000
9,94.062,2.48,3.5664,3.56640,9.000
9,94.188,3.23,3.6914,3.69138,9.000
9,94.312,4.09,3.8163,3.81635,9.000
9,94.438,5.08,3.9414,3.94135,9.000
9,94.625,4.45,3.8795,3.87950,9.000
9,94.750,3.36,3.7546,3.75460,9.000
9,94.875,2.50,3.6294,3.62945,9.000
9,95.000,1.82,3.5044,3.50440,9.000
9,95.125,1.28,3.3795,3.37950,9.000
9,95.250,0.86,3.2546,3.25460,9.000
9,95.375,0.54,3.1295,3.12950,9.000
9,95.500,0.30,3.0045,3.00450,9.000
9,95.625,0.14,2.8795,2.87950,9.000
9,95.750,0.07,2.7545,2.75450,9.000
9,95.875,0.03,2.6293,2.62930,9.000
9,96.000,0.00,2.5043,2.50430,9.000
9,96.125,0.01,2.3794,2.37940,9.000
9,96.250,0.02,2.2544,2.25440,9.000
9,96.375,0.01,2.1295,2.12945,9.000
9,96.500,0.01,2.0045,2.00450,9.000
9,96.625,0.02,1.8795,1.87950,9.000
9,96.750,0.01,1.7545,1.75450,9.000
9,96.875,0.02,1.6294,1.62940,9.000
9,97.000,0.00,1.5043,1.50430,9.000
9,97.125,0.01,1.3793,1.37930,9.000
9,97.250,0.01,1.2543,1.25430,9.000
9,97.375,0.01,1.1293,1.12930,9.000
9,97.500,-0.01,1.0043,1.00430,9.000
9,97.625,0.01,0.8794,0.87945,9.000
9,97.750,0.01,0.7545,0.75450,9.000
9,97.875,0.01,0.6292,0.62920,9.000
9,98.000,0.01,0.5043,0.50430,9.000
9,98.125,0.00,0.3792,0.37925,9.000
9,98.250,0.01,0.2542,0.25420,9.000
9,98.375,0.01,0.1291,0.12915,9.000
9,98.500,0.02,0.0042,0.00420,9.000
9,98.688,0.01,-0.0002,-0.00015,9.000
9,98.812,0.01,-0.0002,-0.00020,9.000
9,98.938,0.01,-0.0002,-0.00020,9.000
9,99.062,0.02,-0.0002,-0.00020,9.000
9,99.188,0.01,-0.0002,-0.00020,9.000
9,99.312,0.01,-0.0002,-0.00020,9.000
9,99.438,0.01,-0.0002,-0.00020,9.000
9,99.562,0.02,-0.0002,-0.00020,9.000
9,99.688,0.00,-0.0002,-0.00020,9.000
9,99.812,0.00,-0.0002,-0.00020,9.000
9,99.938,0.01,-0.0002,-0.00020,9.000
9,100.062,0.01,-0.0002,-0.00020,9.000
9,100.188,0.01,-0.0002,-0.00020,9.000
9,100.312,0.01,-0.0002,-0.00018,9.000
9,100.438,0.01,-0.0001,-0.00010,9.000
9,100.562,0.01,-0.0001,-0.00010,9.000
9,100.688,0.01,-0.0001,-0.00010,9.000
9,100.812,0.02,-0.0001,-0.00010,9.000
9,100.938,0.01,-0.0001,-0.00010,9.000
9,101.062,0.00,-0.0001,-0.00010,9.000
9,101.188,0.01,-0.0001,-0.00010,9.000
9,101.312,0.01,-0.0001,-0.00010,9.000
9,101.438,0.01,-0.0001,-0.00010,9.000
9,101.562,0.00,-0.0001,-0.00010,9.000
10,101.875,0.00,0.0924,0.09255,10.000
10,102.000,0.00,0.2175,0.21760,10.000
10,102.125,0.00,0.3426,0.34270,10.000
10,102.250,0.00,0.4676,0.46770,10.000
10,102.375,0.01,0.5926,0.59265,10.000
10,102.500,0.00,0.7176,0.71770,10.000
10,102.625,0.01,0.8428,0.84285,10.000
10,102.750,0.00,0.9678,0.96790,10.000
10,102.875,0.00,1.0926,1.09270,10.000
10,103.000,0.00,1.2176,1.21770,10.000
10,103.125,0.01,1.3426,1.34265,10.000
10,103.250,0.01,1.4677,1.46780,10.000
10,103.375,0.01,1.5927,1.59280,10.000
10,103.500,0.01,1.7178,1.71790,10.000
10,103.625,0.01,1.8428,1.84295,10.000
10,103.750,0.00,1.9677,1.96780,10.000
10,103.875,0.00,2.0927,2.09280,10.000
10,104.000,-0.01,2.2176,2.21770,10.000
10,104.125,0.00,2.3427,2.34280,10.000
10,104.250,0.02,2.4678,2.46790,10.000
10,104.375,0.05,2.5926,2.59270,10.000
10,104.500,0.10,2.7178,2.71790,10.000
10,104.625,0.20,2.8428,2.84285,10.000
10,104.750,0.38,2.9679,2.96800,10.000
10,104.875,0.64,3.0928,3.09290,10.000
10,105.000,0.99,3.2177,3.21780,10.000
10,105.125,1.43,3.3429,3.34295,10.000
10,105.250,1.98,3.4677,3.46780,10.000
10,105.375,2.63,3.5928,3.59290,10.000
10,105.500,3.38,3.7179,3.71800,10.000
10,105.625,4.28,3.8429,3.84295,10.000
10,105.750,5.31,3.9679,3.96800,10.000
10,105.875,4.90,3.9236,3.92365,10.000
10,106.000,3.70,3.7985,3.79860,10.000
10,106.125,2.77,3.6735,3.67360,10.000
10,106.250,2.03,3.5483,3.54840,10.000
10,106.375,1.45,3.4234,3.42355,10.000
10,106.500,0.98,3.2985,3.29860,10.000
10,106.625,0.64,3.1735,3.17360,10.000
10,106.750,0.37,3.0485,3.04860,10.000
10,106.875,0.19,2.9236,2.92365,10.000
10,107.000,0.09,2.7985,2.79860,10.000
10,107.125,0.04,2.6734,2.67350,10.000
10,107.250,0.01,2.5484,2.54850,10.000
10,107.375,0.01,2.4235,2.42355,10.000
10,107.500,0.01,2.2984,2.29850,10.000
10,107.625,0.01,2.1734,2.17350,10.000
10,107.750,0.00,2.0485,2.04860,10.000
10,107.875,0.00,1.9234,1.92350,10.000
10,108.000,0.01,1.7985,1.79860,10.000
10,108.125,0.01,1.6734,1.67350,10.000
10,108.250,0.01,1.5484,1.54850,10.000
10,108.375,0.01,1.4233,1.42340,10.000
10,108.500,0.00,1.2983,1.29840,10.000
10,108.625,0.01,1.1733,1.17340,10.000
10,108.750,0.00,1.0484,1.04850,10.000
10,108.875,0.00,0.9234,0.92345,10.000
10,109.000,0.00,0.7986,0.79870,10.000
10,109.125,0.00,0.6732,0.67330,10.000
10,109.250,0.00,0.5483,0.54840,10.000
10,109.375,0.01,0.4232,0.42335,10.000
10,109.500,0.01,0.2981,0.29820,10.000
10,109.625,0.01,0.1732,0.17330,10.000
10,109.750,0.00,0.0483,0.04840,10.000
10,109.938,0.01,-0.0067,-0.00660,10.000
10,110.062,0.00,-0.0001,0.00000,10.000
10,110.188,0.01,-0.0001,0.00000,10.000
10,110.312,0.01,-0.0001,0.00000,10.000
10,110.438,0.01,-0.0001,0.00000,10.000
10,110.562,0.00,-0.0001,0.00000,10.000
10,110.688,0.00,-0.0001,0.00000,10.000
10,110.812,0.00,-0.0001,0.00000,10.000
10,110.938,0.00,-0.0001,0.00000,10.000
10,111.062,0.00,-0.0001,0.00000,10.000
10,111.188,0.00,-0.0001,0.00000,10.000
10,111.312,0.01,-0.0001,0.00000,10.000
10,111.438,0.01,-0.0001,0.00000,10.000
10,111.562,0.00,-0.0001,0.00000,10.000
10,111.688,0.01,-0.0001,0.00000,10.000
10,111.812,0.00,-0.0001,0.00000,10.000
10,111.938,0.01,-0.0001,0.00000,10.000
10,112.062,0.00,-0.0001,0.00000,10.000
10,112.188,0.01,-0.0001,0.00000,10.000
10,112.312,0.01,-0.0001,0.00000,10.000
10,112.438,0.00,-0.0001,0.00000,10.000
10,112.562,0.00,-0.0001,0.00000,10.000
10,112.688,0.01,-0.0001,0.00000,10.000
10,112.812,0.01,-0.0001,0.00000,10.000
10,112.875,0.00,-0.0001,0.00000,10.000