File: calibDATA_loadcell/date_02:22:2018/Instron/1N_0_1_1_0.txt
""
"Test Method","Radhen_Load_Cntrl_Cmprsn_250N_12-7.msm"
"Sample I. D.","Sample1.mss"
"Specimen Number","4"

"TheCycle_Output ()","_Time (s)","_Load (N)","_Extension (mm)","RealTimeDepth (mm)","CycleNumber ()"

1,0.312,0.01,0.0711,0.07115,1.000
1,0.438,0.01,0.1962,0.19615,1.000
1,0.562,0.01,0.3212,0.32120,1.000
1,0.688,0.00,0.4462,0.44618,1.000
1,0.812,0.01,0.5712,0.57125,1.000
1,0.938,0.01,0.6964,0.69640,1.000
1,1.062,0.01,0.8213,0.82132,1.000
1,1.188,0.01,0.9464,0.94638,1.000
1,1.312,0.01,1.0714,1.07138,1.000
1,1.438,0.01,1.1963,1.19630,1.000
1,1.562,0.01,1.3213,1.32130,1.000
1,1.688,0.01,1.4463,1.44630,1.000
1,1.812,0.01,1.5714,1.57138,1.000
1,1.938,0.01,1.6965,1.69648,1.000
1,2.062,0.00,1.8212,1.82125,1.000
1,2.188,0.01,1.9463,1.94632,1.000
1,2.312,0.00,2.0714,2.07138,1.000
1,2.438,0.01,2.1964,2.19640,1.000
1,2.562,0.00,2.3214,2.32140,1.000
1,2.688,0.00,2.4463,2.44630,1.000
1,2.812,0.01,2.5712,2.57122,1.000
1,2.938,0.01,2.6964,2.69635,1.000
1,3.062,0.00,2.8214,2.82142,1.000
1,3.188,0.01,2.9465,2.94648,1.000
1,3.312,0.02,3.0715,3.07152,1.000
1,3.438,0.03,3.1965,3.19648,1.000
1,3.562,0.04,3.3214,3.32145,1.000
1,3.688,0.08,3.4462,3.44625,1.000
1,3.812,0.15,3.5715,3.57148,1.000
1,3.938,0.29,3.6965,3.69645,1.000
1,4.062,0.52,3.8214,3.82142,1.000
1,4.188,0.82,3.9465,3.94648,1.000
1,4.375,1.04,4.0046,4.00455,1.000
1,4.500,0.60,3.8797,3.87970,1.000
1,4.625,0.33,3.7548,3.75475,1.000
1,4.750,0.16,3.6299,3.62990,1.000
1,4.875,0.07,3.5047,3.50470,1.000
1,5.000,0.03,3.3797,3.37970,1.000
1,5.125,0.02,3.2546,3.25455,1.000
1,5.250,0.01,3.1296,3.12960,1.000
1,5.375,0.01,3.0046,3.00460,1.000
1,5.500,0.01,2.8796,2.87960,1.000
1,5.625,0.00,2.7546,2.75460,1.000
1,5.750,0.01,2.6296,2.62960,1.000
1,5.875,0.01,2.5046,2.50455,1.000
1,6.000,0.01,2.3796,2.37960,1.000
1,6.125,0.01,2.2545,2.25450,1.000
1,6.250,0.01,2.1294,2.12940,1.000
1,6.375,0.01,2.0044,2.00440,1.000
1,6.500,0.01,1.8794,1.87940,1.000
1,6.625,0.01,1.7544,1.75440,1.000
1,6.750,0.00,1.6296,1.62960,1.000
1,6.875,0.01,1.5045,1.50450,1.000
1,7.000,0.00,1.3796,1.37960,1.000
1,7.125,0.01,1.2544,1.25445,1.000
1,7.250,0.01,1.1293,1.12930,1.000
1,7.375,0.01,1.0044,1.00440,1.000
1,7.500,0.00,0.8792,0.87920,1.000
1,7.625,0.00,0.7544,0.75440,1.000
1,7.750,0.01,0.6294,0.62940,1.000
1,7.875,0.01,0.5044,0.50440,1.000
1,8.000,0.00,0.3795,0.37950,1.000
1,8.125,0.00,0.2544,0.25440,1.000
1,8.250,0.01,0.1292,0.12920,1.000
1,8.375,0.01,0.0042,0.00415,1.000
1,8.562,0.00,-0.0003,-0.00030,1.000
1,8.688,0.01,-0.0003,-0.00030,1.000
1,8.812,0.00,-0.0003,-0.00030,1.000
1,8.938,0.02,-0.0003,-0.00030,1.000
1,9.062,0.01,-0.0003,-0.00030,1.000
1,9.188,0.01,-0.0003,-0.00030,1.000
1,9.312,0.01,-0.0003,-0.00030,1.000
1,9.438,0.00,-0.0003,-0.00030,1.000
1,9.562,0.01,-0.0003,-0.00030,1.000
1,9.688,0.01,-0.0003,-0.00030,1.000
1,9.812,0.00,-0.0003,-0.00030,1.000
1,9.938,0.01,-0.0002,-0.00020,1.000
1,10.062,0.01,-0.0002,-0.00020,1.000
1,10.188,0.01,-0.0002,-0.00020,1.000
1,10.312,0.01,-0.0002,-0.00020,1.000
1,10.438,0.01,-0.0002,-0.00020,1.000
1,10.562,0.01,-0.0002,-0.00020,1.000
1,10.688,0.00,-0.0002,-0.00020,1.000
1,10.812,0.01,-0.0002,-0.00020,1.000
1,10.938,0.01,-0.0002,-0.00020,1.000
1,11.062,0.01,-0.0002,-0.00020,1.000
1,11.188,0.00,-0.0002,-0.00020,1.000
1,11.312,0.01,-0.0002,-0.00020,1.000
1,11.438,0.01,-0.0002,-0.00020,1.000
2,11.812,0.00,0.1421,0.14220,2.000
2,11.938,0.01,0.2673,0.26735,2.000
2,12.062,0.01,0.3922,0.39227,2.000
2,12.188,0.01,0.5171,0.51723,2.000
2,12.312,0.01,0.6422,0.64227,2.000
2,12.438,0.01,0.7671,0.76720,2.000
2,12.562,0.00,0.8921,0.89222,2.000
2,12.688,0.01,1.0173,1.01738,2.000
2,12.812,0.01,1.1422,1.14230,2.000
2,12.938,0.01,1.2673,1.26743,2.000
2,13.062,0.01,1.3923,1.39237,2.000
2,13.188,0.01,1.5173,1.51740,2.000
2,13.312,0.01,1.6423,1.64242,2.000
2,13.438,0.01,1.7671,1.76723,2.000
2,13.562,0.01,1.8922,1.89230,2.000
2,13.688,0.00,2.0173,2.01738,2.000
2,13.812,0.01,2.1423,2.14240,2.000
2,13.938,0.00,2.2673,2.26743,2.000
2,14.062,0.01,2.3923,2.39245,2.000
2,14.188,0.01,2.5172,2.51733,2.000
2,14.312,0.01,2.6423,2.64238,2.000
2,14.438,0.01,2.7673,2.76738,2.000
2,14.562,0.01,2.8922,2.89232,2.000
2,14.688,0.00,3.0173,3.01740,2.000
2,14.812,0.02,3.1423,3.14245,2.000
2,14.938,0.04,3.2673,3.26738,2.000
2,15.062,0.06,3.3924,3.39248,2.000
2,15.188,0.12,3.5174,3.51750,2.000
2,15.312,0.22,3.6424,3.64250,2.000
2,15.438,0.42,3.7674,3.76745,2.000
2,15.562,0.68,3.8922,3.89232,2.000
2,15.688,1.04,4.0173,4.01738,2.000
2,15.875,0.77,3.9356,3.93565,2.000
2,16.000,0.44,3.8105,3.81060,2.000
2,16.125,0.22,3.6857,3.68575,2.000
2,16.250,0.10,3.5607,3.56080,2.000
2,16.375,0.05,3.4356,3.43570,2.000
2,16.500,0.03,3.3107,3.31080,2.000
2,16.625,0.02,3.1856,3.18570,2.000
2,16.750,0.01,3.0606,3.06070,2.000
2,16.875,0.01,2.9355,2.93560,2.000
2,17.000,0.00,2.8104,2.81050,2.000
2,17.125,0.01,2.6855,2.68560,2.000
2,17.250,0.00,2.5604,2.56050,2.000
2,17.375,0.01,2.4355,2.43560,2.000
2,17.500,0.01,2.3106,2.31070,2.000
2,17.625,0.01,2.1854,2.18555,2.000
2,17.750,0.01,2.0606,2.06070,2.000
2,17.875,0.01,1.9354,1.93550,2.000
2,18.000,0.01,1.8103,1.81040,2.000
2,18.125,0.01,1.6855,1.68560,2.000
2,18.250,0.00,1.5604,1.56050,2.000
2,18.375,0.01,1.4355,1.43560,2.000
2,18.500,0.00,1.3104,1.31050,2.000
2,18.625,0.01,1.1855,1.18555,2.000
2,18.750,0.01,1.0606,1.06070,2.000
2,18.875,0.01,0.9353,0.93540,2.000
2,19.000,0.00,0.8103,0.81040,2.000
2,19.125,0.01,0.6854,0.68545,2.000
2,19.250,0.00,0.5603,0.56040,2.000
2,19.375,0.01,0.4353,0.43540,2.000
2,19.500,0.01,0.3104,0.31050,2.000
2,19.625,0.01,0.1854,0.18545,2.000
2,19.750,0.00,0.0603,0.06040,2.000
2,19.938,0.01,-0.0323,-0.03218,2.000
2,20.062,0.01,-0.0004,-0.00030,2.000
2,20.188,0.01,-0.0003,-0.00020,2.000
2,20.312,0.01,-0.0003,-0.00020,2.000
2,20.438,0.01,-0.0003,-0.00020,2.000
2,20.562,0.01,-0.0003,-0.00020,2.000
2,20.688,0.01,-0.0003,-0.00020,2.000
2,20.812,0.01,-0.0003,-0.00020,2.000
2,20.938,0.01,-0.0003,-0.00020,2.000
2,21.062,0.01,-0.0003,-0.00020,2.000
2,21.188,0.01,-0.0003,-0.00020,2.000
2,21.312,0.00,-0.0003,-0.00020,2.000
2,21.438,0.01,-0.0003,-0.00020,2.000
2,21.562,0.01,-0.0003,-0.00020,2.000
2,21.688,0.00,-0.0003,-0.00020,2.000
2,21.812,0.01,-0.0003,-0.00020,2.000
2,21.938,0.00,-0.0003,-0.00020,2.000
2,22.062,0.01,-0.0003,-0.00020,2.000
2,22.188,0.01,-0.0003,-0.00020,2.000
2,22.312,0.00,-0.0002,-0.00010,2.000
2,22.438,0.01,-0.0002,-0.00010,2.000
2,22.562,0.00,-0.0002,-0.00010,2.000
2,22.688,0.01,-0.0002,-0.00010,2.000
2,22.812,0.00,-0.0002,-0.00010,2.000
3,23.188,0.00,0.0651,0.06517,3.000
3,23.312,0.00,0.1902,0.19025,3.000
3,23.438,0.00,0.3151,0.31522,3.000
3,23.562,0.00,0.4400,0.44013,3.000
3,23.688,0.00,0.5651,0.56520,3.000
3,23.812,0.00,0.6902,0.69025,3.000
3,23.938,0.00,0.8152,0.81527,3.000
3,24.062,0.00,0.9402,0.94030,3.000
3,24.188,0.00,1.0653,1.06545,3.000
3,24.312,-0.01,1.1902,1.19032,3.000
3,24.438,0.00,1.3152,1.31532,3.000
3,24.562,-0.01,1.4403,1.44037,3.000
3,24.688,-0.01,1.5653,1.56542,3.000
3,24.812,0.00,1.6902,1.69035,3.000
3,24.938,0.00,1.8151,1.81525,3.000
3,25.062,0.00,1.9403,1.94037,3.000
3,25.188,0.00,2.0653,2.06537,3.000
3,25.312,-0.01,2.1903,2.19040,3.000
3,25.438,0.00,2.3154,2.31550,3.000
3,25.562,0.00,2.4403,2.44037,3.000
3,25.688,0.00,2.5652,2.56530,3.000
3,25.812,-0.01,2.6902,2.69035,3.000
3,25.938,0.00,2.8152,2.81530,3.000
3,26.062,-0.01,2.9402,2.94035,3.000
3,26.188,0.00,3.0654,3.06547,3.000
3,26.312,0.01,3.1903,3.19045,3.000
3,26.438,0.04,3.3154,3.31547,3.000
3,26.562,0.07,3.4403,3.44037,3.000
3,26.688,0.14,3.5653,3.56545,3.000
3,26.812,0.28,3.6903,3.69042,3.000
3,26.938,0.49,3.8152,3.81535,3.000
3,27.062,0.79,3.9403,3.94042,3.000
3,27.250,1.13,4.0281,4.02820,3.000
3,27.375,0.66,3.9036,3.90370,3.000
3,27.500,0.36,3.7786,3.77870,3.000
3,27.625,0.17,3.6536,3.65370,3.000
3,27.750,0.06,3.5285,3.52860,3.000
3,27.875,0.03,3.4035,3.40360,3.000
3,28.000,0.01,3.2785,3.27860,3.000
3,28.125,0.00,3.1537,3.15380,3.000
3,28.250,-0.01,3.0287,3.02880,3.000
3,28.375,0.00,2.9036,2.90365,3.000
3,28.500,-0.01,2.7785,2.77860,3.000
3,28.625,-0.01,2.6535,2.65355,3.000
3,28.750,0.00,2.5283,2.52840,3.000
3,28.875,-0.01,2.4034,2.40350,3.000
3,29.000,-0.01,2.2785,2.27860,3.000
3,29.125,0.00,2.1535,2.15355,3.000
3,29.250,0.00,2.0285,2.02860,3.000
3,29.375,-0.01,1.9034,1.90350,3.000
3,29.500,-0.01,1.7785,1.77860,3.000
3,29.625,0.00,1.6536,1.65365,3.000
3,29.750,0.00,1.5283,1.52840,3.000
3,29.875,0.00,1.4034,1.40355,3.000
3,30.000,-0.01,1.2785,1.27860,3.000
3,30.125,0.00,1.1534,1.15350,3.000
3,30.250,0.00,1.0285,1.02860,3.000
3,30.375,-0.01,0.9034,0.90350,3.000
3,30.500,-0.01,0.7784,0.77850,3.000
3,30.625,0.00,0.6534,0.65345,3.000
3,30.750,0.00,0.5282,0.52830,3.000
3,30.875,-0.01,0.4032,0.40330,3.000
3,31.000,0.00,0.2782,0.27830,3.000
3,31.125,-0.01,0.1533,0.15340,3.000
3,31.250,0.00,0.0283,0.02840,3.000
3,31.438,0.00,0.0004,0.00052,3.000
3,31.562,0.00,-0.0003,-0.00020,3.000
3,31.688,0.00,-0.0003,-0.00020,3.000
3,31.812,-0.01,-0.0003,-0.00020,3.000
3,31.938,-0.01,-0.0003,-0.00020,3.000
3,32.062,-0.01,-0.0003,-0.00020,3.000
3,32.188,0.00,-0.0003,-0.00020,3.000
3,32.312,0.00,-0.0003,-0.00020,3.000
3,32.438,0.00,-0.0003,-0.00020,3.000
3,32.562,0.00,-0.0003,-0.00020,3.000
3,32.688,0.00,-0.0003,-0.00020,3.000
3,32.812,-0.01,-0.0003,-0.00020,3.000
3,32.938,0.00,-0.0003,-0.00020,3.000
3,33.062,-0.01,-0.0003,-0.00020,3.000
3,33.188,0.00,-0.0002,-0.00010,3.000
3,33.312,-0.01,-0.0002,-0.00010,3.000
3,33.438,-0.01,-0.0002,-0.00010,3.000
3,33.562,0.00,-0.0002,-0.00010,3.000
3,33.688,0.00,-0.0002,-0.00010,3.000
3,33.812,-0.01,-0.0002,-0.00010,3.000
3,33.938,0.00,-0.0002,-0.00010,3.000
3,34.062,-0.01,-0.0002,-0.00010,3.000
3,34.188,-0.01,-0.0002,-0.00010,3.000
3,34.312,-0.01,-0.0002,-0.00010,3.000
4,34.688,0.00,0.0661,0.06618,4.000
4,34.812,0.00,0.1911,0.19125,4.000
4,34.938,0.00,0.3162,0.31625,4.000
4,35.062,0.00,0.4410,0.44110,4.000
4,35.188,0.00,0.5661,0.56620,4.000
4,35.312,0.00,0.6911,0.69120,4.000
4,35.438,0.00,0.8161,0.81620,4.000
4,35.562,0.00,0.9412,0.94127,4.000
4,35.688,0.00,1.0664,1.06645,4.000
4,35.812,0.00,1.1912,1.19130,4.000
4,35.938,0.00,1.3163,1.31638,4.000
4,36.062,0.00,1.4412,1.44130,4.000
4,36.188,0.00,1.5663,1.56643,4.000
4,36.312,0.00,1.6913,1.69140,4.000
4,36.438,0.00,1.8161,1.81618,4.000
4,36.562,-0.01,1.9412,1.94132,4.000
4,36.688,0.00,2.0664,2.06645,4.000
4,36.812,0.00,2.1913,2.19140,4.000
4,36.938,-0.01,2.3165,2.31658,4.000
4,37.062,0.00,2.4412,2.44135,4.000
4,37.188,0.00,2.5662,2.56633,4.000
4,37.312,0.00,2.6911,2.69122,4.000
4,37.438,0.00,2.8162,2.81633,4.000
4,37.562,0.00,2.9412,2.94135,4.000
4,37.688,0.00,3.0663,3.06640,4.000
4,37.812,0.01,3.1914,3.19150,4.000
4,37.938,0.03,3.3163,3.31643,4.000
4,38.062,0.07,3.4413,3.44140,4.000
4,38.188,0.14,3.5664,3.56645,4.000
4,38.312,0.28,3.6913,3.69142,4.000
4,38.438,0.50,3.8164,3.81645,4.000
4,38.562,0.79,3.9413,3.94142,4.000
4,38.750,1.05,4.0095,4.00960,4.000
4,38.875,0.61,3.8846,3.88465,4.000
4,39.000,0.33,3.7597,3.75980,4.000
4,39.125,0.15,3.6347,3.63480,4.000
4,39.250,0.06,3.5096,3.50970,4.000
4,39.375,0.03,3.3846,3.38470,4.000
4,39.500,0.01,3.2596,3.25970,4.000
4,39.625,0.00,3.1346,3.13465,4.000
4,39.750,0.00,3.0095,3.00960,4.000
4,39.875,0.00,2.8845,2.88460,4.000
4,40.000,0.00,2.7596,2.75970,4.000
4,40.125,0.00,2.6346,2.63465,4.000
4,40.250,0.00,2.5096,2.50970,4.000
4,40.375,0.00,2.3846,2.38465,4.000
4,40.500,0.00,2.2596,2.25970,4.000
4,40.625,-0.01,2.1344,2.13445,4.000
4,40.750,0.00,2.0093,2.00940,4.000
4,40.875,0.00,1.8844,1.88445,4.000
4,41.000,0.00,1.7593,1.75940,4.000
4,41.125,0.00,1.6346,1.63470,4.000
4,41.250,-0.01,1.5095,1.50960,4.000
4,41.375,-0.01,1.3846,1.38470,4.000
4,41.500,0.00,1.2594,1.25950,4.000
4,41.625,0.00,1.1344,1.13445,4.000
4,41.750,0.00,1.0093,1.00940,4.000
4,41.875,0.00,0.8842,0.88430,4.000
4,42.000,0.00,0.7593,0.75940,4.000
4,42.125,0.00,0.6344,0.63450,4.000
4,42.250,-0.01,0.5094,0.50950,4.000
4,42.375,0.00,0.3844,0.38450,4.000
4,42.500,0.00,0.2594,0.25950,4.000
4,42.625,0.00,0.1342,0.13435,4.000
4,42.750,0.00,0.0091,0.00920,4.000
4,42.938,0.00,-0.0003,-0.00020,4.000
4,43.062,0.00,-0.0003,-0.00020,4.000
4,43.188,0.00,-0.0003,-0.00020,4.000
4,43.312,0.00,-0.0003,-0.00020,4.000
4,43.438,0.00,-0.0003,-0.00020,4.000
4,43.562,0.00,-0.0003,-0.00020,4.000
4,43.688,-0.01,-0.0003,-0.00020,4.000
4,43.812,0.00,-0.0003,-0.00020,4.000
4,43.938,0.00,-0.0003,-0.00020,4.000
4,44.062,0.00,-0.0003,-0.00020,4.000
4,44.188,0.00,-0.0003,-0.00020,4.000
4,44.312,0.00,-0.0003,-0.00020,4.000
4,44.438,0.00,-0.0003,-0.00020,4.000
4,44.562,0.00,-0.0003,-0.00020,4.000
4,44.688,0.00,-0.0003,-0.00020,4.000
4,44.812,0.00,-0.0003,-0.00020,4.000
4,44.938,0.00,-0.0002,-0.00010,4.000
4,45.062,0.00,-0.0002,-0.00010,4.000
4,45.188,0.00,-0.0002,-0.00010,4.000
4,45.312,0.00,-0.0002,-0.00010,4.000
4,45.438,0.00,-0.0002,-0.00010,4.000
4,45.562,0.00,-0.0002,-0.00010,4.000
4,45.688,0.00,-0.0002,-0.00010,4.000
4,45.812,0.00,-0.0002,-0.00010,4.000
5,46.188,0.00,0.1370,0.13710,5.000
5,46.312,0.00,0.2623,0.26237,5.000
5,46.438,0.00,0.3872,0.38730,5.000
5,46.562,0.00,0.5121,0.51225,5.000
5,46.688,0.00,0.6372,0.63733,5.000
5,46.812,0.00,0.7621,0.76220,5.000
5,46.938,0.00,0.8871,0.88720,5.000
5,47.062,0.00,1.0122,1.01232,5.000
5,47.188,0.01,1.1372,1.13728,5.000
5,47.312,0.01,1.2621,1.26225,5.000
5,47.438,0.00,1.3874,1.38748,5.000
5,47.562,0.00,1.5123,1.51245,5.000
5,47.688,0.00,1.6374,1.63753,5.000
5,47.812,0.00,1.7621,1.76225,5.000
5,47.938,0.00,1.8872,1.88730,5.000
5,48.062,0.00,2.0122,2.01232,5.000
5,48.188,0.00,2.1372,2.13730,5.000
5,48.312,0.00,2.2623,2.26242,5.000
5,48.438,0.01,2.3873,2.38743,5.000
5,48.562,0.01,2.5123,2.51240,5.000
5,48.688,0.01,2.6373,2.63740,5.000
5,48.812,0.00,2.7623,2.76237,5.000
5,48.938,0.00,2.8873,2.88735,5.000
5,49.062,0.00,3.0122,3.01232,5.000
5,49.188,0.01,3.1373,3.13740,5.000
5,49.312,0.03,3.2623,3.26240,5.000
5,49.438,0.06,3.3874,3.38745,5.000
5,49.562,0.11,3.5123,3.51245,5.000
5,49.688,0.22,3.6375,3.63758,5.000
5,49.812,0.41,3.7624,3.76255,5.000
5,49.938,0.66,3.8873,3.88735,5.000
5,50.062,1.02,4.0123,4.01237,5.000
5,50.250,0.78,3.9405,3.94060,5.000
5,50.375,0.45,3.8155,3.81560,5.000
5,50.500,0.22,3.6906,3.69070,5.000
5,50.625,0.10,3.5656,3.56570,5.000
5,50.750,0.04,3.4407,3.44080,5.000
5,50.875,0.02,3.3157,3.31575,5.000
5,51.000,0.02,3.1907,3.19080,5.000
5,51.125,0.01,3.0657,3.06580,5.000
5,51.250,0.00,2.9405,2.94060,5.000
5,51.375,0.01,2.8155,2.81555,5.000
5,51.500,0.00,2.6904,2.69050,5.000
5,51.625,0.00,2.5654,2.56550,5.000
5,51.750,0.00,2.4405,2.44060,5.000
5,51.875,0.00,2.3156,2.31570,5.000
5,52.000,0.00,2.1905,2.19060,5.000
5,52.125,0.00,2.0655,2.06560,5.000
5,52.250,0.00,1.9405,1.94060,5.000
5,52.375,0.00,1.8153,1.81535,5.000
5,52.500,0.00,1.6904,1.69050,5.000
5,52.625,0.01,1.5654,1.56550,5.000
5,52.750,0.00,1.4405,1.44060,5.000
5,52.875,0.01,1.3155,1.31555,5.000
5,53.000,0.00,1.1904,1.19050,5.000
5,53.125,0.01,1.0655,1.06560,5.000
5,53.250,0.01,0.9403,0.94040,5.000
5,53.375,0.00,0.8153,0.81540,5.000
5,53.500,0.01,0.6903,0.69040,5.000
5,53.625,0.00,0.5653,0.56540,5.000
5,53.750,0.00,0.4403,0.44040,5.000
5,53.875,0.00,0.3154,0.31545,5.000
5,54.000,0.00,0.1902,0.19030,5.000
5,54.125,0.01,0.0653,0.06540,5.000
5,54.312,0.00,-0.0171,-0.01703,5.000
5,54.438,0.00,-0.0003,-0.00020,5.000
5,54.562,0.01,-0.0003,-0.00020,5.000
5,54.688,0.01,-0.0003,-0.00020,5.000
5,54.812,0.00,-0.0003,-0.00020,5.000
5,54.938,0.00,-0.0003,-0.00020,5.000
5,55.062,0.00,-0.0003,-0.00020,5.000
5,55.188,0.00,-0.0003,-0.00020,5.000
5,55.312,0.00,-0.0003,-0.00020,5.000
5,55.438,0.00,-0.0003,-0.00020,5.000
5,55.562,0.01,-0.0003,-0.00020,5.000
5,55.688,0.00,-0.0003,-0.00020,5.000
5,55.812,0.00,-0.0003,-0.00020,5.000
5,55.938,0.01,-0.0003,-0.00020,5.000
5,56.062,0.00,-0.0002,-0.00010,5.000
5,56.188,0.00,-0.0002,-0.00010,5.000
5,56.312,0.00,-0.0002,-0.00010,5.000
5,56.438,0.01,-0.0002,-0.00010,5.000
5,56.562,0.00,-0.0002,-0.00010,5.000
5,56.688,0.00,-0.0002,-0.00010,5.000
5,56.812,0.01,-0.0002,-0.00010,5.000
5,56.938,0.01,-0.0002,-0.00010,5.000
5,57.062,0.01,-0.0002,-0.00010,5.000
5,57.188,0.00,-0.0002,-0.00010,5.000
6,57.562,0.01,0.0520,0.05215,6.000
6,57.688,0.01,0.1771,0.17718,6.000
6,57.812,0.01,0.3022,0.30230,6.000
6,57.938,0.01,0.4271,0.42723,6.000
6,58.062,0.01,0.5522,0.55230,6.000
6,58.188,0.01,0.6772,0.67728,6.000
6,58.312,0.01,0.8021,0.80220,6.000
6,58.438,0.01,0.9271,0.92715,6.000
6,58.562,0.01,1.0521,1.05225,6.000
6,58.688,0.01,1.1772,1.17728,6.000
6,58.812,0.01,1.3023,1.30240,6.000
6,58.938,0.01,1.4274,1.42748,6.000
6,59.062,0.01,1.5524,1.55255,6.000
6,59.188,0.01,1.6774,1.67753,6.000
6,59.312,0.01,1.8021,1.80220,6.000
6,59.438,0.01,1.9271,1.92723,6.000
6,59.562,0.01,2.0522,2.05230,6.000
6,59.688,0.01,2.1773,2.17735,6.000
6,59.812,0.01,2.3023,2.30240,6.000
6,59.938,0.01,2.4273,2.42738,6.000
6,60.062,0.01,2.5524,2.55247,6.000
6,60.188,0.01,2.6773,2.67740,6.000
6,60.312,0.01,2.8023,2.80245,6.000
6,60.438,0.01,2.9272,2.92733,6.000
6,60.562,0.01,3.0523,3.05242,6.000
6,60.688,0.02,3.1773,3.17740,6.000
6,60.812,0.04,3.3023,3.30237,6.000
6,60.938,0.08,3.4274,3.42745,6.000
6,61.062,0.14,3.5524,3.55247,6.000
6,61.188,0.27,3.6775,3.67758,6.000
6,61.312,0.48,3.8024,3.80255,6.000
6,61.438,0.77,3.9273,3.92743,6.000
6,61.625,1.13,4.0255,4.02555,6.000
6,61.750,0.67,3.9004,3.90050,6.000
6,61.875,0.37,3.7756,3.77565,6.000
6,62.000,0.18,3.6506,3.65070,6.000
6,62.125,0.08,3.5257,3.52575,6.000
6,62.250,0.03,3.4006,3.40070,6.000
6,62.375,0.02,3.2756,3.27570,6.000
6,62.500,0.02,3.1507,3.15080,6.000
6,62.625,0.01,3.0256,3.02570,6.000
6,62.750,0.01,2.9005,2.90060,6.000
6,62.875,0.01,2.7755,2.77555,6.000
6,63.000,0.01,2.6503,2.65040,6.000
6,63.125,0.01,2.5254,2.52550,6.000
6,63.250,0.01,2.4004,2.40050,6.000
6,63.375,0.01,2.2755,2.27560,6.000
6,63.500,0.01,2.1506,2.15070,6.000
6,63.625,0.01,2.0255,2.02555,6.000
6,63.750,0.01,1.9004,1.90050,6.000
6,63.875,0.01,1.7753,1.77540,6.000
6,64.000,0.01,1.6504,1.65050,6.000
6,64.125,0.01,1.5254,1.52550,6.000
6,64.250,0.01,1.4005,1.40060,6.000
6,64.375,0.00,1.2754,1.27555,6.000
6,64.500,0.01,1.1505,1.15060,6.000
6,64.625,0.01,1.0254,1.02555,6.000
6,64.750,0.01,0.9004,0.90050,6.000
6,64.875,0.01,0.7754,0.77545,6.000
6,65.000,0.01,0.6503,0.65040,6.000
6,65.125,0.01,0.5252,0.52535,6.000
6,65.250,0.01,0.4004,0.40050,6.000
6,65.375,0.01,0.2754,0.27545,6.000
6,65.500,0.01,0.1504,0.15050,6.000
6,65.625,0.01,0.0252,0.02535,6.000
6,65.875,0.01,-0.0003,-0.00020,6.000
6,66.000,0.01,-0.0003,-0.00020,6.000
6,66.125,0.01,-0.0003,-0.00020,6.000
6,66.250,0.01,-0.0003,-0.00020,6.000
6,66.375,0.01,-0.0003,-0.00020,6.000
6,66.500,0.01,-0.0003,-0.00020,6.000
6,66.625,0.01,-0.0003,-0.00020,6.000
6,66.750,0.01,-0.0003,-0.00020,6.000
6,66.875,0.01,-0.0003,-0.00020,6.000
6,67.000,0.01,-0.0003,-0.00020,6.000
6,67.125,0.01,-0.0003,-0.00020,6.000
6,67.250,0.01,-0.0003,-0.00020,6.000
6,67.375,0.01,-0.0003,-0.00020,6.000
6,67.500,0.01,-0.0003,-0.00020,6.000
6,67.625,0.01,-0.0003,-0.00020,6.000
6,67.750,0.02,-0.0003,-0.00020,6.000
6,67.875,0.01,-0.0002,-0.00010,6.000
6,68.000,0.01,-0.0002,-0.00010,6.000
6,68.125,0.01,-0.0002,-0.00010,6.000
6,68.250,0.01,-0.0002,-0.00010,6.000
6,68.375,0.01,-0.0002,-0.00010,6.000
6,68.500,0.01,-0.0002,-0.00010,6.000
6,68.625,0.01,-0.0002,-0.00010,6.000
6,68.750,0.00,-0.0002,-0.00010,6.000
7,69.125,-0.01,0.1536,0.15370,7.000
7,69.250,-0.01,0.2786,0.27870,7.000
7,69.375,-0.01,0.4036,0.40365,7.000
7,69.500,-0.01,0.5285,0.52860,7.000
7,69.625,-0.02,0.6537,0.65375,7.000
7,69.750,-0.02,0.7787,0.77880,7.000
7,69.875,-0.01,0.9036,0.90370,7.000
7,70.000,-0.02,1.0288,1.02890,7.000
7,70.125,-0.01,1.1537,1.15380,7.000
7,70.250,-0.01,1.2787,1.27880,7.000
7,70.375,-0.02,1.4038,1.40385,7.000
7,70.500,-0.02,1.5287,1.52880,7.000
7,70.625,-0.01,1.6538,1.65395,7.000
7,70.750,-0.01,1.7787,1.77880,7.000
7,70.875,-0.01,1.9037,1.90380,7.000
7,71.000,-0.02,2.0288,2.02890,7.000
7,71.125,-0.01,2.1538,2.15385,7.000
7,71.250,-0.02,2.2789,2.27900,7.000
7,71.375,-0.01,2.4038,2.40385,7.000
7,71.500,-0.02,2.5287,2.52880,7.000
7,71.625,-0.02,2.6538,2.65385,7.000
7,71.750,-0.02,2.7788,2.77890,7.000
7,71.875,-0.01,2.9038,2.90390,7.000
7,72.000,-0.01,3.0288,3.02890,7.000
7,72.125,0.00,3.1539,3.15400,7.000
7,72.250,0.01,3.2789,3.27900,7.000
7,72.375,0.05,3.4038,3.40390,7.000
7,72.500,0.11,3.5288,3.52890,7.000
7,72.625,0.22,3.6538,3.65395,7.000
7,72.750,0.41,3.7788,3.77890,7.000
7,72.875,0.69,3.9038,3.90390,7.000
7,73.000,1.06,4.0288,4.02890,7.000
7,73.188,0.83,3.9620,3.96210,7.000
7,73.312,0.47,3.8372,3.83728,7.000
7,73.438,0.23,3.7122,3.71228,7.000
7,73.562,0.10,3.5872,3.58733,7.000
7,73.688,0.03,3.4620,3.46213,7.000
7,73.812,0.01,3.3370,3.33710,7.000
7,73.938,0.00,3.2120,3.21205,7.000
7,74.062,-0.01,3.0871,3.08723,7.000
7,74.188,-0.01,2.9621,2.96220,7.000
7,74.312,-0.01,2.8370,2.83713,7.000
7,74.438,-0.01,2.7121,2.71220,7.000
7,74.562,-0.02,2.5870,2.58705,7.000
7,74.688,-0.02,2.4618,2.46195,7.000
7,74.812,-0.02,2.3370,2.33708,7.000
7,74.938,-0.02,2.2119,2.21200,7.000
7,75.062,-0.01,2.0869,2.08700,7.000
7,75.188,-0.02,1.9620,1.96205,7.000
7,75.312,-0.02,1.8369,1.83698,7.000
7,75.438,-0.02,1.7120,1.71215,7.000
7,75.562,-0.01,1.5871,1.58718,7.000
7,75.688,-0.01,1.4620,1.46205,7.000
7,75.812,-0.02,1.3369,1.33698,7.000
7,75.938,-0.01,1.2118,1.21185,7.000
7,76.062,-0.01,1.0869,1.08700,7.000
7,76.188,-0.01,0.9618,0.96190,7.000
7,76.312,-0.02,0.8369,0.83695,7.000
7,76.438,-0.02,0.7119,0.71200,7.000
7,76.562,-0.02,0.5870,0.58708,7.000
7,76.688,-0.02,0.4618,0.46193,7.000
7,76.812,-0.01,0.3368,0.33688,7.000
7,76.938,-0.01,0.2117,0.21178,7.000
7,77.062,-0.01,0.0866,0.08673,7.000
7,77.250,-0.02,-0.0420,-0.04190,7.000
7,77.375,-0.01,-0.0003,-0.00020,7.000
7,77.500,-0.02,-0.0003,-0.00020,7.000
7,77.625,-0.02,-0.0003,-0.00020,7.000
7,77.750,-0.01,-0.0003,-0.00020,7.000
7,77.875,-0.02,-0.0003,-0.00020,7.000
7,78.000,-0.02,-0.0003,-0.00020,7.000
7,78.125,-0.02,-0.0003,-0.00020,7.000
7,78.250,-0.01,-0.0003,-0.00020,7.000
7,78.375,-0.01,-0.0003,-0.00020,7.000
7,78.500,-0.01,-0.0003,-0.00020,7.000
7,78.625,-0.01,-0.0003,-0.00020,7.000
7,78.750,-0.02,-0.0002,-0.00010,7.000
7,78.875,-0.01,-0.0002,-0.00010,7.000
7,79.000,-0.01,-0.0002,-0.00010,7.000
7,79.125,-0.02,-0.0002,-0.00010,7.000
7,79.250,-0.02,-0.0002,-0.00010,7.000
7,79.375,-0.02,-0.0002,-0.00010,7.000
7,79.500,-0.01,-0.0002,-0.00010,7.000
7,79.625,-0.01,-0.0002,-0.00010,7.000
7,79.750,-0.02,-0.0002,-0.00010,7.000
7,79.875,-0.02,-0.0002,-0.00010,7.000
7,80.000,-0.01,-0.0002,-0.00010,7.000
7,80.125,-0.02,-0.0002,-0.00010,7.000
7,80.250,-0.02,-0.0002,-0.00010,7.000
8,80.625,0.01,0.1636,0.16365,8.000
8,80.750,0.01,0.2886,0.28870,8.000
8,80.875,0.01,0.4136,0.41365,8.000
8,81.000,0.00,0.5386,0.53870,8.000
8,81.125,0.01,0.6637,0.66380,8.000
8,81.250,0.01,0.7887,0.78880,8.000
8,81.375,0.01,0.9137,0.91380,8.000
8,81.500,0.01,1.0388,1.03890,8.000
8,81.625,0.01,1.1637,1.16375,8.000
8,81.750,0.01,1.2887,1.28880,8.000
8,81.875,0.01,1.4138,1.41385,8.000
8,82.000,0.00,1.5388,1.53890,8.000
8,82.125,0.01,1.6639,1.66400,8.000
8,82.250,0.01,1.7887,1.78880,8.000
8,82.375,0.01,1.9138,1.91390,8.000
8,82.500,0.02,2.0388,2.03890,8.000
8,82.625,0.01,2.1638,2.16385,8.000
8,82.750,0.01,2.2887,2.28880,8.000
8,82.875,0.01,2.4137,2.41380,8.000
8,83.000,0.00,2.5387,2.53880,8.000
8,83.125,0.01,2.6637,2.66380,8.000
8,83.250,0.01,2.7888,2.78890,8.000
8,83.375,0.01,2.9138,2.91395,8.000
8,83.500,0.00,3.0390,3.03910,8.000
8,83.625,0.02,3.1639,3.16400,8.000
8,83.750,0.04,3.2888,3.28890,8.000
8,83.875,0.07,3.4138,3.41390,8.000
8,84.000,0.13,3.5388,3.53890,8.000
8,84.125,0.26,3.6639,3.66400,8.000
8,84.250,0.46,3.7889,3.78900,8.000
8,84.375,0.73,3.9138,3.91395,8.000
8,84.500,1.11,4.0388,4.03890,8.000
8,84.625,0.99,3.9946,3.99470,8.000
8,84.750,0.58,3.8696,3.86970,8.000
8,84.875,0.31,3.7446,3.74470,8.000
8,85.000,0.15,3.6197,3.61980,8.000
8,85.125,0.07,3.4946,3.49465,8.000
8,85.250,0.04,3.3696,3.36970,8.000
8,85.375,0.02,3.2445,3.24460,8.000
8,85.500,0.02,3.1197,3.11980,8.000
8,85.625,0.01,2.9946,2.99475,8.000
8,85.750,0.00,2.8696,2.86970,8.000
8,85.875,0.00,2.7446,2.74465,8.000
8,86.000,0.02,2.6194,2.61950,8.000
8,86.125,0.01,2.4943,2.49440,8.000
8,86.250,0.01,2.3695,2.36960,8.000
8,86.375,0.01,2.2444,2.24450,8.000
8,86.500,0.01,2.1195,2.11960,8.000
8,86.625,0.01,1.9944,1.99450,8.000
8,86.750,0.01,1.8694,1.86950,8.000
8,86.875,0.01,1.7444,1.74450,8.000
8,87.000,0.01,1.6195,1.61960,8.000
8,87.125,0.01,1.4944,1.49445,8.000
8,87.250,0.01,1.3694,1.36950,8.000
8,87.375,0.01,1.2443,1.24440,8.000
8,87.500,0.01,1.1195,1.11960,8.000
8,87.625,0.00,0.9944,0.99450,8.000
8,87.750,0.01,0.8694,0.86950,8.000
8,87.875,0.01,0.7444,0.74450,8.000
8,88.000,0.01,0.6195,0.61960,8.000
8,88.125,0.01,0.4942,0.49435,8.000
8,88.250,0.01,0.3693,0.36940,8.000
8,88.375,0.01,0.2443,0.24435,8.000
8,88.500,0.01,0.1193,0.11940,8.000
8,88.625,0.01,-0.0058,-0.00565,8.000
8,88.812,0.01,-0.0003,-0.00020,8.000
8,88.938,0.01,-0.0003,-0.00020,8.000
8,89.062,0.01,-0.0003,-0.00020,8.000
8,89.188,0.01,-0.0003,-0.00020,8.000
8,89.312,0.01,-0.0003,-0.00020,8.000
8,89.438,0.01,-0.0003,-0.00020,8.000
8,89.562,0.01,-0.0003,-0.00020,8.000
8,89.688,0.01,-0.0003,-0.00020,8.000
8,89.812,0.01,-0.0003,-0.00020,8.000
8,89.938,0.01,-0.0003,-0.00020,8.000
8,90.062,0.01,-0.0003,-0.00020,8.000
8,90.188,0.00,-0.0003,-0.00020,8.000
8,90.312,0.00,-0.0003,-0.00020,8.000
8,90.438,0.01,-0.0002,-0.00010,8.000
8,90.562,0.01,-0.0002,-0.00010,8.000
8,90.688,0.01,-0.0002,-0.00010,8.000
8,90.812,0.01,-0.0002,-0.00010,8.000
8,90.938,0.01,-0.0002,-0.00010,8.000
8,91.062,0.01,-0.0002,-0.00010,8.000
8,91.188,0.01,-0.0002,-0.00010,8.000
8,91.312,0.01,-0.0002,-0.00010,8.000
8,91.438,0.01,-0.0002,-0.00010,8.000
8,91.562,0.01,-0.0002,-0.00010,8.000
8,91.688,0.01,-0.0002,-0.00010,8.000
9,92.062,0.01,0.1411,0.14117,9.000
9,92.188,0.00,0.2662,0.26628,9.000
9,92.312,0.00,0.3912,0.39130,9.000
9,92.438,0.00,0.5161,0.51623,9.000
9,92.562,0.00,0.6412,0.64135,9.000
9,92.688,0.01,0.7662,0.76625,9.000
9,92.812,0.00,0.8910,0.89112,9.000
9,92.938,0.00,1.0161,1.01620,9.000
9,93.062,0.01,1.1411,1.14122,9.000
9,93.188,0.01,1.2663,1.26635,9.000
9,93.312,0.00,1.3913,1.39142,9.000
9,93.438,0.01,1.5162,1.51635,9.000
9,93.562,0.01,1.6414,1.64150,9.000
9,93.688,0.01,1.7661,1.76623,9.000
9,93.812,0.00,1.8911,1.89122,9.000
9,93.938,0.01,2.0161,2.01623,9.000
9,94.062,0.00,2.1412,2.14132,9.000
9,94.188,0.01,2.2664,2.26648,9.000
9,94.312,0.00,2.3913,2.39140,9.000
9,94.438,0.01,2.5164,2.51645,9.000
9,94.562,0.01,2.6413,2.64145,9.000
9,94.688,0.00,2.7663,2.76643,9.000
9,94.812,0.00,2.8913,2.89137,9.000
9,94.938,0.00,3.0162,3.01635,9.000
9,95.062,0.02,3.1413,3.14140,9.000
9,95.188,0.03,3.2662,3.26632,9.000
9,95.312,0.06,3.3913,3.39140,9.000
9,95.438,0.12,3.5164,3.51650,9.000
9,95.562,0.22,3.6415,3.64160,9.000
9,95.688,0.40,3.7664,3.76648,9.000
9,95.812,0.67,3.8913,3.89142,9.000
9,95.938,1.03,4.0163,4.01635,9.000
9,96.125,0.83,3.9546,3.95470,9.000
9,96.250,0.47,3.8295,3.82960,9.000
9,96.375,0.25,3.7046,3.70470,9.000
9,96.500,0.11,3.5796,3.57970,9.000
9,96.625,0.05,3.4545,3.45460,9.000
9,96.750,0.02,3.3296,3.32970,9.000
9,96.875,0.01,3.2046,3.20465,9.000
9,97.000,0.00,3.0796,3.07970,9.000
9,97.125,0.00,2.9546,2.95470,9.000
9,97.250,0.00,2.8296,2.82970,9.000
9,97.375,0.00,2.7044,2.70455,9.000
9,97.500,0.00,2.5794,2.57950,9.000
9,97.625,0.00,2.4543,2.45445,9.000
9,97.750,0.01,2.3295,2.32960,9.000
9,97.875,0.00,2.2044,2.20450,9.000
9,98.000,0.00,2.0795,2.07960,9.000
9,98.125,0.00,1.9544,1.95455,9.000
9,98.250,0.01,1.8294,1.82950,9.000
9,98.375,0.00,1.7044,1.70455,9.000
9,98.500,0.01,1.5794,1.57950,9.000
9,98.625,0.00,1.4544,1.45450,9.000
9,98.750,0.00,1.3294,1.32950,9.000
9,98.875,0.01,1.2043,1.20440,9.000
9,99.000,0.01,1.0795,1.07960,9.000
9,99.125,0.00,0.9544,0.95450,9.000
9,99.250,0.01,0.8294,0.82950,9.000
9,99.375,0.00,0.7044,0.70450,9.000
9,99.500,0.01,0.5794,0.57950,9.000
9,99.625,0.00,0.4543,0.45435,9.000
9,99.750,0.00,0.3292,0.32930,9.000
9,99.875,0.00,0.2042,0.20430,9.000
9,100.000,0.01,0.0792,0.07930,9.000
9,100.188,0.01,-0.0338,-0.03365,9.000
9,100.312,0.00,-0.0003,-0.00020,9.000
9,100.438,0.00,-0.0003,-0.00020,9.000
9,100.562,0.00,-0.0003,-0.00020,9.000
9,100.688,0.00,-0.0003,-0.00020,9.000
9,100.812,0.01,-0.0003,-0.00020,9.000
9,100.938,0.01,-0.0003,-0.00020,9.000
9,101.062,0.00,-0.0003,-0.00020,9.000
9,101.188,0.00,-0.0003,-0.00020,9.000
9,101.312,0.00,-0.0003,-0.00020,9.000
9,101.438,0.01,-0.0003,-0.00020,9.000
9,101.562,0.00,-0.0003,-0.00020,9.000
9,101.688,0.00,-0.0002,-0.00012,9.000
9,101.812,0.00,-0.0002,-0.00010,9.000
9,101.938,0.00,-0.0002,-0.00010,9.000
9,102.062,0.00,-0.0002,-0.00010,9.000
9,102.188,0.01,-0.0002,-0.00010,9.000
9,102.312,0.00,-0.0002,-0.00010,9.000
9,102.438,0.01,-0.0002,-0.00010,9.000
9,102.562,0.00,-0.0002,-0.00010,9.000
9,102.688,0.00,-0.0002,-0.00010,9.000
9,102.812,0.00,-0.0002,-0.00010,9.000
9,102.938,0.00,-0.0002,-0.00010,9.000
9,103.062,0.00,-0.0002,-0.00010,9.000
10,103.438,0.01,0.0671,0.06715,10.000
10,103.562,0.01,0.1922,0.19227,10.000
10,103.688,0.01,0.3172,0.31728,10.000
10,103.812,0.01,0.4420,0.44210,10.000
10,103.938,0.01,0.5671,0.56715,10.000
10,104.062,0.00,0.6920,0.69215,10.000
10,104.188,0.01,0.8172,0.81728,10.000
10,104.312,0.01,0.9421,0.94220,10.000
10,104.438,0.01,1.0672,1.06730,10.000
10,104.562,0.00,1.1922,1.19232,10.000
10,104.688,0.01,1.3173,1.31740,10.000
10,104.812,0.01,1.4423,1.44240,10.000
10,104.938,0.01,1.5672,1.56735,10.000
10,105.062,0.01,1.6923,1.69237,10.000
10,105.188,0.01,1.8171,1.81720,10.000
10,105.312,0.01,1.9422,1.94230,10.000
10,105.438,0.01,2.0673,2.06738,10.000
10,105.562,0.01,2.1923,2.19242,10.000
10,105.688,0.01,2.3174,2.31748,10.000
10,105.812,0.01,2.4423,2.44237,10.000
10,105.938,0.01,2.5672,2.56733,10.000
10,106.062,0.01,2.6922,2.69235,10.000
10,106.188,0.00,2.8172,2.81733,10.000
10,106.312,0.01,2.9422,2.94232,10.000
10,106.438,0.01,3.0674,3.06748,10.000
10,106.562,0.03,3.1923,3.19242,10.000
10,106.688,0.05,3.3173,3.31740,10.000
10,106.812,0.09,3.4423,3.44245,10.000
10,106.938,0.15,3.5674,3.56750,10.000
10,107.062,0.29,3.6924,3.69247,10.000
10,107.188,0.51,3.8173,3.81740,10.000
10,107.312,0.81,3.9422,3.94232,10.000
10,107.500,1.15,4.0301,4.03020,10.000
10,107.625,0.68,3.9055,3.90560,10.000
10,107.750,0.38,3.7804,3.78050,10.000
10,107.875,0.19,3.6556,3.65570,10.000
10,108.000,0.08,3.5306,3.53070,10.000
10,108.125,0.04,3.4056,3.40565,10.000
10,108.250,0.02,3.2805,3.28060,10.000
10,108.375,0.02,3.1557,3.15575,10.000
10,108.500,0.01,3.0307,3.03080,10.000
10,108.625,0.01,2.9054,2.90555,10.000
10,108.750,0.01,2.7804,2.78050,10.000
10,108.875,0.01,2.6554,2.65550,10.000
10,109.000,0.01,2.5304,2.53050,10.000
10,109.125,0.01,2.4054,2.40550,10.000
10,109.250,0.00,2.2805,2.28060,10.000
10,109.375,0.01,2.1554,2.15555,10.000
10,109.500,0.01,2.0305,2.03060,10.000
10,109.625,0.01,1.9053,1.90540,10.000
10,109.750,0.02,1.7803,1.78040,10.000
10,109.875,0.01,1.6556,1.65565,10.000
10,110.000,0.01,1.5303,1.53040,10.000
10,110.125,0.01,1.4054,1.40555,10.000
10,110.250,0.01,1.2804,1.28050,10.000
10,110.375,0.01,1.1555,1.15555,10.000
10,110.500,0.01,1.0306,1.03070,10.000
10,110.625,0.01,0.9053,0.90540,10.000
10,110.750,0.01,0.7803,0.78040,10.000
10,110.875,0.01,0.6554,0.65545,10.000
10,111.000,0.01,0.5302,0.53030,10.000
10,111.125,0.01,0.4052,0.40535,10.000
10,111.250,0.01,0.2803,0.28040,10.000
10,111.375,0.01,0.1553,0.15545,10.000
10,111.500,0.01,0.0304,0.03050,10.000
10,111.750,0.01,-0.0003,-0.00020,10.000
10,111.875,0.01,-0.0003,-0.00020,10.000
10,112.000,0.01,-0.0003,-0.00020,10.000
10,112.125,0.01,-0.0003,-0.00020,10.000
10,112.250,0.01,-0.0003,-0.00020,10.000
10,112.375,0.01,-0.0003,-0.00020,10.000
10,112.500,0.01,-0.0003,-0.00020,10.000
10,112.625,0.01,-0.0003,-0.00020,10.000
10,112.750,0.01,-0.0003,-0.00020,10.000
10,112.875,0.01,-0.0003,-0.00020,10.000
10,113.000,0.01,-0.0002,-0.00010,10.000
10,113.125,0.01,-0.0002,-0.00010,10.000
10,113.250,0.01,-0.0002,-0.00010,10.000
10,113.375,0.01,-0.0002,-0.00010,10.000
10,113.500,0.02,-0.0002,-0.00010,10.000
10,113.625,0.01,-0.0002,-0.00010,10.000
10,113.750,0.02,-0.0002,-0.00010,10.000
10,113.875,0.01,-0.0002,-0.00010,10.000
10,114.000,0.01,-0.0002,-0.00010,10.000
10,114.125,0.01,-0.0002,-0.00010,10.000
10,114.250,0.01,-0.0002,-0.00010,10.000
10,114.375,0.01,-0.0002,-0.00010,10.000
10,114.500,0.01,-0.0002,-0.00010,10.000
10,114.625,0.01,-0.0002,-0.00010,10.000