File: calibDATA_loadcell/date_02:22:2018/Instron/1N_0_1_3_0.txt
""
"Test Method","Radhen_Load_Cntrl_Cmprsn_250N_12-7.msm"
"Sample I. D.","Sample1.mss"
"Specimen Number","15"

"TheCycle_Output ()","_Time (s)","_Load (N)","_Extension (mm)","RealTimeDepth (mm)","CycleNumber ()"

1,0.312,0.00,0.0713,0.07125,1.000
1,0.375,0.00,0.1336,0.13360,1.000
1,0.438,0.00,0.1962,0.19622,1.000
1,0.500,0.00,0.2588,0.25880,1.000
1,0.562,0.00,0.3213,0.32130,1.000
1,0.625,0.00,0.3839,0.38390,1.000
1,0.688,0.00,0.4462,0.44620,1.000
1,0.750,0.00,0.5089,0.50890,1.000
1,0.812,0.00,0.5711,0.57115,1.000
1,0.875,0.00,0.6338,0.63380,1.000
1,0.938,0.00,0.6962,0.69620,1.000
1,1.000,0.00,0.7587,0.75870,1.000
1,1.062,0.00,0.8213,0.82130,1.000
1,1.125,0.00,0.8837,0.88370,1.000
1,1.188,0.00,0.9464,0.94638,1.000
1,1.250,0.00,1.0087,1.00870,1.000
1,1.312,0.00,1.0714,1.07140,1.000
1,1.375,0.00,1.1337,1.13375,1.000
1,1.438,0.00,1.1963,1.19630,1.000
1,1.500,0.00,1.2588,1.25880,1.000
1,1.562,0.00,1.3213,1.32128,1.000
1,1.625,0.00,1.3838,1.38385,1.000
1,1.688,0.00,1.4462,1.44625,1.000
1,1.750,0.01,1.5089,1.50890,1.000
1,1.812,0.00,1.5712,1.57122,1.000
1,1.875,0.01,1.6338,1.63380,1.000
1,1.938,0.02,1.6963,1.69628,1.000
1,2.000,0.03,1.7589,1.75890,1.000
1,2.062,0.04,1.8214,1.82140,1.000
1,2.125,0.06,1.8839,1.88390,1.000
1,2.188,0.09,1.9464,1.94638,1.000
1,2.250,0.13,2.0087,2.00870,1.000
1,2.312,0.19,2.0714,2.07140,1.000
1,2.375,0.29,2.1338,2.13380,1.000
1,2.438,0.39,2.1965,2.19645,1.000
1,2.500,0.52,2.2589,2.25890,1.000
1,2.562,0.68,2.3214,2.32145,1.000
1,2.625,0.85,2.3840,2.38395,1.000
1,2.688,1.05,2.4464,2.44638,1.000
1,2.812,1.01,2.4270,2.42698,1.000
1,2.875,0.77,2.3646,2.36455,1.000
1,2.938,0.58,2.3021,2.30205,1.000
1,3.000,0.43,2.2396,2.23960,1.000
1,3.062,0.30,2.1770,2.17702,1.000
1,3.125,0.20,2.1146,2.11465,1.000
1,3.188,0.12,2.0520,2.05200,1.000
1,3.250,0.07,1.9896,1.98960,1.000
1,3.312,0.04,1.9270,1.92695,1.000
1,3.375,0.02,1.8647,1.86470,1.000
1,3.438,0.02,1.8021,1.80210,1.000
1,3.500,0.01,1.7397,1.73970,1.000
1,3.562,0.01,1.6770,1.67702,1.000
1,3.625,0.00,1.6145,1.61445,1.000
1,3.688,0.00,1.5520,1.55202,1.000
1,3.750,0.00,1.4894,1.48940,1.000
1,3.812,0.00,1.4271,1.42708,1.000
1,3.875,0.00,1.3645,1.36445,1.000
1,3.938,0.00,1.3021,1.30210,1.000
1,4.000,0.01,1.2396,1.23960,1.000
1,4.062,0.00,1.1770,1.17700,1.000
1,4.125,0.00,1.1145,1.11450,1.000
1,4.188,0.00,1.0520,1.05200,1.000
1,4.250,0.00,0.9896,0.98960,1.000
1,4.312,0.00,0.9269,0.92693,1.000
1,4.375,0.00,0.8646,0.86455,1.000
1,4.438,0.00,0.8020,0.80198,1.000
1,4.500,0.00,0.7394,0.73940,1.000
1,4.562,0.00,0.6770,0.67700,1.000
1,4.625,0.00,0.6144,0.61435,1.000
1,4.688,0.00,0.5520,0.55198,1.000
1,4.750,0.00,0.4893,0.48930,1.000
1,4.812,0.00,0.4270,0.42700,1.000
1,4.875,0.00,0.3645,0.36445,1.000
1,4.938,0.00,0.3020,0.30203,1.000
1,5.000,0.00,0.2394,0.23940,1.000
1,5.062,0.00,0.1770,0.17695,1.000
1,5.125,0.00,0.1144,0.11440,1.000
1,5.188,0.00,0.0518,0.05183,1.000
1,5.250,0.00,-0.0105,-0.01050,1.000
1,5.375,0.00,-0.0005,-0.00050,1.000
1,5.438,0.00,-0.0001,-0.00010,1.000
1,5.500,0.00,-0.0001,-0.00010,1.000
1,5.562,0.00,-0.0001,-0.00010,1.000
1,5.625,0.00,-0.0001,-0.00010,1.000
1,5.688,0.00,-0.0001,-0.00010,1.000
1,5.750,0.00,-0.0001,-0.00010,1.000
1,5.812,0.00,-0.0001,-0.00010,1.000
1,5.875,0.00,-0.0001,-0.00010,1.000
1,5.938,0.00,-0.0001,-0.00010,1.000
1,6.000,0.00,-0.0001,-0.00010,1.000
1,6.062,0.00,-0.0001,-0.00010,1.000
1,6.125,0.00,-0.0001,-0.00010,1.000
1,6.188,0.00,-0.0001,-0.00010,1.000
1,6.250,0.00,-0.0001,-0.00010,1.000
1,6.312,0.00,-0.0001,-0.00010,1.000
1,6.375,0.00,-0.0001,-0.00010,1.000
1,6.438,0.00,-0.0001,-0.00010,1.000
1,6.500,0.00,-0.0001,-0.00010,1.000
1,6.562,0.00,-0.0001,-0.00010,1.000
1,6.625,0.00,-0.0001,-0.00010,1.000
1,6.688,0.00,-0.0001,-0.00010,1.000
1,6.750,0.00,-0.0001,-0.00010,1.000
1,6.812,0.00,-0.0001,-0.00010,1.000
1,6.875,0.00,-0.0001,-0.00010,1.000
1,6.938,0.00,-0.0001,-0.00010,1.000
1,7.000,0.00,-0.0001,-0.00010,1.000
1,7.062,0.00,-0.0001,-0.00010,1.000
1,7.125,0.00,-0.0001,-0.00010,1.000
1,7.188,0.00,-0.0001,-0.00010,1.000
1,7.250,0.00,-0.0001,-0.00010,1.000
1,7.312,0.00,-0.0001,-0.00010,1.000
1,7.375,0.00,-0.0001,-0.00010,1.000
1,7.438,0.01,-0.0001,-0.00010,1.000
1,7.500,0.00,-0.0001,-0.00010,1.000
1,7.562,0.00,-0.0001,-0.00010,1.000
1,7.625,0.00,-0.0001,-0.00010,1.000
1,7.688,0.00,-0.0001,-0.00010,1.000
1,7.750,0.00,-0.0001,-0.00010,1.000
1,7.812,0.00,-0.0001,-0.00010,1.000
1,7.875,0.00,-0.0001,-0.00010,1.000
1,7.938,0.00,-0.0001,-0.00010,1.000
1,8.000,0.01,-0.0001,-0.00010,1.000
1,8.062,0.00,-0.0001,-0.00010,1.000
1,8.125,0.00,-0.0001,-0.00010,1.000
1,8.188,0.00,-0.0001,-0.00010,1.000
1,8.250,0.00,-0.0001,-0.00010,1.000
1,8.312,0.00,-0.0001,-0.00010,1.000
2,8.500,-0.01,-0.0001,-0.00010,2.000
2,8.625,0.00,0.0926,0.09270,2.000
2,8.688,0.00,0.1552,0.15530,2.000
2,8.750,0.00,0.2177,0.21780,2.000
2,8.812,0.00,0.2802,0.28030,2.000
2,8.875,0.00,0.3428,0.34290,2.000
2,8.938,0.00,0.4052,0.40530,2.000
2,9.000,0.00,0.4678,0.46790,2.000
2,9.062,0.00,0.5300,0.53015,2.000
2,9.125,0.00,0.5927,0.59285,2.000
2,9.188,0.00,0.6552,0.65528,2.000
2,9.250,0.01,0.7177,0.71780,2.000
2,9.312,0.00,0.7802,0.78032,2.000
2,9.375,0.00,0.8426,0.84275,2.000
2,9.438,0.00,0.9053,0.90538,2.000
2,9.500,0.00,0.9676,0.96770,2.000
2,9.562,-0.01,1.0303,1.03045,2.000
2,9.625,0.00,1.0926,1.09275,2.000
2,9.688,0.00,1.1553,1.15538,2.000
2,9.750,-0.01,1.2177,1.21780,2.000
2,9.812,0.00,1.2802,1.28035,2.000
2,9.875,0.00,1.3427,1.34280,2.000
2,9.938,0.00,1.4052,1.40525,2.000
2,10.000,-0.01,1.4677,1.46780,2.000
2,10.062,0.00,1.5301,1.53025,2.000
2,10.125,0.00,1.5927,1.59285,2.000
2,10.188,0.01,1.6552,1.65528,2.000
2,10.250,0.02,1.7178,1.71790,2.000
2,10.312,0.03,1.7804,1.78050,2.000
2,10.375,0.05,1.8428,1.84295,2.000
2,10.438,0.06,1.9053,1.90540,2.000
2,10.500,0.09,1.9676,1.96770,2.000
2,10.562,0.14,2.0304,2.03048,2.000
2,10.625,0.22,2.0927,2.09280,2.000
2,10.688,0.31,2.1554,2.15548,2.000
2,10.750,0.43,2.2178,2.21790,2.000
2,10.812,0.57,2.2804,2.28052,2.000
2,10.875,0.73,2.3428,2.34295,2.000
2,10.938,0.91,2.4054,2.40545,2.000
2,11.062,1.17,2.4652,2.46533,2.000
2,11.125,0.91,2.4035,2.40360,2.000
2,11.188,0.70,2.3410,2.34112,2.000
2,11.250,0.52,2.2786,2.27870,2.000
2,11.312,0.38,2.2160,2.21608,2.000
2,11.375,0.26,2.1536,2.15370,2.000
2,11.438,0.17,2.0910,2.09110,2.000
2,11.500,0.10,2.0285,2.02860,2.000
2,11.562,0.05,1.9660,1.96610,2.000
2,11.625,0.04,1.9035,1.90360,2.000
2,11.688,0.02,1.8411,1.84122,2.000
2,11.750,0.02,1.7786,1.77870,2.000
2,11.812,0.01,1.7160,1.71613,2.000
2,11.875,0.00,1.6534,1.65350,2.000
2,11.938,0.00,1.5911,1.59117,2.000
2,12.000,0.00,1.5284,1.52850,2.000
2,12.062,0.00,1.4661,1.46618,2.000
2,12.125,0.00,1.4034,1.40350,2.000
2,12.188,0.00,1.3409,1.34105,2.000
2,12.250,0.00,1.2784,1.27850,2.000
2,12.312,0.00,1.2159,1.21598,2.000
2,12.375,0.00,1.1535,1.15360,2.000
2,12.438,0.00,1.0909,1.09100,2.000
2,12.500,0.00,1.0285,1.02860,2.000
2,12.562,0.00,0.9659,0.96600,2.000
2,12.625,0.00,0.9035,0.90355,2.000
2,12.688,0.00,0.8409,0.84100,2.000
2,12.750,0.00,0.7784,0.77850,2.000
2,12.812,0.00,0.7159,0.71603,2.000
2,12.875,0.00,0.6533,0.65340,2.000
2,12.938,0.00,0.5909,0.59100,2.000
2,13.000,0.00,0.5283,0.52840,2.000
2,13.062,0.00,0.4660,0.46608,2.000
2,13.125,0.00,0.4034,0.40345,2.000
2,13.188,0.00,0.3410,0.34110,2.000
2,13.250,0.00,0.2784,0.27850,2.000
2,13.312,0.00,0.2160,0.21605,2.000
2,13.375,0.00,0.1534,0.15350,2.000
2,13.438,0.00,0.0907,0.09085,2.000
2,13.500,0.00,0.0285,0.02860,2.000
2,13.625,0.00,-0.0269,-0.02675,2.000
2,13.688,0.00,-0.0001,-0.00005,2.000
2,13.750,-0.01,-0.0002,-0.00010,2.000
2,13.812,0.00,-0.0002,-0.00010,2.000
2,13.875,0.00,-0.0002,-0.00010,2.000
2,13.938,0.00,-0.0002,-0.00010,2.000
2,14.000,0.00,-0.0002,-0.00010,2.000
2,14.062,0.00,-0.0002,-0.00010,2.000
2,14.125,0.00,-0.0002,-0.00010,2.000
2,14.188,0.00,-0.0002,-0.00010,2.000
2,14.250,0.00,-0.0002,-0.00010,2.000
2,14.312,0.00,-0.0002,-0.00010,2.000
2,14.375,0.00,-0.0002,-0.00010,2.000
2,14.438,0.00,-0.0002,-0.00010,2.000
2,14.500,-0.01,-0.0002,-0.00010,2.000
2,14.562,-0.01,-0.0002,-0.00010,2.000
2,14.625,0.00,-0.0002,-0.00010,2.000
2,14.688,0.00,-0.0002,-0.00010,2.000
2,14.750,0.00,-0.0002,-0.00010,2.000
2,14.812,0.00,-0.0002,-0.00010,2.000
2,14.875,0.00,-0.0002,-0.00010,2.000
2,14.938,0.00,-0.0002,-0.00010,2.000
2,15.000,0.00,-0.0002,-0.00010,2.000
2,15.062,0.00,-0.0002,-0.00010,2.000
2,15.125,0.00,-0.0002,-0.00010,2.000
2,15.188,0.00,-0.0002,-0.00010,2.000
2,15.250,0.00,-0.0002,-0.00010,2.000
2,15.312,0.00,-0.0002,-0.00010,2.000
2,15.375,0.00,-0.0002,-0.00010,2.000
2,15.438,0.00,-0.0002,-0.00010,2.000
2,15.500,0.00,-0.0002,-0.00010,2.000
2,15.562,0.00,-0.0002,-0.00010,2.000
2,15.625,0.00,-0.0002,-0.00010,2.000
2,15.688,0.00,-0.0001,0.00000,2.000
2,15.750,0.00,-0.0001,0.00000,2.000
2,15.812,0.00,-0.0001,0.00000,2.000
2,15.875,0.00,-0.0001,0.00000,2.000
2,15.938,0.00,-0.0001,0.00000,2.000
2,16.000,-0.01,-0.0001,0.00000,2.000
2,16.062,0.00,-0.0001,0.00000,2.000
2,16.125,0.00,-0.0001,0.00000,2.000
2,16.188,0.00,-0.0001,0.00000,2.000
2,16.250,0.00,-0.0001,0.00000,2.000
2,16.312,0.00,-0.0001,0.00000,2.000
2,16.375,0.00,-0.0001,0.00000,2.000
2,16.438,0.00,-0.0001,0.00000,2.000
2,16.500,0.00,-0.0001,0.00000,2.000
2,16.562,0.00,-0.0001,0.00000,2.000
3,16.938,0.00,0.0861,0.08620,3.000
3,17.000,0.00,0.1486,0.14870,3.000
3,17.062,0.00,0.2111,0.21118,3.000
3,17.125,0.00,0.2738,0.27385,3.000
3,17.188,0.00,0.3362,0.33632,3.000
3,17.250,0.00,0.3987,0.39880,3.000
3,17.312,0.00,0.4612,0.46133,3.000
3,17.375,0.00,0.5236,0.52365,3.000
3,17.438,0.00,0.5863,0.58637,3.000
3,17.500,0.00,0.6486,0.64870,3.000
3,17.562,0.00,0.7113,0.71135,3.000
3,17.625,0.00,0.7736,0.77375,3.000
3,17.688,0.00,0.8362,0.83632,3.000
3,17.750,0.00,0.8988,0.89890,3.000
3,17.812,0.00,0.9613,0.96135,3.000
3,17.875,0.00,1.0238,1.02390,3.000
3,17.938,0.00,1.0861,1.08622,3.000
3,18.000,0.00,1.1488,1.14890,3.000
3,18.062,0.00,1.2111,1.21123,3.000
3,18.125,0.00,1.2738,1.27385,3.000
3,18.188,0.00,1.3362,1.33627,3.000
3,18.250,0.00,1.3988,1.39890,3.000
3,18.312,0.00,1.4613,1.46135,3.000
3,18.375,0.00,1.5238,1.52390,3.000
3,18.438,0.00,1.5863,1.58640,3.000
3,18.500,0.01,1.6486,1.64870,3.000
3,18.562,0.02,1.7113,1.71140,3.000
3,18.625,0.03,1.7738,1.77390,3.000
3,18.688,0.05,1.8364,1.83647,3.000
3,18.750,0.07,1.8987,1.89880,3.000
3,18.812,0.10,1.9613,1.96138,3.000
3,18.875,0.14,2.0238,2.02390,3.000
3,18.938,0.22,2.0862,2.08635,3.000
3,19.000,0.31,2.1489,2.14900,3.000
3,19.062,0.43,2.2112,2.21130,3.000
3,19.125,0.56,2.2739,2.27395,3.000
3,19.188,0.72,2.3364,2.33647,3.000
3,19.250,0.90,2.3989,2.39900,3.000
3,19.438,1.03,2.4341,2.43423,3.000
3,19.500,0.80,2.3715,2.37160,3.000
3,19.562,0.61,2.3091,2.30917,3.000
3,19.625,0.44,2.2465,2.24660,3.000
3,19.688,0.31,2.1840,2.18413,3.000
3,19.750,0.21,2.1215,2.12160,3.000
3,19.812,0.13,2.0589,2.05902,3.000
3,19.875,0.07,1.9965,1.99660,3.000
3,19.938,0.04,1.9339,1.93400,3.000
3,20.000,0.03,1.8717,1.87180,3.000
3,20.062,0.02,1.8090,1.80912,3.000
3,20.125,0.02,1.7466,1.74670,3.000
3,20.188,0.01,1.6839,1.68403,3.000
3,20.250,0.00,1.6214,1.62150,3.000
3,20.312,0.00,1.5590,1.55912,3.000
3,20.375,0.00,1.4965,1.49660,3.000
3,20.438,0.00,1.4341,1.43418,3.000
3,20.500,0.01,1.3713,1.37140,3.000
3,20.562,0.00,1.3090,1.30907,3.000
3,20.625,0.00,1.2464,1.24645,3.000
3,20.688,0.01,1.1840,1.18408,3.000
3,20.750,0.00,1.1214,1.12150,3.000
3,20.812,0.00,1.0589,1.05897,3.000
3,20.875,0.00,0.9964,0.99655,3.000
3,20.938,0.00,0.9339,0.93395,3.000
3,21.000,0.00,0.8714,0.87150,3.000
3,21.062,0.01,0.8088,0.80890,3.000
3,21.125,0.01,0.7464,0.74655,3.000
3,21.188,0.00,0.6838,0.68385,3.000
3,21.250,0.00,0.6214,0.62150,3.000
3,21.312,0.00,0.5589,0.55900,3.000
3,21.375,0.00,0.4964,0.49650,3.000
3,21.438,0.00,0.4340,0.43405,3.000
3,21.500,0.00,0.3714,0.37150,3.000
3,21.562,0.00,0.3090,0.30910,3.000
3,21.625,0.00,0.2464,0.24645,3.000
3,21.688,0.00,0.1840,0.18408,3.000
3,21.750,0.00,0.1212,0.12130,3.000
3,21.812,0.00,0.0589,0.05897,3.000
3,21.875,0.00,-0.0036,-0.00350,3.000
3,22.000,0.00,-0.0284,-0.02830,3.000
3,22.062,0.00,-0.0005,-0.00042,3.000
3,22.125,0.00,-0.0002,-0.00005,3.000
3,22.188,0.00,-0.0002,-0.00010,3.000
3,22.250,0.00,-0.0001,0.00000,3.000
3,22.312,0.00,-0.0002,-0.00010,3.000
3,22.375,0.00,-0.0001,0.00000,3.000
3,22.438,0.00,-0.0001,0.00000,3.000
3,22.500,0.01,-0.0001,0.00000,3.000
3,22.562,0.00,-0.0001,0.00000,3.000
3,22.625,0.00,-0.0001,0.00000,3.000
3,22.688,0.00,-0.0001,0.00000,3.000
3,22.750,0.00,-0.0001,0.00000,3.000
3,22.812,0.00,-0.0001,0.00000,3.000
3,22.875,0.00,-0.0001,0.00000,3.000
3,22.938,0.00,-0.0001,0.00000,3.000
3,23.000,0.00,-0.0001,0.00000,3.000
3,23.062,0.00,-0.0001,0.00000,3.000
3,23.125,0.00,-0.0001,0.00000,3.000
3,23.188,0.00,-0.0001,0.00000,3.000
3,23.250,0.00,-0.0001,0.00000,3.000
3,23.312,0.01,-0.0001,0.00000,3.000
3,23.375,0.00,-0.0001,0.00000,3.000
3,23.438,0.00,-0.0001,0.00000,3.000
3,23.500,0.01,-0.0001,0.00000,3.000
3,23.562,0.00,-0.0001,0.00000,3.000
3,23.625,0.00,-0.0001,0.00000,3.000
3,23.688,0.00,-0.0001,0.00000,3.000
3,23.750,-0.01,-0.0001,0.00000,3.000
3,23.812,0.01,-0.0001,0.00000,3.000
3,23.875,0.00,-0.0001,0.00000,3.000
3,23.938,0.00,-0.0001,0.00000,3.000
3,24.000,0.00,-0.0001,0.00000,3.000
3,24.062,0.00,-0.0001,0.00000,3.000
3,24.125,0.01,-0.0001,0.00000,3.000
3,24.188,0.01,-0.0001,0.00000,3.000
3,24.250,0.01,-0.0001,0.00000,3.000
3,24.312,0.00,-0.0001,0.00000,3.000
3,24.375,0.00,-0.0001,0.00000,3.000
3,24.438,0.00,-0.0001,0.00000,3.000
3,24.500,0.01,-0.0001,0.00000,3.000
3,24.562,0.01,-0.0001,0.00000,3.000
3,24.625,0.00,-0.0001,0.00000,3.000
3,24.688,0.00,-0.0001,0.00000,3.000
3,24.750,0.00,-0.0001,0.00000,3.000
3,24.812,0.00,-0.0001,0.00000,3.000
3,24.875,0.00,-0.0001,0.00000,3.000
3,24.938,0.01,-0.0001,0.00000,3.000
4,25.250,0.00,0.0776,0.07760,4.000
4,25.312,0.00,0.1401,0.14012,4.000
4,25.375,0.00,0.2026,0.20260,4.000
4,25.438,0.00,0.2652,0.26520,4.000
4,25.500,-0.01,0.3276,0.32760,4.000
4,25.562,0.00,0.3902,0.39022,4.000
4,25.625,0.00,0.4526,0.45260,4.000
4,25.688,0.00,0.5152,0.51520,4.000
4,25.750,0.00,0.5777,0.57770,4.000
4,25.812,0.00,0.6401,0.64015,4.000
4,25.875,0.00,0.7027,0.70270,4.000
4,25.938,0.00,0.7650,0.76505,4.000
4,26.000,0.00,0.8278,0.82780,4.000
4,26.062,0.00,0.8901,0.89010,4.000
4,26.125,0.00,0.9528,0.95275,4.000
4,26.188,0.00,1.0152,1.01522,4.000
4,26.250,0.00,1.0777,1.07770,4.000
4,26.312,0.00,1.1401,1.14015,4.000
4,26.375,0.00,1.2026,1.20265,4.000
4,26.438,0.00,1.2652,1.26520,4.000
4,26.500,0.00,1.3276,1.32760,4.000
4,26.562,0.00,1.3902,1.39022,4.000
4,26.625,0.00,1.4528,1.45275,4.000
4,26.688,0.00,1.5153,1.51530,4.000
4,26.750,0.00,1.5777,1.57770,4.000
4,26.812,0.00,1.6402,1.64025,4.000
4,26.875,0.01,1.7027,1.70270,4.000
4,26.938,0.02,1.7652,1.76525,4.000
4,27.000,0.04,1.8278,1.82780,4.000
4,27.062,0.06,1.8902,1.89020,4.000
4,27.125,0.09,1.9529,1.95285,4.000
4,27.188,0.13,2.0152,2.01520,4.000
4,27.250,0.20,2.0778,2.07780,4.000
4,27.312,0.29,2.1402,2.14022,4.000
4,27.375,0.40,2.2028,2.20280,4.000
4,27.438,0.53,2.2653,2.26530,4.000
4,27.500,0.69,2.3277,2.32770,4.000
4,27.562,0.87,2.3904,2.39042,4.000
4,27.625,1.07,2.4528,2.45280,4.000
4,27.750,1.06,2.4384,2.43840,4.000
4,27.812,0.81,2.3760,2.37598,4.000
4,27.875,0.62,2.3136,2.31360,4.000
4,27.938,0.46,2.2509,2.25093,4.000
4,28.000,0.32,2.1885,2.18850,4.000
4,28.062,0.22,2.1260,2.12603,4.000
4,28.125,0.13,2.0635,2.06350,4.000
4,28.188,0.08,2.0010,2.00098,4.000
4,28.250,0.04,1.9384,1.93840,4.000
4,28.312,0.03,1.8761,1.87608,4.000
4,28.375,0.02,1.8135,1.81350,4.000
4,28.438,0.02,1.7512,1.75118,4.000
4,28.500,0.01,1.6883,1.68830,4.000
4,28.562,0.00,1.6260,1.62595,4.000
4,28.625,0.00,1.5634,1.56345,4.000
4,28.688,0.00,1.5010,1.50103,4.000
4,28.750,0.00,1.4384,1.43840,4.000
4,28.812,0.00,1.3758,1.37583,4.000
4,28.875,0.00,1.3135,1.31350,4.000
4,28.938,0.00,1.2509,1.25085,4.000
4,29.000,0.00,1.1886,1.18860,4.000
4,29.062,0.00,1.1259,1.12590,4.000
4,29.125,0.00,1.0634,1.06345,4.000
4,29.188,0.00,1.0009,1.00085,4.000
4,29.250,0.00,0.9384,0.93840,4.000
4,29.312,0.00,0.8759,0.87585,4.000
4,29.375,0.00,0.8134,0.81335,4.000
4,29.438,0.00,0.7510,0.75098,4.000
4,29.500,0.00,0.6883,0.68830,4.000
4,29.562,0.00,0.6259,0.62590,4.000
4,29.625,0.00,0.5633,0.56330,4.000
4,29.688,0.00,0.5009,0.50093,4.000
4,29.750,0.00,0.4384,0.43840,4.000
4,29.812,0.00,0.3759,0.37593,4.000
4,29.875,0.00,0.3135,0.31350,4.000
4,29.938,0.00,0.2509,0.25093,4.000
4,30.000,0.00,0.1884,0.18840,4.000
4,30.062,0.00,0.1258,0.12580,4.000
4,30.125,0.00,0.0634,0.06335,4.000
4,30.188,0.00,0.0009,0.00085,4.000
4,30.312,0.00,-0.0189,-0.01888,4.000
4,30.375,0.00,-0.0004,-0.00035,4.000
4,30.438,0.00,-0.0001,-0.00010,4.000
4,30.500,0.00,-0.0002,-0.00020,4.000
4,30.562,0.00,-0.0002,-0.00020,4.000
4,30.625,0.00,-0.0001,-0.00010,4.000
4,30.688,0.00,-0.0001,-0.00013,4.000
4,30.750,0.00,-0.0001,-0.00010,4.000
4,30.812,0.00,-0.0001,-0.00010,4.000
4,30.875,0.00,-0.0001,-0.00010,4.000
4,30.938,0.00,-0.0001,-0.00010,4.000
4,31.000,0.00,-0.0001,-0.00010,4.000
4,31.062,0.00,-0.0001,-0.00010,4.000
4,31.125,0.00,-0.0001,-0.00010,4.000
4,31.188,0.00,-0.0001,-0.00010,4.000
4,31.250,0.00,-0.0001,-0.00010,4.000
4,31.312,0.00,-0.0001,-0.00010,4.000
4,31.375,0.00,-0.0001,-0.00010,4.000
4,31.438,0.00,-0.0001,-0.00010,4.000
4,31.500,0.00,-0.0001,-0.00010,4.000
4,31.562,0.00,-0.0001,-0.00010,4.000
4,31.625,0.00,-0.0001,-0.00010,4.000
4,31.688,0.00,-0.0001,-0.00010,4.000
4,31.750,0.00,-0.0001,-0.00010,4.000
4,31.812,0.00,-0.0001,-0.00010,4.000
4,31.875,0.00,-0.0001,-0.00010,4.000
4,31.938,0.00,-0.0001,-0.00010,4.000
4,32.000,0.00,-0.0001,-0.00010,4.000
4,32.062,0.00,-0.0001,-0.00010,4.000
4,32.125,0.00,-0.0001,-0.00010,4.000
4,32.188,0.00,-0.0001,-0.00010,4.000
4,32.250,0.00,-0.0001,-0.00010,4.000
4,32.312,0.00,-0.0001,-0.00010,4.000
4,32.375,0.00,-0.0001,-0.00010,4.000
4,32.438,0.00,-0.0001,-0.00010,4.000
4,32.500,0.00,-0.0001,-0.00010,4.000
4,32.562,0.00,-0.0001,-0.00010,4.000
4,32.625,0.00,-0.0001,-0.00010,4.000
4,32.688,0.00,-0.0001,-0.00010,4.000
4,32.750,0.00,-0.0001,-0.00010,4.000
4,32.812,0.00,-0.0001,-0.00010,4.000
4,32.875,0.00,-0.0001,-0.00010,4.000
4,32.938,0.00,-0.0001,-0.00010,4.000
4,33.000,0.00,-0.0001,-0.00010,4.000
4,33.062,0.00,-0.0001,-0.00010,4.000
4,33.125,0.00,-0.0001,-0.00010,4.000
4,33.188,0.00,-0.0001,-0.00010,4.000
4,33.250,0.00,-0.0001,-0.00010,4.000
5,33.562,-0.01,0.0600,0.06015,5.000
5,33.625,-0.01,0.1225,0.12260,5.000
5,33.688,-0.01,0.1852,0.18528,5.000
5,33.750,-0.01,0.2476,0.24770,5.000
5,33.812,-0.01,0.3103,0.31037,5.000
5,33.875,-0.01,0.3727,0.37275,5.000
5,33.938,-0.01,0.4352,0.43525,5.000
5,34.000,-0.01,0.4976,0.49770,5.000
5,34.062,-0.01,0.5601,0.56017,5.000
5,34.125,-0.01,0.6227,0.62280,5.000
5,34.188,-0.01,0.6851,0.68515,5.000
5,34.250,-0.01,0.7477,0.74780,5.000
5,34.312,-0.01,0.8100,0.81015,5.000
5,34.375,-0.01,0.8727,0.87280,5.000
5,34.438,-0.01,0.9351,0.93520,5.000
5,34.500,-0.01,0.9977,0.99780,5.000
5,34.562,-0.01,1.0602,1.06032,5.000
5,34.625,-0.01,1.1227,1.12280,5.000
5,34.688,-0.01,1.1851,1.18523,5.000
5,34.750,-0.01,1.2475,1.24760,5.000
5,34.812,-0.01,1.3102,1.31032,5.000
5,34.875,-0.01,1.3727,1.37275,5.000
5,34.938,-0.01,1.4353,1.43540,5.000
5,35.000,-0.01,1.4978,1.49790,5.000
5,35.062,-0.01,1.5602,1.56030,5.000
5,35.125,-0.01,1.6227,1.62280,5.000
5,35.188,0.00,1.6852,1.68525,5.000
5,35.250,0.01,1.7477,1.74780,5.000
5,35.312,0.02,1.8103,1.81045,5.000
5,35.375,0.04,1.8728,1.87295,5.000
5,35.438,0.06,1.9353,1.93535,5.000
5,35.500,0.10,1.9979,1.99800,5.000
5,35.562,0.17,2.0602,2.06030,5.000
5,35.625,0.25,2.1228,2.12290,5.000
5,35.688,0.36,2.1852,2.18530,5.000
5,35.750,0.49,2.2477,2.24780,5.000
5,35.812,0.63,2.3103,2.31037,5.000
5,35.875,0.81,2.3728,2.37285,5.000
5,35.938,1.00,2.4355,2.43555,5.000
5,36.062,1.04,2.4361,2.43615,5.000
5,36.125,0.80,2.3734,2.37355,5.000
5,36.188,0.60,2.3110,2.31112,5.000
5,36.250,0.44,2.2485,2.24860,5.000
5,36.312,0.30,2.1860,2.18610,5.000
5,36.375,0.20,2.1235,2.12360,5.000
5,36.438,0.12,2.0609,2.06105,5.000
5,36.500,0.06,1.9985,1.99860,5.000
5,36.562,0.02,1.9360,1.93605,5.000
5,36.625,0.02,1.8736,1.87370,5.000
5,36.688,0.00,1.8110,1.81110,5.000
5,36.750,0.00,1.7486,1.74870,5.000
5,36.812,-0.01,1.6859,1.68595,5.000
5,36.875,-0.01,1.6234,1.62355,5.000
5,36.938,-0.02,1.5609,1.56105,5.000
5,37.000,-0.02,1.4985,1.49860,5.000
5,37.062,-0.01,1.4360,1.43610,5.000
5,37.125,-0.01,1.3734,1.37345,5.000
5,37.188,-0.01,1.3109,1.31102,5.000
5,37.250,-0.01,1.2482,1.24830,5.000
5,37.312,-0.01,1.1860,1.18608,5.000
5,37.375,-0.02,1.1234,1.12345,5.000
5,37.438,-0.01,1.0609,1.06102,5.000
5,37.500,-0.01,0.9984,0.99850,5.000
5,37.562,-0.01,0.9358,0.93590,5.000
5,37.625,-0.01,0.8734,0.87355,5.000
5,37.688,-0.01,0.8108,0.81092,5.000
5,37.750,-0.01,0.7484,0.74850,5.000
5,37.812,-0.01,0.6858,0.68588,5.000
5,37.875,-0.01,0.6235,0.62355,5.000
5,37.938,-0.01,0.5609,0.56097,5.000
5,38.000,-0.01,0.4983,0.49840,5.000
5,38.062,-0.01,0.4359,0.43603,5.000
5,38.125,-0.01,0.3734,0.37350,5.000
5,38.188,-0.01,0.3111,0.31117,5.000
5,38.250,-0.01,0.2484,0.24850,5.000
5,38.312,-0.01,0.1860,0.18608,5.000
5,38.375,-0.01,0.1233,0.12340,5.000
5,38.438,-0.01,0.0608,0.06092,5.000
5,38.500,-0.01,-0.0016,-0.00150,5.000
5,38.625,-0.01,-0.0038,-0.00365,5.000
5,38.688,-0.01,-0.0002,-0.00010,5.000
5,38.750,-0.01,-0.0002,-0.00010,5.000
5,38.812,-0.01,-0.0002,-0.00010,5.000
5,38.875,-0.01,-0.0002,-0.00010,5.000
5,38.938,-0.01,-0.0002,-0.00010,5.000
5,39.000,-0.01,-0.0002,-0.00010,5.000
5,39.062,-0.01,-0.0002,-0.00010,5.000
5,39.125,-0.01,-0.0002,-0.00010,5.000
5,39.188,-0.01,-0.0002,-0.00010,5.000
5,39.250,-0.01,-0.0002,-0.00010,5.000
5,39.312,-0.01,-0.0002,-0.00010,5.000
5,39.375,-0.01,-0.0002,-0.00010,5.000
5,39.438,-0.01,-0.0002,-0.00010,5.000
5,39.500,-0.01,-0.0002,-0.00010,5.000
5,39.562,-0.01,-0.0002,-0.00010,5.000
5,39.625,-0.01,-0.0002,-0.00010,5.000
5,39.688,-0.01,-0.0002,-0.00010,5.000
5,39.750,-0.01,-0.0002,-0.00010,5.000
5,39.812,-0.01,-0.0002,-0.00010,5.000
5,39.875,-0.01,-0.0002,-0.00010,5.000
5,39.938,-0.01,-0.0002,-0.00010,5.000
5,40.000,-0.01,-0.0002,-0.00010,5.000
5,40.062,-0.01,-0.0002,-0.00010,5.000
5,40.125,-0.01,-0.0002,-0.00010,5.000
5,40.188,-0.01,-0.0002,-0.00010,5.000
5,40.250,-0.01,-0.0002,-0.00010,5.000
5,40.312,-0.01,-0.0002,-0.00010,5.000
5,40.375,-0.01,-0.0002,-0.00010,5.000
5,40.438,-0.02,-0.0002,-0.00010,5.000
5,40.500,-0.01,-0.0002,-0.00010,5.000
5,40.562,-0.01,-0.0002,-0.00010,5.000
5,40.625,-0.01,-0.0002,-0.00010,5.000
5,40.688,-0.01,-0.0002,-0.00010,5.000
5,40.750,-0.01,-0.0002,-0.00010,5.000
5,40.812,-0.01,-0.0001,0.00000,5.000
5,40.875,-0.01,-0.0001,0.00000,5.000
5,40.938,-0.01,-0.0001,0.00000,5.000
5,41.000,-0.01,-0.0001,0.00000,5.000
5,41.062,-0.01,-0.0001,0.00000,5.000
5,41.125,-0.01,-0.0001,0.00000,5.000
5,41.188,-0.01,-0.0001,0.00000,5.000
5,41.250,-0.01,-0.0001,0.00000,5.000
5,41.312,-0.01,-0.0001,0.00000,5.000
5,41.375,-0.01,-0.0001,0.00000,5.000
5,41.438,-0.01,-0.0001,0.00000,5.000
5,41.500,-0.01,-0.0001,0.00000,5.000
5,41.562,-0.01,-0.0001,0.00000,5.000
6,41.875,0.00,0.0826,0.08260,6.000
6,41.938,0.00,0.1452,0.14518,6.000
6,42.000,0.00,0.2075,0.20750,6.000
6,42.062,0.00,0.2702,0.27025,6.000
6,42.125,0.00,0.3328,0.33275,6.000
6,42.188,0.00,0.3953,0.39530,6.000
6,42.250,0.00,0.4577,0.45770,6.000
6,42.312,0.00,0.5201,0.52015,6.000
6,42.375,0.00,0.5827,0.58270,6.000
6,42.438,0.00,0.6452,0.64515,6.000
6,42.500,0.00,0.7078,0.70780,6.000
6,42.562,0.00,0.7701,0.77012,6.000
6,42.625,0.00,0.8328,0.83275,6.000
6,42.688,0.00,0.8951,0.89505,6.000
6,42.750,0.00,0.9577,0.95770,6.000
6,42.812,0.00,1.0202,1.02025,6.000
6,42.875,0.00,1.0827,1.08270,6.000
6,42.938,0.00,1.1452,1.14520,6.000
6,43.000,0.00,1.2076,1.20760,6.000
6,43.062,0.00,1.2703,1.27027,6.000
6,43.125,0.00,1.3326,1.33265,6.000
6,43.188,0.00,1.3953,1.39528,6.000
6,43.250,0.00,1.4577,1.45770,6.000
6,43.312,0.00,1.5203,1.52027,6.000
6,43.375,0.00,1.5828,1.58275,6.000
6,43.438,0.00,1.6452,1.64515,6.000
6,43.500,0.01,1.7077,1.70770,6.000
6,43.562,0.03,1.7703,1.77030,6.000
6,43.625,0.04,1.8329,1.83290,6.000
6,43.688,0.06,1.8953,1.89530,6.000
6,43.750,0.09,1.9579,1.95790,6.000
6,43.812,0.14,2.0202,2.02020,6.000
6,43.875,0.20,2.0828,2.08280,6.000
6,43.938,0.30,2.1453,2.14528,6.000
6,44.000,0.41,2.2077,2.20770,6.000
6,44.062,0.54,2.2704,2.27040,6.000
6,44.125,0.70,2.3328,2.33280,6.000
6,44.188,0.88,2.3955,2.39548,6.000
6,44.250,1.09,2.4577,2.45770,6.000
6,44.312,1.20,2.4735,2.47353,6.000
6,44.375,0.96,2.4154,2.41540,6.000
6,44.438,0.73,2.3531,2.35310,6.000
6,44.500,0.56,2.2904,2.29040,6.000
6,44.562,0.40,2.2281,2.22805,6.000
6,44.625,0.28,2.1654,2.16545,6.000
6,44.688,0.18,2.1030,2.10302,6.000
6,44.750,0.10,2.0405,2.04050,6.000
6,44.812,0.06,1.9780,1.97795,6.000
6,44.875,0.03,1.9155,1.91550,6.000
6,44.938,0.02,1.8529,1.85295,6.000
6,45.000,0.01,1.7906,1.79060,6.000
6,45.062,0.00,1.7280,1.72795,6.000
6,45.125,0.00,1.6654,1.66545,6.000
6,45.188,0.00,1.6029,1.60287,6.000
6,45.250,0.00,1.5405,1.54050,6.000
6,45.312,0.00,1.4780,1.47803,6.000
6,45.375,0.00,1.4154,1.41545,6.000
6,45.438,0.00,1.3530,1.35302,6.000
6,45.500,0.00,1.2903,1.29030,6.000
6,45.562,0.00,1.2280,1.22798,6.000
6,45.625,-0.01,1.1654,1.16535,6.000
6,45.688,0.00,1.1030,1.10300,6.000
6,45.750,0.00,1.0404,1.04040,6.000
6,45.812,0.00,0.9779,0.97790,6.000
6,45.875,0.00,0.9155,0.91545,6.000
6,45.938,0.00,0.8528,0.85285,6.000
6,46.000,0.00,0.7905,0.79050,6.000
6,46.062,0.00,0.7278,0.72783,6.000
6,46.125,0.00,0.6654,0.66545,6.000
6,46.188,0.00,0.6028,0.60285,6.000
6,46.250,0.00,0.5403,0.54030,6.000
6,46.312,0.00,0.4779,0.47790,6.000
6,46.375,0.00,0.4154,0.41540,6.000
6,46.438,0.00,0.3530,0.35300,6.000
6,46.500,0.00,0.2903,0.29030,6.000
6,46.562,0.00,0.2280,0.22798,6.000
6,46.625,0.00,0.1654,0.16535,6.000
6,46.688,0.00,0.1028,0.10285,6.000
6,46.750,0.00,0.0403,0.04030,6.000
6,46.938,0.00,-0.0023,-0.00232,6.000
6,47.000,0.00,-0.0002,-0.00020,6.000
6,47.062,0.00,-0.0002,-0.00020,6.000
6,47.125,0.00,-0.0002,-0.00020,6.000
6,47.188,0.00,-0.0002,-0.00020,6.000
6,47.250,0.00,-0.0002,-0.00020,6.000
6,47.312,0.00,-0.0002,-0.00020,6.000
6,47.375,0.00,-0.0002,-0.00020,6.000
6,47.438,0.00,-0.0002,-0.00020,6.000
6,47.500,0.01,-0.0002,-0.00020,6.000
6,47.562,0.00,-0.0002,-0.00020,6.000
6,47.625,0.00,-0.0002,-0.00020,6.000
6,47.688,0.00,-0.0002,-0.00020,6.000
6,47.750,0.00,-0.0002,-0.00020,6.000
6,47.812,0.00,-0.0002,-0.00020,6.000
6,47.875,0.00,-0.0002,-0.00020,6.000
6,47.938,0.00,-0.0002,-0.00020,6.000
6,48.000,0.00,-0.0002,-0.00020,6.000
6,48.062,0.00,-0.0002,-0.00020,6.000
6,48.125,0.00,-0.0002,-0.00020,6.000
6,48.188,0.00,-0.0002,-0.00020,6.000
6,48.250,0.00,-0.0002,-0.00020,6.000
6,48.312,0.00,-0.0002,-0.00020,6.000
6,48.375,0.00,-0.0002,-0.00020,6.000
6,48.438,0.00,-0.0002,-0.00020,6.000
6,48.500,0.00,-0.0002,-0.00020,6.000
6,48.562,0.00,-0.0002,-0.00020,6.000
6,48.625,0.00,-0.0002,-0.00020,6.000
6,48.688,0.00,-0.0002,-0.00020,6.000
6,48.750,0.00,-0.0002,-0.00020,6.000
6,48.812,0.00,-0.0002,-0.00020,6.000
6,48.875,0.00,-0.0002,-0.00020,6.000
6,48.938,0.00,-0.0001,-0.00010,6.000
6,49.000,0.01,-0.0001,-0.00010,6.000
6,49.062,0.00,-0.0001,-0.00010,6.000
6,49.125,0.00,-0.0001,-0.00010,6.000
6,49.188,0.00,-0.0001,-0.00010,6.000
6,49.250,0.00,-0.0001,-0.00010,6.000
6,49.312,0.00,-0.0001,-0.00010,6.000
6,49.375,0.00,-0.0001,-0.00010,6.000
6,49.438,0.00,-0.0001,-0.00010,6.000
6,49.500,0.00,-0.0001,-0.00010,6.000
6,49.562,0.00,-0.0001,-0.00010,6.000
6,49.625,0.00,-0.0001,-0.00010,6.000
6,49.688,0.00,-0.0001,-0.00010,6.000
6,49.750,0.00,-0.0001,-0.00010,6.000
6,49.812,0.00,-0.0001,-0.00010,6.000
6,49.875,0.00,-0.0001,-0.00010,6.000
7,50.188,0.00,0.0762,0.07630,7.000
7,50.250,0.00,0.1386,0.13870,7.000
7,50.312,0.00,0.2012,0.20127,7.000
7,50.375,0.00,0.2637,0.26385,7.000
7,50.438,0.00,0.3262,0.32633,7.000
7,50.500,0.00,0.3888,0.38890,7.000
7,50.562,0.00,0.4510,0.45115,7.000
7,50.625,0.00,0.5137,0.51385,7.000
7,50.688,0.00,0.5761,0.57620,7.000
7,50.750,0.00,0.6387,0.63880,7.000
7,50.812,0.00,0.7011,0.70125,7.000
7,50.875,0.00,0.7636,0.76375,7.000
7,50.938,0.00,0.8263,0.82638,7.000
7,51.000,0.00,0.8887,0.88880,7.000
7,51.062,0.00,0.9513,0.95137,7.000
7,51.125,0.00,1.0136,1.01375,7.000
7,51.188,0.00,1.0763,1.07638,7.000
7,51.250,0.00,1.1387,1.13880,7.000
7,51.312,0.00,1.2012,1.20132,7.000
7,51.375,0.00,1.2637,1.26380,7.000
7,51.438,0.00,1.3261,1.32623,7.000
7,51.500,0.00,1.3887,1.38880,7.000
7,51.562,0.00,1.4511,1.45122,7.000
7,51.625,0.00,1.5138,1.51390,7.000
7,51.688,0.00,1.5761,1.57620,7.000
7,51.750,0.00,1.6387,1.63880,7.000
7,51.812,0.01,1.7012,1.70132,7.000
7,51.875,0.02,1.7639,1.76400,7.000
7,51.938,0.04,1.8264,1.82645,7.000
7,52.000,0.05,1.8888,1.88890,7.000
7,52.062,0.08,1.9514,1.95147,7.000
7,52.125,0.13,2.0137,2.01380,7.000
7,52.188,0.20,2.0764,2.07650,7.000
7,52.250,0.29,2.1387,2.13880,7.000
7,52.312,0.40,2.2013,2.20145,7.000
7,52.375,0.53,2.2638,2.26395,7.000
7,52.438,0.68,2.3263,2.32638,7.000
7,52.500,0.86,2.3890,2.38910,7.000
7,52.688,0.99,2.4220,2.42207,7.000
7,52.750,0.76,2.3597,2.35980,7.000
7,52.812,0.57,2.2970,2.29708,7.000
7,52.875,0.42,2.2346,2.23465,7.000
7,52.938,0.29,2.1720,2.17207,7.000
7,53.000,0.19,2.1096,2.10970,7.000
7,53.062,0.12,2.0470,2.04710,7.000
7,53.125,0.06,1.9845,1.98460,7.000
7,53.188,0.03,1.9220,1.92207,7.000
7,53.250,0.02,1.8596,1.85970,7.000
7,53.312,0.01,1.7972,1.79728,7.000
7,53.375,0.01,1.7345,1.73455,7.000
7,53.438,0.01,1.6720,1.67210,7.000
7,53.500,0.00,1.6093,1.60940,7.000
7,53.562,0.00,1.5471,1.54715,7.000
7,53.625,0.00,1.4845,1.48460,7.000
7,53.688,0.00,1.4221,1.42217,7.000
7,53.750,0.00,1.3595,1.35960,7.000
7,53.812,0.00,1.2969,1.29698,7.000
7,53.875,0.00,1.2345,1.23460,7.000
7,53.938,0.00,1.1719,1.17200,7.000
7,54.000,0.00,1.1095,1.10960,7.000
7,54.062,0.00,1.0469,1.04695,7.000
7,54.125,0.00,0.9845,0.98460,7.000
7,54.188,0.00,0.9219,0.92202,7.000
7,54.250,0.00,0.8595,0.85960,7.000
7,54.312,0.00,0.7969,0.79703,7.000
7,54.375,0.00,0.7344,0.73445,7.000
7,54.438,0.00,0.6719,0.67200,7.000
7,54.500,0.00,0.6093,0.60940,7.000
7,54.562,0.00,0.5469,0.54700,7.000
7,54.625,0.00,0.4844,0.48445,7.000
7,54.688,0.00,0.4220,0.42210,7.000
7,54.750,0.00,0.3595,0.35960,7.000
7,54.812,0.00,0.2969,0.29698,7.000
7,54.875,0.00,0.2345,0.23455,7.000
7,54.938,0.00,0.1718,0.17192,7.000
7,55.000,0.00,0.1094,0.10950,7.000
7,55.062,0.00,0.0468,0.04693,7.000
7,55.250,0.00,0.0000,0.00010,7.000
7,55.312,0.00,-0.0002,-0.00010,7.000
7,55.375,0.00,-0.0002,-0.00010,7.000
7,55.438,0.00,-0.0002,-0.00010,7.000
7,55.500,0.00,-0.0002,-0.00010,7.000
7,55.562,0.00,-0.0002,-0.00010,7.000
7,55.625,0.00,-0.0002,-0.00010,7.000
7,55.688,0.00,-0.0002,-0.00010,7.000
7,55.750,0.00,-0.0002,-0.00010,7.000
7,55.812,0.00,-0.0002,-0.00010,7.000
7,55.875,0.00,-0.0002,-0.00010,7.000
7,55.938,0.00,-0.0002,-0.00010,7.000
7,56.000,0.00,-0.0002,-0.00010,7.000
7,56.062,0.00,-0.0002,-0.00010,7.000
7,56.125,0.00,-0.0002,-0.00010,7.000
7,56.188,0.00,-0.0002,-0.00010,7.000
7,56.250,0.00,-0.0002,-0.00010,7.000
7,56.312,0.00,-0.0002,-0.00010,7.000
7,56.375,0.00,-0.0002,-0.00010,7.000
7,56.438,0.00,-0.0002,-0.00010,7.000
7,56.500,0.00,-0.0002,-0.00010,7.000
7,56.562,0.00,-0.0002,-0.00010,7.000
7,56.625,0.00,-0.0002,-0.00010,7.000
7,56.688,0.00,-0.0002,-0.00010,7.000
7,56.750,0.00,-0.0002,-0.00010,7.000
7,56.812,0.00,-0.0001,0.00000,7.000
7,56.875,0.00,-0.0001,0.00000,7.000
7,56.938,0.00,-0.0001,0.00000,7.000
7,57.000,0.00,-0.0001,0.00000,7.000
7,57.062,-0.01,-0.0001,0.00000,7.000
7,57.125,0.00,-0.0001,0.00000,7.000
7,57.188,0.00,-0.0001,0.00000,7.000
7,57.250,0.00,-0.0001,0.00000,7.000
7,57.312,0.00,-0.0001,0.00000,7.000
7,57.375,0.00,-0.0001,0.00000,7.000
7,57.438,0.00,-0.0001,0.00000,7.000
7,57.500,0.00,-0.0001,0.00000,7.000
7,57.562,0.00,-0.0001,0.00000,7.000
7,57.625,0.00,-0.0001,0.00000,7.000
7,57.688,0.00,-0.0001,0.00000,7.000
7,57.750,0.00,-0.0001,0.00000,7.000
7,57.812,-0.01,-0.0001,0.00000,7.000
7,57.875,0.00,-0.0001,0.00000,7.000
7,57.938,0.00,-0.0001,0.00000,7.000
7,58.000,0.00,-0.0001,0.00000,7.000
7,58.062,0.00,-0.0001,0.00000,7.000
7,58.125,0.00,-0.0001,0.00000,7.000
7,58.188,-0.01,-0.0001,0.00000,7.000
8,58.500,0.01,0.1067,0.10670,8.000
8,58.562,0.01,0.1690,0.16902,8.000
8,58.625,0.01,0.2318,0.23180,8.000
8,58.688,0.01,0.2942,0.29418,8.000
8,58.750,0.01,0.3568,0.35680,8.000
8,58.812,0.01,0.4192,0.41920,8.000
8,58.875,0.01,0.4816,0.48165,8.000
8,58.938,0.01,0.5442,0.54420,8.000
8,59.000,0.01,0.6065,0.60650,8.000
8,59.062,0.01,0.6693,0.66927,8.000
8,59.125,0.01,0.7316,0.73165,8.000
8,59.188,0.00,0.7943,0.79428,8.000
8,59.250,0.01,0.8566,0.85660,8.000
8,59.312,0.00,0.9192,0.91920,8.000
8,59.375,0.01,0.9817,0.98175,8.000
8,59.438,0.01,1.0442,1.04423,8.000
8,59.500,0.01,1.1067,1.10670,8.000
8,59.562,0.01,1.1692,1.16917,8.000
8,59.625,0.01,1.2317,1.23175,8.000
8,59.688,0.01,1.2942,1.29418,8.000
8,59.750,0.01,1.3568,1.35680,8.000
8,59.812,0.01,1.4192,1.41920,8.000
8,59.875,0.01,1.4818,1.48180,8.000
8,59.938,0.01,1.5443,1.54433,8.000
8,60.000,0.01,1.6068,1.60680,8.000
8,60.062,0.01,1.6693,1.66930,8.000
8,60.125,0.03,1.7316,1.73165,8.000
8,60.188,0.04,1.7944,1.79440,8.000
8,60.250,0.06,1.8568,1.85680,8.000
8,60.312,0.08,1.9193,1.91935,8.000
8,60.375,0.11,1.9817,1.98175,8.000
8,60.438,0.17,2.0443,2.04425,8.000
8,60.500,0.25,2.1069,2.10690,8.000
8,60.562,0.35,2.1692,2.16925,8.000
8,60.625,0.47,2.2318,2.23185,8.000
8,60.688,0.61,2.2943,2.29425,8.000
8,60.750,0.78,2.3569,2.35690,8.000
8,60.812,0.97,2.4192,2.41925,8.000
8,60.938,1.13,2.4497,2.44972,8.000
8,61.000,0.87,2.3875,2.38750,8.000
8,61.062,0.66,2.3250,2.32503,8.000
8,61.125,0.50,2.2625,2.26250,8.000
8,61.188,0.36,2.2000,2.20000,8.000
8,61.250,0.24,2.1374,2.13740,8.000
8,61.312,0.16,2.0751,2.07505,8.000
8,61.375,0.09,2.0125,2.01245,8.000
8,61.438,0.05,1.9500,1.95005,8.000
8,61.500,0.03,1.8874,1.88740,8.000
8,61.562,0.02,1.8252,1.82515,8.000
8,61.625,0.02,1.7626,1.76260,8.000
8,61.688,0.02,1.6999,1.69985,8.000
8,61.750,0.01,1.6374,1.63740,8.000
8,61.812,0.00,1.5749,1.57485,8.000
8,61.875,0.01,1.5126,1.51260,8.000
8,61.938,0.00,1.4500,1.44998,8.000
8,62.000,0.00,1.3875,1.38750,8.000
8,62.062,0.01,1.3249,1.32490,8.000
8,62.125,0.01,1.2625,1.26245,8.000
8,62.188,0.01,1.2000,1.19995,8.000
8,62.250,0.01,1.1374,1.13740,8.000
8,62.312,0.01,1.0750,1.07495,8.000
8,62.375,0.01,1.0125,1.01245,8.000
8,62.438,0.01,0.9500,0.95000,8.000
8,62.500,0.01,0.8874,0.88740,8.000
8,62.562,0.01,0.8250,0.82495,8.000
8,62.625,0.01,0.7624,0.76240,8.000
8,62.688,0.00,0.6999,0.69990,8.000
8,62.750,0.01,0.6375,0.63750,8.000
8,62.812,0.01,0.5749,0.57488,8.000
8,62.875,0.01,0.5124,0.51240,8.000
8,62.938,0.01,0.4498,0.44980,8.000
8,63.000,0.01,0.3875,0.38750,8.000
8,63.062,0.01,0.3249,0.32493,8.000
8,63.125,0.01,0.2625,0.26250,8.000
8,63.188,0.01,0.1999,0.19993,8.000
8,63.250,0.01,0.1374,0.13740,8.000
8,63.312,0.01,0.0749,0.07490,8.000
8,63.375,0.01,0.0123,0.01230,8.000
8,63.500,0.01,-0.0129,-0.01290,8.000
8,63.562,0.01,-0.0002,-0.00020,8.000
8,63.625,0.01,-0.0002,-0.00020,8.000
8,63.688,0.01,-0.0002,-0.00020,8.000
8,63.750,0.01,-0.0002,-0.00020,8.000
8,63.812,0.01,-0.0002,-0.00020,8.000
8,63.875,0.01,-0.0002,-0.00020,8.000
8,63.938,0.01,-0.0002,-0.00020,8.000
8,64.000,0.01,-0.0002,-0.00020,8.000
8,64.062,0.01,-0.0002,-0.00020,8.000
8,64.125,0.01,-0.0002,-0.00020,8.000
8,64.188,0.00,-0.0002,-0.00020,8.000
8,64.250,0.01,-0.0002,-0.00020,8.000
8,64.312,0.01,-0.0002,-0.00020,8.000
8,64.375,0.01,-0.0002,-0.00020,8.000
8,64.438,0.01,-0.0002,-0.00020,8.000
8,64.500,0.00,-0.0002,-0.00020,8.000
8,64.562,0.01,-0.0002,-0.00020,8.000
8,64.625,0.01,-0.0002,-0.00020,8.000
8,64.688,0.01,-0.0002,-0.00020,8.000
8,64.750,0.01,-0.0002,-0.00020,8.000
8,64.812,0.01,-0.0002,-0.00020,8.000
8,64.875,0.01,-0.0001,-0.00010,8.000
8,64.938,0.01,-0.0001,-0.00010,8.000
8,65.000,0.01,-0.0001,-0.00010,8.000
8,65.062,0.00,-0.0001,-0.00010,8.000
8,65.125,0.01,-0.0001,-0.00010,8.000
8,65.188,0.00,-0.0001,-0.00010,8.000
8,65.250,0.00,-0.0001,-0.00010,8.000
8,65.312,0.00,-0.0001,-0.00010,8.000
8,65.375,0.00,-0.0001,-0.00010,8.000
8,65.438,0.01,-0.0001,-0.00010,8.000
8,65.500,0.01,-0.0001,-0.00010,8.000
8,65.562,0.00,-0.0001,-0.00010,8.000
8,65.625,0.01,-0.0001,-0.00010,8.000
8,65.688,0.01,-0.0001,-0.00010,8.000
8,65.750,0.01,-0.0001,-0.00010,8.000
8,65.812,0.00,-0.0001,-0.00010,8.000
8,65.875,0.01,-0.0001,-0.00010,8.000
8,65.938,0.01,-0.0001,-0.00010,8.000
8,66.000,0.01,-0.0001,-0.00010,8.000
8,66.062,0.01,-0.0001,-0.00010,8.000
8,66.125,0.01,-0.0001,-0.00010,8.000
8,66.188,0.01,-0.0001,-0.00010,8.000
8,66.250,0.01,-0.0001,-0.00010,8.000
8,66.312,0.01,-0.0001,-0.00010,8.000
8,66.375,0.01,-0.0001,-0.00010,8.000
8,66.438,0.01,-0.0001,-0.00010,8.000
9,66.750,0.01,0.0776,0.07770,9.000
9,66.812,0.01,0.1401,0.14020,9.000
9,66.875,0.01,0.2026,0.20270,9.000
9,66.938,0.01,0.2653,0.26535,9.000
9,67.000,0.01,0.3276,0.32770,9.000
9,67.062,0.01,0.3902,0.39032,9.000
9,67.125,0.01,0.4526,0.45275,9.000
9,67.188,0.01,0.5152,0.51533,9.000
9,67.250,0.02,0.5775,0.57760,9.000
9,67.312,0.01,0.6402,0.64027,9.000
9,67.375,0.01,0.7026,0.70275,9.000
9,67.438,0.01,0.7651,0.76518,9.000
9,67.500,0.01,0.8278,0.82790,9.000
9,67.562,0.01,0.8901,0.89022,9.000
9,67.625,0.01,0.9528,0.95285,9.000
9,67.688,0.01,1.0152,1.01525,9.000
9,67.750,0.01,1.0778,1.07790,9.000
9,67.812,0.01,1.1402,1.14030,9.000
9,67.875,0.01,1.2027,1.20280,9.000
9,67.938,0.01,1.2652,1.26530,9.000
9,68.000,0.02,1.3276,1.32770,9.000
9,68.062,0.01,1.3903,1.39037,9.000
9,68.125,0.02,1.4527,1.45280,9.000
9,68.188,0.01,1.5153,1.51540,9.000
9,68.250,0.01,1.5777,1.57780,9.000
9,68.312,0.02,1.6402,1.64035,9.000
9,68.375,0.03,1.7027,1.70280,9.000
9,68.438,0.04,1.7653,1.76538,9.000
9,68.500,0.05,1.8278,1.82790,9.000
9,68.562,0.07,1.8903,1.89037,9.000
9,68.625,0.10,1.9528,1.95290,9.000
9,68.688,0.15,2.0152,2.01530,9.000
9,68.750,0.21,2.0779,2.07800,9.000
9,68.812,0.31,2.1402,2.14030,9.000
9,68.875,0.42,2.2028,2.20290,9.000
9,68.938,0.55,2.2653,2.26540,9.000
9,69.000,0.71,2.3279,2.32800,9.000
9,69.062,0.89,2.3904,2.39052,9.000
9,69.250,1.00,2.4185,2.41860,9.000
9,69.312,0.76,2.3560,2.35613,9.000
9,69.375,0.58,2.2934,2.29355,9.000
9,69.438,0.43,2.2310,2.23112,9.000
9,69.500,0.30,2.1684,2.16850,9.000
9,69.562,0.20,2.1060,2.10610,9.000
9,69.625,0.13,2.0435,2.04360,9.000
9,69.688,0.08,1.9809,1.98102,9.000
9,69.750,0.05,1.9185,1.91860,9.000
9,69.812,0.04,1.8560,1.85613,9.000
9,69.875,0.03,1.7936,1.79375,9.000
9,69.938,0.02,1.7310,1.73108,9.000
9,70.000,0.02,1.6684,1.66850,9.000
9,70.062,0.01,1.6059,1.60600,9.000
9,70.125,0.01,1.5434,1.54355,9.000
9,70.188,0.01,1.4810,1.48110,9.000
9,70.250,0.01,1.4185,1.41860,9.000
9,70.312,0.02,1.3559,1.35603,9.000
9,70.375,0.01,1.2934,1.29345,9.000
9,70.438,0.01,1.2310,1.23108,9.000
9,70.500,0.01,1.1684,1.16850,9.000
9,70.562,0.01,1.1060,1.10608,9.000
9,70.625,0.01,1.0434,1.04350,9.000
9,70.688,0.01,0.9809,0.98098,9.000
9,70.750,0.01,0.9185,0.91860,9.000
9,70.812,0.01,0.8559,0.85600,9.000
9,70.875,0.01,0.7934,0.79355,9.000
9,70.938,0.01,0.7308,0.73090,9.000
9,71.000,0.01,0.6684,0.66850,9.000
9,71.062,0.01,0.6058,0.60593,9.000
9,71.125,0.02,0.5434,0.54350,9.000
9,71.188,0.01,0.4809,0.48095,9.000
9,71.250,0.01,0.4184,0.41850,9.000
9,71.312,0.01,0.3560,0.35608,9.000
9,71.375,0.01,0.2934,0.29345,9.000
9,71.438,0.01,0.2309,0.23102,9.000
9,71.500,0.02,0.1683,0.16840,9.000
9,71.562,0.01,0.1059,0.10600,9.000
9,71.625,0.01,0.0433,0.04340,9.000
9,71.688,0.01,-0.0191,-0.01898,9.000
9,71.812,0.01,-0.0040,-0.00393,9.000
9,71.875,0.01,-0.0002,-0.00010,9.000
9,71.938,0.01,-0.0001,0.00000,9.000
9,72.000,0.01,-0.0001,0.00000,9.000
9,72.062,0.01,-0.0001,0.00000,9.000
9,72.125,0.01,-0.0001,0.00000,9.000
9,72.188,0.01,-0.0001,0.00000,9.000
9,72.250,0.02,-0.0001,0.00000,9.000
9,72.312,0.02,-0.0001,0.00000,9.000
9,72.375,0.01,-0.0001,0.00000,9.000
9,72.438,0.01,-0.0001,0.00000,9.000
9,72.500,0.01,-0.0001,0.00000,9.000
9,72.562,0.01,-0.0001,0.00000,9.000
9,72.625,0.01,-0.0001,0.00000,9.000
9,72.688,0.01,-0.0001,0.00000,9.000
9,72.750,0.02,-0.0001,0.00000,9.000
9,72.812,0.01,-0.0001,0.00000,9.000
9,72.875,0.01,-0.0001,0.00000,9.000
9,72.938,0.01,-0.0001,0.00000,9.000
9,73.000,0.01,-0.0001,0.00000,9.000
9,73.062,0.01,-0.0001,0.00000,9.000
9,73.125,0.02,-0.0001,0.00000,9.000
9,73.188,0.01,-0.0001,0.00000,9.000
9,73.250,0.00,-0.0001,0.00000,9.000
9,73.312,0.01,-0.0001,0.00000,9.000
9,73.375,0.01,-0.0001,0.00000,9.000
9,73.438,0.01,-0.0001,0.00000,9.000
9,73.500,0.02,-0.0001,0.00000,9.000
9,73.562,0.01,-0.0001,0.00000,9.000
9,73.625,0.01,-0.0001,0.00000,9.000
9,73.688,0.01,-0.0001,0.00000,9.000
9,73.750,0.01,-0.0001,0.00000,9.000
9,73.812,0.01,-0.0001,0.00000,9.000
9,73.875,0.01,-0.0001,0.00000,9.000
9,73.938,0.01,-0.0001,0.00000,9.000
9,74.000,0.01,-0.0001,0.00000,9.000
9,74.062,0.01,-0.0001,0.00000,9.000
9,74.125,0.01,-0.0001,0.00000,9.000
9,74.188,0.02,-0.0001,0.00000,9.000
9,74.250,0.01,-0.0001,0.00000,9.000
9,74.312,0.01,-0.0001,0.00000,9.000
9,74.375,0.01,-0.0001,0.00000,9.000
9,74.438,0.01,-0.0001,0.00000,9.000
9,74.500,0.01,-0.0001,0.00000,9.000
9,74.562,0.01,-0.0001,0.00000,9.000
9,74.625,0.01,-0.0001,0.00000,9.000
9,74.688,0.01,-0.0001,0.00000,9.000
9,74.750,0.01,-0.0001,0.00000,9.000
10,75.062,0.00,0.0910,0.09100,10.000
10,75.125,0.00,0.1536,0.15360,10.000
10,75.188,0.00,0.2162,0.21615,10.000
10,75.250,0.00,0.2787,0.27870,10.000
10,75.312,0.00,0.3412,0.34122,10.000
10,75.375,0.00,0.4037,0.40370,10.000
10,75.438,0.00,0.4661,0.46612,10.000
10,75.500,0.00,0.5285,0.52850,10.000
10,75.562,0.00,0.5911,0.59112,10.000
10,75.625,0.00,0.6536,0.65360,10.000
10,75.688,0.00,0.7163,0.71628,10.000
10,75.750,0.00,0.7787,0.77870,10.000
10,75.812,0.00,0.8412,0.84122,10.000
10,75.875,0.00,0.9037,0.90370,10.000
10,75.938,0.00,0.9661,0.96612,10.000
10,76.000,-0.01,1.0287,1.02870,10.000
10,76.062,0.00,1.0911,1.09112,10.000
10,76.125,0.00,1.1538,1.15375,10.000
10,76.188,-0.01,1.2162,1.21615,10.000
10,76.250,0.00,1.2788,1.27880,10.000
10,76.312,0.00,1.3412,1.34120,10.000
10,76.375,-0.01,1.4037,1.40370,10.000
10,76.438,0.00,1.4662,1.46622,10.000
10,76.500,-0.01,1.5287,1.52870,10.000
10,76.562,0.00,1.5913,1.59127,10.000
10,76.625,0.00,1.6536,1.65365,10.000
10,76.688,0.01,1.7163,1.71630,10.000
10,76.750,0.03,1.7787,1.77870,10.000
10,76.812,0.04,1.8414,1.84137,10.000
10,76.875,0.06,1.9038,1.90375,10.000
10,76.938,0.09,1.9662,1.96618,10.000
10,77.000,0.15,2.0288,2.02880,10.000
10,77.062,0.21,2.0913,2.09127,10.000
10,77.125,0.31,2.1539,2.15385,10.000
10,77.188,0.43,2.2162,2.21620,10.000
10,77.250,0.56,2.2788,2.27880,10.000
10,77.312,0.73,2.3412,2.34125,10.000
10,77.375,0.91,2.4039,2.40385,10.000
10,77.562,1.00,2.4271,2.42710,10.000
10,77.625,0.77,2.3646,2.36455,10.000
10,77.688,0.58,2.3019,2.30195,10.000
10,77.750,0.42,2.2396,2.23960,10.000
10,77.812,0.30,2.1769,2.17693,10.000
10,77.875,0.20,2.1146,2.11455,10.000
10,77.938,0.12,2.0520,2.05198,10.000
10,78.000,0.06,1.9894,1.98940,10.000
10,78.062,0.03,1.9269,1.92688,10.000
10,78.125,0.02,1.8646,1.86455,10.000
10,78.188,0.02,1.8021,1.80213,10.000
10,78.250,0.01,1.7394,1.73940,10.000
10,78.312,0.01,1.6770,1.67700,10.000
10,78.375,0.00,1.6144,1.61435,10.000
10,78.438,-0.01,1.5521,1.55208,10.000
10,78.500,-0.01,1.4894,1.48940,10.000
10,78.562,0.00,1.4270,1.42703,10.000
10,78.625,0.00,1.3644,1.36440,10.000
10,78.688,-0.01,1.3019,1.30190,10.000
10,78.750,0.00,1.2394,1.23940,10.000
10,78.812,-0.01,1.1768,1.17680,10.000
10,78.875,0.00,1.1145,1.11445,10.000
10,78.938,0.00,1.0518,1.05182,10.000
10,79.000,0.00,0.9894,0.98940,10.000
10,79.062,0.00,0.9269,0.92688,10.000
10,79.125,0.00,0.8644,0.86440,10.000
10,79.188,0.00,0.8019,0.80188,10.000
10,79.250,0.00,0.7394,0.73940,10.000
10,79.312,-0.01,0.6769,0.67693,10.000
10,79.375,-0.01,0.6143,0.61430,10.000
10,79.438,-0.01,0.5519,0.55195,10.000
10,79.500,0.00,0.4892,0.48920,10.000
10,79.562,0.00,0.4270,0.42695,10.000
10,79.625,0.00,0.3644,0.36435,10.000
10,79.688,0.00,0.3020,0.30200,10.000
10,79.750,0.00,0.2395,0.23950,10.000
10,79.812,-0.01,0.1768,0.17680,10.000
10,79.875,0.00,0.1144,0.11435,10.000
10,79.938,-0.01,0.0518,0.05180,10.000
10,80.000,0.00,-0.0106,-0.01060,10.000
10,80.125,-0.01,-0.0081,-0.00805,10.000
10,80.188,-0.01,-0.0002,-0.00020,10.000
10,80.250,0.00,-0.0002,-0.00020,10.000
10,80.312,-0.01,-0.0002,-0.00020,10.000
10,80.375,0.00,-0.0002,-0.00020,10.000
10,80.438,0.00,-0.0002,-0.00020,10.000
10,80.500,0.00,-0.0002,-0.00020,10.000
10,80.562,0.00,-0.0002,-0.00020,10.000
10,80.625,0.00,-0.0002,-0.00020,10.000
10,80.688,0.00,-0.0002,-0.00020,10.000
10,80.750,0.00,-0.0002,-0.00020,10.000
10,80.812,0.00,-0.0002,-0.00020,10.000
10,80.875,0.00,-0.0002,-0.00020,10.000
10,80.938,0.00,-0.0002,-0.00020,10.000
10,81.000,0.00,-0.0002,-0.00020,10.000
10,81.062,0.00,-0.0002,-0.00020,10.000
10,81.125,0.00,-0.0002,-0.00020,10.000
10,81.188,0.00,-0.0002,-0.00020,10.000
10,81.250,0.00,-0.0002,-0.00020,10.000
10,81.312,0.00,-0.0002,-0.00020,10.000
10,81.375,0.00,-0.0002,-0.00020,10.000
10,81.438,0.00,-0.0002,-0.00020,10.000
10,81.500,0.00,-0.0002,-0.00020,10.000
10,81.562,0.00,-0.0002,-0.00020,10.000
10,81.625,0.00,-0.0002,-0.00020,10.000
10,81.688,0.00,-0.0002,-0.00020,10.000
10,81.750,0.00,-0.0002,-0.00020,10.000
10,81.812,0.00,-0.0001,-0.00010,10.000
10,81.875,0.00,-0.0001,-0.00010,10.000
10,81.938,0.00,-0.0001,-0.00010,10.000
10,82.000,0.00,-0.0001,-0.00010,10.000
10,82.062,0.00,-0.0001,-0.00010,10.000
10,82.125,0.00,-0.0001,-0.00010,10.000
10,82.188,0.00,-0.0001,-0.00010,10.000
10,82.250,0.00,-0.0001,-0.00010,10.000
10,82.312,0.00,-0.0001,-0.00010,10.000
10,82.375,0.00,-0.0001,-0.00010,10.000
10,82.438,0.00,-0.0001,-0.00010,10.000
10,82.500,0.00,-0.0001,-0.00010,10.000
10,82.562,0.00,-0.0001,-0.00010,10.000
10,82.625,-0.01,-0.0001,-0.00010,10.000
10,82.688,0.00,-0.0001,-0.00010,10.000
10,82.750,0.00,-0.0001,-0.00010,10.000
10,82.812,0.00,-0.0001,-0.00010,10.000
10,82.875,0.00,-0.0001,-0.00010,10.000
10,82.938,0.00,-0.0001,-0.00010,10.000
10,83.000,0.00,-0.0001,-0.00010,10.000
10,83.062,-0.01,-0.0001,-0.00010,10.000