File: calibDATA_loadcell/date_02:22:2018/Instron/50N_0_1_0_0.txt
""
"Test Method","Radhen_Load_Cntrl_Cmprsn_250N_12-7.msm"
"Sample I. D.","Sample1.mss"
"Specimen Number","21"

"TheCycle_Output ()","_Time (s)","_Load (N)","_Extension (mm)","RealTimeDepth (mm)","CycleNumber ()"

1,0.312,0.01,0.0811,0.08108,1.000
1,0.438,0.02,0.2062,0.20618,1.000
1,0.562,0.02,0.3314,0.33135,1.000
1,0.688,0.01,0.4565,0.45647,1.000
1,0.812,0.01,0.5813,0.58132,1.000
1,0.938,0.00,0.7062,0.70625,1.000
1,1.062,0.01,0.8314,0.83138,1.000
1,1.188,0.02,0.9563,0.95630,1.000
1,1.312,0.01,1.0813,1.08130,1.000
1,1.438,0.02,1.2063,1.20630,1.000
1,1.562,0.01,1.3313,1.33135,1.000
1,1.688,0.01,1.4565,1.45645,1.000
1,1.812,0.01,1.5815,1.58150,1.000
1,1.938,0.01,1.7064,1.70642,1.000
1,2.062,0.01,1.8314,1.83143,1.000
1,2.188,0.02,1.9563,1.95630,1.000
1,2.312,0.05,2.0813,2.08132,1.000
1,2.438,0.08,2.2064,2.20635,1.000
1,2.562,0.15,2.3314,2.33142,1.000
1,2.688,0.25,2.4566,2.45662,1.000
1,2.812,0.45,2.5814,2.58138,1.000
1,2.938,0.73,2.7064,2.70640,1.000
1,3.062,1.09,2.8314,2.83145,1.000
1,3.188,1.54,2.9564,2.95635,1.000
1,3.312,2.07,3.0814,3.08138,1.000
1,3.438,2.70,3.2063,3.20630,1.000
1,3.562,3.38,3.3315,3.33152,1.000
1,3.688,4.20,3.4564,3.45645,1.000
1,3.812,5.10,3.5815,3.58148,1.000
1,3.938,6.12,3.7066,3.70655,1.000
1,4.062,7.21,3.8316,3.83155,1.000
1,4.188,8.46,3.9564,3.95645,1.000
1,4.312,10.06,4.0813,4.08132,1.000
1,4.438,11.89,4.2063,4.20632,1.000
1,4.562,13.89,4.3312,4.33125,1.000
1,4.688,16.06,4.4564,4.45637,1.000
1,4.812,18.37,4.5815,4.58150,1.000
1,4.938,20.74,4.7065,4.70650,1.000
1,5.062,22.70,4.8314,4.83145,1.000
1,5.188,23.11,4.9563,4.95632,1.000
1,5.312,25.72,5.0813,5.08132,1.000
1,5.438,28.83,5.2063,5.20632,1.000
1,5.562,32.27,5.3314,5.33140,1.000
1,5.688,36.02,5.4564,5.45640,1.000
1,5.812,40.23,5.5815,5.58150,1.000
1,5.938,44.92,5.7066,5.70655,1.000
1,6.062,50.21,5.8314,5.83140,1.000
1,6.250,40.66,5.7597,5.75970,1.000
1,6.375,31.91,5.6348,5.63485,1.000
1,6.500,25.63,5.5098,5.50980,1.000
1,6.625,20.83,5.3848,5.38480,1.000
1,6.750,17.04,5.2599,5.25990,1.000
1,6.875,14.05,5.1347,5.13465,1.000
1,7.000,11.67,5.0095,5.00950,1.000
1,7.125,9.79,4.8846,4.88460,1.000
1,7.250,8.29,4.7596,4.75960,1.000
1,7.375,7.00,4.6347,4.63470,1.000
1,7.500,5.91,4.5097,4.50970,1.000
1,7.625,4.98,4.3847,4.38465,1.000
1,7.750,4.18,4.2595,4.25950,1.000
1,7.875,3.53,4.1345,4.13450,1.000
1,8.000,2.98,4.0095,4.00950,1.000
1,8.125,2.46,3.8845,3.88450,1.000
1,8.250,1.99,3.7594,3.75940,1.000
1,8.375,1.58,3.6345,3.63450,1.000
1,8.500,1.23,3.5095,3.50950,1.000
1,8.625,0.91,3.3846,3.38455,1.000
1,8.750,0.64,3.2596,3.25960,1.000
1,8.875,0.42,3.1345,3.13445,1.000
1,9.000,0.25,3.0095,3.00950,1.000
1,9.125,0.14,2.8844,2.88435,1.000
1,9.250,0.08,2.7592,2.75920,1.000
1,9.375,0.02,2.6343,2.63425,1.000
1,9.500,0.03,2.5095,2.50950,1.000
1,9.625,0.02,2.3845,2.38450,1.000
1,9.750,0.02,2.2594,2.25940,1.000
1,9.875,0.02,2.1345,2.13445,1.000
1,10.000,0.01,2.0094,2.00940,1.000
1,10.125,0.02,1.8844,1.88435,1.000
1,10.250,0.01,1.7593,1.75930,1.000
1,10.375,0.02,1.6343,1.63430,1.000
1,10.500,0.01,1.5093,1.50930,1.000
1,10.625,0.01,1.3844,1.38440,1.000
1,10.750,0.01,1.2594,1.25940,1.000
1,10.875,0.02,1.1344,1.13440,1.000
1,11.000,0.03,1.0094,1.00940,1.000
1,11.125,0.01,0.8843,0.88430,1.000
1,11.250,0.02,0.7593,0.75930,1.000
1,11.375,0.01,0.6341,0.63410,1.000
1,11.500,0.02,0.5092,0.50920,1.000
1,11.625,0.02,0.3843,0.38430,1.000
1,11.750,0.01,0.2592,0.25920,1.000
1,11.875,0.02,0.1343,0.13425,1.000
1,12.000,0.02,0.0092,0.00920,1.000
1,12.188,0.01,-0.0003,-0.00030,1.000
1,12.312,0.01,-0.0003,-0.00030,1.000
1,12.438,0.02,-0.0003,-0.00030,1.000
1,12.562,0.01,-0.0003,-0.00030,1.000
1,12.688,0.02,-0.0003,-0.00030,1.000
1,12.812,0.01,-0.0003,-0.00030,1.000
1,12.938,0.02,-0.0003,-0.00030,1.000
1,13.062,0.01,-0.0003,-0.00030,1.000
1,13.188,0.02,-0.0003,-0.00030,1.000
1,13.312,0.02,-0.0003,-0.00030,1.000
1,13.438,0.00,-0.0003,-0.00030,1.000
1,13.562,0.02,-0.0003,-0.00030,1.000
1,13.688,0.02,-0.0003,-0.00030,1.000
1,13.812,0.01,-0.0003,-0.00030,1.000
1,13.938,0.01,-0.0003,-0.00030,1.000
1,14.062,0.02,-0.0002,-0.00020,1.000
1,14.188,0.02,-0.0002,-0.00020,1.000
1,14.312,0.01,-0.0002,-0.00020,1.000
1,14.438,0.01,-0.0002,-0.00020,1.000
1,14.562,0.02,-0.0002,-0.00020,1.000
1,14.688,0.00,-0.0002,-0.00020,1.000
1,14.812,0.02,-0.0002,-0.00020,1.000
1,14.938,0.02,-0.0002,-0.00020,1.000
1,15.062,0.02,-0.0002,-0.00020,1.000
2,15.375,0.01,0.1245,0.12465,2.000
2,15.500,0.02,0.2495,0.24960,2.000
2,15.625,0.01,0.3747,0.37485,2.000
2,15.750,0.01,0.4997,0.49980,2.000
2,15.875,0.01,0.6245,0.62460,2.000
2,16.000,0.02,0.7497,0.74980,2.000
2,16.125,0.02,0.8746,0.87470,2.000
2,16.250,0.02,0.9996,0.99970,2.000
2,16.375,0.02,1.1246,1.12470,2.000
2,16.500,0.02,1.2497,1.24980,2.000
2,16.625,0.01,1.3747,1.37480,2.000
2,16.750,0.01,1.4999,1.50000,2.000
2,16.875,0.01,1.6248,1.62495,2.000
2,17.000,0.01,1.7498,1.74990,2.000
2,17.125,0.02,1.8747,1.87480,2.000
2,17.250,0.01,1.9997,1.99980,2.000
2,17.375,0.01,2.1247,2.12480,2.000
2,17.500,0.01,2.2498,2.24990,2.000
2,17.625,0.03,2.3749,2.37495,2.000
2,17.750,0.06,2.4998,2.49990,2.000
2,17.875,0.12,2.6247,2.62480,2.000
2,18.000,0.20,2.7498,2.74990,2.000
2,18.125,0.35,2.8748,2.87490,2.000
2,18.250,0.58,2.9998,2.99990,2.000
2,18.375,0.89,3.1247,3.12480,2.000
2,18.500,1.30,3.2498,3.24990,2.000
2,18.625,1.80,3.3748,3.37485,2.000
2,18.750,2.42,3.4998,3.49990,2.000
2,18.875,3.15,3.6249,3.62500,2.000
2,19.000,4.00,3.7500,3.75010,2.000
2,19.125,4.96,3.8749,3.87500,2.000
2,19.250,6.05,3.9998,3.99990,2.000
2,19.375,7.25,4.1248,4.12485,2.000
2,19.500,8.57,4.2496,4.24970,2.000
2,19.625,10.01,4.3748,4.37485,2.000
2,19.750,11.58,4.4998,4.49990,2.000
2,19.875,13.63,4.6249,4.62500,2.000
2,20.000,15.85,4.7499,4.75000,2.000
2,20.125,18.42,4.8748,4.87490,2.000
2,20.250,21.24,4.9997,4.99980,2.000
2,20.375,24.34,5.1248,5.12485,2.000
2,20.500,27.77,5.2498,5.24990,2.000
2,20.625,31.56,5.3748,5.37490,2.000
2,20.750,35.79,5.4998,5.49990,2.000
2,20.875,40.54,5.6250,5.62510,2.000
2,21.000,45.99,5.7500,5.75010,2.000
2,21.188,52.28,5.8809,5.88095,2.000
2,21.312,39.65,5.7580,5.75812,2.000
2,21.438,31.33,5.6333,5.63338,2.000
2,21.562,25.25,5.5082,5.50825,2.000
2,21.688,20.58,5.3832,5.38330,2.000
2,21.812,16.84,5.2582,5.25832,2.000
2,21.938,13.89,5.1330,5.13305,2.000
2,22.062,11.52,5.0079,5.00802,2.000
2,22.188,9.70,4.8830,4.88308,2.000
2,22.312,8.22,4.7580,4.75805,2.000
2,22.438,6.94,4.6331,4.63322,2.000
2,22.562,5.85,4.5080,4.50812,2.000
2,22.688,4.93,4.3831,4.38318,2.000
2,22.812,4.13,4.2580,4.25807,2.000
2,22.938,3.48,4.1329,4.13303,2.000
2,23.062,2.91,4.0079,4.00800,2.000
2,23.188,2.41,3.8829,3.88300,2.000
2,23.312,1.95,3.7579,3.75800,2.000
2,23.438,1.52,3.6330,3.63308,2.000
2,23.562,1.18,3.5080,3.50807,2.000
2,23.688,0.87,3.3830,3.38310,2.000
2,23.812,0.61,3.2580,3.25815,2.000
2,23.938,0.40,3.1328,3.13290,2.000
2,24.062,0.24,3.0079,3.00803,2.000
2,24.188,0.14,2.8828,2.88293,2.000
2,24.312,0.07,2.7578,2.75785,2.000
2,24.438,0.03,2.6328,2.63285,2.000
2,24.562,0.01,2.5079,2.50795,2.000
2,24.688,0.02,2.3829,2.38300,2.000
2,24.812,0.00,2.2579,2.25798,2.000
2,24.938,0.01,2.1329,2.13300,2.000
2,25.062,0.01,2.0078,2.00788,2.000
2,25.188,0.01,1.8827,1.88283,2.000
2,25.312,0.01,1.7578,1.75793,2.000
2,25.438,0.01,1.6328,1.63288,2.000
2,25.562,0.01,1.5079,1.50803,2.000
2,25.688,0.01,1.3829,1.38298,2.000
2,25.812,0.02,1.2578,1.25790,2.000
2,25.938,0.01,1.1328,1.13290,2.000
2,26.062,0.01,1.0078,1.00785,2.000
2,26.188,0.02,0.8828,0.88285,2.000
2,26.312,0.01,0.7577,0.75783,2.000
2,26.438,0.01,0.6326,0.63270,2.000
2,26.562,0.01,0.5077,0.50778,2.000
2,26.688,0.01,0.3828,0.38288,2.000
2,26.812,0.02,0.2577,0.25780,2.000
2,26.938,0.01,0.1327,0.13280,2.000
2,27.062,0.01,0.0077,0.00778,2.000
2,27.250,0.01,0.0001,0.00020,2.000
2,27.375,0.02,-0.0004,-0.00030,2.000
2,27.500,0.02,-0.0003,-0.00020,2.000
2,27.625,0.01,-0.0003,-0.00020,2.000
2,27.750,0.01,-0.0003,-0.00020,2.000
2,27.875,0.01,-0.0003,-0.00020,2.000
2,28.000,0.01,-0.0003,-0.00020,2.000
2,28.125,0.01,-0.0003,-0.00020,2.000
2,28.250,0.01,-0.0003,-0.00020,2.000
2,28.375,0.01,-0.0003,-0.00020,2.000
2,28.500,0.02,-0.0003,-0.00020,2.000
2,28.625,0.02,-0.0003,-0.00020,2.000
2,28.750,0.00,-0.0003,-0.00020,2.000
2,28.875,0.01,-0.0003,-0.00020,2.000
2,29.000,0.02,-0.0003,-0.00020,2.000
2,29.125,0.01,-0.0003,-0.00020,2.000
2,29.250,0.02,-0.0003,-0.00020,2.000
2,29.375,0.01,-0.0003,-0.00020,2.000
2,29.500,0.01,-0.0003,-0.00020,2.000
2,29.625,0.01,-0.0003,-0.00020,2.000
2,29.750,0.02,-0.0003,-0.00020,2.000
2,29.875,0.02,-0.0002,-0.00010,2.000
2,30.000,0.01,-0.0002,-0.00010,2.000
2,30.125,0.01,-0.0002,-0.00010,2.000
3,30.500,0.01,0.1494,0.14950,3.000
3,30.625,0.02,0.2746,0.27465,3.000
3,30.750,0.00,0.3996,0.39970,3.000
3,30.875,0.00,0.5246,0.52470,3.000
3,31.000,0.01,0.6495,0.64960,3.000
3,31.125,0.00,0.7748,0.77490,3.000
3,31.250,0.00,0.8999,0.90000,3.000
3,31.375,0.01,1.0246,1.02475,3.000
3,31.500,0.01,1.1497,1.14980,3.000
3,31.625,0.00,1.2746,1.27470,3.000
3,31.750,0.00,1.3996,1.39970,3.000
3,31.875,0.01,1.5248,1.52485,3.000
3,32.000,0.00,1.6498,1.64990,3.000
3,32.125,0.01,1.7748,1.77495,3.000
3,32.250,0.00,1.8997,1.89980,3.000
3,32.375,0.01,2.0248,2.02490,3.000
3,32.500,0.00,2.1498,2.14990,3.000
3,32.625,0.01,2.2748,2.27490,3.000
3,32.750,0.03,2.3997,2.39980,3.000
3,32.875,0.04,2.5247,2.52480,3.000
3,33.000,0.11,2.6497,2.64980,3.000
3,33.125,0.20,2.7748,2.77485,3.000
3,33.250,0.35,2.8999,2.90000,3.000
3,33.375,0.61,3.0248,3.02495,3.000
3,33.500,0.93,3.1498,3.14990,3.000
3,33.625,1.34,3.2748,3.27495,3.000
3,33.750,1.86,3.3997,3.39980,3.000
3,33.875,2.48,3.5248,3.52485,3.000
3,34.000,3.24,3.6497,3.64980,3.000
3,34.125,4.08,3.7748,3.77490,3.000
3,34.250,5.07,3.8998,3.89990,3.000
3,34.375,6.19,4.0249,4.02495,3.000
3,34.500,7.41,4.1499,4.15000,3.000
3,34.625,8.74,4.2748,4.27485,3.000
3,34.750,10.20,4.3997,4.39980,3.000
3,34.875,11.82,4.5248,4.52485,3.000
3,35.000,13.87,4.6497,4.64980,3.000
3,35.125,16.15,4.7748,4.77490,3.000
3,35.250,18.74,4.8999,4.90000,3.000
3,35.375,21.60,5.0248,5.02490,3.000
3,35.500,24.75,5.1499,5.15000,3.000
3,35.625,28.23,5.2749,5.27500,3.000
3,35.750,32.08,5.3998,5.39990,3.000
3,35.875,36.37,5.5248,5.52490,3.000
3,36.000,41.22,5.6499,5.65000,3.000
3,36.125,46.79,5.7748,5.77490,3.000
3,36.312,48.05,5.8381,5.83815,3.000
3,36.438,36.58,5.7132,5.71327,3.000
3,36.562,29.17,5.5882,5.58830,3.000
3,36.688,23.59,5.4632,5.46327,3.000
3,36.812,19.25,5.3382,5.33828,3.000
3,36.938,15.77,5.2130,5.21312,3.000
3,37.062,13.05,5.0879,5.08803,3.000
3,37.188,10.83,4.9630,4.96315,3.000
3,37.312,9.17,4.8380,4.83813,3.000
3,37.438,7.75,4.7131,4.71317,3.000
3,37.562,6.53,4.5882,4.58828,3.000
3,37.688,5.49,4.4630,4.46310,3.000
3,37.812,4.61,4.3380,4.33813,3.000
3,37.938,3.86,4.2129,4.21297,3.000
3,38.062,3.24,4.0879,4.08800,3.000
3,38.188,2.70,3.9629,3.96300,3.000
3,38.312,2.21,3.8379,3.83795,3.000
3,38.438,1.77,3.7129,3.71302,3.000
3,38.562,1.37,3.5879,3.58803,3.000
3,38.688,1.03,3.4629,3.46302,3.000
3,38.812,0.75,3.3380,3.33810,3.000
3,38.938,0.51,3.2128,3.21295,3.000
3,39.062,0.32,3.0879,3.08795,3.000
3,39.188,0.18,2.9627,2.96285,3.000
3,39.312,0.09,2.8378,2.83793,3.000
3,39.438,0.04,2.7128,2.71295,3.000
3,39.562,0.02,2.5878,2.58790,3.000
3,39.688,0.02,2.4630,2.46307,3.000
3,39.812,0.01,2.3378,2.33793,3.000
3,39.938,0.00,2.2128,2.21292,3.000
3,40.062,0.01,2.0878,2.08788,3.000
3,40.188,0.00,1.9627,1.96282,3.000
3,40.312,0.01,1.8378,1.83790,3.000
3,40.438,0.01,1.7128,1.71287,3.000
3,40.562,0.00,1.5879,1.58803,3.000
3,40.688,0.01,1.4629,1.46300,3.000
3,40.812,0.00,1.3378,1.33788,3.000
3,40.938,0.00,1.2128,1.21292,3.000
3,41.062,0.00,1.0878,1.08785,3.000
3,41.188,0.00,0.9627,0.96277,3.000
3,41.312,0.00,0.8378,0.83785,3.000
3,41.438,0.01,0.7127,0.71277,3.000
3,41.562,0.01,0.5876,0.58773,3.000
3,41.688,0.01,0.4629,0.46297,3.000
3,41.812,0.01,0.3379,0.33798,3.000
3,41.938,0.00,0.2127,0.21280,3.000
3,42.062,0.01,0.0877,0.08778,3.000
3,42.250,0.00,-0.0461,-0.04600,3.000
3,42.375,0.01,-0.0004,-0.00030,3.000
3,42.500,0.00,-0.0003,-0.00020,3.000
3,42.625,0.01,-0.0003,-0.00020,3.000
3,42.750,0.00,-0.0003,-0.00020,3.000
3,42.875,0.00,-0.0003,-0.00020,3.000
3,43.000,0.01,-0.0003,-0.00020,3.000
3,43.125,0.00,-0.0003,-0.00020,3.000
3,43.250,0.00,-0.0003,-0.00020,3.000
3,43.375,0.00,-0.0003,-0.00020,3.000
3,43.500,0.00,-0.0003,-0.00020,3.000
3,43.625,0.00,-0.0003,-0.00020,3.000
3,43.750,0.00,-0.0003,-0.00020,3.000
3,43.875,0.01,-0.0003,-0.00020,3.000
3,44.000,0.00,-0.0003,-0.00020,3.000
3,44.125,0.00,-0.0003,-0.00020,3.000
3,44.250,0.01,-0.0003,-0.00020,3.000
3,44.375,0.01,-0.0003,-0.00020,3.000
3,44.500,-0.01,-0.0003,-0.00020,3.000
3,44.625,0.00,-0.0003,-0.00020,3.000
3,44.750,0.00,-0.0003,-0.00020,3.000
3,44.875,0.01,-0.0003,-0.00020,3.000
3,45.000,0.00,-0.0002,-0.00010,3.000
3,45.125,0.00,-0.0002,-0.00010,3.000
3,45.250,0.00,-0.0002,-0.00010,3.000
4,45.562,-0.02,0.1210,0.12107,4.000
4,45.688,-0.02,0.2460,0.24610,4.000
4,45.812,-0.01,0.3711,0.37125,4.000
4,45.938,-0.02,0.4963,0.49635,4.000
4,46.062,-0.02,0.6210,0.62110,4.000
4,46.188,-0.01,0.7462,0.74625,4.000
4,46.312,-0.01,0.8712,0.87130,4.000
4,46.438,-0.02,0.9962,0.99628,4.000
4,46.562,-0.02,1.1211,1.12122,4.000
4,46.688,-0.02,1.2461,1.24620,4.000
4,46.812,-0.01,1.3712,1.37132,4.000
4,46.938,-0.01,1.4963,1.49638,4.000
4,47.062,-0.02,1.6213,1.62140,4.000
4,47.188,-0.01,1.7464,1.74645,4.000
4,47.312,-0.01,1.8713,1.87142,4.000
4,47.438,-0.01,1.9961,1.99623,4.000
4,47.562,-0.01,2.1211,2.12125,4.000
4,47.688,-0.01,2.2463,2.24635,4.000
4,47.812,0.00,2.3713,2.37140,4.000
4,47.938,0.02,2.4963,2.49640,4.000
4,48.062,0.06,2.6212,2.62130,4.000
4,48.188,0.14,2.7464,2.74645,4.000
4,48.312,0.29,2.8713,2.87145,4.000
4,48.438,0.50,2.9963,2.99640,4.000
4,48.562,0.80,3.1212,3.12127,4.000
4,48.688,1.20,3.2463,3.24640,4.000
4,48.812,1.69,3.3713,3.37142,4.000
4,48.938,2.27,3.4963,3.49638,4.000
4,49.062,2.98,3.6214,3.62150,4.000
4,49.188,3.82,3.7464,3.74650,4.000
4,49.312,4.76,3.8714,3.87155,4.000
4,49.438,5.85,3.9963,3.99643,4.000
4,49.562,7.04,4.1212,4.12130,4.000
4,49.688,8.36,4.2462,4.24625,4.000
4,49.812,9.79,4.3712,4.37135,4.000
4,49.938,11.34,4.4963,4.49638,4.000
4,50.062,13.30,4.6213,4.62142,4.000
4,50.188,15.50,4.7464,4.74648,4.000
4,50.312,18.01,4.8713,4.87142,4.000
4,50.438,20.78,4.9963,4.99643,4.000
4,50.562,23.88,5.1213,5.12140,4.000
4,50.688,27.25,5.2463,5.24640,4.000
4,50.812,31.01,5.3713,5.37140,4.000
4,50.938,35.13,5.4964,5.49645,4.000
4,51.062,39.82,5.6214,5.62152,4.000
4,51.188,45.18,5.7464,5.74648,4.000
4,51.375,52.08,5.8814,5.88150,4.000
4,51.500,39.61,5.7596,5.75970,4.000
4,51.625,31.28,5.6348,5.63485,4.000
4,51.750,25.21,5.5096,5.50970,4.000
4,51.875,20.54,5.3847,5.38475,4.000
4,52.000,16.81,5.2597,5.25980,4.000
4,52.125,13.86,5.1345,5.13460,4.000
4,52.250,11.48,5.0095,5.00960,4.000
4,52.375,9.66,4.8845,4.88460,4.000
4,52.500,8.18,4.7596,4.75970,4.000
4,52.625,6.90,4.6346,4.63470,4.000
4,52.750,5.80,4.5096,4.50970,4.000
4,52.875,4.86,4.3845,4.38460,4.000
4,53.000,4.06,4.2595,4.25960,4.000
4,53.125,3.40,4.1344,4.13450,4.000
4,53.250,2.84,4.0094,4.00950,4.000
4,53.375,2.34,3.8844,3.88450,4.000
4,53.500,1.88,3.7594,3.75950,4.000
4,53.625,1.47,3.6345,3.63455,4.000
4,53.750,1.11,3.5095,3.50960,4.000
4,53.875,0.82,3.3846,3.38465,4.000
4,54.000,0.56,3.2595,3.25960,4.000
4,54.125,0.35,3.1344,3.13450,4.000
4,54.250,0.20,3.0093,3.00940,4.000
4,54.375,0.10,2.8843,2.88435,4.000
4,54.500,0.04,2.7593,2.75940,4.000
4,54.625,0.00,2.6343,2.63435,4.000
4,54.750,-0.01,2.5094,2.50950,4.000
4,54.875,-0.01,2.3845,2.38460,4.000
4,55.000,-0.02,2.2594,2.25950,4.000
4,55.125,-0.01,2.1344,2.13450,4.000
4,55.250,-0.01,2.0094,2.00950,4.000
4,55.375,-0.02,1.8843,1.88435,4.000
4,55.500,-0.02,1.7593,1.75940,4.000
4,55.625,-0.02,1.6343,1.63440,4.000
4,55.750,-0.01,1.5094,1.50950,4.000
4,55.875,-0.01,1.3844,1.38445,4.000
4,56.000,-0.01,1.2592,1.25930,4.000
4,56.125,-0.01,1.1343,1.13440,4.000
4,56.250,-0.01,1.0093,1.00940,4.000
4,56.375,-0.02,0.8843,0.88435,4.000
4,56.500,-0.01,0.7593,0.75940,4.000
4,56.625,-0.01,0.6341,0.63420,4.000
4,56.750,-0.02,0.5093,0.50940,4.000
4,56.875,-0.02,0.3843,0.38440,4.000
4,57.000,-0.02,0.2592,0.25930,4.000
4,57.125,-0.01,0.1342,0.13430,4.000
4,57.250,-0.01,0.0093,0.00940,4.000
4,57.438,-0.01,-0.0003,-0.00020,4.000
4,57.562,-0.01,-0.0003,-0.00020,4.000
4,57.688,-0.02,-0.0003,-0.00020,4.000
4,57.812,-0.01,-0.0003,-0.00020,4.000
4,57.938,-0.02,-0.0003,-0.00020,4.000
4,58.062,-0.01,-0.0003,-0.00020,4.000
4,58.188,-0.01,-0.0003,-0.00020,4.000
4,58.312,-0.01,-0.0003,-0.00020,4.000
4,58.438,-0.01,-0.0003,-0.00020,4.000
4,58.562,-0.01,-0.0003,-0.00020,4.000
4,58.688,-0.02,-0.0003,-0.00020,4.000
4,58.812,-0.01,-0.0003,-0.00020,4.000
4,58.938,-0.02,-0.0003,-0.00020,4.000
4,59.062,0.00,-0.0003,-0.00020,4.000
4,59.188,-0.02,-0.0003,-0.00020,4.000
4,59.312,-0.01,-0.0003,-0.00020,4.000
4,59.438,-0.01,-0.0003,-0.00020,4.000
4,59.562,-0.01,-0.0003,-0.00020,4.000
4,59.688,-0.01,-0.0003,-0.00020,4.000
4,59.812,-0.02,-0.0003,-0.00020,4.000
4,59.938,-0.01,-0.0003,-0.00020,4.000
4,60.062,-0.01,-0.0003,-0.00020,4.000
4,60.188,-0.01,-0.0002,-0.00010,4.000
4,60.312,-0.02,-0.0002,-0.00010,4.000
5,60.688,0.01,0.1461,0.14618,5.000
5,60.812,0.00,0.2710,0.27112,5.000
5,60.938,0.00,0.3962,0.39628,5.000
5,61.062,0.00,0.5210,0.52115,5.000
5,61.188,0.00,0.6460,0.64608,5.000
5,61.312,0.00,0.7712,0.77127,5.000
5,61.438,0.00,0.8963,0.89638,5.000
5,61.562,0.01,1.0212,1.02135,5.000
5,61.688,0.00,1.1463,1.14637,5.000
5,61.812,0.00,1.2711,1.27125,5.000
5,61.938,0.01,1.3961,1.39622,5.000
5,62.062,0.00,1.5211,1.52122,5.000
5,62.188,0.01,1.6462,1.64630,5.000
5,62.312,0.00,1.7713,1.77140,5.000
5,62.438,0.00,1.8962,1.89635,5.000
5,62.562,0.01,2.0213,2.02140,5.000
5,62.688,0.00,2.1463,2.14640,5.000
5,62.812,0.01,2.2713,2.27142,5.000
5,62.938,0.02,2.3962,2.39635,5.000
5,63.062,0.05,2.5211,2.52125,5.000
5,63.188,0.09,2.6461,2.64622,5.000
5,63.312,0.18,2.7712,2.77132,5.000
5,63.438,0.32,2.8962,2.89632,5.000
5,63.562,0.56,3.0213,3.02142,5.000
5,63.688,0.87,3.1463,3.14645,5.000
5,63.812,1.28,3.2714,3.27147,5.000
5,63.938,1.78,3.3963,3.39637,5.000
5,64.062,2.39,3.5213,3.52140,5.000
5,64.188,3.12,3.6463,3.64640,5.000
5,64.312,3.97,3.7713,3.77140,5.000
5,64.438,4.95,3.8964,3.89648,5.000
5,64.562,6.03,4.0213,4.02142,5.000
5,64.688,7.24,4.1464,4.14652,5.000
5,64.812,8.57,4.2714,4.27147,5.000
5,64.938,10.02,4.3964,4.39648,5.000
5,65.062,11.62,4.5213,4.52145,5.000
5,65.188,13.64,4.6462,4.64632,5.000
5,65.312,15.86,4.7712,4.77132,5.000
5,65.438,18.44,4.8963,4.89638,5.000
5,65.562,21.27,5.0212,5.02135,5.000
5,65.688,24.38,5.1464,5.14645,5.000
5,65.812,27.82,5.2714,5.27152,5.000
5,65.938,31.62,5.3964,5.39650,5.000
5,66.062,35.82,5.5213,5.52140,5.000
5,66.188,40.59,5.6464,5.64650,5.000
5,66.312,46.10,5.7713,5.77140,5.000
5,66.500,51.19,5.8797,5.87980,5.000
5,66.625,38.62,5.7547,5.75475,5.000
5,66.750,30.62,5.6298,5.62990,5.000
5,66.875,24.71,5.5047,5.50480,5.000
5,67.000,20.14,5.3796,5.37970,5.000
5,67.125,16.49,5.2546,5.25465,5.000
5,67.250,13.61,5.1294,5.12950,5.000
5,67.375,11.28,5.0045,5.00460,5.000
5,67.500,9.52,4.8796,4.87970,5.000
5,67.625,8.06,4.7546,4.75465,5.000
5,67.750,6.80,4.6296,4.62970,5.000
5,67.875,5.70,4.5046,4.50470,5.000
5,68.000,4.78,4.3794,4.37950,5.000
5,68.125,4.00,4.2544,4.25450,5.000
5,68.250,3.35,4.1294,4.12950,5.000
5,68.375,2.80,4.0044,4.00450,5.000
5,68.500,2.29,3.8795,3.87960,5.000
5,68.625,1.85,3.7545,3.75460,5.000
5,68.750,1.44,3.6295,3.62960,5.000
5,68.875,1.10,3.5044,3.50455,5.000
5,69.000,0.81,3.3795,3.37960,5.000
5,69.125,0.55,3.2544,3.25450,5.000
5,69.250,0.35,3.1293,3.12940,5.000
5,69.375,0.21,3.0044,3.00450,5.000
5,69.500,0.10,2.8793,2.87940,5.000
5,69.625,0.05,2.7544,2.75450,5.000
5,69.750,0.02,2.6293,2.62940,5.000
5,69.875,0.01,2.5044,2.50450,5.000
5,70.000,0.01,2.3795,2.37960,5.000
5,70.125,0.00,2.2544,2.25450,5.000
5,70.250,-0.01,2.1293,2.12940,5.000
5,70.375,0.00,2.0042,2.00435,5.000
5,70.500,0.01,1.8792,1.87930,5.000
5,70.625,0.01,1.7543,1.75440,5.000
5,70.750,0.00,1.6294,1.62950,5.000
5,70.875,0.00,1.5044,1.50455,5.000
5,71.000,0.00,1.3794,1.37950,5.000
5,71.125,0.00,1.2543,1.25440,5.000
5,71.250,-0.01,1.1292,1.12930,5.000
5,71.375,0.01,1.0042,1.00430,5.000
5,71.500,0.00,0.8792,0.87930,5.000
5,71.625,0.00,0.7544,0.75445,5.000
5,71.750,0.00,0.6291,0.62920,5.000
5,71.875,0.00,0.5043,0.50440,5.000
5,72.000,-0.01,0.3794,0.37950,5.000
5,72.125,0.00,0.2542,0.25435,5.000
5,72.250,0.01,0.1292,0.12930,5.000
5,72.375,0.00,0.0042,0.00425,5.000
5,72.562,0.01,-0.0003,-0.00020,5.000
5,72.688,0.01,-0.0004,-0.00030,5.000
5,72.812,0.00,-0.0003,-0.00020,5.000
5,72.938,0.00,-0.0003,-0.00020,5.000
5,73.062,0.01,-0.0003,-0.00020,5.000
5,73.188,0.00,-0.0003,-0.00020,5.000
5,73.312,0.01,-0.0003,-0.00020,5.000
5,73.438,0.01,-0.0003,-0.00020,5.000
5,73.562,0.00,-0.0003,-0.00020,5.000
5,73.688,-0.01,-0.0003,-0.00020,5.000
5,73.812,0.01,-0.0003,-0.00020,5.000
5,73.938,0.00,-0.0003,-0.00020,5.000
5,74.062,0.01,-0.0003,-0.00020,5.000
5,74.188,0.00,-0.0003,-0.00020,5.000
5,74.312,0.00,-0.0003,-0.00020,5.000
5,74.438,0.00,-0.0003,-0.00020,5.000
5,74.562,0.00,-0.0003,-0.00020,5.000
5,74.688,0.00,-0.0003,-0.00020,5.000
5,74.812,0.00,-0.0003,-0.00020,5.000
5,74.938,0.00,-0.0003,-0.00020,5.000
5,75.062,0.00,-0.0003,-0.00020,5.000
5,75.188,0.00,-0.0002,-0.00010,5.000
5,75.312,0.00,-0.0002,-0.00010,5.000
5,75.438,0.01,-0.0002,-0.00010,5.000
6,75.750,0.00,0.0696,0.06970,6.000
6,75.875,-0.02,0.1944,0.19455,6.000
6,76.000,-0.04,0.3195,0.31960,6.000
6,76.125,-0.01,0.4446,0.44475,6.000
6,76.250,-0.01,0.5696,0.56970,6.000
6,76.375,-0.01,0.6946,0.69470,6.000
6,76.500,-0.01,0.8198,0.81990,6.000
6,76.625,-0.01,0.9448,0.94485,6.000
6,76.750,-0.01,1.0696,1.06970,6.000
6,76.875,-0.01,1.1946,1.19475,6.000
6,77.000,-0.01,1.3195,1.31960,6.000
6,77.125,-0.01,1.4446,1.44475,6.000
6,77.250,-0.01,1.5697,1.56980,6.000
6,77.375,-0.01,1.6948,1.69485,6.000
6,77.500,-0.02,1.8198,1.81990,6.000
6,77.625,-0.02,1.9448,1.94485,6.000
6,77.750,-0.01,2.0698,2.06990,6.000
6,77.875,-0.01,2.1948,2.19485,6.000
6,78.000,-0.01,2.3196,2.31970,6.000
6,78.125,0.01,2.4447,2.44480,6.000
6,78.250,0.04,2.5696,2.56970,6.000
6,78.375,0.10,2.6947,2.69480,6.000
6,78.500,0.21,2.8198,2.81990,6.000
6,78.625,0.38,2.9448,2.94490,6.000
6,78.750,0.64,3.0698,3.06990,6.000
6,78.875,0.99,3.1948,3.19490,6.000
6,79.000,1.43,3.3199,3.32000,6.000
6,79.125,1.97,3.4447,3.44480,6.000
6,79.250,2.63,3.5697,3.56980,6.000
6,79.375,3.39,3.6948,3.69490,6.000
6,79.500,4.27,3.8198,3.81990,6.000
6,79.625,5.30,3.9450,3.94505,6.000
6,79.750,6.44,4.0699,4.07000,6.000
6,79.875,7.69,4.1949,4.19495,6.000
6,80.000,9.06,4.3198,4.31990,6.000
6,80.125,10.56,4.4448,4.44485,6.000
6,80.250,12.25,4.5697,4.56980,6.000
6,80.375,14.38,4.6948,4.69490,6.000
6,80.500,16.72,4.8198,4.81990,6.000
6,80.625,19.38,4.9449,4.94495,6.000
6,80.750,22.31,5.0698,5.06990,6.000
6,80.875,25.53,5.1949,5.19500,6.000
6,81.000,29.10,5.3199,5.32000,6.000
6,81.125,33.02,5.4448,5.44490,6.000
6,81.250,37.39,5.5697,5.56980,6.000
6,81.375,42.42,5.6949,5.69495,6.000
6,81.500,48.24,5.8198,5.81990,6.000
6,81.750,40.91,5.7905,5.79060,6.000
6,81.875,32.18,5.6657,5.66580,6.000
6,82.000,25.92,5.5406,5.54070,6.000
6,82.125,21.07,5.4156,5.41570,6.000
6,82.250,17.23,5.2905,5.29060,6.000
6,82.375,14.20,5.1656,5.16565,6.000
6,82.500,11.75,5.0405,5.04060,6.000
6,82.625,9.87,4.9155,4.91565,6.000
6,82.750,8.36,4.7906,4.79070,6.000
6,82.875,7.05,4.6655,4.66565,6.000
6,83.000,5.94,4.5406,4.54070,6.000
6,83.125,4.97,4.4154,4.41555,6.000
6,83.250,4.16,4.2903,4.29040,6.000
6,83.375,3.48,4.1654,4.16550,6.000
6,83.500,2.92,4.0405,4.04060,6.000
6,83.625,2.41,3.9156,3.91565,6.000
6,83.750,1.94,3.7906,3.79070,6.000
6,83.875,1.52,3.6655,3.66560,6.000
6,84.000,1.17,3.5404,3.54050,6.000
6,84.125,0.86,3.4154,3.41545,6.000
6,84.250,0.58,3.2904,3.29050,6.000
6,84.375,0.38,3.1653,3.16540,6.000
6,84.500,0.22,3.0404,3.04050,6.000
6,84.625,0.11,2.9154,2.91550,6.000
6,84.750,0.04,2.7904,2.79050,6.000
6,84.875,0.01,2.6654,2.66550,6.000
6,85.000,0.00,2.5403,2.54040,6.000
6,85.125,0.00,2.4154,2.41550,6.000
6,85.250,-0.01,2.2903,2.29040,6.000
6,85.375,-0.01,2.1653,2.16535,6.000
6,85.500,0.00,2.0402,2.04030,6.000
6,85.625,-0.01,1.9152,1.91530,6.000
6,85.750,-0.01,1.7905,1.79060,6.000
6,85.875,-0.02,1.6653,1.66540,6.000
6,86.000,-0.01,1.5404,1.54050,6.000
6,86.125,-0.01,1.4154,1.41550,6.000
6,86.250,0.00,1.2902,1.29030,6.000
6,86.375,-0.01,1.1652,1.16525,6.000
6,86.500,-0.01,1.0401,1.04020,6.000
6,86.625,-0.01,0.9152,0.91525,6.000
6,86.750,-0.02,0.7904,0.79050,6.000
6,86.875,0.00,0.6652,0.66530,6.000
6,87.000,-0.01,0.5402,0.54030,6.000
6,87.125,-0.01,0.4154,0.41545,6.000
6,87.250,-0.01,0.2903,0.29040,6.000
6,87.375,-0.01,0.1651,0.16520,6.000
6,87.500,-0.01,0.0400,0.04010,6.000
6,87.688,-0.01,-0.0119,-0.01183,6.000
6,87.812,-0.01,-0.0004,-0.00030,6.000
6,87.938,-0.02,-0.0003,-0.00020,6.000
6,88.062,0.00,-0.0003,-0.00020,6.000
6,88.188,-0.01,-0.0003,-0.00020,6.000
6,88.312,-0.02,-0.0003,-0.00020,6.000
6,88.438,-0.02,-0.0003,-0.00020,6.000
6,88.562,0.00,-0.0003,-0.00020,6.000
6,88.688,-0.01,-0.0003,-0.00020,6.000
6,88.812,-0.01,-0.0003,-0.00020,6.000
6,88.938,-0.01,-0.0003,-0.00020,6.000
6,89.062,0.00,-0.0003,-0.00020,6.000
6,89.188,-0.01,-0.0003,-0.00020,6.000
6,89.312,-0.01,-0.0003,-0.00020,6.000
6,89.438,0.00,-0.0003,-0.00020,6.000
6,89.562,-0.01,-0.0003,-0.00020,6.000
6,89.688,-0.01,-0.0003,-0.00020,6.000
6,89.812,-0.01,-0.0003,-0.00020,6.000
6,89.938,-0.01,-0.0003,-0.00020,6.000
6,90.062,-0.01,-0.0003,-0.00020,6.000
6,90.188,-0.01,-0.0003,-0.00020,6.000
6,90.312,-0.01,-0.0003,-0.00020,6.000
6,90.438,-0.02,-0.0002,-0.00010,6.000
6,90.562,-0.01,-0.0002,-0.00010,6.000
7,90.875,0.00,0.0536,0.05365,7.000
7,91.000,0.00,0.1786,0.17870,7.000
7,91.125,-0.01,0.3037,0.30375,7.000
7,91.250,0.00,0.4287,0.42880,7.000
7,91.375,0.00,0.5536,0.55370,7.000
7,91.500,0.00,0.6784,0.67850,7.000
7,91.625,0.00,0.8037,0.80375,7.000
7,91.750,0.01,0.9286,0.92870,7.000
7,91.875,0.00,1.0537,1.05380,7.000
7,92.000,0.00,1.1786,1.17870,7.000
7,92.125,0.00,1.3038,1.30385,7.000
7,92.250,0.00,1.4287,1.42880,7.000
7,92.375,0.00,1.5538,1.55390,7.000
7,92.500,-0.01,1.6786,1.67870,7.000
7,92.625,0.01,1.8038,1.80385,7.000
7,92.750,-0.01,1.9286,1.92870,7.000
7,92.875,0.00,2.0537,2.05380,7.000
7,93.000,0.01,2.1788,2.17890,7.000
7,93.125,0.00,2.3039,2.30395,7.000
7,93.250,0.02,2.4289,2.42900,7.000
7,93.375,0.05,2.5538,2.55385,7.000
7,93.500,0.10,2.6786,2.67870,7.000
7,93.625,0.19,2.8037,2.80380,7.000
7,93.750,0.36,2.9287,2.92880,7.000
7,93.875,0.59,3.0538,3.05385,7.000
7,94.000,0.94,3.1788,3.17890,7.000
7,94.125,1.35,3.3039,3.30400,7.000
7,94.250,1.88,3.4288,3.42890,7.000
7,94.375,2.52,3.5538,3.55395,7.000
7,94.500,3.27,3.6788,3.67890,7.000
7,94.625,4.14,3.8038,3.80385,7.000
7,94.750,5.15,3.9288,3.92890,7.000
7,94.875,6.27,4.0537,4.05380,7.000
7,95.000,7.52,4.1789,4.17900,7.000
7,95.125,8.88,4.3038,4.30390,7.000
7,95.250,10.35,4.4289,4.42900,7.000
7,95.375,11.98,4.5539,4.55395,7.000
7,95.500,14.07,4.6789,4.67900,7.000
7,95.625,16.37,4.8038,4.80390,7.000
7,95.750,19.00,4.9287,4.92880,7.000
7,95.875,21.88,5.0536,5.05375,7.000
7,96.000,25.05,5.1787,5.17880,7.000
7,96.125,28.56,5.3039,5.30395,7.000
7,96.250,32.44,5.4288,5.42890,7.000
7,96.375,36.74,5.5540,5.55405,7.000
7,96.500,41.66,5.6789,5.67900,7.000
7,96.625,47.36,5.8038,5.80390,7.000
7,96.812,48.81,5.8671,5.86718,7.000
7,96.938,37.10,5.7421,5.74222,7.000
7,97.062,29.55,5.6172,5.61728,7.000
7,97.188,23.89,5.4920,5.49212,7.000
7,97.312,19.47,5.3671,5.36715,7.000
7,97.438,15.94,5.2422,5.24227,7.000
7,97.562,13.18,5.1171,5.11720,7.000
7,97.688,10.93,4.9921,4.99220,7.000
7,97.812,9.26,4.8672,4.86725,7.000
7,97.938,7.83,4.7420,4.74212,7.000
7,98.062,6.60,4.6171,4.61715,7.000
7,98.188,5.54,4.4920,4.49208,7.000
7,98.312,4.64,4.3669,4.36695,7.000
7,98.438,3.87,4.2420,4.24205,7.000
7,98.562,3.24,4.1169,4.11703,7.000
7,98.688,2.69,3.9920,3.99210,7.000
7,98.812,2.21,3.8670,3.86710,7.000
7,98.938,1.76,3.7420,3.74205,7.000
7,99.062,1.37,3.6169,3.61698,7.000
7,99.188,1.04,3.4918,3.49188,7.000
7,99.312,0.75,3.3669,3.36700,7.000
7,99.438,0.51,3.2420,3.24205,7.000
7,99.562,0.32,3.1169,3.11695,7.000
7,99.688,0.19,2.9920,2.99205,7.000
7,99.812,0.09,2.8669,2.86698,7.000
7,99.938,0.03,2.7419,2.74200,7.000
7,100.062,0.01,2.6168,2.61690,7.000
7,100.188,0.00,2.4918,2.49192,7.000
7,100.312,0.00,2.3668,2.36690,7.000
7,100.438,0.01,2.2418,2.24188,7.000
7,100.562,0.00,2.1168,2.11693,7.000
7,100.688,0.00,1.9918,1.99190,7.000
7,100.812,-0.01,1.8669,1.86700,7.000
7,100.938,0.00,1.7419,1.74200,7.000
7,101.062,0.00,1.6169,1.61703,7.000
7,101.188,-0.01,1.4918,1.49192,7.000
7,101.312,-0.02,1.3667,1.36680,7.000
7,101.438,-0.01,1.2418,1.24188,7.000
7,101.562,0.00,1.1167,1.11683,7.000
7,101.688,0.01,0.9917,0.99180,7.000
7,101.812,0.00,0.8668,0.86693,7.000
7,101.938,0.00,0.7419,0.74200,7.000
7,102.062,0.00,0.6166,0.61673,7.000
7,102.188,0.00,0.4918,0.49185,7.000
7,102.312,0.00,0.3668,0.36693,7.000
7,102.438,0.00,0.2416,0.24165,7.000
7,102.562,0.00,0.1166,0.11668,7.000
7,102.688,0.00,-0.0083,-0.00818,7.000
7,102.875,0.00,-0.0004,-0.00030,7.000
7,103.000,0.00,-0.0004,-0.00030,7.000
7,103.125,0.00,-0.0004,-0.00030,7.000
7,103.250,0.00,-0.0004,-0.00030,7.000
7,103.375,0.00,-0.0004,-0.00030,7.000
7,103.500,0.00,-0.0004,-0.00030,7.000
7,103.625,0.00,-0.0004,-0.00030,7.000
7,103.750,0.00,-0.0003,-0.00020,7.000
7,103.875,0.00,-0.0003,-0.00020,7.000
7,104.000,0.00,-0.0003,-0.00020,7.000
7,104.125,0.00,-0.0003,-0.00020,7.000
7,104.250,0.00,-0.0003,-0.00020,7.000
7,104.375,0.00,-0.0003,-0.00020,7.000
7,104.500,0.01,-0.0003,-0.00020,7.000
7,104.625,0.00,-0.0003,-0.00020,7.000
7,104.750,0.00,-0.0003,-0.00020,7.000
7,104.875,0.00,-0.0003,-0.00020,7.000
7,105.000,-0.01,-0.0003,-0.00020,7.000
7,105.125,0.00,-0.0003,-0.00020,7.000
7,105.250,0.00,-0.0003,-0.00020,7.000
7,105.375,0.00,-0.0003,-0.00020,7.000
7,105.500,0.01,-0.0002,-0.00010,7.000
7,105.625,0.00,-0.0002,-0.00010,7.000
7,105.750,0.00,-0.0002,-0.00010,7.000
8,106.062,0.00,0.1209,0.12102,8.000
8,106.188,-0.01,0.2462,0.24625,8.000
8,106.312,0.00,0.3711,0.37125,8.000
8,106.438,0.00,0.4963,0.49638,8.000
8,106.562,0.00,0.6211,0.62120,8.000
8,106.688,0.00,0.7463,0.74638,8.000
8,106.812,-0.02,0.8713,0.87140,8.000
8,106.938,0.00,0.9962,0.99630,8.000
8,107.062,-0.01,1.1211,1.12125,8.000
8,107.188,-0.01,1.2461,1.24623,8.000
8,107.312,0.00,1.3711,1.37120,8.000
8,107.438,0.00,1.4962,1.49635,8.000
8,107.562,0.00,1.6212,1.62135,8.000
8,107.688,-0.01,1.7464,1.74652,8.000
8,107.812,-0.01,1.8713,1.87140,8.000
8,107.938,-0.01,1.9962,1.99633,8.000
8,108.062,0.00,2.1211,2.12122,8.000
8,108.188,-0.01,2.2462,2.24628,8.000
8,108.312,0.00,2.3712,2.37127,8.000
8,108.438,0.02,2.4963,2.49642,8.000
8,108.562,0.06,2.6212,2.62130,8.000
8,108.688,0.13,2.7463,2.74638,8.000
8,108.812,0.26,2.8713,2.87145,8.000
8,108.938,0.46,2.9963,2.99643,8.000
8,109.062,0.76,3.1212,3.12135,8.000
8,109.188,1.14,3.2463,3.24635,8.000
8,109.312,1.61,3.3712,3.37135,8.000
8,109.438,2.20,3.4963,3.49638,8.000
8,109.562,2.90,3.6213,3.62142,8.000
8,109.688,3.69,3.7465,3.74658,8.000
8,109.812,4.63,3.8714,3.87150,8.000
8,109.938,5.69,3.9964,3.99650,8.000
8,110.062,6.88,4.1214,4.12152,8.000
8,110.188,8.17,4.2463,4.24640,8.000
8,110.312,9.58,4.3713,4.37140,8.000
8,110.438,11.13,4.4963,4.49638,8.000
8,110.562,12.95,4.6213,4.62142,8.000
8,110.688,15.14,4.7463,4.74640,8.000
8,110.812,17.61,4.8713,4.87142,8.000
8,110.938,20.38,4.9963,4.99645,8.000
8,111.062,23.39,5.1213,5.12137,8.000
8,111.188,26.73,5.2462,5.24635,8.000
8,111.312,30.40,5.3713,5.37140,8.000
8,111.438,34.45,5.4962,5.49633,8.000
8,111.562,39.04,5.6214,5.62150,8.000
8,111.688,44.30,5.7464,5.74648,8.000
8,111.812,50.52,5.8714,5.87147,8.000
8,112.000,42.74,5.8195,5.81960,8.000
8,112.125,33.41,5.6946,5.69465,8.000
8,112.250,26.85,5.5695,5.56960,8.000
8,112.375,21.78,5.4446,5.44470,8.000
8,112.500,17.80,5.3198,5.31990,8.000
8,112.625,14.61,5.1946,5.19475,8.000
8,112.750,12.13,5.0696,5.06970,8.000
8,112.875,10.14,4.9446,4.94465,8.000
8,113.000,8.58,4.8196,4.81970,8.000
8,113.125,7.25,4.6945,4.69460,8.000
8,113.250,6.09,4.5695,4.56960,8.000
8,113.375,5.11,4.4444,4.44455,8.000
8,113.500,4.28,4.3195,4.31960,8.000
8,113.625,3.58,4.1945,4.19460,8.000
8,113.750,2.99,4.0696,4.06970,8.000
8,113.875,2.47,3.9446,3.94465,8.000
8,114.000,2.01,3.8194,3.81950,8.000
8,114.125,1.58,3.6944,3.69455,8.000
8,114.250,1.21,3.5693,3.56940,8.000
8,114.375,0.91,3.4443,3.44440,8.000
8,114.500,0.63,3.3196,3.31970,8.000
8,114.625,0.42,3.1944,3.19455,8.000
8,114.750,0.26,3.0695,3.06960,8.000
8,114.875,0.13,2.9444,2.94455,8.000
8,115.000,0.06,2.8195,2.81960,8.000
8,115.125,0.02,2.6944,2.69445,8.000
8,115.250,0.01,2.5692,2.56930,8.000
8,115.375,0.00,2.4443,2.44440,8.000
8,115.500,-0.01,2.3193,2.31940,8.000
8,115.625,-0.02,2.1944,2.19445,8.000
8,115.750,0.00,2.0693,2.06940,8.000
8,115.875,-0.01,1.9443,1.94440,8.000
8,116.000,-0.02,1.8194,1.81950,8.000
8,116.125,0.00,1.6944,1.69445,8.000
8,116.250,0.00,1.5693,1.56940,8.000
8,116.375,0.00,1.4444,1.44445,8.000
8,116.500,0.00,1.3192,1.31930,8.000
8,116.625,-0.01,1.1943,1.19440,8.000
8,116.750,-0.01,1.0693,1.06940,8.000
8,116.875,-0.01,0.9443,0.94440,8.000
8,117.000,0.00,0.8195,0.81960,8.000
8,117.125,-0.01,0.6942,0.69430,8.000
8,117.250,0.00,0.5691,0.56920,8.000
8,117.375,-0.01,0.4442,0.44430,8.000
8,117.500,0.00,0.3192,0.31930,8.000
8,117.625,0.00,0.1941,0.19420,8.000
8,117.750,-0.01,0.0692,0.06930,8.000
8,117.938,0.00,-0.0232,-0.02313,8.000
8,118.062,-0.01,-0.0003,-0.00020,8.000
8,118.188,-0.01,-0.0003,-0.00020,8.000
8,118.312,-0.02,-0.0003,-0.00020,8.000
8,118.438,-0.01,-0.0003,-0.00020,8.000
8,118.562,0.00,-0.0003,-0.00020,8.000
8,118.688,-0.01,-0.0003,-0.00020,8.000
8,118.812,-0.01,-0.0003,-0.00020,8.000
8,118.938,-0.01,-0.0003,-0.00020,8.000
8,119.062,-0.01,-0.0003,-0.00020,8.000
8,119.188,-0.01,-0.0003,-0.00020,8.000
8,119.312,-0.01,-0.0003,-0.00020,8.000
8,119.438,0.00,-0.0003,-0.00020,8.000
8,119.562,-0.01,-0.0003,-0.00020,8.000
8,119.688,-0.01,-0.0003,-0.00020,8.000
8,119.812,-0.01,-0.0003,-0.00020,8.000
8,119.938,0.00,-0.0003,-0.00020,8.000
8,120.062,0.00,-0.0003,-0.00020,8.000
8,120.188,0.00,-0.0003,-0.00020,8.000
8,120.312,-0.01,-0.0003,-0.00020,8.000
8,120.438,-0.01,-0.0003,-0.00020,8.000
8,120.562,0.00,-0.0002,-0.00010,8.000
8,120.688,-0.01,-0.0002,-0.00010,8.000
8,120.812,0.00,-0.0002,-0.00010,8.000
9,121.125,0.00,0.0435,0.04360,9.000
9,121.250,-0.03,0.1684,0.16850,9.000
9,121.375,-0.01,0.2937,0.29375,9.000
9,121.500,-0.01,0.4188,0.41890,9.000
9,121.625,-0.01,0.5436,0.54375,9.000
9,121.750,0.00,0.6686,0.66870,9.000
9,121.875,-0.01,0.7938,0.79390,9.000
9,122.000,0.00,0.9186,0.91870,9.000
9,122.125,0.00,1.0436,1.04375,9.000
9,122.250,0.00,1.1686,1.16870,9.000
9,122.375,0.00,1.2937,1.29380,9.000
9,122.500,0.00,1.4187,1.41880,9.000
9,122.625,0.00,1.5438,1.54390,9.000
9,122.750,0.00,1.6687,1.66880,9.000
9,122.875,0.00,1.7938,1.79390,9.000
9,123.000,0.00,1.9187,1.91880,9.000
9,123.125,0.00,2.0436,2.04375,9.000
9,123.250,0.00,2.1686,2.16870,9.000
9,123.375,0.00,2.2937,2.29380,9.000
9,123.500,0.01,2.4189,2.41900,9.000
9,123.625,0.03,2.5438,2.54390,9.000
9,123.750,0.08,2.6688,2.66890,9.000
9,123.875,0.17,2.7938,2.79390,9.000
9,124.000,0.33,2.9189,2.91900,9.000
9,124.125,0.56,3.0438,3.04390,9.000
9,124.250,0.88,3.1686,3.16870,9.000
9,124.375,1.28,3.2938,3.29390,9.000
9,124.500,1.80,3.4188,3.41890,9.000
9,124.625,2.42,3.5438,3.54395,9.000
9,124.750,3.15,3.6689,3.66900,9.000
9,124.875,4.01,3.7938,3.79395,9.000
9,125.000,4.99,3.9190,3.91910,9.000
9,125.125,6.11,4.0437,4.04385,9.000
9,125.250,7.34,4.1687,4.16880,9.000
9,125.375,8.69,4.2937,4.29385,9.000
9,125.500,10.15,4.4187,4.41880,9.000
9,125.625,11.75,4.5438,4.54390,9.000
9,125.750,13.76,4.6689,4.66900,9.000
9,125.875,16.01,4.7938,4.79395,9.000
9,126.000,18.61,4.9190,4.91910,9.000
9,126.125,21.46,5.0437,5.04385,9.000
9,126.250,24.60,5.1687,5.16880,9.000
9,126.375,28.06,5.2938,5.29390,9.000
9,126.500,31.86,5.4187,5.41880,9.000
9,126.625,36.09,5.5438,5.54390,9.000
9,126.750,40.91,5.6691,5.66920,9.000
9,126.875,46.49,5.7938,5.79395,9.000
9,127.062,51.40,5.8970,5.89713,9.000
9,127.188,38.71,5.7720,5.77210,9.000
9,127.312,30.66,5.6471,5.64718,9.000
9,127.438,24.74,5.5222,5.52228,9.000
9,127.562,20.13,5.3972,5.39725,9.000
9,127.688,16.48,5.2722,5.27235,9.000
9,127.812,13.62,5.1472,5.14725,9.000
9,127.938,11.28,5.0220,5.02212,9.000
9,128.062,9.52,4.8970,4.89710,9.000
9,128.188,8.06,4.7720,4.77210,9.000
9,128.312,6.78,4.6470,4.64715,9.000
9,128.438,5.69,4.5220,4.52210,9.000
9,128.562,4.76,4.3970,4.39713,9.000
9,128.688,3.98,4.2720,4.27210,9.000
9,128.812,3.33,4.1470,4.14708,9.000
9,128.938,2.78,4.0220,4.02205,9.000
9,129.062,2.28,3.8969,3.89700,9.000
9,129.188,1.82,3.7719,3.77200,9.000
9,129.312,1.42,3.6469,3.64700,9.000
9,129.438,1.08,3.5220,3.52205,9.000
9,129.562,0.79,3.3970,3.39710,9.000
9,129.688,0.54,3.2720,3.27213,9.000
9,129.812,0.33,3.1469,3.14700,9.000
9,129.938,0.19,3.0220,3.02208,9.000
9,130.062,0.08,2.8968,2.89690,9.000
9,130.188,0.03,2.7718,2.77193,9.000
9,130.312,0.02,2.6467,2.64680,9.000
9,130.438,0.00,2.5217,2.52180,9.000
9,130.562,0.00,2.3969,2.39700,9.000
9,130.688,-0.01,2.2719,2.27198,9.000
9,130.812,-0.01,2.1469,2.14698,9.000
9,130.938,-0.01,2.0218,2.02193,9.000
9,131.062,0.00,1.8968,1.89693,9.000
9,131.188,-0.01,1.7719,1.77195,9.000
9,131.312,-0.01,1.6467,1.64682,9.000
9,131.438,-0.01,1.5218,1.52188,9.000
9,131.562,-0.01,1.3968,1.39692,9.000
9,131.688,0.00,1.2717,1.27182,9.000
9,131.812,0.00,1.1468,1.14690,9.000
9,131.938,-0.01,1.0219,1.02198,9.000
9,132.062,-0.02,0.8968,0.89695,9.000
9,132.188,-0.01,0.7719,0.77200,9.000
9,132.312,0.00,0.6466,0.64668,9.000
9,132.438,0.00,0.5216,0.52175,9.000
9,132.562,-0.01,0.3967,0.39682,9.000
9,132.688,0.00,0.2718,0.27185,9.000
9,132.812,0.00,0.1468,0.14688,9.000
9,132.938,-0.01,0.0218,0.02188,9.000
9,133.125,0.00,-0.0003,-0.00020,9.000
9,133.250,0.00,-0.0003,-0.00020,9.000
9,133.375,0.00,-0.0003,-0.00020,9.000
9,133.500,-0.01,-0.0003,-0.00020,9.000
9,133.625,0.00,-0.0003,-0.00020,9.000
9,133.750,-0.01,-0.0003,-0.00020,9.000
9,133.875,0.00,-0.0003,-0.00020,9.000
9,134.000,-0.01,-0.0003,-0.00020,9.000
9,134.125,0.00,-0.0003,-0.00020,9.000
9,134.250,0.00,-0.0003,-0.00020,9.000
9,134.375,0.00,-0.0003,-0.00020,9.000
9,134.500,-0.01,-0.0003,-0.00020,9.000
9,134.625,0.00,-0.0003,-0.00020,9.000
9,134.750,0.01,-0.0003,-0.00020,9.000
9,134.875,0.00,-0.0003,-0.00020,9.000
9,135.000,-0.01,-0.0003,-0.00020,9.000
9,135.125,-0.01,-0.0003,-0.00020,9.000
9,135.250,-0.01,-0.0003,-0.00020,9.000
9,135.375,0.00,-0.0003,-0.00020,9.000
9,135.500,-0.01,-0.0003,-0.00020,9.000
9,135.625,0.00,-0.0002,-0.00010,9.000
9,135.750,0.00,-0.0002,-0.00010,9.000
9,135.875,-0.01,-0.0002,-0.00010,9.000
9,136.000,-0.02,-0.0002,-0.00010,9.000
10,136.375,-0.01,0.1335,0.13360,10.000
10,136.500,-0.01,0.2587,0.25880,10.000
10,136.625,-0.01,0.3837,0.38380,10.000
10,136.750,0.00,0.5088,0.50890,10.000
10,136.875,-0.01,0.6335,0.63355,10.000
10,137.000,-0.01,0.7586,0.75870,10.000
10,137.125,-0.01,0.8836,0.88375,10.000
10,137.250,-0.01,1.0087,1.00880,10.000
10,137.375,-0.01,1.1336,1.13370,10.000
10,137.500,0.00,1.2587,1.25880,10.000
10,137.625,0.00,1.3837,1.38380,10.000
10,137.750,0.00,1.5087,1.50880,10.000
10,137.875,0.00,1.6338,1.63390,10.000
10,138.000,-0.01,1.7587,1.75880,10.000
10,138.125,-0.01,1.8837,1.88380,10.000
10,138.250,-0.01,2.0086,2.00870,10.000
10,138.375,-0.01,2.1337,2.13380,10.000
10,138.500,-0.01,2.2588,2.25890,10.000
10,138.625,0.00,2.3839,2.38395,10.000
10,138.750,0.02,2.5089,2.50900,10.000
10,138.875,0.07,2.6337,2.63380,10.000
10,139.000,0.13,2.7587,2.75880,10.000
10,139.125,0.26,2.8838,2.88385,10.000
10,139.250,0.47,3.0086,3.00870,10.000
10,139.375,0.76,3.1336,3.13375,10.000
10,139.500,1.15,3.2589,3.25900,10.000
10,139.625,1.63,3.3838,3.38395,10.000
10,139.750,2.21,3.5089,3.50900,10.000
10,139.875,2.91,3.6338,3.63395,10.000
10,140.000,3.74,3.7589,3.75900,10.000
10,140.125,4.67,3.8838,3.88395,10.000
10,140.250,5.74,4.0088,4.00890,10.000
10,140.375,6.93,4.1338,4.13390,10.000
10,140.500,8.24,4.2587,4.25880,10.000
10,140.625,9.65,4.3838,4.38385,10.000
10,140.750,11.20,4.5089,4.50900,10.000
10,140.875,13.05,4.6340,4.63405,10.000
10,141.000,15.25,4.7588,4.75890,10.000
10,141.125,17.73,4.8838,4.88390,10.000
10,141.250,20.50,5.0087,5.00880,10.000
10,141.375,23.53,5.1337,5.13380,10.000
10,141.500,26.88,5.2588,5.25890,10.000
10,141.625,30.57,5.3838,5.38390,10.000
10,141.750,34.62,5.5089,5.50900,10.000
10,141.875,39.23,5.6340,5.63410,10.000
10,142.000,44.56,5.7589,5.75900,10.000
10,142.250,46.04,5.8495,5.84960,10.000
10,142.375,35.40,5.7246,5.72470,10.000
10,142.500,28.30,5.5998,5.59990,10.000
10,142.625,22.91,5.4747,5.47480,10.000
10,142.750,18.70,5.3497,5.34980,10.000
10,142.875,15.31,5.2246,5.22470,10.000
10,143.000,12.67,5.0995,5.09960,10.000
10,143.125,10.56,4.9745,4.97460,10.000
10,143.250,8.94,4.8494,4.84950,10.000
10,143.375,7.54,4.7246,4.72465,10.000
10,143.500,6.33,4.5996,4.59970,10.000
10,143.625,5.31,4.4745,4.47460,10.000
10,143.750,4.44,4.3495,4.34960,10.000
10,143.875,3.71,4.2245,4.22460,10.000
10,144.000,3.10,4.0994,4.09950,10.000
10,144.125,2.56,3.9745,3.97460,10.000
10,144.250,2.08,3.8493,3.84940,10.000
10,144.375,1.64,3.7244,3.72455,10.000
10,144.500,1.27,3.5995,3.59960,10.000
10,144.625,0.95,3.4744,3.47455,10.000
10,144.750,0.67,3.3495,3.34960,10.000
10,144.875,0.45,3.2244,3.22450,10.000
10,145.000,0.28,3.0993,3.09940,10.000
10,145.125,0.14,2.9744,2.97450,10.000
10,145.250,0.05,2.8492,2.84930,10.000
10,145.375,0.02,2.7243,2.72440,10.000
10,145.500,0.00,2.5993,2.59940,10.000
10,145.625,0.00,2.4744,2.47455,10.000
10,145.750,-0.01,2.3494,2.34950,10.000
10,145.875,-0.01,2.2244,2.22445,10.000
10,146.000,-0.01,2.0994,2.09950,10.000
10,146.125,0.00,1.9742,1.97430,10.000
10,146.250,0.00,1.8492,1.84930,10.000
10,146.375,-0.01,1.7243,1.72440,10.000
10,146.500,0.00,1.5993,1.59940,10.000
10,146.625,-0.01,1.4744,1.47445,10.000
10,146.750,0.00,1.3494,1.34950,10.000
10,146.875,-0.01,1.2244,1.22445,10.000
10,147.000,-0.01,1.0993,1.09940,10.000
10,147.125,-0.01,0.9742,0.97430,10.000
10,147.250,0.00,0.8493,0.84940,10.000
10,147.375,-0.01,0.7242,0.72430,10.000
10,147.500,0.00,0.5990,0.59910,10.000
10,147.625,0.00,0.4743,0.47435,10.000
10,147.750,-0.01,0.3492,0.34930,10.000
10,147.875,0.00,0.2242,0.22435,10.000
10,148.000,-0.01,0.0992,0.09930,10.000
10,148.188,0.00,-0.0319,-0.03175,10.000
10,148.312,-0.01,-0.0003,-0.00020,10.000
10,148.438,-0.01,-0.0003,-0.00020,10.000
10,148.562,-0.01,-0.0003,-0.00020,10.000
10,148.688,0.00,-0.0003,-0.00020,10.000
10,148.812,-0.01,-0.0003,-0.00020,10.000
10,148.938,-0.01,-0.0003,-0.00020,10.000
10,149.062,0.00,-0.0003,-0.00020,10.000
10,149.188,-0.01,-0.0003,-0.00020,10.000
10,149.312,0.00,-0.0003,-0.00020,10.000
10,149.438,-0.02,-0.0003,-0.00020,10.000
10,149.562,-0.01,-0.0003,-0.00020,10.000
10,149.688,-0.01,-0.0003,-0.00020,10.000
10,149.812,0.00,-0.0003,-0.00020,10.000
10,149.938,-0.01,-0.0003,-0.00020,10.000
10,150.062,-0.01,-0.0003,-0.00020,10.000
10,150.188,0.00,-0.0003,-0.00020,10.000
10,150.312,-0.01,-0.0003,-0.00020,10.000
10,150.438,-0.02,-0.0003,-0.00020,10.000
10,150.562,0.00,-0.0002,-0.00010,10.000
10,150.688,0.00,-0.0002,-0.00010,10.000
10,150.812,-0.01,-0.0002,-0.00010,10.000
10,150.938,0.00,-0.0002,-0.00010,10.000
10,151.062,-0.01,-0.0002,-0.00010,10.000
10,151.125,0.00,-0.0002,-0.00010,10.000