File: calibDATA_loadcell/date_02:22:2018/Instron/50N_0_1_1_0.txt
""
"Test Method","Radhen_Load_Cntrl_Cmprsn_250N_12-7.msm"
"Sample I. D.","Sample1.mss"
"Specimen Number","2"

"TheCycle_Output ()","_Time (s)","_Load (N)","_Extension (mm)","RealTimeDepth (mm)","CycleNumber ()"

1,0.312,0.00,0.1089,0.10890,1.000
1,0.438,-0.01,0.2341,0.23408,1.000
1,0.562,0.00,0.3591,0.35912,1.000
1,0.688,-0.01,0.4842,0.48415,1.000
1,0.812,0.00,0.6092,0.60920,1.000
1,0.938,-0.01,0.7342,0.73420,1.000
1,1.062,0.00,0.8591,0.85910,1.000
1,1.188,0.00,0.9842,0.98418,1.000
1,1.312,0.00,1.1091,1.10912,1.000
1,1.438,-0.01,1.2342,1.23420,1.000
1,1.562,-0.01,1.3593,1.35932,1.000
1,1.688,-0.01,1.4843,1.48428,1.000
1,1.812,0.00,1.6094,1.60942,1.000
1,1.938,-0.01,1.7342,1.73415,1.000
1,2.062,-0.01,1.8591,1.85908,1.000
1,2.188,-0.01,1.9841,1.98413,1.000
1,2.312,-0.01,2.1091,2.10912,1.000
1,2.438,-0.01,2.2343,2.23430,1.000
1,2.562,0.00,2.3593,2.35932,1.000
1,2.688,0.00,2.4843,2.48428,1.000
1,2.812,0.00,2.6093,2.60930,1.000
1,2.938,0.00,2.7343,2.73432,1.000
1,3.062,-0.01,2.8594,2.85935,1.000
1,3.188,0.00,2.9843,2.98425,1.000
1,3.312,0.01,3.1093,3.10932,1.000
1,3.438,0.03,3.2342,3.23420,1.000
1,3.562,0.06,3.3593,3.35932,1.000
1,3.688,0.14,3.4844,3.48438,1.000
1,3.812,0.26,3.6095,3.60948,1.000
1,3.938,0.46,3.7344,3.73443,1.000
1,4.062,0.74,3.8594,3.85942,1.000
1,4.188,1.11,3.9843,3.98432,1.000
1,4.312,1.60,4.1092,4.10922,1.000
1,4.438,2.22,4.2342,4.23422,1.000
1,4.562,2.97,4.3593,4.35930,1.000
1,4.688,3.87,4.4844,4.48435,1.000
1,4.812,4.94,4.6093,4.60932,1.000
1,4.938,6.19,4.7344,4.73438,1.000
1,5.062,7.64,4.8594,4.85935,1.000
1,5.188,9.31,4.9843,4.98428,1.000
1,5.312,11.23,5.1094,5.10938,1.000
1,5.438,13.45,5.2344,5.23438,1.000
1,5.562,16.00,5.3592,5.35925,1.000
1,5.688,18.93,5.4844,5.48445,1.000
1,5.812,22.26,5.6096,5.60957,1.000
1,5.938,26.04,5.7345,5.73448,1.000
1,6.062,30.32,5.8594,5.85938,1.000
1,6.188,35.17,5.9844,5.98435,1.000
1,6.312,40.67,6.1093,6.10930,1.000
1,6.438,46.55,6.2343,6.23428,1.000
1,6.625,48.00,6.3126,6.31255,1.000
1,6.750,34.88,6.1877,6.18770,1.000
1,6.875,26.90,6.0628,6.06275,1.000
1,7.000,21.14,5.9377,5.93770,1.000
1,7.125,16.81,5.8128,5.81275,1.000
1,7.250,13.45,5.6879,5.68790,1.000
1,7.375,10.83,5.5629,5.56285,1.000
1,7.500,8.81,5.4377,5.43770,1.000
1,7.625,7.21,5.3126,5.31255,1.000
1,7.750,5.94,5.1876,5.18760,1.000
1,7.875,4.90,5.0626,5.06265,1.000
1,8.000,4.04,4.9377,4.93770,1.000
1,8.125,3.30,4.8127,4.81265,1.000
1,8.250,2.68,4.6876,4.68760,1.000
1,8.375,2.13,4.5626,4.56255,1.000
1,8.500,1.65,4.4376,4.43760,1.000
1,8.625,1.24,4.3125,4.31250,1.000
1,8.750,0.90,4.1875,4.18750,1.000
1,8.875,0.61,4.0624,4.06240,1.000
1,9.000,0.39,3.9375,3.93750,1.000
1,9.125,0.20,3.8125,3.81250,1.000
1,9.250,0.08,3.6876,3.68760,1.000
1,9.375,0.01,3.5626,3.56260,1.000
1,9.500,0.00,3.4373,3.43730,1.000
1,9.625,-0.01,3.3124,3.31235,1.000
1,9.750,-0.01,3.1874,3.18740,1.000
1,9.875,0.00,3.0625,3.06245,1.000
1,10.000,0.00,2.9375,2.93750,1.000
1,10.125,-0.01,2.8125,2.81250,1.000
1,10.250,-0.01,2.6874,2.68740,1.000
1,10.375,0.00,2.5624,2.56240,1.000
1,10.500,0.00,2.4374,2.43740,1.000
1,10.625,-0.01,2.3124,2.31240,1.000
1,10.750,0.00,2.1872,2.18720,1.000
1,10.875,0.00,2.0623,2.06225,1.000
1,11.000,0.00,1.9373,1.93730,1.000
1,11.125,0.00,1.8122,1.81220,1.000
1,11.250,0.00,1.6875,1.68750,1.000
1,11.375,0.00,1.5625,1.56250,1.000
1,11.500,0.00,1.4373,1.43730,1.000
1,11.625,-0.01,1.3123,1.31230,1.000
1,11.750,-0.01,1.1871,1.18710,1.000
1,11.875,0.00,1.0623,1.06230,1.000
1,12.000,0.00,0.9373,0.93730,1.000
1,12.125,0.00,0.8123,0.81230,1.000
1,12.250,-0.01,0.6874,0.68740,1.000
1,12.375,0.00,0.5623,0.56230,1.000
1,12.500,0.00,0.4374,0.43740,1.000
1,12.625,0.00,0.3123,0.31225,1.000
1,12.750,0.00,0.1871,0.18710,1.000
1,12.875,-0.01,0.0621,0.06210,1.000
1,13.062,-0.01,-0.0087,-0.00870,1.000
1,13.188,-0.01,-0.0003,-0.00030,1.000
1,13.312,-0.01,-0.0003,-0.00030,1.000
1,13.438,-0.01,-0.0003,-0.00030,1.000
1,13.562,-0.01,-0.0003,-0.00030,1.000
1,13.688,0.00,-0.0003,-0.00030,1.000
1,13.812,-0.01,-0.0003,-0.00030,1.000
1,13.938,0.00,-0.0003,-0.00030,1.000
1,14.062,-0.01,-0.0003,-0.00030,1.000
1,14.188,0.00,-0.0003,-0.00030,1.000
1,14.312,-0.01,-0.0003,-0.00030,1.000
1,14.438,0.00,-0.0003,-0.00030,1.000
1,14.562,0.00,-0.0003,-0.00030,1.000
1,14.688,-0.01,-0.0003,-0.00030,1.000
1,14.812,0.00,-0.0002,-0.00020,1.000
1,14.938,-0.01,-0.0002,-0.00020,1.000
1,15.062,-0.01,-0.0002,-0.00020,1.000
1,15.188,-0.01,-0.0002,-0.00020,1.000
1,15.312,-0.01,-0.0002,-0.00020,1.000
1,15.438,0.00,-0.0002,-0.00020,1.000
1,15.562,0.00,-0.0002,-0.00020,1.000
1,15.688,-0.01,-0.0002,-0.00020,1.000
1,15.812,0.00,-0.0002,-0.00020,1.000
1,15.938,0.00,-0.0002,-0.00020,1.000
2,16.312,0.00,0.0989,0.09900,2.000
2,16.438,0.00,0.2239,0.22400,2.000
2,16.562,-0.01,0.3490,0.34913,2.000
2,16.688,0.00,0.4739,0.47405,2.000
2,16.812,0.00,0.5991,0.59920,2.000
2,16.938,-0.01,0.7241,0.72420,2.000
2,17.062,0.01,0.8491,0.84920,2.000
2,17.188,0.00,0.9741,0.97422,2.000
2,17.312,-0.01,1.0991,1.09923,2.000
2,17.438,0.00,1.2240,1.22407,2.000
2,17.562,0.00,1.3491,1.34923,2.000
2,17.688,0.00,1.4741,1.47417,2.000
2,17.812,0.00,1.5994,1.59950,2.000
2,17.938,0.00,1.7242,1.72435,2.000
2,18.062,0.00,1.8491,1.84923,2.000
2,18.188,0.00,1.9741,1.97422,2.000
2,18.312,0.00,2.0991,2.09920,2.000
2,18.438,0.00,2.2241,2.22425,2.000
2,18.562,0.00,2.3491,2.34923,2.000
2,18.688,0.00,2.4741,2.47420,2.000
2,18.812,0.00,2.5992,2.59925,2.000
2,18.938,0.00,2.7243,2.72438,2.000
2,19.062,0.00,2.8493,2.84935,2.000
2,19.188,0.00,2.9743,2.97440,2.000
2,19.312,0.01,3.0994,3.09953,2.000
2,19.438,0.02,3.2242,3.22432,2.000
2,19.562,0.05,3.3492,3.34928,2.000
2,19.688,0.09,3.4743,3.47438,2.000
2,19.812,0.18,3.5993,3.59938,2.000
2,19.938,0.34,3.7244,3.72447,2.000
2,20.062,0.58,3.8494,3.84948,2.000
2,20.188,0.91,3.9743,3.97442,2.000
2,20.312,1.36,4.0993,4.09935,2.000
2,20.438,1.93,4.2242,4.22435,2.000
2,20.562,2.62,4.3492,4.34925,2.000
2,20.688,3.46,4.4743,4.47437,2.000
2,20.812,4.45,4.5992,4.59933,2.000
2,20.938,5.63,4.7242,4.72432,2.000
2,21.062,7.01,4.8493,4.84940,2.000
2,21.188,8.59,4.9744,4.97447,2.000
2,21.312,10.40,5.0994,5.09945,2.000
2,21.438,12.49,5.2243,5.22442,2.000
2,21.562,14.87,5.3492,5.34928,2.000
2,21.688,17.58,5.4743,5.47440,2.000
2,21.812,20.63,5.5993,5.59943,2.000
2,21.938,24.07,5.7243,5.72437,2.000
2,22.062,27.97,5.8494,5.84945,2.000
2,22.188,32.41,5.9744,5.97455,2.000
2,22.312,37.57,6.0993,6.09940,2.000
2,22.438,43.74,6.2242,6.22435,2.000
2,22.562,51.29,6.3494,6.34948,2.000
2,22.750,40.11,6.2775,6.27760,2.000
2,22.875,30.34,6.1526,6.15265,2.000
2,23.000,23.68,6.0277,6.02780,2.000
2,23.125,18.71,5.9027,5.90280,2.000
2,23.250,14.91,5.7775,5.77760,2.000
2,23.375,11.99,5.6528,5.65285,2.000
2,23.500,9.72,5.5278,5.52790,2.000
2,23.625,7.96,5.4026,5.40270,2.000
2,23.750,6.55,5.2775,5.27760,2.000
2,23.875,5.42,5.1526,5.15270,2.000
2,24.000,4.49,5.0275,5.02760,2.000
2,24.125,3.69,4.9027,4.90275,2.000
2,24.250,3.01,4.7775,4.77760,2.000
2,24.375,2.42,4.6526,4.65265,2.000
2,24.500,1.92,4.5276,4.52770,2.000
2,24.625,1.47,4.4025,4.40260,2.000
2,24.750,1.10,4.2775,4.27760,2.000
2,24.875,0.77,4.1524,4.15250,2.000
2,25.000,0.51,4.0274,4.02750,2.000
2,25.125,0.30,3.9024,3.90250,2.000
2,25.250,0.15,3.7774,3.77750,2.000
2,25.375,0.04,3.6526,3.65265,2.000
2,25.500,0.00,3.5276,3.52770,2.000
2,25.625,0.00,3.4024,3.40250,2.000
2,25.750,0.00,3.2773,3.27740,2.000
2,25.875,0.00,3.1524,3.15250,2.000
2,26.000,0.00,3.0274,3.02750,2.000
2,26.125,-0.01,2.9024,2.90245,2.000
2,26.250,-0.01,2.7773,2.77740,2.000
2,26.375,0.00,2.6524,2.65250,2.000
2,26.500,-0.01,2.5274,2.52750,2.000
2,26.625,0.00,2.4023,2.40240,2.000
2,26.750,-0.01,2.2774,2.27750,2.000
2,26.875,0.00,2.1522,2.15230,2.000
2,27.000,0.00,2.0271,2.02720,2.000
2,27.125,-0.01,1.9022,1.90230,2.000
2,27.250,-0.01,1.7772,1.77730,2.000
2,27.375,0.00,1.6526,1.65265,2.000
2,27.500,-0.01,1.5275,1.52760,2.000
2,27.625,-0.01,1.4024,1.40255,2.000
2,27.750,0.00,1.2773,1.27740,2.000
2,27.875,0.00,1.1522,1.15230,2.000
2,28.000,0.00,1.0272,1.02730,2.000
2,28.125,0.00,0.9022,0.90225,2.000
2,28.250,0.00,0.7771,0.77720,2.000
2,28.375,0.00,0.6523,0.65240,2.000
2,28.500,0.00,0.5273,0.52740,2.000
2,28.625,0.00,0.4022,0.40235,2.000
2,28.750,0.00,0.2772,0.27730,2.000
2,28.875,0.00,0.1522,0.15225,2.000
2,29.000,0.00,0.0270,0.02710,2.000
2,29.188,0.00,-0.0017,-0.00158,2.000
2,29.312,0.00,-0.0003,-0.00020,2.000
2,29.438,0.00,-0.0003,-0.00020,2.000
2,29.562,0.00,-0.0003,-0.00020,2.000
2,29.688,0.00,-0.0003,-0.00020,2.000
2,29.812,0.00,-0.0003,-0.00020,2.000
2,29.938,0.00,-0.0003,-0.00020,2.000
2,30.062,0.00,-0.0003,-0.00020,2.000
2,30.188,0.00,-0.0003,-0.00020,2.000
2,30.312,0.00,-0.0003,-0.00020,2.000
2,30.438,0.00,-0.0003,-0.00020,2.000
2,30.562,0.00,-0.0003,-0.00020,2.000
2,30.688,0.00,-0.0003,-0.00020,2.000
2,30.812,0.00,-0.0003,-0.00020,2.000
2,30.938,0.00,-0.0003,-0.00020,2.000
2,31.062,-0.01,-0.0003,-0.00020,2.000
2,31.188,0.00,-0.0003,-0.00020,2.000
2,31.312,0.00,-0.0002,-0.00010,2.000
2,31.438,0.00,-0.0002,-0.00010,2.000
2,31.562,-0.01,-0.0002,-0.00010,2.000
2,31.688,0.00,-0.0002,-0.00010,2.000
2,31.812,0.00,-0.0002,-0.00010,2.000
2,31.938,0.00,-0.0002,-0.00010,2.000
2,32.062,0.00,-0.0002,-0.00010,2.000
3,32.438,0.01,0.0939,0.09395,3.000
3,32.562,0.01,0.2190,0.21907,3.000
3,32.688,0.01,0.3440,0.34410,3.000
3,32.812,0.01,0.4689,0.46902,3.000
3,32.938,0.01,0.5941,0.59423,3.000
3,33.062,0.01,0.7192,0.71927,3.000
3,33.188,0.01,0.8441,0.84420,3.000
3,33.312,0.01,0.9692,0.96927,3.000
3,33.438,0.01,1.0942,1.09430,3.000
3,33.562,0.02,1.2191,1.21917,3.000
3,33.688,0.01,1.3441,1.34418,3.000
3,33.812,0.01,1.4691,1.46922,3.000
3,33.938,0.01,1.5943,1.59438,3.000
3,34.062,0.01,1.7191,1.71922,3.000
3,34.188,0.01,1.8441,1.84420,3.000
3,34.312,0.01,1.9692,1.96927,3.000
3,34.438,0.01,2.0942,2.09430,3.000
3,34.562,0.02,2.2192,2.21935,3.000
3,34.688,0.01,2.3442,2.34425,3.000
3,34.812,0.01,2.4690,2.46912,3.000
3,34.938,0.01,2.5941,2.59420,3.000
3,35.062,0.01,2.7191,2.71925,3.000
3,35.188,0.01,2.8442,2.84430,3.000
3,35.312,0.01,2.9692,2.96935,3.000
3,35.438,0.02,3.0944,3.09448,3.000
3,35.562,0.03,3.2193,3.21942,3.000
3,35.688,0.05,3.3443,3.34440,3.000
3,35.812,0.10,3.4692,3.46927,3.000
3,35.938,0.18,3.5943,3.59435,3.000
3,36.062,0.33,3.7193,3.71942,3.000
3,36.188,0.57,3.8443,3.84438,3.000
3,36.312,0.89,3.9694,3.96947,3.000
3,36.438,1.32,4.0943,4.09438,3.000
3,36.562,1.88,4.2194,4.21947,3.000
3,36.688,2.56,4.3443,4.34440,3.000
3,36.812,3.39,4.4693,4.46937,3.000
3,36.938,4.37,4.5942,4.59430,3.000
3,37.062,5.54,4.7191,4.71925,3.000
3,37.188,6.90,4.8442,4.84433,3.000
3,37.312,8.46,4.9692,4.96935,3.000
3,37.438,10.25,5.0943,5.09443,3.000
3,37.562,12.31,5.2194,5.21955,3.000
3,37.688,14.64,5.3442,5.34433,3.000
3,37.812,17.28,5.4694,5.46947,3.000
3,37.938,20.25,5.5943,5.59443,3.000
3,38.062,23.60,5.7192,5.71932,3.000
3,38.188,27.36,5.8443,5.84438,3.000
3,38.312,31.63,5.9694,5.96947,3.000
3,38.438,36.59,6.0944,6.09448,3.000
3,38.562,42.48,6.2193,6.21937,3.000
3,38.688,49.83,6.3444,6.34445,3.000
3,38.875,41.50,6.3026,6.30275,3.000
3,39.000,31.18,6.1777,6.17780,3.000
3,39.125,24.27,6.0527,6.05280,3.000
3,39.250,19.16,5.9278,5.92790,3.000
3,39.375,15.28,5.8026,5.80270,3.000
3,39.500,12.28,5.6775,5.67760,3.000
3,39.625,9.95,5.5527,5.55280,3.000
3,39.750,8.14,5.4277,5.42780,3.000
3,39.875,6.71,5.3026,5.30270,3.000
3,40.000,5.55,5.1777,5.17780,3.000
3,40.125,4.59,5.0526,5.05275,3.000
3,40.250,3.78,4.9277,4.92780,3.000
3,40.375,3.10,4.8025,4.80260,3.000
3,40.500,2.50,4.6774,4.67750,3.000
3,40.625,1.98,4.5525,4.55255,3.000
3,40.750,1.53,4.4275,4.42760,3.000
3,40.875,1.14,4.3025,4.30260,3.000
3,41.000,0.82,4.1776,4.17770,3.000
3,41.125,0.56,4.0525,4.05255,3.000
3,41.250,0.34,3.9275,3.92760,3.000
3,41.375,0.18,3.8025,3.80255,3.000
3,41.500,0.07,3.6774,3.67750,3.000
3,41.625,0.01,3.5525,3.55255,3.000
3,41.750,0.01,3.4274,3.42750,3.000
3,41.875,0.01,3.3025,3.30255,3.000
3,42.000,0.01,3.1775,3.17760,3.000
3,42.125,0.01,3.0525,3.05260,3.000
3,42.250,0.01,2.9275,2.92760,3.000
3,42.375,0.01,2.8024,2.80250,3.000
3,42.500,0.01,2.6774,2.67750,3.000
3,42.625,0.01,2.5523,2.55240,3.000
3,42.750,0.00,2.4272,2.42730,3.000
3,42.875,0.01,2.3024,2.30245,3.000
3,43.000,0.01,2.1773,2.17740,3.000
3,43.125,0.01,2.0524,2.05245,3.000
3,43.250,0.01,1.9274,1.92750,3.000
3,43.375,0.01,1.8022,1.80230,3.000
3,43.500,0.01,1.6775,1.67760,3.000
3,43.625,0.01,1.5524,1.55245,3.000
3,43.750,0.01,1.4272,1.42730,3.000
3,43.875,0.01,1.3023,1.30240,3.000
3,44.000,0.01,1.1773,1.17740,3.000
3,44.125,0.01,1.0524,1.05250,3.000
3,44.250,0.02,0.9272,0.92730,3.000
3,44.375,0.01,0.8022,0.80235,3.000
3,44.500,0.01,0.6774,0.67750,3.000
3,44.625,0.01,0.5522,0.55230,3.000
3,44.750,0.01,0.4271,0.42720,3.000
3,44.875,0.01,0.3022,0.30230,3.000
3,45.000,0.01,0.1772,0.17730,3.000
3,45.125,0.01,0.0522,0.05225,3.000
3,45.312,0.01,-0.0046,-0.00450,3.000
3,45.438,0.01,-0.0003,-0.00020,3.000
3,45.562,0.01,-0.0003,-0.00020,3.000
3,45.688,0.01,-0.0003,-0.00020,3.000
3,45.812,0.01,-0.0003,-0.00020,3.000
3,45.938,0.01,-0.0003,-0.00020,3.000
3,46.062,0.02,-0.0003,-0.00020,3.000
3,46.188,0.01,-0.0003,-0.00020,3.000
3,46.312,0.01,-0.0003,-0.00020,3.000
3,46.438,0.01,-0.0003,-0.00020,3.000
3,46.562,0.01,-0.0003,-0.00020,3.000
3,46.688,0.01,-0.0003,-0.00020,3.000
3,46.812,0.01,-0.0003,-0.00020,3.000
3,46.938,0.01,-0.0003,-0.00020,3.000
3,47.062,0.01,-0.0003,-0.00020,3.000
3,47.188,0.01,-0.0003,-0.00020,3.000
3,47.312,0.01,-0.0003,-0.00020,3.000
3,47.438,0.02,-0.0003,-0.00020,3.000
3,47.562,0.02,-0.0003,-0.00020,3.000
3,47.688,0.02,-0.0002,-0.00012,3.000
3,47.812,0.01,-0.0002,-0.00010,3.000
3,47.938,0.01,-0.0002,-0.00010,3.000
3,48.062,0.01,-0.0002,-0.00010,3.000
3,48.188,0.01,-0.0002,-0.00010,3.000
4,48.562,0.00,0.0900,0.09007,4.000
4,48.688,0.00,0.2150,0.21505,4.000
4,48.812,0.00,0.3400,0.34010,4.000
4,48.938,0.00,0.4649,0.46495,4.000
4,49.062,0.00,0.5901,0.59020,4.000
4,49.188,-0.01,0.7151,0.71518,4.000
4,49.312,-0.01,0.8400,0.84015,4.000
4,49.438,0.00,0.9651,0.96520,4.000
4,49.562,0.00,1.0901,1.09022,4.000
4,49.688,0.00,1.2152,1.21528,4.000
4,49.812,0.00,1.3402,1.34035,4.000
4,49.938,0.00,1.4651,1.46518,4.000
4,50.062,0.00,1.5903,1.59040,4.000
4,50.188,-0.01,1.7151,1.71520,4.000
4,50.312,0.00,1.8401,1.84020,4.000
4,50.438,0.00,1.9652,1.96528,4.000
4,50.562,0.00,2.0902,2.09030,4.000
4,50.688,0.00,2.2152,2.21533,4.000
4,50.812,0.00,2.3402,2.34035,4.000
4,50.938,0.00,2.4651,2.46515,4.000
4,51.062,0.00,2.5900,2.59015,4.000
4,51.188,0.00,2.7152,2.71528,4.000
4,51.312,0.00,2.8402,2.84030,4.000
4,51.438,0.00,2.9653,2.96538,4.000
4,51.562,0.00,3.0904,3.09050,4.000
4,51.688,0.02,3.2154,3.21545,4.000
4,51.812,0.04,3.3403,3.34042,4.000
4,51.938,0.08,3.4653,3.46540,4.000
4,52.062,0.15,3.5903,3.59040,4.000
4,52.188,0.31,3.7153,3.71535,4.000
4,52.312,0.54,3.8402,3.84032,4.000
4,52.438,0.85,3.9654,3.96545,4.000
4,52.562,1.28,4.0903,4.09037,4.000
4,52.688,1.83,4.2154,4.21548,4.000
4,52.812,2.51,4.3404,4.34047,4.000
4,52.938,3.32,4.4653,4.46535,4.000
4,53.062,4.31,4.5903,4.59037,4.000
4,53.188,5.46,4.7152,4.71530,4.000
4,53.312,6.81,4.8402,4.84032,4.000
4,53.438,8.37,4.9654,4.96545,4.000
4,53.562,10.15,5.0903,5.09042,4.000
4,53.688,12.19,5.2154,5.21550,4.000
4,53.812,14.50,5.3403,5.34045,4.000
4,53.938,17.12,5.4655,5.46558,4.000
4,54.062,20.05,5.5904,5.59047,4.000
4,54.188,23.35,5.7153,5.71540,4.000
4,54.312,27.07,5.8402,5.84032,4.000
4,54.438,31.25,5.9654,5.96545,4.000
4,54.562,36.12,6.0903,6.09045,4.000
4,54.688,41.90,6.2153,6.21540,4.000
4,54.812,49.10,6.3404,6.34052,4.000
4,55.000,41.79,6.3086,6.30870,4.000
4,55.125,31.33,6.1837,6.18375,4.000
4,55.250,24.36,6.0588,6.05890,4.000
4,55.375,19.21,5.9337,5.93380,4.000
4,55.500,15.31,5.8087,5.80880,4.000
4,55.625,12.30,5.6836,5.68370,4.000
4,55.750,9.96,5.5586,5.55870,4.000
4,55.875,8.15,5.4336,5.43370,4.000
4,56.000,6.72,5.3086,5.30870,4.000
4,56.125,5.55,5.1837,5.18375,4.000
4,56.250,4.58,5.0586,5.05870,4.000
4,56.375,3.77,4.9337,4.93375,4.000
4,56.500,3.08,4.8086,4.80870,4.000
4,56.625,2.49,4.6834,4.68350,4.000
4,56.750,1.96,4.5584,4.55850,4.000
4,56.875,1.52,4.4335,4.43355,4.000
4,57.000,1.13,4.3086,4.30870,4.000
4,57.125,0.80,4.1836,4.18365,4.000
4,57.250,0.53,4.0584,4.05850,4.000
4,57.375,0.33,3.9335,3.93360,4.000
4,57.500,0.16,3.8085,3.80860,4.000
4,57.625,0.05,3.6835,3.68360,4.000
4,57.750,0.00,3.5584,3.55850,4.000
4,57.875,0.00,3.4333,3.43340,4.000
4,58.000,0.00,3.3084,3.30850,4.000
4,58.125,0.00,3.1834,3.18350,4.000
4,58.250,-0.01,3.0585,3.05860,4.000
4,58.375,0.00,2.9335,2.93355,4.000
4,58.500,0.00,2.8085,2.80860,4.000
4,58.625,0.00,2.6834,2.68350,4.000
4,58.750,0.00,2.5583,2.55840,4.000
4,58.875,0.00,2.4332,2.43330,4.000
4,59.000,-0.01,2.3083,2.30840,4.000
4,59.125,0.00,2.1833,2.18335,4.000
4,59.250,0.00,2.0584,2.05850,4.000
4,59.375,0.00,1.9333,1.93340,4.000
4,59.500,-0.01,1.8082,1.80830,4.000
4,59.625,0.00,1.6835,1.68355,4.000
4,59.750,0.00,1.5583,1.55840,4.000
4,59.875,0.00,1.4333,1.43340,4.000
4,60.000,-0.01,1.3083,1.30840,4.000
4,60.125,0.00,1.1832,1.18330,4.000
4,60.250,0.01,1.0583,1.05840,4.000
4,60.375,0.00,0.9333,0.93340,4.000
4,60.500,0.00,0.8083,0.80840,4.000
4,60.625,0.00,0.6833,0.68340,4.000
4,60.750,0.00,0.5583,0.55840,4.000
4,60.875,0.00,0.4332,0.43330,4.000
4,61.000,0.00,0.3082,0.30830,4.000
4,61.125,0.00,0.1832,0.18325,4.000
4,61.250,0.00,0.0582,0.05830,4.000
4,61.438,0.00,-0.0064,-0.00632,4.000
4,61.562,0.00,-0.0003,-0.00020,4.000
4,61.688,-0.01,-0.0003,-0.00020,4.000
4,61.812,-0.01,-0.0003,-0.00020,4.000
4,61.938,0.00,-0.0003,-0.00020,4.000
4,62.062,0.00,-0.0003,-0.00020,4.000
4,62.188,-0.01,-0.0003,-0.00020,4.000
4,62.312,0.00,-0.0003,-0.00020,4.000
4,62.438,0.00,-0.0003,-0.00020,4.000
4,62.562,0.00,-0.0003,-0.00020,4.000
4,62.688,-0.01,-0.0003,-0.00020,4.000
4,62.812,0.00,-0.0003,-0.00020,4.000
4,62.938,0.00,-0.0003,-0.00020,4.000
4,63.062,0.00,-0.0003,-0.00020,4.000
4,63.188,-0.01,-0.0003,-0.00020,4.000
4,63.312,0.00,-0.0003,-0.00020,4.000
4,63.438,-0.01,-0.0003,-0.00020,4.000
4,63.562,0.00,-0.0003,-0.00020,4.000
4,63.688,0.00,-0.0003,-0.00020,4.000
4,63.812,0.00,-0.0002,-0.00010,4.000
4,63.938,0.00,-0.0002,-0.00010,4.000
4,64.062,-0.01,-0.0002,-0.00010,4.000
4,64.188,0.00,-0.0002,-0.00010,4.000
4,64.312,-0.01,-0.0002,-0.00010,4.000
5,64.625,0.00,0.0504,0.05055,5.000
5,64.750,0.00,0.1754,0.17550,5.000
5,64.875,0.00,0.3005,0.30060,5.000
5,65.000,0.00,0.4254,0.42550,5.000
5,65.125,0.00,0.5504,0.55055,5.000
5,65.250,-0.01,0.6756,0.67570,5.000
5,65.375,0.00,0.8006,0.80070,5.000
5,65.500,0.00,0.9256,0.92570,5.000
5,65.625,0.00,1.0508,1.05085,5.000
5,65.750,0.00,1.1756,1.17570,5.000
5,65.875,0.00,1.3007,1.30075,5.000
5,66.000,0.00,1.4257,1.42580,5.000
5,66.125,0.00,1.5507,1.55080,5.000
5,66.250,0.00,1.6758,1.67590,5.000
5,66.375,0.00,1.8006,1.80065,5.000
5,66.500,0.00,1.9256,1.92570,5.000
5,66.625,0.00,2.0507,2.05080,5.000
5,66.750,-0.01,2.1758,2.17590,5.000
5,66.875,-0.01,2.3008,2.30090,5.000
5,67.000,0.00,2.4256,2.42570,5.000
5,67.125,0.00,2.5506,2.55075,5.000
5,67.250,0.00,2.6756,2.67570,5.000
5,67.375,0.00,2.8007,2.80080,5.000
5,67.500,-0.01,2.9258,2.92590,5.000
5,67.625,0.00,3.0509,3.05095,5.000
5,67.750,0.01,3.1760,3.17610,5.000
5,67.875,0.03,3.3008,3.30090,5.000
5,68.000,0.05,3.4257,3.42580,5.000
5,68.125,0.12,3.5508,3.55085,5.000
5,68.250,0.25,3.6758,3.67590,5.000
5,68.375,0.44,3.8007,3.80080,5.000
5,68.500,0.73,3.9258,3.92590,5.000
5,68.625,1.12,4.0508,4.05090,5.000
5,68.750,1.63,4.1758,4.17590,5.000
5,68.875,2.26,4.3009,4.30095,5.000
5,69.000,3.03,4.4259,4.42600,5.000
5,69.125,3.96,4.5508,4.55085,5.000
5,69.250,5.06,4.6757,4.67580,5.000
5,69.375,6.34,4.8007,4.80080,5.000
5,69.500,7.82,4.9258,4.92590,5.000
5,69.625,9.53,5.0508,5.05090,5.000
5,69.750,11.49,5.1759,5.17600,5.000
5,69.875,13.70,5.3008,5.30095,5.000
5,70.000,16.19,5.4259,5.42600,5.000
5,70.125,18.99,5.5510,5.55105,5.000
5,70.250,22.15,5.6758,5.67590,5.000
5,70.375,25.67,5.8007,5.80080,5.000
5,70.500,29.68,5.9258,5.92590,5.000
5,70.625,34.26,6.0508,6.05095,5.000
5,70.750,39.64,6.1759,6.17600,5.000
5,70.875,46.23,6.3008,6.30095,5.000
5,71.062,51.27,6.3940,6.39410,5.000
5,71.188,36.57,6.2692,6.26925,5.000
5,71.312,27.99,6.1441,6.14423,5.000
5,71.438,21.93,6.0193,6.01938,5.000
5,71.562,17.39,5.8943,5.89435,5.000
5,71.688,13.92,5.7690,5.76913,5.000
5,71.812,11.23,5.6442,5.64428,5.000
5,71.938,9.14,5.5191,5.51923,5.000
5,72.062,7.52,5.3940,5.39413,5.000
5,72.188,6.22,5.2692,5.26925,5.000
5,72.312,5.14,5.1441,5.14423,5.000
5,72.438,4.25,5.0191,5.01918,5.000
5,72.562,3.50,4.8942,4.89428,5.000
5,72.688,2.85,4.7691,4.76918,5.000
5,72.812,2.28,4.6440,4.64408,5.000
5,72.938,1.79,4.5190,4.51910,5.000
5,73.062,1.36,4.3939,4.39400,5.000
5,73.188,1.00,4.2690,4.26915,5.000
5,73.312,0.71,4.1439,4.14403,5.000
5,73.438,0.46,4.0190,4.01910,5.000
5,73.562,0.27,3.8939,3.89400,5.000
5,73.688,0.12,3.7690,3.76910,5.000
5,73.812,0.02,3.6441,3.64415,5.000
5,73.938,0.00,3.5188,3.51895,5.000
5,74.062,0.00,3.3938,3.39388,5.000
5,74.188,0.00,3.2688,3.26890,5.000
5,74.312,0.00,3.1439,3.14403,5.000
5,74.438,0.00,3.0190,3.01908,5.000
5,74.562,0.00,2.8939,2.89400,5.000
5,74.688,0.00,2.7689,2.76902,5.000
5,74.812,0.00,2.6440,2.64405,5.000
5,74.938,0.00,2.5187,2.51878,5.000
5,75.062,0.00,2.3938,2.39385,5.000
5,75.188,0.00,2.2689,2.26898,5.000
5,75.312,0.00,2.1438,2.14390,5.000
5,75.438,0.00,2.0188,2.01888,5.000
5,75.562,0.00,1.8938,1.89385,5.000
5,75.688,0.00,1.7688,1.76892,5.000
5,75.812,0.00,1.6441,1.64418,5.000
5,75.938,0.00,1.5188,1.51895,5.000
5,76.062,0.00,1.3938,1.39393,5.000
5,76.188,0.00,1.2688,1.26888,5.000
5,76.312,0.00,1.1437,1.14375,5.000
5,76.438,0.00,1.0189,1.01898,5.000
5,76.562,0.00,0.8937,0.89378,5.000
5,76.688,0.00,0.7689,0.76898,5.000
5,76.812,0.00,0.6438,0.64385,5.000
5,76.938,0.00,0.5187,0.51880,5.000
5,77.062,0.00,0.3937,0.39378,5.000
5,77.188,0.00,0.2686,0.26872,5.000
5,77.312,0.00,0.1436,0.14373,5.000
5,77.438,0.00,0.0186,0.01868,5.000
5,77.625,0.00,-0.0002,-0.00015,5.000
5,77.750,0.00,-0.0004,-0.00030,5.000
5,77.875,0.00,-0.0004,-0.00030,5.000
5,78.000,0.00,-0.0004,-0.00030,5.000
5,78.125,0.00,-0.0004,-0.00030,5.000
5,78.250,0.00,-0.0004,-0.00030,5.000
5,78.375,0.00,-0.0004,-0.00030,5.000
5,78.500,0.00,-0.0004,-0.00030,5.000
5,78.625,0.00,-0.0004,-0.00030,5.000
5,78.750,0.00,-0.0003,-0.00020,5.000
5,78.875,0.00,-0.0003,-0.00020,5.000
5,79.000,0.00,-0.0003,-0.00020,5.000
5,79.125,0.00,-0.0003,-0.00020,5.000
5,79.250,0.00,-0.0003,-0.00020,5.000
5,79.375,0.00,-0.0003,-0.00020,5.000
5,79.500,0.00,-0.0003,-0.00020,5.000
5,79.625,0.00,-0.0003,-0.00020,5.000
5,79.750,0.00,-0.0003,-0.00020,5.000
5,79.875,0.00,-0.0003,-0.00020,5.000
5,80.000,0.00,-0.0003,-0.00020,5.000
5,80.125,0.00,-0.0003,-0.00020,5.000
5,80.250,0.01,-0.0003,-0.00020,5.000
5,80.375,0.00,-0.0002,-0.00010,5.000
5,80.500,0.00,-0.0002,-0.00010,5.000
6,80.812,0.01,0.0609,0.06100,6.000
6,80.938,0.01,0.1859,0.18602,6.000
6,81.062,0.01,0.3111,0.31117,6.000
6,81.188,0.01,0.4359,0.43602,6.000
6,81.312,0.01,0.5611,0.56122,6.000
6,81.438,0.01,0.6862,0.68628,6.000
6,81.562,0.01,0.8111,0.81125,6.000
6,81.688,0.01,0.9361,0.93620,6.000
6,81.812,0.01,1.0612,1.06132,6.000
6,81.938,0.00,1.1860,1.18615,6.000
6,82.062,0.01,1.3110,1.31115,6.000
6,82.188,0.01,1.4361,1.43620,6.000
6,82.312,0.01,1.5613,1.56142,6.000
6,82.438,0.01,1.6863,1.68640,6.000
6,82.562,0.01,1.8111,1.81117,6.000
6,82.688,0.01,1.9362,1.93628,6.000
6,82.812,0.01,2.0612,2.06127,6.000
6,82.938,0.01,2.1862,2.18625,6.000
6,83.062,0.01,2.3111,2.31122,6.000
6,83.188,0.01,2.4361,2.43623,6.000
6,83.312,0.01,2.5611,2.56117,6.000
6,83.438,0.01,2.6862,2.68630,6.000
6,83.562,0.01,2.8113,2.81142,6.000
6,83.688,0.01,2.9364,2.93645,6.000
6,83.812,0.01,3.0614,3.06147,6.000
6,83.938,0.03,3.1862,3.18635,6.000
6,84.062,0.04,3.3112,3.31130,6.000
6,84.188,0.08,3.4362,3.43630,6.000
6,84.312,0.14,3.5613,3.56142,6.000
6,84.438,0.27,3.6864,3.68648,6.000
6,84.562,0.48,3.8114,3.81150,6.000
6,84.688,0.76,3.9364,3.93648,6.000
6,84.812,1.16,4.0613,4.06137,6.000
6,84.938,1.68,4.1863,4.18642,6.000
6,85.062,2.32,4.3112,4.31132,6.000
6,85.188,3.10,4.4362,4.43632,6.000
6,85.312,4.03,4.5611,4.56125,6.000
6,85.438,5.14,4.6862,4.68630,6.000
6,85.562,6.43,4.8112,4.81135,6.000
6,85.688,7.94,4.9364,4.93652,6.000
6,85.812,9.66,5.0614,5.06147,6.000
6,85.938,11.63,5.1864,5.18650,6.000
6,86.062,13.87,5.3113,5.31137,6.000
6,86.188,16.37,5.4362,5.43635,6.000
6,86.312,19.19,5.5613,5.56145,6.000
6,86.438,22.36,5.6864,5.68645,6.000
6,86.562,25.90,5.8113,5.81140,6.000
6,86.688,29.95,5.9364,5.93650,6.000
6,86.812,34.54,6.0614,6.06147,6.000
6,86.938,39.99,6.1863,6.18640,6.000
6,87.062,46.65,6.3113,6.31140,6.000
6,87.250,48.94,6.3798,6.37990,6.000
6,87.375,35.35,6.2546,6.25475,6.000
6,87.500,27.16,6.1298,6.12990,6.000
6,87.625,21.30,6.0046,6.00475,6.000
6,87.750,16.91,5.8795,5.87960,6.000
6,87.875,13.54,5.7544,5.75455,6.000
6,88.000,10.93,5.6297,5.62980,6.000
6,88.125,8.91,5.5048,5.50485,6.000
6,88.250,7.34,5.3797,5.37980,6.000
6,88.375,6.07,5.2547,5.25480,6.000
6,88.500,5.02,5.1296,5.12970,6.000
6,88.625,4.15,5.0046,5.00465,6.000
6,88.750,3.41,4.8795,4.87960,6.000
6,88.875,2.78,4.7544,4.75450,6.000
6,89.000,2.22,4.6294,4.62950,6.000
6,89.125,1.73,4.5045,4.50460,6.000
6,89.250,1.32,4.3795,4.37960,6.000
6,89.375,0.97,4.2546,4.25465,6.000
6,89.500,0.68,4.1294,4.12950,6.000
6,89.625,0.44,4.0044,4.00455,6.000
6,89.750,0.26,3.8792,3.87930,6.000
6,89.875,0.11,3.7544,3.75445,6.000
6,90.000,0.03,3.6295,3.62960,6.000
6,90.125,0.02,3.5044,3.50455,6.000
6,90.250,0.01,3.3794,3.37950,6.000
6,90.375,0.01,3.2544,3.25450,6.000
6,90.500,0.01,3.1295,3.12960,6.000
6,90.625,0.01,3.0044,3.00450,6.000
6,90.750,0.01,2.8793,2.87940,6.000
6,90.875,0.01,2.7543,2.75440,6.000
6,91.000,0.01,2.6293,2.62940,6.000
6,91.125,0.01,2.5042,2.50435,6.000
6,91.250,0.01,2.3793,2.37940,6.000
6,91.375,0.01,2.2545,2.25455,6.000
6,91.500,0.01,2.1293,2.12940,6.000
6,91.625,0.01,2.0043,2.00440,6.000
6,91.750,0.01,1.8792,1.87930,6.000
6,91.875,0.01,1.7541,1.75420,6.000
6,92.000,0.01,1.6294,1.62950,6.000
6,92.125,0.01,1.5043,1.50440,6.000
6,92.250,0.01,1.3794,1.37950,6.000
6,92.375,0.01,1.2543,1.25440,6.000
6,92.500,0.01,1.1294,1.12950,6.000
6,92.625,0.01,1.0044,1.00445,6.000
6,92.750,0.01,0.8792,0.87930,6.000
6,92.875,0.01,0.7543,0.75435,6.000
6,93.000,0.01,0.6293,0.62940,6.000
6,93.125,0.01,0.5041,0.50420,6.000
6,93.250,0.01,0.3792,0.37930,6.000
6,93.375,0.01,0.2542,0.25430,6.000
6,93.500,0.01,0.1293,0.12940,6.000
6,93.625,0.01,0.0042,0.00425,6.000
6,93.812,0.01,-0.0003,-0.00022,6.000
6,93.938,0.01,-0.0004,-0.00030,6.000
6,94.062,0.01,-0.0004,-0.00030,6.000
6,94.188,0.01,-0.0004,-0.00030,6.000
6,94.312,0.01,-0.0004,-0.00030,6.000
6,94.438,0.01,-0.0004,-0.00030,6.000
6,94.562,0.01,-0.0004,-0.00030,6.000
6,94.688,0.01,-0.0004,-0.00030,6.000
6,94.812,0.01,-0.0003,-0.00020,6.000
6,94.938,0.01,-0.0003,-0.00020,6.000
6,95.062,0.01,-0.0003,-0.00020,6.000
6,95.188,0.01,-0.0003,-0.00020,6.000
6,95.312,0.01,-0.0003,-0.00020,6.000
6,95.438,0.01,-0.0003,-0.00020,6.000
6,95.562,0.01,-0.0003,-0.00020,6.000
6,95.688,0.01,-0.0003,-0.00020,6.000
6,95.812,0.01,-0.0003,-0.00020,6.000
6,95.938,0.01,-0.0003,-0.00020,6.000
6,96.062,0.01,-0.0003,-0.00020,6.000
6,96.188,0.01,-0.0003,-0.00020,6.000
6,96.312,0.01,-0.0003,-0.00020,6.000
6,96.438,0.01,-0.0003,-0.00020,6.000
6,96.562,0.01,-0.0002,-0.00010,6.000
6,96.688,0.01,-0.0002,-0.00010,6.000
7,97.062,-0.01,0.1681,0.16820,7.000
7,97.188,0.00,0.2931,0.29322,7.000
7,97.312,0.00,0.4180,0.41815,7.000
7,97.438,0.00,0.5430,0.54308,7.000
7,97.562,0.00,0.6680,0.66812,7.000
7,97.688,-0.01,0.7931,0.79318,7.000
7,97.812,-0.01,0.9180,0.91810,7.000
7,97.938,-0.01,1.0432,1.04330,7.000
7,98.062,0.00,1.1682,1.16830,7.000
7,98.188,-0.01,1.2932,1.29335,7.000
7,98.312,0.00,1.4183,1.41837,7.000
7,98.438,0.00,1.5432,1.54335,7.000
7,98.562,-0.01,1.6683,1.66845,7.000
7,98.688,-0.01,1.7931,1.79318,7.000
7,98.812,0.00,1.9180,1.91815,7.000
7,98.938,0.00,2.0433,2.04335,7.000
7,99.062,-0.01,2.1682,2.16832,7.000
7,99.188,0.00,2.2934,2.29348,7.000
7,99.312,0.00,2.4182,2.41830,7.000
7,99.438,-0.01,2.5433,2.54338,7.000
7,99.562,-0.01,2.6682,2.66835,7.000
7,99.688,-0.01,2.7932,2.79330,7.000
7,99.812,0.00,2.9182,2.91830,7.000
7,99.938,-0.01,3.0432,3.04330,7.000
7,100.062,0.01,3.1683,3.16840,7.000
7,100.188,0.03,3.2933,3.29340,7.000
7,100.312,0.05,3.4182,3.41835,7.000
7,100.438,0.12,3.5434,3.54350,7.000
7,100.562,0.23,3.6683,3.66840,7.000
7,100.688,0.42,3.7932,3.79335,7.000
7,100.812,0.70,3.9182,3.91830,7.000
7,100.938,1.07,4.0433,4.04335,7.000
7,101.062,1.57,4.1682,4.16835,7.000
7,101.188,2.19,4.2933,4.29340,7.000
7,101.312,2.95,4.4183,4.41842,7.000
7,101.438,3.85,4.5433,4.54342,7.000
7,101.562,4.94,4.6683,4.66837,7.000
7,101.688,6.21,4.7932,4.79325,7.000
7,101.812,7.68,4.9182,4.91832,7.000
7,101.938,9.37,5.0432,5.04330,7.000
7,102.062,11.30,5.1683,5.16840,7.000
7,102.188,13.49,5.2934,5.29348,7.000
7,102.312,15.95,5.4183,5.41845,7.000
7,102.438,18.71,5.5435,5.54360,7.000
7,102.562,21.81,5.6684,5.66847,7.000
7,102.688,25.30,5.7932,5.79332,7.000
7,102.812,29.23,5.9183,5.91840,7.000
7,102.938,33.72,6.0433,6.04340,7.000
7,103.062,38.98,6.1682,6.16832,7.000
7,103.188,45.38,6.2934,6.29345,7.000
7,103.375,52.74,6.4112,6.41125,7.000
7,103.500,37.57,6.2867,6.28680,7.000
7,103.625,28.65,6.1616,6.16170,7.000
7,103.750,22.39,6.0366,6.03670,7.000
7,103.875,17.73,5.9116,5.91175,7.000
7,104.000,14.17,5.7866,5.78670,7.000
7,104.125,11.42,5.6617,5.66180,7.000
7,104.250,9.30,5.5368,5.53690,7.000
7,104.375,7.64,5.4116,5.41170,7.000
7,104.500,6.31,5.2866,5.28670,7.000
7,104.625,5.21,5.1616,5.16165,7.000
7,104.750,4.31,5.0365,5.03660,7.000
7,104.875,3.55,4.9116,4.91165,7.000
7,105.000,2.88,4.7865,4.78660,7.000
7,105.125,2.32,4.6616,4.66165,7.000
7,105.250,1.81,4.5365,4.53660,7.000
7,105.375,1.39,4.4115,4.41160,7.000
7,105.500,1.03,4.2865,4.28660,7.000
7,105.625,0.72,4.1614,4.16150,7.000
7,105.750,0.47,4.0363,4.03640,7.000
7,105.875,0.27,3.9114,3.91150,7.000
7,106.000,0.13,3.7865,3.78660,7.000
7,106.125,0.02,3.6616,3.66165,7.000
7,106.250,0.00,3.5365,3.53660,7.000
7,106.375,-0.01,3.4115,3.41155,7.000
7,106.500,-0.01,3.2864,3.28650,7.000
7,106.625,-0.01,3.1614,3.16150,7.000
7,106.750,0.00,3.0363,3.03640,7.000
7,106.875,-0.01,2.9114,2.91145,7.000
7,107.000,-0.01,2.7863,2.78640,7.000
7,107.125,0.00,2.6613,2.66140,7.000
7,107.250,-0.01,2.5363,2.53640,7.000
7,107.375,-0.01,2.4114,2.41145,7.000
7,107.500,0.00,2.2865,2.28660,7.000
7,107.625,-0.01,2.1613,2.16140,7.000
7,107.750,-0.01,2.0362,2.03630,7.000
7,107.875,0.00,1.9112,1.91125,7.000
7,108.000,0.00,1.7861,1.78620,7.000
7,108.125,-0.01,1.6614,1.66155,7.000
7,108.250,-0.01,1.5364,1.53650,7.000
7,108.375,-0.01,1.4114,1.41150,7.000
7,108.500,-0.01,1.2864,1.28650,7.000
7,108.625,-0.01,1.1613,1.16135,7.000
7,108.750,-0.01,1.0363,1.03640,7.000
7,108.875,-0.01,0.9112,0.91125,7.000
7,109.000,-0.01,0.7862,0.78630,7.000
7,109.125,-0.01,0.6612,0.66135,7.000
7,109.250,-0.01,0.5362,0.53630,7.000
7,109.375,-0.01,0.4112,0.41130,7.000
7,109.500,-0.01,0.2863,0.28640,7.000
7,109.625,-0.01,0.1612,0.16135,7.000
7,109.750,-0.01,0.0361,0.03620,7.000
7,110.000,-0.01,-0.0004,-0.00030,7.000
7,110.125,-0.01,-0.0004,-0.00030,7.000
7,110.250,-0.01,-0.0004,-0.00030,7.000
7,110.375,-0.01,-0.0004,-0.00030,7.000
7,110.500,-0.01,-0.0004,-0.00030,7.000
7,110.625,-0.01,-0.0004,-0.00030,7.000
7,110.750,-0.01,-0.0004,-0.00030,7.000
7,110.875,-0.01,-0.0004,-0.00030,7.000
7,111.000,-0.01,-0.0004,-0.00030,7.000
7,111.125,-0.01,-0.0004,-0.00030,7.000
7,111.250,-0.01,-0.0003,-0.00020,7.000
7,111.375,-0.01,-0.0003,-0.00020,7.000
7,111.500,-0.01,-0.0003,-0.00020,7.000
7,111.625,-0.01,-0.0003,-0.00020,7.000
7,111.750,0.00,-0.0003,-0.00020,7.000
7,111.875,-0.01,-0.0003,-0.00020,7.000
7,112.000,-0.01,-0.0003,-0.00020,7.000
7,112.125,-0.01,-0.0003,-0.00020,7.000
7,112.250,-0.01,-0.0003,-0.00020,7.000
7,112.375,-0.01,-0.0003,-0.00020,7.000
7,112.500,0.00,-0.0003,-0.00020,7.000
7,112.625,-0.01,-0.0003,-0.00020,7.000
7,112.750,-0.01,-0.0003,-0.00020,7.000
7,112.875,-0.01,-0.0003,-0.00020,7.000
8,113.188,0.00,0.1059,0.10610,8.000
8,113.312,0.00,0.2309,0.23115,8.000
8,113.438,0.00,0.3560,0.35622,8.000
8,113.562,0.00,0.4810,0.48122,8.000
8,113.688,0.00,0.6062,0.60640,8.000
8,113.812,0.00,0.7312,0.73145,8.000
8,113.938,0.00,0.8562,0.85640,8.000
8,114.062,0.00,0.9811,0.98135,8.000
8,114.188,0.00,1.1061,1.10628,8.000
8,114.312,0.00,1.2310,1.23122,8.000
8,114.438,0.00,1.3562,1.35640,8.000
8,114.562,0.00,1.4811,1.48135,8.000
8,114.688,0.00,1.6064,1.60657,8.000
8,114.812,0.00,1.7311,1.73135,8.000
8,114.938,0.00,1.8562,1.85637,8.000
8,115.062,0.00,1.9812,1.98140,8.000
8,115.188,0.00,2.1062,2.10635,8.000
8,115.312,0.00,2.2311,2.23135,8.000
8,115.438,0.00,2.3562,2.35640,8.000
8,115.562,0.00,2.4812,2.48137,8.000
8,115.688,0.00,2.6063,2.60645,8.000
8,115.812,0.00,2.7313,2.73150,8.000
8,115.938,0.00,2.8564,2.85658,8.000
8,116.062,0.00,2.9814,2.98157,8.000
8,116.188,0.00,3.1063,3.10652,8.000
8,116.312,0.03,3.2312,3.23142,8.000
8,116.438,0.04,3.3562,3.35642,8.000
8,116.562,0.08,3.4812,3.48140,8.000
8,116.688,0.16,3.6063,3.60650,8.000
8,116.812,0.32,3.7313,3.73155,8.000
8,116.938,0.55,3.8564,3.85658,8.000
8,117.062,0.87,3.9814,3.98157,8.000
8,117.188,1.30,4.1062,4.10645,8.000
8,117.312,1.86,4.2313,4.23155,8.000
8,117.438,2.55,4.3562,4.35645,8.000
8,117.562,3.38,4.4813,4.48147,8.000
8,117.688,4.38,4.6062,4.60638,8.000
8,117.812,5.55,4.7312,4.73142,8.000
8,117.938,6.92,4.8563,4.85650,8.000
8,118.062,8.50,4.9813,4.98152,8.000
8,118.188,10.31,5.1064,5.10655,8.000
8,118.312,12.38,5.2314,5.23162,8.000
8,118.438,14.70,5.3563,5.35645,8.000
8,118.562,17.30,5.4813,5.48152,8.000
8,118.688,20.20,5.6064,5.60657,8.000
8,118.812,23.48,5.7312,5.73145,8.000
8,118.938,27.17,5.8563,5.85652,8.000
8,119.062,31.35,5.9813,5.98152,8.000
8,119.188,36.17,6.1064,6.10657,8.000
8,119.312,41.91,6.2313,6.23152,8.000
8,119.438,49.10,6.3564,6.35655,8.000
8,119.625,44.30,6.3546,6.35480,8.000
8,119.750,32.82,6.2296,6.22980,8.000
8,119.875,25.41,6.1047,6.10490,8.000
8,120.000,20.00,5.9798,5.98000,8.000
8,120.125,15.92,5.8547,5.85490,8.000
8,120.250,12.78,5.7297,5.72990,8.000
8,120.375,10.34,5.6046,5.60485,8.000
8,120.500,8.47,5.4796,5.47980,8.000
8,120.625,6.97,5.3545,5.35470,8.000
8,120.750,5.77,5.2296,5.22980,8.000
8,120.875,4.77,5.1046,5.10480,8.000
8,121.000,3.93,4.9797,4.97990,8.000
8,121.125,3.22,4.8546,4.85480,8.000
8,121.250,2.61,4.7295,4.72970,8.000
8,121.375,2.07,4.6044,4.60465,8.000
8,121.500,1.61,4.4794,4.47960,8.000
8,121.625,1.21,4.3544,4.35465,8.000
8,121.750,0.88,4.2295,4.22970,8.000
8,121.875,0.60,4.1044,4.10465,8.000
8,122.000,0.38,3.9794,3.97960,8.000
8,122.125,0.21,3.8545,3.85465,8.000
8,122.250,0.08,3.7294,3.72960,8.000
8,122.375,0.01,3.6044,3.60465,8.000
8,122.500,0.00,3.4793,3.47950,8.000
8,122.625,0.00,3.3544,3.35455,8.000
8,122.750,0.00,3.2294,3.22960,8.000
8,122.875,0.00,3.1044,3.10465,8.000
8,123.000,0.00,2.9795,2.97970,8.000
8,123.125,0.00,2.8545,2.85465,8.000
8,123.250,0.00,2.7295,2.72970,8.000
8,123.375,0.00,2.6043,2.60450,8.000
8,123.500,0.00,2.4792,2.47940,8.000
8,123.625,0.00,2.3543,2.35450,8.000
8,123.750,0.00,2.2293,2.22950,8.000
8,123.875,0.00,2.1043,2.10450,8.000
8,124.000,0.00,1.9793,1.97950,8.000
8,124.125,0.00,1.8542,1.85440,8.000
8,124.250,0.00,1.7294,1.72960,8.000
8,124.375,0.00,1.6045,1.60470,8.000
8,124.500,0.00,1.4792,1.47940,8.000
8,124.625,0.00,1.3543,1.35450,8.000
8,124.750,0.00,1.2292,1.22940,8.000
8,124.875,0.00,1.1043,1.10445,8.000
8,125.000,0.00,0.9792,0.97940,8.000
8,125.125,0.00,0.8543,0.85450,8.000
8,125.250,0.00,0.7294,0.72960,8.000
8,125.375,0.00,0.6043,0.60450,8.000
8,125.500,-0.01,0.4791,0.47930,8.000
8,125.625,0.00,0.3542,0.35440,8.000
8,125.750,0.00,0.2290,0.22920,8.000
8,125.875,0.00,0.1041,0.10430,8.000
8,126.000,0.00,-0.0208,-0.02060,8.000
8,126.188,0.00,-0.0004,-0.00020,8.000
8,126.312,0.00,-0.0004,-0.00020,8.000
8,126.438,0.00,-0.0004,-0.00020,8.000
8,126.562,0.00,-0.0004,-0.00020,8.000
8,126.688,0.00,-0.0004,-0.00020,8.000
8,126.812,0.00,-0.0004,-0.00020,8.000
8,126.938,0.00,-0.0004,-0.00020,8.000
8,127.062,0.00,-0.0004,-0.00020,8.000
8,127.188,0.00,-0.0004,-0.00020,8.000
8,127.312,0.00,-0.0004,-0.00020,8.000
8,127.438,0.00,-0.0003,-0.00010,8.000
8,127.562,0.00,-0.0003,-0.00010,8.000
8,127.688,0.00,-0.0003,-0.00010,8.000
8,127.812,0.00,-0.0003,-0.00010,8.000
8,127.938,0.00,-0.0003,-0.00010,8.000
8,128.062,0.00,-0.0003,-0.00010,8.000
8,128.188,0.00,-0.0003,-0.00010,8.000
8,128.312,0.00,-0.0003,-0.00010,8.000
8,128.438,0.00,-0.0003,-0.00010,8.000
8,128.562,0.00,-0.0003,-0.00010,8.000
8,128.688,0.00,-0.0003,-0.00010,8.000
8,128.812,0.00,-0.0003,-0.00010,8.000
8,128.938,0.00,-0.0003,-0.00010,8.000
8,129.062,0.00,-0.0003,-0.00010,8.000
9,129.438,-0.01,0.1361,0.13618,9.000
9,129.562,-0.01,0.2611,0.26120,9.000
9,129.688,0.00,0.3860,0.38615,9.000
9,129.812,0.00,0.5110,0.51110,9.000
9,129.938,-0.01,0.6361,0.63620,9.000
9,130.062,-0.01,0.7610,0.76115,9.000
9,130.188,0.00,0.8861,0.88622,9.000
9,130.312,-0.01,1.0113,1.01138,9.000
9,130.438,-0.01,1.1362,1.13628,9.000
9,130.562,-0.01,1.2612,1.26132,9.000
9,130.688,-0.01,1.3862,1.38628,9.000
9,130.812,-0.01,1.5111,1.51123,9.000
9,130.938,-0.01,1.6362,1.63635,9.000
9,131.062,-0.01,1.7611,1.76118,9.000
9,131.188,0.00,1.8861,1.88620,9.000
9,131.312,-0.01,2.0112,2.01130,9.000
9,131.438,0.00,2.1362,2.13633,9.000
9,131.562,-0.01,2.2614,2.26145,9.000
9,131.688,-0.01,2.3862,2.38635,9.000
9,131.812,-0.01,2.5112,2.51130,9.000
9,131.938,0.00,2.6361,2.63623,9.000
9,132.062,-0.01,2.7612,2.76130,9.000
9,132.188,0.00,2.8862,2.88630,9.000
9,132.312,-0.01,3.0113,3.01140,9.000
9,132.438,0.00,3.1364,3.13648,9.000
9,132.562,0.02,3.2613,3.26140,9.000
9,132.688,0.04,3.3862,3.38635,9.000
9,132.812,0.09,3.5113,3.51140,9.000
9,132.938,0.18,3.6363,3.63643,9.000
9,133.062,0.36,3.7613,3.76140,9.000
9,133.188,0.61,3.8862,3.88633,9.000
9,133.312,0.95,4.0113,4.01142,9.000
9,133.438,1.41,4.1363,4.13640,9.000
9,133.562,1.99,4.2614,4.26150,9.000
9,133.688,2.71,4.3863,4.38642,9.000
9,133.812,3.57,4.5113,4.51137,9.000
9,133.938,4.60,4.6362,4.63632,9.000
9,134.062,5.82,4.7613,4.76137,9.000
9,134.188,7.24,4.8863,4.88637,9.000
9,134.312,8.87,5.0113,5.01142,9.000
9,134.438,10.73,5.1363,5.13642,9.000
9,134.562,12.85,5.2614,5.26150,9.000
9,134.688,15.23,5.3863,5.38643,9.000
9,134.812,17.88,5.5115,5.51162,9.000
9,134.938,20.86,5.6364,5.63645,9.000
9,135.062,24.21,5.7611,5.76122,9.000
9,135.188,27.98,5.8863,5.88640,9.000
9,135.312,32.28,6.0114,6.01150,9.000
9,135.438,37.23,6.1364,6.13648,9.000
9,135.562,43.19,6.2614,6.26148,9.000
9,135.688,50.76,6.3865,6.38660,9.000
9,135.875,39.19,6.3047,6.30480,9.000
9,136.000,29.68,6.1798,6.17990,9.000
9,136.125,23.15,6.0547,6.05480,9.000
9,136.250,18.32,5.9296,5.92970,9.000
9,136.375,14.63,5.8046,5.80465,9.000
9,136.500,11.77,5.6795,5.67960,9.000
9,136.625,9.56,5.5547,5.55480,9.000
9,136.750,7.83,5.4296,5.42970,9.000
9,136.875,6.46,5.3046,5.30470,9.000
9,137.000,5.33,5.1797,5.17980,9.000
9,137.125,4.40,5.0546,5.05465,9.000
9,137.250,3.62,4.9296,4.92970,9.000
9,137.375,2.94,4.8045,4.80460,9.000
9,137.500,2.37,4.6794,4.67950,9.000
9,137.625,1.86,4.5545,4.55460,9.000
9,137.750,1.43,4.4295,4.42960,9.000
9,137.875,1.06,4.3046,4.30465,9.000
9,138.000,0.75,4.1795,4.17960,9.000
9,138.125,0.49,4.0545,4.05460,9.000
9,138.250,0.29,3.9294,3.92950,9.000
9,138.375,0.14,3.8044,3.80450,9.000
9,138.500,0.03,3.6794,3.67950,9.000
9,138.625,-0.01,3.5544,3.55455,9.000
9,138.750,-0.01,3.4295,3.42960,9.000
9,138.875,-0.01,3.3044,3.30450,9.000
9,139.000,-0.01,3.1795,3.17960,9.000
9,139.125,-0.01,3.0545,3.05460,9.000
9,139.250,-0.01,2.9295,2.92960,9.000
9,139.375,-0.01,2.8044,2.80445,9.000
9,139.500,-0.01,2.6792,2.67930,9.000
9,139.625,-0.01,2.5542,2.55435,9.000
9,139.750,-0.01,2.4292,2.42930,9.000
9,139.875,-0.01,2.3044,2.30455,9.000
9,140.000,-0.01,2.1793,2.17940,9.000
9,140.125,-0.01,2.0544,2.05450,9.000
9,140.250,-0.01,1.9294,1.92950,9.000
9,140.375,-0.01,1.8042,1.80425,9.000
9,140.500,-0.01,1.6793,1.67940,9.000
9,140.625,-0.01,1.5543,1.55440,9.000
9,140.750,-0.01,1.4293,1.42940,9.000
9,140.875,-0.01,1.3043,1.30440,9.000
9,141.000,-0.01,1.1793,1.17940,9.000
9,141.125,0.00,1.0544,1.05450,9.000
9,141.250,-0.01,0.9292,0.92930,9.000
9,141.375,-0.01,0.8042,0.80435,9.000
9,141.500,-0.01,0.6793,0.67940,9.000
9,141.625,-0.01,0.5542,0.55425,9.000
9,141.750,-0.01,0.4291,0.42920,9.000
9,141.875,-0.01,0.3042,0.30425,9.000
9,142.000,-0.01,0.1792,0.17930,9.000
9,142.125,-0.01,0.0542,0.05430,9.000
9,142.312,-0.01,-0.0011,-0.00098,9.000
9,142.438,-0.01,-0.0004,-0.00030,9.000
9,142.562,0.00,-0.0004,-0.00030,9.000
9,142.688,-0.01,-0.0004,-0.00030,9.000
9,142.812,0.00,-0.0004,-0.00030,9.000
9,142.938,-0.01,-0.0004,-0.00030,9.000
9,143.062,-0.01,-0.0004,-0.00030,9.000
9,143.188,-0.01,-0.0004,-0.00030,9.000
9,143.312,-0.01,-0.0004,-0.00030,9.000
9,143.438,-0.01,-0.0004,-0.00030,9.000
9,143.562,-0.01,-0.0004,-0.00030,9.000
9,143.688,-0.01,-0.0003,-0.00020,9.000
9,143.812,0.00,-0.0003,-0.00020,9.000
9,143.938,-0.01,-0.0003,-0.00020,9.000
9,144.062,-0.01,-0.0003,-0.00020,9.000
9,144.188,-0.01,-0.0003,-0.00020,9.000
9,144.312,-0.01,-0.0003,-0.00020,9.000
9,144.438,-0.01,-0.0003,-0.00020,9.000
9,144.562,-0.01,-0.0003,-0.00020,9.000
9,144.688,-0.01,-0.0003,-0.00020,9.000
9,144.812,-0.01,-0.0003,-0.00020,9.000
9,144.938,-0.01,-0.0003,-0.00020,9.000
9,145.062,-0.01,-0.0003,-0.00020,9.000
9,145.188,-0.01,-0.0003,-0.00020,9.000
10,145.562,0.01,0.0911,0.09120,10.000
10,145.688,0.01,0.2161,0.21618,10.000
10,145.812,0.01,0.3411,0.34118,10.000
10,145.938,0.01,0.4660,0.46612,10.000
10,146.062,0.01,0.5911,0.59118,10.000
10,146.188,0.01,0.7162,0.71625,10.000
10,146.312,0.01,0.8411,0.84120,10.000
10,146.438,0.01,0.9662,0.96632,10.000
10,146.562,0.01,1.0912,1.09135,10.000
10,146.688,0.01,1.2162,1.21630,10.000
10,146.812,0.01,1.3414,1.34145,10.000
10,146.938,0.01,1.4662,1.46628,10.000
10,147.062,0.01,1.5913,1.59140,10.000
10,147.188,0.01,1.7161,1.71622,10.000
10,147.312,0.02,1.8410,1.84113,10.000
10,147.438,0.01,1.9661,1.96622,10.000
10,147.562,0.01,2.0912,2.09130,10.000
10,147.688,0.01,2.2163,2.21640,10.000
10,147.812,0.01,2.3414,2.34148,10.000
10,147.938,0.01,2.4662,2.46630,10.000
10,148.062,0.01,2.5912,2.59135,10.000
10,148.188,0.01,2.7162,2.71630,10.000
10,148.312,0.01,2.8412,2.84128,10.000
10,148.438,0.01,2.9662,2.96630,10.000
10,148.562,0.01,3.0914,3.09150,10.000
10,148.688,0.03,3.2163,3.21640,10.000
10,148.812,0.05,3.3413,3.34140,10.000
10,148.938,0.08,3.4664,3.46648,10.000
10,149.062,0.16,3.5914,3.59153,10.000
10,149.188,0.30,3.7162,3.71635,10.000
10,149.312,0.52,3.8412,3.84133,10.000
10,149.438,0.83,3.9663,3.96640,10.000
10,149.562,1.25,4.0913,4.09140,10.000
10,149.688,1.79,4.2163,4.21640,10.000
10,149.812,2.45,4.3413,4.34142,10.000
10,149.938,3.27,4.4664,4.46648,10.000
10,150.062,4.23,4.5914,4.59148,10.000
10,150.188,5.39,4.7163,4.71635,10.000
10,150.312,6.72,4.8413,4.84135,10.000
10,150.438,8.27,4.9663,4.96637,10.000
10,150.562,10.04,5.0913,5.09140,10.000
10,150.688,12.07,5.2164,5.21648,10.000
10,150.812,14.35,5.3414,5.34148,10.000
10,150.938,16.90,5.4665,5.46658,10.000
10,151.062,19.75,5.5915,5.59163,10.000
10,151.188,22.95,5.7163,5.71642,10.000
10,151.312,26.57,5.8412,5.84132,10.000
10,151.438,30.66,5.9664,5.96648,10.000
10,151.562,35.35,6.0913,6.09142,10.000
10,151.688,40.92,6.2162,6.21635,10.000
10,151.812,47.80,6.3415,6.34158,10.000
10,152.000,45.17,6.3616,6.36170,10.000
10,152.125,33.29,6.2366,6.23670,10.000
10,152.250,25.70,6.1117,6.11180,10.000
10,152.375,20.22,5.9867,5.98680,10.000
10,152.500,16.08,5.8618,5.86190,10.000
10,152.625,12.90,5.7366,5.73675,10.000
10,152.750,10.45,5.6117,5.61180,10.000
10,152.875,8.54,5.4867,5.48675,10.000
10,153.000,7.03,5.3614,5.36150,10.000
10,153.125,5.81,5.2366,5.23670,10.000
10,153.250,4.80,5.1116,5.11170,10.000
10,153.375,3.96,4.9866,4.98670,10.000
10,153.500,3.25,4.8617,4.86180,10.000
10,153.625,2.63,4.7366,4.73665,10.000
10,153.750,2.09,4.6116,4.61170,10.000
10,153.875,1.63,4.4864,4.48655,10.000
10,154.000,1.23,4.3613,4.36140,10.000
10,154.125,0.89,4.2365,4.23660,10.000
10,154.250,0.61,4.1114,4.11150,10.000
10,154.375,0.39,3.9864,3.98655,10.000
10,154.500,0.21,3.8615,3.86160,10.000
10,154.625,0.09,3.7365,3.73660,10.000
10,154.750,0.01,3.6115,3.61160,10.000
10,154.875,0.01,3.4864,3.48645,10.000
10,155.000,0.01,3.3613,3.36140,10.000
10,155.125,0.01,3.2363,3.23640,10.000
10,155.250,0.01,3.1115,3.11160,10.000
10,155.375,0.01,2.9865,2.98660,10.000
10,155.500,0.01,2.8615,2.86160,10.000
10,155.625,0.01,2.7364,2.73650,10.000
10,155.750,0.01,2.6114,2.61150,10.000
10,155.875,0.01,2.4862,2.48635,10.000
10,156.000,0.01,2.3613,2.36140,10.000
10,156.125,0.01,2.2363,2.23640,10.000
10,156.250,0.01,2.1112,2.11130,10.000
10,156.375,0.01,1.9862,1.98635,10.000
10,156.500,0.01,1.8612,1.86130,10.000
10,156.625,0.01,1.7363,1.73640,10.000
10,156.750,0.01,1.6115,1.61160,10.000
10,156.875,0.01,1.4863,1.48640,10.000
10,157.000,0.01,1.3613,1.36140,10.000
10,157.125,0.01,1.2362,1.23630,10.000
10,157.250,0.01,1.1113,1.11140,10.000
10,157.375,0.01,0.9863,0.98640,10.000
10,157.500,0.01,0.8612,0.86130,10.000
10,157.625,0.01,0.7364,0.73645,10.000
10,157.750,0.01,0.6114,0.61150,10.000
10,157.875,0.01,0.4862,0.48630,10.000
10,158.000,0.01,0.3612,0.36130,10.000
10,158.125,0.01,0.2362,0.23630,10.000
10,158.250,0.01,0.1110,0.11110,10.000
10,158.375,0.01,-0.0139,-0.01380,10.000
10,158.562,0.01,-0.0005,-0.00040,10.000
10,158.688,0.01,-0.0004,-0.00030,10.000
10,158.812,0.01,-0.0004,-0.00030,10.000
10,158.938,0.01,-0.0004,-0.00030,10.000
10,159.062,0.01,-0.0004,-0.00030,10.000
10,159.188,0.01,-0.0004,-0.00030,10.000
10,159.312,0.01,-0.0004,-0.00030,10.000
10,159.438,0.01,-0.0004,-0.00030,10.000
10,159.562,0.01,-0.0004,-0.00030,10.000
10,159.688,0.01,-0.0004,-0.00030,10.000
10,159.812,0.01,-0.0004,-0.00030,10.000
10,159.938,0.01,-0.0004,-0.00030,10.000
10,160.062,0.01,-0.0004,-0.00028,10.000
10,160.188,0.01,-0.0003,-0.00020,10.000
10,160.312,0.01,-0.0003,-0.00020,10.000
10,160.438,0.01,-0.0003,-0.00020,10.000
10,160.562,0.01,-0.0003,-0.00020,10.000
10,160.688,0.01,-0.0003,-0.00020,10.000
10,160.812,0.01,-0.0003,-0.00020,10.000
10,160.938,0.01,-0.0003,-0.00020,10.000