File: calibDATA_loadcell/date_02:22:2018/Instron/50N_0_1_2_0.txt
""
"Test Method","Radhen_Load_Cntrl_Cmprsn_250N_12-7.msm"
"Sample I. D.","Sample1.mss"
"Specimen Number","7"

"TheCycle_Output ()","_Time (s)","_Load (N)","_Extension (mm)","RealTimeDepth (mm)","CycleNumber ()"

1,0.312,0.00,0.0697,0.06970,1.000
1,0.438,0.00,0.1947,0.19470,1.000
1,0.562,0.00,0.3198,0.31980,1.000
1,0.688,0.00,0.4450,0.44497,1.000
1,0.812,0.00,0.5700,0.56998,1.000
1,0.938,0.00,0.6951,0.69507,1.000
1,1.062,0.00,0.8200,0.81998,1.000
1,1.188,0.00,0.9450,0.94505,1.000
1,1.312,0.00,1.0699,1.06990,1.000
1,1.438,0.00,1.1949,1.19488,1.000
1,1.562,0.00,1.3200,1.32000,1.000
1,1.688,0.00,1.4450,1.44500,1.000
1,1.812,0.00,1.5701,1.57010,1.000
1,1.938,0.00,1.6952,1.69518,1.000
1,2.062,0.00,1.8200,1.82000,1.000
1,2.188,0.00,1.9450,1.94498,1.000
1,2.312,0.00,2.0701,2.07008,1.000
1,2.438,0.00,2.1951,2.19508,1.000
1,2.562,0.02,2.3200,2.32002,1.000
1,2.688,0.07,2.4452,2.44515,1.000
1,2.812,0.14,2.5702,2.57015,1.000
1,2.938,0.29,2.6952,2.69522,1.000
1,3.062,0.51,2.8202,2.82015,1.000
1,3.188,0.81,2.9453,2.94530,1.000
1,3.312,1.22,3.0702,3.07018,1.000
1,3.438,1.72,3.1951,3.19512,1.000
1,3.562,2.34,3.3200,3.32005,1.000
1,3.688,3.09,3.4452,3.44518,1.000
1,3.812,3.98,3.5702,3.57020,1.000
1,3.938,5.01,3.6952,3.69520,1.000
1,4.062,6.19,3.8203,3.82027,1.000
1,4.188,7.55,3.9452,3.94515,1.000
1,4.312,9.10,4.0702,4.07015,1.000
1,4.438,10.87,4.1951,4.19510,1.000
1,4.562,12.86,4.3202,4.32020,1.000
1,4.688,15.09,4.4452,4.44518,1.000
1,4.812,17.61,4.5702,4.57022,1.000
1,4.938,20.46,4.6952,4.69520,1.000
1,5.062,23.69,4.8203,4.82032,1.000
1,5.188,27.34,4.9454,4.94538,1.000
1,5.312,31.57,5.0702,5.07018,1.000
1,5.438,36.47,5.1952,5.19520,1.000
1,5.562,42.29,5.3202,5.32022,1.000
1,5.688,49.09,5.4452,5.44518,1.000
1,5.875,41.30,5.4236,5.42355,1.000
1,6.000,30.62,5.2986,5.29860,1.000
1,6.125,23.72,5.1736,5.17355,1.000
1,6.250,18.69,5.0486,5.04860,1.000
1,6.375,14.86,4.9236,4.92360,1.000
1,6.500,11.87,4.7985,4.79850,1.000
1,6.625,9.57,4.6735,4.67350,1.000
1,6.750,7.77,4.5486,4.54860,1.000
1,6.875,6.38,4.4236,4.42360,1.000
1,7.000,5.29,4.2986,4.29860,1.000
1,7.125,4.43,4.1735,4.17350,1.000
1,7.250,3.74,4.0485,4.04850,1.000
1,7.375,3.14,3.9234,3.92340,1.000
1,7.500,2.59,3.7983,3.79830,1.000
1,7.625,2.09,3.6735,3.67345,1.000
1,7.750,1.66,3.5485,3.54850,1.000
1,7.875,1.27,3.4234,3.42340,1.000
1,8.000,0.93,3.2984,3.29840,1.000
1,8.125,0.65,3.1735,3.17345,1.000
1,8.250,0.42,3.0485,3.04850,1.000
1,8.375,0.24,2.9234,2.92335,1.000
1,8.500,0.12,2.7983,2.79830,1.000
1,8.625,0.05,2.6733,2.67325,1.000
1,8.750,0.03,2.5484,2.54840,1.000
1,8.875,0.01,2.4235,2.42350,1.000
1,9.000,0.00,2.2984,2.29840,1.000
1,9.125,0.00,2.1734,2.17335,1.000
1,9.250,0.00,2.0484,2.04840,1.000
1,9.375,0.00,1.9233,1.92330,1.000
1,9.500,0.00,1.7982,1.79820,1.000
1,9.625,0.00,1.6733,1.67330,1.000
1,9.750,0.00,1.5481,1.54810,1.000
1,9.875,0.00,1.4233,1.42325,1.000
1,10.000,-0.01,1.2984,1.29840,1.000
1,10.125,0.00,1.1733,1.17325,1.000
1,10.250,0.00,1.0485,1.04850,1.000
1,10.375,0.00,0.9234,0.92340,1.000
1,10.500,0.00,0.7983,0.79830,1.000
1,10.625,0.00,0.6733,0.67325,1.000
1,10.750,0.00,0.5481,0.54810,1.000
1,10.875,0.00,0.4233,0.42325,1.000
1,11.000,0.00,0.2981,0.29810,1.000
1,11.125,0.00,0.1732,0.17320,1.000
1,11.250,0.00,0.0483,0.04830,1.000
1,11.500,0.00,-0.0003,-0.00030,1.000
1,11.625,0.00,-0.0003,-0.00030,1.000
1,11.750,0.00,-0.0003,-0.00030,1.000
1,11.875,0.00,-0.0003,-0.00030,1.000
1,12.000,0.00,-0.0003,-0.00030,1.000
1,12.125,0.00,-0.0003,-0.00030,1.000
1,12.250,-0.01,-0.0003,-0.00030,1.000
1,12.375,0.00,-0.0003,-0.00030,1.000
1,12.500,0.00,-0.0003,-0.00030,1.000
1,12.625,0.00,-0.0003,-0.00030,1.000
1,12.750,0.00,-0.0002,-0.00020,1.000
1,12.875,0.00,-0.0002,-0.00020,1.000
1,13.000,0.00,-0.0002,-0.00020,1.000
1,13.125,0.00,-0.0002,-0.00020,1.000
1,13.250,0.00,-0.0002,-0.00020,1.000
1,13.375,0.00,-0.0002,-0.00020,1.000
1,13.500,0.00,-0.0002,-0.00020,1.000
1,13.625,-0.01,-0.0002,-0.00020,1.000
1,13.750,-0.01,-0.0002,-0.00020,1.000
1,13.875,0.00,-0.0002,-0.00020,1.000
1,14.000,0.00,-0.0002,-0.00020,1.000
1,14.125,0.00,-0.0002,-0.00020,1.000
1,14.250,0.00,-0.0002,-0.00020,1.000
1,14.375,0.00,-0.0002,-0.00020,1.000
2,14.750,0.00,0.1575,0.15760,2.000
2,14.875,0.00,0.2825,0.28265,2.000
2,15.000,0.00,0.4077,0.40780,2.000
2,15.125,0.00,0.5326,0.53275,2.000
2,15.250,0.01,0.6576,0.65770,2.000
2,15.375,0.00,0.7826,0.78275,2.000
2,15.500,0.00,0.9075,0.90760,2.000
2,15.625,0.00,1.0326,1.03275,2.000
2,15.750,0.00,1.1575,1.15760,2.000
2,15.875,0.00,1.2825,1.28265,2.000
2,16.000,0.00,1.4077,1.40780,2.000
2,16.125,0.00,1.5326,1.53275,2.000
2,16.250,0.00,1.6578,1.65790,2.000
2,16.375,0.00,1.7826,1.78270,2.000
2,16.500,0.00,1.9075,1.90760,2.000
2,16.625,0.00,2.0326,2.03270,2.000
2,16.750,0.00,2.1576,2.15770,2.000
2,16.875,0.01,2.2827,2.28275,2.000
2,17.000,0.04,2.4077,2.40780,2.000
2,17.125,0.09,2.5328,2.53285,2.000
2,17.250,0.19,2.6577,2.65780,2.000
2,17.375,0.36,2.7828,2.78285,2.000
2,17.500,0.62,2.9078,2.90790,2.000
2,17.625,0.97,3.0328,3.03295,2.000
2,17.750,1.43,3.1577,3.15780,2.000
2,17.875,1.99,3.2827,3.28280,2.000
2,18.000,2.68,3.4078,3.40790,2.000
2,18.125,3.52,3.5328,3.53285,2.000
2,18.250,4.50,3.6579,3.65800,2.000
2,18.375,5.62,3.7828,3.78295,2.000
2,18.500,6.91,3.9078,3.90790,2.000
2,18.625,8.40,4.0328,4.03285,2.000
2,18.750,10.09,4.1576,4.15770,2.000
2,18.875,11.99,4.2828,4.28285,2.000
2,19.000,14.12,4.4078,4.40790,2.000
2,19.125,16.50,4.5328,4.53290,2.000
2,19.250,19.16,4.6578,4.65790,2.000
2,19.375,22.18,4.7828,4.78295,2.000
2,19.500,25.60,4.9080,4.90810,2.000
2,19.625,29.49,5.0328,5.03290,2.000
2,19.750,33.98,5.1577,5.15780,2.000
2,19.875,39.35,5.2828,5.28290,2.000
2,20.000,45.87,5.4077,5.40780,2.000
2,20.188,50.40,5.5008,5.50093,2.000
2,20.312,35.44,5.3762,5.37635,2.000
2,20.438,27.00,5.2512,5.25130,2.000
2,20.562,21.10,5.1260,5.12610,2.000
2,20.688,16.71,5.0010,5.00113,2.000
2,20.812,13.32,4.8762,4.87627,2.000
2,20.938,10.68,4.7511,4.75115,2.000
2,21.062,8.63,4.6261,4.62622,2.000
2,21.188,7.03,4.5012,4.50130,2.000
2,21.312,5.80,4.3761,4.37620,2.000
2,21.438,4.82,4.2510,4.25113,2.000
2,21.562,4.05,4.1260,4.12612,2.000
2,21.688,3.42,4.0009,4.00098,2.000
2,21.812,2.85,3.8759,3.87602,2.000
2,21.938,2.33,3.7510,3.75113,2.000
2,22.062,1.87,3.6260,3.62612,2.000
2,22.188,1.47,3.5010,3.50105,2.000
2,22.312,1.10,3.3760,3.37610,2.000
2,22.438,0.79,3.2510,3.25108,2.000
2,22.562,0.53,3.1260,3.12612,2.000
2,22.688,0.32,3.0009,3.00098,2.000
2,22.812,0.18,2.8758,2.87592,2.000
2,22.938,0.08,2.7509,2.75098,2.000
2,23.062,0.03,2.6258,2.62590,2.000
2,23.188,0.02,2.5010,2.50108,2.000
2,23.312,0.01,2.3760,2.37610,2.000
2,23.438,0.00,2.2509,2.25098,2.000
2,23.562,0.01,2.1259,2.12605,2.000
2,23.688,0.01,2.0007,2.00083,2.000
2,23.812,0.01,1.8757,1.87577,2.000
2,23.938,0.00,1.7508,1.75093,2.000
2,24.062,0.00,1.6258,1.62593,2.000
2,24.188,0.00,1.5009,1.50095,2.000
2,24.312,0.01,1.3759,1.37600,2.000
2,24.438,0.00,1.2509,1.25095,2.000
2,24.562,0.01,1.1258,1.12588,2.000
2,24.688,0.00,1.0009,1.00103,2.000
2,24.812,0.00,0.8757,0.87583,2.000
2,24.938,0.00,0.7508,0.75090,2.000
2,25.062,0.00,0.6258,0.62590,2.000
2,25.188,0.00,0.5008,0.50093,2.000
2,25.312,0.00,0.3758,0.37593,2.000
2,25.438,0.00,0.2507,0.25080,2.000
2,25.562,0.01,0.1258,0.12588,2.000
2,25.688,0.00,0.0008,0.00093,2.000
2,25.875,0.00,-0.0004,-0.00030,2.000
2,26.000,0.00,-0.0002,-0.00010,2.000
2,26.125,0.01,-0.0002,-0.00010,2.000
2,26.250,0.00,-0.0002,-0.00010,2.000
2,26.375,0.00,-0.0002,-0.00010,2.000
2,26.500,0.00,-0.0002,-0.00010,2.000
2,26.625,0.00,-0.0002,-0.00010,2.000
2,26.750,0.00,-0.0002,-0.00010,2.000
2,26.875,0.00,-0.0002,-0.00010,2.000
2,27.000,0.00,-0.0002,-0.00010,2.000
2,27.125,0.01,-0.0002,-0.00010,2.000
2,27.250,0.00,-0.0002,-0.00010,2.000
2,27.375,0.00,-0.0002,-0.00010,2.000
2,27.500,0.01,-0.0002,-0.00010,2.000
2,27.625,0.00,-0.0002,-0.00010,2.000
2,27.750,0.01,-0.0002,-0.00010,2.000
2,27.875,0.00,-0.0002,-0.00010,2.000
2,28.000,0.00,-0.0002,-0.00010,2.000
2,28.125,0.00,-0.0002,-0.00010,2.000
2,28.250,0.00,-0.0002,-0.00010,2.000
2,28.375,0.00,-0.0002,-0.00010,2.000
2,28.500,0.00,-0.0002,-0.00010,2.000
2,28.625,0.00,-0.0002,-0.00010,2.000
2,28.750,0.01,-0.0002,-0.00010,2.000
3,29.125,0.00,0.1335,0.13355,3.000
3,29.250,0.00,0.2586,0.25870,3.000
3,29.375,0.01,0.3836,0.38370,3.000
3,29.500,0.00,0.5084,0.50850,3.000
3,29.625,0.01,0.6335,0.63360,3.000
3,29.750,0.01,0.7586,0.75870,3.000
3,29.875,0.00,0.8836,0.88370,3.000
3,30.000,0.00,1.0088,1.00890,3.000
3,30.125,0.01,1.1336,1.13370,3.000
3,30.250,0.00,1.2587,1.25880,3.000
3,30.375,0.00,1.3836,1.38370,3.000
3,30.500,0.00,1.5085,1.50860,3.000
3,30.625,0.00,1.6337,1.63380,3.000
3,30.750,0.01,1.7586,1.75870,3.000
3,30.875,0.00,1.8836,1.88370,3.000
3,31.000,0.00,2.0086,2.00870,3.000
3,31.125,0.00,2.1338,2.13385,3.000
3,31.250,0.00,2.2587,2.25880,3.000
3,31.375,0.03,2.3838,2.38390,3.000
3,31.500,0.07,2.5088,2.50890,3.000
3,31.625,0.15,2.6336,2.63375,3.000
3,31.750,0.31,2.7587,2.75880,3.000
3,31.875,0.55,2.8837,2.88380,3.000
3,32.000,0.88,3.0089,3.00900,3.000
3,32.125,1.31,3.1338,3.13395,3.000
3,32.250,1.85,3.2587,3.25880,3.000
3,32.375,2.51,3.3838,3.38385,3.000
3,32.500,3.32,3.5088,3.50890,3.000
3,32.625,4.27,3.6338,3.63385,3.000
3,32.750,5.36,3.7587,3.75880,3.000
3,32.875,6.62,3.8837,3.88380,3.000
3,33.000,8.05,4.0087,4.00880,3.000
3,33.125,9.70,4.1337,4.13380,3.000
3,33.250,11.56,4.2588,4.25890,3.000
3,33.375,13.64,4.3839,4.38395,3.000
3,33.500,15.99,4.5089,4.50900,3.000
3,33.625,18.58,4.6338,4.63385,3.000
3,33.750,21.51,4.7587,4.75880,3.000
3,33.875,24.82,4.8838,4.88385,3.000
3,34.000,28.58,5.0088,5.00890,3.000
3,34.125,32.92,5.1337,5.13380,3.000
3,34.250,38.03,5.2589,5.25900,3.000
3,34.375,44.24,5.3839,5.38395,3.000
3,34.562,51.56,5.5063,5.50635,3.000
3,34.688,36.30,5.3822,5.38227,3.000
3,34.812,27.54,5.2572,5.25733,3.000
3,34.938,21.49,5.1320,5.13215,3.000
3,35.062,17.01,5.0070,5.00713,3.000
3,35.188,13.56,4.8820,4.88212,3.000
3,35.312,10.87,4.7570,4.75705,3.000
3,35.438,8.77,4.6320,4.63210,3.000
3,35.562,7.13,4.5072,4.50728,3.000
3,35.688,5.86,4.3821,4.38220,3.000
3,35.812,4.86,4.2572,4.25725,3.000
3,35.938,4.07,4.1319,4.13205,3.000
3,36.062,3.43,4.0070,4.00705,3.000
3,36.188,2.86,3.8819,3.88197,3.000
3,36.312,2.34,3.7569,3.75703,3.000
3,36.438,1.87,3.6320,3.63207,3.000
3,36.562,1.47,3.5069,3.50700,3.000
3,36.688,1.11,3.3820,3.38207,3.000
3,36.812,0.79,3.2569,3.25700,3.000
3,36.938,0.52,3.1319,3.13202,3.000
3,37.062,0.33,3.0071,3.00715,3.000
3,37.188,0.18,2.8818,2.88195,3.000
3,37.312,0.09,2.7568,2.75693,3.000
3,37.438,0.03,2.6318,2.63187,3.000
3,37.562,0.02,2.5070,2.50710,3.000
3,37.688,0.01,2.3820,2.38210,3.000
3,37.812,0.00,2.2568,2.25693,3.000
3,37.938,0.01,2.1320,2.13207,3.000
3,38.062,0.00,2.0068,2.00688,3.000
3,38.188,0.01,1.8817,1.88182,3.000
3,38.312,0.00,1.7567,1.75683,3.000
3,38.438,0.01,1.6317,1.63185,3.000
3,38.562,0.00,1.5068,1.50690,3.000
3,38.688,0.01,1.3818,1.38192,3.000
3,38.812,0.01,1.2568,1.25685,3.000
3,38.938,0.00,1.1318,1.13195,3.000
3,39.062,0.00,1.0069,1.00700,3.000
3,39.188,0.00,0.8818,0.88190,3.000
3,39.312,0.00,0.7568,0.75690,3.000
3,39.438,0.01,0.6317,0.63180,3.000
3,39.562,0.01,0.5068,0.50688,3.000
3,39.688,0.01,0.3818,0.38190,3.000
3,39.812,0.00,0.2568,0.25690,3.000
3,39.938,0.00,0.1318,0.13190,3.000
3,40.062,0.00,0.0068,0.00690,3.000
3,40.250,0.01,-0.0003,-0.00020,3.000
3,40.375,0.00,-0.0003,-0.00020,3.000
3,40.500,0.01,-0.0003,-0.00020,3.000
3,40.625,0.00,-0.0003,-0.00020,3.000
3,40.750,0.01,-0.0003,-0.00020,3.000
3,40.875,0.00,-0.0003,-0.00020,3.000
3,41.000,0.00,-0.0003,-0.00020,3.000
3,41.125,0.00,-0.0003,-0.00020,3.000
3,41.250,0.00,-0.0003,-0.00020,3.000
3,41.375,0.00,-0.0003,-0.00020,3.000
3,41.500,0.01,-0.0002,-0.00010,3.000
3,41.625,0.01,-0.0002,-0.00010,3.000
3,41.750,0.01,-0.0002,-0.00010,3.000
3,41.875,0.00,-0.0002,-0.00010,3.000
3,42.000,0.00,-0.0002,-0.00010,3.000
3,42.125,0.00,-0.0002,-0.00010,3.000
3,42.250,0.00,-0.0002,-0.00010,3.000
3,42.375,0.01,-0.0002,-0.00010,3.000
3,42.500,0.00,-0.0002,-0.00010,3.000
3,42.625,0.00,-0.0002,-0.00010,3.000
3,42.750,0.00,-0.0002,-0.00010,3.000
3,42.875,0.00,-0.0002,-0.00010,3.000
3,43.000,0.00,-0.0002,-0.00010,3.000
3,43.125,0.00,-0.0002,-0.00010,3.000
4,43.500,0.00,0.1366,0.13670,4.000
4,43.625,0.00,0.2615,0.26160,4.000
4,43.750,0.00,0.3865,0.38660,4.000
4,43.875,0.00,0.5114,0.51155,4.000
4,44.000,0.00,0.6365,0.63660,4.000
4,44.125,0.00,0.7616,0.76170,4.000
4,44.250,0.00,0.8866,0.88670,4.000
4,44.375,0.00,1.0118,1.01190,4.000
4,44.500,0.00,1.1366,1.13670,4.000
4,44.625,0.01,1.2617,1.26175,4.000
4,44.750,0.00,1.3867,1.38680,4.000
4,44.875,0.00,1.5116,1.51170,4.000
4,45.000,0.00,1.6366,1.63670,4.000
4,45.125,0.00,1.7617,1.76180,4.000
4,45.250,-0.01,1.8867,1.88680,4.000
4,45.375,0.00,2.0118,2.01185,4.000
4,45.500,0.00,2.1368,2.13690,4.000
4,45.625,0.00,2.2618,2.26185,4.000
4,45.750,0.03,2.3868,2.38690,4.000
4,45.875,0.07,2.5118,2.51190,4.000
4,46.000,0.15,2.6366,2.63670,4.000
4,46.125,0.30,2.7617,2.76175,4.000
4,46.250,0.54,2.8867,2.88680,4.000
4,46.375,0.86,3.0118,3.01195,4.000
4,46.500,1.29,3.1368,3.13690,4.000
4,46.625,1.84,3.2618,3.26190,4.000
4,46.750,2.51,3.3868,3.38690,4.000
4,46.875,3.32,3.5117,3.51180,4.000
4,47.000,4.27,3.6367,3.63680,4.000
4,47.125,5.37,3.7617,3.76180,4.000
4,47.250,6.63,3.8867,3.88680,4.000
4,47.375,8.08,4.0118,4.01185,4.000
4,47.500,9.73,4.1368,4.13690,4.000
4,47.625,11.61,4.2618,4.26190,4.000
4,47.750,13.70,4.3869,4.38700,4.000
4,47.875,16.04,4.5118,4.51190,4.000
4,48.000,18.64,4.6367,4.63680,4.000
4,48.125,21.56,4.7617,4.76185,4.000
4,48.250,24.87,4.8868,4.88690,4.000
4,48.375,28.63,5.0118,5.01190,4.000
4,48.500,32.96,5.1367,5.13680,4.000
4,48.625,38.05,5.2619,5.26205,4.000
4,48.750,44.23,5.3868,5.38690,4.000
4,48.938,52.41,5.5178,5.51792,4.000
4,49.062,37.01,5.3951,5.39520,4.000
4,49.188,28.00,5.2702,5.27027,4.000
4,49.312,21.84,5.1451,5.14523,4.000
4,49.438,17.29,5.0202,5.02027,4.000
4,49.562,13.79,4.8952,4.89528,4.000
4,49.688,11.05,4.7700,4.77007,4.000
4,49.812,8.92,4.6450,4.64510,4.000
4,49.938,7.24,4.5201,4.52017,4.000
4,50.062,5.94,4.3951,4.39520,4.000
4,50.188,4.92,4.2701,4.27017,4.000
4,50.312,4.12,4.1451,4.14518,4.000
4,50.438,3.46,4.0200,4.02015,4.000
4,50.562,2.90,3.8951,3.89515,4.000
4,50.688,2.37,3.7699,3.77005,4.000
4,50.812,1.90,3.6450,3.64510,4.000
4,50.938,1.49,3.5199,3.51997,4.000
4,51.062,1.13,3.3948,3.39488,4.000
4,51.188,0.81,3.2698,3.26995,4.000
4,51.312,0.54,3.1450,3.14510,4.000
4,51.438,0.33,3.0201,3.02020,4.000
4,51.562,0.18,2.8949,2.89503,4.000
4,51.688,0.08,2.7699,2.77002,4.000
4,51.812,0.02,2.6448,2.64490,4.000
4,51.938,0.01,2.5198,2.51992,4.000
4,52.062,0.00,2.3949,2.39495,4.000
4,52.188,0.00,2.2698,2.26995,4.000
4,52.312,0.00,2.1449,2.14503,4.000
4,52.438,0.00,2.0198,2.01995,4.000
4,52.562,0.00,1.8948,1.89493,4.000
4,52.688,0.00,1.7699,1.77000,4.000
4,52.812,0.00,1.6449,1.64498,4.000
4,52.938,0.00,1.5197,1.51985,4.000
4,53.062,0.00,1.3947,1.39480,4.000
4,53.188,0.00,1.2698,1.26987,4.000
4,53.312,0.00,1.1447,1.14483,4.000
4,53.438,0.00,1.0200,1.02007,4.000
4,53.562,0.00,0.8949,0.89500,4.000
4,53.688,0.00,0.7699,0.77000,4.000
4,53.812,0.00,0.6448,0.64485,4.000
4,53.938,0.00,0.5197,0.51982,4.000
4,54.062,0.00,0.3948,0.39485,4.000
4,54.188,0.00,0.2696,0.26975,4.000
4,54.312,0.00,0.1447,0.14483,4.000
4,54.438,0.00,0.0198,0.01987,4.000
4,54.625,0.00,-0.0002,-0.00015,4.000
4,54.750,0.00,-0.0003,-0.00020,4.000
4,54.875,0.00,-0.0003,-0.00020,4.000
4,55.000,0.00,-0.0003,-0.00020,4.000
4,55.125,0.00,-0.0003,-0.00020,4.000
4,55.250,0.00,-0.0003,-0.00020,4.000
4,55.375,0.00,-0.0003,-0.00020,4.000
4,55.500,0.00,-0.0003,-0.00020,4.000
4,55.625,0.00,-0.0003,-0.00020,4.000
4,55.750,0.00,-0.0003,-0.00020,4.000
4,55.875,0.00,-0.0003,-0.00020,4.000
4,56.000,0.00,-0.0002,-0.00010,4.000
4,56.125,0.00,-0.0002,-0.00010,4.000
4,56.250,0.00,-0.0002,-0.00010,4.000
4,56.375,0.00,-0.0002,-0.00010,4.000
4,56.500,0.00,-0.0002,-0.00010,4.000
4,56.625,0.00,-0.0002,-0.00010,4.000
4,56.750,0.00,-0.0002,-0.00010,4.000
4,56.875,0.00,-0.0002,-0.00010,4.000
4,57.000,0.00,-0.0002,-0.00010,4.000
4,57.125,0.00,-0.0002,-0.00010,4.000
4,57.250,0.00,-0.0002,-0.00010,4.000
4,57.375,0.00,-0.0002,-0.00010,4.000
4,57.500,0.00,-0.0002,-0.00010,4.000
5,57.875,-0.01,0.1214,0.12155,5.000
5,58.000,-0.01,0.2466,0.24670,5.000
5,58.125,0.00,0.3716,0.37175,5.000
5,58.250,0.00,0.4966,0.49670,5.000
5,58.375,-0.01,0.6216,0.62175,5.000
5,58.500,0.00,0.7466,0.74670,5.000
5,58.625,-0.01,0.8716,0.87170,5.000
5,58.750,-0.01,0.9966,0.99670,5.000
5,58.875,-0.01,1.1215,1.12160,5.000
5,59.000,-0.01,1.2466,1.24670,5.000
5,59.125,0.00,1.3716,1.37175,5.000
5,59.250,-0.01,1.4967,1.49680,5.000
5,59.375,0.00,1.6217,1.62185,5.000
5,59.500,-0.01,1.7466,1.74670,5.000
5,59.625,-0.01,1.8716,1.87175,5.000
5,59.750,-0.01,1.9966,1.99670,5.000
5,59.875,-0.01,2.1216,2.12175,5.000
5,60.000,0.00,2.2466,2.24670,5.000
5,60.125,0.02,2.3717,2.37185,5.000
5,60.250,0.05,2.4969,2.49700,5.000
5,60.375,0.13,2.6217,2.62185,5.000
5,60.500,0.27,2.7468,2.74690,5.000
5,60.625,0.49,2.8717,2.87185,5.000
5,60.750,0.81,2.9967,2.99680,5.000
5,60.875,1.22,3.1217,3.12180,5.000
5,61.000,1.74,3.2467,3.24680,5.000
5,61.125,2.39,3.3717,3.37185,5.000
5,61.250,3.18,3.4967,3.49680,5.000
5,61.375,4.11,3.6218,3.62195,5.000
5,61.500,5.20,3.7468,3.74690,5.000
5,61.625,6.44,3.8717,3.87185,5.000
5,61.750,7.86,3.9967,3.99680,5.000
5,61.875,9.50,4.1216,4.12175,5.000
5,62.000,11.34,4.2466,4.24670,5.000
5,62.125,13.40,4.3717,4.37185,5.000
5,62.250,15.70,4.4968,4.49690,5.000
5,62.375,18.26,4.6218,4.62195,5.000
5,62.500,21.13,4.7468,4.74690,5.000
5,62.625,24.37,4.8718,4.87195,5.000
5,62.750,28.06,4.9967,4.99680,5.000
5,62.875,32.31,5.1217,5.12185,5.000
5,63.000,37.28,5.2468,5.24690,5.000
5,63.125,43.28,5.3718,5.37195,5.000
5,63.250,50.94,5.4968,5.49690,5.000
5,63.438,38.30,5.4101,5.41020,5.000
5,63.562,28.79,5.2851,5.28515,5.000
5,63.688,22.41,5.1601,5.16018,5.000
5,63.812,17.70,5.0351,5.03520,5.000
5,63.938,14.10,4.9102,4.91028,5.000
5,64.062,11.29,4.7851,4.78523,5.000
5,64.188,9.10,4.6602,4.66030,5.000
5,64.312,7.38,4.5352,4.53525,5.000
5,64.438,6.05,4.4100,4.41015,5.000
5,64.562,5.00,4.2850,4.28513,5.000
5,64.688,4.17,4.1599,4.16000,5.000
5,64.812,3.50,4.0350,4.03510,5.000
5,64.938,2.93,3.9101,3.91015,5.000
5,65.062,2.40,3.7851,3.78518,5.000
5,65.188,1.94,3.6601,3.66020,5.000
5,65.312,1.52,3.5350,3.53508,5.000
5,65.438,1.15,3.4099,3.41000,5.000
5,65.562,0.83,3.2849,3.28498,5.000
5,65.688,0.55,3.1599,3.15998,5.000
5,65.812,0.34,3.0350,3.03505,5.000
5,65.938,0.19,2.9099,2.91000,5.000
5,66.062,0.09,2.7849,2.78498,5.000
5,66.188,0.03,2.6600,2.66008,5.000
5,66.312,0.01,2.5350,2.53508,5.000
5,66.438,0.00,2.4100,2.41010,5.000
5,66.562,-0.01,2.2849,2.28495,5.000
5,66.688,-0.01,2.1599,2.15998,5.000
5,66.812,-0.01,2.0348,2.03493,5.000
5,66.938,0.00,1.9098,1.90992,5.000
5,67.062,0.00,1.7848,1.78493,5.000
5,67.188,-0.01,1.6599,1.66000,5.000
5,67.312,-0.01,1.5349,1.53498,5.000
5,67.438,-0.01,1.4099,1.40998,5.000
5,67.562,0.00,1.2848,1.28488,5.000
5,67.688,-0.01,1.1596,1.15973,5.000
5,67.812,0.00,1.0348,1.03485,5.000
5,67.938,-0.01,0.9098,0.90988,5.000
5,68.062,-0.01,0.7849,0.78500,5.000
5,68.188,0.00,0.6598,0.65995,5.000
5,68.312,-0.01,0.5349,0.53498,5.000
5,68.438,0.00,0.4099,0.41000,5.000
5,68.562,-0.01,0.2847,0.28483,5.000
5,68.688,-0.01,0.1597,0.15975,5.000
5,68.812,-0.01,0.0347,0.03475,5.000
5,69.062,-0.01,-0.0003,-0.00020,5.000
5,69.188,0.00,-0.0003,-0.00020,5.000
5,69.312,0.00,-0.0003,-0.00020,5.000
5,69.438,0.00,-0.0003,-0.00020,5.000
5,69.562,-0.01,-0.0003,-0.00020,5.000
5,69.688,-0.01,-0.0003,-0.00020,5.000
5,69.812,0.00,-0.0003,-0.00020,5.000
5,69.938,-0.01,-0.0003,-0.00020,5.000
5,70.062,-0.01,-0.0003,-0.00020,5.000
5,70.188,-0.01,-0.0003,-0.00020,5.000
5,70.312,0.00,-0.0003,-0.00020,5.000
5,70.438,0.00,-0.0003,-0.00020,5.000
5,70.562,0.00,-0.0003,-0.00018,5.000
5,70.688,0.00,-0.0002,-0.00010,5.000
5,70.812,0.00,-0.0002,-0.00010,5.000
5,70.938,0.00,-0.0002,-0.00010,5.000
5,71.062,0.00,-0.0002,-0.00010,5.000
5,71.188,-0.01,-0.0002,-0.00010,5.000
5,71.312,0.00,-0.0002,-0.00010,5.000
5,71.438,0.00,-0.0002,-0.00010,5.000
5,71.562,0.00,-0.0002,-0.00010,5.000
5,71.688,0.00,-0.0002,-0.00010,5.000
5,71.812,0.00,-0.0002,-0.00010,5.000
5,71.938,0.00,-0.0002,-0.00010,5.000
6,72.312,0.00,0.1391,0.13917,6.000
6,72.438,0.00,0.2639,0.26402,6.000
6,72.562,0.00,0.3891,0.38917,6.000
6,72.688,-0.01,0.5140,0.51410,6.000
6,72.812,0.00,0.6390,0.63915,6.000
6,72.938,-0.01,0.7642,0.76428,6.000
6,73.062,-0.01,0.8892,0.88932,6.000
6,73.188,0.00,1.0143,1.01440,6.000
6,73.312,-0.01,1.1392,1.13927,6.000
6,73.438,0.00,1.2641,1.26423,6.000
6,73.562,-0.01,1.3891,1.38920,6.000
6,73.688,0.00,1.5141,1.51420,6.000
6,73.812,0.00,1.6391,1.63925,6.000
6,73.938,0.00,1.7642,1.76428,6.000
6,74.062,-0.01,1.8892,1.88930,6.000
6,74.188,-0.01,2.0142,2.01430,6.000
6,74.312,0.00,2.1392,2.13932,6.000
6,74.438,0.00,2.2642,2.26435,6.000
6,74.562,0.02,2.3893,2.38942,6.000
6,74.688,0.06,2.5142,2.51435,6.000
6,74.812,0.14,2.6391,2.63922,6.000
6,74.938,0.29,2.7642,2.76428,6.000
6,75.062,0.52,2.8893,2.88942,6.000
6,75.188,0.85,3.0144,3.01448,6.000
6,75.312,1.28,3.1394,3.13947,6.000
6,75.438,1.82,3.2642,3.26433,6.000
6,75.562,2.49,3.3893,3.38945,6.000
6,75.688,3.29,3.5142,3.51425,6.000
6,75.812,4.24,3.6393,3.63937,6.000
6,75.938,5.34,3.7643,3.76438,6.000
6,76.062,6.60,3.8892,3.88932,6.000
6,76.188,8.06,4.0143,4.01437,6.000
6,76.312,9.72,4.1392,4.13932,6.000
6,76.438,11.58,4.2644,4.26452,6.000
6,76.562,13.68,4.3893,4.38945,6.000
6,76.688,16.02,4.5143,4.51442,6.000
6,76.812,18.61,4.6393,4.63937,6.000
6,76.938,21.52,4.7642,4.76432,6.000
6,77.062,24.82,4.8894,4.88947,6.000
6,77.188,28.55,5.0143,5.01440,6.000
6,77.312,32.87,5.1392,5.13935,6.000
6,77.438,37.96,5.2644,5.26455,6.000
6,77.562,44.13,5.3894,5.38947,6.000
6,77.812,45.09,5.4750,5.47510,6.000
6,77.938,32.75,5.3502,5.35028,6.000
6,78.062,25.17,5.2252,5.22530,6.000
6,78.188,19.77,5.1002,5.10028,6.000
6,78.312,15.71,4.9752,4.97533,6.000
6,78.438,12.55,4.8501,4.85022,6.000
6,78.562,10.09,4.7250,4.72510,6.000
6,78.688,8.15,4.6001,4.60018,6.000
6,78.812,6.64,4.4751,4.47520,6.000
6,78.938,5.46,4.3501,4.35020,6.000
6,79.062,4.54,4.2251,4.22518,6.000
6,79.188,3.81,4.1000,4.10013,6.000
6,79.312,3.21,3.9750,3.97508,6.000
6,79.438,2.66,3.8500,3.85005,6.000
6,79.562,2.16,3.7249,3.72503,6.000
6,79.688,1.73,3.6000,3.60008,6.000
6,79.812,1.33,3.4749,3.47500,6.000
6,79.938,0.98,3.3500,3.35005,6.000
6,80.062,0.68,3.2249,3.22503,6.000
6,80.188,0.44,3.1000,3.10010,6.000
6,80.312,0.25,2.9751,2.97515,6.000
6,80.438,0.12,2.8498,2.84995,6.000
6,80.562,0.05,2.7248,2.72493,6.000
6,80.688,0.02,2.5997,2.59982,6.000
6,80.812,0.00,2.4749,2.47495,6.000
6,80.938,0.00,2.3499,2.35000,6.000
6,81.062,0.00,2.2249,2.22498,6.000
6,81.188,0.00,2.1000,2.10008,6.000
6,81.312,0.00,1.9750,1.97505,6.000
6,81.438,-0.01,1.8498,1.84992,6.000
6,81.562,-0.01,1.7248,1.72490,6.000
6,81.688,0.00,1.5998,1.59990,6.000
6,81.812,0.00,1.4747,1.47483,6.000
6,81.938,-0.01,1.3498,1.34988,6.000
6,82.062,0.00,1.2248,1.22490,6.000
6,82.188,-0.01,1.0998,1.09990,6.000
6,82.312,-0.01,0.9749,0.97503,6.000
6,82.438,0.00,0.8498,0.84990,6.000
6,82.562,0.00,0.7249,0.72495,6.000
6,82.688,0.00,0.5997,0.59982,6.000
6,82.812,0.00,0.4747,0.47483,6.000
6,82.938,0.00,0.3498,0.34985,6.000
6,83.062,-0.01,0.2247,0.22483,6.000
6,83.188,-0.01,0.0997,0.09983,6.000
6,83.438,-0.01,-0.0028,-0.00275,6.000
6,83.562,0.00,-0.0003,-0.00020,6.000
6,83.688,0.00,-0.0003,-0.00020,6.000
6,83.812,0.00,-0.0003,-0.00020,6.000
6,83.938,0.00,-0.0003,-0.00020,6.000
6,84.062,0.00,-0.0003,-0.00020,6.000
6,84.188,-0.01,-0.0003,-0.00020,6.000
6,84.312,0.00,-0.0003,-0.00020,6.000
6,84.438,0.00,-0.0003,-0.00020,6.000
6,84.562,0.00,-0.0003,-0.00020,6.000
6,84.688,-0.01,-0.0003,-0.00020,6.000
6,84.812,0.00,-0.0003,-0.00020,6.000
6,84.938,0.00,-0.0003,-0.00020,6.000
6,85.062,0.00,-0.0002,-0.00010,6.000
6,85.188,0.00,-0.0002,-0.00010,6.000
6,85.312,-0.01,-0.0002,-0.00010,6.000
6,85.438,0.00,-0.0002,-0.00010,6.000
6,85.562,0.00,-0.0002,-0.00010,6.000
6,85.688,0.00,-0.0002,-0.00010,6.000
6,85.812,0.00,-0.0002,-0.00010,6.000
6,85.938,0.00,-0.0002,-0.00010,6.000
6,86.062,0.00,-0.0002,-0.00010,6.000
6,86.188,0.00,-0.0002,-0.00010,6.000
6,86.312,-0.01,-0.0002,-0.00010,6.000
7,86.625,0.00,0.0516,0.05170,7.000
7,86.750,0.00,0.1767,0.17680,7.000
7,86.875,0.00,0.3016,0.30165,7.000
7,87.000,0.00,0.4266,0.42670,7.000
7,87.125,0.00,0.5515,0.55160,7.000
7,87.250,0.00,0.6766,0.67670,7.000
7,87.375,-0.01,0.8017,0.80175,7.000
7,87.500,0.00,0.9268,0.92690,7.000
7,87.625,0.00,1.0518,1.05185,7.000
7,87.750,0.00,1.1766,1.17670,7.000
7,87.875,0.00,1.3016,1.30175,7.000
7,88.000,0.00,1.4267,1.42680,7.000
7,88.125,0.00,1.5516,1.55170,7.000
7,88.250,0.00,1.6766,1.67670,7.000
7,88.375,0.00,1.8016,1.80170,7.000
7,88.500,0.00,1.9267,1.92680,7.000
7,88.625,0.00,2.0518,2.05185,7.000
7,88.750,0.00,2.1767,2.17680,7.000
7,88.875,0.00,2.3018,2.30190,7.000
7,89.000,0.03,2.4269,2.42700,7.000
7,89.125,0.08,2.5518,2.55185,7.000
7,89.250,0.17,2.6766,2.67670,7.000
7,89.375,0.35,2.8017,2.80175,7.000
7,89.500,0.61,2.9267,2.92680,7.000
7,89.625,0.97,3.0518,3.05190,7.000
7,89.750,1.43,3.1769,3.17700,7.000
7,89.875,2.01,3.3018,3.30190,7.000
7,90.000,2.72,3.4268,3.42690,7.000
7,90.125,3.56,3.5518,3.55185,7.000
7,90.250,4.55,3.6768,3.67690,7.000
7,90.375,5.70,3.8018,3.80185,7.000
7,90.500,7.02,3.9267,3.92680,7.000
7,90.625,8.53,4.0517,4.05180,7.000
7,90.750,10.25,4.1768,4.17690,7.000
7,90.875,12.19,4.3019,4.30200,7.000
7,91.000,14.36,4.4269,4.42700,7.000
7,91.125,16.77,4.5518,4.55195,7.000
7,91.250,19.45,4.6768,4.67690,7.000
7,91.375,22.47,4.8018,4.80190,7.000
7,91.500,25.89,4.9268,4.92690,7.000
7,91.625,29.78,5.0518,5.05185,7.000
7,91.750,34.30,5.1768,5.17690,7.000
7,91.875,39.66,5.3019,5.30200,7.000
7,92.000,46.23,5.4268,5.42690,7.000
7,92.188,48.85,5.5001,5.50022,7.000
7,92.312,34.67,5.3751,5.37518,7.000
7,92.438,26.47,5.2501,5.25020,7.000
7,92.562,20.73,5.1249,5.12503,7.000
7,92.688,16.45,5.0001,5.00022,7.000
7,92.812,13.13,4.8752,4.87528,7.000
7,92.938,10.54,4.7501,4.75025,7.000
7,93.062,8.52,4.6252,4.62530,7.000
7,93.188,6.93,4.5002,4.50030,7.000
7,93.312,5.68,4.3751,4.37518,7.000
7,93.438,4.71,4.2500,4.25005,7.000
7,93.562,3.95,4.1249,4.12498,7.000
7,93.688,3.32,4.0000,4.00008,7.000
7,93.812,2.76,3.8750,3.87510,7.000
7,93.938,2.26,3.7501,3.75018,7.000
7,94.062,1.81,3.6251,3.62520,7.000
7,94.188,1.41,3.5000,3.50008,7.000
7,94.312,1.05,3.3750,3.37513,7.000
7,94.438,0.74,3.2498,3.24988,7.000
7,94.562,0.48,3.1249,3.12503,7.000
7,94.688,0.29,3.0000,3.00008,7.000
7,94.812,0.15,2.8749,2.87495,7.000
7,94.938,0.06,2.7499,2.75000,7.000
7,95.062,0.02,2.6249,2.62503,7.000
7,95.188,0.01,2.5001,2.50018,7.000
7,95.312,0.00,2.3750,2.37508,7.000
7,95.438,-0.01,2.2498,2.24992,7.000
7,95.562,0.00,2.1248,2.12490,7.000
7,95.688,0.00,1.9997,1.99983,7.000
7,95.812,0.00,1.8747,1.87483,7.000
7,95.938,0.00,1.7498,1.74990,7.000
7,96.062,-0.01,1.6249,1.62500,7.000
7,96.188,-0.01,1.4998,1.49992,7.000
7,96.312,0.00,1.3749,1.37498,7.000
7,96.438,-0.01,1.2498,1.24990,7.000
7,96.562,0.00,1.1247,1.12478,7.000
7,96.688,0.00,0.9999,0.99995,7.000
7,96.812,-0.01,0.8747,0.87483,7.000
7,96.938,0.00,0.7499,0.74998,7.000
7,97.062,0.00,0.6248,0.62493,7.000
7,97.188,0.00,0.4998,0.49995,7.000
7,97.312,0.00,0.3748,0.37493,7.000
7,97.438,0.00,0.2498,0.24988,7.000
7,97.562,0.00,0.1248,0.12485,7.000
7,97.688,0.00,-0.0003,-0.00015,7.000
7,97.875,0.00,-0.0004,-0.00025,7.000
7,98.000,0.00,-0.0003,-0.00020,7.000
7,98.125,0.00,-0.0003,-0.00020,7.000
7,98.250,0.00,-0.0003,-0.00020,7.000
7,98.375,0.00,-0.0003,-0.00020,7.000
7,98.500,0.00,-0.0003,-0.00020,7.000
7,98.625,0.00,-0.0003,-0.00020,7.000
7,98.750,0.00,-0.0003,-0.00020,7.000
7,98.875,0.00,-0.0003,-0.00020,7.000
7,99.000,0.00,-0.0003,-0.00020,7.000
7,99.125,0.00,-0.0003,-0.00020,7.000
7,99.250,0.01,-0.0003,-0.00020,7.000
7,99.375,0.00,-0.0003,-0.00020,7.000
7,99.500,0.00,-0.0003,-0.00020,7.000
7,99.625,0.00,-0.0003,-0.00020,7.000
7,99.750,0.00,-0.0002,-0.00010,7.000
7,99.875,0.00,-0.0002,-0.00010,7.000
7,100.000,0.00,-0.0002,-0.00010,7.000
7,100.125,0.00,-0.0002,-0.00010,7.000
7,100.250,0.00,-0.0002,-0.00010,7.000
7,100.375,0.00,-0.0002,-0.00010,7.000
7,100.500,0.00,-0.0002,-0.00010,7.000
7,100.625,0.00,-0.0002,-0.00010,7.000
7,100.750,0.00,-0.0002,-0.00010,7.000
8,101.125,0.00,0.1525,0.15260,8.000
8,101.250,0.01,0.2774,0.27750,8.000
8,101.375,0.00,0.4026,0.40270,8.000
8,101.500,0.00,0.5275,0.52760,8.000
8,101.625,0.01,0.6527,0.65275,8.000
8,101.750,0.01,0.7777,0.77780,8.000
8,101.875,0.00,0.9028,0.90285,8.000
8,102.000,0.01,1.0278,1.02790,8.000
8,102.125,0.00,1.1526,1.15265,8.000
8,102.250,0.00,1.2775,1.27760,8.000
8,102.375,0.01,1.4026,1.40265,8.000
8,102.500,0.00,1.5277,1.52780,8.000
8,102.625,0.00,1.6527,1.65280,8.000
8,102.750,0.00,1.7777,1.77780,8.000
8,102.875,0.01,1.9027,1.90275,8.000
8,103.000,0.01,2.0278,2.02790,8.000
8,103.125,0.01,2.1528,2.15285,8.000
8,103.250,0.01,2.2776,2.27770,8.000
8,103.375,0.03,2.4027,2.40280,8.000
8,103.500,0.07,2.5277,2.52780,8.000
8,103.625,0.16,2.6528,2.65285,8.000
8,103.750,0.31,2.7777,2.77780,8.000
8,103.875,0.56,2.9028,2.90295,8.000
8,104.000,0.89,3.0279,3.02800,8.000
8,104.125,1.33,3.1528,3.15290,8.000
8,104.250,1.88,3.2777,3.27780,8.000
8,104.375,2.56,3.4026,3.40275,8.000
8,104.500,3.38,3.5277,3.52780,8.000
8,104.625,4.35,3.6528,3.65290,8.000
8,104.750,5.47,3.7778,3.77790,8.000
8,104.875,6.75,3.9028,3.90290,8.000
8,105.000,8.24,4.0279,4.02800,8.000
8,105.125,9.92,4.1528,4.15290,8.000
8,105.250,11.81,4.2779,4.27800,8.000
8,105.375,13.94,4.4028,4.40285,8.000
8,105.500,16.30,4.5278,4.52790,8.000
8,105.625,18.92,4.6528,4.65290,8.000
8,105.750,21.86,4.7778,4.77790,8.000
8,105.875,25.19,4.9029,4.90300,8.000
8,106.000,28.97,5.0279,5.02800,8.000
8,106.125,33.34,5.1528,5.15290,8.000
8,106.250,38.50,5.2779,5.27800,8.000
8,106.375,44.79,5.4027,5.40280,8.000
8,106.562,52.29,5.5251,5.52520,8.000
8,106.688,36.76,5.4011,5.40118,8.000
8,106.812,27.84,5.2762,5.27630,8.000
8,106.938,21.73,5.1510,5.15112,8.000
8,107.062,17.21,5.0262,5.02628,8.000
8,107.188,13.74,4.9012,4.90132,8.000
8,107.312,11.02,4.7761,4.77623,8.000
8,107.438,8.89,4.6511,4.65115,8.000
8,107.562,7.21,4.5260,4.52613,8.000
8,107.688,5.90,4.4010,4.40115,8.000
8,107.812,4.88,4.2761,4.27618,8.000
8,107.938,4.07,4.1510,4.15110,8.000
8,108.062,3.42,4.0260,4.02613,8.000
8,108.188,2.87,3.9011,3.90118,8.000
8,108.312,2.35,3.7761,3.77620,8.000
8,108.438,1.89,3.6510,3.65105,8.000
8,108.562,1.49,3.5259,3.52595,8.000
8,108.688,1.12,3.4009,3.40098,8.000
8,108.812,0.81,3.2759,3.27603,8.000
8,108.938,0.54,3.1509,3.15100,8.000
8,109.062,0.33,3.0260,3.02613,8.000
8,109.188,0.18,2.9010,2.90108,8.000
8,109.312,0.08,2.7760,2.77605,8.000
8,109.438,0.03,2.6508,2.65095,8.000
8,109.562,0.02,2.5259,2.52595,8.000
8,109.688,0.01,2.4010,2.40108,8.000
8,109.812,0.00,2.2758,2.27593,8.000
8,109.938,0.00,2.1508,2.15090,8.000
8,110.062,0.00,2.0259,2.02595,8.000
8,110.188,0.01,1.9009,1.90098,8.000
8,110.312,0.00,1.7759,1.77598,8.000
8,110.438,0.00,1.6508,1.65093,8.000
8,110.562,0.00,1.5258,1.52590,8.000
8,110.688,0.01,1.4007,1.40082,8.000
8,110.812,0.01,1.2757,1.27580,8.000
8,110.938,0.00,1.1508,1.15085,8.000
8,111.062,0.00,1.0259,1.02603,8.000
8,111.188,0.00,0.9009,0.90100,8.000
8,111.312,0.00,0.7759,0.77600,8.000
8,111.438,0.01,0.6508,0.65092,8.000
8,111.562,0.01,0.5258,0.52585,8.000
8,111.688,0.01,0.4008,0.40090,8.000
8,111.812,0.00,0.2757,0.27578,8.000
8,111.938,0.00,0.1507,0.15078,8.000
8,112.062,0.00,0.0258,0.02590,8.000
8,112.250,0.01,0.0008,0.00090,8.000
8,112.375,0.01,-0.0003,-0.00020,8.000
8,112.500,0.00,-0.0003,-0.00020,8.000
8,112.625,0.00,-0.0002,-0.00010,8.000
8,112.750,0.00,-0.0002,-0.00010,8.000
8,112.875,0.00,-0.0002,-0.00015,8.000
8,113.000,0.01,-0.0002,-0.00010,8.000
8,113.125,0.00,-0.0002,-0.00010,8.000
8,113.250,0.01,-0.0002,-0.00010,8.000
8,113.375,0.00,-0.0002,-0.00010,8.000
8,113.500,0.01,-0.0002,-0.00010,8.000
8,113.625,0.00,-0.0002,-0.00010,8.000
8,113.750,0.00,-0.0002,-0.00010,8.000
8,113.875,0.00,-0.0002,-0.00010,8.000
8,114.000,0.00,-0.0002,-0.00010,8.000
8,114.125,0.00,-0.0002,-0.00010,8.000
8,114.250,0.00,-0.0002,-0.00010,8.000
8,114.375,0.00,-0.0002,-0.00010,8.000
8,114.500,0.01,-0.0002,-0.00010,8.000
8,114.625,0.01,-0.0002,-0.00010,8.000
8,114.750,0.01,-0.0002,-0.00010,8.000
8,114.875,0.00,-0.0002,-0.00010,8.000
8,115.000,0.01,-0.0002,-0.00010,8.000
8,115.125,0.01,-0.0002,-0.00010,8.000
9,115.438,0.00,0.0540,0.05410,9.000
9,115.562,0.00,0.1791,0.17917,9.000
9,115.688,0.00,0.3041,0.30418,9.000
9,115.812,0.00,0.4291,0.42920,9.000
9,115.938,0.00,0.5540,0.55408,9.000
9,116.062,0.00,0.6790,0.67912,9.000
9,116.188,0.00,0.8041,0.80418,9.000
9,116.312,0.00,0.9291,0.92925,9.000
9,116.438,0.00,1.0542,1.05427,9.000
9,116.562,0.00,1.1792,1.17927,9.000
9,116.688,0.00,1.3042,1.30427,9.000
9,116.812,0.00,1.4292,1.42927,9.000
9,116.938,0.00,1.5541,1.55418,9.000
9,117.062,0.00,1.6792,1.67927,9.000
9,117.188,0.00,1.8040,1.80412,9.000
9,117.312,0.00,1.9291,1.92922,9.000
9,117.438,0.00,2.0541,2.05420,9.000
9,117.562,0.00,2.1792,2.17930,9.000
9,117.688,0.01,2.3043,2.30438,9.000
9,117.812,0.03,2.4294,2.42947,9.000
9,117.938,0.08,2.5542,2.55435,9.000
9,118.062,0.18,2.6792,2.67935,9.000
9,118.188,0.35,2.8042,2.80425,9.000
9,118.312,0.61,2.9293,2.92940,9.000
9,118.438,0.97,3.0544,3.05448,9.000
9,118.562,1.42,3.1792,3.17935,9.000
9,118.688,2.00,3.3044,3.30448,9.000
9,118.812,2.71,3.4293,3.42937,9.000
9,118.938,3.56,3.5543,3.55440,9.000
9,119.062,4.56,3.6793,3.67937,9.000
9,119.188,5.71,3.8042,3.80430,9.000
9,119.312,7.04,3.9292,3.92930,9.000
9,119.438,8.56,4.0543,4.05438,9.000
9,119.562,10.29,4.1792,4.17930,9.000
9,119.688,12.22,4.3043,4.30440,9.000
9,119.812,14.39,4.4293,4.42942,9.000
9,119.938,16.80,4.5543,4.55440,9.000
9,120.062,19.49,4.6793,4.67937,9.000
9,120.188,22.51,4.8043,4.80440,9.000
9,120.312,25.92,4.9293,4.92940,9.000
9,120.438,29.80,5.0542,5.05430,9.000
9,120.562,34.30,5.1793,5.17942,9.000
9,120.688,39.66,5.3043,5.30442,9.000
9,120.812,46.25,5.4294,5.42947,9.000
9,121.000,50.68,5.5171,5.51720,9.000
9,121.125,35.55,5.3927,5.39275,9.000
9,121.250,27.04,5.2678,5.26790,9.000
9,121.375,21.15,5.1426,5.14270,9.000
9,121.500,16.78,5.0177,5.01780,9.000
9,121.625,13.39,4.8926,4.89275,9.000
9,121.750,10.73,4.7674,4.76750,9.000
9,121.875,8.67,4.6425,4.64260,9.000
9,122.000,7.03,4.5176,4.51770,9.000
9,122.125,5.77,4.3926,4.39275,9.000
9,122.250,4.78,4.2677,4.26780,9.000
9,122.375,4.00,4.1425,4.14260,9.000
9,122.500,3.37,4.0175,4.01760,9.000
9,122.625,2.81,3.8924,3.89255,9.000
9,122.750,2.30,3.7674,3.76750,9.000
9,122.875,1.85,3.6424,3.64255,9.000
9,123.000,1.45,3.5174,3.51750,9.000
9,123.125,1.09,3.3925,3.39260,9.000
9,123.250,0.77,3.2675,3.26760,9.000
9,123.375,0.51,3.1425,3.14260,9.000
9,123.500,0.31,3.0175,3.01760,9.000
9,123.625,0.17,2.8925,2.89255,9.000
9,123.750,0.07,2.7673,2.76740,9.000
9,123.875,0.03,2.6423,2.64235,9.000
9,124.000,0.01,2.5175,2.51760,9.000
9,124.125,0.00,2.3925,2.39255,9.000
9,124.250,0.00,2.2674,2.26750,9.000
9,124.375,0.00,2.1425,2.14255,9.000
9,124.500,0.00,2.0175,2.01760,9.000
9,124.625,0.00,1.8924,1.89245,9.000
9,124.750,0.00,1.7672,1.76730,9.000
9,124.875,0.00,1.6423,1.64235,9.000
9,125.000,0.00,1.5173,1.51740,9.000
9,125.125,0.00,1.3923,1.39240,9.000
9,125.250,0.00,1.2673,1.26740,9.000
9,125.375,0.00,1.1423,1.14240,9.000
9,125.500,0.00,1.0175,1.01760,9.000
9,125.625,0.00,0.8924,0.89245,9.000
9,125.750,0.00,0.7673,0.76740,9.000
9,125.875,0.00,0.6423,0.64235,9.000
9,126.000,0.00,0.5171,0.51720,9.000
9,126.125,0.00,0.3923,0.39235,9.000
9,126.250,0.00,0.2672,0.26730,9.000
9,126.375,0.00,0.1423,0.14240,9.000
9,126.500,0.00,0.0173,0.01740,9.000
9,126.688,0.00,-0.0004,-0.00025,9.000
9,126.812,0.00,-0.0003,-0.00020,9.000
9,126.938,0.00,-0.0003,-0.00020,9.000
9,127.062,0.00,-0.0003,-0.00020,9.000
9,127.188,0.00,-0.0003,-0.00020,9.000
9,127.312,0.00,-0.0003,-0.00020,9.000
9,127.438,-0.01,-0.0003,-0.00020,9.000
9,127.562,0.00,-0.0003,-0.00020,9.000
9,127.688,0.00,-0.0003,-0.00020,9.000
9,127.812,-0.01,-0.0003,-0.00020,9.000
9,127.938,0.00,-0.0003,-0.00020,9.000
9,128.062,0.00,-0.0003,-0.00020,9.000
9,128.188,0.00,-0.0003,-0.00020,9.000
9,128.312,0.00,-0.0003,-0.00020,9.000
9,128.438,0.00,-0.0003,-0.00020,9.000
9,128.562,0.00,-0.0003,-0.00020,9.000
9,128.688,0.00,-0.0003,-0.00020,9.000
9,128.812,0.00,-0.0002,-0.00010,9.000
9,128.938,0.00,-0.0002,-0.00010,9.000
9,129.062,0.00,-0.0002,-0.00010,9.000
9,129.188,0.00,-0.0002,-0.00010,9.000
9,129.312,0.00,-0.0002,-0.00010,9.000
9,129.438,0.00,-0.0002,-0.00010,9.000
9,129.562,0.00,-0.0002,-0.00010,9.000
10,129.938,0.00,0.1060,0.10610,10.000
10,130.062,0.01,0.2310,0.23110,10.000
10,130.188,0.01,0.3560,0.35612,10.000
10,130.312,0.01,0.4810,0.48105,10.000
10,130.438,0.01,0.6061,0.60618,10.000
10,130.562,0.01,0.7312,0.73132,10.000
10,130.688,0.01,0.8562,0.85632,10.000
10,130.812,0.01,0.9814,0.98145,10.000
10,130.938,0.00,1.1061,1.10622,10.000
10,131.062,0.00,1.2312,1.23125,10.000
10,131.188,0.01,1.3560,1.35615,10.000
10,131.312,0.01,1.4811,1.48120,10.000
10,131.438,0.01,1.6062,1.60628,10.000
10,131.562,0.01,1.7312,1.73130,10.000
10,131.688,0.01,1.8562,1.85628,10.000
10,131.812,0.01,1.9813,1.98138,10.000
10,131.938,0.01,2.1063,2.10640,10.000
10,132.062,0.01,2.2313,2.23135,10.000
10,132.188,0.03,2.3562,2.35633,10.000
10,132.312,0.05,2.4812,2.48132,10.000
10,132.438,0.12,2.6062,2.60628,10.000
10,132.562,0.24,2.7312,2.73130,10.000
10,132.688,0.45,2.8563,2.85638,10.000
10,132.812,0.75,2.9814,2.98153,10.000
10,132.938,1.15,3.1064,3.10655,10.000
10,133.062,1.65,3.2313,3.23143,10.000
10,133.188,2.29,3.3562,3.35635,10.000
10,133.312,3.06,3.4811,3.48123,10.000
10,133.438,3.96,3.6062,3.60630,10.000
10,133.562,5.03,3.7312,3.73133,10.000
10,133.688,6.25,3.8564,3.85645,10.000
10,133.812,7.65,3.9812,3.98135,10.000
10,133.938,9.26,4.1063,4.10640,10.000
10,134.062,11.07,4.2313,4.23140,10.000
10,134.188,13.10,4.3563,4.35642,10.000
10,134.312,15.38,4.4814,4.48145,10.000
10,134.438,17.89,4.6062,4.60635,10.000
10,134.562,20.70,4.7312,4.73130,10.000
10,134.688,23.87,4.8564,4.85645,10.000
10,134.812,27.46,4.9814,4.98150,10.000
10,134.938,31.57,5.1063,5.10640,10.000
10,135.062,36.40,5.2313,5.23142,10.000
10,135.188,42.20,5.3564,5.35650,10.000
10,135.312,49.51,5.4812,5.48130,10.000
10,135.500,39.90,5.4297,5.42980,10.000
10,135.625,29.79,5.3047,5.30480,10.000
10,135.750,23.13,5.1795,5.17960,10.000
10,135.875,18.27,5.0546,5.05465,10.000
10,136.000,14.55,4.9297,4.92980,10.000
10,136.125,11.65,4.8046,4.80465,10.000
10,136.250,9.38,4.6796,4.67970,10.000
10,136.375,7.59,4.5547,4.55475,10.000
10,136.500,6.19,4.4297,4.42980,10.000
10,136.625,5.10,4.3047,4.30475,10.000
10,136.750,4.24,4.1795,4.17960,10.000
10,136.875,3.57,4.0544,4.05455,10.000
10,137.000,3.00,3.9293,3.92940,10.000
10,137.125,2.46,3.8044,3.80455,10.000
10,137.250,1.99,3.6795,3.67960,10.000
10,137.375,1.57,3.5544,3.55455,10.000
10,137.500,1.20,3.4295,3.42960,10.000
10,137.625,0.86,3.3044,3.30455,10.000
10,137.750,0.59,3.1794,3.17950,10.000
10,137.875,0.37,3.0545,3.05460,10.000
10,138.000,0.21,2.9293,2.92940,10.000
10,138.125,0.10,2.8043,2.80440,10.000
10,138.250,0.03,2.6794,2.67950,10.000
10,138.375,0.02,2.5544,2.55445,10.000
10,138.500,0.01,2.4295,2.42960,10.000
10,138.625,0.01,2.3044,2.30455,10.000
10,138.750,0.01,2.1795,2.17960,10.000
10,138.875,0.01,2.0544,2.05445,10.000
10,139.000,0.00,1.9293,1.92940,10.000
10,139.125,0.00,1.8042,1.80430,10.000
10,139.250,0.00,1.6792,1.67930,10.000
10,139.375,0.01,1.5542,1.55435,10.000
10,139.500,0.00,1.4294,1.42950,10.000
10,139.625,0.01,1.3043,1.30440,10.000
10,139.750,0.00,1.1794,1.17950,10.000
10,139.875,0.01,1.0544,1.05445,10.000
10,140.000,0.01,0.9294,0.92950,10.000
10,140.125,0.01,0.8043,0.80440,10.000
10,140.250,0.00,0.6792,0.67930,10.000
10,140.375,0.00,0.5542,0.55430,10.000
10,140.500,0.01,0.4294,0.42950,10.000
10,140.625,0.00,0.3043,0.30435,10.000
10,140.750,0.01,0.1793,0.17940,10.000
10,140.875,0.01,0.0543,0.05435,10.000
10,141.062,0.00,-0.0009,-0.00078,10.000
10,141.188,0.01,-0.0003,-0.00020,10.000
10,141.312,0.01,-0.0003,-0.00020,10.000
10,141.438,0.01,-0.0003,-0.00020,10.000
10,141.562,0.01,-0.0003,-0.00020,10.000
10,141.688,0.01,-0.0003,-0.00020,10.000
10,141.812,0.01,-0.0003,-0.00020,10.000
10,141.938,0.01,-0.0003,-0.00020,10.000
10,142.062,0.01,-0.0003,-0.00020,10.000
10,142.188,0.00,-0.0003,-0.00020,10.000
10,142.312,0.00,-0.0003,-0.00020,10.000
10,142.438,0.01,-0.0003,-0.00020,10.000
10,142.562,0.01,-0.0003,-0.00020,10.000
10,142.688,0.01,-0.0003,-0.00020,10.000
10,142.812,0.01,-0.0003,-0.00020,10.000
10,142.938,0.01,-0.0002,-0.00010,10.000
10,143.062,0.01,-0.0002,-0.00010,10.000
10,143.188,0.00,-0.0002,-0.00010,10.000
10,143.312,0.00,-0.0002,-0.00010,10.000
10,143.438,0.00,-0.0002,-0.00010,10.000
10,143.562,0.00,-0.0002,-0.00010,10.000
10,143.688,0.01,-0.0002,-0.00010,10.000
10,143.812,0.00,-0.0002,-0.00010,10.000
10,143.938,0.01,-0.0002,-0.00010,10.000
10,144.000,0.01,-0.0002,-0.00010,10.000