File: calibDATA_loadcell/date_02:22:2018/Instron/5N_0_1_3_0.txt
""
"Test Method","Radhen_Load_Cntrl_Cmprsn_250N_12-7.msm"
"Sample I. D.","Sample1.mss"
"Specimen Number","14"

"TheCycle_Output ()","_Time (s)","_Load (N)","_Extension (mm)","RealTimeDepth (mm)","CycleNumber ()"

1,0.312,-0.01,0.0932,0.09318,1.000
1,0.438,-0.01,0.2184,0.21835,1.000
1,0.562,-0.01,0.3434,0.34340,1.000
1,0.688,-0.01,0.4683,0.46830,1.000
1,0.812,-0.01,0.5932,0.59325,1.000
1,0.938,-0.01,0.7182,0.71822,1.000
1,1.062,-0.01,0.8431,0.84312,1.000
1,1.188,-0.01,0.9683,0.96830,1.000
1,1.312,-0.01,1.0933,1.09330,1.000
1,1.438,-0.01,1.2183,1.21830,1.000
1,1.562,-0.01,1.3433,1.34332,1.000
1,1.688,-0.01,1.4685,1.46848,1.000
1,1.812,-0.01,1.5933,1.59328,1.000
1,1.938,0.01,1.7183,1.71830,1.000
1,2.062,0.04,1.8434,1.84340,1.000
1,2.188,0.10,1.9683,1.96830,1.000
1,2.312,0.22,2.0933,2.09332,1.000
1,2.438,0.44,2.2183,2.21832,1.000
1,2.562,0.73,2.3434,2.34345,1.000
1,2.688,1.12,2.4686,2.46855,1.000
1,2.812,1.62,2.5934,2.59343,1.000
1,2.938,2.23,2.7183,2.71832,1.000
1,3.062,3.00,2.8432,2.84325,1.000
1,3.188,3.94,2.9682,2.96823,1.000
1,3.312,5.06,3.0933,3.09332,1.000
1,3.500,4.25,3.0217,3.02170,1.000
1,3.625,3.08,2.8966,2.89655,1.000
1,3.750,2.19,2.7715,2.77150,1.000
1,3.875,1.52,2.6465,2.64650,1.000
1,4.000,1.02,2.5215,2.52150,1.000
1,4.125,0.64,2.3967,2.39665,1.000
1,4.250,0.36,2.2716,2.27160,1.000
1,4.375,0.17,2.1466,2.14660,1.000
1,4.500,0.05,2.0215,2.02150,1.000
1,4.625,0.02,1.8966,1.89655,1.000
1,4.750,0.00,1.7716,1.77160,1.000
1,4.875,0.00,1.6464,1.64640,1.000
1,5.000,0.00,1.5214,1.52140,1.000
1,5.125,-0.01,1.3964,1.39640,1.000
1,5.250,-0.01,1.2715,1.27150,1.000
1,5.375,-0.01,1.1465,1.14650,1.000
1,5.500,0.00,1.0216,1.02160,1.000
1,5.625,0.00,0.8965,0.89650,1.000
1,5.750,-0.01,0.7714,0.77140,1.000
1,5.875,0.00,0.6464,0.64640,1.000
1,6.000,-0.01,0.5212,0.52120,1.000
1,6.125,-0.01,0.3964,0.39640,1.000
1,6.250,0.00,0.2715,0.27150,1.000
1,6.375,-0.01,0.1465,0.14645,1.000
1,6.500,-0.01,0.0215,0.02150,1.000
1,6.688,-0.01,-0.0003,-0.00027,1.000
1,6.812,0.00,-0.0002,-0.00020,1.000
1,6.938,-0.01,-0.0002,-0.00020,1.000
1,7.062,-0.01,-0.0002,-0.00020,1.000
1,7.188,-0.01,-0.0002,-0.00020,1.000
1,7.312,0.00,-0.0002,-0.00020,1.000
1,7.438,-0.01,-0.0002,-0.00020,1.000
1,7.562,-0.01,-0.0002,-0.00020,1.000
1,7.688,0.00,-0.0002,-0.00020,1.000
1,7.812,0.00,-0.0002,-0.00020,1.000
1,7.938,-0.01,-0.0002,-0.00020,1.000
1,8.062,-0.01,-0.0002,-0.00020,1.000
1,8.188,-0.01,-0.0002,-0.00020,1.000
1,8.312,-0.01,-0.0002,-0.00020,1.000
1,8.438,-0.01,-0.0002,-0.00020,1.000
1,8.562,0.00,-0.0002,-0.00020,1.000
1,8.688,-0.01,-0.0002,-0.00020,1.000
1,8.812,-0.01,-0.0002,-0.00020,1.000
1,8.938,-0.01,-0.0002,-0.00020,1.000
1,9.062,-0.01,-0.0002,-0.00020,1.000
1,9.188,-0.01,-0.0002,-0.00020,1.000
1,9.312,-0.01,-0.0002,-0.00020,1.000
1,9.438,0.00,-0.0001,-0.00010,1.000
1,9.562,-0.01,-0.0001,-0.00010,1.000
2,9.938,0.00,0.1082,0.10828,2.000
2,10.062,0.00,0.2332,0.23335,2.000
2,10.188,0.00,0.3583,0.35840,2.000
2,10.312,0.01,0.4832,0.48327,2.000
2,10.438,0.00,0.6082,0.60828,2.000
2,10.562,0.00,0.7333,0.73337,2.000
2,10.688,0.00,0.8582,0.85830,2.000
2,10.812,0.00,0.9833,0.98340,2.000
2,10.938,0.00,1.1083,1.10840,2.000
2,11.062,0.00,1.2333,1.23342,2.000
2,11.188,0.00,1.3582,1.35825,2.000
2,11.312,0.00,1.4832,1.48330,2.000
2,11.438,0.00,1.6082,1.60828,2.000
2,11.562,0.02,1.7333,1.73340,2.000
2,11.688,0.05,1.8584,1.85845,2.000
2,11.812,0.11,1.9833,1.98340,2.000
2,11.938,0.24,2.1083,2.10843,2.000
2,12.062,0.46,2.2334,2.23347,2.000
2,12.188,0.76,2.3583,2.35843,2.000
2,12.312,1.16,2.4832,2.48335,2.000
2,12.438,1.67,2.6083,2.60838,2.000
2,12.562,2.30,2.7332,2.73332,2.000
2,12.688,3.09,2.8583,2.85838,2.000
2,12.812,4.05,2.9833,2.98342,2.000
2,13.062,4.82,3.0692,3.06928,2.000
2,13.188,3.48,2.9441,2.94420,2.000
2,13.312,2.50,2.8191,2.81915,2.000
2,13.438,1.76,2.6939,2.69400,2.000
2,13.562,1.20,2.5689,2.56903,2.000
2,13.688,0.78,2.4440,2.44412,2.000
2,13.812,0.47,2.3191,2.31920,2.000
2,13.938,0.24,2.1940,2.19410,2.000
2,14.062,0.09,2.0691,2.06918,2.000
2,14.188,0.03,1.9440,1.94410,2.000
2,14.312,0.02,1.8191,1.81920,2.000
2,14.438,0.01,1.6939,1.69405,2.000
2,14.562,0.00,1.5689,1.56898,2.000
2,14.688,0.00,1.4439,1.44400,2.000
2,14.812,0.01,1.3189,1.31895,2.000
2,14.938,0.00,1.1939,1.19397,2.000
2,15.062,0.00,1.0690,1.06913,2.000
2,15.188,0.01,0.9439,0.94402,2.000
2,15.312,0.00,0.8190,0.81910,2.000
2,15.438,0.00,0.6939,0.69400,2.000
2,15.562,0.00,0.5689,0.56898,2.000
2,15.688,0.00,0.4438,0.44390,2.000
2,15.812,0.00,0.3189,0.31895,2.000
2,15.938,0.00,0.1938,0.19390,2.000
2,16.062,0.01,0.0688,0.06892,2.000
2,16.250,0.01,-0.0183,-0.01820,2.000
2,16.375,0.00,-0.0003,-0.00020,2.000
2,16.500,0.01,-0.0002,-0.00010,2.000
2,16.625,0.01,-0.0002,-0.00010,2.000
2,16.750,0.00,-0.0002,-0.00010,2.000
2,16.875,0.00,-0.0002,-0.00010,2.000
2,17.000,0.01,-0.0002,-0.00010,2.000
2,17.125,0.01,-0.0002,-0.00010,2.000
2,17.250,0.01,-0.0002,-0.00010,2.000
2,17.375,0.00,-0.0002,-0.00010,2.000
2,17.500,0.00,-0.0002,-0.00010,2.000
2,17.625,0.01,-0.0002,-0.00010,2.000
2,17.750,0.00,-0.0002,-0.00010,2.000
2,17.875,0.00,-0.0002,-0.00010,2.000
2,18.000,0.01,-0.0002,-0.00010,2.000
2,18.125,0.01,-0.0002,-0.00010,2.000
2,18.250,0.00,-0.0002,-0.00010,2.000
2,18.375,0.00,-0.0002,-0.00010,2.000
2,18.500,0.00,-0.0002,-0.00010,2.000
2,18.625,0.00,-0.0002,-0.00010,2.000
2,18.750,0.01,-0.0002,-0.00010,2.000
2,18.875,0.00,-0.0002,-0.00010,2.000
2,19.000,0.00,-0.0002,-0.00010,2.000
2,19.125,0.01,-0.0002,-0.00010,2.000
3,19.500,0.01,0.0586,0.05870,3.000
3,19.625,0.00,0.1837,0.18380,3.000
3,19.750,0.00,0.3088,0.30890,3.000
3,19.875,0.01,0.4337,0.43380,3.000
3,20.000,0.01,0.5586,0.55870,3.000
3,20.125,0.00,0.6836,0.68375,3.000
3,20.250,0.01,0.8087,0.80880,3.000
3,20.375,0.01,0.9337,0.93375,3.000
3,20.500,0.00,1.0588,1.05890,3.000
3,20.625,0.00,1.1837,1.18380,3.000
3,20.750,0.00,1.3088,1.30890,3.000
3,20.875,0.01,1.4338,1.43390,3.000
3,21.000,0.01,1.5587,1.55880,3.000
3,21.125,0.01,1.6836,1.68375,3.000
3,21.250,0.04,1.8087,1.80880,3.000
3,21.375,0.08,1.9337,1.93380,3.000
3,21.500,0.17,2.0588,2.05890,3.000
3,21.625,0.35,2.1838,2.18390,3.000
3,21.750,0.62,2.3089,2.30900,3.000
3,21.875,0.99,2.4339,2.43400,3.000
3,22.000,1.45,2.5588,2.55890,3.000
3,22.125,2.03,2.6838,2.68385,3.000
3,22.250,2.75,2.8086,2.80870,3.000
3,22.375,3.64,2.9337,2.93380,3.000
3,22.500,4.71,3.0589,3.05900,3.000
3,22.750,4.30,3.0317,3.03180,3.000
3,22.875,3.12,2.9066,2.90665,3.000
3,23.000,2.23,2.7816,2.78170,3.000
3,23.125,1.56,2.6565,2.65660,3.000
3,23.250,1.05,2.5314,2.53150,3.000
3,23.375,0.67,2.4066,2.40665,3.000
3,23.500,0.38,2.2815,2.28160,3.000
3,23.625,0.18,2.1565,2.15660,3.000
3,23.750,0.06,2.0316,2.03170,3.000
3,23.875,0.03,1.9065,1.90660,3.000
3,24.000,0.02,1.7816,1.78170,3.000
3,24.125,0.00,1.6564,1.65650,3.000
3,24.250,0.00,1.5314,1.53150,3.000
3,24.375,0.00,1.4064,1.40645,3.000
3,24.500,0.00,1.2814,1.28150,3.000
3,24.625,0.00,1.1564,1.15645,3.000
3,24.750,0.00,1.0314,1.03150,3.000
3,24.875,0.00,0.9064,0.90650,3.000
3,25.000,0.00,0.7814,0.78150,3.000
3,25.125,0.00,0.6564,0.65650,3.000
3,25.250,0.00,0.5313,0.53140,3.000
3,25.375,0.00,0.4064,0.40645,3.000
3,25.500,0.00,0.2813,0.28140,3.000
3,25.625,0.00,0.1563,0.15645,3.000
3,25.750,0.01,0.0314,0.03150,3.000
3,26.000,0.00,-0.0001,0.00000,3.000
3,26.125,0.00,-0.0002,-0.00010,3.000
3,26.250,0.00,-0.0002,-0.00010,3.000
3,26.375,0.00,-0.0002,-0.00010,3.000
3,26.500,0.00,-0.0002,-0.00010,3.000
3,26.625,0.00,-0.0002,-0.00010,3.000
3,26.750,0.00,-0.0002,-0.00010,3.000
3,26.875,0.00,-0.0002,-0.00010,3.000
3,27.000,0.01,-0.0002,-0.00010,3.000
3,27.125,0.01,-0.0002,-0.00010,3.000
3,27.250,0.00,-0.0002,-0.00010,3.000
3,27.375,0.00,-0.0002,-0.00010,3.000
3,27.500,0.00,-0.0002,-0.00010,3.000
3,27.625,0.01,-0.0002,-0.00010,3.000
3,27.750,0.00,-0.0002,-0.00010,3.000
3,27.875,0.00,-0.0002,-0.00010,3.000
3,28.000,0.01,-0.0002,-0.00010,3.000
3,28.125,0.00,-0.0002,-0.00010,3.000
3,28.250,0.00,-0.0002,-0.00010,3.000
3,28.375,0.00,-0.0002,-0.00010,3.000
3,28.500,0.00,-0.0002,-0.00010,3.000
3,28.625,0.00,-0.0002,-0.00010,3.000
3,28.750,0.00,-0.0002,-0.00010,3.000
3,28.875,0.01,-0.0001,0.00000,3.000
4,29.250,0.00,0.1488,0.14890,4.000
4,29.375,0.00,0.2737,0.27380,4.000
4,29.500,-0.01,0.3987,0.39880,4.000
4,29.625,0.00,0.5236,0.52370,4.000
4,29.750,0.00,0.6486,0.64870,4.000
4,29.875,0.00,0.7736,0.77375,4.000
4,30.000,0.00,0.8988,0.89890,4.000
4,30.125,0.00,1.0238,1.02390,4.000
4,30.250,0.00,1.1487,1.14880,4.000
4,30.375,0.00,1.2737,1.27380,4.000
4,30.500,0.00,1.3987,1.39880,4.000
4,30.625,0.00,1.5237,1.52375,4.000
4,30.750,0.00,1.6486,1.64870,4.000
4,30.875,0.03,1.7738,1.77390,4.000
4,31.000,0.06,1.8988,1.89890,4.000
4,31.125,0.13,2.0238,2.02390,4.000
4,31.250,0.29,2.1489,2.14900,4.000
4,31.375,0.54,2.2739,2.27395,4.000
4,31.500,0.87,2.3989,2.39900,4.000
4,31.625,1.30,2.5238,2.52385,4.000
4,31.750,1.85,2.6488,2.64890,4.000
4,31.875,2.52,2.7737,2.77380,4.000
4,32.000,3.37,2.8987,2.89880,4.000
4,32.125,4.39,3.0238,3.02390,4.000
4,32.312,5.52,3.1271,3.12723,4.000
4,32.438,3.99,3.0021,3.00220,4.000
4,32.562,2.88,2.8770,2.87710,4.000
4,32.688,2.05,2.7520,2.75210,4.000
4,32.812,1.42,2.6270,2.62713,4.000
4,32.938,0.94,2.5020,2.50212,4.000
4,33.062,0.59,2.3771,2.37718,4.000
4,33.188,0.32,2.2519,2.25197,4.000
4,33.312,0.14,2.1269,2.12700,4.000
4,33.438,0.05,2.0019,2.00205,4.000
4,33.562,0.02,1.8770,1.87713,4.000
4,33.688,0.01,1.7520,1.75212,4.000
4,33.812,0.00,1.6269,1.62703,4.000
4,33.938,0.00,1.5021,1.50217,4.000
4,34.062,0.00,1.3770,1.37705,4.000
4,34.188,0.00,1.2518,1.25190,4.000
4,34.312,0.00,1.1269,1.12700,4.000
4,34.438,0.00,1.0019,1.00197,4.000
4,34.562,0.00,0.8769,0.87695,4.000
4,34.688,0.00,0.7518,0.75192,4.000
4,34.812,0.00,0.6269,0.62703,4.000
4,34.938,0.00,0.5019,0.50200,4.000
4,35.062,0.00,0.3769,0.37700,4.000
4,35.188,0.00,0.2518,0.25195,4.000
4,35.312,0.00,0.1268,0.12690,4.000
4,35.438,0.00,0.0018,0.00187,4.000
4,35.625,0.00,-0.0002,-0.00010,4.000
4,35.750,0.00,-0.0002,-0.00010,4.000
4,35.875,0.00,-0.0002,-0.00010,4.000
4,36.000,-0.01,-0.0002,-0.00010,4.000
4,36.125,0.00,-0.0002,-0.00010,4.000
4,36.250,0.00,-0.0002,-0.00010,4.000
4,36.375,0.00,-0.0002,-0.00010,4.000
4,36.500,0.00,-0.0002,-0.00010,4.000
4,36.625,0.00,-0.0002,-0.00010,4.000
4,36.750,0.00,-0.0002,-0.00010,4.000
4,36.875,0.00,-0.0002,-0.00010,4.000
4,37.000,0.00,-0.0002,-0.00010,4.000
4,37.125,0.00,-0.0002,-0.00010,4.000
4,37.250,0.00,-0.0002,-0.00010,4.000
4,37.375,0.00,-0.0002,-0.00010,4.000
4,37.500,0.00,-0.0002,-0.00010,4.000
4,37.625,0.00,-0.0002,-0.00010,4.000
4,37.750,0.00,-0.0002,-0.00010,4.000
4,37.875,0.00,-0.0002,-0.00010,4.000
4,38.000,0.01,-0.0002,-0.00010,4.000
4,38.125,0.00,-0.0002,-0.00010,4.000
4,38.250,0.00,-0.0002,-0.00010,4.000
4,38.375,0.00,-0.0002,-0.00010,4.000
4,38.500,0.00,-0.0002,-0.00010,4.000
5,38.875,0.00,0.1235,0.12360,5.000
5,39.000,0.00,0.2487,0.24880,5.000
5,39.125,0.00,0.3738,0.37390,5.000
5,39.250,-0.01,0.4986,0.49870,5.000
5,39.375,0.00,0.6238,0.62385,5.000
5,39.500,0.00,0.7488,0.74890,5.000
5,39.625,0.00,0.8737,0.87380,5.000
5,39.750,0.00,0.9986,0.99870,5.000
5,39.875,0.00,1.1236,1.12375,5.000
5,40.000,0.00,1.2486,1.24870,5.000
5,40.125,0.00,1.3736,1.37375,5.000
5,40.250,0.00,1.4988,1.49890,5.000
5,40.375,0.00,1.6238,1.62385,5.000
5,40.500,0.02,1.7490,1.74910,5.000
5,40.625,0.05,1.8739,1.87400,5.000
5,40.750,0.11,1.9987,1.99880,5.000
5,40.875,0.25,2.1238,2.12385,5.000
5,41.000,0.48,2.2488,2.24890,5.000
5,41.125,0.79,2.3738,2.37390,5.000
5,41.250,1.21,2.4988,2.49890,5.000
5,41.375,1.73,2.6238,2.62395,5.000
5,41.500,2.38,2.7489,2.74900,5.000
5,41.625,3.18,2.8738,2.87390,5.000
5,41.750,4.18,2.9989,2.99900,5.000
5,41.938,5.37,3.1120,3.11207,5.000
5,42.062,3.88,2.9872,2.98728,5.000
5,42.188,2.79,2.8619,2.86205,5.000
5,42.312,1.98,2.7371,2.73715,5.000
5,42.438,1.36,2.6119,2.61202,5.000
5,42.562,0.90,2.4870,2.48713,5.000
5,42.688,0.56,2.3620,2.36215,5.000
5,42.812,0.30,2.2369,2.23703,5.000
5,42.938,0.12,2.1120,2.11215,5.000
5,43.062,0.04,1.9870,1.98708,5.000
5,43.188,0.02,1.8620,1.86212,5.000
5,43.312,0.01,1.7370,1.73713,5.000
5,43.438,0.00,1.6118,1.61187,5.000
5,43.562,0.00,1.4869,1.48695,5.000
5,43.688,0.00,1.3618,1.36195,5.000
5,43.812,0.00,1.2369,1.23703,5.000
5,43.938,0.00,1.1119,1.11200,5.000
5,44.062,0.00,0.9869,0.98703,5.000
5,44.188,0.00,0.8620,0.86207,5.000
5,44.312,0.00,0.7369,0.73698,5.000
5,44.438,0.00,0.6118,0.61195,5.000
5,44.562,0.00,0.4868,0.48690,5.000
5,44.688,0.00,0.3619,0.36200,5.000
5,44.812,0.00,0.2368,0.23693,5.000
5,44.938,0.00,0.1119,0.11197,5.000
5,45.188,0.00,-0.0003,-0.00020,5.000
5,45.312,0.00,-0.0002,-0.00010,5.000
5,45.438,0.00,-0.0002,-0.00010,5.000
5,45.562,0.00,-0.0002,-0.00010,5.000
5,45.688,0.00,-0.0002,-0.00010,5.000
5,45.812,0.00,-0.0002,-0.00010,5.000
5,45.938,0.00,-0.0002,-0.00010,5.000
5,46.062,0.00,-0.0002,-0.00010,5.000
5,46.188,0.00,-0.0002,-0.00010,5.000
5,46.312,0.00,-0.0002,-0.00010,5.000
5,46.438,0.00,-0.0002,-0.00010,5.000
5,46.562,0.00,-0.0002,-0.00010,5.000
5,46.688,0.00,-0.0002,-0.00010,5.000
5,46.812,0.00,-0.0002,-0.00010,5.000
5,46.938,0.00,-0.0002,-0.00010,5.000
5,47.062,0.00,-0.0002,-0.00010,5.000
5,47.188,0.00,-0.0002,-0.00010,5.000
5,47.312,0.00,-0.0002,-0.00010,5.000
5,47.438,0.00,-0.0002,-0.00010,5.000
5,47.562,0.00,-0.0002,-0.00010,5.000
5,47.688,0.00,-0.0002,-0.00010,5.000
5,47.812,-0.01,-0.0002,-0.00010,5.000
5,47.938,0.00,-0.0002,-0.00010,5.000
5,48.062,0.00,-0.0002,-0.00010,5.000
6,48.438,0.01,0.0761,0.07608,6.000
6,48.562,0.01,0.2011,0.20112,6.000
6,48.688,0.01,0.3262,0.32620,6.000
6,48.812,0.00,0.4512,0.45117,6.000
6,48.938,0.00,0.5761,0.57610,6.000
6,49.062,0.00,0.7011,0.70115,6.000
6,49.188,0.00,0.8263,0.82628,6.000
6,49.312,0.00,0.9512,0.95125,6.000
6,49.438,0.01,1.0763,1.07625,6.000
6,49.562,0.00,1.2012,1.20117,6.000
6,49.688,0.00,1.3262,1.32615,6.000
6,49.812,0.00,1.4512,1.45122,6.000
6,49.938,0.01,1.5762,1.57615,6.000
6,50.062,0.01,1.7013,1.70130,6.000
6,50.188,0.04,1.8265,1.82645,6.000
6,50.312,0.09,1.9513,1.95132,6.000
6,50.438,0.19,2.0764,2.07635,6.000
6,50.562,0.39,2.2013,2.20127,6.000
6,50.688,0.67,2.3263,2.32628,6.000
6,50.812,1.04,2.4513,2.45130,6.000
6,50.938,1.52,2.5763,2.57625,6.000
6,51.062,2.12,2.7012,2.70125,6.000
6,51.188,2.87,2.8263,2.82628,6.000
6,51.312,3.78,2.9514,2.95137,6.000
6,51.438,4.89,3.0764,3.07640,6.000
6,51.625,4.42,3.0366,3.03660,6.000
6,51.750,3.20,2.9116,2.91160,6.000
6,51.875,2.28,2.7866,2.78655,6.000
6,52.000,1.60,2.6615,2.66150,6.000
6,52.125,1.08,2.5365,2.53650,6.000
6,52.250,0.69,2.4114,2.41140,6.000
6,52.375,0.40,2.2865,2.28645,6.000
6,52.500,0.19,2.1615,2.16150,6.000
6,52.625,0.07,2.0365,2.03645,6.000
6,52.750,0.03,1.9116,1.91160,6.000
6,52.875,0.02,1.7866,1.78660,6.000
6,53.000,0.01,1.6615,1.66150,6.000
6,53.125,0.01,1.5365,1.53645,6.000
6,53.250,0.00,1.4114,1.41140,6.000
6,53.375,0.00,1.2864,1.28635,6.000
6,53.500,0.00,1.1614,1.16140,6.000
6,53.625,0.00,1.0364,1.03635,6.000
6,53.750,0.01,0.9114,0.91140,6.000
6,53.875,0.00,0.7864,0.78640,6.000
6,54.000,0.00,0.6614,0.66140,6.000
6,54.125,0.01,0.5364,0.53635,6.000
6,54.250,0.00,0.4114,0.41140,6.000
6,54.375,0.00,0.2864,0.28635,6.000
6,54.500,0.01,0.1612,0.16120,6.000
6,54.625,0.01,0.0364,0.03635,6.000
6,54.875,0.00,-0.0003,-0.00025,6.000
6,55.000,0.01,-0.0002,-0.00020,6.000
6,55.125,0.01,-0.0002,-0.00020,6.000
6,55.250,0.00,-0.0002,-0.00020,6.000
6,55.375,0.01,-0.0002,-0.00020,6.000
6,55.500,0.00,-0.0002,-0.00020,6.000
6,55.625,0.00,-0.0002,-0.00020,6.000
6,55.750,0.00,-0.0002,-0.00020,6.000
6,55.875,0.00,-0.0002,-0.00020,6.000
6,56.000,0.00,-0.0002,-0.00020,6.000
6,56.125,0.00,-0.0002,-0.00020,6.000
6,56.250,0.00,-0.0002,-0.00020,6.000
6,56.375,0.00,-0.0002,-0.00020,6.000
6,56.500,0.00,-0.0002,-0.00020,6.000
6,56.625,0.00,-0.0002,-0.00020,6.000
6,56.750,0.00,-0.0002,-0.00020,6.000
6,56.875,0.00,-0.0002,-0.00020,6.000
6,57.000,0.00,-0.0002,-0.00020,6.000
6,57.125,0.01,-0.0002,-0.00020,6.000
6,57.250,0.00,-0.0002,-0.00020,6.000
6,57.375,0.00,-0.0002,-0.00020,6.000
6,57.500,0.00,-0.0002,-0.00020,6.000
6,57.625,0.00,-0.0002,-0.00020,6.000
6,57.750,0.00,-0.0001,-0.00010,6.000
7,58.125,0.00,0.1436,0.14365,7.000
7,58.250,0.00,0.2689,0.26890,7.000
7,58.375,0.00,0.3938,0.39380,7.000
7,58.500,0.00,0.5186,0.51860,7.000
7,58.625,0.00,0.6436,0.64365,7.000
7,58.750,0.00,0.7685,0.76850,7.000
7,58.875,0.00,0.8936,0.89365,7.000
7,59.000,-0.01,1.0188,1.01880,7.000
7,59.125,0.00,1.1437,1.14375,7.000
7,59.250,0.00,1.2687,1.26870,7.000
7,59.375,0.00,1.3937,1.39370,7.000
7,59.500,0.00,1.5187,1.51870,7.000
7,59.625,0.00,1.6436,1.64365,7.000
7,59.750,0.03,1.7687,1.76870,7.000
7,59.875,0.05,1.8937,1.89375,7.000
7,60.000,0.13,2.0187,2.01870,7.000
7,60.125,0.28,2.1438,2.14380,7.000
7,60.250,0.52,2.2689,2.26890,7.000
7,60.375,0.85,2.3939,2.39390,7.000
7,60.500,1.28,2.5188,2.51880,7.000
7,60.625,1.83,2.6437,2.64375,7.000
7,60.750,2.51,2.7686,2.76860,7.000
7,60.875,3.34,2.8936,2.89365,7.000
7,61.000,4.36,3.0188,3.01880,7.000
7,61.188,5.14,3.0920,3.09197,7.000
7,61.312,3.69,2.9671,2.96708,7.000
7,61.438,2.65,2.8420,2.84197,7.000
7,61.562,1.87,2.7171,2.71708,7.000
7,61.688,1.28,2.5921,2.59208,7.000
7,61.812,0.84,2.4671,2.46710,7.000
7,61.938,0.51,2.3421,2.34213,7.000
7,62.062,0.27,2.2170,2.21698,7.000
7,62.188,0.11,2.0919,2.09193,7.000
7,62.312,0.03,1.9669,1.96690,7.000
7,62.438,0.01,1.8421,1.84205,7.000
7,62.562,0.00,1.7170,1.71695,7.000
7,62.688,0.00,1.5920,1.59195,7.000
7,62.812,0.00,1.4670,1.46703,7.000
7,62.938,0.00,1.3420,1.34198,7.000
7,63.062,0.00,1.2169,1.21693,7.000
7,63.188,0.00,1.0918,1.09183,7.000
7,63.312,0.00,0.9668,0.96683,7.000
7,63.438,0.00,0.8418,0.84180,7.000
7,63.562,0.00,0.7169,0.71685,7.000
7,63.688,0.00,0.5919,0.59190,7.000
7,63.812,0.00,0.4669,0.46685,7.000
7,63.938,0.00,0.3421,0.34205,7.000
7,64.062,0.00,0.2170,0.21695,7.000
7,64.188,0.00,0.0918,0.09185,7.000
7,64.375,0.00,-0.0258,-0.02585,7.000
7,64.500,0.00,-0.0002,-0.00020,7.000
7,64.625,0.00,-0.0002,-0.00020,7.000
7,64.750,0.00,-0.0002,-0.00020,7.000
7,64.875,0.00,-0.0002,-0.00020,7.000
7,65.000,0.00,-0.0002,-0.00020,7.000
7,65.125,0.00,-0.0002,-0.00020,7.000
7,65.250,0.00,-0.0002,-0.00020,7.000
7,65.375,0.00,-0.0002,-0.00020,7.000
7,65.500,0.00,-0.0002,-0.00020,7.000
7,65.625,0.00,-0.0002,-0.00020,7.000
7,65.750,0.00,-0.0002,-0.00020,7.000
7,65.875,0.00,-0.0002,-0.00020,7.000
7,66.000,0.00,-0.0002,-0.00020,7.000
7,66.125,0.00,-0.0002,-0.00020,7.000
7,66.250,0.00,-0.0002,-0.00020,7.000
7,66.375,0.00,-0.0002,-0.00020,7.000
7,66.500,0.00,-0.0002,-0.00020,7.000
7,66.625,0.00,-0.0002,-0.00020,7.000
7,66.750,0.00,-0.0002,-0.00020,7.000
7,66.875,0.00,-0.0002,-0.00020,7.000
7,67.000,0.00,-0.0002,-0.00020,7.000
7,67.125,0.00,-0.0002,-0.00020,7.000
7,67.250,0.00,-0.0002,-0.00020,7.000
8,67.688,0.00,0.0981,0.09810,8.000
8,67.812,-0.01,0.2232,0.22322,8.000
8,67.938,-0.01,0.3484,0.34838,8.000
8,68.062,-0.01,0.4732,0.47325,8.000
8,68.188,-0.01,0.5982,0.59818,8.000
8,68.312,-0.01,0.7232,0.72317,8.000
8,68.438,-0.01,0.8482,0.84818,8.000
8,68.562,0.00,0.9731,0.97315,8.000
8,68.688,-0.01,1.0982,1.09820,8.000
8,68.812,-0.01,1.2233,1.22327,8.000
8,68.938,-0.01,1.3483,1.34830,8.000
8,69.062,0.00,1.4733,1.47330,8.000
8,69.188,0.00,1.5982,1.59818,8.000
8,69.312,0.01,1.7232,1.72325,8.000
8,69.438,0.03,1.8482,1.84825,8.000
8,69.562,0.09,1.9732,1.97322,8.000
8,69.688,0.21,2.0982,2.09820,8.000
8,69.812,0.42,2.2233,2.22332,8.000
8,69.938,0.71,2.3484,2.34838,8.000
8,70.062,1.10,2.4734,2.47345,8.000
8,70.188,1.60,2.5983,2.59825,8.000
8,70.312,2.22,2.7232,2.72322,8.000
8,70.438,3.00,2.8482,2.84820,8.000
8,70.562,3.95,2.9732,2.97320,8.000
8,70.688,5.09,3.0984,3.09835,8.000
8,70.875,4.38,3.0366,3.03660,8.000
8,71.000,3.17,2.9116,2.91160,8.000
8,71.125,2.26,2.7866,2.78660,8.000
8,71.250,1.57,2.6617,2.66170,8.000
8,71.375,1.06,2.5365,2.53645,8.000
8,71.500,0.67,2.4114,2.41140,8.000
8,71.625,0.38,2.2865,2.28645,8.000
8,71.750,0.18,2.1615,2.16150,8.000
8,71.875,0.05,2.0365,2.03650,8.000
8,72.000,0.03,1.9116,1.91160,8.000
8,72.125,0.01,1.7866,1.78660,8.000
8,72.250,-0.01,1.6614,1.66140,8.000
8,72.375,-0.01,1.5364,1.53640,8.000
8,72.500,-0.01,1.4113,1.41130,8.000
8,72.625,-0.01,1.2864,1.28635,8.000
8,72.750,-0.01,1.1614,1.16140,8.000
8,72.875,0.00,1.0365,1.03645,8.000
8,73.000,0.00,0.9114,0.91140,8.000
8,73.125,0.00,0.7865,0.78645,8.000
8,73.250,-0.01,0.6615,0.66150,8.000
8,73.375,-0.01,0.5364,0.53640,8.000
8,73.500,-0.01,0.4113,0.41130,8.000
8,73.625,-0.01,0.2863,0.28630,8.000
8,73.750,0.00,0.1613,0.16130,8.000
8,73.875,-0.01,0.0363,0.03630,8.000
8,74.062,-0.01,-0.0074,-0.00743,8.000
8,74.188,-0.01,-0.0002,-0.00020,8.000
8,74.312,-0.01,-0.0002,-0.00020,8.000
8,74.438,-0.01,-0.0002,-0.00020,8.000
8,74.562,0.00,-0.0002,-0.00020,8.000
8,74.688,-0.01,-0.0002,-0.00020,8.000
8,74.812,0.00,-0.0002,-0.00020,8.000
8,74.938,-0.01,-0.0002,-0.00020,8.000
8,75.062,-0.01,-0.0002,-0.00020,8.000
8,75.188,-0.01,-0.0002,-0.00020,8.000
8,75.312,-0.01,-0.0002,-0.00020,8.000
8,75.438,-0.01,-0.0002,-0.00020,8.000
8,75.562,-0.01,-0.0002,-0.00020,8.000
8,75.688,-0.01,-0.0002,-0.00020,8.000
8,75.812,-0.01,-0.0002,-0.00020,8.000
8,75.938,0.00,-0.0002,-0.00020,8.000
8,76.062,-0.01,-0.0002,-0.00020,8.000
8,76.188,0.00,-0.0002,-0.00020,8.000
8,76.312,-0.01,-0.0002,-0.00020,8.000
8,76.438,0.00,-0.0002,-0.00020,8.000
8,76.562,-0.01,-0.0002,-0.00020,8.000
8,76.688,-0.01,-0.0002,-0.00020,8.000
8,76.812,-0.01,-0.0002,-0.00020,8.000
8,76.938,-0.01,-0.0001,-0.00010,8.000
9,77.312,0.00,0.0900,0.09002,9.000
9,77.438,0.00,0.2152,0.21515,9.000
9,77.562,0.00,0.3403,0.34030,9.000
9,77.688,0.00,0.4653,0.46525,9.000
9,77.812,0.00,0.5902,0.59025,9.000
9,77.938,0.00,0.7153,0.71528,9.000
9,78.062,0.00,0.8401,0.84012,9.000
9,78.188,0.00,0.9651,0.96512,9.000
9,78.312,0.00,1.0901,1.09007,9.000
9,78.438,0.00,1.2152,1.21518,9.000
9,78.562,0.00,1.3403,1.34027,9.000
9,78.688,0.00,1.4654,1.46537,9.000
9,78.812,0.00,1.5903,1.59030,9.000
9,78.938,0.01,1.7153,1.71532,9.000
9,79.062,0.04,1.8403,1.84035,9.000
9,79.188,0.09,1.9652,1.96518,9.000
9,79.312,0.21,2.0901,2.09015,9.000
9,79.438,0.41,2.2153,2.21528,9.000
9,79.562,0.70,2.3403,2.34030,9.000
9,79.688,1.08,2.4654,2.46540,9.000
9,79.812,1.57,2.5904,2.59037,9.000
9,79.938,2.18,2.7153,2.71532,9.000
9,80.062,2.95,2.8403,2.84027,9.000
9,80.188,3.89,2.9653,2.96530,9.000
9,80.312,5.01,3.0902,3.09020,9.000
9,80.500,4.63,3.0605,3.06050,9.000
9,80.625,3.36,2.9355,2.93550,9.000
9,80.750,2.41,2.8104,2.81040,9.000
9,80.875,1.69,2.6855,2.68545,9.000
9,81.000,1.15,2.5606,2.56060,9.000
9,81.125,0.74,2.4356,2.43560,9.000
9,81.250,0.43,2.3106,2.31060,9.000
9,81.375,0.22,2.1855,2.18550,9.000
9,81.500,0.07,2.0605,2.06050,9.000
9,81.625,0.03,1.9354,1.93540,9.000
9,81.750,0.01,1.8105,1.81050,9.000
9,81.875,0.00,1.6854,1.68540,9.000
9,82.000,0.00,1.5605,1.56050,9.000
9,82.125,0.00,1.4354,1.43540,9.000
9,82.250,0.00,1.3104,1.31040,9.000
9,82.375,0.00,1.1855,1.18545,9.000
9,82.500,0.00,1.0604,1.06040,9.000
9,82.625,0.00,0.9354,0.93540,9.000
9,82.750,0.00,0.8103,0.81030,9.000
9,82.875,0.00,0.6854,0.68535,9.000
9,83.000,-0.01,0.5603,0.56030,9.000
9,83.125,0.00,0.4354,0.43535,9.000
9,83.250,0.00,0.3105,0.31050,9.000
9,83.375,0.00,0.1854,0.18545,9.000
9,83.500,0.00,0.0604,0.06040,9.000
9,83.688,0.00,-0.0323,-0.03227,9.000
9,83.812,0.00,-0.0002,-0.00020,9.000
9,83.938,0.00,-0.0002,-0.00020,9.000
9,84.062,0.00,-0.0002,-0.00020,9.000
9,84.188,0.00,-0.0002,-0.00020,9.000
9,84.312,0.00,-0.0002,-0.00020,9.000
9,84.438,0.00,-0.0002,-0.00020,9.000
9,84.562,0.00,-0.0002,-0.00020,9.000
9,84.688,0.00,-0.0002,-0.00020,9.000
9,84.812,0.00,-0.0002,-0.00020,9.000
9,84.938,-0.01,-0.0002,-0.00020,9.000
9,85.062,0.00,-0.0002,-0.00020,9.000
9,85.188,-0.01,-0.0002,-0.00020,9.000
9,85.312,0.00,-0.0002,-0.00020,9.000
9,85.438,0.00,-0.0002,-0.00020,9.000
9,85.562,0.00,-0.0002,-0.00020,9.000
9,85.688,0.00,-0.0002,-0.00020,9.000
9,85.812,0.00,-0.0002,-0.00020,9.000
9,85.938,0.00,-0.0002,-0.00020,9.000
9,86.062,0.00,-0.0002,-0.00020,9.000
9,86.188,0.00,-0.0002,-0.00020,9.000
9,86.312,0.00,-0.0002,-0.00020,9.000
9,86.438,0.00,-0.0002,-0.00020,9.000
9,86.562,0.00,-0.0002,-0.00020,9.000
10,86.938,0.01,0.0771,0.07705,10.000
10,87.062,0.00,0.2021,0.20210,10.000
10,87.188,0.00,0.3271,0.32712,10.000
10,87.312,0.01,0.4521,0.45212,10.000
10,87.438,0.01,0.5772,0.57718,10.000
10,87.562,0.01,0.7022,0.70220,10.000
10,87.688,0.01,0.8273,0.82728,10.000
10,87.812,0.01,0.9523,0.95227,10.000
10,87.938,0.00,1.0772,1.07722,10.000
10,88.062,0.01,1.2021,1.20212,10.000
10,88.188,0.00,1.3272,1.32715,10.000
10,88.312,0.00,1.4522,1.45222,10.000
10,88.438,0.01,1.5772,1.57720,10.000
10,88.562,0.02,1.7022,1.70222,10.000
10,88.688,0.04,1.8274,1.82745,10.000
10,88.812,0.09,1.9523,1.95230,10.000
10,88.938,0.19,2.0773,2.07732,10.000
10,89.062,0.39,2.2023,2.20230,10.000
10,89.188,0.67,2.3273,2.32730,10.000
10,89.312,1.05,2.4523,2.45232,10.000
10,89.438,1.52,2.5772,2.57720,10.000
10,89.562,2.13,2.7022,2.70225,10.000
10,89.688,2.87,2.8273,2.82730,10.000
10,89.812,3.79,2.9524,2.95237,10.000
10,89.938,4.89,3.0774,3.07738,10.000
10,90.125,4.61,3.0555,3.05550,10.000
10,90.250,3.34,2.9304,2.93040,10.000
10,90.375,2.39,2.8055,2.80550,10.000
10,90.500,1.68,2.6805,2.68050,10.000
10,90.625,1.14,2.5556,2.55555,10.000
10,90.750,0.74,2.4306,2.43060,10.000
10,90.875,0.43,2.3056,2.30560,10.000
10,91.000,0.21,2.1805,2.18050,10.000
10,91.125,0.08,2.0555,2.05545,10.000
10,91.250,0.04,1.9304,1.93040,10.000
10,91.375,0.02,1.8055,1.80550,10.000
10,91.500,0.01,1.6804,1.68040,10.000
10,91.625,0.01,1.5555,1.55550,10.000
10,91.750,0.01,1.4305,1.43050,10.000
10,91.875,0.01,1.3054,1.30545,10.000
10,92.000,0.00,1.1805,1.18050,10.000
10,92.125,0.01,1.0554,1.05540,10.000
10,92.250,0.00,0.9303,0.93030,10.000
10,92.375,0.00,0.8053,0.80530,10.000
10,92.500,0.00,0.6803,0.68030,10.000
10,92.625,0.00,0.5554,0.55540,10.000
10,92.750,0.01,0.4304,0.43040,10.000
10,92.875,0.01,0.3054,0.30545,10.000
10,93.000,0.01,0.1805,0.18050,10.000
10,93.125,0.01,0.0554,0.05535,10.000
10,93.312,0.01,-0.0264,-0.02643,10.000
10,93.438,0.01,-0.0003,-0.00030,10.000
10,93.562,0.00,-0.0002,-0.00020,10.000
10,93.688,0.01,-0.0002,-0.00020,10.000
10,93.812,0.01,-0.0002,-0.00020,10.000
10,93.938,0.01,-0.0002,-0.00020,10.000
10,94.062,0.00,-0.0002,-0.00020,10.000
10,94.188,0.01,-0.0002,-0.00020,10.000
10,94.312,0.01,-0.0002,-0.00020,10.000
10,94.438,0.00,-0.0002,-0.00020,10.000
10,94.562,0.01,-0.0002,-0.00020,10.000
10,94.688,0.01,-0.0002,-0.00020,10.000
10,94.812,0.01,-0.0002,-0.00020,10.000
10,94.938,0.00,-0.0002,-0.00020,10.000
10,95.062,0.01,-0.0002,-0.00020,10.000
10,95.188,0.01,-0.0002,-0.00020,10.000
10,95.312,0.01,-0.0002,-0.00020,10.000
10,95.438,0.01,-0.0002,-0.00020,10.000
10,95.562,0.01,-0.0002,-0.00020,10.000
10,95.688,0.01,-0.0002,-0.00020,10.000
10,95.812,0.00,-0.0002,-0.00020,10.000
10,95.938,0.00,-0.0002,-0.00020,10.000
10,96.062,0.01,-0.0002,-0.00020,10.000
10,96.188,0.00,-0.0002,-0.00020,10.000
10,96.250,0.00,-0.0002,-0.00020,10.000