File: calibDATA_loadcell/date_02:22:2018/Instron/5N_0_1_1_0.txt
""
"Test Method","Radhen_Load_Cntrl_Cmprsn_250N_12-7.msm"
"Sample I. D.","Sample1.mss"
"Specimen Number","3"

"TheCycle_Output ()","_Time (s)","_Load (N)","_Extension (mm)","RealTimeDepth (mm)","CycleNumber ()"

1,0.312,0.00,0.0972,0.09718,1.000
1,0.438,0.00,0.2222,0.22220,1.000
1,0.562,0.00,0.3472,0.34717,1.000
1,0.688,0.00,0.4721,0.47215,1.000
1,0.812,0.00,0.5973,0.59732,1.000
1,0.938,0.00,0.7223,0.72230,1.000
1,1.062,0.00,0.8473,0.84732,1.000
1,1.188,0.00,0.9724,0.97238,1.000
1,1.312,0.00,1.0973,1.09732,1.000
1,1.438,0.00,1.2224,1.22235,1.000
1,1.562,0.00,1.3474,1.34740,1.000
1,1.688,0.00,1.4723,1.47230,1.000
1,1.812,0.00,1.5975,1.59750,1.000
1,1.938,0.00,1.7223,1.72230,1.000
1,2.062,0.00,1.8472,1.84722,1.000
1,2.188,0.00,1.9724,1.97238,1.000
1,2.312,0.00,2.0974,2.09740,1.000
1,2.438,0.00,2.2224,2.22240,1.000
1,2.562,0.00,2.3475,2.34745,1.000
1,2.688,0.00,2.4723,2.47228,1.000
1,2.812,0.00,2.5972,2.59722,1.000
1,2.938,0.00,2.7224,2.72235,1.000
1,3.062,0.00,2.8474,2.84740,1.000
1,3.188,0.00,2.9724,2.97240,1.000
1,3.312,0.00,3.0975,3.09750,1.000
1,3.438,0.02,3.2225,3.22250,1.000
1,3.562,0.04,3.3474,3.34745,1.000
1,3.688,0.09,3.4724,3.47235,1.000
1,3.812,0.17,3.5974,3.59740,1.000
1,3.938,0.33,3.7224,3.72240,1.000
1,4.062,0.56,3.8473,3.84735,1.000
1,4.188,0.89,3.9724,3.97240,1.000
1,4.312,1.32,4.0973,4.09735,1.000
1,4.438,1.89,4.2225,4.22248,1.000
1,4.562,2.58,4.3474,4.34745,1.000
1,4.688,3.40,4.4724,4.47242,1.000
1,4.812,4.39,4.5973,4.59730,1.000
1,5.000,5.30,4.6851,4.68510,1.000
1,5.125,3.82,4.5606,4.56065,1.000
1,5.250,2.77,4.4358,4.43580,1.000
1,5.375,1.98,4.3108,4.31075,1.000
1,5.500,1.36,4.1858,4.18580,1.000
1,5.625,0.89,4.0607,4.06070,1.000
1,5.750,0.55,3.9357,3.93570,1.000
1,5.875,0.31,3.8106,3.81060,1.000
1,6.000,0.14,3.6856,3.68560,1.000
1,6.125,0.05,3.5606,3.56060,1.000
1,6.250,0.02,3.4355,3.43550,1.000
1,6.375,0.01,3.3106,3.31055,1.000
1,6.500,0.01,3.1856,3.18560,1.000
1,6.625,0.00,3.0608,3.06075,1.000
1,6.750,0.00,2.9357,2.93570,1.000
1,6.875,0.00,2.8106,2.81055,1.000
1,7.000,0.00,2.6855,2.68550,1.000
1,7.125,0.00,2.5604,2.56040,1.000
1,7.250,0.00,2.4354,2.43540,1.000
1,7.375,0.00,2.3105,2.31050,1.000
1,7.500,0.00,2.1854,2.18540,1.000
1,7.625,-0.01,2.0605,2.06050,1.000
1,7.750,0.00,1.9355,1.93550,1.000
1,7.875,0.00,1.8104,1.81035,1.000
1,8.000,-0.01,1.6856,1.68560,1.000
1,8.125,0.00,1.5605,1.56045,1.000
1,8.250,0.00,1.4353,1.43530,1.000
1,8.375,0.00,1.3104,1.31040,1.000
1,8.500,-0.01,1.1854,1.18540,1.000
1,8.625,0.00,1.0605,1.06050,1.000
1,8.750,0.00,0.9354,0.93540,1.000
1,8.875,0.00,0.8104,0.81040,1.000
1,9.000,0.00,0.6854,0.68540,1.000
1,9.125,0.00,0.5603,0.56030,1.000
1,9.250,0.00,0.4352,0.43520,1.000
1,9.375,0.00,0.3104,0.31035,1.000
1,9.500,0.00,0.1853,0.18530,1.000
1,9.625,0.00,0.0602,0.06020,1.000
1,9.812,0.00,-0.0075,-0.00750,1.000
1,9.938,0.00,-0.0003,-0.00030,1.000
1,10.062,0.00,-0.0003,-0.00030,1.000
1,10.188,0.00,-0.0003,-0.00030,1.000
1,10.312,0.00,-0.0003,-0.00030,1.000
1,10.438,0.00,-0.0003,-0.00030,1.000
1,10.562,0.00,-0.0003,-0.00030,1.000
1,10.688,0.00,-0.0003,-0.00030,1.000
1,10.812,0.00,-0.0003,-0.00030,1.000
1,10.938,-0.01,-0.0003,-0.00030,1.000
1,11.062,0.00,-0.0003,-0.00030,1.000
1,11.188,0.00,-0.0003,-0.00030,1.000
1,11.312,0.00,-0.0003,-0.00030,1.000
1,11.438,0.00,-0.0003,-0.00030,1.000
1,11.562,0.00,-0.0003,-0.00030,1.000
1,11.688,0.00,-0.0002,-0.00020,1.000
1,11.812,0.00,-0.0002,-0.00020,1.000
1,11.938,0.00,-0.0002,-0.00020,1.000
1,12.062,0.00,-0.0002,-0.00020,1.000
1,12.188,0.00,-0.0002,-0.00020,1.000
1,12.312,0.00,-0.0002,-0.00020,1.000
1,12.438,0.00,-0.0002,-0.00020,1.000
1,12.562,0.00,-0.0002,-0.00020,1.000
1,12.688,0.00,-0.0002,-0.00020,1.000
2,13.000,0.00,0.0536,0.05370,2.000
2,13.125,0.00,0.1786,0.17870,2.000
2,13.250,0.00,0.3036,0.30370,2.000
2,13.375,0.00,0.4285,0.42865,2.000
2,13.500,0.00,0.5535,0.55360,2.000
2,13.625,0.00,0.6786,0.67875,2.000
2,13.750,0.00,0.8037,0.80380,2.000
2,13.875,0.00,0.9286,0.92875,2.000
2,14.000,0.00,1.0538,1.05390,2.000
2,14.125,0.00,1.1787,1.17885,2.000
2,14.250,0.01,1.3038,1.30390,2.000
2,14.375,0.00,1.4287,1.42885,2.000
2,14.500,0.00,1.5536,1.55370,2.000
2,14.625,0.00,1.6788,1.67895,2.000
2,14.750,0.00,1.8036,1.80370,2.000
2,14.875,0.01,1.9287,1.92885,2.000
2,15.000,0.01,2.0537,2.05380,2.000
2,15.125,0.00,2.1788,2.17890,2.000
2,15.250,0.00,2.3039,2.30400,2.000
2,15.375,0.00,2.4287,2.42885,2.000
2,15.500,0.00,2.5537,2.55380,2.000
2,15.625,0.00,2.6787,2.67880,2.000
2,15.750,0.00,2.8037,2.80380,2.000
2,15.875,0.00,2.9287,2.92885,2.000
2,16.000,0.00,3.0539,3.05400,2.000
2,16.125,0.02,3.1789,3.17900,2.000
2,16.250,0.03,3.3039,3.30400,2.000
2,16.375,0.07,3.4288,3.42890,2.000
2,16.500,0.13,3.5538,3.55390,2.000
2,16.625,0.26,3.6788,3.67895,2.000
2,16.750,0.47,3.8037,3.80380,2.000
2,16.875,0.75,3.9288,3.92890,2.000
2,17.000,1.15,4.0538,4.05390,2.000
2,17.125,1.67,4.1788,4.17890,2.000
2,17.250,2.31,4.3039,4.30400,2.000
2,17.375,3.09,4.4289,4.42895,2.000
2,17.500,4.02,4.5539,4.55400,2.000
2,17.625,5.12,4.6788,4.67885,2.000
2,17.812,4.44,4.6221,4.62222,2.000
2,17.938,3.24,4.4972,4.49728,2.000
2,18.062,2.33,4.3722,4.37232,2.000
2,18.188,1.64,4.2471,4.24718,2.000
2,18.312,1.10,4.1220,4.12205,2.000
2,18.438,0.71,3.9971,3.99718,2.000
2,18.562,0.42,3.8720,3.87212,2.000
2,18.688,0.22,3.7471,3.74723,2.000
2,18.812,0.09,3.6222,3.62232,2.000
2,18.938,0.04,3.4971,3.49720,2.000
2,19.062,0.02,3.3720,3.37212,2.000
2,19.188,0.01,3.2469,3.24698,2.000
2,19.312,0.00,3.1220,3.12210,2.000
2,19.438,0.00,2.9971,2.99715,2.000
2,19.562,0.00,2.8719,2.87205,2.000
2,19.688,0.00,2.7470,2.74708,2.000
2,19.812,0.00,2.6220,2.62210,2.000
2,19.938,0.00,2.4970,2.49710,2.000
2,20.062,0.00,2.3719,2.37205,2.000
2,20.188,0.00,2.2470,2.24705,2.000
2,20.312,0.00,2.1218,2.12190,2.000
2,20.438,0.00,1.9968,1.99693,2.000
2,20.562,0.00,1.8717,1.87180,2.000
2,20.688,0.00,1.7468,1.74688,2.000
2,20.812,0.00,1.6221,1.62220,2.000
2,20.938,0.00,1.4970,1.49705,2.000
2,21.062,0.00,1.3720,1.37207,2.000
2,21.188,0.00,1.2468,1.24693,2.000
2,21.312,0.00,1.1218,1.12190,2.000
2,21.438,0.00,0.9968,0.99693,2.000
2,21.562,0.00,0.8716,0.87175,2.000
2,21.688,0.00,0.7468,0.74690,2.000
2,21.812,0.00,0.6219,0.62202,2.000
2,21.938,0.01,0.4969,0.49698,2.000
2,22.062,0.00,0.3719,0.37197,2.000
2,22.188,0.00,0.2468,0.24693,2.000
2,22.312,0.00,0.1217,0.12182,2.000
2,22.438,0.00,-0.0034,-0.00332,2.000
2,22.625,0.00,-0.0004,-0.00035,2.000
2,22.750,0.00,-0.0004,-0.00030,2.000
2,22.875,0.00,-0.0004,-0.00030,2.000
2,23.000,0.00,-0.0004,-0.00030,2.000
2,23.125,0.00,-0.0004,-0.00030,2.000
2,23.250,0.00,-0.0004,-0.00030,2.000
2,23.375,0.00,-0.0004,-0.00030,2.000
2,23.500,0.00,-0.0003,-0.00020,2.000
2,23.625,0.00,-0.0003,-0.00020,2.000
2,23.750,0.00,-0.0003,-0.00020,2.000
2,23.875,0.00,-0.0003,-0.00020,2.000
2,24.000,0.00,-0.0003,-0.00020,2.000
2,24.125,0.00,-0.0003,-0.00020,2.000
2,24.250,-0.01,-0.0003,-0.00020,2.000
2,24.375,0.00,-0.0003,-0.00020,2.000
2,24.500,0.00,-0.0003,-0.00020,2.000
2,24.625,0.00,-0.0003,-0.00020,2.000
2,24.750,0.00,-0.0003,-0.00020,2.000
2,24.875,0.00,-0.0003,-0.00020,2.000
2,25.000,0.01,-0.0003,-0.00020,2.000
2,25.125,0.00,-0.0003,-0.00020,2.000
2,25.250,0.00,-0.0003,-0.00020,2.000
2,25.375,0.00,-0.0002,-0.00010,2.000
2,25.500,0.00,-0.0002,-0.00010,2.000
3,25.875,0.00,0.1585,0.15860,3.000
3,26.000,0.00,0.2836,0.28370,3.000
3,26.125,0.00,0.4086,0.40870,3.000
3,26.250,0.00,0.5336,0.53370,3.000
3,26.375,0.00,0.6588,0.65885,3.000
3,26.500,0.00,0.7837,0.78380,3.000
3,26.625,0.00,0.9086,0.90870,3.000
3,26.750,0.00,1.0336,1.03370,3.000
3,26.875,0.00,1.1586,1.15875,3.000
3,27.000,0.00,1.2837,1.28380,3.000
3,27.125,0.00,1.4088,1.40885,3.000
3,27.250,0.00,1.5339,1.53400,3.000
3,27.375,0.00,1.6590,1.65905,3.000
3,27.500,-0.01,1.7838,1.78390,3.000
3,27.625,0.00,1.9087,1.90880,3.000
3,27.750,0.00,2.0337,2.03380,3.000
3,27.875,0.00,2.1586,2.15875,3.000
3,28.000,0.00,2.2838,2.28390,3.000
3,28.125,0.00,2.4087,2.40880,3.000
3,28.250,0.00,2.5338,2.53390,3.000
3,28.375,0.00,2.6588,2.65895,3.000
3,28.500,0.00,2.7838,2.78390,3.000
3,28.625,0.00,2.9088,2.90895,3.000
3,28.750,0.00,3.0339,3.03400,3.000
3,28.875,0.01,3.1588,3.15895,3.000
3,29.000,0.03,3.2838,3.28390,3.000
3,29.125,0.05,3.4087,3.40880,3.000
3,29.250,0.12,3.5339,3.53400,3.000
3,29.375,0.23,3.6590,3.65905,3.000
3,29.500,0.42,3.7839,3.78400,3.000
3,29.625,0.70,3.9088,3.90895,3.000
3,29.750,1.08,4.0338,4.03390,3.000
3,29.875,1.57,4.1588,4.15885,3.000
3,30.000,2.19,4.2838,4.28390,3.000
3,30.125,2.95,4.4088,4.40885,3.000
3,30.250,3.85,4.5338,4.53390,3.000
3,30.375,4.92,4.6588,4.65895,3.000
3,30.562,4.71,4.6460,4.64610,3.000
3,30.688,3.43,4.5210,4.52113,3.000
3,30.812,2.47,4.3961,4.39623,3.000
3,30.938,1.76,4.2713,4.27135,3.000
3,31.062,1.19,4.1461,4.14623,3.000
3,31.188,0.77,4.0212,4.02128,3.000
3,31.312,0.46,3.8961,3.89620,3.000
3,31.438,0.25,3.7710,3.77113,3.000
3,31.562,0.11,3.6461,3.64618,3.000
3,31.688,0.04,3.5211,3.52118,3.000
3,31.812,0.02,3.3960,3.39610,3.000
3,31.938,0.01,3.2711,3.27115,3.000
3,32.062,0.00,3.1461,3.14615,3.000
3,32.188,0.00,3.0211,3.02120,3.000
3,32.312,0.00,2.8960,2.89610,3.000
3,32.438,0.00,2.7710,2.77110,3.000
3,32.562,0.00,2.6459,2.64600,3.000
3,32.688,0.00,2.5208,2.52095,3.000
3,32.812,0.00,2.3959,2.39595,3.000
3,32.938,0.00,2.2710,2.27107,3.000
3,33.062,0.00,2.1459,2.14600,3.000
3,33.188,0.00,2.0210,2.02112,3.000
3,33.312,0.00,1.8959,1.89598,3.000
3,33.438,0.00,1.7708,1.77092,3.000
3,33.562,0.00,1.6461,1.64618,3.000
3,33.688,0.00,1.5208,1.52092,3.000
3,33.812,0.00,1.3959,1.39603,3.000
3,33.938,0.00,1.2708,1.27095,3.000
3,34.062,0.00,1.1460,1.14608,3.000
3,34.188,0.00,1.0209,1.02100,3.000
3,34.312,0.00,0.8958,0.89593,3.000
3,34.438,0.00,0.7708,0.77092,3.000
3,34.562,0.00,0.6459,0.64598,3.000
3,34.688,0.00,0.5207,0.52082,3.000
3,34.812,0.00,0.3957,0.39580,3.000
3,34.938,0.00,0.2707,0.27080,3.000
3,35.062,0.00,0.1457,0.14578,3.000
3,35.188,0.00,0.0207,0.02077,3.000
3,35.375,0.00,-0.0004,-0.00025,3.000
3,35.500,0.00,-0.0004,-0.00030,3.000
3,35.625,0.00,-0.0004,-0.00030,3.000
3,35.750,0.00,-0.0004,-0.00030,3.000
3,35.875,0.00,-0.0004,-0.00030,3.000
3,36.000,0.00,-0.0004,-0.00030,3.000
3,36.125,0.00,-0.0004,-0.00025,3.000
3,36.250,0.00,-0.0003,-0.00020,3.000
3,36.375,0.00,-0.0003,-0.00020,3.000
3,36.500,0.00,-0.0003,-0.00020,3.000
3,36.625,0.00,-0.0003,-0.00020,3.000
3,36.750,0.00,-0.0003,-0.00020,3.000
3,36.875,0.00,-0.0003,-0.00020,3.000
3,37.000,-0.01,-0.0003,-0.00020,3.000
3,37.125,0.00,-0.0003,-0.00020,3.000
3,37.250,0.00,-0.0003,-0.00020,3.000
3,37.375,0.00,-0.0003,-0.00020,3.000
3,37.500,0.00,-0.0003,-0.00020,3.000
3,37.625,0.00,-0.0003,-0.00020,3.000
3,37.750,0.00,-0.0003,-0.00020,3.000
3,37.875,0.00,-0.0003,-0.00020,3.000
3,38.000,0.00,-0.0002,-0.00010,3.000
3,38.125,0.00,-0.0002,-0.00010,3.000
3,38.250,0.00,-0.0002,-0.00010,3.000
4,38.625,0.00,0.1135,0.11360,4.000
4,38.750,0.00,0.2386,0.23870,4.000
4,38.875,0.00,0.3636,0.36370,4.000
4,39.000,0.00,0.4885,0.48860,4.000
4,39.125,0.01,0.6138,0.61385,4.000
4,39.250,0.00,0.7388,0.73890,4.000
4,39.375,0.00,0.8637,0.86380,4.000
4,39.500,0.01,0.9887,0.98880,4.000
4,39.625,0.00,1.1136,1.11370,4.000
4,39.750,0.00,1.2386,1.23870,4.000
4,39.875,0.01,1.3638,1.36385,4.000
4,40.000,0.00,1.4888,1.48890,4.000
4,40.125,0.00,1.6140,1.61405,4.000
4,40.250,0.01,1.7388,1.73890,4.000
4,40.375,0.00,1.8637,1.86380,4.000
4,40.500,0.01,1.9887,1.98880,4.000
4,40.625,0.01,2.1137,2.11380,4.000
4,40.750,0.00,2.2387,2.23880,4.000
4,40.875,0.00,2.3638,2.36385,4.000
4,41.000,0.01,2.4888,2.48890,4.000
4,41.125,0.00,2.6138,2.61385,4.000
4,41.250,0.00,2.7389,2.73900,4.000
4,41.375,0.00,2.8639,2.86400,4.000
4,41.500,0.01,2.9889,2.98900,4.000
4,41.625,0.02,3.1139,3.11400,4.000
4,41.750,0.03,3.2387,3.23880,4.000
4,41.875,0.05,3.3637,3.36380,4.000
4,42.000,0.09,3.4887,3.48880,4.000
4,42.125,0.19,3.6139,3.61400,4.000
4,42.250,0.35,3.7389,3.73900,4.000
4,42.375,0.59,3.8638,3.86395,4.000
4,42.500,0.93,3.9889,3.98900,4.000
4,42.625,1.38,4.1138,4.11385,4.000
4,42.750,1.95,4.2388,4.23890,4.000
4,42.875,2.66,4.3638,4.36390,4.000
4,43.000,3.51,4.4888,4.48890,4.000
4,43.125,4.52,4.6138,4.61390,4.000
4,43.312,4.91,4.6569,4.65703,4.000
4,43.438,3.56,4.5321,4.53217,4.000
4,43.562,2.58,4.4071,4.40715,4.000
4,43.688,1.83,4.2821,4.28220,4.000
4,43.812,1.25,4.1571,4.15715,4.000
4,43.938,0.81,4.0321,4.03217,4.000
4,44.062,0.50,3.9071,3.90715,4.000
4,44.188,0.27,3.7821,3.78222,4.000
4,44.312,0.12,3.6572,3.65733,4.000
4,44.438,0.05,3.5321,3.53222,4.000
4,44.562,0.03,3.4070,3.40708,4.000
4,44.688,0.02,3.2819,3.28200,4.000
4,44.812,0.01,3.1570,3.15710,4.000
4,44.938,0.00,3.0321,3.03217,4.000
4,45.062,0.00,2.9070,2.90713,4.000
4,45.188,0.00,2.7821,2.78217,4.000
4,45.312,0.01,2.6570,2.65708,4.000
4,45.438,0.01,2.5319,2.53202,4.000
4,45.562,0.01,2.4069,2.40698,4.000
4,45.688,0.01,2.2819,2.28202,4.000
4,45.812,0.00,2.1568,2.15685,4.000
4,45.938,0.00,2.0319,2.03197,4.000
4,46.062,0.00,1.9069,1.90695,4.000
4,46.188,0.00,1.7818,1.78195,4.000
4,46.312,0.00,1.6571,1.65720,4.000
4,46.438,0.00,1.5319,1.53197,4.000
4,46.562,0.00,1.4070,1.40705,4.000
4,46.688,0.00,1.2818,1.28192,4.000
4,46.812,0.01,1.1567,1.15683,4.000
4,46.938,0.01,1.0319,1.03197,4.000
4,47.062,0.00,0.9068,0.90693,4.000
4,47.188,0.01,0.7819,0.78197,4.000
4,47.312,0.00,0.6569,0.65703,4.000
4,47.438,0.01,0.5318,0.53190,4.000
4,47.562,0.00,0.4068,0.40688,4.000
4,47.688,0.00,0.2817,0.28185,4.000
4,47.812,0.01,0.1567,0.15675,4.000
4,47.938,0.00,0.0317,0.03177,4.000
4,48.125,0.01,-0.0004,-0.00025,4.000
4,48.250,0.00,-0.0004,-0.00030,4.000
4,48.375,0.00,-0.0003,-0.00020,4.000
4,48.500,0.00,-0.0003,-0.00020,4.000
4,48.625,0.00,-0.0003,-0.00020,4.000
4,48.750,0.00,-0.0003,-0.00020,4.000
4,48.875,0.01,-0.0003,-0.00020,4.000
4,49.000,0.01,-0.0003,-0.00020,4.000
4,49.125,0.00,-0.0003,-0.00020,4.000
4,49.250,0.00,-0.0003,-0.00020,4.000
4,49.375,0.00,-0.0003,-0.00020,4.000
4,49.500,0.00,-0.0003,-0.00020,4.000
4,49.625,0.00,-0.0003,-0.00020,4.000
4,49.750,0.00,-0.0003,-0.00020,4.000
4,49.875,0.00,-0.0003,-0.00020,4.000
4,50.000,0.01,-0.0003,-0.00020,4.000
4,50.125,0.00,-0.0003,-0.00020,4.000
4,50.250,0.00,-0.0003,-0.00020,4.000
4,50.375,0.00,-0.0003,-0.00020,4.000
4,50.500,0.01,-0.0003,-0.00020,4.000
4,50.625,0.00,-0.0003,-0.00020,4.000
4,50.750,0.00,-0.0002,-0.00010,4.000
4,50.875,0.01,-0.0002,-0.00010,4.000
4,51.000,0.01,-0.0002,-0.00010,4.000
5,51.375,0.00,0.1485,0.14860,5.000
5,51.500,0.00,0.2735,0.27360,5.000
5,51.625,0.00,0.3985,0.39865,5.000
5,51.750,0.00,0.5235,0.52360,5.000
5,51.875,0.00,0.6487,0.64880,5.000
5,52.000,0.01,0.7738,0.77390,5.000
5,52.125,0.00,0.8987,0.89880,5.000
5,52.250,0.00,1.0239,1.02400,5.000
5,52.375,0.01,1.1487,1.14880,5.000
5,52.500,0.00,1.2736,1.27370,5.000
5,52.625,0.01,1.3987,1.39880,5.000
5,52.750,0.01,1.5238,1.52390,5.000
5,52.875,0.00,1.6488,1.64895,5.000
5,53.000,0.01,1.7736,1.77370,5.000
5,53.125,0.01,1.8987,1.89880,5.000
5,53.250,0.01,2.0238,2.02390,5.000
5,53.375,0.01,2.1487,2.14885,5.000
5,53.500,0.01,2.2737,2.27380,5.000
5,53.625,0.00,2.3987,2.39880,5.000
5,53.750,0.00,2.5237,2.52380,5.000
5,53.875,0.01,2.6487,2.64880,5.000
5,54.000,0.00,2.7737,2.77380,5.000
5,54.125,0.01,2.8988,2.89895,5.000
5,54.250,0.00,3.0239,3.02400,5.000
5,54.375,0.02,3.1489,3.14900,5.000
5,54.500,0.03,3.2738,3.27390,5.000
5,54.625,0.06,3.3987,3.39885,5.000
5,54.750,0.12,3.5237,3.52380,5.000
5,54.875,0.23,3.6488,3.64895,5.000
5,55.000,0.41,3.7738,3.77390,5.000
5,55.125,0.67,3.8988,3.89890,5.000
5,55.250,1.04,4.0239,4.02400,5.000
5,55.375,1.53,4.1488,4.14895,5.000
5,55.500,2.14,4.2739,4.27400,5.000
5,55.625,2.88,4.3989,4.39900,5.000
5,55.750,3.77,4.5238,4.52390,5.000
5,55.875,4.83,4.6487,4.64880,5.000
5,56.062,4.58,4.6321,4.63223,5.000
5,56.188,3.33,4.5072,4.50735,5.000
5,56.312,2.40,4.3822,4.38228,5.000
5,56.438,1.70,4.2572,4.25735,5.000
5,56.562,1.15,4.1320,4.13210,5.000
5,56.688,0.74,4.0069,4.00705,5.000
5,56.812,0.44,3.8819,3.88203,5.000
5,56.938,0.24,3.7571,3.75717,5.000
5,57.062,0.10,3.6322,3.63233,5.000
5,57.188,0.05,3.5071,3.50717,5.000
5,57.312,0.02,3.3821,3.38220,5.000
5,57.438,0.01,3.2570,3.25712,5.000
5,57.562,0.01,3.1321,3.13218,5.000
5,57.688,0.00,3.0069,3.00705,5.000
5,57.812,0.00,2.8819,2.88203,5.000
5,57.938,0.00,2.7569,2.75700,5.000
5,58.062,0.00,2.6320,2.63210,5.000
5,58.188,0.00,2.5069,2.50705,5.000
5,58.312,0.00,2.3820,2.38208,5.000
5,58.438,0.01,2.2571,2.25717,5.000
5,58.562,0.00,2.1319,2.13198,5.000
5,58.688,0.00,2.0068,2.00695,5.000
5,58.812,0.00,1.8817,1.88178,5.000
5,58.938,0.00,1.7567,1.75685,5.000
5,59.062,0.00,1.6320,1.63213,5.000
5,59.188,0.00,1.5070,1.50707,5.000
5,59.312,0.00,1.3820,1.38205,5.000
5,59.438,0.00,1.2569,1.25697,5.000
5,59.562,0.00,1.1320,1.13205,5.000
5,59.688,0.00,1.0068,1.00695,5.000
5,59.812,0.00,0.8817,0.88183,5.000
5,59.938,0.00,0.7567,0.75682,5.000
5,60.062,0.00,0.6319,0.63195,5.000
5,60.188,0.00,0.5068,0.50695,5.000
5,60.312,0.00,0.3818,0.38193,5.000
5,60.438,0.00,0.2568,0.25692,5.000
5,60.562,0.00,0.1319,0.13195,5.000
5,60.688,0.00,0.0067,0.00682,5.000
5,60.875,0.00,-0.0004,-0.00030,5.000
5,61.000,0.00,-0.0004,-0.00030,5.000
5,61.125,0.01,-0.0004,-0.00030,5.000
5,61.250,0.00,-0.0004,-0.00030,5.000
5,61.375,0.00,-0.0004,-0.00030,5.000
5,61.500,0.00,-0.0004,-0.00030,5.000
5,61.625,0.00,-0.0004,-0.00030,5.000
5,61.750,0.00,-0.0003,-0.00020,5.000
5,61.875,0.00,-0.0003,-0.00020,5.000
5,62.000,0.00,-0.0003,-0.00020,5.000
5,62.125,0.00,-0.0003,-0.00020,5.000
5,62.250,0.00,-0.0003,-0.00020,5.000
5,62.375,0.00,-0.0003,-0.00020,5.000
5,62.500,0.00,-0.0003,-0.00020,5.000
5,62.625,0.00,-0.0003,-0.00020,5.000
5,62.750,0.00,-0.0003,-0.00020,5.000
5,62.875,0.00,-0.0003,-0.00020,5.000
5,63.000,0.00,-0.0003,-0.00020,5.000
5,63.125,0.00,-0.0003,-0.00020,5.000
5,63.250,0.00,-0.0003,-0.00020,5.000
5,63.375,0.00,-0.0003,-0.00020,5.000
5,63.500,0.00,-0.0003,-0.00020,5.000
5,63.625,0.01,-0.0002,-0.00010,5.000
5,63.750,0.01,-0.0002,-0.00010,5.000
6,64.125,0.00,0.1336,0.13365,6.000
6,64.250,0.00,0.2588,0.25890,6.000
6,64.375,0.00,0.3837,0.38380,6.000
6,64.500,0.00,0.5086,0.50870,6.000
6,64.625,0.01,0.6337,0.63380,6.000
6,64.750,0.00,0.7585,0.75860,6.000
6,64.875,0.00,0.8836,0.88365,6.000
6,65.000,0.00,1.0087,1.00880,6.000
6,65.125,0.00,1.1337,1.13380,6.000
6,65.250,0.00,1.2587,1.25880,6.000
6,65.375,0.00,1.3838,1.38395,6.000
6,65.500,0.00,1.5089,1.50900,6.000
6,65.625,0.00,1.6338,1.63395,6.000
6,65.750,0.00,1.7586,1.75870,6.000
6,65.875,0.00,1.8836,1.88375,6.000
6,66.000,0.00,2.0088,2.00890,6.000
6,66.125,0.00,2.1337,2.13380,6.000
6,66.250,0.01,2.2589,2.25900,6.000
6,66.375,0.00,2.3838,2.38390,6.000
6,66.500,0.00,2.5088,2.50890,6.000
6,66.625,0.00,2.6338,2.63385,6.000
6,66.750,0.00,2.7587,2.75880,6.000
6,66.875,0.00,2.8838,2.88385,6.000
6,67.000,0.00,3.0088,3.00890,6.000
6,67.125,0.01,3.1338,3.13395,6.000
6,67.250,0.03,3.2588,3.25890,6.000
6,67.375,0.05,3.3838,3.38395,6.000
6,67.500,0.10,3.5090,3.50910,6.000
6,67.625,0.21,3.6340,3.63405,6.000
6,67.750,0.37,3.7588,3.75890,6.000
6,67.875,0.64,3.8838,3.88385,6.000
6,68.000,0.99,4.0087,4.00880,6.000
6,68.125,1.46,4.1338,4.13390,6.000
6,68.250,2.05,4.2589,4.25900,6.000
6,68.375,2.78,4.3839,4.38400,6.000
6,68.500,3.65,4.5090,4.50910,6.000
6,68.625,4.69,4.6338,4.63395,6.000
6,68.875,4.14,4.5946,4.59475,6.000
6,69.000,3.02,4.4697,4.46980,6.000
6,69.125,2.16,4.3447,4.34480,6.000
6,69.250,1.52,4.2197,4.21980,6.000
6,69.375,1.01,4.0946,4.09465,6.000
6,69.500,0.63,3.9695,3.96960,6.000
6,69.625,0.37,3.8445,3.84460,6.000
6,69.750,0.19,3.7196,3.71970,6.000
6,69.875,0.08,3.5946,3.59475,6.000
6,70.000,0.04,3.4695,3.46960,6.000
6,70.125,0.02,3.3446,3.34465,6.000
6,70.250,0.01,3.2196,3.21970,6.000
6,70.375,0.01,3.0946,3.09465,6.000
6,70.500,0.00,2.9694,2.96950,6.000
6,70.625,0.00,2.8444,2.84455,6.000
6,70.750,0.00,2.7195,2.71960,6.000
6,70.875,0.00,2.5944,2.59450,6.000
6,71.000,0.00,2.4694,2.46950,6.000
6,71.125,0.00,2.3446,2.34465,6.000
6,71.250,0.01,2.2196,2.21970,6.000
6,71.375,0.00,2.0945,2.09460,6.000
6,71.500,0.00,1.9694,1.96950,6.000
6,71.625,0.00,1.8443,1.84435,6.000
6,71.750,0.00,1.7194,1.71950,6.000
6,71.875,0.00,1.5945,1.59460,6.000
6,72.000,0.00,1.4694,1.46950,6.000
6,72.125,0.00,1.3445,1.34460,6.000
6,72.250,0.00,1.2195,1.21960,6.000
6,72.375,0.00,1.0944,1.09450,6.000
6,72.500,0.00,0.9693,0.96940,6.000
6,72.625,0.00,0.8442,0.84435,6.000
6,72.750,0.01,0.7193,0.71940,6.000
6,72.875,0.00,0.5943,0.59435,6.000
6,73.000,0.00,0.4693,0.46940,6.000
6,73.125,0.00,0.3444,0.34450,6.000
6,73.250,-0.01,0.2194,0.21950,6.000
6,73.375,0.00,0.0943,0.09440,6.000
6,73.500,0.00,-0.0307,-0.03060,6.000
6,73.625,0.00,-0.0007,-0.00055,6.000
6,73.750,0.00,-0.0004,-0.00030,6.000
6,73.875,0.00,-0.0004,-0.00030,6.000
6,74.000,0.01,-0.0004,-0.00030,6.000
6,74.125,0.00,-0.0004,-0.00030,6.000
6,74.250,0.00,-0.0004,-0.00030,6.000
6,74.375,0.00,-0.0004,-0.00030,6.000
6,74.500,0.00,-0.0003,-0.00020,6.000
6,74.625,0.00,-0.0003,-0.00020,6.000
6,74.750,0.00,-0.0003,-0.00020,6.000
6,74.875,0.00,-0.0003,-0.00020,6.000
6,75.000,0.00,-0.0003,-0.00020,6.000
6,75.125,0.00,-0.0003,-0.00020,6.000
6,75.250,0.00,-0.0003,-0.00020,6.000
6,75.375,0.00,-0.0003,-0.00020,6.000
6,75.500,0.00,-0.0003,-0.00020,6.000
6,75.625,0.00,-0.0003,-0.00020,6.000
6,75.750,0.01,-0.0003,-0.00020,6.000
6,75.875,0.00,-0.0003,-0.00020,6.000
6,76.000,0.00,-0.0003,-0.00020,6.000
6,76.125,0.00,-0.0003,-0.00020,6.000
6,76.250,0.00,-0.0003,-0.00020,6.000
6,76.375,0.00,-0.0002,-0.00010,6.000
6,76.500,0.00,-0.0002,-0.00010,6.000
7,76.812,0.00,0.0601,0.06017,7.000
7,76.938,0.00,0.1851,0.18522,7.000
7,77.062,0.00,0.3102,0.31032,7.000
7,77.188,0.00,0.4350,0.43512,7.000
7,77.312,0.00,0.5600,0.56015,7.000
7,77.438,0.00,0.6852,0.68528,7.000
7,77.562,0.00,0.8101,0.81020,7.000
7,77.688,0.00,0.9351,0.93520,7.000
7,77.812,0.00,1.0602,1.06032,7.000
7,77.938,0.00,1.1852,1.18532,7.000
7,78.062,0.00,1.3102,1.31030,7.000
7,78.188,-0.01,1.4352,1.43528,7.000
7,78.312,0.00,1.5603,1.56037,7.000
7,78.438,0.00,1.6852,1.68535,7.000
7,78.562,0.00,1.8101,1.81020,7.000
7,78.688,0.00,1.9352,1.93535,7.000
7,78.812,0.00,2.0603,2.06040,7.000
7,78.938,0.00,2.1854,2.18545,7.000
7,79.062,0.00,2.3104,2.31047,7.000
7,79.188,0.00,2.4352,2.43532,7.000
7,79.312,0.00,2.5601,2.56022,7.000
7,79.438,0.00,2.6852,2.68532,7.000
7,79.562,0.00,2.8102,2.81032,7.000
7,79.688,0.00,2.9353,2.93538,7.000
7,79.812,0.00,3.0604,3.06050,7.000
7,79.938,0.01,3.1854,3.18548,7.000
7,80.062,0.03,3.3103,3.31040,7.000
7,80.188,0.07,3.4353,3.43540,7.000
7,80.312,0.14,3.5604,3.56047,7.000
7,80.438,0.26,3.6853,3.68538,7.000
7,80.562,0.47,3.8103,3.81042,7.000
7,80.688,0.76,3.9353,3.93540,7.000
7,80.812,1.16,4.0602,4.06035,7.000
7,80.938,1.68,4.1854,4.18548,7.000
7,81.062,2.33,4.3104,4.31050,7.000
7,81.188,3.11,4.4353,4.43542,7.000
7,81.312,4.05,4.5603,4.56040,7.000
7,81.438,5.16,4.6852,4.68533,7.000
7,81.625,4.43,4.6236,4.62370,7.000
7,81.750,3.24,4.4987,4.49880,7.000
7,81.875,2.33,4.3736,4.37370,7.000
7,82.000,1.64,4.2485,4.24860,7.000
7,82.125,1.11,4.1235,4.12360,7.000
7,82.250,0.70,3.9986,3.99870,7.000
7,82.375,0.42,3.8736,3.87370,7.000
7,82.500,0.22,3.7487,3.74880,7.000
7,82.625,0.10,3.6236,3.62375,7.000
7,82.750,0.04,3.4985,3.49860,7.000
7,82.875,0.01,3.3734,3.37355,7.000
7,83.000,0.01,3.2484,3.24850,7.000
7,83.125,0.00,3.1235,3.12360,7.000
7,83.250,0.00,2.9985,2.99860,7.000
7,83.375,0.00,2.8735,2.87360,7.000
7,83.500,-0.01,2.7485,2.74860,7.000
7,83.625,0.00,2.6236,2.62365,7.000
7,83.750,0.00,2.4985,2.49860,7.000
7,83.875,0.00,2.3734,2.37355,7.000
7,84.000,-0.01,2.2484,2.24850,7.000
7,84.125,0.00,2.1233,2.12340,7.000
7,84.250,0.00,1.9984,1.99850,7.000
7,84.375,0.00,1.8733,1.87340,7.000
7,84.500,0.00,1.7484,1.74850,7.000
7,84.625,0.00,1.6236,1.62375,7.000
7,84.750,0.00,1.4984,1.49850,7.000
7,84.875,-0.01,1.3735,1.37360,7.000
7,85.000,0.00,1.2483,1.24840,7.000
7,85.125,0.00,1.1233,1.12340,7.000
7,85.250,0.00,0.9983,0.99840,7.000
7,85.375,0.00,0.8733,0.87335,7.000
7,85.500,-0.01,0.7484,0.74850,7.000
7,85.625,0.00,0.6235,0.62355,7.000
7,85.750,0.00,0.4984,0.49850,7.000
7,85.875,0.00,0.3733,0.37340,7.000
7,86.000,0.00,0.2483,0.24840,7.000
7,86.125,0.00,0.1232,0.12330,7.000
7,86.250,0.00,-0.0019,-0.00180,7.000
7,86.438,0.00,-0.0004,-0.00028,7.000
7,86.562,0.00,-0.0004,-0.00030,7.000
7,86.688,-0.01,-0.0004,-0.00028,7.000
7,86.812,0.00,-0.0003,-0.00020,7.000
7,86.938,0.00,-0.0003,-0.00020,7.000
7,87.062,0.00,-0.0003,-0.00020,7.000
7,87.188,0.00,-0.0003,-0.00020,7.000
7,87.312,0.00,-0.0003,-0.00020,7.000
7,87.438,0.00,-0.0003,-0.00020,7.000
7,87.562,0.00,-0.0003,-0.00020,7.000
7,87.688,0.00,-0.0003,-0.00020,7.000
7,87.812,0.00,-0.0003,-0.00020,7.000
7,87.938,0.00,-0.0003,-0.00020,7.000
7,88.062,-0.01,-0.0003,-0.00020,7.000
7,88.188,0.00,-0.0003,-0.00020,7.000
7,88.312,0.00,-0.0003,-0.00020,7.000
7,88.438,0.00,-0.0003,-0.00020,7.000
7,88.562,-0.01,-0.0003,-0.00020,7.000
7,88.688,0.00,-0.0003,-0.00020,7.000
7,88.812,0.00,-0.0003,-0.00020,7.000
7,88.938,0.00,-0.0003,-0.00020,7.000
7,89.062,0.00,-0.0003,-0.00020,7.000
7,89.188,0.00,-0.0002,-0.00010,7.000
7,89.312,0.00,-0.0002,-0.00010,7.000
8,89.688,-0.01,0.1610,0.16105,8.000
8,89.812,-0.01,0.2861,0.28622,8.000
8,89.938,-0.01,0.4111,0.41118,8.000
8,90.062,0.00,0.5361,0.53617,8.000
8,90.188,-0.01,0.6612,0.66130,8.000
8,90.312,-0.01,0.7862,0.78635,8.000
8,90.438,-0.01,0.9111,0.91123,8.000
8,90.562,-0.01,1.0362,1.03630,8.000
8,90.688,0.00,1.1611,1.16120,8.000
8,90.812,-0.01,1.2861,1.28622,8.000
8,90.938,0.00,1.4112,1.41130,8.000
8,91.062,-0.01,1.5363,1.53637,8.000
8,91.188,-0.01,1.6615,1.66158,8.000
8,91.312,-0.01,1.7862,1.78630,8.000
8,91.438,-0.01,1.9113,1.91138,8.000
8,91.562,0.00,2.0362,2.03630,8.000
8,91.688,-0.01,2.1611,2.16123,8.000
8,91.812,-0.01,2.2863,2.28637,8.000
8,91.938,0.00,2.4112,2.41132,8.000
8,92.062,-0.01,2.5362,2.53630,8.000
8,92.188,-0.01,2.6613,2.66138,8.000
8,92.312,-0.01,2.7864,2.78647,8.000
8,92.438,-0.01,2.9114,2.91150,8.000
8,92.562,0.00,3.0363,3.03645,8.000
8,92.688,0.00,3.1613,3.16140,8.000
8,92.812,0.02,3.2862,3.28630,8.000
8,92.938,0.05,3.4113,3.41138,8.000
8,93.062,0.11,3.5363,3.53645,8.000
8,93.188,0.22,3.6615,3.66155,8.000
8,93.312,0.42,3.7863,3.78645,8.000
8,93.438,0.69,3.9114,3.91150,8.000
8,93.562,1.07,4.0363,4.03645,8.000
8,93.688,1.57,4.1613,4.16140,8.000
8,93.812,2.19,4.2863,4.28645,8.000
8,93.938,2.95,4.4113,4.41138,8.000
8,94.062,3.85,4.5363,4.53640,8.000
8,94.188,4.92,4.6613,4.66138,8.000
8,94.375,4.66,4.6435,4.64360,8.000
8,94.500,3.40,4.5187,4.51880,8.000
8,94.625,2.46,4.3937,4.39380,8.000
8,94.750,1.74,4.2688,4.26890,8.000
8,94.875,1.17,4.1436,4.14370,8.000
8,95.000,0.75,4.0186,4.01870,8.000
8,95.125,0.45,3.8935,3.89355,8.000
8,95.250,0.24,3.7684,3.76850,8.000
8,95.375,0.10,3.6436,3.64375,8.000
8,95.500,0.03,3.5186,3.51870,8.000
8,95.625,0.01,3.3936,3.39365,8.000
8,95.750,0.00,3.2686,3.26870,8.000
8,95.875,0.00,3.1436,3.14370,8.000
8,96.000,0.00,3.0187,3.01880,8.000
8,96.125,-0.01,2.8934,2.89350,8.000
8,96.250,-0.01,2.7684,2.76850,8.000
8,96.375,-0.01,2.6434,2.64350,8.000
8,96.500,-0.01,2.5184,2.51850,8.000
8,96.625,-0.01,2.3934,2.39350,8.000
8,96.750,-0.01,2.2685,2.26860,8.000
8,96.875,0.00,2.1435,2.14355,8.000
8,97.000,-0.01,2.0186,2.01870,8.000
8,97.125,-0.01,1.8934,1.89345,8.000
8,97.250,-0.01,1.7681,1.76820,8.000
8,97.375,-0.01,1.6435,1.64360,8.000
8,97.500,-0.01,1.5184,1.51850,8.000
8,97.625,-0.01,1.3934,1.39355,8.000
8,97.750,-0.01,1.2683,1.26840,8.000
8,97.875,-0.01,1.1434,1.14350,8.000
8,98.000,0.00,1.0185,1.01860,8.000
8,98.125,-0.01,0.8933,0.89340,8.000
8,98.250,0.00,0.7683,0.76840,8.000
8,98.375,-0.01,0.6434,0.64345,8.000
8,98.500,-0.01,0.5182,0.51830,8.000
8,98.625,-0.01,0.3933,0.39340,8.000
8,98.750,-0.01,0.2683,0.26840,8.000
8,98.875,-0.01,0.1433,0.14340,8.000
8,99.000,-0.01,0.0183,0.01840,8.000
8,99.188,0.00,0.0003,0.00038,8.000
8,99.312,-0.01,-0.0003,-0.00020,8.000
8,99.438,-0.01,-0.0003,-0.00020,8.000
8,99.562,-0.01,-0.0003,-0.00020,8.000
8,99.688,-0.01,-0.0003,-0.00020,8.000
8,99.812,-0.01,-0.0003,-0.00020,8.000
8,99.938,-0.01,-0.0003,-0.00020,8.000
8,100.062,-0.01,-0.0003,-0.00020,8.000
8,100.188,-0.01,-0.0003,-0.00020,8.000
8,100.312,-0.01,-0.0003,-0.00020,8.000
8,100.438,0.00,-0.0003,-0.00020,8.000
8,100.562,-0.01,-0.0003,-0.00020,8.000
8,100.688,-0.01,-0.0003,-0.00020,8.000
8,100.812,0.00,-0.0003,-0.00020,8.000
8,100.938,-0.01,-0.0003,-0.00020,8.000
8,101.062,-0.01,-0.0003,-0.00020,8.000
8,101.188,-0.01,-0.0003,-0.00020,8.000
8,101.312,-0.01,-0.0003,-0.00020,8.000
8,101.438,0.00,-0.0003,-0.00020,8.000
8,101.562,-0.01,-0.0003,-0.00020,8.000
8,101.688,-0.01,-0.0003,-0.00020,8.000
8,101.812,0.00,-0.0003,-0.00020,8.000
8,101.938,-0.01,-0.0002,-0.00010,8.000
8,102.062,-0.01,-0.0002,-0.00010,8.000
9,102.375,0.00,0.0926,0.09265,9.000
9,102.500,0.00,0.2176,0.21770,9.000
9,102.625,0.00,0.3427,0.34280,9.000
9,102.750,0.01,0.4676,0.46770,9.000
9,102.875,0.00,0.5927,0.59280,9.000
9,103.000,0.00,0.7176,0.71770,9.000
9,103.125,0.00,0.8426,0.84265,9.000
9,103.250,0.01,0.9676,0.96770,9.000
9,103.375,0.00,1.0927,1.09275,9.000
9,103.500,0.00,1.2176,1.21770,9.000
9,103.625,0.00,1.3428,1.34295,9.000
9,103.750,0.00,1.4678,1.46790,9.000
9,103.875,0.00,1.5929,1.59300,9.000
9,104.000,0.00,1.7177,1.71780,9.000
9,104.125,0.00,1.8426,1.84270,9.000
9,104.250,0.00,1.9677,1.96780,9.000
9,104.375,0.00,2.0927,2.09280,9.000
9,104.500,0.00,2.2177,2.21780,9.000
9,104.625,0.00,2.3429,2.34295,9.000
9,104.750,0.00,2.4678,2.46790,9.000
9,104.875,0.00,2.5928,2.59290,9.000
9,105.000,0.00,2.7177,2.71780,9.000
9,105.125,0.00,2.8428,2.84290,9.000
9,105.250,0.00,2.9677,2.96780,9.000
9,105.375,0.00,3.0928,3.09290,9.000
9,105.500,0.02,3.2178,3.21790,9.000
9,105.625,0.04,3.3429,3.34295,9.000
9,105.750,0.08,3.4678,3.46790,9.000
9,105.875,0.16,3.5930,3.59305,9.000
9,106.000,0.31,3.7179,3.71800,9.000
9,106.125,0.54,3.8428,3.84290,9.000
9,106.250,0.85,3.9677,3.96780,9.000
9,106.375,1.29,4.0927,4.09280,9.000
9,106.500,1.84,4.2179,4.21800,9.000
9,106.625,2.52,4.3428,4.34290,9.000
9,106.750,3.34,4.4678,4.46790,9.000
9,106.875,4.32,4.5929,4.59295,9.000
9,107.062,5.58,4.7153,4.71535,9.000
9,107.188,4.07,4.5913,4.59135,9.000
9,107.312,2.98,4.4662,4.46630,9.000
9,107.438,2.13,4.3412,4.34125,9.000
9,107.562,1.49,4.2162,4.21625,9.000
9,107.688,0.99,4.0910,4.09110,9.000
9,107.812,0.62,3.9660,3.96613,9.000
9,107.938,0.35,3.8410,3.84110,9.000
9,108.062,0.18,3.7162,3.71628,9.000
9,108.188,0.07,3.5912,3.59130,9.000
9,108.312,0.03,3.4660,3.46613,9.000
9,108.438,0.02,3.3410,3.34115,9.000
9,108.562,0.01,3.2160,3.21608,9.000
9,108.688,0.00,3.0910,3.09110,9.000
9,108.812,0.00,2.9660,2.96613,9.000
9,108.938,0.00,2.8410,2.84108,9.000
9,109.062,0.00,2.7160,2.71610,9.000
9,109.188,0.00,2.5910,2.59110,9.000
9,109.312,0.00,2.4659,2.46600,9.000
9,109.438,0.00,2.3410,2.34113,9.000
9,109.562,0.00,2.2160,2.21605,9.000
9,109.688,0.00,2.0908,2.09095,9.000
9,109.812,0.00,1.9658,1.96593,9.000
9,109.938,0.00,1.8408,1.84088,9.000
9,110.062,0.00,1.7159,1.71595,9.000
9,110.188,0.00,1.5911,1.59118,9.000
9,110.312,0.00,1.4659,1.46600,9.000
9,110.438,0.00,1.3411,1.34118,9.000
9,110.562,0.00,1.2159,1.21603,9.000
9,110.688,0.00,1.0909,1.09095,9.000
9,110.812,0.00,0.9657,0.96583,9.000
9,110.938,0.00,0.8408,0.84088,9.000
9,111.062,0.01,0.7158,0.71593,9.000
9,111.188,0.00,0.5909,0.59095,9.000
9,111.312,0.00,0.4659,0.46598,9.000
9,111.438,0.00,0.3409,0.34098,9.000
9,111.562,0.00,0.2159,0.21595,9.000
9,111.688,0.00,0.0907,0.09078,9.000
9,111.875,0.01,-0.0444,-0.04425,9.000
9,112.000,0.00,-0.0004,-0.00030,9.000
9,112.125,0.01,-0.0004,-0.00025,9.000
9,112.250,0.00,-0.0003,-0.00020,9.000
9,112.375,0.00,-0.0003,-0.00020,9.000
9,112.500,0.00,-0.0003,-0.00020,9.000
9,112.625,0.00,-0.0003,-0.00020,9.000
9,112.750,0.00,-0.0003,-0.00020,9.000
9,112.875,0.00,-0.0003,-0.00020,9.000
9,113.000,0.00,-0.0003,-0.00020,9.000
9,113.125,0.00,-0.0003,-0.00020,9.000
9,113.250,0.00,-0.0003,-0.00020,9.000
9,113.375,0.00,-0.0003,-0.00020,9.000
9,113.500,0.00,-0.0003,-0.00020,9.000
9,113.625,0.00,-0.0003,-0.00020,9.000
9,113.750,0.00,-0.0003,-0.00020,9.000
9,113.875,0.00,-0.0003,-0.00020,9.000
9,114.000,0.00,-0.0003,-0.00020,9.000
9,114.125,0.00,-0.0003,-0.00020,9.000
9,114.250,0.00,-0.0003,-0.00020,9.000
9,114.375,0.00,-0.0003,-0.00020,9.000
9,114.500,0.01,-0.0003,-0.00020,9.000
9,114.625,0.00,-0.0002,-0.00010,9.000
9,114.750,0.00,-0.0002,-0.00010,9.000
9,114.875,0.00,-0.0002,-0.00010,9.000
10,115.188,0.00,0.1310,0.13115,10.000
10,115.312,0.00,0.2561,0.25625,10.000
10,115.438,0.00,0.3812,0.38135,10.000
10,115.562,0.00,0.5061,0.50622,10.000
10,115.688,0.00,0.6313,0.63138,10.000
10,115.812,0.00,0.7562,0.75627,10.000
10,115.938,-0.01,0.8810,0.88112,10.000
10,116.062,0.00,1.0061,1.00622,10.000
10,116.188,-0.01,1.1312,1.13125,10.000
10,116.312,0.00,1.2561,1.25625,10.000
10,116.438,0.00,1.3813,1.38140,10.000
10,116.562,0.00,1.5063,1.50637,10.000
10,116.688,0.00,1.6315,1.63158,10.000
10,116.812,0.00,1.7562,1.75627,10.000
10,116.938,0.00,1.8812,1.88130,10.000
10,117.062,0.00,2.0061,2.00617,10.000
10,117.188,0.00,2.1312,2.13128,10.000
10,117.312,0.00,2.2563,2.25640,10.000
10,117.438,0.00,2.3813,2.38140,10.000
10,117.562,0.00,2.5063,2.50640,10.000
10,117.688,0.00,2.6314,2.63145,10.000
10,117.812,-0.01,2.7563,2.75640,10.000
10,117.938,0.00,2.8813,2.88142,10.000
10,118.062,-0.01,3.0062,3.00630,10.000
10,118.188,0.01,3.1313,3.13140,10.000
10,118.312,0.02,3.2562,3.25632,10.000
10,118.438,0.05,3.3814,3.38145,10.000
10,118.562,0.10,3.5064,3.50647,10.000
10,118.688,0.20,3.6314,3.63153,10.000
10,118.812,0.37,3.7564,3.75655,10.000
10,118.938,0.62,3.8813,3.88143,10.000
10,119.062,0.97,4.0062,4.00632,10.000
10,119.188,1.44,4.1312,4.13133,10.000
10,119.312,2.03,4.2563,4.25637,10.000
10,119.438,2.75,4.3813,4.38142,10.000
10,119.562,3.62,4.5063,4.50645,10.000
10,119.688,4.66,4.6313,4.63142,10.000
10,119.875,5.04,4.6735,4.67360,10.000
10,120.000,3.66,4.5487,4.54880,10.000
10,120.125,2.66,4.4236,4.42370,10.000
10,120.250,1.89,4.2987,4.29880,10.000
10,120.375,1.30,4.1736,4.17365,10.000
10,120.500,0.84,4.0484,4.04850,10.000
10,120.625,0.51,3.9235,3.92360,10.000
10,120.750,0.28,3.7986,3.79870,10.000
10,120.875,0.13,3.6737,3.67380,10.000
10,121.000,0.07,3.5487,3.54880,10.000
10,121.125,0.02,3.4235,3.42360,10.000
10,121.250,0.01,3.2986,3.29870,10.000
10,121.375,0.01,3.1735,3.17360,10.000
10,121.500,0.00,3.0485,3.04860,10.000
10,121.625,0.00,2.9235,2.92355,10.000
10,121.750,-0.01,2.7985,2.79860,10.000
10,121.875,0.00,2.6735,2.67360,10.000
10,122.000,-0.01,2.5484,2.54850,10.000
10,122.125,0.00,2.4235,2.42355,10.000
10,122.250,0.01,2.2985,2.29860,10.000
10,122.375,0.00,2.1734,2.17345,10.000
10,122.500,0.00,2.0483,2.04840,10.000
10,122.625,0.00,1.9232,1.92335,10.000
10,122.750,0.00,1.7982,1.79830,10.000
10,122.875,0.00,1.6736,1.67365,10.000
10,123.000,0.00,1.5486,1.54870,10.000
10,123.125,0.00,1.4236,1.42365,10.000
10,123.250,0.01,1.2985,1.29860,10.000
10,123.375,0.00,1.1733,1.17340,10.000
10,123.500,-0.01,1.0483,1.04840,10.000
10,123.625,0.00,0.9232,0.92330,10.000
10,123.750,0.00,0.7982,0.79830,10.000
10,123.875,0.00,0.6734,0.67345,10.000
10,124.000,0.00,0.5484,0.54850,10.000
10,124.125,0.00,0.4234,0.42345,10.000
10,124.250,0.00,0.2983,0.29840,10.000
10,124.375,0.00,0.1733,0.17340,10.000
10,124.500,0.00,0.0481,0.04820,10.000
10,124.688,0.00,-0.0068,-0.00672,10.000
10,124.812,0.00,-0.0004,-0.00030,10.000
10,124.938,0.00,-0.0003,-0.00020,10.000
10,125.062,0.00,-0.0003,-0.00020,10.000
10,125.188,-0.01,-0.0003,-0.00020,10.000
10,125.312,0.01,-0.0003,-0.00020,10.000
10,125.438,0.00,-0.0003,-0.00020,10.000
10,125.562,0.00,-0.0003,-0.00020,10.000
10,125.688,-0.01,-0.0003,-0.00020,10.000
10,125.812,0.00,-0.0003,-0.00020,10.000
10,125.938,0.00,-0.0003,-0.00020,10.000
10,126.062,0.00,-0.0003,-0.00020,10.000
10,126.188,0.00,-0.0003,-0.00020,10.000
10,126.312,0.00,-0.0003,-0.00020,10.000
10,126.438,-0.01,-0.0003,-0.00020,10.000
10,126.562,0.00,-0.0003,-0.00020,10.000
10,126.688,-0.01,-0.0003,-0.00020,10.000
10,126.812,0.00,-0.0003,-0.00020,10.000
10,126.938,0.00,-0.0003,-0.00020,10.000
10,127.062,0.00,-0.0003,-0.00020,10.000
10,127.188,0.00,-0.0003,-0.00020,10.000
10,127.312,0.00,-0.0002,-0.00010,10.000
10,127.438,0.00,-0.0002,-0.00010,10.000
10,127.562,-0.01,-0.0002,-0.00010,10.000
10,127.625,-0.01,-0.0002,-0.00010,10.000