File: calibDATA_loadcell/date_02:22:2018/Instron/5N_0_1_2_0.txt
""
"Test Method","Radhen_Load_Cntrl_Cmprsn_250N_12-7.msm"
"Sample I. D.","Sample1.mss"
"Specimen Number","9"

"TheCycle_Output ()","_Time (s)","_Load (N)","_Extension (mm)","RealTimeDepth (mm)","CycleNumber ()"

1,0.312,0.00,0.0929,0.09293,1.000
1,0.438,0.00,0.2181,0.21808,1.000
1,0.562,0.00,0.3432,0.34320,1.000
1,0.688,0.00,0.4682,0.46820,1.000
1,0.812,0.01,0.5932,0.59320,1.000
1,0.938,0.00,0.7182,0.71822,1.000
1,1.062,0.00,0.8432,0.84322,1.000
1,1.188,0.00,0.9682,0.96818,1.000
1,1.312,0.00,1.0931,1.09315,1.000
1,1.438,0.00,1.2182,1.21818,1.000
1,1.562,0.00,1.3431,1.34315,1.000
1,1.688,0.00,1.4683,1.46832,1.000
1,1.812,0.00,1.5933,1.59330,1.000
1,1.938,0.00,1.7184,1.71838,1.000
1,2.062,0.00,1.8432,1.84325,1.000
1,2.188,0.00,1.9682,1.96815,1.000
1,2.312,0.00,2.0932,2.09322,1.000
1,2.438,0.01,2.2182,2.21818,1.000
1,2.562,0.02,2.3433,2.34328,1.000
1,2.688,0.05,2.4684,2.46840,1.000
1,2.812,0.12,2.5934,2.59340,1.000
1,2.938,0.26,2.7184,2.71845,1.000
1,3.062,0.47,2.8434,2.84338,1.000
1,3.188,0.77,2.9684,2.96840,1.000
1,3.312,1.17,3.0934,3.09340,1.000
1,3.438,1.68,3.2183,3.21828,1.000
1,3.562,2.31,3.3433,3.34330,1.000
1,3.688,3.07,3.4683,3.46828,1.000
1,3.812,3.98,3.5933,3.59332,1.000
1,3.938,5.03,3.7184,3.71840,1.000
1,4.125,4.36,3.6586,3.65860,1.000
1,4.250,3.21,3.5335,3.53350,1.000
1,4.375,2.32,3.4086,3.40855,1.000
1,4.500,1.64,3.2835,3.28350,1.000
1,4.625,1.12,3.1586,3.15860,1.000
1,4.750,0.71,3.0337,3.03370,1.000
1,4.875,0.41,2.9086,2.90860,1.000
1,5.000,0.21,2.7835,2.78350,1.000
1,5.125,0.08,2.6584,2.65845,1.000
1,5.250,0.04,2.5333,2.53330,1.000
1,5.375,0.02,2.4086,2.40860,1.000
1,5.500,0.00,2.2835,2.28350,1.000
1,5.625,0.00,2.1586,2.15860,1.000
1,5.750,0.00,2.0336,2.03360,1.000
1,5.875,0.00,1.9084,1.90840,1.000
1,6.000,0.00,1.7835,1.78350,1.000
1,6.125,0.00,1.6584,1.65845,1.000
1,6.250,0.00,1.5333,1.53330,1.000
1,6.375,0.00,1.4084,1.40840,1.000
1,6.500,0.00,1.2835,1.28350,1.000
1,6.625,0.00,1.1584,1.15840,1.000
1,6.750,0.00,1.0335,1.03350,1.000
1,6.875,0.00,0.9085,0.90845,1.000
1,7.000,0.01,0.7836,0.78360,1.000
1,7.125,0.00,0.6584,0.65840,1.000
1,7.250,0.00,0.5332,0.53320,1.000
1,7.375,0.00,0.4083,0.40830,1.000
1,7.500,0.00,0.2832,0.28320,1.000
1,7.625,0.00,0.1583,0.15830,1.000
1,7.750,0.00,0.0333,0.03330,1.000
1,7.938,0.00,0.0000,-0.00003,1.000
1,8.062,0.00,-0.0002,-0.00020,1.000
1,8.188,0.00,-0.0002,-0.00020,1.000
1,8.312,0.00,-0.0002,-0.00020,1.000
1,8.438,0.00,-0.0002,-0.00020,1.000
1,8.562,0.00,-0.0002,-0.00020,1.000
1,8.688,0.00,-0.0002,-0.00020,1.000
1,8.812,0.01,-0.0002,-0.00020,1.000
1,8.938,0.01,-0.0002,-0.00020,1.000
1,9.062,0.00,-0.0002,-0.00020,1.000
1,9.188,0.00,-0.0002,-0.00020,1.000
1,9.312,0.01,-0.0002,-0.00020,1.000
1,9.438,0.01,-0.0002,-0.00020,1.000
1,9.562,0.00,-0.0001,-0.00010,1.000
1,9.688,0.00,-0.0001,-0.00010,1.000
1,9.812,0.00,-0.0001,-0.00010,1.000
1,9.938,0.00,-0.0001,-0.00010,1.000
1,10.062,0.00,-0.0001,-0.00010,1.000
1,10.188,0.00,-0.0001,-0.00010,1.000
1,10.312,0.00,-0.0001,-0.00010,1.000
1,10.438,0.00,-0.0001,-0.00010,1.000
1,10.562,0.00,-0.0001,-0.00010,1.000
1,10.688,0.01,-0.0001,-0.00010,1.000
1,10.812,0.00,-0.0001,-0.00010,1.000
2,11.125,0.01,0.0445,0.04460,2.000
2,11.250,0.00,0.1694,0.16950,2.000
2,11.375,0.00,0.2945,0.29460,2.000
2,11.500,0.01,0.4196,0.41970,2.000
2,11.625,0.01,0.5445,0.54465,2.000
2,11.750,0.01,0.6697,0.66980,2.000
2,11.875,0.01,0.7947,0.79485,2.000
2,12.000,0.00,0.9198,0.91990,2.000
2,12.125,0.01,1.0447,1.04485,2.000
2,12.250,0.00,1.1696,1.16970,2.000
2,12.375,0.01,1.2946,1.29475,2.000
2,12.500,0.01,1.4195,1.41960,2.000
2,12.625,0.01,1.5447,1.54480,2.000
2,12.750,0.00,1.6697,1.66980,2.000
2,12.875,0.00,1.7947,1.79480,2.000
2,13.000,0.00,1.9197,1.91980,2.000
2,13.125,0.01,2.0447,2.04480,2.000
2,13.250,0.01,2.1696,2.16970,2.000
2,13.375,0.01,2.2946,2.29475,2.000
2,13.500,0.03,2.4198,2.41990,2.000
2,13.625,0.09,2.5447,2.54485,2.000
2,13.750,0.19,2.6698,2.66990,2.000
2,13.875,0.37,2.7948,2.79495,2.000
2,14.000,0.63,2.9199,2.92000,2.000
2,14.125,0.99,3.0449,3.04500,2.000
2,14.250,1.45,3.1698,3.16990,2.000
2,14.375,2.03,3.2947,3.29485,2.000
2,14.500,2.74,3.4196,3.41970,2.000
2,14.625,3.59,3.5447,3.54480,2.000
2,14.750,4.59,3.6698,3.66990,2.000
2,15.000,4.16,3.6407,3.64080,2.000
2,15.125,3.06,3.5156,3.51565,2.000
2,15.250,2.22,3.3906,3.39070,2.000
2,15.375,1.55,3.2655,3.26555,2.000
2,15.500,1.05,3.1404,3.14050,2.000
2,15.625,0.66,3.0156,3.01565,2.000
2,15.750,0.37,2.8906,2.89070,2.000
2,15.875,0.18,2.7655,2.76560,2.000
2,16.000,0.07,2.6404,2.64050,2.000
2,16.125,0.03,2.5156,2.51570,2.000
2,16.250,0.01,2.3906,2.39070,2.000
2,16.375,0.01,2.2655,2.26555,2.000
2,16.500,0.00,2.1404,2.14050,2.000
2,16.625,0.00,2.0153,2.01545,2.000
2,16.750,0.00,1.8903,1.89040,2.000
2,16.875,0.00,1.7654,1.76545,2.000
2,17.000,0.00,1.6405,1.64060,2.000
2,17.125,0.00,1.5154,1.51550,2.000
2,17.250,0.00,1.3904,1.39050,2.000
2,17.375,0.00,1.2654,1.26545,2.000
2,17.500,0.00,1.1403,1.14040,2.000
2,17.625,0.00,1.0154,1.01550,2.000
2,17.750,0.01,0.8903,0.89040,2.000
2,17.875,0.00,0.7654,0.76545,2.000
2,18.000,0.00,0.6404,0.64050,2.000
2,18.125,0.00,0.5154,0.51545,2.000
2,18.250,0.00,0.3905,0.39060,2.000
2,18.375,0.00,0.2652,0.26535,2.000
2,18.500,0.00,0.1402,0.14030,2.000
2,18.625,0.00,0.0153,0.01540,2.000
2,18.812,0.00,-0.0005,-0.00042,2.000
2,18.938,0.00,-0.0002,-0.00010,2.000
2,19.062,0.00,-0.0002,-0.00010,2.000
2,19.188,0.01,-0.0002,-0.00010,2.000
2,19.312,0.01,-0.0002,-0.00010,2.000
2,19.438,0.01,-0.0002,-0.00010,2.000
2,19.562,0.00,-0.0002,-0.00010,2.000
2,19.688,0.00,-0.0002,-0.00010,2.000
2,19.812,0.00,-0.0002,-0.00010,2.000
2,19.938,0.01,-0.0002,-0.00010,2.000
2,20.062,0.00,-0.0002,-0.00010,2.000
2,20.188,0.00,-0.0002,-0.00010,2.000
2,20.312,0.01,-0.0002,-0.00010,2.000
2,20.438,0.00,-0.0002,-0.00010,2.000
2,20.562,0.01,-0.0002,-0.00010,2.000
2,20.688,0.00,-0.0001,0.00000,2.000
2,20.812,0.00,-0.0001,0.00000,2.000
2,20.938,0.00,-0.0001,0.00000,2.000
2,21.062,0.01,-0.0001,0.00000,2.000
2,21.188,0.01,-0.0001,0.00000,2.000
2,21.312,0.00,-0.0001,0.00000,2.000
2,21.438,0.01,-0.0001,0.00000,2.000
2,21.562,0.01,-0.0001,0.00000,2.000
2,21.688,0.01,-0.0001,0.00000,2.000
3,22.000,0.00,0.0496,0.04960,3.000
3,22.125,0.00,0.1744,0.17445,3.000
3,22.250,0.00,0.2996,0.29960,3.000
3,22.375,0.00,0.4247,0.42470,3.000
3,22.500,0.01,0.5496,0.54960,3.000
3,22.625,0.00,0.6747,0.67470,3.000
3,22.750,0.00,0.7997,0.79970,3.000
3,22.875,0.00,0.9247,0.92465,3.000
3,23.000,0.00,1.0497,1.04970,3.000
3,23.125,0.00,1.1746,1.17455,3.000
3,23.250,0.00,1.2996,1.29960,3.000
3,23.375,0.00,1.4247,1.42470,3.000
3,23.500,0.00,1.5498,1.54980,3.000
3,23.625,0.00,1.6749,1.67485,3.000
3,23.750,0.00,1.7998,1.79980,3.000
3,23.875,0.00,1.9247,1.92470,3.000
3,24.000,0.00,2.0496,2.04960,3.000
3,24.125,0.00,2.1748,2.17475,3.000
3,24.250,0.01,2.2997,2.29970,3.000
3,24.375,0.03,2.4248,2.42480,3.000
3,24.500,0.08,2.5497,2.54970,3.000
3,24.625,0.19,2.6748,2.67480,3.000
3,24.750,0.37,2.7998,2.79980,3.000
3,24.875,0.64,2.9248,2.92485,3.000
3,25.000,1.01,3.0499,3.04990,3.000
3,25.125,1.47,3.1748,3.17475,3.000
3,25.250,2.05,3.2998,3.29980,3.000
3,25.375,2.77,3.4247,3.42470,3.000
3,25.500,3.63,3.5498,3.54980,3.000
3,25.625,4.63,3.6748,3.67485,3.000
3,25.812,5.01,3.7180,3.71798,3.000
3,25.938,3.68,3.5931,3.59313,3.000
3,26.062,2.70,3.4680,3.46803,3.000
3,26.188,1.93,3.3430,3.34295,3.000
3,26.312,1.34,3.2179,3.21793,3.000
3,26.438,0.88,3.0930,3.09300,3.000
3,26.562,0.54,2.9681,2.96813,3.000
3,26.688,0.29,2.8430,2.84300,3.000
3,26.812,0.12,2.7180,2.71803,3.000
3,26.938,0.05,2.5931,2.59308,3.000
3,27.062,0.02,2.4681,2.46813,3.000
3,27.188,0.01,2.3430,2.34295,3.000
3,27.312,0.00,2.2179,2.21785,3.000
3,27.438,0.00,2.0929,2.09290,3.000
3,27.562,0.00,1.9679,1.96785,3.000
3,27.688,0.00,1.8429,1.84288,3.000
3,27.812,0.00,1.7179,1.71793,3.000
3,27.938,0.00,1.5929,1.59290,3.000
3,28.062,0.00,1.4680,1.46795,3.000
3,28.188,0.00,1.3429,1.34285,3.000
3,28.312,0.00,1.2177,1.21770,3.000
3,28.438,0.00,1.0928,1.09280,3.000
3,28.562,0.00,0.9679,0.96793,3.000
3,28.688,0.00,0.8429,0.84285,3.000
3,28.812,0.00,0.7179,0.71790,3.000
3,28.938,0.00,0.5929,0.59290,3.000
3,29.062,0.00,0.4679,0.46793,3.000
3,29.188,0.00,0.3428,0.34275,3.000
3,29.312,0.00,0.2178,0.21775,3.000
3,29.438,0.00,0.0927,0.09270,3.000
3,29.688,0.00,-0.0052,-0.00518,3.000
3,29.812,0.00,-0.0002,-0.00020,3.000
3,29.938,0.00,-0.0002,-0.00020,3.000
3,30.062,0.00,-0.0002,-0.00020,3.000
3,30.188,0.00,-0.0002,-0.00020,3.000
3,30.312,0.00,-0.0002,-0.00020,3.000
3,30.438,0.00,-0.0002,-0.00020,3.000
3,30.562,0.00,-0.0002,-0.00020,3.000
3,30.688,0.00,-0.0002,-0.00020,3.000
3,30.812,0.00,-0.0002,-0.00020,3.000
3,30.938,0.00,-0.0002,-0.00020,3.000
3,31.062,0.00,-0.0002,-0.00020,3.000
3,31.188,0.00,-0.0001,-0.00010,3.000
3,31.312,0.00,-0.0001,-0.00010,3.000
3,31.438,0.00,-0.0001,-0.00010,3.000
3,31.562,0.00,-0.0001,-0.00010,3.000
3,31.688,0.00,-0.0001,-0.00010,3.000
3,31.812,0.00,-0.0001,-0.00010,3.000
3,31.938,0.00,-0.0001,-0.00010,3.000
3,32.062,0.00,-0.0001,-0.00010,3.000
3,32.188,0.00,-0.0001,-0.00010,3.000
3,32.312,0.00,-0.0001,-0.00010,3.000
3,32.438,0.00,-0.0001,-0.00010,3.000
3,32.562,0.00,-0.0001,-0.00010,3.000
4,32.938,0.00,0.0879,0.08790,4.000
4,33.062,0.00,0.2130,0.21300,4.000
4,33.188,0.00,0.3381,0.33808,4.000
4,33.312,0.00,0.4631,0.46310,4.000
4,33.438,0.00,0.5882,0.58815,4.000
4,33.562,0.00,0.7133,0.71327,4.000
4,33.688,0.00,0.8382,0.83820,4.000
4,33.812,0.00,0.9632,0.96325,4.000
4,33.938,0.00,1.0881,1.08813,4.000
4,34.062,0.00,1.2130,1.21302,4.000
4,34.188,0.00,1.3381,1.33813,4.000
4,34.312,0.00,1.4632,1.46317,4.000
4,34.438,0.00,1.5883,1.58825,4.000
4,34.562,0.00,1.7132,1.71322,4.000
4,34.688,0.00,1.8382,1.83818,4.000
4,34.812,0.00,1.9632,1.96325,4.000
4,34.938,0.00,2.0882,2.08818,4.000
4,35.062,0.00,2.2131,2.21310,4.000
4,35.188,0.01,2.3381,2.33813,4.000
4,35.312,0.05,2.4633,2.46330,4.000
4,35.438,0.11,2.5883,2.58825,4.000
4,35.562,0.24,2.7132,2.71325,4.000
4,35.688,0.44,2.8384,2.83835,4.000
4,35.812,0.74,2.9634,2.96337,4.000
4,35.938,1.13,3.0884,3.08843,4.000
4,36.062,1.64,3.2132,3.21322,4.000
4,36.188,2.26,3.3383,3.33828,4.000
4,36.312,3.01,3.4632,3.46320,4.000
4,36.438,3.92,3.5883,3.58825,4.000
4,36.562,4.96,3.7133,3.71330,4.000
4,36.750,4.37,3.6616,3.66160,4.000
4,36.875,3.22,3.5365,3.53645,4.000
4,37.000,2.33,3.4114,3.41140,4.000
4,37.125,1.65,3.2865,3.28650,4.000
4,37.250,1.12,3.1615,3.16150,4.000
4,37.375,0.72,3.0367,3.03670,4.000
4,37.500,0.41,2.9116,2.91160,4.000
4,37.625,0.21,2.7865,2.78650,4.000
4,37.750,0.08,2.6614,2.66140,4.000
4,37.875,0.03,2.5364,2.53640,4.000
4,38.000,0.01,2.4115,2.41150,4.000
4,38.125,0.00,2.2864,2.28640,4.000
4,38.250,0.00,2.1616,2.16160,4.000
4,38.375,0.00,2.0365,2.03645,4.000
4,38.500,0.00,1.9114,1.91140,4.000
4,38.625,0.00,1.7864,1.78640,4.000
4,38.750,0.00,1.6614,1.66140,4.000
4,38.875,0.00,1.5364,1.53635,4.000
4,39.000,0.00,1.4113,1.41130,4.000
4,39.125,0.00,1.2863,1.28630,4.000
4,39.250,0.00,1.1612,1.16120,4.000
4,39.375,0.00,1.0365,1.03650,4.000
4,39.500,0.00,0.9115,0.91150,4.000
4,39.625,0.00,0.7865,0.78645,4.000
4,39.750,0.00,0.6614,0.66140,4.000
4,39.875,0.00,0.5362,0.53625,4.000
4,40.000,0.00,0.4113,0.41130,4.000
4,40.125,0.00,0.2862,0.28620,4.000
4,40.250,0.00,0.1614,0.16140,4.000
4,40.375,0.00,0.0363,0.03630,4.000
4,40.625,0.00,-0.0002,-0.00020,4.000
4,40.750,0.00,-0.0002,-0.00020,4.000
4,40.875,0.00,-0.0002,-0.00020,4.000
4,41.000,0.00,-0.0002,-0.00020,4.000
4,41.125,0.00,-0.0002,-0.00020,4.000
4,41.250,-0.01,-0.0002,-0.00020,4.000
4,41.375,0.00,-0.0002,-0.00020,4.000
4,41.500,0.00,-0.0002,-0.00020,4.000
4,41.625,0.00,-0.0002,-0.00020,4.000
4,41.750,-0.01,-0.0002,-0.00020,4.000
4,41.875,0.00,-0.0001,-0.00010,4.000
4,42.000,0.00,-0.0001,-0.00010,4.000
4,42.125,0.00,-0.0001,-0.00010,4.000
4,42.250,0.00,-0.0001,-0.00010,4.000
4,42.375,0.00,-0.0001,-0.00010,4.000
4,42.500,0.00,-0.0001,-0.00010,4.000
4,42.625,0.00,-0.0001,-0.00010,4.000
4,42.750,0.00,-0.0001,-0.00010,4.000
4,42.875,0.00,-0.0001,-0.00010,4.000
4,43.000,0.00,-0.0001,-0.00010,4.000
4,43.125,0.00,-0.0001,-0.00010,4.000
4,43.250,0.00,-0.0001,-0.00010,4.000
4,43.375,0.00,-0.0001,-0.00010,4.000
4,43.500,0.00,-0.0001,-0.00010,4.000
5,43.875,0.00,0.1234,0.12345,5.000
5,44.000,0.00,0.2485,0.24850,5.000
5,44.125,0.00,0.3736,0.37355,5.000
5,44.250,0.00,0.4985,0.49850,5.000
5,44.375,0.00,0.6236,0.62355,5.000
5,44.500,0.00,0.7487,0.74870,5.000
5,44.625,0.00,0.8738,0.87375,5.000
5,44.750,0.00,0.9989,0.99890,5.000
5,44.875,0.00,1.1236,1.12360,5.000
5,45.000,0.01,1.2487,1.24870,5.000
5,45.125,0.00,1.3736,1.37355,5.000
5,45.250,0.00,1.4986,1.49860,5.000
5,45.375,0.01,1.6237,1.62370,5.000
5,45.500,0.00,1.7486,1.74860,5.000
5,45.625,0.00,1.8737,1.87370,5.000
5,45.750,0.00,1.9987,1.99870,5.000
5,45.875,0.00,2.1238,2.12375,5.000
5,46.000,0.01,2.2486,2.24860,5.000
5,46.125,0.03,2.3737,2.37370,5.000
5,46.250,0.06,2.4986,2.49860,5.000
5,46.375,0.14,2.6237,2.62370,5.000
5,46.500,0.29,2.7488,2.74880,5.000
5,46.625,0.52,2.8738,2.87380,5.000
5,46.750,0.84,2.9988,2.99880,5.000
5,46.875,1.27,3.1239,3.12390,5.000
5,47.000,1.80,3.2487,3.24870,5.000
5,47.125,2.46,3.3738,3.37375,5.000
5,47.250,3.26,3.4985,3.49850,5.000
5,47.375,4.20,3.6237,3.62370,5.000
5,47.562,5.39,3.7461,3.74608,5.000
5,47.688,3.98,3.6220,3.62197,5.000
5,47.812,2.92,3.4969,3.49690,5.000
5,47.938,2.10,3.3720,3.37197,5.000
5,48.062,1.47,3.2470,3.24700,5.000
5,48.188,0.98,3.1222,3.12217,5.000
5,48.312,0.61,2.9971,2.99713,5.000
5,48.438,0.34,2.8721,2.87207,5.000
5,48.562,0.16,2.7470,2.74703,5.000
5,48.688,0.06,2.6218,2.62182,5.000
5,48.812,0.02,2.4970,2.49695,5.000
5,48.938,0.01,2.3720,2.37197,5.000
5,49.062,0.00,2.2470,2.24698,5.000
5,49.188,0.00,2.1220,2.12205,5.000
5,49.312,0.01,1.9970,1.99698,5.000
5,49.438,0.00,1.8719,1.87190,5.000
5,49.562,0.00,1.7470,1.74695,5.000
5,49.688,0.01,1.6219,1.62187,5.000
5,49.812,0.00,1.4968,1.49683,5.000
5,49.938,0.00,1.3719,1.37187,5.000
5,50.062,0.00,1.2468,1.24680,5.000
5,50.188,0.00,1.1219,1.12187,5.000
5,50.312,0.00,0.9970,0.99695,5.000
5,50.438,0.00,0.8720,0.87197,5.000
5,50.562,0.00,0.7470,0.74703,5.000
5,50.688,0.00,0.6219,0.62187,5.000
5,50.812,0.00,0.4968,0.49680,5.000
5,50.938,0.00,0.3717,0.37172,5.000
5,51.062,0.00,0.2467,0.24670,5.000
5,51.188,0.00,0.1218,0.12182,5.000
5,51.312,0.00,-0.0031,-0.00307,5.000
5,51.500,0.00,-0.0001,-0.00010,5.000
5,51.625,0.00,-0.0001,-0.00010,5.000
5,51.750,0.00,-0.0001,-0.00010,5.000
5,51.875,0.00,-0.0001,-0.00010,5.000
5,52.000,0.00,-0.0001,-0.00010,5.000
5,52.125,0.00,-0.0001,-0.00010,5.000
5,52.250,0.00,-0.0001,-0.00010,5.000
5,52.375,0.00,-0.0001,-0.00010,5.000
5,52.500,0.00,-0.0001,-0.00010,5.000
5,52.625,0.00,-0.0001,-0.00010,5.000
5,52.750,0.00,-0.0001,-0.00010,5.000
5,52.875,0.00,-0.0001,-0.00010,5.000
5,53.000,0.00,-0.0001,-0.00010,5.000
5,53.125,0.00,-0.0001,-0.00010,5.000
5,53.250,0.00,-0.0001,-0.00010,5.000
5,53.375,0.00,-0.0001,-0.00010,5.000
5,53.500,0.00,-0.0001,-0.00010,5.000
5,53.625,0.00,-0.0001,-0.00010,5.000
5,53.750,0.00,-0.0001,-0.00010,5.000
5,53.875,0.00,-0.0001,-0.00010,5.000
5,54.000,0.00,-0.0001,-0.00010,5.000
5,54.125,0.00,-0.0001,-0.00010,5.000
5,54.250,0.00,-0.0001,-0.00010,5.000
5,54.375,0.00,-0.0001,-0.00010,5.000
6,54.750,0.00,0.1294,0.12940,6.000
6,54.875,0.00,0.2544,0.25445,6.000
6,55.000,0.00,0.3795,0.37950,6.000
6,55.125,0.00,0.5045,0.50455,6.000
6,55.250,0.00,0.6295,0.62950,6.000
6,55.375,0.00,0.7547,0.75470,6.000
6,55.500,0.00,0.8798,0.87980,6.000
6,55.625,0.00,1.0047,1.00475,6.000
6,55.750,0.00,1.1296,1.12960,6.000
6,55.875,0.00,1.2545,1.25455,6.000
6,56.000,0.00,1.3796,1.37960,6.000
6,56.125,0.00,1.5046,1.50460,6.000
6,56.250,0.00,1.6298,1.62980,6.000
6,56.375,0.00,1.7547,1.75470,6.000
6,56.500,0.00,1.8796,1.87960,6.000
6,56.625,0.00,2.0047,2.00470,6.000
6,56.750,0.01,2.1298,2.12980,6.000
6,56.875,0.00,2.2546,2.25465,6.000
6,57.000,0.03,2.3796,2.37960,6.000
6,57.125,0.06,2.5047,2.50475,6.000
6,57.250,0.14,2.6297,2.62970,6.000
6,57.375,0.29,2.7547,2.75475,6.000
6,57.500,0.53,2.8798,2.87980,6.000
6,57.625,0.86,3.0048,3.00485,6.000
6,57.750,1.29,3.1299,3.12990,6.000
6,57.875,1.83,3.2547,3.25470,6.000
6,58.000,2.50,3.3796,3.37960,6.000
6,58.125,3.31,3.5046,3.50460,6.000
6,58.250,4.25,3.6298,3.62980,6.000
6,58.438,5.43,3.7503,3.75035,6.000
6,58.562,4.01,3.6260,3.62600,6.000
6,58.688,2.94,3.5009,3.50090,6.000
6,58.812,2.11,3.3760,3.37598,6.000
6,58.938,1.48,3.2509,3.25095,6.000
6,59.062,0.99,3.1260,3.12603,6.000
6,59.188,0.62,3.0012,3.00117,6.000
6,59.312,0.35,2.8760,2.87600,6.000
6,59.438,0.16,2.7511,2.75107,6.000
6,59.562,0.06,2.6260,2.62595,6.000
6,59.688,0.02,2.5010,2.50097,6.000
6,59.812,0.01,2.3759,2.37593,6.000
6,59.938,0.00,2.2509,2.25087,6.000
6,60.062,0.00,2.1260,2.12600,6.000
6,60.188,0.00,2.0009,2.00090,6.000
6,60.312,0.00,1.8759,1.87590,6.000
6,60.438,0.00,1.7510,1.75097,6.000
6,60.562,0.00,1.6259,1.62588,6.000
6,60.688,0.00,1.5008,1.50085,6.000
6,60.812,0.00,1.3757,1.37573,6.000
6,60.938,0.00,1.2507,1.25072,6.000
6,61.062,0.00,1.1258,1.12583,6.000
6,61.188,0.00,1.0010,1.00097,6.000
6,61.312,0.00,0.8759,0.87585,6.000
6,61.438,0.00,0.7509,0.75092,6.000
6,61.562,0.00,0.6259,0.62588,6.000
6,61.688,0.00,0.5008,0.50075,6.000
6,61.812,0.00,0.3757,0.37573,6.000
6,61.938,0.00,0.2508,0.25075,6.000
6,62.062,0.00,0.1257,0.12568,6.000
6,62.188,0.00,0.0008,0.00080,6.000
6,62.375,0.00,-0.0001,-0.00010,6.000
6,62.500,0.00,-0.0001,-0.00010,6.000
6,62.625,0.00,-0.0001,-0.00010,6.000
6,62.750,0.00,-0.0001,-0.00010,6.000
6,62.875,0.00,-0.0001,-0.00010,6.000
6,63.000,0.00,-0.0001,-0.00010,6.000
6,63.125,0.00,-0.0001,-0.00010,6.000
6,63.250,0.00,-0.0001,-0.00010,6.000
6,63.375,0.00,-0.0001,-0.00010,6.000
6,63.500,0.00,-0.0001,-0.00010,6.000
6,63.625,0.00,-0.0001,-0.00010,6.000
6,63.750,0.00,-0.0001,-0.00010,6.000
6,63.875,0.00,-0.0001,-0.00010,6.000
6,64.000,0.00,-0.0001,-0.00010,6.000
6,64.125,0.00,-0.0001,-0.00010,6.000
6,64.250,0.00,-0.0001,-0.00010,6.000
6,64.375,0.00,-0.0001,-0.00010,6.000
6,64.500,0.00,-0.0001,-0.00010,6.000
6,64.625,0.00,-0.0001,-0.00010,6.000
6,64.750,0.00,-0.0001,-0.00010,6.000
6,64.875,0.00,-0.0001,-0.00010,6.000
6,65.000,0.00,-0.0001,-0.00010,6.000
6,65.125,0.00,-0.0001,-0.00010,6.000
6,65.250,0.00,-0.0001,-0.00010,6.000
7,65.625,0.00,0.1455,0.14560,7.000
7,65.750,0.00,0.2705,0.27060,7.000
7,65.875,0.00,0.3957,0.39580,7.000
7,66.000,0.00,0.5206,0.52070,7.000
7,66.125,0.00,0.6456,0.64570,7.000
7,66.250,0.00,0.7705,0.77060,7.000
7,66.375,0.00,0.8956,0.89570,7.000
7,66.500,0.00,1.0207,1.02080,7.000
7,66.625,0.00,1.1456,1.14565,7.000
7,66.750,0.00,1.2706,1.27070,7.000
7,66.875,0.00,1.3957,1.39580,7.000
7,67.000,0.00,1.5206,1.52070,7.000
7,67.125,0.00,1.6457,1.64580,7.000
7,67.250,0.00,1.7706,1.77070,7.000
7,67.375,0.00,1.8956,1.89570,7.000
7,67.500,0.00,2.0206,2.02070,7.000
7,67.625,0.00,2.1457,2.14580,7.000
7,67.750,0.00,2.2707,2.27080,7.000
7,67.875,0.03,2.3959,2.39595,7.000
7,68.000,0.07,2.5209,2.52100,7.000
7,68.125,0.16,2.6458,2.64590,7.000
7,68.250,0.32,2.7707,2.77080,7.000
7,68.375,0.57,2.8957,2.89580,7.000
7,68.500,0.91,3.0207,3.02080,7.000
7,68.625,1.35,3.1457,3.14580,7.000
7,68.750,1.91,3.2707,3.27080,7.000
7,68.875,2.59,3.3958,3.39590,7.000
7,69.000,3.41,3.5208,3.52090,7.000
7,69.125,4.38,3.6458,3.64595,7.000
7,69.312,5.49,3.7570,3.75708,7.000
7,69.438,4.04,3.6321,3.63215,7.000
7,69.562,2.97,3.5070,3.50708,7.000
7,69.688,2.14,3.3819,3.38202,7.000
7,69.812,1.50,3.2569,3.25703,7.000
7,69.938,1.00,3.1320,3.13213,7.000
7,70.062,0.63,3.0071,3.00715,7.000
7,70.188,0.35,2.8820,2.88213,7.000
7,70.312,0.17,2.7571,2.75715,7.000
7,70.438,0.06,2.6320,2.63210,7.000
7,70.562,0.02,2.5070,2.50708,7.000
7,70.688,0.01,2.3819,2.38198,7.000
7,70.812,0.00,2.2568,2.25688,7.000
7,70.938,0.00,2.1320,2.13205,7.000
7,71.062,0.00,2.0069,2.00695,7.000
7,71.188,0.00,1.8820,1.88205,7.000
7,71.312,0.00,1.7569,1.75695,7.000
7,71.438,0.00,1.6320,1.63208,7.000
7,71.562,0.00,1.5069,1.50703,7.000
7,71.688,0.00,1.3818,1.38188,7.000
7,71.812,0.00,1.2568,1.25690,7.000
7,71.938,0.00,1.1318,1.13190,7.000
7,72.062,0.00,1.0069,1.00703,7.000
7,72.188,0.00,0.8820,0.88208,7.000
7,72.312,0.00,0.7569,0.75703,7.000
7,72.438,0.00,0.6319,0.63200,7.000
7,72.562,0.00,0.5069,0.50695,7.000
7,72.688,0.00,0.3818,0.38188,7.000
7,72.812,0.00,0.2566,0.25673,7.000
7,72.938,0.00,0.1317,0.13180,7.000
7,73.062,0.00,0.0068,0.00688,7.000
7,73.250,0.00,-0.0001,0.00000,7.000
7,73.375,0.00,-0.0002,-0.00005,7.000
7,73.500,0.00,-0.0001,0.00000,7.000
7,73.625,0.00,-0.0001,0.00000,7.000
7,73.750,0.00,-0.0001,0.00000,7.000
7,73.875,0.00,-0.0001,0.00000,7.000
7,74.000,0.00,-0.0001,0.00000,7.000
7,74.125,0.00,-0.0001,0.00000,7.000
7,74.250,0.00,-0.0001,0.00000,7.000
7,74.375,0.00,-0.0001,0.00000,7.000
7,74.500,0.00,-0.0001,0.00000,7.000
7,74.625,0.00,-0.0001,0.00000,7.000
7,74.750,0.00,-0.0001,0.00000,7.000
7,74.875,0.00,-0.0001,0.00000,7.000
7,75.000,0.00,-0.0001,0.00000,7.000
7,75.125,0.00,-0.0001,0.00000,7.000
7,75.250,0.00,-0.0001,0.00000,7.000
7,75.375,0.00,-0.0001,0.00000,7.000
7,75.500,0.00,-0.0001,0.00000,7.000
7,75.625,0.00,-0.0001,0.00000,7.000
7,75.750,-0.01,-0.0001,0.00000,7.000
7,75.875,0.00,-0.0001,0.00000,7.000
7,76.000,0.00,-0.0001,0.00000,7.000
7,76.125,0.00,-0.0001,0.00000,7.000
8,76.500,0.00,0.1293,0.12940,8.000
8,76.625,0.00,0.2544,0.25455,8.000
8,76.750,0.00,0.3796,0.37970,8.000
8,76.875,0.00,0.5045,0.50460,8.000
8,77.000,0.00,0.6295,0.62960,8.000
8,77.125,0.00,0.7547,0.75480,8.000
8,77.250,0.00,0.8797,0.87980,8.000
8,77.375,0.00,1.0048,1.00485,8.000
8,77.500,0.00,1.1296,1.12970,8.000
8,77.625,0.00,1.2546,1.25465,8.000
8,77.750,0.01,1.3795,1.37960,8.000
8,77.875,0.01,1.5046,1.50470,8.000
8,78.000,0.00,1.6297,1.62980,8.000
8,78.125,0.00,1.7547,1.75480,8.000
8,78.250,0.00,1.8797,1.87980,8.000
8,78.375,0.00,2.0047,2.00480,8.000
8,78.500,0.00,2.1298,2.12990,8.000
8,78.625,0.01,2.2547,2.25480,8.000
8,78.750,0.02,2.3797,2.37980,8.000
8,78.875,0.06,2.5047,2.50480,8.000
8,79.000,0.14,2.6297,2.62980,8.000
8,79.125,0.30,2.7547,2.75480,8.000
8,79.250,0.53,2.8799,2.88000,8.000
8,79.375,0.86,3.0049,3.00500,8.000
8,79.500,1.30,3.1298,3.12990,8.000
8,79.625,1.83,3.2547,3.25480,8.000
8,79.750,2.51,3.3796,3.37970,8.000
8,79.875,3.31,3.5046,3.50475,8.000
8,80.000,4.25,3.6298,3.62990,8.000
8,80.188,5.53,3.7610,3.76105,8.000
8,80.312,4.11,3.6382,3.63828,8.000
8,80.438,3.02,3.5130,3.51310,8.000
8,80.562,2.18,3.3879,3.38803,8.000
8,80.688,1.53,3.2629,3.26300,8.000
8,80.812,1.03,3.1380,3.13805,8.000
8,80.938,0.65,3.0131,3.01318,8.000
8,81.062,0.37,2.8881,2.88818,8.000
8,81.188,0.18,2.7630,2.76312,8.000
8,81.312,0.07,2.6380,2.63805,8.000
8,81.438,0.03,2.5130,2.51312,8.000
8,81.562,0.01,2.3880,2.38813,8.000
8,81.688,0.00,2.2628,2.26288,8.000
8,81.812,0.00,2.1379,2.13795,8.000
8,81.938,0.00,2.0128,2.01290,8.000
8,82.062,0.00,1.8879,1.88798,8.000
8,82.188,0.00,1.7629,1.76300,8.000
8,82.312,0.01,1.6379,1.63803,8.000
8,82.438,0.00,1.5129,1.51300,8.000
8,82.562,0.00,1.3879,1.38798,8.000
8,82.688,0.00,1.2628,1.26292,8.000
8,82.812,0.00,1.1377,1.13783,8.000
8,82.938,0.00,1.0129,1.01300,8.000
8,83.062,0.00,0.8879,0.88800,8.000
8,83.188,0.00,0.7629,0.76300,8.000
8,83.312,0.00,0.6378,0.63793,8.000
8,83.438,0.00,0.5129,0.51298,8.000
8,83.562,0.00,0.3879,0.38795,8.000
8,83.688,0.00,0.2628,0.26285,8.000
8,83.812,0.00,0.1377,0.13778,8.000
8,83.938,0.00,0.0128,0.01288,8.000
8,84.125,0.00,-0.0002,-0.00010,8.000
8,84.250,0.00,-0.0001,0.00000,8.000
8,84.375,0.00,-0.0001,0.00000,8.000
8,84.500,0.00,-0.0001,0.00000,8.000
8,84.625,0.00,-0.0001,0.00000,8.000
8,84.750,0.00,-0.0001,0.00000,8.000
8,84.875,0.00,-0.0001,0.00000,8.000
8,85.000,-0.01,-0.0001,0.00000,8.000
8,85.125,0.00,-0.0001,0.00000,8.000
8,85.250,0.00,-0.0001,0.00000,8.000
8,85.375,0.00,-0.0001,0.00000,8.000
8,85.500,0.00,-0.0001,0.00000,8.000
8,85.625,0.00,-0.0001,0.00000,8.000
8,85.750,0.00,-0.0001,0.00000,8.000
8,85.875,0.00,-0.0001,0.00000,8.000
8,86.000,0.00,-0.0001,0.00000,8.000
8,86.125,0.01,-0.0001,0.00000,8.000
8,86.250,0.00,-0.0001,0.00000,8.000
8,86.375,0.00,-0.0001,0.00000,8.000
8,86.500,0.01,-0.0001,0.00000,8.000
8,86.625,0.00,-0.0001,0.00000,8.000
8,86.750,0.00,-0.0001,0.00000,8.000
8,86.875,0.00,-0.0001,0.00000,8.000
8,87.000,0.00,-0.0001,0.00000,8.000
9,87.375,0.00,0.1244,0.12445,9.000
9,87.500,0.00,0.2494,0.24940,9.000
9,87.625,0.00,0.3745,0.37450,9.000
9,87.750,0.00,0.4995,0.49950,9.000
9,87.875,0.00,0.6245,0.62450,9.000
9,88.000,0.00,0.7496,0.74960,9.000
9,88.125,0.00,0.8747,0.87470,9.000
9,88.250,0.00,0.9998,0.99980,9.000
9,88.375,0.00,1.1247,1.12465,9.000
9,88.500,0.00,1.2495,1.24950,9.000
9,88.625,0.00,1.3746,1.37460,9.000
9,88.750,0.00,1.4996,1.49960,9.000
9,88.875,0.00,1.6246,1.62460,9.000
9,89.000,0.00,1.7497,1.74970,9.000
9,89.125,0.00,1.8747,1.87465,9.000
9,89.250,0.00,1.9997,1.99970,9.000
9,89.375,0.00,2.1248,2.12480,9.000
9,89.500,0.00,2.2497,2.24970,9.000
9,89.625,0.02,2.3747,2.37470,9.000
9,89.750,0.06,2.4997,2.49970,9.000
9,89.875,0.13,2.6246,2.62465,9.000
9,90.000,0.28,2.7497,2.74970,9.000
9,90.125,0.52,2.8748,2.87475,9.000
9,90.250,0.84,2.9998,2.99980,9.000
9,90.375,1.27,3.1249,3.12485,9.000
9,90.500,1.81,3.2498,3.24980,9.000
9,90.625,2.47,3.3747,3.37470,9.000
9,90.750,3.27,3.4996,3.49960,9.000
9,90.875,4.21,3.6246,3.62465,9.000
9,91.000,5.30,3.7496,3.74960,9.000
9,91.125,4.86,3.7055,3.70550,9.000
9,91.250,3.57,3.5804,3.58040,9.000
9,91.375,2.61,3.4554,3.45540,9.000
9,91.500,1.86,3.3305,3.33050,9.000
9,91.625,1.28,3.2056,3.20555,9.000
9,91.750,0.84,3.0806,3.08060,9.000
9,91.875,0.51,2.9556,2.95555,9.000
9,92.000,0.27,2.8305,2.83050,9.000
9,92.125,0.11,2.7054,2.70545,9.000
9,92.250,0.04,2.5804,2.58040,9.000
9,92.375,0.02,2.4555,2.45550,9.000
9,92.500,0.00,2.3305,2.33050,9.000
9,92.625,0.00,2.2055,2.20550,9.000
9,92.750,0.00,2.0805,2.08050,9.000
9,92.875,0.00,1.9554,1.95545,9.000
9,93.000,0.00,1.8304,1.83040,9.000
9,93.125,0.00,1.7054,1.70540,9.000
9,93.250,0.00,1.5802,1.58020,9.000
9,93.375,0.00,1.4554,1.45535,9.000
9,93.500,0.00,1.3304,1.33040,9.000
9,93.625,0.00,1.2053,1.20530,9.000
9,93.750,0.00,1.0805,1.08050,9.000
9,93.875,0.00,0.9555,0.95550,9.000
9,94.000,0.00,0.8305,0.83050,9.000
9,94.125,0.00,0.7053,0.70530,9.000
9,94.250,0.00,0.5802,0.58020,9.000
9,94.375,0.00,0.4554,0.45535,9.000
9,94.500,0.00,0.3303,0.33030,9.000
9,94.625,0.00,0.2053,0.20530,9.000
9,94.750,0.00,0.0802,0.08020,9.000
9,94.938,0.00,-0.0506,-0.05065,9.000
9,95.062,0.00,-0.0001,-0.00012,9.000
9,95.188,-0.01,-0.0001,-0.00010,9.000
9,95.312,0.00,-0.0001,-0.00010,9.000
9,95.438,0.00,-0.0001,-0.00010,9.000
9,95.562,0.00,-0.0001,-0.00010,9.000
9,95.688,0.00,-0.0001,-0.00010,9.000
9,95.812,0.00,-0.0001,-0.00010,9.000
9,95.938,0.00,-0.0001,-0.00010,9.000
9,96.062,0.00,-0.0001,-0.00010,9.000
9,96.188,0.00,-0.0001,-0.00010,9.000
9,96.312,0.00,-0.0001,-0.00010,9.000
9,96.438,0.00,-0.0001,-0.00010,9.000
9,96.562,0.00,-0.0001,-0.00010,9.000
9,96.688,0.00,-0.0001,-0.00010,9.000
9,96.812,0.00,-0.0001,-0.00010,9.000
9,96.938,0.00,-0.0001,-0.00010,9.000
9,97.062,-0.01,-0.0001,-0.00010,9.000
9,97.188,0.00,-0.0001,-0.00010,9.000
9,97.312,0.00,-0.0001,-0.00010,9.000
9,97.438,-0.01,-0.0001,-0.00010,9.000
9,97.562,0.00,-0.0001,-0.00010,9.000
9,97.688,0.00,-0.0001,-0.00010,9.000
9,97.812,0.00,-0.0001,-0.00010,9.000
9,97.938,0.00,-0.0001,-0.00010,9.000
10,98.250,0.00,0.1105,0.11050,10.000
10,98.375,0.00,0.2356,0.23555,10.000
10,98.500,0.00,0.3606,0.36060,10.000
10,98.625,0.00,0.4856,0.48560,10.000
10,98.750,-0.01,0.6105,0.61050,10.000
10,98.875,0.00,0.7356,0.73560,10.000
10,99.000,0.00,0.8605,0.86050,10.000
10,99.125,0.00,0.9858,0.98575,10.000
10,99.250,-0.01,1.1105,1.11050,10.000
10,99.375,0.00,1.2357,1.23565,10.000
10,99.500,0.00,1.3607,1.36070,10.000
10,99.625,0.00,1.4857,1.48570,10.000
10,99.750,0.00,1.6106,1.61060,10.000
10,99.875,0.00,1.7356,1.73560,10.000
10,100.000,-0.01,1.8606,1.86060,10.000
10,100.125,0.00,1.9856,1.98560,10.000
10,100.250,0.00,2.1107,2.11070,10.000
10,100.375,0.00,2.2358,2.23575,10.000
10,100.500,0.02,2.3607,2.36070,10.000
10,100.625,0.05,2.4858,2.48585,10.000
10,100.750,0.13,2.6108,2.61080,10.000
10,100.875,0.27,2.7358,2.73575,10.000
10,101.000,0.49,2.8606,2.86060,10.000
10,101.125,0.80,2.9858,2.98575,10.000
10,101.250,1.22,3.1108,3.11080,10.000
10,101.375,1.74,3.2358,3.23575,10.000
10,101.500,2.39,3.3607,3.36070,10.000
10,101.625,3.18,3.4857,3.48570,10.000
10,101.750,4.11,3.6109,3.61090,10.000
10,101.875,5.18,3.7358,3.73575,10.000
10,102.062,4.32,3.6590,3.65903,10.000
10,102.188,3.18,3.5340,3.53398,10.000
10,102.312,2.30,3.4090,3.40895,10.000
10,102.438,1.63,3.2840,3.28400,10.000
10,102.562,1.11,3.1591,3.15908,10.000
10,102.688,0.70,3.0341,3.03410,10.000
10,102.812,0.41,2.9090,2.90898,10.000
10,102.938,0.20,2.7840,2.78395,10.000
10,103.062,0.08,2.6589,2.65890,10.000
10,103.188,0.03,2.5340,2.53395,10.000
10,103.312,0.01,2.4091,2.40908,10.000
10,103.438,0.00,2.2840,2.28398,10.000
10,103.562,0.00,2.1591,2.15905,10.000
10,103.688,0.00,2.0339,2.03392,10.000
10,103.812,0.00,1.9088,1.90880,10.000
10,103.938,0.00,1.7838,1.78383,10.000
10,104.062,0.00,1.6588,1.65880,10.000
10,104.188,0.00,1.5339,1.53385,10.000
10,104.312,0.00,1.4089,1.40890,10.000
10,104.438,0.00,1.2839,1.28390,10.000
10,104.562,0.00,1.1589,1.15888,10.000
10,104.688,0.00,1.0340,1.03400,10.000
10,104.812,0.00,0.9089,0.90888,10.000
10,104.938,0.00,0.7838,0.78385,10.000
10,105.062,0.00,0.6588,0.65875,10.000
10,105.188,0.00,0.5338,0.53378,10.000
10,105.312,0.00,0.4089,0.40888,10.000
10,105.438,0.00,0.2837,0.28370,10.000
10,105.562,0.00,0.1588,0.15880,10.000
10,105.688,0.00,0.0339,0.03385,10.000
10,105.875,0.00,-0.0058,-0.00580,10.000
10,106.000,0.00,-0.0001,-0.00010,10.000
10,106.125,0.00,-0.0001,-0.00010,10.000
10,106.250,0.00,-0.0001,-0.00010,10.000
10,106.375,0.00,-0.0001,-0.00010,10.000
10,106.500,0.00,-0.0001,-0.00010,10.000
10,106.625,0.00,-0.0001,-0.00010,10.000
10,106.750,0.00,-0.0001,-0.00010,10.000
10,106.875,0.00,-0.0001,-0.00010,10.000
10,107.000,0.00,-0.0001,-0.00010,10.000
10,107.125,0.00,-0.0001,-0.00010,10.000
10,107.250,0.00,-0.0001,-0.00010,10.000
10,107.375,0.00,-0.0001,-0.00010,10.000
10,107.500,0.00,-0.0001,-0.00010,10.000
10,107.625,0.00,-0.0001,-0.00010,10.000
10,107.750,0.00,-0.0001,-0.00010,10.000
10,107.875,0.00,-0.0001,-0.00010,10.000
10,108.000,0.00,-0.0001,-0.00010,10.000
10,108.125,0.00,-0.0001,-0.00010,10.000
10,108.250,0.00,-0.0001,-0.00010,10.000
10,108.375,0.00,-0.0001,-0.00010,10.000
10,108.500,0.00,-0.0001,-0.00010,10.000
10,108.625,0.00,-0.0001,-0.00010,10.000
10,108.750,0.00,-0.0001,-0.00010,10.000
10,108.812,0.00,-0.0001,-0.00010,10.000