File: calibDATA_loadcell/date_02:22:2018/Instron/5N_0_1_4_0.txt
""
"Test Method","Radhen_Load_Cntrl_Cmprsn_250N_12-7.msm"
"Sample I. D.","Sample1.mss"
"Specimen Number","19"

"TheCycle_Output ()","_Time (s)","_Load (N)","_Extension (mm)","RealTimeDepth (mm)","CycleNumber ()"

1,0.312,0.00,0.0651,0.06508,1.000
1,0.438,0.01,0.1903,0.19032,1.000
1,0.562,0.01,0.3153,0.31530,1.000
1,0.688,0.00,0.4403,0.44028,1.000
1,0.812,0.01,0.5652,0.56525,1.000
1,0.938,0.01,0.6904,0.69035,1.000
1,1.062,0.01,0.8154,0.81535,1.000
1,1.188,0.00,0.9405,0.94045,1.000
1,1.312,0.00,1.0654,1.06542,1.000
1,1.438,0.01,1.1904,1.19045,1.000
1,1.562,0.00,1.3154,1.31545,1.000
1,1.688,0.00,1.4403,1.44030,1.000
1,1.812,0.00,1.5652,1.56525,1.000
1,1.938,0.01,1.6904,1.69042,1.000
1,2.062,0.01,1.8154,1.81543,1.000
1,2.188,0.02,1.9405,1.94048,1.000
1,2.312,0.04,2.0655,2.06548,1.000
1,2.438,0.08,2.1904,2.19043,1.000
1,2.562,0.14,2.3154,2.31538,1.000
1,2.688,0.24,2.4404,2.44040,1.000
1,2.812,0.41,2.5653,2.56532,1.000
1,2.938,0.67,2.6904,2.69040,1.000
1,3.062,1.03,2.8154,2.81542,1.000
1,3.188,1.50,2.9404,2.94040,1.000
1,3.312,2.09,3.0654,3.06545,1.000
1,3.438,2.82,3.1905,3.19048,1.000
1,3.562,3.71,3.3155,3.31552,1.000
1,3.688,4.78,3.4404,3.44040,1.000
1,3.875,4.71,3.4386,3.43855,1.000
1,4.000,3.42,3.3137,3.31370,1.000
1,4.125,2.46,3.1887,3.18870,1.000
1,4.250,1.74,3.0638,3.06380,1.000
1,4.375,1.19,2.9386,2.93860,1.000
1,4.500,0.77,2.8136,2.81360,1.000
1,4.625,0.47,2.6886,2.68855,1.000
1,4.750,0.27,2.5634,2.56340,1.000
1,4.875,0.14,2.4386,2.43855,1.000
1,5.000,0.07,2.3136,2.31360,1.000
1,5.125,0.04,2.1886,2.18865,1.000
1,5.250,0.03,2.0636,2.06360,1.000
1,5.375,0.01,1.9386,1.93855,1.000
1,5.500,0.01,1.8136,1.81360,1.000
1,5.625,0.01,1.6884,1.68845,1.000
1,5.750,0.01,1.5633,1.56330,1.000
1,5.875,0.01,1.4384,1.43840,1.000
1,6.000,0.00,1.3135,1.31350,1.000
1,6.125,0.01,1.1886,1.18860,1.000
1,6.250,0.00,1.0636,1.06360,1.000
1,6.375,0.01,0.9385,0.93850,1.000
1,6.500,0.01,0.8135,0.81350,1.000
1,6.625,0.01,0.6884,0.68840,1.000
1,6.750,0.00,0.5633,0.56330,1.000
1,6.875,0.01,0.4384,0.43835,1.000
1,7.000,0.00,0.3133,0.31330,1.000
1,7.125,0.01,0.1884,0.18845,1.000
1,7.250,0.01,0.0633,0.06330,1.000
1,7.438,0.01,-0.0119,-0.01193,1.000
1,7.562,0.01,-0.0002,-0.00020,1.000
1,7.688,0.00,-0.0002,-0.00020,1.000
1,7.812,0.00,-0.0002,-0.00020,1.000
1,7.938,0.01,-0.0002,-0.00020,1.000
1,8.062,0.00,-0.0002,-0.00020,1.000
1,8.188,0.00,-0.0002,-0.00020,1.000
1,8.312,0.01,-0.0002,-0.00020,1.000
1,8.438,0.00,-0.0002,-0.00020,1.000
1,8.562,0.00,-0.0002,-0.00020,1.000
1,8.688,0.01,-0.0002,-0.00020,1.000
1,8.812,0.01,-0.0002,-0.00020,1.000
1,8.938,0.00,-0.0002,-0.00020,1.000
1,9.062,0.01,-0.0002,-0.00020,1.000
1,9.188,0.01,-0.0002,-0.00020,1.000
1,9.312,0.01,-0.0002,-0.00020,1.000
1,9.438,0.01,-0.0002,-0.00020,1.000
1,9.562,0.01,-0.0002,-0.00020,1.000
1,9.688,0.01,-0.0002,-0.00020,1.000
1,9.812,0.00,-0.0002,-0.00020,1.000
1,9.938,0.01,-0.0002,-0.00020,1.000
1,10.062,0.01,-0.0002,-0.00020,1.000
1,10.188,0.00,-0.0002,-0.00020,1.000
1,10.312,0.00,-0.0002,-0.00020,1.000
2,10.688,0.00,0.0800,0.08005,2.000
2,10.812,0.00,0.2051,0.20522,2.000
2,10.938,-0.01,0.3302,0.33030,2.000
2,11.062,0.00,0.4553,0.45537,2.000
2,11.188,0.00,0.5803,0.58035,2.000
2,11.312,0.00,0.7052,0.70532,2.000
2,11.438,0.00,0.8303,0.83043,2.000
2,11.562,0.00,0.9553,0.95542,2.000
2,11.688,0.00,1.0802,1.08033,2.000
2,11.812,0.00,1.2052,1.20532,2.000
2,11.938,0.00,1.3303,1.33035,2.000
2,12.062,-0.01,1.4553,1.45540,2.000
2,12.188,0.00,1.5803,1.58040,2.000
2,12.312,-0.01,1.7054,1.70547,2.000
2,12.438,0.00,1.8304,1.83048,2.000
2,12.562,0.01,1.9553,1.95537,2.000
2,12.688,0.04,2.0802,2.08033,2.000
2,12.812,0.08,2.2052,2.20530,2.000
2,12.938,0.13,2.3303,2.33038,2.000
2,13.062,0.24,2.4553,2.45542,2.000
2,13.188,0.41,2.5803,2.58040,2.000
2,13.312,0.69,2.7055,2.70560,2.000
2,13.438,1.05,2.8305,2.83055,2.000
2,13.562,1.54,2.9554,2.95548,2.000
2,13.688,2.14,3.0803,3.08043,2.000
2,13.812,2.89,3.2053,3.20540,2.000
2,13.938,3.81,3.3304,3.33048,2.000
2,14.062,4.90,3.4553,3.45540,2.000
2,14.250,4.51,3.4236,3.42370,2.000
2,14.375,3.27,3.2986,3.29870,2.000
2,14.500,2.36,3.1735,3.17360,2.000
2,14.625,1.66,3.0485,3.04860,2.000
2,14.750,1.12,2.9234,2.92350,2.000
2,14.875,0.72,2.7986,2.79870,2.000
2,15.000,0.42,2.6737,2.67380,2.000
2,15.125,0.23,2.5486,2.54865,2.000
2,15.250,0.12,2.4237,2.42380,2.000
2,15.375,0.06,2.2985,2.29860,2.000
2,15.500,0.03,2.1734,2.17350,2.000
2,15.625,0.02,2.0484,2.04850,2.000
2,15.750,0.00,1.9233,1.92340,2.000
2,15.875,0.00,1.7984,1.79850,2.000
2,16.000,0.00,1.6735,1.67360,2.000
2,16.125,0.00,1.5486,1.54865,2.000
2,16.250,0.00,1.4235,1.42360,2.000
2,16.375,0.00,1.2985,1.29860,2.000
2,16.500,0.00,1.1736,1.17370,2.000
2,16.625,0.00,1.0484,1.04845,2.000
2,16.750,0.00,0.9234,0.92350,2.000
2,16.875,0.00,0.7984,0.79845,2.000
2,17.000,0.00,0.6733,0.67340,2.000
2,17.125,0.00,0.5484,0.54845,2.000
2,17.250,0.00,0.4234,0.42350,2.000
2,17.375,0.00,0.2984,0.29855,2.000
2,17.500,-0.01,0.1735,0.17360,2.000
2,17.625,0.00,0.0482,0.04825,2.000
2,17.812,0.00,-0.0132,-0.01312,2.000
2,17.938,-0.01,-0.0003,-0.00020,2.000
2,18.062,0.00,-0.0003,-0.00020,2.000
2,18.188,0.00,-0.0003,-0.00020,2.000
2,18.312,0.00,-0.0003,-0.00020,2.000
2,18.438,0.00,-0.0003,-0.00020,2.000
2,18.562,0.00,-0.0003,-0.00020,2.000
2,18.688,0.00,-0.0003,-0.00020,2.000
2,18.812,0.00,-0.0003,-0.00020,2.000
2,18.938,0.00,-0.0003,-0.00020,2.000
2,19.062,-0.01,-0.0003,-0.00020,2.000
2,19.188,0.00,-0.0003,-0.00020,2.000
2,19.312,0.00,-0.0003,-0.00020,2.000
2,19.438,0.00,-0.0003,-0.00020,2.000
2,19.562,-0.01,-0.0002,-0.00010,2.000
2,19.688,0.00,-0.0002,-0.00010,2.000
2,19.812,0.00,-0.0002,-0.00010,2.000
2,19.938,0.01,-0.0002,-0.00010,2.000
2,20.062,0.00,-0.0002,-0.00010,2.000
2,20.188,0.00,-0.0002,-0.00010,2.000
2,20.312,0.00,-0.0002,-0.00010,2.000
2,20.438,0.00,-0.0002,-0.00010,2.000
2,20.562,0.00,-0.0002,-0.00010,2.000
2,20.688,0.00,-0.0002,-0.00010,2.000
3,21.062,0.01,0.0710,0.07108,3.000
3,21.188,0.00,0.1961,0.19625,3.000
3,21.312,0.00,0.3212,0.32125,3.000
3,21.438,0.00,0.4462,0.44627,3.000
3,21.562,0.00,0.5712,0.57130,3.000
3,21.688,0.00,0.6962,0.69630,3.000
3,21.812,0.00,0.8213,0.82140,3.000
3,21.938,0.01,0.9463,0.94640,3.000
3,22.062,0.00,1.0713,1.07138,3.000
3,22.188,0.01,1.1963,1.19642,3.000
3,22.312,0.01,1.3212,1.32133,3.000
3,22.438,0.00,1.4462,1.44627,3.000
3,22.562,0.00,1.5712,1.57130,3.000
3,22.688,0.01,1.6963,1.69640,3.000
3,22.812,0.00,1.8214,1.82148,3.000
3,22.938,0.02,1.9464,1.94647,3.000
3,23.062,0.05,2.0714,2.07145,3.000
3,23.188,0.08,2.1962,2.19635,3.000
3,23.312,0.14,2.3212,2.32133,3.000
3,23.438,0.23,2.4462,2.44632,3.000
3,23.562,0.40,2.5712,2.57125,3.000
3,23.688,0.67,2.6964,2.69647,3.000
3,23.812,1.03,2.8214,2.82150,3.000
3,23.938,1.50,2.9464,2.94652,3.000
3,24.062,2.09,3.0714,3.07155,3.000
3,24.188,2.83,3.1964,3.19650,3.000
3,24.312,3.73,3.3214,3.32147,3.000
3,24.438,4.81,3.4463,3.44640,3.000
3,24.625,4.75,3.4444,3.44455,3.000
3,24.750,3.45,3.3196,3.31970,3.000
3,24.875,2.49,3.1946,3.19470,3.000
3,25.000,1.76,3.0697,3.06980,3.000
3,25.125,1.20,2.9446,2.94465,3.000
3,25.250,0.78,2.8196,2.81970,3.000
3,25.375,0.48,2.6946,2.69470,3.000
3,25.500,0.27,2.5694,2.56950,3.000
3,25.625,0.14,2.4445,2.44460,3.000
3,25.750,0.07,2.3195,2.31960,3.000
3,25.875,0.04,2.1945,2.19455,3.000
3,26.000,0.02,2.0694,2.06950,3.000
3,26.125,0.01,1.9445,1.94460,3.000
3,26.250,0.01,1.8195,1.81960,3.000
3,26.375,0.00,1.6944,1.69450,3.000
3,26.500,0.00,1.5693,1.56940,3.000
3,26.625,0.00,1.4444,1.44445,3.000
3,26.750,0.01,1.3194,1.31950,3.000
3,26.875,0.00,1.1944,1.19455,3.000
3,27.000,0.00,1.0694,1.06950,3.000
3,27.125,0.00,0.9445,0.94460,3.000
3,27.250,0.01,0.8195,0.81960,3.000
3,27.375,0.00,0.6944,0.69445,3.000
3,27.500,0.00,0.5693,0.56940,3.000
3,27.625,0.00,0.4442,0.44435,3.000
3,27.750,0.00,0.3193,0.31940,3.000
3,27.875,0.00,0.1944,0.19445,3.000
3,28.000,0.00,0.0691,0.06920,3.000
3,28.188,0.00,-0.0232,-0.02313,3.000
3,28.312,0.00,-0.0003,-0.00020,3.000
3,28.438,0.01,-0.0003,-0.00020,3.000
3,28.562,0.00,-0.0003,-0.00020,3.000
3,28.688,0.01,-0.0003,-0.00020,3.000
3,28.812,0.01,-0.0003,-0.00020,3.000
3,28.938,0.01,-0.0003,-0.00020,3.000
3,29.062,0.01,-0.0003,-0.00020,3.000
3,29.188,0.01,-0.0003,-0.00020,3.000
3,29.312,0.01,-0.0003,-0.00020,3.000
3,29.438,0.00,-0.0003,-0.00020,3.000
3,29.562,0.01,-0.0003,-0.00020,3.000
3,29.688,0.00,-0.0003,-0.00020,3.000
3,29.812,0.01,-0.0003,-0.00020,3.000
3,29.938,0.01,-0.0003,-0.00020,3.000
3,30.062,0.01,-0.0003,-0.00020,3.000
3,30.188,0.01,-0.0003,-0.00020,3.000
3,30.312,0.00,-0.0003,-0.00020,3.000
3,30.438,0.01,-0.0002,-0.00010,3.000
3,30.562,0.00,-0.0002,-0.00010,3.000
3,30.688,0.00,-0.0002,-0.00010,3.000
3,30.812,0.00,-0.0002,-0.00010,3.000
3,30.938,0.01,-0.0002,-0.00010,3.000
3,31.062,0.01,-0.0002,-0.00010,3.000
4,31.438,0.00,0.0550,0.05510,4.000
4,31.562,0.00,0.1803,0.18037,4.000
4,31.688,0.00,0.3053,0.30545,4.000
4,31.812,0.00,0.4302,0.43035,4.000
4,31.938,0.00,0.5551,0.55522,4.000
4,32.062,0.00,0.6802,0.68030,4.000
4,32.188,0.00,0.8052,0.80528,4.000
4,32.312,-0.01,0.9303,0.93037,4.000
4,32.438,-0.01,1.0553,1.05538,4.000
4,32.562,0.00,1.1804,1.18050,4.000
4,32.688,0.01,1.3053,1.30543,4.000
4,32.812,0.00,1.4303,1.43037,4.000
4,32.938,0.00,1.5553,1.55535,4.000
4,33.062,0.00,1.6802,1.68032,4.000
4,33.188,0.00,1.8052,1.80530,4.000
4,33.312,0.01,1.9302,1.93035,4.000
4,33.438,0.04,2.0553,2.05538,4.000
4,33.562,0.07,2.1802,2.18035,4.000
4,33.688,0.12,2.3054,2.30548,4.000
4,33.812,0.21,2.4303,2.43042,4.000
4,33.938,0.37,2.5553,2.55535,4.000
4,34.062,0.63,2.6804,2.68047,4.000
4,34.188,0.97,2.8053,2.80543,4.000
4,34.312,1.43,2.9302,2.93035,4.000
4,34.438,2.01,3.0553,3.05540,4.000
4,34.562,2.72,3.1804,3.18050,4.000
4,34.688,3.60,3.3055,3.30558,4.000
4,34.812,4.65,3.4304,3.43052,4.000
4,35.000,4.68,3.4384,3.43850,4.000
4,35.125,3.40,3.3137,3.31380,4.000
4,35.250,2.45,3.1887,3.18880,4.000
4,35.375,1.73,3.0636,3.06370,4.000
4,35.500,1.18,2.9385,2.93860,4.000
4,35.625,0.77,2.8136,2.81365,4.000
4,35.750,0.46,2.6885,2.68860,4.000
4,35.875,0.26,2.5634,2.56350,4.000
4,36.000,0.13,2.4386,2.43870,4.000
4,36.125,0.07,2.3135,2.31360,4.000
4,36.250,0.03,2.1886,2.18870,4.000
4,36.375,0.02,2.0635,2.06360,4.000
4,36.500,0.01,1.9385,1.93860,4.000
4,36.625,0.00,1.8135,1.81360,4.000
4,36.750,0.01,1.6884,1.68850,4.000
4,36.875,0.00,1.5634,1.56345,4.000
4,37.000,0.00,1.4384,1.43850,4.000
4,37.125,0.00,1.3134,1.31355,4.000
4,37.250,0.00,1.1885,1.18860,4.000
4,37.375,0.01,1.0635,1.06360,4.000
4,37.500,0.01,0.9384,0.93850,4.000
4,37.625,0.00,0.8134,0.81350,4.000
4,37.750,0.00,0.6883,0.68840,4.000
4,37.875,0.00,0.5632,0.56335,4.000
4,38.000,0.01,0.4383,0.43840,4.000
4,38.125,0.01,0.3134,0.31350,4.000
4,38.250,0.00,0.1884,0.18850,4.000
4,38.375,0.00,0.0632,0.06335,4.000
4,38.562,0.00,-0.0051,-0.00500,4.000
4,38.688,0.00,-0.0003,-0.00020,4.000
4,38.812,0.00,-0.0003,-0.00020,4.000
4,38.938,0.00,-0.0003,-0.00020,4.000
4,39.062,0.00,-0.0003,-0.00020,4.000
4,39.188,0.00,-0.0003,-0.00020,4.000
4,39.312,0.00,-0.0003,-0.00020,4.000
4,39.438,0.00,-0.0003,-0.00020,4.000
4,39.562,0.00,-0.0003,-0.00020,4.000
4,39.688,0.00,-0.0003,-0.00020,4.000
4,39.812,0.00,-0.0003,-0.00020,4.000
4,39.938,0.00,-0.0003,-0.00020,4.000
4,40.062,0.00,-0.0003,-0.00020,4.000
4,40.188,0.00,-0.0003,-0.00020,4.000
4,40.312,0.00,-0.0003,-0.00020,4.000
4,40.438,0.00,-0.0003,-0.00020,4.000
4,40.562,0.00,-0.0002,-0.00010,4.000
4,40.688,0.00,-0.0002,-0.00010,4.000
4,40.812,0.00,-0.0002,-0.00010,4.000
4,40.938,0.00,-0.0002,-0.00010,4.000
4,41.062,0.00,-0.0002,-0.00010,4.000
4,41.188,0.00,-0.0002,-0.00010,4.000
4,41.312,0.00,-0.0002,-0.00010,4.000
4,41.438,0.00,-0.0002,-0.00010,4.000
5,41.812,0.00,0.0610,0.06112,5.000
5,41.938,0.00,0.1863,0.18638,5.000
5,42.062,0.00,0.3113,0.31142,5.000
5,42.188,0.00,0.4362,0.43625,5.000
5,42.312,0.00,0.5611,0.56125,5.000
5,42.438,0.00,0.6861,0.68620,5.000
5,42.562,0.00,0.8112,0.81130,5.000
5,42.688,0.01,0.9362,0.93630,5.000
5,42.812,0.00,1.0613,1.06142,5.000
5,42.938,0.01,1.1864,1.18650,5.000
5,43.062,0.00,1.3113,1.31140,5.000
5,43.188,0.00,1.4362,1.43633,5.000
5,43.312,0.00,1.5612,1.56130,5.000
5,43.438,0.00,1.6863,1.68638,5.000
5,43.562,0.00,1.8112,1.81135,5.000
5,43.688,0.02,1.9363,1.93643,5.000
5,43.812,0.05,2.0613,2.06142,5.000
5,43.938,0.08,2.1864,2.18645,5.000
5,44.062,0.13,2.3113,2.31140,5.000
5,44.188,0.22,2.4363,2.43643,5.000
5,44.312,0.39,2.5612,2.56130,5.000
5,44.438,0.65,2.6864,2.68645,5.000
5,44.562,1.00,2.8112,2.81135,5.000
5,44.688,1.45,2.9363,2.93640,5.000
5,44.812,2.04,3.0614,3.06150,5.000
5,44.938,2.76,3.1864,3.18648,5.000
5,45.062,3.65,3.3115,3.31157,5.000
5,45.188,4.70,3.4364,3.43650,5.000
5,45.375,4.63,3.4346,3.43470,5.000
5,45.500,3.37,3.3097,3.30980,5.000
5,45.625,2.43,3.1846,3.18465,5.000
5,45.750,1.71,3.0595,3.05960,5.000
5,45.875,1.17,2.9345,2.93460,5.000
5,46.000,0.77,2.8094,2.80950,5.000
5,46.125,0.46,2.6846,2.68470,5.000
5,46.250,0.26,2.5594,2.55950,5.000
5,46.375,0.14,2.4345,2.43465,5.000
5,46.500,0.07,2.3096,2.30970,5.000
5,46.625,0.04,2.1845,2.18465,5.000
5,46.750,0.02,2.0594,2.05950,5.000
5,46.875,0.00,1.9344,1.93455,5.000
5,47.000,0.00,1.8095,1.80960,5.000
5,47.125,0.01,1.6844,1.68450,5.000
5,47.250,0.00,1.5594,1.55950,5.000
5,47.375,0.00,1.4344,1.43450,5.000
5,47.500,0.00,1.3096,1.30970,5.000
5,47.625,0.00,1.1846,1.18465,5.000
5,47.750,0.00,1.0595,1.05960,5.000
5,47.875,0.00,0.9345,0.93455,5.000
5,48.000,0.00,0.8093,0.80940,5.000
5,48.125,0.00,0.6843,0.68440,5.000
5,48.250,0.00,0.5593,0.55940,5.000
5,48.375,0.00,0.4343,0.43440,5.000
5,48.500,0.01,0.3095,0.30960,5.000
5,48.625,0.00,0.1845,0.18455,5.000
5,48.750,0.00,0.0592,0.05930,5.000
5,48.938,0.01,-0.0023,-0.00225,5.000
5,49.062,0.00,-0.0003,-0.00020,5.000
5,49.188,0.00,-0.0003,-0.00020,5.000
5,49.312,0.00,-0.0003,-0.00020,5.000
5,49.438,0.00,-0.0003,-0.00020,5.000
5,49.562,0.00,-0.0003,-0.00020,5.000
5,49.688,0.00,-0.0003,-0.00020,5.000
5,49.812,0.00,-0.0003,-0.00020,5.000
5,49.938,0.00,-0.0003,-0.00020,5.000
5,50.062,0.00,-0.0003,-0.00020,5.000
5,50.188,0.00,-0.0003,-0.00020,5.000
5,50.312,0.00,-0.0003,-0.00020,5.000
5,50.438,0.00,-0.0003,-0.00020,5.000
5,50.562,0.01,-0.0003,-0.00018,5.000
5,50.688,0.00,-0.0002,-0.00010,5.000
5,50.812,0.01,-0.0002,-0.00010,5.000
5,50.938,0.00,-0.0002,-0.00010,5.000
5,51.062,0.00,-0.0002,-0.00010,5.000
5,51.188,0.00,-0.0002,-0.00010,5.000
5,51.312,0.01,-0.0002,-0.00010,5.000
5,51.438,0.00,-0.0002,-0.00010,5.000
5,51.562,0.00,-0.0002,-0.00010,5.000
5,51.688,0.00,-0.0002,-0.00010,5.000
5,51.812,0.00,-0.0002,-0.00010,5.000
6,52.188,-0.01,0.0701,0.07015,6.000
6,52.312,-0.01,0.1953,0.19542,6.000
6,52.438,-0.01,0.3202,0.32025,6.000
6,52.562,0.00,0.4451,0.44517,6.000
6,52.688,-0.01,0.5701,0.57020,6.000
6,52.812,-0.01,0.6952,0.69530,6.000
6,52.938,-0.01,0.8203,0.82038,6.000
6,53.062,-0.02,0.9452,0.94535,6.000
6,53.188,-0.01,1.0704,1.07048,6.000
6,53.312,-0.01,1.1954,1.19555,6.000
6,53.438,0.00,1.3203,1.32035,6.000
6,53.562,-0.02,1.4452,1.44530,6.000
6,53.688,0.00,1.5703,1.57035,6.000
6,53.812,-0.01,1.6953,1.69540,6.000
6,53.938,-0.01,1.8204,1.82045,6.000
6,54.062,-0.01,1.9454,1.94547,6.000
6,54.188,0.03,2.0704,2.07045,6.000
6,54.312,0.06,2.1954,2.19552,6.000
6,54.438,0.11,2.3203,2.32040,6.000
6,54.562,0.22,2.4453,2.44540,6.000
6,54.688,0.39,2.5703,2.57038,6.000
6,54.812,0.65,2.6954,2.69550,6.000
6,54.938,1.01,2.8204,2.82045,6.000
6,55.062,1.48,2.9454,2.94550,6.000
6,55.188,2.08,3.0705,3.07055,6.000
6,55.312,2.81,3.1954,3.19555,6.000
6,55.438,3.71,3.3204,3.32050,6.000
6,55.562,4.79,3.4453,3.44540,6.000
6,55.750,4.62,3.4336,3.43370,6.000
6,55.875,3.35,3.3087,3.30880,6.000
6,56.000,2.41,3.1835,3.18360,6.000
6,56.125,1.70,3.0586,3.05865,6.000
6,56.250,1.15,2.9334,2.93350,6.000
6,56.375,0.74,2.8085,2.80860,6.000
6,56.500,0.44,2.6836,2.68370,6.000
6,56.625,0.24,2.5585,2.55855,6.000
6,56.750,0.12,2.4336,2.43370,6.000
6,56.875,0.06,2.3086,2.30865,6.000
6,57.000,0.02,2.1835,2.18360,6.000
6,57.125,0.01,2.0584,2.05850,6.000
6,57.250,-0.01,1.9334,1.93350,6.000
6,57.375,-0.01,1.8084,1.80850,6.000
6,57.500,-0.01,1.6834,1.68350,6.000
6,57.625,-0.01,1.5584,1.55850,6.000
6,57.750,-0.01,1.4334,1.43350,6.000
6,57.875,-0.01,1.3085,1.30860,6.000
6,58.000,-0.01,1.1836,1.18370,6.000
6,58.125,-0.01,1.0585,1.05860,6.000
6,58.250,-0.01,0.9333,0.93340,6.000
6,58.375,-0.01,0.8084,0.80845,6.000
6,58.500,0.00,0.6832,0.68330,6.000
6,58.625,0.00,0.5583,0.55840,6.000
6,58.750,-0.01,0.4334,0.43350,6.000
6,58.875,-0.01,0.3084,0.30850,6.000
6,59.000,-0.02,0.1834,0.18350,6.000
6,59.125,-0.01,0.0582,0.05830,6.000
6,59.312,0.00,-0.0083,-0.00823,6.000
6,59.438,-0.01,-0.0003,-0.00020,6.000
6,59.562,-0.01,-0.0003,-0.00020,6.000
6,59.688,0.00,-0.0003,-0.00020,6.000
6,59.812,-0.02,-0.0003,-0.00020,6.000
6,59.938,0.00,-0.0003,-0.00020,6.000
6,60.062,-0.01,-0.0003,-0.00020,6.000
6,60.188,0.00,-0.0003,-0.00020,6.000
6,60.312,-0.01,-0.0003,-0.00020,6.000
6,60.438,-0.01,-0.0003,-0.00020,6.000
6,60.562,-0.01,-0.0002,-0.00010,6.000
6,60.688,-0.02,-0.0002,-0.00010,6.000
6,60.812,-0.02,-0.0002,-0.00010,6.000
6,60.938,-0.01,-0.0002,-0.00010,6.000
6,61.062,-0.01,-0.0002,-0.00010,6.000
6,61.188,-0.01,-0.0002,-0.00010,6.000
6,61.312,-0.02,-0.0002,-0.00010,6.000
6,61.438,-0.01,-0.0002,-0.00010,6.000
6,61.562,-0.01,-0.0002,-0.00010,6.000
6,61.688,-0.02,-0.0002,-0.00010,6.000
6,61.812,-0.01,-0.0002,-0.00010,6.000
6,61.938,-0.01,-0.0002,-0.00010,6.000
6,62.062,-0.01,-0.0002,-0.00010,6.000
6,62.188,-0.01,-0.0002,-0.00010,6.000
7,62.562,0.01,0.0610,0.06112,7.000
7,62.688,0.00,0.1863,0.18637,7.000
7,62.812,0.01,0.3113,0.31142,7.000
7,62.938,0.01,0.4361,0.43625,7.000
7,63.062,0.01,0.5611,0.56120,7.000
7,63.188,0.01,0.6862,0.68627,7.000
7,63.312,0.01,0.8112,0.81132,7.000
7,63.438,0.00,0.9362,0.93627,7.000
7,63.562,0.01,1.0612,1.06135,7.000
7,63.688,0.01,1.1864,1.18647,7.000
7,63.812,0.01,1.3113,1.31142,7.000
7,63.938,0.01,1.4362,1.43632,7.000
7,64.062,0.02,1.5612,1.56130,7.000
7,64.188,0.02,1.6862,1.68630,7.000
7,64.312,0.01,1.8112,1.81132,7.000
7,64.438,0.02,1.9363,1.93638,7.000
7,64.562,0.05,2.0613,2.06140,7.000
7,64.688,0.07,2.1863,2.18640,7.000
7,64.812,0.14,2.3114,2.31147,7.000
7,64.938,0.22,2.4364,2.43650,7.000
7,65.062,0.39,2.5612,2.56135,7.000
7,65.188,0.64,2.6864,2.68645,7.000
7,65.312,1.00,2.8113,2.81137,7.000
7,65.438,1.46,2.9363,2.93638,7.000
7,65.562,2.04,3.0613,3.06142,7.000
7,65.688,2.77,3.1864,3.18648,7.000
7,65.812,3.66,3.3114,3.31150,7.000
7,65.938,4.72,3.4364,3.43650,7.000
7,66.062,5.62,3.5130,3.51308,7.000
7,66.188,4.15,3.3922,3.39228,7.000
7,66.312,3.02,3.2671,3.26720,7.000
7,66.438,2.17,3.1420,3.14215,7.000
7,66.562,1.51,3.0169,3.01703,7.000
7,66.688,1.03,2.8920,2.89208,7.000
7,66.812,0.66,2.7670,2.76713,7.000
7,66.938,0.38,2.6420,2.64210,7.000
7,67.062,0.21,2.5170,2.51710,7.000
7,67.188,0.10,2.3920,2.39212,7.000
7,67.312,0.06,2.2670,2.26708,7.000
7,67.438,0.04,2.1420,2.14205,7.000
7,67.562,0.02,2.0169,2.01695,7.000
7,67.688,0.01,1.8919,1.89195,7.000
7,67.812,0.00,1.7669,1.76695,7.000
7,67.938,0.00,1.6419,1.64202,7.000
7,68.062,0.01,1.5169,1.51703,7.000
7,68.188,0.00,1.3919,1.39198,7.000
7,68.312,0.02,1.2670,1.26713,7.000
7,68.438,0.01,1.1420,1.14212,7.000
7,68.562,0.00,1.0170,1.01708,7.000
7,68.688,0.01,0.8918,0.89193,7.000
7,68.812,0.00,0.7668,0.76690,7.000
7,68.938,0.01,0.6418,0.64188,7.000
7,69.062,0.00,0.5169,0.51700,7.000
7,69.188,0.01,0.3918,0.39192,7.000
7,69.312,0.01,0.2670,0.26710,7.000
7,69.438,0.01,0.1419,0.14198,7.000
7,69.562,0.01,0.0168,0.01685,7.000
7,69.750,0.00,-0.0004,-0.00030,7.000
7,69.875,0.01,-0.0003,-0.00020,7.000
7,70.000,0.01,-0.0003,-0.00020,7.000
7,70.125,0.01,-0.0003,-0.00020,7.000
7,70.250,0.01,-0.0003,-0.00020,7.000
7,70.375,0.01,-0.0003,-0.00020,7.000
7,70.500,0.01,-0.0003,-0.00020,7.000
7,70.625,0.01,-0.0003,-0.00020,7.000
7,70.750,0.01,-0.0003,-0.00020,7.000
7,70.875,0.00,-0.0003,-0.00020,7.000
7,71.000,0.01,-0.0003,-0.00020,7.000
7,71.125,0.01,-0.0003,-0.00020,7.000
7,71.250,0.01,-0.0003,-0.00020,7.000
7,71.375,0.01,-0.0003,-0.00020,7.000
7,71.500,0.01,-0.0003,-0.00020,7.000
7,71.625,0.00,-0.0002,-0.00010,7.000
7,71.750,0.01,-0.0002,-0.00010,7.000
7,71.875,0.01,-0.0002,-0.00010,7.000
7,72.000,0.01,-0.0002,-0.00010,7.000
7,72.125,0.00,-0.0002,-0.00010,7.000
7,72.250,0.01,-0.0002,-0.00010,7.000
7,72.375,0.01,-0.0002,-0.00010,7.000
7,72.500,0.00,-0.0002,-0.00010,7.000
7,72.625,0.00,-0.0002,-0.00010,7.000
8,73.000,0.00,0.1325,0.13260,8.000
8,73.125,0.00,0.2577,0.25780,8.000
8,73.250,0.02,0.3827,0.38280,8.000
8,73.375,0.00,0.5077,0.50780,8.000
8,73.500,0.00,0.6327,0.63280,8.000
8,73.625,0.00,0.7577,0.75780,8.000
8,73.750,0.00,0.8827,0.88280,8.000
8,73.875,0.01,1.0078,1.00785,8.000
8,74.000,0.00,1.1327,1.13280,8.000
8,74.125,0.00,1.2579,1.25795,8.000
8,74.250,0.00,1.3827,1.38280,8.000
8,74.375,0.00,1.5078,1.50790,8.000
8,74.500,0.00,1.6328,1.63290,8.000
8,74.625,0.00,1.7578,1.75785,8.000
8,74.750,0.02,1.8827,1.88280,8.000
8,74.875,0.03,2.0078,2.00785,8.000
8,75.000,0.05,2.1326,2.13270,8.000
8,75.125,0.10,2.2577,2.25785,8.000
8,75.250,0.18,2.3828,2.38290,8.000
8,75.375,0.30,2.5078,2.50790,8.000
8,75.500,0.53,2.6329,2.63300,8.000
8,75.625,0.82,2.7580,2.75805,8.000
8,75.750,1.23,2.8829,2.88300,8.000
8,75.875,1.76,3.0079,3.00795,8.000
8,76.000,2.43,3.1327,3.13280,8.000
8,76.125,3.24,3.2579,3.25795,8.000
8,76.250,4.24,3.3829,3.38300,8.000
8,76.438,5.63,3.5139,3.51402,8.000
8,76.562,4.12,3.3913,3.39135,8.000
8,76.688,3.00,3.2661,3.26620,8.000
8,76.812,2.14,3.1411,3.14118,8.000
8,76.938,1.50,3.0160,3.01605,8.000
8,77.062,1.01,2.8910,2.89110,8.000
8,77.188,0.64,2.7662,2.76625,8.000
8,77.312,0.37,2.6411,2.64118,8.000
8,77.438,0.20,2.5161,2.51618,8.000
8,77.562,0.10,2.3911,2.39120,8.000
8,77.688,0.05,2.2660,2.26610,8.000
8,77.812,0.03,2.1410,2.14110,8.000
8,77.938,0.02,2.0159,2.01595,8.000
8,78.062,0.01,1.8908,1.89088,8.000
8,78.188,0.00,1.7660,1.76605,8.000
8,78.312,0.00,1.6409,1.64103,8.000
8,78.438,0.00,1.5159,1.51603,8.000
8,78.562,0.00,1.3910,1.39108,8.000
8,78.688,0.01,1.2661,1.26618,8.000
8,78.812,0.00,1.1410,1.14113,8.000
8,78.938,0.00,1.0159,1.01598,8.000
8,79.062,0.00,0.8908,0.89093,8.000
8,79.188,0.00,0.7658,0.76590,8.000
8,79.312,0.00,0.6408,0.64093,8.000
8,79.438,0.00,0.5159,0.51603,8.000
8,79.562,0.00,0.3909,0.39100,8.000
8,79.688,0.00,0.2660,0.26610,8.000
8,79.812,0.01,0.1409,0.14095,8.000
8,79.938,0.00,0.0157,0.01582,8.000
8,80.125,0.00,0.0003,0.00040,8.000
8,80.250,0.00,-0.0003,-0.00020,8.000
8,80.375,0.00,-0.0003,-0.00020,8.000
8,80.500,0.00,-0.0003,-0.00020,8.000
8,80.625,0.00,-0.0003,-0.00020,8.000
8,80.750,0.00,-0.0003,-0.00020,8.000
8,80.875,0.00,-0.0003,-0.00020,8.000
8,81.000,-0.01,-0.0003,-0.00020,8.000
8,81.125,0.00,-0.0003,-0.00020,8.000
8,81.250,0.01,-0.0003,-0.00020,8.000
8,81.375,0.00,-0.0002,-0.00010,8.000
8,81.500,0.01,-0.0002,-0.00010,8.000
8,81.625,0.00,-0.0002,-0.00010,8.000
8,81.750,0.00,-0.0002,-0.00010,8.000
8,81.875,0.01,-0.0002,-0.00010,8.000
8,82.000,0.01,-0.0002,-0.00010,8.000
8,82.125,0.00,-0.0002,-0.00010,8.000
8,82.250,0.01,-0.0002,-0.00010,8.000
8,82.375,0.00,-0.0002,-0.00010,8.000
8,82.500,0.00,-0.0002,-0.00010,8.000
8,82.625,0.01,-0.0002,-0.00010,8.000
8,82.750,0.00,-0.0002,-0.00010,8.000
8,82.875,0.01,-0.0002,-0.00010,8.000
8,83.000,0.00,-0.0002,-0.00010,8.000
9,83.312,-0.01,0.0540,0.05407,9.000
9,83.438,0.00,0.1792,0.17932,9.000
9,83.562,-0.01,0.3042,0.30432,9.000
9,83.688,-0.01,0.4292,0.42932,9.000
9,83.812,0.00,0.5542,0.55430,9.000
9,83.938,0.00,0.6792,0.67925,9.000
9,84.062,0.00,0.8041,0.80422,9.000
9,84.188,0.00,0.9292,0.92930,9.000
9,84.312,-0.01,1.0542,1.05435,9.000
9,84.438,0.01,1.1793,1.17942,9.000
9,84.562,0.00,1.3043,1.30442,9.000
9,84.688,-0.01,1.4293,1.42940,9.000
9,84.812,0.00,1.5543,1.55445,9.000
9,84.938,0.00,1.6792,1.67935,9.000
9,85.062,-0.01,1.8042,1.80430,9.000
9,85.188,0.00,1.9292,1.92930,9.000
9,85.312,0.04,2.0541,2.05422,9.000
9,85.438,0.07,2.1792,2.17928,9.000
9,85.562,0.12,2.3042,2.30435,9.000
9,85.688,0.22,2.4294,2.42948,9.000
9,85.812,0.37,2.5543,2.55440,9.000
9,85.938,0.61,2.6795,2.67958,9.000
9,86.062,0.96,2.8044,2.80447,9.000
9,86.188,1.42,2.9292,2.92935,9.000
9,86.312,1.99,3.0542,3.05432,9.000
9,86.438,2.72,3.1792,3.17933,9.000
9,86.562,3.59,3.3044,3.30450,9.000
9,86.688,4.65,3.4293,3.42942,9.000
9,86.875,5.04,3.4695,3.46960,9.000
9,87.000,3.66,3.3447,3.34480,9.000
9,87.125,2.65,3.2195,3.21960,9.000
9,87.250,1.88,3.0945,3.09460,9.000
9,87.375,1.29,2.9695,2.96960,9.000
9,87.500,0.84,2.8446,2.84470,9.000
9,87.625,0.52,2.7196,2.71975,9.000
9,87.750,0.30,2.5946,2.59470,9.000
9,87.875,0.15,2.4696,2.46965,9.000
9,88.000,0.07,2.3445,2.34460,9.000
9,88.125,0.04,2.2194,2.21950,9.000
9,88.250,0.02,2.0943,2.09440,9.000
9,88.375,0.01,1.9694,1.96945,9.000
9,88.500,-0.01,1.8445,1.84460,9.000
9,88.625,0.00,1.7194,1.71955,9.000
9,88.750,0.00,1.5944,1.59450,9.000
9,88.875,0.00,1.4694,1.46955,9.000
9,89.000,0.01,1.3444,1.34450,9.000
9,89.125,0.00,1.2195,1.21960,9.000
9,89.250,0.00,1.0944,1.09450,9.000
9,89.375,0.00,0.9693,0.96940,9.000
9,89.500,0.01,0.8444,0.84450,9.000
9,89.625,0.01,0.7193,0.71940,9.000
9,89.750,0.00,0.5944,0.59450,9.000
9,89.875,0.00,0.4694,0.46955,9.000
9,90.000,0.00,0.3445,0.34460,9.000
9,90.125,0.00,0.2195,0.21960,9.000
9,90.250,0.00,0.0941,0.09420,9.000
9,90.500,-0.02,-0.0024,-0.00230,9.000
9,90.625,0.00,-0.0003,-0.00020,9.000
9,90.750,0.00,-0.0003,-0.00020,9.000
9,90.875,0.00,-0.0003,-0.00020,9.000
9,91.000,0.00,-0.0003,-0.00020,9.000
9,91.125,0.00,-0.0003,-0.00020,9.000
9,91.250,-0.01,-0.0003,-0.00020,9.000
9,91.375,0.00,-0.0003,-0.00020,9.000
9,91.500,0.00,-0.0003,-0.00020,9.000
9,91.625,-0.02,-0.0003,-0.00020,9.000
9,91.750,0.00,-0.0003,-0.00020,9.000
9,91.875,0.00,-0.0003,-0.00020,9.000
9,92.000,0.00,-0.0003,-0.00020,9.000
9,92.125,-0.01,-0.0002,-0.00010,9.000
9,92.250,0.00,-0.0002,-0.00010,9.000
9,92.375,0.01,-0.0002,-0.00010,9.000
9,92.500,0.01,-0.0002,-0.00010,9.000
9,92.625,0.00,-0.0002,-0.00010,9.000
9,92.750,0.00,-0.0002,-0.00010,9.000
9,92.875,0.00,-0.0002,-0.00010,9.000
9,93.000,0.00,-0.0002,-0.00010,9.000
9,93.125,0.00,-0.0002,-0.00010,9.000
9,93.250,0.01,-0.0002,-0.00010,9.000
9,93.375,0.00,-0.0002,-0.00010,9.000
10,93.688,0.01,0.0490,0.04910,10.000
10,93.812,0.01,0.1741,0.17420,10.000
10,93.938,0.01,0.2992,0.29930,10.000
10,94.062,0.01,0.4243,0.42437,10.000
10,94.188,0.00,0.5492,0.54930,10.000
10,94.312,0.00,0.6742,0.67432,10.000
10,94.438,0.00,0.7992,0.79933,10.000
10,94.562,0.01,0.9242,0.92430,10.000
10,94.688,0.00,1.0492,1.04925,10.000
10,94.812,0.01,1.1742,1.17427,10.000
10,94.938,0.00,1.2993,1.29938,10.000
10,95.062,0.01,1.4242,1.42432,10.000
10,95.188,0.00,1.5493,1.54940,10.000
10,95.312,0.01,1.6743,1.67440,10.000
10,95.438,0.00,1.7993,1.79942,10.000
10,95.562,0.02,1.9243,1.92437,10.000
10,95.688,0.04,2.0492,2.04930,10.000
10,95.812,0.08,2.1741,2.17425,10.000
10,95.938,0.12,2.2992,2.29928,10.000
10,96.062,0.21,2.4244,2.42447,10.000
10,96.188,0.37,2.5493,2.54940,10.000
10,96.312,0.60,2.6744,2.67452,10.000
10,96.438,0.95,2.7995,2.79958,10.000
10,96.562,1.40,2.9244,2.92452,10.000
10,96.688,1.97,3.0492,3.04935,10.000
10,96.812,2.67,3.1742,3.17432,10.000
10,96.938,3.56,3.2994,3.29945,10.000
10,97.062,4.59,3.4244,3.42447,10.000
10,97.250,5.08,3.4724,3.47250,10.000
10,97.375,3.69,3.3476,3.34770,10.000
10,97.500,2.67,3.2225,3.22260,10.000
10,97.625,1.90,3.0975,3.09760,10.000
10,97.750,1.32,2.9724,2.97250,10.000
10,97.875,0.87,2.8475,2.84760,10.000
10,98.000,0.52,2.7225,2.72260,10.000
10,98.125,0.31,2.5975,2.59760,10.000
10,98.250,0.17,2.4726,2.47270,10.000
10,98.375,0.07,2.3476,2.34770,10.000
10,98.500,0.05,2.2225,2.22260,10.000
10,98.625,0.03,2.0975,2.09755,10.000
10,98.750,0.01,1.9723,1.97240,10.000
10,98.875,0.00,1.8474,1.84755,10.000
10,99.000,0.00,1.7225,1.72260,10.000
10,99.125,0.01,1.5974,1.59755,10.000
10,99.250,0.01,1.4725,1.47260,10.000
10,99.375,0.01,1.3474,1.34755,10.000
10,99.500,0.01,1.2226,1.22270,10.000
10,99.625,0.00,1.0974,1.09745,10.000
10,99.750,0.00,0.9724,0.97250,10.000
10,99.875,0.00,0.8474,0.84745,10.000
10,100.000,0.01,0.7224,0.72250,10.000
10,100.125,0.00,0.5973,0.59740,10.000
10,100.250,0.01,0.4723,0.47240,10.000
10,100.375,0.01,0.3474,0.34750,10.000
10,100.500,0.00,0.2225,0.22260,10.000
10,100.625,0.00,0.0972,0.09730,10.000
10,100.750,0.00,-0.0278,-0.02770,10.000
10,100.938,0.00,-0.0003,-0.00020,10.000
10,101.062,0.00,-0.0003,-0.00020,10.000
10,101.188,0.01,-0.0003,-0.00020,10.000
10,101.312,0.00,-0.0003,-0.00020,10.000
10,101.438,0.00,-0.0003,-0.00020,10.000
10,101.562,0.01,-0.0003,-0.00020,10.000
10,101.688,0.00,-0.0003,-0.00020,10.000
10,101.812,0.01,-0.0003,-0.00020,10.000
10,101.938,0.01,-0.0003,-0.00020,10.000
10,102.062,0.00,-0.0003,-0.00020,10.000
10,102.188,0.01,-0.0003,-0.00020,10.000
10,102.312,0.01,-0.0003,-0.00020,10.000
10,102.438,0.00,-0.0002,-0.00010,10.000
10,102.562,0.00,-0.0002,-0.00010,10.000
10,102.688,0.00,-0.0002,-0.00010,10.000
10,102.812,0.00,-0.0002,-0.00010,10.000
10,102.938,0.00,-0.0002,-0.00010,10.000
10,103.062,0.00,-0.0002,-0.00010,10.000
10,103.188,0.00,-0.0002,-0.00010,10.000
10,103.312,0.00,-0.0002,-0.00010,10.000
10,103.438,0.01,-0.0002,-0.00010,10.000
10,103.562,0.00,-0.0002,-0.00010,10.000
10,103.688,0.00,-0.0002,-0.00010,10.000
10,103.812,0.00,-0.0002,-0.00010,10.000