File: calibDATA_loadcell/date_30:1:2018/MTSdata_date_1.30/radhen_10cyc_black_2_0deg_1mms_1N.txt
""
"Test Method","Radhen_Load_Cntrl_Cmprsn_250N_12-7.msm"
"Sample I. D.","Sample1.mss"
"Specimen Number","21"

"TheCycle_Output ()","_Time (s)","_Load (N)","_Extension (mm)","RealTimeDepth (mm)","CycleNumber ()"

0,0.180,0.00,0.0000,0.00000,0.000
1,0.300,0.00,0.0516,0.05160,1.000
1,0.410,0.00,0.1615,0.16150,1.000
1,0.520,0.00,0.2718,0.27180,1.000
1,0.630,0.00,0.3818,0.38180,1.000
1,0.740,0.01,0.4916,0.49160,1.000
1,0.850,0.00,0.6016,0.60160,1.000
1,0.960,0.00,0.7118,0.71180,1.000
1,1.070,0.01,0.8218,0.82180,1.000
1,1.180,0.00,0.9317,0.93170,1.000
1,1.290,0.00,1.0418,1.04180,1.000
1,1.400,0.00,1.1517,1.15170,1.000
1,1.510,0.00,1.2618,1.26180,1.000
1,1.620,0.00,1.3716,1.37160,1.000
1,1.730,0.01,1.4817,1.48170,1.000
1,1.840,0.01,1.5919,1.59190,1.000
1,1.950,0.00,1.7017,1.70170,1.000
1,2.060,0.00,1.8117,1.81170,1.000
1,2.170,0.01,1.9219,1.92190,1.000
1,2.280,0.01,2.0318,2.03180,1.000
1,2.390,0.00,2.1418,2.14180,1.000
1,2.500,0.00,2.2517,2.25170,1.000
1,2.610,0.01,2.3618,2.36180,1.000
1,2.720,0.00,2.4718,2.47180,1.000
1,2.830,0.00,2.5818,2.58180,1.000
1,2.940,0.00,2.6917,2.69170,1.000
1,3.050,0.00,2.8019,2.80190,1.000
1,3.160,0.01,2.9118,2.91180,1.000
1,3.270,0.00,3.0218,3.02180,1.000
1,3.380,0.02,3.1318,3.13180,1.000
1,3.490,0.02,3.2419,3.24190,1.000
1,3.600,0.03,3.3519,3.35190,1.000
1,3.710,0.07,3.4618,3.46180,1.000
1,3.820,0.11,3.5719,3.57190,1.000
1,3.930,0.23,3.6820,3.68200,1.000
1,4.040,0.40,3.7920,3.79200,1.000
1,4.150,0.61,3.9018,3.90180,1.000
1,4.260,0.90,4.0119,4.01190,1.000
1,4.390,1.21,4.0929,4.09290,1.000
1,4.500,0.83,3.9865,3.98650,1.000
1,4.610,0.52,3.8766,3.87660,1.000
1,4.720,0.31,3.7667,3.76670,1.000
1,4.830,0.17,3.6565,3.65650,1.000
1,4.940,0.07,3.5465,3.54650,1.000
1,5.050,0.03,3.4367,3.43670,1.000
1,5.160,0.02,3.3266,3.32660,1.000
1,5.270,0.01,3.2165,3.21650,1.000
1,5.380,0.01,3.1066,3.10660,1.000
1,5.490,0.00,2.9966,2.99660,1.000
1,5.600,0.01,2.8865,2.88650,1.000
1,5.710,0.01,2.7764,2.77640,1.000
1,5.820,0.00,2.6666,2.66660,1.000
1,5.930,0.00,2.5565,2.55650,1.000
1,6.040,0.00,2.4465,2.44650,1.000
1,6.150,0.01,2.3363,2.33630,1.000
1,6.260,0.01,2.2265,2.22650,1.000
1,6.370,0.00,2.1165,2.11650,1.000
1,6.480,0.00,2.0065,2.00650,1.000
1,6.590,0.00,1.8963,1.89630,1.000
1,6.700,0.00,1.7864,1.78640,1.000
1,6.810,0.00,1.6764,1.67640,1.000
1,6.920,0.01,1.5664,1.56640,1.000
1,7.030,0.01,1.4563,1.45630,1.000
1,7.140,-0.01,1.3464,1.34640,1.000
1,7.250,0.01,1.2363,1.23630,1.000
1,7.360,0.01,1.1263,1.12630,1.000
1,7.470,0.00,1.0164,1.01640,1.000
1,7.580,0.01,0.9066,0.90660,1.000
1,7.690,0.00,0.7964,0.79640,1.000
1,7.800,0.00,0.6862,0.68620,1.000
1,7.910,0.01,0.5762,0.57620,1.000
1,8.020,0.00,0.4664,0.46640,1.000
1,8.130,0.01,0.3563,0.35630,1.000
1,8.240,0.00,0.2461,0.24610,1.000
1,8.350,0.01,0.1361,0.13610,1.000
1,8.460,0.01,0.0262,0.02620,1.000
1,8.580,0.00,-0.0448,-0.04480,1.000
1,8.690,0.01,-0.0002,-0.00020,1.000
1,8.800,0.00,-0.0002,-0.00020,1.000
1,8.910,0.01,-0.0002,-0.00020,1.000
1,9.020,0.01,-0.0002,-0.00020,1.000
1,9.130,0.01,-0.0002,-0.00020,1.000
1,9.240,0.00,-0.0002,-0.00020,1.000
1,9.350,0.01,-0.0002,-0.00020,1.000
1,9.460,0.00,-0.0002,-0.00020,1.000
1,9.570,0.00,-0.0002,-0.00020,1.000
1,9.680,0.01,-0.0002,-0.00020,1.000
1,9.790,0.00,-0.0002,-0.00020,1.000
1,9.900,0.01,-0.0002,-0.00020,1.000
1,10.010,0.01,-0.0002,-0.00020,1.000
1,10.120,0.01,-0.0002,-0.00020,1.000
1,10.230,0.01,-0.0002,-0.00020,1.000
1,10.340,0.01,-0.0002,-0.00020,1.000
1,10.450,0.01,-0.0002,-0.00020,1.000
1,10.560,0.01,-0.0002,-0.00020,1.000
1,10.670,0.01,-0.0002,-0.00020,1.000
1,10.780,0.01,-0.0002,-0.00020,1.000
1,10.890,0.01,-0.0002,-0.00020,1.000
1,11.000,0.00,-0.0002,-0.00020,1.000
1,11.110,0.01,-0.0002,-0.00020,1.000
1,11.220,0.00,-0.0002,-0.00020,1.000
1,11.330,0.01,-0.0002,-0.00020,1.000
1,11.440,0.01,-0.0002,-0.00020,1.000
1,11.550,0.00,-0.0002,-0.00020,1.000
1,11.680,0.01,-0.0002,-0.00020,1.000
1,11.790,0.00,-0.0002,-0.00020,1.000
1,11.900,0.01,-0.0002,-0.00020,1.000
1,12.010,0.00,-0.0002,-0.00020,1.000
1,12.120,0.00,-0.0001,-0.00010,1.000
1,12.230,0.00,-0.0001,-0.00010,1.000
1,12.340,0.00,-0.0001,-0.00010,1.000
1,12.450,0.01,-0.0001,-0.00010,1.000
1,12.560,0.00,-0.0001,-0.00010,1.000
1,12.670,0.00,-0.0001,-0.00010,1.000
1,12.780,0.00,-0.0001,-0.00010,1.000
1,12.890,0.00,-0.0001,-0.00010,1.000
1,13.000,0.00,-0.0001,-0.00010,1.000
1,13.110,0.01,-0.0001,-0.00010,1.000
1,13.220,0.00,-0.0001,-0.00010,1.000
1,13.330,0.01,-0.0001,-0.00010,1.000
1,13.440,0.00,-0.0001,-0.00010,1.000
1,13.550,0.01,-0.0001,-0.00010,1.000
1,13.660,0.00,-0.0001,-0.00010,1.000
1,13.770,0.00,-0.0001,-0.00010,1.000
1,13.880,0.01,-0.0001,-0.00010,1.000
1,13.990,0.00,-0.0001,-0.00010,1.000
1,14.100,-0.01,-0.0001,-0.00010,1.000
1,14.210,0.00,-0.0001,-0.00010,1.000
1,14.320,0.01,-0.0001,-0.00010,1.000
1,14.430,0.00,-0.0001,-0.00010,1.000
1,14.540,0.00,-0.0001,-0.00010,1.000
2,14.750,0.01,0.0000,0.00000,2.000
2,14.860,0.01,0.0916,0.09160,2.000
2,14.970,0.01,0.2016,0.20160,2.000
2,15.080,0.01,0.3117,0.31170,2.000
2,15.190,0.01,0.4217,0.42170,2.000
2,15.300,0.01,0.5316,0.53160,2.000
2,15.410,0.00,0.6417,0.64170,2.000
2,15.520,0.01,0.7518,0.75180,2.000
2,15.630,0.00,0.8617,0.86170,2.000
2,15.740,0.02,0.9717,0.97170,2.000
2,15.850,0.01,1.0818,1.08180,2.000
2,15.960,0.01,1.1918,1.19180,2.000
2,16.070,0.02,1.3018,1.30180,2.000
2,16.180,0.02,1.4117,1.41170,2.000
2,16.290,-0.01,1.5218,1.52180,2.000
2,16.400,0.00,1.6319,1.63190,2.000
2,16.510,0.01,1.7417,1.74170,2.000
2,16.620,0.00,1.8516,1.85160,2.000
2,16.730,0.01,1.9619,1.96190,2.000
2,16.840,0.01,2.0719,2.07190,2.000
2,16.950,0.00,2.1819,2.18190,2.000
2,17.060,0.01,2.2917,2.29170,2.000
2,17.170,-0.01,2.4019,2.40190,2.000
2,17.280,0.01,2.5119,2.51190,2.000
2,17.390,0.00,2.6218,2.62180,2.000
2,17.500,0.00,2.7318,2.73180,2.000
2,17.610,0.00,2.8419,2.84190,2.000
2,17.720,0.01,2.9519,2.95190,2.000
2,17.830,0.02,3.0618,3.06180,2.000
2,17.940,0.01,3.1717,3.17170,2.000
2,18.050,0.03,3.2819,3.28190,2.000
2,18.160,0.04,3.3920,3.39200,2.000
2,18.270,0.08,3.5017,3.50170,2.000
2,18.380,0.15,3.6118,3.61180,2.000
2,18.490,0.28,3.7219,3.72190,2.000
2,18.600,0.47,3.8320,3.83200,2.000
2,18.710,0.71,3.9418,3.94180,2.000
2,18.820,1.03,4.0519,4.05190,2.000
2,18.950,1.08,4.0565,4.05650,2.000
2,19.060,0.70,3.9466,3.94660,2.000
2,19.170,0.44,3.8367,3.83670,2.000
2,19.280,0.26,3.7265,3.72650,2.000
2,19.390,0.12,3.6165,3.61650,2.000
2,19.500,0.06,3.5065,3.50650,2.000
2,19.610,0.03,3.3966,3.39660,2.000
2,19.720,0.02,3.2865,3.28650,2.000
2,19.830,0.01,3.1764,3.17640,2.000
2,19.940,0.00,3.0666,3.06660,2.000
2,20.050,0.01,2.9567,2.95670,2.000
2,20.160,0.01,2.8466,2.84660,2.000
2,20.270,0.01,2.7364,2.73640,2.000
2,20.380,0.02,2.6265,2.62650,2.000
2,20.490,0.01,2.5165,2.51650,2.000
2,20.600,0.00,2.4065,2.40650,2.000
2,20.710,0.00,2.2963,2.29630,2.000
2,20.820,0.01,2.1865,2.18650,2.000
2,20.930,0.01,2.0766,2.07660,2.000
2,21.040,0.00,1.9665,1.96650,2.000
2,21.150,0.01,1.8563,1.85630,2.000
2,21.260,0.01,1.7465,1.74650,2.000
2,21.370,0.01,1.6366,1.63660,2.000
2,21.480,-0.01,1.5264,1.52640,2.000
2,21.590,0.00,1.4162,1.41620,2.000
2,21.700,0.00,1.3064,1.30640,2.000
2,21.810,0.01,1.1964,1.19640,2.000
2,21.920,0.01,1.0864,1.08640,2.000
2,22.030,0.01,0.9763,0.97630,2.000
2,22.140,0.01,0.8666,0.86660,2.000
2,22.250,0.00,0.7564,0.75640,2.000
2,22.360,0.01,0.6461,0.64610,2.000
2,22.470,0.01,0.5362,0.53620,2.000
2,22.580,0.01,0.4265,0.42650,2.000
2,22.690,0.01,0.3163,0.31630,2.000
2,22.800,0.01,0.2063,0.20630,2.000
2,22.910,0.00,0.0962,0.09620,2.000
2,23.020,0.01,-0.0137,-0.01370,2.000
2,23.140,0.01,-0.0093,-0.00930,2.000
2,23.250,0.01,-0.0002,-0.00020,2.000
2,23.360,0.01,-0.0002,-0.00020,2.000
2,23.470,0.01,-0.0002,-0.00020,2.000
2,23.580,0.00,-0.0002,-0.00020,2.000
2,23.690,0.01,-0.0002,-0.00020,2.000
2,23.800,0.01,-0.0002,-0.00020,2.000
2,23.910,0.00,-0.0002,-0.00020,2.000
2,24.020,0.01,-0.0002,-0.00020,2.000
2,24.130,0.00,-0.0002,-0.00020,2.000
2,24.240,0.01,-0.0002,-0.00020,2.000
2,24.350,0.01,-0.0002,-0.00020,2.000
2,24.460,0.00,-0.0002,-0.00020,2.000
2,24.570,0.01,-0.0002,-0.00020,2.000
2,24.680,0.01,-0.0002,-0.00020,2.000
2,24.790,0.01,-0.0002,-0.00020,2.000
2,24.900,0.01,-0.0002,-0.00020,2.000
2,25.010,0.00,-0.0002,-0.00020,2.000
2,25.120,0.01,-0.0002,-0.00020,2.000
2,25.230,0.01,-0.0002,-0.00020,2.000
2,25.340,0.01,-0.0002,-0.00020,2.000
2,25.450,0.02,-0.0002,-0.00020,2.000
2,25.560,0.02,-0.0002,-0.00020,2.000
2,25.670,0.01,-0.0002,-0.00020,2.000
2,25.780,0.01,-0.0002,-0.00020,2.000
2,25.890,0.00,-0.0002,-0.00020,2.000
2,26.000,0.01,-0.0002,-0.00020,2.000
2,26.120,0.01,-0.0002,-0.00020,2.000
2,26.230,0.01,-0.0002,-0.00020,2.000
2,26.340,0.00,-0.0002,-0.00020,2.000
2,26.450,0.02,-0.0001,-0.00010,2.000
2,26.560,0.01,-0.0001,-0.00010,2.000
2,26.670,0.01,-0.0001,-0.00010,2.000
2,26.780,-0.01,-0.0001,-0.00010,2.000
2,26.890,0.00,-0.0001,-0.00010,2.000
2,27.000,0.00,-0.0001,-0.00010,2.000
2,27.110,0.00,-0.0001,-0.00010,2.000
2,27.220,0.00,-0.0001,-0.00010,2.000
2,27.330,0.01,-0.0001,-0.00010,2.000
2,27.440,0.01,-0.0001,-0.00010,2.000
2,27.550,0.00,-0.0001,-0.00010,2.000
2,27.660,0.00,-0.0001,-0.00010,2.000
2,27.770,0.01,-0.0001,-0.00010,2.000
2,27.880,0.01,-0.0001,-0.00010,2.000
2,27.990,0.01,-0.0001,-0.00010,2.000
2,28.100,0.01,-0.0001,-0.00010,2.000
2,28.210,0.00,-0.0001,-0.00010,2.000
2,28.320,0.01,-0.0001,-0.00010,2.000
2,28.430,0.02,-0.0001,-0.00010,2.000
2,28.540,0.00,-0.0001,-0.00010,2.000
2,28.650,0.00,-0.0001,-0.00010,2.000
2,28.760,0.01,-0.0001,-0.00010,2.000
2,28.870,0.00,-0.0001,-0.00010,2.000
2,28.980,0.01,-0.0001,-0.00010,2.000
2,29.090,0.00,-0.0001,-0.00010,2.000
3,29.300,-0.01,0.0056,0.00560,3.000
3,29.410,0.00,0.1117,0.11170,3.000
3,29.520,-0.01,0.2216,0.22160,3.000
3,29.630,0.01,0.3316,0.33160,3.000
3,29.740,0.00,0.4417,0.44170,3.000
3,29.850,-0.02,0.5517,0.55170,3.000
3,29.960,-0.01,0.6617,0.66170,3.000
3,30.070,-0.02,0.7716,0.77160,3.000
3,30.180,-0.01,0.8818,0.88180,3.000
3,30.290,0.00,0.9919,0.99190,3.000
3,30.400,-0.01,1.1017,1.10170,3.000
3,30.510,-0.01,1.2116,1.21160,3.000
3,30.620,-0.01,1.3217,1.32170,3.000
3,30.730,0.00,1.4318,1.43180,3.000
3,30.840,-0.01,1.5418,1.54180,3.000
3,30.950,0.00,1.6518,1.65180,3.000
3,31.060,-0.01,1.7619,1.76190,3.000
3,31.170,0.00,1.8717,1.87170,3.000
3,31.280,-0.01,1.9817,1.98170,3.000
3,31.390,0.00,2.0918,2.09180,3.000
3,31.500,0.01,2.2020,2.20200,3.000
3,31.610,-0.01,2.3119,2.31190,3.000
3,31.720,0.01,2.4217,2.42170,3.000
3,31.830,0.00,2.5316,2.53160,3.000
3,31.940,0.00,2.6419,2.64190,3.000
3,32.050,0.00,2.7519,2.75190,3.000
3,32.160,0.00,2.8618,2.86180,3.000
3,32.270,0.01,2.9717,2.97170,3.000
3,32.380,0.01,3.0820,3.08200,3.000
3,32.490,0.01,3.1918,3.19180,3.000
3,32.600,0.02,3.3019,3.30190,3.000
3,32.710,0.04,3.4120,3.41200,3.000
3,32.820,0.08,3.5219,3.52190,3.000
3,32.930,0.17,3.6318,3.63180,3.000
3,33.040,0.31,3.7418,3.74180,3.000
3,33.150,0.49,3.8518,3.85180,3.000
3,33.260,0.75,3.9621,3.96210,3.000
3,33.390,1.16,4.0904,4.09040,3.000
3,33.500,1.00,4.0367,4.03670,3.000
3,33.610,0.64,3.9266,3.92660,3.000
3,33.720,0.40,3.8165,3.81650,3.000
3,33.830,0.22,3.7066,3.70660,3.000
3,33.940,0.11,3.5967,3.59670,3.000
3,34.050,0.04,3.4866,3.48660,3.000
3,34.160,0.01,3.3765,3.37650,3.000
3,34.270,0.01,3.2666,3.26660,3.000
3,34.380,0.01,3.1565,3.15650,3.000
3,34.490,0.01,3.0466,3.04660,3.000
3,34.600,0.01,2.9364,2.93640,3.000
3,34.710,0.00,2.8265,2.82650,3.000
3,34.820,0.00,2.7166,2.71660,3.000
3,34.930,0.00,2.6064,2.60640,3.000
3,35.040,0.00,2.4963,2.49630,3.000
3,35.150,0.00,2.3864,2.38640,3.000
3,35.260,0.00,2.2765,2.27650,3.000
3,35.370,0.00,2.1665,2.16650,3.000
3,35.480,0.00,2.0564,2.05640,3.000
3,35.590,0.00,1.9465,1.94650,3.000
3,35.700,0.00,1.8364,1.83640,3.000
3,35.810,0.00,1.7263,1.72630,3.000
3,35.920,0.00,1.6164,1.61640,3.000
3,36.030,0.01,1.5065,1.50650,3.000
3,36.140,0.00,1.3965,1.39650,3.000
3,36.250,0.00,1.2863,1.28630,3.000
3,36.360,0.01,1.1762,1.17620,3.000
3,36.470,0.00,1.0664,1.06640,3.000
3,36.580,0.00,0.9565,0.95650,3.000
3,36.690,0.00,0.8465,0.84650,3.000
3,36.800,0.01,0.7363,0.73630,3.000
3,36.910,0.00,0.6263,0.62630,3.000
3,37.020,0.00,0.5164,0.51640,3.000
3,37.130,0.00,0.4062,0.40620,3.000
3,37.240,0.00,0.2961,0.29610,3.000
3,37.350,0.00,0.1862,0.18620,3.000
3,37.460,0.00,0.0763,0.07630,3.000
3,37.580,0.00,-0.0423,-0.04230,3.000
3,37.690,0.00,-0.0005,-0.00050,3.000
3,37.800,0.00,-0.0002,-0.00020,3.000
3,37.910,-0.01,-0.0002,-0.00020,3.000
3,38.020,0.00,-0.0002,-0.00020,3.000
3,38.130,0.00,-0.0002,-0.00020,3.000
3,38.240,0.00,-0.0002,-0.00020,3.000
3,38.350,0.00,-0.0002,-0.00020,3.000
3,38.460,0.00,-0.0002,-0.00020,3.000
3,38.570,0.00,-0.0002,-0.00020,3.000
3,38.680,0.00,-0.0002,-0.00020,3.000
3,38.790,0.00,-0.0002,-0.00020,3.000
3,38.900,0.00,-0.0002,-0.00020,3.000
3,39.010,0.00,-0.0002,-0.00020,3.000
3,39.120,-0.01,-0.0002,-0.00020,3.000
3,39.230,0.00,-0.0002,-0.00020,3.000
3,39.340,0.00,-0.0002,-0.00020,3.000
3,39.450,0.00,-0.0002,-0.00020,3.000
3,39.560,0.00,-0.0002,-0.00020,3.000
3,39.670,0.01,-0.0002,-0.00020,3.000
3,39.780,0.00,-0.0002,-0.00020,3.000
3,39.890,0.00,-0.0002,-0.00020,3.000
3,40.000,-0.01,-0.0002,-0.00020,3.000
3,40.110,0.00,-0.0002,-0.00020,3.000
3,40.220,-0.01,-0.0002,-0.00020,3.000
3,40.330,-0.01,-0.0002,-0.00020,3.000
3,40.440,0.01,-0.0002,-0.00020,3.000
3,40.550,-0.01,-0.0002,-0.00020,3.000
3,40.680,0.00,-0.0002,-0.00020,3.000
3,40.790,0.00,-0.0002,-0.00020,3.000
3,40.900,0.00,-0.0001,-0.00010,3.000
3,41.010,0.00,-0.0001,-0.00010,3.000
3,41.120,0.00,-0.0001,-0.00010,3.000
3,41.230,0.00,-0.0001,-0.00010,3.000
3,41.340,-0.01,-0.0001,-0.00010,3.000
3,41.450,0.01,-0.0001,-0.00010,3.000
3,41.560,-0.01,-0.0001,-0.00010,3.000
3,41.670,0.00,-0.0001,-0.00010,3.000
3,41.780,0.00,-0.0001,-0.00010,3.000
3,41.890,-0.01,-0.0001,-0.00010,3.000
3,42.000,-0.01,-0.0001,-0.00010,3.000
3,42.110,0.00,-0.0001,-0.00010,3.000
3,42.220,0.00,-0.0001,-0.00010,3.000
3,42.330,-0.01,-0.0001,-0.00010,3.000
3,42.440,0.00,-0.0001,-0.00010,3.000
3,42.550,0.00,-0.0001,-0.00010,3.000
3,42.660,-0.01,-0.0001,-0.00010,3.000
3,42.770,0.00,-0.0001,-0.00010,3.000
3,42.880,0.00,-0.0001,-0.00010,3.000
3,42.990,0.00,-0.0001,-0.00010,3.000
3,43.100,0.00,-0.0001,-0.00010,3.000
3,43.210,-0.01,-0.0001,-0.00010,3.000
3,43.320,0.00,-0.0001,-0.00010,3.000
3,43.430,0.00,-0.0001,-0.00010,3.000
3,43.540,-0.01,-0.0001,-0.00010,3.000
3,43.650,0.00,-0.0001,-0.00010,3.000
4,43.860,-0.01,0.0415,0.04150,4.000
4,43.970,0.00,0.1517,0.15170,4.000
4,44.080,-0.01,0.2617,0.26170,4.000
4,44.190,0.01,0.3716,0.37160,4.000
4,44.300,0.00,0.4816,0.48160,4.000
4,44.410,-0.01,0.5917,0.59170,4.000
4,44.520,-0.01,0.7017,0.70170,4.000
4,44.630,0.00,0.8117,0.81170,4.000
4,44.740,-0.01,0.9218,0.92180,4.000
4,44.850,-0.01,1.0319,1.03190,4.000
4,44.960,-0.01,1.1417,1.14170,4.000
4,45.070,0.00,1.2517,1.25170,4.000
4,45.180,-0.01,1.3618,1.36180,4.000
4,45.290,-0.01,1.4718,1.47180,4.000
4,45.400,-0.02,1.5817,1.58170,4.000
4,45.510,-0.01,1.6917,1.69170,4.000
4,45.620,-0.01,1.8019,1.80190,4.000
4,45.730,-0.01,1.9118,1.91180,4.000
4,45.840,-0.01,2.0218,2.02180,4.000
4,45.950,-0.01,2.1319,2.13190,4.000
4,46.060,-0.01,2.2419,2.24190,4.000
4,46.170,-0.01,2.3519,2.35190,4.000
4,46.280,-0.01,2.4617,2.46170,4.000
4,46.390,-0.01,2.5718,2.57180,4.000
4,46.500,-0.02,2.6819,2.68190,4.000
4,46.610,0.00,2.7918,2.79180,4.000
4,46.720,0.01,2.9017,2.90170,4.000
4,46.830,0.00,3.0118,3.01180,4.000
4,46.940,0.02,3.1219,3.12190,4.000
4,47.050,0.01,3.2319,3.23190,4.000
4,47.160,0.03,3.3417,3.34170,4.000
4,47.270,0.05,3.4518,3.45180,4.000
4,47.380,0.10,3.5620,3.56200,4.000
4,47.490,0.21,3.6719,3.67190,4.000
4,47.600,0.37,3.7818,3.78180,4.000
4,47.710,0.58,3.8919,3.89190,4.000
4,47.820,0.86,4.0019,4.00190,4.000
4,47.940,1.22,4.1087,4.10870,4.000
4,48.050,0.95,4.0266,4.02660,4.000
4,48.160,0.61,3.9167,3.91670,4.000
4,48.270,0.37,3.8066,3.80660,4.000
4,48.380,0.20,3.6965,3.69650,4.000
4,48.490,0.10,3.5865,3.58650,4.000
4,48.600,0.02,3.4766,3.47660,4.000
4,48.710,0.00,3.3665,3.36650,4.000
4,48.820,0.00,3.2564,3.25640,4.000
4,48.930,0.00,3.1465,3.14650,4.000
4,49.040,-0.01,3.0366,3.03660,4.000
4,49.150,0.01,2.9265,2.92650,4.000
4,49.260,0.01,2.8164,2.81640,4.000
4,49.370,-0.01,2.7065,2.70650,4.000
4,49.480,-0.01,2.5966,2.59660,4.000
4,49.590,-0.01,2.4865,2.48650,4.000
4,49.700,-0.01,2.3763,2.37630,4.000
4,49.810,0.00,2.2665,2.26650,4.000
4,49.920,-0.01,2.1565,2.15650,4.000
4,50.030,-0.01,2.0465,2.04650,4.000
4,50.140,-0.01,1.9362,1.93620,4.000
4,50.250,-0.01,1.8264,1.82640,4.000
4,50.360,0.01,1.7164,1.71640,4.000
4,50.470,-0.01,1.6065,1.60650,4.000
4,50.580,-0.01,1.4963,1.49630,4.000
4,50.690,-0.01,1.3864,1.38640,4.000
4,50.800,0.00,1.2765,1.27650,4.000
4,50.910,0.00,1.1663,1.16630,4.000
4,51.020,0.00,1.0564,1.05640,4.000
4,51.130,-0.01,0.9465,0.94650,4.000
4,51.240,0.00,0.8365,0.83650,4.000
4,51.350,-0.01,0.7264,0.72640,4.000
4,51.460,-0.01,0.6161,0.61610,4.000
4,51.570,-0.01,0.5064,0.50640,4.000
4,51.680,0.00,0.3963,0.39630,4.000
4,51.790,0.00,0.2863,0.28630,4.000
4,51.900,-0.01,0.1762,0.17620,4.000
4,52.010,0.00,0.0663,0.06630,4.000
4,52.140,0.00,-0.0507,-0.05070,4.000
4,52.250,0.00,-0.0003,-0.00030,4.000
4,52.360,0.00,-0.0002,-0.00020,4.000
4,52.470,0.00,-0.0002,-0.00020,4.000
4,52.580,-0.01,-0.0002,-0.00020,4.000
4,52.690,-0.01,-0.0002,-0.00020,4.000
4,52.800,-0.01,-0.0002,-0.00020,4.000
4,52.910,0.00,-0.0002,-0.00020,4.000
4,53.020,0.00,-0.0002,-0.00020,4.000
4,53.130,-0.01,-0.0002,-0.00020,4.000
4,53.240,0.00,-0.0002,-0.00020,4.000
4,53.350,0.00,-0.0002,-0.00020,4.000
4,53.460,0.00,-0.0002,-0.00020,4.000
4,53.570,-0.01,-0.0002,-0.00020,4.000
4,53.680,-0.01,-0.0002,-0.00020,4.000
4,53.790,-0.01,-0.0002,-0.00020,4.000
4,53.900,0.00,-0.0002,-0.00020,4.000
4,54.010,0.00,-0.0002,-0.00020,4.000
4,54.120,0.00,-0.0002,-0.00020,4.000
4,54.230,-0.01,-0.0002,-0.00020,4.000
4,54.340,-0.01,-0.0002,-0.00020,4.000
4,54.450,-0.01,-0.0002,-0.00020,4.000
4,54.560,-0.01,-0.0002,-0.00020,4.000
4,54.670,-0.01,-0.0002,-0.00020,4.000
4,54.780,0.00,-0.0002,-0.00020,4.000
4,54.890,0.00,-0.0002,-0.00020,4.000
4,55.000,0.00,-0.0002,-0.00020,4.000
4,55.110,0.00,-0.0002,-0.00020,4.000
4,55.240,-0.01,-0.0002,-0.00020,4.000
4,55.350,-0.01,-0.0001,-0.00010,4.000
4,55.460,0.00,-0.0001,-0.00010,4.000
4,55.570,0.00,-0.0001,-0.00010,4.000
4,55.680,-0.01,-0.0001,-0.00010,4.000
4,55.790,0.00,-0.0001,-0.00010,4.000
4,55.900,0.00,-0.0001,-0.00010,4.000
4,56.010,-0.01,-0.0001,-0.00010,4.000
4,56.120,-0.01,-0.0001,-0.00010,4.000
4,56.230,-0.01,-0.0001,-0.00010,4.000
4,56.340,0.00,-0.0001,-0.00010,4.000
4,56.450,-0.01,-0.0001,-0.00010,4.000
4,56.560,0.00,-0.0001,-0.00010,4.000
4,56.670,-0.01,-0.0001,-0.00010,4.000
4,56.780,0.00,-0.0001,-0.00010,4.000
4,56.890,-0.01,-0.0001,-0.00010,4.000
4,57.000,0.00,-0.0001,-0.00010,4.000
4,57.110,0.00,-0.0001,-0.00010,4.000
4,57.220,-0.01,-0.0001,-0.00010,4.000
4,57.330,0.00,-0.0001,-0.00010,4.000
4,57.440,0.00,-0.0001,-0.00010,4.000
4,57.550,0.00,-0.0001,-0.00010,4.000
4,57.660,0.00,-0.0001,-0.00010,4.000
4,57.770,0.00,-0.0001,-0.00010,4.000
4,57.880,-0.01,-0.0001,-0.00010,4.000
4,57.990,0.00,-0.0001,-0.00010,4.000
4,58.100,-0.01,-0.0001,-0.00010,4.000
5,58.300,0.00,0.0000,0.00000,5.000
5,58.420,0.01,0.0615,0.06150,5.000
5,58.530,-0.01,0.1715,0.17150,5.000
5,58.640,0.01,0.2818,0.28180,5.000
5,58.750,0.01,0.3918,0.39180,5.000
5,58.860,0.00,0.5018,0.50180,5.000
5,58.970,0.00,0.6116,0.61160,5.000
5,59.080,0.00,0.7218,0.72180,5.000
5,59.190,0.02,0.8319,0.83190,5.000
5,59.300,-0.02,0.9418,0.94180,5.000
5,59.410,0.00,1.0517,1.05170,5.000
5,59.520,0.00,1.1618,1.16180,5.000
5,59.630,0.01,1.2717,1.27170,5.000
5,59.740,-0.01,1.3817,1.38170,5.000
5,59.850,0.00,1.4916,1.49160,5.000
5,59.960,0.01,1.6020,1.60200,5.000
5,60.070,0.01,1.7118,1.71180,5.000
5,60.180,0.01,1.8217,1.82170,5.000
5,60.290,0.01,1.9317,1.93170,5.000
5,60.400,0.01,2.0419,2.04190,5.000
5,60.510,-0.01,2.1519,2.15190,5.000
5,60.620,0.01,2.2618,2.26180,5.000
5,60.730,0.01,2.3717,2.37170,5.000
5,60.840,0.01,2.4818,2.48180,5.000
5,60.950,0.00,2.5918,2.59180,5.000
5,61.060,0.01,2.7017,2.70170,5.000
5,61.170,0.01,2.8118,2.81180,5.000
5,61.280,0.01,2.9218,2.92180,5.000
5,61.390,0.02,3.0318,3.03180,5.000
5,61.500,0.02,3.1417,3.14170,5.000
5,61.610,0.02,3.2518,3.25180,5.000
5,61.720,0.04,3.3621,3.36210,5.000
5,61.830,0.07,3.4718,3.47180,5.000
5,61.940,0.12,3.5818,3.58180,5.000
5,62.050,0.24,3.6918,3.69180,5.000
5,62.160,0.41,3.8020,3.80200,5.000
5,62.270,0.63,3.9119,3.91190,5.000
5,62.380,0.93,4.0217,4.02170,5.000
5,62.510,1.17,4.0861,4.08610,5.000
5,62.620,0.79,3.9766,3.97660,5.000
5,62.730,0.50,3.8665,3.86650,5.000
5,62.840,0.29,3.7566,3.75660,5.000
5,62.950,0.16,3.6466,3.64660,5.000
5,63.060,0.07,3.5364,3.53640,5.000
5,63.170,0.02,3.4266,3.42660,5.000
5,63.280,0.02,3.3167,3.31670,5.000
5,63.390,0.01,3.2066,3.20660,5.000
5,63.500,0.01,3.0965,3.09650,5.000
5,63.610,0.01,2.9865,2.98650,5.000
5,63.720,0.01,2.8766,2.87660,5.000
5,63.830,0.01,2.7666,2.76660,5.000
5,63.940,0.00,2.6564,2.65640,5.000
5,64.050,0.01,2.5465,2.54650,5.000
5,64.160,0.01,2.4366,2.43660,5.000
5,64.270,0.01,2.3265,2.32650,5.000
5,64.380,0.00,2.2163,2.21630,5.000
5,64.490,0.00,2.1066,2.10660,5.000
5,64.600,0.02,1.9966,1.99660,5.000
5,64.710,0.01,1.8864,1.88640,5.000
5,64.820,0.00,1.7764,1.77640,5.000
5,64.930,0.01,1.6664,1.66640,5.000
5,65.040,0.00,1.5565,1.55650,5.000
5,65.150,0.01,1.4464,1.44640,5.000
5,65.260,0.01,1.3362,1.33620,5.000
5,65.370,0.00,1.2264,1.22640,5.000
5,65.480,0.01,1.1164,1.11640,5.000
5,65.590,0.00,1.0063,1.00630,5.000
5,65.700,0.00,0.8964,0.89640,5.000
5,65.810,0.01,0.7864,0.78640,5.000
5,65.920,0.00,0.6762,0.67620,5.000
5,66.030,0.00,0.5663,0.56630,5.000
5,66.140,0.00,0.4563,0.45630,5.000
5,66.250,0.01,0.3463,0.34630,5.000
5,66.360,0.01,0.2363,0.23630,5.000
5,66.470,0.00,0.1262,0.12620,5.000
5,66.580,0.00,0.0161,0.01610,5.000
5,66.700,0.01,-0.0378,-0.03780,5.000
5,66.810,0.01,-0.0002,-0.00020,5.000
5,66.920,0.01,-0.0002,-0.00020,5.000
5,67.030,0.01,-0.0002,-0.00020,5.000
5,67.140,0.01,-0.0002,-0.00020,5.000
5,67.250,0.00,-0.0002,-0.00020,5.000
5,67.360,0.00,-0.0002,-0.00020,5.000
5,67.470,0.00,-0.0002,-0.00020,5.000
5,67.580,0.00,-0.0002,-0.00020,5.000
5,67.690,0.01,-0.0002,-0.00020,5.000
5,67.800,0.01,-0.0002,-0.00020,5.000
5,67.910,0.01,-0.0002,-0.00020,5.000
5,68.020,0.00,-0.0002,-0.00020,5.000
5,68.130,0.01,-0.0002,-0.00020,5.000
5,68.240,0.01,-0.0002,-0.00020,5.000
5,68.350,0.00,-0.0002,-0.00020,5.000
5,68.460,0.01,-0.0002,-0.00020,5.000
5,68.570,0.01,-0.0002,-0.00020,5.000
5,68.680,0.01,-0.0002,-0.00020,5.000
5,68.790,0.01,-0.0002,-0.00020,5.000
5,68.900,0.00,-0.0002,-0.00020,5.000
5,69.010,0.00,-0.0002,-0.00020,5.000
5,69.120,0.01,-0.0002,-0.00020,5.000
5,69.230,0.01,-0.0002,-0.00020,5.000
5,69.340,0.01,-0.0002,-0.00020,5.000
5,69.450,0.00,-0.0002,-0.00020,5.000
5,69.560,0.00,-0.0002,-0.00020,5.000
5,69.670,0.01,-0.0002,-0.00020,5.000
5,69.790,0.01,-0.0001,-0.00010,5.000
5,69.900,0.01,-0.0001,-0.00010,5.000
5,70.010,0.00,-0.0001,-0.00010,5.000
5,70.120,0.01,-0.0001,-0.00010,5.000
5,70.230,0.00,-0.0001,-0.00010,5.000
5,70.340,0.00,-0.0001,-0.00010,5.000
5,70.450,0.01,-0.0001,-0.00010,5.000
5,70.560,0.01,-0.0001,-0.00010,5.000
5,70.670,0.00,-0.0001,-0.00010,5.000
5,70.780,0.01,-0.0001,-0.00010,5.000
5,70.890,0.00,-0.0001,-0.00010,5.000
5,71.000,0.00,-0.0001,-0.00010,5.000
5,71.110,0.00,-0.0001,-0.00010,5.000
5,71.220,0.00,-0.0001,-0.00010,5.000
5,71.330,0.01,-0.0001,-0.00010,5.000
5,71.440,0.01,-0.0001,-0.00010,5.000
5,71.550,0.01,-0.0001,-0.00010,5.000
5,71.660,0.01,-0.0001,-0.00010,5.000
5,71.770,0.01,-0.0001,-0.00010,5.000
5,71.880,0.01,-0.0001,-0.00010,5.000
5,71.990,0.01,-0.0001,-0.00010,5.000
5,72.100,0.01,-0.0001,-0.00010,5.000
5,72.210,0.00,-0.0001,-0.00010,5.000
5,72.320,-0.01,-0.0001,-0.00010,5.000
5,72.430,0.00,-0.0001,-0.00010,5.000
5,72.540,0.01,-0.0001,-0.00010,5.000
5,72.650,0.01,-0.0001,-0.00010,5.000
6,72.860,0.00,0.0000,0.00000,6.000
6,72.970,0.01,0.0816,0.08160,6.000
6,73.080,0.01,0.1916,0.19160,6.000
6,73.190,0.01,0.3017,0.30170,6.000
6,73.300,0.01,0.4115,0.41150,6.000
6,73.410,0.01,0.5218,0.52180,6.000
6,73.520,0.01,0.6317,0.63170,6.000
6,73.630,0.01,0.7417,0.74170,6.000
6,73.740,0.01,0.8517,0.85170,6.000
6,73.850,0.01,0.9619,0.96190,6.000
6,73.960,0.01,1.0718,1.07180,6.000
6,74.070,0.01,1.1816,1.18160,6.000
6,74.180,0.02,1.2916,1.29160,6.000
6,74.290,0.01,1.4018,1.40180,6.000
6,74.400,0.02,1.5117,1.51170,6.000
6,74.510,0.01,1.6218,1.62180,6.000
6,74.620,0.02,1.7317,1.73170,6.000
6,74.730,0.01,1.8417,1.84170,6.000
6,74.840,0.01,1.9518,1.95180,6.000
6,74.950,0.02,2.0617,2.06170,6.000
6,75.060,0.01,2.1717,2.17170,6.000
6,75.170,0.01,2.2819,2.28190,6.000
6,75.280,0.01,2.3918,2.39180,6.000
6,75.390,0.01,2.5017,2.50170,6.000
6,75.500,0.01,2.6118,2.61180,6.000
6,75.610,0.01,2.7219,2.72190,6.000
6,75.720,0.01,2.8318,2.83180,6.000
6,75.830,0.02,2.9417,2.94170,6.000
6,75.940,0.03,3.0518,3.05180,6.000
6,76.050,0.02,3.1619,3.16190,6.000
6,76.160,0.05,3.2718,3.27180,6.000
6,76.270,0.05,3.3817,3.38170,6.000
6,76.380,0.09,3.4919,3.49190,6.000
6,76.490,0.16,3.6019,3.60190,6.000
6,76.600,0.28,3.7120,3.71200,6.000
6,76.710,0.46,3.8218,3.82180,6.000
6,76.820,0.69,3.9319,3.93190,6.000
6,76.930,1.00,4.0419,4.04190,6.000
6,77.060,1.15,4.0682,4.06820,6.000
6,77.170,0.75,3.9587,3.95870,6.000
6,77.280,0.47,3.8487,3.84870,6.000
6,77.390,0.28,3.7384,3.73840,6.000
6,77.500,0.15,3.6285,3.62850,6.000
6,77.610,0.08,3.5185,3.51850,6.000
6,77.720,0.02,3.4086,3.40860,6.000
6,77.830,0.01,3.2984,3.29840,6.000
6,77.940,0.02,3.1885,3.18850,6.000
6,78.050,0.02,3.0786,3.07860,6.000
6,78.160,0.02,2.9685,2.96850,6.000
6,78.270,0.01,2.8584,2.85840,6.000
6,78.380,0.01,2.7486,2.74860,6.000
6,78.490,0.01,2.6386,2.63860,6.000
6,78.600,0.01,2.5284,2.52840,6.000
6,78.710,0.01,2.4184,2.41840,6.000
6,78.820,0.01,2.3085,2.30850,6.000
6,78.930,0.02,2.1986,2.19860,6.000
6,79.040,0.01,2.0885,2.08850,6.000
6,79.150,0.01,1.9784,1.97840,6.000
6,79.260,0.01,1.8684,1.86840,6.000
6,79.370,0.01,1.7585,1.75850,6.000
6,79.480,0.01,1.6484,1.64840,6.000
6,79.590,0.02,1.5383,1.53830,6.000
6,79.700,0.01,1.4285,1.42850,6.000
6,79.810,0.01,1.3184,1.31840,6.000
6,79.920,0.02,1.2082,1.20820,6.000
6,80.030,0.01,1.0984,1.09840,6.000
6,80.140,0.00,0.9884,0.98840,6.000
6,80.250,0.02,0.8785,0.87850,6.000
6,80.360,0.01,0.7684,0.76840,6.000
6,80.470,0.01,0.6582,0.65820,6.000
6,80.580,0.01,0.5484,0.54840,6.000
6,80.690,0.02,0.4384,0.43840,6.000
6,80.800,0.00,0.3283,0.32830,6.000
6,80.910,0.01,0.2181,0.21810,6.000
6,81.020,0.02,0.1084,0.10840,6.000
6,81.130,0.01,-0.0018,-0.00180,6.000
6,81.250,0.02,-0.0152,-0.01520,6.000
6,81.360,0.01,-0.0002,-0.00020,6.000
6,81.470,0.01,-0.0002,-0.00020,6.000
6,81.580,0.02,-0.0002,-0.00020,6.000
6,81.690,0.02,-0.0002,-0.00020,6.000
6,81.800,0.02,-0.0002,-0.00020,6.000
6,81.910,0.01,-0.0002,-0.00020,6.000
6,82.020,0.01,-0.0002,-0.00020,6.000
6,82.130,0.01,-0.0002,-0.00020,6.000
6,82.240,0.01,-0.0002,-0.00020,6.000
6,82.350,0.02,-0.0002,-0.00020,6.000
6,82.460,0.00,-0.0002,-0.00020,6.000
6,82.570,0.01,-0.0002,-0.00020,6.000
6,82.680,0.01,-0.0002,-0.00020,6.000
6,82.790,0.02,-0.0002,-0.00020,6.000
6,82.900,0.01,-0.0002,-0.00020,6.000
6,83.010,0.02,-0.0002,-0.00020,6.000
6,83.120,0.02,-0.0002,-0.00020,6.000
6,83.230,0.01,-0.0002,-0.00020,6.000
6,83.340,0.02,-0.0002,-0.00020,6.000
6,83.450,0.01,-0.0002,-0.00020,6.000
6,83.560,0.02,-0.0002,-0.00020,6.000
6,83.670,0.01,-0.0002,-0.00020,6.000
6,83.780,0.01,-0.0002,-0.00020,6.000
6,83.890,0.02,-0.0002,-0.00020,6.000
6,84.000,0.01,-0.0001,-0.00010,6.000
6,84.110,0.01,-0.0001,-0.00010,6.000
6,84.240,0.01,-0.0001,-0.00010,6.000
6,84.350,0.01,-0.0001,-0.00010,6.000
6,84.460,0.01,-0.0001,-0.00010,6.000
6,84.570,0.01,-0.0001,-0.00010,6.000
6,84.680,0.01,-0.0001,-0.00010,6.000
6,84.790,0.01,-0.0001,-0.00010,6.000
6,84.900,0.02,-0.0001,-0.00010,6.000
6,85.010,0.01,-0.0001,-0.00010,6.000
6,85.120,0.01,-0.0001,-0.00010,6.000
6,85.230,0.01,-0.0001,-0.00010,6.000
6,85.340,0.02,-0.0001,-0.00010,6.000
6,85.450,0.01,-0.0001,-0.00010,6.000
6,85.560,0.02,-0.0001,-0.00010,6.000
6,85.670,0.01,-0.0001,-0.00010,6.000
6,85.780,0.01,-0.0001,-0.00010,6.000
6,85.890,0.02,-0.0001,-0.00010,6.000
6,86.000,0.02,-0.0001,-0.00010,6.000
6,86.110,0.01,-0.0001,-0.00010,6.000
6,86.220,0.02,-0.0001,-0.00010,6.000
6,86.330,0.02,-0.0001,-0.00010,6.000
6,86.440,0.02,-0.0001,-0.00010,6.000
6,86.550,0.02,-0.0001,-0.00010,6.000
6,86.660,0.01,-0.0001,-0.00010,6.000
6,86.770,0.01,-0.0001,-0.00010,6.000
6,86.880,0.01,-0.0001,-0.00010,6.000
6,86.990,0.02,-0.0001,-0.00010,6.000
6,87.100,0.01,-0.0001,-0.00010,6.000
6,87.210,0.01,-0.0001,-0.00010,6.000
7,87.410,0.00,0.0213,0.02130,7.000
7,87.520,0.00,0.1316,0.13160,7.000
7,87.630,0.00,0.2416,0.24160,7.000
7,87.740,0.00,0.3518,0.35180,7.000
7,87.850,-0.02,0.4617,0.46170,7.000
7,87.960,0.00,0.5716,0.57160,7.000
7,88.070,0.00,0.6817,0.68170,7.000
7,88.180,-0.01,0.7919,0.79190,7.000
7,88.290,0.00,0.9018,0.90180,7.000
7,88.400,0.00,1.0117,1.01170,7.000
7,88.510,0.00,1.1218,1.12180,7.000
7,88.620,0.00,1.2317,1.23170,7.000
7,88.730,-0.01,1.3417,1.34170,7.000
7,88.840,0.00,1.4517,1.45170,7.000
7,88.950,0.00,1.5619,1.56190,7.000
7,89.060,0.00,1.6718,1.67180,7.000
7,89.170,-0.01,1.7818,1.78180,7.000
7,89.280,0.00,1.8917,1.89170,7.000
7,89.390,0.00,2.0018,2.00180,7.000
7,89.500,-0.01,2.1119,2.11190,7.000
7,89.610,0.01,2.2217,2.22170,7.000
7,89.720,0.00,2.3318,2.33180,7.000
7,89.830,0.00,2.4419,2.44190,7.000
7,89.940,-0.01,2.5518,2.55180,7.000
7,90.050,0.00,2.6617,2.66170,7.000
7,90.160,0.00,2.7718,2.77180,7.000
7,90.270,0.00,2.8819,2.88190,7.000
7,90.380,0.01,2.9918,2.99180,7.000
7,90.490,-0.01,3.1017,3.10170,7.000
7,90.600,0.00,3.2119,3.21190,7.000
7,90.710,0.02,3.3220,3.32200,7.000
7,90.820,0.05,3.4319,3.43190,7.000
7,90.930,0.10,3.5417,3.54170,7.000
7,91.040,0.19,3.6519,3.65190,7.000
7,91.150,0.34,3.7620,3.76200,7.000
7,91.260,0.54,3.8718,3.87180,7.000
7,91.370,0.81,3.9819,3.98190,7.000
7,91.500,1.21,4.0996,4.09960,7.000
7,91.610,0.93,4.0186,4.01860,7.000
7,91.720,0.60,3.9086,3.90860,7.000
7,91.830,0.35,3.7986,3.79860,7.000
7,91.940,0.20,3.6887,3.68870,7.000
7,92.050,0.09,3.5785,3.57850,7.000
7,92.160,0.04,3.4685,3.46850,7.000
7,92.270,0.00,3.3586,3.35860,7.000
7,92.380,0.01,3.2486,3.24860,7.000
7,92.490,0.00,3.1384,3.13840,7.000
7,92.600,0.00,3.0285,3.02850,7.000
7,92.710,0.01,2.9186,2.91860,7.000
7,92.820,0.00,2.8085,2.80850,7.000
7,92.930,0.00,2.6984,2.69840,7.000
7,93.040,0.00,2.5884,2.58840,7.000
7,93.150,0.00,2.4785,2.47850,7.000
7,93.260,0.00,2.3684,2.36840,7.000
7,93.370,-0.02,2.2583,2.25830,7.000
7,93.480,-0.01,2.1485,2.14850,7.000
7,93.590,0.01,2.0386,2.03860,7.000
7,93.700,0.00,1.9284,1.92840,7.000
7,93.810,0.00,1.8183,1.81830,7.000
7,93.920,0.00,1.7084,1.70840,7.000
7,94.030,0.00,1.5985,1.59850,7.000
7,94.140,-0.01,1.4884,1.48840,7.000
7,94.250,-0.01,1.3782,1.37820,7.000
7,94.360,0.00,1.2683,1.26830,7.000
7,94.470,0.01,1.1584,1.15840,7.000
7,94.580,0.00,1.0483,1.04830,7.000
7,94.690,0.01,0.9384,0.93840,7.000
7,94.800,0.00,0.8285,0.82850,7.000
7,94.910,0.01,0.7185,0.71850,7.000
7,95.020,-0.01,0.6082,0.60820,7.000
7,95.130,-0.01,0.4982,0.49820,7.000
7,95.240,0.00,0.3883,0.38830,7.000
7,95.350,0.00,0.2783,0.27830,7.000
7,95.460,0.00,0.1683,0.16830,7.000
7,95.570,0.00,0.0582,0.05820,7.000
7,95.690,-0.01,-0.0486,-0.04860,7.000
7,95.800,0.00,-0.0003,-0.00030,7.000
7,95.910,-0.01,-0.0002,-0.00020,7.000
7,96.020,0.00,-0.0002,-0.00020,7.000
7,96.130,0.00,-0.0002,-0.00020,7.000
7,96.240,0.00,-0.0002,-0.00020,7.000
7,96.350,0.01,-0.0002,-0.00020,7.000
7,96.460,0.00,-0.0002,-0.00020,7.000
7,96.570,0.00,-0.0002,-0.00020,7.000
7,96.680,0.00,-0.0002,-0.00020,7.000
7,96.790,-0.01,-0.0002,-0.00020,7.000
7,96.900,0.00,-0.0002,-0.00020,7.000
7,97.010,0.00,-0.0002,-0.00020,7.000
7,97.120,0.00,-0.0002,-0.00020,7.000
7,97.230,-0.02,-0.0002,-0.00020,7.000
7,97.340,0.00,-0.0002,-0.00020,7.000
7,97.450,0.00,-0.0002,-0.00020,7.000
7,97.560,0.00,-0.0002,-0.00020,7.000
7,97.670,0.00,-0.0002,-0.00020,7.000
7,97.780,0.00,-0.0002,-0.00020,7.000
7,97.890,0.00,-0.0002,-0.00020,7.000
7,98.000,0.00,-0.0002,-0.00020,7.000
7,98.110,0.00,-0.0002,-0.00020,7.000
7,98.220,0.00,-0.0002,-0.00020,7.000
7,98.330,-0.01,-0.0002,-0.00020,7.000
7,98.440,0.00,-0.0001,-0.00010,7.000
7,98.550,0.00,-0.0001,-0.00010,7.000
7,98.660,0.00,-0.0001,-0.00010,7.000
7,98.780,-0.01,-0.0001,-0.00010,7.000
7,98.890,0.01,-0.0001,-0.00010,7.000
7,99.000,0.00,-0.0001,-0.00010,7.000
7,99.110,0.00,-0.0001,-0.00010,7.000
7,99.220,0.01,-0.0001,-0.00010,7.000
7,99.330,-0.01,-0.0001,-0.00010,7.000
7,99.440,0.00,-0.0001,-0.00010,7.000
7,99.550,0.00,-0.0001,-0.00010,7.000
7,99.660,0.00,-0.0001,-0.00010,7.000
7,99.770,0.00,-0.0001,-0.00010,7.000
7,99.880,0.00,-0.0001,-0.00010,7.000
7,99.990,-0.02,-0.0001,-0.00010,7.000
7,100.100,0.00,-0.0001,-0.00010,7.000
7,100.210,0.00,-0.0001,-0.00010,7.000
7,100.320,0.00,-0.0001,-0.00010,7.000
7,100.430,0.00,-0.0001,-0.00010,7.000
7,100.540,0.00,-0.0001,-0.00010,7.000
7,100.650,0.00,-0.0001,-0.00010,7.000
7,100.760,-0.01,-0.0001,-0.00010,7.000
7,100.870,0.01,-0.0001,-0.00010,7.000
7,100.980,0.01,-0.0001,-0.00010,7.000
7,101.090,0.01,-0.0001,-0.00010,7.000
7,101.200,-0.01,-0.0001,-0.00010,7.000
7,101.310,0.01,-0.0001,-0.00010,7.000
7,101.420,0.01,-0.0001,-0.00010,7.000
7,101.530,0.00,-0.0001,-0.00010,7.000
7,101.640,0.00,-0.0001,-0.00010,7.000
7,101.750,-0.01,-0.0001,-0.00010,7.000
8,101.960,0.02,0.0415,0.04150,8.000
8,102.070,0.00,0.1517,0.15170,8.000
8,102.180,0.01,0.2616,0.26160,8.000
8,102.290,0.01,0.3716,0.37160,8.000
8,102.400,0.00,0.4818,0.48180,8.000
8,102.510,0.00,0.5916,0.59160,8.000
8,102.620,0.01,0.7016,0.70160,8.000
8,102.730,0.01,0.8117,0.81170,8.000
8,102.840,0.01,0.9218,0.92180,8.000
8,102.950,0.01,1.0319,1.03190,8.000
8,103.060,0.00,1.1417,1.14170,8.000
8,103.170,0.01,1.2517,1.25170,8.000
8,103.280,0.00,1.3618,1.36180,8.000
8,103.390,0.01,1.4717,1.47170,8.000
8,103.500,0.01,1.5817,1.58170,8.000
8,103.610,0.01,1.6917,1.69170,8.000
8,103.720,0.01,1.8019,1.80190,8.000
8,103.830,0.00,1.9118,1.91180,8.000
8,103.940,0.00,2.0217,2.02170,8.000
8,104.050,0.01,2.1319,2.13190,8.000
8,104.160,-0.01,2.2419,2.24190,8.000
8,104.270,0.00,2.3518,2.35180,8.000
8,104.380,0.00,2.4617,2.46170,8.000
8,104.490,0.01,2.5717,2.57170,8.000
8,104.600,0.01,2.6818,2.68180,8.000
8,104.710,0.00,2.7918,2.79180,8.000
8,104.820,0.00,2.9018,2.90180,8.000
8,104.930,0.02,3.0119,3.01190,8.000
8,105.040,0.01,3.1218,3.12180,8.000
8,105.150,0.03,3.2318,3.23180,8.000
8,105.260,0.02,3.3418,3.34180,8.000
8,105.370,0.06,3.4520,3.45200,8.000
8,105.480,0.12,3.5619,3.56190,8.000
8,105.590,0.22,3.6719,3.67190,8.000
8,105.700,0.37,3.7817,3.78170,8.000
8,105.810,0.60,3.8919,3.89190,8.000
8,105.920,0.87,4.0019,4.00190,8.000
8,106.050,1.22,4.0972,4.09720,8.000
8,106.160,0.85,3.9966,3.99660,8.000
8,106.270,0.54,3.8866,3.88660,8.000
8,106.380,0.33,3.7765,3.77650,8.000
8,106.490,0.18,3.6664,3.66640,8.000
8,106.600,0.08,3.5566,3.55660,8.000
8,106.710,0.03,3.4466,3.44660,8.000
8,106.820,0.02,3.3366,3.33660,8.000
8,106.930,0.03,3.2265,3.22650,8.000
8,107.040,0.03,3.1166,3.11660,8.000
8,107.150,0.01,3.0066,3.00660,8.000
8,107.260,0.01,2.8964,2.89640,8.000
8,107.370,0.01,2.7864,2.78640,8.000
8,107.480,0.01,2.6765,2.67650,8.000
8,107.590,0.01,2.5665,2.56650,8.000
8,107.700,0.01,2.4564,2.45640,8.000
8,107.810,0.01,2.3465,2.34650,8.000
8,107.920,0.01,2.2365,2.23650,8.000
8,108.030,0.00,2.1265,2.12650,8.000
8,108.140,0.01,2.0165,2.01650,8.000
8,108.250,0.01,1.9063,1.90630,8.000
8,108.360,0.01,1.7965,1.79650,8.000
8,108.470,0.01,1.6865,1.68650,8.000
8,108.580,0.01,1.5763,1.57630,8.000
8,108.690,0.02,1.4665,1.46650,8.000
8,108.800,0.01,1.3564,1.35640,8.000
8,108.910,0.02,1.2464,1.24640,8.000
8,109.020,0.01,1.1362,1.13620,8.000
8,109.130,0.00,1.0264,1.02640,8.000
8,109.240,0.01,0.9165,0.91650,8.000
8,109.350,0.01,0.8065,0.80650,8.000
8,109.460,0.01,0.6962,0.69620,8.000
8,109.570,0.02,0.5862,0.58620,8.000
8,109.680,0.00,0.4763,0.47630,8.000
8,109.790,0.01,0.3663,0.36630,8.000
8,109.900,0.01,0.2561,0.25610,8.000
8,110.010,0.01,0.1463,0.14630,8.000
8,110.120,0.01,0.0363,0.03630,8.000
8,110.240,0.02,-0.0490,-0.04900,8.000
8,110.350,0.02,-0.0002,-0.00020,8.000
8,110.460,0.01,-0.0002,-0.00020,8.000
8,110.570,0.00,-0.0002,-0.00020,8.000
8,110.680,0.01,-0.0002,-0.00020,8.000
8,110.790,0.01,-0.0002,-0.00020,8.000
8,110.900,0.01,-0.0002,-0.00020,8.000
8,111.010,-0.01,-0.0002,-0.00020,8.000
8,111.120,0.01,-0.0002,-0.00020,8.000
8,111.230,0.01,-0.0002,-0.00020,8.000
8,111.340,0.01,-0.0002,-0.00020,8.000
8,111.450,0.00,-0.0002,-0.00020,8.000
8,111.560,0.01,-0.0002,-0.00020,8.000
8,111.670,0.01,-0.0002,-0.00020,8.000
8,111.780,0.01,-0.0002,-0.00020,8.000
8,111.890,0.01,-0.0002,-0.00020,8.000
8,112.000,0.00,-0.0002,-0.00020,8.000
8,112.110,0.00,-0.0002,-0.00020,8.000
8,112.220,0.01,-0.0002,-0.00020,8.000
8,112.330,0.02,-0.0002,-0.00020,8.000
8,112.440,0.00,-0.0002,-0.00020,8.000
8,112.550,0.01,-0.0002,-0.00020,8.000
8,112.660,0.01,-0.0002,-0.00020,8.000
8,112.770,-0.01,-0.0002,-0.00020,8.000
8,112.880,0.02,-0.0002,-0.00020,8.000
8,112.990,0.00,-0.0001,-0.00010,8.000
8,113.100,0.01,-0.0001,-0.00010,8.000
8,113.210,0.01,-0.0001,-0.00010,8.000
8,113.330,0.00,-0.0001,-0.00010,8.000
8,113.440,0.01,-0.0001,-0.00010,8.000
8,113.550,0.00,-0.0001,-0.00010,8.000
8,113.660,0.00,-0.0001,-0.00010,8.000
8,113.770,0.01,-0.0001,-0.00010,8.000
8,113.880,0.00,-0.0001,-0.00010,8.000
8,113.990,0.00,-0.0001,-0.00010,8.000
8,114.100,0.00,-0.0001,-0.00010,8.000
8,114.210,0.01,-0.0001,-0.00010,8.000
8,114.320,0.01,-0.0001,-0.00010,8.000
8,114.430,-0.01,-0.0001,-0.00010,8.000
8,114.540,0.02,-0.0001,-0.00010,8.000
8,114.650,0.01,-0.0001,-0.00010,8.000
8,114.760,0.01,-0.0001,-0.00010,8.000
8,114.870,0.00,-0.0001,-0.00010,8.000
8,114.980,0.01,-0.0001,-0.00010,8.000
8,115.090,0.00,-0.0001,-0.00010,8.000
8,115.200,0.01,-0.0001,-0.00010,8.000
8,115.310,0.02,-0.0001,-0.00010,8.000
8,115.420,0.00,-0.0001,-0.00010,8.000
8,115.530,0.00,-0.0001,-0.00010,8.000
8,115.640,-0.01,-0.0001,-0.00010,8.000
8,115.750,0.00,-0.0001,-0.00010,8.000
8,115.860,0.00,-0.0001,-0.00010,8.000
8,115.970,0.01,-0.0001,-0.00010,8.000
8,116.080,0.00,-0.0001,-0.00010,8.000
8,116.190,0.01,-0.0001,-0.00010,8.000
9,116.390,-0.01,0.0000,0.00000,9.000
9,116.510,-0.01,0.0615,0.06150,9.000
9,116.620,-0.02,0.1715,0.17150,9.000
9,116.730,-0.02,0.2818,0.28180,9.000
9,116.840,-0.01,0.3918,0.39180,9.000
9,116.950,-0.02,0.5016,0.50160,9.000
9,117.060,-0.02,0.6115,0.61150,9.000
9,117.170,-0.02,0.7218,0.72180,9.000
9,117.280,-0.01,0.8318,0.83180,9.000
9,117.390,-0.02,0.9418,0.94180,9.000
9,117.500,-0.02,1.0517,1.05170,9.000
9,117.610,-0.01,1.1617,1.16170,9.000
9,117.720,-0.01,1.2718,1.27180,9.000
9,117.830,-0.02,1.3816,1.38160,9.000
9,117.940,0.00,1.4918,1.49180,9.000
9,118.050,-0.03,1.6019,1.60190,9.000
9,118.160,-0.01,1.7119,1.71190,9.000
9,118.270,-0.01,1.8217,1.82170,9.000
9,118.380,-0.02,1.9317,1.93170,9.000
9,118.490,-0.02,2.0419,2.04190,9.000
9,118.600,-0.02,2.1519,2.15190,9.000
9,118.710,-0.02,2.2617,2.26170,9.000
9,118.820,-0.01,2.3718,2.37180,9.000
9,118.930,-0.03,2.4818,2.48180,9.000
9,119.040,-0.01,2.5918,2.59180,9.000
9,119.150,-0.01,2.7018,2.70180,9.000
9,119.260,-0.01,2.8118,2.81180,9.000
9,119.370,-0.02,2.9218,2.92180,9.000
9,119.480,0.00,3.0319,3.03190,9.000
9,119.590,0.00,3.1417,3.14170,9.000
9,119.700,0.00,3.2519,3.25190,9.000
9,119.810,0.01,3.3620,3.36200,9.000
9,119.920,0.04,3.4719,3.47190,9.000
9,120.030,0.11,3.5817,3.58170,9.000
9,120.140,0.22,3.6920,3.69200,9.000
9,120.250,0.40,3.8020,3.80200,9.000
9,120.360,0.61,3.9119,3.91190,9.000
9,120.470,0.92,4.0218,4.02180,9.000
9,120.590,1.24,4.1071,4.10710,9.000
9,120.700,0.88,4.0067,4.00670,9.000
9,120.810,0.56,3.8966,3.89660,9.000
9,120.920,0.33,3.7865,3.78650,9.000
9,121.030,0.17,3.6766,3.67660,9.000
9,121.140,0.07,3.5665,3.56650,9.000
9,121.250,0.01,3.4566,3.45660,9.000
9,121.360,0.00,3.3466,3.34660,9.000
9,121.470,0.00,3.2366,3.23660,9.000
9,121.580,-0.01,3.1265,3.12650,9.000
9,121.690,-0.01,3.0165,3.01650,9.000
9,121.800,-0.02,2.9064,2.90640,9.000
9,121.910,-0.01,2.7966,2.79660,9.000
9,122.020,-0.01,2.6866,2.68660,9.000
9,122.130,-0.02,2.5764,2.57640,9.000
9,122.240,-0.01,2.4664,2.46640,9.000
9,122.350,-0.02,2.3566,2.35660,9.000
9,122.460,-0.01,2.2465,2.24650,9.000
9,122.570,-0.01,2.1365,2.13650,9.000
9,122.680,-0.01,2.0264,2.02640,9.000
9,122.790,-0.01,1.9165,1.91650,9.000
9,122.900,-0.02,1.8064,1.80640,9.000
9,123.010,-0.02,1.6963,1.69630,9.000
9,123.120,-0.02,1.5864,1.58640,9.000
9,123.230,-0.01,1.4765,1.47650,9.000
9,123.340,-0.02,1.3664,1.36640,9.000
9,123.450,-0.02,1.2563,1.25630,9.000
9,123.560,-0.01,1.1464,1.14640,9.000
9,123.670,-0.01,1.0364,1.03640,9.000
9,123.780,-0.02,0.9265,0.92650,9.000
9,123.890,-0.02,0.8163,0.81630,9.000
9,124.000,-0.01,0.7063,0.70630,9.000
9,124.110,-0.02,0.5963,0.59630,9.000
9,124.220,-0.01,0.4864,0.48640,9.000
9,124.330,-0.02,0.3761,0.37610,9.000
9,124.440,-0.02,0.2663,0.26630,9.000
9,124.550,-0.02,0.1562,0.15620,9.000
9,124.660,-0.03,0.0463,0.04630,9.000
9,124.790,-0.02,-0.0490,-0.04900,9.000
9,124.900,0.00,-0.0002,-0.00020,9.000
9,125.010,-0.02,-0.0002,-0.00020,9.000
9,125.120,-0.01,-0.0002,-0.00020,9.000
9,125.230,-0.02,-0.0002,-0.00020,9.000
9,125.340,-0.01,-0.0002,-0.00020,9.000
9,125.450,-0.01,-0.0002,-0.00020,9.000
9,125.560,-0.01,-0.0002,-0.00020,9.000
9,125.670,-0.03,-0.0002,-0.00020,9.000
9,125.780,-0.01,-0.0002,-0.00020,9.000
9,125.890,-0.02,-0.0002,-0.00020,9.000
9,126.000,-0.03,-0.0002,-0.00020,9.000
9,126.110,-0.01,-0.0002,-0.00020,9.000
9,126.220,-0.01,-0.0002,-0.00020,9.000
9,126.330,-0.01,-0.0002,-0.00020,9.000
9,126.440,-0.01,-0.0002,-0.00020,9.000
9,126.550,-0.01,-0.0002,-0.00020,9.000
9,126.660,-0.02,-0.0002,-0.00020,9.000
9,126.770,0.00,-0.0002,-0.00020,9.000
9,126.880,-0.01,-0.0002,-0.00020,9.000
9,126.990,-0.01,-0.0002,-0.00020,9.000
9,127.100,-0.01,-0.0001,-0.00010,9.000
9,127.210,-0.01,-0.0001,-0.00010,9.000
9,127.320,-0.01,-0.0001,-0.00010,9.000
9,127.430,-0.01,-0.0001,-0.00010,9.000
9,127.540,-0.02,-0.0001,-0.00010,9.000
9,127.650,-0.01,-0.0001,-0.00010,9.000
9,127.760,-0.02,-0.0001,-0.00010,9.000
9,127.880,-0.02,-0.0001,-0.00010,9.000
9,127.990,-0.02,-0.0001,-0.00010,9.000
9,128.100,-0.02,-0.0001,-0.00010,9.000
9,128.210,-0.02,-0.0001,-0.00010,9.000
9,128.320,-0.02,-0.0001,-0.00010,9.000
9,128.430,-0.01,-0.0001,-0.00010,9.000
9,128.540,-0.02,-0.0001,-0.00010,9.000
9,128.650,-0.01,-0.0001,-0.00010,9.000
9,128.760,-0.01,-0.0001,-0.00010,9.000
9,128.870,-0.02,-0.0001,-0.00010,9.000
9,128.980,-0.02,-0.0001,-0.00010,9.000
9,129.090,-0.01,-0.0001,-0.00010,9.000
9,129.200,-0.02,-0.0001,-0.00010,9.000
9,129.310,-0.02,-0.0001,-0.00010,9.000
9,129.420,-0.01,-0.0001,-0.00010,9.000
9,129.530,-0.03,-0.0001,-0.00010,9.000
9,129.640,-0.03,-0.0001,-0.00010,9.000
9,129.750,-0.02,-0.0001,-0.00010,9.000
9,129.860,-0.01,-0.0001,-0.00010,9.000
9,129.970,-0.01,-0.0001,-0.00010,9.000
9,130.080,-0.01,-0.0001,-0.00010,9.000
9,130.190,-0.03,-0.0001,-0.00010,9.000
9,130.300,0.00,-0.0001,-0.00010,9.000
9,130.410,-0.01,-0.0001,-0.00010,9.000
9,130.520,-0.01,-0.0001,-0.00010,9.000
9,130.630,-0.01,-0.0001,-0.00010,9.000
9,130.740,-0.01,-0.0001,-0.00010,9.000
10,130.940,0.01,0.0000,0.00000,10.000
10,131.050,-0.01,0.0816,0.08160,10.000
10,131.160,0.00,0.1916,0.19160,10.000
10,131.270,0.00,0.3016,0.30160,10.000
10,131.380,0.01,0.4116,0.41160,10.000
10,131.490,0.01,0.5217,0.52170,10.000
10,131.600,-0.01,0.6316,0.63160,10.000
10,131.710,0.00,0.7417,0.74170,10.000
10,131.820,0.00,0.8517,0.85170,10.000
10,131.930,-0.01,0.9619,0.96190,10.000
10,132.040,0.00,1.0718,1.07180,10.000
10,132.150,0.00,1.1816,1.18160,10.000
10,132.260,0.00,1.2917,1.29170,10.000
10,132.370,0.00,1.4018,1.40180,10.000
10,132.480,0.00,1.5117,1.51170,10.000
10,132.590,0.01,1.6217,1.62170,10.000
10,132.700,0.00,1.7317,1.73170,10.000
10,132.810,0.00,1.8418,1.84180,10.000
10,132.920,0.00,1.9517,1.95170,10.000
10,133.030,-0.01,2.0617,2.06170,10.000
10,133.140,0.00,2.1718,2.17180,10.000
10,133.250,0.00,2.2818,2.28180,10.000
10,133.360,0.00,2.3919,2.39190,10.000
10,133.470,0.01,2.5017,2.50170,10.000
10,133.580,0.01,2.6118,2.61180,10.000
10,133.690,0.00,2.7219,2.72190,10.000
10,133.800,-0.01,2.8318,2.83180,10.000
10,133.910,0.00,2.9416,2.94160,10.000
10,134.020,0.02,3.0519,3.05190,10.000
10,134.130,0.02,3.1618,3.16180,10.000
10,134.240,0.02,3.2718,3.27180,10.000
10,134.350,0.03,3.3818,3.38180,10.000
10,134.460,0.05,3.4919,3.49190,10.000
10,134.570,0.15,3.6019,3.60190,10.000
10,134.680,0.27,3.7119,3.71190,10.000
10,134.790,0.43,3.8218,3.82180,10.000
10,134.900,0.69,3.9320,3.93200,10.000
10,135.010,1.00,4.0420,4.04200,10.000
10,135.130,1.11,4.0561,4.05610,10.000
10,135.240,0.72,3.9465,3.94650,10.000
10,135.350,0.44,3.8366,3.83660,10.000
10,135.460,0.26,3.7267,3.72670,10.000
10,135.570,0.13,3.6165,3.61650,10.000
10,135.680,0.05,3.5064,3.50640,10.000
10,135.790,0.01,3.3967,3.39670,10.000
10,135.900,0.02,3.2867,3.28670,10.000
10,136.010,0.02,3.1765,3.17650,10.000
10,136.120,0.02,3.0664,3.06640,10.000
10,136.230,0.00,2.9565,2.95650,10.000
10,136.340,0.01,2.8465,2.84650,10.000
10,136.450,0.01,2.7365,2.73650,10.000
10,136.560,0.00,2.6263,2.62630,10.000
10,136.670,0.00,2.5165,2.51650,10.000
10,136.780,0.01,2.4065,2.40650,10.000
10,136.890,0.00,2.2963,2.29630,10.000
10,137.000,0.00,2.1864,2.18640,10.000
10,137.110,0.00,2.0765,2.07650,10.000
10,137.220,0.00,1.9665,1.96650,10.000
10,137.330,-0.01,1.8563,1.85630,10.000
10,137.440,0.01,1.7463,1.74630,10.000
10,137.550,0.01,1.6365,1.63650,10.000
10,137.660,0.01,1.5264,1.52640,10.000
10,137.770,-0.01,1.4163,1.41630,10.000
10,137.880,0.00,1.3063,1.30630,10.000
10,137.990,0.00,1.1964,1.19640,10.000
10,138.100,-0.01,1.0863,1.08630,10.000
10,138.210,0.01,0.9763,0.97630,10.000
10,138.320,0.00,0.8665,0.86650,10.000
10,138.430,0.00,0.7564,0.75640,10.000
10,138.540,0.00,0.6463,0.64630,10.000
10,138.650,0.00,0.5362,0.53620,10.000
10,138.760,0.00,0.4264,0.42640,10.000
10,138.870,0.00,0.3164,0.31640,10.000
10,138.980,0.00,0.2062,0.20620,10.000
10,139.090,0.00,0.0961,0.09610,10.000
10,139.220,0.01,-0.0338,-0.03380,10.000
10,139.330,-0.01,-0.0039,-0.00390,10.000
10,139.440,0.00,-0.0001,-0.00010,10.000
10,139.550,0.00,-0.0001,-0.00010,10.000
10,139.660,0.00,-0.0001,-0.00010,10.000
10,139.770,0.00,-0.0001,-0.00010,10.000
10,139.880,0.00,-0.0001,-0.00010,10.000
10,139.990,0.00,-0.0001,-0.00010,10.000
10,140.100,0.00,-0.0001,-0.00010,10.000
10,140.210,0.00,-0.0001,-0.00010,10.000
10,140.320,0.00,-0.0001,-0.00010,10.000
10,140.430,0.00,-0.0001,-0.00010,10.000
10,140.540,0.00,-0.0001,-0.00010,10.000
10,140.650,0.01,-0.0001,-0.00010,10.000
10,140.760,0.00,-0.0001,-0.00010,10.000
10,140.870,0.00,-0.0001,-0.00010,10.000
10,140.980,0.00,-0.0001,-0.00010,10.000
10,141.090,0.00,-0.0001,-0.00010,10.000
10,141.200,0.00,-0.0001,-0.00010,10.000
10,141.310,0.00,-0.0001,-0.00010,10.000
10,141.420,0.00,-0.0001,-0.00010,10.000
10,141.530,0.00,-0.0001,-0.00010,10.000
10,141.640,0.00,-0.0001,-0.00010,10.000
10,141.750,0.00,-0.0001,-0.00010,10.000
10,141.860,0.00,-0.0001,-0.00010,10.000
10,141.970,0.00,-0.0001,-0.00010,10.000
10,142.080,0.00,-0.0001,-0.00010,10.000
10,142.190,0.00,-0.0001,-0.00010,10.000
10,142.320,0.00,-0.0001,-0.00010,10.000
10,142.430,0.00,-0.0001,-0.00010,10.000
10,142.540,0.00,-0.0001,-0.00010,10.000
10,142.650,0.00,-0.0001,-0.00010,10.000
10,142.760,0.00,-0.0001,-0.00010,10.000
10,142.870,0.00,-0.0001,-0.00010,10.000
10,142.980,0.00,-0.0001,-0.00010,10.000
10,143.090,0.00,-0.0001,-0.00010,10.000
10,143.200,0.00,-0.0001,-0.00010,10.000
10,143.310,0.00,-0.0001,-0.00010,10.000
10,143.420,0.00,-0.0001,-0.00010,10.000
10,143.530,0.00,-0.0001,-0.00010,10.000
10,143.640,0.00,-0.0001,-0.00010,10.000
10,143.750,0.00,-0.0001,-0.00010,10.000
10,143.860,-0.01,-0.0001,-0.00010,10.000
10,143.970,0.00,-0.0001,-0.00010,10.000
10,144.080,0.00,-0.0001,-0.00010,10.000
10,144.190,0.00,-0.0001,-0.00010,10.000
10,144.300,0.00,-0.0001,-0.00010,10.000
10,144.410,0.00,-0.0001,-0.00010,10.000
10,144.520,0.00,-0.0001,-0.00010,10.000
10,144.630,0.00,-0.0001,-0.00010,10.000
10,144.740,0.00,-0.0001,-0.00010,10.000
10,144.850,0.00,-0.0001,-0.00010,10.000
10,144.960,0.00,-0.0001,-0.00010,10.000
10,145.070,0.00,-0.0001,-0.00010,10.000
10,145.180,0.00,-0.0001,-0.00010,10.000
10,145.280,0.00,-0.0001,-0.00010,10.000