File: calibDATA_loadcell/date_30:1:2018/MTSdata_date_1.30/radhen_10cyc_black_20deg_1mms_1N.txt
""
"Test Method","Radhen_Load_Cntrl_Cmprsn_250N_12-7.msm"
"Sample I. D.","Sample1.mss"
"Specimen Number","17"

"TheCycle_Output ()","_Time (s)","_Load (N)","_Extension (mm)","RealTimeDepth (mm)","CycleNumber ()"

0,0.170,-0.02,0.0000,0.00000,0.000
1,0.280,0.00,0.0586,0.05860,1.000
1,0.380,0.00,0.1587,0.15870,1.000
1,0.480,-0.01,0.2586,0.25860,1.000
1,0.580,-0.01,0.3587,0.35870,1.000
1,0.680,-0.01,0.4588,0.45880,1.000
1,0.780,-0.01,0.5589,0.55890,1.000
1,0.880,-0.01,0.6587,0.65870,1.000
1,0.980,-0.01,0.7587,0.75870,1.000
1,1.080,-0.01,0.8588,0.85880,1.000
1,1.180,-0.01,0.9588,0.95880,1.000
1,1.280,0.00,1.0587,1.05870,1.000
1,1.380,0.00,1.1588,1.15880,1.000
1,1.480,-0.02,1.2588,1.25880,1.000
1,1.580,-0.01,1.3589,1.35890,1.000
1,1.680,-0.01,1.4589,1.45890,1.000
1,1.780,-0.01,1.5589,1.55890,1.000
1,1.880,-0.01,1.6588,1.65880,1.000
1,1.980,-0.01,1.7588,1.75880,1.000
1,2.080,0.00,1.8588,1.85880,1.000
1,2.180,-0.01,1.9589,1.95890,1.000
1,2.280,0.00,2.0589,2.05890,1.000
1,2.380,-0.01,2.1591,2.15910,1.000
1,2.480,0.00,2.2589,2.25890,1.000
1,2.580,-0.01,2.3588,2.35880,1.000
1,2.680,-0.01,2.4588,2.45880,1.000
1,2.780,0.00,2.5590,2.55900,1.000
1,2.880,-0.01,2.6587,2.65870,1.000
1,2.980,0.00,2.7588,2.75880,1.000
1,3.080,-0.01,2.8588,2.85880,1.000
1,3.180,-0.01,2.9589,2.95890,1.000
1,3.280,0.02,3.0588,3.05880,1.000
1,3.380,0.09,3.1589,3.15890,1.000
1,3.480,0.26,3.2589,3.25890,1.000
1,3.580,0.52,3.3590,3.35900,1.000
1,3.680,0.85,3.4589,3.45890,1.000
1,3.790,1.25,3.5381,3.53810,1.000
1,3.890,0.84,3.4495,3.44950,1.000
1,3.990,0.48,3.3497,3.34970,1.000
1,4.090,0.22,3.2495,3.24950,1.000
1,4.190,0.07,3.1496,3.14960,1.000
1,4.290,0.00,3.0494,3.04940,1.000
1,4.390,-0.01,2.9496,2.94960,1.000
1,4.490,0.00,2.8495,2.84950,1.000
1,4.590,-0.01,2.7495,2.74950,1.000
1,4.690,0.00,2.6493,2.64930,1.000
1,4.790,0.00,2.5496,2.54960,1.000
1,4.890,-0.01,2.4494,2.44940,1.000
1,4.990,-0.01,2.3495,2.34950,1.000
1,5.090,-0.01,2.2495,2.24950,1.000
1,5.190,-0.02,2.1497,2.14970,1.000
1,5.290,-0.01,2.0493,2.04930,1.000
1,5.390,-0.01,1.9496,1.94960,1.000
1,5.490,-0.01,1.8494,1.84940,1.000
1,5.590,-0.01,1.7496,1.74960,1.000
1,5.690,-0.01,1.6493,1.64930,1.000
1,5.790,-0.03,1.5494,1.54940,1.000
1,5.890,-0.02,1.4493,1.44930,1.000
1,5.990,0.00,1.3495,1.34950,1.000
1,6.090,0.00,1.2494,1.24940,1.000
1,6.190,-0.01,1.1494,1.14940,1.000
1,6.290,-0.01,1.0492,1.04920,1.000
1,6.390,-0.01,0.9494,0.94940,1.000
1,6.490,0.00,0.8492,0.84920,1.000
1,6.590,0.00,0.7494,0.74940,1.000
1,6.690,-0.01,0.6493,0.64930,1.000
1,6.790,0.00,0.5495,0.54950,1.000
1,6.890,-0.02,0.4494,0.44940,1.000
1,6.990,-0.01,0.3493,0.34930,1.000
1,7.090,0.00,0.2491,0.24910,1.000
1,7.190,-0.01,0.1494,0.14940,1.000
1,7.290,-0.01,0.0493,0.04930,1.000
1,7.400,0.00,-0.0311,-0.03110,1.000
1,7.500,-0.02,-0.0001,-0.00010,1.000
1,7.600,-0.01,-0.0001,-0.00010,1.000
1,7.700,-0.01,-0.0001,-0.00010,1.000
1,7.800,-0.01,-0.0001,-0.00010,1.000
1,7.900,-0.01,-0.0001,-0.00010,1.000
1,8.000,-0.01,-0.0001,-0.00010,1.000
1,8.100,-0.01,-0.0001,-0.00010,1.000
1,8.200,-0.01,-0.0001,-0.00010,1.000
1,8.300,-0.01,-0.0001,-0.00010,1.000
1,8.400,0.00,-0.0001,-0.00010,1.000
1,8.500,-0.02,-0.0001,-0.00010,1.000
1,8.600,-0.01,-0.0001,-0.00010,1.000
1,8.700,0.00,-0.0001,-0.00010,1.000
1,8.800,0.01,-0.0001,-0.00010,1.000
1,8.900,-0.01,-0.0001,-0.00010,1.000
1,9.000,-0.01,-0.0001,-0.00010,1.000
1,9.100,-0.01,-0.0001,-0.00010,1.000
1,9.200,0.01,-0.0001,-0.00010,1.000
1,9.300,-0.01,-0.0001,-0.00010,1.000
1,9.400,0.00,-0.0001,-0.00010,1.000
1,9.500,-0.01,-0.0001,-0.00010,1.000
1,9.600,0.00,-0.0001,-0.00010,1.000
1,9.700,-0.01,-0.0001,-0.00010,1.000
1,9.800,-0.01,-0.0001,-0.00010,1.000
1,9.900,0.01,-0.0001,-0.00010,1.000
1,10.000,-0.02,-0.0001,-0.00010,1.000
1,10.100,0.01,-0.0001,-0.00010,1.000
1,10.200,-0.01,-0.0001,-0.00010,1.000
1,10.300,0.00,-0.0001,-0.00010,1.000
1,10.400,-0.01,-0.0001,-0.00010,1.000
1,10.510,0.00,-0.0001,-0.00010,1.000
1,10.610,-0.01,-0.0001,-0.00010,1.000
1,10.710,-0.03,-0.0001,-0.00010,1.000
1,10.810,0.00,-0.0001,-0.00010,1.000
1,10.910,0.00,-0.0001,-0.00010,1.000
1,11.010,-0.01,-0.0001,-0.00010,1.000
1,11.110,-0.01,-0.0001,-0.00010,1.000
1,11.210,-0.01,-0.0001,-0.00010,1.000
1,11.310,0.00,-0.0001,-0.00010,1.000
1,11.410,-0.01,-0.0001,-0.00010,1.000
1,11.510,-0.01,-0.0001,-0.00010,1.000
1,11.610,0.00,-0.0001,-0.00010,1.000
1,11.710,-0.02,-0.0001,-0.00010,1.000
1,11.810,-0.01,-0.0001,-0.00010,1.000
1,11.910,0.00,-0.0001,-0.00010,1.000
1,12.010,-0.01,-0.0001,-0.00010,1.000
1,12.110,0.00,-0.0001,-0.00010,1.000
1,12.210,0.00,-0.0001,-0.00010,1.000
1,12.310,-0.01,-0.0001,-0.00010,1.000
1,12.410,-0.01,-0.0001,-0.00010,1.000
1,12.510,-0.01,-0.0001,-0.00010,1.000
1,12.610,-0.01,-0.0001,-0.00010,1.000
1,12.710,-0.02,-0.0001,-0.00010,1.000
1,12.810,0.00,-0.0001,-0.00010,1.000
1,12.910,-0.01,-0.0001,-0.00010,1.000
1,13.010,-0.01,-0.0001,-0.00010,1.000
1,13.110,0.00,-0.0001,-0.00010,1.000
1,13.210,0.00,-0.0001,-0.00010,1.000
1,13.310,0.00,-0.0001,-0.00010,1.000
1,13.410,0.00,-0.0001,-0.00010,1.000
2,13.580,0.01,0.0004,0.00040,2.000
2,13.680,0.01,0.0886,0.08860,2.000
2,13.780,0.01,0.1888,0.18880,2.000
2,13.880,0.01,0.2886,0.28860,2.000
2,13.980,0.02,0.3888,0.38880,2.000
2,14.080,0.01,0.4887,0.48870,2.000
2,14.180,0.00,0.5888,0.58880,2.000
2,14.280,0.01,0.6888,0.68880,2.000
2,14.380,0.01,0.7888,0.78880,2.000
2,14.480,0.01,0.8886,0.88860,2.000
2,14.580,0.01,0.9887,0.98870,2.000
2,14.680,0.02,1.0886,1.08860,2.000
2,14.780,0.01,1.1888,1.18880,2.000
2,14.880,0.01,1.2887,1.28870,2.000
2,14.980,0.01,1.3888,1.38880,2.000
2,15.080,0.01,1.4886,1.48860,2.000
2,15.180,0.01,1.5888,1.58880,2.000
2,15.280,0.00,1.6887,1.68870,2.000
2,15.380,0.01,1.7888,1.78880,2.000
2,15.480,0.01,1.8887,1.88870,2.000
2,15.580,0.01,1.9889,1.98890,2.000
2,15.680,0.01,2.0887,2.08870,2.000
2,15.780,0.01,2.1890,2.18900,2.000
2,15.880,0.01,2.2887,2.28870,2.000
2,15.980,0.01,2.3887,2.38870,2.000
2,16.080,0.00,2.4887,2.48870,2.000
2,16.180,0.02,2.5889,2.58890,2.000
2,16.280,0.00,2.6886,2.68860,2.000
2,16.380,0.01,2.7888,2.78880,2.000
2,16.480,0.01,2.8887,2.88870,2.000
2,16.580,0.01,2.9889,2.98890,2.000
2,16.680,0.05,3.0886,3.08860,2.000
2,16.780,0.15,3.1889,3.18890,2.000
2,16.880,0.35,3.2888,3.28880,2.000
2,16.980,0.63,3.3889,3.38890,2.000
2,17.080,1.00,3.4889,3.48890,2.000
2,17.200,1.18,3.5092,3.50920,2.000
2,17.300,0.70,3.4095,3.40950,2.000
2,17.400,0.38,3.3097,3.30970,2.000
2,17.500,0.17,3.2096,3.20960,2.000
2,17.600,0.05,3.1096,3.10960,2.000
2,17.700,0.01,3.0094,3.00940,2.000
2,17.800,0.00,2.9096,2.90960,2.000
2,17.900,0.01,2.8093,2.80930,2.000
2,18.000,0.01,2.7095,2.70950,2.000
2,18.100,0.01,2.6095,2.60950,2.000
2,18.200,0.01,2.5096,2.50960,2.000
2,18.300,0.00,2.4092,2.40920,2.000
2,18.400,0.01,2.3094,2.30940,2.000
2,18.500,0.01,2.2095,2.20950,2.000
2,18.600,0.01,2.1096,2.10960,2.000
2,18.700,0.01,2.0094,2.00940,2.000
2,18.800,0.01,1.9096,1.90960,2.000
2,18.900,0.01,1.8093,1.80930,2.000
2,19.000,0.01,1.7095,1.70950,2.000
2,19.100,0.01,1.6093,1.60930,2.000
2,19.200,0.02,1.5095,1.50950,2.000
2,19.300,0.01,1.4093,1.40930,2.000
2,19.400,0.02,1.3095,1.30950,2.000
2,19.500,0.01,1.2094,1.20940,2.000
2,19.600,0.01,1.1094,1.10940,2.000
2,19.700,0.02,1.0092,1.00920,2.000
2,19.800,0.02,0.9094,0.90940,2.000
2,19.900,0.00,0.8091,0.80910,2.000
2,20.000,0.01,0.7094,0.70940,2.000
2,20.100,0.02,0.6093,0.60930,2.000
2,20.200,0.01,0.5095,0.50950,2.000
2,20.300,0.00,0.4092,0.40920,2.000
2,20.400,0.01,0.3093,0.30930,2.000
2,20.500,0.02,0.2091,0.20910,2.000
2,20.600,0.00,0.1094,0.10940,2.000
2,20.700,0.01,0.0093,0.00930,2.000
2,20.820,0.01,-0.0316,-0.03160,2.000
2,20.920,0.01,-0.0002,-0.00020,2.000
2,21.020,0.01,-0.0002,-0.00020,2.000
2,21.120,0.01,-0.0002,-0.00020,2.000
2,21.220,0.01,-0.0002,-0.00020,2.000
2,21.320,0.01,-0.0002,-0.00020,2.000
2,21.420,0.01,-0.0002,-0.00020,2.000
2,21.520,0.01,-0.0002,-0.00020,2.000
2,21.620,0.01,-0.0002,-0.00020,2.000
2,21.720,0.01,-0.0002,-0.00020,2.000
2,21.820,0.01,-0.0002,-0.00020,2.000
2,21.920,0.01,-0.0002,-0.00020,2.000
2,22.020,0.01,-0.0002,-0.00020,2.000
2,22.120,0.01,-0.0002,-0.00020,2.000
2,22.220,0.01,-0.0002,-0.00020,2.000
2,22.320,0.02,-0.0002,-0.00020,2.000
2,22.420,0.01,-0.0002,-0.00020,2.000
2,22.520,0.00,-0.0002,-0.00020,2.000
2,22.620,0.01,-0.0002,-0.00020,2.000
2,22.720,0.01,-0.0002,-0.00020,2.000
2,22.820,0.01,-0.0002,-0.00020,2.000
2,22.920,0.01,-0.0002,-0.00020,2.000
2,23.020,0.01,-0.0002,-0.00020,2.000
2,23.120,0.01,-0.0002,-0.00020,2.000
2,23.220,0.00,-0.0002,-0.00020,2.000
2,23.320,0.01,-0.0002,-0.00020,2.000
2,23.420,0.01,-0.0002,-0.00020,2.000
2,23.520,0.01,-0.0002,-0.00020,2.000
2,23.620,0.01,-0.0002,-0.00020,2.000
2,23.720,0.02,-0.0002,-0.00020,2.000
2,23.820,0.01,-0.0002,-0.00020,2.000
2,23.920,0.01,-0.0002,-0.00020,2.000
2,24.020,0.01,-0.0002,-0.00020,2.000
2,24.120,0.02,-0.0002,-0.00020,2.000
2,24.220,0.01,-0.0001,-0.00010,2.000
2,24.320,0.01,-0.0001,-0.00010,2.000
2,24.420,0.01,-0.0001,-0.00010,2.000
2,24.520,0.01,-0.0001,-0.00010,2.000
2,24.620,0.01,-0.0001,-0.00010,2.000
2,24.720,0.01,-0.0001,-0.00010,2.000
2,24.820,0.00,-0.0001,-0.00010,2.000
2,24.920,0.02,-0.0001,-0.00010,2.000
2,25.020,0.01,-0.0001,-0.00010,2.000
2,25.120,0.01,-0.0001,-0.00010,2.000
2,25.220,0.02,-0.0001,-0.00010,2.000
2,25.320,0.01,-0.0001,-0.00010,2.000
2,25.420,0.02,-0.0001,-0.00010,2.000
2,25.520,0.01,-0.0001,-0.00010,2.000
2,25.620,0.01,-0.0001,-0.00010,2.000
2,25.720,0.01,-0.0001,-0.00010,2.000
2,25.820,0.01,-0.0001,-0.00010,2.000
2,25.920,0.02,-0.0001,-0.00010,2.000
2,26.020,0.01,-0.0001,-0.00010,2.000
2,26.120,0.01,-0.0001,-0.00010,2.000
2,26.220,0.01,-0.0001,-0.00010,2.000
2,26.320,0.00,-0.0001,-0.00010,2.000
2,26.420,0.00,-0.0001,-0.00010,2.000
2,26.520,0.01,-0.0001,-0.00010,2.000
2,26.620,0.01,-0.0001,-0.00010,2.000
2,26.720,0.01,-0.0001,-0.00010,2.000
2,26.880,0.00,0.0000,0.00000,2.000
3,26.990,0.01,0.0678,0.06780,3.000
3,27.090,0.01,0.1675,0.16750,3.000
3,27.190,0.01,0.2677,0.26770,3.000
3,27.290,0.01,0.3677,0.36770,3.000
3,27.390,0.01,0.4678,0.46780,3.000
3,27.490,0.00,0.5677,0.56770,3.000
3,27.590,0.01,0.6678,0.66780,3.000
3,27.690,0.00,0.7677,0.76770,3.000
3,27.790,-0.01,0.8678,0.86780,3.000
3,27.890,0.00,0.9677,0.96770,3.000
3,27.990,0.01,1.0678,1.06780,3.000
3,28.090,0.00,1.1677,1.16770,3.000
3,28.190,0.01,1.2679,1.26790,3.000
3,28.290,0.01,1.3678,1.36780,3.000
3,28.390,0.00,1.4679,1.46790,3.000
3,28.490,0.01,1.5677,1.56770,3.000
3,28.590,0.01,1.6678,1.66780,3.000
3,28.690,0.01,1.7676,1.76760,3.000
3,28.790,0.00,1.8678,1.86780,3.000
3,28.890,0.01,1.9677,1.96770,3.000
3,28.990,0.01,2.0679,2.06790,3.000
3,29.090,0.01,2.1678,2.16780,3.000
3,29.190,0.00,2.2679,2.26790,3.000
3,29.290,0.01,2.3676,2.36760,3.000
3,29.390,0.01,2.4679,2.46790,3.000
3,29.490,0.00,2.5678,2.56780,3.000
3,29.590,0.01,2.6679,2.66790,3.000
3,29.690,0.01,2.7677,2.76770,3.000
3,29.790,0.01,2.8678,2.86780,3.000
3,29.890,0.00,2.9678,2.96780,3.000
3,29.990,0.03,3.0678,3.06780,3.000
3,30.090,0.11,3.1677,3.16770,3.000
3,30.190,0.29,3.2679,3.26790,3.000
3,30.290,0.55,3.3679,3.36790,3.000
3,30.390,0.90,3.4679,3.46790,3.000
3,30.510,1.31,3.5436,3.54360,3.000
3,30.610,0.86,3.4486,3.44860,3.000
3,30.710,0.48,3.3487,3.34870,3.000
3,30.810,0.23,3.2485,3.24850,3.000
3,30.910,0.08,3.1486,3.14860,3.000
3,31.010,0.01,3.0484,3.04840,3.000
3,31.110,0.01,2.9486,2.94860,3.000
3,31.210,0.00,2.8484,2.84840,3.000
3,31.310,0.01,2.7485,2.74850,3.000
3,31.410,0.00,2.6483,2.64830,3.000
3,31.510,-0.01,2.5486,2.54860,3.000
3,31.610,-0.01,2.4484,2.44840,3.000
3,31.710,0.00,2.3485,2.34850,3.000
3,31.810,0.02,2.2485,2.24850,3.000
3,31.910,0.02,2.1486,2.14860,3.000
3,32.010,0.00,2.0484,2.04840,3.000
3,32.110,0.01,1.9486,1.94860,3.000
3,32.210,0.00,1.8484,1.84840,3.000
3,32.310,0.00,1.7484,1.74840,3.000
3,32.410,0.01,1.6482,1.64820,3.000
3,32.510,0.01,1.5485,1.54850,3.000
3,32.610,0.00,1.4483,1.44830,3.000
3,32.710,0.01,1.3486,1.34860,3.000
3,32.810,0.00,1.2484,1.24840,3.000
3,32.910,0.00,1.1484,1.14840,3.000
3,33.010,0.00,1.0482,1.04820,3.000
3,33.110,0.01,0.9484,0.94840,3.000
3,33.210,0.01,0.8482,0.84820,3.000
3,33.310,-0.01,0.7485,0.74850,3.000
3,33.410,0.00,0.6484,0.64840,3.000
3,33.510,0.00,0.5485,0.54850,3.000
3,33.610,0.00,0.4484,0.44840,3.000
3,33.710,0.00,0.3485,0.34850,3.000
3,33.810,0.00,0.2481,0.24810,3.000
3,33.910,0.01,0.1484,0.14840,3.000
3,34.010,0.00,0.0483,0.04830,3.000
3,34.120,0.01,-0.0420,-0.04200,3.000
3,34.220,0.00,-0.0002,-0.00020,3.000
3,34.320,0.01,-0.0002,-0.00020,3.000
3,34.420,0.00,-0.0002,-0.00020,3.000
3,34.520,0.00,-0.0002,-0.00020,3.000
3,34.620,0.00,-0.0002,-0.00020,3.000
3,34.720,0.00,-0.0002,-0.00020,3.000
3,34.820,0.02,-0.0002,-0.00020,3.000
3,34.920,0.00,-0.0002,-0.00020,3.000
3,35.020,0.00,-0.0002,-0.00020,3.000
3,35.120,0.01,-0.0002,-0.00020,3.000
3,35.220,0.00,-0.0002,-0.00020,3.000
3,35.320,0.00,-0.0002,-0.00020,3.000
3,35.420,0.01,-0.0002,-0.00020,3.000
3,35.520,0.01,-0.0002,-0.00020,3.000
3,35.620,0.01,-0.0002,-0.00020,3.000
3,35.720,-0.01,-0.0002,-0.00020,3.000
3,35.820,0.00,-0.0002,-0.00020,3.000
3,35.920,0.01,-0.0002,-0.00020,3.000
3,36.020,0.00,-0.0002,-0.00020,3.000
3,36.120,0.01,-0.0002,-0.00020,3.000
3,36.220,0.00,-0.0002,-0.00020,3.000
3,36.320,0.01,-0.0002,-0.00020,3.000
3,36.420,0.00,-0.0002,-0.00020,3.000
3,36.520,-0.02,-0.0002,-0.00020,3.000
3,36.620,-0.01,-0.0002,-0.00020,3.000
3,36.720,0.00,-0.0002,-0.00020,3.000
3,36.820,0.00,-0.0002,-0.00020,3.000
3,36.920,0.00,-0.0002,-0.00020,3.000
3,37.020,0.00,-0.0002,-0.00020,3.000
3,37.120,0.00,-0.0001,-0.00010,3.000
3,37.230,0.00,-0.0001,-0.00010,3.000
3,37.330,0.00,-0.0001,-0.00010,3.000
3,37.430,0.00,-0.0001,-0.00010,3.000
3,37.530,-0.01,-0.0001,-0.00010,3.000
3,37.630,0.00,-0.0001,-0.00010,3.000
3,37.730,0.01,-0.0001,-0.00010,3.000
3,37.830,0.01,-0.0001,-0.00010,3.000
3,37.930,0.00,-0.0001,-0.00010,3.000
3,38.030,0.00,-0.0001,-0.00010,3.000
3,38.130,0.00,-0.0001,-0.00010,3.000
3,38.230,-0.01,-0.0001,-0.00010,3.000
3,38.330,0.01,-0.0001,-0.00010,3.000
3,38.430,0.00,-0.0001,-0.00010,3.000
3,38.530,0.00,-0.0001,-0.00010,3.000
3,38.630,0.01,-0.0001,-0.00010,3.000
3,38.730,0.00,-0.0001,-0.00010,3.000
3,38.830,0.00,-0.0001,-0.00010,3.000
3,38.930,0.01,-0.0001,-0.00010,3.000
3,39.030,0.00,-0.0001,-0.00010,3.000
3,39.130,0.00,-0.0001,-0.00010,3.000
3,39.230,0.01,-0.0001,-0.00010,3.000
3,39.330,0.00,-0.0001,-0.00010,3.000
3,39.430,0.00,-0.0001,-0.00010,3.000
3,39.530,0.00,-0.0001,-0.00010,3.000
3,39.630,0.00,-0.0001,-0.00010,3.000
3,39.730,0.00,-0.0001,-0.00010,3.000
3,39.830,0.00,-0.0001,-0.00010,3.000
3,39.930,0.00,-0.0001,-0.00010,3.000
3,40.030,0.00,-0.0001,-0.00010,3.000
3,40.130,0.01,-0.0001,-0.00010,3.000
4,40.330,0.01,0.0156,0.01560,4.000
4,40.430,0.00,0.1157,0.11570,4.000
4,40.530,0.01,0.2157,0.21570,4.000
4,40.630,0.01,0.3158,0.31580,4.000
4,40.730,0.01,0.4157,0.41570,4.000
4,40.830,0.00,0.5159,0.51590,4.000
4,40.930,0.01,0.6157,0.61570,4.000
4,41.030,0.00,0.7159,0.71590,4.000
4,41.130,0.00,0.8157,0.81570,4.000
4,41.230,0.00,0.9158,0.91580,4.000
4,41.330,0.00,1.0157,1.01570,4.000
4,41.430,0.00,1.1158,1.11580,4.000
4,41.530,0.01,1.2158,1.21580,4.000
4,41.630,0.00,1.3158,1.31580,4.000
4,41.730,0.01,1.4157,1.41570,4.000
4,41.830,0.00,1.5159,1.51590,4.000
4,41.930,0.00,1.6157,1.61570,4.000
4,42.030,0.01,1.7159,1.71590,4.000
4,42.130,0.00,1.8157,1.81570,4.000
4,42.230,0.00,1.9159,1.91590,4.000
4,42.330,0.01,2.0158,2.01580,4.000
4,42.430,0.00,2.1160,2.11600,4.000
4,42.530,0.01,2.2160,2.21600,4.000
4,42.630,0.00,2.3158,2.31580,4.000
4,42.730,0.00,2.4156,2.41560,4.000
4,42.830,0.00,2.5160,2.51600,4.000
4,42.930,0.00,2.6157,2.61570,4.000
4,43.030,0.00,2.7159,2.71590,4.000
4,43.130,0.00,2.8158,2.81580,4.000
4,43.230,0.00,2.9158,2.91580,4.000
4,43.330,0.01,3.0158,3.01580,4.000
4,43.430,0.07,3.1159,3.11590,4.000
4,43.530,0.19,3.2158,3.21580,4.000
4,43.630,0.41,3.3160,3.31600,4.000
4,43.730,0.70,3.4159,3.41590,4.000
4,43.840,1.15,3.5253,3.52530,4.000
4,43.940,1.04,3.4863,3.48630,4.000
4,44.040,0.61,3.3867,3.38670,4.000
4,44.140,0.31,3.2866,3.28660,4.000
4,44.240,0.12,3.1867,3.18670,4.000
4,44.340,0.02,3.0864,3.08640,4.000
4,44.440,0.01,2.9865,2.98650,4.000
4,44.540,0.00,2.8865,2.88650,4.000
4,44.640,0.01,2.7865,2.78650,4.000
4,44.740,0.00,2.6865,2.68650,4.000
4,44.840,0.01,2.5866,2.58660,4.000
4,44.940,0.01,2.4865,2.48650,4.000
4,45.040,0.01,2.3864,2.38640,4.000
4,45.140,-0.01,2.2865,2.28650,4.000
4,45.240,0.01,2.1868,2.18680,4.000
4,45.340,0.00,2.0865,2.08650,4.000
4,45.440,0.00,1.9866,1.98660,4.000
4,45.540,0.00,1.8864,1.88640,4.000
4,45.640,0.01,1.7865,1.78650,4.000
4,45.740,0.00,1.6863,1.68630,4.000
4,45.840,0.00,1.5865,1.58650,4.000
4,45.940,0.00,1.4863,1.48630,4.000
4,46.040,0.01,1.3866,1.38660,4.000
4,46.140,0.00,1.2864,1.28640,4.000
4,46.240,0.00,1.1865,1.18650,4.000
4,46.340,0.00,1.0863,1.08630,4.000
4,46.440,0.01,0.9865,0.98650,4.000
4,46.540,0.00,0.8863,0.88630,4.000
4,46.640,0.00,0.7865,0.78650,4.000
4,46.740,0.01,0.6863,0.68630,4.000
4,46.840,0.00,0.5865,0.58650,4.000
4,46.940,0.01,0.4863,0.48630,4.000
4,47.040,0.00,0.3865,0.38650,4.000
4,47.140,0.00,0.2863,0.28630,4.000
4,47.240,0.00,0.1864,0.18640,4.000
4,47.340,0.00,0.0862,0.08620,4.000
4,47.440,0.00,-0.0135,-0.01350,4.000
4,47.550,0.01,-0.0071,-0.00710,4.000
4,47.650,0.00,-0.0002,-0.00020,4.000
4,47.750,0.01,-0.0002,-0.00020,4.000
4,47.850,0.01,-0.0002,-0.00020,4.000
4,47.950,0.00,-0.0002,-0.00020,4.000
4,48.050,0.00,-0.0002,-0.00020,4.000
4,48.150,0.00,-0.0002,-0.00020,4.000
4,48.250,0.01,-0.0002,-0.00020,4.000
4,48.350,0.00,-0.0002,-0.00020,4.000
4,48.450,0.00,-0.0002,-0.00020,4.000
4,48.550,0.00,-0.0002,-0.00020,4.000
4,48.650,0.01,-0.0002,-0.00020,4.000
4,48.750,0.00,-0.0002,-0.00020,4.000
4,48.850,0.01,-0.0002,-0.00020,4.000
4,48.950,0.00,-0.0002,-0.00020,4.000
4,49.050,0.01,-0.0002,-0.00020,4.000
4,49.150,0.00,-0.0002,-0.00020,4.000
4,49.250,0.00,-0.0002,-0.00020,4.000
4,49.350,0.00,-0.0002,-0.00020,4.000
4,49.450,0.01,-0.0002,-0.00020,4.000
4,49.550,-0.01,-0.0002,-0.00020,4.000
4,49.650,0.00,-0.0002,-0.00020,4.000
4,49.750,0.00,-0.0002,-0.00020,4.000
4,49.850,0.00,-0.0002,-0.00020,4.000
4,49.950,0.00,-0.0002,-0.00020,4.000
4,50.050,0.01,-0.0002,-0.00020,4.000
4,50.150,0.00,-0.0002,-0.00020,4.000
4,50.250,0.01,-0.0002,-0.00020,4.000
4,50.350,0.00,-0.0001,-0.00010,4.000
4,50.450,0.00,-0.0001,-0.00010,4.000
4,50.560,0.01,-0.0001,-0.00010,4.000
4,50.660,0.01,-0.0001,-0.00010,4.000
4,50.760,0.00,-0.0001,-0.00010,4.000
4,50.860,0.00,-0.0001,-0.00010,4.000
4,50.960,0.00,-0.0001,-0.00010,4.000
4,51.060,0.00,-0.0001,-0.00010,4.000
4,51.160,0.00,-0.0001,-0.00010,4.000
4,51.260,0.00,-0.0001,-0.00010,4.000
4,51.360,0.00,-0.0001,-0.00010,4.000
4,51.460,0.01,-0.0001,-0.00010,4.000
4,51.560,0.00,-0.0001,-0.00010,4.000
4,51.660,0.00,-0.0001,-0.00010,4.000
4,51.760,0.01,-0.0001,-0.00010,4.000
4,51.860,0.00,-0.0001,-0.00010,4.000
4,51.960,0.00,-0.0001,-0.00010,4.000
4,52.060,0.00,-0.0001,-0.00010,4.000
4,52.160,0.01,-0.0001,-0.00010,4.000
4,52.260,0.01,-0.0001,-0.00010,4.000
4,52.360,0.01,-0.0001,-0.00010,4.000
4,52.460,0.01,-0.0001,-0.00010,4.000
4,52.560,0.00,-0.0001,-0.00010,4.000
4,52.660,0.00,-0.0001,-0.00010,4.000
4,52.760,0.01,-0.0001,-0.00010,4.000
4,52.860,0.00,-0.0001,-0.00010,4.000
4,52.960,0.00,-0.0001,-0.00010,4.000
4,53.060,0.00,-0.0001,-0.00010,4.000
4,53.160,0.00,-0.0001,-0.00010,4.000
4,53.260,0.01,-0.0001,-0.00010,4.000
4,53.360,0.00,-0.0001,-0.00010,4.000
4,53.460,0.00,-0.0001,-0.00010,4.000
5,53.690,0.00,0.0000,0.00000,5.000
5,53.790,0.01,0.0768,0.07680,5.000
5,53.890,0.01,0.1767,0.17670,5.000
5,53.990,0.01,0.2768,0.27680,5.000
5,54.090,0.01,0.3767,0.37670,5.000
5,54.190,0.01,0.4768,0.47680,5.000
5,54.290,0.01,0.5768,0.57680,5.000
5,54.390,0.01,0.6769,0.67690,5.000
5,54.490,0.01,0.7768,0.77680,5.000
5,54.590,0.01,0.8768,0.87680,5.000
5,54.690,0.00,0.9767,0.97670,5.000
5,54.790,0.01,1.0767,1.07670,5.000
5,54.890,0.00,1.1768,1.17680,5.000
5,54.990,0.01,1.2769,1.27690,5.000
5,55.090,0.00,1.3768,1.37680,5.000
5,55.190,0.00,1.4769,1.47690,5.000
5,55.290,0.01,1.5768,1.57680,5.000
5,55.390,0.01,1.6769,1.67690,5.000
5,55.490,0.01,1.7767,1.77670,5.000
5,55.590,-0.01,1.8769,1.87690,5.000
5,55.690,0.01,1.9768,1.97680,5.000
5,55.790,0.00,2.0770,2.07700,5.000
5,55.890,0.00,2.1769,2.17690,5.000
5,55.990,0.00,2.2771,2.27710,5.000
5,56.090,0.01,2.3767,2.37670,5.000
5,56.190,0.01,2.4770,2.47700,5.000
5,56.290,0.00,2.5768,2.57680,5.000
5,56.390,0.01,2.6769,2.67690,5.000
5,56.490,0.01,2.7768,2.77680,5.000
5,56.590,0.01,2.8769,2.87690,5.000
5,56.690,0.00,2.9767,2.97670,5.000
5,56.790,0.03,3.0769,3.07690,5.000
5,56.890,0.13,3.1768,3.17680,5.000
5,56.990,0.31,3.2770,3.27700,5.000
5,57.090,0.57,3.3769,3.37690,5.000
5,57.190,0.93,3.4770,3.47700,5.000
5,57.300,1.16,3.5098,3.50980,5.000
5,57.400,0.70,3.4096,3.40960,5.000
5,57.500,0.37,3.3098,3.30980,5.000
5,57.600,0.16,3.2095,3.20950,5.000
5,57.700,0.05,3.1096,3.10960,5.000
5,57.800,0.01,3.0095,3.00950,5.000
5,57.900,0.01,2.9097,2.90970,5.000
5,58.000,0.00,2.8094,2.80940,5.000
5,58.100,0.00,2.7096,2.70960,5.000
5,58.200,0.01,2.6095,2.60950,5.000
5,58.300,0.00,2.5097,2.50970,5.000
5,58.400,0.01,2.4093,2.40930,5.000
5,58.500,0.01,2.3095,2.30950,5.000
5,58.600,0.01,2.2095,2.20950,5.000
5,58.700,0.00,2.1096,2.10960,5.000
5,58.800,0.00,2.0094,2.00940,5.000
5,58.900,0.00,1.9095,1.90950,5.000
5,59.000,0.00,1.8093,1.80930,5.000
5,59.100,0.00,1.7094,1.70940,5.000
5,59.200,0.00,1.6093,1.60930,5.000
5,59.300,0.01,1.5095,1.50950,5.000
5,59.400,0.00,1.4094,1.40940,5.000
5,59.500,0.01,1.3096,1.30960,5.000
5,59.600,0.00,1.2093,1.20930,5.000
5,59.700,0.00,1.1094,1.10940,5.000
5,59.800,0.00,1.0092,1.00920,5.000
5,59.900,0.01,0.9094,0.90940,5.000
5,60.000,0.01,0.8092,0.80920,5.000
5,60.100,0.00,0.7094,0.70940,5.000
5,60.200,0.01,0.6094,0.60940,5.000
5,60.300,0.00,0.5095,0.50950,5.000
5,60.400,0.00,0.4092,0.40920,5.000
5,60.500,0.00,0.3094,0.30940,5.000
5,60.600,0.00,0.2091,0.20910,5.000
5,60.700,0.01,0.1094,0.10940,5.000
5,60.800,0.01,0.0093,0.00930,5.000
5,60.910,0.01,-0.0215,-0.02150,5.000
5,61.010,-0.01,-0.0002,-0.00020,5.000
5,61.110,0.01,-0.0002,-0.00020,5.000
5,61.210,0.00,-0.0002,-0.00020,5.000
5,61.310,0.01,-0.0002,-0.00020,5.000
5,61.410,0.01,-0.0002,-0.00020,5.000
5,61.510,0.00,-0.0002,-0.00020,5.000
5,61.610,0.00,-0.0002,-0.00020,5.000
5,61.710,0.00,-0.0002,-0.00020,5.000
5,61.810,0.00,-0.0002,-0.00020,5.000
5,61.910,0.00,-0.0002,-0.00020,5.000
5,62.010,0.01,-0.0002,-0.00020,5.000
5,62.110,0.00,-0.0002,-0.00020,5.000
5,62.210,0.01,-0.0002,-0.00020,5.000
5,62.310,0.00,-0.0002,-0.00020,5.000
5,62.410,0.01,-0.0002,-0.00020,5.000
5,62.510,-0.01,-0.0002,-0.00020,5.000
5,62.610,0.01,-0.0002,-0.00020,5.000
5,62.710,0.01,-0.0002,-0.00020,5.000
5,62.810,0.01,-0.0002,-0.00020,5.000
5,62.910,0.00,-0.0002,-0.00020,5.000
5,63.010,-0.01,-0.0002,-0.00020,5.000
5,63.110,0.01,-0.0002,-0.00020,5.000
5,63.210,0.00,-0.0002,-0.00020,5.000
5,63.310,0.01,-0.0001,-0.00010,5.000
5,63.410,0.02,-0.0001,-0.00010,5.000
5,63.510,0.00,-0.0001,-0.00010,5.000
5,63.610,0.00,-0.0001,-0.00010,5.000
5,63.710,0.00,-0.0001,-0.00010,5.000
5,63.810,0.01,-0.0001,-0.00010,5.000
5,63.920,0.00,-0.0001,-0.00010,5.000
5,64.020,0.01,-0.0001,-0.00010,5.000
5,64.120,0.00,-0.0001,-0.00010,5.000
5,64.220,0.00,-0.0001,-0.00010,5.000
5,64.320,0.00,-0.0001,-0.00010,5.000
5,64.420,0.01,-0.0001,-0.00010,5.000
5,64.520,0.01,-0.0001,-0.00010,5.000
5,64.620,0.00,-0.0001,-0.00010,5.000
5,64.720,0.01,-0.0001,-0.00010,5.000
5,64.820,0.01,-0.0001,-0.00010,5.000
5,64.920,0.00,-0.0001,-0.00010,5.000
5,65.020,0.01,-0.0001,-0.00010,5.000
5,65.120,0.01,-0.0001,-0.00010,5.000
5,65.220,-0.01,-0.0001,-0.00010,5.000
5,65.320,-0.01,-0.0001,-0.00010,5.000
5,65.420,0.00,-0.0001,-0.00010,5.000
5,65.520,-0.01,-0.0001,-0.00010,5.000
5,65.620,0.01,-0.0001,-0.00010,5.000
5,65.720,0.01,-0.0001,-0.00010,5.000
5,65.820,0.00,-0.0001,-0.00010,5.000
5,65.920,0.01,-0.0001,-0.00010,5.000
5,66.020,0.00,-0.0001,-0.00010,5.000
5,66.120,0.01,-0.0001,-0.00010,5.000
5,66.220,-0.01,-0.0001,-0.00010,5.000
5,66.320,0.01,-0.0001,-0.00010,5.000
5,66.420,0.01,-0.0001,-0.00010,5.000
5,66.520,0.00,-0.0001,-0.00010,5.000
5,66.620,0.01,-0.0001,-0.00010,5.000
5,66.720,0.01,-0.0001,-0.00010,5.000
5,66.820,0.00,-0.0001,-0.00010,5.000
5,66.920,0.01,-0.0001,-0.00010,5.000
6,67.140,0.00,0.0677,0.06770,6.000
6,67.240,0.00,0.1675,0.16750,6.000
6,67.340,0.00,0.2677,0.26770,6.000
6,67.440,0.00,0.3676,0.36760,6.000
6,67.540,0.00,0.4678,0.46780,6.000
6,67.640,0.00,0.5677,0.56770,6.000
6,67.740,0.01,0.6679,0.66790,6.000
6,67.840,0.00,0.7676,0.76760,6.000
6,67.940,-0.01,0.8677,0.86770,6.000
6,68.040,0.00,0.9676,0.96760,6.000
6,68.140,-0.01,1.0677,1.06770,6.000
6,68.240,0.00,1.1678,1.16780,6.000
6,68.340,0.00,1.2678,1.26780,6.000
6,68.440,0.00,1.3677,1.36770,6.000
6,68.540,0.01,1.4678,1.46780,6.000
6,68.640,0.00,1.5676,1.56760,6.000
6,68.740,0.00,1.6677,1.66770,6.000
6,68.840,0.00,1.7676,1.76760,6.000
6,68.940,0.00,1.8677,1.86770,6.000
6,69.040,0.01,1.9677,1.96770,6.000
6,69.140,0.00,2.0679,2.06790,6.000
6,69.240,0.00,2.1679,2.16790,6.000
6,69.340,0.00,2.2680,2.26800,6.000
6,69.440,0.00,2.3676,2.36760,6.000
6,69.540,0.00,2.4679,2.46790,6.000
6,69.640,-0.01,2.5678,2.56780,6.000
6,69.740,0.00,2.6678,2.66780,6.000
6,69.840,0.00,2.7677,2.76770,6.000
6,69.940,0.00,2.8679,2.86790,6.000
6,70.040,-0.01,2.9677,2.96770,6.000
6,70.140,0.01,3.0678,3.06780,6.000
6,70.240,0.11,3.1677,3.16770,6.000
6,70.340,0.27,3.2678,3.26780,6.000
6,70.440,0.54,3.3678,3.36780,6.000
6,70.540,0.89,3.4679,3.46790,6.000
6,70.650,1.20,3.5210,3.52100,6.000
6,70.750,0.75,3.4226,3.42260,6.000
6,70.850,0.40,3.3227,3.32270,6.000
6,70.950,0.18,3.2226,3.22260,6.000
6,71.050,0.06,3.1225,3.12250,6.000
6,71.150,0.00,3.0225,3.02250,6.000
6,71.250,0.00,2.9226,2.92260,6.000
6,71.350,0.00,2.8226,2.82260,6.000
6,71.450,-0.01,2.7224,2.72240,6.000
6,71.550,0.00,2.6224,2.62240,6.000
6,71.650,-0.01,2.5226,2.52260,6.000
6,71.750,-0.01,2.4224,2.42240,6.000
6,71.850,0.00,2.3224,2.32240,6.000
6,71.950,0.00,2.2227,2.22270,6.000
6,72.050,0.00,2.1226,2.12260,6.000
6,72.150,0.00,2.0225,2.02250,6.000
6,72.250,-0.01,1.9225,1.92250,6.000
6,72.350,0.00,1.8225,1.82250,6.000
6,72.450,0.00,1.7224,1.72240,6.000
6,72.550,0.00,1.6224,1.62240,6.000
6,72.650,0.00,1.5224,1.52240,6.000
6,72.750,0.00,1.4225,1.42250,6.000
6,72.850,-0.01,1.3226,1.32260,6.000
6,72.950,0.00,1.2225,1.22250,6.000
6,73.050,0.00,1.1224,1.12240,6.000
6,73.150,-0.01,1.0224,1.02240,6.000
6,73.250,0.00,0.9223,0.92230,6.000
6,73.350,0.00,0.8224,0.82240,6.000
6,73.450,0.00,0.7223,0.72230,6.000
6,73.550,-0.01,0.6224,0.62240,6.000
6,73.650,0.00,0.5224,0.52240,6.000
6,73.750,0.00,0.4224,0.42240,6.000
6,73.850,0.01,0.3223,0.32230,6.000
6,73.950,0.00,0.2223,0.22230,6.000
6,74.050,0.01,0.1224,0.12240,6.000
6,74.150,-0.01,0.0224,0.02240,6.000
6,74.270,0.00,-0.0389,-0.03890,6.000
6,74.370,0.01,-0.0002,-0.00020,6.000
6,74.470,0.00,-0.0002,-0.00020,6.000
6,74.570,0.00,-0.0002,-0.00020,6.000
6,74.670,0.00,-0.0002,-0.00020,6.000
6,74.770,0.00,-0.0002,-0.00020,6.000
6,74.870,0.00,-0.0002,-0.00020,6.000
6,74.970,0.00,-0.0002,-0.00020,6.000
6,75.070,0.00,-0.0002,-0.00020,6.000
6,75.170,0.01,-0.0002,-0.00020,6.000
6,75.270,0.00,-0.0002,-0.00020,6.000
6,75.370,0.00,-0.0002,-0.00020,6.000
6,75.470,0.00,-0.0002,-0.00020,6.000
6,75.570,0.01,-0.0002,-0.00020,6.000
6,75.670,0.00,-0.0002,-0.00020,6.000
6,75.770,0.00,-0.0002,-0.00020,6.000
6,75.870,0.00,-0.0002,-0.00020,6.000
6,75.970,0.00,-0.0002,-0.00020,6.000
6,76.070,0.01,-0.0002,-0.00020,6.000
6,76.170,0.01,-0.0002,-0.00020,6.000
6,76.270,0.01,-0.0002,-0.00020,6.000
6,76.370,0.00,-0.0002,-0.00020,6.000
6,76.470,0.00,-0.0002,-0.00020,6.000
6,76.570,0.00,-0.0002,-0.00020,6.000
6,76.670,0.01,-0.0002,-0.00020,6.000
6,76.770,0.01,-0.0002,-0.00020,6.000
6,76.870,0.00,-0.0002,-0.00020,6.000
6,76.970,0.00,-0.0002,-0.00020,6.000
6,77.070,0.00,-0.0001,-0.00010,6.000
6,77.170,0.00,-0.0001,-0.00010,6.000
6,77.270,0.01,-0.0001,-0.00010,6.000
6,77.390,0.00,-0.0001,-0.00010,6.000
6,77.490,0.00,-0.0001,-0.00010,6.000
6,77.590,0.00,-0.0001,-0.00010,6.000
6,77.690,0.00,-0.0001,-0.00010,6.000
6,77.790,-0.02,-0.0001,-0.00010,6.000
6,77.890,-0.01,-0.0001,-0.00010,6.000
6,77.990,-0.01,-0.0001,-0.00010,6.000
6,78.090,-0.01,-0.0001,-0.00010,6.000
6,78.190,0.00,-0.0001,-0.00010,6.000
6,78.290,-0.01,-0.0001,-0.00010,6.000
6,78.390,0.00,-0.0001,-0.00010,6.000
6,78.490,0.00,-0.0001,-0.00010,6.000
6,78.590,0.00,-0.0001,-0.00010,6.000
6,78.690,-0.01,-0.0001,-0.00010,6.000
6,78.790,0.01,-0.0001,-0.00010,6.000
6,78.890,0.00,-0.0001,-0.00010,6.000
6,78.990,0.00,-0.0001,-0.00010,6.000
6,79.090,0.00,-0.0001,-0.00010,6.000
6,79.190,0.00,-0.0001,-0.00010,6.000
6,79.290,0.01,-0.0001,-0.00010,6.000
6,79.390,0.00,-0.0001,-0.00010,6.000
6,79.490,0.01,-0.0001,-0.00010,6.000
6,79.590,0.00,-0.0001,-0.00010,6.000
6,79.690,0.01,-0.0001,-0.00010,6.000
6,79.790,0.00,-0.0001,-0.00010,6.000
6,79.890,-0.01,-0.0001,-0.00010,6.000
6,79.990,-0.01,-0.0001,-0.00010,6.000
6,80.090,0.01,-0.0001,-0.00010,6.000
6,80.190,0.01,-0.0001,-0.00010,6.000
6,80.290,0.01,-0.0001,-0.00010,6.000
7,80.480,0.02,0.0476,0.04760,7.000
7,80.580,0.01,0.1477,0.14770,7.000
7,80.680,0.00,0.2476,0.24760,7.000
7,80.780,0.00,0.3478,0.34780,7.000
7,80.880,0.02,0.4476,0.44760,7.000
7,80.980,0.01,0.5478,0.54780,7.000
7,81.080,0.01,0.6477,0.64770,7.000
7,81.180,0.01,0.7477,0.74770,7.000
7,81.280,0.01,0.8477,0.84770,7.000
7,81.380,0.01,0.9478,0.94780,7.000
7,81.480,0.02,1.0475,1.04750,7.000
7,81.580,0.01,1.1478,1.14780,7.000
7,81.680,0.01,1.2477,1.24770,7.000
7,81.780,0.02,1.3478,1.34780,7.000
7,81.880,0.01,1.4477,1.44770,7.000
7,81.980,0.01,1.5478,1.54780,7.000
7,82.080,0.02,1.6477,1.64770,7.000
7,82.180,0.01,1.7477,1.74770,7.000
7,82.280,-0.01,1.8477,1.84770,7.000
7,82.380,0.00,1.9479,1.94790,7.000
7,82.480,0.01,2.0478,2.04780,7.000
7,82.580,0.01,2.1480,2.14800,7.000
7,82.680,0.01,2.2479,2.24790,7.000
7,82.780,0.01,2.3478,2.34780,7.000
7,82.880,0.01,2.4478,2.44780,7.000
7,82.980,0.01,2.5479,2.54790,7.000
7,83.080,0.01,2.6477,2.64770,7.000
7,83.180,0.02,2.7478,2.74780,7.000
7,83.280,0.00,2.8478,2.84780,7.000
7,83.380,0.02,2.9479,2.94790,7.000
7,83.480,0.01,3.0477,3.04770,7.000
7,83.580,0.10,3.1479,3.14790,7.000
7,83.680,0.26,3.2478,3.24780,7.000
7,83.780,0.49,3.3479,3.34790,7.000
7,83.880,0.83,3.4478,3.44780,7.000
7,84.000,1.26,3.5370,3.53700,7.000
7,84.100,0.86,3.4485,3.44850,7.000
7,84.200,0.50,3.3488,3.34880,7.000
7,84.300,0.23,3.2487,3.24870,7.000
7,84.400,0.09,3.1486,3.14860,7.000
7,84.500,0.01,3.0484,3.04840,7.000
7,84.600,0.01,2.9485,2.94850,7.000
7,84.700,0.01,2.8485,2.84850,7.000
7,84.800,-0.01,2.7485,2.74850,7.000
7,84.900,0.01,2.6484,2.64840,7.000
7,85.000,0.00,2.5487,2.54870,7.000
7,85.100,0.01,2.4484,2.44840,7.000
7,85.200,0.02,2.3485,2.34850,7.000
7,85.300,0.02,2.2486,2.24860,7.000
7,85.400,0.01,2.1486,2.14860,7.000
7,85.500,0.01,2.0485,2.04850,7.000
7,85.600,0.01,1.9485,1.94850,7.000
7,85.700,0.02,1.8484,1.84840,7.000
7,85.800,0.01,1.7485,1.74850,7.000
7,85.900,0.01,1.6483,1.64830,7.000
7,86.000,0.01,1.5484,1.54840,7.000
7,86.100,0.01,1.4484,1.44840,7.000
7,86.200,0.01,1.3485,1.34850,7.000
7,86.300,0.00,1.2484,1.24840,7.000
7,86.400,0.02,1.1484,1.14840,7.000
7,86.500,0.00,1.0483,1.04830,7.000
7,86.600,0.01,0.9485,0.94850,7.000
7,86.700,0.01,0.8483,0.84830,7.000
7,86.800,0.00,0.7485,0.74850,7.000
7,86.900,0.01,0.6483,0.64830,7.000
7,87.000,0.01,0.5486,0.54860,7.000
7,87.100,0.01,0.4483,0.44830,7.000
7,87.200,0.02,0.3484,0.34840,7.000
7,87.300,0.01,0.2481,0.24810,7.000
7,87.400,0.00,0.1484,0.14840,7.000
7,87.500,0.01,0.0483,0.04830,7.000
7,87.620,0.01,-0.0519,-0.05190,7.000
7,87.720,0.01,0.0003,0.00030,7.000
7,87.820,0.01,-0.0002,-0.00020,7.000
7,87.920,0.02,-0.0002,-0.00020,7.000
7,88.020,0.01,-0.0002,-0.00020,7.000
7,88.120,0.02,-0.0002,-0.00020,7.000
7,88.220,0.01,-0.0002,-0.00020,7.000
7,88.320,0.00,-0.0002,-0.00020,7.000
7,88.420,0.01,-0.0002,-0.00020,7.000
7,88.520,0.00,-0.0002,-0.00020,7.000
7,88.620,0.01,-0.0002,-0.00020,7.000
7,88.720,0.02,-0.0002,-0.00020,7.000
7,88.820,0.00,-0.0002,-0.00020,7.000
7,88.920,0.02,-0.0002,-0.00020,7.000
7,89.020,0.00,-0.0002,-0.00020,7.000
7,89.120,0.01,-0.0002,-0.00020,7.000
7,89.220,0.02,-0.0002,-0.00020,7.000
7,89.320,0.00,-0.0001,-0.00010,7.000
7,89.420,0.00,-0.0001,-0.00010,7.000
7,89.520,0.02,-0.0001,-0.00010,7.000
7,89.620,0.01,-0.0001,-0.00010,7.000
7,89.720,0.02,-0.0001,-0.00010,7.000
7,89.820,0.02,-0.0001,-0.00010,7.000
7,89.920,0.00,-0.0001,-0.00010,7.000
7,90.020,0.01,-0.0001,-0.00010,7.000
7,90.120,0.01,-0.0001,-0.00010,7.000
7,90.220,0.00,-0.0001,-0.00010,7.000
7,90.320,0.01,-0.0001,-0.00010,7.000
7,90.420,0.01,-0.0001,-0.00010,7.000
7,90.520,0.01,-0.0001,-0.00010,7.000
7,90.620,0.00,-0.0001,-0.00010,7.000
7,90.730,0.01,-0.0001,-0.00010,7.000
7,90.830,0.01,-0.0001,-0.00010,7.000
7,90.930,0.00,-0.0001,-0.00010,7.000
7,91.030,0.01,-0.0001,-0.00010,7.000
7,91.130,0.01,-0.0001,-0.00010,7.000
7,91.230,0.01,-0.0001,-0.00010,7.000
7,91.330,0.01,-0.0001,-0.00010,7.000
7,91.430,0.01,-0.0001,-0.00010,7.000
7,91.530,0.02,-0.0001,-0.00010,7.000
7,91.630,0.02,-0.0001,-0.00010,7.000
7,91.730,0.01,-0.0001,-0.00010,7.000
7,91.830,0.00,-0.0001,-0.00010,7.000
7,91.930,0.01,-0.0001,-0.00010,7.000
7,92.030,0.01,-0.0001,-0.00010,7.000
7,92.130,0.01,-0.0001,-0.00010,7.000
7,92.230,0.02,-0.0001,-0.00010,7.000
7,92.330,0.01,-0.0001,-0.00010,7.000
7,92.430,0.01,-0.0001,-0.00010,7.000
7,92.530,0.02,-0.0001,-0.00010,7.000
7,92.630,0.02,-0.0001,-0.00010,7.000
7,92.730,0.00,-0.0001,-0.00010,7.000
7,92.830,0.02,-0.0001,-0.00010,7.000
7,92.930,0.01,-0.0001,-0.00010,7.000
7,93.030,0.02,-0.0001,-0.00010,7.000
7,93.130,0.01,-0.0001,-0.00010,7.000
7,93.230,0.01,-0.0001,-0.00010,7.000
7,93.330,0.01,-0.0001,-0.00010,7.000
7,93.430,0.01,-0.0001,-0.00010,7.000
7,93.530,0.01,-0.0001,-0.00010,7.000
7,93.630,0.01,-0.0001,-0.00010,7.000
8,93.850,-0.01,0.0386,0.03860,8.000
8,93.950,0.00,0.1386,0.13860,8.000
8,94.050,-0.01,0.2387,0.23870,8.000
8,94.150,-0.01,0.3387,0.33870,8.000
8,94.250,0.00,0.4387,0.43870,8.000
8,94.350,-0.01,0.5388,0.53880,8.000
8,94.450,0.00,0.6389,0.63890,8.000
8,94.550,-0.01,0.7387,0.73870,8.000
8,94.650,-0.01,0.8388,0.83880,8.000
8,94.750,0.01,0.9388,0.93880,8.000
8,94.850,0.00,1.0388,1.03880,8.000
8,94.950,0.00,1.1387,1.13870,8.000
8,95.050,-0.01,1.2389,1.23890,8.000
8,95.150,-0.01,1.3387,1.33870,8.000
8,95.250,0.00,1.4388,1.43880,8.000
8,95.350,0.00,1.5388,1.53880,8.000
8,95.450,0.00,1.6389,1.63890,8.000
8,95.550,-0.01,1.7388,1.73880,8.000
8,95.650,-0.01,1.8388,1.83880,8.000
8,95.750,0.00,1.9388,1.93880,8.000
8,95.850,0.00,2.0388,2.03880,8.000
8,95.950,-0.01,2.1389,2.13890,8.000
8,96.050,-0.02,2.2390,2.23900,8.000
8,96.150,0.00,2.3385,2.33850,8.000
8,96.250,-0.01,2.4389,2.43890,8.000
8,96.350,-0.01,2.5387,2.53870,8.000
8,96.450,0.01,2.6388,2.63880,8.000
8,96.550,-0.01,2.7387,2.73870,8.000
8,96.650,0.00,2.8388,2.83880,8.000
8,96.750,0.00,2.9387,2.93870,8.000
8,96.850,0.01,3.0389,3.03890,8.000
8,96.950,0.07,3.1387,3.13870,8.000
8,97.050,0.23,3.2388,3.23880,8.000
8,97.150,0.46,3.3388,3.33880,8.000
8,97.250,0.77,3.4389,3.43890,8.000
8,97.360,1.21,3.5312,3.53120,8.000
8,97.460,0.86,3.4535,3.45350,8.000
8,97.560,0.48,3.3537,3.35370,8.000
8,97.660,0.23,3.2535,3.25350,8.000
8,97.760,0.08,3.1535,3.15350,8.000
8,97.860,-0.01,3.0535,3.05350,8.000
8,97.960,-0.02,2.9536,2.95360,8.000
8,98.060,0.00,2.8535,2.85350,8.000
8,98.160,0.00,2.7535,2.75350,8.000
8,98.260,-0.02,2.6534,2.65340,8.000
8,98.360,0.01,2.5537,2.55370,8.000
8,98.460,-0.02,2.4533,2.45330,8.000
8,98.560,0.00,2.3533,2.35330,8.000
8,98.660,0.00,2.2534,2.25340,8.000
8,98.760,-0.01,2.1537,2.15370,8.000
8,98.860,0.00,2.0534,2.05340,8.000
8,98.960,-0.01,1.9536,1.95360,8.000
8,99.060,-0.01,1.8533,1.85330,8.000
8,99.160,-0.01,1.7535,1.75350,8.000
8,99.260,-0.01,1.6533,1.65330,8.000
8,99.360,-0.01,1.5535,1.55350,8.000
8,99.460,-0.01,1.4534,1.45340,8.000
8,99.560,0.00,1.3536,1.35360,8.000
8,99.660,-0.01,1.2534,1.25340,8.000
8,99.760,-0.01,1.1534,1.15340,8.000
8,99.860,0.00,1.0532,1.05320,8.000
8,99.960,0.00,0.9535,0.95350,8.000
8,100.060,0.00,0.8532,0.85320,8.000
8,100.160,-0.01,0.7534,0.75340,8.000
8,100.260,-0.01,0.6533,0.65330,8.000
8,100.360,-0.01,0.5535,0.55350,8.000
8,100.460,-0.01,0.4532,0.45320,8.000
8,100.560,-0.01,0.3534,0.35340,8.000
8,100.660,-0.01,0.2531,0.25310,8.000
8,100.760,0.00,0.1534,0.15340,8.000
8,100.860,-0.02,0.0533,0.05330,8.000
8,100.980,-0.01,-0.0558,-0.05580,8.000
8,101.080,-0.02,0.0001,0.00010,8.000
8,101.180,-0.01,-0.0002,-0.00020,8.000
8,101.280,0.00,-0.0002,-0.00020,8.000
8,101.380,-0.01,-0.0002,-0.00020,8.000
8,101.480,0.00,-0.0002,-0.00020,8.000
8,101.580,-0.01,-0.0002,-0.00020,8.000
8,101.680,0.00,-0.0002,-0.00020,8.000
8,101.780,-0.01,-0.0002,-0.00020,8.000
8,101.880,-0.01,-0.0002,-0.00020,8.000
8,101.980,-0.01,-0.0002,-0.00020,8.000
8,102.080,-0.01,-0.0002,-0.00020,8.000
8,102.180,0.00,-0.0002,-0.00020,8.000
8,102.280,-0.01,-0.0002,-0.00020,8.000
8,102.380,-0.01,-0.0002,-0.00020,8.000
8,102.480,0.00,-0.0002,-0.00020,8.000
8,102.580,-0.01,-0.0002,-0.00020,8.000
8,102.680,0.00,-0.0002,-0.00020,8.000
8,102.780,-0.01,-0.0002,-0.00020,8.000
8,102.880,-0.01,-0.0001,-0.00010,8.000
8,102.980,0.00,-0.0001,-0.00010,8.000
8,103.080,0.00,-0.0001,-0.00010,8.000
8,103.180,-0.01,-0.0001,-0.00010,8.000
8,103.280,0.00,-0.0001,-0.00010,8.000
8,103.380,-0.01,-0.0001,-0.00010,8.000
8,103.480,-0.01,-0.0001,-0.00010,8.000
8,103.580,0.00,-0.0001,-0.00010,8.000
8,103.680,-0.01,-0.0001,-0.00010,8.000
8,103.780,-0.01,-0.0001,-0.00010,8.000
8,103.880,-0.01,-0.0001,-0.00010,8.000
8,103.980,0.00,-0.0001,-0.00010,8.000
8,104.100,-0.01,-0.0001,-0.00010,8.000
8,104.200,-0.01,-0.0001,-0.00010,8.000
8,104.300,-0.01,-0.0001,-0.00010,8.000
8,104.400,0.00,-0.0001,-0.00010,8.000
8,104.500,-0.01,-0.0001,-0.00010,8.000
8,104.600,-0.01,-0.0001,-0.00010,8.000
8,104.700,-0.01,-0.0001,-0.00010,8.000
8,104.800,-0.02,-0.0001,-0.00010,8.000
8,104.900,0.00,-0.0001,-0.00010,8.000
8,105.000,0.00,-0.0001,-0.00010,8.000
8,105.100,0.00,-0.0001,-0.00010,8.000
8,105.200,-0.01,-0.0001,-0.00010,8.000
8,105.300,-0.01,-0.0001,-0.00010,8.000
8,105.400,0.00,-0.0001,-0.00010,8.000
8,105.500,0.00,-0.0001,-0.00010,8.000
8,105.600,0.00,-0.0001,-0.00010,8.000
8,105.700,-0.01,-0.0001,-0.00010,8.000
8,105.800,-0.01,-0.0001,-0.00010,8.000
8,105.900,0.00,-0.0001,-0.00010,8.000
8,106.000,-0.01,-0.0001,-0.00010,8.000
8,106.100,0.00,-0.0001,-0.00010,8.000
8,106.200,0.00,-0.0001,-0.00010,8.000
8,106.300,0.00,-0.0001,-0.00010,8.000
8,106.400,0.00,-0.0001,-0.00010,8.000
8,106.500,-0.01,-0.0001,-0.00010,8.000
8,106.600,-0.01,-0.0001,-0.00010,8.000
8,106.700,0.00,-0.0001,-0.00010,8.000
8,106.800,-0.01,-0.0001,-0.00010,8.000
8,106.900,0.00,-0.0001,-0.00010,8.000
8,107.000,0.00,-0.0001,-0.00010,8.000
9,107.210,0.00,0.0173,0.01730,9.000
9,107.310,0.01,0.1176,0.11760,9.000
9,107.410,0.01,0.2177,0.21770,9.000
9,107.510,0.01,0.3177,0.31770,9.000
9,107.610,0.00,0.4176,0.41760,9.000
9,107.710,0.00,0.5179,0.51790,9.000
9,107.810,0.01,0.6177,0.61770,9.000
9,107.910,0.00,0.7178,0.71780,9.000
9,108.010,0.01,0.8177,0.81770,9.000
9,108.110,0.02,0.9179,0.91790,9.000
9,108.210,0.01,1.0177,1.01770,9.000
9,108.310,0.01,1.1178,1.11780,9.000
9,108.410,0.00,1.2177,1.21770,9.000
9,108.510,0.00,1.3179,1.31790,9.000
9,108.610,0.01,1.4178,1.41780,9.000
9,108.710,0.02,1.5178,1.51780,9.000
9,108.810,0.00,1.6176,1.61760,9.000
9,108.910,0.01,1.7179,1.71790,9.000
9,109.010,0.00,1.8177,1.81770,9.000
9,109.110,-0.01,1.9178,1.91780,9.000
9,109.210,0.01,2.0178,2.01780,9.000
9,109.310,0.01,2.1180,2.11800,9.000
9,109.410,0.00,2.2179,2.21790,9.000
9,109.510,0.00,2.3178,2.31780,9.000
9,109.610,0.01,2.4176,2.41760,9.000
9,109.710,-0.01,2.5179,2.51790,9.000
9,109.810,0.00,2.6178,2.61780,9.000
9,109.910,0.00,2.7179,2.71790,9.000
9,110.010,0.01,2.8177,2.81770,9.000
9,110.110,-0.01,2.9179,2.91790,9.000
9,110.210,0.00,3.0178,3.01780,9.000
9,110.310,0.07,3.1179,3.11790,9.000
9,110.410,0.19,3.2178,3.21780,9.000
9,110.510,0.41,3.3179,3.31790,9.000
9,110.610,0.73,3.4178,3.41780,9.000
9,110.720,1.18,3.5242,3.52420,9.000
9,110.820,0.98,3.4726,3.47260,9.000
9,110.920,0.57,3.3726,3.37260,9.000
9,111.020,0.28,3.2727,3.27270,9.000
9,111.120,0.10,3.1724,3.17240,9.000
9,111.220,0.02,3.0725,3.07250,9.000
9,111.320,-0.01,2.9724,2.97240,9.000
9,111.420,0.00,2.8726,2.87260,9.000
9,111.520,0.00,2.7723,2.77230,9.000
9,111.620,0.01,2.6724,2.67240,9.000
9,111.720,0.01,2.5726,2.57260,9.000
9,111.820,0.01,2.4726,2.47260,9.000
9,111.920,0.01,2.3722,2.37220,9.000
9,112.020,0.01,2.2727,2.27270,9.000
9,112.120,0.01,2.1725,2.17250,9.000
9,112.220,0.00,2.0726,2.07260,9.000
9,112.320,0.00,1.9724,1.97240,9.000
9,112.420,0.00,1.8726,1.87260,9.000
9,112.520,0.00,1.7722,1.77220,9.000
9,112.620,-0.01,1.6725,1.67250,9.000
9,112.720,0.00,1.5724,1.57240,9.000
9,112.820,0.01,1.4725,1.47250,9.000
9,112.920,0.00,1.3723,1.37230,9.000
9,113.020,0.01,1.2725,1.27250,9.000
9,113.120,0.00,1.1723,1.17230,9.000
9,113.220,0.00,1.0724,1.07240,9.000
9,113.320,0.00,0.9722,0.97220,9.000
9,113.420,0.01,0.8723,0.87230,9.000
9,113.520,0.00,0.7722,0.77220,9.000
9,113.620,0.01,0.6725,0.67250,9.000
9,113.720,0.00,0.5723,0.57230,9.000
9,113.820,0.00,0.4724,0.47240,9.000
9,113.920,-0.01,0.3722,0.37220,9.000
9,114.020,0.00,0.2724,0.27240,9.000
9,114.120,0.01,0.1722,0.17220,9.000
9,114.220,0.01,0.0724,0.07240,9.000
9,114.340,0.01,-0.0468,-0.04681,9.000
9,114.440,0.01,-0.0088,-0.00880,9.000
9,114.540,-0.02,-0.0002,-0.00020,9.000
9,114.640,0.01,-0.0002,-0.00020,9.000
9,114.740,0.01,-0.0002,-0.00020,9.000
9,114.840,0.00,-0.0002,-0.00020,9.000
9,114.940,0.00,-0.0002,-0.00020,9.000
9,115.040,0.01,-0.0002,-0.00020,9.000
9,115.140,0.00,-0.0002,-0.00020,9.000
9,115.240,0.01,-0.0002,-0.00020,9.000
9,115.340,0.00,-0.0002,-0.00020,9.000
9,115.440,0.00,-0.0002,-0.00020,9.000
9,115.540,-0.01,-0.0002,-0.00020,9.000
9,115.640,0.00,-0.0002,-0.00020,9.000
9,115.740,0.01,-0.0002,-0.00020,9.000
9,115.840,0.00,-0.0002,-0.00020,9.000
9,115.940,0.00,-0.0002,-0.00020,9.000
9,116.040,0.00,-0.0002,-0.00020,9.000
9,116.140,0.00,-0.0002,-0.00020,9.000
9,116.240,0.01,-0.0002,-0.00020,9.000
9,116.340,0.01,-0.0002,-0.00020,9.000
9,116.440,0.01,-0.0002,-0.00020,9.000
9,116.540,0.00,-0.0002,-0.00020,9.000
9,116.640,0.00,-0.0002,-0.00020,9.000
9,116.740,0.01,-0.0001,-0.00010,9.000
9,116.840,0.00,-0.0001,-0.00010,9.000
9,116.940,0.00,-0.0001,-0.00010,9.000
9,117.040,-0.01,-0.0001,-0.00010,9.000
9,117.140,0.01,-0.0001,-0.00010,9.000
9,117.240,-0.01,-0.0001,-0.00010,9.000
9,117.340,0.01,-0.0001,-0.00010,9.000
9,117.450,0.00,-0.0001,-0.00010,9.000
9,117.550,0.01,-0.0001,-0.00010,9.000
9,117.650,0.00,-0.0001,-0.00010,9.000
9,117.750,0.00,-0.0001,-0.00010,9.000
9,117.850,0.01,-0.0001,-0.00010,9.000
9,117.950,0.01,-0.0001,-0.00010,9.000
9,118.050,0.00,-0.0001,-0.00010,9.000
9,118.150,0.00,-0.0001,-0.00010,9.000
9,118.250,0.00,-0.0001,-0.00010,9.000
9,118.350,0.01,-0.0001,-0.00010,9.000
9,118.450,0.01,-0.0001,-0.00010,9.000
9,118.550,0.01,-0.0001,-0.00010,9.000
9,118.650,0.01,-0.0001,-0.00010,9.000
9,118.750,0.00,-0.0001,-0.00010,9.000
9,118.850,0.00,-0.0001,-0.00010,9.000
9,118.950,0.01,-0.0001,-0.00010,9.000
9,119.050,0.00,-0.0001,-0.00010,9.000
9,119.150,0.00,-0.0001,-0.00010,9.000
9,119.250,0.01,-0.0001,-0.00010,9.000
9,119.350,0.00,-0.0001,-0.00010,9.000
9,119.450,0.01,-0.0001,-0.00010,9.000
9,119.550,0.00,-0.0001,-0.00010,9.000
9,119.650,0.00,-0.0001,-0.00010,9.000
9,119.750,0.00,-0.0001,-0.00010,9.000
9,119.850,0.01,-0.0001,-0.00010,9.000
9,119.950,0.00,-0.0001,-0.00010,9.000
9,120.050,0.00,-0.0001,-0.00010,9.000
9,120.150,0.00,-0.0001,-0.00010,9.000
9,120.250,0.00,-0.0001,-0.00010,9.000
9,120.350,0.01,-0.0001,-0.00010,9.000
10,120.570,0.01,0.0098,0.00980,10.000
10,120.670,0.02,0.1087,0.10870,10.000
10,120.770,0.01,0.2086,0.20860,10.000
10,120.870,0.01,0.3088,0.30880,10.000
10,120.970,0.01,0.4087,0.40870,10.000
10,121.070,0.00,0.5089,0.50890,10.000
10,121.170,0.00,0.6087,0.60870,10.000
10,121.270,0.01,0.7088,0.70880,10.000
10,121.370,0.00,0.8086,0.80860,10.000
10,121.470,0.01,0.9088,0.90880,10.000
10,121.570,0.01,1.0086,1.00860,10.000
10,121.670,0.02,1.1088,1.10880,10.000
10,121.770,0.02,1.2087,1.20870,10.000
10,121.870,0.01,1.3088,1.30880,10.000
10,121.970,0.01,1.4088,1.40880,10.000
10,122.070,0.00,1.5088,1.50880,10.000
10,122.170,0.02,1.6087,1.60870,10.000
10,122.270,0.00,1.7088,1.70880,10.000
10,122.370,0.02,1.8087,1.80870,10.000
10,122.470,0.00,1.9089,1.90890,10.000
10,122.570,0.01,2.0088,2.00880,10.000
10,122.670,0.02,2.1090,2.10900,10.000
10,122.770,0.02,2.2089,2.20890,10.000
10,122.870,0.00,2.3087,2.30870,10.000
10,122.970,0.01,2.4087,2.40870,10.000
10,123.070,0.01,2.5089,2.50890,10.000
10,123.170,0.02,2.6088,2.60880,10.000
10,123.270,0.00,2.7088,2.70880,10.000
10,123.370,0.01,2.8087,2.80870,10.000
10,123.470,0.00,2.9088,2.90880,10.000
10,123.570,0.00,3.0088,3.00880,10.000
10,123.670,0.07,3.1088,3.10880,10.000
10,123.770,0.19,3.2089,3.20890,10.000
10,123.870,0.40,3.3089,3.30890,10.000
10,123.970,0.70,3.4089,3.40890,10.000
10,124.080,1.13,3.5187,3.51870,10.000
10,124.180,1.05,3.4834,3.48340,10.000
10,124.280,0.61,3.3837,3.38370,10.000
10,124.380,0.32,3.2837,3.28370,10.000
10,124.480,0.14,3.1836,3.18360,10.000
10,124.580,0.03,3.0835,3.08350,10.000
10,124.680,0.02,2.9835,2.98350,10.000
10,124.780,0.01,2.8836,2.88360,10.000
10,124.880,0.01,2.7835,2.78350,10.000
10,124.980,0.01,2.6835,2.68350,10.000
10,125.080,0.02,2.5835,2.58350,10.000
10,125.180,0.01,2.4835,2.48350,10.000
10,125.280,0.02,2.3833,2.38330,10.000
10,125.380,0.01,2.2835,2.28350,10.000
10,125.480,0.00,2.1837,2.18370,10.000
10,125.580,0.01,2.0836,2.08360,10.000
10,125.680,0.02,1.9835,1.98350,10.000
10,125.780,0.02,1.8835,1.88350,10.000
10,125.880,0.02,1.7834,1.78340,10.000
10,125.980,0.01,1.6834,1.68340,10.000
10,126.080,0.01,1.5833,1.58330,10.000
10,126.180,0.02,1.4833,1.48330,10.000
10,126.280,0.01,1.3835,1.38350,10.000
10,126.380,0.01,1.2835,1.28350,10.000
10,126.480,0.01,1.1833,1.18330,10.000
10,126.580,0.02,1.0833,1.08330,10.000
10,126.680,0.01,0.9834,0.98340,10.000
10,126.780,0.01,0.8834,0.88340,10.000
10,126.880,0.02,0.7834,0.78340,10.000
10,126.980,0.00,0.6833,0.68330,10.000
10,127.080,0.03,0.5835,0.58350,10.000
10,127.180,0.01,0.4834,0.48340,10.000
10,127.280,0.02,0.3834,0.38340,10.000
10,127.380,0.01,0.2833,0.28330,10.000
10,127.480,0.01,0.1834,0.18340,10.000
10,127.580,0.01,0.0833,0.08330,10.000
10,127.680,0.01,-0.0164,-0.01640,10.000
10,127.800,0.01,-0.0167,-0.01670,10.000
10,127.900,0.01,-0.0002,-0.00020,10.000
10,128.000,0.00,-0.0002,-0.00020,10.000
10,128.100,0.02,-0.0002,-0.00020,10.000
10,128.200,0.01,-0.0002,-0.00020,10.000
10,128.300,0.01,-0.0002,-0.00020,10.000
10,128.400,0.01,-0.0002,-0.00020,10.000
10,128.500,0.01,-0.0002,-0.00020,10.000
10,128.600,0.02,-0.0002,-0.00020,10.000
10,128.700,0.02,-0.0002,-0.00020,10.000
10,128.800,0.01,-0.0002,-0.00020,10.000
10,128.900,0.01,-0.0002,-0.00020,10.000
10,129.000,0.01,-0.0002,-0.00020,10.000
10,129.100,0.01,-0.0002,-0.00020,10.000
10,129.200,0.02,-0.0002,-0.00020,10.000
10,129.300,0.01,-0.0002,-0.00020,10.000
10,129.400,0.01,-0.0002,-0.00020,10.000
10,129.500,0.01,-0.0002,-0.00020,10.000
10,129.600,0.02,-0.0002,-0.00020,10.000
10,129.700,0.01,-0.0002,-0.00020,10.000
10,129.800,0.01,-0.0002,-0.00020,10.000
10,129.900,0.01,-0.0002,-0.00020,10.000
10,130.000,0.01,-0.0002,-0.00020,10.000
10,130.100,0.01,-0.0002,-0.00020,10.000
10,130.200,0.01,-0.0001,-0.00010,10.000
10,130.300,0.01,-0.0001,-0.00010,10.000
10,130.400,0.01,-0.0001,-0.00010,10.000
10,130.500,0.01,-0.0001,-0.00010,10.000
10,130.600,0.01,-0.0001,-0.00010,10.000
10,130.700,0.01,-0.0001,-0.00010,10.000
10,130.810,0.01,-0.0001,-0.00010,10.000
10,130.910,0.00,-0.0001,-0.00010,10.000
10,131.010,0.01,-0.0001,-0.00010,10.000
10,131.110,0.00,-0.0001,-0.00010,10.000
10,131.210,0.01,-0.0001,-0.00010,10.000
10,131.310,0.02,-0.0001,-0.00010,10.000
10,131.410,0.01,-0.0001,-0.00010,10.000
10,131.510,0.02,-0.0001,-0.00010,10.000
10,131.610,0.02,-0.0001,-0.00010,10.000
10,131.710,0.01,-0.0001,-0.00010,10.000
10,131.810,0.01,-0.0001,-0.00010,10.000
10,131.910,0.01,-0.0001,-0.00010,10.000
10,132.010,0.01,-0.0001,-0.00010,10.000
10,132.110,0.02,-0.0001,-0.00010,10.000
10,132.210,0.01,-0.0001,-0.00010,10.000
10,132.310,0.00,-0.0001,-0.00010,10.000
10,132.410,0.01,-0.0001,-0.00010,10.000
10,132.510,0.03,-0.0001,-0.00010,10.000
10,132.610,0.02,-0.0001,-0.00010,10.000
10,132.710,0.01,-0.0001,-0.00010,10.000
10,132.810,0.00,-0.0001,-0.00010,10.000
10,132.910,0.01,-0.0001,-0.00010,10.000
10,133.010,0.01,-0.0001,-0.00010,10.000
10,133.110,0.01,-0.0001,-0.00010,10.000
10,133.210,0.01,-0.0001,-0.00010,10.000
10,133.310,0.03,-0.0001,-0.00010,10.000
10,133.410,0.01,-0.0001,-0.00010,10.000
10,133.510,0.01,-0.0001,-0.00010,10.000
10,133.610,0.01,-0.0001,-0.00010,10.000
10,133.710,0.01,-0.0001,-0.00010,10.000
10,133.790,0.01,-0.0001,-0.00010,10.000