File: calibDATA_loadcell/date_30:1:2018/MTSdata_date_1.30/radhen_10cyc_black_0deg_1mms_5N.txt
""
"Test Method","Radhen_Load_Cntrl_Cmprsn_250N_12-7.msm"
"Sample I. D.","Sample1.mss"
"Specimen Number","10"

"TheCycle_Output ()","_Time (s)","_Load (N)","_Extension (mm)","RealTimeDepth (mm)","CycleNumber ()"

0,0.160,-0.02,0.0000,-1.86720,0.000
1,0.310,-0.01,0.0863,0.08630,1.000
1,0.450,-0.01,0.2264,0.22640,1.000
1,0.590,-0.01,0.3666,0.36660,1.000
1,0.730,-0.01,0.5065,0.50650,1.000
1,0.870,-0.01,0.6464,0.64640,1.000
1,1.010,-0.01,0.7866,0.78660,1.000
1,1.150,-0.01,0.9266,0.92660,1.000
1,1.290,-0.01,1.0667,1.06670,1.000
1,1.430,-0.01,1.2069,1.20690,1.000
1,1.570,-0.01,1.3464,1.34640,1.000
1,1.710,-0.01,1.4866,1.48660,1.000
1,1.850,-0.01,1.6266,1.62660,1.000
1,1.990,-0.01,1.7666,1.76660,1.000
1,2.130,-0.01,1.9065,1.90650,1.000
1,2.270,-0.01,2.0466,2.04660,1.000
1,2.410,-0.01,2.1865,2.18650,1.000
1,2.550,-0.01,2.3267,2.32670,1.000
1,2.690,-0.01,2.4668,2.46680,1.000
1,2.830,-0.01,2.6067,2.60670,1.000
1,2.970,-0.01,2.7467,2.74670,1.000
1,3.110,-0.01,2.8868,2.88680,1.000
1,3.250,-0.01,3.0266,3.02660,1.000
1,3.390,-0.01,3.1667,3.16670,1.000
1,3.530,-0.01,3.3067,3.30670,1.000
1,3.670,-0.01,3.4468,3.44680,1.000
1,3.810,-0.01,3.5868,3.58680,1.000
1,3.950,-0.01,3.7267,3.72670,1.000
1,4.090,-0.01,3.8667,3.86670,1.000
1,4.230,-0.01,4.0069,4.00690,1.000
1,4.370,-0.01,4.1467,4.14670,1.000
1,4.510,-0.01,4.2869,4.28690,1.000
1,4.650,-0.01,4.4267,4.42670,1.000
1,4.790,-0.01,4.5668,4.56680,1.000
1,4.930,-0.01,4.7068,4.70680,1.000
1,5.070,-0.02,4.8468,4.84680,1.000
1,5.210,-0.01,4.9867,4.98670,1.000
1,5.350,-0.01,5.1269,5.12690,1.000
1,5.490,0.01,5.2668,5.26680,1.000
1,5.630,0.09,5.4070,5.40700,1.000
1,5.770,0.26,5.5468,5.54680,1.000
1,5.910,0.60,5.6869,5.68690,1.000
1,6.050,1.06,5.8267,5.82670,1.000
1,6.190,1.68,5.9668,5.96680,1.000
1,6.330,2.44,6.1067,6.10670,1.000
1,6.470,3.36,6.2469,6.24690,1.000
1,6.610,4.45,6.3866,6.38660,1.000
1,6.770,5.53,6.4916,6.49160,1.000
1,6.910,3.99,6.3536,6.35360,1.000
1,7.050,2.82,6.2137,6.21370,1.000
1,7.190,1.92,6.0736,6.07360,1.000
1,7.330,1.23,5.9336,5.93360,1.000
1,7.470,0.73,5.7934,5.79340,1.000
1,7.610,0.36,5.6536,5.65360,1.000
1,7.750,0.13,5.5135,5.51350,1.000
1,7.890,0.02,5.3736,5.37360,1.000
1,8.030,-0.01,5.2335,5.23350,1.000
1,8.170,-0.01,5.0935,5.09350,1.000
1,8.310,0.00,4.9536,4.95360,1.000
1,8.450,-0.01,4.8136,4.81360,1.000
1,8.590,-0.01,4.6736,4.67360,1.000
1,8.730,-0.01,4.5335,4.53350,1.000
1,8.870,-0.01,4.3935,4.39350,1.000
1,9.010,-0.01,4.2534,4.25340,1.000
1,9.150,-0.01,4.1135,4.11350,1.000
1,9.290,-0.01,3.9735,3.97350,1.000
1,9.430,-0.01,3.8335,3.83350,1.000
1,9.570,-0.01,3.6934,3.69340,1.000
1,9.710,-0.01,3.5535,3.55350,1.000
1,9.850,-0.01,3.4134,3.41340,1.000
1,9.990,-0.01,3.2734,3.27340,1.000
1,10.130,-0.01,3.1334,3.13340,1.000
1,10.270,-0.01,2.9934,2.99340,1.000
1,10.410,-0.01,2.8534,2.85340,1.000
1,10.550,-0.01,2.7135,2.71350,1.000
1,10.690,-0.01,2.5732,2.57320,1.000
1,10.830,-0.01,2.4334,2.43340,1.000
1,10.970,-0.01,2.2934,2.29340,1.000
1,11.110,-0.01,2.1533,2.15330,1.000
1,11.250,-0.01,2.0132,2.01320,1.000
1,11.390,-0.01,1.8733,1.87330,1.000
1,11.530,-0.01,1.7331,1.73310,1.000
1,11.670,-0.01,1.5933,1.59330,1.000
1,11.810,-0.01,1.4531,1.45310,1.000
1,11.950,-0.01,1.3132,1.31320,1.000
1,12.090,-0.01,1.1734,1.17340,1.000
1,12.230,-0.01,1.0333,1.03330,1.000
1,12.370,-0.01,0.8932,0.89320,1.000
1,12.510,-0.01,0.7533,0.75330,1.000
1,12.650,-0.01,0.6129,0.61290,1.000
1,12.790,-0.01,0.4732,0.47320,1.000
1,12.930,-0.01,0.3331,0.33310,1.000
1,13.070,-0.02,0.1932,0.19320,1.000
1,13.210,-0.01,0.0530,0.05300,1.000
1,13.360,-0.01,-0.0414,-0.04140,1.000
1,13.500,-0.01,-0.0003,-0.00030,1.000
1,13.640,-0.01,-0.0003,-0.00030,1.000
1,13.780,-0.01,-0.0003,-0.00030,1.000
1,13.920,-0.01,-0.0003,-0.00030,1.000
1,14.060,-0.01,-0.0003,-0.00030,1.000
1,14.200,-0.01,-0.0003,-0.00030,1.000
1,14.340,-0.01,-0.0003,-0.00030,1.000
1,14.480,-0.01,-0.0003,-0.00030,1.000
1,14.620,-0.01,-0.0003,-0.00030,1.000
1,14.760,-0.01,-0.0003,-0.00030,1.000
1,14.900,-0.01,-0.0003,-0.00030,1.000
1,15.040,-0.01,-0.0003,-0.00030,1.000
1,15.180,-0.01,-0.0003,-0.00030,1.000
1,15.320,-0.01,-0.0003,-0.00030,1.000
1,15.460,-0.01,-0.0003,-0.00030,1.000
1,15.600,-0.01,-0.0003,-0.00030,1.000
1,15.740,-0.01,-0.0002,-0.00020,1.000
1,15.880,-0.01,-0.0002,-0.00020,1.000
1,16.020,-0.02,-0.0002,-0.00020,1.000
1,16.160,-0.01,-0.0002,-0.00020,1.000
1,16.300,-0.01,-0.0002,-0.00020,1.000
1,16.460,-0.01,-0.0002,-0.00020,1.000
1,16.600,-0.01,-0.0002,-0.00020,1.000
1,16.740,-0.01,-0.0002,-0.00020,1.000
1,16.880,-0.01,-0.0002,-0.00020,1.000
1,17.020,-0.01,-0.0002,-0.00020,1.000
1,17.160,-0.01,-0.0002,-0.00020,1.000
1,17.300,-0.01,-0.0002,-0.00020,1.000
1,17.440,-0.01,-0.0002,-0.00020,1.000
1,17.580,-0.01,-0.0002,-0.00020,1.000
1,17.720,-0.01,-0.0002,-0.00020,1.000
1,17.860,-0.01,-0.0002,-0.00020,1.000
1,18.000,-0.01,-0.0002,-0.00020,1.000
1,18.140,-0.01,-0.0002,-0.00020,1.000
1,18.280,-0.01,-0.0002,-0.00020,1.000
1,18.420,-0.01,-0.0002,-0.00020,1.000
1,18.560,-0.01,-0.0002,-0.00020,1.000
1,18.700,-0.01,-0.0001,-0.00010,1.000
1,18.840,-0.01,-0.0001,-0.00010,1.000
1,18.980,-0.01,-0.0001,-0.00010,1.000
1,19.120,-0.01,-0.0001,-0.00010,1.000
1,19.260,-0.01,-0.0001,-0.00010,1.000
2,19.490,-0.01,0.0000,0.00000,2.000
2,19.640,0.00,0.0955,0.09550,2.000
2,19.780,0.00,0.2357,0.23570,2.000
2,19.920,0.00,0.3756,0.37560,2.000
2,20.060,0.00,0.5157,0.51570,2.000
2,20.200,0.00,0.6556,0.65560,2.000
2,20.340,0.00,0.7957,0.79570,2.000
2,20.480,0.00,0.9356,0.93560,2.000
2,20.620,0.00,1.0758,1.07580,2.000
2,20.760,0.00,1.2158,1.21580,2.000
2,20.900,0.00,1.3556,1.35560,2.000
2,21.040,0.00,1.4957,1.49570,2.000
2,21.180,0.00,1.6357,1.63570,2.000
2,21.320,0.00,1.7756,1.77560,2.000
2,21.460,0.00,1.9157,1.91570,2.000
2,21.600,0.00,2.0556,2.05560,2.000
2,21.740,0.00,2.1958,2.19580,2.000
2,21.880,0.00,2.3359,2.33590,2.000
2,22.020,0.00,2.4759,2.47590,2.000
2,22.160,0.00,2.6156,2.61560,2.000
2,22.300,0.00,2.7559,2.75590,2.000
2,22.440,-0.01,2.8957,2.89570,2.000
2,22.580,0.00,3.0358,3.03580,2.000
2,22.720,0.00,3.1757,3.17570,2.000
2,22.860,-0.01,3.3158,3.31580,2.000
2,23.000,0.00,3.4558,3.45580,2.000
2,23.140,0.00,3.5959,3.59590,2.000
2,23.280,0.00,3.7357,3.73570,2.000
2,23.420,0.00,3.8758,3.87580,2.000
2,23.560,0.00,4.0158,4.01580,2.000
2,23.700,0.00,4.1559,4.15590,2.000
2,23.840,-0.01,4.2958,4.29580,2.000
2,23.980,0.00,4.4358,4.43580,2.000
2,24.120,-0.01,4.5758,4.57580,2.000
2,24.260,-0.01,4.7158,4.71580,2.000
2,24.400,0.00,4.8559,4.85590,2.000
2,24.540,0.00,4.9958,4.99580,2.000
2,24.680,0.00,5.1358,5.13580,2.000
2,24.820,0.02,5.2760,5.27600,2.000
2,24.960,0.09,5.4160,5.41600,2.000
2,25.100,0.27,5.5558,5.55580,2.000
2,25.240,0.60,5.6960,5.69600,2.000
2,25.380,1.07,5.8358,5.83580,2.000
2,25.520,1.68,5.9760,5.97600,2.000
2,25.660,2.46,6.1159,6.11590,2.000
2,25.800,3.40,6.2560,6.25600,2.000
2,25.940,4.50,6.3958,6.39580,2.000
2,26.100,5.43,6.4808,6.48080,2.000
2,26.240,3.87,6.3407,6.34070,2.000
2,26.380,2.73,6.2008,6.20080,2.000
2,26.520,1.86,6.0607,6.06070,2.000
2,26.660,1.18,5.9207,5.92070,2.000
2,26.800,0.69,5.7806,5.78060,2.000
2,26.940,0.33,5.6407,5.64070,2.000
2,27.080,0.12,5.5006,5.50060,2.000
2,27.220,0.02,5.3607,5.36070,2.000
2,27.360,0.00,5.2206,5.22060,2.000
2,27.500,-0.01,5.0806,5.08060,2.000
2,27.640,0.00,4.9405,4.94050,2.000
2,27.780,0.00,4.8007,4.80070,2.000
2,27.920,0.00,4.6605,4.66050,2.000
2,28.060,0.00,4.5206,4.52060,2.000
2,28.200,0.00,4.3803,4.38030,2.000
2,28.340,0.00,4.2406,4.24060,2.000
2,28.480,-0.01,4.1004,4.10040,2.000
2,28.620,0.00,3.9605,3.96050,2.000
2,28.760,0.00,3.8204,3.82040,2.000
2,28.900,0.00,3.6805,3.68050,2.000
2,29.040,0.00,3.5403,3.54030,2.000
2,29.180,0.00,3.4006,3.40060,2.000
2,29.320,-0.01,3.2602,3.26020,2.000
2,29.460,0.00,3.1205,3.12050,2.000
2,29.600,0.00,2.9803,2.98030,2.000
2,29.740,0.00,2.8404,2.84040,2.000
2,29.880,0.00,2.7002,2.70020,2.000
2,30.020,0.00,2.5604,2.56040,2.000
2,30.160,0.00,2.4203,2.42030,2.000
2,30.300,0.00,2.2804,2.28040,2.000
2,30.440,0.00,2.1401,2.14010,2.000
2,30.580,-0.01,2.0004,2.00040,2.000
2,30.720,0.00,1.8601,1.86010,2.000
2,30.860,0.00,1.7203,1.72030,2.000
2,31.000,0.00,1.5802,1.58020,2.000
2,31.140,0.00,1.4403,1.44030,2.000
2,31.280,0.00,1.3000,1.30000,2.000
2,31.420,0.00,1.1605,1.16050,2.000
2,31.560,-0.01,1.0202,1.02020,2.000
2,31.700,0.00,0.8803,0.88030,2.000
2,31.840,0.00,0.7401,0.74010,2.000
2,31.980,0.00,0.6002,0.60020,2.000
2,32.120,0.00,0.4601,0.46010,2.000
2,32.260,-0.01,0.3202,0.32020,2.000
2,32.400,0.00,0.1801,0.18010,2.000
2,32.540,0.00,0.0401,0.04010,2.000
2,32.690,0.00,-0.0346,-0.03460,2.000
2,32.830,0.00,-0.0003,-0.00030,2.000
2,32.970,0.00,-0.0003,-0.00030,2.000
2,33.110,0.00,-0.0003,-0.00030,2.000
2,33.250,0.00,-0.0003,-0.00030,2.000
2,33.390,0.00,-0.0003,-0.00030,2.000
2,33.530,0.00,-0.0003,-0.00030,2.000
2,33.670,0.00,-0.0003,-0.00030,2.000
2,33.810,0.00,-0.0003,-0.00030,2.000
2,33.950,0.00,-0.0003,-0.00030,2.000
2,34.090,0.00,-0.0003,-0.00030,2.000
2,34.230,0.00,-0.0003,-0.00030,2.000
2,34.370,0.00,-0.0003,-0.00030,2.000
2,34.510,0.00,-0.0003,-0.00030,2.000
2,34.650,0.00,-0.0002,-0.00020,2.000
2,34.790,0.00,-0.0002,-0.00020,2.000
2,34.930,0.00,-0.0002,-0.00020,2.000
2,35.070,0.00,-0.0002,-0.00020,2.000
2,35.210,0.00,-0.0002,-0.00020,2.000
2,35.350,0.00,-0.0002,-0.00020,2.000
2,35.490,0.00,-0.0002,-0.00020,2.000
2,35.630,0.00,-0.0002,-0.00020,2.000
2,35.790,0.00,-0.0002,-0.00020,2.000
2,35.930,0.00,-0.0002,-0.00020,2.000
2,36.070,0.00,-0.0002,-0.00020,2.000
2,36.210,0.00,-0.0002,-0.00020,2.000
2,36.350,0.00,-0.0002,-0.00020,2.000
2,36.490,0.00,-0.0002,-0.00020,2.000
2,36.630,0.00,-0.0002,-0.00020,2.000
2,36.770,0.00,-0.0002,-0.00020,2.000
2,36.910,0.00,-0.0002,-0.00020,2.000
2,37.050,0.00,-0.0002,-0.00020,2.000
2,37.190,0.00,-0.0002,-0.00020,2.000
2,37.330,0.00,-0.0002,-0.00020,2.000
2,37.470,0.00,-0.0001,-0.00010,2.000
2,37.610,-0.01,-0.0001,-0.00010,2.000
2,37.750,0.00,-0.0001,-0.00010,2.000
2,37.890,0.00,-0.0001,-0.00010,2.000
2,38.030,0.00,-0.0001,-0.00010,2.000
2,38.170,-0.01,-0.0001,-0.00010,2.000
2,38.310,-0.01,-0.0001,-0.00010,2.000
2,38.450,0.00,-0.0001,-0.00010,2.000
2,38.590,0.00,-0.0001,-0.00010,2.000
3,38.830,0.00,0.0000,0.00000,3.000
3,38.970,0.00,0.1065,0.10650,3.000
3,39.110,0.01,0.2466,0.24660,3.000
3,39.250,0.00,0.3868,0.38680,3.000
3,39.390,0.00,0.5268,0.52680,3.000
3,39.530,0.00,0.6667,0.66670,3.000
3,39.670,0.00,0.8068,0.80680,3.000
3,39.810,0.00,0.9466,0.94660,3.000
3,39.950,0.00,1.0869,1.08690,3.000
3,40.090,0.00,1.2269,1.22690,3.000
3,40.230,0.00,1.3666,1.36660,3.000
3,40.370,0.00,1.5068,1.50680,3.000
3,40.510,0.00,1.6467,1.64670,3.000
3,40.650,0.00,1.7867,1.78670,3.000
3,40.790,0.00,1.9268,1.92680,3.000
3,40.930,0.01,2.0667,2.06670,3.000
3,41.070,0.00,2.2068,2.20680,3.000
3,41.210,0.01,2.3468,2.34680,3.000
3,41.350,0.00,2.4868,2.48680,3.000
3,41.490,0.00,2.6267,2.62670,3.000
3,41.630,0.00,2.7668,2.76680,3.000
3,41.770,0.00,2.9067,2.90670,3.000
3,41.910,0.00,3.0468,3.04680,3.000
3,42.050,0.00,3.1868,3.18680,3.000
3,42.190,0.00,3.3269,3.32690,3.000
3,42.330,0.00,3.4668,3.46680,3.000
3,42.470,0.00,3.6069,3.60690,3.000
3,42.610,0.00,3.7467,3.74670,3.000
3,42.750,0.00,3.8868,3.88680,3.000
3,42.890,0.00,4.0267,4.02670,3.000
3,43.030,0.00,4.1669,4.16690,3.000
3,43.170,0.00,4.3068,4.30680,3.000
3,43.310,0.00,4.4469,4.44690,3.000
3,43.450,0.00,4.5868,4.58680,3.000
3,43.590,0.00,4.7269,4.72690,3.000
3,43.730,0.00,4.8668,4.86680,3.000
3,43.870,0.00,5.0069,5.00690,3.000
3,44.010,0.00,5.1468,5.14680,3.000
3,44.150,0.02,5.2870,5.28700,3.000
3,44.290,0.10,5.4268,5.42680,3.000
3,44.430,0.29,5.5670,5.56700,3.000
3,44.570,0.63,5.7069,5.70690,3.000
3,44.710,1.11,5.8470,5.84700,3.000
3,44.850,1.73,5.9868,5.98680,3.000
3,44.990,2.52,6.1269,6.12690,3.000
3,45.130,3.46,6.2667,6.26670,3.000
3,45.270,4.58,6.4068,6.40680,3.000
3,45.430,5.34,6.4733,6.47330,3.000
3,45.570,3.79,6.3337,6.33370,3.000
3,45.710,2.67,6.1936,6.19360,3.000
3,45.850,1.81,6.0538,6.05380,3.000
3,45.990,1.15,5.9136,5.91360,3.000
3,46.130,0.66,5.7736,5.77360,3.000
3,46.270,0.31,5.6336,5.63360,3.000
3,46.410,0.11,5.4936,5.49360,3.000
3,46.550,0.02,5.3536,5.35360,3.000
3,46.690,0.00,5.2135,5.21350,3.000
3,46.830,0.00,5.0734,5.07340,3.000
3,46.970,0.00,4.9336,4.93360,3.000
3,47.110,0.00,4.7935,4.79350,3.000
3,47.250,0.00,4.6536,4.65360,3.000
3,47.390,0.00,4.5135,4.51350,3.000
3,47.530,0.00,4.3734,4.37340,3.000
3,47.670,0.00,4.2334,4.23340,3.000
3,47.810,0.00,4.0935,4.09350,3.000
3,47.950,0.00,3.9534,3.95340,3.000
3,48.090,0.00,3.8135,3.81350,3.000
3,48.230,0.00,3.6735,3.67350,3.000
3,48.370,0.00,3.5335,3.53350,3.000
3,48.510,0.00,3.3935,3.39350,3.000
3,48.650,0.00,3.2533,3.25330,3.000
3,48.790,0.00,3.1135,3.11350,3.000
3,48.930,0.00,2.9733,2.97330,3.000
3,49.070,0.00,2.8335,2.83350,3.000
3,49.210,0.00,2.6933,2.69330,3.000
3,49.350,0.00,2.5534,2.55340,3.000
3,49.490,0.00,2.4134,2.41340,3.000
3,49.630,0.00,2.2734,2.27340,3.000
3,49.770,0.00,2.1333,2.13330,3.000
3,49.910,0.00,1.9934,1.99340,3.000
3,50.050,0.00,1.8532,1.85320,3.000
3,50.190,0.00,1.7133,1.71330,3.000
3,50.330,0.00,1.5732,1.57320,3.000
3,50.470,0.00,1.4333,1.43330,3.000
3,50.610,0.00,1.2932,1.29320,3.000
3,50.750,0.00,1.1535,1.15350,3.000
3,50.890,0.00,1.0132,1.01320,3.000
3,51.030,0.00,0.8733,0.87330,3.000
3,51.170,0.00,0.7332,0.73320,3.000
3,51.310,0.00,0.5932,0.59320,3.000
3,51.450,0.00,0.4531,0.45310,3.000
3,51.590,0.00,0.3133,0.31330,3.000
3,51.730,0.00,0.1731,0.17310,3.000
3,51.870,0.00,0.0332,0.03320,3.000
3,52.020,0.00,-0.0211,-0.02110,3.000
3,52.160,0.00,-0.0003,-0.00030,3.000
3,52.300,0.00,-0.0003,-0.00030,3.000
3,52.440,0.00,-0.0003,-0.00030,3.000
3,52.580,0.00,-0.0003,-0.00030,3.000
3,52.720,0.00,-0.0003,-0.00030,3.000
3,52.860,0.00,-0.0003,-0.00030,3.000
3,53.000,0.00,-0.0003,-0.00030,3.000
3,53.140,0.00,-0.0003,-0.00030,3.000
3,53.280,0.00,-0.0003,-0.00030,3.000
3,53.420,0.00,-0.0003,-0.00030,3.000
3,53.560,0.00,-0.0003,-0.00030,3.000
3,53.700,0.00,-0.0003,-0.00030,3.000
3,53.840,0.00,-0.0003,-0.00030,3.000
3,53.980,0.00,-0.0003,-0.00030,3.000
3,54.120,0.00,-0.0002,-0.00020,3.000
3,54.260,0.00,-0.0002,-0.00020,3.000
3,54.400,0.00,-0.0002,-0.00020,3.000
3,54.540,0.01,-0.0002,-0.00020,3.000
3,54.680,0.00,-0.0002,-0.00020,3.000
3,54.820,0.00,-0.0002,-0.00020,3.000
3,54.960,0.00,-0.0002,-0.00020,3.000
3,55.120,0.00,-0.0002,-0.00020,3.000
3,55.260,0.00,-0.0002,-0.00020,3.000
3,55.400,0.00,-0.0002,-0.00020,3.000
3,55.540,0.00,-0.0002,-0.00020,3.000
3,55.680,0.00,-0.0002,-0.00020,3.000
3,55.820,0.00,-0.0002,-0.00020,3.000
3,55.960,0.00,-0.0002,-0.00020,3.000
3,56.100,0.00,-0.0002,-0.00020,3.000
3,56.240,0.00,-0.0002,-0.00020,3.000
3,56.380,0.00,-0.0002,-0.00020,3.000
3,56.520,0.00,-0.0002,-0.00020,3.000
3,56.660,0.00,-0.0002,-0.00020,3.000
3,56.800,0.00,-0.0002,-0.00020,3.000
3,56.940,0.00,-0.0001,-0.00010,3.000
3,57.080,0.00,-0.0001,-0.00010,3.000
3,57.220,0.00,-0.0001,-0.00010,3.000
3,57.360,0.00,-0.0001,-0.00010,3.000
3,57.500,0.00,-0.0001,-0.00010,3.000
3,57.640,0.00,-0.0001,-0.00010,3.000
3,57.780,0.00,-0.0001,-0.00010,3.000
3,57.920,0.00,-0.0001,-0.00010,3.000
4,58.160,0.00,0.0000,0.00000,4.000
4,58.300,-0.01,0.1156,0.11560,4.000
4,58.440,0.00,0.2556,0.25560,4.000
4,58.580,0.00,0.3958,0.39580,4.000
4,58.720,0.00,0.5355,0.53550,4.000
4,58.860,0.00,0.6757,0.67570,4.000
4,59.000,-0.01,0.8156,0.81560,4.000
4,59.140,0.00,0.9558,0.95580,4.000
4,59.280,0.00,1.0957,1.09570,4.000
4,59.420,0.00,1.2359,1.23590,4.000
4,59.560,0.00,1.3756,1.37560,4.000
4,59.700,0.00,1.5157,1.51570,4.000
4,59.840,0.00,1.6557,1.65570,4.000
4,59.980,0.00,1.7957,1.79570,4.000
4,60.120,0.00,1.9357,1.93570,4.000
4,60.260,0.00,2.0758,2.07580,4.000
4,60.400,0.00,2.2156,2.21560,4.000
4,60.540,0.00,2.3559,2.35590,4.000
4,60.680,0.00,2.4957,2.49570,4.000
4,60.820,0.00,2.6357,2.63570,4.000
4,60.960,0.00,2.7758,2.77580,4.000
4,61.100,0.00,2.9158,2.91580,4.000
4,61.240,0.00,3.0558,3.05580,4.000
4,61.380,0.00,3.1958,3.19580,4.000
4,61.520,0.00,3.3357,3.33570,4.000
4,61.660,-0.01,3.4758,3.47580,4.000
4,61.800,-0.01,3.6158,3.61580,4.000
4,61.940,0.00,3.7559,3.75590,4.000
4,62.080,0.00,3.8958,3.89580,4.000
4,62.220,0.00,4.0358,4.03580,4.000
4,62.360,0.00,4.1758,4.17580,4.000
4,62.500,0.00,4.3159,4.31590,4.000
4,62.640,0.00,4.4558,4.45580,4.000
4,62.780,0.00,4.5959,4.59590,4.000
4,62.920,0.00,4.7359,4.73590,4.000
4,63.060,-0.01,4.8760,4.87600,4.000
4,63.200,0.00,5.0158,5.01580,4.000
4,63.340,0.00,5.1559,5.15590,4.000
4,63.480,0.02,5.2960,5.29600,4.000
4,63.620,0.10,5.4359,5.43590,4.000
4,63.760,0.30,5.5760,5.57600,4.000
4,63.900,0.65,5.7160,5.71600,4.000
4,64.040,1.14,5.8559,5.85590,4.000
4,64.180,1.77,5.9958,5.99580,4.000
4,64.320,2.57,6.1361,6.13610,4.000
4,64.460,3.52,6.2759,6.27590,4.000
4,64.600,4.65,6.4160,6.41600,4.000
4,64.760,5.20,6.4625,6.46250,4.000
4,64.900,3.69,6.3227,6.32270,4.000
4,65.040,2.59,6.1826,6.18260,4.000
4,65.180,1.75,6.0427,6.04270,4.000
4,65.320,1.10,5.9026,5.90260,4.000
4,65.460,0.63,5.7627,5.76270,4.000
4,65.600,0.29,5.6226,5.62260,4.000
4,65.740,0.10,5.4827,5.48270,4.000
4,65.880,0.02,5.3425,5.34250,4.000
4,66.020,0.00,5.2026,5.20260,4.000
4,66.160,0.00,5.0625,5.06250,4.000
4,66.300,0.00,4.9227,4.92270,4.000
4,66.440,-0.01,4.7825,4.78250,4.000
4,66.580,0.00,4.6426,4.64260,4.000
4,66.720,0.00,4.5023,4.50230,4.000
4,66.860,0.00,4.3625,4.36250,4.000
4,67.000,0.00,4.2223,4.22230,4.000
4,67.140,0.00,4.0826,4.08260,4.000
4,67.280,0.00,3.9423,3.94230,4.000
4,67.420,0.00,3.8025,3.80250,4.000
4,67.560,-0.01,3.6624,3.66240,4.000
4,67.700,0.00,3.5225,3.52250,4.000
4,67.840,0.00,3.3824,3.38240,4.000
4,67.980,-0.01,3.2424,3.24240,4.000
4,68.120,-0.01,3.1023,3.10230,4.000
4,68.260,0.00,2.9624,2.96240,4.000
4,68.400,0.00,2.8223,2.82230,4.000
4,68.540,0.00,2.6823,2.68230,4.000
4,68.680,-0.01,2.5422,2.54220,4.000
4,68.820,0.00,2.4025,2.40250,4.000
4,68.960,0.00,2.2624,2.26240,4.000
4,69.100,0.00,2.1223,2.12230,4.000
4,69.240,0.00,1.9821,1.98210,4.000
4,69.380,0.00,1.8424,1.84240,4.000
4,69.520,-0.01,1.7020,1.70200,4.000
4,69.660,0.00,1.5623,1.56230,4.000
4,69.800,0.00,1.4220,1.42200,4.000
4,69.940,-0.01,1.2824,1.28240,4.000
4,70.080,0.00,1.1423,1.14230,4.000
4,70.220,0.00,1.0024,1.00240,4.000
4,70.360,0.00,0.8621,0.86210,4.000
4,70.500,0.00,0.7222,0.72220,4.000
4,70.640,0.00,0.5820,0.58200,4.000
4,70.780,0.00,0.4422,0.44220,4.000
4,70.920,0.00,0.3020,0.30200,4.000
4,71.060,0.00,0.1623,0.16230,4.000
4,71.200,0.00,0.0221,0.02210,4.000
4,71.350,0.00,-0.0134,-0.01340,4.000
4,71.490,0.00,-0.0003,-0.00030,4.000
4,71.630,0.00,-0.0003,-0.00030,4.000
4,71.770,0.00,-0.0003,-0.00030,4.000
4,71.910,0.00,-0.0003,-0.00030,4.000
4,72.050,0.00,-0.0003,-0.00030,4.000
4,72.190,-0.01,-0.0003,-0.00030,4.000
4,72.330,0.00,-0.0003,-0.00030,4.000
4,72.470,0.00,-0.0003,-0.00030,4.000
4,72.610,0.00,-0.0003,-0.00030,4.000
4,72.750,0.00,-0.0003,-0.00030,4.000
4,72.890,0.00,-0.0003,-0.00030,4.000
4,73.030,0.00,-0.0003,-0.00030,4.000
4,73.170,0.00,-0.0003,-0.00030,4.000
4,73.310,-0.01,-0.0003,-0.00030,4.000
4,73.450,0.00,-0.0002,-0.00020,4.000
4,73.590,-0.01,-0.0002,-0.00020,4.000
4,73.730,0.00,-0.0002,-0.00020,4.000
4,73.870,-0.01,-0.0002,-0.00020,4.000
4,74.010,0.00,-0.0002,-0.00020,4.000
4,74.150,0.00,-0.0002,-0.00020,4.000
4,74.290,0.00,-0.0002,-0.00020,4.000
4,74.440,0.00,-0.0002,-0.00020,4.000
4,74.580,0.00,-0.0002,-0.00020,4.000
4,74.720,0.00,-0.0002,-0.00020,4.000
4,74.860,0.00,-0.0002,-0.00020,4.000
4,75.000,-0.01,-0.0002,-0.00020,4.000
4,75.140,0.00,-0.0002,-0.00020,4.000
4,75.280,-0.01,-0.0002,-0.00020,4.000
4,75.420,-0.01,-0.0002,-0.00020,4.000
4,75.560,0.00,-0.0002,-0.00020,4.000
4,75.700,0.00,-0.0002,-0.00020,4.000
4,75.840,0.00,-0.0002,-0.00020,4.000
4,75.980,-0.01,-0.0002,-0.00020,4.000
4,76.120,-0.01,-0.0002,-0.00020,4.000
4,76.260,0.00,-0.0001,-0.00010,4.000
4,76.400,0.00,-0.0001,-0.00010,4.000
4,76.540,0.00,-0.0001,-0.00010,4.000
4,76.680,0.00,-0.0001,-0.00010,4.000
4,76.820,-0.01,-0.0001,-0.00010,4.000
4,76.960,0.00,-0.0001,-0.00010,4.000
4,77.100,0.00,-0.0001,-0.00010,4.000
4,77.240,0.00,-0.0001,-0.00010,4.000
5,77.480,0.01,0.0000,0.00000,5.000
5,77.620,0.01,0.1055,0.10550,5.000
5,77.760,0.01,0.2457,0.24570,5.000
5,77.900,0.00,0.3857,0.38570,5.000
5,78.040,0.00,0.5258,0.52580,5.000
5,78.180,0.00,0.6656,0.66560,5.000
5,78.320,0.01,0.8058,0.80580,5.000
5,78.460,0.00,0.9457,0.94570,5.000
5,78.600,0.00,1.0859,1.08590,5.000
5,78.740,0.01,1.2258,1.22580,5.000
5,78.880,0.01,1.3657,1.36570,5.000
5,79.020,0.01,1.5056,1.50560,5.000
5,79.160,0.00,1.6458,1.64580,5.000
5,79.300,0.01,1.7857,1.78570,5.000
5,79.440,0.00,1.9257,1.92570,5.000
5,79.580,0.01,2.0656,2.06560,5.000
5,79.720,0.00,2.2057,2.20570,5.000
5,79.860,0.01,2.3458,2.34580,5.000
5,80.000,0.01,2.4860,2.48600,5.000
5,80.140,0.00,2.6257,2.62570,5.000
5,80.280,0.00,2.7659,2.76590,5.000
5,80.420,0.00,2.9057,2.90570,5.000
5,80.560,0.01,3.0459,3.04590,5.000
5,80.700,0.00,3.1857,3.18570,5.000
5,80.840,0.00,3.3259,3.32590,5.000
5,80.980,0.00,3.4658,3.46580,5.000
5,81.120,0.01,3.6059,3.60590,5.000
5,81.260,0.00,3.7458,3.74580,5.000
5,81.400,0.01,3.8858,3.88580,5.000
5,81.540,0.00,4.0258,4.02580,5.000
5,81.680,0.01,4.1659,4.16590,5.000
5,81.820,0.00,4.3057,4.30570,5.000
5,81.960,0.01,4.4459,4.44590,5.000
5,82.100,0.00,4.5857,4.58570,5.000
5,82.240,0.01,4.7259,4.72590,5.000
5,82.380,0.01,4.8659,4.86590,5.000
5,82.520,0.01,5.0059,5.00590,5.000
5,82.660,0.01,5.1457,5.14570,5.000
5,82.800,0.03,5.2861,5.28610,5.000
5,82.940,0.10,5.4258,5.42580,5.000
5,83.080,0.29,5.5660,5.56600,5.000
5,83.220,0.63,5.7059,5.70590,5.000
5,83.360,1.10,5.8458,5.84580,5.000
5,83.500,1.73,5.9859,5.98590,5.000
5,83.640,2.51,6.1259,6.12590,5.000
5,83.780,3.45,6.2658,6.26580,5.000
5,83.920,4.57,6.4058,6.40580,5.000
5,84.080,5.45,6.4849,6.48490,5.000
5,84.220,3.89,6.3447,6.34470,5.000
5,84.360,2.75,6.2047,6.20470,5.000
5,84.500,1.87,6.0646,6.06460,5.000
5,84.640,1.20,5.9247,5.92470,5.000
5,84.780,0.70,5.7845,5.78450,5.000
5,84.920,0.34,5.6447,5.64470,5.000
5,85.060,0.13,5.5044,5.50440,5.000
5,85.200,0.04,5.3647,5.36470,5.000
5,85.340,0.01,5.2246,5.22460,5.000
5,85.480,0.01,5.0846,5.08460,5.000
5,85.620,0.01,4.9445,4.94450,5.000
5,85.760,0.01,4.8046,4.80460,5.000
5,85.900,0.00,4.6644,4.66440,5.000
5,86.040,0.01,4.5246,4.52460,5.000
5,86.180,0.01,4.3844,4.38440,5.000
5,86.320,0.00,4.2445,4.24450,5.000
5,86.460,0.00,4.1044,4.10440,5.000
5,86.600,0.01,3.9644,3.96440,5.000
5,86.740,0.01,3.8244,3.82440,5.000
5,86.880,0.00,3.6845,3.68450,5.000
5,87.020,0.01,3.5443,3.54430,5.000
5,87.160,0.01,3.4046,3.40460,5.000
5,87.300,0.01,3.2643,3.26430,5.000
5,87.440,0.00,3.1245,3.12450,5.000
5,87.580,0.00,2.9842,2.98420,5.000
5,87.720,0.01,2.8444,2.84440,5.000
5,87.860,0.00,2.7042,2.70420,5.000
5,88.000,0.01,2.5643,2.56430,5.000
5,88.140,0.01,2.4244,2.42440,5.000
5,88.280,0.01,2.2845,2.28450,5.000
5,88.420,0.01,2.1442,2.14420,5.000
5,88.560,0.01,2.0043,2.00430,5.000
5,88.700,0.00,1.8642,1.86420,5.000
5,88.840,0.00,1.7242,1.72420,5.000
5,88.980,0.00,1.5842,1.58420,5.000
5,89.120,0.00,1.4442,1.44420,5.000
5,89.260,0.00,1.3040,1.30400,5.000
5,89.400,0.00,1.1644,1.16440,5.000
5,89.540,0.01,1.0241,1.02410,5.000
5,89.680,0.01,0.8842,0.88420,5.000
5,89.820,0.01,0.7441,0.74410,5.000
5,89.960,0.00,0.6041,0.60410,5.000
5,90.100,0.01,0.4642,0.46420,5.000
5,90.240,0.00,0.3243,0.32430,5.000
5,90.380,0.00,0.1841,0.18410,5.000
5,90.520,0.00,0.0442,0.04420,5.000
5,90.680,0.00,-0.0222,-0.02220,5.000
5,90.820,0.01,-0.0003,-0.00030,5.000
5,90.960,0.01,-0.0003,-0.00030,5.000
5,91.100,0.00,-0.0003,-0.00030,5.000
5,91.240,0.00,-0.0003,-0.00030,5.000
5,91.380,0.01,-0.0003,-0.00030,5.000
5,91.520,0.00,-0.0003,-0.00030,5.000
5,91.660,0.01,-0.0003,-0.00030,5.000
5,91.800,0.00,-0.0003,-0.00030,5.000
5,91.940,0.00,-0.0003,-0.00030,5.000
5,92.080,0.00,-0.0003,-0.00030,5.000
5,92.220,0.01,-0.0003,-0.00030,5.000
5,92.360,0.00,-0.0003,-0.00030,5.000
5,92.500,0.00,-0.0003,-0.00030,5.000
5,92.640,0.00,-0.0002,-0.00020,5.000
5,92.780,0.00,-0.0002,-0.00020,5.000
5,92.920,0.01,-0.0002,-0.00020,5.000
5,93.060,0.01,-0.0002,-0.00020,5.000
5,93.200,0.01,-0.0002,-0.00020,5.000
5,93.340,0.01,-0.0002,-0.00020,5.000
5,93.480,0.01,-0.0002,-0.00020,5.000
5,93.620,0.01,-0.0002,-0.00020,5.000
5,93.770,0.00,-0.0002,-0.00020,5.000
5,93.910,0.01,-0.0002,-0.00020,5.000
5,94.050,0.01,-0.0002,-0.00020,5.000
5,94.190,0.01,-0.0002,-0.00020,5.000
5,94.330,0.00,-0.0002,-0.00020,5.000
5,94.470,0.00,-0.0002,-0.00020,5.000
5,94.610,0.00,-0.0002,-0.00020,5.000
5,94.750,0.00,-0.0002,-0.00020,5.000
5,94.890,0.00,-0.0002,-0.00020,5.000
5,95.030,0.01,-0.0002,-0.00020,5.000
5,95.170,0.00,-0.0002,-0.00020,5.000
5,95.310,0.00,-0.0001,-0.00010,5.000
5,95.450,0.01,-0.0001,-0.00010,5.000
5,95.590,0.01,-0.0001,-0.00010,5.000
5,95.730,0.00,-0.0001,-0.00010,5.000
5,95.870,0.00,-0.0001,-0.00010,5.000
5,96.010,0.00,-0.0001,-0.00010,5.000
5,96.150,0.00,-0.0001,-0.00010,5.000
5,96.290,0.00,-0.0001,-0.00010,5.000
5,96.430,0.00,-0.0001,-0.00010,5.000
5,96.570,0.00,-0.0001,-0.00010,5.000
6,96.800,0.00,0.0000,0.00000,6.000
6,96.950,0.00,0.0954,0.09540,6.000
6,97.090,0.00,0.2357,0.23570,6.000
6,97.230,0.00,0.3757,0.37570,6.000
6,97.370,0.00,0.5157,0.51570,6.000
6,97.510,0.00,0.6556,0.65560,6.000
6,97.650,0.00,0.7958,0.79580,6.000
6,97.790,0.00,0.9357,0.93570,6.000
6,97.930,0.00,1.0757,1.07570,6.000
6,98.070,0.00,1.2159,1.21590,6.000
6,98.210,0.00,1.3556,1.35560,6.000
6,98.350,0.00,1.4957,1.49570,6.000
6,98.490,0.00,1.6358,1.63580,6.000
6,98.630,0.00,1.7757,1.77570,6.000
6,98.770,0.00,1.9158,1.91580,6.000
6,98.910,0.00,2.0556,2.05560,6.000
6,99.050,0.00,2.1958,2.19580,6.000
6,99.190,0.00,2.3358,2.33580,6.000
6,99.330,0.00,2.4758,2.47580,6.000
6,99.470,0.00,2.6157,2.61570,6.000
6,99.610,0.00,2.7558,2.75580,6.000
6,99.750,0.00,2.8957,2.89570,6.000
6,99.890,0.00,3.0357,3.03570,6.000
6,100.030,0.00,3.1758,3.17580,6.000
6,100.170,0.00,3.3158,3.31580,6.000
6,100.310,0.00,3.4558,3.45580,6.000
6,100.450,0.01,3.5959,3.59590,6.000
6,100.590,0.00,3.7358,3.73580,6.000
6,100.730,0.00,3.8759,3.87590,6.000
6,100.870,0.00,4.0158,4.01580,6.000
6,101.010,0.00,4.1558,4.15580,6.000
6,101.150,0.00,4.2958,4.29580,6.000
6,101.290,0.00,4.4358,4.43580,6.000
6,101.430,0.00,4.5759,4.57590,6.000
6,101.570,0.00,4.7159,4.71590,6.000
6,101.710,0.00,4.8561,4.85610,6.000
6,101.850,0.00,4.9958,4.99580,6.000
6,101.990,0.00,5.1359,5.13590,6.000
6,102.130,0.02,5.2760,5.27600,6.000
6,102.270,0.09,5.4160,5.41600,6.000
6,102.410,0.26,5.5559,5.55590,6.000
6,102.550,0.59,5.6961,5.69610,6.000
6,102.690,1.06,5.8358,5.83580,6.000
6,102.830,1.67,5.9759,5.97590,6.000
6,102.970,2.45,6.1159,6.11590,6.000
6,103.110,3.37,6.2560,6.25600,6.000
6,103.250,4.48,6.3957,6.39570,6.000
6,103.410,5.43,6.4826,6.48260,6.000
6,103.550,3.88,6.3425,6.34250,6.000
6,103.690,2.74,6.2027,6.20270,6.000
6,103.830,1.86,6.0626,6.06260,6.000
6,103.970,1.18,5.9227,5.92270,6.000
6,104.110,0.68,5.7826,5.78260,6.000
6,104.250,0.33,5.6427,5.64270,6.000
6,104.390,0.12,5.5026,5.50260,6.000
6,104.530,0.02,5.3626,5.36260,6.000
6,104.670,0.00,5.2225,5.22250,6.000
6,104.810,0.00,5.0826,5.08260,6.000
6,104.950,0.00,4.9425,4.94250,6.000
6,105.090,-0.01,4.8027,4.80270,6.000
6,105.230,0.00,4.6625,4.66250,6.000
6,105.370,0.00,4.5226,4.52260,6.000
6,105.510,0.00,4.3824,4.38240,6.000
6,105.650,0.00,4.2426,4.24260,6.000
6,105.790,0.00,4.1025,4.10250,6.000
6,105.930,0.00,3.9625,3.96250,6.000
6,106.070,0.00,3.8223,3.82230,6.000
6,106.210,0.00,3.6825,3.68250,6.000
6,106.350,0.00,3.5423,3.54230,6.000
6,106.490,0.00,3.4025,3.40250,6.000
6,106.630,0.00,3.2622,3.26220,6.000
6,106.770,0.00,3.1225,3.12250,6.000
6,106.910,0.00,2.9823,2.98230,6.000
6,107.050,0.00,2.8425,2.84250,6.000
6,107.190,0.00,2.7022,2.70220,6.000
6,107.330,0.00,2.5623,2.56230,6.000
6,107.470,0.00,2.4223,2.42230,6.000
6,107.610,0.00,2.2824,2.28240,6.000
6,107.750,-0.01,2.1422,2.14220,6.000
6,107.890,0.00,2.0023,2.00230,6.000
6,108.030,-0.01,1.8622,1.86220,6.000
6,108.170,0.00,1.7223,1.72230,6.000
6,108.310,0.00,1.5822,1.58220,6.000
6,108.450,0.00,1.4422,1.44220,6.000
6,108.590,0.00,1.3021,1.30210,6.000
6,108.730,0.00,1.1625,1.16250,6.000
6,108.870,0.00,1.0221,1.02210,6.000
6,109.010,0.00,0.8824,0.88240,6.000
6,109.150,0.00,0.7421,0.74210,6.000
6,109.290,0.00,0.6023,0.60230,6.000
6,109.430,-0.01,0.4620,0.46200,6.000
6,109.570,0.00,0.3223,0.32230,6.000
6,109.710,0.00,0.1821,0.18210,6.000
6,109.850,0.00,0.0422,0.04220,6.000
6,110.000,0.00,-0.0345,-0.03450,6.000
6,110.140,0.00,-0.0003,-0.00030,6.000
6,110.280,0.00,-0.0003,-0.00030,6.000
6,110.420,0.00,-0.0003,-0.00030,6.000
6,110.560,0.00,-0.0003,-0.00030,6.000
6,110.700,0.00,-0.0003,-0.00030,6.000
6,110.840,0.00,-0.0003,-0.00030,6.000
6,110.980,0.00,-0.0003,-0.00030,6.000
6,111.120,0.00,-0.0003,-0.00030,6.000
6,111.260,0.00,-0.0003,-0.00030,6.000
6,111.400,0.00,-0.0003,-0.00030,6.000
6,111.540,0.00,-0.0003,-0.00030,6.000
6,111.680,0.00,-0.0003,-0.00030,6.000
6,111.820,0.00,-0.0003,-0.00030,6.000
6,111.960,0.00,-0.0003,-0.00030,6.000
6,112.100,0.00,-0.0002,-0.00020,6.000
6,112.240,0.00,-0.0002,-0.00020,6.000
6,112.380,0.00,-0.0002,-0.00020,6.000
6,112.520,0.00,-0.0002,-0.00020,6.000
6,112.660,0.00,-0.0002,-0.00020,6.000
6,112.800,0.00,-0.0002,-0.00020,6.000
6,112.940,0.00,-0.0002,-0.00020,6.000
6,113.090,0.00,-0.0002,-0.00020,6.000
6,113.230,0.00,-0.0002,-0.00020,6.000
6,113.370,0.00,-0.0002,-0.00020,6.000
6,113.510,0.00,-0.0002,-0.00020,6.000
6,113.650,0.00,-0.0002,-0.00020,6.000
6,113.790,0.00,-0.0002,-0.00020,6.000
6,113.930,0.00,-0.0002,-0.00020,6.000
6,114.070,0.00,-0.0002,-0.00020,6.000
6,114.210,0.00,-0.0002,-0.00020,6.000
6,114.350,0.00,-0.0002,-0.00020,6.000
6,114.490,0.00,-0.0002,-0.00020,6.000
6,114.630,0.00,-0.0002,-0.00020,6.000
6,114.770,0.00,-0.0001,-0.00010,6.000
6,114.910,0.00,-0.0001,-0.00010,6.000
6,115.050,0.00,-0.0001,-0.00010,6.000
6,115.190,0.00,-0.0001,-0.00010,6.000
6,115.330,0.00,-0.0001,-0.00010,6.000
6,115.470,-0.01,-0.0001,-0.00010,6.000
6,115.610,0.00,-0.0001,-0.00010,6.000
6,115.750,0.00,-0.0001,-0.00010,6.000
6,115.890,0.00,-0.0001,-0.00010,6.000
6,116.120,0.00,0.0000,0.00000,6.000
7,116.270,0.00,0.0856,0.08560,7.000
7,116.410,0.00,0.2256,0.22560,7.000
7,116.550,0.00,0.3659,0.36590,7.000
7,116.690,0.00,0.5057,0.50570,7.000
7,116.830,0.00,0.6458,0.64580,7.000
7,116.970,0.00,0.7856,0.78560,7.000
7,117.110,0.00,0.9257,0.92570,7.000
7,117.250,0.00,1.0657,1.06570,7.000
7,117.390,0.00,1.2059,1.20590,7.000
7,117.530,0.00,1.3456,1.34560,7.000
7,117.670,0.00,1.4858,1.48580,7.000
7,117.810,0.00,1.6257,1.62570,7.000
7,117.950,0.00,1.7657,1.76570,7.000
7,118.090,0.00,1.9057,1.90570,7.000
7,118.230,0.00,2.0457,2.04570,7.000
7,118.370,0.00,2.1856,2.18560,7.000
7,118.510,0.00,2.3259,2.32590,7.000
7,118.650,0.00,2.4657,2.46570,7.000
7,118.790,0.00,2.6057,2.60570,7.000
7,118.930,0.00,2.7457,2.74570,7.000
7,119.070,0.00,2.8859,2.88590,7.000
7,119.210,0.00,3.0258,3.02580,7.000
7,119.350,0.00,3.1659,3.16590,7.000
7,119.490,0.00,3.3057,3.30570,7.000
7,119.630,0.00,3.4459,3.44590,7.000
7,119.770,0.00,3.5858,3.58580,7.000
7,119.910,0.00,3.7259,3.72590,7.000
7,120.050,-0.01,3.8656,3.86560,7.000
7,120.190,0.00,4.0059,4.00590,7.000
7,120.330,0.00,4.1456,4.14560,7.000
7,120.470,0.00,4.2858,4.28580,7.000
7,120.610,0.00,4.4257,4.42570,7.000
7,120.750,0.00,4.5658,4.56580,7.000
7,120.890,0.00,4.7058,4.70580,7.000
7,121.030,0.00,4.8459,4.84590,7.000
7,121.170,0.00,4.9858,4.98580,7.000
7,121.310,0.00,5.1258,5.12580,7.000
7,121.450,0.02,5.2658,5.26580,7.000
7,121.590,0.08,5.4060,5.40600,7.000
7,121.730,0.25,5.5458,5.54580,7.000
7,121.870,0.56,5.6859,5.68590,7.000
7,122.010,1.02,5.8257,5.82570,7.000
7,122.150,1.61,5.9659,5.96590,7.000
7,122.290,2.38,6.1059,6.10590,7.000
7,122.430,3.29,6.2459,6.24590,7.000
7,122.570,4.38,6.3858,6.38580,7.000
7,122.720,5.64,6.5088,6.50880,7.000
7,122.860,4.23,6.3825,6.38250,7.000
7,123.000,3.01,6.2427,6.24270,7.000
7,123.140,2.08,6.1027,6.10270,7.000
7,123.280,1.35,5.9628,5.96280,7.000
7,123.420,0.80,5.8225,5.82250,7.000
7,123.560,0.42,5.6827,5.68270,7.000
7,123.700,0.16,5.5426,5.54260,7.000
7,123.840,0.04,5.4027,5.40270,7.000
7,123.980,0.00,5.2627,5.26270,7.000
7,124.120,0.00,5.1226,5.12260,7.000
7,124.260,0.00,4.9825,4.98250,7.000
7,124.400,0.00,4.8426,4.84260,7.000
7,124.540,0.00,4.7025,4.70250,7.000
7,124.680,0.00,4.5625,4.56250,7.000
7,124.820,-0.01,4.4224,4.42240,7.000
7,124.960,0.00,4.2825,4.28250,7.000
7,125.100,0.00,4.1424,4.14240,7.000
7,125.240,0.00,4.0025,4.00250,7.000
7,125.380,0.00,3.8624,3.86240,7.000
7,125.520,0.00,3.7226,3.72260,7.000
7,125.660,0.00,3.5823,3.58230,7.000
7,125.800,0.00,3.4426,3.44260,7.000
7,125.940,0.00,3.3023,3.30230,7.000
7,126.080,0.00,3.1624,3.16240,7.000
7,126.220,0.00,3.0223,3.02230,7.000
7,126.360,0.00,2.8824,2.88240,7.000
7,126.500,0.00,2.7423,2.74230,7.000
7,126.640,0.00,2.6023,2.60230,7.000
7,126.780,0.00,2.4623,2.46230,7.000
7,126.920,0.00,2.3225,2.32250,7.000
7,127.060,0.00,2.1822,2.18220,7.000
7,127.200,0.00,2.0423,2.04230,7.000
7,127.340,-0.01,1.9021,1.90210,7.000
7,127.480,0.00,1.7623,1.76230,7.000
7,127.620,-0.01,1.6221,1.62210,7.000
7,127.760,0.00,1.4823,1.48230,7.000
7,127.900,0.00,1.3420,1.34200,7.000
7,128.040,0.00,1.2025,1.20250,7.000
7,128.180,0.00,1.0622,1.06220,7.000
7,128.320,0.00,0.9224,0.92240,7.000
7,128.460,0.00,0.7822,0.78220,7.000
7,128.600,0.00,0.6422,0.64220,7.000
7,128.740,0.00,0.5020,0.50200,7.000
7,128.880,0.00,0.3622,0.36220,7.000
7,129.020,0.00,0.2221,0.22210,7.000
7,129.160,0.00,0.0821,0.08210,7.000
7,129.320,0.00,-0.0495,-0.04950,7.000
7,129.460,-0.01,-0.0003,-0.00030,7.000
7,129.600,0.00,-0.0002,-0.00020,7.000
7,129.740,0.00,-0.0002,-0.00020,7.000
7,129.880,0.00,-0.0002,-0.00020,7.000
7,130.020,0.00,-0.0002,-0.00020,7.000
7,130.160,0.00,-0.0002,-0.00020,7.000
7,130.300,0.00,-0.0002,-0.00020,7.000
7,130.440,0.00,-0.0002,-0.00020,7.000
7,130.580,0.00,-0.0002,-0.00020,7.000
7,130.720,0.00,-0.0002,-0.00020,7.000
7,130.860,0.00,-0.0002,-0.00020,7.000
7,131.000,0.00,-0.0002,-0.00020,7.000
7,131.140,0.00,-0.0002,-0.00020,7.000
7,131.280,0.00,-0.0002,-0.00020,7.000
7,131.420,0.00,-0.0002,-0.00020,7.000
7,131.560,0.00,-0.0002,-0.00020,7.000
7,131.700,0.00,-0.0002,-0.00020,7.000
7,131.840,0.00,-0.0002,-0.00020,7.000
7,131.980,0.00,-0.0002,-0.00020,7.000
7,132.120,0.00,-0.0002,-0.00020,7.000
7,132.260,0.00,-0.0002,-0.00020,7.000
7,132.420,0.00,-0.0002,-0.00020,7.000
7,132.560,0.00,-0.0002,-0.00020,7.000
7,132.700,0.00,-0.0002,-0.00020,7.000
7,132.840,0.00,-0.0002,-0.00020,7.000
7,132.980,0.00,-0.0002,-0.00020,7.000
7,133.120,0.00,-0.0002,-0.00020,7.000
7,133.260,0.00,-0.0002,-0.00020,7.000
7,133.400,0.00,-0.0002,-0.00020,7.000
7,133.540,0.00,-0.0002,-0.00020,7.000
7,133.680,0.00,-0.0002,-0.00020,7.000
7,133.820,0.00,-0.0002,-0.00020,7.000
7,133.960,0.00,-0.0002,-0.00020,7.000
7,134.100,0.00,-0.0002,-0.00020,7.000
7,134.240,-0.01,-0.0001,-0.00010,7.000
7,134.380,0.00,-0.0001,-0.00010,7.000
7,134.520,0.00,-0.0001,-0.00010,7.000
7,134.660,0.00,-0.0001,-0.00010,7.000
7,134.800,0.00,-0.0001,-0.00010,7.000
7,134.940,0.00,-0.0001,-0.00010,7.000
7,135.080,0.00,-0.0001,-0.00010,7.000
7,135.220,0.00,-0.0001,-0.00010,7.000
7,135.360,0.00,-0.0001,-0.00010,7.000
8,135.600,0.00,0.0754,0.07540,8.000
8,135.740,0.01,0.2155,0.21550,8.000
8,135.880,0.01,0.3557,0.35570,8.000
8,136.020,0.01,0.4956,0.49560,8.000
8,136.160,0.01,0.6356,0.63560,8.000
8,136.300,0.01,0.7756,0.77560,8.000
8,136.440,0.01,0.9157,0.91570,8.000
8,136.580,0.01,1.0557,1.05570,8.000
8,136.720,0.01,1.1959,1.19590,8.000
8,136.860,0.01,1.3356,1.33560,8.000
8,137.000,0.00,1.4758,1.47580,8.000
8,137.140,0.01,1.6157,1.61570,8.000
8,137.280,0.01,1.7557,1.75570,8.000
8,137.420,0.01,1.8957,1.89570,8.000
8,137.560,0.01,2.0357,2.03570,8.000
8,137.700,0.01,2.1757,2.17570,8.000
8,137.840,0.01,2.3158,2.31580,8.000
8,137.980,0.01,2.4558,2.45580,8.000
8,138.120,0.01,2.5956,2.59560,8.000
8,138.260,0.01,2.7358,2.73580,8.000
8,138.400,0.01,2.8757,2.87570,8.000
8,138.540,0.01,3.0158,3.01580,8.000
8,138.680,0.01,3.1557,3.15570,8.000
8,138.820,0.01,3.2958,3.29580,8.000
8,138.960,0.01,3.4359,3.43590,8.000
8,139.100,0.01,3.5760,3.57600,8.000
8,139.240,0.01,3.7158,3.71580,8.000
8,139.380,0.01,3.8558,3.85580,8.000
8,139.520,0.00,3.9959,3.99590,8.000
8,139.660,0.01,4.1359,4.13590,8.000
8,139.800,0.01,4.2758,4.27580,8.000
8,139.940,0.01,4.4158,4.41580,8.000
8,140.080,0.01,4.5558,4.55580,8.000
8,140.220,0.01,4.6960,4.69600,8.000
8,140.360,0.01,4.8359,4.83590,8.000
8,140.500,0.01,4.9760,4.97600,8.000
8,140.640,0.01,5.1158,5.11580,8.000
8,140.780,0.02,5.2561,5.25610,8.000
8,140.920,0.08,5.3959,5.39590,8.000
8,141.060,0.24,5.5360,5.53600,8.000
8,141.200,0.55,5.6760,5.67600,8.000
8,141.340,0.99,5.8159,5.81590,8.000
8,141.480,1.58,5.9558,5.95580,8.000
8,141.620,2.33,6.0960,6.09600,8.000
8,141.760,3.23,6.2358,6.23580,8.000
8,141.900,4.30,6.3760,6.37600,8.000
8,142.060,5.54,6.4959,6.49590,8.000
8,142.200,4.06,6.3626,6.36260,8.000
8,142.340,2.88,6.2227,6.22270,8.000
8,142.480,1.97,6.0826,6.08260,8.000
8,142.620,1.27,5.9425,5.94250,8.000
8,142.760,0.76,5.8025,5.80250,8.000
8,142.900,0.38,5.6626,5.66260,8.000
8,143.040,0.14,5.5226,5.52260,8.000
8,143.180,0.04,5.3827,5.38270,8.000
8,143.320,0.01,5.2427,5.24270,8.000
8,143.460,0.01,5.1026,5.10260,8.000
8,143.600,0.01,4.9626,4.96260,8.000
8,143.740,0.01,4.8225,4.82250,8.000
8,143.880,0.01,4.6825,4.68250,8.000
8,144.020,0.01,4.5423,4.54230,8.000
8,144.160,0.01,4.4024,4.40240,8.000
8,144.300,0.01,4.2625,4.26250,8.000
8,144.440,0.01,4.1225,4.12250,8.000
8,144.580,0.01,3.9823,3.98230,8.000
8,144.720,0.01,3.8424,3.84240,8.000
8,144.860,0.01,3.7024,3.70240,8.000
8,145.000,0.01,3.5624,3.56240,8.000
8,145.140,0.01,3.4223,3.42230,8.000
8,145.280,0.01,3.2824,3.28240,8.000
8,145.420,0.01,3.1424,3.14240,8.000
8,145.560,0.01,3.0024,3.00240,8.000
8,145.700,0.01,2.8623,2.86230,8.000
8,145.840,0.01,2.7224,2.72240,8.000
8,145.980,0.00,2.5822,2.58220,8.000
8,146.120,0.01,2.4425,2.44250,8.000
8,146.260,0.00,2.3023,2.30230,8.000
8,146.400,0.01,2.1624,2.16240,8.000
8,146.540,0.01,2.0222,2.02220,8.000
8,146.680,0.01,1.8824,1.88240,8.000
8,146.820,0.01,1.7420,1.74200,8.000
8,146.960,0.01,1.6024,1.60240,8.000
8,147.100,0.01,1.4621,1.46210,8.000
8,147.240,0.01,1.3222,1.32220,8.000
8,147.380,0.01,1.1824,1.18240,8.000
8,147.520,0.01,1.0423,1.04230,8.000
8,147.660,0.01,0.9021,0.90210,8.000
8,147.800,0.01,0.7622,0.76220,8.000
8,147.940,0.00,0.6220,0.62200,8.000
8,148.080,0.01,0.4824,0.48240,8.000
8,148.220,0.01,0.3422,0.34220,8.000
8,148.360,0.01,0.2023,0.20230,8.000
8,148.500,0.01,0.0619,0.06190,8.000
8,148.650,0.01,-0.0477,-0.04770,8.000
8,148.790,0.01,-0.0003,-0.00030,8.000
8,148.930,0.00,-0.0003,-0.00030,8.000
8,149.070,0.01,-0.0003,-0.00030,8.000
8,149.210,0.01,-0.0003,-0.00030,8.000
8,149.350,0.01,-0.0003,-0.00030,8.000
8,149.490,0.01,-0.0003,-0.00030,8.000
8,149.630,0.01,-0.0003,-0.00030,8.000
8,149.770,0.01,-0.0003,-0.00030,8.000
8,149.910,0.01,-0.0003,-0.00030,8.000
8,150.050,0.01,-0.0003,-0.00030,8.000
8,150.190,0.01,-0.0003,-0.00030,8.000
8,150.330,0.01,-0.0003,-0.00030,8.000
8,150.470,0.01,-0.0003,-0.00030,8.000
8,150.610,0.01,-0.0002,-0.00020,8.000
8,150.750,0.01,-0.0002,-0.00020,8.000
8,150.890,0.01,-0.0002,-0.00020,8.000
8,151.030,0.01,-0.0002,-0.00020,8.000
8,151.170,0.01,-0.0002,-0.00020,8.000
8,151.310,0.01,-0.0002,-0.00020,8.000
8,151.450,0.01,-0.0002,-0.00020,8.000
8,151.590,0.01,-0.0002,-0.00020,8.000
8,151.750,0.01,-0.0002,-0.00020,8.000
8,151.890,0.01,-0.0002,-0.00020,8.000
8,152.030,0.01,-0.0002,-0.00020,8.000
8,152.170,0.01,-0.0002,-0.00020,8.000
8,152.310,0.00,-0.0002,-0.00020,8.000
8,152.450,0.01,-0.0002,-0.00020,8.000
8,152.590,0.01,-0.0002,-0.00020,8.000
8,152.730,0.01,-0.0002,-0.00020,8.000
8,152.870,0.01,-0.0002,-0.00020,8.000
8,153.010,0.00,-0.0002,-0.00020,8.000
8,153.150,0.01,-0.0002,-0.00020,8.000
8,153.290,0.01,-0.0002,-0.00020,8.000
8,153.430,0.01,-0.0001,-0.00010,8.000
8,153.570,0.00,-0.0001,-0.00010,8.000
8,153.710,0.01,-0.0001,-0.00010,8.000
8,153.850,0.00,-0.0001,-0.00010,8.000
8,153.990,0.01,-0.0001,-0.00010,8.000
8,154.130,0.01,-0.0001,-0.00010,8.000
8,154.270,0.01,-0.0001,-0.00010,8.000
8,154.410,0.01,-0.0001,-0.00010,8.000
8,154.550,0.00,-0.0001,-0.00010,8.000
8,154.780,0.00,0.0000,0.00000,8.000
9,154.930,0.00,0.0856,0.08560,9.000
9,155.070,0.00,0.2256,0.22560,9.000
9,155.210,0.00,0.3658,0.36580,9.000
9,155.350,0.00,0.5057,0.50570,9.000
9,155.490,0.00,0.6457,0.64570,9.000
9,155.630,0.00,0.7856,0.78560,9.000
9,155.770,0.00,0.9258,0.92580,9.000
9,155.910,0.00,1.0656,1.06560,9.000
9,156.050,0.00,1.2060,1.20600,9.000
9,156.190,0.00,1.3455,1.34550,9.000
9,156.330,0.00,1.4858,1.48580,9.000
9,156.470,0.00,1.6257,1.62570,9.000
9,156.610,0.00,1.7658,1.76580,9.000
9,156.750,0.00,1.9056,1.90560,9.000
9,156.890,0.00,2.0457,2.04570,9.000
9,157.030,0.00,2.1856,2.18560,9.000
9,157.170,-0.01,2.3259,2.32590,9.000
9,157.310,0.00,2.4657,2.46570,9.000
9,157.450,0.01,2.6057,2.60570,9.000
9,157.590,0.00,2.7457,2.74570,9.000
9,157.730,0.00,2.8859,2.88590,9.000
9,157.870,0.00,3.0256,3.02560,9.000
9,158.010,0.00,3.1658,3.16580,9.000
9,158.150,0.00,3.3057,3.30570,9.000
9,158.290,0.00,3.4459,3.44590,9.000
9,158.430,0.01,3.5858,3.58580,9.000
9,158.570,0.00,3.7258,3.72580,9.000
9,158.710,0.00,3.8657,3.86570,9.000
9,158.850,0.00,4.0059,4.00590,9.000
9,158.990,0.00,4.1458,4.14580,9.000
9,159.130,0.00,4.2858,4.28580,9.000
9,159.270,0.00,4.4257,4.42570,9.000
9,159.410,0.00,4.5659,4.56590,9.000
9,159.550,0.00,4.7058,4.70580,9.000
9,159.690,0.00,4.8459,4.84590,9.000
9,159.830,0.00,4.9858,4.98580,9.000
9,159.970,0.00,5.1258,5.12580,9.000
9,160.110,0.01,5.2658,5.26580,9.000
9,160.250,0.08,5.4060,5.40600,9.000
9,160.390,0.24,5.5459,5.54590,9.000
9,160.530,0.57,5.6860,5.68600,9.000
9,160.670,1.02,5.8258,5.82580,9.000
9,160.810,1.61,5.9659,5.96590,9.000
9,160.950,2.38,6.1059,6.10590,9.000
9,161.090,3.29,6.2459,6.24590,9.000
9,161.230,4.38,6.3858,6.38580,9.000
9,161.380,5.64,6.5088,6.50880,9.000
9,161.520,4.23,6.3826,6.38260,9.000
9,161.660,3.01,6.2426,6.24260,9.000
9,161.800,2.07,6.1026,6.10260,9.000
9,161.940,1.34,5.9626,5.96260,9.000
9,162.080,0.80,5.8225,5.82250,9.000
9,162.220,0.42,5.6826,5.68260,9.000
9,162.360,0.16,5.5425,5.54250,9.000
9,162.500,0.04,5.4026,5.40260,9.000
9,162.640,0.00,5.2627,5.26270,9.000
9,162.780,0.00,5.1225,5.12250,9.000
9,162.920,0.00,4.9825,4.98250,9.000
9,163.060,0.00,4.8425,4.84250,9.000
9,163.200,0.00,4.7026,4.70260,9.000
9,163.340,0.00,4.5625,4.56250,9.000
9,163.480,0.00,4.4224,4.42240,9.000
9,163.620,0.00,4.2825,4.28250,9.000
9,163.760,0.00,4.1425,4.14250,9.000
9,163.900,0.00,4.0025,4.00250,9.000
9,164.040,0.00,3.8624,3.86240,9.000
9,164.180,0.00,3.7224,3.72240,9.000
9,164.320,0.00,3.5824,3.58240,9.000
9,164.460,0.00,3.4425,3.44250,9.000
9,164.600,0.00,3.3023,3.30230,9.000
9,164.740,0.00,3.1625,3.16250,9.000
9,164.880,-0.01,3.0223,3.02230,9.000
9,165.020,0.00,2.8824,2.88240,9.000
9,165.160,0.00,2.7424,2.74240,9.000
9,165.300,0.00,2.6023,2.60230,9.000
9,165.440,0.01,2.4623,2.46230,9.000
9,165.580,-0.01,2.3225,2.32250,9.000
9,165.720,0.00,2.1823,2.18230,9.000
9,165.860,0.00,2.0424,2.04240,9.000
9,166.000,0.00,1.9022,1.90220,9.000
9,166.140,0.00,1.7624,1.76240,9.000
9,166.280,0.00,1.6223,1.62230,9.000
9,166.420,0.00,1.4823,1.48230,9.000
9,166.560,0.00,1.3421,1.34210,9.000
9,166.700,-0.01,1.2025,1.20250,9.000
9,166.840,0.00,1.0622,1.06220,9.000
9,166.980,0.00,0.9224,0.92240,9.000
9,167.120,0.00,0.7820,0.78200,9.000
9,167.260,0.00,0.6423,0.64230,9.000
9,167.400,0.00,0.5020,0.50200,9.000
9,167.540,0.00,0.3624,0.36240,9.000
9,167.680,0.00,0.2220,0.22200,9.000
9,167.820,0.00,0.0821,0.08210,9.000
9,167.980,0.00,-0.0508,-0.05080,9.000
9,168.120,0.00,-0.0003,-0.00030,9.000
9,168.260,0.00,-0.0003,-0.00030,9.000
9,168.400,0.00,-0.0003,-0.00030,9.000
9,168.540,0.00,-0.0003,-0.00030,9.000
9,168.680,0.00,-0.0003,-0.00030,9.000
9,168.820,0.00,-0.0003,-0.00030,9.000
9,168.960,0.00,-0.0003,-0.00030,9.000
9,169.100,0.00,-0.0003,-0.00030,9.000
9,169.240,0.00,-0.0003,-0.00030,9.000
9,169.380,0.00,-0.0003,-0.00030,9.000
9,169.520,0.00,-0.0003,-0.00030,9.000
9,169.660,0.00,-0.0003,-0.00030,9.000
9,169.800,0.00,-0.0003,-0.00030,9.000
9,169.940,0.00,-0.0003,-0.00030,9.000
9,170.080,0.00,-0.0003,-0.00030,9.000
9,170.220,0.00,-0.0002,-0.00020,9.000
9,170.360,0.00,-0.0002,-0.00020,9.000
9,170.500,0.00,-0.0002,-0.00020,9.000
9,170.640,0.00,-0.0002,-0.00020,9.000
9,170.780,-0.01,-0.0002,-0.00020,9.000
9,170.920,0.00,-0.0002,-0.00020,9.000
9,171.080,0.00,-0.0002,-0.00020,9.000
9,171.220,0.00,-0.0002,-0.00020,9.000
9,171.360,0.00,-0.0002,-0.00020,9.000
9,171.500,0.00,-0.0002,-0.00020,9.000
9,171.640,0.00,-0.0002,-0.00020,9.000
9,171.780,0.00,-0.0002,-0.00020,9.000
9,171.920,0.00,-0.0002,-0.00020,9.000
9,172.060,0.00,-0.0002,-0.00020,9.000
9,172.200,0.00,-0.0002,-0.00020,9.000
9,172.340,0.00,-0.0002,-0.00020,9.000
9,172.480,0.00,-0.0002,-0.00020,9.000
9,172.620,0.00,-0.0002,-0.00020,9.000
9,172.760,0.00,-0.0002,-0.00020,9.000
9,172.900,0.00,-0.0001,-0.00010,9.000
9,173.040,0.00,-0.0001,-0.00010,9.000
9,173.180,0.00,-0.0001,-0.00010,9.000
9,173.320,0.00,-0.0001,-0.00010,9.000
9,173.460,0.00,-0.0001,-0.00010,9.000
9,173.600,0.00,-0.0001,-0.00010,9.000
9,173.740,0.00,-0.0001,-0.00010,9.000
9,173.880,0.00,-0.0001,-0.00010,9.000
9,174.110,0.01,0.0000,0.00000,9.000
10,174.260,0.01,0.0855,0.08550,10.000
10,174.400,0.00,0.2256,0.22560,10.000
10,174.540,0.01,0.3657,0.36570,10.000
10,174.680,0.01,0.5056,0.50560,10.000
10,174.820,0.01,0.6457,0.64570,10.000
10,174.960,0.01,0.7856,0.78560,10.000
10,175.100,0.01,0.9257,0.92570,10.000
10,175.240,0.01,1.0657,1.06570,10.000
10,175.380,0.01,1.2059,1.20590,10.000
10,175.520,0.01,1.3455,1.34550,10.000
10,175.660,0.00,1.4859,1.48590,10.000
10,175.800,0.01,1.6257,1.62570,10.000
10,175.940,0.01,1.7657,1.76570,10.000
10,176.080,0.01,1.9056,1.90560,10.000
10,176.220,0.01,2.0458,2.04580,10.000
10,176.360,0.01,2.1856,2.18560,10.000
10,176.500,0.01,2.3260,2.32600,10.000
10,176.640,0.01,2.4657,2.46570,10.000
10,176.780,0.01,2.6058,2.60580,10.000
10,176.920,0.01,2.7457,2.74570,10.000
10,177.060,0.01,2.8859,2.88590,10.000
10,177.200,0.01,3.0258,3.02580,10.000
10,177.340,0.01,3.1659,3.16590,10.000
10,177.480,0.01,3.3057,3.30570,10.000
10,177.620,0.01,3.4458,3.44580,10.000
10,177.760,0.01,3.5857,3.58570,10.000
10,177.900,0.01,3.7258,3.72580,10.000
10,178.040,0.01,3.8657,3.86570,10.000
10,178.180,0.01,4.0059,4.00590,10.000
10,178.320,0.01,4.1458,4.14580,10.000
10,178.460,0.01,4.2858,4.28580,10.000
10,178.600,0.01,4.4257,4.42570,10.000
10,178.740,0.01,4.5658,4.56580,10.000
10,178.880,0.01,4.7058,4.70580,10.000
10,179.020,0.01,4.8460,4.84600,10.000
10,179.160,0.01,4.9859,4.98590,10.000
10,179.300,0.02,5.1258,5.12580,10.000
10,179.440,0.03,5.2659,5.26590,10.000
10,179.580,0.09,5.4059,5.40590,10.000
10,179.720,0.25,5.5459,5.54590,10.000
10,179.860,0.57,5.6859,5.68590,10.000
10,180.000,1.02,5.8258,5.82580,10.000
10,180.140,1.62,5.9659,5.96590,10.000
10,180.280,2.38,6.1060,6.10600,10.000
10,180.420,3.30,6.2459,6.24590,10.000
10,180.560,4.38,6.3858,6.38580,10.000
10,180.710,5.65,6.5088,6.50880,10.000
10,180.850,4.25,6.3826,6.38260,10.000
10,180.990,3.02,6.2427,6.24270,10.000
10,181.130,2.08,6.1027,6.10270,10.000
10,181.270,1.35,5.9625,5.96250,10.000
10,181.410,0.81,5.8225,5.82250,10.000
10,181.550,0.42,5.6827,5.68270,10.000
10,181.690,0.17,5.5426,5.54260,10.000
10,181.830,0.05,5.4026,5.40260,10.000
10,181.970,0.01,5.2626,5.26260,10.000
10,182.110,0.01,5.1225,5.12250,10.000
10,182.250,0.01,4.9826,4.98260,10.000
10,182.390,0.01,4.8425,4.84250,10.000
10,182.530,0.01,4.7026,4.70260,10.000
10,182.670,0.01,4.5625,4.56250,10.000
10,182.810,0.01,4.4225,4.42250,10.000
10,182.950,0.01,4.2825,4.28250,10.000
10,183.090,0.01,4.1424,4.14240,10.000
10,183.230,0.01,4.0025,4.00250,10.000
10,183.370,0.01,3.8624,3.86240,10.000
10,183.510,0.01,3.7226,3.72260,10.000
10,183.650,0.01,3.5824,3.58240,10.000
10,183.790,0.01,3.4425,3.44250,10.000
10,183.930,0.01,3.3024,3.30240,10.000
10,184.070,0.01,3.1625,3.16250,10.000
10,184.210,0.01,3.0223,3.02230,10.000
10,184.350,0.01,2.8825,2.88250,10.000
10,184.490,0.01,2.7425,2.74250,10.000
10,184.630,0.01,2.6024,2.60240,10.000
10,184.770,0.01,2.4624,2.46240,10.000
10,184.910,0.01,2.3224,2.32240,10.000
10,185.050,0.01,2.1823,2.18230,10.000
10,185.190,0.01,2.0423,2.04230,10.000
10,185.330,0.01,1.9021,1.90210,10.000
10,185.470,0.01,1.7623,1.76230,10.000
10,185.610,0.01,1.6222,1.62220,10.000
10,185.750,0.01,1.4824,1.48240,10.000
10,185.890,0.01,1.3421,1.34210,10.000
10,186.030,0.01,1.2025,1.20250,10.000
10,186.170,0.01,1.0623,1.06230,10.000
10,186.310,0.01,0.9223,0.92230,10.000
10,186.450,0.01,0.7822,0.78220,10.000
10,186.590,0.01,0.6423,0.64230,10.000
10,186.730,0.01,0.5022,0.50220,10.000
10,186.870,0.01,0.3623,0.36230,10.000
10,187.010,0.01,0.2221,0.22210,10.000
10,187.150,0.01,0.0822,0.08220,10.000
10,187.310,0.01,-0.0508,-0.05080,10.000
10,187.450,0.01,-0.0003,-0.00030,10.000
10,187.590,0.01,-0.0003,-0.00030,10.000
10,187.730,0.00,-0.0003,-0.00030,10.000
10,187.870,0.01,-0.0003,-0.00030,10.000
10,188.010,0.01,-0.0003,-0.00030,10.000
10,188.150,0.01,-0.0003,-0.00030,10.000
10,188.290,0.01,-0.0003,-0.00030,10.000
10,188.430,0.01,-0.0003,-0.00030,10.000
10,188.570,0.01,-0.0003,-0.00030,10.000
10,188.710,0.01,-0.0003,-0.00030,10.000
10,188.850,0.01,-0.0003,-0.00030,10.000
10,188.990,0.01,-0.0003,-0.00030,10.000
10,189.130,0.01,-0.0003,-0.00030,10.000
10,189.270,0.01,-0.0003,-0.00030,10.000
10,189.410,0.01,-0.0003,-0.00030,10.000
10,189.550,0.01,-0.0003,-0.00030,10.000
10,189.690,0.01,-0.0002,-0.00020,10.000
10,189.830,0.01,-0.0002,-0.00020,10.000
10,189.970,0.01,-0.0002,-0.00020,10.000
10,190.110,0.01,-0.0002,-0.00020,10.000
10,190.250,0.01,-0.0002,-0.00020,10.000
10,190.410,0.01,-0.0002,-0.00020,10.000
10,190.550,0.01,-0.0002,-0.00020,10.000
10,190.690,0.01,-0.0002,-0.00020,10.000
10,190.830,0.01,-0.0002,-0.00020,10.000
10,190.970,0.01,-0.0002,-0.00020,10.000
10,191.110,0.01,-0.0002,-0.00020,10.000
10,191.250,0.01,-0.0002,-0.00020,10.000
10,191.390,0.01,-0.0002,-0.00020,10.000
10,191.530,0.01,-0.0002,-0.00020,10.000
10,191.670,0.01,-0.0002,-0.00020,10.000
10,191.810,0.01,-0.0002,-0.00020,10.000
10,191.950,0.01,-0.0002,-0.00020,10.000
10,192.090,0.01,-0.0002,-0.00020,10.000
10,192.230,0.01,-0.0001,-0.00010,10.000
10,192.370,0.01,-0.0001,-0.00010,10.000
10,192.510,0.01,-0.0001,-0.00010,10.000
10,192.650,0.01,-0.0001,-0.00010,10.000
10,192.790,0.01,-0.0001,-0.00010,10.000
10,192.930,0.01,-0.0001,-0.00010,10.000
10,193.070,0.01,-0.0001,-0.00010,10.000
10,193.210,0.01,-0.0001,-0.00010,10.000
10,193.350,0.01,-0.0001,-0.00010,10.000