File: calibDATA_loadcell/date_30:1:2018/MTSdata_date_1.30/radhen_10cyc_black_2_0deg_1mms_5N.txt
""
"Test Method","Radhen_Load_Cntrl_Cmprsn_250N_12-7.msm"
"Sample I. D.","Sample1.mss"
"Specimen Number","19"

"TheCycle_Output ()","_Time (s)","_Load (N)","_Extension (mm)","RealTimeDepth (mm)","CycleNumber ()"

0,0.160,0.02,0.0000,0.00000,0.000
1,0.290,0.02,0.0666,0.06660,1.000
1,0.410,0.02,0.1866,0.18660,1.000
1,0.530,0.02,0.3067,0.30670,1.000
1,0.650,0.03,0.4267,0.42670,1.000
1,0.770,0.00,0.5466,0.54660,1.000
1,0.890,0.02,0.6666,0.66660,1.000
1,1.010,0.01,0.7868,0.78680,1.000
1,1.130,0.01,0.9068,0.90680,1.000
1,1.250,0.01,1.0268,1.02680,1.000
1,1.370,0.01,1.1467,1.14670,1.000
1,1.490,0.02,1.2668,1.26680,1.000
1,1.610,0.02,1.3868,1.38680,1.000
1,1.730,0.02,1.5068,1.50680,1.000
1,1.850,0.01,1.6269,1.62690,1.000
1,1.970,0.01,1.7469,1.74690,1.000
1,2.090,0.02,1.8668,1.86680,1.000
1,2.210,0.02,1.9869,1.98690,1.000
1,2.330,0.01,2.1069,2.10690,1.000
1,2.450,0.01,2.2269,2.22690,1.000
1,2.570,0.01,2.3468,2.34680,1.000
1,2.690,0.02,2.4668,2.46680,1.000
1,2.810,0.02,2.5870,2.58700,1.000
1,2.930,0.02,2.7070,2.70700,1.000
1,3.050,0.03,2.8270,2.82700,1.000
1,3.170,0.03,2.9470,2.94700,1.000
1,3.290,0.03,3.0669,3.06690,1.000
1,3.410,0.04,3.1869,3.18690,1.000
1,3.530,0.04,3.3070,3.30700,1.000
1,3.650,0.06,3.4270,3.42700,1.000
1,3.770,0.11,3.5470,3.54700,1.000
1,3.890,0.21,3.6669,3.66690,1.000
1,4.010,0.39,3.7870,3.78700,1.000
1,4.130,0.61,3.9070,3.90700,1.000
1,4.250,0.93,4.0269,4.02690,1.000
1,4.370,1.34,4.1470,4.14700,1.000
1,4.490,1.82,4.2669,4.26690,1.000
1,4.610,2.38,4.3869,4.38690,1.000
1,4.730,3.07,4.5070,4.50700,1.000
1,4.850,3.85,4.6270,4.62700,1.000
1,4.970,4.77,4.7470,4.74700,1.000
1,5.110,5.26,4.7913,4.79130,1.000
1,5.230,3.99,4.6718,4.67180,1.000
1,5.350,3.05,4.5518,4.55180,1.000
1,5.470,2.29,4.4317,4.43170,1.000
1,5.590,1.71,4.3116,4.31160,1.000
1,5.710,1.24,4.1915,4.19150,1.000
1,5.830,0.84,4.0716,4.07160,1.000
1,5.950,0.54,3.9517,3.95170,1.000
1,6.070,0.31,3.8316,3.83160,1.000
1,6.190,0.18,3.7116,3.71160,1.000
1,6.310,0.09,3.5915,3.59150,1.000
1,6.430,0.02,3.4716,3.47160,1.000
1,6.550,0.02,3.3516,3.35160,1.000
1,6.670,0.02,3.2316,3.23160,1.000
1,6.790,0.02,3.1115,3.11150,1.000
1,6.910,0.03,2.9915,2.99150,1.000
1,7.030,0.01,2.8715,2.87150,1.000
1,7.150,0.02,2.7515,2.75150,1.000
1,7.270,0.02,2.6314,2.63140,1.000
1,7.390,0.02,2.5113,2.51130,1.000
1,7.510,0.03,2.3913,2.39130,1.000
1,7.630,0.01,2.2713,2.27130,1.000
1,7.750,0.02,2.1514,2.15140,1.000
1,7.870,0.02,2.0315,2.03150,1.000
1,7.990,0.02,1.9114,1.91140,1.000
1,8.110,0.01,1.7914,1.79140,1.000
1,8.230,0.01,1.6714,1.67140,1.000
1,8.350,0.02,1.5514,1.55140,1.000
1,8.470,0.03,1.4313,1.43130,1.000
1,8.590,0.03,1.3113,1.31130,1.000
1,8.710,0.02,1.1913,1.19130,1.000
1,8.830,0.02,1.0713,1.07130,1.000
1,8.950,0.01,0.9513,0.95130,1.000
1,9.070,0.03,0.8314,0.83140,1.000
1,9.190,0.03,0.7113,0.71130,1.000
1,9.310,0.01,0.5912,0.59120,1.000
1,9.430,0.02,0.4711,0.47110,1.000
1,9.550,0.02,0.3511,0.35110,1.000
1,9.670,0.02,0.2310,0.23100,1.000
1,9.790,0.02,0.1111,0.11110,1.000
1,9.910,0.01,-0.0088,-0.00880,1.000
1,10.040,0.01,-0.0065,-0.00650,1.000
1,10.160,0.02,-0.0003,-0.00030,1.000
1,10.280,0.02,-0.0003,-0.00030,1.000
1,10.400,0.01,-0.0003,-0.00030,1.000
1,10.520,0.01,-0.0003,-0.00030,1.000
1,10.640,0.02,-0.0003,-0.00030,1.000
1,10.760,0.02,-0.0003,-0.00030,1.000
1,10.880,0.02,-0.0003,-0.00030,1.000
1,11.000,0.04,-0.0003,-0.00030,1.000
1,11.120,0.02,-0.0003,-0.00030,1.000
1,11.240,0.01,-0.0003,-0.00030,1.000
1,11.360,0.02,-0.0003,-0.00030,1.000
1,11.480,0.02,-0.0003,-0.00030,1.000
1,11.600,0.02,-0.0003,-0.00030,1.000
1,11.720,0.02,-0.0003,-0.00030,1.000
1,11.840,0.01,-0.0003,-0.00030,1.000
1,11.960,0.02,-0.0002,-0.00020,1.000
1,12.080,0.02,-0.0002,-0.00020,1.000
1,12.200,0.02,-0.0002,-0.00020,1.000
1,12.320,0.01,-0.0002,-0.00020,1.000
1,12.440,0.02,-0.0002,-0.00020,1.000
1,12.560,0.01,-0.0002,-0.00020,1.000
1,12.680,0.02,-0.0002,-0.00020,1.000
1,12.800,0.02,-0.0002,-0.00020,1.000
1,12.920,0.01,-0.0002,-0.00020,1.000
1,13.050,0.01,-0.0002,-0.00020,1.000
1,13.170,0.02,-0.0002,-0.00020,1.000
1,13.290,0.01,-0.0002,-0.00020,1.000
1,13.410,0.01,-0.0002,-0.00020,1.000
1,13.530,0.02,-0.0002,-0.00020,1.000
1,13.650,0.01,-0.0002,-0.00020,1.000
1,13.770,0.02,-0.0002,-0.00020,1.000
1,13.890,0.01,-0.0002,-0.00020,1.000
1,14.010,0.02,-0.0002,-0.00020,1.000
1,14.130,0.01,-0.0002,-0.00020,1.000
1,14.250,0.01,-0.0002,-0.00020,1.000
1,14.370,0.01,-0.0002,-0.00020,1.000
1,14.490,0.01,-0.0002,-0.00020,1.000
1,14.610,0.02,-0.0002,-0.00020,1.000
1,14.730,0.02,-0.0001,-0.00010,1.000
1,14.850,0.02,-0.0001,-0.00010,1.000
1,14.970,0.02,-0.0001,-0.00010,1.000
1,15.090,0.02,-0.0001,-0.00010,1.000
1,15.210,0.03,-0.0001,-0.00010,1.000
1,15.330,0.02,-0.0001,-0.00010,1.000
1,15.450,0.02,-0.0001,-0.00010,1.000
1,15.570,0.01,-0.0001,-0.00010,1.000
1,15.690,0.02,-0.0001,-0.00010,1.000
1,15.810,0.02,-0.0001,-0.00010,1.000
1,15.930,0.01,-0.0001,-0.00010,1.000
1,16.130,0.02,0.0000,0.00000,1.000
2,16.260,0.01,0.0666,0.06660,2.000
2,16.380,0.01,0.1866,0.18660,2.000
2,16.500,0.01,0.3068,0.30680,2.000
2,16.620,0.01,0.4267,0.42670,2.000
2,16.740,0.00,0.5468,0.54680,2.000
2,16.860,0.02,0.6667,0.66670,2.000
2,16.980,0.02,0.7868,0.78680,2.000
2,17.100,0.00,0.9068,0.90680,2.000
2,17.220,0.01,1.0269,1.02690,2.000
2,17.340,0.00,1.1469,1.14690,2.000
2,17.460,0.01,1.2668,1.26680,2.000
2,17.580,0.02,1.3868,1.38680,2.000
2,17.700,0.00,1.5068,1.50680,2.000
2,17.820,0.01,1.6269,1.62690,2.000
2,17.940,-0.01,1.7469,1.74690,2.000
2,18.060,0.01,1.8669,1.86690,2.000
2,18.180,0.02,1.9868,1.98680,2.000
2,18.300,0.01,2.1069,2.10690,2.000
2,18.420,0.02,2.2269,2.22690,2.000
2,18.540,0.00,2.3469,2.34690,2.000
2,18.660,0.01,2.4668,2.46680,2.000
2,18.780,0.00,2.5870,2.58700,2.000
2,18.900,0.01,2.7070,2.70700,2.000
2,19.020,0.01,2.8269,2.82690,2.000
2,19.140,0.02,2.9469,2.94690,2.000
2,19.260,0.02,3.0669,3.06690,2.000
2,19.380,0.02,3.1870,3.18700,2.000
2,19.500,0.04,3.3070,3.30700,2.000
2,19.620,0.04,3.4270,3.42700,2.000
2,19.740,0.09,3.5469,3.54690,2.000
2,19.860,0.19,3.6670,3.66700,2.000
2,19.980,0.36,3.7871,3.78710,2.000
2,20.100,0.60,3.9070,3.90700,2.000
2,20.220,0.91,4.0270,4.02700,2.000
2,20.340,1.31,4.1470,4.14700,2.000
2,20.460,1.78,4.2670,4.26700,2.000
2,20.580,2.37,4.3868,4.38680,2.000
2,20.700,3.04,4.5070,4.50700,2.000
2,20.820,3.83,4.6271,4.62710,2.000
2,20.940,4.77,4.7470,4.74700,2.000
2,21.080,5.25,4.7913,4.79130,2.000
2,21.200,3.98,4.6718,4.67180,2.000
2,21.320,3.04,4.5517,4.55170,2.000
2,21.440,2.30,4.4316,4.43160,2.000
2,21.560,1.69,4.3116,4.31160,2.000
2,21.680,1.21,4.1917,4.19170,2.000
2,21.800,0.84,4.0716,4.07160,2.000
2,21.920,0.52,3.9517,3.95170,2.000
2,22.040,0.33,3.8315,3.83150,2.000
2,22.160,0.18,3.7116,3.71160,2.000
2,22.280,0.07,3.5915,3.59150,2.000
2,22.400,0.03,3.4715,3.47150,2.000
2,22.520,0.02,3.3515,3.35150,2.000
2,22.640,0.01,3.2316,3.23160,2.000
2,22.760,0.01,3.1115,3.11150,2.000
2,22.880,0.00,2.9915,2.99150,2.000
2,23.000,0.00,2.8714,2.87140,2.000
2,23.120,0.01,2.7514,2.75140,2.000
2,23.240,0.01,2.6315,2.63150,2.000
2,23.360,0.01,2.5115,2.51150,2.000
2,23.480,0.01,2.3914,2.39140,2.000
2,23.600,0.01,2.2714,2.27140,2.000
2,23.720,0.01,2.1514,2.15140,2.000
2,23.840,0.01,2.0314,2.03140,2.000
2,23.960,0.01,1.9114,1.91140,2.000
2,24.080,0.01,1.7914,1.79140,2.000
2,24.200,0.01,1.6714,1.67140,2.000
2,24.320,0.00,1.5514,1.55140,2.000
2,24.440,0.00,1.4314,1.43140,2.000
2,24.560,0.01,1.3114,1.31140,2.000
2,24.680,0.00,1.1913,1.19130,2.000
2,24.800,0.00,1.0712,1.07120,2.000
2,24.920,-0.01,0.9514,0.95140,2.000
2,25.040,0.01,0.8314,0.83140,2.000
2,25.160,0.01,0.7112,0.71120,2.000
2,25.280,0.01,0.5910,0.59100,2.000
2,25.400,0.02,0.4713,0.47130,2.000
2,25.520,0.01,0.3512,0.35120,2.000
2,25.640,0.01,0.2312,0.23120,2.000
2,25.760,0.00,0.1112,0.11120,2.000
2,25.880,0.01,-0.0088,-0.00880,2.000
2,26.010,0.00,-0.0065,-0.00650,2.000
2,26.130,0.00,-0.0003,-0.00030,2.000
2,26.250,-0.01,-0.0003,-0.00030,2.000
2,26.370,0.02,-0.0003,-0.00030,2.000
2,26.490,0.02,-0.0003,-0.00030,2.000
2,26.610,0.01,-0.0003,-0.00030,2.000
2,26.730,0.01,-0.0003,-0.00030,2.000
2,26.850,0.01,-0.0003,-0.00030,2.000
2,26.970,0.02,-0.0003,-0.00030,2.000
2,27.090,0.01,-0.0003,-0.00030,2.000
2,27.210,0.01,-0.0003,-0.00030,2.000
2,27.330,0.00,-0.0003,-0.00030,2.000
2,27.450,0.00,-0.0003,-0.00030,2.000
2,27.570,0.01,-0.0003,-0.00030,2.000
2,27.690,0.01,-0.0003,-0.00030,2.000
2,27.810,-0.01,-0.0003,-0.00030,2.000
2,27.930,0.01,-0.0003,-0.00030,2.000
2,28.050,0.01,-0.0003,-0.00030,2.000
2,28.170,0.01,-0.0002,-0.00020,2.000
2,28.290,0.01,-0.0002,-0.00020,2.000
2,28.410,0.00,-0.0002,-0.00020,2.000
2,28.530,0.00,-0.0002,-0.00020,2.000
2,28.650,0.01,-0.0002,-0.00020,2.000
2,28.770,0.00,-0.0002,-0.00020,2.000
2,28.890,0.00,-0.0002,-0.00020,2.000
2,29.020,0.00,-0.0002,-0.00020,2.000
2,29.140,0.02,-0.0002,-0.00020,2.000
2,29.260,0.00,-0.0002,-0.00020,2.000
2,29.380,0.02,-0.0002,-0.00020,2.000
2,29.500,0.01,-0.0002,-0.00020,2.000
2,29.620,0.00,-0.0002,-0.00020,2.000
2,29.740,0.00,-0.0002,-0.00020,2.000
2,29.860,0.02,-0.0002,-0.00020,2.000
2,29.980,0.01,-0.0002,-0.00020,2.000
2,30.100,0.00,-0.0002,-0.00020,2.000
2,30.220,0.00,-0.0002,-0.00020,2.000
2,30.340,0.00,-0.0002,-0.00020,2.000
2,30.460,0.00,-0.0002,-0.00020,2.000
2,30.580,0.01,-0.0002,-0.00020,2.000
2,30.700,0.00,-0.0002,-0.00020,2.000
2,30.820,0.00,-0.0001,-0.00010,2.000
2,30.940,0.01,-0.0001,-0.00010,2.000
2,31.060,0.01,-0.0001,-0.00010,2.000
2,31.180,0.01,-0.0001,-0.00010,2.000
2,31.300,0.00,-0.0001,-0.00010,2.000
2,31.420,0.00,-0.0001,-0.00010,2.000
2,31.540,0.01,-0.0001,-0.00010,2.000
2,31.660,0.00,-0.0001,-0.00010,2.000
2,31.780,0.02,-0.0001,-0.00010,2.000
2,31.900,-0.01,-0.0001,-0.00010,2.000
3,32.110,0.01,0.0000,0.00000,3.000
3,32.240,-0.01,0.0766,0.07660,3.000
3,32.360,0.00,0.1965,0.19650,3.000
3,32.480,-0.01,0.3166,0.31660,3.000
3,32.600,0.00,0.4366,0.43660,3.000
3,32.720,0.00,0.5565,0.55650,3.000
3,32.840,0.00,0.6766,0.67660,3.000
3,32.960,-0.01,0.7968,0.79680,3.000
3,33.080,-0.01,0.9168,0.91680,3.000
3,33.200,0.00,1.0367,1.03670,3.000
3,33.320,0.00,1.1566,1.15660,3.000
3,33.440,-0.01,1.2767,1.27670,3.000
3,33.560,-0.01,1.3967,1.39670,3.000
3,33.680,0.00,1.5167,1.51670,3.000
3,33.800,0.00,1.6368,1.63680,3.000
3,33.920,-0.01,1.7567,1.75670,3.000
3,34.040,-0.01,1.8767,1.87670,3.000
3,34.160,-0.01,1.9968,1.99680,3.000
3,34.280,-0.01,2.1169,2.11690,3.000
3,34.400,-0.01,2.2368,2.23680,3.000
3,34.520,-0.01,2.3567,2.35670,3.000
3,34.640,0.00,2.4767,2.47670,3.000
3,34.760,-0.01,2.5967,2.59670,3.000
3,34.880,-0.01,2.7168,2.71680,3.000
3,35.000,0.00,2.8368,2.83680,3.000
3,35.120,0.00,2.9567,2.95670,3.000
3,35.240,0.00,3.0768,3.07680,3.000
3,35.360,0.01,3.1968,3.19680,3.000
3,35.480,0.01,3.3169,3.31690,3.000
3,35.600,0.03,3.4369,3.43690,3.000
3,35.720,0.09,3.5569,3.55690,3.000
3,35.840,0.21,3.6769,3.67690,3.000
3,35.960,0.37,3.7969,3.79690,3.000
3,36.080,0.62,3.9170,3.91700,3.000
3,36.200,0.93,4.0369,4.03690,3.000
3,36.320,1.34,4.1568,4.15680,3.000
3,36.440,1.83,4.2768,4.27680,3.000
3,36.560,2.41,4.3968,4.39680,3.000
3,36.680,3.08,4.5168,4.51680,3.000
3,36.800,3.89,4.6369,4.63690,3.000
3,36.920,4.83,4.7570,4.75700,3.000
3,37.060,5.21,4.7893,4.78930,3.000
3,37.180,3.94,4.6697,4.66970,3.000
3,37.300,3.00,4.5497,4.54970,3.000
3,37.420,2.28,4.4297,4.42970,3.000
3,37.540,1.68,4.3095,4.30950,3.000
3,37.660,1.20,4.1897,4.18970,3.000
3,37.780,0.82,4.0696,4.06960,3.000
3,37.900,0.51,3.9496,3.94960,3.000
3,38.020,0.29,3.8295,3.82950,3.000
3,38.140,0.15,3.7095,3.70950,3.000
3,38.260,0.06,3.5895,3.58950,3.000
3,38.380,0.00,3.4696,3.46960,3.000
3,38.500,0.00,3.3497,3.34970,3.000
3,38.620,-0.02,3.2295,3.22950,3.000
3,38.740,-0.01,3.1095,3.10950,3.000
3,38.860,0.01,2.9895,2.98950,3.000
3,38.980,-0.01,2.8696,2.86960,3.000
3,39.100,0.00,2.7495,2.74950,3.000
3,39.220,0.00,2.6295,2.62950,3.000
3,39.340,-0.01,2.5094,2.50940,3.000
3,39.460,0.00,2.3894,2.38940,3.000
3,39.580,0.00,2.2694,2.26940,3.000
3,39.700,-0.02,2.1495,2.14950,3.000
3,39.820,0.00,2.0295,2.02950,3.000
3,39.940,-0.01,1.9094,1.90940,3.000
3,40.060,0.00,1.7894,1.78940,3.000
3,40.180,0.00,1.6695,1.66950,3.000
3,40.300,0.00,1.5494,1.54940,3.000
3,40.420,0.00,1.4293,1.42930,3.000
3,40.540,0.00,1.3093,1.30930,3.000
3,40.660,-0.01,1.1893,1.18930,3.000
3,40.780,0.00,1.0694,1.06940,3.000
3,40.900,-0.02,0.9494,0.94940,3.000
3,41.020,-0.01,0.8295,0.82950,3.000
3,41.140,-0.02,0.7093,0.70930,3.000
3,41.260,-0.01,0.5892,0.58920,3.000
3,41.380,-0.01,0.4693,0.46930,3.000
3,41.500,-0.01,0.3492,0.34920,3.000
3,41.620,0.00,0.2292,0.22920,3.000
3,41.740,-0.02,0.1093,0.10930,3.000
3,41.860,-0.01,-0.0108,-0.01080,3.000
3,41.990,0.00,-0.0003,-0.00030,3.000
3,42.110,0.00,-0.0003,-0.00030,3.000
3,42.230,0.00,-0.0003,-0.00030,3.000
3,42.350,0.00,-0.0003,-0.00030,3.000
3,42.470,0.00,-0.0003,-0.00030,3.000
3,42.590,-0.01,-0.0003,-0.00030,3.000
3,42.710,0.01,-0.0003,-0.00030,3.000
3,42.830,-0.01,-0.0003,-0.00030,3.000
3,42.950,0.00,-0.0003,-0.00030,3.000
3,43.070,0.00,-0.0003,-0.00030,3.000
3,43.190,0.00,-0.0003,-0.00030,3.000
3,43.310,0.00,-0.0003,-0.00030,3.000
3,43.430,0.00,-0.0003,-0.00030,3.000
3,43.550,-0.01,-0.0003,-0.00030,3.000
3,43.670,0.00,-0.0003,-0.00030,3.000
3,43.790,0.00,-0.0003,-0.00030,3.000
3,43.910,-0.01,-0.0003,-0.00030,3.000
3,44.030,-0.01,-0.0002,-0.00020,3.000
3,44.150,-0.01,-0.0002,-0.00020,3.000
3,44.270,-0.01,-0.0002,-0.00020,3.000
3,44.390,-0.01,-0.0002,-0.00020,3.000
3,44.510,-0.01,-0.0002,-0.00020,3.000
3,44.630,-0.01,-0.0002,-0.00020,3.000
3,44.750,0.00,-0.0002,-0.00020,3.000
3,44.870,0.00,-0.0002,-0.00020,3.000
3,45.010,0.00,-0.0002,-0.00020,3.000
3,45.130,-0.01,-0.0002,-0.00020,3.000
3,45.250,-0.01,-0.0002,-0.00020,3.000
3,45.370,0.00,-0.0002,-0.00020,3.000
3,45.490,-0.02,-0.0002,-0.00020,3.000
3,45.610,-0.01,-0.0002,-0.00020,3.000
3,45.730,-0.02,-0.0002,-0.00020,3.000
3,45.850,0.01,-0.0002,-0.00020,3.000
3,45.970,-0.01,-0.0002,-0.00020,3.000
3,46.090,-0.02,-0.0002,-0.00020,3.000
3,46.210,-0.01,-0.0002,-0.00020,3.000
3,46.330,-0.01,-0.0002,-0.00020,3.000
3,46.450,-0.01,-0.0002,-0.00020,3.000
3,46.570,-0.01,-0.0002,-0.00020,3.000
3,46.690,0.00,-0.0001,-0.00010,3.000
3,46.810,0.00,-0.0001,-0.00010,3.000
3,46.930,-0.01,-0.0001,-0.00010,3.000
3,47.050,-0.01,-0.0001,-0.00010,3.000
3,47.170,-0.01,-0.0001,-0.00010,3.000
3,47.290,0.00,-0.0001,-0.00010,3.000
3,47.410,-0.01,-0.0001,-0.00010,3.000
3,47.530,-0.01,-0.0001,-0.00010,3.000
3,47.650,0.00,-0.0001,-0.00010,3.000
3,47.770,-0.01,-0.0001,-0.00010,3.000
3,47.890,-0.01,-0.0001,-0.00010,3.000
4,48.110,0.01,0.0001,0.00010,4.000
4,48.230,-0.01,0.1066,0.10660,4.000
4,48.350,0.02,0.2266,0.22660,4.000
4,48.470,0.01,0.3468,0.34680,4.000
4,48.590,0.00,0.4668,0.46680,4.000
4,48.710,0.01,0.5867,0.58670,4.000
4,48.830,-0.01,0.7068,0.70680,4.000
4,48.950,0.01,0.8269,0.82690,4.000
4,49.070,0.00,0.9469,0.94690,4.000
4,49.190,0.00,1.0669,1.06690,4.000
4,49.310,0.00,1.1867,1.18670,4.000
4,49.430,0.01,1.3069,1.30690,4.000
4,49.550,0.01,1.4268,1.42680,4.000
4,49.670,0.01,1.5469,1.54690,4.000
4,49.790,0.01,1.6669,1.66690,4.000
4,49.910,0.01,1.7868,1.78680,4.000
4,50.030,0.01,1.9068,1.90680,4.000
4,50.150,0.01,2.0270,2.02700,4.000
4,50.270,0.00,2.1469,2.14690,4.000
4,50.390,0.01,2.2670,2.26700,4.000
4,50.510,0.01,2.3870,2.38700,4.000
4,50.630,0.00,2.5069,2.50690,4.000
4,50.750,0.01,2.6269,2.62690,4.000
4,50.870,0.01,2.7469,2.74690,4.000
4,50.990,0.01,2.8670,2.86700,4.000
4,51.110,0.01,2.9869,2.98690,4.000
4,51.230,0.01,3.1070,3.10700,4.000
4,51.350,0.02,3.2270,3.22700,4.000
4,51.470,0.04,3.3470,3.34700,4.000
4,51.590,0.06,3.4670,3.46700,4.000
4,51.710,0.13,3.5871,3.58710,4.000
4,51.830,0.25,3.7069,3.70690,4.000
4,51.950,0.44,3.8269,3.82690,4.000
4,52.070,0.69,3.9470,3.94700,4.000
4,52.190,1.03,4.0670,4.06700,4.000
4,52.310,1.46,4.1870,4.18700,4.000
4,52.430,1.97,4.3069,4.30690,4.000
4,52.550,2.58,4.4269,4.42690,4.000
4,52.670,3.29,4.5470,4.54700,4.000
4,52.790,4.14,4.6671,4.66710,4.000
4,52.930,5.27,4.8067,4.80670,4.000
4,53.050,4.84,4.7596,4.75960,4.000
4,53.170,3.69,4.6397,4.63970,4.000
4,53.290,2.81,4.5197,4.51970,4.000
4,53.410,2.13,4.3996,4.39960,4.000
4,53.530,1.55,4.2795,4.27950,4.000
4,53.650,1.10,4.1596,4.15960,4.000
4,53.770,0.74,4.0395,4.03950,4.000
4,53.890,0.46,3.9196,3.91960,4.000
4,54.010,0.26,3.7995,3.79950,4.000
4,54.130,0.14,3.6795,3.67950,4.000
4,54.250,0.04,3.5594,3.55940,4.000
4,54.370,0.01,3.4394,3.43940,4.000
4,54.490,0.01,3.3195,3.31950,4.000
4,54.610,0.01,3.1994,3.19940,4.000
4,54.730,0.00,3.0794,3.07940,4.000
4,54.850,0.02,2.9594,2.95940,4.000
4,54.970,0.01,2.8393,2.83930,4.000
4,55.090,0.01,2.7194,2.71940,4.000
4,55.210,0.02,2.5993,2.59930,4.000
4,55.330,0.00,2.4793,2.47930,4.000
4,55.450,0.00,2.3593,2.35930,4.000
4,55.570,0.01,2.2393,2.23930,4.000
4,55.690,0.01,2.1193,2.11930,4.000
4,55.810,0.01,1.9993,1.99930,4.000
4,55.930,0.01,1.8792,1.87920,4.000
4,56.050,0.01,1.7592,1.75920,4.000
4,56.170,0.00,1.6393,1.63930,4.000
4,56.290,0.01,1.5192,1.51920,4.000
4,56.410,0.01,1.3993,1.39930,4.000
4,56.530,0.00,1.2792,1.27920,4.000
4,56.650,0.01,1.1591,1.15910,4.000
4,56.770,-0.01,1.0393,1.03930,4.000
4,56.890,0.01,0.9193,0.91930,4.000
4,57.010,0.00,0.7993,0.79930,4.000
4,57.130,0.00,0.6792,0.67920,4.000
4,57.250,0.02,0.5591,0.55910,4.000
4,57.370,0.00,0.4393,0.43930,4.000
4,57.490,0.00,0.3192,0.31920,4.000
4,57.610,0.01,0.1991,0.19910,4.000
4,57.730,0.00,0.0792,0.07920,4.000
4,57.860,0.01,-0.0416,-0.04160,4.000
4,57.980,0.01,-0.0003,-0.00030,4.000
4,58.100,0.00,-0.0003,-0.00030,4.000
4,58.220,0.01,-0.0003,-0.00030,4.000
4,58.340,0.00,-0.0003,-0.00030,4.000
4,58.460,0.00,-0.0003,-0.00030,4.000
4,58.580,0.01,-0.0003,-0.00030,4.000
4,58.700,0.01,-0.0003,-0.00030,4.000
4,58.820,0.01,-0.0003,-0.00030,4.000
4,58.940,0.01,-0.0003,-0.00030,4.000
4,59.060,0.00,-0.0003,-0.00030,4.000
4,59.180,0.00,-0.0003,-0.00030,4.000
4,59.300,0.01,-0.0003,-0.00030,4.000
4,59.420,0.00,-0.0003,-0.00030,4.000
4,59.540,0.00,-0.0003,-0.00030,4.000
4,59.660,0.01,-0.0003,-0.00030,4.000
4,59.780,0.00,-0.0003,-0.00030,4.000
4,59.900,0.01,-0.0002,-0.00020,4.000
4,60.020,0.01,-0.0002,-0.00020,4.000
4,60.140,0.01,-0.0002,-0.00020,4.000
4,60.260,0.01,-0.0002,-0.00020,4.000
4,60.380,0.00,-0.0002,-0.00020,4.000
4,60.500,0.01,-0.0002,-0.00020,4.000
4,60.620,0.01,-0.0002,-0.00020,4.000
4,60.740,0.02,-0.0002,-0.00020,4.000
4,60.860,0.00,-0.0002,-0.00020,4.000
4,60.990,0.01,-0.0002,-0.00020,4.000
4,61.110,0.00,-0.0002,-0.00020,4.000
4,61.230,0.00,-0.0002,-0.00020,4.000
4,61.350,0.00,-0.0002,-0.00020,4.000
4,61.470,0.00,-0.0002,-0.00020,4.000
4,61.590,0.00,-0.0002,-0.00020,4.000
4,61.710,0.01,-0.0002,-0.00020,4.000
4,61.830,0.01,-0.0002,-0.00020,4.000
4,61.950,0.01,-0.0002,-0.00020,4.000
4,62.070,0.01,-0.0002,-0.00020,4.000
4,62.190,0.00,-0.0002,-0.00020,4.000
4,62.310,0.01,-0.0002,-0.00020,4.000
4,62.430,0.00,-0.0002,-0.00020,4.000
4,62.550,0.01,-0.0002,-0.00020,4.000
4,62.670,0.00,-0.0001,-0.00010,4.000
4,62.790,0.01,-0.0001,-0.00010,4.000
4,62.910,0.00,-0.0001,-0.00010,4.000
4,63.030,0.00,-0.0001,-0.00010,4.000
4,63.150,0.01,-0.0001,-0.00010,4.000
4,63.270,0.01,-0.0001,-0.00010,4.000
4,63.390,0.00,-0.0001,-0.00010,4.000
4,63.510,0.00,-0.0001,-0.00010,4.000
4,63.630,0.00,-0.0001,-0.00010,4.000
4,63.750,0.00,-0.0001,-0.00010,4.000
4,63.870,0.01,-0.0001,-0.00010,4.000
5,64.080,0.01,0.0001,0.00010,5.000
5,64.200,0.01,0.1067,0.10670,5.000
5,64.320,0.01,0.2267,0.22670,5.000
5,64.440,0.00,0.3467,0.34670,5.000
5,64.560,0.01,0.4669,0.46690,5.000
5,64.680,0.02,0.5867,0.58670,5.000
5,64.800,0.01,0.7067,0.70670,5.000
5,64.920,0.00,0.8269,0.82690,5.000
5,65.040,0.00,0.9469,0.94690,5.000
5,65.160,0.00,1.0669,1.06690,5.000
5,65.280,0.00,1.1868,1.18680,5.000
5,65.400,0.01,1.3068,1.30680,5.000
5,65.520,0.00,1.4269,1.42690,5.000
5,65.640,0.01,1.5470,1.54700,5.000
5,65.760,0.01,1.6670,1.66700,5.000
5,65.880,0.01,1.7868,1.78680,5.000
5,66.000,0.00,1.9069,1.90690,5.000
5,66.120,0.00,2.0270,2.02700,5.000
5,66.240,0.00,2.1469,2.14690,5.000
5,66.360,0.00,2.2669,2.26690,5.000
5,66.480,0.00,2.3868,2.38680,5.000
5,66.600,0.00,2.5069,2.50690,5.000
5,66.720,0.00,2.6269,2.62690,5.000
5,66.840,0.00,2.7470,2.74700,5.000
5,66.960,0.00,2.8669,2.86690,5.000
5,67.080,0.01,2.9869,2.98690,5.000
5,67.200,0.02,3.1069,3.10690,5.000
5,67.320,0.02,3.2268,3.22680,5.000
5,67.440,0.03,3.3471,3.34710,5.000
5,67.560,0.05,3.4670,3.46700,5.000
5,67.680,0.12,3.5870,3.58700,5.000
5,67.800,0.25,3.7070,3.70700,5.000
5,67.920,0.42,3.8269,3.82690,5.000
5,68.040,0.69,3.9471,3.94710,5.000
5,68.160,1.02,4.0669,4.06690,5.000
5,68.280,1.45,4.1871,4.18710,5.000
5,68.400,1.97,4.3069,4.30690,5.000
5,68.520,2.57,4.4269,4.42690,5.000
5,68.640,3.27,4.5470,4.54700,5.000
5,68.760,4.13,4.6669,4.66690,5.000
5,68.880,5.09,4.7869,4.78690,5.000
5,69.010,5.10,4.7836,4.78360,5.000
5,69.130,3.88,4.6638,4.66380,5.000
5,69.250,2.96,4.5436,4.54360,5.000
5,69.370,2.24,4.4235,4.42350,5.000
5,69.490,1.66,4.3035,4.30350,5.000
5,69.610,1.19,4.1836,4.18360,5.000
5,69.730,0.80,4.0637,4.06370,5.000
5,69.850,0.49,3.9436,3.94360,5.000
5,69.970,0.29,3.8236,3.82360,5.000
5,70.090,0.16,3.7037,3.70370,5.000
5,70.210,0.06,3.5836,3.58360,5.000
5,70.330,0.02,3.4636,3.46360,5.000
5,70.450,0.00,3.3436,3.34360,5.000
5,70.570,0.01,3.2236,3.22360,5.000
5,70.690,0.01,3.1035,3.10350,5.000
5,70.810,0.00,2.9836,2.98360,5.000
5,70.930,0.00,2.8635,2.86350,5.000
5,71.050,0.01,2.7436,2.74360,5.000
5,71.170,0.00,2.6235,2.62350,5.000
5,71.290,0.01,2.5035,2.50350,5.000
5,71.410,0.01,2.3835,2.38350,5.000
5,71.530,0.00,2.2635,2.26350,5.000
5,71.650,0.00,2.1436,2.14360,5.000
5,71.770,0.00,2.0236,2.02360,5.000
5,71.890,0.01,1.9035,1.90350,5.000
5,72.010,0.00,1.7834,1.78340,5.000
5,72.130,0.00,1.6635,1.66350,5.000
5,72.250,0.01,1.5433,1.54330,5.000
5,72.370,0.00,1.4234,1.42340,5.000
5,72.490,0.01,1.3034,1.30340,5.000
5,72.610,0.01,1.1834,1.18340,5.000
5,72.730,0.00,1.0634,1.06340,5.000
5,72.850,0.01,0.9434,0.94340,5.000
5,72.970,0.00,0.8235,0.82350,5.000
5,73.090,0.00,0.7034,0.70340,5.000
5,73.210,0.01,0.5832,0.58320,5.000
5,73.330,0.00,0.4634,0.46340,5.000
5,73.450,0.01,0.3433,0.34330,5.000
5,73.570,0.00,0.2233,0.22330,5.000
5,73.690,0.00,0.1032,0.10320,5.000
5,73.830,0.00,-0.0363,-0.03632,5.000
5,73.950,0.00,-0.0001,-0.00010,5.000
5,74.070,0.00,-0.0003,-0.00030,5.000
5,74.190,0.00,-0.0003,-0.00030,5.000
5,74.310,0.00,-0.0003,-0.00030,5.000
5,74.430,0.00,-0.0003,-0.00030,5.000
5,74.550,0.01,-0.0003,-0.00030,5.000
5,74.670,0.00,-0.0003,-0.00030,5.000
5,74.790,0.00,-0.0003,-0.00030,5.000
5,74.910,0.00,-0.0003,-0.00030,5.000
5,75.030,0.00,-0.0003,-0.00030,5.000
5,75.150,0.00,-0.0003,-0.00030,5.000
5,75.270,0.01,-0.0003,-0.00030,5.000
5,75.390,0.01,-0.0003,-0.00030,5.000
5,75.510,0.00,-0.0003,-0.00030,5.000
5,75.630,0.00,-0.0003,-0.00030,5.000
5,75.750,0.01,-0.0003,-0.00030,5.000
5,75.870,0.00,-0.0003,-0.00030,5.000
5,75.990,0.01,-0.0003,-0.00030,5.000
5,76.110,0.00,-0.0003,-0.00030,5.000
5,76.230,0.01,-0.0002,-0.00020,5.000
5,76.350,0.00,-0.0002,-0.00020,5.000
5,76.470,0.00,-0.0002,-0.00020,5.000
5,76.590,-0.01,-0.0002,-0.00020,5.000
5,76.710,0.01,-0.0002,-0.00020,5.000
5,76.830,-0.01,-0.0002,-0.00020,5.000
5,76.960,0.00,-0.0002,-0.00020,5.000
5,77.080,0.01,-0.0002,-0.00020,5.000
5,77.200,0.01,-0.0002,-0.00020,5.000
5,77.320,0.01,-0.0002,-0.00020,5.000
5,77.440,0.00,-0.0002,-0.00020,5.000
5,77.560,0.00,-0.0002,-0.00020,5.000
5,77.680,0.01,-0.0002,-0.00020,5.000
5,77.800,0.00,-0.0002,-0.00020,5.000
5,77.920,0.01,-0.0002,-0.00020,5.000
5,78.040,0.00,-0.0002,-0.00020,5.000
5,78.160,0.01,-0.0002,-0.00020,5.000
5,78.280,0.00,-0.0002,-0.00020,5.000
5,78.400,0.00,-0.0002,-0.00020,5.000
5,78.520,0.00,-0.0002,-0.00020,5.000
5,78.640,0.00,-0.0002,-0.00020,5.000
5,78.760,0.00,-0.0002,-0.00020,5.000
5,78.880,0.00,-0.0001,-0.00010,5.000
5,79.000,0.00,-0.0001,-0.00010,5.000
5,79.120,0.00,-0.0001,-0.00010,5.000
5,79.240,0.00,-0.0001,-0.00010,5.000
5,79.360,0.01,-0.0001,-0.00010,5.000
5,79.480,0.00,-0.0001,-0.00010,5.000
5,79.600,0.01,-0.0001,-0.00010,5.000
5,79.720,0.00,-0.0001,-0.00010,5.000
5,79.840,0.00,-0.0001,-0.00010,5.000
6,80.060,-0.01,0.0000,0.00000,6.000
6,80.180,0.00,0.0957,0.09570,6.000
6,80.300,0.01,0.2158,0.21580,6.000
6,80.420,0.00,0.3358,0.33580,6.000
6,80.540,0.00,0.4558,0.45580,6.000
6,80.660,0.00,0.5758,0.57580,6.000
6,80.780,0.00,0.6958,0.69580,6.000
6,80.900,0.00,0.8158,0.81580,6.000
6,81.020,0.00,0.9358,0.93580,6.000
6,81.140,0.00,1.0559,1.05590,6.000
6,81.260,-0.01,1.1758,1.17580,6.000
6,81.380,0.00,1.2957,1.29570,6.000
6,81.500,0.00,1.4158,1.41580,6.000
6,81.620,0.00,1.5358,1.53580,6.000
6,81.740,0.00,1.6559,1.65590,6.000
6,81.860,-0.01,1.7759,1.77590,6.000
6,81.980,0.00,1.8958,1.89580,6.000
6,82.100,0.00,2.0159,2.01590,6.000
6,82.220,-0.01,2.1360,2.13600,6.000
6,82.340,0.00,2.2559,2.25590,6.000
6,82.460,0.00,2.3759,2.37590,6.000
6,82.580,0.01,2.4959,2.49590,6.000
6,82.700,0.00,2.6159,2.61590,6.000
6,82.820,-0.01,2.7359,2.73590,6.000
6,82.940,0.00,2.8559,2.85590,6.000
6,83.060,0.00,2.9758,2.97580,6.000
6,83.180,0.01,3.0959,3.09590,6.000
6,83.300,0.01,3.2158,3.21580,6.000
6,83.420,0.03,3.3360,3.33600,6.000
6,83.540,0.05,3.4559,3.45590,6.000
6,83.660,0.11,3.5759,3.57590,6.000
6,83.780,0.23,3.6959,3.69590,6.000
6,83.900,0.41,3.8159,3.81590,6.000
6,84.020,0.67,3.9360,3.93600,6.000
6,84.140,1.00,4.0559,4.05590,6.000
6,84.260,1.41,4.1759,4.17590,6.000
6,84.380,1.90,4.2959,4.29590,6.000
6,84.500,2.50,4.4158,4.41580,6.000
6,84.620,3.20,4.5358,4.53580,6.000
6,84.740,4.02,4.6559,4.65590,6.000
6,84.860,4.97,4.7758,4.77580,6.000
6,84.990,5.18,4.7906,4.79060,6.000
6,85.110,3.94,4.6708,4.67080,6.000
6,85.230,3.00,4.5507,4.55070,6.000
6,85.350,2.27,4.4306,4.43060,6.000
6,85.470,1.67,4.3106,4.31060,6.000
6,85.590,1.20,4.1906,4.19060,6.000
6,85.710,0.82,4.0705,4.07050,6.000
6,85.830,0.52,3.9507,3.95070,6.000
6,85.950,0.30,3.8306,3.83060,6.000
6,86.070,0.16,3.7105,3.71050,6.000
6,86.190,0.06,3.5905,3.59050,6.000
6,86.310,0.01,3.4706,3.47060,6.000
6,86.430,0.00,3.3507,3.35070,6.000
6,86.550,0.00,3.2305,3.23050,6.000
6,86.670,0.01,3.1106,3.11060,6.000
6,86.790,0.00,2.9905,2.99050,6.000
6,86.910,0.00,2.8705,2.87050,6.000
6,87.030,0.00,2.7505,2.75050,6.000
6,87.150,0.00,2.6305,2.63050,6.000
6,87.270,0.00,2.5103,2.51030,6.000
6,87.390,0.00,2.3905,2.39050,6.000
6,87.510,0.00,2.2704,2.27040,6.000
6,87.630,-0.01,2.1504,2.15040,6.000
6,87.750,0.00,2.0305,2.03050,6.000
6,87.870,0.00,1.9104,1.91040,6.000
6,87.990,0.00,1.7904,1.79040,6.000
6,88.110,0.00,1.6705,1.67050,6.000
6,88.230,0.01,1.5504,1.55040,6.000
6,88.350,0.01,1.4305,1.43050,6.000
6,88.470,-0.01,1.3105,1.31050,6.000
6,88.590,0.00,1.1903,1.19030,6.000
6,88.710,0.00,1.0704,1.07040,6.000
6,88.830,0.00,0.9504,0.95040,6.000
6,88.950,0.00,0.8305,0.83050,6.000
6,89.070,0.00,0.7104,0.71040,6.000
6,89.190,0.00,0.5903,0.59030,6.000
6,89.310,0.00,0.4703,0.47030,6.000
6,89.430,0.00,0.3503,0.35030,6.000
6,89.550,0.00,0.2302,0.23020,6.000
6,89.670,0.00,0.1103,0.11030,6.000
6,89.790,0.00,-0.0097,-0.00970,6.000
6,89.930,0.00,-0.0025,-0.00250,6.000
6,90.050,0.00,-0.0003,-0.00030,6.000
6,90.170,-0.01,-0.0003,-0.00030,6.000
6,90.290,0.00,-0.0003,-0.00030,6.000
6,90.410,0.00,-0.0003,-0.00030,6.000
6,90.530,0.00,-0.0003,-0.00030,6.000
6,90.650,0.00,-0.0003,-0.00030,6.000
6,90.770,0.00,-0.0003,-0.00030,6.000
6,90.890,0.00,-0.0003,-0.00030,6.000
6,91.010,0.00,-0.0003,-0.00030,6.000
6,91.130,0.00,-0.0003,-0.00030,6.000
6,91.250,0.00,-0.0003,-0.00030,6.000
6,91.370,0.00,-0.0003,-0.00030,6.000
6,91.490,0.00,-0.0003,-0.00030,6.000
6,91.610,0.00,-0.0003,-0.00030,6.000
6,91.730,-0.01,-0.0003,-0.00030,6.000
6,91.850,0.01,-0.0003,-0.00030,6.000
6,91.970,0.00,-0.0003,-0.00030,6.000
6,92.090,0.01,-0.0003,-0.00030,6.000
6,92.210,-0.01,-0.0002,-0.00020,6.000
6,92.330,0.00,-0.0002,-0.00020,6.000
6,92.450,0.00,-0.0002,-0.00020,6.000
6,92.570,0.01,-0.0002,-0.00020,6.000
6,92.690,0.00,-0.0002,-0.00020,6.000
6,92.810,0.00,-0.0002,-0.00020,6.000
6,92.940,0.00,-0.0002,-0.00020,6.000
6,93.060,0.00,-0.0002,-0.00020,6.000
6,93.180,0.00,-0.0002,-0.00020,6.000
6,93.300,0.00,-0.0002,-0.00020,6.000
6,93.420,0.00,-0.0002,-0.00020,6.000
6,93.540,0.00,-0.0002,-0.00020,6.000
6,93.660,0.00,-0.0002,-0.00020,6.000
6,93.780,0.00,-0.0002,-0.00020,6.000
6,93.900,0.00,-0.0002,-0.00020,6.000
6,94.020,0.00,-0.0002,-0.00020,6.000
6,94.140,0.00,-0.0002,-0.00020,6.000
6,94.260,0.00,-0.0002,-0.00020,6.000
6,94.380,0.00,-0.0002,-0.00020,6.000
6,94.500,0.00,-0.0002,-0.00020,6.000
6,94.620,0.00,-0.0002,-0.00020,6.000
6,94.740,0.00,-0.0002,-0.00020,6.000
6,94.860,0.00,-0.0001,-0.00010,6.000
6,94.980,0.00,-0.0001,-0.00010,6.000
6,95.100,-0.01,-0.0001,-0.00010,6.000
6,95.220,0.00,-0.0001,-0.00010,6.000
6,95.340,0.00,-0.0001,-0.00010,6.000
6,95.460,0.00,-0.0001,-0.00010,6.000
6,95.580,0.00,-0.0001,-0.00010,6.000
6,95.700,0.00,-0.0001,-0.00010,6.000
6,95.820,0.00,-0.0001,-0.00010,6.000
7,96.040,0.01,0.0000,0.00000,7.000
7,96.160,0.00,0.0856,0.08560,7.000
7,96.280,0.01,0.2057,0.20570,7.000
7,96.400,0.00,0.3257,0.32570,7.000
7,96.520,0.01,0.4458,0.44580,7.000
7,96.640,0.00,0.5657,0.56570,7.000
7,96.760,0.00,0.6856,0.68560,7.000
7,96.880,0.00,0.8057,0.80570,7.000
7,97.000,0.01,0.9258,0.92580,7.000
7,97.120,0.01,1.0458,1.04580,7.000
7,97.240,0.02,1.1657,1.16570,7.000
7,97.360,0.00,1.2858,1.28580,7.000
7,97.480,0.00,1.4057,1.40570,7.000
7,97.600,0.01,1.5257,1.52570,7.000
7,97.720,0.00,1.6457,1.64570,7.000
7,97.840,0.00,1.7657,1.76570,7.000
7,97.960,0.00,1.8857,1.88570,7.000
7,98.080,0.01,2.0058,2.00580,7.000
7,98.200,0.00,2.1258,2.12580,7.000
7,98.320,0.00,2.2458,2.24580,7.000
7,98.440,0.01,2.3658,2.36580,7.000
7,98.560,0.00,2.4858,2.48580,7.000
7,98.680,0.01,2.6057,2.60570,7.000
7,98.800,0.01,2.7258,2.72580,7.000
7,98.920,0.01,2.8457,2.84570,7.000
7,99.040,0.01,2.9658,2.96580,7.000
7,99.160,0.01,3.0859,3.08590,7.000
7,99.280,0.02,3.2057,3.20570,7.000
7,99.400,0.03,3.3259,3.32590,7.000
7,99.520,0.06,3.4458,3.44580,7.000
7,99.640,0.11,3.5658,3.56580,7.000
7,99.760,0.23,3.6858,3.68580,7.000
7,99.880,0.40,3.8057,3.80570,7.000
7,100.000,0.63,3.9259,3.92590,7.000
7,100.120,0.97,4.0459,4.04590,7.000
7,100.240,1.38,4.1657,4.16570,7.000
7,100.360,1.88,4.2857,4.28570,7.000
7,100.480,2.47,4.4057,4.40570,7.000
7,100.600,3.16,4.5259,4.52590,7.000
7,100.720,3.97,4.6459,4.64590,7.000
7,100.840,4.92,4.7658,4.76580,7.000
7,100.970,5.33,4.8002,4.80020,7.000
7,101.090,4.04,4.6807,4.68070,7.000
7,101.210,3.09,4.5606,4.56060,7.000
7,101.330,2.34,4.4406,4.44060,7.000
7,101.450,1.73,4.3206,4.32060,7.000
7,101.570,1.24,4.2006,4.20060,7.000
7,101.690,0.86,4.0806,4.08060,7.000
7,101.810,0.55,3.9606,3.96060,7.000
7,101.930,0.32,3.8405,3.84050,7.000
7,102.050,0.16,3.7206,3.72060,7.000
7,102.170,0.07,3.6005,3.60050,7.000
7,102.290,0.02,3.4805,3.48050,7.000
7,102.410,0.01,3.3605,3.36050,7.000
7,102.530,0.01,3.2405,3.24050,7.000
7,102.650,0.00,3.1205,3.12050,7.000
7,102.770,0.01,3.0004,3.00040,7.000
7,102.890,0.00,2.8804,2.88040,7.000
7,103.010,0.00,2.7604,2.76040,7.000
7,103.130,0.00,2.6404,2.64040,7.000
7,103.250,0.00,2.5204,2.52040,7.000
7,103.370,0.01,2.4003,2.40030,7.000
7,103.490,0.01,2.2804,2.28040,7.000
7,103.610,0.00,2.1604,2.16040,7.000
7,103.730,0.01,2.0404,2.04040,7.000
7,103.850,0.01,1.9202,1.92020,7.000
7,103.970,0.01,1.8003,1.80030,7.000
7,104.090,0.00,1.6803,1.68030,7.000
7,104.210,0.01,1.5603,1.56030,7.000
7,104.330,0.00,1.4403,1.44030,7.000
7,104.450,0.00,1.3202,1.32020,7.000
7,104.570,0.01,1.2002,1.20020,7.000
7,104.690,0.00,1.0802,1.08020,7.000
7,104.810,-0.01,0.9603,0.96030,7.000
7,104.930,0.01,0.8403,0.84030,7.000
7,105.050,0.01,0.7202,0.72020,7.000
7,105.170,0.00,0.6001,0.60010,7.000
7,105.290,0.01,0.4802,0.48020,7.000
7,105.410,0.00,0.3601,0.36010,7.000
7,105.530,0.00,0.2401,0.24010,7.000
7,105.650,-0.01,0.1201,0.12010,7.000
7,105.770,0.00,0.0000,0.00000,7.000
7,105.900,0.00,-0.0022,-0.00220,7.000
7,106.020,0.00,-0.0003,-0.00030,7.000
7,106.140,0.00,-0.0003,-0.00030,7.000
7,106.260,0.00,-0.0003,-0.00030,7.000
7,106.380,0.01,-0.0003,-0.00030,7.000
7,106.500,0.00,-0.0003,-0.00030,7.000
7,106.620,0.00,-0.0003,-0.00030,7.000
7,106.740,0.00,-0.0003,-0.00030,7.000
7,106.860,0.01,-0.0003,-0.00030,7.000
7,106.980,0.00,-0.0003,-0.00030,7.000
7,107.100,0.00,-0.0003,-0.00030,7.000
7,107.220,0.00,-0.0003,-0.00030,7.000
7,107.340,0.00,-0.0003,-0.00030,7.000
7,107.460,0.00,-0.0003,-0.00030,7.000
7,107.580,0.02,-0.0003,-0.00030,7.000
7,107.700,0.00,-0.0003,-0.00030,7.000
7,107.820,0.01,-0.0003,-0.00030,7.000
7,107.940,-0.01,-0.0002,-0.00020,7.000
7,108.060,-0.01,-0.0002,-0.00020,7.000
7,108.180,0.00,-0.0002,-0.00020,7.000
7,108.300,-0.01,-0.0002,-0.00020,7.000
7,108.420,0.00,-0.0002,-0.00020,7.000
7,108.540,0.00,-0.0002,-0.00020,7.000
7,108.660,0.00,-0.0002,-0.00020,7.000
7,108.780,-0.01,-0.0002,-0.00020,7.000
7,108.910,0.00,-0.0002,-0.00020,7.000
7,109.030,0.00,-0.0002,-0.00020,7.000
7,109.150,0.00,-0.0002,-0.00020,7.000
7,109.270,0.01,-0.0002,-0.00020,7.000
7,109.390,0.00,-0.0002,-0.00020,7.000
7,109.510,0.01,-0.0002,-0.00020,7.000
7,109.630,0.01,-0.0002,-0.00020,7.000
7,109.750,0.00,-0.0002,-0.00020,7.000
7,109.870,0.00,-0.0002,-0.00020,7.000
7,109.990,0.00,-0.0002,-0.00020,7.000
7,110.110,0.00,-0.0002,-0.00020,7.000
7,110.230,-0.01,-0.0002,-0.00020,7.000
7,110.350,0.01,-0.0002,-0.00020,7.000
7,110.470,-0.01,-0.0002,-0.00020,7.000
7,110.590,0.00,-0.0001,-0.00010,7.000
7,110.710,0.00,-0.0001,-0.00010,7.000
7,110.830,0.01,-0.0001,-0.00010,7.000
7,110.950,0.01,-0.0001,-0.00010,7.000
7,111.070,0.00,-0.0001,-0.00010,7.000
7,111.190,0.00,-0.0001,-0.00010,7.000
7,111.310,0.01,-0.0001,-0.00010,7.000
7,111.430,0.01,-0.0001,-0.00010,7.000
7,111.550,0.00,-0.0001,-0.00010,7.000
7,111.670,0.01,-0.0001,-0.00010,7.000
7,111.790,0.00,-0.0001,-0.00010,7.000
8,112.000,0.00,0.0000,0.00000,8.000
8,112.130,0.00,0.0766,0.07660,8.000
8,112.250,0.00,0.1966,0.19660,8.000
8,112.370,0.00,0.3168,0.31680,8.000
8,112.490,0.00,0.4366,0.43660,8.000
8,112.610,0.00,0.5566,0.55660,8.000
8,112.730,0.00,0.6766,0.67660,8.000
8,112.850,0.00,0.7968,0.79680,8.000
8,112.970,0.00,0.9168,0.91680,8.000
8,113.090,0.00,1.0367,1.03670,8.000
8,113.210,0.00,1.1566,1.15660,8.000
8,113.330,0.00,1.2766,1.27660,8.000
8,113.450,0.00,1.3967,1.39670,8.000
8,113.570,0.00,1.5167,1.51670,8.000
8,113.690,0.00,1.6367,1.63670,8.000
8,113.810,0.00,1.7567,1.75670,8.000
8,113.930,0.00,1.8767,1.87670,8.000
8,114.050,0.00,1.9967,1.99670,8.000
8,114.170,0.00,2.1168,2.11680,8.000
8,114.290,0.00,2.2369,2.23690,8.000
8,114.410,0.00,2.3568,2.35680,8.000
8,114.530,0.00,2.4769,2.47690,8.000
8,114.650,0.00,2.5968,2.59680,8.000
8,114.770,0.00,2.7169,2.71690,8.000
8,114.890,0.00,2.8369,2.83690,8.000
8,115.010,0.00,2.9569,2.95690,8.000
8,115.130,0.00,3.0768,3.07680,8.000
8,115.250,0.00,3.1969,3.19690,8.000
8,115.370,0.02,3.3171,3.31710,8.000
8,115.490,0.04,3.4369,3.43690,8.000
8,115.610,0.10,3.5569,3.55690,8.000
8,115.730,0.21,3.6769,3.67690,8.000
8,115.850,0.38,3.7970,3.79700,8.000
8,115.970,0.62,3.9171,3.91710,8.000
8,116.090,0.94,4.0370,4.03700,8.000
8,116.210,1.34,4.1571,4.15710,8.000
8,116.330,1.83,4.2769,4.27690,8.000
8,116.450,2.41,4.3968,4.39680,8.000
8,116.570,3.10,4.5170,4.51700,8.000
8,116.690,3.90,4.6370,4.63700,8.000
8,116.810,4.83,4.7570,4.75700,8.000
8,116.950,5.23,4.7913,4.79130,8.000
8,117.070,3.96,4.6718,4.67180,8.000
8,117.190,3.03,4.5517,4.55170,8.000
8,117.310,2.28,4.4317,4.43170,8.000
8,117.430,1.69,4.3115,4.31150,8.000
8,117.550,1.21,4.1917,4.19170,8.000
8,117.670,0.83,4.0717,4.07170,8.000
8,117.790,0.53,3.9516,3.95160,8.000
8,117.910,0.31,3.8317,3.83170,8.000
8,118.030,0.16,3.7116,3.71160,8.000
8,118.150,0.07,3.5915,3.59150,8.000
8,118.270,0.01,3.4716,3.47160,8.000
8,118.390,0.00,3.3517,3.35170,8.000
8,118.510,0.00,3.2316,3.23160,8.000
8,118.630,0.01,3.1115,3.11150,8.000
8,118.750,0.00,2.9916,2.99160,8.000
8,118.870,0.01,2.8714,2.87140,8.000
8,118.990,0.00,2.7515,2.75150,8.000
8,119.110,0.00,2.6316,2.63160,8.000
8,119.230,0.00,2.5114,2.51140,8.000
8,119.350,0.00,2.3914,2.39140,8.000
8,119.470,0.01,2.2714,2.27140,8.000
8,119.590,0.00,2.1516,2.15160,8.000
8,119.710,0.00,2.0315,2.03150,8.000
8,119.830,0.00,1.9114,1.91140,8.000
8,119.950,0.00,1.7913,1.79130,8.000
8,120.070,0.01,1.6715,1.67150,8.000
8,120.190,0.00,1.5515,1.55150,8.000
8,120.310,0.00,1.4314,1.43140,8.000
8,120.430,-0.01,1.3114,1.31140,8.000
8,120.550,0.00,1.1913,1.19130,8.000
8,120.670,0.00,1.0714,1.07140,8.000
8,120.790,0.00,0.9513,0.95130,8.000
8,120.910,-0.01,0.8314,0.83140,8.000
8,121.030,0.00,0.7113,0.71130,8.000
8,121.150,0.00,0.5913,0.59130,8.000
8,121.270,0.01,0.4713,0.47130,8.000
8,121.390,0.00,0.3513,0.35130,8.000
8,121.510,-0.01,0.2313,0.23130,8.000
8,121.630,0.00,0.1113,0.11130,8.000
8,121.750,0.00,-0.0087,-0.00870,8.000
8,121.890,-0.01,-0.0016,-0.00160,8.000
8,122.010,0.01,-0.0003,-0.00030,8.000
8,122.130,0.00,-0.0003,-0.00030,8.000
8,122.250,-0.01,-0.0003,-0.00030,8.000
8,122.370,0.01,-0.0003,-0.00030,8.000
8,122.490,0.00,-0.0003,-0.00030,8.000
8,122.610,-0.01,-0.0003,-0.00030,8.000
8,122.730,-0.01,-0.0003,-0.00030,8.000
8,122.850,0.00,-0.0003,-0.00030,8.000
8,122.970,-0.01,-0.0003,-0.00030,8.000
8,123.090,0.01,-0.0003,-0.00030,8.000
8,123.210,0.01,-0.0003,-0.00030,8.000
8,123.330,0.00,-0.0003,-0.00030,8.000
8,123.450,0.00,-0.0003,-0.00030,8.000
8,123.570,0.01,-0.0003,-0.00030,8.000
8,123.690,0.01,-0.0002,-0.00020,8.000
8,123.810,0.00,-0.0002,-0.00020,8.000
8,123.930,0.00,-0.0002,-0.00020,8.000
8,124.050,0.00,-0.0002,-0.00020,8.000
8,124.170,0.01,-0.0002,-0.00020,8.000
8,124.290,0.00,-0.0002,-0.00020,8.000
8,124.410,0.01,-0.0002,-0.00020,8.000
8,124.530,0.00,-0.0002,-0.00020,8.000
8,124.650,0.00,-0.0002,-0.00020,8.000
8,124.770,0.01,-0.0002,-0.00020,8.000
8,124.900,0.01,-0.0002,-0.00020,8.000
8,125.020,0.00,-0.0002,-0.00020,8.000
8,125.140,0.00,-0.0002,-0.00020,8.000
8,125.260,0.00,-0.0002,-0.00020,8.000
8,125.380,0.00,-0.0002,-0.00020,8.000
8,125.500,0.00,-0.0002,-0.00020,8.000
8,125.620,0.00,-0.0002,-0.00020,8.000
8,125.740,-0.01,-0.0002,-0.00020,8.000
8,125.860,0.00,-0.0002,-0.00020,8.000
8,125.980,0.00,-0.0002,-0.00020,8.000
8,126.100,0.00,-0.0002,-0.00020,8.000
8,126.220,-0.01,-0.0002,-0.00020,8.000
8,126.340,0.00,-0.0002,-0.00020,8.000
8,126.460,0.00,-0.0001,-0.00010,8.000
8,126.580,0.00,-0.0001,-0.00010,8.000
8,126.700,0.01,-0.0001,-0.00010,8.000
8,126.820,0.00,-0.0001,-0.00010,8.000
8,126.940,0.00,-0.0001,-0.00010,8.000
8,127.060,0.00,-0.0001,-0.00010,8.000
8,127.180,0.00,-0.0001,-0.00010,8.000
8,127.300,0.01,-0.0001,-0.00010,8.000
8,127.420,0.00,-0.0001,-0.00010,8.000
8,127.540,0.00,-0.0001,-0.00010,8.000
8,127.660,-0.01,-0.0001,-0.00010,8.000
8,127.780,0.01,-0.0001,-0.00010,8.000
9,128.000,0.02,0.0000,0.00000,9.000
9,128.120,0.00,0.0856,0.08560,9.000
9,128.240,0.01,0.2056,0.20560,9.000
9,128.360,0.00,0.3257,0.32570,9.000
9,128.480,0.02,0.4457,0.44570,9.000
9,128.600,0.02,0.5656,0.56560,9.000
9,128.720,-0.01,0.6856,0.68560,9.000
9,128.840,0.00,0.8057,0.80570,9.000
9,128.960,0.01,0.9257,0.92570,9.000
9,129.080,0.02,1.0457,1.04570,9.000
9,129.200,0.00,1.1656,1.16560,9.000
9,129.320,0.00,1.2858,1.28580,9.000
9,129.440,0.01,1.4057,1.40570,9.000
9,129.560,0.00,1.5257,1.52570,9.000
9,129.680,0.00,1.6458,1.64580,9.000
9,129.800,-0.01,1.7657,1.76570,9.000
9,129.920,0.01,1.8858,1.88580,9.000
9,130.040,0.00,2.0058,2.00580,9.000
9,130.160,-0.01,2.1258,2.12580,9.000
9,130.280,0.01,2.2457,2.24570,9.000
9,130.400,0.00,2.3658,2.36580,9.000
9,130.520,0.02,2.4857,2.48570,9.000
9,130.640,0.00,2.6057,2.60570,9.000
9,130.760,-0.01,2.7257,2.72570,9.000
9,130.880,0.02,2.8457,2.84570,9.000
9,131.000,0.02,2.9658,2.96580,9.000
9,131.120,0.01,3.0857,3.08570,9.000
9,131.240,0.03,3.2057,3.20570,9.000
9,131.360,0.03,3.3258,3.32580,9.000
9,131.480,0.04,3.4458,3.44580,9.000
9,131.600,0.12,3.5659,3.56590,9.000
9,131.720,0.23,3.6858,3.68580,9.000
9,131.840,0.40,3.8058,3.80580,9.000
9,131.960,0.65,3.9259,3.92590,9.000
9,132.080,0.97,4.0458,4.04580,9.000
9,132.200,1.38,4.1658,4.16580,9.000
9,132.320,1.88,4.2858,4.28580,9.000
9,132.440,2.47,4.4058,4.40580,9.000
9,132.560,3.17,4.5258,4.52580,9.000
9,132.680,3.98,4.6460,4.64600,9.000
9,132.800,4.92,4.7658,4.76580,9.000
9,132.940,5.08,4.7786,4.77860,9.000
9,133.060,3.86,4.6587,4.65870,9.000
9,133.180,2.95,4.5387,4.53870,9.000
9,133.300,2.24,4.4186,4.41860,9.000
9,133.420,1.64,4.2986,4.29860,9.000
9,133.540,1.18,4.1786,4.17860,9.000
9,133.660,0.80,4.0585,4.05850,9.000
9,133.780,0.51,3.9387,3.93870,9.000
9,133.900,0.30,3.8184,3.81840,9.000
9,134.020,0.16,3.6986,3.69860,9.000
9,134.140,0.06,3.5785,3.57850,9.000
9,134.260,0.01,3.4584,3.45840,9.000
9,134.380,0.01,3.3387,3.33870,9.000
9,134.500,0.01,3.2184,3.21840,9.000
9,134.620,0.01,3.0985,3.09850,9.000
9,134.740,0.01,2.9785,2.97850,9.000
9,134.860,0.01,2.8584,2.85840,9.000
9,134.980,0.01,2.7385,2.73850,9.000
9,135.100,0.01,2.6185,2.61850,9.000
9,135.220,0.01,2.4985,2.49850,9.000
9,135.340,0.01,2.3785,2.37850,9.000
9,135.460,0.00,2.2586,2.25860,9.000
9,135.580,0.01,2.1385,2.13850,9.000
9,135.700,0.01,2.0185,2.01850,9.000
9,135.820,0.01,1.8983,1.89830,9.000
9,135.940,0.01,1.7783,1.77830,9.000
9,136.060,0.01,1.6585,1.65850,9.000
9,136.180,0.00,1.5385,1.53850,9.000
9,136.300,0.00,1.4184,1.41840,9.000
9,136.420,0.01,1.2984,1.29840,9.000
9,136.540,0.00,1.1784,1.17840,9.000
9,136.660,0.01,1.0583,1.05830,9.000
9,136.780,0.01,0.9385,0.93850,9.000
9,136.900,0.01,0.8185,0.81850,9.000
9,137.020,0.00,0.6984,0.69840,9.000
9,137.140,0.01,0.5784,0.57840,9.000
9,137.260,0.01,0.4584,0.45840,9.000
9,137.380,0.01,0.3383,0.33830,9.000
9,137.500,0.01,0.2183,0.21830,9.000
9,137.620,0.01,0.0984,0.09840,9.000
9,137.750,0.01,-0.0314,-0.03136,9.000
9,137.870,0.00,-0.0001,-0.00010,9.000
9,137.990,0.01,-0.0003,-0.00030,9.000
9,138.110,0.01,-0.0003,-0.00030,9.000
9,138.230,0.01,-0.0003,-0.00030,9.000
9,138.350,0.02,-0.0003,-0.00030,9.000
9,138.470,0.01,-0.0003,-0.00030,9.000
9,138.590,0.01,-0.0003,-0.00030,9.000
9,138.710,0.00,-0.0003,-0.00030,9.000
9,138.830,0.01,-0.0003,-0.00030,9.000
9,138.950,0.01,-0.0003,-0.00030,9.000
9,139.070,0.01,-0.0003,-0.00030,9.000
9,139.190,0.01,-0.0003,-0.00030,9.000
9,139.310,0.01,-0.0003,-0.00030,9.000
9,139.430,0.01,-0.0003,-0.00030,9.000
9,139.550,0.01,-0.0003,-0.00030,9.000
9,139.670,0.01,-0.0003,-0.00030,9.000
9,139.790,0.01,-0.0003,-0.00030,9.000
9,139.910,0.01,-0.0003,-0.00030,9.000
9,140.030,0.01,-0.0002,-0.00020,9.000
9,140.150,0.00,-0.0002,-0.00020,9.000
9,140.270,0.00,-0.0002,-0.00020,9.000
9,140.390,0.01,-0.0002,-0.00020,9.000
9,140.510,0.02,-0.0002,-0.00020,9.000
9,140.630,0.01,-0.0002,-0.00020,9.000
9,140.750,0.02,-0.0002,-0.00020,9.000
9,140.890,0.01,-0.0002,-0.00020,9.000
9,141.010,0.01,-0.0002,-0.00020,9.000
9,141.130,0.00,-0.0002,-0.00020,9.000
9,141.250,0.01,-0.0002,-0.00020,9.000
9,141.370,0.01,-0.0002,-0.00020,9.000
9,141.490,0.00,-0.0002,-0.00020,9.000
9,141.610,0.01,-0.0002,-0.00020,9.000
9,141.730,0.00,-0.0002,-0.00020,9.000
9,141.850,0.01,-0.0002,-0.00020,9.000
9,141.970,0.00,-0.0002,-0.00020,9.000
9,142.090,0.01,-0.0002,-0.00020,9.000
9,142.210,0.01,-0.0002,-0.00020,9.000
9,142.330,0.00,-0.0002,-0.00020,9.000
9,142.450,0.02,-0.0002,-0.00020,9.000
9,142.570,0.02,-0.0002,-0.00020,9.000
9,142.690,0.01,-0.0002,-0.00020,9.000
9,142.810,0.01,-0.0001,-0.00010,9.000
9,142.930,0.02,-0.0001,-0.00010,9.000
9,143.050,0.01,-0.0001,-0.00010,9.000
9,143.170,0.02,-0.0001,-0.00010,9.000
9,143.290,0.00,-0.0001,-0.00010,9.000
9,143.410,0.02,-0.0001,-0.00010,9.000
9,143.530,0.00,-0.0001,-0.00010,9.000
9,143.650,0.01,-0.0001,-0.00010,9.000
9,143.770,0.00,-0.0001,-0.00010,9.000
10,143.990,0.00,0.0028,0.00280,10.000
10,144.110,0.00,0.1156,0.11560,10.000
10,144.230,0.00,0.2357,0.23570,10.000
10,144.350,0.00,0.3557,0.35570,10.000
10,144.470,0.00,0.4757,0.47570,10.000
10,144.590,0.01,0.5955,0.59550,10.000
10,144.710,0.00,0.7156,0.71560,10.000
10,144.830,0.00,0.8358,0.83580,10.000
10,144.950,0.00,0.9558,0.95580,10.000
10,145.070,0.00,1.0758,1.07580,10.000
10,145.190,-0.01,1.1958,1.19580,10.000
10,145.310,0.00,1.3157,1.31570,10.000
10,145.430,0.00,1.4358,1.43580,10.000
10,145.550,0.00,1.5559,1.55590,10.000
10,145.670,0.00,1.6758,1.67580,10.000
10,145.790,0.00,1.7957,1.79570,10.000
10,145.910,0.00,1.9158,1.91580,10.000
10,146.030,-0.01,2.0359,2.03590,10.000
10,146.150,0.00,2.1559,2.15590,10.000
10,146.270,0.00,2.2758,2.27580,10.000
10,146.390,-0.01,2.3959,2.39590,10.000
10,146.510,-0.01,2.5158,2.51580,10.000
10,146.630,0.00,2.6358,2.63580,10.000
10,146.750,0.00,2.7558,2.75580,10.000
10,146.870,0.00,2.8759,2.87590,10.000
10,146.990,0.01,2.9960,2.99600,10.000
10,147.110,0.02,3.1160,3.11600,10.000
10,147.230,0.01,3.2360,3.23600,10.000
10,147.350,0.03,3.3560,3.35600,10.000
10,147.470,0.06,3.4760,3.47600,10.000
10,147.590,0.12,3.5960,3.59600,10.000
10,147.710,0.26,3.7160,3.71600,10.000
10,147.830,0.44,3.8361,3.83610,10.000
10,147.950,0.71,3.9560,3.95600,10.000
10,148.070,1.06,4.0760,4.07600,10.000
10,148.190,1.48,4.1961,4.19610,10.000
10,148.310,2.00,4.3159,4.31590,10.000
10,148.430,2.61,4.4359,4.43590,10.000
10,148.550,3.32,4.5561,4.55610,10.000
10,148.670,4.18,4.6761,4.67610,10.000
10,148.790,5.16,4.7959,4.79590,10.000
10,148.920,4.95,4.7705,4.77050,10.000
10,149.040,3.76,4.6506,4.65060,10.000
10,149.160,2.87,4.5306,4.53060,10.000
10,149.280,2.17,4.4105,4.41050,10.000
10,149.400,1.60,4.2905,4.29050,10.000
10,149.520,1.13,4.1705,4.17050,10.000
10,149.640,0.77,4.0505,4.05050,10.000
10,149.760,0.48,3.9305,3.93050,10.000
10,149.880,0.27,3.8104,3.81040,10.000
10,150.000,0.13,3.6904,3.69040,10.000
10,150.120,0.05,3.5704,3.57040,10.000
10,150.240,0.01,3.4504,3.45040,10.000
10,150.360,0.00,3.3305,3.33050,10.000
10,150.480,0.00,3.2103,3.21030,10.000
10,150.600,0.00,3.0903,3.09030,10.000
10,150.720,0.00,2.9704,2.97040,10.000
10,150.840,0.00,2.8503,2.85030,10.000
10,150.960,0.00,2.7303,2.73030,10.000
10,151.080,0.00,2.6103,2.61030,10.000
10,151.200,0.00,2.4903,2.49030,10.000
10,151.320,0.00,2.3704,2.37040,10.000
10,151.440,0.00,2.2503,2.25030,10.000
10,151.560,0.00,2.1304,2.13040,10.000
10,151.680,0.00,2.0104,2.01040,10.000
10,151.800,0.00,1.8903,1.89030,10.000
10,151.920,0.00,1.7703,1.77030,10.000
10,152.040,0.00,1.6503,1.65030,10.000
10,152.160,0.00,1.5303,1.53030,10.000
10,152.280,0.00,1.4103,1.41030,10.000
10,152.400,0.00,1.2902,1.29020,10.000
10,152.520,0.00,1.1702,1.17020,10.000
10,152.640,0.00,1.0503,1.05030,10.000
10,152.760,-0.01,0.9304,0.93040,10.000
10,152.880,0.00,0.8103,0.81030,10.000
10,153.000,-0.01,0.6902,0.69020,10.000
10,153.120,0.00,0.5702,0.57020,10.000
10,153.240,0.00,0.4502,0.45020,10.000
10,153.360,-0.01,0.3302,0.33020,10.000
10,153.480,-0.01,0.2101,0.21010,10.000
10,153.600,-0.01,0.0901,0.09010,10.000
10,153.740,-0.01,-0.0461,-0.04610,10.000
10,153.860,-0.01,0.0007,0.00070,10.000
10,153.980,0.00,-0.0003,-0.00030,10.000
10,154.100,0.00,-0.0003,-0.00030,10.000
10,154.220,-0.01,-0.0003,-0.00030,10.000
10,154.340,0.00,-0.0003,-0.00030,10.000
10,154.460,0.00,-0.0003,-0.00030,10.000
10,154.580,0.00,-0.0003,-0.00030,10.000
10,154.700,-0.01,-0.0003,-0.00030,10.000
10,154.820,0.00,-0.0003,-0.00030,10.000
10,154.940,-0.01,-0.0003,-0.00030,10.000
10,155.060,0.00,-0.0003,-0.00030,10.000
10,155.180,0.00,-0.0003,-0.00030,10.000
10,155.300,0.00,-0.0003,-0.00030,10.000
10,155.420,0.00,-0.0003,-0.00030,10.000
10,155.540,-0.01,-0.0002,-0.00020,10.000
10,155.660,0.00,-0.0002,-0.00020,10.000
10,155.780,0.00,-0.0002,-0.00020,10.000
10,155.900,0.00,-0.0002,-0.00020,10.000
10,156.020,0.00,-0.0002,-0.00020,10.000
10,156.140,0.00,-0.0002,-0.00020,10.000
10,156.260,-0.01,-0.0002,-0.00020,10.000
10,156.380,-0.01,-0.0002,-0.00020,10.000
10,156.500,0.00,-0.0002,-0.00020,10.000
10,156.620,0.00,-0.0002,-0.00020,10.000
10,156.740,-0.01,-0.0002,-0.00020,10.000
10,156.880,-0.01,-0.0002,-0.00020,10.000
10,157.000,0.00,-0.0002,-0.00020,10.000
10,157.120,-0.01,-0.0002,-0.00020,10.000
10,157.240,-0.01,-0.0002,-0.00020,10.000
10,157.360,-0.01,-0.0002,-0.00020,10.000
10,157.480,-0.01,-0.0002,-0.00020,10.000
10,157.600,0.00,-0.0002,-0.00020,10.000
10,157.720,-0.01,-0.0002,-0.00020,10.000
10,157.840,-0.01,-0.0002,-0.00020,10.000
10,157.960,0.00,-0.0002,-0.00020,10.000
10,158.080,0.00,-0.0002,-0.00020,10.000
10,158.200,0.00,-0.0002,-0.00020,10.000
10,158.320,0.00,-0.0001,-0.00010,10.000
10,158.440,0.01,-0.0001,-0.00010,10.000
10,158.560,0.00,-0.0001,-0.00010,10.000
10,158.680,0.00,-0.0001,-0.00010,10.000
10,158.800,0.00,-0.0001,-0.00010,10.000
10,158.920,0.00,-0.0001,-0.00010,10.000
10,159.040,0.00,-0.0001,-0.00010,10.000
10,159.160,0.00,-0.0001,-0.00010,10.000
10,159.280,0.00,-0.0001,-0.00010,10.000
10,159.400,0.00,-0.0001,-0.00010,10.000
10,159.520,0.00,-0.0001,-0.00010,10.000
10,159.640,0.00,-0.0001,-0.00010,10.000
10,159.760,0.00,-0.0001,-0.00010,10.000
10,159.810,-0.01,-0.0001,-0.00010,10.000