File: calibDATA_loadcell/date_30:1:2018/MTSdata_date_1.30/radhen_10cyc_black_0deg_0.5mms_50N.txt
""
"Test Method","Radhen_Load_Cntrl_Cmprsn_250N_12-7.msm"
"Sample I. D.","Sample1.mss"
"Specimen Number","5"

"TheCycle_Output ()","_Time (s)","_Load (N)","_Extension (mm)","RealTimeDepth (mm)","CycleNumber ()"

0,0.170,0.01,0.0000,-0.14290,0.000
1,0.380,0.01,0.0784,0.07840,1.000
1,0.580,0.01,0.1784,0.17840,1.000
1,0.780,0.00,0.2784,0.27840,1.000
1,0.980,0.01,0.3785,0.37850,1.000
1,1.180,0.00,0.4785,0.47850,1.000
1,1.380,0.01,0.5786,0.57860,1.000
1,1.580,0.00,0.6786,0.67860,1.000
1,1.780,0.00,0.7785,0.77850,1.000
1,1.980,0.01,0.8785,0.87850,1.000
1,2.180,0.00,0.9787,0.97870,1.000
1,2.380,0.01,1.0786,1.07860,1.000
1,2.580,0.01,1.1786,1.17860,1.000
1,2.780,0.00,1.2786,1.27860,1.000
1,2.980,0.01,1.3787,1.37870,1.000
1,3.180,0.01,1.4786,1.47860,1.000
1,3.380,0.01,1.5787,1.57870,1.000
1,3.580,0.01,1.6788,1.67880,1.000
1,3.780,0.00,1.7787,1.77870,1.000
1,3.980,0.01,1.8789,1.87890,1.000
1,4.180,0.01,1.9786,1.97860,1.000
1,4.380,0.01,2.0788,2.07880,1.000
1,4.580,0.01,2.1788,2.17880,1.000
1,4.780,0.03,2.2789,2.27890,1.000
1,4.980,0.07,2.3787,2.37870,1.000
1,5.180,0.16,2.4789,2.47890,1.000
1,5.380,0.32,2.5788,2.57880,1.000
1,5.580,0.56,2.6789,2.67890,1.000
1,5.780,0.85,2.7787,2.77870,1.000
1,5.980,1.23,2.8789,2.87890,1.000
1,6.180,1.67,2.9788,2.97880,1.000
1,6.380,2.20,3.0790,3.07900,1.000
1,6.580,2.79,3.1789,3.17890,1.000
1,6.780,3.47,3.2788,3.27880,1.000
1,6.980,4.23,3.3787,3.37870,1.000
1,7.180,5.08,3.4788,3.47880,1.000
1,7.380,6.01,3.5788,3.57880,1.000
1,7.580,7.14,3.6789,3.67890,1.000
1,7.780,8.37,3.7789,3.77890,1.000
1,7.980,9.73,3.8791,3.87910,1.000
1,8.180,11.23,3.9790,3.97900,1.000
1,8.380,12.89,4.0787,4.07870,1.000
1,8.580,14.72,4.1786,4.17860,1.000
1,8.780,16.74,4.2790,4.27900,1.000
1,8.980,18.93,4.3788,4.37880,1.000
1,9.180,21.40,4.4788,4.47880,1.000
1,9.380,24.14,4.5789,4.57890,1.000
1,9.580,27.14,4.6789,4.67890,1.000
1,9.780,30.43,4.7789,4.77890,1.000
1,9.980,34.07,4.8790,4.87900,1.000
1,10.180,38.07,4.9788,4.97880,1.000
1,10.380,42.59,5.0790,5.07900,1.000
1,10.580,47.77,5.1790,5.17900,1.000
1,10.790,47.17,5.1961,5.19610,1.000
1,10.990,38.52,5.0962,5.09620,1.000
1,11.190,32.16,4.9962,4.99620,1.000
1,11.390,27.10,4.8961,4.89610,1.000
1,11.590,22.97,4.7962,4.79620,1.000
1,11.790,19.56,4.6960,4.69600,1.000
1,11.990,16.70,4.5962,4.59620,1.000
1,12.190,14.30,4.4959,4.49590,1.000
1,12.390,12.29,4.3961,4.39610,1.000
1,12.590,10.55,4.2960,4.29600,1.000
1,12.790,9.09,4.1960,4.19600,1.000
1,12.990,7.84,4.0956,4.09560,1.000
1,13.190,6.75,3.9962,3.99620,1.000
1,13.390,5.79,3.8961,3.89610,1.000
1,13.590,4.97,3.7960,3.79600,1.000
1,13.790,4.25,3.6958,3.69580,1.000
1,13.990,3.60,3.5960,3.59600,1.000
1,14.190,3.03,3.4958,3.49580,1.000
1,14.390,2.50,3.3958,3.39580,1.000
1,14.590,2.04,3.2957,3.29570,1.000
1,14.790,1.63,3.1960,3.19600,1.000
1,14.990,1.26,3.0958,3.09580,1.000
1,15.190,0.94,2.9959,2.99590,1.000
1,15.390,0.68,2.8958,2.89580,1.000
1,15.590,0.45,2.7957,2.79570,1.000
1,15.790,0.27,2.6956,2.69560,1.000
1,15.990,0.13,2.5959,2.59590,1.000
1,16.190,0.06,2.4957,2.49570,1.000
1,16.390,0.02,2.3958,2.39580,1.000
1,16.590,0.01,2.2958,2.29580,1.000
1,16.790,0.01,2.1958,2.19580,1.000
1,16.990,0.01,2.0956,2.09560,1.000
1,17.190,0.00,1.9957,1.99570,1.000
1,17.390,0.00,1.8956,1.89560,1.000
1,17.590,0.01,1.7958,1.79580,1.000
1,17.790,0.00,1.6957,1.69570,1.000
1,17.990,0.00,1.5957,1.59570,1.000
1,18.190,0.01,1.4956,1.49560,1.000
1,18.390,0.01,1.3957,1.39570,1.000
1,18.590,0.01,1.2956,1.29560,1.000
1,18.790,0.00,1.1957,1.19570,1.000
1,18.990,0.01,1.0957,1.09570,1.000
1,19.190,0.01,0.9956,0.99560,1.000
1,19.390,0.01,0.8955,0.89550,1.000
1,19.590,0.00,0.7957,0.79570,1.000
1,19.790,0.00,0.6957,0.69570,1.000
1,19.990,0.00,0.5957,0.59570,1.000
1,20.190,0.01,0.4956,0.49560,1.000
1,20.390,0.01,0.3957,0.39570,1.000
1,20.590,0.01,0.2955,0.29550,1.000
1,20.790,0.01,0.1955,0.19550,1.000
1,20.990,0.00,0.0955,0.09550,1.000
1,21.190,0.01,-0.0043,-0.00430,1.000
1,21.410,0.01,-0.0004,-0.00040,1.000
1,21.610,0.01,-0.0003,-0.00030,1.000
1,21.810,0.00,-0.0003,-0.00030,1.000
1,22.010,0.01,-0.0003,-0.00030,1.000
1,22.210,0.01,-0.0003,-0.00030,1.000
1,22.410,0.01,-0.0003,-0.00030,1.000
1,22.610,0.02,-0.0003,-0.00030,1.000
1,22.810,0.01,-0.0003,-0.00030,1.000
1,23.010,0.00,-0.0003,-0.00030,1.000
1,23.210,0.00,-0.0003,-0.00030,1.000
1,23.410,0.01,-0.0003,-0.00030,1.000
1,23.610,0.01,-0.0003,-0.00030,1.000
1,23.810,0.01,-0.0003,-0.00030,1.000
1,24.010,0.01,-0.0003,-0.00030,1.000
1,24.210,0.01,-0.0003,-0.00030,1.000
1,24.430,0.01,-0.0003,-0.00030,1.000
1,24.630,0.00,-0.0002,-0.00020,1.000
1,24.830,0.01,-0.0002,-0.00020,1.000
1,25.030,0.01,-0.0002,-0.00020,1.000
1,25.230,0.02,-0.0002,-0.00020,1.000
1,25.430,0.01,-0.0002,-0.00020,1.000
1,25.630,0.01,-0.0002,-0.00020,1.000
1,25.830,0.01,-0.0002,-0.00020,1.000
1,26.030,0.01,-0.0002,-0.00020,1.000
1,26.230,0.01,-0.0002,-0.00020,1.000
1,26.430,0.01,-0.0002,-0.00020,1.000
1,26.630,0.00,-0.0002,-0.00020,1.000
1,26.830,0.01,-0.0002,-0.00020,1.000
1,27.030,0.01,-0.0002,-0.00020,1.000
1,27.230,0.01,-0.0002,-0.00020,1.000
2,27.520,-0.01,0.0436,0.04360,2.000
2,27.720,-0.01,0.1436,0.14360,2.000
2,27.920,0.00,0.2436,0.24360,2.000
2,28.120,-0.01,0.3438,0.34380,2.000
2,28.320,-0.01,0.4437,0.44370,2.000
2,28.520,-0.01,0.5437,0.54370,2.000
2,28.720,0.00,0.6436,0.64360,2.000
2,28.920,-0.01,0.7437,0.74370,2.000
2,29.120,0.00,0.8436,0.84360,2.000
2,29.320,0.00,0.9437,0.94370,2.000
2,29.520,-0.01,1.0438,1.04380,2.000
2,29.720,-0.01,1.1437,1.14370,2.000
2,29.920,-0.01,1.2437,1.24370,2.000
2,30.120,-0.01,1.3439,1.34390,2.000
2,30.320,-0.01,1.4438,1.44380,2.000
2,30.520,0.00,1.5438,1.54380,2.000
2,30.720,-0.01,1.6437,1.64370,2.000
2,30.920,0.00,1.7438,1.74380,2.000
2,31.120,0.00,1.8439,1.84390,2.000
2,31.320,-0.01,1.9438,1.94380,2.000
2,31.520,0.00,2.0438,2.04380,2.000
2,31.720,-0.01,2.1439,2.14390,2.000
2,31.920,0.00,2.2439,2.24390,2.000
2,32.120,0.03,2.3438,2.34380,2.000
2,32.320,0.09,2.4439,2.44390,2.000
2,32.520,0.21,2.5439,2.54390,2.000
2,32.720,0.40,2.6438,2.64380,2.000
2,32.920,0.67,2.7439,2.74390,2.000
2,33.120,1.01,2.8438,2.84380,2.000
2,33.320,1.41,2.9439,2.94390,2.000
2,33.520,1.90,3.0439,3.04390,2.000
2,33.720,2.46,3.1440,3.14400,2.000
2,33.920,3.10,3.2438,3.24380,2.000
2,34.120,3.83,3.3439,3.34390,2.000
2,34.320,4.63,3.4438,3.44380,2.000
2,34.520,5.53,3.5438,3.54380,2.000
2,34.720,6.58,3.6440,3.64400,2.000
2,34.920,7.77,3.7438,3.74380,2.000
2,35.120,9.10,3.8441,3.84410,2.000
2,35.320,10.54,3.9441,3.94410,2.000
2,35.520,12.15,4.0439,4.04390,2.000
2,35.720,13.91,4.1438,4.14380,2.000
2,35.920,15.86,4.2440,4.24400,2.000
2,36.120,17.97,4.3439,4.34390,2.000
2,36.320,20.33,4.4439,4.44390,2.000
2,36.520,22.95,4.5438,4.54380,2.000
2,36.720,25.85,4.6440,4.64400,2.000
2,36.920,29.01,4.7438,4.74380,2.000
2,37.120,32.53,4.8439,4.84390,2.000
2,37.320,36.40,4.9438,4.94380,2.000
2,37.520,40.73,5.0440,5.04400,2.000
2,37.720,45.65,5.1439,5.14390,2.000
2,37.930,51.51,5.2397,5.23970,2.000
2,38.130,41.69,5.1417,5.14170,2.000
2,38.330,34.56,5.0418,5.04180,2.000
2,38.530,29.01,4.9415,4.94150,2.000
2,38.730,24.53,4.8416,4.84160,2.000
2,38.930,20.83,4.7415,4.74150,2.000
2,39.130,17.75,4.6416,4.64160,2.000
2,39.330,15.19,4.5414,4.54140,2.000
2,39.530,13.02,4.4415,4.44150,2.000
2,39.730,11.17,4.3414,4.34140,2.000
2,39.930,9.61,4.2415,4.24150,2.000
2,40.130,8.28,4.1412,4.14120,2.000
2,40.330,7.13,4.0415,4.04150,2.000
2,40.530,6.12,3.9416,3.94160,2.000
2,40.730,5.24,3.8415,3.84150,2.000
2,40.930,4.49,3.7414,3.74140,2.000
2,41.130,3.82,3.6415,3.64150,2.000
2,41.330,3.21,3.5414,3.54140,2.000
2,41.530,2.67,3.4413,3.44130,2.000
2,41.730,2.19,3.3412,3.34120,2.000
2,41.930,1.75,3.2413,3.24130,2.000
2,42.130,1.37,3.1413,3.14130,2.000
2,42.330,1.04,3.0414,3.04140,2.000
2,42.530,0.75,2.9413,2.94130,2.000
2,42.730,0.51,2.8413,2.84130,2.000
2,42.930,0.32,2.7411,2.74110,2.000
2,43.130,0.16,2.6412,2.64120,2.000
2,43.330,0.07,2.5411,2.54110,2.000
2,43.530,0.02,2.4412,2.44120,2.000
2,43.730,-0.01,2.3413,2.34130,2.000
2,43.930,-0.01,2.2413,2.24130,2.000
2,44.130,-0.01,2.1412,2.14120,2.000
2,44.330,0.00,2.0412,2.04120,2.000
2,44.530,-0.01,1.9411,1.94110,2.000
2,44.730,-0.01,1.8413,1.84130,2.000
2,44.930,-0.01,1.7411,1.74110,2.000
2,45.130,-0.01,1.6411,1.64110,2.000
2,45.330,0.00,1.5412,1.54120,2.000
2,45.530,-0.01,1.4411,1.44110,2.000
2,45.730,-0.01,1.3412,1.34120,2.000
2,45.930,-0.01,1.2412,1.24120,2.000
2,46.130,0.00,1.1412,1.14120,2.000
2,46.330,-0.01,1.0411,1.04110,2.000
2,46.530,0.00,0.9412,0.94120,2.000
2,46.730,0.00,0.8411,0.84110,2.000
2,46.930,-0.01,0.7412,0.74120,2.000
2,47.130,-0.01,0.6411,0.64110,2.000
2,47.330,-0.01,0.5412,0.54120,2.000
2,47.530,0.00,0.4411,0.44110,2.000
2,47.730,0.00,0.3412,0.34120,2.000
2,47.930,-0.01,0.2410,0.24100,2.000
2,48.130,-0.02,0.1411,0.14110,2.000
2,48.330,-0.01,0.0410,0.04100,2.000
2,48.550,-0.01,-0.0003,-0.00030,2.000
2,48.750,0.00,-0.0003,-0.00030,2.000
2,48.950,0.00,-0.0003,-0.00030,2.000
2,49.150,-0.01,-0.0003,-0.00030,2.000
2,49.350,-0.01,-0.0003,-0.00030,2.000
2,49.550,-0.01,-0.0003,-0.00030,2.000
2,49.750,-0.01,-0.0003,-0.00030,2.000
2,49.950,-0.01,-0.0003,-0.00030,2.000
2,50.150,-0.01,-0.0003,-0.00030,2.000
2,50.350,-0.01,-0.0003,-0.00030,2.000
2,50.550,-0.01,-0.0003,-0.00030,2.000
2,50.750,-0.01,-0.0003,-0.00030,2.000
2,50.950,-0.01,-0.0003,-0.00030,2.000
2,51.150,-0.01,-0.0003,-0.00030,2.000
2,51.350,0.00,-0.0003,-0.00030,2.000
2,51.570,-0.01,-0.0003,-0.00030,2.000
2,51.770,0.00,-0.0002,-0.00020,2.000
2,51.970,0.00,-0.0002,-0.00020,2.000
2,52.170,-0.01,-0.0002,-0.00020,2.000
2,52.370,-0.01,-0.0002,-0.00020,2.000
2,52.570,0.00,-0.0002,-0.00020,2.000
2,52.770,0.00,-0.0002,-0.00020,2.000
2,52.970,-0.01,-0.0002,-0.00020,2.000
2,53.170,-0.01,-0.0002,-0.00020,2.000
2,53.370,0.00,-0.0002,-0.00020,2.000
2,53.570,-0.02,-0.0002,-0.00020,2.000
2,53.770,-0.01,-0.0002,-0.00020,2.000
2,53.970,0.00,-0.0002,-0.00020,2.000
2,54.170,-0.01,-0.0002,-0.00020,2.000
2,54.370,0.00,-0.0002,-0.00020,2.000
3,54.670,0.01,-0.0001,-0.00010,3.000
3,54.870,0.00,0.0935,0.09350,3.000
3,55.070,0.01,0.1936,0.19360,3.000
3,55.270,0.01,0.2935,0.29350,3.000
3,55.470,0.00,0.3937,0.39370,3.000
3,55.670,0.00,0.4936,0.49360,3.000
3,55.870,0.01,0.5938,0.59380,3.000
3,56.070,0.00,0.6936,0.69360,3.000
3,56.270,0.00,0.7937,0.79370,3.000
3,56.470,0.01,0.8936,0.89360,3.000
3,56.670,0.01,0.9939,0.99390,3.000
3,56.870,0.01,1.0938,1.09380,3.000
3,57.070,0.00,1.1938,1.19380,3.000
3,57.270,0.01,1.2938,1.29380,3.000
3,57.470,0.01,1.3938,1.39380,3.000
3,57.670,0.00,1.4937,1.49370,3.000
3,57.870,0.00,1.5940,1.59400,3.000
3,58.070,0.00,1.6937,1.69370,3.000
3,58.270,0.00,1.7939,1.79390,3.000
3,58.470,0.00,1.8938,1.89380,3.000
3,58.670,0.00,1.9939,1.99390,3.000
3,58.870,0.01,2.0938,2.09380,3.000
3,59.070,0.01,2.1940,2.19400,3.000
3,59.270,0.02,2.2939,2.29390,3.000
3,59.470,0.07,2.3939,2.39390,3.000
3,59.670,0.15,2.4938,2.49380,3.000
3,59.870,0.29,2.5940,2.59400,3.000
3,60.070,0.53,2.6937,2.69370,3.000
3,60.270,0.82,2.7938,2.79380,3.000
3,60.470,1.19,2.8938,2.89380,3.000
3,60.670,1.64,2.9940,2.99400,3.000
3,60.870,2.16,3.0939,3.09390,3.000
3,61.070,2.76,3.1940,3.19400,3.000
3,61.270,3.43,3.2937,3.29370,3.000
3,61.470,4.20,3.3939,3.39390,3.000
3,61.670,5.05,3.4938,3.49380,3.000
3,61.870,6.00,3.5940,3.59400,3.000
3,62.070,7.15,3.6938,3.69380,3.000
3,62.270,8.41,3.7940,3.79400,3.000
3,62.470,9.79,3.8939,3.89390,3.000
3,62.670,11.32,3.9941,3.99410,3.000
3,62.870,13.01,4.0937,4.09370,3.000
3,63.070,14.86,4.1939,4.19390,3.000
3,63.270,16.90,4.2940,4.29400,3.000
3,63.470,19.12,4.3939,4.39390,3.000
3,63.670,21.59,4.4937,4.49370,3.000
3,63.870,24.34,4.5939,4.59390,3.000
3,64.070,27.39,4.6938,4.69380,3.000
3,64.270,30.72,4.7940,4.79400,3.000
3,64.470,34.40,4.8939,4.89390,3.000
3,64.670,38.49,4.9939,4.99390,3.000
3,64.870,43.09,5.0940,5.09400,3.000
3,65.070,48.34,5.1941,5.19410,3.000
3,65.290,46.09,5.1916,5.19160,3.000
3,65.490,37.75,5.0917,5.09170,3.000
3,65.690,31.55,4.9917,4.99170,3.000
3,65.890,26.59,4.8916,4.89160,3.000
3,66.090,22.54,4.7916,4.79160,3.000
3,66.290,19.17,4.6915,4.69150,3.000
3,66.490,16.36,4.5916,4.59160,3.000
3,66.690,14.01,4.4914,4.49140,3.000
3,66.890,12.01,4.3915,4.39150,3.000
3,67.090,10.32,4.2915,4.29150,3.000
3,67.290,8.88,4.1915,4.19150,3.000
3,67.490,7.65,4.0913,4.09130,3.000
3,67.690,6.60,3.9916,3.99160,3.000
3,67.890,5.65,3.8916,3.89160,3.000
3,68.090,4.84,3.7916,3.79160,3.000
3,68.290,4.13,3.6914,3.69140,3.000
3,68.490,3.50,3.5915,3.59150,3.000
3,68.690,2.92,3.4912,3.49120,3.000
3,68.890,2.42,3.3914,3.39140,3.000
3,69.090,1.96,3.2913,3.29130,3.000
3,69.290,1.55,3.1914,3.19140,3.000
3,69.490,1.20,3.0913,3.09130,3.000
3,69.690,0.89,2.9914,2.99140,3.000
3,69.890,0.63,2.8912,2.89120,3.000
3,70.090,0.41,2.7913,2.79130,3.000
3,70.290,0.25,2.6912,2.69120,3.000
3,70.490,0.12,2.5914,2.59140,3.000
3,70.690,0.05,2.4911,2.49110,3.000
3,70.890,0.02,2.3914,2.39140,3.000
3,71.090,0.01,2.2913,2.29130,3.000
3,71.290,0.01,2.1914,2.19140,3.000
3,71.490,0.01,2.0911,2.09110,3.000
3,71.690,0.01,1.9913,1.99130,3.000
3,71.890,0.01,1.8911,1.89110,3.000
3,72.090,0.02,1.7912,1.79120,3.000
3,72.290,0.01,1.6911,1.69110,3.000
3,72.490,0.01,1.5913,1.59130,3.000
3,72.690,0.00,1.4911,1.49110,3.000
3,72.890,0.01,1.3912,1.39120,3.000
3,73.090,0.01,1.2910,1.29100,3.000
3,73.290,0.01,1.1912,1.19120,3.000
3,73.490,0.01,1.0911,1.09110,3.000
3,73.690,0.01,0.9912,0.99120,3.000
3,73.890,0.01,0.8911,0.89110,3.000
3,74.090,0.01,0.7911,0.79110,3.000
3,74.290,0.00,0.6912,0.69120,3.000
3,74.490,0.01,0.5911,0.59110,3.000
3,74.690,0.01,0.4911,0.49110,3.000
3,74.890,0.01,0.3913,0.39130,3.000
3,75.090,0.00,0.2910,0.29100,3.000
3,75.290,0.01,0.1911,0.19110,3.000
3,75.490,0.01,0.0911,0.09110,3.000
3,75.710,0.01,-0.0184,-0.01836,3.000
3,75.910,0.00,-0.0003,-0.00030,3.000
3,76.110,0.01,-0.0003,-0.00030,3.000
3,76.310,0.01,-0.0003,-0.00030,3.000
3,76.510,0.01,-0.0003,-0.00030,3.000
3,76.710,0.01,-0.0003,-0.00030,3.000
3,76.910,0.01,-0.0003,-0.00030,3.000
3,77.110,0.01,-0.0003,-0.00030,3.000
3,77.310,0.02,-0.0003,-0.00030,3.000
3,77.510,0.01,-0.0003,-0.00030,3.000
3,77.710,0.01,-0.0003,-0.00030,3.000
3,77.910,0.01,-0.0003,-0.00030,3.000
3,78.110,0.00,-0.0003,-0.00030,3.000
3,78.310,0.01,-0.0003,-0.00030,3.000
3,78.510,0.00,-0.0003,-0.00030,3.000
3,78.710,0.01,-0.0002,-0.00020,3.000
3,78.930,0.02,-0.0002,-0.00020,3.000
3,79.130,0.01,-0.0002,-0.00020,3.000
3,79.330,0.00,-0.0002,-0.00020,3.000
3,79.530,0.01,-0.0002,-0.00020,3.000
3,79.730,0.01,-0.0002,-0.00020,3.000
3,79.930,0.01,-0.0002,-0.00020,3.000
3,80.130,0.01,-0.0002,-0.00020,3.000
3,80.330,0.01,-0.0002,-0.00020,3.000
3,80.530,0.00,-0.0002,-0.00020,3.000
3,80.730,0.01,-0.0002,-0.00020,3.000
3,80.930,0.02,-0.0002,-0.00020,3.000
3,81.130,0.01,-0.0002,-0.00020,3.000
3,81.330,0.01,-0.0002,-0.00020,3.000
3,81.530,0.00,-0.0001,-0.00010,3.000
3,81.730,0.00,-0.0001,-0.00010,3.000
4,82.020,0.00,0.0480,0.04800,4.000
4,82.220,0.00,0.1481,0.14810,4.000
4,82.420,0.00,0.2481,0.24810,4.000
4,82.620,0.00,0.3482,0.34820,4.000
4,82.820,0.00,0.4481,0.44810,4.000
4,83.020,0.00,0.5483,0.54830,4.000
4,83.220,0.00,0.6482,0.64820,4.000
4,83.420,0.01,0.7483,0.74830,4.000
4,83.620,0.01,0.8482,0.84820,4.000
4,83.820,0.00,0.9483,0.94830,4.000
4,84.020,0.00,1.0483,1.04830,4.000
4,84.220,0.01,1.1483,1.14830,4.000
4,84.420,0.00,1.2481,1.24810,4.000
4,84.620,0.00,1.3483,1.34830,4.000
4,84.820,0.01,1.4482,1.44820,4.000
4,85.020,0.01,1.5484,1.54840,4.000
4,85.220,0.01,1.6482,1.64820,4.000
4,85.420,0.01,1.7484,1.74840,4.000
4,85.620,0.00,1.8483,1.84830,4.000
4,85.820,0.01,1.9483,1.94830,4.000
4,86.020,0.01,2.0483,2.04830,4.000
4,86.220,0.00,2.1484,2.14840,4.000
4,86.420,0.01,2.2483,2.24830,4.000
4,86.620,0.03,2.3484,2.34840,4.000
4,86.820,0.10,2.4483,2.44830,4.000
4,87.020,0.22,2.5484,2.54840,4.000
4,87.220,0.40,2.6484,2.64840,4.000
4,87.420,0.65,2.7483,2.74830,4.000
4,87.620,0.99,2.8482,2.84820,4.000
4,87.820,1.41,2.9484,2.94840,4.000
4,88.020,1.89,3.0484,3.04840,4.000
4,88.220,2.45,3.1484,3.14840,4.000
4,88.420,3.09,3.2484,3.24840,4.000
4,88.620,3.82,3.3483,3.34830,4.000
4,88.820,4.63,3.4484,3.44840,4.000
4,89.020,5.53,3.5483,3.54830,4.000
4,89.220,6.59,3.6483,3.64830,4.000
4,89.420,7.79,3.7484,3.74840,4.000
4,89.620,9.12,3.8485,3.84850,4.000
4,89.820,10.60,3.9485,3.94850,4.000
4,90.020,12.22,4.0483,4.04830,4.000
4,90.220,13.99,4.1483,4.14830,4.000
4,90.420,15.94,4.2484,4.24840,4.000
4,90.620,18.06,4.3484,4.34840,4.000
4,90.820,20.42,4.4485,4.44850,4.000
4,91.020,23.04,4.5484,4.54840,4.000
4,91.220,25.95,4.6483,4.64830,4.000
4,91.420,29.11,4.7483,4.74830,4.000
4,91.620,32.64,4.8484,4.84840,4.000
4,91.820,36.51,4.9484,4.94840,4.000
4,92.020,40.83,5.0485,5.04850,4.000
4,92.220,45.74,5.1484,5.14840,4.000
4,92.430,51.64,5.2444,5.24440,4.000
4,92.630,41.81,5.1467,5.14670,4.000
4,92.830,34.63,5.0467,5.04670,4.000
4,93.030,29.07,4.9466,4.94660,4.000
4,93.230,24.57,4.8466,4.84660,4.000
4,93.430,20.86,4.7465,4.74650,4.000
4,93.630,17.78,4.6466,4.64660,4.000
4,93.830,15.21,4.5464,4.54640,4.000
4,94.030,13.03,4.4465,4.44650,4.000
4,94.230,11.19,4.3465,4.34650,4.000
4,94.430,9.60,4.2465,4.24650,4.000
4,94.630,8.28,4.1462,4.14620,4.000
4,94.830,7.13,4.0464,4.04640,4.000
4,95.030,6.13,3.9467,3.94670,4.000
4,95.230,5.23,3.8465,3.84650,4.000
4,95.430,4.48,3.7464,3.74640,4.000
4,95.630,3.81,3.6464,3.64640,4.000
4,95.830,3.22,3.5464,3.54640,4.000
4,96.030,2.67,3.4463,3.44630,4.000
4,96.230,2.18,3.3463,3.34630,4.000
4,96.430,1.75,3.2463,3.24630,4.000
4,96.630,1.37,3.1464,3.14640,4.000
4,96.830,1.04,3.0463,3.04630,4.000
4,97.030,0.75,2.9463,2.94630,4.000
4,97.230,0.51,2.8463,2.84630,4.000
4,97.430,0.32,2.7462,2.74620,4.000
4,97.630,0.17,2.6462,2.64620,4.000
4,97.830,0.07,2.5463,2.54630,4.000
4,98.030,0.02,2.4462,2.44620,4.000
4,98.230,0.00,2.3462,2.34620,4.000
4,98.430,0.00,2.2462,2.24620,4.000
4,98.630,0.00,2.1462,2.14620,4.000
4,98.830,0.00,2.0461,2.04610,4.000
4,99.030,0.00,1.9462,1.94620,4.000
4,99.230,0.01,1.8463,1.84630,4.000
4,99.430,0.00,1.7463,1.74630,4.000
4,99.630,0.00,1.6462,1.64620,4.000
4,99.830,0.01,1.5462,1.54620,4.000
4,100.030,0.01,1.4460,1.44600,4.000
4,100.230,0.00,1.3463,1.34630,4.000
4,100.430,0.01,1.2460,1.24600,4.000
4,100.630,0.00,1.1463,1.14630,4.000
4,100.830,0.00,1.0463,1.04630,4.000
4,101.030,0.01,0.9462,0.94620,4.000
4,101.230,0.01,0.8460,0.84600,4.000
4,101.430,0.01,0.7462,0.74620,4.000
4,101.630,0.00,0.6461,0.64610,4.000
4,101.830,0.00,0.5461,0.54610,4.000
4,102.030,0.00,0.4460,0.44600,4.000
4,102.230,0.01,0.3462,0.34620,4.000
4,102.430,0.01,0.2460,0.24600,4.000
4,102.630,0.01,0.1462,0.14620,4.000
4,102.830,0.00,0.0461,0.04610,4.000
4,103.050,0.01,-0.0006,-0.00060,4.000
4,103.250,0.00,-0.0003,-0.00030,4.000
4,103.450,0.01,-0.0003,-0.00030,4.000
4,103.650,0.00,-0.0003,-0.00030,4.000
4,103.850,0.00,-0.0003,-0.00030,4.000
4,104.050,0.00,-0.0003,-0.00030,4.000
4,104.250,0.00,-0.0003,-0.00030,4.000
4,104.450,0.01,-0.0003,-0.00030,4.000
4,104.650,0.00,-0.0003,-0.00030,4.000
4,104.850,0.00,-0.0003,-0.00030,4.000
4,105.050,0.01,-0.0003,-0.00030,4.000
4,105.250,0.00,-0.0003,-0.00030,4.000
4,105.450,0.01,-0.0003,-0.00030,4.000
4,105.650,0.00,-0.0003,-0.00030,4.000
4,105.850,0.00,-0.0002,-0.00020,4.000
4,106.060,0.00,-0.0002,-0.00020,4.000
4,106.260,0.00,-0.0002,-0.00020,4.000
4,106.460,0.01,-0.0002,-0.00020,4.000
4,106.660,0.00,-0.0002,-0.00020,4.000
4,106.860,0.00,-0.0002,-0.00020,4.000
4,107.060,-0.01,-0.0002,-0.00020,4.000
4,107.260,0.01,-0.0002,-0.00020,4.000
4,107.460,0.00,-0.0002,-0.00020,4.000
4,107.660,0.00,-0.0002,-0.00020,4.000
4,107.860,0.00,-0.0002,-0.00020,4.000
4,108.060,0.00,-0.0002,-0.00020,4.000
4,108.260,0.00,-0.0002,-0.00020,4.000
4,108.460,0.01,-0.0002,-0.00020,4.000
4,108.660,0.00,-0.0001,-0.00010,4.000
4,108.860,0.00,-0.0001,-0.00010,4.000
4,109.150,-0.02,0.0000,0.00000,4.000
5,109.360,0.00,0.0781,0.07810,5.000
5,109.560,-0.01,0.1781,0.17810,5.000
5,109.760,0.00,0.2781,0.27810,5.000
5,109.960,0.00,0.3781,0.37810,5.000
5,110.160,0.00,0.4782,0.47820,5.000
5,110.360,0.00,0.5782,0.57820,5.000
5,110.560,0.00,0.6783,0.67830,5.000
5,110.760,-0.01,0.7781,0.77810,5.000
5,110.960,0.00,0.8782,0.87820,5.000
5,111.160,0.00,0.9782,0.97820,5.000
5,111.360,0.00,1.0783,1.07830,5.000
5,111.560,0.00,1.1782,1.17820,5.000
5,111.760,0.00,1.2783,1.27830,5.000
5,111.960,0.00,1.3782,1.37820,5.000
5,112.160,0.00,1.4783,1.47830,5.000
5,112.360,-0.01,1.5783,1.57830,5.000
5,112.560,-0.01,1.6784,1.67840,5.000
5,112.760,0.00,1.7782,1.77820,5.000
5,112.960,0.00,1.8785,1.87850,5.000
5,113.160,0.00,1.9783,1.97830,5.000
5,113.360,-0.01,2.0783,2.07830,5.000
5,113.560,0.00,2.1784,2.17840,5.000
5,113.760,0.00,2.2785,2.27850,5.000
5,113.960,0.04,2.3783,2.37830,5.000
5,114.160,0.12,2.4784,2.47840,5.000
5,114.360,0.24,2.5784,2.57840,5.000
5,114.560,0.46,2.6785,2.67850,5.000
5,114.760,0.73,2.7782,2.77820,5.000
5,114.960,1.09,2.8785,2.87850,5.000
5,115.160,1.53,2.9783,2.97830,5.000
5,115.360,2.03,3.0786,3.07860,5.000
5,115.560,2.61,3.1784,3.17840,5.000
5,115.760,3.28,3.2785,3.27850,5.000
5,115.960,4.02,3.3783,3.37830,5.000
5,116.160,4.87,3.4785,3.47850,5.000
5,116.360,5.80,3.5783,3.57830,5.000
5,116.560,6.91,3.6785,3.67850,5.000
5,116.760,8.14,3.7783,3.77830,5.000
5,116.960,9.53,3.8786,3.87860,5.000
5,117.160,11.04,3.9785,3.97850,5.000
5,117.360,12.70,4.0783,4.07830,5.000
5,117.560,14.53,4.1782,4.17820,5.000
5,117.760,16.53,4.2786,4.27860,5.000
5,117.960,18.70,4.3783,4.37830,5.000
5,118.160,21.13,4.4784,4.47840,5.000
5,118.360,23.83,4.5783,4.57830,5.000
5,118.560,26.81,4.6784,4.67840,5.000
5,118.760,30.07,4.7783,4.77830,5.000
5,118.960,33.68,4.8785,4.87850,5.000
5,119.160,37.68,4.9783,4.97830,5.000
5,119.360,42.15,5.0786,5.07860,5.000
5,119.560,47.26,5.1784,5.17840,5.000
5,119.770,48.40,5.2164,5.21640,5.000
5,119.970,39.33,5.1167,5.11670,5.000
5,120.170,32.74,5.0167,5.01670,5.000
5,120.370,27.56,4.9166,4.91660,5.000
5,120.570,23.32,4.8166,4.81660,5.000
5,120.770,19.83,4.7166,4.71660,5.000
5,120.970,16.89,4.6164,4.61640,5.000
5,121.170,14.45,4.5166,4.51660,5.000
5,121.370,12.39,4.4164,4.41640,5.000
5,121.570,10.63,4.3165,4.31650,5.000
5,121.770,9.13,4.2164,4.21640,5.000
5,121.970,7.88,4.1164,4.11640,5.000
5,122.170,6.78,4.0165,4.01650,5.000
5,122.370,5.80,3.9167,3.91670,5.000
5,122.570,4.96,3.8165,3.81650,5.000
5,122.770,4.24,3.7164,3.71640,5.000
5,122.970,3.58,3.6164,3.61640,5.000
5,123.170,3.01,3.5164,3.51640,5.000
5,123.370,2.49,3.4162,3.41620,5.000
5,123.570,2.02,3.3164,3.31640,5.000
5,123.770,1.61,3.2162,3.21620,5.000
5,123.970,1.24,3.1164,3.11640,5.000
5,124.170,0.92,3.0163,3.01630,5.000
5,124.370,0.66,2.9163,2.91630,5.000
5,124.570,0.44,2.8161,2.81610,5.000
5,124.770,0.26,2.7163,2.71630,5.000
5,124.970,0.13,2.6160,2.61600,5.000
5,125.170,0.05,2.5164,2.51640,5.000
5,125.370,0.01,2.4161,2.41610,5.000
5,125.570,-0.01,2.3164,2.31640,5.000
5,125.770,-0.01,2.2161,2.21610,5.000
5,125.970,-0.01,2.1164,2.11640,5.000
5,126.170,0.00,2.0161,2.01610,5.000
5,126.370,-0.01,1.9163,1.91630,5.000
5,126.570,0.00,1.8162,1.81620,5.000
5,126.770,0.00,1.7163,1.71630,5.000
5,126.970,0.00,1.6162,1.61620,5.000
5,127.170,0.00,1.5162,1.51620,5.000
5,127.370,0.00,1.4161,1.41610,5.000
5,127.570,-0.01,1.3162,1.31620,5.000
5,127.770,0.00,1.2160,1.21600,5.000
5,127.970,0.00,1.1162,1.11620,5.000
5,128.170,0.00,1.0161,1.01610,5.000
5,128.370,-0.01,0.9163,0.91630,5.000
5,128.570,0.00,0.8161,0.81610,5.000
5,128.770,0.00,0.7163,0.71630,5.000
5,128.970,-0.01,0.6161,0.61610,5.000
5,129.170,-0.01,0.5162,0.51620,5.000
5,129.370,-0.01,0.4161,0.41610,5.000
5,129.570,-0.01,0.3162,0.31620,5.000
5,129.770,0.00,0.2161,0.21610,5.000
5,129.970,0.00,0.1162,0.11620,5.000
5,130.170,0.00,0.0161,0.01610,5.000
5,130.380,-0.01,-0.0003,-0.00030,5.000
5,130.580,0.00,-0.0003,-0.00030,5.000
5,130.780,0.01,-0.0003,-0.00030,5.000
5,130.980,0.00,-0.0003,-0.00030,5.000
5,131.180,0.00,-0.0003,-0.00030,5.000
5,131.380,-0.01,-0.0003,-0.00030,5.000
5,131.580,0.00,-0.0003,-0.00030,5.000
5,131.780,0.00,-0.0003,-0.00030,5.000
5,131.980,0.00,-0.0003,-0.00030,5.000
5,132.180,0.00,-0.0003,-0.00030,5.000
5,132.380,0.00,-0.0003,-0.00030,5.000
5,132.580,-0.01,-0.0003,-0.00030,5.000
5,132.780,-0.01,-0.0003,-0.00030,5.000
5,132.980,0.00,-0.0002,-0.00020,5.000
5,133.180,0.00,-0.0002,-0.00020,5.000
5,133.400,-0.01,-0.0002,-0.00020,5.000
5,133.600,-0.01,-0.0002,-0.00020,5.000
5,133.800,-0.01,-0.0002,-0.00020,5.000
5,134.000,-0.01,-0.0002,-0.00020,5.000
5,134.200,-0.01,-0.0002,-0.00020,5.000
5,134.400,0.00,-0.0002,-0.00020,5.000
5,134.600,0.00,-0.0002,-0.00020,5.000
5,134.800,0.00,-0.0002,-0.00020,5.000
5,135.000,-0.01,-0.0002,-0.00020,5.000
5,135.200,-0.01,-0.0002,-0.00020,5.000
5,135.400,0.00,-0.0002,-0.00020,5.000
5,135.600,0.00,-0.0002,-0.00020,5.000
5,135.800,-0.01,-0.0001,-0.00010,5.000
5,136.000,0.00,-0.0001,-0.00010,5.000
5,136.200,-0.01,-0.0001,-0.00010,5.000
6,136.500,0.01,0.0130,0.01310,6.000
6,136.700,0.01,0.1131,0.11320,6.000
6,136.900,0.00,0.2131,0.21320,6.000
6,137.100,0.00,0.3132,0.31330,6.000
6,137.300,0.00,0.4132,0.41330,6.000
6,137.500,0.01,0.5133,0.51340,6.000
6,137.700,0.00,0.6131,0.61320,6.000
6,137.900,0.00,0.7133,0.71340,6.000
6,138.100,0.00,0.8131,0.81320,6.000
6,138.300,0.00,0.9133,0.91340,6.000
6,138.500,0.01,1.0133,1.01340,6.000
6,138.700,0.00,1.1133,1.11340,6.000
6,138.900,0.00,1.2133,1.21340,6.000
6,139.100,0.00,1.3133,1.31340,6.000
6,139.300,0.00,1.4132,1.41330,6.000
6,139.500,0.00,1.5134,1.51350,6.000
6,139.700,0.00,1.6133,1.61340,6.000
6,139.900,0.00,1.7135,1.71360,6.000
6,140.100,0.01,1.8133,1.81340,6.000
6,140.300,0.00,1.9134,1.91350,6.000
6,140.500,0.00,2.0133,2.01340,6.000
6,140.700,0.00,2.1134,2.11350,6.000
6,140.900,0.00,2.2134,2.21350,6.000
6,141.100,0.02,2.3134,2.31350,6.000
6,141.300,0.06,2.4132,2.41330,6.000
6,141.500,0.15,2.5134,2.51350,6.000
6,141.700,0.31,2.6134,2.61350,6.000
6,141.900,0.54,2.7135,2.71360,6.000
6,142.100,0.85,2.8133,2.81340,6.000
6,142.300,1.22,2.9135,2.91360,6.000
6,142.500,1.69,3.0133,3.01340,6.000
6,142.700,2.22,3.1135,3.11360,6.000
6,142.900,2.83,3.2134,3.21350,6.000
6,143.100,3.52,3.3133,3.31340,6.000
6,143.300,4.30,3.4132,3.41330,6.000
6,143.500,5.17,3.5135,3.51360,6.000
6,143.700,6.15,3.6134,3.61350,6.000
6,143.900,7.31,3.7135,3.71360,6.000
6,144.100,8.60,3.8134,3.81350,6.000
6,144.300,10.02,3.9136,3.91370,6.000
6,144.500,11.58,4.0134,4.01350,6.000
6,144.700,13.31,4.1132,4.11330,6.000
6,144.900,15.19,4.2134,4.21350,6.000
6,145.100,17.24,4.3134,4.31350,6.000
6,145.300,19.49,4.4133,4.41340,6.000
6,145.500,22.00,4.5134,4.51350,6.000
6,145.700,24.80,4.6134,4.61350,6.000
6,145.900,27.89,4.7135,4.71360,6.000
6,146.100,31.25,4.8133,4.81340,6.000
6,146.300,34.98,4.9134,4.91350,6.000
6,146.500,39.13,5.0133,5.01340,6.000
6,146.700,43.79,5.1136,5.11370,6.000
6,146.900,49.16,5.2135,5.21360,6.000
6,147.110,44.72,5.1816,5.18170,6.000
6,147.310,36.78,5.0818,5.08190,6.000
6,147.510,30.76,4.9816,4.98170,6.000
6,147.710,25.94,4.8817,4.88180,6.000
6,147.910,21.98,4.7814,4.78150,6.000
6,148.110,18.71,4.6817,4.68180,6.000
6,148.310,15.97,4.5815,4.58160,6.000
6,148.510,13.66,4.4816,4.48170,6.000
6,148.710,11.70,4.3814,4.38150,6.000
6,148.910,10.06,4.2816,4.28170,6.000
6,149.110,8.65,4.1813,4.18140,6.000
6,149.310,7.45,4.0813,4.08140,6.000
6,149.510,6.41,3.9816,3.98170,6.000
6,149.710,5.47,3.8816,3.88170,6.000
6,149.910,4.69,3.7814,3.78150,6.000
6,150.110,4.00,3.6815,3.68160,6.000
6,150.310,3.37,3.5813,3.58140,6.000
6,150.510,2.81,3.4813,3.48140,6.000
6,150.710,2.31,3.3812,3.38130,6.000
6,150.910,1.86,3.2814,3.28150,6.000
6,151.110,1.47,3.1813,3.18140,6.000
6,151.310,1.13,3.0814,3.08150,6.000
6,151.510,0.83,2.9813,2.98140,6.000
6,151.710,0.58,2.8813,2.88140,6.000
6,151.910,0.37,2.7811,2.78120,6.000
6,152.110,0.21,2.6814,2.68150,6.000
6,152.310,0.10,2.5811,2.58120,6.000
6,152.510,0.04,2.4814,2.48150,6.000
6,152.710,0.02,2.3811,2.38120,6.000
6,152.910,0.00,2.2814,2.28150,6.000
6,153.110,0.01,2.1812,2.18130,6.000
6,153.310,0.00,2.0813,2.08140,6.000
6,153.510,0.01,1.9811,1.98120,6.000
6,153.710,0.00,1.8814,1.88150,6.000
6,153.910,0.00,1.7812,1.78130,6.000
6,154.110,0.01,1.6812,1.68130,6.000
6,154.310,0.00,1.5811,1.58120,6.000
6,154.510,0.01,1.4813,1.48140,6.000
6,154.710,0.00,1.3812,1.38130,6.000
6,154.910,0.00,1.2812,1.28130,6.000
6,155.110,0.00,1.1810,1.18110,6.000
6,155.310,0.00,1.0813,1.08140,6.000
6,155.510,0.00,0.9811,0.98120,6.000
6,155.710,0.01,0.8812,0.88130,6.000
6,155.910,0.00,0.7810,0.78110,6.000
6,156.110,0.00,0.6812,0.68130,6.000
6,156.310,0.01,0.5811,0.58120,6.000
6,156.510,0.00,0.4812,0.48130,6.000
6,156.710,0.00,0.3811,0.38120,6.000
6,156.910,0.00,0.2811,0.28120,6.000
6,157.110,0.01,0.1811,0.18120,6.000
6,157.310,0.01,0.0811,0.08120,6.000
6,157.520,0.00,-0.0202,-0.02010,6.000
6,157.720,0.00,-0.0003,-0.00020,6.000
6,157.920,0.00,-0.0003,-0.00020,6.000
6,158.120,0.00,-0.0003,-0.00020,6.000
6,158.320,0.00,-0.0003,-0.00020,6.000
6,158.520,0.00,-0.0003,-0.00020,6.000
6,158.720,0.00,-0.0003,-0.00020,6.000
6,158.920,0.01,-0.0003,-0.00020,6.000
6,159.120,0.01,-0.0003,-0.00020,6.000
6,159.320,0.00,-0.0003,-0.00020,6.000
6,159.520,0.00,-0.0003,-0.00020,6.000
6,159.720,0.01,-0.0003,-0.00020,6.000
6,159.920,0.00,-0.0003,-0.00020,6.000
6,160.120,0.00,-0.0002,-0.00010,6.000
6,160.320,0.00,-0.0002,-0.00010,6.000
6,160.520,0.00,-0.0002,-0.00010,6.000
6,160.740,0.01,-0.0002,-0.00010,6.000
6,160.940,0.01,-0.0002,-0.00010,6.000
6,161.140,0.01,-0.0002,-0.00010,6.000
6,161.340,0.00,-0.0002,-0.00010,6.000
6,161.540,0.00,-0.0002,-0.00010,6.000
6,161.740,0.01,-0.0002,-0.00010,6.000
6,161.940,0.00,-0.0002,-0.00010,6.000
6,162.140,0.01,-0.0002,-0.00010,6.000
6,162.340,0.00,-0.0002,-0.00010,6.000
6,162.540,0.01,-0.0002,-0.00010,6.000
6,162.740,0.00,-0.0002,-0.00010,6.000
6,162.940,0.00,-0.0002,-0.00010,6.000
6,163.140,0.00,-0.0001,0.00000,6.000
6,163.340,0.01,-0.0001,0.00000,6.000
6,163.540,0.00,-0.0001,0.00000,6.000
7,163.840,0.00,0.0481,0.04820,7.000
7,164.040,0.00,0.1482,0.14830,7.000
7,164.240,0.01,0.2480,0.24810,7.000
7,164.440,0.00,0.3482,0.34830,7.000
7,164.640,0.00,0.4482,0.44830,7.000
7,164.840,0.00,0.5482,0.54830,7.000
7,165.040,0.00,0.6481,0.64820,7.000
7,165.240,0.00,0.7482,0.74830,7.000
7,165.440,0.01,0.8481,0.84820,7.000
7,165.640,0.00,0.9482,0.94830,7.000
7,165.840,0.00,1.0483,1.04840,7.000
7,166.040,0.00,1.1482,1.14830,7.000
7,166.240,0.01,1.2481,1.24820,7.000
7,166.440,0.01,1.3483,1.34840,7.000
7,166.640,0.01,1.4482,1.44830,7.000
7,166.840,0.00,1.5483,1.54840,7.000
7,167.040,0.00,1.6483,1.64840,7.000
7,167.240,0.00,1.7482,1.74830,7.000
7,167.440,0.00,1.8484,1.84850,7.000
7,167.640,0.01,1.9483,1.94840,7.000
7,167.840,0.00,2.0483,2.04840,7.000
7,168.040,0.00,2.1483,2.14840,7.000
7,168.240,0.01,2.2484,2.24850,7.000
7,168.440,0.03,2.3484,2.34850,7.000
7,168.640,0.09,2.4484,2.44850,7.000
7,168.840,0.19,2.5484,2.54850,7.000
7,169.040,0.38,2.6484,2.64850,7.000
7,169.240,0.63,2.7482,2.74830,7.000
7,169.440,0.96,2.8484,2.84850,7.000
7,169.640,1.37,2.9484,2.94850,7.000
7,169.840,1.85,3.0483,3.04840,7.000
7,170.040,2.40,3.1485,3.14860,7.000
7,170.240,3.04,3.2484,3.24850,7.000
7,170.440,3.76,3.3482,3.34830,7.000
7,170.640,4.57,3.4483,3.44840,7.000
7,170.840,5.48,3.5484,3.54850,7.000
7,171.040,6.52,3.6484,3.64850,7.000
7,171.240,7.72,3.7484,3.74850,7.000
7,171.440,9.06,3.8485,3.84860,7.000
7,171.640,10.52,3.9486,3.94870,7.000
7,171.840,12.15,4.0484,4.04850,7.000
7,172.040,13.92,4.1483,4.14840,7.000
7,172.240,15.86,4.2484,4.24850,7.000
7,172.440,17.98,4.3484,4.34850,7.000
7,172.640,20.30,4.4483,4.44840,7.000
7,172.840,22.91,4.5483,4.54840,7.000
7,173.040,25.81,4.6483,4.64840,7.000
7,173.240,28.97,4.7484,4.74850,7.000
7,173.440,32.45,4.8484,4.84850,7.000
7,173.640,36.30,4.9485,4.94860,7.000
7,173.840,40.62,5.0485,5.04860,7.000
7,174.040,45.46,5.1485,5.14860,7.000
7,174.260,51.65,5.2499,5.25000,7.000
7,174.460,41.82,5.1521,5.15220,7.000
7,174.660,34.64,5.0522,5.05230,7.000
7,174.860,29.07,4.9522,4.95230,7.000
7,175.060,24.56,4.8522,4.85230,7.000
7,175.260,20.84,4.7521,4.75220,7.000
7,175.460,17.75,4.6521,4.65220,7.000
7,175.660,15.17,4.5521,4.55220,7.000
7,175.860,12.98,4.4519,4.45200,7.000
7,176.060,11.13,4.3521,4.35220,7.000
7,176.260,9.56,4.2521,4.25220,7.000
7,176.460,8.23,4.1519,4.15200,7.000
7,176.660,7.09,4.0518,4.05190,7.000
7,176.860,6.09,3.9523,3.95240,7.000
7,177.060,5.19,3.8520,3.85210,7.000
7,177.260,4.45,3.7520,3.75210,7.000
7,177.460,3.78,3.6518,3.65190,7.000
7,177.660,3.18,3.5520,3.55210,7.000
7,177.860,2.64,3.4518,3.45190,7.000
7,178.060,2.16,3.3518,3.35190,7.000
7,178.260,1.72,3.2518,3.25190,7.000
7,178.460,1.35,3.1518,3.15190,7.000
7,178.660,1.02,3.0518,3.05190,7.000
7,178.860,0.74,2.9519,2.95200,7.000
7,179.060,0.50,2.8516,2.85170,7.000
7,179.260,0.31,2.7518,2.75190,7.000
7,179.460,0.16,2.6516,2.65170,7.000
7,179.660,0.07,2.5518,2.55190,7.000
7,179.860,0.02,2.4517,2.45180,7.000
7,180.060,0.01,2.3518,2.35190,7.000
7,180.260,-0.01,2.2518,2.25190,7.000
7,180.460,0.00,2.1518,2.15190,7.000
7,180.660,0.01,2.0516,2.05170,7.000
7,180.860,0.00,1.9518,1.95190,7.000
7,181.060,0.00,1.8517,1.85180,7.000
7,181.260,0.01,1.7518,1.75190,7.000
7,181.460,0.00,1.6516,1.65170,7.000
7,181.660,-0.01,1.5517,1.55180,7.000
7,181.860,0.00,1.4516,1.45170,7.000
7,182.060,0.01,1.3517,1.35180,7.000
7,182.260,0.00,1.2515,1.25160,7.000
7,182.460,0.01,1.1516,1.15170,7.000
7,182.660,0.00,1.0517,1.05180,7.000
7,182.860,0.00,0.9518,0.95190,7.000
7,183.060,0.00,0.8515,0.85160,7.000
7,183.260,0.00,0.7517,0.75180,7.000
7,183.460,0.00,0.6516,0.65170,7.000
7,183.660,0.00,0.5517,0.55180,7.000
7,183.860,0.00,0.4516,0.45170,7.000
7,184.060,0.00,0.3517,0.35180,7.000
7,184.260,0.00,0.2515,0.25160,7.000
7,184.460,0.00,0.1518,0.15190,7.000
7,184.660,0.00,0.0514,0.05150,7.000
7,184.880,0.00,0.0007,0.00080,7.000
7,185.080,0.00,-0.0003,-0.00020,7.000
7,185.280,0.00,-0.0003,-0.00020,7.000
7,185.480,0.00,-0.0003,-0.00020,7.000
7,185.680,0.00,-0.0003,-0.00020,7.000
7,185.880,0.00,-0.0003,-0.00020,7.000
7,186.080,0.00,-0.0003,-0.00020,7.000
7,186.280,0.00,-0.0003,-0.00020,7.000
7,186.480,0.00,-0.0003,-0.00020,7.000
7,186.680,0.00,-0.0003,-0.00020,7.000
7,186.880,0.00,-0.0003,-0.00020,7.000
7,187.080,0.00,-0.0002,-0.00010,7.000
7,187.280,0.00,-0.0002,-0.00010,7.000
7,187.480,0.00,-0.0002,-0.00010,7.000
7,187.680,0.00,-0.0002,-0.00010,7.000
7,187.900,0.00,-0.0002,-0.00010,7.000
7,188.100,0.00,-0.0002,-0.00010,7.000
7,188.300,0.00,-0.0002,-0.00010,7.000
7,188.500,0.00,-0.0002,-0.00010,7.000
7,188.700,0.00,-0.0002,-0.00010,7.000
7,188.900,0.00,-0.0002,-0.00010,7.000
7,189.100,0.00,-0.0002,-0.00010,7.000
7,189.300,0.00,-0.0002,-0.00010,7.000
7,189.500,0.01,-0.0002,-0.00010,7.000
7,189.700,0.00,-0.0002,-0.00010,7.000
7,189.900,0.00,-0.0002,-0.00010,7.000
7,190.100,0.00,-0.0001,0.00000,7.000
7,190.300,0.00,-0.0001,0.00000,7.000
7,190.500,0.01,-0.0001,0.00000,7.000
7,190.700,0.00,-0.0001,0.00000,7.000
8,191.000,-0.01,0.0000,0.00010,8.000
8,191.200,0.00,0.0930,0.09310,8.000
8,191.400,-0.01,0.1931,0.19320,8.000
8,191.600,-0.01,0.2930,0.29310,8.000
8,191.800,-0.01,0.3932,0.39330,8.000
8,192.000,-0.01,0.4930,0.49310,8.000
8,192.200,-0.01,0.5933,0.59340,8.000
8,192.400,-0.01,0.6931,0.69320,8.000
8,192.600,-0.01,0.7933,0.79340,8.000
8,192.800,-0.01,0.8932,0.89330,8.000
8,193.000,-0.01,0.9934,0.99350,8.000
8,193.200,-0.01,1.0932,1.09330,8.000
8,193.400,0.00,1.1933,1.19340,8.000
8,193.600,-0.01,1.2933,1.29340,8.000
8,193.800,0.00,1.3933,1.39340,8.000
8,194.000,-0.01,1.4931,1.49320,8.000
8,194.200,0.00,1.5934,1.59350,8.000
8,194.400,0.00,1.6933,1.69340,8.000
8,194.600,0.00,1.7934,1.79350,8.000
8,194.800,-0.01,1.8933,1.89340,8.000
8,195.000,-0.01,1.9934,1.99350,8.000
8,195.200,-0.01,2.0932,2.09330,8.000
8,195.400,-0.01,2.1934,2.19350,8.000
8,195.600,0.01,2.2933,2.29340,8.000
8,195.800,0.04,2.3935,2.39360,8.000
8,196.000,0.12,2.4933,2.49340,8.000
8,196.200,0.25,2.5933,2.59340,8.000
8,196.400,0.47,2.6933,2.69340,8.000
8,196.600,0.76,2.7933,2.79340,8.000
8,196.800,1.12,2.8932,2.89330,8.000
8,197.000,1.55,2.9934,2.99350,8.000
8,197.200,2.07,3.0933,3.09340,8.000
8,197.400,2.66,3.1934,3.19350,8.000
8,197.600,3.33,3.2934,3.29350,8.000
8,197.800,4.08,3.3933,3.39340,8.000
8,198.000,4.94,3.4933,3.49340,8.000
8,198.200,5.88,3.5935,3.59360,8.000
8,198.400,7.02,3.6934,3.69350,8.000
8,198.600,8.27,3.7934,3.79350,8.000
8,198.800,9.66,3.8936,3.89370,8.000
8,199.000,11.20,3.9936,3.99370,8.000
8,199.200,12.89,4.0932,4.09330,8.000
8,199.400,14.73,4.1933,4.19340,8.000
8,199.600,16.74,4.2934,4.29350,8.000
8,199.800,18.94,4.3933,4.39340,8.000
8,200.000,21.38,4.4933,4.49340,8.000
8,200.200,24.11,4.5934,4.59350,8.000
8,200.400,27.13,4.6933,4.69340,8.000
8,200.600,30.43,4.7934,4.79350,8.000
8,200.800,34.08,4.8934,4.89350,8.000
8,201.000,38.12,4.9935,4.99360,8.000
8,201.200,42.68,5.0935,5.09360,8.000
8,201.400,47.83,5.1935,5.19360,8.000
8,201.620,46.79,5.2062,5.20630,8.000
8,201.820,38.22,5.1061,5.10620,8.000
8,202.020,31.87,5.0062,5.00630,8.000
8,202.220,26.83,4.9060,4.90610,8.000
8,202.420,22.72,4.8061,4.80620,8.000
8,202.620,19.31,4.7059,4.70600,8.000
8,202.820,16.46,4.6061,4.60620,8.000
8,203.020,14.07,4.5059,4.50600,8.000
8,203.220,12.04,4.4060,4.40610,8.000
8,203.420,10.35,4.3060,4.30610,8.000
8,203.620,8.89,4.2060,4.20610,8.000
8,203.820,7.66,4.1057,4.10580,8.000
8,204.020,6.58,4.0061,4.00620,8.000
8,204.220,5.63,3.9061,3.90620,8.000
8,204.420,4.81,3.8060,3.80610,8.000
8,204.620,4.11,3.7058,3.70590,8.000
8,204.820,3.47,3.6060,3.60610,8.000
8,205.020,2.90,3.5058,3.50590,8.000
8,205.220,2.39,3.4059,3.40600,8.000
8,205.420,1.93,3.3057,3.30580,8.000
8,205.620,1.53,3.2058,3.20590,8.000
8,205.820,1.17,3.1058,3.10590,8.000
8,206.020,0.86,3.0059,3.00600,8.000
8,206.220,0.61,2.9057,2.90580,8.000
8,206.420,0.39,2.8057,2.80580,8.000
8,206.620,0.23,2.7056,2.70570,8.000
8,206.820,0.10,2.6058,2.60590,8.000
8,207.020,0.03,2.5056,2.50570,8.000
8,207.220,0.01,2.4058,2.40590,8.000
8,207.420,-0.01,2.3058,2.30590,8.000
8,207.620,-0.01,2.2058,2.20590,8.000
8,207.820,0.00,2.1057,2.10580,8.000
8,208.020,-0.01,2.0058,2.00590,8.000
8,208.220,0.00,1.9057,1.90580,8.000
8,208.420,-0.01,1.8057,1.80580,8.000
8,208.620,-0.01,1.7056,1.70570,8.000
8,208.820,0.00,1.6057,1.60580,8.000
8,209.020,-0.01,1.5057,1.50580,8.000
8,209.220,0.00,1.4056,1.40570,8.000
8,209.420,0.00,1.3057,1.30580,8.000
8,209.620,0.00,1.2057,1.20580,8.000
8,209.820,-0.01,1.1057,1.10580,8.000
8,210.020,-0.01,1.0057,1.00580,8.000
8,210.220,-0.01,0.9056,0.90570,8.000
8,210.420,-0.01,0.8057,0.80580,8.000
8,210.620,-0.01,0.7056,0.70570,8.000
8,210.820,-0.01,0.6057,0.60580,8.000
8,211.020,-0.01,0.5057,0.50580,8.000
8,211.220,-0.01,0.4056,0.40570,8.000
8,211.420,-0.01,0.3056,0.30570,8.000
8,211.620,-0.01,0.2055,0.20560,8.000
8,211.820,-0.01,0.1056,0.10570,8.000
8,212.020,0.00,0.0055,0.00560,8.000
8,212.240,-0.01,-0.0003,-0.00020,8.000
8,212.440,0.00,-0.0003,-0.00020,8.000
8,212.640,0.00,-0.0003,-0.00020,8.000
8,212.840,-0.01,-0.0003,-0.00020,8.000
8,213.040,0.00,-0.0003,-0.00020,8.000
8,213.240,-0.01,-0.0003,-0.00020,8.000
8,213.440,-0.01,-0.0003,-0.00020,8.000
8,213.640,-0.01,-0.0003,-0.00020,8.000
8,213.840,-0.01,-0.0003,-0.00020,8.000
8,214.040,-0.01,-0.0003,-0.00020,8.000
8,214.240,0.00,-0.0003,-0.00020,8.000
8,214.440,0.00,-0.0002,-0.00010,8.000
8,214.640,-0.01,-0.0002,-0.00010,8.000
8,214.840,-0.01,-0.0002,-0.00010,8.000
8,215.040,-0.01,-0.0002,-0.00010,8.000
8,215.260,-0.01,-0.0002,-0.00010,8.000
8,215.460,0.00,-0.0002,-0.00010,8.000
8,215.660,-0.01,-0.0002,-0.00010,8.000
8,215.860,-0.01,-0.0002,-0.00010,8.000
8,216.060,-0.01,-0.0002,-0.00010,8.000
8,216.260,0.00,-0.0002,-0.00010,8.000
8,216.460,0.00,-0.0002,-0.00010,8.000
8,216.660,-0.01,-0.0002,-0.00010,8.000
8,216.860,0.00,-0.0002,-0.00010,8.000
8,217.060,-0.01,-0.0002,-0.00010,8.000
8,217.260,-0.01,-0.0001,0.00000,8.000
8,217.460,-0.01,-0.0001,0.00000,8.000
8,217.660,-0.01,-0.0001,0.00000,8.000
8,217.860,0.00,-0.0001,0.00000,8.000
8,218.060,-0.01,-0.0001,0.00000,8.000
9,218.360,0.00,0.0282,0.02820,9.000
9,218.560,0.00,0.1280,0.12800,9.000
9,218.760,0.00,0.2280,0.22800,9.000
9,218.960,0.00,0.3280,0.32800,9.000
9,219.160,0.00,0.4282,0.42820,9.000
9,219.360,0.00,0.5282,0.52820,9.000
9,219.560,0.00,0.6283,0.62830,9.000
9,219.760,0.00,0.7282,0.72820,9.000
9,219.960,0.00,0.8281,0.82810,9.000
9,220.160,0.00,0.9282,0.92820,9.000
9,220.360,0.00,1.0283,1.02830,9.000
9,220.560,0.00,1.1282,1.12820,9.000
9,220.760,0.00,1.2283,1.22830,9.000
9,220.960,-0.01,1.3283,1.32830,9.000
9,221.160,0.00,1.4281,1.42810,9.000
9,221.360,0.00,1.5283,1.52830,9.000
9,221.560,0.01,1.6283,1.62830,9.000
9,221.760,0.00,1.7283,1.72830,9.000
9,221.960,0.00,1.8284,1.82840,9.000
9,222.160,0.00,1.9284,1.92840,9.000
9,222.360,0.00,2.0283,2.02830,9.000
9,222.560,0.00,2.1283,2.12830,9.000
9,222.760,0.00,2.2283,2.22830,9.000
9,222.960,0.02,2.3283,2.32830,9.000
9,223.160,0.06,2.4284,2.42840,9.000
9,223.360,0.16,2.5283,2.52830,9.000
9,223.560,0.33,2.6284,2.62840,9.000
9,223.760,0.57,2.7284,2.72840,9.000
9,223.960,0.88,2.8282,2.82820,9.000
9,224.160,1.26,2.9284,2.92840,9.000
9,224.360,1.73,3.0283,3.02830,9.000
9,224.560,2.27,3.1285,3.12850,9.000
9,224.760,2.89,3.2284,3.22840,9.000
9,224.960,3.60,3.3283,3.32830,9.000
9,225.160,4.39,3.4283,3.42830,9.000
9,225.360,5.27,3.5284,3.52840,9.000
9,225.560,6.27,3.6283,3.62830,9.000
9,225.760,7.46,3.7284,3.72840,9.000
9,225.960,8.75,3.8284,3.82840,9.000
9,226.160,10.19,3.9287,3.92870,9.000
9,226.360,11.78,4.0285,4.02850,9.000
9,226.560,13.53,4.1283,4.12830,9.000
9,226.760,15.43,4.2283,4.22830,9.000
9,226.960,17.51,4.3285,4.32850,9.000
9,227.160,19.78,4.4284,4.42840,9.000
9,227.360,22.34,4.5284,4.52840,9.000
9,227.560,25.16,4.6284,4.62840,9.000
9,227.760,28.29,4.7284,4.72840,9.000
9,227.960,31.69,4.8283,4.82830,9.000
9,228.160,35.49,4.9284,4.92840,9.000
9,228.360,39.67,5.0284,5.02840,9.000
9,228.560,44.42,5.1285,5.12850,9.000
9,228.760,49.84,5.2284,5.22840,9.000
9,228.980,43.36,5.1712,5.17120,9.000
9,229.180,35.76,5.0711,5.07110,9.000
9,229.380,29.94,4.9711,4.97110,9.000
9,229.580,25.27,4.8711,4.87110,9.000
9,229.780,21.43,4.7711,4.77110,9.000
9,229.980,18.23,4.6711,4.67110,9.000
9,230.180,15.56,4.5711,4.57110,9.000
9,230.380,13.30,4.4710,4.47100,9.000
9,230.580,11.38,4.3710,4.37100,9.000
9,230.780,9.77,4.2710,4.27100,9.000
9,230.980,8.39,4.1709,4.17090,9.000
9,231.180,7.22,4.0707,4.07070,9.000
9,231.380,6.18,3.9711,3.97110,9.000
9,231.580,5.28,3.8711,3.87110,9.000
9,231.780,4.52,3.7709,3.77090,9.000
9,231.980,3.86,3.6709,3.67090,9.000
9,232.180,3.27,3.5709,3.57090,9.000
9,232.380,2.74,3.4708,3.47080,9.000
9,232.580,2.28,3.3708,3.37080,9.000
9,232.780,1.86,3.2709,3.27090,9.000
9,232.980,1.48,3.1709,3.17090,9.000
9,233.180,1.14,3.0709,3.07090,9.000
9,233.380,0.84,2.9708,2.97080,9.000
9,233.580,0.60,2.8707,2.87070,9.000
9,233.780,0.38,2.7707,2.77070,9.000
9,233.980,0.22,2.6707,2.67070,9.000
9,234.180,0.11,2.5707,2.57070,9.000
9,234.380,0.04,2.4707,2.47070,9.000
9,234.580,0.01,2.3708,2.37080,9.000
9,234.780,0.00,2.2709,2.27090,9.000
9,234.980,0.00,2.1708,2.17080,9.000
9,235.180,0.00,2.0706,2.07060,9.000
9,235.380,0.00,1.9706,1.97060,9.000
9,235.580,0.00,1.8707,1.87070,9.000
9,235.780,0.00,1.7707,1.77070,9.000
9,235.980,0.00,1.6707,1.67070,9.000
9,236.180,0.00,1.5706,1.57060,9.000
9,236.380,0.00,1.4707,1.47070,9.000
9,236.580,0.00,1.3706,1.37060,9.000
9,236.780,0.00,1.2707,1.27070,9.000
9,236.980,0.00,1.1706,1.17060,9.000
9,237.180,0.00,1.0707,1.07070,9.000
9,237.380,0.00,0.9706,0.97060,9.000
9,237.580,-0.01,0.8706,0.87060,9.000
9,237.780,0.00,0.7706,0.77060,9.000
9,237.980,0.00,0.6707,0.67070,9.000
9,238.180,0.00,0.5706,0.57060,9.000
9,238.380,0.00,0.4708,0.47080,9.000
9,238.580,-0.01,0.3707,0.37070,9.000
9,238.780,0.00,0.2706,0.27060,9.000
9,238.980,0.00,0.1706,0.17060,9.000
9,239.180,0.00,0.0707,0.07070,9.000
9,239.400,0.00,-0.0194,-0.01940,9.000
9,239.600,0.00,-0.0003,-0.00030,9.000
9,239.800,0.00,-0.0003,-0.00030,9.000
9,240.000,0.00,-0.0003,-0.00030,9.000
9,240.200,0.00,-0.0003,-0.00030,9.000
9,240.400,0.00,-0.0003,-0.00030,9.000
9,240.600,0.00,-0.0003,-0.00030,9.000
9,240.800,0.00,-0.0003,-0.00030,9.000
9,241.000,0.00,-0.0003,-0.00030,9.000
9,241.200,0.00,-0.0003,-0.00030,9.000
9,241.400,0.00,-0.0002,-0.00020,9.000
9,241.600,0.00,-0.0002,-0.00020,9.000
9,241.800,-0.01,-0.0002,-0.00020,9.000
9,242.000,0.00,-0.0002,-0.00020,9.000
9,242.200,0.00,-0.0002,-0.00020,9.000
9,242.400,0.00,-0.0002,-0.00020,9.000
9,242.620,-0.01,-0.0002,-0.00020,9.000
9,242.820,0.01,-0.0002,-0.00020,9.000
9,243.020,0.00,-0.0002,-0.00020,9.000
9,243.220,0.00,-0.0002,-0.00020,9.000
9,243.420,0.00,-0.0002,-0.00020,9.000
9,243.620,0.00,-0.0002,-0.00020,9.000
9,243.820,0.00,-0.0002,-0.00020,9.000
9,244.020,0.00,-0.0002,-0.00020,9.000
9,244.220,0.00,-0.0002,-0.00020,9.000
9,244.420,0.00,-0.0001,-0.00010,9.000
9,244.620,0.00,-0.0001,-0.00010,9.000
9,244.820,0.00,-0.0001,-0.00010,9.000
9,245.020,0.00,-0.0001,-0.00010,9.000
9,245.220,0.00,-0.0001,-0.00010,9.000
9,245.420,0.00,-0.0001,-0.00010,9.000
10,245.720,0.00,0.0630,0.06300,10.000
10,245.920,0.01,0.1631,0.16310,10.000
10,246.120,0.00,0.2632,0.26320,10.000
10,246.320,0.00,0.3632,0.36320,10.000
10,246.520,0.01,0.4631,0.46310,10.000
10,246.720,0.00,0.5632,0.56320,10.000
10,246.920,0.01,0.6632,0.66320,10.000
10,247.120,0.00,0.7631,0.76310,10.000
10,247.320,0.00,0.8632,0.86320,10.000
10,247.520,0.01,0.9632,0.96320,10.000
10,247.720,0.01,1.0632,1.06320,10.000
10,247.920,0.00,1.1633,1.16330,10.000
10,248.120,0.01,1.2632,1.26320,10.000
10,248.320,0.01,1.3633,1.36330,10.000
10,248.520,0.00,1.4632,1.46320,10.000
10,248.720,0.00,1.5633,1.56330,10.000
10,248.920,0.01,1.6632,1.66320,10.000
10,249.120,0.00,1.7633,1.76330,10.000
10,249.320,0.01,1.8632,1.86320,10.000
10,249.520,0.01,1.9633,1.96330,10.000
10,249.720,0.00,2.0633,2.06330,10.000
10,249.920,0.00,2.1634,2.16340,10.000
10,250.120,0.01,2.2634,2.26340,10.000
10,250.320,0.04,2.3635,2.36350,10.000
10,250.520,0.10,2.4633,2.46330,10.000
10,250.720,0.23,2.5633,2.56330,10.000
10,250.920,0.42,2.6632,2.66320,10.000
10,251.120,0.69,2.7633,2.76330,10.000
10,251.320,1.04,2.8633,2.86330,10.000
10,251.520,1.46,2.9634,2.96340,10.000
10,251.720,1.96,3.0633,3.06330,10.000
10,251.920,2.52,3.1635,3.16350,10.000
10,252.120,3.18,3.2632,3.26320,10.000
10,252.320,3.93,3.3634,3.36340,10.000
10,252.520,4.76,3.4634,3.46340,10.000
10,252.720,5.67,3.5635,3.56350,10.000
10,252.920,6.74,3.6633,3.66330,10.000
10,253.120,7.95,3.7635,3.76350,10.000
10,253.320,9.30,3.8635,3.86350,10.000
10,253.520,10.79,3.9636,3.96360,10.000
10,253.720,12.43,4.0632,4.06320,10.000
10,253.920,14.25,4.1634,4.16340,10.000
10,254.120,16.22,4.2635,4.26350,10.000
10,254.320,18.38,4.3634,4.36340,10.000
10,254.520,20.73,4.4633,4.46330,10.000
10,254.720,23.38,4.5635,4.56350,10.000
10,254.920,26.32,4.6633,4.66330,10.000
10,255.120,29.53,4.7635,4.76350,10.000
10,255.320,33.02,4.8633,4.86330,10.000
10,255.520,36.96,4.9635,4.96350,10.000
10,255.720,41.34,5.0635,5.06350,10.000
10,255.920,46.31,5.1636,5.16360,10.000
10,256.140,50.52,5.2364,5.23640,10.000
10,256.340,40.53,5.1365,5.13650,10.000
10,256.540,33.65,5.0368,5.03680,10.000
10,256.740,28.24,4.9366,4.93660,10.000
10,256.940,23.90,4.8366,4.83660,10.000
10,257.140,20.30,4.7365,4.73650,10.000
10,257.340,17.30,4.6366,4.63660,10.000
10,257.540,14.77,4.5364,4.53640,10.000
10,257.740,12.63,4.4366,4.43660,10.000
10,257.940,10.83,4.3366,4.33660,10.000
10,258.140,9.30,4.2365,4.23650,10.000
10,258.340,7.99,4.1363,4.13630,10.000
10,258.540,6.87,4.0365,4.03650,10.000
10,258.740,5.87,3.9367,3.93670,10.000
10,258.940,5.01,3.8364,3.83640,10.000
10,259.140,4.31,3.7364,3.73640,10.000
10,259.340,3.68,3.6364,3.63640,10.000
10,259.540,3.09,3.5363,3.53630,10.000
10,259.740,2.60,3.4365,3.43650,10.000
10,259.940,2.13,3.3363,3.33630,10.000
10,260.140,1.72,3.2365,3.23650,10.000
10,260.340,1.36,3.1364,3.13640,10.000
10,260.540,1.03,3.0364,3.03640,10.000
10,260.740,0.75,2.9363,2.93630,10.000
10,260.940,0.52,2.8364,2.83640,10.000
10,261.140,0.33,2.7362,2.73620,10.000
10,261.340,0.18,2.6364,2.63640,10.000
10,261.540,0.08,2.5362,2.53620,10.000
10,261.740,0.03,2.4362,2.43620,10.000
10,261.940,0.01,2.3362,2.33620,10.000
10,262.140,0.00,2.2363,2.23630,10.000
10,262.340,0.00,2.1361,2.13610,10.000
10,262.540,0.01,2.0362,2.03620,10.000
10,262.740,0.00,1.9361,1.93610,10.000
10,262.940,0.00,1.8363,1.83630,10.000
10,263.140,0.01,1.7362,1.73620,10.000
10,263.340,0.00,1.6363,1.63630,10.000
10,263.540,0.00,1.5360,1.53600,10.000
10,263.740,0.00,1.4361,1.43610,10.000
10,263.940,0.00,1.3361,1.33610,10.000
10,264.140,0.00,1.2362,1.23620,10.000
10,264.340,0.00,1.1360,1.13600,10.000
10,264.540,0.00,1.0363,1.03630,10.000
10,264.740,0.00,0.9361,0.93610,10.000
10,264.940,0.01,0.8361,0.83610,10.000
10,265.140,0.01,0.7362,0.73620,10.000
10,265.340,0.00,0.6361,0.63610,10.000
10,265.540,0.01,0.5361,0.53610,10.000
10,265.740,0.01,0.4363,0.43630,10.000
10,265.940,0.00,0.3361,0.33610,10.000
10,266.140,0.01,0.2362,0.23620,10.000
10,266.340,0.00,0.1361,0.13610,10.000
10,266.540,0.01,0.0361,0.03610,10.000
10,266.760,0.00,-0.0002,-0.00020,10.000
10,266.960,0.00,-0.0003,-0.00030,10.000
10,267.160,0.01,-0.0002,-0.00020,10.000
10,267.360,0.01,-0.0002,-0.00020,10.000
10,267.560,0.00,-0.0002,-0.00020,10.000
10,267.760,0.00,-0.0002,-0.00020,10.000
10,267.960,0.00,-0.0002,-0.00020,10.000
10,268.160,0.00,-0.0002,-0.00020,10.000
10,268.360,0.00,-0.0002,-0.00020,10.000
10,268.560,0.00,-0.0002,-0.00020,10.000
10,268.760,0.00,-0.0002,-0.00020,10.000
10,268.960,0.00,-0.0002,-0.00020,10.000
10,269.160,0.00,-0.0002,-0.00020,10.000
10,269.360,0.00,-0.0002,-0.00020,10.000
10,269.560,0.00,-0.0002,-0.00020,10.000
10,269.780,0.01,-0.0002,-0.00020,10.000
10,269.980,0.00,-0.0002,-0.00020,10.000
10,270.180,0.00,-0.0002,-0.00020,10.000
10,270.380,0.00,-0.0002,-0.00020,10.000
10,270.580,0.00,-0.0002,-0.00020,10.000
10,270.780,0.01,-0.0002,-0.00020,10.000
10,270.980,0.00,-0.0002,-0.00020,10.000
10,271.180,0.01,-0.0002,-0.00020,10.000
10,271.380,0.00,-0.0002,-0.00020,10.000
10,271.580,0.00,-0.0002,-0.00020,10.000
10,271.780,0.00,-0.0002,-0.00020,10.000
10,271.980,0.01,-0.0001,-0.00010,10.000
10,272.180,0.01,-0.0001,-0.00010,10.000
10,272.380,0.00,-0.0001,-0.00010,10.000
10,272.580,0.01,-0.0001,-0.00010,10.000
10,272.730,0.01,-0.0001,-0.00010,10.000