File: calibDATA_loadcell/date_30:1:2018/MTSdata_date_1.30/radhen_10cyc_black_2_0deg_1mms_50N.txt
""
"Test Method","Radhen_Load_Cntrl_Cmprsn_250N_12-7.msm"
"Sample I. D.","Sample1.mss"
"Specimen Number","18"

"TheCycle_Output ()","_Time (s)","_Load (N)","_Extension (mm)","RealTimeDepth (mm)","CycleNumber ()"

0,0.160,0.01,0.0000,0.00000,0.000
1,0.320,0.01,0.0973,0.09730,1.000
1,0.470,0.01,0.2474,0.24740,1.000
1,0.620,0.01,0.3975,0.39750,1.000
1,0.770,0.01,0.5473,0.54730,1.000
1,0.920,0.00,0.6974,0.69740,1.000
1,1.070,0.01,0.8476,0.84760,1.000
1,1.220,0.02,0.9975,0.99750,1.000
1,1.370,0.01,1.1473,1.14730,1.000
1,1.520,0.02,1.2975,1.29750,1.000
1,1.670,0.01,1.4476,1.44760,1.000
1,1.820,0.01,1.5976,1.59760,1.000
1,1.970,0.01,1.7474,1.74740,1.000
1,2.120,0.02,1.8975,1.89750,1.000
1,2.270,0.01,2.0476,2.04760,1.000
1,2.420,0.02,2.1977,2.19770,1.000
1,2.570,0.01,2.3475,2.34750,1.000
1,2.720,0.02,2.4977,2.49770,1.000
1,2.870,0.01,2.6476,2.64760,1.000
1,3.020,0.02,2.7976,2.79760,1.000
1,3.170,0.02,2.9475,2.94750,1.000
1,3.320,0.03,3.0978,3.09780,1.000
1,3.470,0.04,3.2477,3.24770,1.000
1,3.620,0.09,3.3977,3.39770,1.000
1,3.770,0.19,3.5476,3.54760,1.000
1,3.920,0.40,3.6977,3.69770,1.000
1,4.070,0.71,3.8477,3.84770,1.000
1,4.220,1.15,3.9977,3.99770,1.000
1,4.370,1.70,4.1477,4.14770,1.000
1,4.520,2.40,4.2977,4.29770,1.000
1,4.670,3.25,4.4477,4.44770,1.000
1,4.820,4.30,4.5978,4.59780,1.000
1,4.970,5.53,4.7478,4.74780,1.000
1,5.120,6.96,4.8977,4.89770,1.000
1,5.270,8.62,5.0478,5.04780,1.000
1,5.420,10.54,5.1977,5.19770,1.000
1,5.570,12.65,5.3480,5.34800,1.000
1,5.720,15.00,5.4979,5.49790,1.000
1,5.870,17.24,5.6478,5.64780,1.000
1,6.020,19.77,5.7977,5.79770,1.000
1,6.170,23.56,5.9477,5.94770,1.000
1,6.320,27.88,6.0978,6.09780,1.000
1,6.470,32.82,6.2478,6.24780,1.000
1,6.620,38.51,6.3976,6.39760,1.000
1,6.770,45.05,6.5480,6.54800,1.000
1,6.940,53.15,6.7004,6.70040,1.000
1,7.090,40.58,6.5728,6.57280,1.000
1,7.240,30.89,6.4225,6.42250,1.000
1,7.390,24.21,6.2725,6.27250,1.000
1,7.540,19.19,6.1225,6.12250,1.000
1,7.690,15.27,5.9726,5.97260,1.000
1,7.840,12.20,5.8226,5.82260,1.000
1,7.990,9.81,5.6724,5.67240,1.000
1,8.140,7.96,5.5225,5.52250,1.000
1,8.290,6.47,5.3728,5.37280,1.000
1,8.440,5.24,5.2227,5.22270,1.000
1,8.590,4.21,5.0724,5.07240,1.000
1,8.740,3.33,4.9224,4.92240,1.000
1,8.890,2.59,4.7726,4.77260,1.000
1,9.040,1.96,4.6226,4.62260,1.000
1,9.190,1.48,4.4722,4.47220,1.000
1,9.340,1.06,4.3224,4.32240,1.000
1,9.490,0.72,4.1725,4.17250,1.000
1,9.640,0.46,4.0225,4.02250,1.000
1,9.790,0.26,3.8723,3.87230,1.000
1,9.940,0.11,3.7224,3.72240,1.000
1,10.090,0.04,3.5725,3.57250,1.000
1,10.240,0.02,3.4225,3.42250,1.000
1,10.390,0.02,3.2723,3.27230,1.000
1,10.540,0.01,3.1224,3.12240,1.000
1,10.690,0.01,2.9724,2.97240,1.000
1,10.840,0.01,2.8224,2.82240,1.000
1,10.990,0.01,2.6722,2.67220,1.000
1,11.140,0.01,2.5223,2.52230,1.000
1,11.290,0.01,2.3724,2.37240,1.000
1,11.440,0.01,2.2223,2.22230,1.000
1,11.590,0.01,2.0724,2.07240,1.000
1,11.740,0.01,1.9223,1.92230,1.000
1,11.890,0.01,1.7722,1.77220,1.000
1,12.040,0.01,1.6223,1.62230,1.000
1,12.190,0.00,1.4721,1.47210,1.000
1,12.340,0.02,1.3222,1.32220,1.000
1,12.490,0.02,1.1723,1.17230,1.000
1,12.640,0.01,1.0223,1.02230,1.000
1,12.790,0.00,0.8722,0.87220,1.000
1,12.940,0.01,0.7224,0.72240,1.000
1,13.090,0.02,0.5722,0.57220,1.000
1,13.240,0.01,0.4221,0.42210,1.000
1,13.390,0.01,0.2720,0.27200,1.000
1,13.540,0.02,0.1223,0.12230,1.000
1,13.700,0.02,-0.0372,-0.03723,1.000
1,13.850,0.03,-0.0002,-0.00020,1.000
1,14.000,0.02,-0.0003,-0.00030,1.000
1,14.150,0.02,-0.0003,-0.00030,1.000
1,14.300,0.02,-0.0003,-0.00030,1.000
1,14.450,0.01,-0.0003,-0.00030,1.000
1,14.600,0.01,-0.0003,-0.00030,1.000
1,14.750,0.01,-0.0003,-0.00030,1.000
1,14.900,0.01,-0.0003,-0.00030,1.000
1,15.050,0.00,-0.0003,-0.00030,1.000
1,15.200,0.02,-0.0003,-0.00030,1.000
1,15.350,0.01,-0.0003,-0.00030,1.000
1,15.500,0.02,-0.0003,-0.00030,1.000
1,15.650,0.01,-0.0003,-0.00030,1.000
1,15.800,0.01,-0.0002,-0.00020,1.000
1,15.950,0.00,-0.0002,-0.00020,1.000
1,16.100,0.02,-0.0002,-0.00020,1.000
1,16.250,0.03,-0.0002,-0.00020,1.000
1,16.400,0.02,-0.0002,-0.00020,1.000
1,16.550,0.02,-0.0002,-0.00020,1.000
1,16.700,0.02,-0.0002,-0.00020,1.000
1,16.860,0.01,-0.0002,-0.00020,1.000
1,17.010,0.01,-0.0002,-0.00020,1.000
1,17.160,0.02,-0.0002,-0.00020,1.000
1,17.310,0.02,-0.0002,-0.00020,1.000
1,17.460,0.00,-0.0002,-0.00020,1.000
1,17.610,0.02,-0.0002,-0.00020,1.000
1,17.760,0.03,-0.0002,-0.00020,1.000
1,17.910,0.01,-0.0002,-0.00020,1.000
1,18.060,0.01,-0.0002,-0.00020,1.000
1,18.210,0.01,-0.0002,-0.00020,1.000
1,18.360,0.02,-0.0002,-0.00020,1.000
1,18.510,0.00,-0.0001,-0.00010,1.000
1,18.660,0.02,-0.0001,-0.00010,1.000
1,18.810,0.01,-0.0001,-0.00010,1.000
1,18.960,0.01,-0.0001,-0.00010,1.000
1,19.110,0.01,-0.0001,-0.00010,1.000
1,19.260,0.01,-0.0001,-0.00010,1.000
1,19.410,0.02,-0.0001,-0.00010,1.000
1,19.560,0.01,-0.0001,-0.00010,1.000
1,19.710,0.02,-0.0001,-0.00010,1.000
2,19.960,-0.01,0.0085,0.00850,2.000
2,20.110,-0.01,0.1566,0.15660,2.000
2,20.260,-0.01,0.3065,0.30650,2.000
2,20.410,-0.01,0.4567,0.45670,2.000
2,20.560,-0.01,0.6065,0.60650,2.000
2,20.710,-0.01,0.7567,0.75670,2.000
2,20.860,0.00,0.9068,0.90680,2.000
2,21.010,-0.01,1.0569,1.05690,2.000
2,21.160,0.00,1.2067,1.20670,2.000
2,21.310,-0.01,1.3567,1.35670,2.000
2,21.460,-0.01,1.5066,1.50660,2.000
2,21.610,0.00,1.6569,1.65690,2.000
2,21.760,-0.01,1.8067,1.80670,2.000
2,21.910,-0.02,1.9566,1.95660,2.000
2,22.060,-0.01,2.1067,2.10670,2.000
2,22.210,-0.01,2.2568,2.25680,2.000
2,22.360,-0.02,2.4067,2.40670,2.000
2,22.510,-0.01,2.5568,2.55680,2.000
2,22.660,-0.01,2.7067,2.70670,2.000
2,22.810,-0.01,2.8568,2.85680,2.000
2,22.960,0.00,3.0069,3.00690,2.000
2,23.110,0.00,3.1567,3.15670,2.000
2,23.260,0.02,3.3069,3.30690,2.000
2,23.410,0.06,3.4568,3.45680,2.000
2,23.560,0.17,3.6069,3.60690,2.000
2,23.710,0.37,3.7568,3.75680,2.000
2,23.860,0.68,3.9069,3.90690,2.000
2,24.010,1.13,4.0569,4.05690,2.000
2,24.160,1.68,4.2068,4.20680,2.000
2,24.310,2.37,4.3566,4.35660,2.000
2,24.460,3.26,4.5069,4.50690,2.000
2,24.610,4.34,4.6570,4.65700,2.000
2,24.760,5.59,4.8069,4.80690,2.000
2,24.910,7.04,4.9567,4.95670,2.000
2,25.060,8.72,5.1068,5.10680,2.000
2,25.210,10.62,5.2570,5.25700,2.000
2,25.360,12.72,5.4070,5.40700,2.000
2,25.510,15.11,5.5567,5.55670,2.000
2,25.660,17.57,5.7069,5.70690,2.000
2,25.810,20.54,5.8568,5.85680,2.000
2,25.960,24.30,6.0068,6.00680,2.000
2,26.110,28.57,6.1568,6.15680,2.000
2,26.260,33.49,6.3068,6.30680,2.000
2,26.410,39.32,6.4569,6.45690,2.000
2,26.560,46.43,6.6069,6.60690,2.000
2,26.720,51.15,6.6918,6.69180,2.000
2,26.870,37.21,6.5418,6.54180,2.000
2,27.020,28.60,6.3915,6.39150,2.000
2,27.170,22.51,6.2415,6.24150,2.000
2,27.320,17.87,6.0917,6.09170,2.000
2,27.470,14.23,5.9417,5.94170,2.000
2,27.620,11.39,5.7916,5.79160,2.000
2,27.770,9.18,5.6413,5.64130,2.000
2,27.920,7.46,5.4917,5.49170,2.000
2,28.070,6.06,5.3418,5.34180,2.000
2,28.220,4.90,5.1915,5.19150,2.000
2,28.370,3.91,5.0414,5.04140,2.000
2,28.520,3.07,4.8915,4.89150,2.000
2,28.670,2.38,4.7416,4.74160,2.000
2,28.820,1.80,4.5914,4.59140,2.000
2,28.970,1.33,4.4413,4.44130,2.000
2,29.120,0.94,4.2915,4.29150,2.000
2,29.270,0.62,4.1415,4.14150,2.000
2,29.420,0.38,3.9914,3.99140,2.000
2,29.570,0.19,3.8414,3.84140,2.000
2,29.720,0.07,3.6915,3.69150,2.000
2,29.870,-0.01,3.5414,3.54140,2.000
2,30.020,-0.01,3.3914,3.39140,2.000
2,30.170,-0.01,3.2413,3.24130,2.000
2,30.320,-0.01,3.0915,3.09150,2.000
2,30.470,-0.01,2.9414,2.94140,2.000
2,30.620,-0.01,2.7912,2.79120,2.000
2,30.770,-0.01,2.6413,2.64130,2.000
2,30.920,-0.01,2.4913,2.49130,2.000
2,31.070,0.00,2.3413,2.34130,2.000
2,31.220,-0.02,2.1912,2.19120,2.000
2,31.370,-0.01,2.0415,2.04150,2.000
2,31.520,-0.01,1.8914,1.89140,2.000
2,31.670,-0.01,1.7413,1.74130,2.000
2,31.820,-0.01,1.5912,1.59120,2.000
2,31.970,-0.02,1.4413,1.44130,2.000
2,32.120,0.00,1.2914,1.29140,2.000
2,32.270,-0.01,1.1412,1.14120,2.000
2,32.420,-0.01,0.9912,0.99120,2.000
2,32.570,-0.01,0.8414,0.84140,2.000
2,32.720,0.00,0.6912,0.69120,2.000
2,32.870,-0.02,0.5411,0.54110,2.000
2,33.020,-0.02,0.3911,0.39110,2.000
2,33.170,-0.02,0.2413,0.24130,2.000
2,33.320,-0.01,0.0912,0.09120,2.000
2,33.480,-0.01,-0.0514,-0.05140,2.000
2,33.630,-0.01,-0.0003,-0.00030,2.000
2,33.780,-0.01,-0.0003,-0.00030,2.000
2,33.930,-0.01,-0.0003,-0.00030,2.000
2,34.080,-0.01,-0.0003,-0.00030,2.000
2,34.230,0.00,-0.0003,-0.00030,2.000
2,34.380,0.00,-0.0003,-0.00030,2.000
2,34.530,-0.01,-0.0003,-0.00030,2.000
2,34.680,-0.01,-0.0003,-0.00030,2.000
2,34.830,-0.01,-0.0003,-0.00030,2.000
2,34.980,-0.01,-0.0003,-0.00030,2.000
2,35.130,-0.02,-0.0003,-0.00030,2.000
2,35.280,-0.01,-0.0003,-0.00030,2.000
2,35.430,-0.02,-0.0003,-0.00030,2.000
2,35.580,-0.01,-0.0003,-0.00030,2.000
2,35.730,-0.01,-0.0003,-0.00030,2.000
2,35.880,-0.01,-0.0002,-0.00020,2.000
2,36.030,0.00,-0.0002,-0.00020,2.000
2,36.180,0.00,-0.0002,-0.00020,2.000
2,36.330,0.00,-0.0002,-0.00020,2.000
2,36.480,-0.01,-0.0002,-0.00020,2.000
2,36.650,-0.01,-0.0002,-0.00020,2.000
2,36.800,0.00,-0.0002,-0.00020,2.000
2,36.950,-0.01,-0.0002,-0.00020,2.000
2,37.100,-0.01,-0.0002,-0.00020,2.000
2,37.250,-0.01,-0.0002,-0.00020,2.000
2,37.400,0.00,-0.0002,-0.00020,2.000
2,37.550,-0.01,-0.0002,-0.00020,2.000
2,37.700,-0.02,-0.0002,-0.00020,2.000
2,37.850,0.00,-0.0002,-0.00020,2.000
2,38.000,-0.01,-0.0002,-0.00020,2.000
2,38.150,-0.01,-0.0002,-0.00020,2.000
2,38.300,0.00,-0.0002,-0.00020,2.000
2,38.450,0.00,-0.0002,-0.00020,2.000
2,38.600,-0.02,-0.0001,-0.00010,2.000
2,38.750,0.00,-0.0001,-0.00010,2.000
2,38.900,-0.03,-0.0001,-0.00010,2.000
2,39.050,-0.01,-0.0001,-0.00010,2.000
2,39.200,-0.01,-0.0001,-0.00010,2.000
2,39.350,-0.01,-0.0001,-0.00010,2.000
2,39.500,0.00,-0.0001,-0.00010,2.000
3,39.750,-0.02,0.0576,0.05760,3.000
3,39.900,-0.02,0.2076,0.20760,3.000
3,40.050,-0.02,0.3577,0.35770,3.000
3,40.200,-0.01,0.5075,0.50750,3.000
3,40.350,-0.01,0.6576,0.65760,3.000
3,40.500,-0.02,0.8078,0.80780,3.000
3,40.650,-0.01,0.9578,0.95780,3.000
3,40.800,-0.01,1.1076,1.10760,3.000
3,40.950,-0.01,1.2578,1.25780,3.000
3,41.100,-0.01,1.4078,1.40780,3.000
3,41.250,-0.01,1.5578,1.55780,3.000
3,41.400,-0.02,1.7076,1.70760,3.000
3,41.550,-0.01,1.8578,1.85780,3.000
3,41.700,-0.02,2.0079,2.00790,3.000
3,41.850,-0.02,2.1578,2.15780,3.000
3,42.000,-0.01,2.3078,2.30780,3.000
3,42.150,-0.03,2.4579,2.45790,3.000
3,42.300,-0.01,2.6078,2.60780,3.000
3,42.450,-0.01,2.7577,2.75770,3.000
3,42.600,-0.01,2.9078,2.90780,3.000
3,42.750,0.00,3.0579,3.05790,3.000
3,42.900,0.01,3.2079,3.20790,3.000
3,43.050,0.02,3.3579,3.35790,3.000
3,43.200,0.08,3.5079,3.50790,3.000
3,43.350,0.22,3.6578,3.65780,3.000
3,43.500,0.43,3.8078,3.80780,3.000
3,43.650,0.78,3.9580,3.95800,3.000
3,43.800,1.25,4.1078,4.10780,3.000
3,43.950,1.84,4.2580,4.25800,3.000
3,44.100,2.57,4.4078,4.40780,3.000
3,44.250,3.49,4.5578,4.55780,3.000
3,44.400,4.63,4.7079,4.70790,3.000
3,44.550,5.93,4.8578,4.85780,3.000
3,44.700,7.43,5.0078,5.00780,3.000
3,44.850,9.17,5.1577,5.15770,3.000
3,45.000,11.13,5.3079,5.30790,3.000
3,45.150,13.29,5.4580,5.45800,3.000
3,45.300,15.75,5.6077,5.60770,3.000
3,45.450,18.30,5.7578,5.75780,3.000
3,45.600,21.59,5.9079,5.90790,3.000
3,45.750,25.45,6.0579,6.05790,3.000
3,45.900,29.87,6.2079,6.20790,3.000
3,46.050,35.01,6.3577,6.35770,3.000
3,46.200,41.15,6.5080,6.50800,3.000
3,46.350,48.72,6.6581,6.65810,3.000
3,46.510,48.54,6.6824,6.68240,3.000
3,46.660,35.62,6.5329,6.53290,3.000
3,46.810,27.53,6.3827,6.38270,3.000
3,46.960,21.71,6.2326,6.23260,3.000
3,47.110,17.25,6.0826,6.08260,3.000
3,47.260,13.75,5.9327,5.93270,3.000
3,47.410,11.02,5.7825,5.78250,3.000
3,47.560,8.91,5.6324,5.63240,3.000
3,47.710,7.26,5.4825,5.48250,3.000
3,47.860,5.90,5.3327,5.33270,3.000
3,48.010,4.77,5.1827,5.18270,3.000
3,48.160,3.81,5.0324,5.03240,3.000
3,48.310,2.99,4.8823,4.88230,3.000
3,48.460,2.31,4.7326,4.73260,3.000
3,48.610,1.75,4.5826,4.58260,3.000
3,48.760,1.28,4.4323,4.43230,3.000
3,48.910,0.91,4.2823,4.28230,3.000
3,49.060,0.59,4.1325,4.13250,3.000
3,49.210,0.34,3.9825,3.98250,3.000
3,49.360,0.17,3.8323,3.83230,3.000
3,49.510,0.06,3.6824,3.68240,3.000
3,49.660,-0.01,3.5324,3.53240,3.000
3,49.810,-0.02,3.3824,3.38240,3.000
3,49.960,-0.01,3.2322,3.23220,3.000
3,50.110,-0.01,3.0824,3.08240,3.000
3,50.260,-0.01,2.9324,2.93240,3.000
3,50.410,-0.03,2.7823,2.78230,3.000
3,50.560,-0.01,2.6322,2.63220,3.000
3,50.710,-0.01,2.4823,2.48230,3.000
3,50.860,-0.01,2.3323,2.33230,3.000
3,51.010,-0.02,2.1824,2.18240,3.000
3,51.160,-0.02,2.0323,2.03230,3.000
3,51.310,-0.01,1.8823,1.88230,3.000
3,51.460,-0.01,1.7323,1.73230,3.000
3,51.610,-0.02,1.5824,1.58240,3.000
3,51.760,-0.02,1.4321,1.43210,3.000
3,51.910,0.00,1.2823,1.28230,3.000
3,52.060,-0.01,1.1323,1.13230,3.000
3,52.210,0.00,0.9822,0.98220,3.000
3,52.360,-0.01,0.8323,0.83230,3.000
3,52.510,-0.02,0.6823,0.68230,3.000
3,52.660,-0.01,0.5323,0.53230,3.000
3,52.810,-0.02,0.3822,0.38220,3.000
3,52.960,-0.03,0.2320,0.23200,3.000
3,53.110,-0.01,0.0823,0.08230,3.000
3,53.280,-0.01,-0.0450,-0.04500,3.000
3,53.430,0.00,-0.0003,-0.00030,3.000
3,53.580,-0.02,-0.0003,-0.00030,3.000
3,53.730,-0.03,-0.0003,-0.00030,3.000
3,53.880,-0.01,-0.0003,-0.00030,3.000
3,54.030,-0.01,-0.0003,-0.00030,3.000
3,54.180,-0.02,-0.0003,-0.00030,3.000
3,54.330,-0.02,-0.0003,-0.00030,3.000
3,54.480,-0.03,-0.0003,-0.00030,3.000
3,54.630,-0.03,-0.0003,-0.00030,3.000
3,54.780,-0.01,-0.0003,-0.00030,3.000
3,54.930,-0.02,-0.0003,-0.00030,3.000
3,55.080,-0.01,-0.0003,-0.00030,3.000
3,55.230,-0.01,-0.0003,-0.00030,3.000
3,55.380,-0.01,-0.0003,-0.00030,3.000
3,55.530,-0.02,-0.0003,-0.00030,3.000
3,55.680,-0.01,-0.0003,-0.00030,3.000
3,55.830,0.00,-0.0002,-0.00020,3.000
3,55.980,-0.01,-0.0002,-0.00020,3.000
3,56.130,-0.01,-0.0002,-0.00020,3.000
3,56.280,0.00,-0.0002,-0.00020,3.000
3,56.450,-0.01,-0.0002,-0.00020,3.000
3,56.600,-0.02,-0.0002,-0.00020,3.000
3,56.750,-0.01,-0.0002,-0.00020,3.000
3,56.900,-0.01,-0.0002,-0.00020,3.000
3,57.050,-0.02,-0.0002,-0.00020,3.000
3,57.200,-0.02,-0.0002,-0.00020,3.000
3,57.350,-0.02,-0.0002,-0.00020,3.000
3,57.500,-0.01,-0.0002,-0.00020,3.000
3,57.650,-0.03,-0.0002,-0.00020,3.000
3,57.800,-0.01,-0.0002,-0.00020,3.000
3,57.950,-0.03,-0.0002,-0.00020,3.000
3,58.100,-0.02,-0.0002,-0.00020,3.000
3,58.250,-0.02,-0.0002,-0.00020,3.000
3,58.400,-0.01,-0.0001,-0.00010,3.000
3,58.550,-0.02,-0.0001,-0.00010,3.000
3,58.700,-0.01,-0.0001,-0.00010,3.000
3,58.850,-0.01,-0.0001,-0.00010,3.000
3,59.000,-0.02,-0.0001,-0.00010,3.000
3,59.150,-0.01,-0.0001,-0.00010,3.000
3,59.300,-0.01,-0.0001,-0.00010,3.000
4,59.550,0.00,0.0776,0.07760,4.000
4,59.700,0.00,0.2275,0.22750,4.000
4,59.850,0.00,0.3777,0.37770,4.000
4,60.000,-0.01,0.5278,0.52780,4.000
4,60.150,-0.01,0.6777,0.67770,4.000
4,60.300,0.00,0.8276,0.82760,4.000
4,60.450,0.00,0.9778,0.97780,4.000
4,60.600,0.00,1.1278,1.12780,4.000
4,60.750,-0.01,1.2777,1.27770,4.000
4,60.900,-0.01,1.4277,1.42770,4.000
4,61.050,-0.01,1.5779,1.57790,4.000
4,61.200,0.00,1.7277,1.72770,4.000
4,61.350,0.00,1.8777,1.87770,4.000
4,61.500,0.01,2.0277,2.02770,4.000
4,61.650,0.01,2.1779,2.17790,4.000
4,61.800,0.00,2.3278,2.32780,4.000
4,61.950,-0.01,2.4777,2.47770,4.000
4,62.100,0.00,2.6277,2.62770,4.000
4,62.250,0.00,2.7778,2.77780,4.000
4,62.400,0.00,2.9278,2.92780,4.000
4,62.550,0.01,3.0777,3.07770,4.000
4,62.700,0.01,3.2278,3.22780,4.000
4,62.850,0.04,3.3779,3.37790,4.000
4,63.000,0.09,3.5279,3.52790,4.000
4,63.150,0.23,3.6778,3.67780,4.000
4,63.300,0.47,3.8280,3.82800,4.000
4,63.450,0.81,3.9780,3.97800,4.000
4,63.600,1.30,4.1278,4.12780,4.000
4,63.750,1.90,4.2778,4.27780,4.000
4,63.900,2.67,4.4279,4.42790,4.000
4,64.050,3.60,4.5780,4.57800,4.000
4,64.200,4.75,4.7279,4.72790,4.000
4,64.350,6.07,4.8777,4.87770,4.000
4,64.500,7.58,5.0278,5.02780,4.000
4,64.650,9.35,5.1780,5.17800,4.000
4,64.800,11.32,5.3278,5.32780,4.000
4,64.950,13.53,5.4779,5.47790,4.000
4,65.100,16.01,5.6279,5.62790,4.000
4,65.250,18.65,5.7779,5.77790,4.000
4,65.400,22.04,5.9278,5.92780,4.000
4,65.550,25.91,6.0778,6.07780,4.000
4,65.700,30.39,6.2279,6.22790,4.000
4,65.850,35.58,6.3779,6.37790,4.000
4,66.000,41.80,6.5279,6.52790,4.000
4,66.150,49.55,6.6778,6.67780,4.000
4,66.310,45.89,6.6607,6.66070,4.000
4,66.460,34.12,6.5107,6.51070,4.000
4,66.610,26.50,6.3605,6.36050,4.000
4,66.760,20.90,6.2106,6.21060,4.000
4,66.910,16.61,6.0606,6.06060,4.000
4,67.060,13.26,5.9105,5.91050,4.000
4,67.210,10.64,5.7605,5.76050,4.000
4,67.360,8.62,5.6105,5.61050,4.000
4,67.510,7.02,5.4608,5.46080,4.000
4,67.660,5.69,5.3106,5.31060,4.000
4,67.810,4.60,5.1603,5.16030,4.000
4,67.960,3.66,5.0105,5.01050,4.000
4,68.110,2.86,4.8604,4.86040,4.000
4,68.260,2.20,4.7105,4.71050,4.000
4,68.410,1.67,4.5604,4.56040,4.000
4,68.560,1.22,4.4105,4.41050,4.000
4,68.710,0.84,4.2605,4.26050,4.000
4,68.860,0.55,4.1104,4.11040,4.000
4,69.010,0.31,3.9603,3.96030,4.000
4,69.160,0.16,3.8106,3.81060,4.000
4,69.310,0.05,3.6605,3.66050,4.000
4,69.460,-0.02,3.5104,3.51040,4.000
4,69.610,0.00,3.3604,3.36040,4.000
4,69.760,0.00,3.2104,3.21040,4.000
4,69.910,-0.02,3.0605,3.06050,4.000
4,70.060,-0.01,2.9102,2.91020,4.000
4,70.210,-0.01,2.7603,2.76030,4.000
4,70.360,-0.01,2.6104,2.61040,4.000
4,70.510,0.00,2.4604,2.46040,4.000
4,70.660,0.01,2.3102,2.31020,4.000
4,70.810,0.01,2.1603,2.16030,4.000
4,70.960,0.00,2.0104,2.01040,4.000
4,71.110,0.00,1.8603,1.86030,4.000
4,71.260,0.00,1.7102,1.71020,4.000
4,71.410,-0.01,1.5603,1.56030,4.000
4,71.560,0.00,1.4102,1.41020,4.000
4,71.710,0.00,1.2603,1.26030,4.000
4,71.860,-0.01,1.1101,1.11010,4.000
4,72.010,0.00,0.9603,0.96030,4.000
4,72.160,0.00,0.8104,0.81040,4.000
4,72.310,-0.01,0.6602,0.66020,4.000
4,72.460,0.00,0.5101,0.51010,4.000
4,72.610,-0.02,0.3602,0.36020,4.000
4,72.760,-0.01,0.2101,0.21010,4.000
4,72.910,0.00,0.0601,0.06010,4.000
4,73.080,0.00,-0.0326,-0.03260,4.000
4,73.230,0.00,-0.0003,-0.00030,4.000
4,73.380,0.01,-0.0003,-0.00030,4.000
4,73.530,0.00,-0.0003,-0.00030,4.000
4,73.680,-0.01,-0.0003,-0.00030,4.000
4,73.830,-0.01,-0.0003,-0.00030,4.000
4,73.980,0.00,-0.0003,-0.00030,4.000
4,74.130,0.01,-0.0003,-0.00030,4.000
4,74.280,-0.01,-0.0003,-0.00030,4.000
4,74.430,0.00,-0.0003,-0.00030,4.000
4,74.580,0.00,-0.0003,-0.00030,4.000
4,74.730,-0.01,-0.0003,-0.00030,4.000
4,74.880,-0.01,-0.0003,-0.00030,4.000
4,75.030,-0.01,-0.0003,-0.00030,4.000
4,75.180,0.01,-0.0003,-0.00030,4.000
4,75.330,0.01,-0.0003,-0.00030,4.000
4,75.480,0.00,-0.0003,-0.00030,4.000
4,75.630,0.00,-0.0002,-0.00020,4.000
4,75.780,0.00,-0.0002,-0.00020,4.000
4,75.930,0.00,-0.0002,-0.00020,4.000
4,76.090,-0.01,-0.0002,-0.00020,4.000
4,76.240,0.00,-0.0002,-0.00020,4.000
4,76.390,0.00,-0.0002,-0.00020,4.000
4,76.540,0.01,-0.0002,-0.00020,4.000
4,76.690,-0.01,-0.0002,-0.00020,4.000
4,76.840,0.00,-0.0002,-0.00020,4.000
4,76.990,0.00,-0.0002,-0.00020,4.000
4,77.140,0.00,-0.0002,-0.00020,4.000
4,77.290,0.00,-0.0002,-0.00020,4.000
4,77.440,-0.01,-0.0002,-0.00020,4.000
4,77.590,-0.01,-0.0002,-0.00020,4.000
4,77.740,0.00,-0.0002,-0.00020,4.000
4,77.890,-0.01,-0.0002,-0.00020,4.000
4,78.040,-0.01,-0.0002,-0.00020,4.000
4,78.190,0.01,-0.0002,-0.00020,4.000
4,78.340,0.01,-0.0001,-0.00010,4.000
4,78.490,0.00,-0.0001,-0.00010,4.000
4,78.640,-0.01,-0.0001,-0.00010,4.000
4,78.790,-0.01,-0.0001,-0.00010,4.000
4,78.940,-0.02,-0.0001,-0.00010,4.000
4,79.170,0.01,0.0000,0.00000,4.000
5,79.330,0.02,0.0976,0.09760,5.000
5,79.480,0.00,0.2477,0.24770,5.000
5,79.630,0.01,0.3978,0.39780,5.000
5,79.780,0.01,0.5476,0.54760,5.000
5,79.930,-0.01,0.6976,0.69760,5.000
5,80.080,0.02,0.8479,0.84790,5.000
5,80.230,0.00,0.9978,0.99780,5.000
5,80.380,0.01,1.1477,1.14770,5.000
5,80.530,0.01,1.2978,1.29780,5.000
5,80.680,0.01,1.4478,1.44780,5.000
5,80.830,0.00,1.5978,1.59780,5.000
5,80.980,0.01,1.7476,1.74760,5.000
5,81.130,0.01,1.8977,1.89770,5.000
5,81.280,0.01,2.0479,2.04790,5.000
5,81.430,0.00,2.1978,2.19780,5.000
5,81.580,0.01,2.3478,2.34780,5.000
5,81.730,0.01,2.4978,2.49780,5.000
5,81.880,0.02,2.6479,2.64790,5.000
5,82.030,0.02,2.7978,2.79780,5.000
5,82.180,0.01,2.9478,2.94780,5.000
5,82.330,0.02,3.0979,3.09790,5.000
5,82.480,0.02,3.2478,3.24780,5.000
5,82.630,0.05,3.3978,3.39780,5.000
5,82.780,0.11,3.5478,3.54780,5.000
5,82.930,0.25,3.6979,3.69790,5.000
5,83.080,0.50,3.8478,3.84780,5.000
5,83.230,0.86,3.9978,3.99780,5.000
5,83.380,1.34,4.1479,4.14790,5.000
5,83.530,1.97,4.2980,4.29800,5.000
5,83.680,2.74,4.4479,4.44790,5.000
5,83.830,3.70,4.5979,4.59790,5.000
5,83.980,4.86,4.7479,4.74790,5.000
5,84.130,6.19,4.8978,4.89780,5.000
5,84.280,7.76,5.0478,5.04780,5.000
5,84.430,9.52,5.1978,5.19780,5.000
5,84.580,11.51,5.3480,5.34800,5.000
5,84.730,13.75,5.4980,5.49800,5.000
5,84.880,16.27,5.6478,5.64780,5.000
5,85.030,19.03,5.7978,5.79780,5.000
5,85.180,22.46,5.9479,5.94790,5.000
5,85.330,26.42,6.0979,6.09790,5.000
5,85.480,30.96,6.2478,6.24780,5.000
5,85.630,36.26,6.3977,6.39770,5.000
5,85.780,42.59,6.5480,6.54800,5.000
5,85.930,50.56,6.6980,6.69800,5.000
5,86.090,45.40,6.6628,6.66280,5.000
5,86.240,33.83,6.5127,6.51270,5.000
5,86.390,26.26,6.3624,6.36240,5.000
5,86.540,20.75,6.2126,6.21260,5.000
5,86.690,16.49,6.0626,6.06260,5.000
5,86.840,13.17,5.9125,5.91250,5.000
5,86.990,10.57,5.7624,5.76240,5.000
5,87.140,8.57,5.6125,5.61250,5.000
5,87.290,6.98,5.4627,5.46270,5.000
5,87.440,5.67,5.3125,5.31250,5.000
5,87.590,4.60,5.1623,5.16230,5.000
5,87.740,3.66,5.0126,5.01260,5.000
5,87.890,2.86,4.8625,4.86250,5.000
5,88.040,2.22,4.7125,4.71250,5.000
5,88.190,1.68,4.5624,4.56240,5.000
5,88.340,1.22,4.4124,4.41240,5.000
5,88.490,0.85,4.2625,4.26250,5.000
5,88.640,0.55,4.1124,4.11240,5.000
5,88.790,0.32,3.9624,3.96240,5.000
5,88.940,0.16,3.8124,3.81240,5.000
5,89.090,0.04,3.6625,3.66250,5.000
5,89.240,0.01,3.5123,3.51230,5.000
5,89.390,0.01,3.3624,3.36240,5.000
5,89.540,0.01,3.2124,3.21240,5.000
5,89.690,0.01,3.0624,3.06240,5.000
5,89.840,0.01,2.9122,2.91220,5.000
5,89.990,0.00,2.7623,2.76230,5.000
5,90.140,0.01,2.6123,2.61230,5.000
5,90.290,0.00,2.4623,2.46230,5.000
5,90.440,0.00,2.3122,2.31220,5.000
5,90.590,0.01,2.1624,2.16240,5.000
5,90.740,0.01,2.0124,2.01240,5.000
5,90.890,0.00,1.8622,1.86220,5.000
5,91.040,0.01,1.7121,1.71210,5.000
5,91.190,0.01,1.5624,1.56240,5.000
5,91.340,0.01,1.4123,1.41230,5.000
5,91.490,0.00,1.2623,1.26230,5.000
5,91.640,0.01,1.1121,1.11210,5.000
5,91.790,0.01,0.9623,0.96230,5.000
5,91.940,0.02,0.8123,0.81230,5.000
5,92.090,0.01,0.6621,0.66210,5.000
5,92.240,0.01,0.5122,0.51220,5.000
5,92.390,0.01,0.3622,0.36220,5.000
5,92.540,0.00,0.2122,0.21220,5.000
5,92.690,0.00,0.0622,0.06220,5.000
5,92.850,0.01,-0.0408,-0.04080,5.000
5,93.000,0.01,-0.0003,-0.00030,5.000
5,93.150,0.01,-0.0003,-0.00030,5.000
5,93.300,0.01,-0.0003,-0.00030,5.000
5,93.450,0.00,-0.0003,-0.00030,5.000
5,93.600,0.01,-0.0003,-0.00030,5.000
5,93.750,-0.01,-0.0003,-0.00030,5.000
5,93.900,0.01,-0.0003,-0.00030,5.000
5,94.050,0.01,-0.0003,-0.00030,5.000
5,94.200,0.01,-0.0003,-0.00030,5.000
5,94.350,0.01,-0.0003,-0.00030,5.000
5,94.500,0.01,-0.0003,-0.00030,5.000
5,94.650,0.01,-0.0003,-0.00030,5.000
5,94.800,0.00,-0.0003,-0.00030,5.000
5,94.950,0.01,-0.0003,-0.00030,5.000
5,95.100,0.01,-0.0003,-0.00030,5.000
5,95.250,0.01,-0.0002,-0.00020,5.000
5,95.400,0.01,-0.0002,-0.00020,5.000
5,95.550,0.01,-0.0002,-0.00020,5.000
5,95.700,0.01,-0.0002,-0.00020,5.000
5,95.850,0.01,-0.0002,-0.00020,5.000
5,96.010,0.00,-0.0002,-0.00020,5.000
5,96.160,0.00,-0.0002,-0.00020,5.000
5,96.310,0.01,-0.0002,-0.00020,5.000
5,96.460,0.00,-0.0002,-0.00020,5.000
5,96.610,0.01,-0.0002,-0.00020,5.000
5,96.760,0.01,-0.0002,-0.00020,5.000
5,96.910,0.01,-0.0002,-0.00020,5.000
5,97.060,0.01,-0.0002,-0.00020,5.000
5,97.210,0.01,-0.0002,-0.00020,5.000
5,97.360,0.01,-0.0002,-0.00020,5.000
5,97.510,0.00,-0.0002,-0.00020,5.000
5,97.660,0.01,-0.0002,-0.00020,5.000
5,97.810,0.01,-0.0002,-0.00020,5.000
5,97.960,0.01,-0.0001,-0.00010,5.000
5,98.110,0.01,-0.0001,-0.00010,5.000
5,98.260,0.01,-0.0001,-0.00010,5.000
5,98.410,0.01,-0.0001,-0.00010,5.000
5,98.560,0.01,-0.0001,-0.00010,5.000
5,98.710,0.01,-0.0001,-0.00010,5.000
5,98.860,0.01,-0.0001,-0.00010,5.000
6,99.110,0.02,0.0666,0.06660,6.000
6,99.260,0.01,0.2167,0.21670,6.000
6,99.410,0.02,0.3667,0.36670,6.000
6,99.560,0.01,0.5166,0.51660,6.000
6,99.710,0.01,0.6666,0.66660,6.000
6,99.860,0.01,0.8168,0.81680,6.000
6,100.010,0.01,0.9668,0.96680,6.000
6,100.160,0.02,1.1166,1.11660,6.000
6,100.310,0.01,1.2666,1.26660,6.000
6,100.460,0.02,1.4169,1.41690,6.000
6,100.610,0.01,1.5668,1.56680,6.000
6,100.760,0.01,1.7166,1.71660,6.000
6,100.910,0.02,1.8667,1.86670,6.000
6,101.060,0.01,2.0169,2.01690,6.000
6,101.210,0.02,2.1669,2.16690,6.000
6,101.360,0.01,2.3166,2.31660,6.000
6,101.510,0.02,2.4667,2.46670,6.000
6,101.660,0.02,2.6170,2.61700,6.000
6,101.810,0.02,2.7668,2.76680,6.000
6,101.960,0.01,2.9167,2.91670,6.000
6,102.110,0.03,3.0669,3.06690,6.000
6,102.260,0.03,3.2169,3.21690,6.000
6,102.410,0.05,3.3668,3.36680,6.000
6,102.560,0.08,3.5167,3.51670,6.000
6,102.710,0.21,3.6669,3.66690,6.000
6,102.860,0.43,3.8169,3.81690,6.000
6,103.010,0.75,3.9670,3.96700,6.000
6,103.160,1.22,4.1168,4.11680,6.000
6,103.310,1.81,4.2668,4.26680,6.000
6,103.460,2.54,4.4169,4.41690,6.000
6,103.610,3.46,4.5669,4.56690,6.000
6,103.760,4.58,4.7168,4.71680,6.000
6,103.910,5.87,4.8669,4.86690,6.000
6,104.060,7.37,5.0168,5.01680,6.000
6,104.210,9.10,5.1668,5.16680,6.000
6,104.360,11.04,5.3168,5.31680,6.000
6,104.510,13.20,5.4671,5.46710,6.000
6,104.660,15.70,5.6169,5.61690,6.000
6,104.810,18.40,5.7668,5.76680,6.000
6,104.960,21.71,5.9168,5.91680,6.000
6,105.110,25.53,6.0669,6.06690,6.000
6,105.260,29.91,6.2168,6.21680,6.000
6,105.410,35.01,6.3667,6.36670,6.000
6,105.560,41.09,6.5168,6.51680,6.000
6,105.710,48.61,6.6671,6.66710,6.000
6,105.870,48.51,6.6915,6.69150,6.000
6,106.020,35.63,6.5419,6.54190,6.000
6,106.170,27.55,6.3915,6.39150,6.000
6,106.320,21.71,6.2416,6.24160,6.000
6,106.470,17.25,6.0915,6.09150,6.000
6,106.620,13.76,5.9417,5.94170,6.000
6,106.770,11.03,5.7916,5.79160,6.000
6,106.920,8.92,5.6414,5.64140,6.000
6,107.070,7.27,5.4917,5.49170,6.000
6,107.220,5.91,5.3418,5.34180,6.000
6,107.370,4.79,5.1916,5.19160,6.000
6,107.520,3.83,5.0413,5.04130,6.000
6,107.670,3.00,4.8914,4.89140,6.000
6,107.820,2.33,4.7415,4.74150,6.000
6,107.970,1.77,4.5916,4.59160,6.000
6,108.120,1.30,4.4413,4.44130,6.000
6,108.270,0.91,4.2915,4.29150,6.000
6,108.420,0.60,4.1415,4.14150,6.000
6,108.570,0.36,3.9915,3.99150,6.000
6,108.720,0.18,3.8413,3.84130,6.000
6,108.870,0.08,3.6915,3.69150,6.000
6,109.020,0.03,3.5414,3.54140,6.000
6,109.170,0.01,3.3914,3.39140,6.000
6,109.320,0.01,3.2413,3.24130,6.000
6,109.470,0.02,3.0915,3.09150,6.000
6,109.620,0.01,2.9413,2.94130,6.000
6,109.770,0.01,2.7913,2.79130,6.000
6,109.920,-0.01,2.6413,2.64130,6.000
6,110.070,0.02,2.4914,2.49140,6.000
6,110.220,0.00,2.3414,2.34140,6.000
6,110.370,0.01,2.1912,2.19120,6.000
6,110.520,0.01,2.0413,2.04130,6.000
6,110.670,0.02,1.8914,1.89140,6.000
6,110.820,0.01,1.7413,1.74130,6.000
6,110.970,0.02,1.5913,1.59130,6.000
6,111.120,0.01,1.4413,1.44130,6.000
6,111.270,0.01,1.2912,1.29120,6.000
6,111.420,0.01,1.1412,1.14120,6.000
6,111.570,0.02,0.9912,0.99120,6.000
6,111.720,0.01,0.8414,0.84140,6.000
6,111.870,0.02,0.6912,0.69120,6.000
6,112.020,0.01,0.5411,0.54110,6.000
6,112.170,0.01,0.3911,0.39110,6.000
6,112.320,0.02,0.2411,0.24110,6.000
6,112.470,0.01,0.0912,0.09120,6.000
6,112.630,0.01,-0.0504,-0.05040,6.000
6,112.780,0.02,-0.0003,-0.00030,6.000
6,112.930,0.02,-0.0003,-0.00030,6.000
6,113.080,0.01,-0.0003,-0.00030,6.000
6,113.230,0.01,-0.0003,-0.00030,6.000
6,113.380,0.00,-0.0003,-0.00030,6.000
6,113.530,0.00,-0.0003,-0.00030,6.000
6,113.680,0.01,-0.0003,-0.00030,6.000
6,113.830,0.02,-0.0003,-0.00030,6.000
6,113.980,0.02,-0.0003,-0.00030,6.000
6,114.130,0.02,-0.0003,-0.00030,6.000
6,114.280,0.01,-0.0003,-0.00030,6.000
6,114.430,0.01,-0.0003,-0.00030,6.000
6,114.580,0.02,-0.0003,-0.00030,6.000
6,114.730,0.02,-0.0003,-0.00030,6.000
6,114.880,0.01,-0.0003,-0.00030,6.000
6,115.030,0.02,-0.0003,-0.00030,6.000
6,115.180,0.01,-0.0003,-0.00030,6.000
6,115.330,-0.01,-0.0002,-0.00020,6.000
6,115.480,0.02,-0.0002,-0.00020,6.000
6,115.630,0.01,-0.0002,-0.00020,6.000
6,115.790,0.00,-0.0002,-0.00020,6.000
6,115.940,0.01,-0.0002,-0.00020,6.000
6,116.090,0.02,-0.0002,-0.00020,6.000
6,116.240,0.01,-0.0002,-0.00020,6.000
6,116.390,0.02,-0.0002,-0.00020,6.000
6,116.540,0.02,-0.0002,-0.00020,6.000
6,116.690,0.01,-0.0002,-0.00020,6.000
6,116.840,0.02,-0.0002,-0.00020,6.000
6,116.990,0.01,-0.0002,-0.00020,6.000
6,117.140,0.02,-0.0002,-0.00020,6.000
6,117.290,0.00,-0.0002,-0.00020,6.000
6,117.440,0.01,-0.0002,-0.00020,6.000
6,117.590,0.02,-0.0002,-0.00020,6.000
6,117.740,0.00,-0.0002,-0.00020,6.000
6,117.890,0.02,-0.0002,-0.00020,6.000
6,118.040,0.01,-0.0002,-0.00020,6.000
6,118.190,0.00,-0.0001,-0.00010,6.000
6,118.340,0.01,-0.0001,-0.00010,6.000
6,118.490,0.02,-0.0001,-0.00010,6.000
6,118.640,0.03,-0.0001,-0.00010,6.000
7,118.890,0.01,0.0366,0.03670,7.000
7,119.040,-0.01,0.1865,0.18660,7.000
7,119.190,0.01,0.3368,0.33690,7.000
7,119.340,0.02,0.4868,0.48690,7.000
7,119.490,0.02,0.6366,0.63670,7.000
7,119.640,0.02,0.7867,0.78680,7.000
7,119.790,-0.01,0.9369,0.93700,7.000
7,119.940,0.01,1.0867,1.08680,7.000
7,120.090,0.01,1.2367,1.23680,7.000
7,120.240,0.00,1.3867,1.38680,7.000
7,120.390,0.01,1.5369,1.53700,7.000
7,120.540,0.01,1.6868,1.68690,7.000
7,120.690,0.01,1.8367,1.83680,7.000
7,120.840,0.01,1.9868,1.98690,7.000
7,120.990,0.01,2.1369,2.13700,7.000
7,121.140,0.00,2.2868,2.28690,7.000
7,121.290,0.00,2.4367,2.43680,7.000
7,121.440,0.01,2.5868,2.58690,7.000
7,121.590,0.01,2.7368,2.73690,7.000
7,121.740,0.01,2.8868,2.88690,7.000
7,121.890,0.02,3.0368,3.03690,7.000
7,122.040,0.01,3.1868,3.18690,7.000
7,122.190,0.03,3.3369,3.33700,7.000
7,122.340,0.07,3.4868,3.48690,7.000
7,122.490,0.19,3.6368,3.63690,7.000
7,122.640,0.36,3.7870,3.78710,7.000
7,122.790,0.66,3.9370,3.93710,7.000
7,122.940,1.10,4.0868,4.08690,7.000
7,123.090,1.64,4.2368,4.23690,7.000
7,123.240,2.35,4.3868,4.38690,7.000
7,123.390,3.20,4.5370,4.53710,7.000
7,123.540,4.27,4.6869,4.68700,7.000
7,123.690,5.52,4.8368,4.83690,7.000
7,123.840,6.97,4.9869,4.98700,7.000
7,123.990,8.66,5.1369,5.13700,7.000
7,124.140,10.54,5.2869,5.28700,7.000
7,124.290,12.67,5.4370,5.43710,7.000
7,124.440,15.07,5.5869,5.58700,7.000
7,124.590,17.75,5.7370,5.73710,7.000
7,124.740,20.92,5.8868,5.88690,7.000
7,124.890,24.65,6.0368,6.03690,7.000
7,125.040,28.92,6.1869,6.18700,7.000
7,125.190,33.81,6.3369,6.33700,7.000
7,125.340,39.66,6.4867,6.48680,7.000
7,125.490,46.80,6.6369,6.63700,7.000
7,125.660,50.88,6.7114,6.71150,7.000
7,125.810,36.87,6.5616,6.56170,7.000
7,125.960,28.38,6.4115,6.41160,7.000
7,126.110,22.31,6.2617,6.26180,7.000
7,126.260,17.71,6.1117,6.11180,7.000
7,126.410,14.12,5.9614,5.96150,7.000
7,126.560,11.29,5.8115,5.81160,7.000
7,126.710,9.13,5.6616,5.66170,7.000
7,126.860,7.41,5.5117,5.51180,7.000
7,127.010,6.03,5.3615,5.36160,7.000
7,127.160,4.90,5.2116,5.21170,7.000
7,127.310,3.93,5.0615,5.06160,7.000
7,127.460,3.09,4.9115,4.91160,7.000
7,127.610,2.39,4.7613,4.76140,7.000
7,127.760,1.83,4.6115,4.61160,7.000
7,127.910,1.34,4.4615,4.46160,7.000
7,128.060,0.94,4.3114,4.31150,7.000
7,128.210,0.63,4.1613,4.16140,7.000
7,128.360,0.37,4.0114,4.01150,7.000
7,128.510,0.20,3.8614,3.86150,7.000
7,128.660,0.07,3.7115,3.71160,7.000
7,128.810,0.02,3.5612,3.56130,7.000
7,128.960,0.00,3.4116,3.41170,7.000
7,129.110,0.01,3.2615,3.26160,7.000
7,129.260,0.01,3.1113,3.11140,7.000
7,129.410,0.01,2.9612,2.96130,7.000
7,129.560,0.01,2.8113,2.81140,7.000
7,129.710,0.01,2.6613,2.66140,7.000
7,129.860,0.00,2.5113,2.51140,7.000
7,130.010,0.01,2.3613,2.36140,7.000
7,130.160,0.00,2.2114,2.21150,7.000
7,130.310,0.01,2.0615,2.06160,7.000
7,130.460,0.01,1.9111,1.91120,7.000
7,130.610,0.00,1.7613,1.76140,7.000
7,130.760,-0.01,1.6115,1.61160,7.000
7,130.910,0.00,1.4613,1.46140,7.000
7,131.060,0.01,1.3111,1.31120,7.000
7,131.210,-0.01,1.1612,1.16130,7.000
7,131.360,0.01,1.0114,1.01150,7.000
7,131.510,0.00,0.8614,0.86150,7.000
7,131.660,0.01,0.7111,0.71120,7.000
7,131.810,0.00,0.5612,0.56130,7.000
7,131.960,0.00,0.4113,0.41140,7.000
7,132.110,0.01,0.2612,0.26130,7.000
7,132.260,0.01,0.1110,0.11110,7.000
7,132.420,0.01,-0.0453,-0.04520,7.000
7,132.570,0.00,-0.0004,-0.00030,7.000
7,132.720,0.01,-0.0003,-0.00020,7.000
7,132.870,0.01,-0.0003,-0.00020,7.000
7,133.020,0.01,-0.0003,-0.00020,7.000
7,133.170,0.00,-0.0003,-0.00020,7.000
7,133.320,0.01,-0.0003,-0.00020,7.000
7,133.470,-0.01,-0.0003,-0.00020,7.000
7,133.620,0.00,-0.0003,-0.00020,7.000
7,133.770,0.01,-0.0003,-0.00020,7.000
7,133.920,0.00,-0.0003,-0.00020,7.000
7,134.070,0.01,-0.0003,-0.00020,7.000
7,134.220,0.01,-0.0003,-0.00020,7.000
7,134.370,0.00,-0.0003,-0.00020,7.000
7,134.520,0.00,-0.0003,-0.00020,7.000
7,134.670,0.01,-0.0003,-0.00020,7.000
7,134.820,0.02,-0.0003,-0.00020,7.000
7,134.970,0.00,-0.0003,-0.00020,7.000
7,135.120,0.01,-0.0003,-0.00020,7.000
7,135.270,0.02,-0.0002,-0.00010,7.000
7,135.420,0.01,-0.0002,-0.00010,7.000
7,135.590,0.00,-0.0002,-0.00010,7.000
7,135.740,0.00,-0.0002,-0.00010,7.000
7,135.890,0.01,-0.0002,-0.00010,7.000
7,136.040,0.01,-0.0002,-0.00010,7.000
7,136.190,0.01,-0.0002,-0.00010,7.000
7,136.340,0.01,-0.0002,-0.00010,7.000
7,136.490,0.01,-0.0002,-0.00010,7.000
7,136.640,0.00,-0.0002,-0.00010,7.000
7,136.790,-0.01,-0.0002,-0.00010,7.000
7,136.940,0.01,-0.0002,-0.00010,7.000
7,137.090,0.01,-0.0002,-0.00010,7.000
7,137.240,0.02,-0.0002,-0.00010,7.000
7,137.390,0.00,-0.0002,-0.00010,7.000
7,137.540,0.01,-0.0002,-0.00010,7.000
7,137.690,0.01,-0.0002,-0.00010,7.000
7,137.840,0.00,-0.0002,-0.00010,7.000
7,137.990,0.00,-0.0002,-0.00010,7.000
7,138.140,0.01,-0.0001,0.00000,7.000
7,138.290,0.01,-0.0001,0.00000,7.000
7,138.440,0.01,-0.0001,0.00000,7.000
8,138.690,0.00,0.0375,0.03750,8.000
8,138.840,-0.01,0.1876,0.18760,8.000
8,138.990,0.00,0.3379,0.33790,8.000
8,139.140,0.00,0.4878,0.48780,8.000
8,139.290,0.00,0.6376,0.63760,8.000
8,139.440,0.00,0.7877,0.78770,8.000
8,139.590,-0.01,0.9378,0.93780,8.000
8,139.740,0.00,1.0877,1.08770,8.000
8,139.890,0.00,1.2377,1.23770,8.000
8,140.040,0.00,1.3876,1.38760,8.000
8,140.190,-0.01,1.5379,1.53790,8.000
8,140.340,0.00,1.6878,1.68780,8.000
8,140.490,-0.01,1.8377,1.83770,8.000
8,140.640,0.00,1.9878,1.98780,8.000
8,140.790,0.00,2.1378,2.13780,8.000
8,140.940,-0.01,2.2878,2.28780,8.000
8,141.090,0.00,2.4376,2.43760,8.000
8,141.240,-0.01,2.5878,2.58780,8.000
8,141.390,0.00,2.7380,2.73800,8.000
8,141.540,0.00,2.8878,2.88780,8.000
8,141.690,0.00,3.0379,3.03790,8.000
8,141.840,0.01,3.1879,3.18790,8.000
8,141.990,0.02,3.3379,3.33790,8.000
8,142.140,0.05,3.4878,3.48780,8.000
8,142.290,0.16,3.6377,3.63770,8.000
8,142.440,0.34,3.7880,3.78800,8.000
8,142.590,0.63,3.9379,3.93790,8.000
8,142.740,1.07,4.0879,4.08790,8.000
8,142.890,1.63,4.2378,4.23780,8.000
8,143.040,2.35,4.3878,4.38780,8.000
8,143.190,3.20,4.5380,4.53800,8.000
8,143.340,4.27,4.6879,4.68790,8.000
8,143.490,5.51,4.8377,4.83770,8.000
8,143.640,6.96,4.9880,4.98800,8.000
8,143.790,8.65,5.1379,5.13790,8.000
8,143.940,10.56,5.2878,5.28780,8.000
8,144.090,12.67,5.4379,5.43790,8.000
8,144.240,15.10,5.5880,5.58800,8.000
8,144.390,17.79,5.7379,5.73790,8.000
8,144.540,21.01,5.8878,5.88780,8.000
8,144.690,24.72,6.0379,6.03790,8.000
8,144.840,28.99,6.1879,6.18790,8.000
8,144.990,33.91,6.3378,6.33780,8.000
8,145.140,39.75,6.4879,6.48790,8.000
8,145.290,46.93,6.6379,6.63790,8.000
8,145.460,51.01,6.7123,6.71230,8.000
8,145.610,36.95,6.5626,6.56260,8.000
8,145.760,28.45,6.4126,6.41260,8.000
8,145.910,22.36,6.2627,6.26270,8.000
8,146.060,17.75,6.1127,6.11270,8.000
8,146.210,14.15,5.9625,5.96250,8.000
8,146.360,11.32,5.8125,5.81250,8.000
8,146.510,9.14,5.6625,5.66250,8.000
8,146.660,7.43,5.5127,5.51270,8.000
8,146.810,6.04,5.3625,5.36250,8.000
8,146.960,4.89,5.2126,5.21260,8.000
8,147.110,3.92,5.0625,5.06250,8.000
8,147.260,3.09,4.9125,4.91250,8.000
8,147.410,2.39,4.7624,4.76240,8.000
8,147.560,1.82,4.6126,4.61260,8.000
8,147.710,1.33,4.4626,4.46260,8.000
8,147.860,0.94,4.3124,4.31240,8.000
8,148.010,0.61,4.1623,4.16230,8.000
8,148.160,0.36,4.0124,4.01240,8.000
8,148.310,0.19,3.8625,3.86250,8.000
8,148.460,0.07,3.7125,3.71250,8.000
8,148.610,0.00,3.5623,3.56230,8.000
8,148.760,-0.01,3.4125,3.41250,8.000
8,148.910,-0.01,3.2624,3.26240,8.000
8,149.060,0.01,3.1124,3.11240,8.000
8,149.210,0.00,2.9622,2.96220,8.000
8,149.360,-0.01,2.8125,2.81250,8.000
8,149.510,-0.01,2.6624,2.66240,8.000
8,149.660,-0.01,2.5122,2.51220,8.000
8,149.810,-0.01,2.3622,2.36220,8.000
8,149.960,0.00,2.2123,2.21230,8.000
8,150.110,0.00,2.0625,2.06250,8.000
8,150.260,-0.01,1.9122,1.91220,8.000
8,150.410,-0.01,1.7623,1.76230,8.000
8,150.560,-0.01,1.6125,1.61250,8.000
8,150.710,-0.01,1.4623,1.46230,8.000
8,150.860,0.00,1.3121,1.31210,8.000
8,151.010,-0.01,1.1623,1.16230,8.000
8,151.160,0.00,1.0123,1.01230,8.000
8,151.310,-0.01,0.8624,0.86240,8.000
8,151.460,-0.01,0.7121,0.71210,8.000
8,151.610,-0.01,0.5622,0.56220,8.000
8,151.760,0.00,0.4123,0.41230,8.000
8,151.910,0.00,0.2621,0.26210,8.000
8,152.060,0.00,0.1120,0.11200,8.000
8,152.220,0.00,-0.0443,-0.04430,8.000
8,152.370,-0.01,-0.0003,-0.00030,8.000
8,152.520,-0.01,-0.0003,-0.00030,8.000
8,152.670,-0.01,-0.0003,-0.00030,8.000
8,152.820,-0.01,-0.0003,-0.00030,8.000
8,152.970,-0.01,-0.0003,-0.00030,8.000
8,153.120,-0.01,-0.0003,-0.00030,8.000
8,153.270,-0.01,-0.0003,-0.00030,8.000
8,153.420,-0.01,-0.0003,-0.00030,8.000
8,153.570,0.00,-0.0003,-0.00030,8.000
8,153.720,0.00,-0.0003,-0.00030,8.000
8,153.870,-0.01,-0.0003,-0.00030,8.000
8,154.020,-0.01,-0.0003,-0.00030,8.000
8,154.170,-0.01,-0.0003,-0.00030,8.000
8,154.320,-0.01,-0.0003,-0.00030,8.000
8,154.470,-0.01,-0.0003,-0.00030,8.000
8,154.620,0.00,-0.0003,-0.00030,8.000
8,154.770,-0.01,-0.0003,-0.00030,8.000
8,154.920,0.00,-0.0003,-0.00030,8.000
8,155.070,0.00,-0.0002,-0.00020,8.000
8,155.220,0.00,-0.0002,-0.00020,8.000
8,155.390,-0.01,-0.0002,-0.00020,8.000
8,155.540,0.00,-0.0002,-0.00020,8.000
8,155.690,0.00,-0.0002,-0.00020,8.000
8,155.840,-0.02,-0.0002,-0.00020,8.000
8,155.990,0.00,-0.0002,-0.00020,8.000
8,156.140,-0.01,-0.0002,-0.00020,8.000
8,156.290,0.00,-0.0002,-0.00020,8.000
8,156.440,0.00,-0.0002,-0.00020,8.000
8,156.590,-0.01,-0.0002,-0.00020,8.000
8,156.740,-0.01,-0.0002,-0.00020,8.000
8,156.890,0.01,-0.0002,-0.00020,8.000
8,157.040,-0.02,-0.0002,-0.00020,8.000
8,157.190,0.00,-0.0002,-0.00020,8.000
8,157.340,-0.01,-0.0002,-0.00020,8.000
8,157.490,0.01,-0.0002,-0.00020,8.000
8,157.640,-0.01,-0.0002,-0.00020,8.000
8,157.790,-0.01,-0.0001,-0.00010,8.000
8,157.940,0.00,-0.0001,-0.00010,8.000
8,158.090,0.00,-0.0001,-0.00010,8.000
8,158.240,-0.01,-0.0001,-0.00010,8.000
9,158.490,-0.01,0.0365,0.03660,9.000
9,158.640,-0.01,0.1865,0.18660,9.000
9,158.790,0.00,0.3368,0.33690,9.000
9,158.940,-0.02,0.4867,0.48680,9.000
9,159.090,-0.01,0.6366,0.63670,9.000
9,159.240,-0.01,0.7867,0.78680,9.000
9,159.390,-0.02,0.9369,0.93700,9.000
9,159.540,0.00,1.0867,1.08680,9.000
9,159.690,-0.01,1.2367,1.23680,9.000
9,159.840,0.00,1.3867,1.38680,9.000
9,159.990,-0.01,1.5368,1.53690,9.000
9,160.140,0.00,1.6869,1.68700,9.000
9,160.290,0.00,1.8366,1.83670,9.000
9,160.440,-0.01,1.9868,1.98690,9.000
9,160.590,-0.01,2.1369,2.13700,9.000
9,160.740,0.00,2.2867,2.28680,9.000
9,160.890,-0.01,2.4367,2.43680,9.000
9,161.040,-0.01,2.5868,2.58690,9.000
9,161.190,-0.01,2.7369,2.73700,9.000
9,161.340,-0.01,2.8868,2.88690,9.000
9,161.490,0.01,3.0367,3.03680,9.000
9,161.640,0.00,3.1868,3.18690,9.000
9,161.790,0.02,3.3370,3.33710,9.000
9,161.940,0.05,3.4868,3.48690,9.000
9,162.090,0.16,3.6368,3.63690,9.000
9,162.240,0.32,3.7869,3.78700,9.000
9,162.390,0.64,3.9370,3.93710,9.000
9,162.540,1.04,4.0868,4.08690,9.000
9,162.690,1.60,4.2368,4.23690,9.000
9,162.840,2.30,4.3869,4.38700,9.000
9,162.990,3.16,4.5369,4.53700,9.000
9,163.140,4.21,4.6868,4.68690,9.000
9,163.290,5.47,4.8368,4.83690,9.000
9,163.440,6.91,4.9869,4.98700,9.000
9,163.590,8.58,5.1369,5.13700,9.000
9,163.740,10.46,5.2869,5.28700,9.000
9,163.890,12.57,5.4371,5.43720,9.000
9,164.040,14.99,5.5869,5.58700,9.000
9,164.190,17.72,5.7369,5.73700,9.000
9,164.340,20.91,5.8868,5.88690,9.000
9,164.490,24.62,6.0369,6.03700,9.000
9,164.640,28.85,6.1869,6.18700,9.000
9,164.790,33.76,6.3368,6.33690,9.000
9,164.940,39.56,6.4868,6.48690,9.000
9,165.090,46.67,6.6369,6.63700,9.000
9,165.260,50.72,6.7114,6.71150,9.000
9,165.410,36.75,6.5617,6.56180,9.000
9,165.560,28.29,6.4116,6.41170,9.000
9,165.710,22.24,6.2616,6.26170,9.000
9,165.860,17.65,6.1117,6.11180,9.000
9,166.010,14.07,5.9615,5.96160,9.000
9,166.160,11.26,5.8115,5.81160,9.000
9,166.310,9.09,5.6616,5.66170,9.000
9,166.460,7.38,5.5117,5.51180,9.000
9,166.610,6.00,5.3616,5.36170,9.000
9,166.760,4.87,5.2115,5.21160,9.000
9,166.910,3.89,5.0616,5.06170,9.000
9,167.060,3.06,4.9115,4.91160,9.000
9,167.210,2.36,4.7613,4.76140,9.000
9,167.360,1.80,4.6115,4.61160,9.000
9,167.510,1.31,4.4615,4.46160,9.000
9,167.660,0.91,4.3114,4.31150,9.000
9,167.810,0.60,4.1614,4.16150,9.000
9,167.960,0.35,4.0115,4.01160,9.000
9,168.110,0.17,3.8614,3.86150,9.000
9,168.260,0.06,3.7115,3.71160,9.000
9,168.410,-0.02,3.5613,3.56140,9.000
9,168.560,-0.01,3.4115,3.41160,9.000
9,168.710,-0.01,3.2615,3.26160,9.000
9,168.860,0.00,3.1113,3.11140,9.000
9,169.010,0.00,2.9613,2.96140,9.000
9,169.160,0.01,2.8114,2.81150,9.000
9,169.310,-0.01,2.6613,2.66140,9.000
9,169.460,-0.01,2.5112,2.51130,9.000
9,169.610,-0.01,2.3612,2.36130,9.000
9,169.760,-0.01,2.2114,2.21150,9.000
9,169.910,-0.01,2.0615,2.06160,9.000
9,170.060,-0.01,1.9112,1.91130,9.000
9,170.210,-0.01,1.7611,1.76120,9.000
9,170.360,-0.01,1.6115,1.61160,9.000
9,170.510,-0.01,1.4613,1.46140,9.000
9,170.660,-0.01,1.3111,1.31120,9.000
9,170.810,-0.02,1.1611,1.16120,9.000
9,170.960,-0.01,1.0113,1.01140,9.000
9,171.110,0.00,0.8614,0.86150,9.000
9,171.260,-0.01,0.7111,0.71120,9.000
9,171.410,-0.01,0.5612,0.56130,9.000
9,171.560,0.00,0.4113,0.41140,9.000
9,171.710,-0.01,0.2612,0.26130,9.000
9,171.860,0.00,0.1110,0.11110,9.000
9,172.020,-0.01,-0.0453,-0.04520,9.000
9,172.170,-0.01,-0.0004,-0.00030,9.000
9,172.320,-0.01,-0.0004,-0.00030,9.000
9,172.470,-0.01,-0.0004,-0.00030,9.000
9,172.620,-0.01,-0.0004,-0.00030,9.000
9,172.770,-0.01,-0.0004,-0.00030,9.000
9,172.920,-0.01,-0.0004,-0.00030,9.000
9,173.070,-0.02,-0.0003,-0.00020,9.000
9,173.220,-0.01,-0.0003,-0.00020,9.000
9,173.370,0.00,-0.0003,-0.00020,9.000
9,173.520,-0.01,-0.0003,-0.00020,9.000
9,173.670,-0.01,-0.0003,-0.00020,9.000
9,173.820,-0.02,-0.0003,-0.00020,9.000
9,173.970,-0.02,-0.0003,-0.00020,9.000
9,174.120,-0.01,-0.0003,-0.00020,9.000
9,174.270,-0.01,-0.0003,-0.00020,9.000
9,174.420,0.00,-0.0003,-0.00020,9.000
9,174.570,0.00,-0.0003,-0.00020,9.000
9,174.720,0.00,-0.0003,-0.00020,9.000
9,174.870,-0.01,-0.0003,-0.00020,9.000
9,175.020,-0.01,-0.0002,-0.00010,9.000
9,175.190,-0.01,-0.0002,-0.00010,9.000
9,175.340,-0.01,-0.0002,-0.00010,9.000
9,175.490,-0.01,-0.0002,-0.00010,9.000
9,175.640,0.00,-0.0002,-0.00010,9.000
9,175.790,-0.01,-0.0002,-0.00010,9.000
9,175.940,-0.01,-0.0002,-0.00010,9.000
9,176.090,0.00,-0.0002,-0.00010,9.000
9,176.240,-0.01,-0.0002,-0.00010,9.000
9,176.390,-0.01,-0.0002,-0.00010,9.000
9,176.540,-0.01,-0.0002,-0.00010,9.000
9,176.690,-0.01,-0.0002,-0.00010,9.000
9,176.840,-0.01,-0.0002,-0.00010,9.000
9,176.990,0.00,-0.0002,-0.00010,9.000
9,177.140,-0.01,-0.0002,-0.00010,9.000
9,177.290,-0.01,-0.0002,-0.00010,9.000
9,177.440,0.00,-0.0002,-0.00010,9.000
9,177.590,0.00,-0.0001,0.00000,9.000
9,177.740,-0.01,-0.0001,0.00000,9.000
9,177.890,-0.02,-0.0001,0.00000,9.000
9,178.040,0.00,-0.0001,0.00000,9.000
10,178.290,-0.01,0.0365,0.03660,10.000
10,178.440,-0.01,0.1866,0.18670,10.000
10,178.590,0.00,0.3368,0.33690,10.000
10,178.740,0.01,0.4868,0.48690,10.000
10,178.890,0.00,0.6366,0.63670,10.000
10,179.040,0.00,0.7867,0.78680,10.000
10,179.190,0.01,0.9370,0.93710,10.000
10,179.340,-0.01,1.0868,1.08690,10.000
10,179.490,0.00,1.2367,1.23680,10.000
10,179.640,0.00,1.3867,1.38680,10.000
10,179.790,0.00,1.5369,1.53700,10.000
10,179.940,0.00,1.6868,1.68690,10.000
10,180.090,0.01,1.8366,1.83670,10.000
10,180.240,0.00,1.9868,1.98690,10.000
10,180.390,0.00,2.1369,2.13700,10.000
10,180.540,-0.01,2.2868,2.28690,10.000
10,180.690,-0.01,2.4367,2.43680,10.000
10,180.840,-0.01,2.5869,2.58700,10.000
10,180.990,0.01,2.7369,2.73700,10.000
10,181.140,0.00,2.8868,2.88690,10.000
10,181.290,0.00,3.0367,3.03680,10.000
10,181.440,0.01,3.1868,3.18690,10.000
10,181.590,0.03,3.3371,3.33720,10.000
10,181.740,0.06,3.4869,3.48700,10.000
10,181.890,0.14,3.6368,3.63690,10.000
10,182.040,0.33,3.7870,3.78710,10.000
10,182.190,0.63,3.9370,3.93710,10.000
10,182.340,1.04,4.0867,4.08680,10.000
10,182.490,1.59,4.2368,4.23690,10.000
10,182.640,2.30,4.3868,4.38690,10.000
10,182.790,3.14,4.5368,4.53690,10.000
10,182.940,4.20,4.6869,4.68700,10.000
10,183.090,5.47,4.8368,4.83690,10.000
10,183.240,6.91,4.9870,4.98710,10.000
10,183.390,8.58,5.1368,5.13690,10.000
10,183.540,10.47,5.2868,5.28690,10.000
10,183.690,12.58,5.4370,5.43710,10.000
10,183.840,15.00,5.5869,5.58700,10.000
10,183.990,17.74,5.7369,5.73700,10.000
10,184.140,20.95,5.8868,5.88690,10.000
10,184.290,24.68,6.0368,6.03690,10.000
10,184.440,28.93,6.1870,6.18710,10.000
10,184.590,33.83,6.3368,6.33690,10.000
10,184.740,39.63,6.4868,6.48690,10.000
10,184.890,46.79,6.6371,6.63720,10.000
10,185.060,50.82,6.7114,6.71150,10.000
10,185.210,36.84,6.5616,6.56170,10.000
10,185.360,28.36,6.4115,6.41160,10.000
10,185.510,22.30,6.2617,6.26180,10.000
10,185.660,17.70,6.1117,6.11180,10.000
10,185.810,14.11,5.9614,5.96150,10.000
10,185.960,11.30,5.8114,5.81150,10.000
10,186.110,9.09,5.6615,5.66160,10.000
10,186.260,7.39,5.5117,5.51180,10.000
10,186.410,6.02,5.3617,5.36180,10.000
10,186.560,4.87,5.2115,5.21160,10.000
10,186.710,3.90,5.0615,5.06160,10.000
10,186.860,3.06,4.9115,4.91160,10.000
10,187.010,2.37,4.7615,4.76160,10.000
10,187.160,1.81,4.6115,4.61160,10.000
10,187.310,1.32,4.4616,4.46170,10.000
10,187.460,0.91,4.3114,4.31150,10.000
10,187.610,0.60,4.1613,4.16140,10.000
10,187.760,0.35,4.0115,4.01160,10.000
10,187.910,0.18,3.8614,3.86150,10.000
10,188.060,0.06,3.7115,3.71160,10.000
10,188.210,-0.01,3.5612,3.56130,10.000
10,188.360,0.00,3.4114,3.41150,10.000
10,188.510,0.00,3.2615,3.26160,10.000
10,188.660,0.00,3.1114,3.11150,10.000
10,188.810,0.00,2.9613,2.96140,10.000
10,188.960,0.00,2.8114,2.81150,10.000
10,189.110,0.01,2.6614,2.66150,10.000
10,189.260,0.00,2.5112,2.51130,10.000
10,189.410,0.00,2.3612,2.36130,10.000
10,189.560,0.00,2.2114,2.21150,10.000
10,189.710,0.00,2.0615,2.06160,10.000
10,189.860,0.00,1.9113,1.91140,10.000
10,190.010,0.00,1.7613,1.76140,10.000
10,190.160,0.00,1.6114,1.61150,10.000
10,190.310,-0.01,1.4613,1.46140,10.000
10,190.460,0.00,1.3111,1.31120,10.000
10,190.610,0.00,1.1612,1.16130,10.000
10,190.760,0.00,1.0113,1.01140,10.000
10,190.910,0.00,0.8613,0.86140,10.000
10,191.060,0.00,0.7112,0.71130,10.000
10,191.210,0.00,0.5611,0.56120,10.000
10,191.360,-0.01,0.4113,0.41140,10.000
10,191.510,0.00,0.2612,0.26130,10.000
10,191.660,0.00,0.1111,0.11120,10.000
10,191.820,0.00,-0.0453,-0.04520,10.000
10,191.970,0.00,-0.0004,-0.00030,10.000
10,192.120,0.00,-0.0004,-0.00030,10.000
10,192.270,0.00,-0.0004,-0.00030,10.000
10,192.420,0.00,-0.0004,-0.00030,10.000
10,192.570,0.00,-0.0004,-0.00030,10.000
10,192.720,0.00,-0.0004,-0.00030,10.000
10,192.870,0.00,-0.0004,-0.00030,10.000
10,193.020,0.00,-0.0003,-0.00020,10.000
10,193.170,0.00,-0.0003,-0.00020,10.000
10,193.320,0.00,-0.0003,-0.00020,10.000
10,193.470,0.01,-0.0003,-0.00020,10.000
10,193.620,0.00,-0.0003,-0.00020,10.000
10,193.770,0.01,-0.0003,-0.00020,10.000
10,193.920,0.00,-0.0003,-0.00020,10.000
10,194.070,0.00,-0.0003,-0.00020,10.000
10,194.220,-0.01,-0.0003,-0.00020,10.000
10,194.370,0.00,-0.0003,-0.00020,10.000
10,194.520,-0.01,-0.0003,-0.00020,10.000
10,194.670,0.00,-0.0003,-0.00020,10.000
10,194.820,-0.01,-0.0003,-0.00020,10.000
10,194.990,0.00,-0.0002,-0.00010,10.000
10,195.140,0.00,-0.0002,-0.00010,10.000
10,195.290,0.01,-0.0002,-0.00010,10.000
10,195.440,0.00,-0.0002,-0.00010,10.000
10,195.590,0.00,-0.0002,-0.00010,10.000
10,195.740,0.00,-0.0002,-0.00010,10.000
10,195.890,-0.01,-0.0002,-0.00010,10.000
10,196.040,0.01,-0.0002,-0.00010,10.000
10,196.190,0.00,-0.0002,-0.00010,10.000
10,196.340,0.00,-0.0002,-0.00010,10.000
10,196.490,0.00,-0.0002,-0.00010,10.000
10,196.640,-0.01,-0.0002,-0.00010,10.000
10,196.790,0.01,-0.0002,-0.00010,10.000
10,196.940,0.00,-0.0002,-0.00010,10.000
10,197.090,0.01,-0.0002,-0.00010,10.000
10,197.240,0.01,-0.0002,-0.00010,10.000
10,197.390,-0.01,-0.0002,-0.00010,10.000
10,197.540,-0.01,-0.0001,0.00000,10.000
10,197.690,0.00,-0.0001,0.00000,10.000
10,197.840,0.01,-0.0001,0.00000,10.000
10,197.890,0.00,-0.0001,0.00000,10.000