File: calibDATA_loadcell/date_30:1:2018/MTSdata_date_1.30/radhen_10cyc_black_-20deg_1mms_1N.txt
""
"Test Method","Radhen_Load_Cntrl_Cmprsn_250N_12-7.msm"
"Sample I. D.","Sample1.mss"
"Specimen Number","14"

"TheCycle_Output ()","_Time (s)","_Load (N)","_Extension (mm)","RealTimeDepth (mm)","CycleNumber ()"

0,0.170,0.00,0.0000,0.00000,0.000
1,0.300,0.00,0.0613,0.06130,1.000
1,0.420,0.00,0.1816,0.18160,1.000
1,0.540,0.00,0.3017,0.30170,1.000
1,0.660,0.00,0.4215,0.42150,1.000
1,0.780,0.00,0.5416,0.54160,1.000
1,0.900,0.00,0.6617,0.66170,1.000
1,1.020,0.00,0.7816,0.78160,1.000
1,1.140,0.00,0.9017,0.90170,1.000
1,1.260,0.00,1.0217,1.02170,1.000
1,1.380,0.00,1.1418,1.14180,1.000
1,1.500,0.00,1.2617,1.26170,1.000
1,1.620,0.00,1.3817,1.38170,1.000
1,1.740,0.00,1.5019,1.50190,1.000
1,1.860,0.00,1.6218,1.62180,1.000
1,1.980,0.00,1.7418,1.74180,1.000
1,2.100,0.00,1.8618,1.86180,1.000
1,2.220,0.00,1.9818,1.98180,1.000
1,2.340,0.00,2.1017,2.10170,1.000
1,2.460,0.00,2.2219,2.22190,1.000
1,2.580,0.00,2.3419,2.34190,1.000
1,2.700,0.00,2.4619,2.46190,1.000
1,2.820,0.00,2.5818,2.58180,1.000
1,2.940,0.00,2.7018,2.70180,1.000
1,3.060,0.00,2.8218,2.82180,1.000
1,3.180,0.00,2.9420,2.94200,1.000
1,3.300,0.00,3.0619,3.06190,1.000
1,3.420,0.00,3.1820,3.18200,1.000
1,3.540,0.00,3.3018,3.30180,1.000
1,3.660,0.00,3.4219,3.42190,1.000
1,3.780,0.00,3.5420,3.54200,1.000
1,3.900,0.00,3.6620,3.66200,1.000
1,4.020,0.00,3.7819,3.78190,1.000
1,4.140,0.00,3.9020,3.90200,1.000
1,4.260,0.01,4.0219,4.02190,1.000
1,4.380,0.15,4.1418,4.14180,1.000
1,4.500,0.41,4.2619,4.26190,1.000
1,4.620,0.79,4.3820,4.38200,1.000
1,4.750,1.32,4.4903,4.49030,1.000
1,4.870,0.83,4.3888,4.38880,1.000
1,4.990,0.41,4.2686,4.26860,1.000
1,5.110,0.14,4.1487,4.14870,1.000
1,5.230,0.01,4.0285,4.02850,1.000
1,5.350,0.00,3.9085,3.90850,1.000
1,5.470,0.00,3.7885,3.78850,1.000
1,5.590,0.00,3.6685,3.66850,1.000
1,5.710,0.00,3.5485,3.54850,1.000
1,5.830,0.00,3.4285,3.42850,1.000
1,5.950,0.00,3.3083,3.30830,1.000
1,6.070,0.00,3.1887,3.18870,1.000
1,6.190,-0.01,3.0686,3.06860,1.000
1,6.310,0.00,2.9486,2.94860,1.000
1,6.430,0.00,2.8285,2.82850,1.000
1,6.550,0.00,2.7083,2.70830,1.000
1,6.670,0.00,2.5884,2.58840,1.000
1,6.790,0.00,2.4684,2.46840,1.000
1,6.910,0.00,2.3485,2.34850,1.000
1,7.030,0.00,2.2285,2.22850,1.000
1,7.150,0.00,2.1083,2.10830,1.000
1,7.270,-0.01,1.9883,1.98830,1.000
1,7.390,0.00,1.8684,1.86840,1.000
1,7.510,0.00,1.7483,1.74830,1.000
1,7.630,0.00,1.6284,1.62840,1.000
1,7.750,0.00,1.5083,1.50830,1.000
1,7.870,0.00,1.3883,1.38830,1.000
1,7.990,0.00,1.2682,1.26820,1.000
1,8.110,0.00,1.1484,1.14840,1.000
1,8.230,0.00,1.0283,1.02830,1.000
1,8.350,0.00,0.9083,0.90830,1.000
1,8.470,0.00,0.7883,0.78830,1.000
1,8.590,0.00,0.6681,0.66810,1.000
1,8.710,0.00,0.5482,0.54820,1.000
1,8.830,0.00,0.4281,0.42810,1.000
1,8.950,0.00,0.3082,0.30820,1.000
1,9.070,0.00,0.1881,0.18810,1.000
1,9.190,0.00,0.0680,0.06800,1.000
1,9.330,0.00,-0.0501,-0.05010,1.000
1,9.450,0.00,-0.0005,-0.00050,1.000
1,9.570,0.00,-0.0002,-0.00020,1.000
1,9.690,0.00,-0.0002,-0.00020,1.000
1,9.810,0.00,-0.0002,-0.00020,1.000
1,9.930,0.00,-0.0002,-0.00020,1.000
1,10.050,0.00,-0.0002,-0.00020,1.000
1,10.170,0.00,-0.0002,-0.00020,1.000
1,10.290,0.00,-0.0002,-0.00020,1.000
1,10.410,0.00,-0.0002,-0.00020,1.000
1,10.530,0.00,-0.0002,-0.00020,1.000
1,10.650,0.00,-0.0002,-0.00020,1.000
1,10.770,0.00,-0.0002,-0.00020,1.000
1,10.890,0.00,-0.0002,-0.00020,1.000
1,11.010,0.00,-0.0002,-0.00020,1.000
1,11.130,0.00,-0.0002,-0.00020,1.000
1,11.250,0.00,-0.0002,-0.00020,1.000
1,11.370,0.00,-0.0002,-0.00020,1.000
1,11.490,0.00,-0.0002,-0.00020,1.000
1,11.610,0.00,-0.0002,-0.00020,1.000
1,11.730,0.00,-0.0002,-0.00020,1.000
1,11.850,0.00,-0.0002,-0.00020,1.000
1,11.970,0.00,-0.0002,-0.00020,1.000
1,12.090,0.00,-0.0002,-0.00020,1.000
1,12.210,0.00,-0.0002,-0.00020,1.000
1,12.330,0.00,-0.0002,-0.00020,1.000
1,12.470,0.00,-0.0002,-0.00020,1.000
1,12.590,0.00,-0.0002,-0.00020,1.000
1,12.710,0.00,-0.0002,-0.00020,1.000
1,12.830,0.00,-0.0002,-0.00020,1.000
1,12.950,0.00,-0.0002,-0.00020,1.000
1,13.070,0.00,-0.0002,-0.00020,1.000
1,13.190,0.00,-0.0001,-0.00010,1.000
1,13.310,-0.01,-0.0001,-0.00010,1.000
1,13.430,0.00,-0.0001,-0.00010,1.000
1,13.550,0.00,-0.0001,-0.00010,1.000
1,13.670,0.00,-0.0001,-0.00010,1.000
1,13.790,0.00,-0.0001,-0.00010,1.000
1,13.910,0.00,-0.0001,-0.00010,1.000
1,14.030,0.00,-0.0001,-0.00010,1.000
1,14.150,0.00,-0.0001,-0.00010,1.000
1,14.270,0.00,-0.0001,-0.00010,1.000
1,14.390,0.00,-0.0001,-0.00010,1.000
1,14.510,0.00,-0.0001,-0.00010,1.000
1,14.630,0.00,-0.0001,-0.00010,1.000
1,14.750,0.00,-0.0001,-0.00010,1.000
1,14.870,0.00,-0.0001,-0.00010,1.000
1,14.990,0.00,-0.0001,-0.00010,1.000
1,15.110,0.00,-0.0001,-0.00010,1.000
1,15.230,0.00,-0.0001,-0.00010,1.000
1,15.350,0.00,-0.0001,-0.00010,1.000
2,15.570,-0.01,0.0414,0.04140,2.000
2,15.690,-0.01,0.1615,0.16150,2.000
2,15.810,-0.01,0.2817,0.28170,2.000
2,15.930,-0.01,0.4017,0.40170,2.000
2,16.050,-0.01,0.5216,0.52160,2.000
2,16.170,-0.01,0.6416,0.64160,2.000
2,16.290,-0.01,0.7617,0.76170,2.000
2,16.410,-0.01,0.8817,0.88170,2.000
2,16.530,-0.01,1.0017,1.00170,2.000
2,16.650,-0.01,1.1218,1.12180,2.000
2,16.770,-0.01,1.2417,1.24170,2.000
2,16.890,-0.01,1.3617,1.36170,2.000
2,17.010,-0.01,1.4817,1.48170,2.000
2,17.130,-0.01,1.6018,1.60180,2.000
2,17.250,-0.01,1.7218,1.72180,2.000
2,17.370,-0.01,1.8418,1.84180,2.000
2,17.490,-0.02,1.9618,1.96180,2.000
2,17.610,-0.01,2.0817,2.08170,2.000
2,17.730,-0.01,2.2017,2.20170,2.000
2,17.850,-0.01,2.3218,2.32180,2.000
2,17.970,-0.01,2.4419,2.44190,2.000
2,18.090,-0.01,2.5617,2.56170,2.000
2,18.210,-0.01,2.6817,2.68170,2.000
2,18.330,-0.01,2.8017,2.80170,2.000
2,18.450,-0.01,2.9218,2.92180,2.000
2,18.570,-0.01,3.0418,3.04180,2.000
2,18.690,-0.01,3.1619,3.16190,2.000
2,18.810,-0.01,3.2818,3.28180,2.000
2,18.930,-0.01,3.4016,3.40160,2.000
2,19.050,-0.01,3.5219,3.52190,2.000
2,19.170,-0.01,3.6417,3.64170,2.000
2,19.290,-0.01,3.7617,3.76170,2.000
2,19.410,-0.01,3.8818,3.88180,2.000
2,19.530,-0.01,4.0018,4.00180,2.000
2,19.650,0.11,4.1218,4.12180,2.000
2,19.770,0.34,4.2417,4.24170,2.000
2,19.890,0.70,4.3618,4.36180,2.000
2,20.020,1.25,4.4861,4.48610,2.000
2,20.140,0.91,4.4087,4.40870,2.000
2,20.260,0.45,4.2886,4.28860,2.000
2,20.380,0.17,4.1687,4.16870,2.000
2,20.500,0.02,4.0487,4.04870,2.000
2,20.620,-0.01,3.9286,3.92860,2.000
2,20.740,-0.01,3.8086,3.80860,2.000
2,20.860,-0.01,3.6885,3.68850,2.000
2,20.980,-0.01,3.5686,3.56860,2.000
2,21.100,-0.01,3.4485,3.44850,2.000
2,21.220,-0.01,3.3284,3.32840,2.000
2,21.340,-0.01,3.2086,3.20860,2.000
2,21.460,-0.01,3.0886,3.08860,2.000
2,21.580,-0.01,2.9685,2.96850,2.000
2,21.700,-0.01,2.8486,2.84860,2.000
2,21.820,-0.01,2.7285,2.72850,2.000
2,21.940,-0.01,2.6084,2.60840,2.000
2,22.060,-0.01,2.4885,2.48850,2.000
2,22.180,0.00,2.3684,2.36840,2.000
2,22.300,-0.01,2.2485,2.24850,2.000
2,22.420,-0.01,2.1284,2.12840,2.000
2,22.540,-0.02,2.0083,2.00830,2.000
2,22.660,-0.01,1.8885,1.88850,2.000
2,22.780,-0.02,1.7684,1.76840,2.000
2,22.900,-0.01,1.6485,1.64850,2.000
2,23.020,-0.01,1.5285,1.52850,2.000
2,23.140,-0.01,1.4084,1.40840,2.000
2,23.260,-0.01,1.2883,1.28830,2.000
2,23.380,-0.01,1.1684,1.16840,2.000
2,23.500,-0.01,1.0485,1.04850,2.000
2,23.620,-0.01,0.9284,0.92840,2.000
2,23.740,-0.01,0.8084,0.80840,2.000
2,23.860,-0.01,0.6883,0.68830,2.000
2,23.980,-0.01,0.5684,0.56840,2.000
2,24.100,-0.01,0.4483,0.44830,2.000
2,24.220,-0.01,0.3285,0.32850,2.000
2,24.340,-0.01,0.2083,0.20830,2.000
2,24.460,-0.01,0.0883,0.08830,2.000
2,24.600,-0.01,-0.0460,-0.04600,2.000
2,24.720,-0.01,-0.0010,-0.00100,2.000
2,24.840,-0.01,-0.0002,-0.00020,2.000
2,24.960,-0.01,-0.0002,-0.00020,2.000
2,25.080,-0.01,-0.0002,-0.00020,2.000
2,25.200,-0.01,-0.0002,-0.00020,2.000
2,25.320,-0.01,-0.0002,-0.00020,2.000
2,25.440,-0.01,-0.0002,-0.00020,2.000
2,25.560,-0.01,-0.0002,-0.00020,2.000
2,25.680,-0.01,-0.0002,-0.00020,2.000
2,25.800,-0.01,-0.0002,-0.00020,2.000
2,25.920,-0.01,-0.0002,-0.00020,2.000
2,26.040,-0.01,-0.0002,-0.00020,2.000
2,26.160,-0.01,-0.0002,-0.00020,2.000
2,26.280,-0.01,-0.0002,-0.00020,2.000
2,26.400,-0.02,-0.0002,-0.00020,2.000
2,26.520,-0.01,-0.0002,-0.00020,2.000
2,26.640,-0.01,-0.0002,-0.00020,2.000
2,26.760,-0.01,-0.0002,-0.00020,2.000
2,26.880,-0.01,-0.0002,-0.00020,2.000
2,27.000,-0.01,-0.0002,-0.00020,2.000
2,27.120,-0.01,-0.0002,-0.00020,2.000
2,27.240,-0.01,-0.0002,-0.00020,2.000
2,27.360,-0.01,-0.0002,-0.00020,2.000
2,27.480,-0.01,-0.0002,-0.00020,2.000
2,27.600,-0.01,-0.0002,-0.00020,2.000
2,27.730,-0.01,-0.0002,-0.00020,2.000
2,27.850,-0.01,-0.0002,-0.00020,2.000
2,27.970,-0.01,-0.0002,-0.00020,2.000
2,28.090,-0.01,-0.0002,-0.00020,2.000
2,28.210,-0.01,-0.0002,-0.00020,2.000
2,28.330,-0.01,-0.0002,-0.00020,2.000
2,28.450,-0.01,-0.0002,-0.00020,2.000
2,28.570,-0.01,-0.0002,-0.00020,2.000
2,28.690,-0.01,-0.0002,-0.00020,2.000
2,28.810,-0.01,-0.0001,-0.00010,2.000
2,28.930,-0.01,-0.0001,-0.00010,2.000
2,29.050,-0.01,-0.0001,-0.00010,2.000
2,29.170,-0.02,-0.0001,-0.00010,2.000
2,29.290,-0.01,-0.0001,-0.00010,2.000
2,29.410,-0.01,-0.0001,-0.00010,2.000
2,29.530,-0.02,-0.0001,-0.00010,2.000
2,29.650,-0.01,-0.0001,-0.00010,2.000
2,29.770,-0.01,-0.0001,-0.00010,2.000
2,29.890,-0.01,-0.0001,-0.00010,2.000
2,30.010,-0.01,-0.0001,-0.00010,2.000
2,30.130,-0.01,-0.0001,-0.00010,2.000
2,30.250,-0.01,-0.0001,-0.00010,2.000
2,30.370,-0.01,-0.0001,-0.00010,2.000
2,30.490,-0.01,-0.0001,-0.00010,2.000
2,30.610,-0.01,-0.0001,-0.00010,2.000
3,30.820,0.00,0.0113,0.01130,3.000
3,30.940,0.00,0.1306,0.13060,3.000
3,31.060,0.00,0.2508,0.25080,3.000
3,31.180,0.00,0.3708,0.37080,3.000
3,31.300,0.00,0.4907,0.49070,3.000
3,31.420,0.01,0.6108,0.61080,3.000
3,31.540,0.00,0.7308,0.73080,3.000
3,31.660,0.00,0.8508,0.85080,3.000
3,31.780,0.00,0.9707,0.97070,3.000
3,31.900,0.00,1.0909,1.09090,3.000
3,32.020,0.01,1.2109,1.21090,3.000
3,32.140,0.00,1.3307,1.33070,3.000
3,32.260,0.00,1.4509,1.45090,3.000
3,32.380,0.01,1.5708,1.57080,3.000
3,32.500,0.00,1.6908,1.69080,3.000
3,32.620,0.01,1.8109,1.81090,3.000
3,32.740,0.00,1.9308,1.93080,3.000
3,32.860,0.01,2.0508,2.05080,3.000
3,32.980,0.00,2.1708,2.17080,3.000
3,33.100,0.01,2.2910,2.29100,3.000
3,33.220,0.00,2.4109,2.41090,3.000
3,33.340,0.00,2.5308,2.53080,3.000
3,33.460,0.01,2.6508,2.65080,3.000
3,33.580,0.00,2.7709,2.77090,3.000
3,33.700,0.01,2.8909,2.89090,3.000
3,33.820,0.00,3.0109,3.01090,3.000
3,33.940,0.00,3.1310,3.13100,3.000
3,34.060,0.00,3.2510,3.25100,3.000
3,34.180,0.00,3.3707,3.37070,3.000
3,34.300,0.00,3.4908,3.49080,3.000
3,34.420,0.00,3.6109,3.61090,3.000
3,34.540,0.00,3.7308,3.73080,3.000
3,34.660,0.00,3.8509,3.85090,3.000
3,34.780,0.00,3.9709,3.97090,3.000
3,34.900,0.09,4.0908,4.09080,3.000
3,35.020,0.29,4.2109,4.21090,3.000
3,35.140,0.62,4.3310,4.33100,3.000
3,35.260,1.08,4.4510,4.45100,3.000
3,35.390,1.08,4.4374,4.43740,3.000
3,35.510,0.56,4.3176,4.31760,3.000
3,35.630,0.24,4.1976,4.19760,3.000
3,35.750,0.07,4.0775,4.07750,3.000
3,35.870,0.00,3.9575,3.95750,3.000
3,35.990,0.01,3.8374,3.83740,3.000
3,36.110,0.00,3.7173,3.71730,3.000
3,36.230,0.01,3.5975,3.59750,3.000
3,36.350,0.00,3.4775,3.47750,3.000
3,36.470,0.00,3.3573,3.35730,3.000
3,36.590,0.01,3.2376,3.23760,3.000
3,36.710,0.00,3.1175,3.11750,3.000
3,36.830,0.01,2.9974,2.99740,3.000
3,36.950,0.01,2.8773,2.87730,3.000
3,37.070,0.00,2.7573,2.75730,3.000
3,37.190,0.01,2.6372,2.63720,3.000
3,37.310,0.00,2.5172,2.51720,3.000
3,37.430,0.00,2.3974,2.39740,3.000
3,37.550,0.00,2.2773,2.27730,3.000
3,37.670,0.00,2.1574,2.15740,3.000
3,37.790,0.00,2.0371,2.03710,3.000
3,37.910,0.00,1.9172,1.91720,3.000
3,38.030,0.00,1.7972,1.79720,3.000
3,38.150,0.00,1.6774,1.67740,3.000
3,38.270,0.00,1.5574,1.55740,3.000
3,38.390,0.00,1.4372,1.43720,3.000
3,38.510,0.00,1.3172,1.31720,3.000
3,38.630,0.00,1.1972,1.19720,3.000
3,38.750,0.00,1.0774,1.07740,3.000
3,38.870,0.00,0.9573,0.95730,3.000
3,38.990,0.00,0.8374,0.83740,3.000
3,39.110,0.00,0.7172,0.71720,3.000
3,39.230,0.00,0.5972,0.59720,3.000
3,39.350,0.01,0.4772,0.47720,3.000
3,39.470,0.00,0.3572,0.35720,3.000
3,39.590,0.00,0.2372,0.23720,3.000
3,39.710,0.00,0.1170,0.11700,3.000
3,39.830,0.00,-0.0028,-0.00280,3.000
3,39.970,0.00,-0.0041,-0.00410,3.000
3,40.090,0.01,-0.0003,-0.00030,3.000
3,40.210,0.00,-0.0003,-0.00030,3.000
3,40.330,0.00,-0.0003,-0.00030,3.000
3,40.450,0.01,-0.0003,-0.00030,3.000
3,40.570,0.00,-0.0003,-0.00030,3.000
3,40.690,0.00,-0.0003,-0.00030,3.000
3,40.810,0.00,-0.0003,-0.00030,3.000
3,40.930,0.00,-0.0003,-0.00030,3.000
3,41.050,0.00,-0.0003,-0.00030,3.000
3,41.170,0.00,-0.0003,-0.00030,3.000
3,41.290,0.00,-0.0003,-0.00030,3.000
3,41.410,0.00,-0.0003,-0.00030,3.000
3,41.530,0.00,-0.0002,-0.00020,3.000
3,41.650,0.00,-0.0002,-0.00020,3.000
3,41.770,0.00,-0.0002,-0.00020,3.000
3,41.890,0.00,-0.0002,-0.00020,3.000
3,42.010,0.00,-0.0002,-0.00020,3.000
3,42.130,0.01,-0.0002,-0.00020,3.000
3,42.250,0.00,-0.0002,-0.00020,3.000
3,42.370,0.00,-0.0002,-0.00020,3.000
3,42.490,0.01,-0.0002,-0.00020,3.000
3,42.610,0.01,-0.0002,-0.00020,3.000
3,42.730,0.00,-0.0002,-0.00020,3.000
3,42.850,0.00,-0.0002,-0.00020,3.000
3,42.990,0.00,-0.0002,-0.00020,3.000
3,43.110,0.01,-0.0002,-0.00020,3.000
3,43.230,0.00,-0.0002,-0.00020,3.000
3,43.350,0.01,-0.0002,-0.00020,3.000
3,43.470,0.01,-0.0002,-0.00020,3.000
3,43.590,0.00,-0.0002,-0.00020,3.000
3,43.710,0.00,-0.0002,-0.00020,3.000
3,43.830,0.00,-0.0002,-0.00020,3.000
3,43.950,0.00,-0.0002,-0.00020,3.000
3,44.070,0.01,-0.0002,-0.00020,3.000
3,44.190,0.00,-0.0001,-0.00010,3.000
3,44.310,0.00,-0.0001,-0.00010,3.000
3,44.430,0.00,-0.0001,-0.00010,3.000
3,44.550,0.00,-0.0001,-0.00010,3.000
3,44.670,0.01,-0.0001,-0.00010,3.000
3,44.790,0.00,-0.0001,-0.00010,3.000
3,44.910,0.00,-0.0001,-0.00010,3.000
3,45.030,0.01,-0.0001,-0.00010,3.000
3,45.150,0.01,-0.0001,-0.00010,3.000
3,45.270,0.00,-0.0001,-0.00010,3.000
3,45.390,0.01,-0.0001,-0.00010,3.000
3,45.510,0.00,-0.0001,-0.00010,3.000
3,45.630,0.00,-0.0001,-0.00010,3.000
3,45.750,0.00,-0.0001,-0.00010,3.000
3,45.870,0.01,-0.0001,-0.00010,3.000
4,46.090,0.00,0.0051,0.00510,4.000
4,46.210,0.00,0.1205,0.12050,4.000
4,46.330,0.00,0.2406,0.24060,4.000
4,46.450,-0.01,0.3607,0.36070,4.000
4,46.570,0.00,0.4807,0.48070,4.000
4,46.690,-0.01,0.6008,0.60080,4.000
4,46.810,0.00,0.7207,0.72070,4.000
4,46.930,0.00,0.8406,0.84060,4.000
4,47.050,-0.01,0.9607,0.96070,4.000
4,47.170,-0.01,1.0808,1.08080,4.000
4,47.290,0.00,1.2008,1.20080,4.000
4,47.410,-0.01,1.3208,1.32080,4.000
4,47.530,-0.01,1.4407,1.44070,4.000
4,47.650,0.00,1.5608,1.56080,4.000
4,47.770,0.00,1.6808,1.68080,4.000
4,47.890,0.00,1.8007,1.80070,4.000
4,48.010,0.00,1.9207,1.92070,4.000
4,48.130,0.00,2.0407,2.04070,4.000
4,48.250,0.00,2.1608,2.16080,4.000
4,48.370,-0.01,2.2808,2.28080,4.000
4,48.490,0.00,2.4008,2.40080,4.000
4,48.610,0.00,2.5208,2.52080,4.000
4,48.730,-0.01,2.6407,2.64070,4.000
4,48.850,0.00,2.7607,2.76070,4.000
4,48.970,0.00,2.8807,2.88070,4.000
4,49.090,-0.01,3.0008,3.00080,4.000
4,49.210,-0.01,3.1208,3.12080,4.000
4,49.330,-0.01,3.2409,3.24090,4.000
4,49.450,0.00,3.3606,3.36060,4.000
4,49.570,0.00,3.4808,3.48080,4.000
4,49.690,0.00,3.6009,3.60090,4.000
4,49.810,-0.01,3.7207,3.72070,4.000
4,49.930,0.00,3.8408,3.84080,4.000
4,50.050,0.00,3.9607,3.96070,4.000
4,50.170,0.07,4.0808,4.08080,4.000
4,50.290,0.26,4.2008,4.20080,4.000
4,50.410,0.59,4.3209,4.32090,4.000
4,50.530,1.04,4.4409,4.44090,4.000
4,50.660,1.14,4.4477,4.44770,4.000
4,50.780,0.60,4.3277,4.32770,4.000
4,50.900,0.26,4.2077,4.20770,4.000
4,51.020,0.07,4.0876,4.08760,4.000
4,51.140,-0.01,3.9675,3.96750,4.000
4,51.260,-0.01,3.8476,3.84760,4.000
4,51.380,-0.01,3.7275,3.72750,4.000
4,51.500,0.00,3.6075,3.60750,4.000
4,51.620,0.00,3.4875,3.48750,4.000
4,51.740,-0.01,3.3673,3.36730,4.000
4,51.860,0.00,3.2475,3.24750,4.000
4,51.980,0.00,3.1276,3.12760,4.000
4,52.100,0.00,3.0076,3.00760,4.000
4,52.220,0.00,2.8876,2.88760,4.000
4,52.340,0.00,2.7675,2.76750,4.000
4,52.460,0.00,2.6474,2.64740,4.000
4,52.580,0.00,2.5274,2.52740,4.000
4,52.700,-0.01,2.4075,2.40750,4.000
4,52.820,-0.01,2.2875,2.28750,4.000
4,52.940,0.00,2.1674,2.16740,4.000
4,53.060,0.00,2.0473,2.04730,4.000
4,53.180,-0.01,1.9275,1.92750,4.000
4,53.300,0.00,1.8074,1.80740,4.000
4,53.420,0.00,1.6874,1.68740,4.000
4,53.540,0.00,1.5674,1.56740,4.000
4,53.660,0.00,1.4475,1.44750,4.000
4,53.780,0.00,1.3274,1.32740,4.000
4,53.900,0.00,1.2074,1.20740,4.000
4,54.020,0.00,1.0875,1.08750,4.000
4,54.140,0.00,0.9675,0.96750,4.000
4,54.260,0.00,0.8474,0.84740,4.000
4,54.380,0.00,0.7273,0.72730,4.000
4,54.500,-0.01,0.6074,0.60740,4.000
4,54.620,0.00,0.4874,0.48740,4.000
4,54.740,-0.01,0.3674,0.36740,4.000
4,54.860,0.00,0.2475,0.24750,4.000
4,54.980,-0.01,0.1272,0.12720,4.000
4,55.100,-0.01,0.0073,0.00730,4.000
4,55.240,0.00,-0.0087,-0.00870,4.000
4,55.360,0.00,-0.0002,-0.00020,4.000
4,55.480,0.00,-0.0002,-0.00020,4.000
4,55.600,0.00,-0.0002,-0.00020,4.000
4,55.720,-0.01,-0.0002,-0.00020,4.000
4,55.840,-0.01,-0.0002,-0.00020,4.000
4,55.960,-0.01,-0.0002,-0.00020,4.000
4,56.080,-0.01,-0.0002,-0.00020,4.000
4,56.200,0.00,-0.0002,-0.00020,4.000
4,56.320,-0.01,-0.0002,-0.00020,4.000
4,56.440,-0.01,-0.0002,-0.00020,4.000
4,56.560,0.00,-0.0002,-0.00020,4.000
4,56.680,0.00,-0.0002,-0.00020,4.000
4,56.800,0.00,-0.0002,-0.00020,4.000
4,56.920,0.00,-0.0002,-0.00020,4.000
4,57.040,-0.01,-0.0002,-0.00020,4.000
4,57.160,-0.01,-0.0002,-0.00020,4.000
4,57.280,-0.01,-0.0002,-0.00020,4.000
4,57.400,0.00,-0.0002,-0.00020,4.000
4,57.520,0.00,-0.0002,-0.00020,4.000
4,57.640,-0.01,-0.0002,-0.00020,4.000
4,57.760,-0.01,-0.0002,-0.00020,4.000
4,57.880,0.00,-0.0002,-0.00020,4.000
4,58.000,0.00,-0.0002,-0.00020,4.000
4,58.120,-0.01,-0.0002,-0.00020,4.000
4,58.260,-0.01,-0.0002,-0.00020,4.000
4,58.380,-0.01,-0.0002,-0.00020,4.000
4,58.500,0.00,-0.0002,-0.00020,4.000
4,58.620,0.00,-0.0002,-0.00020,4.000
4,58.740,0.00,-0.0002,-0.00020,4.000
4,58.860,-0.01,-0.0002,-0.00020,4.000
4,58.980,0.00,-0.0002,-0.00020,4.000
4,59.100,0.00,-0.0002,-0.00020,4.000
4,59.220,0.00,-0.0002,-0.00020,4.000
4,59.340,-0.01,-0.0002,-0.00020,4.000
4,59.460,-0.01,-0.0002,-0.00020,4.000
4,59.580,0.00,-0.0001,-0.00010,4.000
4,59.700,-0.01,-0.0001,-0.00010,4.000
4,59.820,0.00,-0.0001,-0.00010,4.000
4,59.940,0.00,-0.0001,-0.00010,4.000
4,60.060,-0.01,-0.0001,-0.00010,4.000
4,60.180,0.00,-0.0001,-0.00010,4.000
4,60.300,-0.01,-0.0001,-0.00010,4.000
4,60.420,-0.01,-0.0001,-0.00010,4.000
4,60.540,-0.01,-0.0001,-0.00010,4.000
4,60.660,0.00,-0.0001,-0.00010,4.000
4,60.780,-0.01,-0.0001,-0.00010,4.000
4,60.900,-0.01,-0.0001,-0.00010,4.000
4,61.020,0.00,-0.0001,-0.00010,4.000
4,61.140,0.00,-0.0001,-0.00010,4.000
5,61.360,0.01,0.0000,0.00000,5.000
5,61.480,0.01,0.1005,0.10050,5.000
5,61.600,0.01,0.2207,0.22070,5.000
5,61.720,0.01,0.3408,0.34080,5.000
5,61.840,0.01,0.4607,0.46070,5.000
5,61.960,0.01,0.5808,0.58080,5.000
5,62.080,0.01,0.7007,0.70070,5.000
5,62.200,0.01,0.8207,0.82070,5.000
5,62.320,0.01,0.9408,0.94080,5.000
5,62.440,0.01,1.0609,1.06090,5.000
5,62.560,0.01,1.1809,1.18090,5.000
5,62.680,0.01,1.3008,1.30080,5.000
5,62.800,0.01,1.4209,1.42090,5.000
5,62.920,0.01,1.5409,1.54090,5.000
5,63.040,0.01,1.6609,1.66090,5.000
5,63.160,0.01,1.7808,1.78080,5.000
5,63.280,0.01,1.9008,1.90080,5.000
5,63.400,0.01,2.0208,2.02080,5.000
5,63.520,0.02,2.1408,2.14080,5.000
5,63.640,0.01,2.2609,2.26090,5.000
5,63.760,0.01,2.3810,2.38100,5.000
5,63.880,0.01,2.5010,2.50100,5.000
5,64.000,0.01,2.6209,2.62090,5.000
5,64.120,0.01,2.7409,2.74090,5.000
5,64.240,0.01,2.8609,2.86090,5.000
5,64.360,0.01,2.9809,2.98090,5.000
5,64.480,0.01,3.1011,3.10110,5.000
5,64.600,0.01,3.2210,3.22100,5.000
5,64.720,0.01,3.3408,3.34080,5.000
5,64.840,0.01,3.4609,3.46090,5.000
5,64.960,0.01,3.5810,3.58100,5.000
5,65.080,0.01,3.7008,3.70080,5.000
5,65.200,0.01,3.8209,3.82090,5.000
5,65.320,0.01,3.9408,3.94080,5.000
5,65.440,0.06,4.0609,4.06090,5.000
5,65.560,0.23,4.1809,4.18090,5.000
5,65.680,0.53,4.3010,4.30100,5.000
5,65.800,0.96,4.4210,4.42100,5.000
5,65.940,1.10,4.4377,4.43770,5.000
5,66.060,0.58,4.3176,4.31760,5.000
5,66.180,0.24,4.1975,4.19750,5.000
5,66.300,0.08,4.0775,4.07750,5.000
5,66.420,0.01,3.9575,3.95750,5.000
5,66.540,0.01,3.8374,3.83740,5.000
5,66.660,0.01,3.7174,3.71740,5.000
5,66.780,0.01,3.5975,3.59750,5.000
5,66.900,0.01,3.4776,3.47760,5.000
5,67.020,0.01,3.3574,3.35740,5.000
5,67.140,0.01,3.2376,3.23760,5.000
5,67.260,0.01,3.1175,3.11750,5.000
5,67.380,0.01,2.9975,2.99750,5.000
5,67.500,0.01,2.8774,2.87740,5.000
5,67.620,0.01,2.7573,2.75730,5.000
5,67.740,0.01,2.6373,2.63730,5.000
5,67.860,0.01,2.5174,2.51740,5.000
5,67.980,0.01,2.3975,2.39750,5.000
5,68.100,0.01,2.2774,2.27740,5.000
5,68.220,0.01,2.1573,2.15730,5.000
5,68.340,0.01,2.0372,2.03720,5.000
5,68.460,0.01,1.9173,1.91730,5.000
5,68.580,0.01,1.7973,1.79730,5.000
5,68.700,0.01,1.6774,1.67740,5.000
5,68.820,0.01,1.5574,1.55740,5.000
5,68.940,0.01,1.4373,1.43730,5.000
5,69.060,0.01,1.3173,1.31730,5.000
5,69.180,0.01,1.1973,1.19730,5.000
5,69.300,0.02,1.0773,1.07730,5.000
5,69.420,0.01,0.9573,0.95730,5.000
5,69.540,0.01,0.8373,0.83730,5.000
5,69.660,0.01,0.7173,0.71730,5.000
5,69.780,0.01,0.5972,0.59720,5.000
5,69.900,0.01,0.4772,0.47720,5.000
5,70.020,0.01,0.3572,0.35720,5.000
5,70.140,0.01,0.2372,0.23720,5.000
5,70.260,0.01,0.1171,0.11710,5.000
5,70.380,0.01,-0.0027,-0.00270,5.000
5,70.510,0.01,-0.0100,-0.01000,5.000
5,70.630,0.01,-0.0003,-0.00030,5.000
5,70.750,0.01,-0.0003,-0.00030,5.000
5,70.870,0.02,-0.0003,-0.00030,5.000
5,70.990,0.01,-0.0003,-0.00030,5.000
5,71.110,0.01,-0.0003,-0.00030,5.000
5,71.230,0.01,-0.0003,-0.00030,5.000
5,71.350,0.01,-0.0003,-0.00030,5.000
5,71.470,0.01,-0.0003,-0.00030,5.000
5,71.590,0.01,-0.0003,-0.00030,5.000
5,71.710,0.01,-0.0003,-0.00030,5.000
5,71.830,0.01,-0.0003,-0.00030,5.000
5,71.950,0.01,-0.0003,-0.00030,5.000
5,72.070,0.01,-0.0003,-0.00030,5.000
5,72.190,0.01,-0.0003,-0.00030,5.000
5,72.310,0.01,-0.0003,-0.00030,5.000
5,72.430,0.01,-0.0002,-0.00020,5.000
5,72.550,0.01,-0.0002,-0.00020,5.000
5,72.670,0.01,-0.0002,-0.00020,5.000
5,72.790,0.01,-0.0002,-0.00020,5.000
5,72.910,0.01,-0.0002,-0.00020,5.000
5,73.030,0.01,-0.0002,-0.00020,5.000
5,73.150,0.01,-0.0002,-0.00020,5.000
5,73.270,0.01,-0.0002,-0.00020,5.000
5,73.390,0.01,-0.0002,-0.00020,5.000
5,73.530,0.01,-0.0002,-0.00020,5.000
5,73.650,0.01,-0.0002,-0.00020,5.000
5,73.770,0.01,-0.0002,-0.00020,5.000
5,73.890,0.01,-0.0002,-0.00020,5.000
5,74.010,0.01,-0.0002,-0.00020,5.000
5,74.130,0.01,-0.0002,-0.00020,5.000
5,74.250,0.01,-0.0002,-0.00020,5.000
5,74.370,0.01,-0.0002,-0.00020,5.000
5,74.490,0.01,-0.0002,-0.00020,5.000
5,74.610,0.01,-0.0002,-0.00020,5.000
5,74.730,0.01,-0.0002,-0.00020,5.000
5,74.850,0.01,-0.0002,-0.00020,5.000
5,74.970,0.01,-0.0002,-0.00020,5.000
5,75.090,0.01,-0.0001,-0.00010,5.000
5,75.210,0.01,-0.0001,-0.00010,5.000
5,75.330,0.01,-0.0001,-0.00010,5.000
5,75.450,0.01,-0.0001,-0.00010,5.000
5,75.570,0.01,-0.0001,-0.00010,5.000
5,75.690,0.01,-0.0001,-0.00010,5.000
5,75.810,0.01,-0.0001,-0.00010,5.000
5,75.930,0.01,-0.0001,-0.00010,5.000
5,76.050,0.01,-0.0001,-0.00010,5.000
5,76.170,0.01,-0.0001,-0.00010,5.000
5,76.290,0.01,-0.0001,-0.00010,5.000
5,76.410,0.01,-0.0001,-0.00010,5.000
6,76.620,0.00,0.0000,0.00000,6.000
6,76.740,0.00,0.1006,0.10060,6.000
6,76.860,0.00,0.2208,0.22080,6.000
6,76.980,0.00,0.3409,0.34090,6.000
6,77.100,0.00,0.4607,0.46070,6.000
6,77.220,0.00,0.5809,0.58090,6.000
6,77.340,0.00,0.7008,0.70080,6.000
6,77.460,0.00,0.8208,0.82080,6.000
6,77.580,0.00,0.9409,0.94090,6.000
6,77.700,0.00,1.0609,1.06090,6.000
6,77.820,0.00,1.1809,1.18090,6.000
6,77.940,0.00,1.3008,1.30080,6.000
6,78.060,0.00,1.4209,1.42090,6.000
6,78.180,0.00,1.5409,1.54090,6.000
6,78.300,0.00,1.6610,1.66100,6.000
6,78.420,0.00,1.7809,1.78090,6.000
6,78.540,0.00,1.9009,1.90090,6.000
6,78.660,0.00,2.0209,2.02090,6.000
6,78.780,0.00,2.1409,2.14090,6.000
6,78.900,0.00,2.2609,2.26090,6.000
6,79.020,0.00,2.3811,2.38110,6.000
6,79.140,0.00,2.5010,2.50100,6.000
6,79.260,0.00,2.6208,2.62080,6.000
6,79.380,0.00,2.7409,2.74090,6.000
6,79.500,0.00,2.8609,2.86090,6.000
6,79.620,0.00,2.9810,2.98100,6.000
6,79.740,0.00,3.1011,3.10110,6.000
6,79.860,0.00,3.2210,3.22100,6.000
6,79.980,0.00,3.3408,3.34080,6.000
6,80.100,0.00,3.4609,3.46090,6.000
6,80.220,0.00,3.5810,3.58100,6.000
6,80.340,0.00,3.7009,3.70090,6.000
6,80.460,0.00,3.8210,3.82100,6.000
6,80.580,0.00,3.9409,3.94090,6.000
6,80.700,0.05,4.0609,4.06090,6.000
6,80.820,0.22,4.1809,4.18090,6.000
6,80.940,0.52,4.3010,4.30100,6.000
6,81.060,0.95,4.4210,4.42100,6.000
6,81.190,1.25,4.4680,4.46800,6.000
6,81.310,0.67,4.3478,4.34780,6.000
6,81.430,0.30,4.2277,4.22770,6.000
6,81.550,0.09,4.1077,4.10770,6.000
6,81.670,0.00,3.9876,3.98760,6.000
6,81.790,0.00,3.8677,3.86770,6.000
6,81.910,0.00,3.7475,3.74750,6.000
6,82.030,0.00,3.6276,3.62760,6.000
6,82.150,0.00,3.5077,3.50770,6.000
6,82.270,-0.01,3.3875,3.38750,6.000
6,82.390,0.00,3.2676,3.26760,6.000
6,82.510,-0.01,3.1478,3.14780,6.000
6,82.630,0.00,3.0275,3.02750,6.000
6,82.750,0.00,2.9076,2.90760,6.000
6,82.870,-0.01,2.7875,2.78750,6.000
6,82.990,0.00,2.6674,2.66740,6.000
6,83.110,0.00,2.5475,2.54750,6.000
6,83.230,0.00,2.4275,2.42750,6.000
6,83.350,0.00,2.3075,2.30750,6.000
6,83.470,0.00,2.1875,2.18750,6.000
6,83.590,0.00,2.0674,2.06740,6.000
6,83.710,0.00,1.9475,1.94750,6.000
6,83.830,0.00,1.8274,1.82740,6.000
6,83.950,0.00,1.7073,1.70730,6.000
6,84.070,0.00,1.5874,1.58740,6.000
6,84.190,0.00,1.4674,1.46740,6.000
6,84.310,0.00,1.3474,1.34740,6.000
6,84.430,0.00,1.2273,1.22730,6.000
6,84.550,0.00,1.1074,1.10740,6.000
6,84.670,0.00,0.9875,0.98750,6.000
6,84.790,0.00,0.8674,0.86740,6.000
6,84.910,0.00,0.7474,0.74740,6.000
6,85.030,0.00,0.6274,0.62740,6.000
6,85.150,0.00,0.5074,0.50740,6.000
6,85.270,0.00,0.3872,0.38720,6.000
6,85.390,0.00,0.2674,0.26740,6.000
6,85.510,0.00,0.1471,0.14710,6.000
6,85.630,0.00,0.0272,0.02720,6.000
6,85.770,0.00,-0.0275,-0.02750,6.000
6,85.890,0.00,-0.0003,-0.00030,6.000
6,86.010,0.00,-0.0002,-0.00020,6.000
6,86.130,-0.01,-0.0003,-0.00030,6.000
6,86.250,0.00,-0.0002,-0.00020,6.000
6,86.370,0.00,-0.0002,-0.00020,6.000
6,86.490,0.00,-0.0002,-0.00020,6.000
6,86.610,0.00,-0.0002,-0.00020,6.000
6,86.730,0.00,-0.0002,-0.00020,6.000
6,86.850,0.00,-0.0002,-0.00020,6.000
6,86.970,0.00,-0.0002,-0.00020,6.000
6,87.090,0.00,-0.0002,-0.00020,6.000
6,87.210,0.00,-0.0002,-0.00020,6.000
6,87.330,0.00,-0.0002,-0.00020,6.000
6,87.450,0.00,-0.0002,-0.00020,6.000
6,87.570,0.00,-0.0002,-0.00020,6.000
6,87.690,0.00,-0.0002,-0.00020,6.000
6,87.810,0.00,-0.0002,-0.00020,6.000
6,87.930,0.00,-0.0002,-0.00020,6.000
6,88.050,0.00,-0.0002,-0.00020,6.000
6,88.170,0.00,-0.0002,-0.00020,6.000
6,88.290,-0.01,-0.0002,-0.00020,6.000
6,88.410,0.00,-0.0002,-0.00020,6.000
6,88.530,0.00,-0.0002,-0.00020,6.000
6,88.650,0.00,-0.0002,-0.00020,6.000
6,88.780,0.00,-0.0002,-0.00020,6.000
6,88.900,0.00,-0.0002,-0.00020,6.000
6,89.020,0.00,-0.0002,-0.00020,6.000
6,89.140,0.00,-0.0002,-0.00020,6.000
6,89.260,0.00,-0.0002,-0.00020,6.000
6,89.380,0.00,-0.0002,-0.00020,6.000
6,89.500,0.00,-0.0002,-0.00020,6.000
6,89.620,0.00,-0.0002,-0.00020,6.000
6,89.740,0.00,-0.0002,-0.00020,6.000
6,89.860,-0.01,-0.0002,-0.00020,6.000
6,89.980,0.00,-0.0002,-0.00020,6.000
6,90.100,0.00,-0.0002,-0.00020,6.000
6,90.220,-0.01,-0.0002,-0.00020,6.000
6,90.340,0.00,-0.0001,-0.00010,6.000
6,90.460,-0.01,-0.0001,-0.00010,6.000
6,90.580,-0.01,-0.0001,-0.00010,6.000
6,90.700,0.00,-0.0001,-0.00010,6.000
6,90.820,0.00,-0.0001,-0.00010,6.000
6,90.940,0.00,-0.0001,-0.00010,6.000
6,91.060,0.00,-0.0001,-0.00010,6.000
6,91.180,0.00,-0.0001,-0.00010,6.000
6,91.300,0.00,-0.0001,-0.00010,6.000
6,91.420,0.00,-0.0001,-0.00010,6.000
6,91.540,0.00,-0.0001,-0.00010,6.000
6,91.660,0.00,-0.0001,-0.00010,6.000
6,91.870,-0.01,0.0000,0.00000,6.000
7,92.000,-0.01,0.0605,0.06050,7.000
7,92.120,0.00,0.1806,0.18060,7.000
7,92.240,-0.01,0.3008,0.30080,7.000
7,92.360,0.00,0.4208,0.42080,7.000
7,92.480,-0.01,0.5407,0.54070,7.000
7,92.600,0.00,0.6607,0.66070,7.000
7,92.720,0.00,0.7808,0.78080,7.000
7,92.840,0.00,0.9008,0.90080,7.000
7,92.960,-0.01,1.0208,1.02080,7.000
7,93.080,-0.01,1.1410,1.14100,7.000
7,93.200,0.00,1.2609,1.26090,7.000
7,93.320,0.00,1.3809,1.38090,7.000
7,93.440,-0.01,1.5009,1.50090,7.000
7,93.560,-0.01,1.6209,1.62090,7.000
7,93.680,0.00,1.7409,1.74090,7.000
7,93.800,0.00,1.8608,1.86080,7.000
7,93.920,-0.01,1.9809,1.98090,7.000
7,94.040,-0.01,2.1008,2.10080,7.000
7,94.160,0.00,2.2210,2.22100,7.000
7,94.280,0.00,2.3409,2.34090,7.000
7,94.400,-0.01,2.4610,2.46100,7.000
7,94.520,-0.01,2.5809,2.58090,7.000
7,94.640,-0.01,2.7009,2.70090,7.000
7,94.760,0.00,2.8208,2.82080,7.000
7,94.880,-0.01,2.9410,2.94100,7.000
7,95.000,-0.01,3.0610,3.06100,7.000
7,95.120,-0.01,3.1810,3.18100,7.000
7,95.240,-0.01,3.3007,3.30070,7.000
7,95.360,-0.01,3.4208,3.42080,7.000
7,95.480,-0.01,3.5410,3.54100,7.000
7,95.600,-0.01,3.6608,3.66080,7.000
7,95.720,0.00,3.7809,3.78090,7.000
7,95.840,-0.01,3.9009,3.90090,7.000
7,95.960,0.01,4.0208,4.02080,7.000
7,96.080,0.14,4.1409,4.14090,7.000
7,96.200,0.40,4.2608,4.26080,7.000
7,96.320,0.79,4.3810,4.38100,7.000
7,96.450,1.31,4.4892,4.48920,7.000
7,96.570,0.83,4.3878,4.38780,7.000
7,96.690,0.40,4.2677,4.26770,7.000
7,96.810,0.14,4.1476,4.14760,7.000
7,96.930,0.01,4.0275,4.02750,7.000
7,97.050,-0.01,3.9075,3.90750,7.000
7,97.170,-0.01,3.7876,3.78760,7.000
7,97.290,-0.01,3.6675,3.66750,7.000
7,97.410,0.00,3.5476,3.54760,7.000
7,97.530,-0.01,3.4275,3.42750,7.000
7,97.650,-0.01,3.3075,3.30750,7.000
7,97.770,0.00,3.1877,3.18770,7.000
7,97.890,-0.01,3.0675,3.06750,7.000
7,98.010,-0.01,2.9476,2.94760,7.000
7,98.130,-0.01,2.8275,2.82750,7.000
7,98.250,-0.01,2.7075,2.70750,7.000
7,98.370,0.00,2.5875,2.58750,7.000
7,98.490,-0.01,2.4674,2.46740,7.000
7,98.610,-0.01,2.3475,2.34750,7.000
7,98.730,-0.01,2.2275,2.22750,7.000
7,98.850,0.00,2.1074,2.10740,7.000
7,98.970,-0.01,1.9874,1.98740,7.000
7,99.090,-0.01,1.8675,1.86750,7.000
7,99.210,0.00,1.7473,1.74730,7.000
7,99.330,-0.01,1.6274,1.62740,7.000
7,99.450,0.00,1.5075,1.50750,7.000
7,99.570,-0.01,1.3873,1.38730,7.000
7,99.690,-0.01,1.2673,1.26730,7.000
7,99.810,-0.01,1.1474,1.14740,7.000
7,99.930,0.00,1.0275,1.02750,7.000
7,100.050,-0.01,0.9074,0.90740,7.000
7,100.170,-0.01,0.7873,0.78730,7.000
7,100.290,-0.01,0.6673,0.66730,7.000
7,100.410,-0.01,0.5474,0.54740,7.000
7,100.530,-0.01,0.4273,0.42730,7.000
7,100.650,0.00,0.3074,0.30740,7.000
7,100.770,0.00,0.1873,0.18730,7.000
7,100.890,0.00,0.0672,0.06720,7.000
7,101.030,-0.01,-0.0511,-0.05110,7.000
7,101.150,-0.01,-0.0003,-0.00030,7.000
7,101.270,-0.01,-0.0003,-0.00030,7.000
7,101.390,-0.01,-0.0003,-0.00030,7.000
7,101.510,-0.01,-0.0003,-0.00030,7.000
7,101.630,-0.01,-0.0003,-0.00030,7.000
7,101.750,0.00,-0.0003,-0.00030,7.000
7,101.870,0.00,-0.0003,-0.00030,7.000
7,101.990,-0.01,-0.0003,-0.00030,7.000
7,102.110,-0.01,-0.0003,-0.00030,7.000
7,102.230,-0.01,-0.0003,-0.00030,7.000
7,102.350,-0.01,-0.0003,-0.00030,7.000
7,102.470,-0.01,-0.0003,-0.00030,7.000
7,102.590,-0.01,-0.0003,-0.00030,7.000
7,102.710,-0.01,-0.0003,-0.00030,7.000
7,102.830,-0.01,-0.0003,-0.00030,7.000
7,102.950,-0.01,-0.0003,-0.00030,7.000
7,103.070,0.00,-0.0003,-0.00030,7.000
7,103.190,-0.01,-0.0002,-0.00020,7.000
7,103.310,-0.01,-0.0002,-0.00020,7.000
7,103.430,-0.01,-0.0002,-0.00020,7.000
7,103.550,0.00,-0.0002,-0.00020,7.000
7,103.670,-0.01,-0.0002,-0.00020,7.000
7,103.790,0.00,-0.0002,-0.00020,7.000
7,103.910,-0.01,-0.0002,-0.00020,7.000
7,104.030,-0.01,-0.0002,-0.00020,7.000
7,104.160,-0.01,-0.0002,-0.00020,7.000
7,104.280,-0.01,-0.0002,-0.00020,7.000
7,104.400,-0.01,-0.0002,-0.00020,7.000
7,104.520,0.00,-0.0002,-0.00020,7.000
7,104.640,-0.01,-0.0002,-0.00020,7.000
7,104.760,-0.01,-0.0002,-0.00020,7.000
7,104.880,-0.01,-0.0002,-0.00020,7.000
7,105.000,0.00,-0.0002,-0.00020,7.000
7,105.120,-0.01,-0.0002,-0.00020,7.000
7,105.240,-0.01,-0.0002,-0.00020,7.000
7,105.360,-0.01,-0.0002,-0.00020,7.000
7,105.480,-0.01,-0.0002,-0.00020,7.000
7,105.600,-0.01,-0.0002,-0.00020,7.000
7,105.720,-0.01,-0.0002,-0.00020,7.000
7,105.840,0.00,-0.0002,-0.00020,7.000
7,105.960,-0.01,-0.0001,-0.00010,7.000
7,106.080,0.00,-0.0001,-0.00010,7.000
7,106.200,0.00,-0.0001,-0.00010,7.000
7,106.320,0.00,-0.0001,-0.00010,7.000
7,106.440,-0.01,-0.0001,-0.00010,7.000
7,106.560,0.00,-0.0001,-0.00010,7.000
7,106.680,0.00,-0.0001,-0.00010,7.000
7,106.800,-0.01,-0.0001,-0.00010,7.000
7,106.920,0.00,-0.0001,-0.00010,7.000
7,107.040,0.00,-0.0001,-0.00010,7.000
8,107.260,0.00,0.0214,0.02140,8.000
8,107.380,0.00,0.1417,0.14170,8.000
8,107.500,0.00,0.2618,0.26180,8.000
8,107.620,0.00,0.3819,0.38190,8.000
8,107.740,0.00,0.5019,0.50190,8.000
8,107.860,0.00,0.6219,0.62190,8.000
8,107.980,0.00,0.7419,0.74190,8.000
8,108.100,0.00,0.8618,0.86180,8.000
8,108.220,0.00,0.9819,0.98190,8.000
8,108.340,0.00,1.1020,1.10200,8.000
8,108.460,0.00,1.2219,1.22190,8.000
8,108.580,0.00,1.3418,1.34180,8.000
8,108.700,0.00,1.4618,1.46180,8.000
8,108.820,0.00,1.5819,1.58190,8.000
8,108.940,0.00,1.7020,1.70200,8.000
8,109.060,0.00,1.8218,1.82180,8.000
8,109.180,0.00,1.9420,1.94200,8.000
8,109.300,0.00,2.0618,2.06180,8.000
8,109.420,0.00,2.1819,2.18190,8.000
8,109.540,0.00,2.3019,2.30190,8.000
8,109.660,0.00,2.4219,2.42190,8.000
8,109.780,0.00,2.5419,2.54190,8.000
8,109.900,0.00,2.6619,2.66190,8.000
8,110.020,0.00,2.7819,2.78190,8.000
8,110.140,0.00,2.9020,2.90200,8.000
8,110.260,0.00,3.0220,3.02200,8.000
8,110.380,0.00,3.1421,3.14210,8.000
8,110.500,0.00,3.2621,3.26210,8.000
8,110.620,0.00,3.3817,3.38170,8.000
8,110.740,0.00,3.5020,3.50200,8.000
8,110.860,0.00,3.6220,3.62200,8.000
8,110.980,0.00,3.7419,3.74190,8.000
8,111.100,0.00,3.8619,3.86190,8.000
8,111.220,0.00,3.9818,3.98180,8.000
8,111.340,0.09,4.1019,4.10190,8.000
8,111.460,0.31,4.2218,4.22180,8.000
8,111.580,0.65,4.3419,4.34190,8.000
8,111.710,1.17,4.4721,4.47210,8.000
8,111.830,1.03,4.4288,4.42880,8.000
8,111.950,0.53,4.3088,4.30880,8.000
8,112.070,0.22,4.1887,4.18870,8.000
8,112.190,0.05,4.0686,4.06860,8.000
8,112.310,0.00,3.9486,3.94860,8.000
8,112.430,-0.01,3.8286,3.82860,8.000
8,112.550,-0.01,3.7086,3.70860,8.000
8,112.670,0.00,3.5886,3.58860,8.000
8,112.790,0.00,3.4686,3.46860,8.000
8,112.910,0.00,3.3485,3.34850,8.000
8,113.030,0.00,3.2287,3.22870,8.000
8,113.150,0.00,3.1086,3.10860,8.000
8,113.270,0.00,2.9887,2.98870,8.000
8,113.390,0.00,2.8686,2.86860,8.000
8,113.510,0.00,2.7484,2.74840,8.000
8,113.630,0.00,2.6285,2.62850,8.000
8,113.750,0.00,2.5085,2.50850,8.000
8,113.870,0.00,2.3884,2.38840,8.000
8,113.990,0.00,2.2686,2.26860,8.000
8,114.110,0.00,2.1484,2.14840,8.000
8,114.230,0.00,2.0283,2.02830,8.000
8,114.350,0.00,1.9085,1.90850,8.000
8,114.470,0.00,1.7884,1.78840,8.000
8,114.590,0.00,1.6685,1.66850,8.000
8,114.710,-0.01,1.5485,1.54850,8.000
8,114.830,0.00,1.4284,1.42840,8.000
8,114.950,0.00,1.3084,1.30840,8.000
8,115.070,0.00,1.1885,1.18850,8.000
8,115.190,0.00,1.0686,1.06860,8.000
8,115.310,0.00,0.9484,0.94840,8.000
8,115.430,0.00,0.8284,0.82840,8.000
8,115.550,0.00,0.7082,0.70820,8.000
8,115.670,0.00,0.5883,0.58830,8.000
8,115.790,0.00,0.4683,0.46830,8.000
8,115.910,0.00,0.3484,0.34840,8.000
8,116.030,0.00,0.2284,0.22840,8.000
8,116.150,0.00,0.1082,0.10820,8.000
8,116.290,0.00,-0.0317,-0.03170,8.000
8,116.410,0.00,-0.0002,-0.00020,8.000
8,116.530,0.00,-0.0003,-0.00030,8.000
8,116.650,0.00,-0.0003,-0.00030,8.000
8,116.770,0.00,-0.0003,-0.00030,8.000
8,116.890,0.00,-0.0003,-0.00030,8.000
8,117.010,0.00,-0.0003,-0.00030,8.000
8,117.130,0.00,-0.0003,-0.00030,8.000
8,117.250,0.00,-0.0003,-0.00030,8.000
8,117.370,0.00,-0.0003,-0.00030,8.000
8,117.490,0.00,-0.0003,-0.00030,8.000
8,117.610,0.00,-0.0003,-0.00030,8.000
8,117.730,0.00,-0.0003,-0.00030,8.000
8,117.850,0.00,-0.0003,-0.00030,8.000
8,117.970,0.00,-0.0002,-0.00020,8.000
8,118.090,0.00,-0.0002,-0.00020,8.000
8,118.210,0.00,-0.0002,-0.00020,8.000
8,118.330,0.00,-0.0002,-0.00020,8.000
8,118.450,0.00,-0.0002,-0.00020,8.000
8,118.570,0.00,-0.0002,-0.00020,8.000
8,118.690,0.00,-0.0002,-0.00020,8.000
8,118.810,0.00,-0.0002,-0.00020,8.000
8,118.930,0.00,-0.0002,-0.00020,8.000
8,119.050,0.00,-0.0002,-0.00020,8.000
8,119.170,0.00,-0.0002,-0.00020,8.000
8,119.290,0.00,-0.0002,-0.00020,8.000
8,119.420,0.00,-0.0002,-0.00020,8.000
8,119.540,0.00,-0.0002,-0.00020,8.000
8,119.660,0.00,-0.0002,-0.00020,8.000
8,119.780,0.00,-0.0002,-0.00020,8.000
8,119.900,0.00,-0.0002,-0.00020,8.000
8,120.020,-0.01,-0.0002,-0.00020,8.000
8,120.140,0.00,-0.0002,-0.00020,8.000
8,120.260,0.00,-0.0002,-0.00020,8.000
8,120.380,0.00,-0.0002,-0.00020,8.000
8,120.500,0.00,-0.0002,-0.00020,8.000
8,120.620,0.00,-0.0001,-0.00010,8.000
8,120.740,0.00,-0.0001,-0.00010,8.000
8,120.860,0.00,-0.0001,-0.00010,8.000
8,120.980,0.00,-0.0001,-0.00010,8.000
8,121.100,0.00,-0.0001,-0.00010,8.000
8,121.220,0.00,-0.0001,-0.00010,8.000
8,121.340,0.00,-0.0001,-0.00010,8.000
8,121.460,0.00,-0.0001,-0.00010,8.000
8,121.580,0.00,-0.0001,-0.00010,8.000
8,121.700,0.00,-0.0001,-0.00010,8.000
8,121.820,0.00,-0.0001,-0.00010,8.000
8,121.940,0.00,-0.0001,-0.00010,8.000
8,122.060,0.00,-0.0001,-0.00010,8.000
8,122.180,0.00,-0.0001,-0.00010,8.000
8,122.300,0.00,-0.0001,-0.00010,8.000
9,122.520,0.01,0.0000,0.00000,9.000
9,122.640,0.01,0.1006,0.10060,9.000
9,122.760,0.00,0.2208,0.22080,9.000
9,122.880,0.00,0.3409,0.34090,9.000
9,123.000,0.00,0.4607,0.46070,9.000
9,123.120,0.00,0.5807,0.58070,9.000
9,123.240,0.00,0.7008,0.70080,9.000
9,123.360,0.00,0.8209,0.82090,9.000
9,123.480,0.00,0.9408,0.94080,9.000
9,123.600,0.00,1.0609,1.06090,9.000
9,123.720,0.00,1.1808,1.18080,9.000
9,123.840,0.00,1.3008,1.30080,9.000
9,123.960,0.00,1.4209,1.42090,9.000
9,124.080,0.00,1.5409,1.54090,9.000
9,124.200,0.00,1.6610,1.66100,9.000
9,124.320,0.00,1.7808,1.78080,9.000
9,124.440,0.00,1.9008,1.90080,9.000
9,124.560,0.00,2.0208,2.02080,9.000
9,124.680,0.00,2.1408,2.14080,9.000
9,124.800,0.00,2.2609,2.26090,9.000
9,124.920,0.00,2.3809,2.38090,9.000
9,125.040,0.00,2.5009,2.50090,9.000
9,125.160,0.00,2.6209,2.62090,9.000
9,125.280,0.00,2.7408,2.74080,9.000
9,125.400,0.00,2.8609,2.86090,9.000
9,125.520,0.00,2.9809,2.98090,9.000
9,125.640,0.00,3.1009,3.10090,9.000
9,125.760,0.00,3.2210,3.22100,9.000
9,125.880,0.00,3.3408,3.34080,9.000
9,126.000,0.00,3.4610,3.46100,9.000
9,126.120,0.00,3.5810,3.58100,9.000
9,126.240,0.00,3.7009,3.70090,9.000
9,126.360,0.00,3.8209,3.82090,9.000
9,126.480,0.00,3.9409,3.94090,9.000
9,126.600,0.05,4.0608,4.06080,9.000
9,126.720,0.22,4.1808,4.18080,9.000
9,126.840,0.52,4.3010,4.30100,9.000
9,126.960,0.95,4.4210,4.42100,9.000
9,127.090,1.26,4.4680,4.46800,9.000
9,127.210,0.68,4.3477,4.34770,9.000
9,127.330,0.31,4.2277,4.22770,9.000
9,127.450,0.09,4.1076,4.10760,9.000
9,127.570,-0.01,3.9877,3.98770,9.000
9,127.690,0.00,3.8677,3.86770,9.000
9,127.810,0.00,3.7476,3.74760,9.000
9,127.930,0.00,3.6276,3.62760,9.000
9,128.050,0.00,3.5076,3.50760,9.000
9,128.170,0.00,3.3875,3.38750,9.000
9,128.290,0.00,3.2676,3.26760,9.000
9,128.410,0.00,3.1478,3.14780,9.000
9,128.530,0.00,3.0275,3.02750,9.000
9,128.650,0.00,2.9076,2.90760,9.000
9,128.770,0.00,2.7876,2.78760,9.000
9,128.890,0.00,2.6674,2.66740,9.000
9,129.010,0.00,2.5474,2.54740,9.000
9,129.130,-0.01,2.4275,2.42750,9.000
9,129.250,0.00,2.3074,2.30740,9.000
9,129.370,0.00,2.1876,2.18760,9.000
9,129.490,0.00,2.0674,2.06740,9.000
9,129.610,0.00,1.9475,1.94750,9.000
9,129.730,0.00,1.8273,1.82730,9.000
9,129.850,0.01,1.7074,1.70740,9.000
9,129.970,0.00,1.5875,1.58750,9.000
9,130.090,0.00,1.4674,1.46740,9.000
9,130.210,0.00,1.3475,1.34750,9.000
9,130.330,0.01,1.2274,1.22740,9.000
9,130.450,0.00,1.1074,1.10740,9.000
9,130.570,0.00,0.9874,0.98740,9.000
9,130.690,0.00,0.8674,0.86740,9.000
9,130.810,0.00,0.7474,0.74740,9.000
9,130.930,0.00,0.6274,0.62740,9.000
9,131.050,0.00,0.5074,0.50740,9.000
9,131.170,0.00,0.3873,0.38730,9.000
9,131.290,0.00,0.2674,0.26740,9.000
9,131.410,0.00,0.1472,0.14720,9.000
9,131.530,0.00,0.0273,0.02730,9.000
9,131.670,0.01,-0.0296,-0.02960,9.000
9,131.790,0.00,-0.0003,-0.00030,9.000
9,131.910,0.00,-0.0003,-0.00030,9.000
9,132.030,0.00,-0.0003,-0.00030,9.000
9,132.150,0.00,-0.0003,-0.00030,9.000
9,132.270,0.00,-0.0003,-0.00030,9.000
9,132.390,0.00,-0.0003,-0.00030,9.000
9,132.510,0.00,-0.0003,-0.00030,9.000
9,132.630,0.00,-0.0003,-0.00030,9.000
9,132.750,0.00,-0.0003,-0.00030,9.000
9,132.870,0.00,-0.0003,-0.00030,9.000
9,132.990,0.00,-0.0003,-0.00030,9.000
9,133.110,0.00,-0.0003,-0.00030,9.000
9,133.230,0.00,-0.0003,-0.00030,9.000
9,133.350,0.00,-0.0003,-0.00030,9.000
9,133.470,0.00,-0.0003,-0.00030,9.000
9,133.590,0.00,-0.0003,-0.00030,9.000
9,133.710,0.00,-0.0002,-0.00020,9.000
9,133.830,0.00,-0.0002,-0.00020,9.000
9,133.950,0.00,-0.0002,-0.00020,9.000
9,134.070,0.00,-0.0002,-0.00020,9.000
9,134.190,0.00,-0.0002,-0.00020,9.000
9,134.310,0.00,-0.0002,-0.00020,9.000
9,134.430,0.00,-0.0002,-0.00020,9.000
9,134.550,0.00,-0.0002,-0.00020,9.000
9,134.690,0.00,-0.0002,-0.00020,9.000
9,134.810,0.00,-0.0002,-0.00020,9.000
9,134.930,0.00,-0.0002,-0.00020,9.000
9,135.050,0.00,-0.0002,-0.00020,9.000
9,135.170,-0.01,-0.0002,-0.00020,9.000
9,135.290,0.00,-0.0002,-0.00020,9.000
9,135.410,0.00,-0.0002,-0.00020,9.000
9,135.530,0.00,-0.0002,-0.00020,9.000
9,135.650,0.00,-0.0002,-0.00020,9.000
9,135.770,0.00,-0.0002,-0.00020,9.000
9,135.890,0.00,-0.0002,-0.00020,9.000
9,136.010,0.00,-0.0002,-0.00020,9.000
9,136.130,0.00,-0.0002,-0.00020,9.000
9,136.250,0.00,-0.0002,-0.00020,9.000
9,136.370,0.00,-0.0001,-0.00010,9.000
9,136.490,0.00,-0.0001,-0.00010,9.000
9,136.610,0.00,-0.0001,-0.00010,9.000
9,136.730,0.00,-0.0001,-0.00010,9.000
9,136.850,0.00,-0.0001,-0.00010,9.000
9,136.970,0.00,-0.0001,-0.00010,9.000
9,137.090,0.00,-0.0001,-0.00010,9.000
9,137.210,0.00,-0.0001,-0.00010,9.000
9,137.330,0.00,-0.0001,-0.00010,9.000
9,137.450,0.00,-0.0001,-0.00010,9.000
9,137.570,0.00,-0.0001,-0.00010,9.000
10,137.780,0.00,0.0000,0.00000,10.000
10,137.900,0.00,0.0906,0.09060,10.000
10,138.020,0.00,0.2108,0.21080,10.000
10,138.140,0.00,0.3308,0.33080,10.000
10,138.260,0.00,0.4508,0.45080,10.000
10,138.380,0.00,0.5708,0.57080,10.000
10,138.500,0.00,0.6907,0.69070,10.000
10,138.620,0.00,0.8107,0.81070,10.000
10,138.740,0.00,0.9307,0.93070,10.000
10,138.860,0.00,1.0508,1.05080,10.000
10,138.980,0.00,1.1709,1.17090,10.000
10,139.100,0.00,1.2908,1.29080,10.000
10,139.220,0.00,1.4109,1.41090,10.000
10,139.340,0.00,1.5309,1.53090,10.000
10,139.460,0.00,1.6507,1.65070,10.000
10,139.580,0.00,1.7708,1.77080,10.000
10,139.700,0.00,1.8908,1.89080,10.000
10,139.820,0.00,2.0107,2.01070,10.000
10,139.940,0.00,2.1307,2.13070,10.000
10,140.060,0.00,2.2508,2.25080,10.000
10,140.180,0.00,2.3709,2.37090,10.000
10,140.300,0.00,2.4909,2.49090,10.000
10,140.420,0.00,2.6108,2.61080,10.000
10,140.540,0.00,2.7308,2.73080,10.000
10,140.660,0.00,2.8508,2.85080,10.000
10,140.780,0.00,2.9708,2.97080,10.000
10,140.900,0.00,3.0909,3.09090,10.000
10,141.020,0.00,3.2109,3.21090,10.000
10,141.140,0.00,3.3308,3.33080,10.000
10,141.260,0.00,3.4508,3.45080,10.000
10,141.380,0.00,3.5709,3.57090,10.000
10,141.500,0.00,3.6908,3.69080,10.000
10,141.620,0.00,3.8108,3.81080,10.000
10,141.740,0.00,3.9309,3.93090,10.000
10,141.860,0.04,4.0508,4.05080,10.000
10,141.980,0.20,4.1708,4.17080,10.000
10,142.100,0.49,4.2908,4.29080,10.000
10,142.220,0.91,4.4109,4.41090,10.000
10,142.350,1.30,4.4787,4.47870,10.000
10,142.470,0.72,4.3596,4.35960,10.000
10,142.590,0.33,4.2397,4.23970,10.000
10,142.710,0.10,4.1196,4.11960,10.000
10,142.830,0.00,3.9995,3.99950,10.000
10,142.950,0.00,3.8796,3.87960,10.000
10,143.070,0.00,3.7595,3.75950,10.000
10,143.190,0.00,3.6395,3.63950,10.000
10,143.310,0.00,3.5196,3.51960,10.000
10,143.430,0.00,3.3994,3.39940,10.000
10,143.550,0.00,3.2795,3.27950,10.000
10,143.670,0.00,3.1597,3.15970,10.000
10,143.790,0.00,3.0395,3.03950,10.000
10,143.910,-0.01,2.9194,2.91940,10.000
10,144.030,0.00,2.7995,2.79950,10.000
10,144.150,0.00,2.6794,2.67940,10.000
10,144.270,0.00,2.5593,2.55930,10.000
10,144.390,0.00,2.4395,2.43950,10.000
10,144.510,0.00,2.3195,2.31950,10.000
10,144.630,0.00,2.1994,2.19940,10.000
10,144.750,0.00,2.0792,2.07920,10.000
10,144.870,0.00,1.9593,1.95930,10.000
10,144.990,0.00,1.8394,1.83940,10.000
10,145.110,0.00,1.7193,1.71930,10.000
10,145.230,0.00,1.5994,1.59940,10.000
10,145.350,0.00,1.4793,1.47930,10.000
10,145.470,0.00,1.3593,1.35930,10.000
10,145.590,0.00,1.2393,1.23930,10.000
10,145.710,0.00,1.1193,1.11930,10.000
10,145.830,0.00,0.9993,0.99930,10.000
10,145.950,0.01,0.8793,0.87930,10.000
10,146.070,0.00,0.7593,0.75930,10.000
10,146.190,0.00,0.6393,0.63930,10.000
10,146.310,0.00,0.5192,0.51920,10.000
10,146.430,0.00,0.3992,0.39920,10.000
10,146.550,0.00,0.2792,0.27920,10.000
10,146.670,0.00,0.1591,0.15910,10.000
10,146.790,0.00,0.0390,0.03900,10.000
10,146.930,0.00,-0.0366,-0.03660,10.000
10,147.050,0.00,-0.0003,-0.00030,10.000
10,147.170,0.00,-0.0003,-0.00030,10.000
10,147.290,0.00,-0.0003,-0.00030,10.000
10,147.410,0.00,-0.0003,-0.00030,10.000
10,147.530,0.00,-0.0003,-0.00030,10.000
10,147.650,0.00,-0.0003,-0.00030,10.000
10,147.770,0.00,-0.0003,-0.00030,10.000
10,147.890,0.00,-0.0003,-0.00030,10.000
10,148.010,0.00,-0.0003,-0.00030,10.000
10,148.130,0.00,-0.0003,-0.00030,10.000
10,148.250,0.00,-0.0003,-0.00030,10.000
10,148.370,0.00,-0.0003,-0.00030,10.000
10,148.490,0.00,-0.0003,-0.00030,10.000
10,148.610,0.00,-0.0003,-0.00030,10.000
10,148.730,0.00,-0.0003,-0.00030,10.000
10,148.850,0.00,-0.0003,-0.00030,10.000
10,148.970,0.00,-0.0003,-0.00030,10.000
10,149.090,0.00,-0.0002,-0.00020,10.000
10,149.210,-0.01,-0.0002,-0.00020,10.000
10,149.330,0.00,-0.0002,-0.00020,10.000
10,149.450,0.00,-0.0002,-0.00020,10.000
10,149.570,0.00,-0.0002,-0.00020,10.000
10,149.690,0.00,-0.0002,-0.00020,10.000
10,149.810,0.00,-0.0002,-0.00020,10.000
10,149.950,0.00,-0.0002,-0.00020,10.000
10,150.070,0.00,-0.0002,-0.00020,10.000
10,150.190,0.00,-0.0002,-0.00020,10.000
10,150.310,0.00,-0.0002,-0.00020,10.000
10,150.430,0.00,-0.0002,-0.00020,10.000
10,150.550,-0.01,-0.0002,-0.00020,10.000
10,150.670,0.00,-0.0002,-0.00020,10.000
10,150.790,0.00,-0.0002,-0.00020,10.000
10,150.910,0.00,-0.0002,-0.00020,10.000
10,151.030,0.00,-0.0002,-0.00020,10.000
10,151.150,0.00,-0.0002,-0.00020,10.000
10,151.270,0.00,-0.0002,-0.00020,10.000
10,151.390,0.00,-0.0002,-0.00020,10.000
10,151.510,0.00,-0.0002,-0.00020,10.000
10,151.630,0.00,-0.0002,-0.00020,10.000
10,151.750,0.00,-0.0001,-0.00010,10.000
10,151.870,0.00,-0.0001,-0.00010,10.000
10,151.990,0.00,-0.0001,-0.00010,10.000
10,152.110,0.00,-0.0001,-0.00010,10.000
10,152.230,0.00,-0.0001,-0.00010,10.000
10,152.350,0.00,-0.0001,-0.00010,10.000
10,152.470,0.00,-0.0001,-0.00010,10.000
10,152.590,0.00,-0.0001,-0.00010,10.000
10,152.710,0.00,-0.0001,-0.00010,10.000
10,152.830,0.00,-0.0001,-0.00010,10.000
10,152.930,0.00,-0.0001,-0.00010,10.000