File: calibDATA_loadcell/date_30:1:2018/MTSdata_date_1.30/radhen_10cyc_black_20deg_1mms_5N.txt
""
"Test Method","Radhen_Load_Cntrl_Cmprsn_250N_12-7.msm"
"Sample I. D.","Sample1.mss"
"Specimen Number","16"

"TheCycle_Output ()","_Time (s)","_Load (N)","_Extension (mm)","RealTimeDepth (mm)","CycleNumber ()"

0,0.180,0.04,0.0000,0.00000,0.000
1,0.300,0.02,0.0577,0.05770,1.000
1,0.410,0.02,0.1677,0.16770,1.000
1,0.520,0.02,0.2777,0.27770,1.000
1,0.630,0.03,0.3879,0.38790,1.000
1,0.740,0.01,0.4979,0.49790,1.000
1,0.850,0.02,0.6079,0.60790,1.000
1,0.960,0.02,0.7178,0.71780,1.000
1,1.070,0.03,0.8279,0.82790,1.000
1,1.180,0.02,0.9379,0.93790,1.000
1,1.290,0.02,1.0477,1.04770,1.000
1,1.400,0.02,1.1577,1.15770,1.000
1,1.510,0.03,1.2679,1.26790,1.000
1,1.620,0.02,1.3780,1.37800,1.000
1,1.730,0.01,1.4878,1.48780,1.000
1,1.840,0.02,1.5978,1.59780,1.000
1,1.950,0.01,1.7079,1.70790,1.000
1,2.060,0.02,1.8179,1.81790,1.000
1,2.170,0.01,1.9278,1.92780,1.000
1,2.280,0.02,2.0378,2.03780,1.000
1,2.390,0.02,2.1481,2.14810,1.000
1,2.500,0.00,2.2580,2.25800,1.000
1,2.610,0.01,2.3677,2.36770,1.000
1,2.720,0.02,2.4778,2.47780,1.000
1,2.830,0.02,2.5879,2.58790,1.000
1,2.940,0.02,2.6978,2.69780,1.000
1,3.050,0.02,2.8079,2.80790,1.000
1,3.160,0.02,2.9178,2.91780,1.000
1,3.270,0.02,3.0279,3.02790,1.000
1,3.380,0.10,3.1378,3.13780,1.000
1,3.490,0.24,3.2478,3.24780,1.000
1,3.600,0.51,3.3579,3.35790,1.000
1,3.710,0.89,3.4680,3.46800,1.000
1,3.820,1.35,3.5779,3.57790,1.000
1,3.930,1.98,3.6878,3.68780,1.000
1,4.040,2.73,3.7979,3.79790,1.000
1,4.150,3.66,3.9079,3.90790,1.000
1,4.260,4.79,4.0179,4.01790,1.000
1,4.380,5.46,4.0609,4.06090,1.000
1,4.490,3.90,3.9506,3.95060,1.000
1,4.600,2.76,3.8406,3.84060,1.000
1,4.710,1.91,3.7305,3.73050,1.000
1,4.820,1.30,3.6207,3.62070,1.000
1,4.930,0.82,3.5108,3.51080,1.000
1,5.040,0.47,3.4006,3.40060,1.000
1,5.150,0.21,3.2907,3.29070,1.000
1,5.260,0.09,3.1807,3.18070,1.000
1,5.370,0.01,3.0704,3.07040,1.000
1,5.480,0.02,2.9604,2.96040,1.000
1,5.590,0.02,2.8505,2.85050,1.000
1,5.700,0.02,2.7406,2.74060,1.000
1,5.810,0.02,2.6305,2.63050,1.000
1,5.920,0.02,2.5205,2.52050,1.000
1,6.030,0.02,2.4103,2.41030,1.000
1,6.140,0.01,2.3005,2.30050,1.000
1,6.250,0.01,2.1907,2.19070,1.000
1,6.360,0.02,2.0804,2.08040,1.000
1,6.470,0.02,1.9704,1.97040,1.000
1,6.580,0.02,1.8605,1.86050,1.000
1,6.690,0.02,1.7505,1.75050,1.000
1,6.800,0.02,1.6402,1.64020,1.000
1,6.910,0.02,1.5305,1.53050,1.000
1,7.020,0.02,1.4205,1.42050,1.000
1,7.130,0.02,1.3104,1.31040,1.000
1,7.240,0.02,1.2003,1.20030,1.000
1,7.350,0.03,1.0904,1.09040,1.000
1,7.460,0.02,0.9805,0.98050,1.000
1,7.570,0.03,0.8704,0.87040,1.000
1,7.680,0.01,0.7604,0.76040,1.000
1,7.790,0.01,0.6505,0.65050,1.000
1,7.900,0.01,0.5405,0.54050,1.000
1,8.010,0.02,0.4303,0.43030,1.000
1,8.120,0.02,0.3203,0.32030,1.000
1,8.230,0.02,0.2104,0.21040,1.000
1,8.340,0.02,0.1003,0.10030,1.000
1,8.450,0.02,-0.0096,-0.00960,1.000
1,8.570,0.02,-0.0117,-0.01170,1.000
1,8.680,0.01,-0.0003,-0.00030,1.000
1,8.790,0.02,-0.0003,-0.00030,1.000
1,8.900,0.02,-0.0003,-0.00030,1.000
1,9.010,0.03,-0.0003,-0.00030,1.000
1,9.120,0.02,-0.0003,-0.00030,1.000
1,9.230,0.01,-0.0003,-0.00030,1.000
1,9.340,0.02,-0.0003,-0.00030,1.000
1,9.450,0.01,-0.0003,-0.00030,1.000
1,9.560,0.00,-0.0003,-0.00030,1.000
1,9.670,0.00,-0.0002,-0.00020,1.000
1,9.780,0.02,-0.0002,-0.00020,1.000
1,9.890,0.02,-0.0002,-0.00020,1.000
1,10.000,0.02,-0.0002,-0.00020,1.000
1,10.110,0.02,-0.0002,-0.00020,1.000
1,10.220,0.02,-0.0002,-0.00020,1.000
1,10.330,0.02,-0.0002,-0.00020,1.000
1,10.440,0.02,-0.0002,-0.00020,1.000
1,10.550,0.02,-0.0002,-0.00020,1.000
1,10.660,0.02,-0.0002,-0.00020,1.000
1,10.770,0.01,-0.0002,-0.00020,1.000
1,10.880,0.01,-0.0002,-0.00020,1.000
1,10.990,0.02,-0.0002,-0.00020,1.000
1,11.100,0.01,-0.0002,-0.00020,1.000
1,11.210,0.02,-0.0002,-0.00020,1.000
1,11.320,0.02,-0.0002,-0.00020,1.000
1,11.430,0.02,-0.0002,-0.00020,1.000
1,11.540,0.02,-0.0002,-0.00020,1.000
1,11.670,0.01,-0.0002,-0.00020,1.000
1,11.780,0.02,-0.0002,-0.00020,1.000
1,11.890,0.02,-0.0002,-0.00020,1.000
1,12.000,0.02,-0.0002,-0.00020,1.000
1,12.110,0.02,-0.0002,-0.00020,1.000
1,12.220,0.01,-0.0001,-0.00010,1.000
1,12.330,0.02,-0.0001,-0.00010,1.000
1,12.440,0.02,-0.0001,-0.00010,1.000
1,12.550,0.01,-0.0001,-0.00010,1.000
1,12.660,0.02,-0.0001,-0.00010,1.000
1,12.770,0.01,-0.0001,-0.00010,1.000
1,12.880,0.02,-0.0001,-0.00010,1.000
1,12.990,0.02,-0.0001,-0.00010,1.000
1,13.100,0.02,-0.0001,-0.00010,1.000
1,13.210,0.02,-0.0001,-0.00010,1.000
1,13.320,0.01,-0.0001,-0.00010,1.000
1,13.430,0.02,-0.0001,-0.00010,1.000
1,13.540,0.02,-0.0001,-0.00010,1.000
1,13.650,0.02,-0.0001,-0.00010,1.000
1,13.760,0.02,-0.0001,-0.00010,1.000
1,13.870,0.02,-0.0001,-0.00010,1.000
1,13.980,0.02,-0.0001,-0.00010,1.000
1,14.090,0.02,-0.0001,-0.00010,1.000
1,14.200,0.02,-0.0001,-0.00010,1.000
1,14.310,0.02,-0.0001,-0.00010,1.000
1,14.420,0.03,-0.0001,-0.00010,1.000
1,14.530,0.02,-0.0001,-0.00010,1.000
2,14.740,0.01,0.0174,0.01740,2.000
2,14.850,-0.01,0.1277,0.12770,2.000
2,14.960,-0.01,0.2375,0.23750,2.000
2,15.070,0.01,0.3478,0.34780,2.000
2,15.180,-0.01,0.4578,0.45780,2.000
2,15.290,0.00,0.5678,0.56780,2.000
2,15.400,0.00,0.6777,0.67770,2.000
2,15.510,-0.01,0.7878,0.78780,2.000
2,15.620,0.01,0.8979,0.89790,2.000
2,15.730,0.00,1.0077,1.00770,2.000
2,15.840,0.00,1.1177,1.11770,2.000
2,15.950,0.00,1.2279,1.22790,2.000
2,16.060,-0.01,1.3378,1.33780,2.000
2,16.170,0.00,1.4479,1.44790,2.000
2,16.280,0.00,1.5577,1.55770,2.000
2,16.390,-0.01,1.6679,1.66790,2.000
2,16.500,-0.01,1.7777,1.77770,2.000
2,16.610,0.01,1.8878,1.88780,2.000
2,16.720,-0.01,1.9978,1.99780,2.000
2,16.830,-0.02,2.1080,2.10800,2.000
2,16.940,0.00,2.2180,2.21800,2.000
2,17.050,0.00,2.3277,2.32770,2.000
2,17.160,0.00,2.4377,2.43770,2.000
2,17.270,-0.01,2.5481,2.54810,2.000
2,17.380,0.00,2.6579,2.65790,2.000
2,17.490,0.01,2.7677,2.76770,2.000
2,17.600,-0.01,2.8778,2.87780,2.000
2,17.710,0.00,2.9878,2.98780,2.000
2,17.820,0.03,3.0978,3.09780,2.000
2,17.930,0.17,3.2078,3.20780,2.000
2,18.040,0.39,3.3180,3.31800,2.000
2,18.150,0.71,3.4280,3.42800,2.000
2,18.260,1.17,3.5379,3.53790,2.000
2,18.370,1.72,3.6477,3.64770,2.000
2,18.480,2.42,3.7578,3.75780,2.000
2,18.590,3.30,3.8679,3.86790,2.000
2,18.700,4.36,3.9779,3.97790,2.000
2,18.820,5.56,4.0697,4.06970,2.000
2,18.930,4.20,3.9726,3.97260,2.000
2,19.040,2.98,3.8627,3.86270,2.000
2,19.150,2.06,3.7527,3.75270,2.000
2,19.260,1.39,3.6424,3.64240,2.000
2,19.370,0.91,3.5326,3.53260,2.000
2,19.480,0.52,3.4227,3.42270,2.000
2,19.590,0.25,3.3127,3.31270,2.000
2,19.700,0.08,3.2025,3.20250,2.000
2,19.810,-0.01,3.0926,3.09260,2.000
2,19.920,0.00,2.9826,2.98260,2.000
2,20.030,0.00,2.8726,2.87260,2.000
2,20.140,0.00,2.7623,2.76230,2.000
2,20.250,-0.01,2.6524,2.65240,2.000
2,20.360,0.00,2.5427,2.54270,2.000
2,20.470,0.00,2.4324,2.43240,2.000
2,20.580,0.01,2.3223,2.32230,2.000
2,20.690,0.00,2.2126,2.21260,2.000
2,20.800,0.00,2.1026,2.10260,2.000
2,20.910,-0.01,1.9926,1.99260,2.000
2,21.020,-0.01,1.8823,1.88230,2.000
2,21.130,0.00,1.7723,1.77230,2.000
2,21.240,0.00,1.6625,1.66250,2.000
2,21.350,0.00,1.5523,1.55230,2.000
2,21.460,0.00,1.4423,1.44230,2.000
2,21.570,-0.01,1.3325,1.33250,2.000
2,21.680,0.00,1.2225,1.22250,2.000
2,21.790,0.00,1.1123,1.11230,2.000
2,21.900,-0.01,1.0023,1.00230,2.000
2,22.010,-0.01,0.8924,0.89240,2.000
2,22.120,-0.01,0.7824,0.78240,2.000
2,22.230,0.00,0.6724,0.67240,2.000
2,22.340,-0.02,0.5623,0.56230,2.000
2,22.450,-0.01,0.4524,0.45240,2.000
2,22.560,0.00,0.3423,0.34230,2.000
2,22.670,-0.02,0.2323,0.23230,2.000
2,22.780,0.00,0.1222,0.12220,2.000
2,22.890,0.00,0.0124,0.01240,2.000
2,23.010,0.00,-0.0305,-0.03050,2.000
2,23.120,0.00,-0.0003,-0.00030,2.000
2,23.230,0.00,-0.0003,-0.00030,2.000
2,23.340,-0.01,-0.0003,-0.00030,2.000
2,23.450,0.00,-0.0003,-0.00030,2.000
2,23.560,0.00,-0.0003,-0.00030,2.000
2,23.670,0.00,-0.0003,-0.00030,2.000
2,23.780,0.00,-0.0003,-0.00030,2.000
2,23.890,0.00,-0.0003,-0.00030,2.000
2,24.000,-0.01,-0.0003,-0.00030,2.000
2,24.110,0.00,-0.0003,-0.00030,2.000
2,24.220,0.00,-0.0003,-0.00030,2.000
2,24.330,0.00,-0.0002,-0.00020,2.000
2,24.440,0.00,-0.0002,-0.00020,2.000
2,24.550,-0.02,-0.0002,-0.00020,2.000
2,24.660,0.00,-0.0002,-0.00020,2.000
2,24.770,0.00,-0.0002,-0.00020,2.000
2,24.880,-0.01,-0.0002,-0.00020,2.000
2,24.990,0.00,-0.0002,-0.00020,2.000
2,25.100,-0.01,-0.0002,-0.00020,2.000
2,25.210,-0.01,-0.0002,-0.00020,2.000
2,25.320,0.00,-0.0002,-0.00020,2.000
2,25.430,0.01,-0.0002,-0.00020,2.000
2,25.540,-0.01,-0.0002,-0.00020,2.000
2,25.650,0.00,-0.0002,-0.00020,2.000
2,25.760,0.00,-0.0002,-0.00020,2.000
2,25.870,-0.01,-0.0002,-0.00020,2.000
2,25.980,0.00,-0.0002,-0.00020,2.000
2,26.110,-0.01,-0.0002,-0.00020,2.000
2,26.220,0.00,-0.0002,-0.00020,2.000
2,26.330,0.00,-0.0002,-0.00020,2.000
2,26.440,0.00,-0.0002,-0.00020,2.000
2,26.550,-0.01,-0.0002,-0.00020,2.000
2,26.660,0.01,-0.0002,-0.00020,2.000
2,26.770,0.00,-0.0002,-0.00020,2.000
2,26.880,0.00,-0.0001,-0.00010,2.000
2,26.990,-0.02,-0.0001,-0.00010,2.000
2,27.100,-0.01,-0.0001,-0.00010,2.000
2,27.210,-0.03,-0.0001,-0.00010,2.000
2,27.320,-0.02,-0.0001,-0.00010,2.000
2,27.430,0.00,-0.0001,-0.00010,2.000
2,27.540,0.01,-0.0001,-0.00010,2.000
2,27.650,-0.01,-0.0001,-0.00010,2.000
2,27.760,0.00,-0.0001,-0.00010,2.000
2,27.870,-0.01,-0.0001,-0.00010,2.000
2,27.980,-0.01,-0.0001,-0.00010,2.000
2,28.090,0.00,-0.0001,-0.00010,2.000
2,28.200,-0.01,-0.0001,-0.00010,2.000
2,28.310,0.00,-0.0001,-0.00010,2.000
2,28.420,0.00,-0.0001,-0.00010,2.000
2,28.530,-0.01,-0.0001,-0.00010,2.000
2,28.640,-0.01,-0.0001,-0.00010,2.000
2,28.750,-0.02,-0.0001,-0.00010,2.000
2,28.860,-0.02,-0.0001,-0.00010,2.000
2,28.970,0.00,-0.0001,-0.00010,2.000
3,29.200,0.00,0.0092,0.00920,3.000
3,29.310,0.00,0.1176,0.11760,3.000
3,29.420,0.00,0.2278,0.22780,3.000
3,29.530,0.00,0.3378,0.33780,3.000
3,29.640,-0.01,0.4478,0.44780,3.000
3,29.750,-0.01,0.5577,0.55770,3.000
3,29.860,0.00,0.6678,0.66780,3.000
3,29.970,-0.01,0.7778,0.77780,3.000
3,30.080,0.00,0.8878,0.88780,3.000
3,30.190,0.00,0.9977,0.99770,3.000
3,30.300,0.00,1.1078,1.10780,3.000
3,30.410,0.00,1.2179,1.21790,3.000
3,30.520,0.00,1.3279,1.32790,3.000
3,30.630,0.00,1.4378,1.43780,3.000
3,30.740,-0.01,1.5479,1.54790,3.000
3,30.850,-0.01,1.6579,1.65790,3.000
3,30.960,-0.01,1.7678,1.76780,3.000
3,31.070,-0.01,1.8778,1.87780,3.000
3,31.180,0.00,1.9880,1.98800,3.000
3,31.290,0.00,2.0980,2.09800,3.000
3,31.400,0.00,2.2080,2.20800,3.000
3,31.510,-0.01,2.3178,2.31780,3.000
3,31.620,0.00,2.4278,2.42780,3.000
3,31.730,-0.01,2.5379,2.53790,3.000
3,31.840,0.00,2.6478,2.64780,3.000
3,31.950,-0.01,2.7578,2.75780,3.000
3,32.060,0.00,2.8679,2.86790,3.000
3,32.170,-0.01,2.9778,2.97780,3.000
3,32.280,0.02,3.0878,3.08780,3.000
3,32.390,0.14,3.1978,3.19780,3.000
3,32.500,0.36,3.3079,3.30790,3.000
3,32.610,0.68,3.4180,3.41800,3.000
3,32.720,1.12,3.5278,3.52780,3.000
3,32.830,1.66,3.6377,3.63770,3.000
3,32.940,2.35,3.7479,3.74790,3.000
3,33.050,3.21,3.8578,3.85780,3.000
3,33.160,4.25,3.9677,3.96770,3.000
3,33.280,5.60,4.0780,4.07800,3.000
3,33.390,4.55,4.0006,4.00060,3.000
3,33.500,3.23,3.8906,3.89060,3.000
3,33.610,2.25,3.7806,3.78060,3.000
3,33.720,1.54,3.6706,3.67060,3.000
3,33.830,1.00,3.5606,3.56060,3.000
3,33.940,0.60,3.4507,3.45070,3.000
3,34.050,0.30,3.3408,3.34080,3.000
3,34.160,0.11,3.2306,3.23060,3.000
3,34.270,0.01,3.1204,3.12040,3.000
3,34.380,0.00,3.0104,3.01040,3.000
3,34.490,-0.01,2.9006,2.90060,3.000
3,34.600,-0.01,2.7905,2.79050,3.000
3,34.710,0.00,2.6804,2.68040,3.000
3,34.820,-0.01,2.5706,2.57060,3.000
3,34.930,-0.01,2.4604,2.46040,3.000
3,35.040,0.00,2.3504,2.35040,3.000
3,35.150,-0.01,2.2405,2.24050,3.000
3,35.260,-0.01,2.1306,2.13060,3.000
3,35.370,0.00,2.0206,2.02060,3.000
3,35.480,-0.01,1.9105,1.91050,3.000
3,35.590,-0.01,1.8002,1.80020,3.000
3,35.700,-0.01,1.6903,1.69030,3.000
3,35.810,0.00,1.5804,1.58040,3.000
3,35.920,-0.01,1.4703,1.47030,3.000
3,36.030,-0.01,1.3604,1.36040,3.000
3,36.140,-0.01,1.2504,1.25040,3.000
3,36.250,-0.01,1.1404,1.14040,3.000
3,36.360,0.00,1.0304,1.03040,3.000
3,36.470,0.00,0.9202,0.92020,3.000
3,36.580,0.00,0.8104,0.81040,3.000
3,36.690,0.00,0.7004,0.70040,3.000
3,36.800,-0.01,0.5904,0.59040,3.000
3,36.910,-0.01,0.4802,0.48020,3.000
3,37.020,-0.01,0.3704,0.37040,3.000
3,37.130,-0.01,0.2604,0.26040,3.000
3,37.240,-0.01,0.1503,0.15030,3.000
3,37.350,-0.01,0.0402,0.04020,3.000
3,37.470,0.00,-0.0501,-0.05010,3.000
3,37.580,-0.01,-0.0003,-0.00030,3.000
3,37.690,-0.01,-0.0003,-0.00030,3.000
3,37.800,-0.01,-0.0003,-0.00030,3.000
3,37.910,-0.01,-0.0003,-0.00030,3.000
3,38.020,-0.01,-0.0003,-0.00030,3.000
3,38.130,0.00,-0.0003,-0.00030,3.000
3,38.240,0.00,-0.0003,-0.00030,3.000
3,38.350,-0.01,-0.0003,-0.00030,3.000
3,38.460,-0.02,-0.0003,-0.00030,3.000
3,38.570,0.00,-0.0003,-0.00030,3.000
3,38.680,0.00,-0.0003,-0.00030,3.000
3,38.790,-0.01,-0.0003,-0.00030,3.000
3,38.900,0.00,-0.0002,-0.00020,3.000
3,39.010,0.00,-0.0002,-0.00020,3.000
3,39.120,-0.01,-0.0002,-0.00020,3.000
3,39.230,0.00,-0.0002,-0.00020,3.000
3,39.340,0.00,-0.0002,-0.00020,3.000
3,39.450,-0.01,-0.0002,-0.00020,3.000
3,39.560,-0.01,-0.0002,-0.00020,3.000
3,39.670,-0.01,-0.0002,-0.00020,3.000
3,39.780,-0.01,-0.0002,-0.00020,3.000
3,39.890,-0.01,-0.0002,-0.00020,3.000
3,40.000,0.00,-0.0002,-0.00020,3.000
3,40.110,-0.01,-0.0002,-0.00020,3.000
3,40.220,0.00,-0.0002,-0.00020,3.000
3,40.330,-0.01,-0.0002,-0.00020,3.000
3,40.440,-0.01,-0.0002,-0.00020,3.000
3,40.570,-0.01,-0.0002,-0.00020,3.000
3,40.680,-0.01,-0.0002,-0.00020,3.000
3,40.790,-0.01,-0.0002,-0.00020,3.000
3,40.900,0.00,-0.0002,-0.00020,3.000
3,41.010,-0.01,-0.0002,-0.00020,3.000
3,41.120,0.00,-0.0002,-0.00020,3.000
3,41.230,-0.01,-0.0002,-0.00020,3.000
3,41.340,0.00,-0.0002,-0.00020,3.000
3,41.450,0.00,-0.0001,-0.00010,3.000
3,41.560,-0.01,-0.0001,-0.00010,3.000
3,41.670,0.00,-0.0001,-0.00010,3.000
3,41.780,-0.01,-0.0001,-0.00010,3.000
3,41.890,-0.01,-0.0001,-0.00010,3.000
3,42.000,-0.01,-0.0001,-0.00010,3.000
3,42.110,-0.01,-0.0001,-0.00010,3.000
3,42.220,0.00,-0.0001,-0.00010,3.000
3,42.330,-0.01,-0.0001,-0.00010,3.000
3,42.440,0.00,-0.0001,-0.00010,3.000
3,42.550,0.00,-0.0001,-0.00010,3.000
3,42.660,-0.01,-0.0001,-0.00010,3.000
3,42.770,-0.01,-0.0001,-0.00010,3.000
3,42.880,0.00,-0.0001,-0.00010,3.000
3,42.990,-0.01,-0.0001,-0.00010,3.000
3,43.100,-0.01,-0.0001,-0.00010,3.000
3,43.210,0.00,-0.0001,-0.00010,3.000
3,43.320,-0.01,-0.0001,-0.00010,3.000
3,43.430,-0.01,-0.0001,-0.00010,3.000
4,43.640,0.00,0.0000,0.00000,4.000
4,43.750,-0.01,0.0766,0.07660,4.000
4,43.860,0.00,0.1868,0.18680,4.000
4,43.970,0.00,0.2968,0.29680,4.000
4,44.080,0.00,0.4066,0.40660,4.000
4,44.190,0.00,0.5167,0.51670,4.000
4,44.300,0.00,0.6269,0.62690,4.000
4,44.410,-0.01,0.7368,0.73680,4.000
4,44.520,-0.01,0.8467,0.84670,4.000
4,44.630,-0.01,0.9567,0.95670,4.000
4,44.740,0.00,1.0667,1.06670,4.000
4,44.850,0.00,1.1769,1.17690,4.000
4,44.960,-0.01,1.2867,1.28670,4.000
4,45.070,0.00,1.3968,1.39680,4.000
4,45.180,-0.01,1.5068,1.50680,4.000
4,45.290,0.00,1.6167,1.61670,4.000
4,45.400,0.01,1.7267,1.72670,4.000
4,45.510,-0.01,1.8368,1.83680,4.000
4,45.620,-0.01,1.9469,1.94690,4.000
4,45.730,0.00,2.0569,2.05690,4.000
4,45.840,0.00,2.1669,2.16690,4.000
4,45.950,-0.01,2.2769,2.27690,4.000
4,46.060,0.00,2.3868,2.38680,4.000
4,46.170,-0.01,2.4969,2.49690,4.000
4,46.280,0.00,2.6068,2.60680,4.000
4,46.390,0.00,2.7169,2.71690,4.000
4,46.500,0.00,2.8269,2.82690,4.000
4,46.610,-0.01,2.9369,2.93690,4.000
4,46.720,0.00,3.0467,3.04670,4.000
4,46.830,0.08,3.1568,3.15680,4.000
4,46.940,0.26,3.2670,3.26700,4.000
4,47.050,0.54,3.3769,3.37690,4.000
4,47.160,0.94,3.4868,3.48680,4.000
4,47.270,1.45,3.5968,3.59680,4.000
4,47.380,2.07,3.7069,3.70690,4.000
4,47.490,2.87,3.8169,3.81690,4.000
4,47.600,3.84,3.9267,3.92670,4.000
4,47.710,5.02,4.0370,4.03700,4.000
4,47.840,4.99,4.0295,4.02950,4.000
4,47.950,3.55,3.9196,3.91960,4.000
4,48.060,2.49,3.8095,3.80950,4.000
4,48.170,1.71,3.6996,3.69960,4.000
4,48.280,1.13,3.5896,3.58960,4.000
4,48.390,0.70,3.4796,3.47960,4.000
4,48.500,0.37,3.3696,3.36960,4.000
4,48.610,0.15,3.2596,3.25960,4.000
4,48.720,0.04,3.1496,3.14960,4.000
4,48.830,-0.01,3.0395,3.03950,4.000
4,48.940,0.00,2.9294,2.92940,4.000
4,49.050,-0.01,2.8197,2.81970,4.000
4,49.160,-0.01,2.7094,2.70940,4.000
4,49.270,-0.01,2.5995,2.59950,4.000
4,49.380,0.00,2.4894,2.48940,4.000
4,49.490,0.00,2.3794,2.37940,4.000
4,49.600,0.00,2.2695,2.26950,4.000
4,49.710,0.00,2.1596,2.15960,4.000
4,49.820,0.00,2.0493,2.04930,4.000
4,49.930,-0.01,1.9396,1.93960,4.000
4,50.040,0.00,1.8294,1.82940,4.000
4,50.150,0.00,1.7194,1.71940,4.000
4,50.260,0.00,1.6092,1.60920,4.000
4,50.370,-0.01,1.4994,1.49940,4.000
4,50.480,0.00,1.3894,1.38940,4.000
4,50.590,-0.01,1.2795,1.27950,4.000
4,50.700,-0.01,1.1693,1.16930,4.000
4,50.810,-0.01,1.0593,1.05930,4.000
4,50.920,0.00,0.9495,0.94950,4.000
4,51.030,-0.01,0.8393,0.83930,4.000
4,51.140,-0.01,0.7293,0.72930,4.000
4,51.250,-0.01,0.6195,0.61950,4.000
4,51.360,0.00,0.5094,0.50940,4.000
4,51.470,-0.02,0.3993,0.39930,4.000
4,51.580,0.00,0.2893,0.28930,4.000
4,51.690,-0.01,0.1794,0.17940,4.000
4,51.800,-0.01,0.0694,0.06940,4.000
4,51.930,-0.01,-0.0421,-0.04210,4.000
4,52.040,-0.01,-0.0003,-0.00030,4.000
4,52.150,-0.01,-0.0003,-0.00030,4.000
4,52.260,-0.01,-0.0003,-0.00030,4.000
4,52.370,0.00,-0.0003,-0.00030,4.000
4,52.480,-0.01,-0.0003,-0.00030,4.000
4,52.590,0.00,-0.0003,-0.00030,4.000
4,52.700,-0.01,-0.0003,-0.00030,4.000
4,52.810,0.00,-0.0003,-0.00030,4.000
4,52.920,-0.01,-0.0003,-0.00030,4.000
4,53.030,-0.01,-0.0002,-0.00020,4.000
4,53.140,-0.01,-0.0002,-0.00020,4.000
4,53.250,0.00,-0.0002,-0.00020,4.000
4,53.360,0.00,-0.0002,-0.00020,4.000
4,53.470,0.00,-0.0002,-0.00020,4.000
4,53.580,0.00,-0.0002,-0.00020,4.000
4,53.690,-0.01,-0.0002,-0.00020,4.000
4,53.800,0.00,-0.0002,-0.00020,4.000
4,53.910,0.00,-0.0002,-0.00020,4.000
4,54.020,0.00,-0.0002,-0.00020,4.000
4,54.130,-0.01,-0.0002,-0.00020,4.000
4,54.240,0.00,-0.0002,-0.00020,4.000
4,54.350,0.00,-0.0002,-0.00020,4.000
4,54.460,0.00,-0.0002,-0.00020,4.000
4,54.570,-0.01,-0.0002,-0.00020,4.000
4,54.680,0.00,-0.0002,-0.00020,4.000
4,54.790,-0.01,-0.0002,-0.00020,4.000
4,54.900,0.00,-0.0002,-0.00020,4.000
4,55.030,0.00,-0.0002,-0.00020,4.000
4,55.140,0.00,-0.0002,-0.00020,4.000
4,55.250,0.00,-0.0002,-0.00020,4.000
4,55.360,-0.01,-0.0002,-0.00020,4.000
4,55.470,0.00,-0.0002,-0.00020,4.000
4,55.580,-0.01,-0.0002,-0.00020,4.000
4,55.690,0.00,-0.0002,-0.00020,4.000
4,55.800,-0.01,-0.0001,-0.00010,4.000
4,55.910,-0.01,-0.0001,-0.00010,4.000
4,56.020,-0.01,-0.0001,-0.00010,4.000
4,56.130,0.00,-0.0001,-0.00010,4.000
4,56.240,-0.01,-0.0001,-0.00010,4.000
4,56.350,0.00,-0.0001,-0.00010,4.000
4,56.460,0.00,-0.0001,-0.00010,4.000
4,56.570,0.00,-0.0001,-0.00010,4.000
4,56.680,-0.01,-0.0001,-0.00010,4.000
4,56.790,0.00,-0.0001,-0.00010,4.000
4,56.900,0.00,-0.0001,-0.00010,4.000
4,57.010,0.00,-0.0001,-0.00010,4.000
4,57.120,0.00,-0.0001,-0.00010,4.000
4,57.230,0.00,-0.0001,-0.00010,4.000
4,57.340,-0.01,-0.0001,-0.00010,4.000
4,57.450,-0.01,-0.0001,-0.00010,4.000
4,57.560,-0.01,-0.0001,-0.00010,4.000
4,57.670,-0.01,-0.0001,-0.00010,4.000
4,57.780,0.00,-0.0001,-0.00010,4.000
4,57.890,-0.01,-0.0001,-0.00010,4.000
5,58.090,-0.01,0.0000,0.00000,5.000
5,58.210,-0.01,0.0678,0.06780,5.000
5,58.320,-0.01,0.1777,0.17770,5.000
5,58.430,-0.01,0.2876,0.28760,5.000
5,58.540,0.00,0.3976,0.39760,5.000
5,58.650,-0.01,0.5079,0.50790,5.000
5,58.760,0.00,0.6179,0.61790,5.000
5,58.870,0.00,0.7277,0.72770,5.000
5,58.980,0.00,0.8377,0.83770,5.000
5,59.090,0.00,0.9479,0.94790,5.000
5,59.200,0.00,1.0578,1.05780,5.000
5,59.310,-0.01,1.1677,1.16770,5.000
5,59.420,0.00,1.2777,1.27770,5.000
5,59.530,-0.01,1.3879,1.38790,5.000
5,59.640,0.01,1.4978,1.49780,5.000
5,59.750,-0.01,1.6078,1.60780,5.000
5,59.860,0.00,1.7178,1.71780,5.000
5,59.970,-0.01,1.8279,1.82790,5.000
5,60.080,0.01,1.9379,1.93790,5.000
5,60.190,0.00,2.0478,2.04780,5.000
5,60.300,0.00,2.1579,2.15790,5.000
5,60.410,0.00,2.2680,2.26800,5.000
5,60.520,-0.01,2.3778,2.37780,5.000
5,60.630,0.00,2.4877,2.48770,5.000
5,60.740,0.00,2.5978,2.59780,5.000
5,60.850,0.00,2.7080,2.70800,5.000
5,60.960,0.00,2.8177,2.81770,5.000
5,61.070,0.00,2.9276,2.92760,5.000
5,61.180,0.00,3.0378,3.03780,5.000
5,61.290,0.09,3.1479,3.14790,5.000
5,61.400,0.24,3.2579,3.25790,5.000
5,61.510,0.53,3.3678,3.36780,5.000
5,61.620,0.91,3.4778,3.47780,5.000
5,61.730,1.41,3.5879,3.58790,5.000
5,61.840,2.03,3.6978,3.69780,5.000
5,61.950,2.80,3.8077,3.80770,5.000
5,62.060,3.76,3.9179,3.91790,5.000
5,62.170,4.91,4.0279,4.02790,5.000
5,62.300,5.22,4.0426,4.04260,5.000
5,62.410,3.70,3.9325,3.93250,5.000
5,62.520,2.61,3.8226,3.82260,5.000
5,62.630,1.79,3.7126,3.71260,5.000
5,62.740,1.19,3.6025,3.60250,5.000
5,62.850,0.75,3.4926,3.49260,5.000
5,62.960,0.42,3.3827,3.38270,5.000
5,63.070,0.17,3.2727,3.27270,5.000
5,63.180,0.05,3.1626,3.16260,5.000
5,63.290,-0.01,3.0524,3.05240,5.000
5,63.400,-0.01,2.9425,2.94250,5.000
5,63.510,-0.01,2.8326,2.83260,5.000
5,63.620,0.00,2.7224,2.72240,5.000
5,63.730,0.00,2.6124,2.61240,5.000
5,63.840,0.00,2.5026,2.50260,5.000
5,63.950,-0.01,2.3924,2.39240,5.000
5,64.060,0.00,2.2824,2.28240,5.000
5,64.170,0.00,2.1726,2.17260,5.000
5,64.280,0.00,2.0625,2.06250,5.000
5,64.390,0.00,1.9525,1.95250,5.000
5,64.500,0.00,1.8423,1.84230,5.000
5,64.610,0.01,1.7323,1.73230,5.000
5,64.720,0.00,1.6224,1.62240,5.000
5,64.830,-0.01,1.5124,1.51240,5.000
5,64.940,-0.01,1.4023,1.40230,5.000
5,65.050,0.00,1.2924,1.29240,5.000
5,65.160,-0.01,1.1825,1.18250,5.000
5,65.270,0.02,1.0723,1.07230,5.000
5,65.380,-0.01,0.9622,0.96220,5.000
5,65.490,0.00,0.8524,0.85240,5.000
5,65.600,0.01,0.7425,0.74250,5.000
5,65.710,0.00,0.6324,0.63240,5.000
5,65.820,0.00,0.5222,0.52220,5.000
5,65.930,-0.02,0.4124,0.41240,5.000
5,66.040,0.00,0.3024,0.30240,5.000
5,66.150,-0.01,0.1923,0.19230,5.000
5,66.260,0.00,0.0822,0.08220,5.000
5,66.380,-0.01,-0.0372,-0.03716,5.000
5,66.490,-0.02,-0.0008,-0.00080,5.000
5,66.600,-0.01,-0.0002,-0.00020,5.000
5,66.710,-0.01,-0.0002,-0.00020,5.000
5,66.820,0.01,-0.0002,-0.00020,5.000
5,66.930,0.00,-0.0002,-0.00020,5.000
5,67.040,-0.01,-0.0002,-0.00020,5.000
5,67.150,0.00,-0.0002,-0.00020,5.000
5,67.260,-0.01,-0.0002,-0.00020,5.000
5,67.370,-0.01,-0.0002,-0.00020,5.000
5,67.480,0.00,-0.0002,-0.00020,5.000
5,67.590,0.00,-0.0002,-0.00020,5.000
5,67.700,-0.01,-0.0002,-0.00020,5.000
5,67.810,0.00,-0.0002,-0.00020,5.000
5,67.920,0.00,-0.0002,-0.00020,5.000
5,68.030,0.00,-0.0002,-0.00020,5.000
5,68.140,-0.01,-0.0002,-0.00020,5.000
5,68.250,-0.01,-0.0002,-0.00020,5.000
5,68.360,0.00,-0.0002,-0.00020,5.000
5,68.470,-0.01,-0.0002,-0.00020,5.000
5,68.580,0.01,-0.0002,-0.00020,5.000
5,68.690,0.00,-0.0002,-0.00020,5.000
5,68.800,0.00,-0.0002,-0.00020,5.000
5,68.910,0.00,-0.0002,-0.00020,5.000
5,69.020,0.00,-0.0002,-0.00020,5.000
5,69.130,0.00,-0.0002,-0.00020,5.000
5,69.240,0.01,-0.0002,-0.00020,5.000
5,69.350,-0.01,-0.0002,-0.00020,5.000
5,69.470,-0.01,-0.0002,-0.00020,5.000
5,69.580,0.01,-0.0002,-0.00020,5.000
5,69.690,0.00,-0.0002,-0.00020,5.000
5,69.800,-0.01,-0.0002,-0.00020,5.000
5,69.910,0.00,-0.0002,-0.00020,5.000
5,70.020,0.00,-0.0002,-0.00020,5.000
5,70.130,-0.01,-0.0001,-0.00010,5.000
5,70.240,0.00,-0.0001,-0.00010,5.000
5,70.350,0.00,-0.0001,-0.00010,5.000
5,70.460,0.00,-0.0001,-0.00010,5.000
5,70.570,-0.01,-0.0001,-0.00010,5.000
5,70.680,-0.01,-0.0001,-0.00010,5.000
5,70.790,-0.01,-0.0001,-0.00010,5.000
5,70.900,-0.01,-0.0001,-0.00010,5.000
5,71.010,0.00,-0.0001,-0.00010,5.000
5,71.120,0.00,-0.0001,-0.00010,5.000
5,71.230,0.00,-0.0001,-0.00010,5.000
5,71.340,-0.01,-0.0001,-0.00010,5.000
5,71.450,0.00,-0.0001,-0.00010,5.000
5,71.560,0.00,-0.0001,-0.00010,5.000
5,71.670,0.00,-0.0001,-0.00010,5.000
5,71.780,0.00,-0.0001,-0.00010,5.000
5,71.890,-0.01,-0.0001,-0.00010,5.000
5,72.000,-0.01,-0.0001,-0.00010,5.000
5,72.110,0.00,-0.0001,-0.00010,5.000
5,72.220,0.00,-0.0001,-0.00010,5.000
5,72.330,0.00,-0.0001,-0.00010,5.000
5,72.440,0.00,-0.0001,-0.00010,5.000
6,72.640,0.00,0.0375,0.03750,6.000
6,72.750,0.00,0.1477,0.14770,6.000
6,72.860,0.00,0.2576,0.25760,6.000
6,72.970,0.00,0.3677,0.36770,6.000
6,73.080,0.00,0.4776,0.47760,6.000
6,73.190,0.00,0.5878,0.58780,6.000
6,73.300,-0.01,0.6978,0.69780,6.000
6,73.410,0.00,0.8077,0.80770,6.000
6,73.520,0.00,0.9178,0.91780,6.000
6,73.630,0.00,1.0278,1.02780,6.000
6,73.740,0.00,1.1378,1.13780,6.000
6,73.850,0.01,1.2477,1.24770,6.000
6,73.960,0.00,1.3579,1.35790,6.000
6,74.070,0.00,1.4679,1.46790,6.000
6,74.180,0.00,1.5778,1.57780,6.000
6,74.290,0.00,1.6876,1.68760,6.000
6,74.400,0.00,1.7978,1.79780,6.000
6,74.510,0.00,1.9079,1.90790,6.000
6,74.620,0.00,2.0178,2.01780,6.000
6,74.730,-0.01,2.1278,2.12780,6.000
6,74.840,0.00,2.2379,2.23790,6.000
6,74.950,0.00,2.3478,2.34780,6.000
6,75.060,0.00,2.4579,2.45790,6.000
6,75.170,0.00,2.5678,2.56780,6.000
6,75.280,0.00,2.6777,2.67770,6.000
6,75.390,0.00,2.7878,2.78780,6.000
6,75.500,0.00,2.8978,2.89780,6.000
6,75.610,0.00,3.0076,3.00760,6.000
6,75.720,0.06,3.1178,3.11780,6.000
6,75.830,0.20,3.2280,3.22800,6.000
6,75.940,0.45,3.3378,3.33780,6.000
6,76.050,0.80,3.4478,3.44780,6.000
6,76.160,1.28,3.5579,3.55790,6.000
6,76.270,1.85,3.6678,3.66780,6.000
6,76.380,2.59,3.7778,3.77780,6.000
6,76.490,3.51,3.8877,3.88770,6.000
6,76.600,4.61,3.9979,3.99790,6.000
6,76.720,5.71,4.0765,4.07650,6.000
6,76.830,4.22,3.9725,3.97250,6.000
6,76.940,2.99,3.8626,3.86260,6.000
6,77.050,2.08,3.7526,3.75260,6.000
6,77.160,1.41,3.6424,3.64240,6.000
6,77.270,0.91,3.5325,3.53250,6.000
6,77.380,0.53,3.4226,3.42260,6.000
6,77.490,0.25,3.3127,3.31270,6.000
6,77.600,0.09,3.2025,3.20250,6.000
6,77.710,0.00,3.0924,3.09240,6.000
6,77.820,0.01,2.9825,2.98250,6.000
6,77.930,0.00,2.8724,2.87240,6.000
6,78.040,0.00,2.7624,2.76240,6.000
6,78.150,-0.02,2.6523,2.65230,6.000
6,78.260,0.00,2.5426,2.54260,6.000
6,78.370,0.00,2.4324,2.43240,6.000
6,78.480,0.00,2.3222,2.32220,6.000
6,78.590,0.00,2.2125,2.21250,6.000
6,78.700,0.00,2.1025,2.10250,6.000
6,78.810,-0.01,1.9925,1.99250,6.000
6,78.920,0.00,1.8824,1.88240,6.000
6,79.030,0.00,1.7723,1.77230,6.000
6,79.140,0.00,1.6624,1.66240,6.000
6,79.250,0.00,1.5524,1.55240,6.000
6,79.360,-0.01,1.4423,1.44230,6.000
6,79.470,0.00,1.3323,1.33230,6.000
6,79.580,0.00,1.2226,1.22260,6.000
6,79.690,0.00,1.1124,1.11240,6.000
6,79.800,0.00,1.0023,1.00230,6.000
6,79.910,0.00,0.8923,0.89230,6.000
6,80.020,0.00,0.7824,0.78240,6.000
6,80.130,0.00,0.6724,0.67240,6.000
6,80.240,0.01,0.5623,0.56230,6.000
6,80.350,0.00,0.4523,0.45230,6.000
6,80.460,0.00,0.3424,0.34240,6.000
6,80.570,0.00,0.2323,0.23230,6.000
6,80.680,0.00,0.1223,0.12230,6.000
6,80.790,0.00,0.0124,0.01240,6.000
6,80.910,0.00,-0.0325,-0.03250,6.000
6,81.020,0.00,-0.0003,-0.00030,6.000
6,81.130,0.00,-0.0002,-0.00020,6.000
6,81.240,0.00,-0.0002,-0.00020,6.000
6,81.350,0.00,-0.0002,-0.00020,6.000
6,81.460,0.00,-0.0002,-0.00020,6.000
6,81.570,0.00,-0.0002,-0.00020,6.000
6,81.680,0.00,-0.0002,-0.00020,6.000
6,81.790,0.01,-0.0002,-0.00020,6.000
6,81.900,0.01,-0.0002,-0.00020,6.000
6,82.010,0.00,-0.0002,-0.00020,6.000
6,82.120,0.00,-0.0002,-0.00020,6.000
6,82.230,0.00,-0.0002,-0.00020,6.000
6,82.340,0.01,-0.0002,-0.00020,6.000
6,82.450,0.00,-0.0002,-0.00020,6.000
6,82.560,0.00,-0.0002,-0.00020,6.000
6,82.670,0.00,-0.0002,-0.00020,6.000
6,82.780,0.00,-0.0002,-0.00020,6.000
6,82.890,0.01,-0.0002,-0.00020,6.000
6,83.000,0.00,-0.0002,-0.00020,6.000
6,83.110,0.00,-0.0002,-0.00020,6.000
6,83.220,0.00,-0.0002,-0.00020,6.000
6,83.330,0.00,-0.0002,-0.00020,6.000
6,83.440,0.00,-0.0002,-0.00020,6.000
6,83.550,0.00,-0.0002,-0.00020,6.000
6,83.660,0.00,-0.0002,-0.00020,6.000
6,83.770,0.00,-0.0002,-0.00020,6.000
6,83.880,0.00,-0.0002,-0.00020,6.000
6,84.000,0.00,-0.0002,-0.00020,6.000
6,84.110,0.00,-0.0002,-0.00020,6.000
6,84.220,0.01,-0.0002,-0.00020,6.000
6,84.330,0.01,-0.0002,-0.00020,6.000
6,84.440,0.00,-0.0002,-0.00020,6.000
6,84.550,0.00,-0.0001,-0.00010,6.000
6,84.660,0.00,-0.0001,-0.00010,6.000
6,84.770,0.00,-0.0001,-0.00010,6.000
6,84.880,0.00,-0.0001,-0.00010,6.000
6,84.990,0.00,-0.0001,-0.00010,6.000
6,85.100,0.00,-0.0001,-0.00010,6.000
6,85.210,0.00,-0.0001,-0.00010,6.000
6,85.320,0.01,-0.0001,-0.00010,6.000
6,85.430,0.00,-0.0001,-0.00010,6.000
6,85.540,0.00,-0.0001,-0.00010,6.000
6,85.650,0.01,-0.0001,-0.00010,6.000
6,85.760,0.01,-0.0001,-0.00010,6.000
6,85.870,0.00,-0.0001,-0.00010,6.000
6,85.980,0.00,-0.0001,-0.00010,6.000
6,86.090,0.00,-0.0001,-0.00010,6.000
6,86.200,0.01,-0.0001,-0.00010,6.000
6,86.310,0.00,-0.0001,-0.00010,6.000
6,86.420,0.00,-0.0001,-0.00010,6.000
6,86.530,0.00,-0.0001,-0.00010,6.000
6,86.640,0.00,-0.0001,-0.00010,6.000
6,86.750,0.00,-0.0001,-0.00010,6.000
6,86.860,0.01,-0.0001,-0.00010,6.000
7,87.070,0.00,0.0000,0.00000,7.000
7,87.180,0.01,0.0866,0.08660,7.000
7,87.290,0.00,0.1966,0.19660,7.000
7,87.400,0.01,0.3067,0.30670,7.000
7,87.510,0.01,0.4168,0.41680,7.000
7,87.620,0.01,0.5268,0.52680,7.000
7,87.730,0.01,0.6367,0.63670,7.000
7,87.840,0.00,0.7469,0.74690,7.000
7,87.950,0.01,0.8567,0.85670,7.000
7,88.060,0.01,0.9667,0.96670,7.000
7,88.170,0.01,1.0767,1.07670,7.000
7,88.280,0.01,1.1868,1.18680,7.000
7,88.390,0.01,1.2968,1.29680,7.000
7,88.500,0.01,1.4068,1.40680,7.000
7,88.610,0.00,1.5169,1.51690,7.000
7,88.720,0.00,1.6268,1.62680,7.000
7,88.830,0.00,1.7368,1.73680,7.000
7,88.940,0.00,1.8467,1.84670,7.000
7,89.050,0.00,1.9569,1.95690,7.000
7,89.160,0.01,2.0669,2.06690,7.000
7,89.270,0.01,2.1769,2.17690,7.000
7,89.380,0.00,2.2867,2.28670,7.000
7,89.490,0.00,2.3968,2.39680,7.000
7,89.600,0.01,2.5070,2.50700,7.000
7,89.710,0.01,2.6169,2.61690,7.000
7,89.820,0.01,2.7266,2.72660,7.000
7,89.930,0.01,2.8368,2.83680,7.000
7,90.040,0.01,2.9469,2.94690,7.000
7,90.150,0.01,3.0567,3.05670,7.000
7,90.260,0.11,3.1667,3.16670,7.000
7,90.370,0.31,3.2770,3.27700,7.000
7,90.480,0.60,3.3870,3.38700,7.000
7,90.590,1.00,3.4968,3.49680,7.000
7,90.700,1.52,3.6067,3.60670,7.000
7,90.810,2.17,3.7168,3.71680,7.000
7,90.920,2.98,3.8269,3.82690,7.000
7,91.030,3.98,3.9368,3.93680,7.000
7,91.160,5.41,4.0666,4.06660,7.000
7,91.270,4.89,4.0196,4.01960,7.000
7,91.380,3.47,3.9096,3.90960,7.000
7,91.490,2.43,3.7997,3.79970,7.000
7,91.600,1.68,3.6895,3.68950,7.000
7,91.710,1.12,3.5795,3.57950,7.000
7,91.820,0.69,3.4696,3.46960,7.000
7,91.930,0.36,3.3597,3.35970,7.000
7,92.040,0.15,3.2495,3.24950,7.000
7,92.150,0.04,3.1396,3.13960,7.000
7,92.260,0.00,3.0296,3.02960,7.000
7,92.370,0.01,2.9194,2.91940,7.000
7,92.480,0.00,2.8093,2.80930,7.000
7,92.590,0.01,2.6995,2.69950,7.000
7,92.700,0.01,2.5896,2.58960,7.000
7,92.810,0.00,2.4795,2.47950,7.000
7,92.920,0.00,2.3692,2.36920,7.000
7,93.030,0.01,2.2595,2.25950,7.000
7,93.140,0.01,2.1497,2.14970,7.000
7,93.250,0.01,2.0395,2.03950,7.000
7,93.360,0.00,1.9294,1.92940,7.000
7,93.470,0.00,1.8195,1.81950,7.000
7,93.580,0.01,1.7094,1.70940,7.000
7,93.690,0.02,1.5993,1.59930,7.000
7,93.800,0.00,1.4893,1.48930,7.000
7,93.910,0.01,1.3795,1.37950,7.000
7,94.020,0.00,1.2695,1.26950,7.000
7,94.130,0.01,1.1593,1.15930,7.000
7,94.240,0.01,1.0492,1.04920,7.000
7,94.350,0.00,0.9394,0.93940,7.000
7,94.460,0.00,0.8294,0.82940,7.000
7,94.570,0.00,0.7194,0.71940,7.000
7,94.680,0.00,0.6093,0.60930,7.000
7,94.790,0.01,0.4994,0.49940,7.000
7,94.900,0.00,0.3894,0.38940,7.000
7,95.010,0.00,0.2793,0.27930,7.000
7,95.120,0.01,0.1692,0.16920,7.000
7,95.230,0.01,0.0595,0.05950,7.000
7,95.350,0.01,-0.0421,-0.04210,7.000
7,95.460,0.01,-0.0003,-0.00030,7.000
7,95.570,0.00,-0.0003,-0.00030,7.000
7,95.680,0.01,-0.0003,-0.00030,7.000
7,95.790,0.00,-0.0003,-0.00030,7.000
7,95.900,0.00,-0.0003,-0.00030,7.000
7,96.010,0.01,-0.0003,-0.00030,7.000
7,96.120,0.00,-0.0003,-0.00030,7.000
7,96.230,0.01,-0.0003,-0.00030,7.000
7,96.340,0.01,-0.0003,-0.00030,7.000
7,96.450,0.01,-0.0002,-0.00020,7.000
7,96.560,0.00,-0.0002,-0.00020,7.000
7,96.670,0.00,-0.0002,-0.00020,7.000
7,96.780,0.01,-0.0002,-0.00020,7.000
7,96.890,0.01,-0.0002,-0.00020,7.000
7,97.000,0.00,-0.0002,-0.00020,7.000
7,97.110,0.01,-0.0002,-0.00020,7.000
7,97.220,0.00,-0.0002,-0.00020,7.000
7,97.330,0.00,-0.0002,-0.00020,7.000
7,97.440,0.01,-0.0002,-0.00020,7.000
7,97.550,0.01,-0.0002,-0.00020,7.000
7,97.660,0.00,-0.0002,-0.00020,7.000
7,97.770,0.01,-0.0002,-0.00020,7.000
7,97.880,0.00,-0.0002,-0.00020,7.000
7,97.990,0.01,-0.0002,-0.00020,7.000
7,98.100,0.00,-0.0002,-0.00020,7.000
7,98.210,0.01,-0.0002,-0.00020,7.000
7,98.320,0.00,-0.0002,-0.00020,7.000
7,98.440,0.00,-0.0002,-0.00020,7.000
7,98.550,0.00,-0.0002,-0.00020,7.000
7,98.660,0.02,-0.0002,-0.00020,7.000
7,98.770,0.00,-0.0002,-0.00020,7.000
7,98.880,0.01,-0.0002,-0.00020,7.000
7,98.990,0.00,-0.0002,-0.00020,7.000
7,99.100,0.00,-0.0002,-0.00020,7.000
7,99.210,0.00,-0.0001,-0.00010,7.000
7,99.320,0.02,-0.0001,-0.00010,7.000
7,99.430,0.01,-0.0001,-0.00010,7.000
7,99.540,0.01,-0.0001,-0.00010,7.000
7,99.650,0.01,-0.0001,-0.00010,7.000
7,99.760,0.01,-0.0001,-0.00010,7.000
7,99.870,0.01,-0.0001,-0.00010,7.000
7,99.980,-0.01,-0.0001,-0.00010,7.000
7,100.090,0.02,-0.0001,-0.00010,7.000
7,100.200,0.01,-0.0001,-0.00010,7.000
7,100.310,0.01,-0.0001,-0.00010,7.000
7,100.420,0.00,-0.0001,-0.00010,7.000
7,100.530,0.01,-0.0001,-0.00010,7.000
7,100.640,0.00,-0.0001,-0.00010,7.000
7,100.750,0.01,-0.0001,-0.00010,7.000
7,100.860,0.01,-0.0001,-0.00010,7.000
7,100.970,0.01,-0.0001,-0.00010,7.000
7,101.080,0.01,-0.0001,-0.00010,7.000
7,101.190,0.01,-0.0001,-0.00010,7.000
7,101.300,0.01,-0.0001,-0.00010,7.000
7,101.490,0.03,0.0000,0.00000,7.000
8,101.610,0.01,0.0567,0.05670,8.000
8,101.720,0.01,0.1666,0.16660,8.000
8,101.830,0.01,0.2766,0.27660,8.000
8,101.940,0.01,0.3868,0.38680,8.000
8,102.050,0.00,0.4968,0.49680,8.000
8,102.160,0.00,0.6067,0.60670,8.000
8,102.270,0.00,0.7168,0.71680,8.000
8,102.380,0.01,0.8268,0.82680,8.000
8,102.490,0.01,0.9368,0.93680,8.000
8,102.600,0.01,1.0466,1.04660,8.000
8,102.710,0.00,1.1567,1.15670,8.000
8,102.820,0.01,1.2669,1.26690,8.000
8,102.930,0.01,1.3769,1.37690,8.000
8,103.040,0.01,1.4868,1.48680,8.000
8,103.150,0.00,1.5969,1.59690,8.000
8,103.260,0.01,1.7069,1.70690,8.000
8,103.370,0.01,1.8167,1.81670,8.000
8,103.480,0.01,1.9268,1.92680,8.000
8,103.590,0.01,2.0368,2.03680,8.000
8,103.700,0.00,2.1470,2.14700,8.000
8,103.810,0.00,2.2570,2.25700,8.000
8,103.920,0.01,2.3665,2.36650,8.000
8,104.030,0.01,2.4769,2.47690,8.000
8,104.140,0.01,2.5870,2.58700,8.000
8,104.250,0.01,2.6969,2.69690,8.000
8,104.360,0.02,2.8068,2.80680,8.000
8,104.470,0.01,2.9168,2.91680,8.000
8,104.580,0.01,3.0269,3.02690,8.000
8,104.690,0.10,3.1367,3.13670,8.000
8,104.800,0.24,3.2468,3.24680,8.000
8,104.910,0.51,3.3570,3.35700,8.000
8,105.020,0.87,3.4669,3.46690,8.000
8,105.130,1.37,3.5769,3.57690,8.000
8,105.240,1.97,3.6867,3.68670,8.000
8,105.350,2.74,3.7969,3.79690,8.000
8,105.460,3.68,3.9069,3.90690,8.000
8,105.570,4.83,4.0168,4.01680,8.000
8,105.700,5.40,4.0512,4.05120,8.000
8,105.810,3.83,3.9416,3.94160,8.000
8,105.920,2.71,3.8318,3.83180,8.000
8,106.030,1.86,3.7216,3.72160,8.000
8,106.140,1.26,3.6115,3.61150,8.000
8,106.250,0.79,3.5017,3.50170,8.000
8,106.360,0.44,3.3918,3.39180,8.000
8,106.470,0.20,3.2817,3.28170,8.000
8,106.580,0.07,3.1714,3.17140,8.000
8,106.690,-0.01,3.0615,3.06150,8.000
8,106.800,0.00,2.9515,2.95150,8.000
8,106.910,0.00,2.8415,2.84150,8.000
8,107.020,0.00,2.7313,2.73130,8.000
8,107.130,0.01,2.6215,2.62150,8.000
8,107.240,0.01,2.5117,2.51170,8.000
8,107.350,0.01,2.4012,2.40120,8.000
8,107.460,0.01,2.2914,2.29140,8.000
8,107.570,0.00,2.1816,2.18160,8.000
8,107.680,0.01,2.0715,2.07150,8.000
8,107.790,0.01,1.9615,1.96150,8.000
8,107.900,0.01,1.8513,1.85130,8.000
8,108.010,0.00,1.7414,1.74140,8.000
8,108.120,0.01,1.6314,1.63140,8.000
8,108.230,0.01,1.5212,1.52120,8.000
8,108.340,0.01,1.4113,1.41130,8.000
8,108.450,0.00,1.3015,1.30150,8.000
8,108.560,0.01,1.1914,1.19140,8.000
8,108.670,0.00,1.0812,1.08120,8.000
8,108.780,0.00,0.9713,0.97130,8.000
8,108.890,-0.01,0.8615,0.86150,8.000
8,109.000,0.00,0.7513,0.75130,8.000
8,109.110,-0.01,0.6413,0.64130,8.000
8,109.220,0.01,0.5314,0.53140,8.000
8,109.330,0.00,0.4214,0.42140,8.000
8,109.440,0.00,0.3114,0.31140,8.000
8,109.550,0.01,0.2012,0.20120,8.000
8,109.660,0.00,0.0913,0.09130,8.000
8,109.790,0.01,-0.0381,-0.03810,8.000
8,109.900,0.00,-0.0016,-0.00160,8.000
8,110.010,0.01,-0.0003,-0.00030,8.000
8,110.120,0.01,-0.0003,-0.00030,8.000
8,110.230,0.00,-0.0003,-0.00030,8.000
8,110.340,0.00,-0.0003,-0.00030,8.000
8,110.450,0.00,-0.0003,-0.00030,8.000
8,110.560,0.00,-0.0003,-0.00030,8.000
8,110.670,0.00,-0.0003,-0.00030,8.000
8,110.780,0.01,-0.0003,-0.00030,8.000
8,110.890,0.00,-0.0003,-0.00030,8.000
8,111.000,0.00,-0.0003,-0.00030,8.000
8,111.110,0.01,-0.0002,-0.00020,8.000
8,111.220,0.00,-0.0002,-0.00020,8.000
8,111.330,0.00,-0.0002,-0.00020,8.000
8,111.440,0.00,-0.0002,-0.00020,8.000
8,111.550,0.01,-0.0002,-0.00020,8.000
8,111.660,0.01,-0.0002,-0.00020,8.000
8,111.770,0.00,-0.0002,-0.00020,8.000
8,111.880,0.00,-0.0002,-0.00020,8.000
8,111.990,0.01,-0.0002,-0.00020,8.000
8,112.100,0.00,-0.0002,-0.00020,8.000
8,112.210,0.01,-0.0002,-0.00020,8.000
8,112.320,0.01,-0.0002,-0.00020,8.000
8,112.430,0.01,-0.0002,-0.00020,8.000
8,112.540,0.01,-0.0002,-0.00020,8.000
8,112.650,0.00,-0.0002,-0.00020,8.000
8,112.760,0.00,-0.0002,-0.00020,8.000
8,112.890,0.00,-0.0002,-0.00020,8.000
8,113.000,0.00,-0.0002,-0.00020,8.000
8,113.110,0.00,-0.0002,-0.00020,8.000
8,113.220,0.01,-0.0002,-0.00020,8.000
8,113.330,0.00,-0.0002,-0.00020,8.000
8,113.440,0.00,-0.0002,-0.00020,8.000
8,113.550,0.01,-0.0002,-0.00020,8.000
8,113.660,0.00,-0.0002,-0.00020,8.000
8,113.770,0.01,-0.0001,-0.00010,8.000
8,113.880,0.00,-0.0001,-0.00010,8.000
8,113.990,0.01,-0.0001,-0.00010,8.000
8,114.100,0.00,-0.0001,-0.00010,8.000
8,114.210,0.00,-0.0001,-0.00010,8.000
8,114.320,0.01,-0.0001,-0.00010,8.000
8,114.430,0.00,-0.0001,-0.00010,8.000
8,114.540,0.01,-0.0001,-0.00010,8.000
8,114.650,0.00,-0.0001,-0.00010,8.000
8,114.760,0.00,-0.0001,-0.00010,8.000
8,114.870,0.00,-0.0001,-0.00010,8.000
8,114.980,0.01,-0.0001,-0.00010,8.000
8,115.090,0.00,-0.0001,-0.00010,8.000
8,115.200,-0.01,-0.0001,-0.00010,8.000
8,115.310,0.00,-0.0001,-0.00010,8.000
8,115.420,0.02,-0.0001,-0.00010,8.000
8,115.530,0.01,-0.0001,-0.00010,8.000
8,115.640,0.01,-0.0001,-0.00010,8.000
8,115.750,0.01,-0.0001,-0.00010,8.000
8,115.860,0.01,-0.0001,-0.00010,8.000
9,116.060,0.00,0.0466,0.04660,9.000
9,116.170,0.00,0.1567,0.15670,9.000
9,116.280,0.00,0.2668,0.26680,9.000
9,116.390,0.00,0.3767,0.37670,9.000
9,116.500,0.00,0.4868,0.48680,9.000
9,116.610,0.00,0.5969,0.59690,9.000
9,116.720,0.00,0.7069,0.70690,9.000
9,116.830,0.00,0.8167,0.81670,9.000
9,116.940,0.00,0.9268,0.92680,9.000
9,117.050,-0.01,1.0367,1.03670,9.000
9,117.160,-0.01,1.1468,1.14680,9.000
9,117.270,0.00,1.2569,1.25690,9.000
9,117.380,0.00,1.3668,1.36680,9.000
9,117.490,-0.01,1.4768,1.47680,9.000
9,117.600,0.00,1.5869,1.58690,9.000
9,117.710,0.00,1.6968,1.69680,9.000
9,117.820,0.00,1.8067,1.80670,9.000
9,117.930,0.00,1.9169,1.91690,9.000
9,118.040,0.00,2.0269,2.02690,9.000
9,118.150,0.00,2.1369,2.13690,9.000
9,118.260,0.00,2.2469,2.24690,9.000
9,118.370,0.00,2.3568,2.35680,9.000
9,118.480,0.00,2.4668,2.46680,9.000
9,118.590,0.00,2.5769,2.57690,9.000
9,118.700,0.01,2.6867,2.68670,9.000
9,118.810,0.00,2.7969,2.79690,9.000
9,118.920,0.00,2.9069,2.90690,9.000
9,119.030,0.00,3.0168,3.01680,9.000
9,119.140,0.07,3.1268,3.12680,9.000
9,119.250,0.21,3.2369,3.23690,9.000
9,119.360,0.47,3.3470,3.34700,9.000
9,119.470,0.85,3.4569,3.45690,9.000
9,119.580,1.31,3.5669,3.56690,9.000
9,119.690,1.90,3.6769,3.67690,9.000
9,119.800,2.66,3.7870,3.78700,9.000
9,119.910,3.57,3.8968,3.89680,9.000
9,120.020,4.70,4.0068,4.00680,9.000
9,120.150,5.53,4.0617,4.06170,9.000
9,120.260,3.94,3.9516,3.95160,9.000
9,120.370,2.80,3.8417,3.84170,9.000
9,120.480,1.92,3.7315,3.73150,9.000
9,120.590,1.30,3.6216,3.62160,9.000
9,120.700,0.83,3.5117,3.51170,9.000
9,120.810,0.47,3.4017,3.40170,9.000
9,120.920,0.21,3.2915,3.29150,9.000
9,121.030,0.08,3.1816,3.18160,9.000
9,121.140,-0.01,3.0715,3.07150,9.000
9,121.250,0.00,2.9614,2.96140,9.000
9,121.360,0.00,2.8513,2.85130,9.000
9,121.470,0.00,2.7415,2.74150,9.000
9,121.580,0.00,2.6315,2.63150,9.000
9,121.690,0.00,2.5215,2.52150,9.000
9,121.800,0.00,2.4112,2.41120,9.000
9,121.910,0.00,2.3014,2.30140,9.000
9,122.020,0.00,2.1916,2.19160,9.000
9,122.130,0.00,2.0814,2.08140,9.000
9,122.240,0.00,1.9714,1.97140,9.000
9,122.350,-0.01,1.8614,1.86140,9.000
9,122.460,0.00,1.7514,1.75140,9.000
9,122.570,0.00,1.6414,1.64140,9.000
9,122.680,0.00,1.5314,1.53140,9.000
9,122.790,-0.01,1.4215,1.42150,9.000
9,122.900,0.00,1.3116,1.31160,9.000
9,123.010,0.00,1.2013,1.20130,9.000
9,123.120,0.01,1.0912,1.09120,9.000
9,123.230,0.00,0.9815,0.98150,9.000
9,123.340,0.00,0.8714,0.87140,9.000
9,123.450,-0.01,0.7613,0.76130,9.000
9,123.560,0.00,0.6513,0.65130,9.000
9,123.670,0.00,0.5415,0.54150,9.000
9,123.780,-0.01,0.4314,0.43140,9.000
9,123.890,0.00,0.3213,0.32130,9.000
9,124.000,0.01,0.2112,0.21120,9.000
9,124.110,0.00,0.1014,0.10140,9.000
9,124.220,0.00,-0.0086,-0.00860,9.000
9,124.350,0.00,-0.0064,-0.00640,9.000
9,124.460,0.00,-0.0003,-0.00030,9.000
9,124.570,0.00,-0.0003,-0.00030,9.000
9,124.680,0.00,-0.0003,-0.00030,9.000
9,124.790,0.00,-0.0003,-0.00030,9.000
9,124.900,0.00,-0.0003,-0.00030,9.000
9,125.010,0.00,-0.0003,-0.00030,9.000
9,125.120,-0.01,-0.0003,-0.00030,9.000
9,125.230,0.00,-0.0003,-0.00030,9.000
9,125.340,0.01,-0.0003,-0.00030,9.000
9,125.450,0.00,-0.0002,-0.00020,9.000
9,125.560,0.01,-0.0002,-0.00020,9.000
9,125.670,0.00,-0.0002,-0.00020,9.000
9,125.780,0.00,-0.0002,-0.00020,9.000
9,125.890,0.00,-0.0002,-0.00020,9.000
9,126.000,0.01,-0.0002,-0.00020,9.000
9,126.110,0.00,-0.0002,-0.00020,9.000
9,126.220,0.00,-0.0002,-0.00020,9.000
9,126.330,0.00,-0.0002,-0.00020,9.000
9,126.440,0.00,-0.0002,-0.00020,9.000
9,126.550,0.00,-0.0002,-0.00020,9.000
9,126.660,0.00,-0.0002,-0.00020,9.000
9,126.770,0.00,-0.0002,-0.00020,9.000
9,126.880,0.01,-0.0002,-0.00020,9.000
9,126.990,0.00,-0.0002,-0.00020,9.000
9,127.100,0.00,-0.0002,-0.00020,9.000
9,127.210,0.01,-0.0002,-0.00020,9.000
9,127.340,0.00,-0.0002,-0.00020,9.000
9,127.450,0.00,-0.0002,-0.00020,9.000
9,127.560,0.00,-0.0002,-0.00020,9.000
9,127.670,0.00,-0.0002,-0.00020,9.000
9,127.780,0.00,-0.0002,-0.00020,9.000
9,127.890,0.00,-0.0002,-0.00020,9.000
9,128.000,0.01,-0.0002,-0.00020,9.000
9,128.110,0.01,-0.0001,-0.00010,9.000
9,128.220,0.00,-0.0001,-0.00010,9.000
9,128.330,0.00,-0.0001,-0.00010,9.000
9,128.440,0.00,-0.0001,-0.00010,9.000
9,128.550,0.00,-0.0001,-0.00010,9.000
9,128.660,0.00,-0.0001,-0.00010,9.000
9,128.770,0.00,-0.0001,-0.00010,9.000
9,128.880,0.00,-0.0001,-0.00010,9.000
9,128.990,0.00,-0.0001,-0.00010,9.000
9,129.100,0.00,-0.0001,-0.00010,9.000
9,129.210,0.00,-0.0001,-0.00010,9.000
9,129.320,-0.02,-0.0001,-0.00010,9.000
9,129.430,0.00,-0.0001,-0.00010,9.000
9,129.540,0.00,-0.0001,-0.00010,9.000
9,129.650,0.00,-0.0001,-0.00010,9.000
9,129.760,0.01,-0.0001,-0.00010,9.000
9,129.870,0.00,-0.0001,-0.00010,9.000
9,129.980,0.00,-0.0001,-0.00010,9.000
9,130.090,0.00,-0.0001,-0.00010,9.000
9,130.200,0.00,-0.0001,-0.00010,9.000
9,130.310,0.00,-0.0001,-0.00010,9.000
10,130.510,0.00,0.0366,0.03660,10.000
10,130.620,0.00,0.1469,0.14690,10.000
10,130.730,0.00,0.2567,0.25670,10.000
10,130.840,0.00,0.3666,0.36660,10.000
10,130.950,0.00,0.4767,0.47670,10.000
10,131.060,0.00,0.5869,0.58690,10.000
10,131.170,0.00,0.6968,0.69680,10.000
10,131.280,0.00,0.8066,0.80660,10.000
10,131.390,0.00,0.9167,0.91670,10.000
10,131.500,0.00,1.0267,1.02670,10.000
10,131.610,0.01,1.1367,1.13670,10.000
10,131.720,0.00,1.2467,1.24670,10.000
10,131.830,-0.01,1.3570,1.35700,10.000
10,131.940,-0.01,1.4669,1.46690,10.000
10,132.050,-0.01,1.5767,1.57670,10.000
10,132.160,0.00,1.6867,1.68670,10.000
10,132.270,0.00,1.7969,1.79690,10.000
10,132.380,0.00,1.9068,1.90680,10.000
10,132.490,0.00,2.0168,2.01680,10.000
10,132.600,0.00,2.1269,2.12690,10.000
10,132.710,0.00,2.2369,2.23690,10.000
10,132.820,0.01,2.3467,2.34670,10.000
10,132.930,0.01,2.4568,2.45680,10.000
10,133.040,-0.01,2.5669,2.56690,10.000
10,133.150,-0.01,2.6769,2.67690,10.000
10,133.260,0.00,2.7868,2.78680,10.000
10,133.370,0.00,2.8968,2.89680,10.000
10,133.480,0.00,3.0067,3.00670,10.000
10,133.590,0.06,3.1168,3.11680,10.000
10,133.700,0.19,3.2269,3.22690,10.000
10,133.810,0.44,3.3369,3.33690,10.000
10,133.920,0.80,3.4468,3.44680,10.000
10,134.030,1.26,3.5569,3.55690,10.000
10,134.140,1.84,3.6668,3.66680,10.000
10,134.250,2.59,3.7769,3.77690,10.000
10,134.360,3.48,3.8868,3.88680,10.000
10,134.470,4.59,3.9969,3.99690,10.000
10,134.600,5.62,4.0700,4.07000,10.000
10,134.710,4.06,3.9615,3.96150,10.000
10,134.820,2.87,3.8516,3.85160,10.000
10,134.930,1.98,3.7417,3.74170,10.000
10,135.040,1.35,3.6317,3.63170,10.000
10,135.150,0.86,3.5217,3.52170,10.000
10,135.260,0.49,3.4115,3.41150,10.000
10,135.370,0.23,3.3017,3.30170,10.000
10,135.480,0.09,3.1916,3.19160,10.000
10,135.590,0.00,3.0815,3.08150,10.000
10,135.700,0.00,2.9714,2.97140,10.000
10,135.810,0.00,2.8616,2.86160,10.000
10,135.920,0.00,2.7515,2.75150,10.000
10,136.030,-0.01,2.6415,2.64150,10.000
10,136.140,0.00,2.5314,2.53140,10.000
10,136.250,0.00,2.4213,2.42130,10.000
10,136.360,0.00,2.3114,2.31140,10.000
10,136.470,0.00,2.2016,2.20160,10.000
10,136.580,0.00,2.0915,2.09150,10.000
10,136.690,0.00,1.9816,1.98160,10.000
10,136.800,0.00,1.8715,1.87150,10.000
10,136.910,0.00,1.7614,1.76140,10.000
10,137.020,0.00,1.6513,1.65130,10.000
10,137.130,0.00,1.5414,1.54140,10.000
10,137.240,0.00,1.4314,1.43140,10.000
10,137.350,0.00,1.3215,1.32150,10.000
10,137.460,0.00,1.2113,1.21130,10.000
10,137.570,0.00,1.1013,1.10130,10.000
10,137.680,0.00,0.9914,0.99140,10.000
10,137.790,0.00,0.8814,0.88140,10.000
10,137.900,0.00,0.7713,0.77130,10.000
10,138.010,0.00,0.6615,0.66150,10.000
10,138.120,0.00,0.5515,0.55150,10.000
10,138.230,0.00,0.4413,0.44130,10.000
10,138.340,-0.01,0.3313,0.33130,10.000
10,138.450,0.01,0.2213,0.22130,10.000
10,138.560,0.00,0.1114,0.11140,10.000
10,138.670,0.00,0.0014,0.00140,10.000
10,138.790,0.00,-0.0228,-0.02280,10.000
10,138.900,0.00,-0.0003,-0.00030,10.000
10,139.010,0.00,-0.0003,-0.00030,10.000
10,139.120,0.00,-0.0003,-0.00030,10.000
10,139.230,0.00,-0.0003,-0.00030,10.000
10,139.340,0.00,-0.0003,-0.00030,10.000
10,139.450,0.00,-0.0003,-0.00030,10.000
10,139.560,0.00,-0.0003,-0.00030,10.000
10,139.670,0.00,-0.0003,-0.00030,10.000
10,139.780,0.00,-0.0003,-0.00030,10.000
10,139.890,0.00,-0.0002,-0.00020,10.000
10,140.000,0.00,-0.0002,-0.00020,10.000
10,140.110,0.00,-0.0002,-0.00020,10.000
10,140.220,0.00,-0.0002,-0.00020,10.000
10,140.330,0.00,-0.0002,-0.00020,10.000
10,140.440,0.00,-0.0002,-0.00020,10.000
10,140.550,0.01,-0.0002,-0.00020,10.000
10,140.660,0.00,-0.0002,-0.00020,10.000
10,140.770,0.01,-0.0002,-0.00020,10.000
10,140.880,0.00,-0.0002,-0.00020,10.000
10,140.990,0.00,-0.0002,-0.00020,10.000
10,141.100,-0.01,-0.0002,-0.00020,10.000
10,141.210,0.00,-0.0002,-0.00020,10.000
10,141.320,0.00,-0.0002,-0.00020,10.000
10,141.430,0.00,-0.0002,-0.00020,10.000
10,141.540,0.00,-0.0002,-0.00020,10.000
10,141.650,0.00,-0.0002,-0.00020,10.000
10,141.760,0.00,-0.0002,-0.00020,10.000
10,141.890,0.00,-0.0002,-0.00020,10.000
10,142.000,0.00,-0.0002,-0.00020,10.000
10,142.110,0.00,-0.0002,-0.00020,10.000
10,142.220,-0.01,-0.0002,-0.00020,10.000
10,142.330,0.00,-0.0002,-0.00020,10.000
10,142.440,0.00,-0.0002,-0.00020,10.000
10,142.550,0.00,-0.0001,-0.00010,10.000
10,142.660,0.00,-0.0001,-0.00010,10.000
10,142.770,0.00,-0.0001,-0.00010,10.000
10,142.880,0.00,-0.0001,-0.00010,10.000
10,142.990,-0.01,-0.0001,-0.00010,10.000
10,143.100,0.00,-0.0001,-0.00010,10.000
10,143.210,0.00,-0.0001,-0.00010,10.000
10,143.320,0.00,-0.0001,-0.00010,10.000
10,143.430,0.00,-0.0001,-0.00010,10.000
10,143.540,0.00,-0.0001,-0.00010,10.000
10,143.650,0.00,-0.0001,-0.00010,10.000
10,143.760,0.00,-0.0001,-0.00010,10.000
10,143.870,0.00,-0.0001,-0.00010,10.000
10,143.980,0.00,-0.0001,-0.00010,10.000
10,144.090,0.00,-0.0001,-0.00010,10.000
10,144.200,0.00,-0.0001,-0.00010,10.000
10,144.310,-0.01,-0.0001,-0.00010,10.000
10,144.420,0.00,-0.0001,-0.00010,10.000
10,144.530,0.00,-0.0001,-0.00010,10.000
10,144.640,0.00,-0.0001,-0.00010,10.000
10,144.750,0.00,-0.0001,-0.00010,10.000
10,144.790,0.01,-0.0001,-0.00010,10.000