File: calibDATA_loadcell/date_30:1:2018/MTSdata_date_1.30/radhen_10cyc_black_0deg_1mms_1N.txt
""
"Test Method","Radhen_Load_Cntrl_Cmprsn_250N_12-7.msm"
"Sample I. D.","Sample1.mss"
"Specimen Number","11"

"TheCycle_Output ()","_Time (s)","_Load (N)","_Extension (mm)","RealTimeDepth (mm)","CycleNumber ()"

0,0.180,0.02,0.0000,0.00000,0.000
1,0.330,0.00,0.0876,0.08760,1.000
1,0.470,0.01,0.2276,0.22760,1.000
1,0.610,0.00,0.3678,0.36780,1.000
1,0.750,0.01,0.5076,0.50760,1.000
1,0.890,0.01,0.6476,0.64760,1.000
1,1.030,0.00,0.7876,0.78760,1.000
1,1.170,0.01,0.9278,0.92780,1.000
1,1.310,0.01,1.0676,1.06760,1.000
1,1.450,0.01,1.2079,1.20790,1.000
1,1.590,0.01,1.3475,1.34750,1.000
1,1.730,0.01,1.4878,1.48780,1.000
1,1.870,0.01,1.6276,1.62760,1.000
1,2.010,0.01,1.7678,1.76780,1.000
1,2.150,0.01,1.9076,1.90760,1.000
1,2.290,0.02,2.0478,2.04780,1.000
1,2.430,0.01,2.1875,2.18750,1.000
1,2.570,0.01,2.3279,2.32790,1.000
1,2.710,0.01,2.4678,2.46780,1.000
1,2.850,0.01,2.6077,2.60770,1.000
1,2.990,0.01,2.7477,2.74770,1.000
1,3.130,0.01,2.8879,2.88790,1.000
1,3.270,0.01,3.0277,3.02770,1.000
1,3.410,0.01,3.1679,3.16790,1.000
1,3.550,0.01,3.3077,3.30770,1.000
1,3.690,0.01,3.4479,3.44790,1.000
1,3.830,0.01,3.5878,3.58780,1.000
1,3.970,0.01,3.7278,3.72780,1.000
1,4.110,0.01,3.8677,3.86770,1.000
1,4.250,0.01,4.0078,4.00780,1.000
1,4.390,0.01,4.1477,4.14770,1.000
1,4.530,0.01,4.2879,4.28790,1.000
1,4.670,0.01,4.4277,4.42770,1.000
1,4.810,0.01,4.5679,4.56790,1.000
1,4.950,0.01,4.7078,4.70780,1.000
1,5.090,0.01,4.8480,4.84800,1.000
1,5.230,0.01,4.9878,4.98780,1.000
1,5.370,0.01,5.1279,5.12790,1.000
1,5.510,0.02,5.2680,5.26800,1.000
1,5.650,0.09,5.4080,5.40800,1.000
1,5.790,0.26,5.5479,5.54790,1.000
1,5.930,0.59,5.6881,5.68810,1.000
1,6.070,1.05,5.8278,5.82780,1.000
1,6.220,0.90,5.7805,5.78050,1.000
1,6.360,0.45,5.6408,5.64080,1.000
1,6.500,0.17,5.5006,5.50060,1.000
1,6.640,0.04,5.3606,5.36060,1.000
1,6.780,0.01,5.2207,5.22070,1.000
1,6.920,0.01,5.0805,5.08050,1.000
1,7.060,0.00,4.9407,4.94070,1.000
1,7.200,0.01,4.8007,4.80070,1.000
1,7.340,0.01,4.6606,4.66060,1.000
1,7.480,0.01,4.5205,4.52050,1.000
1,7.620,0.01,4.3806,4.38060,1.000
1,7.760,0.01,4.2405,4.24050,1.000
1,7.900,0.01,4.1006,4.10060,1.000
1,8.040,0.01,3.9605,3.96050,1.000
1,8.180,0.01,3.8205,3.82050,1.000
1,8.320,0.01,3.6806,3.68060,1.000
1,8.460,0.01,3.5405,3.54050,1.000
1,8.600,0.01,3.4005,3.40050,1.000
1,8.740,0.00,3.2604,3.26040,1.000
1,8.880,0.01,3.1205,3.12050,1.000
1,9.020,0.01,2.9805,2.98050,1.000
1,9.160,0.01,2.8405,2.84050,1.000
1,9.300,0.01,2.7004,2.70040,1.000
1,9.440,0.01,2.5604,2.56040,1.000
1,9.580,0.01,2.4204,2.42040,1.000
1,9.720,0.01,2.2805,2.28050,1.000
1,9.860,0.01,2.1404,2.14040,1.000
1,10.000,0.01,2.0004,2.00040,1.000
1,10.140,0.01,1.8603,1.86030,1.000
1,10.280,0.01,1.7203,1.72030,1.000
1,10.420,0.01,1.5802,1.58020,1.000
1,10.560,0.01,1.4402,1.44020,1.000
1,10.700,0.00,1.3003,1.30030,1.000
1,10.840,0.01,1.1605,1.16050,1.000
1,10.980,0.01,1.0202,1.02020,1.000
1,11.120,0.00,0.8805,0.88050,1.000
1,11.260,0.01,0.7401,0.74010,1.000
1,11.400,0.01,0.6002,0.60020,1.000
1,11.540,0.01,0.4601,0.46010,1.000
1,11.680,0.01,0.3203,0.32030,1.000
1,11.820,0.01,0.1802,0.18020,1.000
1,11.960,0.01,0.0401,0.04010,1.000
1,12.110,0.01,-0.0326,-0.03260,1.000
1,12.250,0.00,-0.0003,-0.00030,1.000
1,12.390,0.01,-0.0003,-0.00030,1.000
1,12.530,0.01,-0.0003,-0.00030,1.000
1,12.670,0.01,-0.0003,-0.00030,1.000
1,12.810,0.01,-0.0003,-0.00030,1.000
1,12.950,0.01,-0.0003,-0.00030,1.000
1,13.090,0.01,-0.0003,-0.00030,1.000
1,13.230,0.01,-0.0003,-0.00030,1.000
1,13.370,0.01,-0.0003,-0.00030,1.000
1,13.510,0.01,-0.0003,-0.00030,1.000
1,13.650,0.01,-0.0003,-0.00030,1.000
1,13.790,0.01,-0.0003,-0.00030,1.000
1,13.930,0.01,-0.0003,-0.00030,1.000
1,14.070,0.01,-0.0002,-0.00020,1.000
1,14.210,0.01,-0.0002,-0.00020,1.000
1,14.350,0.01,-0.0002,-0.00020,1.000
1,14.490,0.01,-0.0002,-0.00020,1.000
1,14.630,0.01,-0.0002,-0.00020,1.000
1,14.770,0.01,-0.0002,-0.00020,1.000
1,14.910,0.01,-0.0002,-0.00020,1.000
1,15.050,0.01,-0.0002,-0.00020,1.000
1,15.210,0.01,-0.0002,-0.00020,1.000
1,15.350,0.01,-0.0002,-0.00020,1.000
1,15.490,0.01,-0.0002,-0.00020,1.000
1,15.630,0.01,-0.0002,-0.00020,1.000
1,15.770,0.01,-0.0002,-0.00020,1.000
1,15.910,0.01,-0.0002,-0.00020,1.000
1,16.050,0.01,-0.0002,-0.00020,1.000
1,16.190,0.01,-0.0002,-0.00020,1.000
1,16.330,0.01,-0.0002,-0.00020,1.000
1,16.470,0.01,-0.0002,-0.00020,1.000
1,16.610,0.00,-0.0002,-0.00020,1.000
1,16.750,0.01,-0.0001,-0.00010,1.000
1,16.890,0.01,-0.0001,-0.00010,1.000
1,17.030,0.01,-0.0001,-0.00010,1.000
1,17.170,0.01,-0.0001,-0.00010,1.000
1,17.310,0.00,-0.0001,-0.00010,1.000
1,17.450,0.00,-0.0001,-0.00010,1.000
1,17.590,0.01,-0.0001,-0.00010,1.000
1,17.730,0.01,-0.0001,-0.00010,1.000
1,17.870,0.01,-0.0001,-0.00010,1.000
1,18.010,0.01,-0.0001,-0.00010,1.000
2,18.270,0.01,0.0000,0.00000,2.000
2,18.410,0.01,0.1175,0.11750,2.000
2,18.550,0.01,0.2576,0.25760,2.000
2,18.690,0.01,0.3978,0.39780,2.000
2,18.830,0.01,0.5378,0.53780,2.000
2,18.970,0.01,0.6776,0.67760,2.000
2,19.110,0.00,0.8178,0.81780,2.000
2,19.250,0.01,0.9578,0.95780,2.000
2,19.390,0.01,1.0978,1.09780,2.000
2,19.530,0.01,1.2379,1.23790,2.000
2,19.670,0.01,1.3776,1.37760,2.000
2,19.810,0.01,1.5178,1.51780,2.000
2,19.950,0.00,1.6577,1.65770,2.000
2,20.090,0.01,1.7976,1.79760,2.000
2,20.230,0.01,1.9378,1.93780,2.000
2,20.370,0.01,2.0777,2.07770,2.000
2,20.510,0.01,2.2178,2.21780,2.000
2,20.650,0.01,2.3578,2.35780,2.000
2,20.790,0.00,2.4979,2.49790,2.000
2,20.930,0.01,2.6377,2.63770,2.000
2,21.070,0.01,2.7780,2.77800,2.000
2,21.210,0.00,2.9178,2.91780,2.000
2,21.350,0.01,3.0578,3.05780,2.000
2,21.490,0.01,3.1978,3.19780,2.000
2,21.630,0.01,3.3379,3.33790,2.000
2,21.770,0.01,3.4778,3.47780,2.000
2,21.910,0.00,3.6179,3.61790,2.000
2,22.050,0.01,3.7578,3.75780,2.000
2,22.190,0.00,3.8979,3.89790,2.000
2,22.330,0.01,4.0378,4.03780,2.000
2,22.470,0.01,4.1779,4.17790,2.000
2,22.610,0.00,4.3178,4.31780,2.000
2,22.750,0.01,4.4579,4.45790,2.000
2,22.890,0.00,4.5977,4.59770,2.000
2,23.030,0.00,4.7379,4.73790,2.000
2,23.170,0.00,4.8778,4.87780,2.000
2,23.310,0.01,5.0180,5.01800,2.000
2,23.450,0.01,5.1577,5.15770,2.000
2,23.590,0.03,5.2981,5.29810,2.000
2,23.730,0.11,5.4378,5.43780,2.000
2,23.870,0.32,5.5781,5.57810,2.000
2,24.010,0.67,5.7178,5.71780,2.000
2,24.160,1.17,5.8503,5.85030,2.000
2,24.300,0.72,5.7327,5.73270,2.000
2,24.440,0.32,5.5926,5.59260,2.000
2,24.580,0.10,5.4528,5.45280,2.000
2,24.720,0.02,5.3126,5.31260,2.000
2,24.860,0.00,5.1727,5.17270,2.000
2,25.000,0.00,5.0325,5.03250,2.000
2,25.140,0.00,4.8927,4.89270,2.000
2,25.280,0.00,4.7526,4.75260,2.000
2,25.420,0.00,4.6126,4.61260,2.000
2,25.560,0.00,4.4724,4.47240,2.000
2,25.700,0.01,4.3326,4.33260,2.000
2,25.840,0.00,4.1923,4.19230,2.000
2,25.980,0.00,4.0526,4.05260,2.000
2,26.120,0.00,3.9123,3.91230,2.000
2,26.260,0.01,3.7726,3.77260,2.000
2,26.400,0.00,3.6323,3.63230,2.000
2,26.540,0.01,3.4926,3.49260,2.000
2,26.680,0.00,3.3523,3.35230,2.000
2,26.820,0.00,3.2125,3.21250,2.000
2,26.960,0.00,3.0723,3.07230,2.000
2,27.100,0.00,2.9324,2.93240,2.000
2,27.240,0.00,2.7924,2.79240,2.000
2,27.380,0.01,2.6524,2.65240,2.000
2,27.520,0.01,2.5123,2.51230,2.000
2,27.660,0.01,2.3726,2.37260,2.000
2,27.800,0.00,2.2323,2.23230,2.000
2,27.940,0.01,2.0924,2.09240,2.000
2,28.080,0.00,1.9522,1.95220,2.000
2,28.220,0.00,1.8124,1.81240,2.000
2,28.360,0.01,1.6722,1.67220,2.000
2,28.500,0.00,1.5323,1.53230,2.000
2,28.640,0.01,1.3920,1.39200,2.000
2,28.780,0.01,1.2524,1.25240,2.000
2,28.920,0.00,1.1122,1.11220,2.000
2,29.060,0.01,0.9723,0.97230,2.000
2,29.200,0.00,0.8322,0.83220,2.000
2,29.340,0.00,0.6922,0.69220,2.000
2,29.480,0.00,0.5521,0.55210,2.000
2,29.620,0.01,0.4122,0.41220,2.000
2,29.760,0.00,0.2723,0.27230,2.000
2,29.900,0.01,0.1322,0.13220,2.000
2,30.040,0.00,-0.0079,-0.00790,2.000
2,30.190,0.01,0.0000,0.00000,2.000
2,30.330,0.01,-0.0003,-0.00030,2.000
2,30.470,0.00,-0.0003,-0.00030,2.000
2,30.610,0.00,-0.0003,-0.00030,2.000
2,30.750,0.00,-0.0003,-0.00030,2.000
2,30.890,0.01,-0.0003,-0.00030,2.000
2,31.030,0.00,-0.0003,-0.00030,2.000
2,31.170,0.00,-0.0003,-0.00030,2.000
2,31.310,0.01,-0.0003,-0.00030,2.000
2,31.450,0.01,-0.0003,-0.00030,2.000
2,31.590,0.00,-0.0003,-0.00030,2.000
2,31.730,0.01,-0.0003,-0.00030,2.000
2,31.870,0.01,-0.0002,-0.00020,2.000
2,32.010,0.01,-0.0002,-0.00020,2.000
2,32.150,0.01,-0.0002,-0.00020,2.000
2,32.290,0.00,-0.0002,-0.00020,2.000
2,32.430,0.01,-0.0002,-0.00020,2.000
2,32.570,0.00,-0.0002,-0.00020,2.000
2,32.710,0.00,-0.0002,-0.00020,2.000
2,32.850,0.00,-0.0002,-0.00020,2.000
2,32.990,0.01,-0.0002,-0.00020,2.000
2,33.140,0.00,-0.0002,-0.00020,2.000
2,33.280,0.00,-0.0002,-0.00020,2.000
2,33.420,0.00,-0.0002,-0.00020,2.000
2,33.560,0.01,-0.0002,-0.00020,2.000
2,33.700,0.00,-0.0002,-0.00020,2.000
2,33.840,0.01,-0.0002,-0.00020,2.000
2,33.980,0.00,-0.0002,-0.00020,2.000
2,34.120,0.00,-0.0002,-0.00020,2.000
2,34.260,0.00,-0.0002,-0.00020,2.000
2,34.400,0.00,-0.0002,-0.00020,2.000
2,34.540,0.00,-0.0001,-0.00010,2.000
2,34.680,0.01,-0.0001,-0.00010,2.000
2,34.820,0.00,-0.0001,-0.00010,2.000
2,34.960,0.00,-0.0001,-0.00010,2.000
2,35.100,0.00,-0.0001,-0.00010,2.000
2,35.240,0.00,-0.0001,-0.00010,2.000
2,35.380,0.00,-0.0001,-0.00010,2.000
2,35.520,0.00,-0.0001,-0.00010,2.000
2,35.660,0.00,-0.0001,-0.00010,2.000
2,35.800,0.00,-0.0001,-0.00010,2.000
2,35.940,0.00,-0.0001,-0.00010,2.000
2,36.080,0.00,-0.0001,-0.00010,2.000
3,36.310,0.00,0.0266,0.02660,3.000
3,36.450,0.00,0.1667,0.16670,3.000
3,36.590,0.00,0.3067,0.30670,3.000
3,36.730,0.00,0.4467,0.44670,3.000
3,36.870,0.00,0.5867,0.58670,3.000
3,37.010,0.00,0.7268,0.72680,3.000
3,37.150,0.00,0.8666,0.86660,3.000
3,37.290,0.00,1.0068,1.00680,3.000
3,37.430,0.00,1.1469,1.14690,3.000
3,37.570,0.00,1.2868,1.28680,3.000
3,37.710,0.00,1.4266,1.42660,3.000
3,37.850,0.00,1.5669,1.56690,3.000
3,37.990,0.00,1.7066,1.70660,3.000
3,38.130,0.00,1.8468,1.84680,3.000
3,38.270,0.00,1.9866,1.98660,3.000
3,38.410,0.00,2.1268,2.12680,3.000
3,38.550,0.00,2.2667,2.26670,3.000
3,38.690,0.00,2.4069,2.40690,3.000
3,38.830,0.00,2.5467,2.54670,3.000
3,38.970,0.00,2.6868,2.68680,3.000
3,39.110,0.00,2.8267,2.82670,3.000
3,39.250,-0.01,2.9669,2.96690,3.000
3,39.390,0.00,3.1067,3.10670,3.000
3,39.530,0.00,3.2468,3.24680,3.000
3,39.670,0.00,3.3868,3.38680,3.000
3,39.810,0.00,3.5269,3.52690,3.000
3,39.950,0.00,3.6667,3.66670,3.000
3,40.090,0.00,3.8068,3.80680,3.000
3,40.230,0.00,3.9468,3.94680,3.000
3,40.370,0.00,4.0869,4.08690,3.000
3,40.510,0.00,4.2269,4.22690,3.000
3,40.650,0.00,4.3668,4.36680,3.000
3,40.790,0.00,4.5068,4.50680,3.000
3,40.930,0.00,4.6469,4.64690,3.000
3,41.070,0.00,4.7869,4.78690,3.000
3,41.210,0.00,4.9269,4.92690,3.000
3,41.350,0.00,5.0669,5.06690,3.000
3,41.490,0.01,5.2069,5.20690,3.000
3,41.630,0.05,5.3469,5.34690,3.000
3,41.770,0.17,5.4869,5.48690,3.000
3,41.910,0.42,5.6269,5.62690,3.000
3,42.050,0.81,5.7669,5.76690,3.000
3,42.200,1.25,5.8648,5.86480,3.000
3,42.340,0.69,5.7276,5.72760,3.000
3,42.480,0.31,5.5876,5.58760,3.000
3,42.620,0.09,5.4476,5.44760,3.000
3,42.760,0.02,5.3076,5.30760,3.000
3,42.900,0.00,5.1676,5.16760,3.000
3,43.040,0.00,5.0275,5.02750,3.000
3,43.180,0.00,4.8876,4.88760,3.000
3,43.320,0.00,4.7476,4.74760,3.000
3,43.460,0.00,4.6075,4.60750,3.000
3,43.600,0.00,4.4675,4.46750,3.000
3,43.740,0.00,4.3276,4.32760,3.000
3,43.880,0.00,4.1875,4.18750,3.000
3,44.020,0.00,4.0476,4.04760,3.000
3,44.160,0.00,3.9075,3.90750,3.000
3,44.300,0.00,3.7675,3.76750,3.000
3,44.440,-0.01,3.6274,3.62740,3.000
3,44.580,0.00,3.4875,3.48750,3.000
3,44.720,0.00,3.3474,3.34740,3.000
3,44.860,0.00,3.2074,3.20740,3.000
3,45.000,0.00,3.0673,3.06730,3.000
3,45.140,0.00,2.9275,2.92750,3.000
3,45.280,0.00,2.7874,2.78740,3.000
3,45.420,0.00,2.6474,2.64740,3.000
3,45.560,0.00,2.5073,2.50730,3.000
3,45.700,0.00,2.3675,2.36750,3.000
3,45.840,0.00,2.2272,2.22720,3.000
3,45.980,0.00,2.0873,2.08730,3.000
3,46.120,0.00,1.9472,1.94720,3.000
3,46.260,0.00,1.8073,1.80730,3.000
3,46.400,0.01,1.6672,1.66720,3.000
3,46.540,0.00,1.5273,1.52730,3.000
3,46.680,0.00,1.3871,1.38710,3.000
3,46.820,0.00,1.2475,1.24750,3.000
3,46.960,0.00,1.1073,1.10730,3.000
3,47.100,0.00,0.9673,0.96730,3.000
3,47.240,0.00,0.8271,0.82710,3.000
3,47.380,0.00,0.6872,0.68720,3.000
3,47.520,0.00,0.5471,0.54710,3.000
3,47.660,0.00,0.4074,0.40740,3.000
3,47.800,0.01,0.2672,0.26720,3.000
3,47.940,0.00,0.1272,0.12720,3.000
3,48.100,0.00,-0.0322,-0.03220,3.000
3,48.240,0.00,-0.0003,-0.00030,3.000
3,48.380,0.00,-0.0003,-0.00030,3.000
3,48.520,0.00,-0.0003,-0.00030,3.000
3,48.660,0.00,-0.0003,-0.00030,3.000
3,48.800,0.00,-0.0003,-0.00030,3.000
3,48.940,0.00,-0.0003,-0.00030,3.000
3,49.080,0.00,-0.0003,-0.00030,3.000
3,49.220,0.00,-0.0003,-0.00030,3.000
3,49.360,0.00,-0.0003,-0.00030,3.000
3,49.500,0.00,-0.0003,-0.00030,3.000
3,49.640,0.00,-0.0003,-0.00030,3.000
3,49.780,0.01,-0.0003,-0.00030,3.000
3,49.920,0.00,-0.0003,-0.00030,3.000
3,50.060,0.00,-0.0003,-0.00030,3.000
3,50.200,0.00,-0.0002,-0.00020,3.000
3,50.340,0.00,-0.0002,-0.00020,3.000
3,50.480,0.00,-0.0002,-0.00020,3.000
3,50.620,0.00,-0.0002,-0.00020,3.000
3,50.760,0.00,-0.0002,-0.00020,3.000
3,50.900,0.00,-0.0002,-0.00020,3.000
3,51.040,0.00,-0.0002,-0.00020,3.000
3,51.200,0.00,-0.0002,-0.00020,3.000
3,51.340,0.00,-0.0002,-0.00020,3.000
3,51.480,0.00,-0.0002,-0.00020,3.000
3,51.620,0.00,-0.0002,-0.00020,3.000
3,51.760,0.00,-0.0002,-0.00020,3.000
3,51.900,0.00,-0.0002,-0.00020,3.000
3,52.040,0.00,-0.0002,-0.00020,3.000
3,52.180,0.00,-0.0002,-0.00020,3.000
3,52.320,0.00,-0.0002,-0.00020,3.000
3,52.460,0.00,-0.0002,-0.00020,3.000
3,52.600,0.00,-0.0002,-0.00020,3.000
3,52.740,0.00,-0.0002,-0.00020,3.000
3,52.880,0.00,-0.0001,-0.00010,3.000
3,53.020,0.00,-0.0001,-0.00010,3.000
3,53.160,0.00,-0.0001,-0.00010,3.000
3,53.300,0.00,-0.0001,-0.00010,3.000
3,53.440,0.00,-0.0001,-0.00010,3.000
3,53.580,0.00,-0.0001,-0.00010,3.000
3,53.720,0.00,-0.0001,-0.00010,3.000
3,53.860,0.00,-0.0001,-0.00010,3.000
3,54.000,0.00,-0.0001,-0.00010,3.000
3,54.140,0.00,-0.0001,-0.00010,3.000
4,54.380,0.01,0.0477,0.04770,4.000
4,54.520,0.00,0.1875,0.18750,4.000
4,54.660,0.01,0.3278,0.32780,4.000
4,54.800,0.01,0.4676,0.46760,4.000
4,54.940,0.00,0.6078,0.60780,4.000
4,55.080,0.00,0.7476,0.74760,4.000
4,55.220,0.01,0.8877,0.88770,4.000
4,55.360,0.01,1.0276,1.02760,4.000
4,55.500,0.00,1.1680,1.16800,4.000
4,55.640,0.00,1.3075,1.30750,4.000
4,55.780,0.00,1.4477,1.44770,4.000
4,55.920,0.01,1.5877,1.58770,4.000
4,56.060,0.00,1.7278,1.72780,4.000
4,56.200,0.01,1.8677,1.86770,4.000
4,56.340,0.00,2.0077,2.00770,4.000
4,56.480,0.01,2.1477,2.14770,4.000
4,56.620,0.01,2.2879,2.28790,4.000
4,56.760,0.00,2.4278,2.42780,4.000
4,56.900,0.01,2.5678,2.56780,4.000
4,57.040,0.00,2.7076,2.70760,4.000
4,57.180,0.01,2.8478,2.84780,4.000
4,57.320,0.00,2.9877,2.98770,4.000
4,57.460,0.00,3.1279,3.12790,4.000
4,57.600,0.00,3.2677,3.26770,4.000
4,57.740,0.00,3.4078,3.40780,4.000
4,57.880,0.00,3.5477,3.54770,4.000
4,58.020,0.00,3.6879,3.68790,4.000
4,58.160,0.01,3.8278,3.82780,4.000
4,58.300,0.00,3.9679,3.96790,4.000
4,58.440,0.01,4.1078,4.10780,4.000
4,58.580,0.00,4.2479,4.24790,4.000
4,58.720,0.01,4.3878,4.38780,4.000
4,58.860,0.01,4.5279,4.52790,4.000
4,59.000,0.00,4.6678,4.66780,4.000
4,59.140,0.01,4.8079,4.80790,4.000
4,59.280,0.00,4.9478,4.94780,4.000
4,59.420,0.00,5.0879,5.08790,4.000
4,59.560,0.01,5.2280,5.22800,4.000
4,59.700,0.06,5.3679,5.36790,4.000
4,59.840,0.20,5.5080,5.50800,4.000
4,59.980,0.47,5.6480,5.64800,4.000
4,60.120,0.89,5.7878,5.78780,4.000
4,60.270,1.17,5.8400,5.84000,4.000
4,60.410,0.61,5.7008,5.70080,4.000
4,60.550,0.26,5.5605,5.56050,4.000
4,60.690,0.08,5.4208,5.42080,4.000
4,60.830,0.02,5.2806,5.28060,4.000
4,60.970,0.00,5.1406,5.14060,4.000
4,61.110,0.00,5.0004,5.00040,4.000
4,61.250,0.00,4.8607,4.86070,4.000
4,61.390,0.00,4.7205,4.72050,4.000
4,61.530,0.00,4.5806,4.58060,4.000
4,61.670,0.01,4.4405,4.44050,4.000
4,61.810,0.00,4.3006,4.30060,4.000
4,61.950,0.00,4.1604,4.16040,4.000
4,62.090,0.00,4.0206,4.02060,4.000
4,62.230,0.01,3.8805,3.88050,4.000
4,62.370,0.00,3.7405,3.74050,4.000
4,62.510,0.00,3.6004,3.60040,4.000
4,62.650,0.00,3.4605,3.46050,4.000
4,62.790,0.00,3.3204,3.32040,4.000
4,62.930,0.00,3.1804,3.18040,4.000
4,63.070,0.00,3.0404,3.04040,4.000
4,63.210,0.00,2.9004,2.90040,4.000
4,63.350,0.00,2.7605,2.76050,4.000
4,63.490,0.00,2.6202,2.62020,4.000
4,63.630,0.00,2.4805,2.48050,4.000
4,63.770,0.01,2.3405,2.34050,4.000
4,63.910,0.01,2.2003,2.20030,4.000
4,64.050,0.01,2.0603,2.06030,4.000
4,64.190,0.01,1.9203,1.92030,4.000
4,64.330,0.00,1.7803,1.78030,4.000
4,64.470,0.00,1.6402,1.64020,4.000
4,64.610,0.00,1.5004,1.50040,4.000
4,64.750,0.00,1.3602,1.36020,4.000
4,64.890,0.01,1.2205,1.22050,4.000
4,65.030,0.01,1.0804,1.08040,4.000
4,65.170,0.00,0.9404,0.94040,4.000
4,65.310,0.00,0.8003,0.80030,4.000
4,65.450,0.00,0.6602,0.66020,4.000
4,65.590,0.00,0.5202,0.52020,4.000
4,65.730,0.01,0.3802,0.38020,4.000
4,65.870,0.01,0.2402,0.24020,4.000
4,66.010,0.01,0.1001,0.10010,4.000
4,66.160,0.01,-0.0406,-0.04060,4.000
4,66.300,0.00,-0.0003,-0.00030,4.000
4,66.440,0.00,-0.0003,-0.00030,4.000
4,66.580,0.01,-0.0003,-0.00030,4.000
4,66.720,0.01,-0.0003,-0.00030,4.000
4,66.860,0.00,-0.0003,-0.00030,4.000
4,67.000,0.01,-0.0003,-0.00030,4.000
4,67.140,0.00,-0.0003,-0.00030,4.000
4,67.280,0.00,-0.0003,-0.00030,4.000
4,67.420,0.00,-0.0003,-0.00030,4.000
4,67.560,0.01,-0.0003,-0.00030,4.000
4,67.700,0.00,-0.0003,-0.00030,4.000
4,67.840,0.00,-0.0003,-0.00030,4.000
4,67.980,0.00,-0.0003,-0.00030,4.000
4,68.120,0.01,-0.0003,-0.00030,4.000
4,68.260,0.00,-0.0003,-0.00030,4.000
4,68.400,0.01,-0.0002,-0.00020,4.000
4,68.540,0.00,-0.0002,-0.00020,4.000
4,68.680,0.01,-0.0002,-0.00020,4.000
4,68.820,0.01,-0.0002,-0.00020,4.000
4,68.960,0.00,-0.0002,-0.00020,4.000
4,69.100,0.01,-0.0002,-0.00020,4.000
4,69.250,0.01,-0.0002,-0.00020,4.000
4,69.390,0.00,-0.0002,-0.00020,4.000
4,69.530,0.00,-0.0002,-0.00020,4.000
4,69.670,0.01,-0.0002,-0.00020,4.000
4,69.810,0.01,-0.0002,-0.00020,4.000
4,69.950,0.01,-0.0002,-0.00020,4.000
4,70.090,0.01,-0.0002,-0.00020,4.000
4,70.230,0.00,-0.0002,-0.00020,4.000
4,70.370,0.01,-0.0002,-0.00020,4.000
4,70.510,0.00,-0.0002,-0.00020,4.000
4,70.650,0.01,-0.0002,-0.00020,4.000
4,70.790,0.00,-0.0002,-0.00020,4.000
4,70.930,0.01,-0.0002,-0.00020,4.000
4,71.070,0.01,-0.0001,-0.00010,4.000
4,71.210,0.01,-0.0001,-0.00010,4.000
4,71.350,0.01,-0.0001,-0.00010,4.000
4,71.490,0.00,-0.0001,-0.00010,4.000
4,71.630,0.01,-0.0001,-0.00010,4.000
4,71.770,0.00,-0.0001,-0.00010,4.000
4,71.910,0.00,-0.0001,-0.00010,4.000
4,72.050,0.00,-0.0001,-0.00010,4.000
4,72.190,0.01,-0.0001,-0.00010,4.000
5,72.450,0.00,0.0776,0.07760,5.000
5,72.590,0.00,0.2178,0.21780,5.000
5,72.730,0.00,0.3578,0.35780,5.000
5,72.870,0.00,0.4978,0.49780,5.000
5,73.010,0.00,0.6376,0.63760,5.000
5,73.150,0.00,0.7777,0.77770,5.000
5,73.290,0.00,0.9178,0.91780,5.000
5,73.430,0.01,1.0578,1.05780,5.000
5,73.570,0.01,1.1979,1.19790,5.000
5,73.710,0.00,1.3377,1.33770,5.000
5,73.850,0.00,1.4777,1.47770,5.000
5,73.990,0.01,1.6178,1.61780,5.000
5,74.130,0.00,1.7577,1.75770,5.000
5,74.270,0.00,1.8978,1.89780,5.000
5,74.410,0.00,2.0377,2.03770,5.000
5,74.550,0.00,2.1779,2.17790,5.000
5,74.690,0.01,2.3179,2.31790,5.000
5,74.830,0.00,2.4579,2.45790,5.000
5,74.970,0.00,2.5978,2.59780,5.000
5,75.110,0.00,2.7379,2.73790,5.000
5,75.250,0.00,2.8777,2.87770,5.000
5,75.390,0.00,3.0179,3.01790,5.000
5,75.530,0.00,3.1578,3.15780,5.000
5,75.670,0.00,3.2978,3.29780,5.000
5,75.810,0.01,3.4378,3.43780,5.000
5,75.950,0.00,3.5779,3.57790,5.000
5,76.090,0.01,3.7178,3.71780,5.000
5,76.230,0.01,3.8579,3.85790,5.000
5,76.370,0.00,3.9978,3.99780,5.000
5,76.510,0.01,4.1380,4.13800,5.000
5,76.650,0.00,4.2778,4.27780,5.000
5,76.790,0.01,4.4180,4.41800,5.000
5,76.930,0.00,4.5578,4.55780,5.000
5,77.070,0.00,4.6980,4.69800,5.000
5,77.210,0.01,4.8379,4.83790,5.000
5,77.350,0.01,4.9779,4.97790,5.000
5,77.490,0.01,5.1178,5.11780,5.000
5,77.630,0.02,5.2580,5.25800,5.000
5,77.770,0.08,5.3980,5.39800,5.000
5,77.910,0.24,5.5381,5.53810,5.000
5,78.050,0.55,5.6779,5.67790,5.000
5,78.190,1.00,5.8179,5.81790,5.000
5,78.340,0.88,5.7746,5.77460,5.000
5,78.480,0.43,5.6347,5.63470,5.000
5,78.620,0.16,5.4947,5.49470,5.000
5,78.760,0.04,5.3546,5.35460,5.000
5,78.900,0.01,5.2147,5.21470,5.000
5,79.040,0.01,5.0745,5.07450,5.000
5,79.180,0.00,4.9347,4.93470,5.000
5,79.320,0.00,4.7946,4.79460,5.000
5,79.460,0.00,4.6546,4.65460,5.000
5,79.600,0.01,4.5145,4.51450,5.000
5,79.740,0.00,4.3747,4.37470,5.000
5,79.880,0.00,4.2344,4.23440,5.000
5,80.020,0.00,4.0946,4.09460,5.000
5,80.160,0.00,3.9544,3.95440,5.000
5,80.300,0.01,3.8145,3.81450,5.000
5,80.440,0.00,3.6744,3.67440,5.000
5,80.580,0.01,3.5346,3.53460,5.000
5,80.720,0.00,3.3944,3.39440,5.000
5,80.860,0.00,3.2545,3.25450,5.000
5,81.000,0.00,3.1144,3.11440,5.000
5,81.140,0.00,2.9745,2.97450,5.000
5,81.280,0.01,2.8343,2.83430,5.000
5,81.420,0.00,2.6944,2.69440,5.000
5,81.560,0.00,2.5542,2.55420,5.000
5,81.700,0.00,2.4145,2.41450,5.000
5,81.840,0.00,2.2744,2.27440,5.000
5,81.980,0.01,2.1344,2.13440,5.000
5,82.120,0.00,1.9942,1.99420,5.000
5,82.260,0.00,1.8543,1.85430,5.000
5,82.400,0.00,1.7141,1.71410,5.000
5,82.540,0.01,1.5743,1.57430,5.000
5,82.680,0.00,1.4341,1.43410,5.000
5,82.820,0.00,1.2943,1.29430,5.000
5,82.960,0.00,1.1543,1.15430,5.000
5,83.100,0.00,1.0144,1.01440,5.000
5,83.240,0.00,0.8741,0.87410,5.000
5,83.380,0.00,0.7342,0.73420,5.000
5,83.520,0.00,0.5940,0.59400,5.000
5,83.660,0.00,0.4542,0.45420,5.000
5,83.800,0.00,0.3142,0.31420,5.000
5,83.940,0.01,0.1743,0.17430,5.000
5,84.080,0.01,0.0340,0.03400,5.000
5,84.230,0.00,-0.0052,-0.00520,5.000
5,84.370,0.01,-0.0003,-0.00030,5.000
5,84.510,0.00,-0.0003,-0.00030,5.000
5,84.650,0.01,-0.0003,-0.00030,5.000
5,84.790,0.00,-0.0003,-0.00030,5.000
5,84.930,0.00,-0.0003,-0.00030,5.000
5,85.070,0.00,-0.0003,-0.00030,5.000
5,85.210,0.00,-0.0003,-0.00030,5.000
5,85.350,0.00,-0.0003,-0.00030,5.000
5,85.490,0.00,-0.0003,-0.00030,5.000
5,85.630,0.00,-0.0003,-0.00030,5.000
5,85.770,0.00,-0.0003,-0.00030,5.000
5,85.910,0.00,-0.0003,-0.00030,5.000
5,86.050,0.00,-0.0003,-0.00030,5.000
5,86.190,0.01,-0.0003,-0.00030,5.000
5,86.330,0.01,-0.0002,-0.00020,5.000
5,86.470,0.00,-0.0002,-0.00020,5.000
5,86.610,0.00,-0.0002,-0.00020,5.000
5,86.750,0.00,-0.0002,-0.00020,5.000
5,86.890,0.00,-0.0002,-0.00020,5.000
5,87.030,0.00,-0.0002,-0.00020,5.000
5,87.170,0.00,-0.0002,-0.00020,5.000
5,87.320,0.00,-0.0002,-0.00020,5.000
5,87.460,0.00,-0.0002,-0.00020,5.000
5,87.600,0.00,-0.0002,-0.00020,5.000
5,87.740,0.00,-0.0002,-0.00020,5.000
5,87.880,0.01,-0.0002,-0.00020,5.000
5,88.020,0.00,-0.0002,-0.00020,5.000
5,88.160,0.01,-0.0002,-0.00020,5.000
5,88.300,0.00,-0.0002,-0.00020,5.000
5,88.440,0.00,-0.0002,-0.00020,5.000
5,88.580,0.00,-0.0002,-0.00020,5.000
5,88.720,0.00,-0.0002,-0.00020,5.000
5,88.860,0.00,-0.0002,-0.00020,5.000
5,89.000,0.00,-0.0002,-0.00020,5.000
5,89.140,0.00,-0.0001,-0.00010,5.000
5,89.280,0.00,-0.0001,-0.00010,5.000
5,89.420,0.00,-0.0001,-0.00010,5.000
5,89.560,0.00,-0.0001,-0.00010,5.000
5,89.700,0.00,-0.0001,-0.00010,5.000
5,89.840,0.00,-0.0001,-0.00010,5.000
5,89.980,0.00,-0.0001,-0.00010,5.000
5,90.120,0.01,-0.0001,-0.00010,5.000
6,90.380,0.00,0.0091,0.00910,6.000
6,90.520,0.00,0.1475,0.14750,6.000
6,90.660,0.00,0.2879,0.28790,6.000
6,90.800,0.00,0.4277,0.42770,6.000
6,90.940,0.00,0.5676,0.56760,6.000
6,91.080,0.00,0.7076,0.70760,6.000
6,91.220,0.00,0.8477,0.84770,6.000
6,91.360,-0.01,0.9877,0.98770,6.000
6,91.500,-0.01,1.1279,1.12790,6.000
6,91.640,-0.01,1.2677,1.26770,6.000
6,91.780,-0.01,1.4077,1.40770,6.000
6,91.920,-0.01,1.5477,1.54770,6.000
6,92.060,-0.01,1.6877,1.68770,6.000
6,92.200,0.00,1.8277,1.82770,6.000
6,92.340,-0.01,1.9677,1.96770,6.000
6,92.480,0.00,2.1076,2.10760,6.000
6,92.620,0.00,2.2477,2.24770,6.000
6,92.760,0.00,2.3878,2.38780,6.000
6,92.900,0.00,2.5278,2.52780,6.000
6,93.040,0.00,2.6677,2.66770,6.000
6,93.180,0.00,2.8079,2.80790,6.000
6,93.320,0.00,2.9478,2.94780,6.000
6,93.460,0.00,3.0880,3.08800,6.000
6,93.600,-0.01,3.2277,3.22770,6.000
6,93.740,0.00,3.3679,3.36790,6.000
6,93.880,0.00,3.5078,3.50780,6.000
6,94.020,0.00,3.6479,3.64790,6.000
6,94.160,0.00,3.7879,3.78790,6.000
6,94.300,0.00,3.9279,3.92790,6.000
6,94.440,-0.01,4.0679,4.06790,6.000
6,94.580,0.00,4.2079,4.20790,6.000
6,94.720,-0.01,4.3478,4.34780,6.000
6,94.860,-0.01,4.4879,4.48790,6.000
6,95.000,0.00,4.6278,4.62780,6.000
6,95.140,0.00,4.7678,4.76780,6.000
6,95.280,0.00,4.9079,4.90790,6.000
6,95.420,0.00,5.0478,5.04780,6.000
6,95.560,-0.01,5.1880,5.18800,6.000
6,95.700,0.03,5.3279,5.32790,6.000
6,95.840,0.13,5.4681,5.46810,6.000
6,95.980,0.37,5.6079,5.60790,6.000
6,96.120,0.75,5.7480,5.74800,6.000
6,96.270,1.21,5.8563,5.85630,6.000
6,96.410,0.67,5.7225,5.72250,6.000
6,96.550,0.29,5.5826,5.58260,6.000
6,96.690,0.09,5.4425,5.44250,6.000
6,96.830,0.01,5.3027,5.30270,6.000
6,96.970,-0.01,5.1625,5.16250,6.000
6,97.110,-0.01,5.0227,5.02270,6.000
6,97.250,0.00,4.8825,4.88250,6.000
6,97.390,0.00,4.7426,4.74260,6.000
6,97.530,0.00,4.6025,4.60250,6.000
6,97.670,0.00,4.4625,4.46250,6.000
6,97.810,0.00,4.3224,4.32240,6.000
6,97.950,-0.01,4.1825,4.18250,6.000
6,98.090,0.00,4.0425,4.04250,6.000
6,98.230,-0.01,3.9025,3.90250,6.000
6,98.370,0.00,3.7624,3.76240,6.000
6,98.510,-0.01,3.6225,3.62250,6.000
6,98.650,0.00,3.4824,3.48240,6.000
6,98.790,-0.01,3.3424,3.34240,6.000
6,98.930,0.00,3.2023,3.20230,6.000
6,99.070,0.00,3.0624,3.06240,6.000
6,99.210,0.00,2.9223,2.92230,6.000
6,99.350,0.00,2.7825,2.78250,6.000
6,99.490,0.00,2.6423,2.64230,6.000
6,99.630,-0.01,2.5025,2.50250,6.000
6,99.770,-0.01,2.3624,2.36240,6.000
6,99.910,0.00,2.2225,2.22250,6.000
6,100.050,-0.01,2.0824,2.08240,6.000
6,100.190,0.00,1.9423,1.94230,6.000
6,100.330,-0.01,1.8023,1.80230,6.000
6,100.470,0.00,1.6623,1.66230,6.000
6,100.610,0.00,1.5223,1.52230,6.000
6,100.750,0.00,1.3820,1.38200,6.000
6,100.890,0.00,1.2425,1.24250,6.000
6,101.030,-0.01,1.1024,1.10240,6.000
6,101.170,-0.01,0.9622,0.96220,6.000
6,101.310,0.00,0.8222,0.82220,6.000
6,101.450,-0.01,0.6823,0.68230,6.000
6,101.590,0.00,0.5422,0.54220,6.000
6,101.730,0.00,0.4023,0.40230,6.000
6,101.870,0.00,0.2623,0.26230,6.000
6,102.010,0.00,0.1222,0.12220,6.000
6,102.170,0.00,-0.0372,-0.03725,6.000
6,102.310,0.00,-0.0003,-0.00030,6.000
6,102.450,0.00,-0.0003,-0.00030,6.000
6,102.590,0.00,-0.0003,-0.00030,6.000
6,102.730,0.00,-0.0003,-0.00030,6.000
6,102.870,0.00,-0.0003,-0.00030,6.000
6,103.010,0.00,-0.0003,-0.00030,6.000
6,103.150,-0.01,-0.0003,-0.00030,6.000
6,103.290,0.00,-0.0003,-0.00030,6.000
6,103.430,0.00,-0.0003,-0.00030,6.000
6,103.570,-0.01,-0.0003,-0.00030,6.000
6,103.710,0.00,-0.0003,-0.00030,6.000
6,103.850,-0.01,-0.0003,-0.00030,6.000
6,103.990,0.00,-0.0003,-0.00030,6.000
6,104.130,-0.01,-0.0003,-0.00030,6.000
6,104.270,0.00,-0.0003,-0.00030,6.000
6,104.410,0.00,-0.0003,-0.00030,6.000
6,104.550,0.00,-0.0003,-0.00030,6.000
6,104.690,0.00,-0.0003,-0.00030,6.000
6,104.830,0.00,-0.0002,-0.00020,6.000
6,104.970,0.00,-0.0002,-0.00020,6.000
6,105.110,-0.01,-0.0002,-0.00020,6.000
6,105.260,-0.01,-0.0002,-0.00020,6.000
6,105.400,0.00,-0.0002,-0.00020,6.000
6,105.540,-0.01,-0.0002,-0.00020,6.000
6,105.680,-0.01,-0.0002,-0.00020,6.000
6,105.820,0.00,-0.0002,-0.00020,6.000
6,105.960,0.00,-0.0002,-0.00020,6.000
6,106.100,0.00,-0.0002,-0.00020,6.000
6,106.240,-0.01,-0.0002,-0.00020,6.000
6,106.380,0.00,-0.0002,-0.00020,6.000
6,106.520,0.00,-0.0002,-0.00020,6.000
6,106.660,0.00,-0.0002,-0.00020,6.000
6,106.800,0.00,-0.0002,-0.00020,6.000
6,106.940,0.00,-0.0002,-0.00020,6.000
6,107.080,0.00,-0.0002,-0.00020,6.000
6,107.220,-0.01,-0.0002,-0.00020,6.000
6,107.360,0.00,-0.0001,-0.00010,6.000
6,107.500,0.00,-0.0001,-0.00010,6.000
6,107.640,0.00,-0.0001,-0.00010,6.000
6,107.780,0.00,-0.0001,-0.00010,6.000
6,107.920,-0.01,-0.0001,-0.00010,6.000
6,108.060,0.00,-0.0001,-0.00010,6.000
6,108.200,-0.01,-0.0001,-0.00010,6.000
7,108.450,0.01,0.0575,0.05750,7.000
7,108.590,0.00,0.1977,0.19770,7.000
7,108.730,0.00,0.3378,0.33780,7.000
7,108.870,0.01,0.4777,0.47770,7.000
7,109.010,0.01,0.6178,0.61780,7.000
7,109.150,0.01,0.7577,0.75770,7.000
7,109.290,0.00,0.8978,0.89780,7.000
7,109.430,0.01,1.0378,1.03780,7.000
7,109.570,0.00,1.1780,1.17800,7.000
7,109.710,0.00,1.3176,1.31760,7.000
7,109.850,0.00,1.4579,1.45790,7.000
7,109.990,0.00,1.5977,1.59770,7.000
7,110.130,0.00,1.7378,1.73780,7.000
7,110.270,0.00,1.8777,1.87770,7.000
7,110.410,0.00,2.0178,2.01780,7.000
7,110.550,0.00,2.1576,2.15760,7.000
7,110.690,0.00,2.2978,2.29780,7.000
7,110.830,0.00,2.4378,2.43780,7.000
7,110.970,0.00,2.5778,2.57780,7.000
7,111.110,0.00,2.7177,2.71770,7.000
7,111.250,0.00,2.8579,2.85790,7.000
7,111.390,0.01,2.9978,2.99780,7.000
7,111.530,0.01,3.1380,3.13800,7.000
7,111.670,0.00,3.2777,3.27770,7.000
7,111.810,0.00,3.4179,3.41790,7.000
7,111.950,0.01,3.5578,3.55780,7.000
7,112.090,0.00,3.6979,3.69790,7.000
7,112.230,0.00,3.8377,3.83770,7.000
7,112.370,0.00,3.9779,3.97790,7.000
7,112.510,0.00,4.1177,4.11770,7.000
7,112.650,0.00,4.2580,4.25800,7.000
7,112.790,0.01,4.3977,4.39770,7.000
7,112.930,0.00,4.5379,4.53790,7.000
7,113.070,0.00,4.6778,4.67780,7.000
7,113.210,0.00,4.8180,4.81800,7.000
7,113.350,0.00,4.9577,4.95770,7.000
7,113.490,0.00,5.0979,5.09790,7.000
7,113.630,0.01,5.2378,5.23780,7.000
7,113.770,0.07,5.3780,5.37800,7.000
7,113.910,0.21,5.5178,5.51780,7.000
7,114.050,0.50,5.6579,5.65790,7.000
7,114.190,0.93,5.7977,5.79770,7.000
7,114.340,1.03,5.8102,5.81020,7.000
7,114.480,0.51,5.6707,5.67070,7.000
7,114.620,0.20,5.5307,5.53070,7.000
7,114.760,0.05,5.3907,5.39070,7.000
7,114.900,0.01,5.2507,5.25070,7.000
7,115.040,0.01,5.1106,5.11060,7.000
7,115.180,0.01,4.9707,4.97070,7.000
7,115.320,0.01,4.8307,4.83070,7.000
7,115.460,0.00,4.6907,4.69070,7.000
7,115.600,0.00,4.5505,4.55050,7.000
7,115.740,0.00,4.4106,4.41060,7.000
7,115.880,0.01,4.2704,4.27040,7.000
7,116.020,0.00,4.1306,4.13060,7.000
7,116.160,0.00,3.9905,3.99050,7.000
7,116.300,0.01,3.8505,3.85050,7.000
7,116.440,0.00,3.7105,3.71050,7.000
7,116.580,0.00,3.5706,3.57060,7.000
7,116.720,0.00,3.4305,3.43050,7.000
7,116.860,0.01,3.2905,3.29050,7.000
7,117.000,0.00,3.1505,3.15050,7.000
7,117.140,0.00,3.0105,3.01050,7.000
7,117.280,0.00,2.8704,2.87040,7.000
7,117.420,0.00,2.7305,2.73050,7.000
7,117.560,0.01,2.5903,2.59030,7.000
7,117.700,0.01,2.4506,2.45060,7.000
7,117.840,0.01,2.3104,2.31040,7.000
7,117.980,0.01,2.1704,2.17040,7.000
7,118.120,0.01,2.0303,2.03030,7.000
7,118.260,0.00,1.8904,1.89040,7.000
7,118.400,0.00,1.7501,1.75010,7.000
7,118.540,0.00,1.6103,1.61030,7.000
7,118.680,0.01,1.4703,1.47030,7.000
7,118.820,0.01,1.3301,1.33010,7.000
7,118.960,0.00,1.1904,1.19040,7.000
7,119.100,0.01,1.0504,1.05040,7.000
7,119.240,0.00,0.9102,0.91020,7.000
7,119.380,0.00,0.7704,0.77040,7.000
7,119.520,0.01,0.6301,0.63010,7.000
7,119.660,0.01,0.4903,0.49030,7.000
7,119.800,0.01,0.3503,0.35030,7.000
7,119.940,0.01,0.2103,0.21030,7.000
7,120.080,0.01,0.0699,0.06990,7.000
7,120.230,0.01,-0.0383,-0.03830,7.000
7,120.370,0.01,-0.0003,-0.00030,7.000
7,120.510,0.01,-0.0003,-0.00030,7.000
7,120.650,0.00,-0.0003,-0.00030,7.000
7,120.790,0.00,-0.0003,-0.00030,7.000
7,120.930,0.01,-0.0003,-0.00030,7.000
7,121.070,0.01,-0.0003,-0.00030,7.000
7,121.210,0.01,-0.0003,-0.00030,7.000
7,121.350,0.00,-0.0003,-0.00030,7.000
7,121.490,0.01,-0.0003,-0.00030,7.000
7,121.630,0.00,-0.0003,-0.00030,7.000
7,121.770,0.00,-0.0003,-0.00030,7.000
7,121.910,0.01,-0.0003,-0.00030,7.000
7,122.050,0.01,-0.0003,-0.00030,7.000
7,122.190,0.01,-0.0003,-0.00030,7.000
7,122.330,0.00,-0.0003,-0.00030,7.000
7,122.470,0.00,-0.0003,-0.00030,7.000
7,122.610,0.00,-0.0003,-0.00030,7.000
7,122.750,0.01,-0.0003,-0.00030,7.000
7,122.890,0.00,-0.0003,-0.00030,7.000
7,123.030,0.01,-0.0002,-0.00020,7.000
7,123.170,0.00,-0.0002,-0.00020,7.000
7,123.330,0.00,-0.0002,-0.00020,7.000
7,123.470,0.01,-0.0002,-0.00020,7.000
7,123.610,0.01,-0.0002,-0.00020,7.000
7,123.750,0.01,-0.0002,-0.00020,7.000
7,123.890,0.01,-0.0002,-0.00020,7.000
7,124.030,0.00,-0.0002,-0.00020,7.000
7,124.170,0.00,-0.0002,-0.00020,7.000
7,124.310,0.00,-0.0002,-0.00020,7.000
7,124.450,0.01,-0.0002,-0.00020,7.000
7,124.590,0.01,-0.0002,-0.00020,7.000
7,124.730,0.01,-0.0002,-0.00020,7.000
7,124.870,0.00,-0.0002,-0.00020,7.000
7,125.010,0.00,-0.0002,-0.00020,7.000
7,125.150,0.01,-0.0002,-0.00020,7.000
7,125.290,0.01,-0.0002,-0.00020,7.000
7,125.430,0.00,-0.0002,-0.00020,7.000
7,125.570,0.01,-0.0001,-0.00010,7.000
7,125.710,0.00,-0.0001,-0.00010,7.000
7,125.850,0.00,-0.0001,-0.00010,7.000
7,125.990,0.01,-0.0001,-0.00010,7.000
7,126.130,0.01,-0.0001,-0.00010,7.000
7,126.350,0.01,0.0000,0.00000,7.000
8,126.500,0.00,0.0876,0.08760,8.000
8,126.640,0.00,0.2276,0.22760,8.000
8,126.780,0.00,0.3678,0.36780,8.000
8,126.920,0.00,0.5077,0.50770,8.000
8,127.060,0.00,0.6477,0.64770,8.000
8,127.200,0.00,0.7878,0.78780,8.000
8,127.340,0.00,0.9278,0.92780,8.000
8,127.480,0.00,1.0677,1.06770,8.000
8,127.620,0.00,1.2079,1.20790,8.000
8,127.760,0.00,1.3476,1.34760,8.000
8,127.900,0.00,1.4878,1.48780,8.000
8,128.040,0.00,1.6277,1.62770,8.000
8,128.180,0.00,1.7678,1.76780,8.000
8,128.320,0.00,1.9076,1.90760,8.000
8,128.460,0.00,2.0477,2.04770,8.000
8,128.600,0.00,2.1878,2.18780,8.000
8,128.740,0.00,2.3278,2.32780,8.000
8,128.880,0.00,2.4678,2.46780,8.000
8,129.020,0.00,2.6077,2.60770,8.000
8,129.160,-0.01,2.7478,2.74780,8.000
8,129.300,0.00,2.8878,2.88780,8.000
8,129.440,0.00,3.0278,3.02780,8.000
8,129.580,0.00,3.1678,3.16780,8.000
8,129.720,0.00,3.3079,3.30790,8.000
8,129.860,0.00,3.4478,3.44780,8.000
8,130.000,0.00,3.5880,3.58800,8.000
8,130.140,0.00,3.7278,3.72780,8.000
8,130.280,0.00,3.8679,3.86790,8.000
8,130.420,-0.01,4.0079,4.00790,8.000
8,130.560,0.00,4.1480,4.14800,8.000
8,130.700,0.00,4.2878,4.28780,8.000
8,130.840,0.00,4.4279,4.42790,8.000
8,130.980,0.00,4.5679,4.56790,8.000
8,131.120,0.00,4.7079,4.70790,8.000
8,131.260,-0.01,4.8479,4.84790,8.000
8,131.400,0.00,4.9880,4.98800,8.000
8,131.540,0.00,5.1279,5.12790,8.000
8,131.680,0.01,5.2680,5.26800,8.000
8,131.820,0.08,5.4079,5.40790,8.000
8,131.960,0.25,5.5480,5.54800,8.000
8,132.100,0.57,5.6879,5.68790,8.000
8,132.240,1.03,5.8278,5.82780,8.000
8,132.390,0.98,5.8023,5.80230,8.000
8,132.530,0.48,5.6627,5.66270,8.000
8,132.670,0.19,5.5225,5.52250,8.000
8,132.810,0.04,5.3828,5.38280,8.000
8,132.950,0.00,5.2425,5.24250,8.000
8,133.090,0.00,5.1027,5.10270,8.000
8,133.230,0.00,4.9625,4.96250,8.000
8,133.370,0.00,4.8227,4.82270,8.000
8,133.510,-0.01,4.6824,4.68240,8.000
8,133.650,-0.01,4.5426,4.54260,8.000
8,133.790,0.00,4.4024,4.40240,8.000
8,133.930,0.00,4.2626,4.26260,8.000
8,134.070,0.00,4.1224,4.12240,8.000
8,134.210,0.00,3.9825,3.98250,8.000
8,134.350,-0.01,3.8425,3.84250,8.000
8,134.490,0.00,3.7026,3.70260,8.000
8,134.630,0.00,3.5624,3.56240,8.000
8,134.770,0.00,3.4226,3.42260,8.000
8,134.910,0.00,3.2823,3.28230,8.000
8,135.050,0.00,3.1426,3.14260,8.000
8,135.190,-0.01,3.0024,3.00240,8.000
8,135.330,0.00,2.8625,2.86250,8.000
8,135.470,-0.01,2.7223,2.72230,8.000
8,135.610,0.00,2.5823,2.58230,8.000
8,135.750,0.00,2.4425,2.44250,8.000
8,135.890,0.00,2.3025,2.30250,8.000
8,136.030,0.00,2.1624,2.16240,8.000
8,136.170,0.00,2.0224,2.02240,8.000
8,136.310,0.00,1.8824,1.88240,8.000
8,136.450,0.00,1.7422,1.74220,8.000
8,136.590,0.00,1.6023,1.60230,8.000
8,136.730,0.00,1.4623,1.46230,8.000
8,136.870,0.00,1.3221,1.32210,8.000
8,137.010,0.00,1.1825,1.18250,8.000
8,137.150,0.00,1.0422,1.04220,8.000
8,137.290,0.00,0.9023,0.90230,8.000
8,137.430,0.00,0.7623,0.76230,8.000
8,137.570,0.00,0.6222,0.62220,8.000
8,137.710,0.00,0.4822,0.48220,8.000
8,137.850,0.00,0.3422,0.34220,8.000
8,137.990,0.00,0.2024,0.20240,8.000
8,138.130,0.00,0.0621,0.06210,8.000
8,138.290,0.00,-0.0407,-0.04070,8.000
8,138.430,0.00,-0.0003,-0.00030,8.000
8,138.570,0.00,-0.0003,-0.00030,8.000
8,138.710,0.00,-0.0003,-0.00030,8.000
8,138.850,0.00,-0.0003,-0.00030,8.000
8,138.990,0.00,-0.0003,-0.00030,8.000
8,139.130,0.00,-0.0003,-0.00030,8.000
8,139.270,0.00,-0.0003,-0.00030,8.000
8,139.410,0.00,-0.0003,-0.00030,8.000
8,139.550,0.00,-0.0003,-0.00030,8.000
8,139.690,0.00,-0.0003,-0.00030,8.000
8,139.830,0.00,-0.0003,-0.00030,8.000
8,139.970,0.00,-0.0003,-0.00030,8.000
8,140.110,-0.01,-0.0003,-0.00030,8.000
8,140.250,0.00,-0.0003,-0.00030,8.000
8,140.390,0.00,-0.0003,-0.00030,8.000
8,140.530,0.00,-0.0003,-0.00030,8.000
8,140.670,0.00,-0.0003,-0.00030,8.000
8,140.810,0.00,-0.0003,-0.00030,8.000
8,140.950,0.00,-0.0002,-0.00020,8.000
8,141.090,0.00,-0.0002,-0.00020,8.000
8,141.230,0.00,-0.0002,-0.00020,8.000
8,141.390,0.00,-0.0002,-0.00020,8.000
8,141.530,0.00,-0.0002,-0.00020,8.000
8,141.670,0.00,-0.0002,-0.00020,8.000
8,141.810,0.00,-0.0002,-0.00020,8.000
8,141.950,0.00,-0.0002,-0.00020,8.000
8,142.090,0.00,-0.0002,-0.00020,8.000
8,142.230,0.00,-0.0002,-0.00020,8.000
8,142.370,0.00,-0.0002,-0.00020,8.000
8,142.510,0.00,-0.0002,-0.00020,8.000
8,142.650,0.00,-0.0002,-0.00020,8.000
8,142.790,0.00,-0.0002,-0.00020,8.000
8,142.930,0.00,-0.0002,-0.00020,8.000
8,143.070,0.00,-0.0002,-0.00020,8.000
8,143.210,0.00,-0.0002,-0.00020,8.000
8,143.350,-0.01,-0.0002,-0.00020,8.000
8,143.490,0.00,-0.0002,-0.00020,8.000
8,143.630,-0.01,-0.0001,-0.00010,8.000
8,143.770,0.00,-0.0001,-0.00010,8.000
8,143.910,0.00,-0.0001,-0.00010,8.000
8,144.050,0.00,-0.0001,-0.00010,8.000
8,144.190,0.00,-0.0001,-0.00010,8.000
9,144.420,0.00,0.0000,0.00000,9.000
9,144.560,-0.01,0.1074,0.10740,9.000
9,144.700,-0.01,0.2478,0.24780,9.000
9,144.840,-0.01,0.3877,0.38770,9.000
9,144.980,0.00,0.5278,0.52780,9.000
9,145.120,-0.01,0.6676,0.66760,9.000
9,145.260,0.00,0.8077,0.80770,9.000
9,145.400,-0.01,0.9478,0.94780,9.000
9,145.540,-0.01,1.0879,1.08790,9.000
9,145.680,-0.01,1.2278,1.22780,9.000
9,145.820,-0.01,1.3676,1.36760,9.000
9,145.960,-0.01,1.5078,1.50780,9.000
9,146.100,-0.01,1.6479,1.64790,9.000
9,146.240,-0.01,1.7877,1.78770,9.000
9,146.380,-0.01,1.9278,1.92780,9.000
9,146.520,-0.01,2.0676,2.06760,9.000
9,146.660,-0.01,2.2078,2.20780,9.000
9,146.800,0.00,2.3478,2.34780,9.000
9,146.940,-0.01,2.4879,2.48790,9.000
9,147.080,0.00,2.6277,2.62770,9.000
9,147.220,0.00,2.7679,2.76790,9.000
9,147.360,-0.01,2.9079,2.90790,9.000
9,147.500,0.00,3.0479,3.04790,9.000
9,147.640,0.00,3.1878,3.18780,9.000
9,147.780,-0.01,3.3278,3.32780,9.000
9,147.920,-0.01,3.4679,3.46790,9.000
9,148.060,-0.01,3.6079,3.60790,9.000
9,148.200,0.00,3.7479,3.74790,9.000
9,148.340,0.00,3.8879,3.88790,9.000
9,148.480,0.00,4.0279,4.02790,9.000
9,148.620,-0.01,4.1679,4.16790,9.000
9,148.760,0.00,4.3078,4.30780,9.000
9,148.900,-0.01,4.4478,4.44780,9.000
9,149.040,0.00,4.5879,4.58790,9.000
9,149.180,0.00,4.7278,4.72780,9.000
9,149.320,-0.01,4.8680,4.86800,9.000
9,149.460,0.00,5.0079,5.00790,9.000
9,149.600,-0.01,5.1480,5.14800,9.000
9,149.740,0.02,5.2880,5.28800,9.000
9,149.880,0.09,5.4280,5.42800,9.000
9,150.020,0.29,5.5679,5.56790,9.000
9,150.160,0.62,5.7081,5.70810,9.000
9,150.310,1.14,5.8576,5.85760,9.000
9,150.450,0.89,5.7825,5.78250,9.000
9,150.590,0.43,5.6426,5.64260,9.000
9,150.730,0.15,5.5026,5.50260,9.000
9,150.870,0.03,5.3626,5.36260,9.000
9,151.010,0.00,5.2226,5.22260,9.000
9,151.150,0.00,5.0824,5.08240,9.000
9,151.290,0.00,4.9427,4.94270,9.000
9,151.430,-0.01,4.8026,4.80260,9.000
9,151.570,0.00,4.6626,4.66260,9.000
9,151.710,-0.01,4.5223,4.52230,9.000
9,151.850,0.00,4.3825,4.38250,9.000
9,151.990,-0.01,4.2424,4.24240,9.000
9,152.130,0.00,4.1026,4.10260,9.000
9,152.270,0.00,3.9624,3.96240,9.000
9,152.410,0.00,3.8226,3.82260,9.000
9,152.550,-0.01,3.6824,3.68240,9.000
9,152.690,-0.01,3.5426,3.54260,9.000
9,152.830,-0.01,3.4024,3.40240,9.000
9,152.970,-0.01,3.2624,3.26240,9.000
9,153.110,-0.01,3.1224,3.12240,9.000
9,153.250,-0.01,2.9825,2.98250,9.000
9,153.390,0.00,2.8425,2.84250,9.000
9,153.530,-0.01,2.7023,2.70230,9.000
9,153.670,-0.01,2.5623,2.56230,9.000
9,153.810,-0.01,2.4225,2.42250,9.000
9,153.950,-0.01,2.2823,2.28230,9.000
9,154.090,0.00,2.1424,2.14240,9.000
9,154.230,-0.01,2.0023,2.00230,9.000
9,154.370,-0.01,1.8624,1.86240,9.000
9,154.510,-0.01,1.7223,1.72230,9.000
9,154.650,-0.01,1.5823,1.58230,9.000
9,154.790,-0.01,1.4422,1.44220,9.000
9,154.930,-0.01,1.3022,1.30220,9.000
9,155.070,0.00,1.1624,1.16240,9.000
9,155.210,-0.01,1.0223,1.02230,9.000
9,155.350,0.00,0.8823,0.88230,9.000
9,155.490,0.00,0.7423,0.74230,9.000
9,155.630,-0.01,0.6023,0.60230,9.000
9,155.770,-0.01,0.4622,0.46220,9.000
9,155.910,-0.01,0.3223,0.32230,9.000
9,156.050,0.00,0.1822,0.18220,9.000
9,156.190,0.00,0.0421,0.04210,9.000
9,156.350,-0.01,-0.0219,-0.02190,9.000
9,156.490,-0.01,-0.0003,-0.00030,9.000
9,156.630,-0.01,-0.0003,-0.00030,9.000
9,156.770,0.00,-0.0003,-0.00030,9.000
9,156.910,-0.01,-0.0003,-0.00030,9.000
9,157.050,-0.01,-0.0003,-0.00030,9.000
9,157.190,-0.01,-0.0003,-0.00030,9.000
9,157.330,0.00,-0.0003,-0.00030,9.000
9,157.470,0.00,-0.0003,-0.00030,9.000
9,157.610,-0.01,-0.0003,-0.00030,9.000
9,157.750,0.00,-0.0003,-0.00030,9.000
9,157.890,0.00,-0.0003,-0.00030,9.000
9,158.030,-0.01,-0.0003,-0.00030,9.000
9,158.170,-0.01,-0.0003,-0.00030,9.000
9,158.310,-0.01,-0.0003,-0.00030,9.000
9,158.450,-0.01,-0.0003,-0.00030,9.000
9,158.590,-0.01,-0.0003,-0.00030,9.000
9,158.730,-0.01,-0.0003,-0.00030,9.000
9,158.870,-0.01,-0.0003,-0.00030,9.000
9,159.010,-0.01,-0.0003,-0.00030,9.000
9,159.150,0.00,-0.0002,-0.00020,9.000
9,159.290,0.00,-0.0002,-0.00020,9.000
9,159.450,-0.01,-0.0002,-0.00020,9.000
9,159.590,0.00,-0.0002,-0.00020,9.000
9,159.730,0.00,-0.0002,-0.00020,9.000
9,159.870,0.00,-0.0002,-0.00020,9.000
9,160.010,-0.01,-0.0002,-0.00020,9.000
9,160.150,-0.01,-0.0002,-0.00020,9.000
9,160.290,-0.01,-0.0002,-0.00020,9.000
9,160.430,0.00,-0.0002,-0.00020,9.000
9,160.570,-0.01,-0.0002,-0.00020,9.000
9,160.710,-0.01,-0.0002,-0.00020,9.000
9,160.850,-0.01,-0.0002,-0.00020,9.000
9,160.990,-0.01,-0.0002,-0.00020,9.000
9,161.130,-0.01,-0.0002,-0.00020,9.000
9,161.270,0.00,-0.0002,-0.00020,9.000
9,161.410,0.00,-0.0002,-0.00020,9.000
9,161.550,-0.01,-0.0002,-0.00020,9.000
9,161.690,-0.01,-0.0001,-0.00010,9.000
9,161.830,-0.01,-0.0001,-0.00010,9.000
9,161.970,0.00,-0.0001,-0.00010,9.000
9,162.110,0.00,-0.0001,-0.00010,9.000
9,162.250,-0.01,-0.0001,-0.00010,9.000
10,162.490,0.00,0.0000,0.00010,10.000
10,162.630,0.00,0.1175,0.11760,10.000
10,162.770,0.00,0.2577,0.25780,10.000
10,162.910,0.00,0.3978,0.39790,10.000
10,163.050,0.00,0.5379,0.53800,10.000
10,163.190,0.00,0.6776,0.67770,10.000
10,163.330,0.01,0.8178,0.81790,10.000
10,163.470,0.00,0.9578,0.95790,10.000
10,163.610,0.00,1.0980,1.09810,10.000
10,163.750,0.01,1.2378,1.23790,10.000
10,163.890,0.00,1.3777,1.37780,10.000
10,164.030,0.00,1.5178,1.51790,10.000
10,164.170,0.00,1.6579,1.65800,10.000
10,164.310,0.00,1.7977,1.79780,10.000
10,164.450,0.00,1.9379,1.93800,10.000
10,164.590,0.00,2.0777,2.07780,10.000
10,164.730,0.00,2.2178,2.21790,10.000
10,164.870,0.00,2.3578,2.35790,10.000
10,165.010,0.01,2.4980,2.49810,10.000
10,165.150,0.00,2.6376,2.63770,10.000
10,165.290,0.00,2.7779,2.77800,10.000
10,165.430,0.00,2.9177,2.91780,10.000
10,165.570,0.00,3.0579,3.05800,10.000
10,165.710,0.00,3.1978,3.19790,10.000
10,165.850,0.00,3.3379,3.33800,10.000
10,165.990,0.00,3.4778,3.47790,10.000
10,166.130,0.00,3.6180,3.61810,10.000
10,166.270,0.00,3.7577,3.75780,10.000
10,166.410,0.00,3.8978,3.89790,10.000
10,166.550,0.00,4.0378,4.03790,10.000
10,166.690,0.00,4.1779,4.17800,10.000
10,166.830,0.00,4.3178,4.31790,10.000
10,166.970,0.00,4.4578,4.45790,10.000
10,167.110,0.00,4.5978,4.59790,10.000
10,167.250,0.00,4.7379,4.73800,10.000
10,167.390,0.00,4.8780,4.87810,10.000
10,167.530,0.00,5.0178,5.01790,10.000
10,167.670,0.00,5.1578,5.15790,10.000
10,167.810,0.02,5.2981,5.29820,10.000
10,167.950,0.10,5.4379,5.43800,10.000
10,168.090,0.31,5.5779,5.57800,10.000
10,168.230,0.66,5.7178,5.71790,10.000
10,168.380,1.19,5.8637,5.86380,10.000
10,168.520,0.84,5.7705,5.77060,10.000
10,168.660,0.40,5.6308,5.63090,10.000
10,168.800,0.14,5.4905,5.49060,10.000
10,168.940,0.03,5.3508,5.35090,10.000
10,169.080,0.00,5.2106,5.21070,10.000
10,169.220,0.01,5.0706,5.07070,10.000
10,169.360,0.00,4.9305,4.93060,10.000
10,169.500,0.00,4.7907,4.79080,10.000
10,169.640,0.00,4.6505,4.65060,10.000
10,169.780,0.01,4.5105,4.51060,10.000
10,169.920,0.00,4.3706,4.37070,10.000
10,170.060,0.00,4.2305,4.23060,10.000
10,170.200,0.00,4.0906,4.09070,10.000
10,170.340,-0.01,3.9505,3.95060,10.000
10,170.480,0.00,3.8105,3.81060,10.000
10,170.620,0.00,3.6705,3.67060,10.000
10,170.760,0.00,3.5305,3.53060,10.000
10,170.900,0.00,3.3905,3.39060,10.000
10,171.040,0.00,3.2503,3.25040,10.000
10,171.180,0.00,3.1105,3.11060,10.000
10,171.320,0.00,2.9705,2.97060,10.000
10,171.460,0.00,2.8305,2.83060,10.000
10,171.600,0.00,2.6904,2.69050,10.000
10,171.740,0.00,2.5504,2.55050,10.000
10,171.880,0.00,2.4105,2.41060,10.000
10,172.020,0.00,2.2703,2.27040,10.000
10,172.160,0.00,2.1305,2.13060,10.000
10,172.300,0.00,1.9903,1.99040,10.000
10,172.440,0.00,1.8505,1.85060,10.000
10,172.580,0.00,1.7102,1.71030,10.000
10,172.720,0.00,1.5704,1.57050,10.000
10,172.860,0.00,1.4302,1.43030,10.000
10,173.000,0.00,1.2904,1.29050,10.000
10,173.140,0.00,1.1504,1.15050,10.000
10,173.280,0.00,1.0104,1.01050,10.000
10,173.420,0.00,0.8703,0.87040,10.000
10,173.560,0.00,0.7303,0.73040,10.000
10,173.700,0.00,0.5902,0.59030,10.000
10,173.840,0.00,0.4504,0.45050,10.000
10,173.980,0.00,0.3101,0.31020,10.000
10,174.120,0.00,0.1703,0.17040,10.000
10,174.260,0.00,0.0300,0.03010,10.000
10,174.420,0.00,-0.0119,-0.01180,10.000
10,174.560,0.00,-0.0004,-0.00030,10.000
10,174.700,0.00,-0.0004,-0.00030,10.000
10,174.840,0.00,-0.0004,-0.00030,10.000
10,174.980,0.00,-0.0004,-0.00030,10.000
10,175.120,0.00,-0.0004,-0.00030,10.000
10,175.260,0.00,-0.0004,-0.00030,10.000
10,175.400,0.00,-0.0004,-0.00030,10.000
10,175.540,0.00,-0.0003,-0.00020,10.000
10,175.680,0.00,-0.0003,-0.00020,10.000
10,175.820,0.00,-0.0003,-0.00020,10.000
10,175.960,-0.01,-0.0003,-0.00020,10.000
10,176.100,0.00,-0.0003,-0.00020,10.000
10,176.240,0.00,-0.0003,-0.00020,10.000
10,176.380,0.00,-0.0003,-0.00020,10.000
10,176.520,0.00,-0.0003,-0.00020,10.000
10,176.660,0.00,-0.0003,-0.00020,10.000
10,176.800,0.00,-0.0003,-0.00020,10.000
10,176.940,-0.01,-0.0003,-0.00020,10.000
10,177.080,0.00,-0.0003,-0.00020,10.000
10,177.220,0.00,-0.0003,-0.00020,10.000
10,177.360,0.00,-0.0002,-0.00010,10.000
10,177.520,0.00,-0.0002,-0.00010,10.000
10,177.660,0.00,-0.0002,-0.00010,10.000
10,177.800,0.00,-0.0002,-0.00010,10.000
10,177.940,0.00,-0.0002,-0.00010,10.000
10,178.080,0.00,-0.0002,-0.00010,10.000
10,178.220,0.00,-0.0002,-0.00010,10.000
10,178.360,0.00,-0.0002,-0.00010,10.000
10,178.500,0.00,-0.0002,-0.00010,10.000
10,178.640,0.00,-0.0002,-0.00010,10.000
10,178.780,0.00,-0.0002,-0.00010,10.000
10,178.920,0.00,-0.0002,-0.00010,10.000
10,179.060,0.00,-0.0002,-0.00010,10.000
10,179.200,0.00,-0.0002,-0.00010,10.000
10,179.340,0.00,-0.0002,-0.00010,10.000
10,179.480,0.00,-0.0002,-0.00010,10.000
10,179.620,0.00,-0.0002,-0.00010,10.000
10,179.760,0.00,-0.0002,-0.00010,10.000
10,179.900,0.00,-0.0001,0.00000,10.000
10,180.040,0.00,-0.0001,0.00000,10.000
10,180.180,0.00,-0.0001,0.00000,10.000
10,180.320,0.00,-0.0001,0.00000,10.000
10,180.410,0.00,-0.0001,0.00000,10.000