File: calibDATA_loadcell/date_30:1:2018/MTSdata_date_1.30/radhen_10cyc_black_-20deg_1mms_50N.txt
""
"Test Method","Radhen_Load_Cntrl_Cmprsn_250N_12-7.msm"
"Sample I. D.","Sample1.mss"
"Specimen Number","12"

"TheCycle_Output ()","_Time (s)","_Load (N)","_Extension (mm)","RealTimeDepth (mm)","CycleNumber ()"

0,0.150,0.00,0.0000,0.00000,0.000
1,0.300,-0.01,0.0883,0.08830,1.000
1,0.440,-0.01,0.2286,0.22860,1.000
1,0.580,0.00,0.3683,0.36830,1.000
1,0.720,-0.01,0.5086,0.50860,1.000
1,0.860,-0.01,0.6483,0.64830,1.000
1,1.000,-0.01,0.7885,0.78850,1.000
1,1.140,0.00,0.9284,0.92840,1.000
1,1.280,-0.01,1.0688,1.06880,1.000
1,1.420,-0.01,1.2085,1.20850,1.000
1,1.560,-0.01,1.3485,1.34850,1.000
1,1.700,-0.01,1.4886,1.48860,1.000
1,1.840,-0.01,1.6287,1.62870,1.000
1,1.980,-0.01,1.7685,1.76850,1.000
1,2.120,-0.01,1.9086,1.90860,1.000
1,2.260,0.00,2.0484,2.04840,1.000
1,2.400,-0.01,2.1886,2.18860,1.000
1,2.540,-0.01,2.3286,2.32860,1.000
1,2.680,-0.01,2.4687,2.46870,1.000
1,2.820,-0.01,2.6086,2.60860,1.000
1,2.960,-0.01,2.7487,2.74870,1.000
1,3.100,-0.01,2.8886,2.88860,1.000
1,3.240,-0.01,3.0287,3.02870,1.000
1,3.380,-0.01,3.1688,3.16880,1.000
1,3.520,-0.01,3.3086,3.30860,1.000
1,3.660,-0.01,3.4486,3.44860,1.000
1,3.800,-0.01,3.5887,3.58870,1.000
1,3.940,-0.01,3.7286,3.72860,1.000
1,4.080,-0.01,3.8688,3.86880,1.000
1,4.220,0.01,4.0086,4.00860,1.000
1,4.360,0.20,4.1488,4.14880,1.000
1,4.500,0.53,4.2888,4.28880,1.000
1,4.640,1.04,4.4289,4.42890,1.000
1,4.780,1.77,4.5686,4.56860,1.000
1,4.920,2.76,4.7088,4.70880,1.000
1,5.060,4.01,4.8487,4.84870,1.000
1,5.200,5.54,4.9887,4.98870,1.000
1,5.340,7.38,5.1289,5.12890,1.000
1,5.480,9.59,5.2687,5.26870,1.000
1,5.620,12.36,5.4089,5.40890,1.000
1,5.760,15.63,5.5489,5.54890,1.000
1,5.900,19.50,5.6888,5.68880,1.000
1,6.040,24.09,5.8287,5.82870,1.000
1,6.180,29.79,5.9689,5.96890,1.000
1,6.320,36.94,6.1087,6.10870,1.000
1,6.460,46.22,6.2488,6.24880,1.000
1,6.600,54.89,6.3488,6.34880,1.000
1,6.740,35.68,6.2155,6.21550,1.000
1,6.880,24.22,6.0757,6.07570,1.000
1,7.020,17.09,5.9355,5.93550,1.000
1,7.160,12.32,5.7956,5.79560,1.000
1,7.300,9.08,5.6556,5.65560,1.000
1,7.440,7.07,5.5157,5.51570,1.000
1,7.580,5.47,5.3754,5.37540,1.000
1,7.720,4.05,5.2355,5.23550,1.000
1,7.860,2.95,5.0955,5.09550,1.000
1,8.000,2.11,4.9555,4.95550,1.000
1,8.140,1.45,4.8154,4.81540,1.000
1,8.280,0.94,4.6755,4.67550,1.000
1,8.420,0.56,4.5353,4.53530,1.000
1,8.560,0.27,4.3956,4.39560,1.000
1,8.700,0.10,4.2553,4.25530,1.000
1,8.840,0.00,4.1154,4.11540,1.000
1,8.980,-0.01,3.9753,3.97530,1.000
1,9.120,-0.01,3.8355,3.83550,1.000
1,9.260,-0.01,3.6952,3.69520,1.000
1,9.400,0.00,3.5555,3.55550,1.000
1,9.540,-0.01,3.4152,3.41520,1.000
1,9.680,-0.01,3.2755,3.27550,1.000
1,9.820,-0.01,3.1354,3.13540,1.000
1,9.960,-0.01,2.9955,2.99550,1.000
1,10.100,-0.01,2.8553,2.85530,1.000
1,10.240,-0.01,2.7153,2.71530,1.000
1,10.380,-0.01,2.5751,2.57510,1.000
1,10.520,0.00,2.4354,2.43540,1.000
1,10.660,-0.01,2.2952,2.29520,1.000
1,10.800,-0.01,2.1554,2.15540,1.000
1,10.940,-0.01,2.0151,2.01510,1.000
1,11.080,-0.01,1.8754,1.87540,1.000
1,11.220,-0.01,1.7352,1.73520,1.000
1,11.360,-0.01,1.5953,1.59530,1.000
1,11.500,-0.01,1.4552,1.45520,1.000
1,11.640,-0.01,1.3154,1.31540,1.000
1,11.780,-0.01,1.1752,1.17520,1.000
1,11.920,-0.01,1.0354,1.03540,1.000
1,12.060,-0.01,0.8952,0.89520,1.000
1,12.200,-0.01,0.7553,0.75530,1.000
1,12.340,-0.01,0.6152,0.61520,1.000
1,12.480,-0.01,0.4752,0.47520,1.000
1,12.620,-0.01,0.3351,0.33510,1.000
1,12.760,-0.01,0.1953,0.19530,1.000
1,12.900,-0.01,0.0551,0.05510,1.000
1,13.050,0.00,-0.0272,-0.02720,1.000
1,13.190,-0.01,-0.0004,-0.00040,1.000
1,13.330,-0.01,-0.0004,-0.00040,1.000
1,13.470,-0.01,-0.0004,-0.00040,1.000
1,13.610,-0.01,-0.0004,-0.00040,1.000
1,13.750,-0.01,-0.0004,-0.00040,1.000
1,13.890,0.00,-0.0004,-0.00040,1.000
1,14.030,-0.01,-0.0004,-0.00040,1.000
1,14.170,-0.01,-0.0004,-0.00040,1.000
1,14.310,-0.01,-0.0004,-0.00040,1.000
1,14.450,0.00,-0.0004,-0.00040,1.000
1,14.590,-0.01,-0.0004,-0.00040,1.000
1,14.730,-0.01,-0.0003,-0.00030,1.000
1,14.870,-0.01,-0.0003,-0.00030,1.000
1,15.010,0.00,-0.0003,-0.00030,1.000
1,15.150,-0.01,-0.0003,-0.00030,1.000
1,15.290,-0.01,-0.0003,-0.00030,1.000
1,15.430,0.00,-0.0003,-0.00030,1.000
1,15.570,-0.01,-0.0003,-0.00030,1.000
1,15.710,-0.01,-0.0003,-0.00030,1.000
1,15.850,-0.01,-0.0003,-0.00030,1.000
1,15.990,-0.01,-0.0003,-0.00030,1.000
1,16.140,-0.01,-0.0003,-0.00030,1.000
1,16.280,-0.01,-0.0003,-0.00030,1.000
1,16.420,-0.01,-0.0003,-0.00030,1.000
1,16.560,0.00,-0.0002,-0.00020,1.000
1,16.700,-0.01,-0.0002,-0.00020,1.000
1,16.840,-0.01,-0.0002,-0.00020,1.000
1,16.980,-0.01,-0.0002,-0.00020,1.000
1,17.120,-0.01,-0.0002,-0.00020,1.000
1,17.260,-0.01,-0.0002,-0.00020,1.000
1,17.400,-0.01,-0.0002,-0.00020,1.000
1,17.540,0.00,-0.0002,-0.00020,1.000
1,17.680,-0.01,-0.0002,-0.00020,1.000
1,17.820,-0.01,-0.0002,-0.00020,1.000
1,17.960,0.00,-0.0002,-0.00020,1.000
1,18.100,-0.01,-0.0002,-0.00020,1.000
1,18.240,0.00,-0.0002,-0.00020,1.000
1,18.380,-0.01,-0.0002,-0.00020,1.000
1,18.520,0.00,-0.0002,-0.00020,1.000
1,18.660,0.00,-0.0002,-0.00020,1.000
1,18.800,0.00,-0.0002,-0.00020,1.000
1,18.940,-0.01,-0.0002,-0.00020,1.000
2,19.160,0.00,0.0091,0.00910,2.000
2,19.300,0.00,0.1476,0.14760,2.000
2,19.440,0.00,0.2877,0.28770,2.000
2,19.580,0.01,0.4277,0.42770,2.000
2,19.720,0.00,0.5676,0.56760,2.000
2,19.860,0.00,0.7078,0.70780,2.000
2,20.000,0.00,0.8476,0.84760,2.000
2,20.140,0.00,0.9877,0.98770,2.000
2,20.280,0.00,1.1278,1.12780,2.000
2,20.420,0.00,1.2678,1.26780,2.000
2,20.560,0.00,1.4077,1.40770,2.000
2,20.700,0.00,1.5479,1.54790,2.000
2,20.840,-0.01,1.6878,1.68780,2.000
2,20.980,0.00,1.8279,1.82790,2.000
2,21.120,0.00,1.9677,1.96770,2.000
2,21.260,0.00,2.1078,2.10780,2.000
2,21.400,0.00,2.2479,2.24790,2.000
2,21.540,0.00,2.3879,2.38790,2.000
2,21.680,0.00,2.5278,2.52780,2.000
2,21.820,0.00,2.6679,2.66790,2.000
2,21.960,0.00,2.8079,2.80790,2.000
2,22.100,0.00,2.9478,2.94780,2.000
2,22.240,0.00,3.0879,3.08790,2.000
2,22.380,0.00,3.2280,3.22800,2.000
2,22.520,-0.01,3.3677,3.36770,2.000
2,22.660,0.00,3.5080,3.50800,2.000
2,22.800,0.00,3.6479,3.64790,2.000
2,22.940,0.00,3.7878,3.78780,2.000
2,23.080,0.00,3.9279,3.92790,2.000
2,23.220,0.07,4.0678,4.06780,2.000
2,23.360,0.30,4.2078,4.20780,2.000
2,23.500,0.70,4.3479,4.34790,2.000
2,23.640,1.28,4.4880,4.48800,2.000
2,23.780,2.10,4.6279,4.62790,2.000
2,23.920,3.18,4.7680,4.76800,2.000
2,24.060,4.53,4.9079,4.90790,2.000
2,24.200,6.19,5.0479,5.04790,2.000
2,24.340,8.17,5.1878,5.18780,2.000
2,24.480,10.59,5.3279,5.32790,2.000
2,24.620,13.53,5.4680,5.46800,2.000
2,24.760,17.03,5.6080,5.60800,2.000
2,24.900,21.11,5.7478,5.74780,2.000
2,25.040,26.06,5.8880,5.88800,2.000
2,25.180,32.18,6.0279,6.02790,2.000
2,25.320,40.00,6.1679,6.16790,2.000
2,25.460,50.39,6.3078,6.30780,2.000
2,25.600,47.59,6.3064,6.30640,2.000
2,25.740,30.68,6.1666,6.16660,2.000
2,25.880,21.24,6.0267,6.02670,2.000
2,26.020,15.09,5.8866,5.88660,2.000
2,26.160,10.96,5.7465,5.74650,2.000
2,26.300,8.25,5.6066,5.60660,2.000
2,26.440,6.42,5.4666,5.46660,2.000
2,26.580,4.89,5.3267,5.32670,2.000
2,26.720,3.61,5.1866,5.18660,2.000
2,26.860,2.61,5.0466,5.04660,2.000
2,27.000,1.84,4.9066,4.90660,2.000
2,27.140,1.23,4.7665,4.76650,2.000
2,27.280,0.78,4.6264,4.62640,2.000
2,27.420,0.45,4.4866,4.48660,2.000
2,27.560,0.21,4.3466,4.34660,2.000
2,27.700,0.06,4.2065,4.20650,2.000
2,27.840,0.00,4.0666,4.06660,2.000
2,27.980,0.00,3.9264,3.92640,2.000
2,28.120,0.00,3.7864,3.78640,2.000
2,28.260,0.00,3.6464,3.64640,2.000
2,28.400,0.00,3.5064,3.50640,2.000
2,28.540,0.00,3.3663,3.36630,2.000
2,28.680,0.00,3.2266,3.22660,2.000
2,28.820,0.00,3.0864,3.08640,2.000
2,28.960,0.00,2.9464,2.94640,2.000
2,29.100,-0.01,2.8064,2.80640,2.000
2,29.240,0.00,2.6663,2.66630,2.000
2,29.380,0.00,2.5263,2.52630,2.000
2,29.520,0.00,2.3864,2.38640,2.000
2,29.660,0.00,2.2464,2.24640,2.000
2,29.800,0.00,2.1064,2.10640,2.000
2,29.940,0.00,1.9662,1.96620,2.000
2,30.080,0.00,1.8264,1.82640,2.000
2,30.220,0.00,1.6864,1.68640,2.000
2,30.360,0.00,1.5465,1.54650,2.000
2,30.500,0.00,1.4063,1.40630,2.000
2,30.640,-0.01,1.2663,1.26630,2.000
2,30.780,0.00,1.1263,1.12630,2.000
2,30.920,0.00,0.9865,0.98650,2.000
2,31.060,0.00,0.8462,0.84620,2.000
2,31.200,0.00,0.7064,0.70640,2.000
2,31.340,0.00,0.5662,0.56620,2.000
2,31.480,0.00,0.4263,0.42630,2.000
2,31.620,0.00,0.2861,0.28610,2.000
2,31.760,0.00,0.1463,0.14630,2.000
2,31.900,0.00,0.0061,0.00610,2.000
2,32.050,0.00,-0.0057,-0.00570,2.000
2,32.190,0.00,-0.0004,-0.00040,2.000
2,32.330,0.00,-0.0004,-0.00040,2.000
2,32.470,-0.01,-0.0004,-0.00040,2.000
2,32.610,0.00,-0.0004,-0.00040,2.000
2,32.750,0.00,-0.0004,-0.00040,2.000
2,32.890,-0.01,-0.0004,-0.00040,2.000
2,33.030,0.00,-0.0004,-0.00040,2.000
2,33.170,0.00,-0.0004,-0.00040,2.000
2,33.310,0.00,-0.0003,-0.00030,2.000
2,33.450,0.00,-0.0003,-0.00030,2.000
2,33.590,0.00,-0.0003,-0.00030,2.000
2,33.730,0.00,-0.0003,-0.00030,2.000
2,33.870,0.00,-0.0003,-0.00030,2.000
2,34.010,0.00,-0.0003,-0.00030,2.000
2,34.150,0.00,-0.0003,-0.00030,2.000
2,34.290,0.00,-0.0003,-0.00030,2.000
2,34.430,0.00,-0.0003,-0.00030,2.000
2,34.570,0.00,-0.0003,-0.00030,2.000
2,34.710,0.00,-0.0003,-0.00030,2.000
2,34.850,0.00,-0.0003,-0.00030,2.000
2,34.990,0.00,-0.0003,-0.00030,2.000
2,35.130,0.00,-0.0003,-0.00030,2.000
2,35.270,0.00,-0.0002,-0.00020,2.000
2,35.410,0.00,-0.0002,-0.00020,2.000
2,35.550,0.00,-0.0002,-0.00020,2.000
2,35.690,0.00,-0.0002,-0.00020,2.000
2,35.830,0.00,-0.0002,-0.00020,2.000
2,35.970,0.00,-0.0002,-0.00020,2.000
2,36.110,0.00,-0.0002,-0.00020,2.000
2,36.250,0.00,-0.0002,-0.00020,2.000
2,36.390,0.00,-0.0002,-0.00020,2.000
2,36.530,0.00,-0.0002,-0.00020,2.000
2,36.670,0.00,-0.0002,-0.00020,2.000
2,36.810,0.00,-0.0002,-0.00020,2.000
2,36.950,0.00,-0.0002,-0.00020,2.000
2,37.090,0.00,-0.0002,-0.00020,2.000
2,37.230,0.00,-0.0002,-0.00020,2.000
2,37.370,0.00,-0.0002,-0.00020,2.000
2,37.510,0.00,-0.0002,-0.00020,2.000
2,37.650,0.00,-0.0002,-0.00020,2.000
2,37.790,0.00,-0.0002,-0.00020,2.000
2,37.930,0.00,-0.0001,-0.00010,2.000
3,38.170,0.00,0.0084,0.00850,3.000
3,38.310,0.00,0.1467,0.14680,3.000
3,38.450,0.00,0.2867,0.28680,3.000
3,38.590,0.00,0.4267,0.42680,3.000
3,38.730,0.00,0.5666,0.56670,3.000
3,38.870,0.00,0.7067,0.70680,3.000
3,39.010,0.00,0.8467,0.84680,3.000
3,39.150,0.00,0.9869,0.98700,3.000
3,39.290,0.00,1.1267,1.12680,3.000
3,39.430,0.00,1.2668,1.26690,3.000
3,39.570,0.00,1.4068,1.40690,3.000
3,39.710,0.00,1.5469,1.54700,3.000
3,39.850,0.00,1.6868,1.68690,3.000
3,39.990,0.00,1.8269,1.82700,3.000
3,40.130,0.00,1.9667,1.96680,3.000
3,40.270,-0.01,2.1069,2.10700,3.000
3,40.410,0.00,2.2468,2.24690,3.000
3,40.550,0.00,2.3869,2.38700,3.000
3,40.690,0.00,2.5268,2.52690,3.000
3,40.830,0.00,2.6668,2.66690,3.000
3,40.970,0.00,2.8069,2.80700,3.000
3,41.110,0.00,2.9468,2.94690,3.000
3,41.250,0.00,3.0870,3.08710,3.000
3,41.390,0.00,3.2270,3.22710,3.000
3,41.530,0.00,3.3667,3.36680,3.000
3,41.670,0.00,3.5069,3.50700,3.000
3,41.810,0.00,3.6469,3.64700,3.000
3,41.950,0.00,3.7869,3.78700,3.000
3,42.090,0.00,3.9269,3.92700,3.000
3,42.230,0.06,4.0668,4.06690,3.000
3,42.370,0.29,4.2069,4.20700,3.000
3,42.510,0.68,4.3469,4.34700,3.000
3,42.650,1.25,4.4870,4.48710,3.000
3,42.790,2.06,4.6269,4.62700,3.000
3,42.930,3.13,4.7669,4.76700,3.000
3,43.070,4.48,4.9068,4.90690,3.000
3,43.210,6.12,5.0469,5.04700,3.000
3,43.350,8.09,5.1869,5.18700,3.000
3,43.490,10.50,5.3270,5.32710,3.000
3,43.630,13.43,5.4669,5.46700,3.000
3,43.770,16.88,5.6071,5.60720,3.000
3,43.910,20.94,5.7469,5.74700,3.000
3,44.050,25.85,5.8870,5.88710,3.000
3,44.190,31.94,6.0268,6.02690,3.000
3,44.330,39.61,6.1670,6.16710,3.000
3,44.470,49.91,6.3067,6.30680,3.000
3,44.610,50.00,6.3258,6.32590,3.000
3,44.750,31.83,6.1855,6.18560,3.000
3,44.890,21.92,6.0457,6.04580,3.000
3,45.030,15.54,5.9056,5.90570,3.000
3,45.170,11.25,5.7655,5.76560,3.000
3,45.310,8.47,5.6257,5.62580,3.000
3,45.450,6.56,5.4856,5.48570,3.000
3,45.590,5.02,5.3456,5.34570,3.000
3,45.730,3.71,5.2056,5.20570,3.000
3,45.870,2.69,5.0656,5.06570,3.000
3,46.010,1.91,4.9256,4.92570,3.000
3,46.150,1.29,4.7855,4.78560,3.000
3,46.290,0.81,4.6455,4.64560,3.000
3,46.430,0.47,4.5055,4.50560,3.000
3,46.570,0.22,4.3656,4.36570,3.000
3,46.710,0.08,4.2255,4.22560,3.000
3,46.850,0.00,4.0855,4.08560,3.000
3,46.990,0.00,3.9454,3.94550,3.000
3,47.130,0.00,3.8054,3.80550,3.000
3,47.270,0.00,3.6653,3.66540,3.000
3,47.410,0.00,3.5255,3.52560,3.000
3,47.550,0.00,3.3852,3.38530,3.000
3,47.690,0.00,3.2455,3.24560,3.000
3,47.830,0.00,3.1055,3.10560,3.000
3,47.970,0.00,2.9655,2.96560,3.000
3,48.110,0.00,2.8253,2.82540,3.000
3,48.250,0.00,2.6854,2.68550,3.000
3,48.390,0.00,2.5454,2.54550,3.000
3,48.530,0.00,2.4054,2.40550,3.000
3,48.670,0.00,2.2654,2.26550,3.000
3,48.810,0.00,2.1253,2.12540,3.000
3,48.950,0.00,1.9854,1.98550,3.000
3,49.090,0.00,1.8452,1.84530,3.000
3,49.230,0.00,1.7053,1.70540,3.000
3,49.370,0.00,1.5653,1.56540,3.000
3,49.510,0.00,1.4253,1.42540,3.000
3,49.650,0.00,1.2853,1.28540,3.000
3,49.790,0.00,1.1455,1.14560,3.000
3,49.930,-0.01,1.0053,1.00540,3.000
3,50.070,0.00,0.8654,0.86550,3.000
3,50.210,0.00,0.7252,0.72530,3.000
3,50.350,0.00,0.5853,0.58540,3.000
3,50.490,0.00,0.4452,0.44530,3.000
3,50.630,0.00,0.3053,0.30540,3.000
3,50.770,0.00,0.1651,0.16520,3.000
3,50.910,0.00,0.0252,0.02530,3.000
3,51.060,0.00,-0.0002,-0.00010,3.000
3,51.200,0.00,-0.0003,-0.00020,3.000
3,51.340,0.00,-0.0003,-0.00020,3.000
3,51.480,0.00,-0.0003,-0.00020,3.000
3,51.620,0.00,-0.0003,-0.00020,3.000
3,51.760,0.00,-0.0003,-0.00020,3.000
3,51.900,-0.01,-0.0003,-0.00020,3.000
3,52.040,0.00,-0.0003,-0.00020,3.000
3,52.180,0.00,-0.0003,-0.00020,3.000
3,52.320,0.00,-0.0003,-0.00020,3.000
3,52.460,0.00,-0.0003,-0.00020,3.000
3,52.600,0.00,-0.0003,-0.00020,3.000
3,52.740,0.00,-0.0003,-0.00020,3.000
3,52.880,0.00,-0.0003,-0.00020,3.000
3,53.020,0.00,-0.0003,-0.00020,3.000
3,53.160,0.00,-0.0003,-0.00020,3.000
3,53.300,0.00,-0.0003,-0.00020,3.000
3,53.440,0.00,-0.0003,-0.00020,3.000
3,53.580,0.00,-0.0003,-0.00020,3.000
3,53.720,0.00,-0.0003,-0.00020,3.000
3,53.860,0.00,-0.0003,-0.00020,3.000
3,54.000,-0.01,-0.0002,-0.00010,3.000
3,54.150,0.00,-0.0002,-0.00010,3.000
3,54.290,0.00,-0.0002,-0.00010,3.000
3,54.430,0.00,-0.0002,-0.00010,3.000
3,54.570,0.00,-0.0002,-0.00010,3.000
3,54.710,-0.01,-0.0002,-0.00010,3.000
3,54.850,0.00,-0.0002,-0.00010,3.000
3,54.990,0.00,-0.0002,-0.00010,3.000
3,55.130,0.00,-0.0002,-0.00010,3.000
3,55.270,0.00,-0.0002,-0.00010,3.000
3,55.410,0.00,-0.0002,-0.00010,3.000
3,55.550,0.00,-0.0002,-0.00010,3.000
3,55.690,0.00,-0.0002,-0.00010,3.000
3,55.830,0.00,-0.0002,-0.00010,3.000
3,55.970,0.00,-0.0002,-0.00010,3.000
3,56.110,0.00,-0.0002,-0.00010,3.000
3,56.250,0.00,-0.0002,-0.00010,3.000
3,56.390,0.00,-0.0002,-0.00010,3.000
3,56.530,0.00,-0.0002,-0.00010,3.000
3,56.670,0.00,-0.0002,-0.00010,3.000
3,56.810,0.00,-0.0002,-0.00010,3.000
3,56.950,0.00,-0.0001,0.00000,3.000
4,57.180,0.00,0.0035,0.00350,4.000
4,57.320,0.00,0.1376,0.13760,4.000
4,57.460,0.00,0.2778,0.27780,4.000
4,57.600,0.00,0.4177,0.41770,4.000
4,57.740,-0.01,0.5578,0.55780,4.000
4,57.880,-0.01,0.6976,0.69760,4.000
4,58.020,-0.01,0.8379,0.83790,4.000
4,58.160,-0.01,0.9777,0.97770,4.000
4,58.300,-0.01,1.1179,1.11790,4.000
4,58.440,-0.01,1.2577,1.25770,4.000
4,58.580,-0.01,1.3979,1.39790,4.000
4,58.720,-0.01,1.5378,1.53780,4.000
4,58.860,0.00,1.6780,1.67800,4.000
4,59.000,0.00,1.8177,1.81770,4.000
4,59.140,0.00,1.9579,1.95790,4.000
4,59.280,0.00,2.0977,2.09770,4.000
4,59.420,-0.01,2.2379,2.23790,4.000
4,59.560,0.00,2.3779,2.37790,4.000
4,59.700,-0.01,2.5180,2.51800,4.000
4,59.840,-0.01,2.6578,2.65780,4.000
4,59.980,-0.01,2.7979,2.79790,4.000
4,60.120,-0.01,2.9378,2.93780,4.000
4,60.260,-0.01,3.0781,3.07810,4.000
4,60.400,0.00,3.2180,3.21800,4.000
4,60.540,-0.01,3.3578,3.35780,4.000
4,60.680,-0.01,3.4979,3.49790,4.000
4,60.820,-0.01,3.6378,3.63780,4.000
4,60.960,-0.01,3.7777,3.77770,4.000
4,61.100,0.00,3.9178,3.91780,4.000
4,61.240,0.04,4.0577,4.05770,4.000
4,61.380,0.25,4.1978,4.19780,4.000
4,61.520,0.63,4.3378,4.33780,4.000
4,61.660,1.19,4.4780,4.47800,4.000
4,61.800,1.98,4.6177,4.61770,4.000
4,61.940,3.03,4.7580,4.75800,4.000
4,62.080,4.35,4.8977,4.89770,4.000
4,62.220,5.97,5.0378,5.03780,4.000
4,62.360,7.93,5.1778,5.17780,4.000
4,62.500,10.29,5.3179,5.31790,4.000
4,62.640,13.18,5.4578,5.45780,4.000
4,62.780,16.59,5.5981,5.59810,4.000
4,62.920,20.57,5.7379,5.73790,4.000
4,63.060,25.34,5.8779,5.87790,4.000
4,63.200,31.28,6.0178,6.01780,4.000
4,63.340,38.72,6.1578,6.15780,4.000
4,63.480,48.71,6.2979,6.29790,4.000
4,63.630,45.12,6.2907,6.29070,4.000
4,63.770,29.36,6.1507,6.15070,4.000
4,63.910,20.33,6.0108,6.01080,4.000
4,64.050,14.46,5.8706,5.87060,4.000
4,64.190,10.47,5.7307,5.73070,4.000
4,64.330,7.96,5.5907,5.59070,4.000
4,64.470,6.15,5.4507,5.45070,4.000
4,64.610,4.66,5.3106,5.31060,4.000
4,64.750,3.42,5.1706,5.17060,4.000
4,64.890,2.47,5.0307,5.03070,4.000
4,65.030,1.73,4.8905,4.89050,4.000
4,65.170,1.16,4.7506,4.75060,4.000
4,65.310,0.72,4.6105,4.61050,4.000
4,65.450,0.39,4.4706,4.47060,4.000
4,65.590,0.17,4.3306,4.33060,4.000
4,65.730,0.04,4.1906,4.19060,4.000
4,65.870,-0.01,4.0504,4.05040,4.000
4,66.010,-0.01,3.9105,3.91050,4.000
4,66.150,-0.01,3.7703,3.77030,4.000
4,66.290,0.00,3.6305,3.63050,4.000
4,66.430,-0.01,3.4904,3.49040,4.000
4,66.570,-0.01,3.3504,3.35040,4.000
4,66.710,-0.01,3.2105,3.21050,4.000
4,66.850,-0.01,3.0704,3.07040,4.000
4,66.990,0.00,2.9304,2.93040,4.000
4,67.130,-0.01,2.7904,2.79040,4.000
4,67.270,-0.01,2.6503,2.65030,4.000
4,67.410,0.00,2.5104,2.51040,4.000
4,67.550,-0.01,2.3703,2.37030,4.000
4,67.690,-0.01,2.2305,2.23050,4.000
4,67.830,-0.01,2.0901,2.09010,4.000
4,67.970,-0.01,1.9504,1.95040,4.000
4,68.110,0.00,1.8102,1.81020,4.000
4,68.250,0.00,1.6705,1.67050,4.000
4,68.390,-0.01,1.5303,1.53030,4.000
4,68.530,-0.01,1.3903,1.39030,4.000
4,68.670,-0.01,1.2501,1.25010,4.000
4,68.810,-0.01,1.1104,1.11040,4.000
4,68.950,-0.01,0.9703,0.97030,4.000
4,69.090,-0.01,0.8303,0.83030,4.000
4,69.230,-0.01,0.6901,0.69010,4.000
4,69.370,0.00,0.5504,0.55040,4.000
4,69.510,0.00,0.4101,0.41010,4.000
4,69.650,0.00,0.2704,0.27040,4.000
4,69.790,-0.01,0.1300,0.13000,4.000
4,69.930,0.00,-0.0096,-0.00960,4.000
4,70.070,-0.01,-0.0101,-0.01010,4.000
4,70.210,0.00,-0.0003,-0.00030,4.000
4,70.350,0.00,-0.0003,-0.00030,4.000
4,70.490,-0.01,-0.0003,-0.00030,4.000
4,70.630,-0.01,-0.0003,-0.00030,4.000
4,70.770,-0.01,-0.0003,-0.00030,4.000
4,70.910,-0.01,-0.0003,-0.00030,4.000
4,71.050,-0.01,-0.0003,-0.00030,4.000
4,71.190,-0.01,-0.0003,-0.00030,4.000
4,71.330,-0.01,-0.0003,-0.00030,4.000
4,71.470,-0.01,-0.0003,-0.00030,4.000
4,71.610,-0.01,-0.0003,-0.00030,4.000
4,71.750,0.00,-0.0003,-0.00030,4.000
4,71.890,-0.01,-0.0003,-0.00030,4.000
4,72.030,-0.01,-0.0003,-0.00030,4.000
4,72.170,-0.01,-0.0003,-0.00030,4.000
4,72.310,-0.01,-0.0003,-0.00030,4.000
4,72.450,-0.01,-0.0003,-0.00030,4.000
4,72.590,-0.01,-0.0003,-0.00030,4.000
4,72.730,-0.01,-0.0003,-0.00030,4.000
4,72.870,0.00,-0.0003,-0.00030,4.000
4,73.030,-0.01,-0.0003,-0.00030,4.000
4,73.170,-0.01,-0.0002,-0.00020,4.000
4,73.310,-0.01,-0.0002,-0.00020,4.000
4,73.450,-0.01,-0.0002,-0.00020,4.000
4,73.590,-0.01,-0.0002,-0.00020,4.000
4,73.730,-0.01,-0.0002,-0.00020,4.000
4,73.870,0.00,-0.0002,-0.00020,4.000
4,74.010,-0.01,-0.0002,-0.00020,4.000
4,74.150,-0.01,-0.0002,-0.00020,4.000
4,74.290,-0.01,-0.0002,-0.00020,4.000
4,74.430,-0.01,-0.0002,-0.00020,4.000
4,74.570,0.00,-0.0002,-0.00020,4.000
4,74.710,-0.01,-0.0002,-0.00020,4.000
4,74.850,-0.01,-0.0002,-0.00020,4.000
4,74.990,0.00,-0.0002,-0.00020,4.000
4,75.130,0.00,-0.0002,-0.00020,4.000
4,75.270,-0.01,-0.0002,-0.00020,4.000
4,75.410,0.00,-0.0002,-0.00020,4.000
4,75.550,-0.01,-0.0002,-0.00020,4.000
4,75.690,-0.01,-0.0002,-0.00020,4.000
4,75.830,-0.01,-0.0002,-0.00020,4.000
4,75.970,-0.01,-0.0002,-0.00020,4.000
5,76.190,0.00,0.0476,0.04760,5.000
5,76.330,-0.01,0.1877,0.18770,5.000
5,76.470,-0.01,0.3276,0.32760,5.000
5,76.610,-0.01,0.4678,0.46780,5.000
5,76.750,-0.01,0.6076,0.60760,5.000
5,76.890,-0.01,0.7478,0.74780,5.000
5,77.030,-0.01,0.8877,0.88770,5.000
5,77.170,-0.01,1.0278,1.02780,5.000
5,77.310,0.00,1.1677,1.16770,5.000
5,77.450,0.00,1.3078,1.30780,5.000
5,77.590,0.00,1.4478,1.44780,5.000
5,77.730,-0.01,1.5879,1.58790,5.000
5,77.870,-0.01,1.7279,1.72790,5.000
5,78.010,-0.01,1.8679,1.86790,5.000
5,78.150,-0.01,2.0078,2.00780,5.000
5,78.290,0.00,2.1478,2.14780,5.000
5,78.430,-0.01,2.2878,2.28780,5.000
5,78.570,0.00,2.4279,2.42790,5.000
5,78.710,0.00,2.5679,2.56790,5.000
5,78.850,0.00,2.7079,2.70790,5.000
5,78.990,-0.01,2.8479,2.84790,5.000
5,79.130,0.00,2.9878,2.98780,5.000
5,79.270,-0.01,3.1280,3.12800,5.000
5,79.410,0.00,3.2679,3.26790,5.000
5,79.550,-0.01,3.4077,3.40770,5.000
5,79.690,-0.01,3.5479,3.54790,5.000
5,79.830,-0.01,3.6879,3.68790,5.000
5,79.970,-0.01,3.8278,3.82780,5.000
5,80.110,0.00,3.9679,3.96790,5.000
5,80.250,0.09,4.1078,4.10780,5.000
5,80.390,0.35,4.2480,4.24800,5.000
5,80.530,0.79,4.3879,4.38790,5.000
5,80.670,1.43,4.5279,4.52790,5.000
5,80.810,2.30,4.6678,4.66780,5.000
5,80.950,3.44,4.8079,4.80790,5.000
5,81.090,4.87,4.9478,4.94780,5.000
5,81.230,6.59,5.0880,5.08800,5.000
5,81.370,8.66,5.2278,5.22780,5.000
5,81.510,11.22,5.3679,5.36790,5.000
5,81.650,14.27,5.5079,5.50790,5.000
5,81.790,17.87,5.6481,5.64810,5.000
5,81.930,22.09,5.7878,5.78780,5.000
5,82.070,27.22,5.9279,5.92790,5.000
5,82.210,33.63,6.0678,6.06780,5.000
5,82.350,41.82,6.2080,6.20800,5.000
5,82.510,55.03,6.3627,6.36270,5.000
5,82.650,40.30,6.2666,6.26660,5.000
5,82.790,26.81,6.1267,6.12670,5.000
5,82.930,18.73,5.9866,5.98660,5.000
5,83.070,13.38,5.8466,5.84660,5.000
5,83.210,9.76,5.7066,5.70660,5.000
5,83.350,7.52,5.5667,5.56670,5.000
5,83.490,5.82,5.4265,5.42650,5.000
5,83.630,4.36,5.2866,5.28660,5.000
5,83.770,3.19,5.1465,5.14650,5.000
5,83.910,2.30,5.0067,5.00670,5.000
5,84.050,1.59,4.8664,4.86640,5.000
5,84.190,1.04,4.7265,4.72650,5.000
5,84.330,0.64,4.5865,4.58650,5.000
5,84.470,0.33,4.4465,4.44650,5.000
5,84.610,0.15,4.3065,4.30650,5.000
5,84.750,0.03,4.1666,4.16660,5.000
5,84.890,-0.01,4.0265,4.02650,5.000
5,85.030,-0.01,3.8865,3.88650,5.000
5,85.170,-0.01,3.7463,3.74630,5.000
5,85.310,-0.01,3.6065,3.60650,5.000
5,85.450,0.00,3.4664,3.46640,5.000
5,85.590,-0.01,3.3262,3.32620,5.000
5,85.730,-0.01,3.1865,3.18650,5.000
5,85.870,-0.01,3.0465,3.04650,5.000
5,86.010,-0.01,2.9064,2.90640,5.000
5,86.150,0.00,2.7663,2.76630,5.000
5,86.290,-0.01,2.6263,2.62630,5.000
5,86.430,-0.01,2.4864,2.48640,5.000
5,86.570,-0.01,2.3463,2.34630,5.000
5,86.710,-0.01,2.2063,2.20630,5.000
5,86.850,-0.01,2.0663,2.06630,5.000
5,86.990,-0.01,1.9264,1.92640,5.000
5,87.130,-0.01,1.7864,1.78640,5.000
5,87.270,0.00,1.6463,1.64630,5.000
5,87.410,-0.01,1.5064,1.50640,5.000
5,87.550,-0.01,1.3663,1.36630,5.000
5,87.690,-0.01,1.2263,1.22630,5.000
5,87.830,-0.01,1.0864,1.08640,5.000
5,87.970,0.00,0.9464,0.94640,5.000
5,88.110,-0.01,0.8062,0.80620,5.000
5,88.250,-0.01,0.6664,0.66640,5.000
5,88.390,-0.01,0.5262,0.52620,5.000
5,88.530,-0.01,0.3863,0.38630,5.000
5,88.670,-0.01,0.2462,0.24620,5.000
5,88.810,0.00,0.1062,0.10620,5.000
5,88.960,-0.01,-0.0431,-0.04310,5.000
5,89.100,-0.01,-0.0003,-0.00030,5.000
5,89.240,0.00,-0.0003,-0.00030,5.000
5,89.380,0.00,-0.0003,-0.00030,5.000
5,89.520,0.00,-0.0003,-0.00030,5.000
5,89.660,-0.01,-0.0003,-0.00030,5.000
5,89.800,0.00,-0.0003,-0.00030,5.000
5,89.940,0.00,-0.0003,-0.00030,5.000
5,90.080,0.00,-0.0003,-0.00030,5.000
5,90.220,-0.01,-0.0003,-0.00030,5.000
5,90.360,-0.01,-0.0003,-0.00030,5.000
5,90.500,0.00,-0.0003,-0.00030,5.000
5,90.640,-0.01,-0.0003,-0.00030,5.000
5,90.780,0.00,-0.0003,-0.00030,5.000
5,90.920,-0.01,-0.0003,-0.00030,5.000
5,91.060,0.00,-0.0003,-0.00030,5.000
5,91.200,0.00,-0.0003,-0.00030,5.000
5,91.340,-0.01,-0.0003,-0.00030,5.000
5,91.480,0.00,-0.0003,-0.00030,5.000
5,91.620,-0.01,-0.0003,-0.00030,5.000
5,91.760,-0.01,-0.0003,-0.00030,5.000
5,91.900,0.00,-0.0003,-0.00030,5.000
5,92.040,0.00,-0.0002,-0.00020,5.000
5,92.180,0.00,-0.0002,-0.00020,5.000
5,92.320,0.00,-0.0002,-0.00020,5.000
5,92.460,0.00,-0.0002,-0.00020,5.000
5,92.600,0.00,-0.0002,-0.00020,5.000
5,92.740,0.00,-0.0002,-0.00020,5.000
5,92.880,0.00,-0.0002,-0.00020,5.000
5,93.020,0.00,-0.0002,-0.00020,5.000
5,93.160,0.00,-0.0002,-0.00020,5.000
5,93.300,0.00,-0.0002,-0.00020,5.000
5,93.440,-0.01,-0.0002,-0.00020,5.000
5,93.580,-0.01,-0.0002,-0.00020,5.000
5,93.720,-0.01,-0.0002,-0.00020,5.000
5,93.860,-0.01,-0.0002,-0.00020,5.000
5,94.000,-0.01,-0.0002,-0.00020,5.000
5,94.140,-0.01,-0.0002,-0.00020,5.000
5,94.280,-0.01,-0.0002,-0.00020,5.000
5,94.420,-0.01,-0.0002,-0.00020,5.000
5,94.560,-0.01,-0.0002,-0.00020,5.000
5,94.700,-0.01,-0.0002,-0.00020,5.000
5,94.840,-0.01,-0.0001,-0.00010,5.000
5,94.980,-0.01,-0.0001,-0.00010,5.000
6,95.200,0.00,0.0874,0.08740,6.000
6,95.340,0.00,0.2278,0.22780,6.000
6,95.480,0.00,0.3676,0.36760,6.000
6,95.620,0.00,0.5076,0.50760,6.000
6,95.760,0.00,0.6476,0.64760,6.000
6,95.900,0.00,0.7878,0.78780,6.000
6,96.040,0.00,0.9277,0.92770,6.000
6,96.180,-0.01,1.0679,1.06790,6.000
6,96.320,0.00,1.2078,1.20780,6.000
6,96.460,-0.01,1.3478,1.34780,6.000
6,96.600,-0.01,1.4878,1.48780,6.000
6,96.740,-0.01,1.6278,1.62780,6.000
6,96.880,0.00,1.7678,1.76780,6.000
6,97.020,-0.01,1.9077,1.90770,6.000
6,97.160,-0.01,2.0477,2.04770,6.000
6,97.300,-0.01,2.1878,2.18780,6.000
6,97.440,0.00,2.3279,2.32790,6.000
6,97.580,0.00,2.4677,2.46770,6.000
6,97.720,0.00,2.6078,2.60780,6.000
6,97.860,-0.01,2.7478,2.74780,6.000
6,98.000,-0.01,2.8880,2.88800,6.000
6,98.140,0.00,3.0278,3.02780,6.000
6,98.280,0.00,3.1681,3.16810,6.000
6,98.420,0.00,3.3078,3.30780,6.000
6,98.560,-0.01,3.4479,3.44790,6.000
6,98.700,0.00,3.5879,3.58790,6.000
6,98.840,-0.01,3.7278,3.72780,6.000
6,98.980,-0.01,3.8678,3.86780,6.000
6,99.120,0.00,4.0079,4.00790,6.000
6,99.260,0.15,4.1477,4.14770,6.000
6,99.400,0.46,4.2880,4.28800,6.000
6,99.540,0.95,4.4279,4.42790,6.000
6,99.680,1.64,4.5679,4.56790,6.000
6,99.820,2.59,4.7077,4.70770,6.000
6,99.960,3.81,4.8479,4.84790,6.000
6,100.100,5.31,4.9878,4.98780,6.000
6,100.240,7.14,5.1280,5.12800,6.000
6,100.380,9.31,5.2678,5.26780,6.000
6,100.520,12.00,5.4080,5.40800,6.000
6,100.660,15.19,5.5478,5.54780,6.000
6,100.800,18.92,5.6881,5.68810,6.000
6,100.940,23.33,5.8277,5.82770,6.000
6,101.080,28.74,5.9680,5.96800,6.000
6,101.220,35.53,6.1077,6.10770,6.000
6,101.360,44.31,6.2479,6.24790,6.000
6,101.520,55.06,6.3637,6.36370,6.000
6,101.660,35.49,6.2286,6.22860,6.000
6,101.800,24.04,6.0886,6.08860,6.000
6,101.940,16.94,5.9486,5.94860,6.000
6,102.080,12.16,5.8086,5.80860,6.000
6,102.220,9.03,5.6686,5.66860,6.000
6,102.360,6.96,5.5287,5.52870,6.000
6,102.500,5.39,5.3886,5.38860,6.000
6,102.640,3.97,5.2486,5.24860,6.000
6,102.780,2.89,5.1086,5.10860,6.000
6,102.920,2.07,4.9686,4.96860,6.000
6,103.060,1.42,4.8284,4.82840,6.000
6,103.200,0.91,4.6885,4.68850,6.000
6,103.340,0.54,4.5485,4.54850,6.000
6,103.480,0.27,4.4085,4.40850,6.000
6,103.620,0.10,4.2685,4.26850,6.000
6,103.760,0.00,4.1286,4.12860,6.000
6,103.900,-0.01,3.9884,3.98840,6.000
6,104.040,0.00,3.8485,3.84850,6.000
6,104.180,0.00,3.7082,3.70820,6.000
6,104.320,0.00,3.5685,3.56850,6.000
6,104.460,-0.01,3.4283,3.42830,6.000
6,104.600,0.00,3.2884,3.28840,6.000
6,104.740,0.00,3.1485,3.14850,6.000
6,104.880,-0.01,3.0085,3.00850,6.000
6,105.020,0.00,2.8684,2.86840,6.000
6,105.160,0.00,2.7284,2.72840,6.000
6,105.300,-0.01,2.5883,2.58830,6.000
6,105.440,-0.01,2.4484,2.44840,6.000
6,105.580,-0.01,2.3083,2.30830,6.000
6,105.720,-0.01,2.1684,2.16840,6.000
6,105.860,0.00,2.0283,2.02830,6.000
6,106.000,-0.01,1.8883,1.88830,6.000
6,106.140,0.00,1.7484,1.74840,6.000
6,106.280,0.00,1.6084,1.60840,6.000
6,106.420,0.00,1.4683,1.46830,6.000
6,106.560,0.00,1.3283,1.32830,6.000
6,106.700,0.00,1.1884,1.18840,6.000
6,106.840,-0.01,1.0483,1.04830,6.000
6,106.980,-0.01,0.9084,0.90840,6.000
6,107.120,0.00,0.7682,0.76820,6.000
6,107.260,0.00,0.6284,0.62840,6.000
6,107.400,0.00,0.4883,0.48830,6.000
6,107.540,-0.01,0.3484,0.34840,6.000
6,107.680,0.00,0.2082,0.20820,6.000
6,107.820,-0.01,0.0682,0.06820,6.000
6,107.960,0.00,-0.0521,-0.05210,6.000
6,108.100,-0.01,-0.0003,-0.00030,6.000
6,108.240,0.00,-0.0003,-0.00030,6.000
6,108.380,0.00,-0.0003,-0.00030,6.000
6,108.520,-0.01,-0.0003,-0.00030,6.000
6,108.660,0.00,-0.0003,-0.00030,6.000
6,108.800,0.00,-0.0003,-0.00030,6.000
6,108.940,0.00,-0.0003,-0.00030,6.000
6,109.080,0.00,-0.0003,-0.00030,6.000
6,109.220,0.00,-0.0003,-0.00030,6.000
6,109.360,0.00,-0.0003,-0.00030,6.000
6,109.500,0.00,-0.0003,-0.00030,6.000
6,109.640,0.00,-0.0003,-0.00030,6.000
6,109.780,-0.01,-0.0003,-0.00030,6.000
6,109.920,-0.01,-0.0003,-0.00030,6.000
6,110.060,0.00,-0.0002,-0.00020,6.000
6,110.200,-0.01,-0.0002,-0.00020,6.000
6,110.340,0.00,-0.0002,-0.00020,6.000
6,110.480,0.00,-0.0002,-0.00020,6.000
6,110.620,0.00,-0.0002,-0.00020,6.000
6,110.760,0.00,-0.0002,-0.00020,6.000
6,110.900,0.00,-0.0002,-0.00020,6.000
6,111.050,0.00,-0.0002,-0.00020,6.000
6,111.190,0.00,-0.0002,-0.00020,6.000
6,111.330,0.00,-0.0002,-0.00020,6.000
6,111.470,0.00,-0.0002,-0.00020,6.000
6,111.610,0.00,-0.0002,-0.00020,6.000
6,111.750,-0.01,-0.0002,-0.00020,6.000
6,111.890,0.00,-0.0002,-0.00020,6.000
6,112.030,0.00,-0.0002,-0.00020,6.000
6,112.170,0.00,-0.0002,-0.00020,6.000
6,112.310,0.00,-0.0002,-0.00020,6.000
6,112.450,0.00,-0.0002,-0.00020,6.000
6,112.590,0.00,-0.0002,-0.00020,6.000
6,112.730,0.00,-0.0002,-0.00020,6.000
6,112.870,0.00,-0.0002,-0.00020,6.000
6,113.010,0.00,-0.0001,-0.00010,6.000
6,113.150,-0.01,-0.0001,-0.00010,6.000
6,113.290,-0.01,-0.0001,-0.00010,6.000
6,113.430,0.00,-0.0001,-0.00010,6.000
6,113.570,0.00,-0.0001,-0.00010,6.000
6,113.710,-0.01,-0.0001,-0.00010,6.000
6,113.850,0.00,-0.0001,-0.00010,6.000
6,113.990,-0.01,-0.0001,-0.00010,6.000
7,114.210,0.00,0.0975,0.09750,7.000
7,114.350,0.00,0.2378,0.23780,7.000
7,114.490,0.00,0.3775,0.37750,7.000
7,114.630,0.00,0.5178,0.51780,7.000
7,114.770,0.00,0.6576,0.65760,7.000
7,114.910,0.00,0.7977,0.79770,7.000
7,115.050,0.00,0.9376,0.93760,7.000
7,115.190,0.00,1.0779,1.07790,7.000
7,115.330,0.00,1.2177,1.21770,7.000
7,115.470,0.00,1.3577,1.35770,7.000
7,115.610,0.00,1.4977,1.49770,7.000
7,115.750,0.00,1.6378,1.63780,7.000
7,115.890,0.00,1.7777,1.77770,7.000
7,116.030,0.00,1.9178,1.91780,7.000
7,116.170,0.00,2.0576,2.05760,7.000
7,116.310,0.00,2.1979,2.19790,7.000
7,116.450,0.00,2.3377,2.33770,7.000
7,116.590,0.00,2.4779,2.47790,7.000
7,116.730,0.00,2.6177,2.61770,7.000
7,116.870,0.00,2.7578,2.75780,7.000
7,117.010,0.00,2.8977,2.89770,7.000
7,117.150,0.00,3.0380,3.03800,7.000
7,117.290,0.00,3.1779,3.17790,7.000
7,117.430,0.00,3.3177,3.31770,7.000
7,117.570,0.00,3.4577,3.45770,7.000
7,117.710,-0.01,3.5979,3.59790,7.000
7,117.850,0.00,3.7377,3.73770,7.000
7,117.990,-0.01,3.8779,3.87790,7.000
7,118.130,0.01,4.0177,4.01770,7.000
7,118.270,0.16,4.1578,4.15780,7.000
7,118.410,0.49,4.2978,4.29780,7.000
7,118.550,0.99,4.4380,4.43800,7.000
7,118.690,1.70,4.5777,4.57770,7.000
7,118.830,2.67,4.7178,4.71780,7.000
7,118.970,3.90,4.8577,4.85770,7.000
7,119.110,5.42,4.9978,4.99780,7.000
7,119.250,7.27,5.1379,5.13790,7.000
7,119.390,9.47,5.2779,5.27790,7.000
7,119.530,12.21,5.4179,5.41790,7.000
7,119.670,15.43,5.5579,5.55790,7.000
7,119.810,19.21,5.6980,5.69800,7.000
7,119.950,23.66,5.8379,5.83790,7.000
7,120.090,29.15,5.9779,5.97790,7.000
7,120.230,36.03,6.1177,6.11770,7.000
7,120.370,45.03,6.2578,6.25780,7.000
7,120.510,55.60,6.3672,6.36720,7.000
7,120.650,36.60,6.2386,6.23860,7.000
7,120.790,24.71,6.0986,6.09860,7.000
7,120.930,17.35,5.9587,5.95870,7.000
7,121.070,12.43,5.8185,5.81850,7.000
7,121.210,9.18,5.6787,5.67870,7.000
7,121.350,7.08,5.5387,5.53870,7.000
7,121.490,5.48,5.3987,5.39870,7.000
7,121.630,4.06,5.2585,5.25850,7.000
7,121.770,2.96,5.1187,5.11870,7.000
7,121.910,2.12,4.9785,4.97850,7.000
7,122.050,1.46,4.8386,4.83860,7.000
7,122.190,0.94,4.6984,4.69840,7.000
7,122.330,0.57,4.5586,4.55860,7.000
7,122.470,0.29,4.4185,4.41850,7.000
7,122.610,0.11,4.2787,4.27870,7.000
7,122.750,0.02,4.1384,4.13840,7.000
7,122.890,0.00,3.9984,3.99840,7.000
7,123.030,0.00,3.8583,3.85830,7.000
7,123.170,0.00,3.7185,3.71850,7.000
7,123.310,0.00,3.5783,3.57830,7.000
7,123.450,0.00,3.4385,3.43850,7.000
7,123.590,0.00,3.2983,3.29830,7.000
7,123.730,0.00,3.1587,3.15870,7.000
7,123.870,0.00,3.0183,3.01830,7.000
7,124.010,0.00,2.8784,2.87840,7.000
7,124.150,-0.01,2.7382,2.73820,7.000
7,124.290,0.00,2.5984,2.59840,7.000
7,124.430,0.00,2.4581,2.45810,7.000
7,124.570,0.00,2.3185,2.31850,7.000
7,124.710,0.00,2.1782,2.17820,7.000
7,124.850,0.00,2.0383,2.03830,7.000
7,124.990,0.00,1.8982,1.89820,7.000
7,125.130,0.00,1.7583,1.75830,7.000
7,125.270,0.00,1.6182,1.61820,7.000
7,125.410,0.01,1.4784,1.47840,7.000
7,125.550,0.00,1.3381,1.33810,7.000
7,125.690,0.00,1.1983,1.19830,7.000
7,125.830,0.00,1.0582,1.05820,7.000
7,125.970,0.00,0.9183,0.91830,7.000
7,126.110,0.00,0.7781,0.77810,7.000
7,126.250,0.00,0.6383,0.63830,7.000
7,126.390,-0.01,0.4981,0.49810,7.000
7,126.530,0.00,0.3582,0.35820,7.000
7,126.670,0.00,0.2181,0.21810,7.000
7,126.810,0.00,0.0782,0.07820,7.000
7,126.960,0.00,-0.0522,-0.05220,7.000
7,127.100,0.00,-0.0003,-0.00030,7.000
7,127.240,0.00,-0.0003,-0.00030,7.000
7,127.380,0.00,-0.0003,-0.00030,7.000
7,127.520,0.00,-0.0003,-0.00030,7.000
7,127.660,0.00,-0.0003,-0.00030,7.000
7,127.800,0.00,-0.0003,-0.00030,7.000
7,127.940,0.00,-0.0003,-0.00030,7.000
7,128.080,0.00,-0.0003,-0.00030,7.000
7,128.220,0.00,-0.0003,-0.00030,7.000
7,128.360,0.00,-0.0003,-0.00030,7.000
7,128.500,0.00,-0.0003,-0.00030,7.000
7,128.640,0.00,-0.0003,-0.00030,7.000
7,128.780,0.00,-0.0003,-0.00030,7.000
7,128.920,0.00,-0.0002,-0.00020,7.000
7,129.060,0.00,-0.0002,-0.00020,7.000
7,129.200,0.00,-0.0002,-0.00020,7.000
7,129.340,0.00,-0.0002,-0.00020,7.000
7,129.480,0.00,-0.0002,-0.00020,7.000
7,129.620,0.00,-0.0002,-0.00020,7.000
7,129.760,0.00,-0.0002,-0.00020,7.000
7,129.900,0.00,-0.0002,-0.00020,7.000
7,130.050,0.00,-0.0002,-0.00020,7.000
7,130.190,0.00,-0.0002,-0.00020,7.000
7,130.330,0.00,-0.0002,-0.00020,7.000
7,130.470,0.00,-0.0002,-0.00020,7.000
7,130.610,0.00,-0.0002,-0.00020,7.000
7,130.750,0.00,-0.0002,-0.00020,7.000
7,130.890,0.00,-0.0002,-0.00020,7.000
7,131.030,0.00,-0.0002,-0.00020,7.000
7,131.170,0.00,-0.0002,-0.00020,7.000
7,131.310,0.00,-0.0002,-0.00020,7.000
7,131.450,0.00,-0.0002,-0.00020,7.000
7,131.590,0.00,-0.0002,-0.00020,7.000
7,131.730,0.00,-0.0002,-0.00020,7.000
7,131.870,0.00,-0.0001,-0.00010,7.000
7,132.010,0.00,-0.0001,-0.00010,7.000
7,132.150,0.00,-0.0001,-0.00010,7.000
7,132.290,-0.01,-0.0001,-0.00010,7.000
7,132.430,0.00,-0.0001,-0.00010,7.000
7,132.570,0.00,-0.0001,-0.00010,7.000
7,132.710,0.00,-0.0001,-0.00010,7.000
7,132.850,0.00,-0.0001,-0.00010,7.000
8,133.110,0.00,0.0000,0.00000,8.000
8,133.260,0.00,0.1175,0.11750,8.000
8,133.400,0.00,0.2576,0.25760,8.000
8,133.540,0.00,0.3978,0.39780,8.000
8,133.680,0.00,0.5375,0.53750,8.000
8,133.820,0.00,0.6777,0.67770,8.000
8,133.960,0.00,0.8176,0.81760,8.000
8,134.100,0.00,0.9577,0.95770,8.000
8,134.240,0.00,1.0977,1.09770,8.000
8,134.380,0.00,1.2378,1.23780,8.000
8,134.520,0.00,1.3777,1.37770,8.000
8,134.660,0.00,1.5180,1.51800,8.000
8,134.800,0.00,1.6576,1.65760,8.000
8,134.940,0.00,1.7978,1.79780,8.000
8,135.080,0.00,1.9376,1.93760,8.000
8,135.220,0.00,2.0779,2.07790,8.000
8,135.360,0.00,2.2177,2.21770,8.000
8,135.500,-0.01,2.3578,2.35780,8.000
8,135.640,0.00,2.4977,2.49770,8.000
8,135.780,0.00,2.6378,2.63780,8.000
8,135.920,0.00,2.7777,2.77770,8.000
8,136.060,0.00,2.9179,2.91790,8.000
8,136.200,0.00,3.0577,3.05770,8.000
8,136.340,0.00,3.1980,3.19800,8.000
8,136.480,0.00,3.3376,3.33760,8.000
8,136.620,0.00,3.4779,3.47790,8.000
8,136.760,0.00,3.6177,3.61770,8.000
8,136.900,0.00,3.7577,3.75770,8.000
8,137.040,0.00,3.8978,3.89780,8.000
8,137.180,0.02,4.0379,4.03790,8.000
8,137.320,0.19,4.1777,4.17770,8.000
8,137.460,0.54,4.3180,4.31800,8.000
8,137.600,1.06,4.4578,4.45780,8.000
8,137.740,1.79,4.5978,4.59780,8.000
8,137.880,2.80,4.7379,4.73790,8.000
8,138.020,4.06,4.8777,4.87770,8.000
8,138.160,5.63,5.0177,5.01770,8.000
8,138.300,7.51,5.1579,5.15790,8.000
8,138.440,9.77,5.2978,5.29780,8.000
8,138.580,12.56,5.4379,5.43790,8.000
8,138.720,15.87,5.5779,5.57790,8.000
8,138.860,19.71,5.7180,5.71800,8.000
8,139.000,24.29,5.8578,5.85780,8.000
8,139.140,29.92,5.9979,5.99790,8.000
8,139.280,37.00,6.1378,6.13780,8.000
8,139.420,46.31,6.2779,6.27790,8.000
8,139.570,50.70,6.3303,6.33030,8.000
8,139.710,32.01,6.1906,6.19060,8.000
8,139.850,21.96,6.0508,6.05080,8.000
8,139.990,15.51,5.9105,5.91050,8.000
8,140.130,11.17,5.7707,5.77070,8.000
8,140.270,8.41,5.6306,5.63060,8.000
8,140.410,6.47,5.4906,5.49060,8.000
8,140.550,4.95,5.3505,5.35050,8.000
8,140.690,3.65,5.2106,5.21060,8.000
8,140.830,2.65,5.0706,5.07060,8.000
8,140.970,1.87,4.9306,4.93060,8.000
8,141.110,1.26,4.7906,4.79060,8.000
8,141.250,0.79,4.6504,4.65040,8.000
8,141.390,0.46,4.5104,4.51040,8.000
8,141.530,0.21,4.3706,4.37060,8.000
8,141.670,0.07,4.2305,4.23050,8.000
8,141.810,0.00,4.0904,4.09040,8.000
8,141.950,0.00,3.9503,3.95030,8.000
8,142.090,0.00,3.8104,3.81040,8.000
8,142.230,0.00,3.6703,3.67030,8.000
8,142.370,0.01,3.5305,3.53050,8.000
8,142.510,0.00,3.3903,3.39030,8.000
8,142.650,0.00,3.2505,3.25050,8.000
8,142.790,0.00,3.1104,3.11040,8.000
8,142.930,0.00,2.9704,2.97040,8.000
8,143.070,0.00,2.8304,2.83040,8.000
8,143.210,0.00,2.6904,2.69040,8.000
8,143.350,0.00,2.5502,2.55020,8.000
8,143.490,0.00,2.4103,2.41030,8.000
8,143.630,0.00,2.2703,2.27030,8.000
8,143.770,0.00,2.1303,2.13030,8.000
8,143.910,0.00,1.9903,1.99030,8.000
8,144.050,0.00,1.8503,1.85030,8.000
8,144.190,0.00,1.7104,1.71040,8.000
8,144.330,0.00,1.5704,1.57040,8.000
8,144.470,0.00,1.4303,1.43030,8.000
8,144.610,0.00,1.2903,1.29030,8.000
8,144.750,0.00,1.1504,1.15040,8.000
8,144.890,0.00,1.0104,1.01040,8.000
8,145.030,0.00,0.8703,0.87030,8.000
8,145.170,0.00,0.7301,0.73010,8.000
8,145.310,0.00,0.5903,0.59030,8.000
8,145.450,0.00,0.4502,0.45020,8.000
8,145.590,0.00,0.3104,0.31040,8.000
8,145.730,0.00,0.1701,0.17010,8.000
8,145.870,0.00,0.0303,0.03030,8.000
8,146.020,0.00,-0.0061,-0.00610,8.000
8,146.160,0.00,-0.0003,-0.00030,8.000
8,146.300,0.00,-0.0003,-0.00030,8.000
8,146.440,0.00,-0.0003,-0.00030,8.000
8,146.580,0.00,-0.0003,-0.00030,8.000
8,146.720,0.00,-0.0003,-0.00030,8.000
8,146.860,0.00,-0.0003,-0.00030,8.000
8,147.000,0.00,-0.0003,-0.00030,8.000
8,147.140,0.00,-0.0003,-0.00030,8.000
8,147.280,0.00,-0.0003,-0.00030,8.000
8,147.420,0.00,-0.0003,-0.00030,8.000
8,147.560,0.00,-0.0003,-0.00030,8.000
8,147.700,0.00,-0.0003,-0.00030,8.000
8,147.840,0.00,-0.0002,-0.00020,8.000
8,147.980,0.00,-0.0002,-0.00020,8.000
8,148.120,0.00,-0.0002,-0.00020,8.000
8,148.260,0.00,-0.0002,-0.00020,8.000
8,148.400,0.00,-0.0002,-0.00020,8.000
8,148.540,0.00,-0.0002,-0.00020,8.000
8,148.680,0.00,-0.0002,-0.00020,8.000
8,148.820,0.00,-0.0002,-0.00020,8.000
8,148.960,0.00,-0.0002,-0.00020,8.000
8,149.100,0.00,-0.0002,-0.00020,8.000
8,149.240,0.00,-0.0002,-0.00020,8.000
8,149.380,0.00,-0.0002,-0.00020,8.000
8,149.520,0.00,-0.0002,-0.00020,8.000
8,149.660,0.00,-0.0002,-0.00020,8.000
8,149.800,0.00,-0.0002,-0.00020,8.000
8,149.940,0.00,-0.0002,-0.00020,8.000
8,150.080,0.00,-0.0002,-0.00020,8.000
8,150.220,0.00,-0.0002,-0.00020,8.000
8,150.360,0.00,-0.0002,-0.00020,8.000
8,150.500,0.00,-0.0002,-0.00020,8.000
8,150.640,0.00,-0.0002,-0.00020,8.000
8,150.780,0.00,-0.0001,-0.00010,8.000
8,150.920,0.00,-0.0001,-0.00010,8.000
8,151.060,0.00,-0.0001,-0.00010,8.000
8,151.200,0.00,-0.0001,-0.00010,8.000
8,151.340,0.00,-0.0001,-0.00010,8.000
8,151.480,0.00,-0.0001,-0.00010,8.000
8,151.620,0.00,-0.0001,-0.00010,8.000
8,151.760,0.00,-0.0001,-0.00010,8.000
8,151.900,0.00,-0.0001,-0.00010,8.000
9,152.150,0.00,0.0090,0.00900,9.000
9,152.290,0.00,0.1476,0.14760,9.000
9,152.430,-0.01,0.2878,0.28780,9.000
9,152.570,0.00,0.4276,0.42760,9.000
9,152.710,0.00,0.5676,0.56760,9.000
9,152.850,0.00,0.7077,0.70770,9.000
9,152.990,0.00,0.8477,0.84770,9.000
9,153.130,0.00,0.9877,0.98770,9.000
9,153.270,0.00,1.1278,1.12780,9.000
9,153.410,0.00,1.2678,1.26780,9.000
9,153.550,-0.01,1.4078,1.40780,9.000
9,153.690,-0.01,1.5478,1.54780,9.000
9,153.830,0.00,1.6878,1.68780,9.000
9,153.970,0.00,1.8277,1.82770,9.000
9,154.110,0.00,1.9679,1.96790,9.000
9,154.250,-0.01,2.1077,2.10770,9.000
9,154.390,0.00,2.2478,2.24780,9.000
9,154.530,0.00,2.3878,2.38780,9.000
9,154.670,0.00,2.5279,2.52790,9.000
9,154.810,-0.01,2.6676,2.66760,9.000
9,154.950,0.00,2.8079,2.80790,9.000
9,155.090,0.00,2.9477,2.94770,9.000
9,155.230,0.00,3.0880,3.08800,9.000
9,155.370,0.00,3.2278,3.22780,9.000
9,155.510,0.00,3.3678,3.36780,9.000
9,155.650,-0.01,3.5078,3.50780,9.000
9,155.790,-0.01,3.6478,3.64780,9.000
9,155.930,0.00,3.7877,3.78770,9.000
9,156.070,0.00,3.9279,3.92790,9.000
9,156.210,0.04,4.0677,4.06770,9.000
9,156.350,0.25,4.2079,4.20790,9.000
9,156.490,0.63,4.3478,4.34780,9.000
9,156.630,1.19,4.4880,4.48800,9.000
9,156.770,1.99,4.6277,4.62770,9.000
9,156.910,3.04,4.7679,4.76790,9.000
9,157.050,4.37,4.9077,4.90770,9.000
9,157.190,6.01,5.0480,5.04800,9.000
9,157.330,7.96,5.1877,5.18770,9.000
9,157.470,10.33,5.3279,5.32790,9.000
9,157.610,13.23,5.4678,5.46780,9.000
9,157.750,16.62,5.6081,5.60810,9.000
9,157.890,20.59,5.7478,5.74780,9.000
9,158.030,25.34,5.8878,5.88780,9.000
9,158.170,31.25,6.0279,6.02790,9.000
9,158.310,38.67,6.1679,6.16790,9.000
9,158.450,48.70,6.3078,6.30780,9.000
9,158.600,46.22,6.3084,6.30840,9.000
9,158.740,29.81,6.1686,6.16860,9.000
9,158.880,20.61,6.0287,6.02870,9.000
9,159.020,14.59,5.8886,5.88860,9.000
9,159.160,10.54,5.7485,5.74850,9.000
9,159.300,8.02,5.6088,5.60880,9.000
9,159.440,6.18,5.4686,5.46860,9.000
9,159.580,4.68,5.3287,5.32870,9.000
9,159.720,3.45,5.1885,5.18850,9.000
9,159.860,2.48,5.0487,5.04870,9.000
9,160.000,1.74,4.9083,4.90830,9.000
9,160.140,1.16,4.7686,4.76860,9.000
9,160.280,0.72,4.6285,4.62850,9.000
9,160.420,0.40,4.4886,4.48860,9.000
9,160.560,0.18,4.3484,4.34840,9.000
9,160.700,0.05,4.2086,4.20860,9.000
9,160.840,-0.01,4.0683,4.06830,9.000
9,160.980,0.00,3.9285,3.92850,9.000
9,161.120,-0.01,3.7882,3.78820,9.000
9,161.260,-0.01,3.6484,3.64840,9.000
9,161.400,-0.01,3.5084,3.50840,9.000
9,161.540,0.00,3.3682,3.36820,9.000
9,161.680,0.00,3.2284,3.22840,9.000
9,161.820,-0.01,3.0885,3.08850,9.000
9,161.960,-0.01,2.9483,2.94830,9.000
9,162.100,0.00,2.8084,2.80840,9.000
9,162.240,0.00,2.6682,2.66820,9.000
9,162.380,0.00,2.5284,2.52840,9.000
9,162.520,-0.01,2.3884,2.38840,9.000
9,162.660,-0.01,2.2484,2.24840,9.000
9,162.800,0.00,2.1082,2.10820,9.000
9,162.940,0.00,1.9683,1.96830,9.000
9,163.080,0.00,1.8282,1.82820,9.000
9,163.220,-0.01,1.6883,1.68830,9.000
9,163.360,0.00,1.5483,1.54830,9.000
9,163.500,0.00,1.4083,1.40830,9.000
9,163.640,0.00,1.2682,1.26820,9.000
9,163.780,0.00,1.1283,1.12830,9.000
9,163.920,-0.01,0.9882,0.98820,9.000
9,164.060,0.00,0.8483,0.84830,9.000
9,164.200,0.00,0.7083,0.70830,9.000
9,164.340,-0.01,0.5682,0.56820,9.000
9,164.480,-0.01,0.4283,0.42830,9.000
9,164.620,-0.01,0.2883,0.28830,9.000
9,164.760,0.00,0.1483,0.14830,9.000
9,164.900,-0.01,0.0082,0.00820,9.000
9,165.050,-0.01,-0.0006,-0.00060,9.000
9,165.190,-0.01,-0.0002,-0.00020,9.000
9,165.330,-0.01,-0.0002,-0.00020,9.000
9,165.470,-0.01,-0.0002,-0.00020,9.000
9,165.610,-0.01,-0.0002,-0.00020,9.000
9,165.750,0.00,-0.0002,-0.00020,9.000
9,165.890,0.00,-0.0002,-0.00020,9.000
9,166.030,0.00,-0.0002,-0.00020,9.000
9,166.170,0.00,-0.0002,-0.00020,9.000
9,166.310,0.00,-0.0002,-0.00020,9.000
9,166.450,0.00,-0.0002,-0.00020,9.000
9,166.590,-0.01,-0.0002,-0.00020,9.000
9,166.730,0.00,-0.0002,-0.00020,9.000
9,166.870,0.00,-0.0002,-0.00020,9.000
9,167.010,0.00,-0.0002,-0.00020,9.000
9,167.150,-0.01,-0.0002,-0.00020,9.000
9,167.290,0.00,-0.0002,-0.00020,9.000
9,167.430,-0.01,-0.0002,-0.00020,9.000
9,167.570,-0.01,-0.0002,-0.00020,9.000
9,167.710,0.00,-0.0002,-0.00020,9.000
9,167.850,0.00,-0.0002,-0.00020,9.000
9,168.000,-0.01,-0.0002,-0.00020,9.000
9,168.140,0.00,-0.0002,-0.00020,9.000
9,168.280,0.00,-0.0002,-0.00020,9.000
9,168.420,-0.01,-0.0002,-0.00020,9.000
9,168.560,0.00,-0.0002,-0.00020,9.000
9,168.700,-0.01,-0.0002,-0.00020,9.000
9,168.840,-0.01,-0.0002,-0.00020,9.000
9,168.980,0.00,-0.0002,-0.00020,9.000
9,169.120,0.00,-0.0002,-0.00020,9.000
9,169.260,-0.01,-0.0002,-0.00020,9.000
9,169.400,0.00,-0.0001,-0.00010,9.000
9,169.540,0.00,-0.0001,-0.00010,9.000
9,169.680,0.00,-0.0001,-0.00010,9.000
9,169.820,0.00,-0.0001,-0.00010,9.000
9,169.960,0.00,-0.0001,-0.00010,9.000
9,170.100,0.00,-0.0001,-0.00010,9.000
9,170.240,0.00,-0.0001,-0.00010,9.000
9,170.380,0.00,-0.0001,-0.00010,9.000
9,170.520,0.00,-0.0001,-0.00010,9.000
9,170.660,0.00,-0.0001,-0.00010,9.000
9,170.800,0.00,-0.0001,-0.00010,9.000
9,170.940,0.00,-0.0001,-0.00010,9.000
10,171.210,0.00,0.0375,0.03750,10.000
10,171.350,0.00,0.1774,0.17740,10.000
10,171.490,0.00,0.3176,0.31760,10.000
10,171.630,0.00,0.4576,0.45760,10.000
10,171.770,0.00,0.5977,0.59770,10.000
10,171.910,0.00,0.7375,0.73750,10.000
10,172.050,0.00,0.8777,0.87770,10.000
10,172.190,0.00,1.0176,1.01760,10.000
10,172.330,0.00,1.1578,1.15780,10.000
10,172.470,0.00,1.2976,1.29760,10.000
10,172.610,0.00,1.4378,1.43780,10.000
10,172.750,0.01,1.5776,1.57760,10.000
10,172.890,0.00,1.7179,1.71790,10.000
10,173.030,0.00,1.8577,1.85770,10.000
10,173.170,0.00,1.9977,1.99770,10.000
10,173.310,0.00,2.1377,2.13770,10.000
10,173.450,0.00,2.2778,2.27780,10.000
10,173.590,0.00,2.4178,2.41780,10.000
10,173.730,0.00,2.5578,2.55780,10.000
10,173.870,0.00,2.6976,2.69760,10.000
10,174.010,0.00,2.8378,2.83780,10.000
10,174.150,0.00,2.9778,2.97780,10.000
10,174.290,-0.01,3.1180,3.11800,10.000
10,174.430,0.00,3.2579,3.25790,10.000
10,174.570,0.00,3.3977,3.39770,10.000
10,174.710,0.00,3.5379,3.53790,10.000
10,174.850,0.01,3.6777,3.67770,10.000
10,174.990,0.01,3.8178,3.81780,10.000
10,175.130,0.01,3.9577,3.95770,10.000
10,175.270,0.08,4.0978,4.09780,10.000
10,175.410,0.32,4.2378,4.23780,10.000
10,175.550,0.73,4.3779,4.37790,10.000
10,175.690,1.34,4.5179,4.51790,10.000
10,175.830,2.18,4.6577,4.65770,10.000
10,175.970,3.29,4.7977,4.79770,10.000
10,176.110,4.68,4.9379,4.93790,10.000
10,176.250,6.38,5.0779,5.07790,10.000
10,176.390,8.39,5.2178,5.21780,10.000
10,176.530,10.88,5.3579,5.35790,10.000
10,176.670,13.88,5.4980,5.49800,10.000
10,176.810,17.40,5.6380,5.63800,10.000
10,176.950,21.51,5.7779,5.77790,10.000
10,177.090,26.46,5.9179,5.91790,10.000
10,177.230,32.63,6.0579,6.05790,10.000
10,177.370,40.49,6.1978,6.19780,10.000
10,177.520,52.25,6.3474,6.34740,10.000
10,177.660,40.73,6.2704,6.27040,10.000
10,177.800,26.95,6.1307,6.13070,10.000
10,177.940,18.77,5.9905,5.99050,10.000
10,178.080,13.36,5.8506,5.85060,10.000
10,178.220,9.71,5.7106,5.71060,10.000
10,178.360,7.46,5.5708,5.57080,10.000
10,178.500,5.77,5.4306,5.43060,10.000
10,178.640,4.31,5.2907,5.29070,10.000
10,178.780,3.16,5.1506,5.15060,10.000
10,178.920,2.26,5.0105,5.01050,10.000
10,179.060,1.57,4.8704,4.87040,10.000
10,179.200,1.03,4.7306,4.73060,10.000
10,179.340,0.63,4.5903,4.59030,10.000
10,179.480,0.33,4.4505,4.45050,10.000
10,179.620,0.14,4.3105,4.31050,10.000
10,179.760,0.03,4.1706,4.17060,10.000
10,179.900,0.00,4.0303,4.03030,10.000
10,180.040,0.00,3.8904,3.89040,10.000
10,180.180,0.00,3.7502,3.75020,10.000
10,180.320,0.00,3.6104,3.61040,10.000
10,180.460,0.00,3.4703,3.47030,10.000
10,180.600,0.00,3.3302,3.33020,10.000
10,180.740,0.00,3.1905,3.19050,10.000
10,180.880,-0.01,3.0504,3.05040,10.000
10,181.020,0.00,2.9102,2.91020,10.000
10,181.160,0.00,2.7705,2.77050,10.000
10,181.300,0.00,2.6302,2.63020,10.000
10,181.440,0.00,2.4904,2.49040,10.000
10,181.580,0.00,2.3503,2.35030,10.000
10,181.720,0.00,2.2104,2.21040,10.000
10,181.860,0.00,2.0701,2.07010,10.000
10,182.000,0.00,1.9303,1.93030,10.000
10,182.140,0.00,1.7902,1.79020,10.000
10,182.280,0.00,1.6504,1.65040,10.000
10,182.420,0.00,1.5103,1.51030,10.000
10,182.560,0.00,1.3702,1.37020,10.000
10,182.700,0.00,1.2303,1.23030,10.000
10,182.840,0.00,1.0904,1.09040,10.000
10,182.980,0.00,0.9503,0.95030,10.000
10,183.120,0.00,0.8103,0.81030,10.000
10,183.260,0.00,0.6703,0.67030,10.000
10,183.400,0.00,0.5302,0.53020,10.000
10,183.540,0.00,0.3903,0.39030,10.000
10,183.680,0.00,0.2503,0.25030,10.000
10,183.820,0.00,0.1101,0.11010,10.000
10,183.970,0.00,-0.0392,-0.03920,10.000
10,184.110,0.00,-0.0004,-0.00040,10.000
10,184.250,0.00,-0.0003,-0.00030,10.000
10,184.390,0.00,-0.0003,-0.00030,10.000
10,184.530,0.01,-0.0003,-0.00030,10.000
10,184.670,0.00,-0.0003,-0.00030,10.000
10,184.810,0.00,-0.0003,-0.00030,10.000
10,184.950,0.00,-0.0003,-0.00030,10.000
10,185.090,0.00,-0.0003,-0.00030,10.000
10,185.230,0.00,-0.0003,-0.00030,10.000
10,185.370,0.00,-0.0003,-0.00030,10.000
10,185.510,0.00,-0.0003,-0.00030,10.000
10,185.650,0.00,-0.0002,-0.00020,10.000
10,185.790,0.00,-0.0002,-0.00020,10.000
10,185.930,0.00,-0.0002,-0.00020,10.000
10,186.070,0.00,-0.0002,-0.00020,10.000
10,186.210,0.00,-0.0002,-0.00020,10.000
10,186.350,0.00,-0.0002,-0.00020,10.000
10,186.490,0.00,-0.0002,-0.00020,10.000
10,186.630,0.00,-0.0002,-0.00020,10.000
10,186.770,0.00,-0.0002,-0.00020,10.000
10,186.910,0.00,-0.0002,-0.00020,10.000
10,187.060,0.00,-0.0002,-0.00020,10.000
10,187.200,0.01,-0.0002,-0.00020,10.000
10,187.340,0.01,-0.0002,-0.00020,10.000
10,187.480,0.01,-0.0002,-0.00020,10.000
10,187.620,0.00,-0.0002,-0.00020,10.000
10,187.760,0.00,-0.0002,-0.00020,10.000
10,187.900,0.00,-0.0002,-0.00020,10.000
10,188.040,0.01,-0.0002,-0.00020,10.000
10,188.180,0.00,-0.0002,-0.00020,10.000
10,188.320,0.00,-0.0002,-0.00020,10.000
10,188.460,0.00,-0.0001,-0.00010,10.000
10,188.600,0.00,-0.0001,-0.00010,10.000
10,188.740,0.00,-0.0001,-0.00010,10.000
10,188.880,0.01,-0.0001,-0.00010,10.000
10,189.020,0.00,-0.0001,-0.00010,10.000
10,189.160,0.00,-0.0001,-0.00010,10.000
10,189.300,0.00,-0.0001,-0.00010,10.000
10,189.440,0.00,-0.0001,-0.00010,10.000
10,189.580,0.00,-0.0001,-0.00010,10.000
10,189.720,0.00,-0.0001,-0.00010,10.000
10,189.860,0.00,-0.0001,-0.00010,10.000
10,190.000,0.01,-0.0001,-0.00010,10.000
10,190.070,0.00,-0.0001,-0.00010,10.000