File: InstronData15-3/test6_March15th.is_comp_RawData/Specimen_RawData_1.csv
Maximum Load : Compressive strain (Extension) at Maximum Load,"0.49566",mm/mm
Maximum Load : Compressive stress at Maximum Load,"0.34429",MPa
Maximum Load : Maximum Load,"48.00226",N
Maximum Load : Compressive extension at Maximum Load,"1.25401",mm
Maximum Load : Time at Maximum Load,"37.70600",s
Modulus (Automatic) : Modulus (Automatic),"1.57589",MPa

Time,Extension,Load,Compressive strain (Extension),Compressive stress
(s),(mm),(N),(mm/mm),(MPa)
"0.00000","0.00000","-0.00165","0.00000","-0.00001"
"0.10000","0.00020","-0.00117","0.00008","-0.00001"
"0.20000","0.00078","-0.00071","0.00031","-0.00001"
"0.30000","0.00191","-0.00063","0.00075","0.00000"
"0.40000","0.00563","0.00218","0.00222","0.00002"
"0.50000","0.01419","0.00833","0.00561","0.00006"
"0.60000","0.01739","0.01106","0.00687","0.00008"
"0.70000","0.02029","0.01348","0.00802","0.00010"
"0.80000","0.02363","0.01822","0.00934","0.00013"
"0.90000","0.02699","0.02036","0.01067","0.00015"
"1.00000","0.03039","0.02265","0.01201","0.00016"
"1.10000","0.03397","0.02518","0.01343","0.00018"
"1.20000","0.03764","0.02719","0.01488","0.00020"
"1.30000","0.04099","0.02943","0.01620","0.00021"
"1.40000","0.04416","0.03112","0.01746","0.00022"
"1.50000","0.04735","0.03365","0.01872","0.00024"
"1.60000","0.05051","0.03581","0.01997","0.00026"
"1.70000","0.05370","0.03867","0.02123","0.00028"
"1.80000","0.05703","0.04154","0.02254","0.00030"
"1.90000","0.06027","0.04465","0.02382","0.00032"
"2.00000","0.06399","0.04771","0.02529","0.00034"
"2.10000","0.06771","0.05138","0.02676","0.00037"
"2.20000","0.07091","0.05470","0.02803","0.00039"
"2.30000","0.07378","0.05656","0.02916","0.00041"
"2.40000","0.07716","0.06029","0.03050","0.00043"
"2.50000","0.08041","0.06318","0.03178","0.00045"
"2.60000","0.08369","0.06605","0.03308","0.00047"
"2.70000","0.08702","0.06940","0.03440","0.00050"
"2.80000","0.09035","0.07232","0.03571","0.00052"
"2.90000","0.09393","0.07558","0.03713","0.00054"
"3.00000","0.09766","0.07932","0.03860","0.00057"
"3.10000","0.10106","0.07894","0.03994","0.00057"
"3.20000","0.10423","0.03381","0.04120","0.00024"
"3.30000","0.10740","0.03949","0.04245","0.00028"
"3.40000","0.11073","0.04434","0.04377","0.00032"
"3.50000","0.11398","0.04817","0.04505","0.00035"
"3.60000","0.11711","0.05240","0.04629","0.00038"
"3.70000","0.12035","0.05649","0.04757","0.00041"
"3.80000","0.12377","0.06126","0.04892","0.00044"
"3.90000","0.12748","0.06568","0.05039","0.00047"
"4.00000","0.13093","0.07039","0.05175","0.00050"
"4.10000","0.13405","0.07448","0.05299","0.00053"
"4.20000","0.13705","0.07852","0.05417","0.00056"
"4.30000","0.14048","0.08296","0.05553","0.00060"
"4.40000","0.14372","0.08779","0.05680","0.00063"
"4.50000","0.14707","0.09279","0.05813","0.00067"
"4.60000","0.15038","0.09793","0.05944","0.00070"
"4.70000","0.15374","0.10310","0.06077","0.00074"
"4.80000","0.15735","0.10964","0.06220","0.00079"
"4.90000","0.16102","0.11851","0.06364","0.00085"
"5.00000","0.16428","0.12678","0.06493","0.00091"
"5.10000","0.16750","0.13677","0.06621","0.00098"
"5.20000","0.17072","0.14824","0.06748","0.00106"
"5.30000","0.17400","0.16102","0.06877","0.00115"
"5.40000","0.17717","0.17433","0.07003","0.00125"
"5.50000","0.18033","0.08410","0.07128","0.00060"
"5.60000","0.18367","0.09998","0.07260","0.00072"
"5.70000","0.18728","0.11901","0.07402","0.00085"
"5.80000","0.19101","0.13861","0.07550","0.00099"
"5.90000","0.19423","0.15575","0.07677","0.00112"
"6.00000","0.19710","0.17233","0.07791","0.00124"
"6.10000","0.20043","0.19226","0.07922","0.00138"
"6.20000","0.20380","0.21337","0.08055","0.00153"
"6.30000","0.20700","0.23577","0.08182","0.00169"
"6.40000","0.21041","0.26025","0.08316","0.00187"
"6.50000","0.21373","0.28564","0.08448","0.00205"
"6.60000","0.21723","0.31353","0.08586","0.00225"
"6.70000","0.22087","0.34458","0.08730","0.00247"
"6.80000","0.22432","0.37443","0.08866","0.00269"
"6.90000","0.22755","0.40340","0.08994","0.00289"
"7.00000","0.23077","0.43295","0.09121","0.00311"
"7.10000","0.23409","0.46459","0.09253","0.00333"
"7.20000","0.23734","0.49573","0.09381","0.00356"
"7.30000","0.24044","0.52634","0.09503","0.00378"
"7.40000","0.24365","0.55830","0.09630","0.00400"
"7.50000","0.24700","0.59241","0.09763","0.00425"
"7.60000","0.25079","0.63171","0.09912","0.00453"
"7.70000","0.25427","0.48917","0.10050","0.00351"
"7.80000","0.25741","0.53640","0.10174","0.00385"
"7.90000","0.26034","0.56863","0.10290","0.00408"
"8.00000","0.26394","0.60850","0.10432","0.00436"
"8.10000","0.26717","0.64324","0.10560","0.00461"
"8.20000","0.27031","0.67776","0.10684","0.00486"
"8.30000","0.27372","0.71525","0.10819","0.00513"
"8.40000","0.27704","0.75246","0.10950","0.00540"
"8.50000","0.28054","0.79173","0.11088","0.00568"
"8.60000","0.28417","0.83347","0.11232","0.00598"
"8.70000","0.28770","0.87380","0.11371","0.00627"
"8.80000","0.29090","0.91104","0.11498","0.00653"
"8.90000","0.29407","0.94825","0.11623","0.00680"
"9.00000","0.29743","0.98826","0.11756","0.00709"
"9.10000","0.30065","1.02682","0.11883","0.00736"
"9.20000","0.30378","1.06448","0.12007","0.00763"
"9.30000","0.30701","1.10446","0.12135","0.00792"
"9.40000","0.31047","1.14899","0.12272","0.00824"
"9.50000","0.31427","1.19889","0.12422","0.00860"
"9.60000","0.31766","1.24416","0.12556","0.00892"
"9.70000","0.32056","1.28239","0.12671","0.00920"
"9.80000","0.32381","1.32711","0.12799","0.00952"
"9.90000","0.32721","1.37524","0.12933","0.00986"
"10.00000","0.33035","1.41885","0.13057","0.01018"
"10.10000","0.33369","1.46717","0.13189","0.01052"
"10.20000","0.33705","1.51626","0.13322","0.01088"
"10.30000","0.34045","1.56621","0.13457","0.01123"
"10.40000","0.34417","1.55743","0.13603","0.01117"
"10.50000","0.34765","1.49038","0.13741","0.01069"
"10.60000","0.35088","1.53858","0.13869","0.01104"
"10.70000","0.35419","1.59107","0.14000","0.01141"
"10.80000","0.35741","1.64092","0.14127","0.01177"
"10.90000","0.36076","1.69334","0.14259","0.01215"
"11.00000","0.36390","1.74227","0.14383","0.01250"
"11.10000","0.36693","1.78915","0.14503","0.01283"
"11.20000","0.37024","1.84285","0.14634","0.01322"
"11.30000","0.37395","1.90470","0.14781","0.01366"
"11.40000","0.37768","1.96745","0.14928","0.01411"
"11.50000","0.38092","2.02175","0.15056","0.01450"
"11.60000","0.38380","2.07001","0.15170","0.01485"
"11.70000","0.38717","2.12870","0.15303","0.01527"
"11.80000","0.39045","2.18641","0.15433","0.01568"
"11.90000","0.39371","2.24418","0.15562","0.01610"
"12.00000","0.39705","2.30446","0.15694","0.01653"
"12.10000","0.40033","2.36384","0.15823","0.01695"
"12.20000","0.40388","2.43045","0.15964","0.01743"
"12.30000","0.40753","2.49935","0.16108","0.01793"
"12.40000","0.41097","2.56405","0.16244","0.01839"
"12.50000","0.41426","2.62656","0.16374","0.01884"
"12.60000","0.41748","2.62317","0.16501","0.01881"
"12.70000","0.42077","2.48620","0.16631","0.01783"
"12.80000","0.42403","2.55709","0.16760","0.01834"
"12.90000","0.42708","2.61861","0.16881","0.01878"
"13.00000","0.43036","2.68417","0.17010","0.01925"
"13.10000","0.43376","2.75205","0.17145","0.01974"
"13.20000","0.43746","2.82601","0.17291","0.02027"
"13.30000","0.44095","2.89606","0.17429","0.02077"
"13.40000","0.44406","2.95769","0.17552","0.02121"
"13.50000","0.44705","3.01759","0.17670","0.02164"
"13.60000","0.45049","3.08953","0.17806","0.02216"
"13.70000","0.45373","3.15734","0.17934","0.02265"
"13.80000","0.45707","3.22926","0.18066","0.02316"
"13.90000","0.46035","3.29911","0.18196","0.02366"
"14.00000","0.46368","3.36868","0.18327","0.02416"
"14.10000","0.46733","3.45083","0.18472","0.02475"
"14.20000","0.47108","3.53530","0.18620","0.02536"
"14.30000","0.47431","3.60819","0.18747","0.02588"
"14.40000","0.47751","3.68142","0.18874","0.02640"
"14.50000","0.48075","3.75650","0.19002","0.02694"
"14.60000","0.48402","3.83435","0.19131","0.02750"
"14.70000","0.48710","3.90719","0.19253","0.02802"
"14.80000","0.49029","3.98608","0.19379","0.02859"
"14.90000","0.49367","4.06995","0.19513","0.02919"
"15.00000","0.49724","4.16101","0.19654","0.02984"
"15.10000","0.50099","4.25871","0.19802","0.03054"
"15.20000","0.50429","4.34338","0.19932","0.03115"
"15.30000","0.50726","4.42016","0.20050","0.03170"
"15.40000","0.51041","4.50411","0.20174","0.03230"
"15.50000","0.51376","4.59532","0.20307","0.03296"
"15.60000","0.51701","4.68595","0.20435","0.03361"
"15.70000","0.52029","4.77891","0.20565","0.03428"
"15.80000","0.52363","4.87564","0.20697","0.03497"
"15.90000","0.52717","4.98124","0.20837","0.03573"
"16.00000","0.53090","5.09441","0.20984","0.03654"
"16.10000","0.53440","5.20006","0.21123","0.03730"
"16.20000","0.53758","5.29613","0.21248","0.03799"
"16.30000","0.54080","5.39495","0.21375","0.03869"
"16.40000","0.54410","5.49895","0.21506","0.03944"
"16.50000","0.54735","5.60137","0.21635","0.04017"
"16.60000","0.55046","5.66785","0.21757","0.04065"
"16.70000","0.55365","5.08078","0.21883","0.03644"
"16.80000","0.55703","5.21362","0.22017","0.03739"
"16.90000","0.56074","5.34144","0.22164","0.03831"
"17.00000","0.56438","5.46255","0.22308","0.03918"
"17.10000","0.56756","5.56751","0.22433","0.03993"
"17.20000","0.57038","5.65811","0.22544","0.04058"
"17.30000","0.57382","5.77433","0.22681","0.04142"
"17.40000","0.57703","5.88204","0.22808","0.04219"
"17.50000","0.58035","5.99449","0.22939","0.04299"
"17.60000","0.58364","6.10742","0.23069","0.04380"
"17.70000","0.58700","6.22321","0.23202","0.04463"
"17.80000","0.59069","6.35440","0.23347","0.04558"
"17.90000","0.59440","6.48674","0.23494","0.04652"
"18.00000","0.59767","6.60113","0.23623","0.04735"
"18.10000","0.60077","6.71046","0.23746","0.04813"
"18.20000","0.60402","6.82777","0.23874","0.04897"
"18.30000","0.60727","6.94551","0.24003","0.04982"
"18.40000","0.61039","7.05857","0.24126","0.05063"
"18.50000","0.61375","7.17678","0.24259","0.05147"
"18.60000","0.61702","7.29872","0.24388","0.05235"
"18.70000","0.62049","7.43174","0.24525","0.05330"
"18.80000","0.62432","7.58048","0.24677","0.05437"
"18.90000","0.62760","7.70490","0.24806","0.05526"
"19.00000","0.63067","7.82138","0.24928","0.05610"
"19.10000","0.63375","7.94069","0.25050","0.05695"
"19.20000","0.63713","8.07509","0.25183","0.05792"
"19.30000","0.64040","8.20279","0.25312","0.05883"
"19.40000","0.64372","8.33520","0.25443","0.05978"
"19.50000","0.64699","8.46626","0.25573","0.06072"
"19.60000","0.65048","8.60946","0.25711","0.06175"
"19.70000","0.65425","8.76628","0.25860","0.06287"
"19.80000","0.65775","8.91023","0.25998","0.06391"
"19.90000","0.66093","9.04038","0.26124","0.06484"
"20.00000","0.66418","9.17644","0.26252","0.06582"
"20.10000","0.66739","9.31023","0.26379","0.06678"
"20.20000","0.67067","9.44882","0.26509","0.06777"
"20.30000","0.67378","9.57928","0.26632","0.06871"
"20.40000","0.67699","9.71471","0.26758","0.06968"
"20.50000","0.68038","9.86289","0.26893","0.07074"
"20.60000","0.68405","10.02453","0.27037","0.07190"
"20.70000","0.68764","10.18320","0.27179","0.07304"
"20.80000","0.69083","10.32143","0.27306","0.07403"
"20.90000","0.69375","10.44673","0.27421","0.07493"
"21.00000","0.69713","10.59897","0.27555","0.07602"
"21.10000","0.70046","10.74784","0.27686","0.07709"
"21.20000","0.70374","10.89611","0.27816","0.07815"
"21.30000","0.70705","11.04698","0.27947","0.07923"
"21.40000","0.71043","11.20158","0.28080","0.08034"
"21.50000","0.71400","11.36765","0.28221","0.08153"
"21.60000","0.71755","11.53291","0.28361","0.08272"
"21.70000","0.72085","11.68472","0.28492","0.08381"
"21.80000","0.72414","11.83748","0.28622","0.08490"
"21.90000","0.72741","11.98962","0.28751","0.08599"
"22.00000","0.73075","12.14776","0.28883","0.08713"
"22.10000","0.73399","12.30090","0.29011","0.08823"
"22.20000","0.73710","12.44814","0.29134","0.08928"
"22.30000","0.74037","12.60752","0.29264","0.09043"
"22.40000","0.74384","12.77800","0.29401","0.09165"
"22.50000","0.74749","12.96121","0.29545","0.09296"
"22.60000","0.75093","13.13354","0.29681","0.09420"
"22.70000","0.75408","13.28889","0.29805","0.09531"
"22.80000","0.75709","13.43823","0.29924","0.09638"
"22.90000","0.76047","13.61277","0.30058","0.09764"
"23.00000","0.76372","13.77892","0.30187","0.09883"
"23.10000","0.76703","13.95130","0.30317","0.10006"
"23.20000","0.77033","14.12205","0.30448","0.10129"
"23.30000","0.77376","14.30203","0.30583","0.10258"
"23.40000","0.77737","14.49666","0.30726","0.10397"
"23.50000","0.78103","14.69335","0.30871","0.10539"
"23.60000","0.78431","14.85577","0.31000","0.10655"
"23.70000","0.78745","15.02293","0.31124","0.10775"
"23.80000","0.79077","15.20293","0.31256","0.10904"
"23.90000","0.79409","15.38526","0.31387","0.11035"
"24.00000","0.79733","15.56139","0.31515","0.11161"
"24.10000","0.80036","15.72517","0.31635","0.11279"
"24.20000","0.80358","15.90324","0.31762","0.11406"
"24.30000","0.80724","16.11206","0.31907","0.11556"
"24.40000","0.81097","16.32558","0.32054","0.11709"
"24.50000","0.81430","16.51117","0.32186","0.11842"
"24.60000","0.81729","16.67484","0.32304","0.11960"
"24.70000","0.82042","16.85178","0.32427","0.12087"
"24.80000","0.82376","17.04567","0.32560","0.12226"
"24.90000","0.82708","17.23877","0.32691","0.12364"
"25.00000","0.83038","17.43129","0.32821","0.12502"
"25.10000","0.83371","17.62539","0.32953","0.12641"
"25.20000","0.83721","17.83377","0.33091","0.12791"
"25.30000","0.84082","18.04811","0.33234","0.12945"
"25.40000","0.84437","18.25991","0.33374","0.13097"
"25.50000","0.84755","18.44644","0.33500","0.13230"
"25.60000","0.85077","18.63711","0.33627","0.13367"
"25.70000","0.85409","18.83822","0.33759","0.13511"
"25.80000","0.85733","19.03217","0.33886","0.13650"
"25.90000","0.86036","19.21290","0.34006","0.13780"
"26.00000","0.86361","19.41184","0.34135","0.13923"
"26.10000","0.86701","19.62165","0.34269","0.14073"
"26.20000","0.87079","19.86178","0.34419","0.14245"
"26.30000","0.87432","20.08020","0.34558","0.14402"
"26.40000","0.87750","20.27268","0.34684","0.14540"
"26.50000","0.88049","20.03826","0.34802","0.14372"
"26.60000","0.88378","19.96375","0.34932","0.14319"
"26.70000","0.88708","20.18182","0.35063","0.14475"
"26.80000","0.89036","20.39804","0.35192","0.14630"
"26.90000","0.89366","20.61351","0.35322","0.14785"
"27.00000","0.89705","20.83590","0.35457","0.14944"
"27.10000","0.90069","21.07586","0.35600","0.15116"
"27.20000","0.90438","21.31794","0.35746","0.15290"
"27.30000","0.90765","21.52707","0.35875","0.15440"
"27.40000","0.91078","21.72501","0.35999","0.15582"
"27.50000","0.91411","21.94185","0.36131","0.15737"
"27.60000","0.91738","22.15386","0.36260","0.15889"
"27.70000","0.92055","22.35973","0.36385","0.16037"
"27.80000","0.92361","22.55698","0.36506","0.16179"
"27.90000","0.92694","22.77714","0.36638","0.16336"
"28.00000","0.93052","23.01812","0.36780","0.16509"
"28.10000","0.93431","23.27576","0.36929","0.16694"
"28.20000","0.93768","23.48344","0.37063","0.16843"
"28.30000","0.94061","23.67186","0.37178","0.16978"
"28.40000","0.94372","23.87809","0.37301","0.17126"
"28.50000","0.94711","24.10938","0.37435","0.17292"
"28.60000","0.95035","24.32693","0.37563","0.17448"
"28.70000","0.95367","24.55250","0.37695","0.17610"
"28.80000","0.95699","24.77432","0.37826","0.17769"
"28.90000","0.96053","25.01748","0.37966","0.17943"
"29.00000","0.96420","25.27114","0.38111","0.18125"
"29.10000","0.96773","25.50839","0.38250","0.18295"
"29.20000","0.97089","25.71962","0.38375","0.18447"
"29.30000","0.97416","25.94357","0.38504","0.18608"
"29.40000","0.97740","26.16434","0.38633","0.18766"
"29.50000","0.98066","26.38783","0.38761","0.18926"
"29.60000","0.98375","26.59794","0.38883","0.19077"
"29.70000","0.98697","26.81918","0.39011","0.19236"
"29.80000","0.99039","27.05698","0.39146","0.19406"
"29.90000","0.99407","27.31190","0.39291","0.19589"
"30.00000","0.99766","27.53289","0.39433","0.19747"
"30.10000","1.00086","27.60645","0.39560","0.19800"
"30.20000","1.00385","27.67431","0.39678","0.19849"
"30.30000","1.00704","27.88067","0.39804","0.19997"
"30.40000","1.01043","28.12761","0.39938","0.20174"
"30.50000","1.01364","28.35944","0.40065","0.20340"
"30.60000","1.01695","28.60327","0.40196","0.20515"
"30.70000","1.02033","28.85472","0.40329","0.20696"
"30.80000","1.02397","29.13114","0.40473","0.20894"
"30.90000","1.02767","29.41217","0.40619","0.21095"
"31.00000","1.03105","29.66165","0.40753","0.21274"
"31.10000","1.03414","29.88574","0.40875","0.21435"
"31.20000","1.03744","30.13165","0.41005","0.21611"
"31.30000","1.04074","30.38056","0.41136","0.21790"
"31.40000","1.04390","30.61600","0.41261","0.21959"
"31.50000","1.04698","30.84533","0.41383","0.22123"
"31.60000","1.05026","31.09451","0.41512","0.22302"
"31.70000","1.05376","31.36500","0.41650","0.22496"
"31.80000","1.05760","31.67039","0.41802","0.22715"
"31.90000","1.06101","31.93056","0.41937","0.22902"
"32.00000","1.06395","32.14629","0.42053","0.23056"
"32.10000","1.06704","32.38004","0.42176","0.23224"
"32.20000","1.07048","32.63674","0.42311","0.23408"
"32.30000","1.07368","32.88600","0.42438","0.23587"
"32.40000","1.07700","33.14938","0.42569","0.23776"
"32.50000","1.08037","33.41899","0.42702","0.23969"
"32.60000","1.08384","33.69892","0.42840","0.24170"
"32.70000","1.08746","33.99261","0.42982","0.24381"
"32.80000","1.09111","34.29060","0.43127","0.24594"
"32.90000","1.09437","34.54936","0.43256","0.24780"
"33.00000","1.09745","34.79117","0.43377","0.24953"
"33.10000","1.10070","35.05154","0.43506","0.25140"
"33.20000","1.10394","35.31226","0.43634","0.25327"
"33.30000","1.10709","35.56430","0.43758","0.25508"
"33.40000","1.11032","35.82732","0.43886","0.25696"
"33.50000","1.11353","36.08731","0.44013","0.25883"
"33.60000","1.11744","36.42569","0.44167","0.26126"
"33.70000","1.12107","36.72888","0.44311","0.26343"
"33.80000","1.12415","36.97196","0.44433","0.26517"
"33.90000","1.12715","37.21164","0.44551","0.26689"
"34.00000","1.13037","37.47794","0.44679","0.26880"
"34.10000","1.13375","37.75958","0.44812","0.27082"
"34.20000","1.13711","38.04448","0.44945","0.27287"
"34.30000","1.14036","38.31814","0.45074","0.27483"
"34.40000","1.14375","38.60667","0.45207","0.27690"
"34.50000","1.14721","38.90315","0.45344","0.27903"
"34.60000","1.15076","39.21112","0.45485","0.28123"
"34.70000","1.15435","39.52284","0.45626","0.28347"
"34.80000","1.15759","39.79597","0.45754","0.28543"
"34.90000","1.16076","40.06433","0.45880","0.28735"
"35.00000","1.16408","40.35221","0.46011","0.28942"
"35.10000","1.16734","40.63555","0.46140","0.29145"
"35.20000","1.17051","40.91098","0.46265","0.29343"
"35.30000","1.17367","41.18779","0.46390","0.29541"
"35.40000","1.17708","41.49243","0.46525","0.29760"
"35.50000","1.18087","41.84252","0.46675","0.30011"
"35.60000","1.18436","42.15469","0.46813","0.30235"
"35.70000","1.18739","42.41412","0.46932","0.30421"
"35.80000","1.19041","42.67671","0.47052","0.30609"
"35.90000","1.19382","42.99080","0.47187","0.30834"
"36.00000","1.19708","43.28497","0.47315","0.31045"
"36.10000","1.20039","43.58719","0.47446","0.31262"
"36.20000","1.20367","43.88491","0.47576","0.31476"
"36.30000","1.20702","44.19112","0.47708","0.31695"
"36.40000","1.21065","44.52181","0.47852","0.31932"
"36.50000","1.21431","44.84724","0.47997","0.32166"
"36.60000","1.21766","45.14383","0.48129","0.32379"
"36.70000","1.22081","45.42140","0.48253","0.32578"
"36.80000","1.22411","45.72545","0.48384","0.32796"
"36.90000","1.22741","46.03298","0.48514","0.33016"
"37.00000","1.23067","46.33709","0.48643","0.33234"
"37.10000","1.23369","46.61152","0.48763","0.33431"
"37.20000","1.23680","46.89703","0.48885","0.33636"
"37.30000","1.24054","47.26288","0.49033","0.33898"
"37.40000","1.24431","47.62232","0.49182","0.34156"
"37.50000","1.24758","47.88921","0.49311","0.34348"
"37.60000","1.25050","47.87571","0.49427","0.34338"
"37.70000","1.25380","47.98492","0.49557","0.34416"
"37.70600","1.25401","48.00226","0.49566","0.34429"