File: calibDATA_loadcell/data/date_08:02:2018/MTS/-20deg_30N_2.txt
""
"Test Method","Radhen_Load_Cntrl_Cmprsn_250N_12-7.msm"
"Sample I. D.","Sample1.mss"
"Specimen Number","10"

"TheCycle_Output ()","_Time (s)","_Load (N)","_Extension (mm)","RealTimeDepth (mm)","CycleNumber ()"

1,0.250,0.00,0.0373,0.03730,1.000
1,0.350,0.00,0.1375,0.13750,1.000
1,0.450,0.00,0.2374,0.23740,1.000
1,0.550,0.00,0.3377,0.33770,1.000
1,0.650,0.00,0.4376,0.43760,1.000
1,0.750,0.00,0.5377,0.53770,1.000
1,0.850,0.00,0.6375,0.63750,1.000
1,0.950,0.00,0.7376,0.73760,1.000
1,1.050,0.00,0.8375,0.83750,1.000
1,1.150,0.00,0.9376,0.93760,1.000
1,1.250,0.00,1.0375,1.03750,1.000
1,1.350,0.00,1.1376,1.13760,1.000
1,1.450,0.00,1.2376,1.23760,1.000
1,1.550,0.00,1.3378,1.33780,1.000
1,1.650,0.00,1.4376,1.43760,1.000
1,1.750,0.00,1.5377,1.53770,1.000
1,1.850,0.00,1.6376,1.63760,1.000
1,1.950,0.00,1.7376,1.73760,1.000
1,2.050,0.00,1.8376,1.83760,1.000
1,2.150,0.00,1.9376,1.93760,1.000
1,2.250,0.00,2.0377,2.03770,1.000
1,2.350,0.00,2.1378,2.13780,1.000
1,2.450,0.00,2.2377,2.23770,1.000
1,2.550,0.00,2.3376,2.33760,1.000
1,2.650,0.00,2.4378,2.43780,1.000
1,2.750,0.00,2.5378,2.53780,1.000
1,2.850,0.00,2.6379,2.63790,1.000
1,2.950,0.00,2.7378,2.73780,1.000
1,3.050,0.00,2.8377,2.83770,1.000
1,3.150,0.00,2.9378,2.93780,1.000
1,3.250,0.00,3.0378,3.03780,1.000
1,3.350,0.00,3.1377,3.13770,1.000
1,3.450,0.01,3.2378,3.23780,1.000
1,3.550,0.00,3.3379,3.33790,1.000
1,3.650,0.00,3.4379,3.43790,1.000
1,3.750,0.00,3.5378,3.53780,1.000
1,3.850,0.00,3.6378,3.63780,1.000
1,3.950,0.00,3.7377,3.73770,1.000
1,4.050,0.00,3.8378,3.83780,1.000
1,4.150,0.00,3.9378,3.93780,1.000
1,4.250,0.00,4.0379,4.03790,1.000
1,4.350,0.00,4.1378,4.13780,1.000
1,4.450,0.00,4.2380,4.23800,1.000
1,4.550,0.00,4.3377,4.33770,1.000
1,4.650,0.00,4.4378,4.43780,1.000
1,4.750,0.00,4.5378,4.53780,1.000
1,4.850,0.05,4.6378,4.63780,1.000
1,4.950,0.14,4.7378,4.73780,1.000
1,5.050,0.27,4.8378,4.83780,1.000
1,5.150,0.47,4.9378,4.93780,1.000
1,5.250,0.79,5.0379,5.03790,1.000
1,5.350,1.19,5.1377,5.13770,1.000
1,5.450,1.68,5.2380,5.23800,1.000
1,5.550,2.27,5.3379,5.33790,1.000
1,5.650,2.97,5.4379,5.43790,1.000
1,5.750,3.76,5.5380,5.53800,1.000
1,5.850,4.68,5.6380,5.63800,1.000
1,5.950,5.71,5.7378,5.73780,1.000
1,6.050,6.78,5.8379,5.83790,1.000
1,6.150,8.18,5.9377,5.93770,1.000
1,6.250,9.74,6.0380,6.03800,1.000
1,6.350,11.51,6.1379,6.13790,1.000
1,6.450,13.49,6.2380,6.23800,1.000
1,6.550,15.74,6.3378,6.33780,1.000
1,6.650,18.27,6.4381,6.43810,1.000
1,6.750,21.12,6.5378,6.53780,1.000
1,6.850,24.39,6.6378,6.63780,1.000
1,6.950,28.10,6.7378,6.73780,1.000
1,7.100,31.56,6.8257,6.82570,1.000
1,7.200,23.43,6.7265,6.72650,1.000
1,7.300,18.08,6.6267,6.62670,1.000
1,7.400,14.24,6.5267,6.52670,1.000
1,7.500,11.32,6.4267,6.42670,1.000
1,7.600,9.02,6.3265,6.32650,1.000
1,7.700,7.25,6.2267,6.22670,1.000
1,7.800,5.86,6.1266,6.12660,1.000
1,7.900,4.71,6.0267,6.02670,1.000
1,8.000,3.79,5.9265,5.92650,1.000
1,8.100,3.07,5.8266,5.82660,1.000
1,8.200,2.49,5.7264,5.72640,1.000
1,8.300,1.96,5.6267,5.62670,1.000
1,8.400,1.49,5.5266,5.52660,1.000
1,8.500,1.10,5.4267,5.42670,1.000
1,8.600,0.78,5.3266,5.32660,1.000
1,8.700,0.52,5.2267,5.22670,1.000
1,8.800,0.33,5.1264,5.12640,1.000
1,8.900,0.18,5.0266,5.02660,1.000
1,9.000,0.10,4.9264,4.92640,1.000
1,9.100,0.02,4.8266,4.82660,1.000
1,9.200,0.00,4.7263,4.72630,1.000
1,9.300,0.00,4.6265,4.62650,1.000
1,9.400,0.00,4.5264,4.52640,1.000
1,9.500,0.00,4.4265,4.42650,1.000
1,9.600,0.00,4.3264,4.32640,1.000
1,9.700,0.00,4.2265,4.22650,1.000
1,9.800,0.00,4.1264,4.12640,1.000
1,9.900,0.00,4.0264,4.02640,1.000
1,10.000,0.00,3.9264,3.92640,1.000
1,10.100,0.00,3.8264,3.82640,1.000
1,10.200,0.00,3.7263,3.72630,1.000
1,10.300,0.01,3.6265,3.62650,1.000
1,10.400,0.00,3.5264,3.52640,1.000
1,10.500,0.00,3.4265,3.42650,1.000
1,10.600,0.00,3.3264,3.32640,1.000
1,10.700,0.00,3.2265,3.22650,1.000
1,10.800,0.00,3.1262,3.12620,1.000
1,10.900,0.00,3.0264,3.02640,1.000
1,11.000,0.00,2.9262,2.92620,1.000
1,11.100,0.00,2.8264,2.82640,1.000
1,11.200,0.00,2.7263,2.72630,1.000
1,11.300,0.00,2.6265,2.62650,1.000
1,11.400,0.00,2.5262,2.52620,1.000
1,11.500,0.00,2.4264,2.42640,1.000
1,11.600,0.00,2.3262,2.32620,1.000
1,11.700,0.00,2.2263,2.22630,1.000
1,11.800,0.00,2.1263,2.12630,1.000
1,11.900,0.00,2.0264,2.02640,1.000
1,12.000,0.00,1.9261,1.92610,1.000
1,12.100,0.00,1.8263,1.82630,1.000
1,12.200,0.00,1.7262,1.72620,1.000
1,12.300,0.00,1.6264,1.62640,1.000
1,12.400,0.00,1.5262,1.52620,1.000
1,12.500,0.00,1.4262,1.42620,1.000
1,12.600,0.00,1.3262,1.32620,1.000
1,12.700,0.00,1.2264,1.22640,1.000
1,12.800,0.00,1.1261,1.12610,1.000
1,12.900,0.00,1.0263,1.02630,1.000
1,13.000,0.00,0.9261,0.92610,1.000
1,13.100,0.00,0.8262,0.82620,1.000
1,13.200,0.00,0.7261,0.72610,1.000
1,13.300,0.00,0.6264,0.62640,1.000
1,13.400,0.00,0.5261,0.52610,1.000
1,13.500,0.00,0.4263,0.42630,1.000
1,13.600,0.00,0.3261,0.32610,1.000
1,13.700,0.00,0.2261,0.22610,1.000
1,13.800,0.00,0.1260,0.12600,1.000
1,13.900,0.00,0.0262,0.02620,1.000
1,14.050,0.00,-0.0064,-0.00640,1.000
1,14.150,-0.01,-0.0004,-0.00040,1.000
1,14.250,0.00,-0.0004,-0.00040,1.000
1,14.350,0.00,-0.0004,-0.00040,1.000
1,14.450,0.00,-0.0004,-0.00040,1.000
1,14.550,0.00,-0.0004,-0.00040,1.000
1,14.650,0.00,-0.0004,-0.00040,1.000
1,14.750,0.00,-0.0004,-0.00040,1.000
1,14.850,0.00,-0.0004,-0.00040,1.000
1,14.950,0.00,-0.0004,-0.00040,1.000
1,15.050,0.00,-0.0004,-0.00040,1.000
1,15.150,0.00,-0.0004,-0.00040,1.000
1,15.250,0.00,-0.0004,-0.00040,1.000
1,15.350,0.00,-0.0004,-0.00040,1.000
1,15.450,0.00,-0.0004,-0.00040,1.000
1,15.550,0.00,-0.0004,-0.00040,1.000
1,15.650,0.00,-0.0003,-0.00030,1.000
1,15.750,0.00,-0.0003,-0.00030,1.000
1,15.850,0.00,-0.0003,-0.00030,1.000
1,15.950,0.00,-0.0003,-0.00030,1.000
1,16.050,0.00,-0.0003,-0.00030,1.000
1,16.150,-0.01,-0.0003,-0.00030,1.000
1,16.250,0.00,-0.0003,-0.00030,1.000
1,16.350,0.00,-0.0003,-0.00030,1.000
1,16.450,0.00,-0.0003,-0.00030,1.000
1,16.550,0.00,-0.0003,-0.00030,1.000
1,16.650,0.00,-0.0003,-0.00030,1.000
1,16.750,0.00,-0.0003,-0.00030,1.000
1,16.850,0.00,-0.0003,-0.00030,1.000
1,16.950,0.00,-0.0003,-0.00030,1.000
1,17.100,0.00,-0.0003,-0.00030,1.000
1,17.200,0.00,-0.0003,-0.00030,1.000
1,17.300,0.00,-0.0003,-0.00030,1.000
1,17.400,0.00,-0.0002,-0.00020,1.000
1,17.500,0.00,-0.0002,-0.00020,1.000
1,17.600,0.00,-0.0002,-0.00020,1.000
1,17.700,0.00,-0.0002,-0.00020,1.000
1,17.800,0.00,-0.0002,-0.00020,1.000
1,17.900,0.00,-0.0002,-0.00020,1.000
1,18.000,0.00,-0.0002,-0.00020,1.000
2,18.250,0.00,0.0794,0.07950,2.000
2,18.350,-0.01,0.1796,0.17970,2.000
2,18.450,0.00,0.2796,0.27970,2.000
2,18.550,0.00,0.3797,0.37980,2.000
2,18.650,0.00,0.4796,0.47970,2.000
2,18.750,0.00,0.5797,0.57980,2.000
2,18.850,0.00,0.6796,0.67970,2.000
2,18.950,0.00,0.7796,0.77970,2.000
2,19.050,-0.01,0.8796,0.87970,2.000
2,19.150,0.00,0.9797,0.97980,2.000
2,19.250,-0.01,1.0796,1.07970,2.000
2,19.350,0.00,1.1797,1.17980,2.000
2,19.450,0.00,1.2797,1.27980,2.000
2,19.550,0.00,1.3797,1.37980,2.000
2,19.650,0.00,1.4795,1.47960,2.000
2,19.750,0.00,1.5798,1.57990,2.000
2,19.850,-0.01,1.6797,1.67980,2.000
2,19.950,0.00,1.7797,1.77980,2.000
2,20.050,0.00,1.8797,1.87980,2.000
2,20.150,0.00,1.9797,1.97980,2.000
2,20.250,0.00,2.0799,2.08000,2.000
2,20.350,0.00,2.1799,2.18000,2.000
2,20.450,0.00,2.2798,2.27990,2.000
2,20.550,0.00,2.3797,2.37980,2.000
2,20.650,0.00,2.4798,2.47990,2.000
2,20.750,-0.01,2.5799,2.58000,2.000
2,20.850,0.00,2.6799,2.68000,2.000
2,20.950,-0.01,2.7798,2.77990,2.000
2,21.050,-0.01,2.8797,2.87980,2.000
2,21.150,-0.01,2.9798,2.97990,2.000
2,21.250,0.00,3.0798,3.07990,2.000
2,21.350,-0.01,3.1798,3.17990,2.000
2,21.450,-0.01,3.2799,3.28000,2.000
2,21.550,-0.01,3.3798,3.37990,2.000
2,21.650,-0.01,3.4800,3.48010,2.000
2,21.750,-0.01,3.5799,3.58000,2.000
2,21.850,-0.01,3.6799,3.68000,2.000
2,21.950,0.00,3.7798,3.77990,2.000
2,22.050,0.00,3.8798,3.87990,2.000
2,22.150,-0.01,3.9799,3.98000,2.000
2,22.250,0.00,4.0799,4.08000,2.000
2,22.350,0.00,4.1798,4.17990,2.000
2,22.450,0.00,4.2800,4.28010,2.000
2,22.550,0.00,4.3798,4.37990,2.000
2,22.650,0.00,4.4800,4.48010,2.000
2,22.750,-0.01,4.5799,4.58000,2.000
2,22.850,0.02,4.6799,4.68000,2.000
2,22.950,0.10,4.7799,4.78000,2.000
2,23.050,0.24,4.8800,4.88010,2.000
2,23.150,0.37,4.9799,4.98000,2.000
2,23.250,0.66,5.0799,5.08000,2.000
2,23.350,1.05,5.1798,5.17990,2.000
2,23.450,1.53,5.2800,5.28010,2.000
2,23.550,2.12,5.3799,5.38000,2.000
2,23.650,2.81,5.4800,5.48010,2.000
2,23.750,3.62,5.5799,5.58000,2.000
2,23.850,4.55,5.6800,5.68010,2.000
2,23.950,5.62,5.7797,5.77980,2.000
2,24.050,6.84,5.8799,5.88000,2.000
2,24.150,8.22,5.9798,5.97990,2.000
2,24.250,9.76,6.0801,6.08020,2.000
2,24.350,10.97,6.1798,6.17990,2.000
2,24.450,13.01,6.2799,6.28000,2.000
2,24.550,15.29,6.3799,6.38000,2.000
2,24.650,17.80,6.4799,6.48000,2.000
2,24.750,20.65,6.5797,6.57980,2.000
2,24.850,23.95,6.6800,6.68010,2.000
2,24.950,27.94,6.7797,6.77980,2.000
2,25.100,32.24,6.8677,6.86780,2.000
2,25.200,23.85,6.7685,6.76860,2.000
2,25.300,18.35,6.6687,6.66880,2.000
2,25.400,14.42,6.5686,6.56870,2.000
2,25.500,11.44,6.4688,6.46890,2.000
2,25.600,9.11,6.3687,6.36880,2.000
2,25.700,7.35,6.2687,6.26880,2.000
2,25.800,5.88,6.1686,6.16870,2.000
2,25.900,4.70,6.0686,6.06870,2.000
2,26.000,3.84,5.9685,5.96860,2.000
2,26.100,3.15,5.8685,5.86860,2.000
2,26.200,2.56,5.7684,5.76850,2.000
2,26.300,1.96,5.6687,5.66880,2.000
2,26.400,1.51,5.5686,5.56870,2.000
2,26.500,1.12,5.4687,5.46880,2.000
2,26.600,0.81,5.3686,5.36870,2.000
2,26.700,0.56,5.2687,5.26880,2.000
2,26.800,0.35,5.1685,5.16860,2.000
2,26.900,0.20,5.0684,5.06850,2.000
2,27.000,0.09,4.9684,4.96850,2.000
2,27.100,0.02,4.8685,4.86860,2.000
2,27.200,0.00,4.7683,4.76840,2.000
2,27.300,0.00,4.6685,4.66860,2.000
2,27.400,0.00,4.5684,4.56850,2.000
2,27.500,0.00,4.4686,4.46870,2.000
2,27.600,0.00,4.3683,4.36840,2.000
2,27.700,0.00,4.2686,4.26870,2.000
2,27.800,-0.01,4.1684,4.16850,2.000
2,27.900,-0.01,4.0686,4.06870,2.000
2,28.000,0.00,3.9684,3.96850,2.000
2,28.100,-0.01,3.8684,3.86850,2.000
2,28.200,0.00,3.7683,3.76840,2.000
2,28.300,0.00,3.6684,3.66850,2.000
2,28.400,-0.01,3.5683,3.56840,2.000
2,28.500,0.00,3.4684,3.46850,2.000
2,28.600,0.00,3.3683,3.36840,2.000
2,28.700,0.00,3.2684,3.26850,2.000
2,28.800,-0.01,3.1683,3.16840,2.000
2,28.900,0.00,3.0683,3.06840,2.000
2,29.000,0.00,2.9683,2.96840,2.000
2,29.100,0.00,2.8683,2.86840,2.000
2,29.200,0.00,2.7681,2.76820,2.000
2,29.300,0.00,2.6685,2.66860,2.000
2,29.400,0.00,2.5683,2.56840,2.000
2,29.500,0.00,2.4683,2.46840,2.000
2,29.600,-0.01,2.3681,2.36820,2.000
2,29.700,0.00,2.2683,2.26840,2.000
2,29.800,-0.01,2.1682,2.16830,2.000
2,29.900,0.00,2.0685,2.06860,2.000
2,30.000,0.00,1.9682,1.96830,2.000
2,30.100,0.00,1.8684,1.86850,2.000
2,30.200,0.00,1.7682,1.76830,2.000
2,30.300,-0.01,1.6683,1.66840,2.000
2,30.400,0.00,1.5682,1.56830,2.000
2,30.500,0.00,1.4683,1.46840,2.000
2,30.600,0.00,1.3681,1.36820,2.000
2,30.700,0.00,1.2683,1.26840,2.000
2,30.800,-0.01,1.1682,1.16830,2.000
2,30.900,0.00,1.0682,1.06830,2.000
2,31.000,0.00,0.9681,0.96820,2.000
2,31.100,-0.01,0.8682,0.86830,2.000
2,31.200,0.00,0.7681,0.76820,2.000
2,31.300,0.00,0.6684,0.66850,2.000
2,31.400,0.00,0.5681,0.56820,2.000
2,31.500,0.00,0.4682,0.46830,2.000
2,31.600,0.00,0.3682,0.36830,2.000
2,31.700,0.00,0.2683,0.26840,2.000
2,31.800,0.00,0.1680,0.16810,2.000
2,31.900,-0.01,0.0682,0.06830,2.000
2,32.050,0.00,-0.0361,-0.03600,2.000
2,32.150,-0.01,-0.0004,-0.00030,2.000
2,32.250,0.00,-0.0004,-0.00030,2.000
2,32.350,0.00,-0.0004,-0.00030,2.000
2,32.450,0.00,-0.0004,-0.00030,2.000
2,32.550,0.00,-0.0004,-0.00030,2.000
2,32.650,0.00,-0.0004,-0.00030,2.000
2,32.750,0.00,-0.0004,-0.00030,2.000
2,32.850,-0.01,-0.0004,-0.00030,2.000
2,32.950,0.00,-0.0004,-0.00030,2.000
2,33.050,0.00,-0.0004,-0.00030,2.000
2,33.150,0.00,-0.0004,-0.00030,2.000
2,33.250,0.00,-0.0004,-0.00030,2.000
2,33.350,0.00,-0.0004,-0.00030,2.000
2,33.450,0.00,-0.0003,-0.00020,2.000
2,33.550,0.00,-0.0003,-0.00020,2.000
2,33.650,0.00,-0.0003,-0.00020,2.000
2,33.750,-0.01,-0.0003,-0.00020,2.000
2,33.850,0.00,-0.0003,-0.00020,2.000
2,33.950,0.00,-0.0003,-0.00020,2.000
2,34.050,0.00,-0.0003,-0.00020,2.000
2,34.150,0.00,-0.0003,-0.00020,2.000
2,34.250,-0.01,-0.0003,-0.00020,2.000
2,34.350,0.00,-0.0003,-0.00020,2.000
2,34.450,-0.01,-0.0003,-0.00020,2.000
2,34.550,0.00,-0.0003,-0.00020,2.000
2,34.650,0.00,-0.0003,-0.00020,2.000
2,34.750,0.00,-0.0003,-0.00020,2.000
2,34.850,0.00,-0.0003,-0.00020,2.000
2,34.950,0.00,-0.0003,-0.00020,2.000
2,35.100,0.00,-0.0003,-0.00020,2.000
2,35.200,0.00,-0.0003,-0.00020,2.000
2,35.300,0.00,-0.0002,-0.00010,2.000
2,35.400,0.00,-0.0002,-0.00010,2.000
2,35.500,0.00,-0.0002,-0.00010,2.000
2,35.600,0.00,-0.0002,-0.00010,2.000
2,35.700,0.00,-0.0002,-0.00010,2.000
2,35.800,0.00,-0.0002,-0.00010,2.000
2,35.900,0.00,-0.0002,-0.00010,2.000
2,36.000,0.00,-0.0002,-0.00010,2.000
3,36.200,0.00,-0.0001,0.00000,3.000
3,36.300,0.00,0.0775,0.07760,3.000
3,36.400,0.00,0.1776,0.17770,3.000
3,36.500,0.00,0.2776,0.27770,3.000
3,36.600,0.01,0.3778,0.37790,3.000
3,36.700,0.01,0.4777,0.47780,3.000
3,36.800,0.00,0.5777,0.57780,3.000
3,36.900,0.00,0.6777,0.67780,3.000
3,37.000,0.00,0.7777,0.77780,3.000
3,37.100,0.01,0.8776,0.87770,3.000
3,37.200,0.00,0.9777,0.97780,3.000
3,37.300,0.00,1.0776,1.07770,3.000
3,37.400,0.00,1.1776,1.17770,3.000
3,37.500,0.01,1.2777,1.27780,3.000
3,37.600,0.00,1.3776,1.37770,3.000
3,37.700,0.00,1.4777,1.47780,3.000
3,37.800,0.00,1.5778,1.57790,3.000
3,37.900,0.00,1.6777,1.67780,3.000
3,38.000,0.00,1.7778,1.77790,3.000
3,38.100,0.00,1.8778,1.87790,3.000
3,38.200,0.00,1.9778,1.97790,3.000
3,38.300,0.00,2.0778,2.07790,3.000
3,38.400,0.00,2.1777,2.17780,3.000
3,38.500,0.00,2.2778,2.27790,3.000
3,38.600,0.00,2.3777,2.37780,3.000
3,38.700,0.00,2.4779,2.47800,3.000
3,38.800,0.00,2.5779,2.57800,3.000
3,38.900,0.00,2.6779,2.67800,3.000
3,39.000,0.00,2.7777,2.77780,3.000
3,39.100,0.00,2.8778,2.87790,3.000
3,39.200,0.00,2.9779,2.97800,3.000
3,39.300,0.00,3.0779,3.07800,3.000
3,39.400,0.00,3.1779,3.17800,3.000
3,39.500,0.00,3.2780,3.27810,3.000
3,39.600,0.00,3.3778,3.37790,3.000
3,39.700,0.00,3.4779,3.47800,3.000
3,39.800,0.00,3.5778,3.57790,3.000
3,39.900,0.00,3.6780,3.67810,3.000
3,40.000,0.00,3.7776,3.77770,3.000
3,40.100,0.00,3.8779,3.87800,3.000
3,40.200,0.00,3.9778,3.97790,3.000
3,40.300,0.00,4.0780,4.07810,3.000
3,40.400,0.00,4.1778,4.17790,3.000
3,40.500,0.00,4.2779,4.27800,3.000
3,40.600,0.00,4.3777,4.37780,3.000
3,40.700,0.00,4.4780,4.47810,3.000
3,40.800,0.00,4.5779,4.57800,3.000
3,40.900,0.01,4.6779,4.67800,3.000
3,41.000,0.09,4.7777,4.77780,3.000
3,41.100,0.23,4.8779,4.87800,3.000
3,41.200,0.36,4.9777,4.97780,3.000
3,41.300,0.64,5.0779,5.07800,3.000
3,41.400,1.01,5.1778,5.17790,3.000
3,41.500,1.49,5.2780,5.27810,3.000
3,41.600,2.07,5.3779,5.37800,3.000
3,41.700,2.74,5.4780,5.47810,3.000
3,41.800,3.54,5.5779,5.57800,3.000
3,41.900,4.46,5.6780,5.67810,3.000
3,42.000,5.53,5.7778,5.77790,3.000
3,42.100,6.73,5.8779,5.87800,3.000
3,42.200,8.09,5.9777,5.97780,3.000
3,42.300,9.62,6.0780,6.07810,3.000
3,42.400,10.90,6.1778,6.17790,3.000
3,42.500,12.78,6.2779,6.27800,3.000
3,42.600,15.03,6.3778,6.37790,3.000
3,42.700,17.52,6.4780,6.47810,3.000
3,42.800,20.31,6.5778,6.57790,3.000
3,42.900,23.53,6.6781,6.67820,3.000
3,43.000,27.41,6.7778,6.77790,3.000
3,43.150,32.77,6.8822,6.88230,3.000
3,43.250,24.57,6.7865,6.78660,3.000
3,43.350,18.81,6.6867,6.68680,3.000
3,43.450,14.77,6.5866,6.58670,3.000
3,43.550,11.70,6.4867,6.48680,3.000
3,43.650,9.33,6.3868,6.38690,3.000
3,43.750,7.50,6.2866,6.28670,3.000
3,43.850,5.98,6.1866,6.18670,3.000
3,43.950,4.80,6.0867,6.08680,3.000
3,44.050,3.89,5.9866,5.98670,3.000
3,44.150,3.21,5.8865,5.88660,3.000
3,44.250,2.61,5.7865,5.78660,3.000
3,44.350,2.12,5.6865,5.68660,3.000
3,44.450,1.59,5.5866,5.58670,3.000
3,44.550,1.19,5.4865,5.48660,3.000
3,44.650,0.86,5.3866,5.38670,3.000
3,44.750,0.60,5.2867,5.28680,3.000
3,44.850,0.38,5.1865,5.18660,3.000
3,44.950,0.22,5.0864,5.08650,3.000
3,45.050,0.10,4.9865,4.98660,3.000
3,45.150,0.03,4.8864,4.88650,3.000
3,45.250,0.02,4.7865,4.78660,3.000
3,45.350,0.00,4.6864,4.68650,3.000
3,45.450,0.00,4.5866,4.58670,3.000
3,45.550,0.00,4.4864,4.48650,3.000
3,45.650,0.01,4.3864,4.38650,3.000
3,45.750,0.00,4.2864,4.28650,3.000
3,45.850,0.01,4.1865,4.18660,3.000
3,45.950,0.01,4.0863,4.08640,3.000
3,46.050,0.01,3.9865,3.98660,3.000
3,46.150,0.00,3.8864,3.88650,3.000
3,46.250,0.00,3.7865,3.78660,3.000
3,46.350,0.00,3.6863,3.68640,3.000
3,46.450,0.00,3.5864,3.58650,3.000
3,46.550,0.00,3.4862,3.48630,3.000
3,46.650,0.01,3.3865,3.38660,3.000
3,46.750,0.00,3.2864,3.28650,3.000
3,46.850,0.01,3.1865,3.18660,3.000
3,46.950,0.00,3.0863,3.08640,3.000
3,47.050,0.00,2.9864,2.98650,3.000
3,47.150,0.00,2.8862,2.88630,3.000
3,47.250,0.00,2.7864,2.78650,3.000
3,47.350,0.00,2.6863,2.68640,3.000
3,47.450,0.00,2.5864,2.58650,3.000
3,47.550,0.00,2.4863,2.48640,3.000
3,47.650,0.00,2.3864,2.38650,3.000
3,47.750,0.00,2.2863,2.28640,3.000
3,47.850,0.00,2.1864,2.18650,3.000
3,47.950,0.00,2.0864,2.08650,3.000
3,48.050,0.01,1.9864,1.98650,3.000
3,48.150,0.00,1.8862,1.88630,3.000
3,48.250,0.01,1.7864,1.78650,3.000
3,48.350,0.00,1.6862,1.68630,3.000
3,48.450,0.00,1.5863,1.58640,3.000
3,48.550,0.00,1.4861,1.48620,3.000
3,48.650,0.00,1.3862,1.38630,3.000
3,48.750,0.01,1.2861,1.28620,3.000
3,48.850,0.00,1.1863,1.18640,3.000
3,48.950,0.00,1.0861,1.08620,3.000
3,49.050,0.00,0.9862,0.98630,3.000
3,49.150,0.00,0.8861,0.88620,3.000
3,49.250,0.00,0.7863,0.78640,3.000
3,49.350,0.00,0.6863,0.68640,3.000
3,49.450,-0.01,0.5863,0.58640,3.000
3,49.550,0.00,0.4860,0.48610,3.000
3,49.650,0.00,0.3863,0.38640,3.000
3,49.750,0.00,0.2861,0.28620,3.000
3,49.850,0.00,0.1862,0.18630,3.000
3,49.950,0.00,0.0860,0.08610,3.000
3,50.100,0.00,-0.0434,-0.04330,3.000
3,50.200,0.00,-0.0004,-0.00030,3.000
3,50.300,0.00,-0.0004,-0.00030,3.000
3,50.400,0.00,-0.0004,-0.00030,3.000
3,50.500,0.00,-0.0004,-0.00030,3.000
3,50.600,0.00,-0.0004,-0.00030,3.000
3,50.700,0.00,-0.0004,-0.00030,3.000
3,50.800,0.00,-0.0004,-0.00030,3.000
3,50.900,0.00,-0.0004,-0.00030,3.000
3,51.000,0.00,-0.0004,-0.00030,3.000
3,51.100,0.00,-0.0004,-0.00030,3.000
3,51.200,0.00,-0.0004,-0.00030,3.000
3,51.300,0.00,-0.0004,-0.00030,3.000
3,51.400,0.00,-0.0004,-0.00030,3.000
3,51.500,0.00,-0.0004,-0.00030,3.000
3,51.600,0.00,-0.0003,-0.00020,3.000
3,51.700,0.00,-0.0003,-0.00020,3.000
3,51.800,0.00,-0.0003,-0.00020,3.000
3,51.900,0.00,-0.0003,-0.00020,3.000
3,52.000,0.00,-0.0003,-0.00020,3.000
3,52.100,0.00,-0.0003,-0.00020,3.000
3,52.200,0.00,-0.0003,-0.00020,3.000
3,52.300,0.00,-0.0003,-0.00020,3.000
3,52.400,0.00,-0.0003,-0.00020,3.000
3,52.500,0.01,-0.0003,-0.00020,3.000
3,52.600,0.00,-0.0003,-0.00020,3.000
3,52.700,0.00,-0.0003,-0.00020,3.000
3,52.800,0.00,-0.0003,-0.00020,3.000
3,52.900,0.00,-0.0003,-0.00020,3.000
3,53.000,0.00,-0.0003,-0.00020,3.000
3,53.100,0.00,-0.0003,-0.00020,3.000
3,53.250,0.00,-0.0003,-0.00020,3.000
3,53.350,0.00,-0.0002,-0.00010,3.000
3,53.450,0.00,-0.0002,-0.00010,3.000
3,53.550,0.01,-0.0002,-0.00010,3.000
3,53.650,0.00,-0.0002,-0.00010,3.000
3,53.750,0.00,-0.0002,-0.00010,3.000
3,53.850,0.00,-0.0002,-0.00010,3.000
3,53.950,0.00,-0.0002,-0.00010,3.000
3,54.050,0.00,-0.0002,-0.00010,3.000
4,54.350,0.00,0.0299,0.03000,4.000
4,54.450,0.01,0.1294,0.12950,4.000
4,54.550,0.00,0.2298,0.22990,4.000
4,54.650,0.01,0.3296,0.32970,4.000
4,54.750,0.01,0.4298,0.42990,4.000
4,54.850,0.00,0.5296,0.52970,4.000
4,54.950,0.00,0.6299,0.63000,4.000
4,55.050,0.00,0.7296,0.72970,4.000
4,55.150,0.00,0.8298,0.82990,4.000
4,55.250,0.01,0.9296,0.92970,4.000
4,55.350,0.01,1.0298,1.02990,4.000
4,55.450,0.00,1.1296,1.12970,4.000
4,55.550,0.01,1.2300,1.23010,4.000
4,55.650,0.00,1.3297,1.32980,4.000
4,55.750,0.01,1.4296,1.42970,4.000
4,55.850,0.01,1.5296,1.52970,4.000
4,55.950,0.01,1.6297,1.62980,4.000
4,56.050,0.01,1.7296,1.72970,4.000
4,56.150,0.01,1.8298,1.82990,4.000
4,56.250,0.01,1.9296,1.92970,4.000
4,56.350,0.01,2.0299,2.03000,4.000
4,56.450,0.00,2.1297,2.12980,4.000
4,56.550,0.00,2.2298,2.22990,4.000
4,56.650,0.00,2.3297,2.32980,4.000
4,56.750,0.00,2.4297,2.42980,4.000
4,56.850,0.01,2.5297,2.52980,4.000
4,56.950,0.00,2.6300,2.63010,4.000
4,57.050,0.00,2.7298,2.72990,4.000
4,57.150,0.01,2.8298,2.82990,4.000
4,57.250,0.01,2.9297,2.92980,4.000
4,57.350,0.01,3.0299,3.03000,4.000
4,57.450,0.00,3.1296,3.12970,4.000
4,57.550,0.01,3.2299,3.23000,4.000
4,57.650,0.01,3.3298,3.32990,4.000
4,57.750,0.00,3.4300,3.43010,4.000
4,57.850,0.01,3.5297,3.52980,4.000
4,57.950,0.01,3.6299,3.63000,4.000
4,58.050,0.00,3.7298,3.72990,4.000
4,58.150,0.01,3.8299,3.83000,4.000
4,58.250,0.00,3.9297,3.92980,4.000
4,58.350,0.01,4.0298,4.02990,4.000
4,58.450,0.01,4.1299,4.13000,4.000
4,58.550,0.01,4.2299,4.23000,4.000
4,58.650,0.01,4.3298,4.32990,4.000
4,58.750,0.00,4.4299,4.43000,4.000
4,58.850,0.01,4.5299,4.53000,4.000
4,58.950,0.01,4.6299,4.63000,4.000
4,59.050,0.05,4.7297,4.72980,4.000
4,59.150,0.15,4.8298,4.82990,4.000
4,59.250,0.29,4.9298,4.92990,4.000
4,59.350,0.50,5.0298,5.02990,4.000
4,59.450,0.79,5.1297,5.12980,4.000
4,59.550,1.15,5.2299,5.23000,4.000
4,59.650,1.64,5.3299,5.33000,4.000
4,59.750,2.25,5.4300,5.43010,4.000
4,59.850,2.96,5.5299,5.53000,4.000
4,59.950,3.81,5.6299,5.63000,4.000
4,60.050,4.76,5.7298,5.72990,4.000
4,60.150,5.86,5.8298,5.82990,4.000
4,60.250,7.14,5.9298,5.92990,4.000
4,60.350,8.58,6.0298,6.02990,4.000
4,60.450,10.20,6.1298,6.12990,4.000
4,60.550,12.02,6.2299,6.23000,4.000
4,60.650,14.08,6.3299,6.33000,4.000
4,60.750,16.37,6.4300,6.43010,4.000
4,60.850,18.96,6.5299,6.53000,4.000
4,60.950,21.94,6.6298,6.62990,4.000
4,61.050,25.48,6.7298,6.72990,4.000
4,61.150,29.76,6.8298,6.82990,4.000
4,61.300,26.33,6.8025,6.80260,4.000
4,61.400,19.98,6.7025,6.70260,4.000
4,61.500,15.59,6.6026,6.60270,4.000
4,61.600,12.33,6.5025,6.50260,4.000
4,61.700,9.78,6.4027,6.40280,4.000
4,61.800,7.83,6.3025,6.30260,4.000
4,61.900,6.29,6.2027,6.20280,4.000
4,62.000,5.04,6.1026,6.10270,4.000
4,62.100,4.05,6.0026,6.00270,4.000
4,62.200,3.31,5.9024,5.90250,4.000
4,62.300,2.69,5.8025,5.80260,4.000
4,62.400,2.19,5.7025,5.70260,4.000
4,62.500,1.73,5.6027,5.60280,4.000
4,62.600,1.31,5.5025,5.50260,4.000
4,62.700,0.94,5.4026,5.40270,4.000
4,62.800,0.66,5.3026,5.30270,4.000
4,62.900,0.43,5.2026,5.20270,4.000
4,63.000,0.26,5.1024,5.10250,4.000
4,63.100,0.13,5.0024,5.00250,4.000
4,63.200,0.05,4.9024,4.90250,4.000
4,63.300,0.01,4.8025,4.80260,4.000
4,63.400,0.00,4.7023,4.70240,4.000
4,63.500,0.00,4.6025,4.60260,4.000
4,63.600,0.00,4.5024,4.50250,4.000
4,63.700,0.01,4.4024,4.40250,4.000
4,63.800,0.01,4.3025,4.30260,4.000
4,63.900,0.01,4.2026,4.20270,4.000
4,64.000,0.01,4.1024,4.10250,4.000
4,64.100,0.01,4.0026,4.00270,4.000
4,64.200,0.00,3.9025,3.90260,4.000
4,64.300,0.01,3.8024,3.80250,4.000
4,64.400,0.01,3.7023,3.70240,4.000
4,64.500,0.00,3.6023,3.60240,4.000
4,64.600,0.00,3.5023,3.50240,4.000
4,64.700,0.00,3.4024,3.40250,4.000
4,64.800,0.01,3.3024,3.30250,4.000
4,64.900,0.00,3.2024,3.20250,4.000
4,65.000,0.01,3.1022,3.10230,4.000
4,65.100,0.00,3.0024,3.00250,4.000
4,65.200,0.00,2.9023,2.90240,4.000
4,65.300,0.00,2.8023,2.80240,4.000
4,65.400,0.01,2.7023,2.70240,4.000
4,65.500,0.00,2.6024,2.60250,4.000
4,65.600,0.00,2.5024,2.50250,4.000
4,65.700,0.01,2.4024,2.40250,4.000
4,65.800,0.01,2.3022,2.30230,4.000
4,65.900,0.01,2.2023,2.20240,4.000
4,66.000,0.01,2.1025,2.10260,4.000
4,66.100,0.00,2.0023,2.00240,4.000
4,66.200,0.00,1.9022,1.90230,4.000
4,66.300,0.00,1.8023,1.80240,4.000
4,66.400,0.01,1.7023,1.70240,4.000
4,66.500,0.01,1.6022,1.60230,4.000
4,66.600,0.01,1.5023,1.50240,4.000
4,66.700,0.01,1.4022,1.40230,4.000
4,66.800,0.00,1.3023,1.30240,4.000
4,66.900,0.01,1.2022,1.20230,4.000
4,67.000,0.00,1.1023,1.10240,4.000
4,67.100,0.01,1.0021,1.00220,4.000
4,67.200,0.01,0.9023,0.90240,4.000
4,67.300,0.01,0.8021,0.80220,4.000
4,67.400,0.01,0.7024,0.70250,4.000
4,67.500,0.00,0.6021,0.60220,4.000
4,67.600,0.00,0.5023,0.50240,4.000
4,67.700,0.01,0.4021,0.40220,4.000
4,67.800,0.00,0.3022,0.30230,4.000
4,67.900,0.01,0.2021,0.20220,4.000
4,68.000,0.01,0.1022,0.10230,4.000
4,68.100,0.00,0.0021,0.00220,4.000
4,68.250,0.00,-0.0005,-0.00040,4.000
4,68.350,0.00,-0.0004,-0.00030,4.000
4,68.450,0.00,-0.0004,-0.00030,4.000
4,68.550,0.00,-0.0004,-0.00030,4.000
4,68.650,0.01,-0.0004,-0.00030,4.000
4,68.750,0.01,-0.0004,-0.00030,4.000
4,68.850,0.00,-0.0004,-0.00030,4.000
4,68.950,0.01,-0.0004,-0.00030,4.000
4,69.050,0.01,-0.0004,-0.00030,4.000
4,69.150,0.00,-0.0004,-0.00030,4.000
4,69.250,0.01,-0.0004,-0.00030,4.000
4,69.350,0.01,-0.0004,-0.00030,4.000
4,69.450,0.00,-0.0004,-0.00030,4.000
4,69.550,0.01,-0.0004,-0.00030,4.000
4,69.650,0.01,-0.0003,-0.00020,4.000
4,69.750,0.00,-0.0003,-0.00020,4.000
4,69.850,0.01,-0.0003,-0.00020,4.000
4,69.950,0.00,-0.0003,-0.00020,4.000
4,70.050,0.00,-0.0003,-0.00020,4.000
4,70.150,0.01,-0.0003,-0.00020,4.000
4,70.250,0.01,-0.0003,-0.00020,4.000
4,70.350,0.00,-0.0003,-0.00020,4.000
4,70.450,0.01,-0.0003,-0.00020,4.000
4,70.550,0.01,-0.0003,-0.00020,4.000
4,70.650,0.01,-0.0003,-0.00020,4.000
4,70.750,0.00,-0.0003,-0.00020,4.000
4,70.850,0.01,-0.0003,-0.00020,4.000
4,70.950,0.01,-0.0003,-0.00020,4.000
4,71.050,0.00,-0.0003,-0.00020,4.000
4,71.150,0.01,-0.0003,-0.00020,4.000
4,71.300,0.01,-0.0003,-0.00020,4.000
4,71.400,0.00,-0.0002,-0.00010,4.000
4,71.500,0.01,-0.0002,-0.00010,4.000
4,71.600,0.00,-0.0002,-0.00010,4.000
4,71.700,0.01,-0.0002,-0.00010,4.000
4,71.800,0.00,-0.0002,-0.00010,4.000
4,71.900,0.01,-0.0002,-0.00010,4.000
4,72.000,0.01,-0.0002,-0.00010,4.000
4,72.100,0.01,-0.0002,-0.00010,4.000
5,72.400,0.00,0.0595,0.05960,5.000
5,72.500,-0.01,0.1595,0.15960,5.000
5,72.600,0.00,0.2597,0.25980,5.000
5,72.700,0.00,0.3597,0.35980,5.000
5,72.800,0.00,0.4597,0.45980,5.000
5,72.900,-0.01,0.5596,0.55970,5.000
5,73.000,0.00,0.6599,0.66000,5.000
5,73.100,0.00,0.7597,0.75980,5.000
5,73.200,0.00,0.8597,0.85980,5.000
5,73.300,0.00,0.9598,0.95990,5.000
5,73.400,-0.01,1.0597,1.05980,5.000
5,73.500,0.00,1.1597,1.15980,5.000
5,73.600,-0.01,1.2597,1.25980,5.000
5,73.700,0.00,1.3597,1.35980,5.000
5,73.800,-0.01,1.4596,1.45970,5.000
5,73.900,0.00,1.5597,1.55980,5.000
5,74.000,-0.01,1.6597,1.65980,5.000
5,74.100,0.00,1.7598,1.75990,5.000
5,74.200,0.00,1.8596,1.85970,5.000
5,74.300,0.00,1.9598,1.95990,5.000
5,74.400,0.00,2.0598,2.05990,5.000
5,74.500,-0.01,2.1599,2.16000,5.000
5,74.600,0.00,2.2597,2.25980,5.000
5,74.700,0.00,2.3599,2.36000,5.000
5,74.800,0.00,2.4597,2.45980,5.000
5,74.900,0.00,2.5599,2.56000,5.000
5,75.000,0.00,2.6598,2.65990,5.000
5,75.100,-0.01,2.7598,2.75990,5.000
5,75.200,0.00,2.8597,2.85980,5.000
5,75.300,0.00,2.9599,2.96000,5.000
5,75.400,0.00,3.0597,3.05980,5.000
5,75.500,0.00,3.1598,3.15990,5.000
5,75.600,0.00,3.2597,3.25980,5.000
5,75.700,0.00,3.3600,3.36010,5.000
5,75.800,0.00,3.4598,3.45990,5.000
5,75.900,0.00,3.5599,3.56000,5.000
5,76.000,0.00,3.6597,3.65980,5.000
5,76.100,0.00,3.7599,3.76000,5.000
5,76.200,0.00,3.8597,3.85980,5.000
5,76.300,0.00,3.9599,3.96000,5.000
5,76.400,0.00,4.0598,4.05990,5.000
5,76.500,0.00,4.1600,4.16010,5.000
5,76.600,0.00,4.2598,4.25990,5.000
5,76.700,-0.01,4.3599,4.36000,5.000
5,76.800,0.00,4.4599,4.46000,5.000
5,76.900,-0.01,4.5600,4.56010,5.000
5,77.000,0.00,4.6598,4.65990,5.000
5,77.100,0.06,4.7599,4.76000,5.000
5,77.200,0.17,4.8598,4.85990,5.000
5,77.300,0.35,4.9599,4.96000,5.000
5,77.400,0.57,5.0597,5.05980,5.000
5,77.500,0.87,5.1599,5.16000,5.000
5,77.600,1.24,5.2598,5.25990,5.000
5,77.700,1.76,5.3600,5.36010,5.000
5,77.800,2.38,5.4597,5.45980,5.000
5,77.900,3.11,5.5600,5.56010,5.000
5,78.000,3.98,5.6597,5.65980,5.000
5,78.100,4.99,5.7599,5.76000,5.000
5,78.200,6.16,5.8596,5.85970,5.000
5,78.300,7.47,5.9599,5.96000,5.000
5,78.400,8.95,6.0598,6.05990,5.000
5,78.500,10.62,6.1600,6.16010,5.000
5,78.600,12.50,6.2599,6.26000,5.000
5,78.700,14.61,6.3599,6.36000,5.000
5,78.800,16.99,6.4598,6.45990,5.000
5,78.900,19.65,6.5600,6.56010,5.000
5,79.000,22.76,6.6597,6.65980,5.000
5,79.100,26.44,6.7599,6.76000,5.000
5,79.200,30.98,6.8597,6.85980,5.000
5,79.300,30.49,6.8580,6.85810,5.000
5,79.400,22.44,6.7587,6.75880,5.000
5,79.500,17.38,6.6585,6.65860,5.000
5,79.600,13.66,6.5586,6.55870,5.000
5,79.700,10.85,6.4585,6.45860,5.000
5,79.800,8.63,6.3587,6.35880,5.000
5,79.900,6.92,6.2584,6.25850,5.000
5,80.000,5.55,6.1586,6.15870,5.000
5,80.100,4.47,6.0585,6.05860,5.000
5,80.200,3.61,5.9586,5.95870,5.000
5,80.300,2.98,5.8585,5.85860,5.000
5,80.400,2.43,5.7586,5.75870,5.000
5,80.500,1.96,5.6584,5.65850,5.000
5,80.600,1.49,5.5587,5.55880,5.000
5,80.700,1.09,5.4583,5.45840,5.000
5,80.800,0.78,5.3587,5.35880,5.000
5,80.900,0.52,5.2585,5.25860,5.000
5,81.000,0.32,5.1585,5.15860,5.000
5,81.100,0.18,5.0583,5.05840,5.000
5,81.200,0.07,4.9584,4.95850,5.000
5,81.300,0.02,4.8582,4.85830,5.000
5,81.400,0.00,4.7584,4.75850,5.000
5,81.500,0.00,4.6583,4.65840,5.000
5,81.600,-0.01,4.5586,4.55870,5.000
5,81.700,-0.01,4.4583,4.45840,5.000
5,81.800,0.00,4.3585,4.35860,5.000
5,81.900,0.00,4.2583,4.25840,5.000
5,82.000,0.00,4.1585,4.15860,5.000
5,82.100,-0.01,4.0582,4.05830,5.000
5,82.200,0.00,3.9586,3.95870,5.000
5,82.300,0.00,3.8582,3.85830,5.000
5,82.400,0.00,3.7584,3.75850,5.000
5,82.500,0.00,3.6583,3.65840,5.000
5,82.600,0.00,3.5584,3.55850,5.000
5,82.700,0.00,3.4582,3.45830,5.000
5,82.800,-0.01,3.3584,3.35850,5.000
5,82.900,0.00,3.2582,3.25830,5.000
5,83.000,0.00,3.1584,3.15850,5.000
5,83.100,0.00,3.0582,3.05830,5.000
5,83.200,0.00,2.9585,2.95860,5.000
5,83.300,0.00,2.8582,2.85830,5.000
5,83.400,0.00,2.7584,2.75850,5.000
5,83.500,-0.01,2.6583,2.65840,5.000
5,83.600,0.00,2.5584,2.55850,5.000
5,83.700,0.00,2.4582,2.45830,5.000
5,83.800,0.00,2.3583,2.35840,5.000
5,83.900,-0.01,2.2582,2.25830,5.000
5,84.000,0.00,2.1585,2.15860,5.000
5,84.100,0.00,2.0583,2.05840,5.000
5,84.200,0.00,1.9584,1.95850,5.000
5,84.300,-0.01,1.8583,1.85840,5.000
5,84.400,0.00,1.7584,1.75850,5.000
5,84.500,0.00,1.6583,1.65840,5.000
5,84.600,0.00,1.5583,1.55840,5.000
5,84.700,-0.01,1.4582,1.45830,5.000
5,84.800,0.00,1.3582,1.35830,5.000
5,84.900,0.00,1.2582,1.25830,5.000
5,85.000,-0.01,1.1582,1.15830,5.000
5,85.100,-0.01,1.0582,1.05830,5.000
5,85.200,-0.01,0.9582,0.95830,5.000
5,85.300,0.00,0.8581,0.85820,5.000
5,85.400,0.00,0.7581,0.75820,5.000
5,85.500,0.00,0.6582,0.65830,5.000
5,85.600,0.00,0.5582,0.55830,5.000
5,85.700,-0.01,0.4582,0.45830,5.000
5,85.800,0.00,0.3582,0.35830,5.000
5,85.900,-0.01,0.2581,0.25820,5.000
5,86.000,-0.01,0.1581,0.15820,5.000
5,86.100,0.00,0.0581,0.05820,5.000
5,86.250,0.00,-0.0297,-0.02960,5.000
5,86.350,0.00,-0.0004,-0.00030,5.000
5,86.450,0.00,-0.0004,-0.00030,5.000
5,86.550,0.00,-0.0004,-0.00030,5.000
5,86.650,-0.01,-0.0004,-0.00030,5.000
5,86.750,-0.01,-0.0004,-0.00030,5.000
5,86.850,0.00,-0.0004,-0.00030,5.000
5,86.950,0.00,-0.0004,-0.00030,5.000
5,87.050,0.00,-0.0004,-0.00030,5.000
5,87.150,0.00,-0.0004,-0.00030,5.000
5,87.250,-0.01,-0.0004,-0.00030,5.000
5,87.350,0.00,-0.0003,-0.00020,5.000
5,87.450,0.00,-0.0003,-0.00020,5.000
5,87.550,0.00,-0.0003,-0.00020,5.000
5,87.650,-0.01,-0.0003,-0.00020,5.000
5,87.750,-0.01,-0.0003,-0.00020,5.000
5,87.850,0.00,-0.0003,-0.00020,5.000
5,87.950,0.00,-0.0003,-0.00020,5.000
5,88.050,0.00,-0.0003,-0.00020,5.000
5,88.150,-0.01,-0.0003,-0.00020,5.000
5,88.250,0.00,-0.0003,-0.00020,5.000
5,88.350,-0.01,-0.0003,-0.00020,5.000
5,88.450,0.00,-0.0003,-0.00020,5.000
5,88.550,-0.01,-0.0003,-0.00020,5.000
5,88.650,-0.01,-0.0003,-0.00020,5.000
5,88.750,0.00,-0.0003,-0.00020,5.000
5,88.850,0.00,-0.0003,-0.00020,5.000
5,88.950,0.00,-0.0003,-0.00020,5.000
5,89.050,0.00,-0.0003,-0.00020,5.000
5,89.150,0.00,-0.0003,-0.00020,5.000
5,89.300,0.00,-0.0002,-0.00010,5.000
5,89.400,0.00,-0.0002,-0.00010,5.000
5,89.500,0.00,-0.0002,-0.00010,5.000
5,89.600,-0.01,-0.0002,-0.00010,5.000
5,89.700,-0.01,-0.0002,-0.00010,5.000
5,89.800,0.00,-0.0002,-0.00010,5.000
5,89.900,0.00,-0.0002,-0.00010,5.000
5,90.000,0.00,-0.0002,-0.00010,5.000
5,90.100,0.00,-0.0002,-0.00010,5.000
5,90.200,0.00,-0.0002,-0.00010,5.000