File: calibDATA_loadcell/data/date_08:02:2018/MTS/-20deg_30N_1.txt
""
"Test Method","Radhen_Load_Cntrl_Cmprsn_250N_12-7.msm"
"Sample I. D.","Sample1.mss"
"Specimen Number","5"

"TheCycle_Output ()","_Time (s)","_Load (N)","_Extension (mm)","RealTimeDepth (mm)","CycleNumber ()"

1,0.300,0.00,0.0576,0.05760,1.000
1,0.400,0.01,0.1574,0.15740,1.000
1,0.500,0.00,0.2576,0.25760,1.000
1,0.600,0.00,0.3576,0.35760,1.000
1,0.700,0.00,0.4578,0.45780,1.000
1,0.800,0.00,0.5575,0.55750,1.000
1,0.900,0.01,0.6578,0.65780,1.000
1,1.000,0.00,0.7574,0.75740,1.000
1,1.100,0.00,0.8577,0.85770,1.000
1,1.200,0.00,0.9576,0.95760,1.000
1,1.300,0.00,1.0577,1.05770,1.000
1,1.400,0.01,1.1576,1.15760,1.000
1,1.500,0.00,1.2578,1.25780,1.000
1,1.600,0.00,1.3576,1.35760,1.000
1,1.700,0.00,1.4576,1.45760,1.000
1,1.800,0.01,1.5576,1.55760,1.000
1,1.900,0.00,1.6577,1.65770,1.000
1,2.000,0.01,1.7576,1.75760,1.000
1,2.100,0.01,1.8577,1.85770,1.000
1,2.200,0.01,1.9576,1.95760,1.000
1,2.300,0.01,2.0578,2.05780,1.000
1,2.400,0.00,2.1577,2.15770,1.000
1,2.500,0.00,2.2577,2.25770,1.000
1,2.600,0.01,2.3577,2.35770,1.000
1,2.700,0.00,2.4577,2.45770,1.000
1,2.800,0.01,2.5577,2.55770,1.000
1,2.900,0.01,2.6579,2.65790,1.000
1,3.000,0.00,2.7577,2.75770,1.000
1,3.100,0.00,2.8578,2.85780,1.000
1,3.200,0.00,2.9577,2.95770,1.000
1,3.300,0.01,3.0578,3.05780,1.000
1,3.400,0.00,3.1577,3.15770,1.000
1,3.500,0.00,3.2578,3.25780,1.000
1,3.600,0.00,3.3577,3.35770,1.000
1,3.700,0.00,3.4578,3.45780,1.000
1,3.800,0.01,3.5577,3.55770,1.000
1,3.900,0.00,3.6579,3.65790,1.000
1,4.000,0.01,3.7577,3.75770,1.000
1,4.100,0.00,3.8578,3.85780,1.000
1,4.200,0.00,3.9578,3.95780,1.000
1,4.300,0.00,4.0579,4.05790,1.000
1,4.400,0.00,4.1579,4.15790,1.000
1,4.500,0.00,4.2579,4.25790,1.000
1,4.600,0.00,4.3578,4.35780,1.000
1,4.700,0.00,4.4579,4.45790,1.000
1,4.800,0.06,4.5578,4.55780,1.000
1,4.900,0.12,4.6579,4.65790,1.000
1,5.000,0.29,4.7577,4.75770,1.000
1,5.100,0.54,4.8578,4.85780,1.000
1,5.200,0.90,4.9577,4.95770,1.000
1,5.300,1.36,5.0578,5.05780,1.000
1,5.400,1.93,5.1578,5.15780,1.000
1,5.500,2.61,5.2579,5.25790,1.000
1,5.600,3.42,5.3579,5.35790,1.000
1,5.700,4.38,5.4578,5.45780,1.000
1,5.800,5.51,5.5579,5.55790,1.000
1,5.900,6.81,5.6579,5.65790,1.000
1,6.000,8.30,5.7579,5.75790,1.000
1,6.100,9.99,5.8578,5.85780,1.000
1,6.200,11.91,5.9579,5.95790,1.000
1,6.300,14.05,6.0580,6.05800,1.000
1,6.400,16.47,6.1580,6.15800,1.000
1,6.500,19.22,6.2579,6.25790,1.000
1,6.600,22.39,6.3580,6.35800,1.000
1,6.700,25.97,6.4580,6.45800,1.000
1,6.800,30.11,6.5578,6.55780,1.000
1,6.950,25.98,6.5324,6.53240,1.000
1,7.050,19.44,6.4328,6.43280,1.000
1,7.150,14.90,6.3326,6.33260,1.000
1,7.250,11.52,6.2326,6.23260,1.000
1,7.350,8.96,6.1326,6.13260,1.000
1,7.450,6.99,6.0327,6.03270,1.000
1,7.550,5.58,5.9325,5.93250,1.000
1,7.650,4.46,5.8325,5.83250,1.000
1,7.750,3.50,5.7324,5.73240,1.000
1,7.850,2.82,5.6326,5.63260,1.000
1,7.950,2.27,5.5326,5.53260,1.000
1,8.050,1.69,5.4326,5.43260,1.000
1,8.150,1.22,5.3326,5.33260,1.000
1,8.250,0.86,5.2327,5.23270,1.000
1,8.350,0.57,5.1325,5.13250,1.000
1,8.450,0.35,5.0325,5.03250,1.000
1,8.550,0.17,4.9325,4.93250,1.000
1,8.650,0.06,4.8325,4.83250,1.000
1,8.750,0.01,4.7325,4.73250,1.000
1,8.850,0.00,4.6324,4.63240,1.000
1,8.950,0.00,4.5325,4.53250,1.000
1,9.050,0.01,4.4325,4.43250,1.000
1,9.150,0.00,4.3324,4.33240,1.000
1,9.250,0.00,4.2326,4.23260,1.000
1,9.350,0.00,4.1325,4.13250,1.000
1,9.450,0.00,4.0325,4.03250,1.000
1,9.550,0.00,3.9325,3.93250,1.000
1,9.650,0.00,3.8325,3.83250,1.000
1,9.750,0.00,3.7324,3.73240,1.000
1,9.850,0.00,3.6324,3.63240,1.000
1,9.950,0.00,3.5323,3.53230,1.000
1,10.050,0.01,3.4325,3.43250,1.000
1,10.150,0.01,3.3324,3.33240,1.000
1,10.250,0.01,3.2324,3.23240,1.000
1,10.350,0.00,3.1322,3.13220,1.000
1,10.450,0.00,3.0323,3.03230,1.000
1,10.550,0.01,2.9323,2.93230,1.000
1,10.650,0.00,2.8323,2.83230,1.000
1,10.750,0.00,2.7325,2.73250,1.000
1,10.850,0.00,2.6324,2.63240,1.000
1,10.950,0.00,2.5324,2.53240,1.000
1,11.050,0.00,2.4324,2.43240,1.000
1,11.150,0.00,2.3324,2.33240,1.000
1,11.250,0.01,2.2323,2.23230,1.000
1,11.350,0.00,2.1325,2.13250,1.000
1,11.450,0.00,2.0324,2.03240,1.000
1,11.550,0.00,1.9324,1.93240,1.000
1,11.650,0.00,1.8322,1.83220,1.000
1,11.750,0.00,1.7324,1.73240,1.000
1,11.850,0.00,1.6323,1.63230,1.000
1,11.950,0.00,1.5324,1.53240,1.000
1,12.050,0.00,1.4322,1.43220,1.000
1,12.150,0.01,1.3324,1.33240,1.000
1,12.250,0.00,1.2323,1.23230,1.000
1,12.350,0.00,1.1323,1.13230,1.000
1,12.450,0.00,1.0322,1.03220,1.000
1,12.550,0.00,0.9324,0.93240,1.000
1,12.650,0.00,0.8321,0.83210,1.000
1,12.750,0.01,0.7323,0.73230,1.000
1,12.850,0.00,0.6322,0.63220,1.000
1,12.950,0.00,0.5321,0.53210,1.000
1,13.050,0.00,0.4322,0.43220,1.000
1,13.150,0.00,0.3323,0.33230,1.000
1,13.250,0.00,0.2321,0.23210,1.000
1,13.350,0.00,0.1322,0.13220,1.000
1,13.450,0.00,0.0321,0.03210,1.000
1,13.600,0.01,-0.0054,-0.00540,1.000
1,13.700,0.01,-0.0004,-0.00040,1.000
1,13.800,0.01,-0.0004,-0.00040,1.000
1,13.900,0.00,-0.0004,-0.00040,1.000
1,14.000,0.00,-0.0004,-0.00040,1.000
1,14.100,0.01,-0.0004,-0.00040,1.000
1,14.200,0.00,-0.0004,-0.00040,1.000
1,14.300,0.00,-0.0004,-0.00040,1.000
1,14.400,0.00,-0.0004,-0.00040,1.000
1,14.500,0.01,-0.0004,-0.00040,1.000
1,14.600,0.00,-0.0004,-0.00040,1.000
1,14.700,0.00,-0.0003,-0.00030,1.000
1,14.800,0.00,-0.0003,-0.00030,1.000
1,14.900,0.01,-0.0003,-0.00030,1.000
1,15.000,0.00,-0.0003,-0.00030,1.000
1,15.100,0.01,-0.0003,-0.00030,1.000
1,15.200,0.00,-0.0003,-0.00030,1.000
1,15.300,0.00,-0.0003,-0.00030,1.000
1,15.400,0.00,-0.0003,-0.00030,1.000
1,15.500,0.01,-0.0003,-0.00030,1.000
1,15.600,0.01,-0.0003,-0.00030,1.000
1,15.700,0.00,-0.0003,-0.00030,1.000
1,15.800,0.01,-0.0003,-0.00030,1.000
1,15.900,0.00,-0.0003,-0.00030,1.000
1,16.000,0.01,-0.0003,-0.00030,1.000
1,16.100,0.01,-0.0003,-0.00030,1.000
1,16.200,0.00,-0.0003,-0.00030,1.000
1,16.300,0.00,-0.0003,-0.00030,1.000
1,16.400,0.00,-0.0002,-0.00020,1.000
1,16.500,0.00,-0.0002,-0.00020,1.000
1,16.650,0.01,-0.0002,-0.00020,1.000
1,16.750,0.00,-0.0002,-0.00020,1.000
1,16.850,0.01,-0.0002,-0.00020,1.000
1,16.950,0.01,-0.0002,-0.00020,1.000
1,17.050,0.00,-0.0002,-0.00020,1.000
1,17.150,0.00,-0.0002,-0.00020,1.000
1,17.250,0.00,-0.0002,-0.00020,1.000
1,17.350,0.00,-0.0002,-0.00020,1.000
1,17.450,0.01,-0.0002,-0.00020,1.000
1,17.550,0.01,-0.0002,-0.00020,1.000
2,17.850,-0.01,0.1076,0.10770,2.000
2,17.950,-0.01,0.2076,0.20770,2.000
2,18.050,-0.01,0.3076,0.30770,2.000
2,18.150,0.00,0.4077,0.40780,2.000
2,18.250,0.00,0.5076,0.50770,2.000
2,18.350,0.00,0.6078,0.60790,2.000
2,18.450,-0.01,0.7077,0.70780,2.000
2,18.550,0.00,0.8076,0.80770,2.000
2,18.650,-0.01,0.9076,0.90770,2.000
2,18.750,0.00,1.0076,1.00770,2.000
2,18.850,0.00,1.1076,1.10770,2.000
2,18.950,-0.01,1.2077,1.20780,2.000
2,19.050,-0.01,1.3078,1.30790,2.000
2,19.150,-0.01,1.4077,1.40780,2.000
2,19.250,0.00,1.5077,1.50780,2.000
2,19.350,0.00,1.6077,1.60780,2.000
2,19.450,-0.01,1.7077,1.70780,2.000
2,19.550,0.00,1.8077,1.80780,2.000
2,19.650,0.00,1.9077,1.90780,2.000
2,19.750,-0.01,2.0077,2.00780,2.000
2,19.850,0.00,2.1079,2.10800,2.000
2,19.950,-0.01,2.2077,2.20780,2.000
2,20.050,0.00,2.3079,2.30800,2.000
2,20.150,0.00,2.4077,2.40780,2.000
2,20.250,-0.01,2.5079,2.50800,2.000
2,20.350,0.00,2.6078,2.60790,2.000
2,20.450,-0.01,2.7079,2.70800,2.000
2,20.550,-0.01,2.8078,2.80790,2.000
2,20.650,0.00,2.9079,2.90800,2.000
2,20.750,-0.01,3.0077,3.00780,2.000
2,20.850,0.00,3.1079,3.10800,2.000
2,20.950,-0.01,3.2078,3.20790,2.000
2,21.050,-0.01,3.3080,3.30810,2.000
2,21.150,0.00,3.4078,3.40790,2.000
2,21.250,0.00,3.5080,3.50810,2.000
2,21.350,0.00,3.6077,3.60780,2.000
2,21.450,-0.01,3.7080,3.70810,2.000
2,21.550,-0.01,3.8077,3.80780,2.000
2,21.650,-0.01,3.9080,3.90810,2.000
2,21.750,-0.01,4.0077,4.00780,2.000
2,21.850,0.00,4.1079,4.10800,2.000
2,21.950,-0.01,4.2078,4.20790,2.000
2,22.050,-0.01,4.3080,4.30810,2.000
2,22.150,-0.01,4.4078,4.40790,2.000
2,22.250,0.00,4.5080,4.50810,2.000
2,22.350,0.00,4.6079,4.60800,2.000
2,22.450,0.09,4.7079,4.70800,2.000
2,22.550,0.26,4.8078,4.80790,2.000
2,22.650,0.49,4.9080,4.90810,2.000
2,22.750,0.79,5.0077,5.00780,2.000
2,22.850,1.17,5.1078,5.10790,2.000
2,22.950,1.66,5.2078,5.20790,2.000
2,23.050,2.33,5.3080,5.30810,2.000
2,23.150,3.12,5.4079,5.40800,2.000
2,23.250,4.08,5.5080,5.50810,2.000
2,23.350,5.19,5.6078,5.60790,2.000
2,23.450,6.49,5.7079,5.70800,2.000
2,23.550,7.99,5.8077,5.80780,2.000
2,23.650,9.70,5.9080,5.90810,2.000
2,23.750,11.62,6.0078,6.00790,2.000
2,23.850,13.77,6.1080,6.10810,2.000
2,23.950,16.22,6.2078,6.20790,2.000
2,24.050,18.94,6.3080,6.30810,2.000
2,24.150,22.17,6.4078,6.40790,2.000
2,24.250,26.00,6.5078,6.50790,2.000
2,24.400,32.33,6.6297,6.62980,2.000
2,24.500,24.68,6.5426,6.54270,2.000
2,24.600,18.50,6.4427,6.44280,2.000
2,24.700,14.12,6.3428,6.34290,2.000
2,24.800,10.88,6.2426,6.24270,2.000
2,24.900,8.42,6.1428,6.14290,2.000
2,25.000,6.66,6.0426,6.04270,2.000
2,25.100,5.30,5.9426,5.94270,2.000
2,25.200,4.16,5.8426,5.84270,2.000
2,25.300,3.38,5.7426,5.74270,2.000
2,25.400,2.71,5.6425,5.64260,2.000
2,25.500,2.04,5.5427,5.54280,2.000
2,25.600,1.51,5.4426,5.44270,2.000
2,25.700,1.10,5.3427,5.34280,2.000
2,25.800,0.79,5.2426,5.24270,2.000
2,25.900,0.52,5.1426,5.14270,2.000
2,26.000,0.30,5.0423,5.04240,2.000
2,26.100,0.14,4.9427,4.94280,2.000
2,26.200,0.04,4.8423,4.84240,2.000
2,26.300,0.01,4.7424,4.74250,2.000
2,26.400,-0.01,4.6423,4.64240,2.000
2,26.500,-0.01,4.5426,4.54270,2.000
2,26.600,0.00,4.4424,4.44250,2.000
2,26.700,-0.01,4.3425,4.34260,2.000
2,26.800,0.00,4.2424,4.24250,2.000
2,26.900,-0.01,4.1425,4.14260,2.000
2,27.000,-0.01,4.0424,4.04250,2.000
2,27.100,0.00,3.9425,3.94260,2.000
2,27.200,-0.01,3.8423,3.84240,2.000
2,27.300,0.00,3.7425,3.74260,2.000
2,27.400,-0.01,3.6423,3.64240,2.000
2,27.500,0.00,3.5424,3.54250,2.000
2,27.600,-0.01,3.4423,3.44240,2.000
2,27.700,-0.01,3.3425,3.34260,2.000
2,27.800,-0.01,3.2423,3.24240,2.000
2,27.900,0.00,3.1424,3.14250,2.000
2,28.000,0.00,3.0423,3.04240,2.000
2,28.100,0.00,2.9424,2.94250,2.000
2,28.200,0.00,2.8422,2.84230,2.000
2,28.300,-0.01,2.7424,2.74250,2.000
2,28.400,0.00,2.6423,2.64240,2.000
2,28.500,-0.01,2.5425,2.54260,2.000
2,28.600,-0.01,2.4423,2.44240,2.000
2,28.700,-0.01,2.3424,2.34250,2.000
2,28.800,0.00,2.2421,2.24220,2.000
2,28.900,0.00,2.1424,2.14250,2.000
2,29.000,0.00,2.0424,2.04250,2.000
2,29.100,0.00,1.9424,1.94250,2.000
2,29.200,-0.01,1.8423,1.84240,2.000
2,29.300,0.00,1.7424,1.74250,2.000
2,29.400,-0.01,1.6421,1.64220,2.000
2,29.500,0.00,1.5422,1.54230,2.000
2,29.600,-0.01,1.4420,1.44210,2.000
2,29.700,0.00,1.3423,1.34240,2.000
2,29.800,-0.01,1.2422,1.24230,2.000
2,29.900,-0.01,1.1422,1.14230,2.000
2,30.000,-0.01,1.0422,1.04230,2.000
2,30.100,0.00,0.9423,0.94240,2.000
2,30.200,-0.01,0.8420,0.84210,2.000
2,30.300,-0.01,0.7422,0.74230,2.000
2,30.400,-0.01,0.6422,0.64230,2.000
2,30.500,0.00,0.5423,0.54240,2.000
2,30.600,0.00,0.4421,0.44220,2.000
2,30.700,0.00,0.3423,0.34240,2.000
2,30.800,-0.01,0.2421,0.24220,2.000
2,30.900,0.00,0.1422,0.14230,2.000
2,31.000,0.00,0.0421,0.04220,2.000
2,31.150,0.00,-0.0124,-0.01230,2.000
2,31.250,0.00,-0.0004,-0.00030,2.000
2,31.350,0.00,-0.0004,-0.00030,2.000
2,31.450,-0.01,-0.0004,-0.00030,2.000
2,31.550,0.00,-0.0004,-0.00030,2.000
2,31.650,-0.01,-0.0004,-0.00030,2.000
2,31.750,0.00,-0.0004,-0.00030,2.000
2,31.850,0.00,-0.0004,-0.00030,2.000
2,31.950,0.00,-0.0004,-0.00030,2.000
2,32.050,0.00,-0.0004,-0.00030,2.000
2,32.150,-0.01,-0.0004,-0.00030,2.000
2,32.250,0.00,-0.0004,-0.00030,2.000
2,32.350,0.00,-0.0003,-0.00020,2.000
2,32.450,0.00,-0.0003,-0.00020,2.000
2,32.550,0.00,-0.0003,-0.00020,2.000
2,32.650,-0.01,-0.0003,-0.00020,2.000
2,32.750,0.00,-0.0003,-0.00020,2.000
2,32.850,0.00,-0.0003,-0.00020,2.000
2,32.950,-0.01,-0.0003,-0.00020,2.000
2,33.050,0.00,-0.0003,-0.00020,2.000
2,33.150,-0.01,-0.0003,-0.00020,2.000
2,33.250,0.00,-0.0003,-0.00020,2.000
2,33.350,0.00,-0.0003,-0.00020,2.000
2,33.450,-0.01,-0.0003,-0.00020,2.000
2,33.550,-0.01,-0.0003,-0.00020,2.000
2,33.650,-0.01,-0.0003,-0.00020,2.000
2,33.750,0.00,-0.0003,-0.00020,2.000
2,33.850,0.00,-0.0003,-0.00020,2.000
2,33.950,-0.01,-0.0003,-0.00020,2.000
2,34.050,0.00,-0.0003,-0.00020,2.000
2,34.200,0.00,-0.0002,-0.00010,2.000
2,34.300,-0.01,-0.0002,-0.00010,2.000
2,34.400,-0.01,-0.0002,-0.00010,2.000
2,34.500,0.00,-0.0002,-0.00010,2.000
2,34.600,-0.01,-0.0002,-0.00010,2.000
2,34.700,-0.01,-0.0002,-0.00010,2.000
2,34.800,0.00,-0.0002,-0.00010,2.000
2,34.900,0.00,-0.0002,-0.00010,2.000
2,35.000,-0.01,-0.0002,-0.00010,2.000
2,35.100,-0.01,-0.0002,-0.00010,2.000
3,35.400,0.00,0.0775,0.07760,3.000
3,35.500,0.00,0.1776,0.17770,3.000
3,35.600,-0.01,0.2776,0.27770,3.000
3,35.700,0.00,0.3778,0.37790,3.000
3,35.800,-0.01,0.4775,0.47760,3.000
3,35.900,-0.01,0.5777,0.57780,3.000
3,36.000,0.00,0.6776,0.67770,3.000
3,36.100,-0.01,0.7777,0.77780,3.000
3,36.200,-0.01,0.8775,0.87760,3.000
3,36.300,0.00,0.9778,0.97790,3.000
3,36.400,-0.01,1.0777,1.07780,3.000
3,36.500,-0.01,1.1778,1.17790,3.000
3,36.600,0.00,1.2777,1.27780,3.000
3,36.700,0.00,1.3777,1.37780,3.000
3,36.800,0.00,1.4775,1.47760,3.000
3,36.900,0.00,1.5778,1.57790,3.000
3,37.000,-0.01,1.6775,1.67760,3.000
3,37.100,-0.01,1.7777,1.77780,3.000
3,37.200,0.00,1.8776,1.87770,3.000
3,37.300,-0.01,1.9779,1.97800,3.000
3,37.400,0.00,2.0777,2.07780,3.000
3,37.500,0.00,2.1778,2.17790,3.000
3,37.600,-0.01,2.2777,2.27780,3.000
3,37.700,0.00,2.3778,2.37790,3.000
3,37.800,-0.01,2.4777,2.47780,3.000
3,37.900,-0.01,2.5779,2.57800,3.000
3,38.000,-0.01,2.6779,2.67800,3.000
3,38.100,0.00,2.7778,2.77790,3.000
3,38.200,0.00,2.8777,2.87780,3.000
3,38.300,-0.01,2.9778,2.97790,3.000
3,38.400,-0.01,3.0777,3.07780,3.000
3,38.500,-0.01,3.1778,3.17790,3.000
3,38.600,0.00,3.2779,3.27800,3.000
3,38.700,-0.01,3.3778,3.37790,3.000
3,38.800,0.00,3.4779,3.47800,3.000
3,38.900,-0.01,3.5778,3.57790,3.000
3,39.000,-0.01,3.6778,3.67790,3.000
3,39.100,-0.01,3.7778,3.77790,3.000
3,39.200,-0.01,3.8779,3.87800,3.000
3,39.300,0.00,3.9779,3.97800,3.000
3,39.400,-0.01,4.0778,4.07790,3.000
3,39.500,0.00,4.1779,4.17800,3.000
3,39.600,-0.01,4.2779,4.27800,3.000
3,39.700,0.00,4.3778,4.37790,3.000
3,39.800,0.00,4.4780,4.47810,3.000
3,39.900,0.00,4.5779,4.57800,3.000
3,40.000,0.04,4.6779,4.67800,3.000
3,40.100,0.17,4.7778,4.77790,3.000
3,40.200,0.37,4.8778,4.87790,3.000
3,40.300,0.57,4.9779,4.97800,3.000
3,40.400,0.98,5.0779,5.07800,3.000
3,40.500,1.50,5.1779,5.17800,3.000
3,40.600,2.13,5.2779,5.27800,3.000
3,40.700,2.90,5.3779,5.37800,3.000
3,40.800,3.71,5.4780,5.47810,3.000
3,40.900,4.69,5.5780,5.57810,3.000
3,41.000,5.81,5.6778,5.67790,3.000
3,41.100,7.21,5.7779,5.77800,3.000
3,41.200,8.86,5.8779,5.87800,3.000
3,41.300,10.68,5.9779,5.97800,3.000
3,41.400,12.73,6.0781,6.07820,3.000
3,41.500,15.03,6.1778,6.17790,3.000
3,41.600,17.65,6.2779,6.27800,3.000
3,41.700,20.66,6.3780,6.37810,3.000
3,41.800,24.28,6.4780,6.47810,3.000
3,41.900,28.69,6.5777,6.57780,3.000
3,42.050,27.98,6.5905,6.59060,3.000
3,42.150,20.52,6.4905,6.49060,3.000
3,42.250,15.50,6.3907,6.39080,3.000
3,42.350,11.86,6.2905,6.29060,3.000
3,42.450,9.15,6.1907,6.19080,3.000
3,42.550,7.20,6.0906,6.09070,3.000
3,42.650,5.69,5.9907,5.99080,3.000
3,42.750,4.46,5.8904,5.89050,3.000
3,42.850,3.61,5.7906,5.79070,3.000
3,42.950,2.88,5.6904,5.69050,3.000
3,43.050,2.17,5.5906,5.59070,3.000
3,43.150,1.63,5.4904,5.49050,3.000
3,43.250,1.19,5.3906,5.39070,3.000
3,43.350,0.87,5.2906,5.29070,3.000
3,43.450,0.59,5.1906,5.19070,3.000
3,43.550,0.35,5.0903,5.09040,3.000
3,43.650,0.18,4.9905,4.99060,3.000
3,43.750,0.09,4.8904,4.89050,3.000
3,43.850,0.02,4.7905,4.79060,3.000
3,43.950,-0.01,4.6903,4.69040,3.000
3,44.050,-0.01,4.5906,4.59070,3.000
3,44.150,-0.01,4.4905,4.49060,3.000
3,44.250,-0.01,4.3904,4.39050,3.000
3,44.350,-0.01,4.2904,4.29050,3.000
3,44.450,-0.01,4.1905,4.19060,3.000
3,44.550,-0.01,4.0904,4.09050,3.000
3,44.650,-0.01,3.9905,3.99060,3.000
3,44.750,0.00,3.8903,3.89040,3.000
3,44.850,0.00,3.7904,3.79050,3.000
3,44.950,-0.01,3.6903,3.69040,3.000
3,45.050,-0.01,3.5903,3.59040,3.000
3,45.150,0.00,3.4903,3.49040,3.000
3,45.250,-0.01,3.3905,3.39060,3.000
3,45.350,-0.01,3.2903,3.29040,3.000
3,45.450,-0.01,3.1903,3.19040,3.000
3,45.550,-0.01,3.0902,3.09030,3.000
3,45.650,0.00,2.9903,2.99040,3.000
3,45.750,-0.01,2.8902,2.89030,3.000
3,45.850,0.00,2.7904,2.79050,3.000
3,45.950,-0.01,2.6904,2.69050,3.000
3,46.050,-0.01,2.5904,2.59050,3.000
3,46.150,-0.01,2.4903,2.49040,3.000
3,46.250,0.00,2.3904,2.39050,3.000
3,46.350,0.00,2.2902,2.29030,3.000
3,46.450,-0.01,2.1904,2.19050,3.000
3,46.550,-0.01,2.0904,2.09050,3.000
3,46.650,-0.01,1.9904,1.99050,3.000
3,46.750,-0.01,1.8902,1.89030,3.000
3,46.850,0.00,1.7902,1.79030,3.000
3,46.950,-0.01,1.6903,1.69040,3.000
3,47.050,-0.01,1.5902,1.59030,3.000
3,47.150,0.00,1.4902,1.49030,3.000
3,47.250,0.00,1.3903,1.39040,3.000
3,47.350,-0.01,1.2904,1.29050,3.000
3,47.450,0.00,1.1903,1.19040,3.000
3,47.550,-0.01,1.0902,1.09030,3.000
3,47.650,-0.01,0.9903,0.99040,3.000
3,47.750,0.00,0.8903,0.89040,3.000
3,47.850,0.00,0.7902,0.79030,3.000
3,47.950,-0.01,0.6904,0.69050,3.000
3,48.050,-0.01,0.5902,0.59030,3.000
3,48.150,-0.01,0.4903,0.49040,3.000
3,48.250,0.00,0.3902,0.39030,3.000
3,48.350,-0.01,0.2903,0.29040,3.000
3,48.450,-0.01,0.1902,0.19030,3.000
3,48.550,0.00,0.0902,0.09030,3.000
3,48.650,-0.01,-0.0099,-0.00980,3.000
3,48.800,0.00,-0.0002,-0.00010,3.000
3,48.900,-0.01,-0.0004,-0.00030,3.000
3,49.000,0.00,-0.0004,-0.00030,3.000
3,49.100,-0.01,-0.0004,-0.00030,3.000
3,49.200,-0.01,-0.0004,-0.00030,3.000
3,49.300,-0.01,-0.0004,-0.00030,3.000
3,49.400,0.00,-0.0004,-0.00030,3.000
3,49.500,-0.01,-0.0004,-0.00030,3.000
3,49.600,0.00,-0.0004,-0.00030,3.000
3,49.700,0.00,-0.0004,-0.00030,3.000
3,49.800,-0.01,-0.0004,-0.00030,3.000
3,49.900,0.00,-0.0004,-0.00030,3.000
3,50.000,0.00,-0.0004,-0.00030,3.000
3,50.100,0.00,-0.0004,-0.00030,3.000
3,50.200,0.00,-0.0004,-0.00030,3.000
3,50.300,0.00,-0.0004,-0.00030,3.000
3,50.400,0.00,-0.0003,-0.00020,3.000
3,50.500,-0.01,-0.0003,-0.00020,3.000
3,50.600,0.00,-0.0003,-0.00020,3.000
3,50.700,0.00,-0.0003,-0.00020,3.000
3,50.800,0.00,-0.0003,-0.00020,3.000
3,50.900,-0.01,-0.0003,-0.00020,3.000
3,51.000,-0.01,-0.0003,-0.00020,3.000
3,51.100,0.00,-0.0003,-0.00020,3.000
3,51.200,-0.01,-0.0003,-0.00020,3.000
3,51.300,0.00,-0.0003,-0.00020,3.000
3,51.400,0.00,-0.0003,-0.00020,3.000
3,51.500,-0.01,-0.0003,-0.00020,3.000
3,51.600,0.00,-0.0003,-0.00020,3.000
3,51.700,0.00,-0.0003,-0.00020,3.000
3,51.850,0.00,-0.0003,-0.00020,3.000
3,51.950,0.00,-0.0003,-0.00020,3.000
3,52.050,-0.01,-0.0003,-0.00020,3.000
3,52.150,0.00,-0.0002,-0.00010,3.000
3,52.250,-0.01,-0.0002,-0.00010,3.000
3,52.350,-0.01,-0.0002,-0.00010,3.000
3,52.450,0.00,-0.0002,-0.00010,3.000
3,52.550,-0.01,-0.0002,-0.00010,3.000
3,52.650,-0.01,-0.0002,-0.00010,3.000
3,52.750,0.00,-0.0002,-0.00010,3.000
4,53.000,0.00,0.0676,0.06770,4.000
4,53.100,0.00,0.1676,0.16770,4.000
4,53.200,0.00,0.2678,0.26790,4.000
4,53.300,0.00,0.3678,0.36790,4.000
4,53.400,0.00,0.4678,0.46790,4.000
4,53.500,0.00,0.5677,0.56780,4.000
4,53.600,0.00,0.6679,0.66800,4.000
4,53.700,0.00,0.7677,0.76780,4.000
4,53.800,0.00,0.8676,0.86770,4.000
4,53.900,0.00,0.9677,0.96780,4.000
4,54.000,0.00,1.0678,1.06790,4.000
4,54.100,0.00,1.1676,1.16770,4.000
4,54.200,0.00,1.2678,1.26790,4.000
4,54.300,0.00,1.3677,1.36780,4.000
4,54.400,0.00,1.4678,1.46790,4.000
4,54.500,0.00,1.5677,1.56780,4.000
4,54.600,0.00,1.6677,1.66780,4.000
4,54.700,0.00,1.7677,1.76780,4.000
4,54.800,0.00,1.8677,1.86780,4.000
4,54.900,0.00,1.9677,1.96780,4.000
4,55.000,0.00,2.0680,2.06810,4.000
4,55.100,0.00,2.1678,2.16790,4.000
4,55.200,0.00,2.2679,2.26800,4.000
4,55.300,0.00,2.3677,2.36780,4.000
4,55.400,0.00,2.4679,2.46800,4.000
4,55.500,0.01,2.5677,2.56780,4.000
4,55.600,0.00,2.6679,2.66800,4.000
4,55.700,0.00,2.7678,2.76790,4.000
4,55.800,0.00,2.8678,2.86790,4.000
4,55.900,0.00,2.9677,2.96780,4.000
4,56.000,0.00,3.0678,3.06790,4.000
4,56.100,0.00,3.1677,3.16780,4.000
4,56.200,0.00,3.2679,3.26800,4.000
4,56.300,0.00,3.3678,3.36790,4.000
4,56.400,0.00,3.4680,3.46810,4.000
4,56.500,0.00,3.5678,3.56790,4.000
4,56.600,0.00,3.6678,3.66790,4.000
4,56.700,0.00,3.7677,3.76780,4.000
4,56.800,0.00,3.8679,3.86800,4.000
4,56.900,0.00,3.9678,3.96790,4.000
4,57.000,0.00,4.0679,4.06800,4.000
4,57.100,0.00,4.1678,4.16790,4.000
4,57.200,0.00,4.2680,4.26810,4.000
4,57.300,0.00,4.3677,4.36780,4.000
4,57.400,0.00,4.4680,4.46810,4.000
4,57.500,0.00,4.5678,4.56790,4.000
4,57.600,0.02,4.6680,4.66810,4.000
4,57.700,0.13,4.7677,4.76780,4.000
4,57.800,0.31,4.8680,4.86810,4.000
4,57.900,0.54,4.9678,4.96790,4.000
4,58.000,0.87,5.0678,5.06790,4.000
4,58.100,1.35,5.1676,5.16770,4.000
4,58.200,1.96,5.2680,5.26810,4.000
4,58.300,2.63,5.3678,5.36790,4.000
4,58.400,3.46,5.4680,5.46810,4.000
4,58.500,4.40,5.5678,5.56790,4.000
4,58.600,5.52,5.6679,5.66800,4.000
4,58.700,6.91,5.7678,5.76790,4.000
4,58.800,8.52,5.8679,5.86800,4.000
4,58.900,10.32,5.9677,5.96780,4.000
4,59.000,12.33,6.0679,6.06800,4.000
4,59.100,14.60,6.1678,6.16790,4.000
4,59.200,17.18,6.2679,6.26800,4.000
4,59.300,20.12,6.3680,6.36810,4.000
4,59.400,23.64,6.4679,6.46800,4.000
4,59.500,27.99,6.5678,6.56790,4.000
4,59.650,28.89,6.6006,6.60070,4.000
4,59.750,20.87,6.5006,6.50070,4.000
4,59.850,15.70,6.4008,6.40090,4.000
4,59.950,11.97,6.3006,6.30070,4.000
4,60.050,9.21,6.2006,6.20070,4.000
4,60.150,7.22,6.1007,6.10080,4.000
4,60.250,5.67,6.0007,6.00080,4.000
4,60.350,4.48,5.9006,5.90070,4.000
4,60.450,3.59,5.8007,5.80080,4.000
4,60.550,2.84,5.7006,5.70070,4.000
4,60.650,2.15,5.6007,5.60080,4.000
4,60.750,1.60,5.5006,5.50070,4.000
4,60.850,1.19,5.4007,5.40080,4.000
4,60.950,0.84,5.3007,5.30080,4.000
4,61.050,0.57,5.2006,5.20070,4.000
4,61.150,0.34,5.1005,5.10060,4.000
4,61.250,0.19,5.0005,5.00060,4.000
4,61.350,0.08,4.9006,4.90070,4.000
4,61.450,0.02,4.8004,4.80050,4.000
4,61.550,0.00,4.7005,4.70060,4.000
4,61.650,0.00,4.6006,4.60070,4.000
4,61.750,0.00,4.5006,4.50070,4.000
4,61.850,0.00,4.4005,4.40060,4.000
4,61.950,0.00,4.3005,4.30060,4.000
4,62.050,0.00,4.2005,4.20060,4.000
4,62.150,0.00,4.1005,4.10060,4.000
4,62.250,0.00,4.0005,4.00060,4.000
4,62.350,0.00,3.9005,3.90060,4.000
4,62.450,0.00,3.8004,3.80050,4.000
4,62.550,0.01,3.7004,3.70050,4.000
4,62.650,0.00,3.6004,3.60050,4.000
4,62.750,0.00,3.5005,3.50060,4.000
4,62.850,0.00,3.4004,3.40050,4.000
4,62.950,0.00,3.3005,3.30060,4.000
4,63.050,0.00,3.2003,3.20040,4.000
4,63.150,0.00,3.1003,3.10040,4.000
4,63.250,0.00,3.0003,3.00040,4.000
4,63.350,0.00,2.9004,2.90050,4.000
4,63.450,0.00,2.8002,2.80030,4.000
4,63.550,0.00,2.7005,2.70060,4.000
4,63.650,0.00,2.6004,2.60050,4.000
4,63.750,0.00,2.5004,2.50050,4.000
4,63.850,0.00,2.4002,2.40030,4.000
4,63.950,0.00,2.3003,2.30040,4.000
4,64.050,0.00,2.2003,2.20040,4.000
4,64.150,0.00,2.1005,2.10060,4.000
4,64.250,0.00,2.0003,2.00040,4.000
4,64.350,0.00,1.9003,1.90040,4.000
4,64.450,0.00,1.8002,1.80030,4.000
4,64.550,0.00,1.7004,1.70050,4.000
4,64.650,0.00,1.6002,1.60030,4.000
4,64.750,0.00,1.5003,1.50040,4.000
4,64.850,0.00,1.4001,1.40020,4.000
4,64.950,0.00,1.3004,1.30050,4.000
4,65.050,0.00,1.2002,1.20030,4.000
4,65.150,0.00,1.1003,1.10040,4.000
4,65.250,0.00,1.0000,1.00010,4.000
4,65.350,0.00,0.9003,0.90040,4.000
4,65.450,0.00,0.8001,0.80020,4.000
4,65.550,0.00,0.7004,0.70050,4.000
4,65.650,0.00,0.6001,0.60020,4.000
4,65.750,0.00,0.5002,0.50030,4.000
4,65.850,0.00,0.4001,0.40020,4.000
4,65.950,0.00,0.3002,0.30030,4.000
4,66.050,0.00,0.2000,0.20010,4.000
4,66.150,0.00,0.1003,0.10040,4.000
4,66.250,0.00,0.0001,0.00020,4.000
4,66.400,0.00,-0.0003,-0.00020,4.000
4,66.500,0.00,-0.0004,-0.00030,4.000
4,66.600,-0.01,-0.0004,-0.00030,4.000
4,66.700,0.00,-0.0004,-0.00030,4.000
4,66.800,0.00,-0.0004,-0.00030,4.000
4,66.900,0.00,-0.0004,-0.00030,4.000
4,67.000,0.00,-0.0004,-0.00030,4.000
4,67.100,0.00,-0.0004,-0.00030,4.000
4,67.200,0.00,-0.0004,-0.00030,4.000
4,67.300,0.00,-0.0004,-0.00030,4.000
4,67.400,0.00,-0.0004,-0.00030,4.000
4,67.500,0.00,-0.0004,-0.00030,4.000
4,67.600,0.00,-0.0004,-0.00030,4.000
4,67.700,0.00,-0.0004,-0.00030,4.000
4,67.800,0.00,-0.0003,-0.00020,4.000
4,67.900,0.00,-0.0003,-0.00020,4.000
4,68.000,0.00,-0.0003,-0.00020,4.000
4,68.100,0.00,-0.0003,-0.00020,4.000
4,68.200,0.00,-0.0003,-0.00020,4.000
4,68.300,0.00,-0.0003,-0.00020,4.000
4,68.400,0.00,-0.0003,-0.00020,4.000
4,68.500,0.00,-0.0003,-0.00020,4.000
4,68.600,0.00,-0.0003,-0.00020,4.000
4,68.700,0.00,-0.0003,-0.00020,4.000
4,68.800,-0.01,-0.0003,-0.00020,4.000
4,68.900,0.00,-0.0003,-0.00020,4.000
4,69.000,0.00,-0.0003,-0.00020,4.000
4,69.100,0.00,-0.0003,-0.00020,4.000
4,69.200,0.00,-0.0003,-0.00020,4.000
4,69.300,0.00,-0.0003,-0.00020,4.000
4,69.450,0.00,-0.0003,-0.00020,4.000
4,69.550,0.00,-0.0002,-0.00010,4.000
4,69.650,0.00,-0.0002,-0.00010,4.000
4,69.750,0.00,-0.0002,-0.00010,4.000
4,69.850,0.00,-0.0002,-0.00010,4.000
4,69.950,0.00,-0.0002,-0.00010,4.000
4,70.050,0.00,-0.0002,-0.00010,4.000
4,70.150,0.00,-0.0002,-0.00010,4.000
4,70.250,0.00,-0.0002,-0.00010,4.000
5,70.550,0.00,0.0374,0.03750,5.000
5,70.650,0.00,0.1375,0.13760,5.000
5,70.750,0.00,0.2376,0.23770,5.000
5,70.850,0.00,0.3378,0.33790,5.000
5,70.950,0.00,0.4375,0.43760,5.000
5,71.050,0.00,0.5377,0.53780,5.000
5,71.150,0.00,0.6378,0.63790,5.000
5,71.250,0.00,0.7378,0.73790,5.000
5,71.350,0.00,0.8375,0.83760,5.000
5,71.450,0.00,0.9377,0.93780,5.000
5,71.550,0.00,1.0377,1.03780,5.000
5,71.650,0.00,1.1378,1.13790,5.000
5,71.750,0.00,1.2377,1.23780,5.000
5,71.850,0.00,1.3377,1.33780,5.000
5,71.950,0.00,1.4376,1.43770,5.000
5,72.050,0.00,1.5377,1.53780,5.000
5,72.150,0.00,1.6376,1.63770,5.000
5,72.250,0.00,1.7378,1.73790,5.000
5,72.350,0.00,1.8377,1.83780,5.000
5,72.450,0.00,1.9378,1.93790,5.000
5,72.550,0.00,2.0377,2.03780,5.000
5,72.650,0.00,2.1378,2.13790,5.000
5,72.750,0.00,2.2377,2.23780,5.000
5,72.850,0.00,2.3377,2.33780,5.000
5,72.950,0.00,2.4378,2.43790,5.000
5,73.050,0.00,2.5379,2.53800,5.000
5,73.150,0.00,2.6379,2.63800,5.000
5,73.250,0.00,2.7379,2.73800,5.000
5,73.350,0.00,2.8379,2.83800,5.000
5,73.450,0.00,2.9378,2.93790,5.000
5,73.550,0.00,3.0379,3.03800,5.000
5,73.650,0.00,3.1378,3.13790,5.000
5,73.750,0.00,3.2379,3.23800,5.000
5,73.850,0.00,3.3379,3.33800,5.000
5,73.950,0.00,3.4379,3.43800,5.000
5,74.050,0.00,3.5379,3.53800,5.000
5,74.150,0.00,3.6379,3.63800,5.000
5,74.250,0.00,3.7377,3.73780,5.000
5,74.350,0.00,3.8379,3.83800,5.000
5,74.450,0.00,3.9379,3.93800,5.000
5,74.550,0.00,4.0380,4.03810,5.000
5,74.650,0.00,4.1379,4.13800,5.000
5,74.750,0.00,4.2380,4.23810,5.000
5,74.850,0.00,4.3378,4.33790,5.000
5,74.950,0.00,4.4379,4.43800,5.000
5,75.050,0.00,4.5379,4.53800,5.000
5,75.150,0.00,4.6379,4.63800,5.000
5,75.250,0.08,4.7379,4.73800,5.000
5,75.350,0.21,4.8379,4.83800,5.000
5,75.450,0.43,4.9378,4.93790,5.000
5,75.550,0.68,5.0378,5.03790,5.000
5,75.650,1.12,5.1378,5.13790,5.000
5,75.750,1.65,5.2380,5.23810,5.000
5,75.850,2.31,5.3379,5.33800,5.000
5,75.950,3.13,5.4380,5.43810,5.000
5,76.050,4.04,5.5379,5.53800,5.000
5,76.150,5.02,5.6379,5.63800,5.000
5,76.250,6.35,5.7378,5.73790,5.000
5,76.350,7.90,5.8379,5.83800,5.000
5,76.450,9.62,5.9378,5.93790,5.000
5,76.550,11.57,6.0380,6.03810,5.000
5,76.650,13.75,6.1378,6.13790,5.000
5,76.750,16.23,6.2380,6.23810,5.000
5,76.850,19.07,6.3378,6.33790,5.000
5,76.950,22.39,6.4381,6.43820,5.000
5,77.050,26.47,6.5377,6.53780,5.000
5,77.200,32.63,6.6464,6.64650,5.000
5,77.300,23.91,6.5527,6.55280,5.000
5,77.400,17.73,6.4527,6.45280,5.000
5,77.500,13.41,6.3528,6.35290,5.000
5,77.600,10.27,6.2525,6.25260,5.000
5,77.700,7.95,6.1527,6.15280,5.000
5,77.800,6.23,6.0526,6.05270,5.000
5,77.900,4.87,5.9527,5.95280,5.000
5,78.000,3.92,5.8524,5.85250,5.000
5,78.100,3.16,5.7526,5.75270,5.000
5,78.200,2.39,5.6524,5.65250,5.000
5,78.300,1.79,5.5526,5.55270,5.000
5,78.400,1.32,5.4525,5.45260,5.000
5,78.500,0.97,5.3528,5.35290,5.000
5,78.600,0.66,5.2526,5.25270,5.000
5,78.700,0.41,5.1525,5.15260,5.000
5,78.800,0.21,5.0524,5.05250,5.000
5,78.900,0.11,4.9525,4.95260,5.000
5,79.000,0.03,4.8524,4.85250,5.000
5,79.100,0.00,4.7524,4.75250,5.000
5,79.200,0.00,4.6524,4.65250,5.000
5,79.300,0.00,4.5525,4.55260,5.000
5,79.400,0.00,4.4523,4.45240,5.000
5,79.500,0.00,4.3524,4.35250,5.000
5,79.600,0.00,4.2524,4.25250,5.000
5,79.700,0.00,4.1526,4.15270,5.000
5,79.800,0.00,4.0524,4.05250,5.000
5,79.900,0.00,3.9526,3.95270,5.000
5,80.000,0.00,3.8522,3.85230,5.000
5,80.100,0.00,3.7525,3.75260,5.000
5,80.200,0.00,3.6522,3.65230,5.000
5,80.300,0.00,3.5524,3.55250,5.000
5,80.400,0.00,3.4522,3.45230,5.000
5,80.500,0.00,3.3524,3.35250,5.000
5,80.600,0.00,3.2523,3.25240,5.000
5,80.700,0.00,3.1523,3.15240,5.000
5,80.800,0.00,3.0522,3.05230,5.000
5,80.900,0.00,2.9524,2.95250,5.000
5,81.000,0.00,2.8522,2.85230,5.000
5,81.100,0.00,2.7524,2.75250,5.000
5,81.200,0.00,2.6524,2.65250,5.000
5,81.300,0.00,2.5524,2.55250,5.000
5,81.400,0.00,2.4523,2.45240,5.000
5,81.500,0.00,2.3524,2.35250,5.000
5,81.600,0.01,2.2522,2.25230,5.000
5,81.700,0.00,2.1524,2.15250,5.000
5,81.800,0.00,2.0525,2.05260,5.000
5,81.900,0.00,1.9524,1.95250,5.000
5,82.000,0.00,1.8523,1.85240,5.000
5,82.100,0.00,1.7524,1.75250,5.000
5,82.200,0.00,1.6523,1.65240,5.000
5,82.300,0.00,1.5524,1.55250,5.000
5,82.400,0.00,1.4523,1.45240,5.000
5,82.500,0.00,1.3523,1.35240,5.000
5,82.600,0.00,1.2522,1.25230,5.000
5,82.700,0.00,1.1523,1.15240,5.000
5,82.800,0.00,1.0522,1.05230,5.000
5,82.900,0.00,0.9522,0.95230,5.000
5,83.000,0.00,0.8522,0.85230,5.000
5,83.100,0.00,0.7523,0.75240,5.000
5,83.200,0.00,0.6524,0.65250,5.000
5,83.300,0.00,0.5521,0.55220,5.000
5,83.400,0.00,0.4522,0.45230,5.000
5,83.500,0.00,0.3522,0.35230,5.000
5,83.600,0.00,0.2522,0.25230,5.000
5,83.700,0.01,0.1521,0.15220,5.000
5,83.800,0.00,0.0522,0.05230,5.000
5,83.950,0.00,-0.0226,-0.02250,5.000
5,84.050,0.00,-0.0004,-0.00030,5.000
5,84.150,0.00,-0.0004,-0.00030,5.000
5,84.250,0.00,-0.0004,-0.00030,5.000
5,84.350,0.00,-0.0004,-0.00030,5.000
5,84.450,0.00,-0.0004,-0.00030,5.000
5,84.550,0.00,-0.0004,-0.00030,5.000
5,84.650,0.00,-0.0004,-0.00030,5.000
5,84.750,0.00,-0.0004,-0.00030,5.000
5,84.850,0.00,-0.0004,-0.00030,5.000
5,84.950,0.00,-0.0004,-0.00030,5.000
5,85.050,0.00,-0.0004,-0.00030,5.000
5,85.150,0.01,-0.0004,-0.00030,5.000
5,85.250,0.00,-0.0004,-0.00030,5.000
5,85.350,0.00,-0.0004,-0.00030,5.000
5,85.450,0.00,-0.0004,-0.00030,5.000
5,85.550,0.00,-0.0003,-0.00020,5.000
5,85.650,0.00,-0.0003,-0.00020,5.000
5,85.750,0.00,-0.0003,-0.00020,5.000
5,85.850,0.00,-0.0003,-0.00020,5.000
5,85.950,0.00,-0.0003,-0.00020,5.000
5,86.050,0.00,-0.0003,-0.00020,5.000
5,86.150,0.00,-0.0003,-0.00020,5.000
5,86.250,0.00,-0.0003,-0.00020,5.000
5,86.350,0.00,-0.0003,-0.00020,5.000
5,86.450,0.00,-0.0003,-0.00020,5.000
5,86.550,0.01,-0.0003,-0.00020,5.000
5,86.650,0.00,-0.0003,-0.00020,5.000
5,86.750,0.00,-0.0003,-0.00020,5.000
5,86.850,0.00,-0.0003,-0.00020,5.000
5,87.000,0.00,-0.0003,-0.00020,5.000
5,87.100,0.00,-0.0003,-0.00020,5.000
5,87.200,0.00,-0.0003,-0.00020,5.000
5,87.300,0.00,-0.0002,-0.00010,5.000
5,87.400,0.00,-0.0002,-0.00010,5.000
5,87.500,0.00,-0.0002,-0.00010,5.000
5,87.600,0.00,-0.0002,-0.00010,5.000
5,87.700,0.00,-0.0002,-0.00010,5.000
5,87.800,0.00,-0.0002,-0.00010,5.000
5,87.900,0.00,-0.0002,-0.00010,5.000