File: calibDATA_loadcell/data/date_08:02:2018/MTS/0deg_30N_1.txt
""
"Test Method","Radhen_Load_Cntrl_Cmprsn_250N_12-7.msm"
"Sample I. D.","Sample1.mss"
"Specimen Number","1"

"TheCycle_Output ()","_Time (s)","_Load (N)","_Extension (mm)","RealTimeDepth (mm)","CycleNumber ()"

1,0.250,0.01,0.0255,0.02550,1.000
1,0.350,0.00,0.1256,0.12560,1.000
1,0.450,0.01,0.2255,0.22550,1.000
1,0.550,0.01,0.3257,0.32570,1.000
1,0.650,0.00,0.4257,0.42570,1.000
1,0.750,0.01,0.5258,0.52580,1.000
1,0.850,0.01,0.6257,0.62570,1.000
1,0.950,0.00,0.7258,0.72580,1.000
1,1.050,0.01,0.8256,0.82560,1.000
1,1.150,0.01,0.9257,0.92570,1.000
1,1.250,0.01,1.0257,1.02570,1.000
1,1.350,0.01,1.1258,1.12580,1.000
1,1.450,0.00,1.2255,1.22550,1.000
1,1.550,0.00,1.3258,1.32580,1.000
1,1.650,0.01,1.4256,1.42560,1.000
1,1.750,0.01,1.5257,1.52570,1.000
1,1.850,0.01,1.6256,1.62560,1.000
1,1.950,0.01,1.7259,1.72590,1.000
1,2.050,0.00,1.8257,1.82570,1.000
1,2.150,0.01,1.9259,1.92590,1.000
1,2.250,0.01,2.0258,2.02580,1.000
1,2.350,0.00,2.1258,2.12580,1.000
1,2.450,0.01,2.2256,2.22560,1.000
1,2.550,0.01,2.3258,2.32580,1.000
1,2.650,0.01,2.4257,2.42570,1.000
1,2.750,0.00,2.5258,2.52580,1.000
1,2.850,0.00,2.6258,2.62580,1.000
1,2.950,0.00,2.7258,2.72580,1.000
1,3.050,0.00,2.8257,2.82570,1.000
1,3.150,0.00,2.9259,2.92590,1.000
1,3.250,0.00,3.0256,3.02560,1.000
1,3.350,0.00,3.1258,3.12580,1.000
1,3.450,0.00,3.2256,3.22560,1.000
1,3.550,0.01,3.3259,3.32590,1.000
1,3.650,0.00,3.4257,3.42570,1.000
1,3.750,0.00,3.5260,3.52600,1.000
1,3.850,0.01,3.6257,3.62570,1.000
1,3.950,0.01,3.7258,3.72580,1.000
1,4.050,0.00,3.8257,3.82570,1.000
1,4.150,0.01,3.9259,3.92590,1.000
1,4.250,0.01,4.0257,4.02570,1.000
1,4.350,0.00,4.1259,4.12590,1.000
1,4.450,0.01,4.2257,4.22570,1.000
1,4.550,0.01,4.3260,4.32600,1.000
1,4.650,0.01,4.4259,4.42590,1.000
1,4.750,0.01,4.5258,4.52580,1.000
1,4.850,0.01,4.6257,4.62570,1.000
1,4.950,0.03,4.7258,4.72580,1.000
1,5.050,0.07,4.8258,4.82580,1.000
1,5.150,0.16,4.9260,4.92600,1.000
1,5.250,0.30,5.0258,5.02580,1.000
1,5.350,0.51,5.1259,5.12590,1.000
1,5.450,0.77,5.2258,5.22580,1.000
1,5.550,1.10,5.3259,5.32590,1.000
1,5.650,1.53,5.4257,5.42570,1.000
1,5.750,2.05,5.5260,5.52600,1.000
1,5.850,2.65,5.6261,5.62610,1.000
1,5.950,3.33,5.7259,5.72590,1.000
1,6.050,4.10,5.8257,5.82570,1.000
1,6.150,4.98,5.9258,5.92580,1.000
1,6.250,5.97,6.0257,6.02570,1.000
1,6.350,7.09,6.1258,6.12580,1.000
1,6.450,8.34,6.2258,6.22580,1.000
1,6.550,9.71,6.3259,6.32590,1.000
1,6.650,11.24,6.4259,6.42590,1.000
1,6.750,12.94,6.5259,6.52590,1.000
1,6.850,14.86,6.6257,6.62570,1.000
1,6.950,16.96,6.7260,6.72600,1.000
1,7.050,19.32,6.8259,6.82590,1.000
1,7.150,21.91,6.9258,6.92580,1.000
1,7.250,24.82,7.0259,7.02590,1.000
1,7.350,28.02,7.1258,7.12580,1.000
1,7.500,31.64,7.2206,7.22060,1.000
1,7.600,26.19,7.1227,7.12270,1.000
1,7.700,21.87,7.0227,7.02270,1.000
1,7.800,18.41,6.9228,6.92280,1.000
1,7.900,15.53,6.8227,6.82270,1.000
1,8.000,13.13,6.7228,6.72280,1.000
1,8.100,11.08,6.6226,6.62260,1.000
1,8.200,9.35,6.5228,6.52280,1.000
1,8.300,7.87,6.4227,6.42270,1.000
1,8.400,6.62,6.3227,6.32270,1.000
1,8.500,5.54,6.2228,6.22280,1.000
1,8.600,4.61,6.1227,6.12270,1.000
1,8.700,3.80,6.0225,6.02250,1.000
1,8.800,3.10,5.9226,5.92260,1.000
1,8.900,2.49,5.8225,5.82250,1.000
1,9.000,1.96,5.7226,5.72260,1.000
1,9.100,1.51,5.6227,5.62270,1.000
1,9.200,1.12,5.5227,5.52270,1.000
1,9.300,0.79,5.4225,5.42250,1.000
1,9.400,0.55,5.3225,5.32250,1.000
1,9.500,0.35,5.2224,5.22240,1.000
1,9.600,0.20,5.1226,5.12260,1.000
1,9.700,0.10,5.0225,5.02250,1.000
1,9.800,0.04,4.9226,4.92260,1.000
1,9.900,0.01,4.8224,4.82240,1.000
1,10.000,0.00,4.7225,4.72250,1.000
1,10.100,0.01,4.6225,4.62250,1.000
1,10.200,0.01,4.5224,4.52240,1.000
1,10.300,0.00,4.4225,4.42250,1.000
1,10.400,0.01,4.3226,4.32260,1.000
1,10.500,0.01,4.2225,4.22250,1.000
1,10.600,0.01,4.1226,4.12260,1.000
1,10.700,0.01,4.0224,4.02240,1.000
1,10.800,0.00,3.9225,3.92250,1.000
1,10.900,0.00,3.8224,3.82240,1.000
1,11.000,0.01,3.7225,3.72250,1.000
1,11.100,0.01,3.6224,3.62240,1.000
1,11.200,0.01,3.5225,3.52250,1.000
1,11.300,0.01,3.4223,3.42230,1.000
1,11.400,0.01,3.3225,3.32250,1.000
1,11.500,0.00,3.2223,3.22230,1.000
1,11.600,0.01,3.1223,3.12230,1.000
1,11.700,0.00,3.0222,3.02220,1.000
1,11.800,0.01,2.9226,2.92260,1.000
1,11.900,0.01,2.8223,2.82230,1.000
1,12.000,0.01,2.7224,2.72240,1.000
1,12.100,0.01,2.6224,2.62240,1.000
1,12.200,0.01,2.5223,2.52230,1.000
1,12.300,0.00,2.4222,2.42220,1.000
1,12.400,0.00,2.3224,2.32240,1.000
1,12.500,0.01,2.2221,2.22210,1.000
1,12.600,0.01,2.1223,2.12230,1.000
1,12.700,0.01,2.0221,2.02210,1.000
1,12.800,0.01,1.9224,1.92240,1.000
1,12.900,0.01,1.8222,1.82220,1.000
1,13.000,0.01,1.7223,1.72230,1.000
1,13.100,0.00,1.6222,1.62220,1.000
1,13.200,0.01,1.5222,1.52220,1.000
1,13.300,0.00,1.4221,1.42210,1.000
1,13.400,0.01,1.3222,1.32220,1.000
1,13.500,0.00,1.2220,1.22200,1.000
1,13.600,0.01,1.1223,1.12230,1.000
1,13.700,0.01,1.0221,1.02210,1.000
1,13.800,0.01,0.9222,0.92220,1.000
1,13.900,0.01,0.8222,0.82220,1.000
1,14.000,0.01,0.7223,0.72230,1.000
1,14.100,0.01,0.6221,0.62210,1.000
1,14.200,0.01,0.5223,0.52230,1.000
1,14.300,0.01,0.4221,0.42210,1.000
1,14.400,0.01,0.3223,0.32230,1.000
1,14.500,0.01,0.2220,0.22200,1.000
1,14.600,0.01,0.1221,0.12210,1.000
1,14.700,0.01,0.0219,0.02190,1.000
1,14.850,0.00,-0.0023,-0.00230,1.000
1,14.950,0.01,-0.0003,-0.00030,1.000
1,15.050,0.01,-0.0002,-0.00020,1.000
1,15.150,0.01,-0.0002,-0.00020,1.000
1,15.250,0.00,-0.0002,-0.00020,1.000
1,15.350,0.01,-0.0002,-0.00020,1.000
1,15.450,0.01,-0.0002,-0.00020,1.000
1,15.550,0.01,-0.0002,-0.00020,1.000
1,15.650,0.01,-0.0002,-0.00020,1.000
1,15.750,0.01,-0.0002,-0.00020,1.000
1,15.850,0.00,-0.0002,-0.00020,1.000
1,15.950,0.01,-0.0002,-0.00020,1.000
1,16.050,0.00,-0.0002,-0.00020,1.000
1,16.150,0.01,-0.0002,-0.00020,1.000
1,16.250,0.01,-0.0002,-0.00020,1.000
1,16.350,0.01,-0.0002,-0.00020,1.000
1,16.450,0.00,-0.0002,-0.00020,1.000
1,16.550,0.01,-0.0002,-0.00020,1.000
1,16.650,0.01,-0.0002,-0.00020,1.000
1,16.750,0.01,-0.0002,-0.00020,1.000
1,16.850,0.01,-0.0002,-0.00020,1.000
1,16.950,0.01,-0.0002,-0.00020,1.000
1,17.050,0.01,-0.0002,-0.00020,1.000
1,17.150,0.01,-0.0002,-0.00020,1.000
1,17.250,0.00,-0.0002,-0.00020,1.000
1,17.350,0.00,-0.0002,-0.00020,1.000
1,17.450,0.01,-0.0002,-0.00020,1.000
1,17.550,0.00,-0.0002,-0.00020,1.000
1,17.650,0.01,-0.0002,-0.00020,1.000
1,17.750,0.01,-0.0002,-0.00020,1.000
1,17.900,0.01,-0.0002,-0.00020,1.000
1,18.000,0.01,-0.0002,-0.00020,1.000
1,18.100,0.00,-0.0002,-0.00020,1.000
1,18.200,0.00,-0.0002,-0.00020,1.000
1,18.300,0.01,-0.0002,-0.00020,1.000
1,18.400,0.01,-0.0002,-0.00020,1.000
1,18.500,0.01,-0.0002,-0.00020,1.000
1,18.600,0.01,-0.0002,-0.00020,1.000
1,18.700,0.00,-0.0002,-0.00020,1.000
1,18.800,0.01,-0.0001,-0.00010,1.000
2,19.050,-0.01,0.0754,0.07540,2.000
2,19.150,-0.01,0.1754,0.17540,2.000
2,19.250,0.00,0.2755,0.27550,2.000
2,19.350,0.00,0.3756,0.37560,2.000
2,19.450,-0.01,0.4756,0.47560,2.000
2,19.550,-0.01,0.5755,0.57550,2.000
2,19.650,-0.01,0.6757,0.67570,2.000
2,19.750,-0.01,0.7755,0.77550,2.000
2,19.850,0.00,0.8756,0.87560,2.000
2,19.950,-0.01,0.9755,0.97550,2.000
2,20.050,0.00,1.0758,1.07580,2.000
2,20.150,-0.01,1.1755,1.17550,2.000
2,20.250,0.00,1.2756,1.27560,2.000
2,20.350,0.00,1.3755,1.37550,2.000
2,20.450,-0.01,1.4756,1.47560,2.000
2,20.550,0.00,1.5755,1.57550,2.000
2,20.650,-0.01,1.6756,1.67560,2.000
2,20.750,0.00,1.7756,1.77560,2.000
2,20.850,-0.01,1.8758,1.87580,2.000
2,20.950,0.00,1.9756,1.97560,2.000
2,21.050,0.00,2.0756,2.07560,2.000
2,21.150,0.00,2.1755,2.17550,2.000
2,21.250,-0.01,2.2757,2.27570,2.000
2,21.350,-0.01,2.3756,2.37560,2.000
2,21.450,0.00,2.4757,2.47570,2.000
2,21.550,0.00,2.5758,2.57580,2.000
2,21.650,-0.01,2.6758,2.67580,2.000
2,21.750,-0.01,2.7757,2.77570,2.000
2,21.850,-0.01,2.8759,2.87590,2.000
2,21.950,-0.01,2.9758,2.97580,2.000
2,22.050,-0.01,3.0757,3.07570,2.000
2,22.150,-0.01,3.1757,3.17570,2.000
2,22.250,-0.01,3.2758,3.27580,2.000
2,22.350,-0.01,3.3757,3.37570,2.000
2,22.450,-0.01,3.4758,3.47580,2.000
2,22.550,0.00,3.5758,3.57580,2.000
2,22.650,0.00,3.6757,3.67570,2.000
2,22.750,-0.01,3.7758,3.77580,2.000
2,22.850,-0.01,3.8758,3.87580,2.000
2,22.950,-0.01,3.9759,3.97590,2.000
2,23.050,0.00,4.0758,4.07580,2.000
2,23.150,-0.01,4.1757,4.17570,2.000
2,23.250,-0.01,4.2759,4.27590,2.000
2,23.350,0.00,4.3759,4.37590,2.000
2,23.450,-0.01,4.4758,4.47580,2.000
2,23.550,-0.01,4.5758,4.57580,2.000
2,23.650,0.00,4.6758,4.67580,2.000
2,23.750,0.01,4.7760,4.77600,2.000
2,23.850,0.06,4.8758,4.87580,2.000
2,23.950,0.15,4.9760,4.97600,2.000
2,24.050,0.30,5.0759,5.07590,2.000
2,24.150,0.51,5.1758,5.17580,2.000
2,24.250,0.77,5.2758,5.27580,2.000
2,24.350,1.11,5.3757,5.37570,2.000
2,24.450,1.54,5.4758,5.47580,2.000
2,24.550,2.07,5.5761,5.57610,2.000
2,24.650,2.69,5.6760,5.67600,2.000
2,24.750,3.38,5.7759,5.77590,2.000
2,24.850,4.19,5.8757,5.87570,2.000
2,24.950,5.11,5.9759,5.97590,2.000
2,25.050,6.14,6.0757,6.07570,2.000
2,25.150,7.29,6.1759,6.17590,2.000
2,25.250,8.58,6.2758,6.27580,2.000
2,25.350,9.98,6.3759,6.37590,2.000
2,25.450,11.55,6.4757,6.47570,2.000
2,25.550,13.30,6.5759,6.57590,2.000
2,25.650,15.25,6.6758,6.67580,2.000
2,25.750,17.43,6.7759,6.77590,2.000
2,25.850,19.86,6.8758,6.87580,2.000
2,25.950,22.57,6.9759,6.97590,2.000
2,26.050,25.63,7.0758,7.07580,2.000
2,26.150,29.04,7.1760,7.17600,2.000
2,26.300,29.26,7.1923,7.19230,2.000
2,26.400,24.13,7.0926,7.09260,2.000
2,26.500,20.23,6.9925,6.99250,2.000
2,26.600,17.03,6.8927,6.89270,2.000
2,26.700,14.37,6.7926,6.79260,2.000
2,26.800,12.11,6.6927,6.69270,2.000
2,26.900,10.20,6.5924,6.59240,2.000
2,27.000,8.59,6.4927,6.49270,2.000
2,27.100,7.22,6.3925,6.39250,2.000
2,27.200,6.05,6.2926,6.29260,2.000
2,27.300,5.06,6.1925,6.19250,2.000
2,27.400,4.19,6.0926,6.09260,2.000
2,27.500,3.45,5.9923,5.99230,2.000
2,27.600,2.79,5.8925,5.89250,2.000
2,27.700,2.23,5.7924,5.79240,2.000
2,27.800,1.75,5.6926,5.69260,2.000
2,27.900,1.33,5.5925,5.59250,2.000
2,28.000,0.97,5.4926,5.49260,2.000
2,28.100,0.69,5.3924,5.39240,2.000
2,28.200,0.46,5.2926,5.29260,2.000
2,28.300,0.28,5.1923,5.19230,2.000
2,28.400,0.14,5.0925,5.09250,2.000
2,28.500,0.07,4.9924,4.99240,2.000
2,28.600,0.02,4.8925,4.89250,2.000
2,28.700,-0.01,4.7924,4.79240,2.000
2,28.800,-0.01,4.6926,4.69260,2.000
2,28.900,0.00,4.5923,4.59230,2.000
2,29.000,0.00,4.4924,4.49240,2.000
2,29.100,0.00,4.3924,4.39240,2.000
2,29.200,-0.01,4.2925,4.29250,2.000
2,29.300,0.00,4.1923,4.19230,2.000
2,29.400,-0.01,4.0924,4.09240,2.000
2,29.500,-0.01,3.9923,3.99230,2.000
2,29.600,-0.01,3.8924,3.89240,2.000
2,29.700,-0.01,3.7924,3.79240,2.000
2,29.800,-0.01,3.6923,3.69230,2.000
2,29.900,-0.01,3.5924,3.59240,2.000
2,30.000,0.00,3.4924,3.49240,2.000
2,30.100,-0.01,3.3923,3.39230,2.000
2,30.200,0.00,3.2924,3.29240,2.000
2,30.300,0.00,3.1924,3.19240,2.000
2,30.400,-0.01,3.0923,3.09230,2.000
2,30.500,0.00,2.9923,2.99230,2.000
2,30.600,0.00,2.8925,2.89250,2.000
2,30.700,-0.01,2.7923,2.79230,2.000
2,30.800,-0.01,2.6924,2.69240,2.000
2,30.900,0.00,2.5922,2.59220,2.000
2,31.000,-0.01,2.4923,2.49230,2.000
2,31.100,0.00,2.3923,2.39230,2.000
2,31.200,0.00,2.2924,2.29240,2.000
2,31.300,-0.01,2.1921,2.19210,2.000
2,31.400,-0.01,2.0922,2.09220,2.000
2,31.500,0.00,1.9924,1.99240,2.000
2,31.600,0.00,1.8924,1.89240,2.000
2,31.700,0.00,1.7924,1.79240,2.000
2,31.800,0.00,1.6923,1.69230,2.000
2,31.900,0.00,1.5921,1.59210,2.000
2,32.000,-0.01,1.4921,1.49210,2.000
2,32.100,0.00,1.3923,1.39230,2.000
2,32.200,0.00,1.2922,1.29220,2.000
2,32.300,-0.01,1.1921,1.19210,2.000
2,32.400,0.00,1.0923,1.09230,2.000
2,32.500,-0.01,0.9922,0.99220,2.000
2,32.600,-0.01,0.8921,0.89210,2.000
2,32.700,-0.01,0.7923,0.79230,2.000
2,32.800,-0.01,0.6923,0.69230,2.000
2,32.900,-0.01,0.5922,0.59220,2.000
2,33.000,-0.01,0.4923,0.49230,2.000
2,33.100,-0.01,0.3922,0.39220,2.000
2,33.200,0.00,0.2922,0.29220,2.000
2,33.300,-0.01,0.1922,0.19220,2.000
2,33.400,-0.01,0.0921,0.09210,2.000
2,33.500,-0.01,-0.0077,-0.00770,2.000
2,33.650,0.00,0.0006,0.00060,2.000
2,33.750,0.00,-0.0002,-0.00020,2.000
2,33.850,0.00,-0.0002,-0.00020,2.000
2,33.950,0.00,-0.0002,-0.00020,2.000
2,34.050,-0.01,-0.0002,-0.00020,2.000
2,34.150,0.00,-0.0002,-0.00020,2.000
2,34.250,0.00,-0.0002,-0.00020,2.000
2,34.350,0.00,-0.0002,-0.00020,2.000
2,34.450,-0.01,-0.0002,-0.00020,2.000
2,34.550,-0.01,-0.0002,-0.00020,2.000
2,34.650,-0.01,-0.0002,-0.00020,2.000
2,34.750,0.00,-0.0002,-0.00020,2.000
2,34.850,-0.01,-0.0002,-0.00020,2.000
2,34.950,0.00,-0.0002,-0.00020,2.000
2,35.050,-0.01,-0.0002,-0.00020,2.000
2,35.150,-0.01,-0.0002,-0.00020,2.000
2,35.250,-0.01,-0.0002,-0.00020,2.000
2,35.350,0.00,-0.0002,-0.00020,2.000
2,35.450,0.00,-0.0002,-0.00020,2.000
2,35.550,-0.01,-0.0002,-0.00020,2.000
2,35.650,-0.01,-0.0002,-0.00020,2.000
2,35.750,0.00,-0.0002,-0.00020,2.000
2,35.850,-0.01,-0.0002,-0.00020,2.000
2,35.950,0.00,-0.0002,-0.00020,2.000
2,36.050,0.00,-0.0002,-0.00020,2.000
2,36.150,-0.01,-0.0002,-0.00020,2.000
2,36.250,0.00,-0.0002,-0.00020,2.000
2,36.350,0.00,-0.0002,-0.00020,2.000
2,36.450,-0.01,-0.0002,-0.00020,2.000
2,36.550,-0.01,-0.0002,-0.00020,2.000
2,36.700,-0.01,-0.0002,-0.00020,2.000
2,36.800,-0.01,-0.0002,-0.00020,2.000
2,36.900,0.00,-0.0002,-0.00020,2.000
2,37.000,0.00,-0.0002,-0.00020,2.000
2,37.100,0.00,-0.0002,-0.00020,2.000
2,37.200,-0.01,-0.0002,-0.00020,2.000
2,37.300,-0.01,-0.0002,-0.00020,2.000
2,37.400,0.00,-0.0002,-0.00020,2.000
2,37.500,-0.01,-0.0001,-0.00010,2.000
2,37.600,-0.01,-0.0001,-0.00010,2.000
3,37.850,0.00,0.0664,0.06650,3.000
3,37.950,0.00,0.1666,0.16670,3.000
3,38.050,0.00,0.2665,0.26660,3.000
3,38.150,0.01,0.3667,0.36680,3.000
3,38.250,0.00,0.4666,0.46670,3.000
3,38.350,0.00,0.5667,0.56680,3.000
3,38.450,0.00,0.6666,0.66670,3.000
3,38.550,0.00,0.7668,0.76690,3.000
3,38.650,0.00,0.8665,0.86660,3.000
3,38.750,0.00,0.9667,0.96680,3.000
3,38.850,0.00,1.0666,1.06670,3.000
3,38.950,0.00,1.1667,1.16680,3.000
3,39.050,0.00,1.2665,1.26660,3.000
3,39.150,0.00,1.3666,1.36670,3.000
3,39.250,0.01,1.4666,1.46670,3.000
3,39.350,0.00,1.5666,1.56670,3.000
3,39.450,0.00,1.6665,1.66660,3.000
3,39.550,0.00,1.7668,1.76690,3.000
3,39.650,0.00,1.8667,1.86680,3.000
3,39.750,0.00,1.9668,1.96690,3.000
3,39.850,0.00,2.0666,2.06670,3.000
3,39.950,0.00,2.1665,2.16660,3.000
3,40.050,0.00,2.2665,2.26660,3.000
3,40.150,0.00,2.3667,2.36680,3.000
3,40.250,0.00,2.4665,2.46660,3.000
3,40.350,0.00,2.5668,2.56690,3.000
3,40.450,0.00,2.6667,2.66680,3.000
3,40.550,0.00,2.7667,2.76680,3.000
3,40.650,0.00,2.8668,2.86690,3.000
3,40.750,0.00,2.9669,2.96700,3.000
3,40.850,0.00,3.0665,3.06660,3.000
3,40.950,0.00,3.1667,3.16680,3.000
3,41.050,0.00,3.2667,3.26680,3.000
3,41.150,-0.01,3.3668,3.36690,3.000
3,41.250,0.00,3.4666,3.46670,3.000
3,41.350,0.00,3.5668,3.56690,3.000
3,41.450,0.00,3.6667,3.66680,3.000
3,41.550,0.00,3.7668,3.76690,3.000
3,41.650,0.00,3.8666,3.86670,3.000
3,41.750,0.00,3.9668,3.96690,3.000
3,41.850,0.00,4.0667,4.06680,3.000
3,41.950,0.00,4.1668,4.16690,3.000
3,42.050,0.01,4.2667,4.26680,3.000
3,42.150,0.00,4.3668,4.36690,3.000
3,42.250,0.01,4.4666,4.46670,3.000
3,42.350,0.00,4.5668,4.56690,3.000
3,42.450,0.00,4.6667,4.66680,3.000
3,42.550,0.02,4.7668,4.76690,3.000
3,42.650,0.06,4.8669,4.86700,3.000
3,42.750,0.14,4.9669,4.96700,3.000
3,42.850,0.28,5.0667,5.06680,3.000
3,42.950,0.49,5.1668,5.16690,3.000
3,43.050,0.75,5.2667,5.26680,3.000
3,43.150,1.08,5.3667,5.36680,3.000
3,43.250,1.51,5.4667,5.46680,3.000
3,43.350,2.03,5.5670,5.56710,3.000
3,43.450,2.64,5.6669,5.66700,3.000
3,43.550,3.33,5.7668,5.76690,3.000
3,43.650,4.12,5.8668,5.86690,3.000
3,43.750,5.02,5.9669,5.96700,3.000
3,43.850,6.03,6.0667,6.06680,3.000
3,43.950,7.17,6.1668,6.16690,3.000
3,44.050,8.42,6.2668,6.26690,3.000
3,44.150,9.81,6.3669,6.36700,3.000
3,44.250,11.37,6.4668,6.46690,3.000
3,44.350,13.09,6.5668,6.56690,3.000
3,44.450,15.02,6.6667,6.66680,3.000
3,44.550,17.15,6.7670,6.76710,3.000
3,44.650,19.53,6.8669,6.86700,3.000
3,44.750,22.19,6.9668,6.96690,3.000
3,44.850,25.17,7.0669,7.06700,3.000
3,44.950,28.49,7.1669,7.16700,3.000
3,45.100,31.52,7.2418,7.24190,3.000
3,45.200,25.86,7.1417,7.14180,3.000
3,45.300,21.60,7.0417,7.04180,3.000
3,45.400,18.15,6.9416,6.94170,3.000
3,45.500,15.29,6.8417,6.84180,3.000
3,45.600,12.89,6.7418,6.74190,3.000
3,45.700,10.86,6.6415,6.64160,3.000
3,45.800,9.14,6.5416,6.54170,3.000
3,45.900,7.70,6.4416,6.44170,3.000
3,46.000,6.47,6.3416,6.34170,3.000
3,46.100,5.42,6.2416,6.24170,3.000
3,46.200,4.51,6.1416,6.14170,3.000
3,46.300,3.73,6.0416,6.04170,3.000
3,46.400,3.05,5.9415,5.94160,3.000
3,46.500,2.47,5.8414,5.84150,3.000
3,46.600,1.95,5.7415,5.74160,3.000
3,46.700,1.51,5.6417,5.64180,3.000
3,46.800,1.12,5.5417,5.54180,3.000
3,46.900,0.80,5.4416,5.44170,3.000
3,47.000,0.57,5.3414,5.34150,3.000
3,47.100,0.36,5.2415,5.24160,3.000
3,47.200,0.21,5.1414,5.14150,3.000
3,47.300,0.10,5.0415,5.04160,3.000
3,47.400,0.04,4.9416,4.94170,3.000
3,47.500,0.00,4.8416,4.84170,3.000
3,47.600,0.00,4.7414,4.74150,3.000
3,47.700,0.00,4.6415,4.64160,3.000
3,47.800,0.00,4.5414,4.54150,3.000
3,47.900,0.00,4.4414,4.44150,3.000
3,48.000,0.00,4.3415,4.34160,3.000
3,48.100,0.00,4.2414,4.24150,3.000
3,48.200,0.00,4.1413,4.14140,3.000
3,48.300,0.00,4.0414,4.04150,3.000
3,48.400,0.00,3.9414,3.94150,3.000
3,48.500,0.00,3.8413,3.84140,3.000
3,48.600,0.00,3.7413,3.74140,3.000
3,48.700,0.00,3.6415,3.64160,3.000
3,48.800,0.00,3.5413,3.54140,3.000
3,48.900,0.00,3.4414,3.44150,3.000
3,49.000,0.00,3.3413,3.34140,3.000
3,49.100,0.00,3.2414,3.24150,3.000
3,49.200,0.00,3.1412,3.14130,3.000
3,49.300,0.00,3.0414,3.04150,3.000
3,49.400,0.00,2.9414,2.94150,3.000
3,49.500,0.00,2.8414,2.84150,3.000
3,49.600,0.00,2.7412,2.74130,3.000
3,49.700,0.01,2.6414,2.64150,3.000
3,49.800,0.00,2.5412,2.54130,3.000
3,49.900,0.00,2.4413,2.44140,3.000
3,50.000,0.00,2.3413,2.34140,3.000
3,50.100,0.00,2.2413,2.24140,3.000
3,50.200,0.00,2.1411,2.14120,3.000
3,50.300,0.00,2.0414,2.04150,3.000
3,50.400,0.00,1.9412,1.94130,3.000
3,50.500,0.00,1.8414,1.84150,3.000
3,50.600,0.00,1.7412,1.74130,3.000
3,50.700,0.00,1.6413,1.64140,3.000
3,50.800,0.00,1.5411,1.54120,3.000
3,50.900,0.00,1.4413,1.44140,3.000
3,51.000,0.00,1.3410,1.34110,3.000
3,51.100,0.00,1.2411,1.24120,3.000
3,51.200,0.00,1.1412,1.14130,3.000
3,51.300,0.00,1.0413,1.04140,3.000
3,51.400,-0.01,0.9411,0.94120,3.000
3,51.500,0.00,0.8412,0.84130,3.000
3,51.600,0.01,0.7411,0.74120,3.000
3,51.700,0.00,0.6414,0.64150,3.000
3,51.800,0.00,0.5411,0.54120,3.000
3,51.900,0.00,0.4413,0.44140,3.000
3,52.000,0.00,0.3410,0.34110,3.000
3,52.100,0.00,0.2412,0.24130,3.000
3,52.200,0.00,0.1411,0.14120,3.000
3,52.300,0.00,0.0412,0.04130,3.000
3,52.450,0.00,-0.0355,-0.03540,3.000
3,52.550,0.00,-0.0002,-0.00010,3.000
3,52.650,0.00,-0.0003,-0.00020,3.000
3,52.750,0.00,-0.0002,-0.00010,3.000
3,52.850,0.00,-0.0002,-0.00010,3.000
3,52.950,0.00,-0.0002,-0.00010,3.000
3,53.050,0.00,-0.0002,-0.00010,3.000
3,53.150,0.00,-0.0002,-0.00010,3.000
3,53.250,0.00,-0.0002,-0.00010,3.000
3,53.350,0.00,-0.0002,-0.00010,3.000
3,53.450,0.00,-0.0002,-0.00010,3.000
3,53.550,0.00,-0.0002,-0.00010,3.000
3,53.650,0.00,-0.0002,-0.00010,3.000
3,53.750,0.00,-0.0002,-0.00010,3.000
3,53.850,0.00,-0.0002,-0.00010,3.000
3,53.950,0.00,-0.0002,-0.00010,3.000
3,54.050,0.00,-0.0002,-0.00010,3.000
3,54.150,0.00,-0.0002,-0.00010,3.000
3,54.250,0.00,-0.0002,-0.00010,3.000
3,54.350,0.01,-0.0002,-0.00010,3.000
3,54.450,-0.01,-0.0002,-0.00010,3.000
3,54.550,0.00,-0.0002,-0.00010,3.000
3,54.650,0.00,-0.0002,-0.00010,3.000
3,54.750,0.00,-0.0002,-0.00010,3.000
3,54.850,0.00,-0.0002,-0.00010,3.000
3,54.950,0.00,-0.0002,-0.00010,3.000
3,55.050,0.00,-0.0002,-0.00010,3.000
3,55.150,0.00,-0.0002,-0.00010,3.000
3,55.250,0.00,-0.0002,-0.00010,3.000
3,55.350,0.00,-0.0002,-0.00010,3.000
3,55.500,0.00,-0.0002,-0.00010,3.000
3,55.600,0.00,-0.0002,-0.00010,3.000
3,55.700,0.00,-0.0002,-0.00010,3.000
3,55.800,0.00,-0.0002,-0.00010,3.000
3,55.900,0.00,-0.0002,-0.00010,3.000
3,56.000,0.00,-0.0002,-0.00010,3.000
3,56.100,0.00,-0.0002,-0.00010,3.000
3,56.200,0.00,-0.0001,0.00000,3.000
3,56.300,0.00,-0.0001,0.00000,3.000
3,56.400,0.00,-0.0001,0.00000,3.000
4,56.650,0.00,0.0154,0.01550,4.000
4,56.750,0.00,0.1155,0.11560,4.000
4,56.850,0.00,0.2155,0.21560,4.000
4,56.950,-0.01,0.3155,0.31560,4.000
4,57.050,0.00,0.4155,0.41560,4.000
4,57.150,0.00,0.5155,0.51560,4.000
4,57.250,0.00,0.6156,0.61570,4.000
4,57.350,0.00,0.7157,0.71580,4.000
4,57.450,0.00,0.8155,0.81560,4.000
4,57.550,0.00,0.9155,0.91560,4.000
4,57.650,0.00,1.0156,1.01570,4.000
4,57.750,0.00,1.1156,1.11570,4.000
4,57.850,0.00,1.2155,1.21560,4.000
4,57.950,0.00,1.3156,1.31570,4.000
4,58.050,0.00,1.4155,1.41560,4.000
4,58.150,0.00,1.5155,1.51560,4.000
4,58.250,0.00,1.6156,1.61570,4.000
4,58.350,0.00,1.7155,1.71560,4.000
4,58.450,0.00,1.8157,1.81580,4.000
4,58.550,0.00,1.9157,1.91580,4.000
4,58.650,0.00,2.0157,2.01580,4.000
4,58.750,0.00,2.1156,2.11570,4.000
4,58.850,0.00,2.2156,2.21570,4.000
4,58.950,0.00,2.3157,2.31580,4.000
4,59.050,0.00,2.4156,2.41570,4.000
4,59.150,0.00,2.5156,2.51570,4.000
4,59.250,0.00,2.6158,2.61590,4.000
4,59.350,0.00,2.7158,2.71590,4.000
4,59.450,0.00,2.8157,2.81580,4.000
4,59.550,0.00,2.9158,2.91590,4.000
4,59.650,0.00,3.0157,3.01580,4.000
4,59.750,0.00,3.1157,3.11580,4.000
4,59.850,0.00,3.2157,3.21580,4.000
4,59.950,0.00,3.3158,3.31590,4.000
4,60.050,0.00,3.4158,3.41590,4.000
4,60.150,-0.01,3.5157,3.51580,4.000
4,60.250,0.00,3.6158,3.61590,4.000
4,60.350,0.00,3.7156,3.71570,4.000
4,60.450,0.00,3.8158,3.81590,4.000
4,60.550,0.00,3.9157,3.91580,4.000
4,60.650,0.00,4.0159,4.01600,4.000
4,60.750,0.00,4.1158,4.11590,4.000
4,60.850,0.00,4.2159,4.21600,4.000
4,60.950,0.00,4.3157,4.31580,4.000
4,61.050,0.00,4.4159,4.41600,4.000
4,61.150,-0.01,4.5157,4.51580,4.000
4,61.250,0.00,4.6159,4.61600,4.000
4,61.350,0.00,4.7157,4.71580,4.000
4,61.450,0.03,4.8159,4.81600,4.000
4,61.550,0.09,4.9158,4.91590,4.000
4,61.650,0.20,5.0159,5.01600,4.000
4,61.750,0.36,5.1159,5.11600,4.000
4,61.850,0.60,5.2158,5.21590,4.000
4,61.950,0.89,5.3156,5.31570,4.000
4,62.050,1.26,5.4158,5.41590,4.000
4,62.150,1.75,5.5158,5.51590,4.000
4,62.250,2.29,5.6160,5.61610,4.000
4,62.350,2.95,5.7159,5.71600,4.000
4,62.450,3.69,5.8158,5.81590,4.000
4,62.550,4.53,5.9157,5.91580,4.000
4,62.650,5.48,6.0159,6.01600,4.000
4,62.750,6.57,6.1157,6.11580,4.000
4,62.850,7.76,6.2160,6.21610,4.000
4,62.950,9.08,6.3157,6.31580,4.000
4,63.050,10.55,6.4160,6.41610,4.000
4,63.150,12.18,6.5158,6.51590,4.000
4,63.250,13.99,6.6158,6.61590,4.000
4,63.350,16.02,6.7157,6.71580,4.000
4,63.450,18.27,6.8160,6.81610,4.000
4,63.550,20.77,6.9157,6.91580,4.000
4,63.650,23.54,7.0158,7.01590,4.000
4,63.750,26.66,7.1159,7.11600,4.000
4,63.850,30.15,7.2160,7.21610,4.000
4,64.000,28.41,7.1924,7.19250,4.000
4,64.100,23.53,7.0927,7.09280,4.000
4,64.200,19.73,6.9925,6.99260,4.000
4,64.300,16.58,6.8927,6.89280,4.000
4,64.400,13.96,6.7925,6.79260,4.000
4,64.500,11.76,6.6928,6.69290,4.000
4,64.600,9.90,6.5925,6.59260,4.000
4,64.700,8.33,6.4928,6.49290,4.000
4,64.800,7.02,6.3926,6.39270,4.000
4,64.900,5.88,6.2927,6.29280,4.000
4,65.000,4.92,6.1925,6.19260,4.000
4,65.100,4.08,6.0926,6.09270,4.000
4,65.200,3.36,5.9923,5.99240,4.000
4,65.300,2.73,5.8925,5.89260,4.000
4,65.400,2.18,5.7924,5.79250,4.000
4,65.500,1.70,5.6927,5.69280,4.000
4,65.600,1.30,5.5924,5.59250,4.000
4,65.700,0.94,5.4925,5.49260,4.000
4,65.800,0.67,5.3924,5.39250,4.000
4,65.900,0.44,5.2925,5.29260,4.000
4,66.000,0.28,5.1923,5.19240,4.000
4,66.100,0.14,5.0926,5.09270,4.000
4,66.200,0.06,4.9924,4.99250,4.000
4,66.300,0.01,4.8926,4.89270,4.000
4,66.400,0.00,4.7924,4.79250,4.000
4,66.500,0.00,4.6925,4.69260,4.000
4,66.600,0.01,4.5923,4.59240,4.000
4,66.700,0.00,4.4925,4.49260,4.000
4,66.800,0.00,4.3924,4.39250,4.000
4,66.900,0.00,4.2925,4.29260,4.000
4,67.000,0.00,4.1923,4.19240,4.000
4,67.100,0.00,4.0925,4.09260,4.000
4,67.200,0.01,3.9923,3.99240,4.000
4,67.300,0.00,3.8923,3.89240,4.000
4,67.400,0.00,3.7922,3.79230,4.000
4,67.500,0.00,3.6923,3.69240,4.000
4,67.600,0.00,3.5923,3.59240,4.000
4,67.700,0.00,3.4924,3.49250,4.000
4,67.800,0.00,3.3923,3.39240,4.000
4,67.900,0.00,3.2924,3.29250,4.000
4,68.000,0.00,3.1921,3.19220,4.000
4,68.100,-0.01,3.0922,3.09230,4.000
4,68.200,0.00,2.9923,2.99240,4.000
4,68.300,0.00,2.8925,2.89260,4.000
4,68.400,0.00,2.7923,2.79240,4.000
4,68.500,0.00,2.6923,2.69240,4.000
4,68.600,0.00,2.5923,2.59240,4.000
4,68.700,0.00,2.4923,2.49240,4.000
4,68.800,0.00,2.3922,2.39230,4.000
4,68.900,0.00,2.2923,2.29240,4.000
4,69.000,0.00,2.1921,2.19220,4.000
4,69.100,0.00,2.0923,2.09240,4.000
4,69.200,0.00,1.9922,1.99230,4.000
4,69.300,0.00,1.8924,1.89250,4.000
4,69.400,0.00,1.7923,1.79240,4.000
4,69.500,0.00,1.6923,1.69240,4.000
4,69.600,0.00,1.5921,1.59220,4.000
4,69.700,0.00,1.4921,1.49220,4.000
4,69.800,-0.01,1.3922,1.39230,4.000
4,69.900,0.00,1.2921,1.29220,4.000
4,70.000,-0.01,1.1922,1.19230,4.000
4,70.100,0.00,1.0922,1.09230,4.000
4,70.200,0.00,0.9922,0.99230,4.000
4,70.300,-0.01,0.8921,0.89220,4.000
4,70.400,0.00,0.7922,0.79230,4.000
4,70.500,0.00,0.6923,0.69240,4.000
4,70.600,-0.01,0.5923,0.59240,4.000
4,70.700,0.00,0.4923,0.49240,4.000
4,70.800,0.00,0.3922,0.39230,4.000
4,70.900,0.00,0.2922,0.29230,4.000
4,71.000,0.00,0.1922,0.19230,4.000
4,71.100,0.00,0.0921,0.09220,4.000
4,71.200,0.00,-0.0078,-0.00770,4.000
4,71.350,0.00,0.0003,0.00040,4.000
4,71.450,0.00,-0.0002,-0.00010,4.000
4,71.550,0.00,-0.0003,-0.00020,4.000
4,71.650,-0.01,-0.0002,-0.00010,4.000
4,71.750,0.00,-0.0002,-0.00010,4.000
4,71.850,0.00,-0.0002,-0.00010,4.000
4,71.950,-0.01,-0.0002,-0.00010,4.000
4,72.050,0.00,-0.0002,-0.00010,4.000
4,72.150,0.00,-0.0002,-0.00010,4.000
4,72.250,0.00,-0.0002,-0.00010,4.000
4,72.350,-0.01,-0.0002,-0.00010,4.000
4,72.450,0.00,-0.0002,-0.00010,4.000
4,72.550,-0.01,-0.0002,-0.00010,4.000
4,72.650,-0.01,-0.0002,-0.00010,4.000
4,72.750,0.00,-0.0002,-0.00010,4.000
4,72.850,0.00,-0.0002,-0.00010,4.000
4,72.950,0.00,-0.0002,-0.00010,4.000
4,73.050,0.00,-0.0002,-0.00010,4.000
4,73.150,-0.01,-0.0002,-0.00010,4.000
4,73.250,0.00,-0.0002,-0.00010,4.000
4,73.350,0.00,-0.0002,-0.00010,4.000
4,73.450,-0.01,-0.0002,-0.00010,4.000
4,73.550,0.00,-0.0002,-0.00010,4.000
4,73.650,0.00,-0.0002,-0.00010,4.000
4,73.750,0.00,-0.0002,-0.00010,4.000
4,73.850,0.00,-0.0002,-0.00010,4.000
4,73.950,0.00,-0.0002,-0.00010,4.000
4,74.050,0.00,-0.0002,-0.00010,4.000
4,74.150,0.00,-0.0002,-0.00010,4.000
4,74.250,0.00,-0.0002,-0.00010,4.000
4,74.400,-0.01,-0.0002,-0.00010,4.000
4,74.500,0.00,-0.0002,-0.00010,4.000
4,74.600,0.00,-0.0002,-0.00010,4.000
4,74.700,0.00,-0.0002,-0.00010,4.000
4,74.800,0.00,-0.0002,-0.00010,4.000
4,74.900,-0.01,-0.0002,-0.00010,4.000
4,75.000,0.00,-0.0002,-0.00010,4.000
4,75.100,0.00,-0.0001,0.00000,4.000
4,75.200,0.00,-0.0001,0.00000,4.000
5,75.500,0.00,0.0254,0.02550,5.000
5,75.600,0.00,0.1255,0.12560,5.000
5,75.700,0.00,0.2254,0.22550,5.000
5,75.800,0.00,0.3257,0.32580,5.000
5,75.900,0.00,0.4255,0.42560,5.000
5,76.000,0.00,0.5257,0.52580,5.000
5,76.100,0.00,0.6256,0.62570,5.000
5,76.200,0.00,0.7256,0.72570,5.000
5,76.300,0.00,0.8254,0.82550,5.000
5,76.400,0.00,0.9256,0.92570,5.000
5,76.500,0.00,1.0255,1.02560,5.000
5,76.600,0.00,1.1258,1.12590,5.000
5,76.700,0.01,1.2255,1.22560,5.000
5,76.800,0.00,1.3257,1.32580,5.000
5,76.900,0.00,1.4255,1.42560,5.000
5,77.000,0.00,1.5256,1.52570,5.000
5,77.100,0.00,1.6254,1.62550,5.000
5,77.200,0.00,1.7258,1.72590,5.000
5,77.300,0.00,1.8256,1.82570,5.000
5,77.400,0.00,1.9257,1.92580,5.000
5,77.500,0.00,2.0255,2.02560,5.000
5,77.600,0.00,2.1258,2.12590,5.000
5,77.700,0.00,2.2255,2.22560,5.000
5,77.800,0.00,2.3259,2.32600,5.000
5,77.900,-0.01,2.4256,2.42570,5.000
5,78.000,0.00,2.5258,2.52590,5.000
5,78.100,0.00,2.6256,2.62570,5.000
5,78.200,0.00,2.7257,2.72580,5.000
5,78.300,0.01,2.8256,2.82570,5.000
5,78.400,0.00,2.9258,2.92590,5.000
5,78.500,0.00,3.0255,3.02560,5.000
5,78.600,0.00,3.1257,3.12580,5.000
5,78.700,0.00,3.2256,3.22570,5.000
5,78.800,0.00,3.3257,3.32580,5.000
5,78.900,0.00,3.4256,3.42570,5.000
5,79.000,0.00,3.5258,3.52590,5.000
5,79.100,0.00,3.6256,3.62570,5.000
5,79.200,0.00,3.7258,3.72590,5.000
5,79.300,0.00,3.8256,3.82570,5.000
5,79.400,0.00,3.9257,3.92580,5.000
5,79.500,0.00,4.0257,4.02580,5.000
5,79.600,0.00,4.1257,4.12580,5.000
5,79.700,0.00,4.2257,4.22580,5.000
5,79.800,0.00,4.3260,4.32610,5.000
5,79.900,0.00,4.4258,4.42590,5.000
5,80.000,0.00,4.5257,4.52580,5.000
5,80.100,0.00,4.6257,4.62580,5.000
5,80.200,0.00,4.7259,4.72600,5.000
5,80.300,0.04,4.8258,4.82590,5.000
5,80.400,0.10,4.9259,4.92600,5.000
5,80.500,0.20,5.0259,5.02600,5.000
5,80.600,0.38,5.1259,5.12600,5.000
5,80.700,0.61,5.2257,5.22580,5.000
5,80.800,0.92,5.3258,5.32590,5.000
5,80.900,1.30,5.4257,5.42580,5.000
5,81.000,1.78,5.5260,5.52610,5.000
5,81.100,2.34,5.6259,5.62600,5.000
5,81.200,3.00,5.7260,5.72610,5.000
5,81.300,3.75,5.8257,5.82580,5.000
5,81.400,4.61,5.9257,5.92580,5.000
5,81.500,5.58,6.0258,6.02590,5.000
5,81.600,6.66,6.1259,6.12600,5.000
5,81.700,7.86,6.2260,6.22610,5.000
5,81.800,9.19,6.3259,6.32600,5.000
5,81.900,10.67,6.4259,6.42600,5.000
5,82.000,12.30,6.5259,6.52600,5.000
5,82.100,14.13,6.6258,6.62590,5.000
5,82.200,16.15,6.7259,6.72600,5.000
5,82.300,18.40,6.8260,6.82610,5.000
5,82.400,20.90,6.9258,6.92590,5.000
5,82.500,23.69,7.0259,7.02600,5.000
5,82.600,26.79,7.1258,7.12590,5.000
5,82.700,30.26,7.2259,7.22600,5.000
5,82.850,28.49,7.2026,7.20270,5.000
5,82.950,23.60,7.1026,7.10270,5.000
5,83.050,19.78,7.0026,7.00270,5.000
5,83.150,16.62,6.9026,6.90270,5.000
5,83.250,13.99,6.8027,6.80280,5.000
5,83.350,11.78,6.7026,6.70270,5.000
5,83.450,9.92,6.6026,6.60270,5.000
5,83.550,8.35,6.5027,6.50280,5.000
5,83.650,7.04,6.4026,6.40270,5.000
5,83.750,5.90,6.3027,6.30280,5.000
5,83.850,4.94,6.2026,6.20270,5.000
5,83.950,4.10,6.1025,6.10260,5.000
5,84.050,3.38,6.0025,6.00260,5.000
5,84.150,2.75,5.9025,5.90260,5.000
5,84.250,2.20,5.8024,5.80250,5.000
5,84.350,1.72,5.7026,5.70270,5.000
5,84.450,1.32,5.6026,5.60270,5.000
5,84.550,0.97,5.5026,5.50270,5.000
5,84.650,0.69,5.4024,5.40250,5.000
5,84.750,0.47,5.3024,5.30250,5.000
5,84.850,0.28,5.2024,5.20250,5.000
5,84.950,0.15,5.1025,5.10260,5.000
5,85.050,0.07,5.0026,5.00270,5.000
5,85.150,0.02,4.9025,4.90260,5.000
5,85.250,0.00,4.8024,4.80250,5.000
5,85.350,0.00,4.7025,4.70260,5.000
5,85.450,0.00,4.6026,4.60270,5.000
5,85.550,0.00,4.5023,4.50240,5.000
5,85.650,0.00,4.4025,4.40260,5.000
5,85.750,0.00,4.3025,4.30260,5.000
5,85.850,0.00,4.2025,4.20260,5.000
5,85.950,0.00,4.1024,4.10250,5.000
5,86.050,0.00,4.0026,4.00270,5.000
5,86.150,0.00,3.9024,3.90250,5.000
5,86.250,0.00,3.8024,3.80250,5.000
5,86.350,0.00,3.7023,3.70240,5.000
5,86.450,0.00,3.6024,3.60250,5.000
5,86.550,0.00,3.5023,3.50240,5.000
5,86.650,0.00,3.4025,3.40260,5.000
5,86.750,0.00,3.3023,3.30240,5.000
5,86.850,0.00,3.2025,3.20260,5.000
5,86.950,0.00,3.1022,3.10230,5.000
5,87.050,0.00,3.0024,3.00250,5.000
5,87.150,0.00,2.9024,2.90250,5.000
5,87.250,0.00,2.8023,2.80240,5.000
5,87.350,0.00,2.7023,2.70240,5.000
5,87.450,0.00,2.6025,2.60260,5.000
5,87.550,0.00,2.5023,2.50240,5.000
5,87.650,0.00,2.4023,2.40240,5.000
5,87.750,0.00,2.3023,2.30240,5.000
5,87.850,0.00,2.2022,2.20230,5.000
5,87.950,0.00,2.1022,2.10230,5.000
5,88.050,0.00,2.0024,2.00250,5.000
5,88.150,0.01,1.9023,1.90240,5.000
5,88.250,0.00,1.8024,1.80250,5.000
5,88.350,0.00,1.7022,1.70230,5.000
5,88.450,0.01,1.6022,1.60230,5.000
5,88.550,0.00,1.5021,1.50220,5.000
5,88.650,0.00,1.4023,1.40240,5.000
5,88.750,0.00,1.3020,1.30210,5.000
5,88.850,0.00,1.2023,1.20240,5.000
5,88.950,0.00,1.1022,1.10230,5.000
5,89.050,0.00,1.0023,1.00240,5.000
5,89.150,0.00,0.9020,0.90210,5.000
5,89.250,0.00,0.8023,0.80240,5.000
5,89.350,0.00,0.7021,0.70220,5.000
5,89.450,0.00,0.6022,0.60230,5.000
5,89.550,0.00,0.5022,0.50230,5.000
5,89.650,0.00,0.4023,0.40240,5.000
5,89.750,0.00,0.3021,0.30220,5.000
5,89.850,0.00,0.2021,0.20220,5.000
5,89.950,0.00,0.1021,0.10220,5.000
5,90.050,0.00,0.0023,0.00240,5.000
5,90.200,0.00,0.0000,0.00010,5.000
5,90.300,0.00,-0.0003,-0.00020,5.000
5,90.400,0.00,-0.0003,-0.00020,5.000
5,90.500,0.00,-0.0003,-0.00020,5.000
5,90.600,-0.01,-0.0003,-0.00020,5.000
5,90.700,0.00,-0.0003,-0.00020,5.000
5,90.800,0.00,-0.0003,-0.00020,5.000
5,90.900,0.00,-0.0003,-0.00020,5.000
5,91.000,0.00,-0.0003,-0.00020,5.000
5,91.100,0.00,-0.0003,-0.00020,5.000
5,91.200,0.00,-0.0003,-0.00020,5.000
5,91.300,0.00,-0.0002,-0.00010,5.000
5,91.400,0.00,-0.0002,-0.00010,5.000
5,91.500,0.00,-0.0002,-0.00010,5.000
5,91.600,0.00,-0.0002,-0.00010,5.000
5,91.700,0.00,-0.0002,-0.00010,5.000
5,91.800,0.00,-0.0002,-0.00010,5.000
5,91.900,0.00,-0.0002,-0.00010,5.000
5,92.000,0.00,-0.0002,-0.00010,5.000
5,92.100,0.00,-0.0002,-0.00010,5.000
5,92.200,0.00,-0.0002,-0.00010,5.000
5,92.300,0.00,-0.0002,-0.00010,5.000
5,92.400,0.00,-0.0002,-0.00010,5.000
5,92.500,0.00,-0.0002,-0.00010,5.000
5,92.600,0.00,-0.0002,-0.00010,5.000
5,92.700,0.00,-0.0002,-0.00010,5.000
5,92.800,0.00,-0.0002,-0.00010,5.000
5,92.900,0.00,-0.0002,-0.00010,5.000
5,93.000,0.00,-0.0002,-0.00010,5.000
5,93.100,0.00,-0.0002,-0.00010,5.000
5,93.250,0.00,-0.0002,-0.00010,5.000
5,93.350,0.00,-0.0002,-0.00010,5.000
5,93.450,0.00,-0.0002,-0.00010,5.000
5,93.550,0.00,-0.0002,-0.00010,5.000
5,93.650,0.01,-0.0002,-0.00010,5.000
5,93.750,0.00,-0.0002,-0.00010,5.000
5,93.850,0.00,-0.0002,-0.00010,5.000
5,93.950,0.00,-0.0001,0.00000,5.000
5,94.050,0.00,-0.0001,0.00000,5.000
5,94.100,0.00,-0.0001,0.00000,5.000