File: calibDATA_loadcell/data/date_08:02:2018/MTS/20deg_30N_2.txt
""
"Test Method","Radhen_Load_Cntrl_Cmprsn_250N_12-7.msm"
"Sample I. D.","Sample1.mss"
"Specimen Number","3"

"TheCycle_Output ()","_Time (s)","_Load (N)","_Extension (mm)","RealTimeDepth (mm)","CycleNumber ()"

1,0.250,0.00,0.0147,0.01470,1.000
1,0.350,0.00,0.1145,0.11450,1.000
1,0.450,0.00,0.2147,0.21470,1.000
1,0.550,0.00,0.3146,0.31460,1.000
1,0.650,0.00,0.4149,0.41490,1.000
1,0.750,0.00,0.5146,0.51460,1.000
1,0.850,0.00,0.6149,0.61490,1.000
1,0.950,0.00,0.7148,0.71480,1.000
1,1.050,0.00,0.8147,0.81470,1.000
1,1.150,0.00,0.9146,0.91460,1.000
1,1.250,0.00,1.0148,1.01480,1.000
1,1.350,-0.01,1.1146,1.11460,1.000
1,1.450,0.00,1.2149,1.21490,1.000
1,1.550,0.00,1.3148,1.31480,1.000
1,1.650,0.00,1.4148,1.41480,1.000
1,1.750,0.00,1.5147,1.51470,1.000
1,1.850,0.00,1.6148,1.61480,1.000
1,1.950,0.00,1.7147,1.71470,1.000
1,2.050,0.00,1.8149,1.81490,1.000
1,2.150,0.00,1.9147,1.91470,1.000
1,2.250,0.00,2.0149,2.01490,1.000
1,2.350,0.00,2.1149,2.11490,1.000
1,2.450,0.00,2.2148,2.21480,1.000
1,2.550,0.00,2.3148,2.31480,1.000
1,2.650,-0.01,2.4149,2.41490,1.000
1,2.750,0.00,2.5149,2.51490,1.000
1,2.850,0.00,2.6150,2.61500,1.000
1,2.950,0.00,2.7149,2.71490,1.000
1,3.050,0.00,2.8149,2.81490,1.000
1,3.150,0.00,2.9149,2.91490,1.000
1,3.250,0.00,3.0148,3.01480,1.000
1,3.350,0.00,3.1148,3.11480,1.000
1,3.450,0.00,3.2149,3.21490,1.000
1,3.550,0.00,3.3149,3.31490,1.000
1,3.650,0.00,3.4149,3.41490,1.000
1,3.750,0.00,3.5149,3.51490,1.000
1,3.850,0.00,3.6148,3.61480,1.000
1,3.950,0.00,3.7149,3.71490,1.000
1,4.050,0.00,3.8149,3.81490,1.000
1,4.150,0.00,3.9150,3.91500,1.000
1,4.250,0.00,4.0150,4.01500,1.000
1,4.350,0.00,4.1150,4.11500,1.000
1,4.450,0.00,4.2150,4.21500,1.000
1,4.550,0.00,4.3150,4.31500,1.000
1,4.650,0.00,4.4149,4.41490,1.000
1,4.750,0.00,4.5151,4.51510,1.000
1,4.850,0.00,4.6149,4.61490,1.000
1,4.950,0.05,4.7149,4.71490,1.000
1,5.050,0.14,4.8148,4.81480,1.000
1,5.150,0.30,4.9149,4.91490,1.000
1,5.250,0.53,5.0148,5.01480,1.000
1,5.350,0.83,5.1149,5.11490,1.000
1,5.450,1.20,5.2148,5.21480,1.000
1,5.550,1.65,5.3150,5.31500,1.000
1,5.650,2.20,5.4149,5.41490,1.000
1,5.750,2.84,5.5151,5.51510,1.000
1,5.850,3.57,5.6149,5.61490,1.000
1,5.950,4.40,5.7150,5.71500,1.000
1,6.050,5.34,5.8148,5.81480,1.000
1,6.150,6.40,5.9149,5.91490,1.000
1,6.250,7.58,6.0149,6.01490,1.000
1,6.350,8.91,6.1151,6.11510,1.000
1,6.450,10.40,6.2149,6.21490,1.000
1,6.550,12.11,6.3151,6.31510,1.000
1,6.650,14.03,6.4150,6.41500,1.000
1,6.750,16.20,6.5149,6.51490,1.000
1,6.850,18.65,6.6149,6.61490,1.000
1,6.950,21.38,6.7149,6.71490,1.000
1,7.050,24.49,6.8148,6.81480,1.000
1,7.150,28.07,6.9151,6.91510,1.000
1,7.300,31.69,7.0044,7.00440,1.000
1,7.400,24.57,6.9058,6.90580,1.000
1,7.500,19.57,6.8057,6.80570,1.000
1,7.600,15.82,6.7057,6.70570,1.000
1,7.700,12.90,6.6056,6.60560,1.000
1,7.800,10.56,6.5057,6.50570,1.000
1,7.900,8.68,6.4057,6.40570,1.000
1,8.000,7.15,6.3058,6.30580,1.000
1,8.100,5.89,6.2055,6.20550,1.000
1,8.200,4.84,6.1058,6.10580,1.000
1,8.300,3.97,6.0056,6.00560,1.000
1,8.400,3.24,5.9056,5.90560,1.000
1,8.500,2.64,5.8055,5.80550,1.000
1,8.600,2.12,5.7056,5.70560,1.000
1,8.700,1.68,5.6054,5.60540,1.000
1,8.800,1.31,5.5056,5.50560,1.000
1,8.900,0.99,5.4054,5.40540,1.000
1,9.000,0.72,5.3057,5.30570,1.000
1,9.100,0.48,5.2055,5.20550,1.000
1,9.200,0.29,5.1056,5.10560,1.000
1,9.300,0.17,5.0054,5.00540,1.000
1,9.400,0.07,4.9056,4.90560,1.000
1,9.500,0.01,4.8054,4.80540,1.000
1,9.600,0.00,4.7056,4.70560,1.000
1,9.700,0.00,4.6054,4.60540,1.000
1,9.800,-0.01,4.5057,4.50570,1.000
1,9.900,0.00,4.4053,4.40530,1.000
1,10.000,-0.01,4.3055,4.30550,1.000
1,10.100,0.00,4.2054,4.20540,1.000
1,10.200,0.00,4.1056,4.10560,1.000
1,10.300,0.00,4.0054,4.00540,1.000
1,10.400,0.00,3.9055,3.90550,1.000
1,10.500,0.00,3.8052,3.80520,1.000
1,10.600,0.00,3.7055,3.70550,1.000
1,10.700,0.00,3.6053,3.60530,1.000
1,10.800,0.00,3.5055,3.50550,1.000
1,10.900,0.00,3.4053,3.40530,1.000
1,11.000,0.00,3.3055,3.30550,1.000
1,11.100,0.00,3.2053,3.20530,1.000
1,11.200,0.00,3.1054,3.10540,1.000
1,11.300,-0.01,3.0052,3.00520,1.000
1,11.400,0.00,2.9053,2.90530,1.000
1,11.500,0.00,2.8052,2.80520,1.000
1,11.600,0.00,2.7054,2.70540,1.000
1,11.700,0.00,2.6052,2.60520,1.000
1,11.800,0.00,2.5053,2.50530,1.000
1,11.900,0.00,2.4051,2.40510,1.000
1,12.000,0.00,2.3053,2.30530,1.000
1,12.100,-0.01,2.2052,2.20520,1.000
1,12.200,0.00,2.1055,2.10550,1.000
1,12.300,0.00,2.0052,2.00520,1.000
1,12.400,0.00,1.9053,1.90530,1.000
1,12.500,0.00,1.8051,1.80510,1.000
1,12.600,0.00,1.7053,1.70530,1.000
1,12.700,0.00,1.6051,1.60510,1.000
1,12.800,0.00,1.5053,1.50530,1.000
1,12.900,0.00,1.4051,1.40510,1.000
1,13.000,-0.01,1.3054,1.30540,1.000
1,13.100,0.00,1.2052,1.20520,1.000
1,13.200,0.00,1.1052,1.10520,1.000
1,13.300,0.00,1.0052,1.00520,1.000
1,13.400,-0.01,0.9051,0.90510,1.000
1,13.500,0.00,0.8052,0.80520,1.000
1,13.600,0.00,0.7053,0.70530,1.000
1,13.700,0.00,0.6052,0.60520,1.000
1,13.800,0.00,0.5052,0.50520,1.000
1,13.900,0.00,0.4052,0.40520,1.000
1,14.000,0.00,0.3052,0.30520,1.000
1,14.100,0.00,0.2052,0.20520,1.000
1,14.200,0.00,0.1052,0.10520,1.000
1,14.300,-0.01,0.0051,0.00510,1.000
1,14.450,-0.01,-0.0010,-0.00100,1.000
1,14.550,0.00,-0.0004,-0.00040,1.000
1,14.650,0.00,-0.0004,-0.00040,1.000
1,14.750,0.00,-0.0003,-0.00030,1.000
1,14.850,-0.01,-0.0003,-0.00030,1.000
1,14.950,0.00,-0.0003,-0.00030,1.000
1,15.050,0.00,-0.0003,-0.00030,1.000
1,15.150,0.00,-0.0003,-0.00030,1.000
1,15.250,0.00,-0.0003,-0.00030,1.000
1,15.350,0.00,-0.0003,-0.00030,1.000
1,15.450,0.00,-0.0003,-0.00030,1.000
1,15.550,0.00,-0.0003,-0.00030,1.000
1,15.650,0.00,-0.0003,-0.00030,1.000
1,15.750,0.00,-0.0003,-0.00030,1.000
1,15.850,0.00,-0.0003,-0.00030,1.000
1,15.950,0.00,-0.0003,-0.00030,1.000
1,16.050,-0.01,-0.0003,-0.00030,1.000
1,16.150,0.00,-0.0003,-0.00030,1.000
1,16.250,0.00,-0.0003,-0.00030,1.000
1,16.350,0.00,-0.0003,-0.00030,1.000
1,16.450,0.00,-0.0003,-0.00030,1.000
1,16.550,0.00,-0.0003,-0.00030,1.000
1,16.650,-0.01,-0.0003,-0.00030,1.000
1,16.750,0.00,-0.0003,-0.00030,1.000
1,16.850,0.00,-0.0003,-0.00030,1.000
1,16.950,0.00,-0.0003,-0.00030,1.000
1,17.050,0.00,-0.0003,-0.00030,1.000
1,17.150,0.00,-0.0003,-0.00030,1.000
1,17.250,0.00,-0.0003,-0.00030,1.000
1,17.350,-0.01,-0.0003,-0.00030,1.000
1,17.500,-0.01,-0.0002,-0.00020,1.000
1,17.600,0.00,-0.0002,-0.00020,1.000
1,17.700,0.00,-0.0002,-0.00020,1.000
1,17.800,0.00,-0.0002,-0.00020,1.000
1,17.900,0.00,-0.0002,-0.00020,1.000
1,18.000,0.00,-0.0002,-0.00020,1.000
1,18.100,-0.01,-0.0002,-0.00020,1.000
1,18.200,0.00,-0.0002,-0.00020,1.000
1,18.300,0.00,-0.0002,-0.00020,1.000
2,18.600,0.00,0.0245,0.02460,2.000
2,18.700,0.00,0.1245,0.12460,2.000
2,18.800,-0.01,0.2247,0.22480,2.000
2,18.900,-0.01,0.3246,0.32470,2.000
2,19.000,0.00,0.4247,0.42480,2.000
2,19.100,0.00,0.5245,0.52460,2.000
2,19.200,-0.01,0.6249,0.62500,2.000
2,19.300,0.00,0.7246,0.72470,2.000
2,19.400,0.00,0.8246,0.82470,2.000
2,19.500,-0.01,0.9246,0.92470,2.000
2,19.600,-0.01,1.0247,1.02480,2.000
2,19.700,-0.01,1.1246,1.12470,2.000
2,19.800,-0.01,1.2249,1.22500,2.000
2,19.900,0.00,1.3247,1.32480,2.000
2,20.000,-0.01,1.4247,1.42480,2.000
2,20.100,0.00,1.5246,1.52470,2.000
2,20.200,0.00,1.6247,1.62480,2.000
2,20.300,0.00,1.7246,1.72470,2.000
2,20.400,0.00,1.8247,1.82480,2.000
2,20.500,0.00,1.9246,1.92470,2.000
2,20.600,0.00,2.0249,2.02500,2.000
2,20.700,0.00,2.1247,2.12480,2.000
2,20.800,0.00,2.2249,2.22500,2.000
2,20.900,0.00,2.3247,2.32480,2.000
2,21.000,-0.01,2.4247,2.42480,2.000
2,21.100,-0.01,2.5247,2.52480,2.000
2,21.200,0.00,2.6250,2.62510,2.000
2,21.300,0.00,2.7247,2.72480,2.000
2,21.400,0.00,2.8249,2.82500,2.000
2,21.500,0.00,2.9246,2.92470,2.000
2,21.600,-0.01,3.0247,3.02480,2.000
2,21.700,-0.01,3.1246,3.12470,2.000
2,21.800,-0.01,3.2249,3.22500,2.000
2,21.900,0.00,3.3248,3.32490,2.000
2,22.000,-0.01,3.4250,3.42510,2.000
2,22.100,-0.01,3.5248,3.52490,2.000
2,22.200,-0.01,3.6248,3.62490,2.000
2,22.300,-0.01,3.7247,3.72480,2.000
2,22.400,-0.01,3.8249,3.82500,2.000
2,22.500,-0.01,3.9248,3.92490,2.000
2,22.600,0.00,4.0248,4.02490,2.000
2,22.700,-0.01,4.1248,4.12490,2.000
2,22.800,0.00,4.2250,4.22510,2.000
2,22.900,0.00,4.3247,4.32480,2.000
2,23.000,-0.01,4.4248,4.42490,2.000
2,23.100,0.00,4.5248,4.52490,2.000
2,23.200,0.00,4.6248,4.62490,2.000
2,23.300,0.04,4.7247,4.72480,2.000
2,23.400,0.11,4.8249,4.82500,2.000
2,23.500,0.27,4.9247,4.92480,2.000
2,23.600,0.48,5.0248,5.02490,2.000
2,23.700,0.77,5.1248,5.12490,2.000
2,23.800,1.12,5.2249,5.22500,2.000
2,23.900,1.57,5.3249,5.32500,2.000
2,24.000,2.09,5.4250,5.42510,2.000
2,24.100,2.72,5.5248,5.52490,2.000
2,24.200,3.43,5.6249,5.62500,2.000
2,24.300,4.24,5.7248,5.72490,2.000
2,24.400,5.18,5.8248,5.82490,2.000
2,24.500,6.24,5.9247,5.92480,2.000
2,24.600,7.41,6.0249,6.02500,2.000
2,24.700,8.72,6.1248,6.12490,2.000
2,24.800,10.17,6.2249,6.22500,2.000
2,24.900,11.82,6.3249,6.32500,2.000
2,25.000,13.65,6.4251,6.42520,2.000
2,25.100,15.74,6.5248,6.52490,2.000
2,25.200,18.07,6.6248,6.62490,2.000
2,25.300,20.74,6.7248,6.72490,2.000
2,25.400,23.84,6.8250,6.82510,2.000
2,25.500,27.45,6.9248,6.92490,2.000
2,25.650,31.71,7.0213,7.02140,2.000
2,25.750,24.65,6.9236,6.92370,2.000
2,25.850,19.57,6.8237,6.82380,2.000
2,25.950,15.79,6.7236,6.72370,2.000
2,26.050,12.83,6.6236,6.62370,2.000
2,26.150,10.49,6.5237,6.52380,2.000
2,26.250,8.61,6.4239,6.42400,2.000
2,26.350,7.08,6.3236,6.32370,2.000
2,26.450,5.83,6.2236,6.22370,2.000
2,26.550,4.79,6.1237,6.12380,2.000
2,26.650,3.94,6.0237,6.02380,2.000
2,26.750,3.22,5.9235,5.92360,2.000
2,26.850,2.63,5.8236,5.82370,2.000
2,26.950,2.13,5.7235,5.72360,2.000
2,27.050,1.68,5.6236,5.62370,2.000
2,27.150,1.31,5.5235,5.52360,2.000
2,27.250,0.97,5.4237,5.42380,2.000
2,27.350,0.70,5.3235,5.32360,2.000
2,27.450,0.47,5.2236,5.22370,2.000
2,27.550,0.31,5.1235,5.12360,2.000
2,27.650,0.18,5.0235,5.02360,2.000
2,27.750,0.07,4.9234,4.92350,2.000
2,27.850,0.01,4.8235,4.82360,2.000
2,27.950,-0.01,4.7233,4.72340,2.000
2,28.050,-0.01,4.6236,4.62370,2.000
2,28.150,-0.01,4.5234,4.52350,2.000
2,28.250,0.00,4.4235,4.42360,2.000
2,28.350,-0.01,4.3234,4.32350,2.000
2,28.450,0.00,4.2235,4.22360,2.000
2,28.550,0.00,4.1233,4.12340,2.000
2,28.650,-0.01,4.0235,4.02360,2.000
2,28.750,0.00,3.9234,3.92350,2.000
2,28.850,-0.01,3.8234,3.82350,2.000
2,28.950,0.00,3.7233,3.72340,2.000
2,29.050,-0.01,3.6233,3.62340,2.000
2,29.150,-0.01,3.5233,3.52340,2.000
2,29.250,-0.01,3.4235,3.42360,2.000
2,29.350,0.00,3.3233,3.32340,2.000
2,29.450,-0.01,3.2234,3.22350,2.000
2,29.550,0.00,3.1231,3.12320,2.000
2,29.650,0.00,3.0234,3.02350,2.000
2,29.750,0.00,2.9232,2.92330,2.000
2,29.850,0.00,2.8234,2.82350,2.000
2,29.950,-0.01,2.7233,2.72340,2.000
2,30.050,-0.01,2.6235,2.62360,2.000
2,30.150,0.00,2.5232,2.52330,2.000
2,30.250,0.00,2.4233,2.42340,2.000
2,30.350,0.00,2.3231,2.32320,2.000
2,30.450,-0.01,2.2234,2.22350,2.000
2,30.550,0.00,2.1232,2.12330,2.000
2,30.650,0.00,2.0234,2.02350,2.000
2,30.750,0.00,1.9233,1.92340,2.000
2,30.850,-0.01,1.8234,1.82350,2.000
2,30.950,-0.01,1.7232,1.72330,2.000
2,31.050,0.00,1.6234,1.62350,2.000
2,31.150,0.00,1.5230,1.52310,2.000
2,31.250,0.00,1.4233,1.42340,2.000
2,31.350,-0.01,1.3232,1.32330,2.000
2,31.450,-0.01,1.2234,1.22350,2.000
2,31.550,-0.01,1.1231,1.12320,2.000
2,31.650,-0.01,1.0233,1.02340,2.000
2,31.750,-0.01,0.9231,0.92320,2.000
2,31.850,-0.01,0.8232,0.82330,2.000
2,31.950,-0.01,0.7231,0.72320,2.000
2,32.050,0.00,0.6234,0.62350,2.000
2,32.150,-0.01,0.5231,0.52320,2.000
2,32.250,-0.01,0.4233,0.42340,2.000
2,32.350,0.00,0.3231,0.32320,2.000
2,32.450,0.00,0.2233,0.22340,2.000
2,32.550,-0.01,0.1231,0.12320,2.000
2,32.650,-0.01,0.0232,0.02330,2.000
2,32.800,-0.01,-0.0029,-0.00280,2.000
2,32.900,0.00,-0.0004,-0.00030,2.000
2,33.000,-0.01,-0.0004,-0.00030,2.000
2,33.100,-0.01,-0.0004,-0.00030,2.000
2,33.200,0.00,-0.0004,-0.00030,2.000
2,33.300,0.00,-0.0004,-0.00030,2.000
2,33.400,0.00,-0.0004,-0.00030,2.000
2,33.500,-0.01,-0.0004,-0.00030,2.000
2,33.600,0.00,-0.0004,-0.00030,2.000
2,33.700,-0.01,-0.0004,-0.00030,2.000
2,33.800,-0.01,-0.0004,-0.00030,2.000
2,33.900,-0.01,-0.0004,-0.00030,2.000
2,34.000,-0.01,-0.0003,-0.00020,2.000
2,34.100,-0.01,-0.0003,-0.00020,2.000
2,34.200,-0.01,-0.0003,-0.00020,2.000
2,34.300,0.00,-0.0003,-0.00020,2.000
2,34.400,0.00,-0.0003,-0.00020,2.000
2,34.500,0.00,-0.0003,-0.00020,2.000
2,34.600,-0.01,-0.0003,-0.00020,2.000
2,34.700,-0.01,-0.0003,-0.00020,2.000
2,34.800,0.00,-0.0003,-0.00020,2.000
2,34.900,-0.01,-0.0003,-0.00020,2.000
2,35.000,0.00,-0.0003,-0.00020,2.000
2,35.100,0.00,-0.0003,-0.00020,2.000
2,35.200,-0.01,-0.0003,-0.00020,2.000
2,35.300,-0.01,-0.0003,-0.00020,2.000
2,35.400,-0.01,-0.0003,-0.00020,2.000
2,35.500,0.00,-0.0003,-0.00020,2.000
2,35.600,-0.01,-0.0003,-0.00020,2.000
2,35.700,-0.01,-0.0003,-0.00020,2.000
2,35.850,-0.01,-0.0002,-0.00010,2.000
2,35.950,-0.01,-0.0002,-0.00010,2.000
2,36.050,-0.01,-0.0002,-0.00010,2.000
2,36.150,-0.01,-0.0002,-0.00010,2.000
2,36.250,-0.01,-0.0002,-0.00010,2.000
2,36.350,0.00,-0.0002,-0.00010,2.000
2,36.450,-0.01,-0.0002,-0.00010,2.000
2,36.550,-0.01,-0.0002,-0.00010,2.000
2,36.650,0.00,-0.0002,-0.00010,2.000
2,36.750,0.00,-0.0002,-0.00010,2.000
3,37.050,0.00,0.0945,0.09460,3.000
3,37.150,-0.01,0.1945,0.19460,3.000
3,37.250,-0.01,0.2948,0.29490,3.000
3,37.350,-0.01,0.3947,0.39480,3.000
3,37.450,-0.01,0.4947,0.49480,3.000
3,37.550,0.00,0.5947,0.59480,3.000
3,37.650,-0.01,0.6948,0.69490,3.000
3,37.750,-0.01,0.7945,0.79460,3.000
3,37.850,0.00,0.8947,0.89480,3.000
3,37.950,-0.01,0.9946,0.99470,3.000
3,38.050,0.00,1.0946,1.09470,3.000
3,38.150,0.00,1.1946,1.19470,3.000
3,38.250,-0.01,1.2948,1.29490,3.000
3,38.350,0.00,1.3946,1.39470,3.000
3,38.450,0.00,1.4947,1.49480,3.000
3,38.550,-0.01,1.5946,1.59470,3.000
3,38.650,0.00,1.6947,1.69480,3.000
3,38.750,0.00,1.7947,1.79480,3.000
3,38.850,0.00,1.8947,1.89480,3.000
3,38.950,-0.01,1.9948,1.99490,3.000
3,39.050,-0.01,2.0948,2.09490,3.000
3,39.150,-0.01,2.1947,2.19480,3.000
3,39.250,-0.01,2.2948,2.29490,3.000
3,39.350,0.00,2.3947,2.39480,3.000
3,39.450,-0.01,2.4948,2.49490,3.000
3,39.550,-0.01,2.5949,2.59500,3.000
3,39.650,-0.01,2.6948,2.69490,3.000
3,39.750,-0.01,2.7949,2.79500,3.000
3,39.850,-0.01,2.8948,2.89490,3.000
3,39.950,0.00,2.9948,2.99490,3.000
3,40.050,-0.01,3.0947,3.09480,3.000
3,40.150,-0.01,3.1950,3.19510,3.000
3,40.250,0.00,3.2949,3.29500,3.000
3,40.350,0.00,3.3949,3.39500,3.000
3,40.450,0.00,3.4949,3.49500,3.000
3,40.550,-0.01,3.5950,3.59510,3.000
3,40.650,-0.01,3.6948,3.69490,3.000
3,40.750,0.00,3.7949,3.79500,3.000
3,40.850,-0.01,3.8949,3.89500,3.000
3,40.950,0.00,3.9950,3.99510,3.000
3,41.050,-0.01,4.0949,4.09500,3.000
3,41.150,-0.01,4.1950,4.19510,3.000
3,41.250,-0.01,4.2949,4.29500,3.000
3,41.350,-0.01,4.3949,4.39500,3.000
3,41.450,-0.01,4.4948,4.49490,3.000
3,41.550,-0.01,4.5949,4.59500,3.000
3,41.650,0.02,4.6948,4.69490,3.000
3,41.750,0.09,4.7950,4.79510,3.000
3,41.850,0.22,4.8948,4.89490,3.000
3,41.950,0.41,4.9949,4.99500,3.000
3,42.050,0.68,5.0947,5.09480,3.000
3,42.150,1.02,5.1949,5.19500,3.000
3,42.250,1.43,5.2949,5.29500,3.000
3,42.350,1.93,5.3949,5.39500,3.000
3,42.450,2.52,5.4948,5.49490,3.000
3,42.550,3.21,5.5950,5.59510,3.000
3,42.650,4.00,5.6948,5.69490,3.000
3,42.750,4.90,5.7949,5.79500,3.000
3,42.850,5.91,5.8947,5.89480,3.000
3,42.950,7.05,5.9950,5.99510,3.000
3,43.050,8.30,6.0949,6.09500,3.000
3,43.150,9.71,6.1950,6.19510,3.000
3,43.250,11.28,6.2948,6.29490,3.000
3,43.350,13.04,6.3951,6.39520,3.000
3,43.450,15.01,6.4948,6.49490,3.000
3,43.550,17.23,6.5949,6.59500,3.000
3,43.650,19.78,6.6949,6.69500,3.000
3,43.750,22.71,6.7949,6.79500,3.000
3,43.850,26.10,6.8948,6.89490,3.000
3,43.950,30.07,6.9950,6.99510,3.000
3,44.100,27.43,6.9735,6.97360,3.000
3,44.200,21.50,6.8738,6.87390,3.000
3,44.300,17.26,6.7735,6.77360,3.000
3,44.400,13.97,6.6738,6.67390,3.000
3,44.500,11.40,6.5735,6.57360,3.000
3,44.600,9.34,6.4737,6.47380,3.000
3,44.700,7.69,6.3736,6.37370,3.000
3,44.800,6.32,6.2736,6.27370,3.000
3,44.900,5.21,6.1734,6.17350,3.000
3,45.000,4.27,6.0737,6.07380,3.000
3,45.100,3.51,5.9734,5.97350,3.000
3,45.200,2.87,5.8735,5.87360,3.000
3,45.300,2.33,5.7734,5.77350,3.000
3,45.400,1.86,5.6735,5.67360,3.000
3,45.500,1.46,5.5733,5.57340,3.000
3,45.600,1.11,5.4736,5.47370,3.000
3,45.700,0.82,5.3735,5.37360,3.000
3,45.800,0.57,5.2737,5.27380,3.000
3,45.900,0.37,5.1735,5.17360,3.000
3,46.000,0.25,5.0734,5.07350,3.000
3,46.100,0.12,4.9733,4.97340,3.000
3,46.200,0.04,4.8735,4.87360,3.000
3,46.300,-0.01,4.7733,4.77340,3.000
3,46.400,-0.01,4.6735,4.67360,3.000
3,46.500,-0.01,4.5734,4.57350,3.000
3,46.600,-0.01,4.4734,4.47350,3.000
3,46.700,-0.01,4.3733,4.37340,3.000
3,46.800,-0.01,4.2735,4.27360,3.000
3,46.900,0.00,4.1734,4.17350,3.000
3,47.000,-0.01,4.0734,4.07350,3.000
3,47.100,-0.01,3.9733,3.97340,3.000
3,47.200,0.00,3.8734,3.87350,3.000
3,47.300,-0.01,3.7733,3.77340,3.000
3,47.400,-0.01,3.6734,3.67350,3.000
3,47.500,-0.01,3.5733,3.57340,3.000
3,47.600,0.00,3.4733,3.47340,3.000
3,47.700,-0.01,3.3734,3.37350,3.000
3,47.800,-0.01,3.2734,3.27350,3.000
3,47.900,-0.01,3.1733,3.17340,3.000
3,48.000,0.00,3.0733,3.07340,3.000
3,48.100,0.00,2.9732,2.97330,3.000
3,48.200,0.00,2.8733,2.87340,3.000
3,48.300,0.00,2.7733,2.77340,3.000
3,48.400,-0.01,2.6735,2.67360,3.000
3,48.500,-0.01,2.5733,2.57340,3.000
3,48.600,0.00,2.4734,2.47350,3.000
3,48.700,-0.01,2.3733,2.37340,3.000
3,48.800,-0.01,2.2733,2.27340,3.000
3,48.900,0.00,2.1733,2.17340,3.000
3,49.000,0.00,2.0735,2.07360,3.000
3,49.100,0.00,1.9733,1.97340,3.000
3,49.200,-0.01,1.8733,1.87340,3.000
3,49.300,-0.01,1.7733,1.77340,3.000
3,49.400,0.00,1.6733,1.67340,3.000
3,49.500,0.00,1.5733,1.57340,3.000
3,49.600,-0.01,1.4732,1.47330,3.000
3,49.700,-0.01,1.3732,1.37330,3.000
3,49.800,0.00,1.2733,1.27340,3.000
3,49.900,0.00,1.1733,1.17340,3.000
3,50.000,0.00,1.0733,1.07340,3.000
3,50.100,0.00,0.9732,0.97330,3.000
3,50.200,-0.01,0.8732,0.87330,3.000
3,50.300,0.00,0.7732,0.77330,3.000
3,50.400,0.00,0.6733,0.67340,3.000
3,50.500,0.00,0.5733,0.57340,3.000
3,50.600,-0.01,0.4731,0.47320,3.000
3,50.700,-0.01,0.3732,0.37330,3.000
3,50.800,0.00,0.2731,0.27320,3.000
3,50.900,0.00,0.1731,0.17320,3.000
3,51.000,-0.01,0.0732,0.07330,3.000
3,51.150,-0.01,-0.0368,-0.03670,3.000
3,51.250,-0.01,-0.0004,-0.00030,3.000
3,51.350,0.00,-0.0004,-0.00030,3.000
3,51.450,-0.01,-0.0004,-0.00030,3.000
3,51.550,0.00,-0.0004,-0.00030,3.000
3,51.650,-0.01,-0.0004,-0.00030,3.000
3,51.750,0.00,-0.0004,-0.00030,3.000
3,51.850,-0.01,-0.0004,-0.00030,3.000
3,51.950,0.00,-0.0004,-0.00030,3.000
3,52.050,-0.01,-0.0004,-0.00030,3.000
3,52.150,-0.01,-0.0004,-0.00030,3.000
3,52.250,-0.01,-0.0004,-0.00030,3.000
3,52.350,0.00,-0.0004,-0.00030,3.000
3,52.450,-0.01,-0.0004,-0.00030,3.000
3,52.550,-0.01,-0.0003,-0.00020,3.000
3,52.650,0.00,-0.0003,-0.00020,3.000
3,52.750,0.00,-0.0003,-0.00020,3.000
3,52.850,-0.01,-0.0003,-0.00020,3.000
3,52.950,-0.01,-0.0003,-0.00020,3.000
3,53.050,-0.01,-0.0003,-0.00020,3.000
3,53.150,0.00,-0.0003,-0.00020,3.000
3,53.250,-0.01,-0.0003,-0.00020,3.000
3,53.350,-0.01,-0.0003,-0.00020,3.000
3,53.450,0.00,-0.0003,-0.00020,3.000
3,53.550,0.00,-0.0003,-0.00020,3.000
3,53.650,-0.01,-0.0003,-0.00020,3.000
3,53.750,0.00,-0.0003,-0.00020,3.000
3,53.850,-0.01,-0.0003,-0.00020,3.000
3,53.950,-0.01,-0.0003,-0.00020,3.000
3,54.050,-0.01,-0.0003,-0.00020,3.000
3,54.200,-0.01,-0.0003,-0.00020,3.000
3,54.300,-0.01,-0.0002,-0.00010,3.000
3,54.400,0.00,-0.0002,-0.00010,3.000
3,54.500,0.00,-0.0002,-0.00010,3.000
3,54.600,0.00,-0.0002,-0.00010,3.000
3,54.700,-0.01,-0.0002,-0.00010,3.000
3,54.800,-0.01,-0.0002,-0.00010,3.000
3,54.900,-0.01,-0.0002,-0.00010,3.000
3,55.000,0.00,-0.0002,-0.00010,3.000
3,55.100,-0.01,-0.0002,-0.00010,3.000
4,55.400,0.00,0.0456,0.04570,4.000
4,55.500,0.00,0.1456,0.14570,4.000
4,55.600,0.01,0.2455,0.24560,4.000
4,55.700,0.01,0.3458,0.34590,4.000
4,55.800,0.00,0.4456,0.44570,4.000
4,55.900,0.01,0.5458,0.54590,4.000
4,56.000,0.00,0.6458,0.64590,4.000
4,56.100,0.00,0.7457,0.74580,4.000
4,56.200,0.00,0.8456,0.84570,4.000
4,56.300,0.00,0.9458,0.94590,4.000
4,56.400,0.00,1.0456,1.04570,4.000
4,56.500,0.00,1.1458,1.14590,4.000
4,56.600,0.00,1.2457,1.24580,4.000
4,56.700,0.01,1.3458,1.34590,4.000
4,56.800,0.00,1.4456,1.44570,4.000
4,56.900,0.00,1.5458,1.54590,4.000
4,57.000,0.00,1.6456,1.64570,4.000
4,57.100,0.00,1.7457,1.74580,4.000
4,57.200,0.00,1.8456,1.84570,4.000
4,57.300,0.00,1.9457,1.94580,4.000
4,57.400,0.00,2.0457,2.04580,4.000
4,57.500,0.00,2.1460,2.14610,4.000
4,57.600,0.00,2.2456,2.24570,4.000
4,57.700,0.00,2.3457,2.34580,4.000
4,57.800,0.00,2.4456,2.44570,4.000
4,57.900,0.00,2.5459,2.54600,4.000
4,58.000,0.00,2.6458,2.64590,4.000
4,58.100,0.00,2.7460,2.74610,4.000
4,58.200,0.00,2.8458,2.84590,4.000
4,58.300,0.00,2.9459,2.94600,4.000
4,58.400,0.00,3.0456,3.04570,4.000
4,58.500,0.00,3.1458,3.14590,4.000
4,58.600,0.00,3.2458,3.24590,4.000
4,58.700,0.00,3.3459,3.34600,4.000
4,58.800,0.00,3.4459,3.44600,4.000
4,58.900,0.00,3.5459,3.54600,4.000
4,59.000,0.00,3.6457,3.64580,4.000
4,59.100,0.01,3.7459,3.74600,4.000
4,59.200,0.00,3.8458,3.84590,4.000
4,59.300,0.00,3.9459,3.94600,4.000
4,59.400,0.00,4.0457,4.04580,4.000
4,59.500,0.00,4.1460,4.14610,4.000
4,59.600,0.00,4.2458,4.24590,4.000
4,59.700,0.00,4.3458,4.34590,4.000
4,59.800,0.00,4.4458,4.44590,4.000
4,59.900,0.00,4.5460,4.54610,4.000
4,60.000,0.01,4.6459,4.64600,4.000
4,60.100,0.07,4.7458,4.74590,4.000
4,60.200,0.16,4.8458,4.84590,4.000
4,60.300,0.33,4.9458,4.94590,4.000
4,60.400,0.55,5.0457,5.04580,4.000
4,60.500,0.85,5.1458,5.14590,4.000
4,60.600,1.22,5.2458,5.24590,4.000
4,60.700,1.68,5.3460,5.34610,4.000
4,60.800,2.22,5.4458,5.44590,4.000
4,60.900,2.86,5.5459,5.54600,4.000
4,61.000,3.60,5.6457,5.64580,4.000
4,61.100,4.44,5.7458,5.74590,4.000
4,61.200,5.39,5.8457,5.84580,4.000
4,61.300,6.46,5.9459,5.94600,4.000
4,61.400,7.64,6.0459,6.04600,4.000
4,61.500,8.94,6.1459,6.14600,4.000
4,61.600,10.41,6.2459,6.24600,4.000
4,61.700,12.04,6.3459,6.34600,4.000
4,61.800,13.88,6.4460,6.44610,4.000
4,61.900,15.94,6.5459,6.54600,4.000
4,62.000,18.34,6.6458,6.64590,4.000
4,62.100,21.02,6.7459,6.74600,4.000
4,62.200,24.13,6.8458,6.84590,4.000
4,62.300,27.71,6.9458,6.94590,4.000
4,62.450,31.93,7.0406,7.04070,4.000
4,62.550,24.77,6.9426,6.94270,4.000
4,62.650,19.66,6.8426,6.84270,4.000
4,62.750,15.85,6.7426,6.74270,4.000
4,62.850,12.89,6.6426,6.64270,4.000
4,62.950,10.54,6.5425,6.54260,4.000
4,63.050,8.66,6.4427,6.44280,4.000
4,63.150,7.14,6.3426,6.34270,4.000
4,63.250,5.88,6.2427,6.24280,4.000
4,63.350,4.85,6.1427,6.14280,4.000
4,63.450,3.98,6.0426,6.04270,4.000
4,63.550,3.26,5.9426,5.94270,4.000
4,63.650,2.67,5.8426,5.84270,4.000
4,63.750,2.17,5.7425,5.74260,4.000
4,63.850,1.72,5.6424,5.64250,4.000
4,63.950,1.33,5.5425,5.54260,4.000
4,64.050,1.01,5.4426,5.44270,4.000
4,64.150,0.74,5.3426,5.34270,4.000
4,64.250,0.51,5.2426,5.24270,4.000
4,64.350,0.35,5.1426,5.14270,4.000
4,64.450,0.21,5.0424,5.04250,4.000
4,64.550,0.09,4.9426,4.94270,4.000
4,64.650,0.03,4.8425,4.84260,4.000
4,64.750,-0.01,4.7425,4.74260,4.000
4,64.850,0.00,4.6425,4.64260,4.000
4,64.950,0.00,4.5425,4.54260,4.000
4,65.050,0.00,4.4425,4.44260,4.000
4,65.150,0.00,4.3423,4.34240,4.000
4,65.250,0.00,4.2425,4.24260,4.000
4,65.350,0.00,4.1424,4.14250,4.000
4,65.450,0.01,4.0425,4.04260,4.000
4,65.550,0.00,3.9424,3.94250,4.000
4,65.650,0.00,3.8424,3.84250,4.000
4,65.750,0.00,3.7423,3.74240,4.000
4,65.850,0.00,3.6423,3.64240,4.000
4,65.950,0.00,3.5425,3.54260,4.000
4,66.050,0.00,3.4424,3.44250,4.000
4,66.150,0.00,3.3424,3.34250,4.000
4,66.250,0.00,3.2424,3.24250,4.000
4,66.350,0.00,3.1423,3.14240,4.000
4,66.450,0.00,3.0423,3.04240,4.000
4,66.550,0.00,2.9424,2.94250,4.000
4,66.650,0.00,2.8423,2.84240,4.000
4,66.750,0.00,2.7423,2.74240,4.000
4,66.850,0.00,2.6423,2.64240,4.000
4,66.950,0.00,2.5424,2.54250,4.000
4,67.050,0.00,2.4423,2.44240,4.000
4,67.150,0.01,2.3424,2.34250,4.000
4,67.250,0.00,2.2422,2.24230,4.000
4,67.350,0.00,2.1425,2.14260,4.000
4,67.450,0.01,2.0423,2.04240,4.000
4,67.550,0.00,1.9424,1.94250,4.000
4,67.650,0.00,1.8422,1.84230,4.000
4,67.750,0.00,1.7423,1.74240,4.000
4,67.850,0.00,1.6421,1.64220,4.000
4,67.950,0.01,1.5422,1.54230,4.000
4,68.050,0.00,1.4422,1.44230,4.000
4,68.150,0.00,1.3423,1.34240,4.000
4,68.250,0.01,1.2422,1.24230,4.000
4,68.350,0.00,1.1423,1.14240,4.000
4,68.450,0.00,1.0421,1.04220,4.000
4,68.550,0.01,0.9423,0.94240,4.000
4,68.650,0.00,0.8421,0.84220,4.000
4,68.750,0.01,0.7422,0.74230,4.000
4,68.850,0.00,0.6422,0.64230,4.000
4,68.950,0.01,0.5423,0.54240,4.000
4,69.050,0.00,0.4421,0.44220,4.000
4,69.150,0.01,0.3424,0.34250,4.000
4,69.250,0.00,0.2422,0.24230,4.000
4,69.350,0.00,0.1423,0.14240,4.000
4,69.450,0.01,0.0421,0.04220,4.000
4,69.600,0.00,-0.0474,-0.04730,4.000
4,69.700,0.00,-0.0004,-0.00030,4.000
4,69.800,0.00,-0.0004,-0.00030,4.000
4,69.900,0.00,-0.0004,-0.00030,4.000
4,70.000,0.00,-0.0004,-0.00030,4.000
4,70.100,0.00,-0.0004,-0.00030,4.000
4,70.200,0.00,-0.0004,-0.00030,4.000
4,70.300,0.00,-0.0004,-0.00030,4.000
4,70.400,0.00,-0.0004,-0.00030,4.000
4,70.500,0.00,-0.0004,-0.00030,4.000
4,70.600,0.00,-0.0004,-0.00030,4.000
4,70.700,0.00,-0.0004,-0.00030,4.000
4,70.800,0.00,-0.0004,-0.00030,4.000
4,70.900,0.01,-0.0004,-0.00030,4.000
4,71.000,0.01,-0.0004,-0.00030,4.000
4,71.100,0.00,-0.0003,-0.00020,4.000
4,71.200,0.00,-0.0003,-0.00020,4.000
4,71.300,0.01,-0.0003,-0.00020,4.000
4,71.400,0.00,-0.0003,-0.00020,4.000
4,71.500,0.00,-0.0003,-0.00020,4.000
4,71.600,0.00,-0.0003,-0.00020,4.000
4,71.700,0.00,-0.0003,-0.00020,4.000
4,71.800,0.00,-0.0003,-0.00020,4.000
4,71.900,0.00,-0.0003,-0.00020,4.000
4,72.000,0.00,-0.0003,-0.00020,4.000
4,72.100,0.00,-0.0003,-0.00020,4.000
4,72.200,0.00,-0.0003,-0.00020,4.000
4,72.300,0.00,-0.0003,-0.00020,4.000
4,72.400,0.01,-0.0003,-0.00020,4.000
4,72.500,0.00,-0.0003,-0.00020,4.000
4,72.650,0.00,-0.0003,-0.00020,4.000
4,72.750,0.01,-0.0003,-0.00020,4.000
4,72.850,0.00,-0.0003,-0.00020,4.000
4,72.950,0.00,-0.0002,-0.00010,4.000
4,73.050,0.00,-0.0002,-0.00010,4.000
4,73.150,0.00,-0.0002,-0.00010,4.000
4,73.250,0.01,-0.0002,-0.00010,4.000
4,73.350,0.01,-0.0002,-0.00010,4.000
4,73.450,0.01,-0.0002,-0.00010,4.000
4,73.550,0.01,-0.0002,-0.00010,4.000
5,73.850,0.00,0.0946,0.09470,5.000
5,73.950,0.00,0.1945,0.19460,5.000
5,74.050,0.00,0.2947,0.29480,5.000
5,74.150,0.00,0.3947,0.39480,5.000
5,74.250,0.00,0.4947,0.49480,5.000
5,74.350,0.00,0.5948,0.59490,5.000
5,74.450,0.00,0.6948,0.69490,5.000
5,74.550,0.00,0.7946,0.79470,5.000
5,74.650,0.00,0.8947,0.89480,5.000
5,74.750,0.00,0.9946,0.99470,5.000
5,74.850,0.00,1.0947,1.09480,5.000
5,74.950,0.00,1.1947,1.19480,5.000
5,75.050,0.00,1.2948,1.29490,5.000
5,75.150,0.00,1.3947,1.39480,5.000
5,75.250,0.00,1.4947,1.49480,5.000
5,75.350,0.00,1.5947,1.59480,5.000
5,75.450,0.00,1.6948,1.69490,5.000
5,75.550,0.00,1.7949,1.79500,5.000
5,75.650,0.00,1.8947,1.89480,5.000
5,75.750,0.00,1.9948,1.99490,5.000
5,75.850,0.00,2.0948,2.09490,5.000
5,75.950,0.00,2.1949,2.19500,5.000
5,76.050,0.00,2.2947,2.29480,5.000
5,76.150,0.00,2.3948,2.39490,5.000
5,76.250,0.00,2.4947,2.49480,5.000
5,76.350,0.00,2.5949,2.59500,5.000
5,76.450,0.00,2.6948,2.69490,5.000
5,76.550,0.00,2.7949,2.79500,5.000
5,76.650,0.00,2.8948,2.89490,5.000
5,76.750,0.00,2.9948,2.99490,5.000
5,76.850,0.00,3.0947,3.09480,5.000
5,76.950,0.00,3.1950,3.19510,5.000
5,77.050,0.00,3.2948,3.29490,5.000
5,77.150,0.00,3.3949,3.39500,5.000
5,77.250,0.00,3.4948,3.49490,5.000
5,77.350,0.00,3.5949,3.59500,5.000
5,77.450,0.00,3.6947,3.69480,5.000
5,77.550,0.00,3.7948,3.79490,5.000
5,77.650,0.00,3.8948,3.89490,5.000
5,77.750,0.00,3.9949,3.99500,5.000
5,77.850,0.00,4.0949,4.09500,5.000
5,77.950,0.00,4.1950,4.19510,5.000
5,78.050,0.00,4.2948,4.29490,5.000
5,78.150,0.00,4.3950,4.39510,5.000
5,78.250,0.00,4.4949,4.49500,5.000
5,78.350,0.00,4.5949,4.59500,5.000
5,78.450,0.03,4.6949,4.69500,5.000
5,78.550,0.10,4.7950,4.79510,5.000
5,78.650,0.24,4.8947,4.89480,5.000
5,78.750,0.43,4.9949,4.99500,5.000
5,78.850,0.70,5.0948,5.09490,5.000
5,78.950,1.03,5.1950,5.19510,5.000
5,79.050,1.44,5.2949,5.29500,5.000
5,79.150,1.94,5.3950,5.39510,5.000
5,79.250,2.53,5.4948,5.49490,5.000
5,79.350,3.22,5.5950,5.59510,5.000
5,79.450,4.00,5.6947,5.69480,5.000
5,79.550,4.90,5.7950,5.79510,5.000
5,79.650,5.91,5.8947,5.89480,5.000
5,79.750,7.03,5.9950,5.99510,5.000
5,79.850,8.27,6.0948,6.09490,5.000
5,79.950,9.64,6.1949,6.19500,5.000
5,80.050,11.17,6.2947,6.29480,5.000
5,80.150,12.88,6.3951,6.39520,5.000
5,80.250,14.84,6.4947,6.49480,5.000
5,80.350,17.06,6.5949,6.59500,5.000
5,80.450,19.57,6.6948,6.69490,5.000
5,80.550,22.42,6.7949,6.79500,5.000
5,80.650,25.73,6.8948,6.89490,5.000
5,80.750,29.58,6.9949,6.99500,5.000
5,80.900,27.02,6.9735,6.97360,5.000
5,81.000,21.21,6.8737,6.87380,5.000
5,81.100,17.02,6.7735,6.77360,5.000
5,81.200,13.80,6.6737,6.67380,5.000
5,81.300,11.27,6.5735,6.57360,5.000
5,81.400,9.24,6.4737,6.47380,5.000
5,81.500,7.62,6.3736,6.37370,5.000
5,81.600,6.27,6.2736,6.27370,5.000
5,81.700,5.17,6.1736,6.17370,5.000
5,81.800,4.24,6.0737,6.07380,5.000
5,81.900,3.48,5.9734,5.97350,5.000
5,82.000,2.84,5.8736,5.87370,5.000
5,82.100,2.33,5.7734,5.77350,5.000
5,82.200,1.85,5.6736,5.67370,5.000
5,82.300,1.45,5.5735,5.57360,5.000
5,82.400,1.11,5.4735,5.47360,5.000
5,82.500,0.82,5.3736,5.37370,5.000
5,82.600,0.57,5.2737,5.27380,5.000
5,82.700,0.38,5.1734,5.17350,5.000
5,82.800,0.26,5.0734,5.07350,5.000
5,82.900,0.13,4.9733,4.97340,5.000
5,83.000,0.05,4.8736,4.87370,5.000
5,83.100,0.00,4.7733,4.77340,5.000
5,83.200,-0.01,4.6735,4.67360,5.000
5,83.300,0.00,4.5734,4.57350,5.000
5,83.400,0.00,4.4735,4.47360,5.000
5,83.500,0.00,4.3732,4.37330,5.000
5,83.600,0.00,4.2735,4.27360,5.000
5,83.700,0.00,4.1734,4.17350,5.000
5,83.800,0.00,4.0734,4.07350,5.000
5,83.900,0.00,3.9733,3.97340,5.000
5,84.000,0.00,3.8734,3.87350,5.000
5,84.100,0.00,3.7732,3.77330,5.000
5,84.200,0.00,3.6733,3.67340,5.000
5,84.300,0.00,3.5733,3.57340,5.000
5,84.400,0.00,3.4734,3.47350,5.000
5,84.500,0.00,3.3733,3.37340,5.000
5,84.600,0.00,3.2735,3.27360,5.000
5,84.700,0.00,3.1733,3.17340,5.000
5,84.800,0.00,3.0734,3.07350,5.000
5,84.900,0.00,2.9732,2.97330,5.000
5,85.000,0.00,2.8734,2.87350,5.000
5,85.100,0.00,2.7732,2.77330,5.000
5,85.200,0.00,2.6734,2.67350,5.000
5,85.300,0.00,2.5733,2.57340,5.000
5,85.400,0.00,2.4733,2.47340,5.000
5,85.500,0.00,2.3732,2.37330,5.000
5,85.600,0.00,2.2734,2.27350,5.000
5,85.700,0.00,2.1732,2.17330,5.000
5,85.800,0.00,2.0734,2.07350,5.000
5,85.900,0.00,1.9733,1.97340,5.000
5,86.000,0.00,1.8733,1.87340,5.000
5,86.100,0.00,1.7732,1.77330,5.000
5,86.200,0.00,1.6733,1.67340,5.000
5,86.300,0.00,1.5733,1.57340,5.000
5,86.400,0.00,1.4732,1.47330,5.000
5,86.500,0.00,1.3733,1.37340,5.000
5,86.600,0.00,1.2732,1.27330,5.000
5,86.700,0.00,1.1732,1.17330,5.000
5,86.800,0.00,1.0733,1.07340,5.000
5,86.900,0.00,0.9732,0.97330,5.000
5,87.000,0.00,0.8731,0.87320,5.000
5,87.100,0.00,0.7731,0.77320,5.000
5,87.200,0.00,0.6733,0.67340,5.000
5,87.300,0.01,0.5733,0.57340,5.000
5,87.400,0.00,0.4732,0.47330,5.000
5,87.500,0.01,0.3732,0.37330,5.000
5,87.600,0.00,0.2731,0.27320,5.000
5,87.700,0.00,0.1732,0.17330,5.000
5,87.800,0.00,0.0732,0.07330,5.000
5,87.950,0.00,-0.0382,-0.03810,5.000
5,88.050,0.00,-0.0004,-0.00030,5.000
5,88.150,0.00,-0.0004,-0.00030,5.000
5,88.250,0.00,-0.0004,-0.00030,5.000
5,88.350,0.00,-0.0004,-0.00030,5.000
5,88.450,0.00,-0.0004,-0.00030,5.000
5,88.550,0.00,-0.0004,-0.00030,5.000
5,88.650,0.00,-0.0004,-0.00030,5.000
5,88.750,0.00,-0.0004,-0.00030,5.000
5,88.850,0.01,-0.0004,-0.00030,5.000
5,88.950,0.01,-0.0004,-0.00030,5.000
5,89.050,0.00,-0.0003,-0.00020,5.000
5,89.150,0.00,-0.0003,-0.00020,5.000
5,89.250,0.00,-0.0003,-0.00020,5.000
5,89.350,0.01,-0.0003,-0.00020,5.000
5,89.450,0.00,-0.0003,-0.00020,5.000
5,89.550,0.00,-0.0003,-0.00020,5.000
5,89.650,0.00,-0.0003,-0.00020,5.000
5,89.750,0.00,-0.0003,-0.00020,5.000
5,89.850,0.00,-0.0003,-0.00020,5.000
5,89.950,0.00,-0.0003,-0.00020,5.000
5,90.050,0.00,-0.0003,-0.00020,5.000
5,90.150,0.00,-0.0003,-0.00020,5.000
5,90.250,0.00,-0.0003,-0.00020,5.000
5,90.350,0.00,-0.0003,-0.00020,5.000
5,90.450,0.00,-0.0003,-0.00020,5.000
5,90.550,0.00,-0.0003,-0.00020,5.000
5,90.650,0.01,-0.0003,-0.00020,5.000
5,90.750,0.00,-0.0003,-0.00020,5.000
5,90.850,0.00,-0.0003,-0.00020,5.000
5,91.000,0.00,-0.0002,-0.00010,5.000
5,91.100,0.00,-0.0002,-0.00010,5.000
5,91.200,0.00,-0.0002,-0.00010,5.000
5,91.300,0.00,-0.0002,-0.00010,5.000
5,91.400,0.00,-0.0002,-0.00010,5.000
5,91.500,0.00,-0.0002,-0.00010,5.000
5,91.600,0.00,-0.0002,-0.00010,5.000
5,91.700,0.00,-0.0002,-0.00010,5.000
5,91.800,0.00,-0.0002,-0.00010,5.000
5,91.900,0.00,-0.0002,-0.00010,5.000
5,91.950,0.00,-0.0002,-0.00010,5.000