File: AIME_journal_files/AIME_data/calibDATA_loadcell/date_02:15:2018/Instron_02.15.2018/1_50N_2__1mm.s_0_0.txt
""
"Test Method","Radhen_Load_Cntrl_Cmprsn_250N_12-7.msm"
"Sample I. D.","Sample1.mss"
"Specimen Number","4"

"TheCycle_Output ()","_Time (s)","_Load (N)","_Extension (mm)","RealTimeDepth (mm)","CycleNumber ()"

1,0.333,0.00,0.1016,0.10160,1.000
1,0.467,0.00,0.2351,0.23507,1.000
1,0.600,0.00,0.3685,0.36850,1.000
1,0.733,0.00,0.5019,0.50187,1.000
1,0.867,0.00,0.6351,0.63513,1.000
1,1.000,0.01,0.7685,0.76850,1.000
1,1.133,0.04,0.9018,0.90180,1.000
1,1.267,0.09,1.0352,1.03517,1.000
1,1.400,0.17,1.1688,1.16880,1.000
1,1.533,0.29,1.3019,1.30193,1.000
1,1.667,0.42,1.4352,1.43517,1.000
1,1.800,0.61,1.5685,1.56850,1.000
1,1.933,0.82,1.7019,1.70193,1.000
1,2.067,1.09,1.8352,1.83520,1.000
1,2.200,1.41,1.9687,1.96870,1.000
1,2.333,1.79,2.1020,2.10200,1.000
1,2.467,2.23,2.2353,2.23527,1.000
1,2.600,2.77,2.3687,2.36870,1.000
1,2.733,3.43,2.5021,2.50213,1.000
1,2.867,4.20,2.6354,2.63543,1.000
1,3.000,4.97,2.7688,2.76880,1.000
1,3.133,5.74,2.9020,2.90197,1.000
1,3.267,6.83,3.0353,3.03527,1.000
1,3.400,8.20,3.1688,3.16880,1.000
1,3.533,9.85,3.3021,3.30213,1.000
1,3.667,11.83,3.4353,3.43527,1.000
1,3.800,14.17,3.5686,3.56860,1.000
1,3.933,16.90,3.7021,3.70210,1.000
1,4.067,20.07,3.8353,3.83530,1.000
1,4.200,23.72,3.9687,3.96870,1.000
1,4.333,27.96,4.1021,4.10213,1.000
1,4.467,32.83,4.2354,4.23537,1.000
1,4.600,38.50,4.3689,4.36890,1.000
1,4.733,45.00,4.5021,4.50213,1.000
1,4.933,50.82,4.5978,4.59780,1.000
1,5.067,38.90,4.4650,4.46497,1.000
1,5.200,30.90,4.3316,4.33160,1.000
1,5.333,24.86,4.1982,4.19820,1.000
1,5.467,20.08,4.0650,4.06500,1.000
1,5.600,16.25,3.9316,3.93160,1.000
1,5.733,13.18,3.7981,3.79813,1.000
1,5.867,10.70,3.6649,3.66493,1.000
1,6.000,8.66,3.5315,3.53150,1.000
1,6.133,6.98,3.3981,3.39810,1.000
1,6.267,5.58,3.2649,3.26493,1.000
1,6.400,4.43,3.1314,3.13140,1.000
1,6.533,3.48,2.9980,2.99800,1.000
1,6.667,2.68,2.8646,2.86463,1.000
1,6.800,2.03,2.7315,2.73150,1.000
1,6.933,1.47,2.5981,2.59810,1.000
1,7.067,1.03,2.4648,2.46483,1.000
1,7.200,0.68,2.3315,2.33150,1.000
1,7.333,0.39,2.1979,2.19787,1.000
1,7.467,0.18,2.0647,2.06473,1.000
1,7.600,0.05,1.9315,1.93150,1.000
1,7.733,0.01,1.7979,1.79790,1.000
1,7.867,0.00,1.6648,1.66480,1.000
1,8.000,0.00,1.5313,1.53130,1.000
1,8.133,0.00,1.3979,1.39793,1.000
1,8.267,0.00,1.2647,1.26467,1.000
1,8.400,0.00,1.1315,1.13150,1.000
1,8.533,0.00,0.9979,0.99793,1.000
1,8.667,0.00,0.8646,0.86457,1.000
1,8.800,0.00,0.7315,0.73150,1.000
1,8.933,0.00,0.5979,0.59793,1.000
1,9.067,0.00,0.4647,0.46467,1.000
1,9.200,0.00,0.3314,0.33140,1.000
1,9.333,0.01,0.1978,0.19780,1.000
1,9.467,0.00,0.0645,0.06447,1.000
1,9.667,0.00,-0.0071,-0.00710,1.000
1,9.800,0.00,-0.0003,-0.00030,1.000
1,9.933,0.00,-0.0003,-0.00030,1.000
1,10.067,0.00,-0.0003,-0.00030,1.000
1,10.200,0.00,-0.0003,-0.00030,1.000
1,10.333,0.00,-0.0003,-0.00030,1.000
1,10.467,0.00,-0.0003,-0.00030,1.000
1,10.600,0.00,-0.0003,-0.00030,1.000
1,10.733,0.00,-0.0003,-0.00030,1.000
1,10.867,0.01,-0.0003,-0.00030,1.000
1,11.000,0.01,-0.0003,-0.00030,1.000
1,11.133,0.00,-0.0003,-0.00030,1.000
1,11.267,0.00,-0.0003,-0.00030,1.000
1,11.400,0.00,-0.0003,-0.00030,1.000
1,11.533,0.00,-0.0002,-0.00020,1.000
1,11.667,0.00,-0.0002,-0.00020,1.000
1,11.800,0.01,-0.0002,-0.00020,1.000
1,11.933,0.00,-0.0002,-0.00020,1.000
1,12.067,0.00,-0.0002,-0.00020,1.000
1,12.200,0.01,-0.0002,-0.00020,1.000
1,12.333,0.00,-0.0002,-0.00020,1.000
1,12.467,0.00,-0.0002,-0.00020,1.000
1,12.600,0.00,-0.0002,-0.00020,1.000
1,12.800,0.00,-0.0002,-0.00020,1.000
1,12.933,0.00,-0.0002,-0.00020,1.000
1,13.067,0.00,-0.0002,-0.00020,1.000
1,13.200,0.00,-0.0002,-0.00020,1.000
1,13.333,0.00,-0.0002,-0.00020,1.000
1,13.467,0.00,-0.0002,-0.00020,1.000
1,13.600,0.00,-0.0002,-0.00020,1.000
2,14.000,0.00,0.1787,0.17870,2.000
2,14.133,0.00,0.3120,0.31197,2.000
2,14.267,0.00,0.4453,0.44533,2.000
2,14.400,0.00,0.5787,0.57870,2.000
2,14.533,0.00,0.7120,0.71203,2.000
2,14.667,0.00,0.8454,0.84537,2.000
2,14.800,0.00,0.9788,0.97880,2.000
2,14.933,0.00,1.1121,1.11210,2.000
2,15.067,0.00,1.2455,1.24547,2.000
2,15.200,0.00,1.3788,1.37880,2.000
2,15.333,0.00,1.5119,1.51193,2.000
2,15.467,0.00,1.6454,1.64540,2.000
2,15.600,0.05,1.7787,1.77870,2.000
2,15.733,0.14,1.9121,1.91207,2.000
2,15.867,0.38,2.0455,2.04550,2.000
2,16.000,0.73,2.1787,2.17870,2.000
2,16.133,1.20,2.3121,2.31207,2.000
2,16.267,1.80,2.4455,2.44550,2.000
2,16.400,2.52,2.5789,2.57890,2.000
2,16.533,3.38,2.7122,2.71220,2.000
2,16.667,4.39,2.8453,2.84530,2.000
2,16.800,5.57,2.9788,2.97880,2.000
2,16.933,7.00,3.1121,3.11207,2.000
2,17.067,8.64,3.2454,3.24540,2.000
2,17.200,10.53,3.3789,3.37890,2.000
2,17.333,12.75,3.5121,3.51207,2.000
2,17.467,15.31,3.6454,3.64537,2.000
2,17.600,18.27,3.7789,3.77890,2.000
2,17.733,21.71,3.9121,3.91213,2.000
2,17.867,25.66,4.0454,4.04543,2.000
2,18.000,30.22,4.1788,4.17880,2.000
2,18.133,35.59,4.3122,4.31217,2.000
2,18.267,41.89,4.4455,4.44547,2.000
2,18.400,49.45,4.5789,4.57890,2.000
2,18.600,44.97,4.5435,4.54350,2.000
2,18.733,35.22,4.4103,4.41033,2.000
2,18.867,28.15,4.2770,4.27697,2.000
2,19.000,22.70,4.1437,4.14370,2.000
2,19.133,18.37,4.0103,4.01030,2.000
2,19.267,14.87,3.8769,3.87690,2.000
2,19.400,12.06,3.7436,3.74360,2.000
2,19.533,9.78,3.6102,3.61023,2.000
2,19.667,7.90,3.4768,3.47677,2.000
2,19.800,6.33,3.3436,3.34360,2.000
2,19.933,5.04,3.2102,3.21020,2.000
2,20.067,3.98,3.0768,3.07680,2.000
2,20.200,3.09,2.9435,2.94350,2.000
2,20.333,2.37,2.8100,2.81003,2.000
2,20.467,1.78,2.6768,2.67680,2.000
2,20.600,1.28,2.5435,2.54350,2.000
2,20.733,0.86,2.4101,2.41013,2.000
2,20.867,0.53,2.2768,2.27677,2.000
2,21.000,0.27,2.1435,2.14350,2.000
2,21.133,0.10,2.0102,2.01020,2.000
2,21.267,0.03,1.8766,1.87660,2.000
2,21.400,-0.01,1.7435,1.74350,2.000
2,21.533,0.00,1.6101,1.61007,2.000
2,21.667,-0.01,1.4766,1.47663,2.000
2,21.800,0.00,1.3433,1.34330,2.000
2,21.933,0.00,1.2102,1.21017,2.000
2,22.067,0.00,1.0767,1.07667,2.000
2,22.200,0.00,0.9433,0.94330,2.000
2,22.333,0.00,0.8101,0.81007,2.000
2,22.467,0.00,0.6766,0.67663,2.000
2,22.600,0.00,0.5433,0.54330,2.000
2,22.733,0.00,0.4100,0.41000,2.000
2,22.867,0.00,0.2766,0.27660,2.000
2,23.000,0.00,0.1432,0.14320,2.000
2,23.133,0.00,0.0100,0.00997,2.000
2,23.333,0.00,-0.0005,-0.00047,2.000
2,23.467,0.00,-0.0003,-0.00030,2.000
2,23.600,0.00,-0.0003,-0.00030,2.000
2,23.733,0.00,-0.0003,-0.00030,2.000
2,23.867,0.00,-0.0003,-0.00030,2.000
2,24.000,0.00,-0.0003,-0.00030,2.000
2,24.133,0.00,-0.0003,-0.00030,2.000
2,24.267,0.00,-0.0003,-0.00030,2.000
2,24.400,0.00,-0.0003,-0.00030,2.000
2,24.533,0.00,-0.0003,-0.00030,2.000
2,24.667,0.00,-0.0003,-0.00030,2.000
2,24.800,0.00,-0.0003,-0.00030,2.000
2,24.933,0.00,-0.0003,-0.00030,2.000
2,25.067,0.00,-0.0003,-0.00030,2.000
2,25.200,0.00,-0.0003,-0.00030,2.000
2,25.333,0.00,-0.0003,-0.00030,2.000
2,25.467,0.00,-0.0002,-0.00020,2.000
2,25.600,0.00,-0.0002,-0.00020,2.000
2,25.733,0.00,-0.0002,-0.00020,2.000
2,25.867,0.00,-0.0002,-0.00020,2.000
2,26.000,0.00,-0.0002,-0.00020,2.000
2,26.133,0.00,-0.0002,-0.00020,2.000
2,26.333,0.00,-0.0002,-0.00020,2.000
2,26.467,0.00,-0.0002,-0.00020,2.000
2,26.600,0.00,-0.0002,-0.00020,2.000
2,26.733,0.00,-0.0002,-0.00020,2.000
2,26.867,0.00,-0.0002,-0.00020,2.000
2,27.000,0.00,-0.0002,-0.00020,2.000
2,27.133,0.00,-0.0002,-0.00020,2.000
3,27.533,0.00,0.1019,0.10197,3.000
3,27.667,0.00,0.2353,0.23540,3.000
3,27.800,0.00,0.3688,0.36890,3.000
3,27.933,0.00,0.5021,0.50223,3.000
3,28.067,0.00,0.6353,0.63543,3.000
3,28.200,0.00,0.7687,0.76880,3.000
3,28.333,0.00,0.9020,0.90213,3.000
3,28.467,0.00,1.0354,1.03553,3.000
3,28.600,0.00,1.1690,1.16910,3.000
3,28.733,0.00,1.3021,1.30220,3.000
3,28.867,0.00,1.4354,1.43547,3.000
3,29.000,0.00,1.5687,1.56880,3.000
3,29.133,0.02,1.7022,1.70233,3.000
3,29.267,0.07,1.8354,1.83547,3.000
3,29.400,0.20,1.9688,1.96890,3.000
3,29.533,0.49,2.1022,2.10227,3.000
3,29.667,0.88,2.2354,2.23550,3.000
3,29.800,1.40,2.3688,2.36890,3.000
3,29.933,2.04,2.5023,2.50237,3.000
3,30.067,2.81,2.6355,2.63560,3.000
3,30.200,3.72,2.7687,2.76880,3.000
3,30.333,4.79,2.9021,2.90223,3.000
3,30.467,6.07,3.0354,3.03547,3.000
3,30.600,7.58,3.1687,3.16880,3.000
3,30.733,9.32,3.3023,3.30240,3.000
3,30.867,11.35,3.4353,3.43543,3.000
3,31.000,13.70,3.5687,3.56880,3.000
3,31.133,16.42,3.7022,3.70227,3.000
3,31.267,19.58,3.8354,3.83553,3.000
3,31.400,23.21,3.9688,3.96890,3.000
3,31.533,27.41,4.1022,4.10227,3.000
3,31.667,32.31,4.2354,4.23553,3.000
3,31.800,38.05,4.3689,4.36900,3.000
3,31.933,44.82,4.5022,4.50227,3.000
3,32.133,51.18,4.5999,4.60003,3.000
3,32.267,39.13,4.4670,4.46710,3.000
3,32.400,31.05,4.3336,4.33370,3.000
3,32.533,24.97,4.2003,4.20037,3.000
3,32.667,20.16,4.0670,4.06710,3.000
3,32.800,16.32,3.9337,3.93380,3.000
3,32.933,13.21,3.8001,3.80023,3.000
3,33.067,10.72,3.6669,3.66703,3.000
3,33.200,8.66,3.5335,3.53360,3.000
3,33.333,6.96,3.4001,3.40023,3.000
3,33.467,5.55,3.2669,3.26697,3.000
3,33.600,4.39,3.1335,3.13360,3.000
3,33.733,3.44,3.0001,3.00020,3.000
3,33.867,2.65,2.8666,2.86673,3.000
3,34.000,2.00,2.7335,2.73360,3.000
3,34.133,1.47,2.6001,2.60017,3.000
3,34.267,1.01,2.4669,2.46700,3.000
3,34.400,0.66,2.3336,2.33370,3.000
3,34.533,0.38,2.1999,2.20003,3.000
3,34.667,0.16,2.0668,2.06693,3.000
3,34.800,0.05,1.9336,1.93370,3.000
3,34.933,0.00,1.8000,1.80010,3.000
3,35.067,0.00,1.6667,1.66680,3.000
3,35.200,0.00,1.5334,1.53350,3.000
3,35.333,0.00,1.3999,1.40003,3.000
3,35.467,0.00,1.2667,1.26677,3.000
3,35.600,0.00,1.1336,1.13370,3.000
3,35.733,0.00,1.0000,1.00010,3.000
3,35.867,0.00,0.8666,0.86670,3.000
3,36.000,0.00,0.7334,0.73350,3.000
3,36.133,0.00,0.6000,0.60013,3.000
3,36.267,0.00,0.4666,0.46670,3.000
3,36.400,0.00,0.3334,0.33350,3.000
3,36.533,0.00,0.1999,0.20000,3.000
3,36.667,0.00,0.0665,0.06660,3.000
3,36.867,0.00,-0.0061,-0.00603,3.000
3,37.000,0.00,-0.0003,-0.00020,3.000
3,37.133,0.00,-0.0003,-0.00020,3.000
3,37.267,0.00,-0.0003,-0.00020,3.000
3,37.400,0.00,-0.0003,-0.00020,3.000
3,37.533,0.00,-0.0003,-0.00020,3.000
3,37.667,0.00,-0.0003,-0.00020,3.000
3,37.800,0.00,-0.0003,-0.00020,3.000
3,37.933,0.00,-0.0003,-0.00020,3.000
3,38.067,0.00,-0.0003,-0.00020,3.000
3,38.200,0.00,-0.0003,-0.00020,3.000
3,38.333,0.00,-0.0002,-0.00010,3.000
3,38.467,0.00,-0.0002,-0.00010,3.000
3,38.600,0.00,-0.0002,-0.00010,3.000
3,38.733,0.00,-0.0002,-0.00010,3.000
3,38.867,0.00,-0.0002,-0.00010,3.000
3,39.000,0.00,-0.0002,-0.00010,3.000
3,39.133,0.00,-0.0002,-0.00010,3.000
3,39.267,0.00,-0.0002,-0.00010,3.000
3,39.400,0.00,-0.0002,-0.00010,3.000
3,39.533,0.00,-0.0002,-0.00010,3.000
3,39.667,0.00,-0.0002,-0.00010,3.000
3,39.800,0.00,-0.0002,-0.00010,3.000
3,40.000,0.00,-0.0002,-0.00010,3.000
3,40.133,0.00,-0.0002,-0.00010,3.000
3,40.267,0.00,-0.0002,-0.00010,3.000
3,40.400,0.00,-0.0002,-0.00010,3.000
3,40.533,0.00,-0.0002,-0.00010,3.000
3,40.667,0.00,-0.0002,-0.00010,3.000
3,40.800,0.00,-0.0002,-0.00010,3.000
4,41.067,0.00,0.0331,0.03323,4.000
4,41.200,0.00,0.1666,0.16670,4.000
4,41.333,0.00,0.3001,0.30017,4.000
4,41.467,0.00,0.4334,0.43347,4.000
4,41.600,0.00,0.5667,0.56680,4.000
4,41.733,0.00,0.7001,0.70017,4.000
4,41.867,-0.01,0.8333,0.83340,4.000
4,42.000,0.00,0.9668,0.96690,4.000
4,42.133,0.00,1.1002,1.10027,4.000
4,42.267,0.00,1.2334,1.23347,4.000
4,42.400,0.00,1.3667,1.36680,4.000
4,42.533,0.00,1.5000,1.50013,4.000
4,42.667,0.00,1.6334,1.63347,4.000
4,42.800,0.03,1.7667,1.76680,4.000
4,42.933,0.11,1.9001,1.90020,4.000
4,43.067,0.32,2.0334,2.03353,4.000
4,43.200,0.65,2.1668,2.16690,4.000
4,43.333,1.09,2.3002,2.30027,4.000
4,43.467,1.67,2.4335,2.43357,4.000
4,43.600,2.36,2.5669,2.56700,4.000
4,43.733,3.20,2.7003,2.70040,4.000
4,43.867,4.18,2.8334,2.83347,4.000
4,44.000,5.34,2.9668,2.96690,4.000
4,44.133,6.73,3.1002,3.10030,4.000
4,44.267,8.36,3.2334,3.23353,4.000
4,44.400,10.23,3.3668,3.36690,4.000
4,44.533,12.39,3.5002,3.50027,4.000
4,44.667,14.92,3.6334,3.63353,4.000
4,44.800,17.83,3.7666,3.76670,4.000
4,44.933,21.19,3.9002,3.90030,4.000
4,45.067,25.07,4.0336,4.03367,4.000
4,45.200,29.58,4.1668,4.16690,4.000
4,45.333,34.84,4.3002,4.30033,4.000
4,45.467,41.04,4.4335,4.43360,4.000
4,45.600,48.49,4.5668,4.56690,4.000
4,45.800,44.16,4.5316,4.53170,4.000
4,45.933,34.60,4.3983,4.39837,4.000
4,46.067,27.66,4.2651,4.26517,4.000
4,46.200,22.31,4.1317,4.13180,4.000
4,46.333,18.03,3.9982,3.99833,4.000
4,46.467,14.58,3.8650,3.86510,4.000
4,46.600,11.82,3.7315,3.73160,4.000
4,46.733,9.57,3.5982,3.59827,4.000
4,46.867,7.70,3.4649,3.46500,4.000
4,47.000,6.16,3.3317,3.33180,4.000
4,47.133,4.88,3.1981,3.19817,4.000
4,47.267,3.85,3.0649,3.06500,4.000
4,47.400,2.99,2.9314,2.93150,4.000
4,47.533,2.27,2.7979,2.79803,4.000
4,47.667,1.69,2.6649,2.66503,4.000
4,47.800,1.20,2.5316,2.53170,4.000
4,47.933,0.81,2.3981,2.39820,4.000
4,48.067,0.49,2.2649,2.26500,4.000
4,48.200,0.24,2.1315,2.13160,4.000
4,48.333,0.08,1.9981,1.99820,4.000
4,48.467,0.02,1.8648,1.86487,4.000
4,48.600,-0.01,1.7315,1.73160,4.000
4,48.733,-0.01,1.5980,1.59807,4.000
4,48.867,0.00,1.4647,1.46477,4.000
4,49.000,0.00,1.3314,1.33150,4.000
4,49.133,0.00,1.1980,1.19807,4.000
4,49.267,0.00,1.0648,1.06487,4.000
4,49.400,0.00,0.9314,0.93150,4.000
4,49.533,0.00,0.7979,0.79800,4.000
4,49.667,0.00,0.6647,0.66480,4.000
4,49.800,0.00,0.5314,0.53150,4.000
4,49.933,0.00,0.3979,0.39800,4.000
4,50.067,0.00,0.2647,0.26480,4.000
4,50.200,0.00,0.1313,0.13140,4.000
4,50.333,0.00,-0.0021,-0.00203,4.000
4,50.533,-0.01,-0.0004,-0.00027,4.000
4,50.667,-0.01,-0.0003,-0.00020,4.000
4,50.800,0.00,-0.0003,-0.00020,4.000
4,50.933,0.00,-0.0003,-0.00020,4.000
4,51.067,-0.01,-0.0003,-0.00020,4.000
4,51.200,0.00,-0.0003,-0.00020,4.000
4,51.333,0.00,-0.0003,-0.00020,4.000
4,51.467,0.00,-0.0003,-0.00020,4.000
4,51.600,0.00,-0.0003,-0.00020,4.000
4,51.733,0.00,-0.0003,-0.00020,4.000
4,51.867,0.00,-0.0003,-0.00020,4.000
4,52.000,0.00,-0.0003,-0.00020,4.000
4,52.133,0.00,-0.0003,-0.00020,4.000
4,52.267,0.00,-0.0003,-0.00020,4.000
4,52.400,0.00,-0.0003,-0.00020,4.000
4,52.533,0.00,-0.0003,-0.00020,4.000
4,52.667,0.00,-0.0002,-0.00010,4.000
4,52.800,-0.01,-0.0002,-0.00010,4.000
4,52.933,0.00,-0.0002,-0.00010,4.000
4,53.067,0.00,-0.0002,-0.00010,4.000
4,53.200,0.00,-0.0002,-0.00010,4.000
4,53.333,0.00,-0.0002,-0.00010,4.000
4,53.533,0.00,-0.0002,-0.00010,4.000
4,53.667,0.00,-0.0002,-0.00010,4.000
4,53.800,0.00,-0.0002,-0.00010,4.000
4,53.933,0.00,-0.0002,-0.00010,4.000
4,54.067,0.00,-0.0002,-0.00010,4.000
4,54.200,0.00,-0.0002,-0.00010,4.000
4,54.333,0.00,-0.0002,-0.00010,4.000
5,54.667,0.00,0.0543,0.05437,5.000
5,54.800,0.00,0.1875,0.18760,5.000
5,54.933,0.00,0.3210,0.32110,5.000
5,55.067,0.00,0.4544,0.45453,5.000
5,55.200,0.00,0.5878,0.58790,5.000
5,55.333,0.00,0.7210,0.72107,5.000
5,55.467,0.00,0.8544,0.85453,5.000
5,55.600,0.00,0.9877,0.98780,5.000
5,55.733,0.00,1.1210,1.12113,5.000
5,55.867,0.00,1.2545,1.25457,5.000
5,56.000,0.00,1.3877,1.38780,5.000
5,56.133,0.00,1.5209,1.52100,5.000
5,56.267,0.00,1.6545,1.65457,5.000
5,56.400,0.04,1.7877,1.78780,5.000
5,56.533,0.13,1.9211,1.92117,5.000
5,56.667,0.35,2.0545,2.05463,5.000
5,56.800,0.69,2.1877,2.18780,5.000
5,56.933,1.16,2.3211,2.32123,5.000
5,57.067,1.75,2.4546,2.45470,5.000
5,57.200,2.47,2.5880,2.58810,5.000
5,57.333,3.32,2.7212,2.72127,5.000
5,57.467,4.32,2.8544,2.85447,5.000
5,57.600,5.51,2.9879,2.98800,5.000
5,57.733,6.95,3.1210,3.12113,5.000
5,57.867,8.61,3.2545,3.25457,5.000
5,58.000,10.51,3.3878,3.38790,5.000
5,58.133,12.73,3.5210,3.52113,5.000
5,58.267,15.30,3.6545,3.65460,5.000
5,58.400,18.27,3.7879,3.78800,5.000
5,58.533,21.71,3.9211,3.92117,5.000
5,58.667,25.67,4.0545,4.05463,5.000
5,58.800,30.28,4.1879,4.18800,5.000
5,58.933,35.70,4.3211,4.32117,5.000
5,59.067,42.04,4.4546,4.45470,5.000
5,59.200,49.73,4.5878,4.58790,5.000
5,59.400,43.84,4.5326,4.53270,5.000
5,59.533,34.41,4.3993,4.39937,5.000
5,59.667,27.53,4.2661,4.26617,5.000
5,59.800,22.22,4.1327,4.13280,5.000
5,59.933,17.97,3.9992,3.99933,5.000
5,60.067,14.53,3.8661,3.86617,5.000
5,60.200,11.78,3.7325,3.73260,5.000
5,60.333,9.53,3.5992,3.59930,5.000
5,60.467,7.67,3.4659,3.46597,5.000
5,60.600,6.14,3.3326,3.33270,5.000
5,60.733,4.86,3.1991,3.19920,5.000
5,60.867,3.84,3.0658,3.06593,5.000
5,61.000,2.98,2.9324,2.93250,5.000
5,61.133,2.26,2.7990,2.79913,5.000
5,61.267,1.69,2.6659,2.66603,5.000
5,61.400,1.20,2.5326,2.53270,5.000
5,61.533,0.81,2.3991,2.39920,5.000
5,61.667,0.49,2.2658,2.26587,5.000
5,61.800,0.24,2.1324,2.13250,5.000
5,61.933,0.08,1.9990,1.99913,5.000
5,62.067,0.02,1.8657,1.86583,5.000
5,62.200,0.00,1.7324,1.73250,5.000
5,62.333,0.00,1.5989,1.59903,5.000
5,62.467,0.00,1.4657,1.46577,5.000
5,62.600,0.00,1.3323,1.33240,5.000
5,62.733,0.00,1.1990,1.19913,5.000
5,62.867,0.00,1.0658,1.06590,5.000
5,63.000,0.00,0.9324,0.93250,5.000
5,63.133,0.00,0.7989,0.79900,5.000
5,63.267,0.00,0.6657,0.66577,5.000
5,63.400,0.00,0.5324,0.53250,5.000
5,63.533,0.00,0.3989,0.39900,5.000
5,63.667,0.00,0.2657,0.26577,5.000
5,63.800,0.00,0.1322,0.13230,5.000
5,63.933,0.00,-0.0011,-0.00100,5.000
5,64.133,0.00,-0.0002,-0.00013,5.000
5,64.267,0.00,-0.0003,-0.00020,5.000
5,64.400,0.00,-0.0003,-0.00020,5.000
5,64.533,0.00,-0.0003,-0.00020,5.000
5,64.667,0.00,-0.0003,-0.00020,5.000
5,64.800,0.00,-0.0003,-0.00020,5.000
5,64.933,0.00,-0.0003,-0.00020,5.000
5,65.067,0.00,-0.0003,-0.00020,5.000
5,65.200,0.00,-0.0003,-0.00020,5.000
5,65.333,0.00,-0.0003,-0.00020,5.000
5,65.467,0.00,-0.0003,-0.00020,5.000
5,65.600,0.00,-0.0003,-0.00020,5.000
5,65.733,0.00,-0.0003,-0.00020,5.000
5,65.867,0.00,-0.0002,-0.00010,5.000
5,66.000,0.00,-0.0002,-0.00010,5.000
5,66.133,0.00,-0.0002,-0.00010,5.000
5,66.267,0.00,-0.0002,-0.00010,5.000
5,66.400,0.00,-0.0002,-0.00010,5.000
5,66.533,0.00,-0.0002,-0.00010,5.000
5,66.667,0.00,-0.0002,-0.00010,5.000
5,66.800,0.00,-0.0002,-0.00010,5.000
5,66.933,0.00,-0.0002,-0.00010,5.000
5,67.133,0.00,-0.0002,-0.00010,5.000
5,67.267,0.00,-0.0002,-0.00010,5.000
5,67.400,0.00,-0.0002,-0.00010,5.000
5,67.533,0.00,-0.0002,-0.00010,5.000
5,67.667,0.00,-0.0002,-0.00010,5.000
5,67.800,0.00,-0.0002,-0.00010,5.000
5,67.933,0.00,-0.0002,-0.00010,5.000
6,68.200,0.00,-0.0001,0.00000,6.000
6,68.333,0.00,0.0998,0.09993,6.000
6,68.467,-0.01,0.2332,0.23333,6.000
6,68.600,0.00,0.3668,0.36690,6.000
6,68.733,0.00,0.5001,0.50020,6.000
6,68.867,-0.01,0.6334,0.63347,6.000
6,69.000,0.00,0.7667,0.76680,6.000
6,69.133,-0.01,0.9001,0.90020,6.000
6,69.267,-0.01,1.0334,1.03350,6.000
6,69.400,-0.01,1.1669,1.16700,6.000
6,69.533,0.00,1.3000,1.30013,6.000
6,69.667,-0.01,1.4333,1.43343,6.000
6,69.800,-0.01,1.5666,1.56670,6.000
6,69.933,0.00,1.7002,1.70027,6.000
6,70.067,0.06,1.8334,1.83347,6.000
6,70.200,0.18,1.9667,1.96680,6.000
6,70.333,0.44,2.1002,2.10030,6.000
6,70.467,0.83,2.2334,2.23350,6.000
6,70.600,1.33,2.3669,2.36700,6.000
6,70.733,1.96,2.5003,2.50037,6.000
6,70.867,2.73,2.6336,2.63370,6.000
6,71.000,3.62,2.7667,2.76680,6.000
6,71.133,4.68,2.9001,2.90023,6.000
6,71.267,5.94,3.0334,3.03350,6.000
6,71.400,7.45,3.1668,3.16690,6.000
6,71.533,9.19,3.3002,3.30030,6.000
6,71.667,11.20,3.4334,3.43350,6.000
6,71.800,13.52,3.5668,3.56690,6.000
6,71.933,16.21,3.7001,3.70020,6.000
6,72.067,19.33,3.8335,3.83363,6.000
6,72.200,22.93,3.9667,3.96680,6.000
6,72.333,27.10,4.1002,4.10033,6.000
6,72.467,31.97,4.2336,4.23367,6.000
6,72.600,37.68,4.3667,4.36680,6.000
6,72.733,44.40,4.5002,4.50027,6.000
6,72.933,52.18,4.6161,4.61623,6.000
6,73.067,39.89,4.4828,4.48293,6.000
6,73.200,31.58,4.3497,4.34980,6.000
6,73.333,25.36,4.2164,4.21647,6.000
6,73.467,20.49,4.0829,4.08300,6.000
6,73.600,16.57,3.9498,3.94990,6.000
6,73.733,13.39,3.8163,3.81640,6.000
6,73.867,10.85,3.6828,3.68293,6.000
6,74.000,8.76,3.5495,3.54960,6.000
6,74.133,7.04,3.4162,3.41633,6.000
6,74.267,5.61,3.2828,3.28287,6.000
6,74.400,4.43,3.1495,3.14960,6.000
6,74.533,3.48,3.0162,3.01630,6.000
6,74.667,2.68,2.8827,2.88280,6.000
6,74.800,2.02,2.7495,2.74960,6.000
6,74.933,1.48,2.6163,2.61637,6.000
6,75.067,1.03,2.4828,2.48287,6.000
6,75.200,0.67,2.3496,2.34970,6.000
6,75.333,0.38,2.2161,2.21620,6.000
6,75.467,0.16,2.0827,2.08277,6.000
6,75.600,0.05,1.9495,1.94960,6.000
6,75.733,0.00,1.8161,1.81620,6.000
6,75.867,-0.01,1.6827,1.68277,6.000
6,76.000,-0.01,1.5492,1.54930,6.000
6,76.133,0.00,1.4160,1.41610,6.000
6,76.267,-0.01,1.2825,1.28263,6.000
6,76.400,-0.01,1.1495,1.14960,6.000
6,76.533,-0.01,1.0161,1.01623,6.000
6,76.667,-0.01,0.8826,0.88267,6.000
6,76.800,0.00,0.7493,0.74940,6.000
6,76.933,0.00,0.6160,0.61613,6.000
6,77.067,-0.01,0.4826,0.48270,6.000
6,77.200,-0.01,0.3493,0.34940,6.000
6,77.333,0.00,0.2160,0.21607,6.000
6,77.467,0.00,0.0825,0.08257,6.000
6,77.667,0.00,-0.0284,-0.02833,6.000
6,77.800,-0.01,-0.0003,-0.00020,6.000
6,77.933,0.00,-0.0003,-0.00020,6.000
6,78.067,-0.01,-0.0003,-0.00020,6.000
6,78.200,-0.01,-0.0003,-0.00020,6.000
6,78.333,0.00,-0.0003,-0.00020,6.000
6,78.467,0.00,-0.0003,-0.00020,6.000
6,78.600,0.00,-0.0003,-0.00020,6.000
6,78.733,-0.01,-0.0003,-0.00020,6.000
6,78.867,0.00,-0.0003,-0.00020,6.000
6,79.000,-0.01,-0.0003,-0.00020,6.000
6,79.133,0.00,-0.0003,-0.00020,6.000
6,79.267,0.00,-0.0003,-0.00020,6.000
6,79.400,-0.01,-0.0003,-0.00020,6.000
6,79.533,0.00,-0.0003,-0.00020,6.000
6,79.667,-0.01,-0.0003,-0.00020,6.000
6,79.800,-0.01,-0.0003,-0.00020,6.000
6,79.933,0.00,-0.0003,-0.00020,6.000
6,80.067,0.00,-0.0002,-0.00010,6.000
6,80.200,0.00,-0.0002,-0.00010,6.000
6,80.333,0.00,-0.0002,-0.00010,6.000
6,80.467,0.00,-0.0002,-0.00010,6.000
6,80.600,0.00,-0.0002,-0.00010,6.000
6,80.800,0.00,-0.0002,-0.00010,6.000
6,80.933,-0.01,-0.0002,-0.00010,6.000
6,81.067,0.00,-0.0002,-0.00010,6.000
6,81.200,0.00,-0.0002,-0.00010,6.000
6,81.333,0.00,-0.0002,-0.00010,6.000
6,81.467,0.00,-0.0002,-0.00010,6.000
6,81.600,-0.01,-0.0002,-0.00010,6.000
7,81.933,0.00,0.0599,0.05997,7.000
7,82.067,0.00,0.1932,0.19333,7.000
7,82.200,0.00,0.3267,0.32680,7.000
7,82.333,0.00,0.4601,0.46017,7.000
7,82.467,0.00,0.5934,0.59350,7.000
7,82.600,0.00,0.7267,0.72680,7.000
7,82.733,0.00,0.8600,0.86013,7.000
7,82.867,0.00,0.9934,0.99347,7.000
7,83.000,0.00,1.1269,1.12700,7.000
7,83.133,0.00,1.2602,1.26030,7.000
7,83.267,0.00,1.3933,1.39337,7.000
7,83.400,0.00,1.5266,1.52670,7.000
7,83.533,0.00,1.6602,1.66027,7.000
7,83.667,0.03,1.7934,1.79347,7.000
7,83.800,0.13,1.9268,1.92690,7.000
7,83.933,0.35,2.0602,2.06030,7.000
7,84.067,0.70,2.1935,2.19357,7.000
7,84.200,1.15,2.3268,2.32690,7.000
7,84.333,1.75,2.4603,2.46037,7.000
7,84.467,2.47,2.5936,2.59370,7.000
7,84.600,3.32,2.7269,2.72700,7.000
7,84.733,4.33,2.8601,2.86017,7.000
7,84.867,5.52,2.9935,2.99357,7.000
7,85.000,6.96,3.1267,3.12680,7.000
7,85.133,8.63,3.2602,3.26033,7.000
7,85.267,10.54,3.3935,3.39357,7.000
7,85.400,12.76,3.5268,3.52690,7.000
7,85.533,15.33,3.6602,3.66027,7.000
7,85.667,18.32,3.7935,3.79363,7.000
7,85.800,21.76,3.9267,3.92680,7.000
7,85.933,25.73,4.0602,4.06033,7.000
7,86.067,30.37,4.1935,4.19363,7.000
7,86.200,35.80,4.3267,4.32680,7.000
7,86.333,42.17,4.4603,4.46037,7.000
7,86.467,49.92,4.5935,4.59357,7.000
7,86.667,44.64,4.5469,4.54703,7.000
7,86.800,34.98,4.4136,4.41370,7.000
7,86.933,27.97,4.2802,4.28033,7.000
7,87.067,22.56,4.1471,4.14717,7.000
7,87.200,18.24,4.0137,4.01380,7.000
7,87.333,14.75,3.8802,3.88030,7.000
7,87.467,11.94,3.7470,3.74707,7.000
7,87.600,9.66,3.6136,3.61370,7.000
7,87.733,7.79,3.4802,3.48027,7.000
7,87.867,6.23,3.3469,3.34703,7.000
7,88.000,4.94,3.2136,3.21370,7.000
7,88.133,3.89,3.0801,3.08017,7.000
7,88.267,3.03,2.9468,2.94690,7.000
7,88.400,2.30,2.8134,2.81350,7.000
7,88.533,1.72,2.6801,2.68023,7.000
7,88.667,1.22,2.5469,2.54700,7.000
7,88.800,0.83,2.4135,2.41360,7.000
7,88.933,0.51,2.2800,2.28013,7.000
7,89.067,0.26,2.1468,2.14687,7.000
7,89.200,0.09,2.0136,2.01370,7.000
7,89.333,0.02,1.8800,1.88013,7.000
7,89.467,0.00,1.7468,1.74687,7.000
7,89.600,0.00,1.6134,1.61350,7.000
7,89.733,0.00,1.4800,1.48007,7.000
7,89.867,0.00,1.3466,1.34673,7.000
7,90.000,0.00,1.2135,1.21360,7.000
7,90.133,0.00,1.0801,1.08017,7.000
7,90.267,0.00,0.9466,0.94673,7.000
7,90.400,0.00,0.8135,0.81360,7.000
7,90.533,0.00,0.6800,0.68007,7.000
7,90.667,0.00,0.5467,0.54677,7.000
7,90.800,0.00,0.4135,0.41360,7.000
7,90.933,0.00,0.2800,0.28010,7.000
7,91.067,0.00,0.1466,0.14673,7.000
7,91.200,0.00,0.0134,0.01350,7.000
7,91.400,0.00,-0.0003,-0.00020,7.000
7,91.533,0.00,-0.0003,-0.00020,7.000
7,91.667,0.00,-0.0003,-0.00020,7.000
7,91.800,0.00,-0.0003,-0.00020,7.000
7,91.933,0.00,-0.0003,-0.00020,7.000
7,92.067,0.00,-0.0003,-0.00020,7.000
7,92.200,0.00,-0.0003,-0.00020,7.000
7,92.333,0.00,-0.0003,-0.00020,7.000
7,92.467,0.00,-0.0003,-0.00020,7.000
7,92.600,0.00,-0.0003,-0.00020,7.000
7,92.733,0.00,-0.0003,-0.00020,7.000
7,92.867,0.00,-0.0003,-0.00020,7.000
7,93.000,0.00,-0.0003,-0.00020,7.000
7,93.133,0.00,-0.0003,-0.00020,7.000
7,93.267,0.00,-0.0003,-0.00020,7.000
7,93.400,0.00,-0.0003,-0.00020,7.000
7,93.533,0.00,-0.0003,-0.00020,7.000
7,93.667,0.00,-0.0002,-0.00010,7.000
7,93.800,0.00,-0.0002,-0.00010,7.000
7,93.933,0.00,-0.0002,-0.00010,7.000
7,94.067,0.00,-0.0002,-0.00010,7.000
7,94.200,0.00,-0.0002,-0.00010,7.000
7,94.400,0.00,-0.0002,-0.00010,7.000
7,94.533,0.00,-0.0002,-0.00010,7.000
7,94.667,0.00,-0.0002,-0.00010,7.000
7,94.800,0.00,-0.0002,-0.00010,7.000
7,94.933,0.00,-0.0002,-0.00010,7.000
7,95.067,0.00,-0.0002,-0.00010,7.000
7,95.200,0.00,-0.0002,-0.00010,7.000
8,95.600,0.01,0.0886,0.08870,8.000
8,95.733,0.01,0.2221,0.22217,8.000
8,95.867,0.01,0.3554,0.35547,8.000
8,96.000,0.00,0.4887,0.48880,8.000
8,96.133,0.01,0.6221,0.62220,8.000
8,96.267,0.01,0.7553,0.75540,8.000
8,96.400,0.01,0.8887,0.88880,8.000
8,96.533,0.01,1.0221,1.02223,8.000
8,96.667,0.01,1.1554,1.15550,8.000
8,96.800,0.01,1.2887,1.28880,8.000
8,96.933,0.01,1.4220,1.42213,8.000
8,97.067,0.00,1.5553,1.55540,8.000
8,97.200,0.01,1.6887,1.68880,8.000
8,97.333,0.06,1.8221,1.82223,8.000
8,97.467,0.16,1.9555,1.95557,8.000
8,97.600,0.42,2.0888,2.08890,8.000
8,97.733,0.79,2.2222,2.22230,8.000
8,97.867,1.27,2.3555,2.35557,8.000
8,98.000,1.89,2.4888,2.48890,8.000
8,98.133,2.64,2.6223,2.62243,8.000
8,98.267,3.52,2.7555,2.75557,8.000
8,98.400,4.56,2.8886,2.88870,8.000
8,98.533,5.80,3.0221,3.02220,8.000
8,98.667,7.29,3.1555,3.15557,8.000
8,98.800,9.00,3.2888,3.28890,8.000
8,98.933,10.97,3.4221,3.42220,8.000
8,99.067,13.27,3.5554,3.55553,8.000
8,99.200,15.92,3.6887,3.68880,8.000
8,99.333,18.99,3.8222,3.82233,8.000
8,99.467,22.53,3.9555,3.95563,8.000
8,99.600,26.64,4.0888,4.08890,8.000
8,99.733,31.43,4.2222,4.22230,8.000
8,99.867,37.05,4.3555,4.35563,8.000
8,100.000,43.67,4.4888,4.48890,8.000
8,100.200,53.28,4.6318,4.63190,8.000
8,100.333,41.02,4.5003,4.50040,8.000
8,100.467,32.41,4.3669,4.36700,8.000
8,100.600,25.98,4.2336,4.23370,8.000
8,100.733,20.98,4.1003,4.10040,8.000
8,100.867,16.96,3.9669,3.96697,8.000
8,101.000,13.71,3.8336,3.83370,8.000
8,101.133,11.11,3.7003,3.70037,8.000
8,101.267,8.97,3.5668,3.56687,8.000
8,101.400,7.21,3.4336,3.43370,8.000
8,101.533,5.75,3.3003,3.30040,8.000
8,101.667,4.55,3.1668,3.16690,8.000
8,101.800,3.58,3.0335,3.03360,8.000
8,101.933,2.76,2.9001,2.90020,8.000
8,102.067,2.09,2.7667,2.76683,8.000
8,102.200,1.54,2.6336,2.63370,8.000
8,102.333,1.08,2.5002,2.50030,8.000
8,102.467,0.71,2.3668,2.36687,8.000
8,102.600,0.42,2.2334,2.23350,8.000
8,102.733,0.19,2.1001,2.10023,8.000
8,102.867,0.07,1.9667,1.96683,8.000
8,103.000,0.02,1.8333,1.83340,8.000
8,103.133,0.00,1.7001,1.70020,8.000
8,103.267,0.01,1.5666,1.56667,8.000
8,103.400,0.01,1.4333,1.43340,8.000
8,103.533,0.01,1.3001,1.30017,8.000
8,103.667,0.01,1.1668,1.16693,8.000
8,103.800,0.00,1.0333,1.03340,8.000
8,103.933,0.01,0.9000,0.90010,8.000
8,104.067,0.01,0.7667,0.76680,8.000
8,104.200,0.01,0.6332,0.63330,8.000
8,104.333,0.00,0.5001,0.50017,8.000
8,104.467,0.01,0.3667,0.36677,8.000
8,104.600,0.01,0.2333,0.23340,8.000
8,104.733,0.01,0.1000,0.10007,8.000
8,104.933,0.01,-0.0370,-0.03687,8.000
8,105.067,0.01,-0.0004,-0.00030,8.000
8,105.200,0.01,-0.0003,-0.00020,8.000
8,105.333,0.01,-0.0003,-0.00020,8.000
8,105.467,0.00,-0.0003,-0.00020,8.000
8,105.600,0.01,-0.0003,-0.00020,8.000
8,105.733,0.01,-0.0003,-0.00020,8.000
8,105.867,0.01,-0.0003,-0.00020,8.000
8,106.000,0.01,-0.0003,-0.00020,8.000
8,106.133,0.01,-0.0003,-0.00020,8.000
8,106.267,0.01,-0.0003,-0.00020,8.000
8,106.400,0.01,-0.0003,-0.00020,8.000
8,106.533,0.01,-0.0003,-0.00020,8.000
8,106.667,0.01,-0.0003,-0.00020,8.000
8,106.800,0.01,-0.0003,-0.00020,8.000
8,106.933,0.01,-0.0003,-0.00020,8.000
8,107.067,0.01,-0.0003,-0.00020,8.000
8,107.200,0.01,-0.0003,-0.00020,8.000
8,107.333,0.01,-0.0003,-0.00017,8.000
8,107.467,0.01,-0.0002,-0.00010,8.000
8,107.600,0.01,-0.0002,-0.00010,8.000
8,107.733,0.01,-0.0002,-0.00010,8.000
8,107.867,0.01,-0.0002,-0.00010,8.000
8,108.133,0.01,-0.0002,-0.00010,8.000
8,108.267,0.01,-0.0002,-0.00010,8.000
8,108.400,0.01,-0.0002,-0.00010,8.000
8,108.533,0.01,-0.0002,-0.00010,8.000
8,108.667,0.01,-0.0002,-0.00010,8.000
8,108.800,0.01,-0.0002,-0.00010,8.000
8,108.933,0.01,-0.0002,-0.00010,8.000
9,109.267,0.01,0.1353,0.13540,9.000
9,109.400,0.01,0.2687,0.26880,9.000
9,109.533,0.01,0.4020,0.40210,9.000
9,109.667,0.00,0.5354,0.53553,9.000
9,109.800,0.00,0.6688,0.66890,9.000
9,109.933,0.00,0.8020,0.80210,9.000
9,110.067,0.00,0.9354,0.93550,9.000
9,110.200,0.00,1.0688,1.06890,9.000
9,110.333,0.00,1.2021,1.20220,9.000
9,110.467,0.00,1.3354,1.33547,9.000
9,110.600,0.01,1.4688,1.46890,9.000
9,110.733,0.01,1.6020,1.60207,9.000
9,110.867,0.02,1.7355,1.73557,9.000
9,111.000,0.08,1.8688,1.86890,9.000
9,111.133,0.23,2.0021,2.00220,9.000
9,111.267,0.53,2.1354,2.13550,9.000
9,111.400,0.93,2.2688,2.26890,9.000
9,111.533,1.46,2.4021,2.40220,9.000
9,111.667,2.12,2.5356,2.53570,9.000
9,111.800,2.91,2.6691,2.66920,9.000
9,111.933,3.85,2.8020,2.80210,9.000
9,112.067,4.95,2.9354,2.93550,9.000
9,112.200,6.28,3.0689,3.06900,9.000
9,112.333,7.85,3.2021,3.20223,9.000
9,112.467,9.64,3.3355,3.33557,9.000
9,112.600,11.71,3.4688,3.46890,9.000
9,112.733,14.12,3.6022,3.60227,9.000
9,112.867,16.91,3.7354,3.73550,9.000
9,113.000,20.13,3.8689,3.86900,9.000
9,113.133,23.85,4.0021,4.00223,9.000
9,113.267,28.19,4.1355,4.13557,9.000
9,113.400,33.24,4.2688,4.26890,9.000
9,113.533,39.18,4.4022,4.40227,9.000
9,113.667,46.24,4.5355,4.53557,9.000
9,113.867,50.49,4.6067,4.60680,9.000
9,114.000,38.79,4.4737,4.47380,9.000
9,114.133,30.80,4.3403,4.34043,9.000
9,114.267,24.77,4.2069,4.20700,9.000
9,114.400,20.00,4.0737,4.07380,9.000
9,114.533,16.17,3.9403,3.94043,9.000
9,114.667,13.08,3.8068,3.80690,9.000
9,114.800,10.59,3.6736,3.67370,9.000
9,114.933,8.55,3.5402,3.54033,9.000
9,115.067,6.86,3.4068,3.40690,9.000
9,115.200,5.46,3.2736,3.27370,9.000
9,115.333,4.32,3.1403,3.14040,9.000
9,115.467,3.38,3.0068,3.00687,9.000
9,115.600,2.60,2.8733,2.87340,9.000
9,115.733,1.95,2.7402,2.74033,9.000
9,115.867,1.43,2.6068,2.60693,9.000
9,116.000,0.99,2.4735,2.47360,9.000
9,116.133,0.64,2.3403,2.34037,9.000
9,116.267,0.36,2.2067,2.20677,9.000
9,116.400,0.15,2.0735,2.07360,9.000
9,116.533,0.05,1.9402,1.94030,9.000
9,116.667,0.01,1.8066,1.80670,9.000
9,116.800,0.00,1.6734,1.67350,9.000
9,116.933,0.00,1.5400,1.54013,9.000
9,117.067,0.01,1.4066,1.40673,9.000
9,117.200,0.01,1.2734,1.27350,9.000
9,117.333,0.00,1.1402,1.14027,9.000
9,117.467,0.01,1.0067,1.00680,9.000
9,117.600,0.01,0.8734,0.87350,9.000
9,117.733,0.00,0.7401,0.74020,9.000
9,117.867,0.00,0.6067,0.60680,9.000
9,118.000,0.01,0.4733,0.47340,9.000
9,118.133,0.00,0.3400,0.34013,9.000
9,118.267,0.00,0.2066,0.20670,9.000
9,118.400,0.00,0.0732,0.07330,9.000
9,118.600,0.01,-0.0309,-0.03080,9.000
9,118.733,0.00,-0.0003,-0.00020,9.000
9,118.867,0.00,-0.0003,-0.00020,9.000
9,119.000,0.00,-0.0003,-0.00020,9.000
9,119.133,0.00,-0.0003,-0.00020,9.000
9,119.267,0.01,-0.0003,-0.00020,9.000
9,119.400,0.00,-0.0003,-0.00020,9.000
9,119.533,0.00,-0.0003,-0.00020,9.000
9,119.667,0.00,-0.0003,-0.00020,9.000
9,119.800,0.01,-0.0003,-0.00020,9.000
9,119.933,0.00,-0.0003,-0.00020,9.000
9,120.067,0.00,-0.0003,-0.00020,9.000
9,120.200,0.00,-0.0003,-0.00020,9.000
9,120.333,0.00,-0.0003,-0.00020,9.000
9,120.467,0.00,-0.0003,-0.00020,9.000
9,120.600,0.00,-0.0003,-0.00020,9.000
9,120.733,0.00,-0.0003,-0.00020,9.000
9,120.867,0.00,-0.0002,-0.00010,9.000
9,121.000,0.00,-0.0002,-0.00010,9.000
9,121.133,0.00,-0.0002,-0.00010,9.000
9,121.267,0.00,-0.0002,-0.00010,9.000
9,121.400,0.00,-0.0002,-0.00010,9.000
9,121.533,0.00,-0.0002,-0.00010,9.000
9,121.733,0.00,-0.0002,-0.00010,9.000
9,121.867,0.00,-0.0002,-0.00010,9.000
9,122.000,0.00,-0.0002,-0.00010,9.000
9,122.133,0.01,-0.0002,-0.00010,9.000
9,122.267,0.01,-0.0002,-0.00010,9.000
9,122.400,0.00,-0.0002,-0.00010,9.000
9,122.533,0.00,-0.0002,-0.00010,9.000
10,122.867,0.00,0.0952,0.09530,10.000
10,123.000,0.00,0.2286,0.22870,10.000
10,123.133,0.00,0.3620,0.36207,10.000
10,123.267,0.00,0.4954,0.49547,10.000
10,123.400,0.00,0.6288,0.62890,10.000
10,123.533,0.00,0.7620,0.76207,10.000
10,123.667,0.00,0.8954,0.89547,10.000
10,123.800,0.00,1.0289,1.02900,10.000
10,123.933,0.00,1.1621,1.16220,10.000
10,124.067,0.00,1.2954,1.29553,10.000
10,124.200,0.00,1.4288,1.42890,10.000
10,124.333,0.00,1.5620,1.56207,10.000
10,124.467,0.00,1.6955,1.69560,10.000
10,124.600,0.05,1.8289,1.82900,10.000
10,124.733,0.16,1.9621,1.96217,10.000
10,124.867,0.41,2.0955,2.09557,10.000
10,125.000,0.79,2.2288,2.22890,10.000
10,125.133,1.28,2.3621,2.36223,10.000
10,125.267,1.90,2.4956,2.49567,10.000
10,125.400,2.65,2.6290,2.62910,10.000
10,125.533,3.54,2.7621,2.76223,10.000
10,125.667,4.59,2.8954,2.89550,10.000
10,125.800,5.84,3.0289,3.02900,10.000
10,125.933,7.34,3.1622,3.16227,10.000
10,126.067,9.06,3.2955,3.29563,10.000
10,126.200,11.05,3.4288,3.42890,10.000
10,126.333,13.34,3.5621,3.56217,10.000
10,126.467,16.00,3.6954,3.69553,10.000
10,126.600,19.09,3.8289,3.82900,10.000
10,126.733,22.65,3.9621,3.96223,10.000
10,126.867,26.78,4.0954,4.09553,10.000
10,127.000,31.60,4.2289,4.22900,10.000
10,127.133,37.26,4.3622,4.36230,10.000
10,127.267,43.92,4.4955,4.49557,10.000
10,127.467,52.74,4.6264,4.62650,10.000
10,127.600,40.43,4.4936,4.49370,10.000
10,127.733,31.97,4.3602,4.36033,10.000
10,127.867,25.64,4.2270,4.22713,10.000
10,128.000,20.70,4.0936,4.09370,10.000
10,128.133,16.73,3.9603,3.96040,10.000
10,128.267,13.51,3.8269,3.82703,10.000
10,128.400,10.95,3.6935,3.69360,10.000
10,128.533,8.83,3.5602,3.56030,10.000
10,128.667,7.10,3.4269,3.42700,10.000
10,128.800,5.66,3.2935,3.29360,10.000
10,128.933,4.47,3.1601,3.16020,10.000
10,129.067,3.50,3.0268,3.02693,10.000
10,129.200,2.69,2.8934,2.89350,10.000
10,129.333,2.03,2.7601,2.76020,10.000
10,129.467,1.49,2.6269,2.62703,10.000
10,129.600,1.04,2.4935,2.49360,10.000
10,129.733,0.68,2.3601,2.36023,10.000
10,129.867,0.39,2.2268,2.22693,10.000
10,130.000,0.17,2.0934,2.09350,10.000
10,130.133,0.05,1.9600,1.96013,10.000
10,130.267,0.01,1.8268,1.82687,10.000
10,130.400,0.00,1.6934,1.69350,10.000
10,130.533,0.00,1.5599,1.56000,10.000
10,130.667,0.00,1.4267,1.42683,10.000
10,130.800,0.00,1.2935,1.29360,10.000
10,130.933,0.00,1.1601,1.16017,10.000
10,131.067,0.00,1.0268,1.02690,10.000
10,131.200,-0.01,0.8934,0.89350,10.000
10,131.333,0.00,0.7600,0.76007,10.000
10,131.467,0.00,0.6267,0.62677,10.000
10,131.600,0.00,0.4933,0.49340,10.000
10,131.733,0.00,0.3599,0.36000,10.000
10,131.867,0.00,0.2266,0.22673,10.000
10,132.000,0.00,0.0934,0.09350,10.000
10,132.200,0.00,-0.0115,-0.01140,10.000
10,132.333,0.00,-0.0003,-0.00020,10.000
10,132.467,0.00,-0.0003,-0.00020,10.000
10,132.600,0.00,-0.0003,-0.00020,10.000
10,132.733,0.00,-0.0003,-0.00020,10.000
10,132.867,0.00,-0.0003,-0.00020,10.000
10,133.000,0.00,-0.0003,-0.00020,10.000
10,133.133,0.00,-0.0003,-0.00020,10.000
10,133.267,0.00,-0.0003,-0.00020,10.000
10,133.400,0.00,-0.0003,-0.00020,10.000
10,133.533,0.00,-0.0003,-0.00020,10.000
10,133.667,0.00,-0.0003,-0.00020,10.000
10,133.800,0.00,-0.0003,-0.00020,10.000
10,133.933,0.00,-0.0003,-0.00020,10.000
10,134.067,0.00,-0.0003,-0.00020,10.000
10,134.200,0.00,-0.0003,-0.00020,10.000
10,134.333,0.00,-0.0003,-0.00020,10.000
10,134.467,0.00,-0.0002,-0.00010,10.000
10,134.600,0.00,-0.0002,-0.00010,10.000
10,134.733,0.00,-0.0002,-0.00010,10.000
10,134.867,0.00,-0.0002,-0.00010,10.000
10,135.000,0.00,-0.0002,-0.00010,10.000
10,135.133,0.00,-0.0002,-0.00010,10.000
10,135.333,0.00,-0.0002,-0.00010,10.000
10,135.467,0.00,-0.0002,-0.00010,10.000
10,135.600,0.00,-0.0002,-0.00010,10.000
10,135.733,0.00,-0.0002,-0.00010,10.000
10,135.867,0.00,-0.0002,-0.00010,10.000
10,136.000,0.00,-0.0002,-0.00010,10.000
10,136.133,0.00,-0.0002,-0.00010,10.000