File: AIME_journal_files/AIME_data/calibDATA_loadcell/date_02:15:2018/Instron_02.15.2018/1_50N_4__1mm.s_0_0.txt
""
"Test Method","Radhen_Load_Cntrl_Cmprsn_250N_12-7.msm"
"Sample I. D.","Sample1.mss"
"Specimen Number","11"

"TheCycle_Output ()","_Time (s)","_Load (N)","_Extension (mm)","RealTimeDepth (mm)","CycleNumber ()"

1,0.333,-0.01,0.0921,0.09207,1.000
1,0.467,-0.01,0.2255,0.22550,1.000
1,0.600,-0.01,0.3589,0.35890,1.000
1,0.733,-0.01,0.4923,0.49227,1.000
1,0.867,-0.01,0.6255,0.62553,1.000
1,1.000,0.00,0.7589,0.75890,1.000
1,1.133,-0.01,0.8922,0.89223,1.000
1,1.267,0.00,1.0255,1.02553,1.000
1,1.400,0.00,1.1589,1.15890,1.000
1,1.533,0.00,1.2922,1.29223,1.000
1,1.667,0.00,1.4255,1.42550,1.000
1,1.800,0.00,1.5587,1.55870,1.000
1,1.933,0.02,1.6923,1.69230,1.000
1,2.067,0.10,1.8255,1.82553,1.000
1,2.200,0.22,1.9588,1.95880,1.000
1,2.333,0.41,2.0923,2.09233,1.000
1,2.467,0.65,2.2256,2.22560,1.000
1,2.600,1.00,2.3589,2.35890,1.000
1,2.733,1.48,2.4923,2.49230,1.000
1,2.867,2.08,2.6257,2.62570,1.000
1,3.000,2.83,2.7589,2.75890,1.000
1,3.133,3.69,2.8922,2.89220,1.000
1,3.267,4.74,3.0256,3.02560,1.000
1,3.400,5.98,3.1587,3.15870,1.000
1,3.533,7.41,3.2922,3.29223,1.000
1,3.667,9.03,3.4257,3.42567,1.000
1,3.800,10.89,3.5587,3.55870,1.000
1,3.933,13.01,3.6922,3.69217,1.000
1,4.067,15.47,3.8256,3.82563,1.000
1,4.200,18.27,3.9588,3.95880,1.000
1,4.333,21.45,4.0922,4.09223,1.000
1,4.467,24.98,4.2256,4.22563,1.000
1,4.600,29.11,4.3588,4.35880,1.000
1,4.733,33.81,4.4922,4.49220,1.000
1,4.867,39.19,4.6256,4.62557,1.000
1,5.000,45.36,4.7588,4.75880,1.000
1,5.200,50.45,4.8593,4.85930,1.000
1,5.333,38.98,4.7263,4.72627,1.000
1,5.467,31.11,4.5930,4.59300,1.000
1,5.600,25.12,4.4598,4.45980,1.000
1,5.733,20.38,4.3263,4.32633,1.000
1,5.867,16.54,4.1930,4.19300,1.000
1,6.000,13.40,4.0598,4.05980,1.000
1,6.133,10.85,3.9262,3.92623,1.000
1,6.267,8.77,3.7929,3.79293,1.000
1,6.400,7.10,3.6597,3.65970,1.000
1,6.533,5.69,3.5261,3.52613,1.000
1,6.667,4.50,3.3928,3.39283,1.000
1,6.800,3.52,3.2596,3.25960,1.000
1,6.933,2.69,3.1261,3.12613,1.000
1,7.067,2.01,2.9928,2.99280,1.000
1,7.200,1.44,2.8595,2.85950,1.000
1,7.333,0.97,2.7262,2.72617,1.000
1,7.467,0.59,2.5928,2.59283,1.000
1,7.600,0.30,2.4597,2.45970,1.000
1,7.733,0.11,2.3261,2.32610,1.000
1,7.867,0.02,2.1927,2.19267,1.000
1,8.000,-0.01,2.0595,2.05950,1.000
1,8.133,-0.01,1.9261,1.92607,1.000
1,8.267,-0.01,1.7927,1.79270,1.000
1,8.400,0.00,1.6595,1.65950,1.000
1,8.533,-0.01,1.5261,1.52607,1.000
1,8.667,-0.01,1.3926,1.39263,1.000
1,8.800,-0.01,1.2594,1.25940,1.000
1,8.933,0.00,1.1261,1.12613,1.000
1,9.067,-0.01,0.9927,0.99270,1.000
1,9.200,-0.01,0.8594,0.85940,1.000
1,9.333,-0.01,0.7261,0.72610,1.000
1,9.467,0.00,0.5926,0.59263,1.000
1,9.600,-0.01,0.4594,0.45940,1.000
1,9.733,0.00,0.3261,0.32610,1.000
1,9.867,-0.01,0.1926,0.19257,1.000
1,10.000,0.00,0.0593,0.05930,1.000
1,10.200,0.00,0.0000,0.00000,1.000
1,10.333,-0.01,-0.0003,-0.00030,1.000
1,10.467,-0.01,-0.0003,-0.00030,1.000
1,10.600,-0.01,-0.0003,-0.00030,1.000
1,10.733,-0.01,-0.0003,-0.00030,1.000
1,10.867,-0.01,-0.0003,-0.00030,1.000
1,11.000,0.00,-0.0003,-0.00030,1.000
1,11.133,-0.01,-0.0003,-0.00030,1.000
1,11.267,-0.01,-0.0003,-0.00030,1.000
1,11.400,0.00,-0.0002,-0.00020,1.000
1,11.533,-0.01,-0.0002,-0.00020,1.000
1,11.667,-0.01,-0.0002,-0.00020,1.000
1,11.800,-0.01,-0.0002,-0.00020,1.000
1,11.933,-0.01,-0.0002,-0.00020,1.000
1,12.067,0.00,-0.0002,-0.00020,1.000
1,12.200,-0.01,-0.0002,-0.00020,1.000
1,12.333,-0.01,-0.0002,-0.00020,1.000
1,12.467,0.00,-0.0002,-0.00020,1.000
1,12.600,0.00,-0.0002,-0.00020,1.000
1,12.733,0.00,-0.0002,-0.00020,1.000
1,12.867,-0.01,-0.0002,-0.00020,1.000
1,13.000,0.00,-0.0002,-0.00020,1.000
1,13.133,0.00,-0.0002,-0.00020,1.000
1,13.333,-0.01,-0.0002,-0.00020,1.000
1,13.467,-0.01,-0.0002,-0.00020,1.000
1,13.600,-0.01,-0.0002,-0.00020,1.000
1,13.733,0.00,-0.0002,-0.00020,1.000
1,13.867,0.00,-0.0002,-0.00020,1.000
1,14.000,0.00,-0.0002,-0.00020,1.000
1,14.133,0.00,-0.0001,-0.00010,1.000
2,14.467,0.01,0.1222,0.12230,2.000
2,14.600,0.00,0.2558,0.25590,2.000
2,14.733,0.00,0.3890,0.38907,2.000
2,14.867,0.00,0.5223,0.52240,2.000
2,15.000,0.00,0.6558,0.65590,2.000
2,15.133,0.00,0.7890,0.78913,2.000
2,15.267,0.00,0.9223,0.92243,2.000
2,15.400,0.00,1.0559,1.05600,2.000
2,15.533,0.00,1.1892,1.18927,2.000
2,15.667,0.00,1.3223,1.32243,2.000
2,15.800,0.01,1.4557,1.45580,2.000
2,15.933,0.00,1.5890,1.58913,2.000
2,16.067,0.00,1.7224,1.72253,2.000
2,16.200,0.00,1.8557,1.85580,2.000
2,16.333,0.02,1.9892,1.98930,2.000
2,16.467,0.09,2.1224,2.12247,2.000
2,16.600,0.27,2.2558,2.25590,2.000
2,16.733,0.60,2.3892,2.38930,2.000
2,16.867,1.04,2.5225,2.52263,2.000
2,17.000,1.64,2.6560,2.65610,2.000
2,17.133,2.37,2.7892,2.78930,2.000
2,17.267,3.27,2.9224,2.92250,2.000
2,17.400,4.35,3.0558,3.05590,2.000
2,17.533,5.62,3.1892,3.18930,2.000
2,17.667,7.09,3.3225,3.32257,2.000
2,17.800,8.76,3.4558,3.45590,2.000
2,17.933,10.69,3.5892,3.58933,2.000
2,18.067,12.89,3.7224,3.72250,2.000
2,18.200,15.38,3.8559,3.85600,2.000
2,18.333,18.19,3.9892,3.98930,2.000
2,18.467,21.42,4.1224,4.12250,2.000
2,18.600,25.13,4.2558,4.25590,2.000
2,18.733,29.38,4.3893,4.38937,2.000
2,18.867,34.26,4.5225,4.52257,2.000
2,19.000,39.86,4.6558,4.65590,2.000
2,19.133,46.36,4.7892,4.78927,2.000
2,19.333,51.44,4.8829,4.88303,2.000
2,19.467,39.73,4.7499,4.75003,2.000
2,19.600,31.73,4.6166,4.61670,2.000
2,19.733,25.62,4.4832,4.48327,2.000
2,19.867,20.79,4.3500,4.35010,2.000
2,20.000,16.89,4.2166,4.21670,2.000
2,20.133,13.70,4.0832,4.08330,2.000
2,20.267,11.10,3.9499,3.95003,2.000
2,20.400,8.97,3.8166,3.81670,2.000
2,20.533,7.25,3.6832,3.68327,2.000
2,20.667,5.82,3.5499,3.54997,2.000
2,20.800,4.61,3.4165,3.41660,2.000
2,20.933,3.61,3.2831,3.28317,2.000
2,21.067,2.76,3.1498,3.14993,2.000
2,21.200,2.08,3.0166,3.01670,2.000
2,21.333,1.50,2.8829,2.88300,2.000
2,21.467,1.01,2.7497,2.74983,2.000
2,21.600,0.64,2.6165,2.61660,2.000
2,21.733,0.34,2.4831,2.48320,2.000
2,21.867,0.12,2.3498,2.34993,2.000
2,22.000,0.03,2.2165,2.21660,2.000
2,22.133,0.00,2.0830,2.08310,2.000
2,22.267,0.00,1.9497,1.94983,2.000
2,22.400,0.00,1.8165,1.81660,2.000
2,22.533,0.00,1.6831,1.68320,2.000
2,22.667,0.00,1.5496,1.54970,2.000
2,22.800,0.00,1.4164,1.41650,2.000
2,22.933,0.00,1.2830,1.28307,2.000
2,23.067,0.00,1.1498,1.14987,2.000
2,23.200,0.00,1.0165,1.01660,2.000
2,23.333,0.00,0.8829,0.88297,2.000
2,23.467,0.00,0.7497,0.74977,2.000
2,23.600,0.00,0.6163,0.61640,2.000
2,23.733,0.00,0.4830,0.48310,2.000
2,23.867,0.00,0.3496,0.34973,2.000
2,24.000,0.00,0.2163,0.21640,2.000
2,24.133,0.00,0.0829,0.08297,2.000
2,24.333,0.00,-0.0309,-0.03077,2.000
2,24.467,0.00,-0.0003,-0.00020,2.000
2,24.600,0.00,-0.0003,-0.00020,2.000
2,24.733,0.00,-0.0003,-0.00020,2.000
2,24.867,0.00,-0.0003,-0.00020,2.000
2,25.000,0.00,-0.0003,-0.00020,2.000
2,25.133,0.00,-0.0003,-0.00020,2.000
2,25.267,0.00,-0.0003,-0.00020,2.000
2,25.400,0.00,-0.0003,-0.00020,2.000
2,25.533,0.00,-0.0003,-0.00020,2.000
2,25.667,0.00,-0.0003,-0.00020,2.000
2,25.800,0.00,-0.0003,-0.00020,2.000
2,25.933,0.00,-0.0003,-0.00020,2.000
2,26.067,0.00,-0.0003,-0.00020,2.000
2,26.200,0.00,-0.0003,-0.00020,2.000
2,26.333,0.00,-0.0002,-0.00010,2.000
2,26.467,0.00,-0.0002,-0.00010,2.000
2,26.600,0.00,-0.0002,-0.00010,2.000
2,26.733,0.00,-0.0002,-0.00010,2.000
2,26.867,0.00,-0.0002,-0.00010,2.000
2,27.000,0.00,-0.0002,-0.00010,2.000
2,27.133,0.00,-0.0002,-0.00010,2.000
2,27.267,0.00,-0.0002,-0.00010,2.000
2,27.467,0.00,-0.0002,-0.00010,2.000
2,27.600,0.00,-0.0002,-0.00010,2.000
2,27.733,0.00,-0.0002,-0.00010,2.000
2,27.867,0.00,-0.0002,-0.00010,2.000
2,28.000,0.00,-0.0002,-0.00010,2.000
2,28.133,0.00,-0.0002,-0.00010,2.000
2,28.267,0.00,-0.0002,-0.00010,2.000
3,28.600,0.00,0.0855,0.08550,3.000
3,28.733,0.00,0.2191,0.21907,3.000
3,28.867,0.00,0.3524,0.35237,3.000
3,29.000,0.00,0.4856,0.48560,3.000
3,29.133,0.00,0.6191,0.61913,3.000
3,29.267,0.00,0.7524,0.75237,3.000
3,29.400,0.00,0.8857,0.88570,3.000
3,29.533,0.00,1.0192,1.01917,3.000
3,29.667,0.00,1.1525,1.15247,3.000
3,29.800,0.00,1.2858,1.28580,3.000
3,29.933,0.00,1.4191,1.41907,3.000
3,30.067,0.00,1.5523,1.55230,3.000
3,30.200,0.00,1.6857,1.68570,3.000
3,30.333,0.00,1.8192,1.81917,3.000
3,30.467,0.01,1.9524,1.95243,3.000
3,30.600,0.05,2.0857,2.08570,3.000
3,30.733,0.19,2.2191,2.21910,3.000
3,30.867,0.47,2.3525,2.35253,3.000
3,31.000,0.88,2.4858,2.48580,3.000
3,31.133,1.42,2.6193,2.61933,3.000
3,31.267,2.12,2.7525,2.75253,3.000
3,31.400,2.96,2.8856,2.88560,3.000
3,31.533,4.00,3.0191,3.01913,3.000
3,31.667,5.21,3.1524,3.15243,3.000
3,31.800,6.60,3.2858,3.28580,3.000
3,31.933,8.21,3.4192,3.41917,3.000
3,32.067,10.06,3.5525,3.55247,3.000
3,32.200,12.19,3.6857,3.68570,3.000
3,32.333,14.59,3.8192,3.81923,3.000
3,32.467,17.30,3.9525,3.95247,3.000
3,32.600,20.41,4.0858,4.08580,3.000
3,32.733,23.98,4.2192,4.21917,3.000
3,32.867,28.09,4.3526,4.35257,3.000
3,33.000,32.79,4.4859,4.48590,3.000
3,33.133,38.18,4.6191,4.61913,3.000
3,33.267,44.43,4.7525,4.75250,3.000
3,33.533,48.30,4.8532,4.85320,3.000
3,33.667,37.78,4.7198,4.71983,3.000
3,33.800,30.26,4.5866,4.58660,3.000
3,33.933,24.48,4.4533,4.45330,3.000
3,34.067,19.88,4.3199,4.31993,3.000
3,34.200,16.13,4.1866,4.18660,3.000
3,34.333,13.08,4.0533,4.05330,3.000
3,34.467,10.60,3.9199,3.91987,3.000
3,34.600,8.55,3.7867,3.78670,3.000
3,34.733,6.91,3.6533,3.65330,3.000
3,34.867,5.52,3.5198,3.51977,3.000
3,35.000,4.36,3.3865,3.38650,3.000
3,35.133,3.39,3.2532,3.25320,3.000
3,35.267,2.58,3.1198,3.11977,3.000
3,35.400,1.92,2.9864,2.98640,3.000
3,35.533,1.37,2.8530,2.85300,3.000
3,35.667,0.91,2.7197,2.71970,3.000
3,35.800,0.55,2.5866,2.58660,3.000
3,35.933,0.26,2.4532,2.45317,3.000
3,36.067,0.09,2.3197,2.31973,3.000
3,36.200,0.02,2.1864,2.18640,3.000
3,36.333,0.00,2.0532,2.05317,3.000
3,36.467,0.00,1.9196,1.91963,3.000
3,36.600,0.00,1.7863,1.78630,3.000
3,36.733,0.00,1.6531,1.65310,3.000
3,36.867,0.00,1.5196,1.51960,3.000
3,37.000,0.00,1.3863,1.38630,3.000
3,37.133,0.00,1.2530,1.25300,3.000
3,37.267,0.00,1.1196,1.11963,3.000
3,37.400,0.00,0.9864,0.98640,3.000
3,37.533,0.00,0.8530,0.85300,3.000
3,37.667,0.00,0.7195,0.71953,3.000
3,37.800,0.00,0.5864,0.58640,3.000
3,37.933,0.00,0.4530,0.45300,3.000
3,38.067,0.00,0.3196,0.31963,3.000
3,38.200,0.01,0.1862,0.18620,3.000
3,38.333,0.00,0.0530,0.05297,3.000
3,38.600,0.00,-0.0003,-0.00030,3.000
3,38.733,0.00,-0.0003,-0.00030,3.000
3,38.867,0.00,-0.0003,-0.00030,3.000
3,39.000,0.00,-0.0003,-0.00030,3.000
3,39.133,0.00,-0.0003,-0.00030,3.000
3,39.267,0.00,-0.0003,-0.00030,3.000
3,39.400,0.00,-0.0003,-0.00030,3.000
3,39.533,0.00,-0.0003,-0.00030,3.000
3,39.667,0.00,-0.0003,-0.00030,3.000
3,39.800,0.00,-0.0003,-0.00030,3.000
3,39.933,0.00,-0.0003,-0.00030,3.000
3,40.067,0.00,-0.0003,-0.00030,3.000
3,40.200,0.00,-0.0003,-0.00030,3.000
3,40.333,0.00,-0.0003,-0.00030,3.000
3,40.467,0.00,-0.0003,-0.00030,3.000
3,40.600,0.00,-0.0002,-0.00020,3.000
3,40.733,0.00,-0.0002,-0.00020,3.000
3,40.867,0.00,-0.0002,-0.00020,3.000
3,41.000,0.00,-0.0002,-0.00020,3.000
3,41.133,0.00,-0.0002,-0.00020,3.000
3,41.267,0.00,-0.0002,-0.00020,3.000
3,41.400,0.00,-0.0002,-0.00020,3.000
3,41.600,0.00,-0.0002,-0.00020,3.000
3,41.733,0.00,-0.0002,-0.00020,3.000
3,41.867,0.00,-0.0002,-0.00020,3.000
3,42.000,0.00,-0.0002,-0.00020,3.000
3,42.133,0.00,-0.0002,-0.00020,3.000
3,42.267,0.00,-0.0002,-0.00020,3.000
3,42.400,0.00,-0.0002,-0.00020,3.000
4,42.733,0.00,0.0778,0.07790,4.000
4,42.867,0.00,0.2114,0.21147,4.000
4,43.000,0.00,0.3448,0.34490,4.000
4,43.133,0.00,0.4779,0.47803,4.000
4,43.267,0.00,0.6115,0.61157,4.000
4,43.400,0.00,0.7448,0.74490,4.000
4,43.533,0.00,0.8779,0.87803,4.000
4,43.667,0.00,1.0114,1.01153,4.000
4,43.800,0.00,1.1448,1.14490,4.000
4,43.933,0.00,1.2780,1.27813,4.000
4,44.067,0.00,1.4113,1.41143,4.000
4,44.200,0.00,1.5447,1.54480,4.000
4,44.333,0.00,1.6780,1.67813,4.000
4,44.467,0.00,1.8114,1.81150,4.000
4,44.600,0.00,1.9449,1.94500,4.000
4,44.733,0.04,2.0781,2.07820,4.000
4,44.867,0.17,2.2114,2.21147,4.000
4,45.000,0.44,2.3449,2.34500,4.000
4,45.133,0.83,2.4782,2.47827,4.000
4,45.267,1.36,2.6115,2.61163,4.000
4,45.400,2.03,2.7450,2.74510,4.000
4,45.533,2.87,2.8780,2.87813,4.000
4,45.667,3.89,3.0114,3.01153,4.000
4,45.800,5.08,3.1450,3.14510,4.000
4,45.933,6.46,3.2781,3.27820,4.000
4,46.067,8.05,3.4115,3.41160,4.000
4,46.200,9.87,3.5448,3.54490,4.000
4,46.333,11.97,3.6782,3.67830,4.000
4,46.467,14.34,3.8114,3.81153,4.000
4,46.600,17.02,3.9449,3.94500,4.000
4,46.733,20.10,4.0782,4.07827,4.000
4,46.867,23.64,4.2114,4.21153,4.000
4,47.000,27.69,4.3450,4.34510,4.000
4,47.133,32.33,4.4782,4.47833,4.000
4,47.267,37.67,4.6114,4.61150,4.000
4,47.400,43.85,4.7449,4.74500,4.000
4,47.667,48.11,4.8508,4.85093,4.000
4,47.800,37.59,4.7175,4.71760,4.000
4,47.933,30.12,4.5843,4.58437,4.000
4,48.067,24.35,4.4509,4.45100,4.000
4,48.200,19.77,4.3176,4.31770,4.000
4,48.333,16.03,4.1843,4.18443,4.000
4,48.467,12.99,4.0509,4.05100,4.000
4,48.600,10.52,3.9175,3.91760,4.000
4,48.733,8.48,3.7842,3.78433,4.000
4,48.867,6.85,3.6509,3.65100,4.000
4,49.000,5.46,3.5174,3.51750,4.000
4,49.133,4.31,3.3842,3.38433,4.000
4,49.267,3.35,3.2508,3.25090,4.000
4,49.400,2.55,3.1175,3.11760,4.000
4,49.533,1.89,2.9841,2.98420,4.000
4,49.667,1.35,2.8506,2.85070,4.000
4,49.800,0.89,2.7174,2.71750,4.000
4,49.933,0.54,2.5841,2.58423,4.000
4,50.067,0.26,2.4508,2.45087,4.000
4,50.200,0.08,2.3174,2.31750,4.000
4,50.333,0.01,2.1841,2.18417,4.000
4,50.467,0.00,2.0508,2.05093,4.000
4,50.600,0.00,1.9174,1.91750,4.000
4,50.733,0.00,1.7840,1.78413,4.000
4,50.867,0.00,1.6507,1.65080,4.000
4,51.000,0.00,1.5172,1.51730,4.000
4,51.133,0.00,1.3840,1.38407,4.000
4,51.267,0.00,1.2507,1.25080,4.000
4,51.400,0.00,1.1173,1.11740,4.000
4,51.533,0.00,0.9841,0.98417,4.000
4,51.667,0.00,0.8506,0.85070,4.000
4,51.800,0.00,0.7172,0.71730,4.000
4,51.933,0.00,0.5841,0.58417,4.000
4,52.067,0.00,0.4506,0.45073,4.000
4,52.200,0.00,0.3172,0.31730,4.000
4,52.333,0.00,0.1839,0.18403,4.000
4,52.467,0.00,0.0506,0.05067,4.000
4,52.733,0.00,-0.0003,-0.00020,4.000
4,52.867,0.01,-0.0003,-0.00020,4.000
4,53.000,0.00,-0.0003,-0.00020,4.000
4,53.133,0.00,-0.0003,-0.00020,4.000
4,53.267,0.00,-0.0003,-0.00020,4.000
4,53.400,0.00,-0.0003,-0.00020,4.000
4,53.533,0.00,-0.0003,-0.00020,4.000
4,53.667,0.00,-0.0003,-0.00020,4.000
4,53.800,0.00,-0.0003,-0.00020,4.000
4,53.933,0.00,-0.0003,-0.00020,4.000
4,54.067,0.00,-0.0003,-0.00020,4.000
4,54.200,0.00,-0.0003,-0.00020,4.000
4,54.333,0.00,-0.0003,-0.00020,4.000
4,54.467,0.00,-0.0003,-0.00020,4.000
4,54.600,0.00,-0.0002,-0.00010,4.000
4,54.733,0.00,-0.0002,-0.00010,4.000
4,54.867,0.00,-0.0002,-0.00010,4.000
4,55.000,0.00,-0.0002,-0.00010,4.000
4,55.133,0.00,-0.0002,-0.00010,4.000
4,55.267,0.00,-0.0002,-0.00010,4.000
4,55.400,0.00,-0.0002,-0.00010,4.000
4,55.533,0.00,-0.0002,-0.00010,4.000
4,55.733,0.00,-0.0002,-0.00010,4.000
4,55.867,0.00,-0.0002,-0.00010,4.000
4,56.000,0.00,-0.0002,-0.00010,4.000
4,56.133,0.00,-0.0002,-0.00010,4.000
4,56.267,0.00,-0.0002,-0.00010,4.000
4,56.400,0.00,-0.0002,-0.00010,4.000
4,56.533,0.00,-0.0002,-0.00010,4.000
5,56.867,-0.01,0.0711,0.07123,5.000
5,57.000,-0.01,0.2046,0.20470,5.000
5,57.133,-0.01,0.3382,0.33827,5.000
5,57.267,-0.01,0.4714,0.47147,5.000
5,57.400,-0.02,0.6047,0.60480,5.000
5,57.533,-0.01,0.7381,0.73817,5.000
5,57.667,-0.01,0.8713,0.87140,5.000
5,57.800,-0.01,1.0047,1.00480,5.000
5,57.933,-0.01,1.1382,1.13830,5.000
5,58.067,-0.01,1.2713,1.27143,5.000
5,58.200,-0.02,1.4047,1.40480,5.000
5,58.333,-0.01,1.5380,1.53813,5.000
5,58.467,-0.01,1.6714,1.67153,5.000
5,58.600,-0.02,1.8047,1.80480,5.000
5,58.733,-0.01,1.9382,1.93827,5.000
5,58.867,0.03,2.0715,2.07157,5.000
5,59.000,0.14,2.2047,2.20480,5.000
5,59.133,0.39,2.3382,2.33833,5.000
5,59.267,0.79,2.4716,2.47167,5.000
5,59.400,1.30,2.6049,2.60500,5.000
5,59.533,1.97,2.7383,2.73840,5.000
5,59.667,2.79,2.8714,2.87153,5.000
5,59.800,3.79,3.0047,3.00480,5.000
5,59.933,4.97,3.1382,3.13827,5.000
5,60.067,6.34,3.2714,3.27153,5.000
5,60.200,7.91,3.4047,3.40480,5.000
5,60.333,9.73,3.5381,3.53823,5.000
5,60.467,11.80,3.6716,3.67167,5.000
5,60.600,14.15,3.8048,3.80490,5.000
5,60.733,16.81,3.9382,3.93827,5.000
5,60.867,19.86,4.0716,4.07170,5.000
5,61.000,23.37,4.2048,4.20490,5.000
5,61.133,27.39,4.3382,4.33830,5.000
5,61.267,31.99,4.4716,4.47173,5.000
5,61.400,37.28,4.6047,4.60480,5.000
5,61.533,43.41,4.7381,4.73823,5.000
5,61.667,50.60,4.8715,4.87163,5.000
5,61.867,42.76,4.7909,4.79103,5.000
5,62.000,33.92,4.6577,4.65780,5.000
5,62.133,27.30,4.5242,4.52427,5.000
5,62.267,22.12,4.3910,4.39113,5.000
5,62.400,17.96,4.2577,4.25780,5.000
5,62.533,14.55,4.1241,4.12423,5.000
5,62.667,11.77,3.9909,3.99103,5.000
5,62.800,9.52,3.8576,3.85770,5.000
5,62.933,7.66,3.7242,3.72427,5.000
5,63.067,6.16,3.5909,3.59097,5.000
5,63.200,4.89,3.4574,3.45750,5.000
5,63.333,3.84,3.3241,3.32417,5.000
5,63.467,2.94,3.1909,3.19100,5.000
5,63.600,2.22,3.0576,3.05770,5.000
5,63.733,1.61,2.9240,2.92407,5.000
5,63.867,1.11,2.7907,2.79083,5.000
5,64.000,0.70,2.6575,2.65760,5.000
5,64.133,0.38,2.5240,2.52413,5.000
5,64.267,0.14,2.3908,2.39093,5.000
5,64.400,0.02,2.2575,2.25760,5.000
5,64.533,-0.02,2.1240,2.12407,5.000
5,64.667,-0.02,1.9908,1.99090,5.000
5,64.800,-0.02,1.8574,1.85750,5.000
5,64.933,-0.02,1.7240,1.72410,5.000
5,65.067,-0.02,1.5906,1.59070,5.000
5,65.200,-0.02,1.4574,1.45750,5.000
5,65.333,-0.01,1.3239,1.32397,5.000
5,65.467,-0.01,1.1907,1.19083,5.000
5,65.600,-0.01,1.0575,1.05760,5.000
5,65.733,-0.01,0.9240,0.92407,5.000
5,65.867,-0.01,0.7906,0.79073,5.000
5,66.000,-0.01,0.6573,0.65740,5.000
5,66.133,-0.01,0.5240,0.52410,5.000
5,66.267,-0.02,0.3906,0.39067,5.000
5,66.400,-0.01,0.2573,0.25740,5.000
5,66.533,-0.01,0.1238,0.12393,5.000
5,66.667,-0.01,-0.0094,-0.00930,5.000
5,66.867,-0.01,-0.0003,-0.00020,5.000
5,67.000,-0.01,-0.0003,-0.00020,5.000
5,67.133,-0.02,-0.0003,-0.00020,5.000
5,67.267,-0.01,-0.0003,-0.00020,5.000
5,67.400,-0.01,-0.0003,-0.00020,5.000
5,67.533,-0.02,-0.0003,-0.00020,5.000
5,67.667,-0.01,-0.0003,-0.00020,5.000
5,67.800,-0.02,-0.0003,-0.00020,5.000
5,67.933,-0.02,-0.0003,-0.00020,5.000
5,68.067,-0.01,-0.0003,-0.00020,5.000
5,68.200,-0.01,-0.0003,-0.00020,5.000
5,68.333,-0.01,-0.0003,-0.00020,5.000
5,68.467,-0.01,-0.0003,-0.00020,5.000
5,68.600,-0.01,-0.0003,-0.00020,5.000
5,68.733,-0.01,-0.0003,-0.00020,5.000
5,68.867,-0.01,-0.0003,-0.00020,5.000
5,69.000,-0.01,-0.0002,-0.00010,5.000
5,69.133,-0.02,-0.0002,-0.00010,5.000
5,69.267,-0.01,-0.0002,-0.00010,5.000
5,69.400,-0.01,-0.0002,-0.00010,5.000
5,69.533,-0.01,-0.0002,-0.00010,5.000
5,69.667,-0.01,-0.0002,-0.00010,5.000
5,69.867,-0.01,-0.0002,-0.00010,5.000
5,70.000,-0.01,-0.0002,-0.00010,5.000
5,70.133,-0.01,-0.0002,-0.00010,5.000
5,70.267,-0.01,-0.0002,-0.00010,5.000
5,70.400,-0.01,-0.0002,-0.00010,5.000
5,70.533,-0.02,-0.0002,-0.00010,5.000
5,70.667,-0.02,-0.0002,-0.00010,5.000
6,71.067,-0.01,0.1111,0.11123,6.000
6,71.200,-0.01,0.2446,0.24470,6.000
6,71.333,0.00,0.3780,0.37813,6.000
6,71.467,0.00,0.5113,0.51140,6.000
6,71.600,-0.01,0.6447,0.64480,6.000
6,71.733,-0.01,0.7781,0.77820,6.000
6,71.867,0.00,0.9113,0.91140,6.000
6,72.000,-0.01,1.0447,1.04480,6.000
6,72.133,-0.01,1.1782,1.17827,6.000
6,72.267,-0.01,1.3113,1.31140,6.000
6,72.400,-0.01,1.4446,1.44470,6.000
6,72.533,-0.01,1.5780,1.57813,6.000
6,72.667,0.00,1.7114,1.71153,6.000
6,72.800,-0.01,1.8447,1.84480,6.000
6,72.933,0.00,1.9782,1.97830,6.000
6,73.067,0.05,2.1114,2.11153,6.000
6,73.200,0.21,2.2446,2.24470,6.000
6,73.333,0.50,2.3782,2.37830,6.000
6,73.467,0.92,2.5116,2.51167,6.000
6,73.600,1.48,2.6449,2.64500,6.000
6,73.733,2.18,2.7782,2.77827,6.000
6,73.867,3.05,2.9114,2.91153,6.000
6,74.000,4.10,3.0447,3.04480,6.000
6,74.133,5.33,3.1782,3.17827,6.000
6,74.267,6.76,3.3115,3.31160,6.000
6,74.400,8.41,3.4447,3.44480,6.000
6,74.533,10.27,3.5781,3.57820,6.000
6,74.667,12.42,3.7115,3.71160,6.000
6,74.800,14.86,3.8448,3.84490,6.000
6,74.933,17.61,3.9782,3.97827,6.000
6,75.067,20.80,4.1116,4.11167,6.000
6,75.200,24.46,4.2448,4.24490,6.000
6,75.333,28.63,4.3783,4.37837,6.000
6,75.467,33.42,4.5116,4.51173,6.000
6,75.600,38.96,4.6448,4.64490,6.000
6,75.733,45.37,4.7782,4.77827,6.000
6,75.933,52.10,4.8922,4.89233,6.000
6,76.067,40.21,4.7589,4.75900,6.000
6,76.200,32.07,4.6256,4.62570,6.000
6,76.333,25.88,4.4922,4.49233,6.000
6,76.467,21.00,4.3590,4.35907,6.000
6,76.600,17.03,4.2257,4.22580,6.000
6,76.733,13.79,4.0922,4.09233,6.000
6,76.867,11.15,3.9589,3.95900,6.000
6,77.000,8.99,3.8256,3.82570,6.000
6,77.133,7.25,3.6922,3.69230,6.000
6,77.267,5.81,3.5588,3.55890,6.000
6,77.400,4.60,3.4255,3.42560,6.000
6,77.533,3.60,3.2921,3.29223,6.000
6,77.667,2.74,3.1587,3.15883,6.000
6,77.800,2.05,3.0256,3.02570,6.000
6,77.933,1.48,2.8920,2.89207,6.000
6,78.067,1.00,2.7587,2.75880,6.000
6,78.200,0.62,2.6256,2.62570,6.000
6,78.333,0.32,2.4921,2.49220,6.000
6,78.467,0.12,2.3588,2.35887,6.000
6,78.600,0.02,2.2254,2.22550,6.000
6,78.733,-0.01,2.0921,2.09220,6.000
6,78.867,-0.01,1.9587,1.95877,6.000
6,79.000,-0.01,1.8255,1.82560,6.000
6,79.133,-0.01,1.6921,1.69220,6.000
6,79.267,-0.01,1.5586,1.55867,6.000
6,79.400,-0.01,1.4254,1.42550,6.000
6,79.533,-0.01,1.2920,1.29213,6.000
6,79.667,-0.01,1.1587,1.15883,6.000
6,79.800,-0.01,1.0255,1.02560,6.000
6,79.933,-0.01,0.8920,0.89207,6.000
6,80.067,-0.01,0.7586,0.75873,6.000
6,80.200,-0.01,0.6254,0.62550,6.000
6,80.333,-0.01,0.4920,0.49213,6.000
6,80.467,-0.01,0.3585,0.35863,6.000
6,80.600,-0.01,0.2253,0.22540,6.000
6,80.733,-0.01,0.0919,0.09197,6.000
6,80.933,0.00,-0.0413,-0.04123,6.000
6,81.067,-0.01,-0.0003,-0.00020,6.000
6,81.200,-0.01,-0.0003,-0.00020,6.000
6,81.333,-0.01,-0.0003,-0.00020,6.000
6,81.467,0.00,-0.0003,-0.00020,6.000
6,81.600,0.00,-0.0003,-0.00020,6.000
6,81.733,-0.01,-0.0003,-0.00020,6.000
6,81.867,0.00,-0.0003,-0.00020,6.000
6,82.000,0.00,-0.0003,-0.00020,6.000
6,82.133,0.00,-0.0003,-0.00020,6.000
6,82.267,-0.01,-0.0003,-0.00020,6.000
6,82.400,-0.01,-0.0003,-0.00020,6.000
6,82.533,-0.01,-0.0003,-0.00020,6.000
6,82.667,0.00,-0.0003,-0.00020,6.000
6,82.800,-0.01,-0.0003,-0.00020,6.000
6,82.933,0.00,-0.0003,-0.00020,6.000
6,83.067,-0.01,-0.0002,-0.00010,6.000
6,83.200,-0.01,-0.0002,-0.00010,6.000
6,83.333,0.00,-0.0002,-0.00010,6.000
6,83.467,-0.01,-0.0002,-0.00010,6.000
6,83.600,-0.01,-0.0002,-0.00010,6.000
6,83.733,0.00,-0.0002,-0.00010,6.000
6,83.867,0.00,-0.0002,-0.00010,6.000
6,84.133,0.00,-0.0002,-0.00010,6.000
6,84.267,-0.01,-0.0002,-0.00010,6.000
6,84.400,-0.01,-0.0002,-0.00010,6.000
6,84.533,-0.01,-0.0002,-0.00010,6.000
6,84.667,0.00,-0.0002,-0.00010,6.000
6,84.800,-0.01,-0.0002,-0.00010,6.000
6,84.933,0.00,-0.0002,-0.00010,6.000
7,85.267,-0.01,0.1511,0.15123,7.000
7,85.400,-0.01,0.2846,0.28470,7.000
7,85.533,-0.01,0.4181,0.41820,7.000
7,85.667,-0.01,0.5513,0.55143,7.000
7,85.800,-0.01,0.6846,0.68470,7.000
7,85.933,-0.01,0.8181,0.81823,7.000
7,86.067,-0.01,0.9513,0.95140,7.000
7,86.200,0.00,1.0847,1.08480,7.000
7,86.333,-0.01,1.2182,1.21827,7.000
7,86.467,-0.01,1.3513,1.35143,7.000
7,86.600,-0.01,1.4846,1.48470,7.000
7,86.733,-0.01,1.6181,1.61817,7.000
7,86.867,0.00,1.7515,1.75157,7.000
7,87.000,-0.01,1.8847,1.88480,7.000
7,87.133,0.01,2.0182,2.01830,7.000
7,87.267,0.08,2.1514,2.15153,7.000
7,87.400,0.27,2.2847,2.28480,7.000
7,87.533,0.61,2.4183,2.41837,7.000
7,87.667,1.06,2.5516,2.55167,7.000
7,87.800,1.67,2.6848,2.68490,7.000
7,87.933,2.41,2.8181,2.81817,7.000
7,88.067,3.33,2.9515,2.95157,7.000
7,88.200,4.43,3.0848,3.08490,7.000
7,88.333,5.71,3.2181,3.21823,7.000
7,88.467,7.20,3.3515,3.35160,7.000
7,88.600,8.90,3.4847,3.48480,7.000
7,88.733,10.86,3.6182,3.61827,7.000
7,88.867,13.08,3.7515,3.75163,7.000
7,89.000,15.59,3.8847,3.88480,7.000
7,89.133,18.47,4.0182,4.01833,7.000
7,89.267,21.79,4.1515,4.15163,7.000
7,89.400,25.59,4.2847,4.28480,7.000
7,89.533,29.93,4.4182,4.41830,7.000
7,89.667,34.93,4.5516,4.55167,7.000
7,89.800,40.70,4.6848,4.68490,7.000
7,89.933,47.44,4.8182,4.81827,7.000
7,90.133,48.82,4.8642,4.86430,7.000
7,90.267,38.10,4.7308,4.73090,7.000
7,90.400,30.51,4.5976,4.59770,7.000
7,90.533,24.68,4.4643,4.46443,7.000
7,90.667,20.02,4.3309,4.33100,7.000
7,90.800,16.23,4.1975,4.19760,7.000
7,90.933,13.14,4.0643,4.06443,7.000
7,91.067,10.63,3.9308,3.93090,7.000
7,91.200,8.56,3.7976,3.79770,7.000
7,91.333,6.90,3.6643,3.66443,7.000
7,91.467,5.52,3.5307,3.53080,7.000
7,91.600,4.36,3.3975,3.39760,7.000
7,91.733,3.39,3.2642,3.26433,7.000
7,91.867,2.58,3.1308,3.13087,7.000
7,92.000,1.91,2.9974,2.99750,7.000
7,92.133,1.35,2.8640,2.86413,7.000
7,92.267,0.90,2.7308,2.73090,7.000
7,92.400,0.54,2.5975,2.59760,7.000
7,92.533,0.26,2.4642,2.46430,7.000
7,92.667,0.08,2.3308,2.33087,7.000
7,92.800,0.01,2.1973,2.19740,7.000
7,92.933,-0.01,2.0641,2.06423,7.000
7,93.067,-0.01,1.9308,1.93087,7.000
7,93.200,-0.01,1.7974,1.79750,7.000
7,93.333,-0.01,1.6641,1.66423,7.000
7,93.467,-0.01,1.5306,1.53073,7.000
7,93.600,-0.01,1.3973,1.39740,7.000
7,93.733,-0.01,1.2640,1.26410,7.000
7,93.867,-0.01,1.1308,1.13087,7.000
7,94.000,-0.01,0.9972,0.99730,7.000
7,94.133,-0.01,0.8640,0.86413,7.000
7,94.267,-0.01,0.7307,0.73077,7.000
7,94.400,-0.01,0.5971,0.59720,7.000
7,94.533,-0.01,0.4640,0.46413,7.000
7,94.667,-0.01,0.3307,0.33083,7.000
7,94.800,-0.01,0.1972,0.19730,7.000
7,94.933,-0.01,0.0639,0.06403,7.000
7,95.133,-0.01,-0.0104,-0.01030,7.000
7,95.267,-0.01,-0.0003,-0.00020,7.000
7,95.400,-0.01,-0.0003,-0.00020,7.000
7,95.533,-0.01,-0.0003,-0.00020,7.000
7,95.667,-0.01,-0.0003,-0.00020,7.000
7,95.800,-0.01,-0.0003,-0.00020,7.000
7,95.933,-0.01,-0.0003,-0.00020,7.000
7,96.067,-0.01,-0.0003,-0.00020,7.000
7,96.200,0.00,-0.0003,-0.00020,7.000
7,96.333,-0.01,-0.0003,-0.00020,7.000
7,96.467,-0.01,-0.0003,-0.00020,7.000
7,96.600,-0.01,-0.0003,-0.00020,7.000
7,96.733,-0.01,-0.0003,-0.00020,7.000
7,96.867,-0.01,-0.0003,-0.00020,7.000
7,97.000,-0.01,-0.0003,-0.00020,7.000
7,97.133,-0.01,-0.0003,-0.00020,7.000
7,97.267,-0.01,-0.0003,-0.00020,7.000
7,97.400,-0.01,-0.0002,-0.00010,7.000
7,97.533,-0.01,-0.0002,-0.00010,7.000
7,97.667,-0.01,-0.0002,-0.00010,7.000
7,97.800,-0.01,-0.0002,-0.00010,7.000
7,97.933,-0.01,-0.0002,-0.00010,7.000
7,98.067,-0.01,-0.0002,-0.00010,7.000
7,98.267,-0.01,-0.0002,-0.00010,7.000
7,98.400,-0.01,-0.0002,-0.00010,7.000
7,98.533,-0.01,-0.0002,-0.00010,7.000
7,98.667,-0.01,-0.0002,-0.00010,7.000
7,98.800,-0.01,-0.0002,-0.00010,7.000
7,98.933,0.00,-0.0002,-0.00010,7.000
7,99.067,-0.01,-0.0002,-0.00010,7.000
8,99.467,0.01,0.1813,0.18143,8.000
8,99.600,0.00,0.3146,0.31470,8.000
8,99.733,0.00,0.4480,0.44810,8.000
8,99.867,0.00,0.5815,0.58157,8.000
8,100.000,0.00,0.7146,0.71470,8.000
8,100.133,0.01,0.8480,0.84813,8.000
8,100.267,0.00,0.9815,0.98157,8.000
8,100.400,0.00,1.1147,1.11480,8.000
8,100.533,0.00,1.2481,1.24823,8.000
8,100.667,0.00,1.3814,1.38147,8.000
8,100.800,0.01,1.5147,1.51480,8.000
8,100.933,0.00,1.6481,1.64817,8.000
8,101.067,0.00,1.7815,1.78163,8.000
8,101.200,0.00,1.9148,1.91490,8.000
8,101.333,0.03,2.0481,2.04823,8.000
8,101.467,0.12,2.1815,2.18157,8.000
8,101.600,0.35,2.3148,2.31490,8.000
8,101.733,0.71,2.4481,2.44820,8.000
8,101.867,1.19,2.5816,2.58170,8.000
8,102.000,1.83,2.7149,2.71500,8.000
8,102.133,2.62,2.8480,2.84810,8.000
8,102.267,3.58,2.9814,2.98150,8.000
8,102.400,4.73,3.1148,3.11490,8.000
8,102.533,6.05,3.2481,3.24823,8.000
8,102.667,7.58,3.3815,3.38163,8.000
8,102.800,9.34,3.5149,3.51500,8.000
8,102.933,11.36,3.6481,3.64817,8.000
8,103.067,13.65,3.7815,3.78163,8.000
8,103.200,16.25,3.9149,3.91500,8.000
8,103.333,19.23,4.0481,4.04823,8.000
8,103.467,22.65,4.1815,4.18157,8.000
8,103.600,26.59,4.3149,4.31500,8.000
8,103.733,31.09,4.4481,4.44823,8.000
8,103.867,36.24,4.5815,4.58157,8.000
8,104.000,42.25,4.7149,4.71500,8.000
8,104.133,49.29,4.8481,4.84817,8.000
8,104.333,46.15,4.8342,4.83433,8.000
8,104.467,36.31,4.7009,4.70097,8.000
8,104.600,29.16,4.5674,4.56750,8.000
8,104.733,23.60,4.4344,4.43447,8.000
8,104.867,19.16,4.3010,4.30113,8.000
8,105.000,15.52,4.1677,4.16780,8.000
8,105.133,12.56,4.0343,4.03440,8.000
8,105.267,10.15,3.9010,3.90110,8.000
8,105.400,8.17,3.7674,3.76750,8.000
8,105.533,6.59,3.6343,3.63437,8.000
8,105.667,5.25,3.5008,3.50093,8.000
8,105.800,4.13,3.3675,3.36760,8.000
8,105.933,3.20,3.2342,3.23433,8.000
8,106.067,2.42,3.1009,3.10097,8.000
8,106.200,1.78,2.9673,2.96740,8.000
8,106.333,1.25,2.8340,2.83410,8.000
8,106.467,0.82,2.7009,2.70103,8.000
8,106.600,0.48,2.5675,2.56760,8.000
8,106.733,0.22,2.4341,2.43423,8.000
8,106.867,0.07,2.3008,2.30090,8.000
8,107.000,0.00,2.1671,2.16720,8.000
8,107.133,0.00,2.0342,2.03427,8.000
8,107.267,0.00,1.9007,1.90083,8.000
8,107.400,-0.01,1.7673,1.76740,8.000
8,107.533,0.00,1.6339,1.63403,8.000
8,107.667,0.00,1.5007,1.50080,8.000
8,107.800,0.00,1.3671,1.36720,8.000
8,107.933,0.00,1.2340,1.23413,8.000
8,108.067,0.00,1.1008,1.10090,8.000
8,108.200,0.00,0.9672,0.96730,8.000
8,108.333,0.00,0.8340,0.83410,8.000
8,108.467,0.00,0.7007,0.70080,8.000
8,108.600,0.00,0.5673,0.56740,8.000
8,108.733,0.00,0.4339,0.43400,8.000
8,108.867,0.00,0.3007,0.30080,8.000
8,109.000,0.00,0.1672,0.16730,8.000
8,109.133,0.00,0.0338,0.03390,8.000
8,109.267,0.00,-0.0443,-0.04417,8.000
8,109.400,0.01,-0.0003,-0.00020,8.000
8,109.533,0.00,-0.0003,-0.00020,8.000
8,109.667,0.00,-0.0003,-0.00020,8.000
8,109.800,0.01,-0.0003,-0.00020,8.000
8,109.933,0.00,-0.0003,-0.00020,8.000
8,110.067,0.00,-0.0003,-0.00020,8.000
8,110.200,0.00,-0.0003,-0.00020,8.000
8,110.333,0.00,-0.0003,-0.00020,8.000
8,110.467,0.00,-0.0003,-0.00020,8.000
8,110.600,0.00,-0.0003,-0.00020,8.000
8,110.733,0.00,-0.0003,-0.00020,8.000
8,110.867,0.00,-0.0003,-0.00020,8.000
8,111.000,0.01,-0.0003,-0.00020,8.000
8,111.133,0.01,-0.0003,-0.00020,8.000
8,111.267,0.00,-0.0003,-0.00020,8.000
8,111.400,0.01,-0.0003,-0.00020,8.000
8,111.533,0.01,-0.0002,-0.00010,8.000
8,111.667,0.00,-0.0002,-0.00010,8.000
8,111.800,0.00,-0.0002,-0.00010,8.000
8,111.933,0.01,-0.0002,-0.00010,8.000
8,112.067,0.00,-0.0002,-0.00010,8.000
8,112.200,0.00,-0.0002,-0.00010,8.000
8,112.400,0.01,-0.0002,-0.00010,8.000
8,112.533,0.00,-0.0002,-0.00010,8.000
8,112.667,0.00,-0.0002,-0.00010,8.000
8,112.800,0.00,-0.0002,-0.00010,8.000
8,112.933,0.00,-0.0002,-0.00010,8.000
8,113.067,0.00,-0.0002,-0.00010,8.000
8,113.200,0.01,-0.0002,-0.00010,8.000
9,113.533,0.00,0.0619,0.06200,9.000
9,113.667,0.00,0.1953,0.19537,9.000
9,113.800,0.00,0.3288,0.32890,9.000
9,113.933,0.00,0.4621,0.46217,9.000
9,114.067,0.00,0.5954,0.59550,9.000
9,114.200,0.00,0.7287,0.72880,9.000
9,114.333,0.00,0.8621,0.86220,9.000
9,114.467,0.00,0.9954,0.99547,9.000
9,114.600,0.00,1.1288,1.12890,9.000
9,114.733,0.00,1.2622,1.26227,9.000
9,114.867,0.00,1.3953,1.39543,9.000
9,115.000,0.00,1.5286,1.52870,9.000
9,115.133,0.00,1.6621,1.66223,9.000
9,115.267,0.00,1.7954,1.79547,9.000
9,115.400,0.00,1.9287,1.92880,9.000
9,115.533,0.03,2.0622,2.06233,9.000
9,115.667,0.13,2.1954,2.19550,9.000
9,115.800,0.36,2.3287,2.32880,9.000
9,115.933,0.74,2.4622,2.46230,9.000
9,116.067,1.24,2.5956,2.59573,9.000
9,116.200,1.88,2.7289,2.72900,9.000
9,116.333,2.70,2.8621,2.86223,9.000
9,116.467,3.68,2.9954,2.99553,9.000
9,116.600,4.85,3.1287,3.12880,9.000
9,116.733,6.19,3.2622,3.26227,9.000
9,116.867,7.74,3.3954,3.39553,9.000
9,117.000,9.53,3.5287,3.52880,9.000
9,117.133,11.56,3.6622,3.66227,9.000
9,117.267,13.88,3.7955,3.79560,9.000
9,117.400,16.53,3.9288,3.92890,9.000
9,117.533,19.53,4.0622,4.06230,9.000
9,117.667,23.00,4.1955,4.19563,9.000
9,117.800,26.99,4.3288,4.32890,9.000
9,117.933,31.55,4.4622,4.46230,9.000
9,118.067,36.79,4.5955,4.59560,9.000
9,118.200,42.88,4.7287,4.72880,9.000
9,118.333,50.01,4.8622,4.86227,9.000
9,118.533,44.58,4.8162,4.81633,9.000
9,118.667,35.23,4.6829,4.68297,9.000
9,118.800,28.31,4.5497,4.54980,9.000
9,118.933,22.96,4.4163,4.41637,9.000
9,119.067,18.63,4.2830,4.28307,9.000
9,119.200,15.10,4.1496,4.14970,9.000
9,119.333,12.23,4.0163,4.01637,9.000
9,119.467,9.88,3.8829,3.88297,9.000
9,119.600,7.95,3.7496,3.74970,9.000
9,119.733,6.42,3.6162,3.61633,9.000
9,119.867,5.12,3.4828,3.48290,9.000
9,120.000,4.03,3.3496,3.34970,9.000
9,120.133,3.14,3.2162,3.21630,9.000
9,120.267,2.38,3.0827,3.08283,9.000
9,120.400,1.76,2.9495,2.94960,9.000
9,120.533,1.23,2.8160,2.81610,9.000
9,120.667,0.80,2.6828,2.68290,9.000
9,120.800,0.47,2.5495,2.54960,9.000
9,120.933,0.21,2.4161,2.41623,9.000
9,121.067,0.06,2.2827,2.28277,9.000
9,121.200,0.01,2.1494,2.14950,9.000
9,121.333,0.00,2.0161,2.01623,9.000
9,121.467,0.00,1.8826,1.88273,9.000
9,121.600,0.00,1.7495,1.74960,9.000
9,121.733,0.00,1.6160,1.61610,9.000
9,121.867,0.00,1.4826,1.48273,9.000
9,122.000,0.00,1.3493,1.34940,9.000
9,122.133,0.00,1.2161,1.21623,9.000
9,122.267,0.00,1.0826,1.08273,9.000
9,122.400,0.00,0.9493,0.94940,9.000
9,122.533,0.00,0.8161,0.81620,9.000
9,122.667,0.00,0.6826,0.68270,9.000
9,122.800,0.00,0.5494,0.54950,9.000
9,122.933,0.00,0.4160,0.41610,9.000
9,123.067,0.00,0.2826,0.28270,9.000
9,123.200,0.00,0.1493,0.14940,9.000
9,123.333,0.00,0.0159,0.01603,9.000
9,123.533,0.00,-0.0003,-0.00020,9.000
9,123.667,0.00,-0.0004,-0.00030,9.000
9,123.800,0.00,-0.0004,-0.00030,9.000
9,123.933,0.00,-0.0004,-0.00030,9.000
9,124.067,0.00,-0.0003,-0.00020,9.000
9,124.200,0.00,-0.0003,-0.00020,9.000
9,124.333,0.00,-0.0003,-0.00020,9.000
9,124.467,0.00,-0.0003,-0.00020,9.000
9,124.600,0.00,-0.0003,-0.00020,9.000
9,124.733,0.00,-0.0003,-0.00020,9.000
9,124.867,0.00,-0.0003,-0.00020,9.000
9,125.000,0.00,-0.0003,-0.00020,9.000
9,125.133,0.00,-0.0003,-0.00020,9.000
9,125.267,0.00,-0.0003,-0.00020,9.000
9,125.400,0.00,-0.0003,-0.00020,9.000
9,125.533,0.00,-0.0003,-0.00020,9.000
9,125.667,0.00,-0.0003,-0.00020,9.000
9,125.800,0.00,-0.0002,-0.00010,9.000
9,125.933,0.00,-0.0002,-0.00010,9.000
9,126.067,0.00,-0.0002,-0.00010,9.000
9,126.200,0.00,-0.0002,-0.00010,9.000
9,126.333,0.00,-0.0002,-0.00010,9.000
9,126.533,0.00,-0.0002,-0.00010,9.000
9,126.667,0.01,-0.0002,-0.00010,9.000
9,126.800,0.00,-0.0002,-0.00010,9.000
9,126.933,0.00,-0.0002,-0.00010,9.000
9,127.067,0.00,-0.0002,-0.00010,9.000
9,127.200,0.00,-0.0002,-0.00010,9.000
9,127.333,0.00,-0.0002,-0.00010,9.000
9,127.467,0.00,-0.0002,-0.00010,9.000
10,127.800,0.00,0.1645,0.16460,10.000
10,127.933,0.01,0.2981,0.29820,10.000
10,128.067,0.01,0.4314,0.43147,10.000
10,128.200,0.00,0.5647,0.56480,10.000
10,128.333,0.00,0.6981,0.69823,10.000
10,128.467,0.01,0.8314,0.83150,10.000
10,128.600,0.01,0.9646,0.96470,10.000
10,128.733,0.00,1.0982,1.09830,10.000
10,128.867,0.00,1.2315,1.23163,10.000
10,129.000,0.00,1.3647,1.36480,10.000
10,129.133,0.00,1.4981,1.49823,10.000
10,129.267,0.01,1.6315,1.63157,10.000
10,129.400,0.00,1.7647,1.76480,10.000
10,129.533,0.00,1.8981,1.89823,10.000
10,129.667,0.03,2.0315,2.03160,10.000
10,129.800,0.11,2.1646,2.16470,10.000
10,129.933,0.31,2.2982,2.29827,10.000
10,130.067,0.66,2.4316,2.43170,10.000
10,130.200,1.12,2.5648,2.56490,10.000
10,130.333,1.73,2.6983,2.69837,10.000
10,130.467,2.49,2.8314,2.83153,10.000
10,130.600,3.42,2.9647,2.96480,10.000
10,130.733,4.53,3.0981,3.09823,10.000
10,130.867,5.82,3.2316,3.23167,10.000
10,131.000,7.32,3.3647,3.36480,10.000
10,131.133,9.04,3.4981,3.49820,10.000
10,131.267,11.01,3.6315,3.63160,10.000
10,131.400,13.25,3.7647,3.76480,10.000
10,131.533,15.80,3.8982,3.89827,10.000
10,131.667,18.71,4.0316,4.03170,10.000
10,131.800,22.05,4.1647,4.16480,10.000
10,131.933,25.88,4.2982,4.29833,10.000
10,132.067,30.28,4.4316,4.43173,10.000
10,132.200,35.36,4.5647,4.56480,10.000
10,132.333,41.19,4.6981,4.69817,10.000
10,132.467,48.04,4.8316,4.83167,10.000
10,132.667,47.41,4.8508,4.85090,10.000
10,132.800,37.15,4.7176,4.71770,10.000
10,132.933,29.79,4.5843,4.58440,10.000
10,133.067,24.11,4.4509,4.45103,10.000
10,133.200,19.58,4.3177,4.31780,10.000
10,133.333,15.89,4.1843,4.18437,10.000
10,133.467,12.88,4.0509,4.05103,10.000
10,133.600,10.42,3.9176,3.91770,10.000
10,133.733,8.40,3.7843,3.78437,10.000
10,133.867,6.80,3.6509,3.65097,10.000
10,134.000,5.45,3.5175,3.51760,10.000
10,134.133,4.31,3.3843,3.38437,10.000
10,134.267,3.37,3.2507,3.25083,10.000
10,134.400,2.57,3.1174,3.11750,10.000
10,134.533,1.92,2.9841,2.98423,10.000
10,134.667,1.37,2.8505,2.85063,10.000
10,134.800,0.91,2.7175,2.71760,10.000
10,134.933,0.55,2.5841,2.58423,10.000
10,135.067,0.28,2.4508,2.45087,10.000
10,135.200,0.10,2.3174,2.31750,10.000
10,135.333,0.02,2.1841,2.18417,10.000
10,135.467,0.00,2.0508,2.05087,10.000
10,135.600,0.00,1.9174,1.91750,10.000
10,135.733,0.00,1.7841,1.78420,10.000
10,135.867,0.00,1.6506,1.65070,10.000
10,136.000,0.00,1.5173,1.51740,10.000
10,136.133,0.00,1.3840,1.38410,10.000
10,136.267,0.00,1.2507,1.25077,10.000
10,136.400,0.01,1.1173,1.11740,10.000
10,136.533,0.00,0.9841,0.98417,10.000
10,136.667,0.00,0.8507,0.85077,10.000
10,136.800,0.00,0.7172,0.71730,10.000
10,136.933,0.01,0.5840,0.58413,10.000
10,137.067,0.00,0.4506,0.45073,10.000
10,137.200,0.00,0.3172,0.31730,10.000
10,137.333,0.01,0.1840,0.18407,10.000
10,137.467,0.01,0.0505,0.05063,10.000
10,137.733,0.01,-0.0003,-0.00020,10.000
10,137.867,0.00,-0.0003,-0.00020,10.000
10,138.000,0.01,-0.0003,-0.00020,10.000
10,138.133,0.00,-0.0003,-0.00020,10.000
10,138.267,0.00,-0.0003,-0.00020,10.000
10,138.400,0.01,-0.0003,-0.00020,10.000
10,138.533,0.01,-0.0003,-0.00020,10.000
10,138.667,0.00,-0.0003,-0.00020,10.000
10,138.800,0.00,-0.0003,-0.00020,10.000
10,138.933,0.01,-0.0003,-0.00020,10.000
10,139.067,0.01,-0.0003,-0.00020,10.000
10,139.200,0.01,-0.0003,-0.00020,10.000
10,139.333,0.00,-0.0003,-0.00020,10.000
10,139.467,0.00,-0.0003,-0.00020,10.000
10,139.600,0.00,-0.0003,-0.00020,10.000
10,139.733,0.00,-0.0002,-0.00010,10.000
10,139.867,0.01,-0.0002,-0.00010,10.000
10,140.000,0.00,-0.0002,-0.00010,10.000
10,140.133,0.01,-0.0002,-0.00010,10.000
10,140.267,0.01,-0.0002,-0.00010,10.000
10,140.400,0.01,-0.0002,-0.00010,10.000
10,140.533,0.00,-0.0002,-0.00010,10.000
10,140.733,0.01,-0.0002,-0.00010,10.000
10,140.867,0.00,-0.0002,-0.00010,10.000
10,141.000,0.00,-0.0002,-0.00010,10.000
10,141.133,0.00,-0.0002,-0.00010,10.000
10,141.267,0.00,-0.0002,-0.00010,10.000
10,141.400,0.00,-0.0002,-0.00010,10.000
10,141.533,0.01,-0.0002,-0.00010,10.000
10,141.600,0.01,-0.0002,-0.00010,10.000