File: AIME_journal_files/AIME_data/calibDATA_loadcell/date_02:15:2018/Instron_02.15.2018/1_50_3_1_0_0.txt
""
"Test Method","Radhen_Load_Cntrl_Cmprsn_250N_12-7.msm"
"Sample I. D.","Sample1.mss"
"Specimen Number","8"

"TheCycle_Output ()","_Time (s)","_Load (N)","_Extension (mm)","RealTimeDepth (mm)","CycleNumber ()"

1,0.333,0.00,0.0916,0.09163,1.000
1,0.467,0.00,0.2251,0.22510,1.000
1,0.600,0.00,0.3584,0.35840,1.000
1,0.733,0.00,0.4919,0.49190,1.000
1,0.867,0.00,0.6252,0.62517,1.000
1,1.000,0.00,0.7585,0.75850,1.000
1,1.133,0.00,0.8919,0.89190,1.000
1,1.267,0.02,1.0252,1.02523,1.000
1,1.400,0.06,1.1586,1.15860,1.000
1,1.533,0.13,1.2919,1.29190,1.000
1,1.667,0.20,1.4251,1.42513,1.000
1,1.800,0.31,1.5586,1.55860,1.000
1,1.933,0.47,1.6920,1.69200,1.000
1,2.067,0.68,1.8253,1.82533,1.000
1,2.200,0.96,1.9586,1.95860,1.000
1,2.333,1.32,2.0920,2.09197,1.000
1,2.467,1.81,2.2253,2.22533,1.000
1,2.600,2.42,2.3587,2.35870,1.000
1,2.733,3.15,2.4921,2.49213,1.000
1,2.867,3.99,2.6254,2.62540,1.000
1,3.000,4.95,2.7586,2.75860,1.000
1,3.133,6.08,2.8920,2.89203,1.000
1,3.267,7.46,3.0253,3.02533,1.000
1,3.400,9.08,3.1586,3.15860,1.000
1,3.533,10.99,3.2921,3.29207,1.000
1,3.667,13.21,3.4253,3.42527,1.000
1,3.800,15.78,3.5586,3.55860,1.000
1,3.933,18.77,3.6921,3.69207,1.000
1,4.067,22.24,3.8254,3.82540,1.000
1,4.200,26.24,3.9587,3.95870,1.000
1,4.333,30.86,4.0921,4.09210,1.000
1,4.467,36.23,4.2255,4.22547,1.000
1,4.600,42.50,4.3587,4.35870,1.000
1,4.733,50.00,4.4920,4.49203,1.000
1,4.933,43.15,4.4261,4.42613,1.000
1,5.067,33.93,4.2930,4.29297,1.000
1,5.200,27.19,4.1595,4.15950,1.000
1,5.333,21.93,4.0262,4.02620,1.000
1,5.467,17.72,3.8930,3.89297,1.000
1,5.600,14.32,3.7594,3.75940,1.000
1,5.733,11.58,3.6262,3.62617,1.000
1,5.867,9.38,3.4929,3.49287,1.000
1,6.000,7.54,3.3593,3.35930,1.000
1,6.133,6.04,3.2261,3.22613,1.000
1,6.267,4.80,3.0928,3.09283,1.000
1,6.400,3.79,2.9593,2.95930,1.000
1,6.533,2.95,2.8260,2.82600,1.000
1,6.667,2.24,2.6927,2.69270,1.000
1,6.800,1.69,2.5595,2.55950,1.000
1,6.933,1.20,2.4260,2.42603,1.000
1,7.067,0.82,2.2929,2.29287,1.000
1,7.200,0.50,2.1593,2.15930,1.000
1,7.333,0.27,2.0259,2.02593,1.000
1,7.467,0.10,1.8929,1.89287,1.000
1,7.600,0.02,1.7593,1.75930,1.000
1,7.733,-0.01,1.6260,1.62597,1.000
1,7.867,0.00,1.4926,1.49263,1.000
1,8.000,0.00,1.3593,1.35930,1.000
1,8.133,0.00,1.2258,1.22580,1.000
1,8.267,0.00,1.0927,1.09273,1.000
1,8.400,0.00,0.9594,0.95940,1.000
1,8.533,0.00,0.8259,0.82587,1.000
1,8.667,0.00,0.6927,0.69270,1.000
1,8.800,0.00,0.5593,0.55930,1.000
1,8.933,0.00,0.4259,0.42593,1.000
1,9.067,0.00,0.2927,0.29270,1.000
1,9.200,0.00,0.1594,0.15940,1.000
1,9.333,0.00,0.0257,0.02573,1.000
1,9.533,0.00,-0.0003,-0.00030,1.000
1,9.667,0.00,-0.0003,-0.00030,1.000
1,9.800,0.00,-0.0003,-0.00030,1.000
1,9.933,0.00,-0.0003,-0.00030,1.000
1,10.067,0.00,-0.0003,-0.00030,1.000
1,10.200,0.00,-0.0003,-0.00030,1.000
1,10.333,0.00,-0.0003,-0.00030,1.000
1,10.467,0.00,-0.0003,-0.00030,1.000
1,10.600,0.00,-0.0003,-0.00030,1.000
1,10.733,0.00,-0.0003,-0.00030,1.000
1,10.867,0.00,-0.0003,-0.00030,1.000
1,11.000,-0.01,-0.0003,-0.00030,1.000
1,11.133,0.00,-0.0003,-0.00030,1.000
1,11.267,0.00,-0.0003,-0.00030,1.000
1,11.400,0.00,-0.0003,-0.00030,1.000
1,11.533,0.00,-0.0002,-0.00020,1.000
1,11.667,0.00,-0.0002,-0.00020,1.000
1,11.800,0.00,-0.0002,-0.00020,1.000
1,11.933,0.00,-0.0002,-0.00020,1.000
1,12.067,0.00,-0.0002,-0.00020,1.000
1,12.200,0.00,-0.0002,-0.00020,1.000
1,12.333,-0.01,-0.0002,-0.00020,1.000
1,12.533,-0.01,-0.0002,-0.00020,1.000
1,12.667,0.00,-0.0002,-0.00020,1.000
1,12.800,-0.01,-0.0002,-0.00020,1.000
1,12.933,0.00,-0.0002,-0.00020,1.000
1,13.067,0.00,-0.0002,-0.00020,1.000
1,13.200,0.00,-0.0002,-0.00020,1.000
1,13.333,-0.01,-0.0002,-0.00020,1.000
2,13.733,0.00,0.1108,0.11093,2.000
2,13.867,0.00,0.2444,0.24450,2.000
2,14.000,0.00,0.3778,0.37790,2.000
2,14.133,0.00,0.5110,0.51110,2.000
2,14.267,0.00,0.6445,0.64460,2.000
2,14.400,0.00,0.7778,0.77790,2.000
2,14.533,0.00,0.9110,0.91110,2.000
2,14.667,0.00,1.0445,1.04457,2.000
2,14.800,0.00,1.1778,1.17790,2.000
2,14.933,0.00,1.3109,1.31100,2.000
2,15.067,0.00,1.4444,1.44447,2.000
2,15.200,0.01,1.5779,1.57800,2.000
2,15.333,0.07,1.7110,1.71113,2.000
2,15.467,0.22,1.8445,1.84457,2.000
2,15.600,0.48,1.9778,1.97790,2.000
2,15.733,0.84,2.1110,2.11110,2.000
2,15.867,1.34,2.2445,2.24460,2.000
2,16.000,1.95,2.3780,2.37810,2.000
2,16.133,2.70,2.5112,2.51130,2.000
2,16.267,3.57,2.6445,2.64460,2.000
2,16.400,4.59,2.7778,2.77790,2.000
2,16.533,5.81,2.9110,2.91113,2.000
2,16.667,7.29,3.0444,3.04453,2.000
2,16.800,9.01,3.1779,3.17800,2.000
2,16.933,10.98,3.3111,3.31120,2.000
2,17.067,13.26,3.4444,3.44453,2.000
2,17.200,15.90,3.5778,3.57790,2.000
2,17.333,18.95,3.7111,3.71117,2.000
2,17.467,22.47,3.8445,3.84460,2.000
2,17.600,26.55,3.9779,3.97800,2.000
2,17.733,31.30,4.1111,4.11120,2.000
2,17.867,36.84,4.2445,4.24460,2.000
2,18.000,43.32,4.3779,4.37800,2.000
2,18.133,51.24,4.5111,4.51120,2.000
2,18.333,42.97,4.4252,4.42530,2.000
2,18.467,33.84,4.2920,4.29207,2.000
2,18.600,27.11,4.1585,4.15860,2.000
2,18.733,21.89,4.0253,4.02537,2.000
2,18.867,17.70,3.8920,3.89213,2.000
2,19.000,14.30,3.7585,3.75860,2.000
2,19.133,11.56,3.6252,3.62530,2.000
2,19.267,9.36,3.4919,3.49200,2.000
2,19.400,7.53,3.3584,3.35850,2.000
2,19.533,6.01,3.2252,3.22533,2.000
2,19.667,4.77,3.0919,3.09203,2.000
2,19.800,3.76,2.9584,2.95850,2.000
2,19.933,2.92,2.8251,2.82517,2.000
2,20.067,2.23,2.6918,2.69190,2.000
2,20.200,1.67,2.5584,2.55850,2.000
2,20.333,1.19,2.4251,2.42520,2.000
2,20.467,0.80,2.2919,2.29197,2.000
2,20.600,0.49,2.1584,2.15850,2.000
2,20.733,0.25,2.0250,2.02510,2.000
2,20.867,0.09,1.8919,1.89200,2.000
2,21.000,0.01,1.7583,1.75840,2.000
2,21.133,-0.01,1.6250,1.62513,2.000
2,21.267,0.00,1.4917,1.49183,2.000
2,21.400,0.00,1.3584,1.35850,2.000
2,21.533,0.00,1.2249,1.22500,2.000
2,21.667,0.00,1.0918,1.09193,2.000
2,21.800,0.00,0.9585,0.95860,2.000
2,21.933,0.00,0.8249,0.82500,2.000
2,22.067,0.00,0.6917,0.69183,2.000
2,22.200,0.00,0.5584,0.55850,2.000
2,22.333,0.00,0.4249,0.42497,2.000
2,22.467,0.00,0.2916,0.29173,2.000
2,22.600,0.00,0.1582,0.15830,2.000
2,22.733,0.00,0.0248,0.02490,2.000
2,22.933,0.00,-0.0003,-0.00017,2.000
2,23.067,0.00,-0.0003,-0.00020,2.000
2,23.200,0.00,-0.0003,-0.00020,2.000
2,23.333,0.00,-0.0003,-0.00020,2.000
2,23.467,0.00,-0.0003,-0.00020,2.000
2,23.600,0.00,-0.0003,-0.00020,2.000
2,23.733,0.00,-0.0003,-0.00020,2.000
2,23.867,0.00,-0.0003,-0.00020,2.000
2,24.000,0.00,-0.0003,-0.00020,2.000
2,24.133,0.00,-0.0003,-0.00020,2.000
2,24.267,0.00,-0.0003,-0.00020,2.000
2,24.400,0.00,-0.0003,-0.00020,2.000
2,24.533,0.00,-0.0003,-0.00020,2.000
2,24.667,0.00,-0.0003,-0.00020,2.000
2,24.800,0.00,-0.0003,-0.00020,2.000
2,24.933,0.00,-0.0002,-0.00010,2.000
2,25.067,0.00,-0.0002,-0.00010,2.000
2,25.200,0.00,-0.0002,-0.00010,2.000
2,25.333,0.00,-0.0002,-0.00010,2.000
2,25.467,0.00,-0.0002,-0.00010,2.000
2,25.600,0.00,-0.0002,-0.00010,2.000
2,25.733,0.00,-0.0002,-0.00010,2.000
2,26.000,0.00,-0.0002,-0.00010,2.000
2,26.133,0.00,-0.0002,-0.00010,2.000
2,26.267,0.00,-0.0002,-0.00010,2.000
2,26.400,0.00,-0.0002,-0.00010,2.000
2,26.533,0.00,-0.0002,-0.00010,2.000
2,26.667,0.00,-0.0002,-0.00010,2.000
2,26.800,0.00,-0.0002,-0.00010,2.000
3,27.133,0.00,0.0718,0.07190,3.000
3,27.267,0.00,0.2054,0.20550,3.000
3,27.400,0.00,0.3388,0.33890,3.000
3,27.533,0.00,0.4720,0.47207,3.000
3,27.667,0.00,0.6055,0.60557,3.000
3,27.800,0.00,0.7388,0.73890,3.000
3,27.933,0.00,0.8719,0.87203,3.000
3,28.067,0.00,1.0055,1.00557,3.000
3,28.200,0.00,1.1388,1.13890,3.000
3,28.333,0.00,1.2719,1.27200,3.000
3,28.467,0.00,1.4054,1.40547,3.000
3,28.600,0.00,1.5387,1.53880,3.000
3,28.733,0.03,1.6720,1.67213,3.000
3,28.867,0.14,1.8054,1.80553,3.000
3,29.000,0.36,1.9389,1.93900,3.000
3,29.133,0.69,2.0720,2.07207,3.000
3,29.267,1.14,2.2055,2.20557,3.000
3,29.400,1.71,2.3390,2.33910,3.000
3,29.533,2.42,2.4722,2.47227,3.000
3,29.667,3.25,2.6056,2.60573,3.000
3,29.800,4.22,2.7388,2.73890,3.000
3,29.933,5.37,2.8720,2.87213,3.000
3,30.067,6.77,3.0055,3.00557,3.000
3,30.200,8.41,3.1389,3.13900,3.000
3,30.333,10.31,3.2721,3.27220,3.000
3,30.467,12.48,3.4054,3.40553,3.000
3,30.600,15.00,3.5390,3.53910,3.000
3,30.733,17.92,3.6720,3.67213,3.000
3,30.867,21.29,3.8055,3.80557,3.000
3,31.000,25.19,3.9389,3.93900,3.000
3,31.133,29.74,4.0722,4.07230,3.000
3,31.267,35.02,4.2055,4.20560,3.000
3,31.400,41.16,4.3390,4.33910,3.000
3,31.533,48.61,4.4721,4.47220,3.000
3,31.733,46.49,4.4662,4.46633,3.000
3,31.867,36.25,4.3330,4.33313,3.000
3,32.000,28.95,4.1995,4.19960,3.000
3,32.133,23.33,4.0663,4.06643,3.000
3,32.267,18.85,3.9330,3.93307,3.000
3,32.400,15.23,3.7995,3.79960,3.000
3,32.533,12.30,3.6662,3.66630,3.000
3,32.667,9.96,3.5330,3.53307,3.000
3,32.800,8.03,3.3993,3.39940,3.000
3,32.933,6.42,3.2662,3.26630,3.000
3,33.067,5.10,3.1329,3.13303,3.000
3,33.200,4.04,2.9995,2.99960,3.000
3,33.333,3.14,2.8662,2.86627,3.000
3,33.467,2.41,2.7327,2.73280,3.000
3,33.600,1.82,2.5994,2.59950,3.000
3,33.733,1.31,2.4661,2.46623,3.000
3,33.867,0.90,2.3329,2.33297,3.000
3,34.000,0.57,2.1994,2.19950,3.000
3,34.133,0.31,2.0660,2.06607,3.000
3,34.267,0.12,1.9329,1.93297,3.000
3,34.400,0.02,1.7993,1.79940,3.000
3,34.533,0.00,1.6660,1.66613,3.000
3,34.667,0.00,1.5328,1.53290,3.000
3,34.800,0.00,1.3993,1.39940,3.000
3,34.933,0.00,1.2659,1.26603,3.000
3,35.067,0.00,1.1327,1.13283,3.000
3,35.200,0.00,0.9994,0.99950,3.000
3,35.333,0.00,0.8659,0.86603,3.000
3,35.467,0.00,0.7327,0.73280,3.000
3,35.600,0.00,0.5994,0.59950,3.000
3,35.733,0.00,0.4659,0.46603,3.000
3,35.867,0.00,0.3327,0.33277,3.000
3,36.000,0.00,0.1993,0.19940,3.000
3,36.133,0.00,0.0658,0.06590,3.000
3,36.333,0.00,-0.0008,-0.00073,3.000
3,36.467,0.00,-0.0003,-0.00020,3.000
3,36.600,0.00,-0.0003,-0.00020,3.000
3,36.733,0.00,-0.0003,-0.00020,3.000
3,36.867,0.00,-0.0003,-0.00020,3.000
3,37.000,0.00,-0.0003,-0.00020,3.000
3,37.133,0.00,-0.0003,-0.00020,3.000
3,37.267,0.00,-0.0003,-0.00020,3.000
3,37.400,0.00,-0.0003,-0.00020,3.000
3,37.533,-0.01,-0.0003,-0.00020,3.000
3,37.667,0.00,-0.0003,-0.00020,3.000
3,37.800,0.00,-0.0003,-0.00020,3.000
3,37.933,0.00,-0.0003,-0.00020,3.000
3,38.067,0.00,-0.0002,-0.00010,3.000
3,38.200,0.00,-0.0002,-0.00010,3.000
3,38.333,0.00,-0.0002,-0.00010,3.000
3,38.467,0.00,-0.0002,-0.00010,3.000
3,38.600,0.00,-0.0002,-0.00010,3.000
3,38.733,0.00,-0.0002,-0.00010,3.000
3,38.867,0.00,-0.0002,-0.00010,3.000
3,39.000,0.00,-0.0002,-0.00010,3.000
3,39.133,0.00,-0.0002,-0.00010,3.000
3,39.267,0.00,-0.0002,-0.00010,3.000
3,39.467,0.00,-0.0002,-0.00010,3.000
3,39.600,0.00,-0.0002,-0.00010,3.000
3,39.733,0.00,-0.0002,-0.00010,3.000
3,39.867,0.00,-0.0002,-0.00010,3.000
3,40.000,0.00,-0.0002,-0.00010,3.000
3,40.133,0.00,-0.0002,-0.00010,3.000
3,40.267,0.00,-0.0002,-0.00010,3.000
4,40.667,0.00,0.1833,0.18327,4.000
4,40.800,0.00,0.3167,0.31670,4.000
4,40.933,0.01,0.4501,0.45007,4.000
4,41.067,0.00,0.5833,0.58333,4.000
4,41.200,0.00,0.7167,0.71670,4.000
4,41.333,0.00,0.8501,0.85007,4.000
4,41.467,0.00,0.9834,0.98343,4.000
4,41.600,0.00,1.1168,1.11680,4.000
4,41.733,0.00,1.2500,1.25000,4.000
4,41.867,0.00,1.3833,1.38333,4.000
4,42.000,0.00,1.5167,1.51670,4.000
4,42.133,0.03,1.6502,1.65017,4.000
4,42.267,0.11,1.7835,1.78347,4.000
4,42.400,0.31,1.9168,1.91680,4.000
4,42.533,0.62,2.0501,2.05007,4.000
4,42.667,1.04,2.1835,2.18350,4.000
4,42.800,1.59,2.3168,2.31680,4.000
4,42.933,2.27,2.4502,2.45023,4.000
4,43.067,3.08,2.5836,2.58360,4.000
4,43.200,4.02,2.7166,2.71660,4.000
4,43.333,5.14,2.8501,2.85013,4.000
4,43.467,6.49,2.9835,2.98350,4.000
4,43.600,8.09,3.1168,3.11680,4.000
4,43.733,9.94,3.2501,3.25013,4.000
4,43.867,12.06,3.3834,3.38340,4.000
4,44.000,14.53,3.5168,3.51680,4.000
4,44.133,17.37,3.6501,3.65013,4.000
4,44.267,20.65,3.7835,3.78353,4.000
4,44.400,24.46,3.9167,3.91670,4.000
4,44.533,28.87,4.0502,4.05017,4.000
4,44.667,34.04,4.1836,4.18357,4.000
4,44.800,40.02,4.3168,4.31680,4.000
4,44.933,47.21,4.4502,4.45017,4.000
4,45.067,53.06,4.5283,4.52833,4.000
4,45.200,40.95,4.3976,4.39760,4.000
4,45.333,32.36,4.2644,4.26437,4.000
4,45.467,25.97,4.1310,4.13097,4.000
4,45.600,20.95,3.9974,3.99740,4.000
4,45.733,16.92,3.8643,3.86427,4.000
4,45.867,13.67,3.7310,3.73097,4.000
4,46.000,11.05,3.5974,3.59740,4.000
4,46.133,8.92,3.4642,3.46420,4.000
4,46.267,7.16,3.3309,3.33087,4.000
4,46.400,5.71,3.1974,3.19740,4.000
4,46.533,4.53,3.0642,3.06417,4.000
4,46.667,3.56,2.9309,2.93087,4.000
4,46.800,2.74,2.7972,2.79720,4.000
4,46.933,2.08,2.6641,2.66410,4.000
4,47.067,1.54,2.5309,2.53093,4.000
4,47.200,1.09,2.3973,2.39730,4.000
4,47.333,0.72,2.2642,2.26420,4.000
4,47.467,0.43,2.1308,2.13077,4.000
4,47.600,0.20,1.9973,1.99730,4.000
4,47.733,0.05,1.8642,1.86417,4.000
4,47.867,0.01,1.7307,1.73073,4.000
4,48.000,0.00,1.5974,1.59740,4.000
4,48.133,0.00,1.4640,1.46400,4.000
4,48.267,0.00,1.3307,1.33073,4.000
4,48.400,0.00,1.1972,1.19720,4.000
4,48.533,0.00,1.0641,1.06407,4.000
4,48.667,0.00,0.9308,0.93080,4.000
4,48.800,0.00,0.7973,0.79730,4.000
4,48.933,0.00,0.6640,0.66403,4.000
4,49.067,0.00,0.5307,0.53067,4.000
4,49.200,0.00,0.3974,0.39740,4.000
4,49.333,0.01,0.2639,0.26390,4.000
4,49.467,0.00,0.1307,0.13067,4.000
4,49.600,0.00,-0.0027,-0.00270,4.000
4,49.800,0.00,-0.0003,-0.00030,4.000
4,49.933,0.01,-0.0003,-0.00030,4.000
4,50.067,0.00,-0.0003,-0.00030,4.000
4,50.200,0.00,-0.0003,-0.00030,4.000
4,50.333,0.00,-0.0003,-0.00030,4.000
4,50.467,0.00,-0.0003,-0.00030,4.000
4,50.600,0.00,-0.0003,-0.00030,4.000
4,50.733,0.01,-0.0003,-0.00030,4.000
4,50.867,0.01,-0.0003,-0.00030,4.000
4,51.000,0.01,-0.0003,-0.00030,4.000
4,51.133,0.00,-0.0003,-0.00030,4.000
4,51.267,0.00,-0.0003,-0.00030,4.000
4,51.400,0.01,-0.0003,-0.00030,4.000
4,51.533,0.01,-0.0003,-0.00030,4.000
4,51.667,0.00,-0.0002,-0.00020,4.000
4,51.800,0.01,-0.0002,-0.00020,4.000
4,51.933,0.01,-0.0002,-0.00020,4.000
4,52.067,0.01,-0.0002,-0.00020,4.000
4,52.200,0.01,-0.0002,-0.00020,4.000
4,52.333,0.00,-0.0002,-0.00020,4.000
4,52.467,0.00,-0.0002,-0.00020,4.000
4,52.600,0.00,-0.0002,-0.00020,4.000
4,52.800,0.00,-0.0002,-0.00020,4.000
4,52.933,0.00,-0.0002,-0.00020,4.000
4,53.067,0.00,-0.0002,-0.00020,4.000
4,53.200,0.00,-0.0002,-0.00020,4.000
4,53.333,0.00,-0.0002,-0.00020,4.000
4,53.467,0.00,-0.0002,-0.00020,4.000
4,53.600,0.00,-0.0002,-0.00020,4.000
5,53.933,0.00,0.0698,0.06993,5.000
5,54.067,0.00,0.2033,0.20343,5.000
5,54.200,0.00,0.3367,0.33680,5.000
5,54.333,0.01,0.4700,0.47013,5.000
5,54.467,0.00,0.6034,0.60353,5.000
5,54.600,0.00,0.7368,0.73690,5.000
5,54.733,0.00,0.8699,0.87003,5.000
5,54.867,0.00,1.0034,1.00353,5.000
5,55.000,0.00,1.1369,1.13700,5.000
5,55.133,0.00,1.2699,1.27000,5.000
5,55.267,0.00,1.4033,1.40343,5.000
5,55.400,0.01,1.5369,1.53700,5.000
5,55.533,0.03,1.6701,1.67017,5.000
5,55.667,0.12,1.8034,1.80353,5.000
5,55.800,0.34,1.9369,1.93700,5.000
5,55.933,0.66,2.0700,2.07013,5.000
5,56.067,1.10,2.2034,2.20353,5.000
5,56.200,1.67,2.3369,2.33700,5.000
5,56.333,2.36,2.4703,2.47037,5.000
5,56.467,3.18,2.6036,2.60367,5.000
5,56.600,4.14,2.7369,2.73700,5.000
5,56.733,5.29,2.8701,2.87023,5.000
5,56.867,6.67,3.0034,3.00353,5.000
5,57.000,8.30,3.1369,3.13700,5.000
5,57.133,10.19,3.2701,3.27023,5.000
5,57.267,12.36,3.4034,3.40347,5.000
5,57.400,14.87,3.5368,3.53690,5.000
5,57.533,17.78,3.6701,3.67020,5.000
5,57.667,21.12,3.8035,3.80357,5.000
5,57.800,24.99,3.9369,3.93700,5.000
5,57.933,29.52,4.0702,4.07033,5.000
5,58.067,34.80,4.2034,4.20353,5.000
5,58.200,40.89,4.3369,4.33700,5.000
5,58.333,48.33,4.4702,4.47027,5.000
5,58.533,46.20,4.4642,4.46430,5.000
5,58.667,36.04,4.3310,4.33113,5.000
5,58.800,28.78,4.1976,4.19770,5.000
5,58.933,23.18,4.0643,4.06440,5.000
5,59.067,18.74,3.9310,3.93110,5.000
5,59.200,15.14,3.7976,3.79770,5.000
5,59.333,12.22,3.6642,3.66433,5.000
5,59.467,9.88,3.5310,3.53107,5.000
5,59.600,7.96,3.3974,3.39750,5.000
5,59.733,6.36,3.2643,3.26437,5.000
5,59.867,5.05,3.1308,3.13093,5.000
5,60.000,3.99,2.9973,2.99740,5.000
5,60.133,3.10,2.8641,2.86423,5.000
5,60.267,2.37,2.7307,2.73077,5.000
5,60.400,1.79,2.5974,2.59750,5.000
5,60.533,1.28,2.4642,2.46430,5.000
5,60.667,0.88,2.3309,2.33100,5.000
5,60.800,0.55,2.1974,2.19750,5.000
5,60.933,0.30,2.0640,2.06410,5.000
5,61.067,0.12,1.9309,1.93097,5.000
5,61.200,0.03,1.7973,1.79740,5.000
5,61.333,0.00,1.6641,1.66420,5.000
5,61.467,0.00,1.5307,1.53083,5.000
5,61.600,0.00,1.3973,1.39740,5.000
5,61.733,0.00,1.2640,1.26410,5.000
5,61.867,0.00,1.1308,1.13093,5.000
5,62.000,0.00,0.9974,0.99750,5.000
5,62.133,0.00,0.8640,0.86410,5.000
5,62.267,0.00,0.7307,0.73083,5.000
5,62.400,0.00,0.5973,0.59740,5.000
5,62.533,0.00,0.4640,0.46407,5.000
5,62.667,0.00,0.3307,0.33083,5.000
5,62.800,0.00,0.1973,0.19740,5.000
5,62.933,0.00,0.0638,0.06393,5.000
5,63.133,0.00,-0.0013,-0.00123,5.000
5,63.267,0.00,-0.0003,-0.00020,5.000
5,63.400,0.00,-0.0003,-0.00020,5.000
5,63.533,0.00,-0.0003,-0.00020,5.000
5,63.667,0.00,-0.0003,-0.00020,5.000
5,63.800,0.00,-0.0003,-0.00020,5.000
5,63.933,0.00,-0.0003,-0.00020,5.000
5,64.067,0.01,-0.0003,-0.00020,5.000
5,64.200,0.01,-0.0003,-0.00020,5.000
5,64.333,0.00,-0.0003,-0.00020,5.000
5,64.467,0.00,-0.0003,-0.00020,5.000
5,64.600,0.00,-0.0003,-0.00020,5.000
5,64.733,0.00,-0.0003,-0.00020,5.000
5,64.867,0.00,-0.0003,-0.00020,5.000
5,65.000,0.00,-0.0003,-0.00020,5.000
5,65.133,0.00,-0.0003,-0.00020,5.000
5,65.267,0.00,-0.0003,-0.00020,5.000
5,65.400,0.00,-0.0002,-0.00010,5.000
5,65.533,0.00,-0.0002,-0.00010,5.000
5,65.667,0.00,-0.0002,-0.00010,5.000
5,65.800,0.00,-0.0002,-0.00010,5.000
5,65.933,0.00,-0.0002,-0.00010,5.000
5,66.067,0.00,-0.0002,-0.00010,5.000
5,66.267,0.00,-0.0002,-0.00010,5.000
5,66.400,0.00,-0.0002,-0.00010,5.000
5,66.533,0.00,-0.0002,-0.00010,5.000
5,66.667,0.00,-0.0002,-0.00010,5.000
5,66.800,0.00,-0.0002,-0.00010,5.000
5,66.933,0.00,-0.0002,-0.00010,5.000
5,67.067,0.00,-0.0002,-0.00010,5.000
6,67.467,0.01,0.1832,0.18333,6.000
6,67.600,0.01,0.3166,0.31670,6.000
6,67.733,0.01,0.4501,0.45017,6.000
6,67.867,0.01,0.5834,0.58347,6.000
6,68.000,0.01,0.7167,0.71680,6.000
6,68.133,0.01,0.8501,0.85017,6.000
6,68.267,0.01,0.9835,0.98357,6.000
6,68.400,0.01,1.1168,1.11690,6.000
6,68.533,0.01,1.2500,1.25010,6.000
6,68.667,0.01,1.3833,1.38340,6.000
6,68.800,0.01,1.5166,1.51670,6.000
6,68.933,0.03,1.6502,1.65027,6.000
6,69.067,0.11,1.7834,1.78353,6.000
6,69.200,0.29,1.9167,1.91680,6.000
6,69.333,0.60,2.0501,2.05023,6.000
6,69.467,1.02,2.1835,2.18360,6.000
6,69.600,1.57,2.3167,2.31680,6.000
6,69.733,2.25,2.4503,2.45037,6.000
6,69.867,3.05,2.5836,2.58370,6.000
6,70.000,3.99,2.7166,2.71670,6.000
6,70.133,5.11,2.8500,2.85013,6.000
6,70.267,6.46,2.9835,2.98363,6.000
6,70.400,8.06,3.1168,3.11690,6.000
6,70.533,9.89,3.2501,3.25023,6.000
6,70.667,12.00,3.3835,3.38357,6.000
6,70.800,14.46,3.5167,3.51680,6.000
6,70.933,17.30,3.6501,3.65020,6.000
6,71.067,20.57,3.7836,3.78367,6.000
6,71.200,24.36,3.9167,3.91680,6.000
6,71.333,28.78,4.0502,4.05027,6.000
6,71.467,33.93,4.1836,4.18367,6.000
6,71.600,39.90,4.3168,4.31690,6.000
6,71.733,47.09,4.4501,4.45023,6.000
6,71.933,49.87,4.5041,4.50417,6.000
6,72.067,38.47,4.3710,4.37113,6.000
6,72.200,30.61,4.2377,4.23780,6.000
6,72.333,24.61,4.1043,4.10443,6.000
6,72.467,19.90,3.9710,3.97113,6.000
6,72.600,16.07,3.8375,3.83760,6.000
6,72.733,12.98,3.7043,3.70437,6.000
6,72.867,10.50,3.5709,3.57100,6.000
6,73.000,8.48,3.4374,3.43750,6.000
6,73.133,6.78,3.3042,3.30430,6.000
6,73.267,5.39,3.1709,3.17097,6.000
6,73.400,4.27,3.0374,3.03750,6.000
6,73.533,3.34,2.9042,2.90430,6.000
6,73.667,2.56,2.7707,2.77077,6.000
6,73.800,1.95,2.6373,2.63740,6.000
6,73.933,1.42,2.5042,2.50430,6.000
6,74.067,0.99,2.3709,2.37097,6.000
6,74.200,0.64,2.2374,2.23750,6.000
6,74.333,0.37,2.1040,2.10413,6.000
6,74.467,0.16,1.9708,1.97090,6.000
6,74.600,0.05,1.8373,1.83740,6.000
6,74.733,0.01,1.7041,1.70420,6.000
6,74.867,0.01,1.5708,1.57090,6.000
6,75.000,0.00,1.4371,1.43720,6.000
6,75.133,0.01,1.3040,1.30410,6.000
6,75.267,0.01,1.1707,1.17077,6.000
6,75.400,0.01,1.0374,1.03750,6.000
6,75.533,0.01,0.9039,0.90403,6.000
6,75.667,0.01,0.7707,0.77080,6.000
6,75.800,0.01,0.6372,0.63730,6.000
6,75.933,0.01,0.5040,0.50410,6.000
6,76.067,0.01,0.3708,0.37087,6.000
6,76.200,0.01,0.2373,0.23740,6.000
6,76.333,0.01,0.1039,0.10397,6.000
6,76.600,0.01,-0.0003,-0.00020,6.000
6,76.733,0.01,-0.0003,-0.00020,6.000
6,76.867,0.01,-0.0003,-0.00020,6.000
6,77.000,0.01,-0.0003,-0.00020,6.000
6,77.133,0.01,-0.0003,-0.00020,6.000
6,77.267,0.01,-0.0003,-0.00020,6.000
6,77.400,0.01,-0.0003,-0.00020,6.000
6,77.533,0.01,-0.0003,-0.00020,6.000
6,77.667,0.01,-0.0003,-0.00020,6.000
6,77.800,0.01,-0.0003,-0.00020,6.000
6,77.933,0.01,-0.0003,-0.00020,6.000
6,78.067,0.01,-0.0003,-0.00020,6.000
6,78.200,0.01,-0.0003,-0.00020,6.000
6,78.333,0.01,-0.0003,-0.00020,6.000
6,78.467,0.01,-0.0003,-0.00020,6.000
6,78.600,0.01,-0.0003,-0.00020,6.000
6,78.733,0.01,-0.0003,-0.00020,6.000
6,78.867,0.01,-0.0003,-0.00020,6.000
6,79.000,0.01,-0.0002,-0.00010,6.000
6,79.133,0.01,-0.0002,-0.00010,6.000
6,79.267,0.01,-0.0002,-0.00010,6.000
6,79.400,0.01,-0.0002,-0.00010,6.000
6,79.533,0.01,-0.0002,-0.00010,6.000
6,79.733,0.01,-0.0002,-0.00010,6.000
6,79.867,0.01,-0.0002,-0.00010,6.000
6,80.000,0.01,-0.0002,-0.00010,6.000
6,80.133,0.01,-0.0002,-0.00010,6.000
6,80.267,0.01,-0.0002,-0.00010,6.000
6,80.400,0.01,-0.0002,-0.00010,6.000
6,80.533,0.01,-0.0002,-0.00010,6.000
7,80.867,0.00,0.1442,0.14433,7.000
7,81.000,-0.01,0.2776,0.27770,7.000
7,81.133,0.00,0.4111,0.41120,7.000
7,81.267,0.00,0.5444,0.54447,7.000
7,81.400,0.00,0.6777,0.67780,7.000
7,81.533,0.00,0.8111,0.81120,7.000
7,81.667,0.00,0.9444,0.94453,7.000
7,81.800,0.00,1.0778,1.07790,7.000
7,81.933,0.00,1.2111,1.21117,7.000
7,82.067,0.00,1.3444,1.34450,7.000
7,82.200,0.00,1.4776,1.47770,7.000
7,82.333,0.01,1.6112,1.61133,7.000
7,82.467,0.06,1.7445,1.74460,7.000
7,82.600,0.21,1.8777,1.87780,7.000
7,82.733,0.48,2.0112,2.01127,7.000
7,82.867,0.85,2.1445,2.14460,7.000
7,83.000,1.37,2.2778,2.27790,7.000
7,83.133,2.00,2.4113,2.41137,7.000
7,83.267,2.76,2.5446,2.54473,7.000
7,83.400,3.68,2.6777,2.67780,7.000
7,83.533,4.74,2.8111,2.81123,7.000
7,83.667,6.02,2.9445,2.94457,7.000
7,83.800,7.55,3.0777,3.07780,7.000
7,83.933,9.31,3.2112,3.21127,7.000
7,84.067,11.35,3.3445,3.34457,7.000
7,84.200,13.70,3.4777,3.47780,7.000
7,84.333,16.43,3.6111,3.61123,7.000
7,84.467,19.57,3.7445,3.74463,7.000
7,84.600,23.22,3.8777,3.87780,7.000
7,84.733,27.44,4.0111,4.01123,7.000
7,84.867,32.38,4.1445,4.14460,7.000
7,85.000,38.11,4.2777,4.27780,7.000
7,85.133,44.92,4.4111,4.41123,7.000
7,85.333,52.72,4.5250,4.52513,7.000
7,85.467,40.24,4.3919,4.39203,7.000
7,85.600,31.86,4.2587,4.25880,7.000
7,85.733,25.59,4.1252,4.12533,7.000
7,85.867,20.65,3.9919,3.99203,7.000
7,86.000,16.68,3.8587,3.85880,7.000
7,86.133,13.48,3.7252,3.72527,7.000
7,86.267,10.89,3.5919,3.59200,7.000
7,86.400,8.79,3.4586,3.45870,7.000
7,86.533,7.03,3.3251,3.32523,7.000
7,86.667,5.60,3.1919,3.19197,7.000
7,86.800,4.43,3.0586,3.05870,7.000
7,86.933,3.47,2.9251,2.92523,7.000
7,87.067,2.66,2.7917,2.79177,7.000
7,87.200,2.01,2.6585,2.65860,7.000
7,87.333,1.48,2.5252,2.52533,7.000
7,87.467,1.05,2.3918,2.39190,7.000
7,87.600,0.68,2.2585,2.25860,7.000
7,87.733,0.40,2.1250,2.12513,7.000
7,87.867,0.18,1.9918,1.99187,7.000
7,88.000,0.04,1.8585,1.85860,7.000
7,88.133,0.01,1.7250,1.72510,7.000
7,88.267,-0.01,1.5917,1.59180,7.000
7,88.400,0.00,1.4583,1.45840,7.000
7,88.533,0.00,1.3250,1.32510,7.000
7,88.667,0.00,1.1916,1.19167,7.000
7,88.800,0.00,1.0585,1.05860,7.000
7,88.933,0.00,0.9251,0.92520,7.000
7,89.067,-0.01,0.7916,0.79170,7.000
7,89.200,0.00,0.6584,0.65850,7.000
7,89.333,0.00,0.5250,0.52513,7.000
7,89.467,0.00,0.3916,0.39170,7.000
7,89.600,0.00,0.2584,0.25850,7.000
7,89.733,-0.01,0.1250,0.12507,7.000
7,89.867,0.00,-0.0086,-0.00847,7.000
7,90.067,0.00,-0.0003,-0.00020,7.000
7,90.200,0.00,-0.0003,-0.00020,7.000
7,90.333,0.00,-0.0003,-0.00020,7.000
7,90.467,0.00,-0.0003,-0.00020,7.000
7,90.600,0.00,-0.0003,-0.00020,7.000
7,90.733,0.00,-0.0003,-0.00020,7.000
7,90.867,0.00,-0.0003,-0.00020,7.000
7,91.000,0.00,-0.0003,-0.00020,7.000
7,91.133,0.00,-0.0003,-0.00020,7.000
7,91.267,0.00,-0.0003,-0.00020,7.000
7,91.400,0.00,-0.0003,-0.00020,7.000
7,91.533,0.00,-0.0003,-0.00020,7.000
7,91.667,0.00,-0.0003,-0.00020,7.000
7,91.800,0.00,-0.0002,-0.00010,7.000
7,91.933,0.00,-0.0002,-0.00010,7.000
7,92.067,0.00,-0.0002,-0.00010,7.000
7,92.200,0.00,-0.0002,-0.00010,7.000
7,92.333,0.00,-0.0002,-0.00010,7.000
7,92.467,0.00,-0.0002,-0.00010,7.000
7,92.600,0.00,-0.0002,-0.00010,7.000
7,92.733,0.00,-0.0002,-0.00010,7.000
7,92.867,0.00,-0.0002,-0.00010,7.000
7,93.067,0.00,-0.0002,-0.00010,7.000
7,93.200,0.00,-0.0002,-0.00010,7.000
7,93.333,0.00,-0.0002,-0.00010,7.000
7,93.467,0.00,-0.0002,-0.00010,7.000
7,93.600,0.00,-0.0002,-0.00010,7.000
7,93.733,0.00,-0.0002,-0.00010,7.000
7,93.867,0.00,-0.0002,-0.00010,7.000
8,94.200,0.00,0.0576,0.05770,8.000
8,94.333,0.00,0.1909,0.19103,8.000
8,94.467,0.00,0.3244,0.32447,8.000
8,94.600,0.00,0.4578,0.45790,8.000
8,94.733,0.00,0.5910,0.59110,8.000
8,94.867,0.00,0.7244,0.72450,8.000
8,95.000,0.00,0.8578,0.85790,8.000
8,95.133,0.00,0.9911,0.99117,8.000
8,95.267,0.00,1.1245,1.12457,8.000
8,95.400,0.00,1.2577,1.25780,8.000
8,95.533,0.00,1.3910,1.39107,8.000
8,95.667,0.00,1.5244,1.52450,8.000
8,95.800,0.01,1.6579,1.65800,8.000
8,95.933,0.09,1.7911,1.79117,8.000
8,96.067,0.28,1.9245,1.92460,8.000
8,96.200,0.59,2.0578,2.05790,8.000
8,96.333,1.01,2.1912,2.19127,8.000
8,96.467,1.56,2.3245,2.32460,8.000
8,96.600,2.24,2.4579,2.45800,8.000
8,96.733,3.05,2.5912,2.59130,8.000
8,96.867,4.01,2.7243,2.72440,8.000
8,97.000,5.14,2.8578,2.85790,8.000
8,97.133,6.51,2.9912,2.99127,8.000
8,97.267,8.12,3.1244,3.12447,8.000
8,97.400,9.97,3.2578,3.25790,8.000
8,97.533,12.11,3.3911,3.39120,8.000
8,97.667,14.59,3.5244,3.52453,8.000
8,97.800,17.45,3.6578,3.65790,8.000
8,97.933,20.77,3.7911,3.79123,8.000
8,98.067,24.60,3.9245,3.92457,8.000
8,98.200,29.05,4.0580,4.05810,8.000
8,98.333,34.25,4.1912,4.19130,8.000
8,98.467,40.31,4.3245,4.32460,8.000
8,98.600,47.59,4.4578,4.45790,8.000
8,98.867,41.73,4.4119,4.41197,8.000
8,99.000,32.94,4.2786,4.27870,8.000
8,99.133,26.41,4.1453,4.14543,8.000
8,99.267,21.31,4.0119,4.01203,8.000
8,99.400,17.21,3.8785,3.87860,8.000
8,99.533,13.90,3.7453,3.74537,8.000
8,99.667,11.23,3.6119,3.61200,8.000
8,99.800,9.07,3.4784,3.47850,8.000
8,99.933,7.26,3.3452,3.34527,8.000
8,100.067,5.79,3.2119,3.21197,8.000
8,100.200,4.58,3.0784,3.07850,8.000
8,100.333,3.59,2.9452,2.94527,8.000
8,100.467,2.76,2.8118,2.81193,8.000
8,100.600,2.10,2.6782,2.67830,8.000
8,100.733,1.55,2.5453,2.54537,8.000
8,100.867,1.10,2.4119,2.41197,8.000
8,101.000,0.72,2.2784,2.27850,8.000
8,101.133,0.43,2.1450,2.14513,8.000
8,101.267,0.20,2.0118,2.01187,8.000
8,101.400,0.05,1.8784,1.87850,8.000
8,101.533,0.00,1.7450,1.74513,8.000
8,101.667,-0.01,1.6118,1.61193,8.000
8,101.800,-0.01,1.4782,1.47830,8.000
8,101.933,0.00,1.3450,1.34507,8.000
8,102.067,0.00,1.2117,1.21180,8.000
8,102.200,0.00,1.0783,1.07840,8.000
8,102.333,0.00,0.9450,0.94510,8.000
8,102.467,0.00,0.8117,0.81180,8.000
8,102.600,-0.01,0.6783,0.67840,8.000
8,102.733,0.00,0.5450,0.54510,8.000
8,102.867,0.00,0.4118,0.41187,8.000
8,103.000,0.00,0.2782,0.27830,8.000
8,103.133,0.00,0.1449,0.14503,8.000
8,103.267,0.00,0.0116,0.01167,8.000
8,103.467,0.00,-0.0004,-0.00030,8.000
8,103.600,0.00,-0.0003,-0.00020,8.000
8,103.733,0.00,-0.0003,-0.00020,8.000
8,103.867,0.00,-0.0003,-0.00020,8.000
8,104.000,0.00,-0.0003,-0.00020,8.000
8,104.133,0.00,-0.0003,-0.00020,8.000
8,104.267,0.00,-0.0003,-0.00020,8.000
8,104.400,0.00,-0.0003,-0.00020,8.000
8,104.533,0.00,-0.0003,-0.00020,8.000
8,104.667,0.00,-0.0003,-0.00020,8.000
8,104.800,0.00,-0.0003,-0.00020,8.000
8,104.933,0.00,-0.0003,-0.00020,8.000
8,105.067,0.00,-0.0003,-0.00020,8.000
8,105.200,-0.01,-0.0003,-0.00020,8.000
8,105.333,0.00,-0.0003,-0.00020,8.000
8,105.467,0.00,-0.0002,-0.00010,8.000
8,105.600,0.00,-0.0002,-0.00010,8.000
8,105.733,0.00,-0.0002,-0.00010,8.000
8,105.867,0.00,-0.0002,-0.00010,8.000
8,106.000,0.00,-0.0002,-0.00010,8.000
8,106.133,0.00,-0.0002,-0.00010,8.000
8,106.267,0.00,-0.0002,-0.00010,8.000
8,106.467,0.00,-0.0002,-0.00010,8.000
8,106.600,0.00,-0.0002,-0.00010,8.000
8,106.733,0.00,-0.0002,-0.00010,8.000
8,106.867,0.00,-0.0002,-0.00010,8.000
8,107.000,0.00,-0.0002,-0.00010,8.000
8,107.133,0.00,-0.0002,-0.00010,8.000
8,107.267,-0.01,-0.0002,-0.00010,8.000
8,107.400,-0.01,-0.0002,-0.00010,8.000
9,107.733,0.00,0.1810,0.18113,9.000
9,107.867,0.00,0.3143,0.31440,9.000
9,108.000,0.00,0.4478,0.44790,9.000
9,108.133,0.00,0.5811,0.58123,9.000
9,108.267,0.00,0.7143,0.71443,9.000
9,108.400,0.00,0.8477,0.84780,9.000
9,108.533,0.00,0.9812,0.98127,9.000
9,108.667,0.00,1.1145,1.11457,9.000
9,108.800,0.00,1.2476,1.24770,9.000
9,108.933,0.00,1.3811,1.38120,9.000
9,109.067,0.00,1.5143,1.51443,9.000
9,109.200,0.01,1.6478,1.64790,9.000
9,109.333,0.09,1.7812,1.78130,9.000
9,109.467,0.27,1.9145,1.91460,9.000
9,109.600,0.56,2.0477,2.04780,9.000
9,109.733,0.97,2.1812,2.18130,9.000
9,109.867,1.51,2.3145,2.31457,9.000
9,110.000,2.18,2.4479,2.44800,9.000
9,110.133,2.98,2.5814,2.58150,9.000
9,110.267,3.91,2.7143,2.71440,9.000
9,110.400,5.02,2.8477,2.84780,9.000
9,110.533,6.36,2.9812,2.98130,9.000
9,110.667,7.95,3.1144,3.11453,9.000
9,110.800,9.78,3.2479,3.24800,9.000
9,110.933,11.89,3.3811,3.38123,9.000
9,111.067,14.33,3.5145,3.51460,9.000
9,111.200,17.15,3.6477,3.64780,9.000
9,111.333,20.41,3.7812,3.78127,9.000
9,111.467,24.19,3.9145,3.91457,9.000
9,111.600,28.59,4.0479,4.04800,9.000
9,111.733,33.70,4.1813,4.18137,9.000
9,111.867,39.64,4.3145,4.31457,9.000
9,112.000,46.82,4.4477,4.44780,9.000
9,112.200,50.12,4.5083,4.50840,9.000
9,112.333,38.64,4.3753,4.37540,9.000
9,112.467,30.73,4.2419,4.24197,9.000
9,112.600,24.69,4.1087,4.10880,9.000
9,112.733,19.95,3.9753,3.97543,9.000
9,112.867,16.11,3.8418,3.84193,9.000
9,113.000,13.00,3.7086,3.70870,9.000
9,113.133,10.52,3.5753,3.57540,9.000
9,113.267,8.48,3.4418,3.44193,9.000
9,113.400,6.77,3.3085,3.30860,9.000
9,113.533,5.39,3.1752,3.17533,9.000
9,113.667,4.26,3.0417,3.04183,9.000
9,113.800,3.33,2.9085,2.90860,9.000
9,113.933,2.55,2.7751,2.77517,9.000
9,114.067,1.94,2.6417,2.64180,9.000
9,114.200,1.40,2.5085,2.50860,9.000
9,114.333,0.98,2.3752,2.37533,9.000
9,114.467,0.63,2.2417,2.24180,9.000
9,114.600,0.36,2.1084,2.10850,9.000
9,114.733,0.15,1.9752,1.97527,9.000
9,114.867,0.04,1.8417,1.84180,9.000
9,115.000,0.00,1.7084,1.70850,9.000
9,115.133,0.00,1.5751,1.57520,9.000
9,115.267,0.00,1.4415,1.44163,9.000
9,115.400,0.00,1.3083,1.30840,9.000
9,115.533,0.00,1.1751,1.17523,9.000
9,115.667,0.00,1.0417,1.04180,9.000
9,115.800,0.00,0.9083,0.90840,9.000
9,115.933,0.00,0.7751,0.77517,9.000
9,116.067,0.00,0.6417,0.64177,9.000
9,116.200,-0.01,0.5083,0.50840,9.000
9,116.333,0.00,0.3750,0.37510,9.000
9,116.467,0.00,0.2416,0.24173,9.000
9,116.600,0.00,0.1082,0.10830,9.000
9,116.867,0.00,0.0003,0.00037,9.000
9,117.000,0.00,-0.0003,-0.00020,9.000
9,117.133,0.00,-0.0003,-0.00020,9.000
9,117.267,0.00,-0.0003,-0.00020,9.000
9,117.400,0.00,-0.0003,-0.00020,9.000
9,117.533,0.00,-0.0003,-0.00020,9.000
9,117.667,0.00,-0.0003,-0.00020,9.000
9,117.800,0.00,-0.0003,-0.00020,9.000
9,117.933,0.00,-0.0003,-0.00020,9.000
9,118.067,0.00,-0.0003,-0.00020,9.000
9,118.200,0.00,-0.0003,-0.00020,9.000
9,118.333,0.00,-0.0003,-0.00020,9.000
9,118.467,0.00,-0.0003,-0.00020,9.000
9,118.600,0.00,-0.0003,-0.00020,9.000
9,118.733,0.00,-0.0003,-0.00020,9.000
9,118.867,0.00,-0.0003,-0.00020,9.000
9,119.000,0.00,-0.0002,-0.00010,9.000
9,119.133,0.00,-0.0002,-0.00010,9.000
9,119.267,0.00,-0.0002,-0.00010,9.000
9,119.400,0.00,-0.0002,-0.00010,9.000
9,119.533,0.00,-0.0002,-0.00010,9.000
9,119.667,0.00,-0.0002,-0.00010,9.000
9,119.800,0.00,-0.0002,-0.00010,9.000
9,120.000,0.00,-0.0002,-0.00010,9.000
9,120.133,0.00,-0.0002,-0.00010,9.000
9,120.267,0.00,-0.0002,-0.00010,9.000
9,120.400,0.00,-0.0002,-0.00010,9.000
9,120.533,0.00,-0.0002,-0.00010,9.000
9,120.667,0.00,-0.0002,-0.00010,9.000
9,120.800,0.00,-0.0002,-0.00010,9.000
10,121.133,0.00,0.1400,0.14010,10.000
10,121.267,0.00,0.2733,0.27337,10.000
10,121.400,0.00,0.4068,0.40690,10.000
10,121.533,0.00,0.5401,0.54020,10.000
10,121.667,0.00,0.6734,0.67347,10.000
10,121.800,0.00,0.8066,0.80670,10.000
10,121.933,-0.01,0.9402,0.94027,10.000
10,122.067,0.00,1.0734,1.07347,10.000
10,122.200,0.00,1.2067,1.20680,10.000
10,122.333,0.00,1.3401,1.34020,10.000
10,122.467,0.00,1.4732,1.47333,10.000
10,122.600,0.00,1.6067,1.60680,10.000
10,122.733,0.05,1.7402,1.74027,10.000
10,122.867,0.19,1.8735,1.87357,10.000
10,123.000,0.45,2.0068,2.00690,10.000
10,123.133,0.82,2.1402,2.14033,10.000
10,123.267,1.32,2.2735,2.27360,10.000
10,123.400,1.95,2.4069,2.40700,10.000
10,123.533,2.70,2.5403,2.54043,10.000
10,123.667,3.59,2.6735,2.67360,10.000
10,123.800,4.64,2.8067,2.80680,10.000
10,123.933,5.89,2.9402,2.94033,10.000
10,124.067,7.41,3.0735,3.07357,10.000
10,124.200,9.16,3.2068,3.20690,10.000
10,124.333,11.19,3.3401,3.34023,10.000
10,124.467,13.52,3.4735,3.47360,10.000
10,124.600,16.21,3.6067,3.60680,10.000
10,124.733,19.32,3.7401,3.74023,10.000
10,124.867,22.92,3.8735,3.87360,10.000
10,125.000,27.11,4.0067,4.00680,10.000
10,125.133,31.99,4.1402,4.14027,10.000
10,125.267,37.66,4.2735,4.27363,10.000
10,125.400,44.38,4.4068,4.40690,10.000
10,125.600,54.02,4.5463,4.54640,10.000
10,125.733,41.49,4.4143,4.41440,10.000
10,125.867,32.78,4.2809,4.28100,10.000
10,126.000,26.28,4.1476,4.14770,10.000
10,126.133,21.21,4.0143,4.01440,10.000
10,126.267,17.14,3.8808,3.88093,10.000
10,126.400,13.83,3.7477,3.74780,10.000
10,126.533,11.17,3.6143,3.61440,10.000
10,126.667,9.02,3.4808,3.48093,10.000
10,126.800,7.22,3.3476,3.34770,10.000
10,126.933,5.75,3.2142,3.21430,10.000
10,127.067,4.55,3.0808,3.08090,10.000
10,127.200,3.57,2.9475,2.94760,10.000
10,127.333,2.75,2.8141,2.81420,10.000
10,127.467,2.09,2.6806,2.68073,10.000
10,127.600,1.54,2.5476,2.54770,10.000
10,127.733,1.09,2.4142,2.41427,10.000
10,127.867,0.72,2.2807,2.28083,10.000
10,128.000,0.42,2.1474,2.14750,10.000
10,128.133,0.20,2.0141,2.01417,10.000
10,128.267,0.05,1.8807,1.88077,10.000
10,128.400,0.00,1.7475,1.74760,10.000
10,128.533,-0.01,1.6142,1.61427,10.000
10,128.667,-0.01,1.4806,1.48070,10.000
10,128.800,-0.01,1.3474,1.34750,10.000
10,128.933,0.00,1.2141,1.21417,10.000
10,129.067,0.00,1.0807,1.08080,10.000
10,129.200,0.00,0.9474,0.94750,10.000
10,129.333,-0.01,0.8140,0.81413,10.000
10,129.467,0.00,0.6806,0.68073,10.000
10,129.600,-0.01,0.5473,0.54740,10.000
10,129.733,0.00,0.4140,0.41413,10.000
10,129.867,0.00,0.2805,0.28063,10.000
10,130.000,0.00,0.1473,0.14740,10.000
10,130.133,-0.01,0.0140,0.01407,10.000
10,130.333,0.00,-0.0004,-0.00030,10.000
10,130.467,0.00,-0.0003,-0.00020,10.000
10,130.600,-0.01,-0.0003,-0.00020,10.000
10,130.733,-0.01,-0.0003,-0.00020,10.000
10,130.867,0.00,-0.0003,-0.00020,10.000
10,131.000,-0.01,-0.0003,-0.00020,10.000
10,131.133,0.00,-0.0003,-0.00020,10.000
10,131.267,0.00,-0.0003,-0.00020,10.000
10,131.400,0.00,-0.0003,-0.00020,10.000
10,131.533,0.00,-0.0003,-0.00020,10.000
10,131.667,-0.01,-0.0003,-0.00020,10.000
10,131.800,-0.01,-0.0003,-0.00020,10.000
10,131.933,-0.01,-0.0003,-0.00020,10.000
10,132.067,0.00,-0.0003,-0.00020,10.000
10,132.200,0.00,-0.0003,-0.00020,10.000
10,132.333,0.00,-0.0003,-0.00020,10.000
10,132.467,0.00,-0.0003,-0.00020,10.000
10,132.600,-0.01,-0.0003,-0.00020,10.000
10,132.733,-0.01,-0.0003,-0.00020,10.000
10,132.867,-0.01,-0.0002,-0.00010,10.000
10,133.000,0.00,-0.0002,-0.00010,10.000
10,133.133,0.00,-0.0002,-0.00010,10.000
10,133.333,0.00,-0.0002,-0.00010,10.000
10,133.467,-0.01,-0.0002,-0.00010,10.000
10,133.600,0.00,-0.0002,-0.00010,10.000
10,133.733,0.00,-0.0002,-0.00010,10.000
10,133.867,0.00,-0.0002,-0.00010,10.000
10,134.000,0.00,-0.0002,-0.00010,10.000
10,134.133,0.00,-0.0002,-0.00010,10.000
10,134.200,0.00,-0.0002,-0.00010,10.000