File: AIME_journal_files/AIME_data/calibDATA_loadcell/date_02:15:2018/Instron_02.15.2018/1_5N_1__1mm.s_0_0.txt
""
"Test Method","Radhen_Load_Cntrl_Cmprsn_250N_12-7.msm"
"Sample I. D.","Sample1.mss"
"Specimen Number","2"

"TheCycle_Output ()","_Time (s)","_Load (N)","_Extension (mm)","RealTimeDepth (mm)","CycleNumber ()"

1,0.267,0.00,0.0552,0.05520,1.000
1,0.400,0.00,0.1888,0.18880,1.000
1,0.533,0.00,0.3221,0.32210,1.000
1,0.667,0.00,0.4555,0.45550,1.000
1,0.800,0.00,0.5888,0.58880,1.000
1,0.933,0.00,0.7221,0.72213,1.000
1,1.067,-0.01,0.8554,0.85543,1.000
1,1.200,0.00,0.9890,0.98900,1.000
1,1.333,0.00,1.1224,1.12243,1.000
1,1.467,0.00,1.2554,1.25540,1.000
1,1.600,0.00,1.3888,1.38880,1.000
1,1.733,-0.01,1.5221,1.52210,1.000
1,1.867,0.00,1.6555,1.65547,1.000
1,2.000,0.00,1.7888,1.78880,1.000
1,2.133,0.00,1.9222,1.92223,1.000
1,2.267,-0.01,2.0555,2.05547,1.000
1,2.400,-0.01,2.1888,2.18880,1.000
1,2.533,-0.01,2.3223,2.32227,1.000
1,2.667,-0.01,2.4554,2.45543,1.000
1,2.800,-0.01,2.5889,2.58890,1.000
1,2.933,-0.01,2.7223,2.72227,1.000
1,3.067,0.00,2.8555,2.85553,1.000
1,3.200,-0.01,2.9889,2.98890,1.000
1,3.333,0.00,3.1221,3.12213,1.000
1,3.467,0.00,3.2555,3.25550,1.000
1,3.600,0.00,3.3889,3.38890,1.000
1,3.733,-0.01,3.5222,3.52220,1.000
1,3.867,0.00,3.6555,3.65547,1.000
1,4.000,-0.01,3.7889,3.78890,1.000
1,4.133,0.00,3.9223,3.92230,1.000
1,4.267,0.00,4.0554,4.05543,1.000
1,4.400,-0.01,4.1889,4.18890,1.000
1,4.533,0.00,4.3222,4.32223,1.000
1,4.667,0.00,4.4555,4.45550,1.000
1,4.800,0.00,4.5888,4.58880,1.000
1,4.933,0.00,4.7223,4.72230,1.000
1,5.067,0.00,4.8555,4.85553,1.000
1,5.200,0.00,4.9890,4.98900,1.000
1,5.333,-0.01,5.1223,5.12230,1.000
1,5.467,0.00,5.2556,5.25557,1.000
1,5.600,0.00,5.3890,5.38900,1.000
1,5.733,0.00,5.5223,5.52230,1.000
1,5.867,0.00,5.6557,5.65567,1.000
1,6.000,-0.01,5.7888,5.78880,1.000
1,6.133,0.01,5.9223,5.92233,1.000
1,6.267,0.06,6.0555,6.05553,1.000
1,6.400,0.19,6.1890,6.18900,1.000
1,6.533,0.47,6.3223,6.32230,1.000
1,6.667,0.86,6.4556,6.45563,1.000
1,6.800,1.39,6.5890,6.58900,1.000
1,6.933,2.04,6.7224,6.72240,1.000
1,7.067,2.82,6.8558,6.85580,1.000
1,7.200,3.76,6.9890,6.98900,1.000
1,7.333,4.86,7.1222,7.12223,1.000
1,7.533,4.36,7.0762,7.07620,1.000
1,7.667,3.15,6.9430,6.94300,1.000
1,7.800,2.21,6.8098,6.80980,1.000
1,7.933,1.48,6.6765,6.67647,1.000
1,8.067,0.93,6.5430,6.54300,1.000
1,8.200,0.51,6.4096,6.40960,1.000
1,8.333,0.23,6.2764,6.27640,1.000
1,8.467,0.08,6.1429,6.14293,1.000
1,8.600,0.02,6.0096,6.00960,1.000
1,8.733,-0.01,5.8762,5.87623,1.000
1,8.867,0.00,5.7427,5.74270,1.000
1,9.000,-0.01,5.6096,5.60960,1.000
1,9.133,0.00,5.4762,5.47623,1.000
1,9.267,-0.01,5.3428,5.34283,1.000
1,9.400,0.00,5.2096,5.20960,1.000
1,9.533,-0.01,5.0762,5.07620,1.000
1,9.667,0.00,4.9428,4.94283,1.000
1,9.800,-0.01,4.8094,4.80940,1.000
1,9.933,0.00,4.6762,4.67623,1.000
1,10.067,-0.01,4.5428,4.54277,1.000
1,10.200,0.00,4.4095,4.40950,1.000
1,10.333,-0.01,4.2762,4.27617,1.000
1,10.467,-0.01,4.1428,4.14277,1.000
1,10.600,0.00,4.0095,4.00950,1.000
1,10.733,0.00,3.8762,3.87620,1.000
1,10.867,-0.01,3.7428,3.74277,1.000
1,11.000,0.00,3.6095,3.60950,1.000
1,11.133,0.00,3.4760,3.47600,1.000
1,11.267,0.00,3.3427,3.34267,1.000
1,11.400,-0.01,3.2093,3.20930,1.000
1,11.533,0.00,3.0760,3.07603,1.000
1,11.667,0.00,2.9426,2.94260,1.000
1,11.800,-0.01,2.8093,2.80930,1.000
1,11.933,0.00,2.6761,2.67613,1.000
1,12.067,0.00,2.5427,2.54267,1.000
1,12.200,0.00,2.4094,2.40940,1.000
1,12.333,0.00,2.2760,2.27600,1.000
1,12.467,0.00,2.1426,2.14257,1.000
1,12.600,0.00,2.0091,2.00910,1.000
1,12.733,0.00,1.8759,1.87593,1.000
1,12.867,0.00,1.7426,1.74263,1.000
1,13.000,0.00,1.6092,1.60920,1.000
1,13.133,0.00,1.4760,1.47597,1.000
1,13.267,-0.01,1.3425,1.34247,1.000
1,13.400,0.00,1.2092,1.20920,1.000
1,13.533,0.00,1.0760,1.07603,1.000
1,13.667,-0.01,0.9426,0.94263,1.000
1,13.800,0.00,0.8091,0.80910,1.000
1,13.933,-0.01,0.6759,0.67590,1.000
1,14.067,-0.01,0.5425,0.54250,1.000
1,14.200,0.00,0.4092,0.40920,1.000
1,14.333,0.00,0.2758,0.27583,1.000
1,14.467,0.00,0.1425,0.14253,1.000
1,14.600,0.00,0.0090,0.00900,1.000
1,14.800,0.00,-0.0004,-0.00040,1.000
1,14.933,0.00,-0.0004,-0.00040,1.000
1,15.067,0.00,-0.0004,-0.00040,1.000
1,15.200,0.00,-0.0004,-0.00040,1.000
1,15.333,0.00,-0.0004,-0.00040,1.000
1,15.467,0.00,-0.0004,-0.00040,1.000
1,15.600,0.00,-0.0004,-0.00040,1.000
1,15.733,-0.01,-0.0004,-0.00040,1.000
1,15.867,0.00,-0.0004,-0.00040,1.000
1,16.000,0.00,-0.0004,-0.00040,1.000
1,16.133,-0.01,-0.0003,-0.00030,1.000
1,16.267,-0.01,-0.0003,-0.00030,1.000
1,16.400,-0.01,-0.0003,-0.00030,1.000
1,16.533,0.00,-0.0003,-0.00030,1.000
1,16.667,0.00,-0.0003,-0.00030,1.000
1,16.800,0.00,-0.0003,-0.00030,1.000
1,16.933,0.00,-0.0003,-0.00030,1.000
1,17.067,0.00,-0.0003,-0.00030,1.000
1,17.200,0.00,-0.0003,-0.00030,1.000
1,17.333,-0.01,-0.0003,-0.00030,1.000
1,17.467,-0.01,-0.0003,-0.00030,1.000
1,17.600,0.00,-0.0003,-0.00030,1.000
1,17.800,-0.01,-0.0003,-0.00030,1.000
1,17.933,0.00,-0.0002,-0.00020,1.000
1,18.067,0.00,-0.0002,-0.00020,1.000
1,18.200,0.00,-0.0002,-0.00020,1.000
1,18.333,-0.01,-0.0002,-0.00020,1.000
1,18.467,0.00,-0.0002,-0.00020,1.000
1,18.600,0.00,-0.0002,-0.00020,1.000
2,18.933,0.00,0.0618,0.06190,2.000
2,19.067,0.00,0.1953,0.19543,2.000
2,19.200,-0.01,0.3286,0.32870,2.000
2,19.333,0.00,0.4620,0.46213,2.000
2,19.467,-0.01,0.5954,0.59547,2.000
2,19.600,-0.01,0.7286,0.72870,2.000
2,19.733,0.00,0.8620,0.86210,2.000
2,19.867,0.00,0.9955,0.99557,2.000
2,20.000,-0.01,1.1289,1.12900,2.000
2,20.133,-0.01,1.2620,1.26213,2.000
2,20.267,-0.01,1.3954,1.39553,2.000
2,20.400,-0.01,1.5285,1.52860,2.000
2,20.533,-0.01,1.6621,1.66217,2.000
2,20.667,0.00,1.7955,1.79557,2.000
2,20.800,-0.01,1.9286,1.92870,2.000
2,20.933,-0.01,2.0620,2.06213,2.000
2,21.067,0.00,2.1954,2.19547,2.000
2,21.200,0.00,2.3287,2.32880,2.000
2,21.333,0.00,2.4620,2.46210,2.000
2,21.467,0.00,2.5955,2.59563,2.000
2,21.600,-0.01,2.7288,2.72890,2.000
2,21.733,0.00,2.8622,2.86227,2.000
2,21.867,-0.01,2.9955,2.99560,2.000
2,22.000,-0.01,3.1286,3.12870,2.000
2,22.133,-0.01,3.2620,3.26213,2.000
2,22.267,0.00,3.3955,3.39557,2.000
2,22.400,-0.01,3.5286,3.52870,2.000
2,22.533,0.00,3.6621,3.66220,2.000
2,22.667,0.00,3.7956,3.79567,2.000
2,22.800,0.00,3.9288,3.92890,2.000
2,22.933,-0.01,4.0621,4.06220,2.000
2,23.067,-0.01,4.1955,4.19557,2.000
2,23.200,-0.01,4.3288,4.32890,2.000
2,23.333,-0.01,4.4621,4.46220,2.000
2,23.467,-0.01,4.5956,4.59570,2.000
2,23.600,0.00,4.7288,4.72890,2.000
2,23.733,0.00,4.8622,4.86227,2.000
2,23.867,0.00,4.9956,4.99570,2.000
2,24.000,-0.01,5.1288,5.12890,2.000
2,24.133,-0.01,5.2622,5.26227,2.000
2,24.267,0.00,5.3956,5.39573,2.000
2,24.400,0.00,5.5289,5.52900,2.000
2,24.533,-0.01,5.6622,5.66227,2.000
2,24.667,0.00,5.7955,5.79557,2.000
2,24.800,0.01,5.9289,5.92900,2.000
2,24.933,0.06,6.0621,6.06223,2.000
2,25.067,0.20,6.1956,6.19570,2.000
2,25.200,0.46,6.3290,6.32910,2.000
2,25.333,0.86,6.4622,6.46227,2.000
2,25.467,1.40,6.5957,6.59577,2.000
2,25.600,2.06,6.7291,6.72920,2.000
2,25.733,2.85,6.8623,6.86243,2.000
2,25.867,3.79,6.9955,6.99560,2.000
2,26.000,4.91,7.1289,7.12900,2.000
2,26.200,4.48,7.0896,7.08970,2.000
2,26.333,3.24,6.9564,6.95647,2.000
2,26.467,2.28,6.8231,6.82320,2.000
2,26.600,1.53,6.6898,6.68990,2.000
2,26.733,0.96,6.5564,6.55647,2.000
2,26.867,0.54,6.4229,6.42300,2.000
2,27.000,0.24,6.2895,6.28960,2.000
2,27.133,0.08,6.1564,6.15650,2.000
2,27.267,0.02,6.0228,6.02290,2.000
2,27.400,-0.01,5.8896,5.88970,2.000
2,27.533,-0.01,5.7561,5.75620,2.000
2,27.667,-0.01,5.6228,5.62290,2.000
2,27.800,0.00,5.4896,5.48970,2.000
2,27.933,0.00,5.3563,5.35640,2.000
2,28.067,-0.01,5.2228,5.22290,2.000
2,28.200,0.00,5.0895,5.08960,2.000
2,28.333,-0.01,4.9562,4.95633,2.000
2,28.467,-0.01,4.8228,4.82287,2.000
2,28.600,0.00,4.6895,4.68960,2.000
2,28.733,0.00,4.5563,4.55637,2.000
2,28.867,-0.01,4.4227,4.42277,2.000
2,29.000,-0.01,4.2894,4.28950,2.000
2,29.133,0.00,4.1562,4.15627,2.000
2,29.267,0.00,4.0227,4.02277,2.000
2,29.400,-0.01,3.8895,3.88960,2.000
2,29.533,0.00,3.7561,3.75623,2.000
2,29.667,0.00,3.6227,3.62277,2.000
2,29.800,0.00,3.4893,3.48940,2.000
2,29.933,0.00,3.3561,3.35617,2.000
2,30.067,0.00,3.2226,3.22273,2.000
2,30.200,-0.01,3.0892,3.08930,2.000
2,30.333,-0.01,2.9560,2.95613,2.000
2,30.467,-0.01,2.8226,2.82273,2.000
2,30.600,-0.01,2.6893,2.68940,2.000
2,30.733,-0.01,2.5560,2.55613,2.000
2,30.867,-0.01,2.4226,2.42273,2.000
2,31.000,0.00,2.2893,2.28940,2.000
2,31.133,-0.01,2.1560,2.15610,2.000
2,31.267,0.00,2.0226,2.02267,2.000
2,31.400,0.00,1.8892,1.88930,2.000
2,31.533,-0.01,1.7561,1.75617,2.000
2,31.667,-0.01,1.6225,1.62263,2.000
2,31.800,-0.01,1.4892,1.48930,2.000
2,31.933,-0.01,1.3559,1.35597,2.000
2,32.067,-0.01,1.2225,1.22263,2.000
2,32.200,-0.01,1.0893,1.08940,2.000
2,32.333,-0.01,0.9559,0.95603,2.000
2,32.467,0.00,0.8225,0.82263,2.000
2,32.600,0.00,0.6891,0.68920,2.000
2,32.733,0.00,0.5559,0.55597,2.000
2,32.867,-0.01,0.4226,0.42270,2.000
2,33.000,-0.01,0.2891,0.28920,2.000
2,33.133,-0.01,0.1559,0.15597,2.000
2,33.267,-0.01,0.0224,0.02250,2.000
2,33.467,-0.01,-0.0004,-0.00033,2.000
2,33.600,0.00,-0.0004,-0.00030,2.000
2,33.733,0.00,-0.0004,-0.00030,2.000
2,33.867,0.00,-0.0004,-0.00030,2.000
2,34.000,0.00,-0.0004,-0.00030,2.000
2,34.133,0.00,-0.0004,-0.00030,2.000
2,34.267,0.00,-0.0004,-0.00030,2.000
2,34.400,-0.01,-0.0004,-0.00030,2.000
2,34.533,-0.01,-0.0004,-0.00030,2.000
2,34.667,-0.01,-0.0004,-0.00030,2.000
2,34.800,0.00,-0.0004,-0.00030,2.000
2,34.933,-0.01,-0.0004,-0.00027,2.000
2,35.067,-0.01,-0.0003,-0.00020,2.000
2,35.200,0.00,-0.0003,-0.00020,2.000
2,35.333,0.00,-0.0003,-0.00020,2.000
2,35.467,-0.01,-0.0003,-0.00020,2.000
2,35.600,0.00,-0.0003,-0.00020,2.000
2,35.733,0.00,-0.0003,-0.00020,2.000
2,35.867,0.00,-0.0003,-0.00020,2.000
2,36.000,0.00,-0.0003,-0.00020,2.000
2,36.133,-0.01,-0.0003,-0.00020,2.000
2,36.267,0.00,-0.0003,-0.00020,2.000
2,36.467,-0.01,-0.0003,-0.00020,2.000
2,36.600,0.00,-0.0003,-0.00020,2.000
2,36.733,0.00,-0.0002,-0.00010,2.000
2,36.867,0.00,-0.0002,-0.00010,2.000
2,37.000,0.00,-0.0002,-0.00010,2.000
2,37.133,-0.01,-0.0002,-0.00010,2.000
2,37.267,-0.01,-0.0002,-0.00010,2.000
3,37.600,0.01,0.0485,0.04860,3.000
3,37.733,0.01,0.1819,0.18197,3.000
3,37.867,0.01,0.3153,0.31540,3.000
3,38.000,0.01,0.4486,0.44870,3.000
3,38.133,0.01,0.5819,0.58203,3.000
3,38.267,0.01,0.7154,0.71550,3.000
3,38.400,0.01,0.8488,0.84890,3.000
3,38.533,0.01,0.9821,0.98217,3.000
3,38.667,0.01,1.1155,1.11563,3.000
3,38.800,0.01,1.2487,1.24880,3.000
3,38.933,0.01,1.3820,1.38207,3.000
3,39.067,0.01,1.5154,1.51550,3.000
3,39.200,0.01,1.6487,1.64880,3.000
3,39.333,0.01,1.7820,1.78213,3.000
3,39.467,0.01,1.9154,1.91553,3.000
3,39.600,0.01,2.0488,2.04890,3.000
3,39.733,0.01,2.1820,2.18207,3.000
3,39.867,0.01,2.3155,2.31560,3.000
3,40.000,0.01,2.4488,2.44890,3.000
3,40.133,0.01,2.5820,2.58210,3.000
3,40.267,0.01,2.7155,2.71563,3.000
3,40.400,0.01,2.8488,2.84890,3.000
3,40.533,0.01,2.9821,2.98217,3.000
3,40.667,0.01,3.1154,3.11547,3.000
3,40.800,0.01,3.2487,3.24880,3.000
3,40.933,0.01,3.3820,3.38210,3.000
3,41.067,0.01,3.5155,3.51557,3.000
3,41.200,0.01,3.6489,3.64900,3.000
3,41.333,0.00,3.7821,3.78217,3.000
3,41.467,0.01,3.9155,3.91563,3.000
3,41.600,0.01,4.0488,4.04890,3.000
3,41.733,0.01,4.1821,4.18217,3.000
3,41.867,0.01,4.3155,4.31560,3.000
3,42.000,0.01,4.4489,4.44900,3.000
3,42.133,0.01,4.5821,4.58217,3.000
3,42.267,0.01,4.7155,4.71563,3.000
3,42.400,0.01,4.8490,4.84910,3.000
3,42.533,0.01,4.9822,4.98227,3.000
3,42.667,0.01,5.1155,5.11563,3.000
3,42.800,0.00,5.2490,5.24910,3.000
3,42.933,0.01,5.3823,5.38237,3.000
3,43.067,0.01,5.5155,5.51563,3.000
3,43.200,0.01,5.6490,5.64910,3.000
3,43.333,0.01,5.7820,5.78213,3.000
3,43.467,0.02,5.9155,5.91563,3.000
3,43.600,0.07,6.0490,6.04910,3.000
3,43.733,0.19,6.1822,6.18233,3.000
3,43.867,0.45,6.3155,6.31563,3.000
3,44.000,0.83,6.4489,6.44900,3.000
3,44.133,1.35,6.5822,6.58233,3.000
3,44.267,2.00,6.7156,6.71573,3.000
3,44.400,2.77,6.8491,6.84920,3.000
3,44.533,3.70,6.9822,6.98230,3.000
3,44.667,4.78,7.1154,7.11553,3.000
3,44.867,4.62,7.1028,7.10287,3.000
3,45.000,3.35,6.9697,6.96980,3.000
3,45.133,2.38,6.8365,6.83657,3.000
3,45.267,1.61,6.7030,6.70313,3.000
3,45.400,1.03,6.5697,6.56980,3.000
3,45.533,0.59,6.4363,6.43643,3.000
3,45.667,0.29,6.3028,6.30293,3.000
3,45.800,0.10,6.1697,6.16980,3.000
3,45.933,0.03,6.0362,6.03633,3.000
3,46.067,0.01,5.9029,5.90300,3.000
3,46.200,0.01,5.7695,5.76960,3.000
3,46.333,0.01,5.6362,5.63633,3.000
3,46.467,0.01,5.5028,5.50287,3.000
3,46.600,0.01,5.3695,5.36960,3.000
3,46.733,0.01,5.2362,5.23633,3.000
3,46.867,0.01,5.1027,5.10280,3.000
3,47.000,0.01,4.9695,4.96960,3.000
3,47.133,0.01,4.8362,4.83630,3.000
3,47.267,0.01,4.7027,4.70280,3.000
3,47.400,0.01,4.5695,4.56960,3.000
3,47.533,0.01,4.4362,4.43630,3.000
3,47.667,0.01,4.3026,4.30273,3.000
3,47.800,0.01,4.1694,4.16950,3.000
3,47.933,0.01,4.0361,4.03620,3.000
3,48.067,0.01,3.9027,3.90277,3.000
3,48.200,0.01,3.7695,3.76960,3.000
3,48.333,0.01,3.6362,3.63630,3.000
3,48.467,0.01,3.5026,3.50273,3.000
3,48.600,0.01,3.3694,3.36950,3.000
3,48.733,0.01,3.2360,3.23610,3.000
3,48.867,0.00,3.1025,3.10263,3.000
3,49.000,0.01,2.9693,2.96940,3.000
3,49.133,0.01,2.8361,2.83620,3.000
3,49.267,0.01,2.7026,2.70267,3.000
3,49.400,0.01,2.5694,2.56950,3.000
3,49.533,0.01,2.4360,2.43610,3.000
3,49.667,0.01,2.3026,2.30267,3.000
3,49.800,0.01,2.1693,2.16940,3.000
3,49.933,0.01,2.0360,2.03610,3.000
3,50.067,0.01,1.9025,1.90260,3.000
3,50.200,0.01,1.7693,1.76940,3.000
3,50.333,0.01,1.6360,1.63610,3.000
3,50.467,0.01,1.5024,1.50253,3.000
3,50.600,0.01,1.3691,1.36920,3.000
3,50.733,0.01,1.2359,1.23603,3.000
3,50.867,0.01,1.1027,1.10277,3.000
3,51.000,0.00,0.9693,0.96940,3.000
3,51.133,0.01,0.8360,0.83607,3.000
3,51.267,0.01,0.7025,0.70260,3.000
3,51.400,0.00,0.5691,0.56920,3.000
3,51.533,0.01,0.4360,0.43607,3.000
3,51.667,0.01,0.3025,0.30260,3.000
3,51.800,0.01,0.1691,0.16920,3.000
3,51.933,0.01,0.0359,0.03597,3.000
3,52.133,0.01,-0.0004,-0.00030,3.000
3,52.267,0.01,-0.0004,-0.00030,3.000
3,52.400,0.01,-0.0004,-0.00030,3.000
3,52.533,0.01,-0.0004,-0.00030,3.000
3,52.667,0.01,-0.0004,-0.00030,3.000
3,52.800,0.01,-0.0004,-0.00030,3.000
3,52.933,0.01,-0.0004,-0.00030,3.000
3,53.067,0.01,-0.0004,-0.00030,3.000
3,53.200,0.01,-0.0004,-0.00030,3.000
3,53.333,0.01,-0.0003,-0.00020,3.000
3,53.467,0.01,-0.0003,-0.00020,3.000
3,53.600,0.00,-0.0003,-0.00020,3.000
3,53.733,0.01,-0.0003,-0.00020,3.000
3,53.867,0.01,-0.0003,-0.00020,3.000
3,54.000,0.01,-0.0003,-0.00020,3.000
3,54.133,0.01,-0.0003,-0.00020,3.000
3,54.267,0.01,-0.0003,-0.00020,3.000
3,54.400,0.01,-0.0003,-0.00020,3.000
3,54.533,0.01,-0.0003,-0.00020,3.000
3,54.667,0.01,-0.0003,-0.00020,3.000
3,54.800,0.01,-0.0003,-0.00020,3.000
3,54.933,0.01,-0.0003,-0.00020,3.000
3,55.133,0.01,-0.0002,-0.00010,3.000
3,55.267,0.01,-0.0002,-0.00010,3.000
3,55.400,0.01,-0.0002,-0.00010,3.000
3,55.533,0.01,-0.0002,-0.00010,3.000
3,55.667,0.01,-0.0002,-0.00010,3.000
3,55.800,0.01,-0.0002,-0.00010,3.000
3,55.933,0.01,-0.0002,-0.00010,3.000
4,56.267,0.00,0.0551,0.05517,4.000
4,56.400,0.00,0.1886,0.18870,4.000
4,56.533,0.00,0.3220,0.32207,4.000
4,56.667,0.00,0.4553,0.45543,4.000
4,56.800,0.00,0.5886,0.58870,4.000
4,56.933,0.00,0.7221,0.72223,4.000
4,57.067,0.00,0.8553,0.85543,4.000
4,57.200,0.00,0.9887,0.98880,4.000
4,57.333,0.00,1.1222,1.12233,4.000
4,57.467,0.00,1.2553,1.25540,4.000
4,57.600,0.00,1.3887,1.38880,4.000
4,57.733,0.00,1.5220,1.52213,4.000
4,57.867,0.00,1.6553,1.65543,4.000
4,58.000,0.00,1.7887,1.78880,4.000
4,58.133,0.00,1.9221,1.92217,4.000
4,58.267,0.00,2.0553,2.05543,4.000
4,58.400,-0.01,2.1888,2.18890,4.000
4,58.533,0.00,2.3221,2.32220,4.000
4,58.667,-0.01,2.4553,2.45543,4.000
4,58.800,0.00,2.5887,2.58880,4.000
4,58.933,0.00,2.7221,2.72217,4.000
4,59.067,0.00,2.8554,2.85550,4.000
4,59.200,0.00,2.9887,2.98880,4.000
4,59.333,0.00,3.1220,3.12210,4.000
4,59.467,-0.01,3.2553,3.25543,4.000
4,59.600,0.00,3.3887,3.38880,4.000
4,59.733,0.00,3.5222,3.52227,4.000
4,59.867,0.00,3.6554,3.65547,4.000
4,60.000,0.00,3.7888,3.78890,4.000
4,60.133,0.00,3.9222,3.92233,4.000
4,60.267,-0.01,4.0554,4.05553,4.000
4,60.400,-0.01,4.1887,4.18880,4.000
4,60.533,0.00,4.3221,4.32223,4.000
4,60.667,-0.01,4.4555,4.45557,4.000
4,60.800,0.00,4.5888,4.58890,4.000
4,60.933,0.00,4.7222,4.72233,4.000
4,61.067,0.00,4.8555,4.85557,4.000
4,61.200,0.00,4.9888,4.98890,4.000
4,61.333,-0.01,5.1222,5.12230,4.000
4,61.467,-0.01,5.2555,5.25563,4.000
4,61.600,0.00,5.3889,5.38900,4.000
4,61.733,0.00,5.5223,5.52237,4.000
4,61.867,0.00,5.6555,5.65563,4.000
4,62.000,0.00,5.7887,5.78880,4.000
4,62.133,0.01,5.9222,5.92230,4.000
4,62.267,0.06,6.0555,6.05563,4.000
4,62.400,0.19,6.1889,6.18900,4.000
4,62.533,0.46,6.3223,6.32237,4.000
4,62.667,0.85,6.4557,6.45577,4.000
4,62.800,1.36,6.5889,6.58900,4.000
4,62.933,2.02,6.7223,6.72240,4.000
4,63.067,2.80,6.8558,6.85587,4.000
4,63.200,3.73,6.9888,6.98890,4.000
4,63.333,4.83,7.1222,7.12233,4.000
4,63.533,4.53,7.0961,7.09623,4.000
4,63.667,3.28,6.9630,6.96313,4.000
4,63.800,2.32,6.8296,6.82970,4.000
4,63.933,1.57,6.6963,6.69643,4.000
4,64.067,0.99,6.5630,6.56313,4.000
4,64.200,0.56,6.4295,6.42960,4.000
4,64.333,0.26,6.2963,6.29637,4.000
4,64.467,0.09,6.1630,6.16313,4.000
4,64.600,0.02,6.0294,6.02950,4.000
4,64.733,0.00,5.8962,5.89633,4.000
4,64.867,0.00,5.7628,5.76290,4.000
4,65.000,0.00,5.6294,5.62950,4.000
4,65.133,0.00,5.4962,5.49627,4.000
4,65.267,0.00,5.3630,5.36310,4.000
4,65.400,0.00,5.2295,5.22960,4.000
4,65.533,0.00,5.0961,5.09620,4.000
4,65.667,0.00,4.9630,4.96307,4.000
4,65.800,0.00,4.8294,4.82950,4.000
4,65.933,0.00,4.6961,4.69620,4.000
4,66.067,0.00,4.5629,4.56300,4.000
4,66.200,-0.01,4.4294,4.42950,4.000
4,66.333,0.00,4.2960,4.29610,4.000
4,66.467,0.00,4.1628,4.16293,4.000
4,66.600,0.00,4.0293,4.02940,4.000
4,66.733,0.00,3.8961,3.89617,4.000
4,66.867,0.00,3.7628,3.76293,4.000
4,67.000,0.00,3.6294,3.62950,4.000
4,67.133,0.00,3.4959,3.49603,4.000
4,67.267,0.00,3.3627,3.36283,4.000
4,67.400,0.00,3.2294,3.22950,4.000
4,67.533,-0.01,3.0958,3.09587,4.000
4,67.667,0.00,2.9627,2.96280,4.000
4,67.800,0.00,2.8293,2.82940,4.000
4,67.933,0.00,2.6960,2.69607,4.000
4,68.067,0.00,2.5627,2.56283,4.000
4,68.200,-0.01,2.4293,2.42940,4.000
4,68.333,0.00,2.2959,2.29597,4.000
4,68.467,0.00,2.1627,2.16280,4.000
4,68.600,0.00,2.0294,2.02950,4.000
4,68.733,0.00,1.8958,1.89593,4.000
4,68.867,0.00,1.7627,1.76280,4.000
4,69.000,0.00,1.6292,1.62930,4.000
4,69.133,0.00,1.4958,1.49587,4.000
4,69.267,0.00,1.3625,1.36260,4.000
4,69.400,0.00,1.2293,1.22940,4.000
4,69.533,-0.01,1.0959,1.09600,4.000
4,69.667,0.00,0.9625,0.96263,4.000
4,69.800,0.00,0.8294,0.82950,4.000
4,69.933,0.00,0.6958,0.69593,4.000
4,70.067,0.00,0.5626,0.56267,4.000
4,70.200,0.00,0.4293,0.42940,4.000
4,70.333,0.00,0.2957,0.29583,4.000
4,70.467,0.00,0.1626,0.16267,4.000
4,70.600,0.00,0.0292,0.02930,4.000
4,70.800,0.00,-0.0005,-0.00040,4.000
4,70.933,0.00,-0.0004,-0.00030,4.000
4,71.067,0.00,-0.0004,-0.00030,4.000
4,71.200,0.00,-0.0004,-0.00030,4.000
4,71.333,0.00,-0.0004,-0.00030,4.000
4,71.467,0.00,-0.0004,-0.00030,4.000
4,71.600,0.00,-0.0004,-0.00030,4.000
4,71.733,0.00,-0.0004,-0.00030,4.000
4,71.867,0.00,-0.0004,-0.00030,4.000
4,72.000,0.00,-0.0003,-0.00020,4.000
4,72.133,0.00,-0.0003,-0.00020,4.000
4,72.267,0.00,-0.0003,-0.00020,4.000
4,72.400,0.00,-0.0003,-0.00020,4.000
4,72.533,0.00,-0.0003,-0.00020,4.000
4,72.667,0.00,-0.0003,-0.00020,4.000
4,72.800,0.00,-0.0003,-0.00020,4.000
4,72.933,0.00,-0.0003,-0.00020,4.000
4,73.067,0.00,-0.0003,-0.00020,4.000
4,73.200,0.00,-0.0003,-0.00020,4.000
4,73.333,0.00,-0.0003,-0.00020,4.000
4,73.467,0.00,-0.0003,-0.00020,4.000
4,73.600,0.00,-0.0003,-0.00020,4.000
4,73.867,0.00,-0.0002,-0.00010,4.000
4,74.000,0.00,-0.0002,-0.00010,4.000
4,74.133,0.00,-0.0002,-0.00010,4.000
4,74.267,0.00,-0.0002,-0.00010,4.000
4,74.400,0.00,-0.0002,-0.00010,4.000
4,74.533,0.00,-0.0002,-0.00010,4.000
4,74.667,-0.01,-0.0002,-0.00010,4.000
5,75.000,0.00,0.0686,0.06870,5.000
5,75.133,-0.01,0.2019,0.20200,5.000
5,75.267,-0.01,0.3352,0.33530,5.000
5,75.400,0.00,0.4687,0.46880,5.000
5,75.533,-0.01,0.6020,0.60210,5.000
5,75.667,0.00,0.7353,0.73540,5.000
5,75.800,0.00,0.8686,0.86870,5.000
5,75.933,-0.01,1.0022,1.00227,5.000
5,76.067,0.00,1.1355,1.13557,5.000
5,76.200,-0.01,1.2686,1.26870,5.000
5,76.333,-0.01,1.4020,1.40210,5.000
5,76.467,-0.01,1.5352,1.53533,5.000
5,76.600,-0.01,1.6688,1.66890,5.000
5,76.733,-0.01,1.8021,1.80223,5.000
5,76.867,0.00,1.9354,1.93547,5.000
5,77.000,-0.01,2.0688,2.06890,5.000
5,77.133,-0.01,2.2021,2.20223,5.000
5,77.267,-0.01,2.3354,2.33553,5.000
5,77.400,0.00,2.4687,2.46880,5.000
5,77.533,0.00,2.6022,2.60227,5.000
5,77.667,0.00,2.7354,2.73547,5.000
5,77.800,0.00,2.8689,2.86900,5.000
5,77.933,0.00,3.0022,3.00227,5.000
5,78.067,0.00,3.1353,3.13540,5.000
5,78.200,-0.01,3.2687,3.26880,5.000
5,78.333,0.00,3.4021,3.40223,5.000
5,78.467,0.00,3.5353,3.53543,5.000
5,78.600,0.00,3.6689,3.66900,5.000
5,78.733,0.00,3.8022,3.80230,5.000
5,78.867,-0.01,3.9355,3.93560,5.000
5,79.000,0.00,4.0687,4.06880,5.000
5,79.133,0.00,4.2021,4.20220,5.000
5,79.267,-0.01,4.3354,4.33553,5.000
5,79.400,-0.01,4.4688,4.46890,5.000
5,79.533,-0.01,4.6022,4.60230,5.000
5,79.667,0.00,4.7355,4.73560,5.000
5,79.800,0.00,4.8688,4.86890,5.000
5,79.933,-0.01,5.0023,5.00237,5.000
5,80.067,0.00,5.1355,5.13557,5.000
5,80.200,-0.01,5.2689,5.26900,5.000
5,80.333,-0.01,5.4023,5.40243,5.000
5,80.467,0.00,5.5355,5.53563,5.000
5,80.600,-0.01,5.6688,5.66890,5.000
5,80.733,-0.01,5.8021,5.80220,5.000
5,80.867,0.01,5.9356,5.93567,5.000
5,81.000,0.07,6.0688,6.06890,5.000
5,81.133,0.21,6.2024,6.20247,5.000
5,81.267,0.49,6.3356,6.33567,5.000
5,81.400,0.89,6.4688,6.46890,5.000
5,81.533,1.43,6.6023,6.60237,5.000
5,81.667,2.09,6.7357,6.73580,5.000
5,81.800,2.89,6.8690,6.86910,5.000
5,81.933,3.85,7.0022,7.00227,5.000
5,82.067,4.97,7.1355,7.13563,5.000
5,82.267,4.60,7.1028,7.10287,5.000
5,82.400,3.33,6.9697,6.96980,5.000
5,82.533,2.36,6.8364,6.83650,5.000
5,82.667,1.60,6.7030,6.70313,5.000
5,82.800,1.02,6.5698,6.56990,5.000
5,82.933,0.57,6.4362,6.43633,5.000
5,83.067,0.27,6.3029,6.30297,5.000
5,83.200,0.09,6.1697,6.16980,5.000
5,83.333,0.02,6.0362,6.03630,5.000
5,83.467,0.00,5.9029,5.90300,5.000
5,83.600,-0.01,5.7695,5.76960,5.000
5,83.733,-0.01,5.6362,5.63627,5.000
5,83.867,0.00,5.5028,5.50290,5.000
5,84.000,0.00,5.3696,5.36970,5.000
5,84.133,0.00,5.2363,5.23637,5.000
5,84.267,-0.01,5.1027,5.10283,5.000
5,84.400,-0.01,4.9696,4.96970,5.000
5,84.533,-0.01,4.8361,4.83623,5.000
5,84.667,-0.01,4.7027,4.70280,5.000
5,84.800,0.00,4.5695,4.56960,5.000
5,84.933,-0.01,4.4361,4.43617,5.000
5,85.067,0.00,4.3026,4.30273,5.000
5,85.200,0.00,4.1694,4.16950,5.000
5,85.333,0.00,4.0361,4.03617,5.000
5,85.467,0.00,3.9027,3.90277,5.000
5,85.600,-0.01,3.7694,3.76950,5.000
5,85.733,-0.01,3.6361,3.63620,5.000
5,85.867,-0.01,3.5026,3.50273,5.000
5,86.000,0.00,3.3694,3.36950,5.000
5,86.133,0.00,3.2361,3.23620,5.000
5,86.267,-0.01,3.1025,3.10260,5.000
5,86.400,-0.01,2.9693,2.96940,5.000
5,86.533,0.00,2.8361,2.83617,5.000
5,86.667,0.00,2.7026,2.70273,5.000
5,86.800,0.00,2.5693,2.56940,5.000
5,86.933,0.00,2.4360,2.43613,5.000
5,87.067,0.00,2.3025,2.30263,5.000
5,87.200,0.00,2.1693,2.16940,5.000
5,87.333,-0.01,2.0360,2.03607,5.000
5,87.467,-0.01,1.9025,1.90257,5.000
5,87.600,0.00,1.7693,1.76940,5.000
5,87.733,0.00,1.6360,1.63610,5.000
5,87.867,-0.01,1.5025,1.50257,5.000
5,88.000,-0.01,1.3691,1.36920,5.000
5,88.133,-0.01,1.2359,1.23597,5.000
5,88.267,-0.01,1.1026,1.10273,5.000
5,88.400,0.00,0.9693,0.96940,5.000
5,88.533,-0.01,0.8359,0.83603,5.000
5,88.667,-0.01,0.7025,0.70260,5.000
5,88.800,-0.01,0.5691,0.56920,5.000
5,88.933,-0.01,0.4360,0.43607,5.000
5,89.067,-0.01,0.3024,0.30253,5.000
5,89.200,-0.01,0.1691,0.16920,5.000
5,89.333,-0.01,0.0358,0.03590,5.000
5,89.467,-0.01,-0.0424,-0.04227,5.000
5,89.600,0.00,-0.0004,-0.00030,5.000
5,89.733,0.00,-0.0004,-0.00030,5.000
5,89.867,-0.01,-0.0004,-0.00030,5.000
5,90.000,0.00,-0.0004,-0.00030,5.000
5,90.133,-0.01,-0.0004,-0.00030,5.000
5,90.267,-0.01,-0.0004,-0.00030,5.000
5,90.400,-0.01,-0.0004,-0.00030,5.000
5,90.533,0.00,-0.0003,-0.00020,5.000
5,90.667,0.00,-0.0003,-0.00020,5.000
5,90.800,0.00,-0.0003,-0.00020,5.000
5,90.933,-0.01,-0.0003,-0.00020,5.000
5,91.067,0.00,-0.0003,-0.00020,5.000
5,91.200,0.00,-0.0003,-0.00020,5.000
5,91.333,-0.01,-0.0003,-0.00020,5.000
5,91.467,0.00,-0.0003,-0.00020,5.000
5,91.600,-0.01,-0.0003,-0.00020,5.000
5,91.733,0.00,-0.0003,-0.00020,5.000
5,91.867,0.00,-0.0003,-0.00020,5.000
5,92.000,-0.01,-0.0003,-0.00020,5.000
5,92.133,0.00,-0.0003,-0.00020,5.000
5,92.267,0.00,-0.0002,-0.00010,5.000
5,92.400,0.00,-0.0002,-0.00010,5.000
5,92.600,0.00,-0.0002,-0.00010,5.000
5,92.733,0.00,-0.0002,-0.00010,5.000
5,92.867,-0.01,-0.0002,-0.00010,5.000
5,93.000,-0.01,-0.0002,-0.00010,5.000
5,93.133,0.00,-0.0002,-0.00010,5.000
5,93.267,0.00,-0.0002,-0.00010,5.000
5,93.400,-0.01,-0.0002,-0.00010,5.000
6,93.733,0.00,0.0819,0.08197,6.000
6,93.867,0.00,0.2152,0.21527,6.000
6,94.000,0.01,0.3486,0.34870,6.000
6,94.133,0.00,0.4821,0.48217,6.000
6,94.267,0.00,0.6152,0.61533,6.000
6,94.400,0.01,0.7486,0.74870,6.000
6,94.533,0.00,0.8821,0.88217,6.000
6,94.667,0.00,1.0153,1.01543,6.000
6,94.800,0.01,1.1489,1.14900,6.000
6,94.933,0.01,1.2819,1.28203,6.000
6,95.067,0.01,1.4153,1.41537,6.000
6,95.200,0.00,1.5487,1.54880,6.000
6,95.333,0.01,1.6821,1.68217,6.000
6,95.467,0.00,1.8153,1.81543,6.000
6,95.600,0.01,1.9487,1.94880,6.000
6,95.733,0.01,2.0821,2.08220,6.000
6,95.867,0.01,2.2153,2.21543,6.000
6,96.000,0.01,2.3488,2.34890,6.000
6,96.133,0.01,2.4821,2.48220,6.000
6,96.267,0.01,2.6154,2.61550,6.000
6,96.400,0.00,2.7487,2.74880,6.000
6,96.533,0.00,2.8823,2.88240,6.000
6,96.667,0.01,3.0154,3.01547,6.000
6,96.800,0.00,3.1486,3.14870,6.000
6,96.933,0.01,3.2822,3.28227,6.000
6,97.067,0.00,3.4154,3.41547,6.000
6,97.200,0.00,3.5487,3.54880,6.000
6,97.333,0.00,3.6822,3.68230,6.000
6,97.467,0.00,3.8154,3.81553,6.000
6,97.600,0.01,3.9488,3.94890,6.000
6,97.733,0.01,4.0822,4.08227,6.000
6,97.867,0.01,4.2155,4.21557,6.000
6,98.000,0.01,4.3488,4.34890,6.000
6,98.133,0.00,4.4822,4.48230,6.000
6,98.267,0.00,4.6155,4.61563,6.000
6,98.400,0.01,4.7488,4.74890,6.000
6,98.533,0.00,4.8822,4.88233,6.000
6,98.667,0.00,5.0155,5.01560,6.000
6,98.800,0.00,5.1488,5.14890,6.000
6,98.933,0.00,5.2823,5.28237,6.000
6,99.067,0.00,5.4156,5.41573,6.000
6,99.200,0.00,5.5488,5.54890,6.000
6,99.333,0.00,5.6822,5.68230,6.000
6,99.467,0.00,5.8155,5.81560,6.000
6,99.600,0.02,5.9488,5.94890,6.000
6,99.733,0.08,6.0822,6.08233,6.000
6,99.867,0.23,6.2157,6.21577,6.000
6,100.000,0.53,6.3487,6.34880,6.000
6,100.133,0.95,6.4822,6.48230,6.000
6,100.267,1.50,6.6157,6.61580,6.000
6,100.400,2.18,6.7488,6.74890,6.000
6,100.533,2.99,6.8824,6.88247,6.000
6,100.667,3.96,7.0156,7.01567,6.000
6,100.800,5.10,7.1487,7.14880,6.000
6,101.000,4.28,7.0693,7.06940,6.000
6,101.133,3.09,6.9365,6.93657,6.000
6,101.267,2.17,6.8031,6.80320,6.000
6,101.400,1.46,6.6696,6.66970,6.000
6,101.533,0.90,6.5364,6.53647,6.000
6,101.667,0.50,6.4029,6.40300,6.000
6,101.800,0.22,6.2695,6.26960,6.000
6,101.933,0.08,6.1363,6.13637,6.000
6,102.067,0.02,6.0029,6.00300,6.000
6,102.200,0.00,5.8694,5.86950,6.000
6,102.333,0.00,5.7361,5.73623,6.000
6,102.467,0.00,5.6029,5.60297,6.000
6,102.600,0.00,5.4694,5.46950,6.000
6,102.733,0.01,5.3363,5.33637,6.000
6,102.867,0.01,5.2029,5.20300,6.000
6,103.000,0.01,5.0693,5.06940,6.000
6,103.133,0.01,4.9362,4.93627,6.000
6,103.267,0.00,4.8028,4.80293,6.000
6,103.400,0.00,4.6694,4.66950,6.000
6,103.533,0.00,4.5361,4.53623,6.000
6,103.667,0.01,4.4028,4.40290,6.000
6,103.800,0.00,4.2693,4.26940,6.000
6,103.933,0.00,4.1361,4.13623,6.000
6,104.067,0.01,4.0028,4.00287,6.000
6,104.200,0.00,3.8693,3.86940,6.000
6,104.333,0.01,3.7361,3.73620,6.000
6,104.467,0.01,3.6028,3.60293,6.000
6,104.600,0.00,3.4693,3.46940,6.000
6,104.733,0.01,3.3360,3.33610,6.000
6,104.867,0.00,3.2027,3.20280,6.000
6,105.000,0.00,3.0693,3.06940,6.000
6,105.133,0.01,2.9359,2.93603,6.000
6,105.267,0.01,2.8027,2.80280,6.000
6,105.400,0.00,2.6692,2.66930,6.000
6,105.533,0.01,2.5359,2.53603,6.000
6,105.667,0.01,2.4027,2.40283,6.000
6,105.800,0.01,2.2692,2.26930,6.000
6,105.933,0.01,2.1359,2.13603,6.000
6,106.067,0.01,2.0026,2.00273,6.000
6,106.200,0.01,1.8692,1.86930,6.000
6,106.333,0.01,1.7359,1.73597,6.000
6,106.467,0.01,1.6026,1.60270,6.000
6,106.600,0.00,1.4692,1.46930,6.000
6,106.733,0.01,1.3357,1.33583,6.000
6,106.867,0.01,1.2027,1.20280,6.000
6,107.000,0.00,1.0693,1.06940,6.000
6,107.133,0.01,0.9359,0.93597,6.000
6,107.267,0.01,0.8027,0.80277,6.000
6,107.400,0.01,0.6691,0.66920,6.000
6,107.533,0.01,0.5358,0.53590,6.000
6,107.667,0.00,0.4025,0.40263,6.000
6,107.800,0.00,0.2691,0.26920,6.000
6,107.933,0.00,0.1357,0.13583,6.000
6,108.067,0.01,0.0025,0.00260,6.000
6,108.267,0.01,-0.0004,-0.00030,6.000
6,108.400,0.00,-0.0004,-0.00030,6.000
6,108.533,0.01,-0.0004,-0.00030,6.000
6,108.667,0.01,-0.0004,-0.00030,6.000
6,108.800,0.00,-0.0004,-0.00030,6.000
6,108.933,0.00,-0.0004,-0.00030,6.000
6,109.067,0.01,-0.0003,-0.00020,6.000
6,109.200,0.01,-0.0003,-0.00020,6.000
6,109.333,0.00,-0.0003,-0.00020,6.000
6,109.467,0.01,-0.0003,-0.00020,6.000
6,109.600,0.01,-0.0003,-0.00020,6.000
6,109.733,0.00,-0.0003,-0.00020,6.000
6,109.867,0.00,-0.0003,-0.00020,6.000
6,110.000,0.00,-0.0003,-0.00020,6.000
6,110.133,0.00,-0.0003,-0.00020,6.000
6,110.267,0.00,-0.0003,-0.00020,6.000
6,110.400,0.01,-0.0003,-0.00020,6.000
6,110.533,0.00,-0.0003,-0.00020,6.000
6,110.667,0.00,-0.0003,-0.00020,6.000
6,110.800,0.00,-0.0002,-0.00010,6.000
6,110.933,0.00,-0.0002,-0.00010,6.000
6,111.067,0.01,-0.0002,-0.00010,6.000
6,111.267,0.00,-0.0002,-0.00010,6.000
6,111.400,0.00,-0.0002,-0.00010,6.000
6,111.533,0.01,-0.0002,-0.00010,6.000
6,111.667,0.00,-0.0002,-0.00010,6.000
6,111.800,0.01,-0.0002,-0.00010,6.000
6,111.933,0.01,-0.0002,-0.00010,6.000
6,112.067,0.00,-0.0002,-0.00010,6.000
7,112.400,0.00,0.0675,0.06760,7.000
7,112.533,0.00,0.2009,0.20103,7.000
7,112.667,0.00,0.3343,0.33437,7.000
7,112.800,0.00,0.4677,0.46780,7.000
7,112.933,0.00,0.6010,0.60110,7.000
7,113.067,0.00,0.7343,0.73443,7.000
7,113.200,0.00,0.8677,0.86780,7.000
7,113.333,0.00,1.0011,1.00123,7.000
7,113.467,0.00,1.1345,1.13460,7.000
7,113.600,0.00,1.2677,1.26780,7.000
7,113.733,0.00,1.4010,1.40110,7.000
7,113.867,0.00,1.5343,1.53437,7.000
7,114.000,-0.01,1.6676,1.66770,7.000
7,114.133,0.00,1.8011,1.80123,7.000
7,114.267,0.00,1.9343,1.93443,7.000
7,114.400,0.00,2.0677,2.06780,7.000
7,114.533,0.00,2.2011,2.20123,7.000
7,114.667,0.00,2.3344,2.33453,7.000
7,114.800,0.00,2.4677,2.46780,7.000
7,114.933,0.00,2.6011,2.60120,7.000
7,115.067,0.00,2.7344,2.73450,7.000
7,115.200,0.00,2.8678,2.86790,7.000
7,115.333,0.00,3.0012,3.00133,7.000
7,115.467,0.00,3.1344,3.13447,7.000
7,115.600,-0.01,3.2678,3.26790,7.000
7,115.733,0.00,3.4012,3.40127,7.000
7,115.867,0.00,3.5343,3.53443,7.000
7,116.000,0.00,3.6677,3.66780,7.000
7,116.133,0.00,3.8012,3.80127,7.000
7,116.267,0.00,3.9345,3.93463,7.000
7,116.400,0.00,4.0677,4.06780,7.000
7,116.533,0.00,4.2012,4.20127,7.000
7,116.667,0.00,4.3344,4.33453,7.000
7,116.800,0.00,4.4678,4.46790,7.000
7,116.933,0.00,4.6012,4.60133,7.000
7,117.067,0.00,4.7345,4.73463,7.000
7,117.200,-0.01,4.8678,4.86790,7.000
7,117.333,0.00,5.0012,5.00133,7.000
7,117.467,0.00,5.1346,5.13467,7.000
7,117.600,-0.01,5.2678,5.26790,7.000
7,117.733,-0.01,5.4013,5.40137,7.000
7,117.867,-0.01,5.5345,5.53460,7.000
7,118.000,0.00,5.6678,5.66790,7.000
7,118.133,0.00,5.8012,5.80127,7.000
7,118.267,0.01,5.9346,5.93467,7.000
7,118.400,0.07,6.0677,6.06780,7.000
7,118.533,0.21,6.2013,6.20140,7.000
7,118.667,0.49,6.3346,6.33470,7.000
7,118.800,0.89,6.4678,6.46790,7.000
7,118.933,1.42,6.6012,6.60133,7.000
7,119.067,2.09,6.7347,6.73480,7.000
7,119.200,2.89,6.8680,6.86810,7.000
7,119.333,3.84,7.0011,7.00120,7.000
7,119.467,4.95,7.1345,7.13460,7.000
7,119.667,4.59,7.1018,7.10190,7.000
7,119.800,3.32,6.9687,6.96880,7.000
7,119.933,2.36,6.8353,6.83543,7.000
7,120.067,1.60,6.7020,6.70213,7.000
7,120.200,1.01,6.5687,6.56880,7.000
7,120.333,0.57,6.4352,6.43533,7.000
7,120.467,0.27,6.3018,6.30193,7.000
7,120.600,0.09,6.1687,6.16880,7.000
7,120.733,0.02,6.0351,6.03520,7.000
7,120.867,-0.01,5.9019,5.90203,7.000
7,121.000,0.00,5.7685,5.76860,7.000
7,121.133,0.00,5.6351,5.63517,7.000
7,121.267,0.00,5.5018,5.50187,7.000
7,121.400,0.00,5.3687,5.36880,7.000
7,121.533,0.00,5.2351,5.23523,7.000
7,121.667,0.00,5.1017,5.10183,7.000
7,121.800,0.00,4.9686,4.96870,7.000
7,121.933,0.00,4.8351,4.83520,7.000
7,122.067,0.00,4.7018,4.70190,7.000
7,122.200,0.00,4.5686,4.56870,7.000
7,122.333,-0.01,4.4351,4.43517,7.000
7,122.467,0.00,4.3017,4.30180,7.000
7,122.600,-0.01,4.1685,4.16860,7.000
7,122.733,0.00,4.0351,4.03520,7.000
7,122.867,0.00,3.9018,3.90187,7.000
7,123.000,0.00,3.7685,3.76860,7.000
7,123.133,0.00,3.6351,3.63520,7.000
7,123.267,-0.01,3.5016,3.50173,7.000
7,123.400,0.00,3.3684,3.36850,7.000
7,123.533,0.00,3.2351,3.23517,7.000
7,123.667,-0.01,3.1015,3.10160,7.000
7,123.800,0.00,2.9684,2.96850,7.000
7,123.933,0.00,2.8350,2.83513,7.000
7,124.067,0.00,2.7016,2.70170,7.000
7,124.200,0.00,2.5684,2.56850,7.000
7,124.333,0.00,2.4350,2.43510,7.000
7,124.467,0.00,2.3015,2.30160,7.000
7,124.600,0.00,2.1683,2.16840,7.000
7,124.733,0.00,2.0350,2.03507,7.000
7,124.867,-0.01,1.9015,1.90157,7.000
7,125.000,0.00,1.7684,1.76850,7.000
7,125.133,0.00,1.6349,1.63503,7.000
7,125.267,0.00,1.5015,1.50160,7.000
7,125.400,0.00,1.3682,1.36830,7.000
7,125.533,0.00,1.2349,1.23497,7.000
7,125.667,0.00,1.1016,1.10170,7.000
7,125.800,0.00,0.9683,0.96840,7.000
7,125.933,0.00,0.8350,0.83510,7.000
7,126.067,0.00,0.7015,0.70160,7.000
7,126.200,0.00,0.5681,0.56820,7.000
7,126.333,0.00,0.4350,0.43510,7.000
7,126.467,0.00,0.3014,0.30147,7.000
7,126.600,-0.01,0.1683,0.16840,7.000
7,126.733,0.00,0.0348,0.03493,7.000
7,126.867,-0.01,-0.0434,-0.04327,7.000
7,127.000,0.00,-0.0003,-0.00020,7.000
7,127.133,0.00,-0.0003,-0.00020,7.000
7,127.267,0.00,-0.0003,-0.00020,7.000
7,127.400,-0.01,-0.0003,-0.00020,7.000
7,127.533,0.00,-0.0003,-0.00020,7.000
7,127.667,0.00,-0.0003,-0.00020,7.000
7,127.800,0.00,-0.0003,-0.00020,7.000
7,127.933,0.00,-0.0003,-0.00020,7.000
7,128.067,-0.01,-0.0003,-0.00020,7.000
7,128.200,0.00,-0.0003,-0.00020,7.000
7,128.333,0.00,-0.0003,-0.00020,7.000
7,128.467,0.00,-0.0003,-0.00020,7.000
7,128.600,0.00,-0.0003,-0.00020,7.000
7,128.733,0.00,-0.0003,-0.00020,7.000
7,128.867,-0.01,-0.0003,-0.00020,7.000
7,129.000,0.00,-0.0003,-0.00020,7.000
7,129.133,-0.01,-0.0003,-0.00017,7.000
7,129.267,0.00,-0.0002,-0.00010,7.000
7,129.400,-0.01,-0.0002,-0.00010,7.000
7,129.533,0.00,-0.0002,-0.00010,7.000
7,129.667,0.00,-0.0002,-0.00010,7.000
7,129.800,0.00,-0.0002,-0.00010,7.000
7,130.000,-0.01,-0.0002,-0.00010,7.000
7,130.133,0.00,-0.0002,-0.00010,7.000
7,130.267,0.00,-0.0002,-0.00010,7.000
7,130.400,0.00,-0.0002,-0.00010,7.000
7,130.533,0.00,-0.0002,-0.00010,7.000
7,130.667,0.00,-0.0002,-0.00010,7.000
7,130.800,0.00,-0.0002,-0.00010,7.000
8,131.133,0.00,0.0808,0.08093,8.000
8,131.267,0.00,0.2141,0.21423,8.000
8,131.400,0.00,0.3476,0.34770,8.000
8,131.533,0.00,0.4810,0.48113,8.000
8,131.667,0.00,0.6142,0.61430,8.000
8,131.800,-0.01,0.7476,0.74770,8.000
8,131.933,0.00,0.8811,0.88117,8.000
8,132.067,0.00,1.0144,1.01447,8.000
8,132.200,0.00,1.1478,1.14790,8.000
8,132.333,0.00,1.2809,1.28103,8.000
8,132.467,0.00,1.4143,1.41440,8.000
8,132.600,-0.01,1.5476,1.54770,8.000
8,132.733,0.00,1.6811,1.68117,8.000
8,132.867,0.00,1.8143,1.81443,8.000
8,133.000,0.00,1.9475,1.94760,8.000
8,133.133,0.00,2.0811,2.08120,8.000
8,133.267,0.00,2.2144,2.21447,8.000
8,133.400,-0.01,2.3477,2.34780,8.000
8,133.533,0.00,2.4811,2.48117,8.000
8,133.667,0.00,2.6144,2.61453,8.000
8,133.800,0.00,2.7476,2.74770,8.000
8,133.933,0.00,2.8812,2.88127,8.000
8,134.067,0.00,3.0145,3.01460,8.000
8,134.200,0.00,3.1476,3.14770,8.000
8,134.333,0.00,3.2812,3.28127,8.000
8,134.467,0.00,3.4144,3.41450,8.000
8,134.600,0.00,3.5476,3.54770,8.000
8,134.733,0.00,3.6812,3.68130,8.000
8,134.867,0.00,3.8144,3.81453,8.000
8,135.000,0.00,3.9477,3.94780,8.000
8,135.133,0.00,4.0811,4.08123,8.000
8,135.267,0.00,4.2145,4.21460,8.000
8,135.400,0.00,4.3477,4.34780,8.000
8,135.533,0.00,4.4812,4.48127,8.000
8,135.667,0.00,4.6146,4.61467,8.000
8,135.800,0.00,4.7477,4.74780,8.000
8,135.933,0.00,4.8812,4.88127,8.000
8,136.067,0.00,5.0145,5.01463,8.000
8,136.200,0.00,5.1477,5.14780,8.000
8,136.333,0.00,5.2812,5.28133,8.000
8,136.467,0.00,5.4147,5.41477,8.000
8,136.600,0.00,5.5477,5.54780,8.000
8,136.733,0.00,5.6812,5.68130,8.000
8,136.867,0.00,5.8145,5.81463,8.000
8,137.000,0.02,5.9478,5.94790,8.000
8,137.133,0.08,6.0812,6.08127,8.000
8,137.267,0.23,6.2147,6.21480,8.000
8,137.400,0.52,6.3477,6.34780,8.000
8,137.533,0.94,6.4812,6.48133,8.000
8,137.667,1.49,6.6147,6.61477,8.000
8,137.800,2.17,6.7480,6.74810,8.000
8,137.933,2.98,6.8813,6.88143,8.000
8,138.067,3.95,7.0146,7.01470,8.000
8,138.200,5.08,7.1479,7.14800,8.000
8,138.400,4.27,7.0685,7.06860,8.000
8,138.533,3.08,6.9354,6.93553,8.000
8,138.667,2.16,6.8020,6.80210,8.000
8,138.800,1.45,6.6687,6.66880,8.000
8,138.933,0.89,6.5353,6.53540,8.000
8,139.067,0.49,6.4018,6.40193,8.000
8,139.200,0.22,6.2686,6.26870,8.000
8,139.333,0.07,6.1354,6.13547,8.000
8,139.467,0.01,6.0018,6.00190,8.000
8,139.600,0.00,5.8685,5.86860,8.000
8,139.733,0.00,5.7352,5.73530,8.000
8,139.867,0.00,5.6018,5.60190,8.000
8,140.000,0.00,5.4684,5.46850,8.000
8,140.133,0.00,5.3353,5.33537,8.000
8,140.267,0.00,5.2019,5.20197,8.000
8,140.400,0.00,5.0684,5.06850,8.000
8,140.533,0.00,4.9352,4.93530,8.000
8,140.667,-0.01,4.8018,4.80190,8.000
8,140.800,0.00,4.6684,4.66850,8.000
8,140.933,-0.01,4.5352,4.53527,8.000
8,141.067,0.00,4.4017,4.40183,8.000
8,141.200,0.00,4.2682,4.26830,8.000
8,141.333,0.00,4.1351,4.13520,8.000
8,141.467,0.00,4.0018,4.00187,8.000
8,141.600,0.00,3.8683,3.86840,8.000
8,141.733,0.00,3.7352,3.73527,8.000
8,141.867,0.00,3.6018,3.60190,8.000
8,142.000,0.00,3.4682,3.46830,8.000
8,142.133,0.00,3.3350,3.33513,8.000
8,142.267,0.00,3.2016,3.20170,8.000
8,142.400,0.00,3.0682,3.06830,8.000
8,142.533,0.00,2.9350,2.93510,8.000
8,142.667,0.00,2.8017,2.80180,8.000
8,142.800,0.00,2.6682,2.66830,8.000
8,142.933,0.00,2.5350,2.53513,8.000
8,143.067,0.00,2.4017,2.40180,8.000
8,143.200,0.00,2.2682,2.26830,8.000
8,143.333,0.00,2.1350,2.13507,8.000
8,143.467,0.00,2.0016,2.00173,8.000
8,143.600,0.00,1.8681,1.86820,8.000
8,143.733,0.00,1.7349,1.73503,8.000
8,143.867,0.00,1.6016,1.60173,8.000
8,144.000,0.00,1.4682,1.46830,8.000
8,144.133,0.00,1.3348,1.33487,8.000
8,144.267,0.00,1.2016,1.20173,8.000
8,144.400,0.00,1.0682,1.06830,8.000
8,144.533,0.00,0.9349,0.93500,8.000
8,144.667,0.00,0.8016,0.80173,8.000
8,144.800,0.00,0.6681,0.66820,8.000
8,144.933,0.00,0.5349,0.53497,8.000
8,145.067,0.00,0.4016,0.40173,8.000
8,145.200,0.00,0.2682,0.26830,8.000
8,145.333,0.00,0.1348,0.13493,8.000
8,145.467,0.00,0.0015,0.00163,8.000
8,145.667,0.00,-0.0003,-0.00020,8.000
8,145.800,0.00,-0.0003,-0.00020,8.000
8,145.933,0.00,-0.0003,-0.00020,8.000
8,146.067,0.00,-0.0003,-0.00020,8.000
8,146.200,0.00,-0.0003,-0.00020,8.000
8,146.333,0.00,-0.0003,-0.00020,8.000
8,146.467,0.00,-0.0003,-0.00020,8.000
8,146.600,0.00,-0.0003,-0.00020,8.000
8,146.733,0.00,-0.0003,-0.00020,8.000
8,146.867,0.00,-0.0003,-0.00020,8.000
8,147.000,0.00,-0.0003,-0.00020,8.000
8,147.133,0.00,-0.0003,-0.00020,8.000
8,147.267,0.00,-0.0003,-0.00020,8.000
8,147.400,0.00,-0.0003,-0.00020,8.000
8,147.533,0.00,-0.0003,-0.00020,8.000
8,147.667,0.00,-0.0003,-0.00020,8.000
8,147.800,0.00,-0.0003,-0.00020,8.000
8,147.933,0.00,-0.0003,-0.00020,8.000
8,148.067,0.00,-0.0002,-0.00010,8.000
8,148.200,0.00,-0.0002,-0.00010,8.000
8,148.333,0.00,-0.0002,-0.00010,8.000
8,148.467,0.00,-0.0002,-0.00010,8.000
8,148.667,0.00,-0.0002,-0.00010,8.000
8,148.800,0.00,-0.0002,-0.00010,8.000
8,148.933,0.00,-0.0002,-0.00010,8.000
8,149.067,0.00,-0.0002,-0.00010,8.000
8,149.200,0.00,-0.0002,-0.00010,8.000
8,149.333,0.00,-0.0002,-0.00010,8.000
8,149.467,0.00,-0.0002,-0.00010,8.000
9,149.800,-0.01,0.0485,0.04860,9.000
9,149.933,0.00,0.1818,0.18193,9.000
9,150.067,0.00,0.3152,0.31533,9.000
9,150.200,0.00,0.4487,0.44880,9.000
9,150.333,0.00,0.5819,0.58200,9.000
9,150.467,0.00,0.7153,0.71543,9.000
9,150.600,0.00,0.8487,0.84880,9.000
9,150.733,0.00,0.9820,0.98207,9.000
9,150.867,0.00,1.1155,1.11557,9.000
9,151.000,0.00,1.2487,1.24880,9.000
9,151.133,0.00,1.3819,1.38200,9.000
9,151.267,0.00,1.5153,1.51537,9.000
9,151.400,0.00,1.6487,1.64880,9.000
9,151.533,0.00,1.7821,1.78217,9.000
9,151.667,0.00,1.9153,1.91543,9.000
9,151.800,0.00,2.0488,2.04890,9.000
9,151.933,0.00,2.1820,2.18213,9.000
9,152.067,0.00,2.3153,2.31543,9.000
9,152.200,0.00,2.4489,2.44900,9.000
9,152.333,0.00,2.5821,2.58217,9.000
9,152.467,0.00,2.7154,2.71553,9.000
9,152.600,0.00,2.8488,2.84890,9.000
9,152.733,0.00,2.9821,2.98220,9.000
9,152.867,0.00,3.1153,3.11543,9.000
9,153.000,0.00,3.2488,3.24890,9.000
9,153.133,-0.01,3.3820,3.38210,9.000
9,153.267,0.00,3.5154,3.51547,9.000
9,153.400,0.00,3.6488,3.64890,9.000
9,153.533,0.00,3.7821,3.78220,9.000
9,153.667,0.00,3.9154,3.91553,9.000
9,153.800,0.00,4.0488,4.04890,9.000
9,153.933,0.00,4.1822,4.18227,9.000
9,154.067,0.00,4.3153,4.31543,9.000
9,154.200,0.00,4.4489,4.44900,9.000
9,154.333,0.00,4.5821,4.58223,9.000
9,154.467,0.00,4.7155,4.71560,9.000
9,154.600,-0.01,4.8489,4.84900,9.000
9,154.733,0.00,4.9822,4.98230,9.000
9,154.867,0.00,5.1154,5.11553,9.000
9,155.000,0.00,5.2490,5.24910,9.000
9,155.133,0.00,5.3823,5.38240,9.000
9,155.267,0.00,5.5155,5.51557,9.000
9,155.400,0.00,5.6489,5.64900,9.000
9,155.533,0.00,5.7821,5.78223,9.000
9,155.667,0.01,5.9155,5.91560,9.000
9,155.800,0.06,6.0489,6.04900,9.000
9,155.933,0.18,6.1824,6.18247,9.000
9,156.067,0.44,6.3155,6.31557,9.000
9,156.200,0.82,6.4489,6.44900,9.000
9,156.333,1.34,6.5823,6.58237,9.000
9,156.467,1.99,6.7156,6.71567,9.000
9,156.600,2.77,6.8491,6.84920,9.000
9,156.733,3.70,6.9823,6.98243,9.000
9,156.867,4.79,7.1155,7.11557,9.000
9,157.067,4.65,7.1048,7.10490,9.000
9,157.200,3.36,6.9716,6.97170,9.000
9,157.333,2.39,6.8384,6.83850,9.000
9,157.467,1.62,6.7050,6.70507,9.000
9,157.600,1.03,6.5718,6.57190,9.000
9,157.733,0.58,6.4382,6.43827,9.000
9,157.867,0.28,6.3049,6.30497,9.000
9,158.000,0.09,6.1717,6.17180,9.000
9,158.133,0.02,6.0381,6.03820,9.000
9,158.267,0.00,5.9049,5.90497,9.000
9,158.400,0.00,5.7715,5.77160,9.000
9,158.533,0.00,5.6382,5.63827,9.000
9,158.667,0.00,5.5048,5.50487,9.000
9,158.800,0.00,5.3716,5.37170,9.000
9,158.933,0.00,5.2382,5.23830,9.000
9,159.067,0.00,5.1048,5.10490,9.000
9,159.200,0.00,4.9716,4.97170,9.000
9,159.333,0.00,4.8380,4.83813,9.000
9,159.467,0.00,4.7048,4.70487,9.000
9,159.600,0.00,4.5716,4.57170,9.000
9,159.733,0.00,4.4380,4.43813,9.000
9,159.867,0.00,4.3047,4.30480,9.000
9,160.000,0.00,4.1715,4.17160,9.000
9,160.133,0.00,4.0381,4.03817,9.000
9,160.267,0.00,3.9047,3.90480,9.000
9,160.400,0.00,3.7715,3.77160,9.000
9,160.533,0.00,3.6381,3.63817,9.000
9,160.667,0.00,3.5046,3.50473,9.000
9,160.800,0.00,3.3713,3.37140,9.000
9,160.933,0.00,3.2380,3.23810,9.000
9,161.067,0.00,3.1045,3.10460,9.000
9,161.200,0.00,2.9714,2.97150,9.000
9,161.333,0.00,2.8380,2.83810,9.000
9,161.467,0.00,2.7047,2.70477,9.000
9,161.600,-0.01,2.5713,2.57140,9.000
9,161.733,0.00,2.4380,2.43807,9.000
9,161.867,0.00,2.3046,2.30470,9.000
9,162.000,0.00,2.1713,2.17140,9.000
9,162.133,0.00,2.0379,2.03803,9.000
9,162.267,0.00,1.9045,1.90460,9.000
9,162.400,0.00,1.7713,1.77140,9.000
9,162.533,0.00,1.6380,1.63807,9.000
9,162.667,0.00,1.5045,1.50457,9.000
9,162.800,0.00,1.3712,1.37130,9.000
9,162.933,0.00,1.2379,1.23797,9.000
9,163.067,0.00,1.1046,1.10470,9.000
9,163.200,-0.01,0.9713,0.97140,9.000
9,163.333,-0.01,0.8379,0.83803,9.000
9,163.467,0.00,0.7045,0.70460,9.000
9,163.600,0.00,0.5712,0.57130,9.000
9,163.733,0.00,0.4380,0.43810,9.000
9,163.867,0.00,0.3044,0.30453,9.000
9,164.000,0.00,0.1713,0.17140,9.000
9,164.133,0.00,0.0378,0.03793,9.000
9,164.400,0.00,-0.0004,-0.00030,9.000
9,164.533,-0.01,-0.0003,-0.00020,9.000
9,164.667,0.00,-0.0003,-0.00020,9.000
9,164.800,0.00,-0.0003,-0.00020,9.000
9,164.933,0.00,-0.0003,-0.00020,9.000
9,165.067,0.00,-0.0003,-0.00020,9.000
9,165.200,0.00,-0.0003,-0.00020,9.000
9,165.333,0.00,-0.0003,-0.00020,9.000
9,165.467,0.00,-0.0003,-0.00020,9.000
9,165.600,0.00,-0.0003,-0.00020,9.000
9,165.733,-0.01,-0.0003,-0.00020,9.000
9,165.867,0.00,-0.0003,-0.00020,9.000
9,166.000,0.00,-0.0003,-0.00020,9.000
9,166.133,0.00,-0.0003,-0.00020,9.000
9,166.267,0.00,-0.0003,-0.00020,9.000
9,166.400,0.00,-0.0003,-0.00020,9.000
9,166.533,0.00,-0.0003,-0.00020,9.000
9,166.667,0.00,-0.0003,-0.00020,9.000
9,166.800,0.00,-0.0003,-0.00020,9.000
9,166.933,-0.01,-0.0002,-0.00010,9.000
9,167.067,0.00,-0.0002,-0.00010,9.000
9,167.200,-0.01,-0.0002,-0.00010,9.000
9,167.467,-0.01,-0.0002,-0.00010,9.000
9,167.600,0.00,-0.0002,-0.00010,9.000
9,167.733,0.00,-0.0002,-0.00010,9.000
9,167.867,0.00,-0.0002,-0.00010,9.000
9,168.000,0.00,-0.0002,-0.00010,9.000
9,168.133,0.00,-0.0002,-0.00010,9.000
9,168.267,-0.01,-0.0002,-0.00010,9.000
10,168.600,0.00,0.1586,0.15870,10.000
10,168.733,0.00,0.2919,0.29203,10.000
10,168.867,0.00,0.4252,0.42533,10.000
10,169.000,0.01,0.5587,0.55880,10.000
10,169.133,0.00,0.6920,0.69207,10.000
10,169.267,0.00,0.8253,0.82537,10.000
10,169.400,0.00,0.9588,0.95890,10.000
10,169.533,0.01,1.0922,1.09233,10.000
10,169.667,0.00,1.2254,1.22547,10.000
10,169.800,0.00,1.3586,1.35870,10.000
10,169.933,0.00,1.4920,1.49210,10.000
10,170.067,0.00,1.6253,1.62543,10.000
10,170.200,0.00,1.7588,1.75890,10.000
10,170.333,0.01,1.8921,1.89217,10.000
10,170.467,0.00,2.0253,2.02543,10.000
10,170.600,0.00,2.1587,2.15880,10.000
10,170.733,0.00,2.2921,2.29220,10.000
10,170.867,0.00,2.4254,2.42547,10.000
10,171.000,0.00,2.5588,2.55890,10.000
10,171.133,0.00,2.6922,2.69227,10.000
10,171.267,0.00,2.8254,2.82553,10.000
10,171.400,0.01,2.9588,2.95890,10.000
10,171.533,0.01,3.0921,3.09217,10.000
10,171.667,0.00,3.2254,3.22547,10.000
10,171.800,0.00,3.3588,3.35890,10.000
10,171.933,0.01,3.4921,3.49220,10.000
10,172.067,0.00,3.6254,3.62550,10.000
10,172.200,0.00,3.7588,3.75890,10.000
10,172.333,0.00,3.8922,3.89230,10.000
10,172.467,0.00,4.0253,4.02543,10.000
10,172.600,0.00,4.1588,4.15890,10.000
10,172.733,0.00,4.2921,4.29223,10.000
10,172.867,0.00,4.4254,4.42550,10.000
10,173.000,0.00,4.5589,4.55900,10.000
10,173.133,0.00,4.6922,4.69233,10.000
10,173.267,0.01,4.8255,4.82560,10.000
10,173.400,0.00,4.9589,4.95900,10.000
10,173.533,0.00,5.0922,5.09230,10.000
10,173.667,0.00,5.2255,5.22563,10.000
10,173.800,0.00,5.3590,5.35910,10.000
10,173.933,0.00,5.4922,5.49230,10.000
10,174.067,0.00,5.6256,5.62567,10.000
10,174.200,0.00,5.7588,5.75890,10.000
10,174.333,0.01,5.8922,5.89233,10.000
10,174.467,0.05,6.0256,6.02567,10.000
10,174.600,0.16,6.1589,6.15900,10.000
10,174.733,0.39,6.2923,6.29237,10.000
10,174.867,0.75,6.4255,6.42560,10.000
10,175.000,1.25,6.5588,6.55890,10.000
10,175.133,1.87,6.6923,6.69243,10.000
10,175.267,2.63,6.8257,6.82583,10.000
10,175.400,3.53,6.9589,6.95900,10.000
10,175.533,4.59,7.0921,7.09220,10.000
10,175.667,5.44,7.1704,7.17050,10.000
10,175.800,4.00,7.0395,7.03960,10.000
10,175.933,2.87,6.9064,6.90650,10.000
10,176.067,2.00,6.7731,6.77320,10.000
10,176.200,1.32,6.6396,6.63970,10.000
10,176.333,0.80,6.5063,6.50637,10.000
10,176.467,0.42,6.3729,6.37303,10.000
10,176.600,0.18,6.2395,6.23960,10.000
10,176.733,0.05,6.1062,6.10633,10.000
10,176.867,0.01,5.9729,5.97300,10.000
10,177.000,0.00,5.8394,5.83950,10.000
10,177.133,0.00,5.7062,5.70627,10.000
10,177.267,0.00,5.5728,5.57293,10.000
10,177.400,0.00,5.4395,5.43960,10.000
10,177.533,0.00,5.3062,5.30633,10.000
10,177.667,0.00,5.1729,5.17297,10.000
10,177.800,0.00,5.0395,5.03960,10.000
10,177.933,0.00,4.9061,4.90620,10.000
10,178.067,0.00,4.7729,4.77297,10.000
10,178.200,0.00,4.6395,4.63960,10.000
10,178.333,0.00,4.5061,4.50620,10.000
10,178.467,0.00,4.3728,4.37293,10.000
10,178.600,0.01,4.2394,4.23950,10.000
10,178.733,0.00,4.1060,4.10610,10.000
10,178.867,0.00,3.9729,3.97297,10.000
10,179.000,0.00,3.8393,3.83940,10.000
10,179.133,0.00,3.7060,3.70613,10.000
10,179.267,0.00,3.5728,3.57287,10.000
10,179.400,0.00,3.4394,3.43950,10.000
10,179.533,0.00,3.3060,3.30610,10.000
10,179.667,0.01,3.1727,3.17277,10.000
10,179.800,0.01,3.0393,3.03940,10.000
10,179.933,0.00,2.9059,2.90597,10.000
10,180.067,0.00,2.7727,2.77283,10.000
10,180.200,0.00,2.6393,2.63940,10.000
10,180.333,0.00,2.5058,2.50593,10.000
10,180.467,0.00,2.3727,2.37277,10.000
10,180.600,0.00,2.2392,2.23930,10.000
10,180.733,0.00,2.1058,2.10593,10.000
10,180.867,0.00,1.9726,1.97267,10.000
10,181.000,0.00,1.8393,1.83940,10.000
10,181.133,0.00,1.7058,1.70593,10.000
10,181.267,0.00,1.5726,1.57270,10.000
10,181.400,0.01,1.4392,1.43930,10.000
10,181.533,0.00,1.3057,1.30580,10.000
10,181.667,0.00,1.1726,1.17273,10.000
10,181.800,0.00,1.0393,1.03940,10.000
10,181.933,0.00,0.9058,0.90593,10.000
10,182.067,0.00,0.7726,0.77273,10.000
10,182.200,0.00,0.6392,0.63930,10.000
10,182.333,0.00,0.5058,0.50593,10.000
10,182.467,0.00,0.3725,0.37263,10.000
10,182.600,0.00,0.2392,0.23930,10.000
10,182.733,0.00,0.1058,0.10587,10.000
10,182.933,0.01,-0.0293,-0.02917,10.000
10,183.067,0.00,-0.0003,-0.00020,10.000
10,183.200,0.00,-0.0003,-0.00020,10.000
10,183.333,0.00,-0.0003,-0.00020,10.000
10,183.467,0.00,-0.0003,-0.00020,10.000
10,183.600,0.00,-0.0003,-0.00020,10.000
10,183.733,0.00,-0.0003,-0.00020,10.000
10,183.867,0.00,-0.0003,-0.00020,10.000
10,184.000,0.00,-0.0003,-0.00020,10.000
10,184.133,0.00,-0.0003,-0.00020,10.000
10,184.267,0.00,-0.0003,-0.00020,10.000
10,184.400,0.00,-0.0003,-0.00020,10.000
10,184.533,0.00,-0.0003,-0.00020,10.000
10,184.667,0.00,-0.0003,-0.00020,10.000
10,184.800,0.00,-0.0003,-0.00020,10.000
10,184.933,0.00,-0.0003,-0.00020,10.000
10,185.067,0.00,-0.0003,-0.00020,10.000
10,185.200,0.00,-0.0003,-0.00020,10.000
10,185.333,0.00,-0.0003,-0.00020,10.000
10,185.467,0.00,-0.0002,-0.00010,10.000
10,185.600,0.00,-0.0002,-0.00010,10.000
10,185.733,0.00,-0.0002,-0.00010,10.000
10,185.867,0.00,-0.0002,-0.00010,10.000
10,186.067,0.00,-0.0002,-0.00010,10.000
10,186.200,0.00,-0.0002,-0.00010,10.000
10,186.333,0.00,-0.0002,-0.00010,10.000
10,186.467,0.00,-0.0002,-0.00010,10.000
10,186.600,0.01,-0.0002,-0.00010,10.000
10,186.733,0.00,-0.0002,-0.00010,10.000
10,186.867,0.00,-0.0002,-0.00010,10.000