File: AIME_journal_files/AIME_data/calibDATA_loadcell/date_02:15:2018/Instron_02.15.2018/1_5N_2__1mm.s_0_0.txt
""
"Test Method","Radhen_Load_Cntrl_Cmprsn_250N_12-7.msm"
"Sample I. D.","Sample1.mss"
"Specimen Number","5"

"TheCycle_Output ()","_Time (s)","_Load (N)","_Extension (mm)","RealTimeDepth (mm)","CycleNumber ()"

1,0.267,0.01,0.0643,0.06433,1.000
1,0.400,0.01,0.1976,0.19760,1.000
1,0.533,0.01,0.3312,0.33117,1.000
1,0.667,0.01,0.4646,0.46457,1.000
1,0.800,0.01,0.5977,0.59770,1.000
1,0.933,0.01,0.7312,0.73123,1.000
1,1.067,0.01,0.8645,0.86453,1.000
1,1.200,0.01,0.9978,0.99780,1.000
1,1.333,0.01,1.1313,1.13127,1.000
1,1.467,0.01,1.2646,1.26460,1.000
1,1.600,0.01,1.3977,1.39770,1.000
1,1.733,0.01,1.5311,1.53113,1.000
1,1.867,0.02,1.6646,1.66463,1.000
1,2.000,0.06,1.7978,1.79780,1.000
1,2.133,0.18,1.9312,1.93123,1.000
1,2.267,0.43,2.0646,2.06463,1.000
1,2.400,0.80,2.1977,2.19770,1.000
1,2.533,1.29,2.3312,2.33120,1.000
1,2.667,1.88,2.4647,2.46470,1.000
1,2.800,2.61,2.5980,2.59800,1.000
1,2.933,3.47,2.7313,2.73127,1.000
1,3.067,4.49,2.8646,2.86457,1.000
1,3.267,4.92,2.9119,2.91190,1.000
1,3.400,3.58,2.7786,2.77860,1.000
1,3.533,2.58,2.6454,2.64537,1.000
1,3.667,1.79,2.5120,2.51200,1.000
1,3.800,1.16,2.3788,2.37880,1.000
1,3.933,0.69,2.2452,2.24517,1.000
1,4.067,0.35,2.1120,2.11197,1.000
1,4.200,0.13,1.9786,1.97860,1.000
1,4.333,0.04,1.8452,1.84520,1.000
1,4.467,0.01,1.7120,1.71197,1.000
1,4.600,0.00,1.5786,1.57860,1.000
1,4.733,0.01,1.4451,1.44513,1.000
1,4.867,0.01,1.3118,1.31180,1.000
1,5.000,0.01,1.1786,1.17860,1.000
1,5.133,0.01,1.0451,1.04513,1.000
1,5.267,0.01,0.9118,0.91177,1.000
1,5.400,0.01,0.7786,0.77860,1.000
1,5.533,0.01,0.6451,0.64510,1.000
1,5.667,0.00,0.5118,0.51177,1.000
1,5.800,0.00,0.3785,0.37850,1.000
1,5.933,0.01,0.2451,0.24510,1.000
1,6.067,0.00,0.1116,0.11163,1.000
1,6.200,0.01,-0.0215,-0.02150,1.000
1,6.333,0.01,-0.0003,-0.00027,1.000
1,6.467,0.01,-0.0002,-0.00020,1.000
1,6.600,0.01,-0.0002,-0.00020,1.000
1,6.733,0.01,-0.0002,-0.00020,1.000
1,6.867,0.01,-0.0002,-0.00020,1.000
1,7.000,0.00,-0.0002,-0.00020,1.000
1,7.133,0.01,-0.0002,-0.00020,1.000
1,7.267,0.01,-0.0002,-0.00020,1.000
1,7.400,0.00,-0.0002,-0.00020,1.000
1,7.533,0.01,-0.0002,-0.00020,1.000
1,7.667,0.01,-0.0002,-0.00020,1.000
1,7.800,0.01,-0.0002,-0.00020,1.000
1,7.933,0.01,-0.0002,-0.00020,1.000
1,8.067,0.01,-0.0002,-0.00020,1.000
1,8.200,0.01,-0.0002,-0.00020,1.000
1,8.333,0.01,-0.0002,-0.00020,1.000
1,8.467,0.01,-0.0002,-0.00020,1.000
1,8.600,0.01,-0.0002,-0.00020,1.000
1,8.733,0.01,-0.0002,-0.00020,1.000
1,8.867,0.01,-0.0002,-0.00020,1.000
1,9.000,0.00,-0.0002,-0.00020,1.000
1,9.133,0.01,-0.0002,-0.00020,1.000
1,9.267,0.01,-0.0001,-0.00010,1.000
1,9.467,0.01,-0.0001,-0.00010,1.000
1,9.600,0.01,-0.0001,-0.00010,1.000
1,9.733,0.01,-0.0001,-0.00010,1.000
1,9.867,0.01,-0.0001,-0.00010,1.000
1,10.000,0.01,-0.0001,-0.00010,1.000
1,10.133,0.01,-0.0001,-0.00010,1.000
1,10.267,0.01,-0.0001,-0.00010,1.000
2,10.533,0.02,0.0999,0.10003,2.000
2,10.667,0.01,0.2333,0.23337,2.000
2,10.800,0.01,0.3667,0.36680,2.000
2,10.933,0.01,0.5002,0.50027,2.000
2,11.067,0.01,0.6334,0.63350,2.000
2,11.200,0.01,0.7668,0.76690,2.000
2,11.333,0.01,0.9001,0.90020,2.000
2,11.467,0.01,1.0335,1.03360,2.000
2,11.600,0.01,1.1668,1.16690,2.000
2,11.733,0.01,1.3001,1.30020,2.000
2,11.867,0.01,1.4334,1.43347,2.000
2,12.000,0.01,1.5666,1.56670,2.000
2,12.133,0.03,1.7002,1.70033,2.000
2,12.267,0.08,1.8335,1.83363,2.000
2,12.400,0.22,1.9669,1.96700,2.000
2,12.533,0.50,2.1002,2.10027,2.000
2,12.667,0.91,2.2335,2.23363,2.000
2,12.800,1.42,2.3668,2.36690,2.000
2,12.933,2.05,2.5003,2.50043,2.000
2,13.067,2.81,2.6337,2.63377,2.000
2,13.200,3.72,2.7667,2.76680,2.000
2,13.333,4.78,2.9001,2.90020,2.000
2,13.533,4.49,2.8740,2.87413,2.000
2,13.667,3.27,2.7410,2.74113,2.000
2,13.800,2.34,2.6076,2.60770,2.000
2,13.933,1.59,2.4743,2.47443,2.000
2,14.067,1.01,2.3410,2.34110,2.000
2,14.200,0.58,2.2074,2.20750,2.000
2,14.333,0.27,2.0742,2.07433,2.000
2,14.467,0.10,1.9409,1.94103,2.000
2,14.600,0.03,1.8074,1.80750,2.000
2,14.733,0.01,1.6742,1.67427,2.000
2,14.867,0.01,1.5408,1.54087,2.000
2,15.000,0.01,1.4073,1.40740,2.000
2,15.133,0.01,1.2741,1.27420,2.000
2,15.267,0.01,1.1409,1.14103,2.000
2,15.400,0.01,1.0074,1.00750,2.000
2,15.533,0.01,0.8740,0.87410,2.000
2,15.667,0.01,0.7408,0.74093,2.000
2,15.800,0.01,0.6074,0.60750,2.000
2,15.933,0.01,0.4741,0.47417,2.000
2,16.067,0.01,0.3408,0.34093,2.000
2,16.200,0.01,0.2074,0.20750,2.000
2,16.333,0.01,0.0739,0.07400,2.000
2,16.533,0.01,-0.0190,-0.01887,2.000
2,16.667,0.01,-0.0003,-0.00020,2.000
2,16.800,0.01,-0.0003,-0.00020,2.000
2,16.933,0.01,-0.0003,-0.00020,2.000
2,17.067,0.01,-0.0003,-0.00020,2.000
2,17.200,0.02,-0.0003,-0.00020,2.000
2,17.333,0.01,-0.0003,-0.00020,2.000
2,17.467,0.01,-0.0003,-0.00020,2.000
2,17.600,0.01,-0.0002,-0.00010,2.000
2,17.733,0.01,-0.0002,-0.00010,2.000
2,17.867,0.01,-0.0002,-0.00010,2.000
2,18.000,0.01,-0.0002,-0.00010,2.000
2,18.133,0.01,-0.0002,-0.00010,2.000
2,18.267,0.01,-0.0002,-0.00010,2.000
2,18.400,0.01,-0.0002,-0.00010,2.000
2,18.533,0.01,-0.0002,-0.00010,2.000
2,18.667,0.01,-0.0002,-0.00010,2.000
2,18.800,0.01,-0.0002,-0.00010,2.000
2,18.933,0.01,-0.0002,-0.00010,2.000
2,19.067,0.01,-0.0002,-0.00010,2.000
2,19.200,0.01,-0.0002,-0.00010,2.000
2,19.333,0.01,-0.0002,-0.00010,2.000
2,19.467,0.01,-0.0002,-0.00010,2.000
2,19.667,0.01,-0.0002,-0.00010,2.000
2,19.800,0.01,-0.0002,-0.00010,2.000
2,19.933,0.01,-0.0002,-0.00010,2.000
2,20.067,0.01,-0.0002,-0.00010,2.000
2,20.200,0.01,-0.0002,-0.00010,2.000
2,20.333,0.01,-0.0001,0.00000,2.000
2,20.467,0.01,-0.0001,0.00000,2.000
3,20.800,0.01,0.1376,0.13760,3.000
3,20.933,0.01,0.2711,0.27113,3.000
3,21.067,0.01,0.4043,0.40433,3.000
3,21.200,0.01,0.5378,0.53780,3.000
3,21.333,0.01,0.6711,0.67107,3.000
3,21.467,0.01,0.8044,0.80443,3.000
3,21.600,0.01,0.9378,0.93780,3.000
3,21.733,0.01,1.0712,1.07117,3.000
3,21.867,0.01,1.2045,1.20450,3.000
3,22.000,0.01,1.3377,1.33770,3.000
3,22.133,0.01,1.4711,1.47113,3.000
3,22.267,0.01,1.6043,1.60433,3.000
3,22.400,0.03,1.7379,1.73790,3.000
3,22.533,0.10,1.8711,1.87113,3.000
3,22.667,0.28,2.0045,2.00453,3.000
3,22.800,0.60,2.1379,2.13790,3.000
3,22.933,1.03,2.2712,2.27120,3.000
3,23.067,1.58,2.4045,2.40450,3.000
3,23.200,2.25,2.5380,2.53800,3.000
3,23.333,3.04,2.6713,2.67133,3.000
3,23.467,3.99,2.8044,2.80440,3.000
3,23.600,5.11,2.9377,2.93770,3.000
3,23.800,4.30,2.8585,2.85850,3.000
3,23.933,3.13,2.7252,2.72523,3.000
3,24.067,2.22,2.5920,2.59200,3.000
3,24.200,1.50,2.4587,2.45870,3.000
3,24.333,0.94,2.3252,2.32523,3.000
3,24.467,0.53,2.1918,2.19183,3.000
3,24.600,0.24,2.0586,2.05860,3.000
3,24.733,0.08,1.9252,1.92517,3.000
3,24.867,0.02,1.7919,1.79190,3.000
3,25.000,0.01,1.6587,1.65870,3.000
3,25.133,0.01,1.5250,1.52500,3.000
3,25.267,0.01,1.3917,1.39173,3.000
3,25.400,0.01,1.2585,1.25850,3.000
3,25.533,0.01,1.1252,1.12520,3.000
3,25.667,0.01,0.9919,0.99187,3.000
3,25.800,0.01,0.8585,0.85850,3.000
3,25.933,0.01,0.7251,0.72507,3.000
3,26.067,0.01,0.5917,0.59170,3.000
3,26.200,0.01,0.4585,0.45850,3.000
3,26.333,0.00,0.3250,0.32503,3.000
3,26.467,0.00,0.1917,0.19170,3.000
3,26.600,0.01,0.0583,0.05830,3.000
3,26.800,0.00,-0.0053,-0.00530,3.000
3,26.933,0.01,-0.0002,-0.00020,3.000
3,27.067,0.01,-0.0002,-0.00020,3.000
3,27.200,0.01,-0.0002,-0.00020,3.000
3,27.333,0.01,-0.0002,-0.00020,3.000
3,27.467,0.01,-0.0002,-0.00020,3.000
3,27.600,0.01,-0.0002,-0.00020,3.000
3,27.733,0.01,-0.0002,-0.00020,3.000
3,27.867,0.01,-0.0002,-0.00020,3.000
3,28.000,0.01,-0.0002,-0.00020,3.000
3,28.133,0.01,-0.0002,-0.00020,3.000
3,28.267,0.01,-0.0002,-0.00020,3.000
3,28.400,0.01,-0.0002,-0.00020,3.000
3,28.533,0.01,-0.0002,-0.00020,3.000
3,28.667,0.01,-0.0002,-0.00020,3.000
3,28.800,0.01,-0.0002,-0.00020,3.000
3,28.933,0.01,-0.0002,-0.00020,3.000
3,29.067,0.01,-0.0002,-0.00020,3.000
3,29.200,0.01,-0.0002,-0.00020,3.000
3,29.333,0.01,-0.0002,-0.00020,3.000
3,29.467,0.01,-0.0002,-0.00020,3.000
3,29.600,0.01,-0.0002,-0.00020,3.000
3,29.733,0.01,-0.0002,-0.00020,3.000
3,29.933,0.01,-0.0002,-0.00020,3.000
3,30.067,0.01,-0.0001,-0.00010,3.000
3,30.200,0.01,-0.0001,-0.00010,3.000
3,30.333,0.01,-0.0001,-0.00010,3.000
3,30.467,0.01,-0.0001,-0.00010,3.000
3,30.600,0.01,-0.0001,-0.00010,3.000
3,30.733,0.01,-0.0001,-0.00010,3.000
4,31.067,-0.01,0.1542,0.15423,4.000
4,31.200,-0.01,0.2877,0.28770,4.000
4,31.333,-0.01,0.4211,0.42113,4.000
4,31.467,-0.01,0.5544,0.55437,4.000
4,31.600,-0.01,0.6878,0.68780,4.000
4,31.733,-0.01,0.8211,0.82113,4.000
4,31.867,-0.01,0.9544,0.95437,4.000
4,32.000,-0.01,1.0878,1.08780,4.000
4,32.133,-0.01,1.2212,1.22123,4.000
4,32.267,-0.01,1.3543,1.35433,4.000
4,32.400,-0.01,1.4877,1.48770,4.000
4,32.533,-0.01,1.6212,1.62117,4.000
4,32.667,0.02,1.7545,1.75450,4.000
4,32.800,0.10,1.8878,1.88780,4.000
4,32.933,0.29,2.0213,2.02130,4.000
4,33.067,0.63,2.1545,2.15447,4.000
4,33.200,1.08,2.2877,2.28770,4.000
4,33.333,1.63,2.4213,2.42127,4.000
4,33.467,2.32,2.5546,2.55463,4.000
4,33.600,3.14,2.6879,2.68790,4.000
4,33.733,4.10,2.8211,2.82110,4.000
4,34.000,4.82,2.9085,2.90850,4.000
4,34.133,3.52,2.7752,2.77520,4.000
4,34.267,2.52,2.6419,2.64193,4.000
4,34.400,1.73,2.5087,2.50870,4.000
4,34.533,1.12,2.3753,2.37527,4.000
4,34.667,0.65,2.2418,2.24180,4.000
4,34.800,0.32,2.1086,2.10860,4.000
4,34.933,0.11,1.9752,1.97520,4.000
4,35.067,0.02,1.8418,1.84177,4.000
4,35.200,-0.01,1.7086,1.70860,4.000
4,35.333,-0.01,1.5751,1.57507,4.000
4,35.467,-0.01,1.4417,1.44173,4.000
4,35.600,-0.01,1.3085,1.30850,4.000
4,35.733,-0.01,1.1753,1.17527,4.000
4,35.867,-0.01,1.0418,1.04177,4.000
4,36.000,-0.01,0.9084,0.90840,4.000
4,36.133,-0.01,0.7751,0.77513,4.000
4,36.267,-0.01,0.6417,0.64170,4.000
4,36.400,-0.01,0.5085,0.50850,4.000
4,36.533,-0.01,0.3751,0.37513,4.000
4,36.667,-0.01,0.2417,0.24170,4.000
4,36.800,-0.01,0.1083,0.10830,4.000
4,37.000,-0.01,-0.0428,-0.04280,4.000
4,37.133,-0.01,-0.0003,-0.00030,4.000
4,37.267,-0.01,-0.0003,-0.00030,4.000
4,37.400,-0.01,-0.0003,-0.00030,4.000
4,37.533,-0.01,-0.0003,-0.00030,4.000
4,37.667,-0.01,-0.0003,-0.00030,4.000
4,37.800,-0.01,-0.0003,-0.00030,4.000
4,37.933,-0.01,-0.0003,-0.00030,4.000
4,38.067,-0.01,-0.0002,-0.00020,4.000
4,38.200,-0.01,-0.0002,-0.00020,4.000
4,38.333,-0.01,-0.0002,-0.00020,4.000
4,38.467,-0.01,-0.0002,-0.00020,4.000
4,38.600,-0.01,-0.0002,-0.00020,4.000
4,38.733,-0.01,-0.0002,-0.00020,4.000
4,38.867,-0.01,-0.0002,-0.00020,4.000
4,39.000,-0.01,-0.0002,-0.00020,4.000
4,39.133,-0.01,-0.0002,-0.00020,4.000
4,39.267,-0.01,-0.0002,-0.00020,4.000
4,39.400,-0.01,-0.0002,-0.00020,4.000
4,39.533,-0.01,-0.0002,-0.00020,4.000
4,39.667,-0.01,-0.0002,-0.00020,4.000
4,39.800,-0.01,-0.0002,-0.00020,4.000
4,39.933,-0.01,-0.0002,-0.00020,4.000
4,40.067,-0.01,-0.0002,-0.00020,4.000
4,40.200,-0.01,-0.0002,-0.00020,4.000
4,40.333,-0.01,-0.0002,-0.00020,4.000
4,40.467,-0.01,-0.0002,-0.00020,4.000
4,40.600,-0.01,-0.0002,-0.00020,4.000
4,40.733,-0.01,-0.0002,-0.00020,4.000
4,40.867,-0.01,-0.0001,-0.00010,4.000
5,41.200,0.01,0.0384,0.03850,5.000
5,41.333,0.01,0.1719,0.17200,5.000
5,41.467,0.01,0.3055,0.30563,5.000
5,41.600,0.00,0.4386,0.43870,5.000
5,41.733,0.00,0.5721,0.57223,5.000
5,41.867,0.00,0.7055,0.70560,5.000
5,42.000,0.01,0.8387,0.83880,5.000
5,42.133,0.00,0.9721,0.97220,5.000
5,42.267,0.00,1.1056,1.10573,5.000
5,42.400,0.00,1.2388,1.23890,5.000
5,42.533,0.01,1.3721,1.37217,5.000
5,42.667,0.00,1.5054,1.50553,5.000
5,42.800,0.00,1.6388,1.63890,5.000
5,42.933,0.04,1.7721,1.77217,5.000
5,43.067,0.13,1.9055,1.90560,5.000
5,43.200,0.35,2.0389,2.03900,5.000
5,43.333,0.70,2.1721,2.17223,5.000
5,43.467,1.16,2.3056,2.30570,5.000
5,43.600,1.74,2.4389,2.43900,5.000
5,43.733,2.44,2.5723,2.57237,5.000
5,43.867,3.27,2.7057,2.70577,5.000
5,44.000,4.26,2.8388,2.83890,5.000
5,44.200,5.25,2.9391,2.93920,5.000
5,44.333,3.82,2.8060,2.80613,5.000
5,44.467,2.76,2.6731,2.67317,5.000
5,44.600,1.93,2.5396,2.53970,5.000
5,44.733,1.27,2.4062,2.40630,5.000
5,44.867,0.77,2.2730,2.27307,5.000
5,45.000,0.41,2.1395,2.13960,5.000
5,45.133,0.16,2.0062,2.00630,5.000
5,45.267,0.05,1.8728,1.87293,5.000
5,45.400,0.01,1.7396,1.73970,5.000
5,45.533,0.00,1.6061,1.60617,5.000
5,45.667,0.00,1.4727,1.47283,5.000
5,45.800,0.01,1.3394,1.33950,5.000
5,45.933,0.00,1.2062,1.20627,5.000
5,46.067,0.00,1.0729,1.07300,5.000
5,46.200,0.01,0.9396,0.93970,5.000
5,46.333,0.00,0.8061,0.80620,5.000
5,46.467,0.00,0.6728,0.67287,5.000
5,46.600,0.01,0.5396,0.53970,5.000
5,46.733,0.00,0.4060,0.40613,5.000
5,46.867,0.01,0.2727,0.27283,5.000
5,47.000,0.01,0.1393,0.13940,5.000
5,47.133,0.00,0.0060,0.00610,5.000
5,47.333,0.00,-0.0003,-0.00020,5.000
5,47.467,0.01,-0.0002,-0.00010,5.000
5,47.600,0.00,-0.0002,-0.00010,5.000
5,47.733,0.00,-0.0002,-0.00010,5.000
5,47.867,0.00,-0.0002,-0.00010,5.000
5,48.000,0.00,-0.0002,-0.00010,5.000
5,48.133,0.00,-0.0002,-0.00010,5.000
5,48.267,0.00,-0.0002,-0.00010,5.000
5,48.400,0.01,-0.0002,-0.00010,5.000
5,48.533,0.00,-0.0002,-0.00010,5.000
5,48.667,0.00,-0.0002,-0.00010,5.000
5,48.800,0.00,-0.0002,-0.00010,5.000
5,48.933,0.01,-0.0002,-0.00010,5.000
5,49.067,0.00,-0.0002,-0.00010,5.000
5,49.200,0.00,-0.0002,-0.00010,5.000
5,49.333,0.00,-0.0002,-0.00010,5.000
5,49.467,0.01,-0.0002,-0.00010,5.000
5,49.600,0.00,-0.0002,-0.00010,5.000
5,49.733,0.00,-0.0002,-0.00010,5.000
5,49.867,0.00,-0.0002,-0.00010,5.000
5,50.000,0.01,-0.0002,-0.00010,5.000
5,50.133,0.00,-0.0002,-0.00010,5.000
5,50.333,0.00,-0.0002,-0.00010,5.000
5,50.467,0.00,-0.0002,-0.00010,5.000
5,50.600,0.00,-0.0002,-0.00010,5.000
5,50.733,0.00,-0.0002,-0.00010,5.000
5,50.867,0.00,-0.0001,0.00000,5.000
5,51.000,0.00,-0.0001,0.00000,5.000
5,51.133,0.00,-0.0001,0.00000,5.000
6,51.467,0.00,0.0752,0.07527,6.000
6,51.600,0.00,0.2087,0.20880,6.000
6,51.733,0.00,0.3421,0.34223,6.000
6,51.867,0.00,0.4753,0.47543,6.000
6,52.000,0.00,0.6087,0.60880,6.000
6,52.133,0.00,0.7422,0.74230,6.000
6,52.267,0.00,0.8754,0.87547,6.000
6,52.400,-0.01,1.0088,1.00890,6.000
6,52.533,0.00,1.1423,1.14237,6.000
6,52.667,0.00,1.2754,1.27553,6.000
6,52.800,0.00,1.4087,1.40880,6.000
6,52.933,-0.01,1.5421,1.54223,6.000
6,53.067,0.00,1.6755,1.67560,6.000
6,53.200,0.05,1.8087,1.80880,6.000
6,53.333,0.17,1.9422,1.94230,6.000
6,53.467,0.43,2.0755,2.07563,6.000
6,53.600,0.81,2.2086,2.20870,6.000
6,53.733,1.31,2.3422,2.34230,6.000
6,53.867,1.92,2.4756,2.47570,6.000
6,54.000,2.66,2.6088,2.60890,6.000
6,54.133,3.54,2.7423,2.74237,6.000
6,54.267,4.57,2.8754,2.87550,6.000
6,54.533,4.11,2.8361,2.83620,6.000
6,54.667,2.98,2.7030,2.70310,6.000
6,54.800,2.10,2.5694,2.56950,6.000
6,54.933,1.40,2.4363,2.43643,6.000
6,55.067,0.87,2.3030,2.30307,6.000
6,55.200,0.47,2.1693,2.16940,6.000
6,55.333,0.20,2.0362,2.03633,6.000
6,55.467,0.06,1.9029,1.90300,6.000
6,55.600,0.01,1.7694,1.76950,6.000
6,55.733,-0.01,1.6362,1.63627,6.000
6,55.867,0.00,1.5028,1.50293,6.000
6,56.000,-0.01,1.3693,1.36940,6.000
6,56.133,0.00,1.2362,1.23630,6.000
6,56.267,0.00,1.1030,1.10307,6.000
6,56.400,-0.01,0.9695,0.96960,6.000
6,56.533,0.00,0.8361,0.83617,6.000
6,56.667,0.00,0.7029,0.70300,6.000
6,56.800,-0.01,0.5693,0.56940,6.000
6,56.933,0.00,0.4360,0.43613,6.000
6,57.067,0.00,0.3028,0.30293,6.000
6,57.200,-0.01,0.1692,0.16930,6.000
6,57.333,0.00,0.0359,0.03597,6.000
6,57.533,0.00,-0.0002,-0.00010,6.000
6,57.667,0.00,-0.0002,-0.00010,6.000
6,57.800,-0.01,-0.0002,-0.00010,6.000
6,57.933,0.00,-0.0002,-0.00010,6.000
6,58.067,0.00,-0.0002,-0.00010,6.000
6,58.200,0.00,-0.0002,-0.00010,6.000
6,58.333,0.00,-0.0002,-0.00010,6.000
6,58.467,0.00,-0.0002,-0.00010,6.000
6,58.600,0.00,-0.0002,-0.00010,6.000
6,58.733,0.00,-0.0002,-0.00010,6.000
6,58.867,0.00,-0.0002,-0.00010,6.000
6,59.000,-0.01,-0.0002,-0.00010,6.000
6,59.133,0.00,-0.0002,-0.00010,6.000
6,59.267,0.00,-0.0002,-0.00010,6.000
6,59.400,0.00,-0.0002,-0.00010,6.000
6,59.533,0.00,-0.0002,-0.00010,6.000
6,59.667,0.00,-0.0002,-0.00010,6.000
6,59.800,0.00,-0.0002,-0.00010,6.000
6,59.933,-0.01,-0.0002,-0.00010,6.000
6,60.067,0.00,-0.0002,-0.00010,6.000
6,60.200,0.00,-0.0002,-0.00010,6.000
6,60.333,0.00,-0.0002,-0.00010,6.000
6,60.533,-0.01,-0.0002,-0.00010,6.000
6,60.667,-0.01,-0.0002,-0.00010,6.000
6,60.800,0.00,-0.0002,-0.00010,6.000
6,60.933,-0.01,-0.0001,0.00000,6.000
6,61.067,0.00,-0.0001,0.00000,6.000
6,61.200,-0.01,-0.0001,0.00000,6.000
6,61.333,0.00,-0.0001,0.00000,6.000
7,61.667,0.00,0.0453,0.04537,7.000
7,61.800,0.00,0.1787,0.17880,7.000
7,61.933,0.00,0.3122,0.31227,7.000
7,62.067,0.00,0.4454,0.44547,7.000
7,62.200,0.00,0.5788,0.57890,7.000
7,62.333,-0.01,0.7121,0.71217,7.000
7,62.467,0.00,0.8453,0.84543,7.000
7,62.600,0.00,0.9789,0.97900,7.000
7,62.733,0.00,1.1123,1.11237,7.000
7,62.867,0.00,1.2455,1.24560,7.000
7,63.000,0.00,1.3787,1.37880,7.000
7,63.133,0.00,1.5121,1.51217,7.000
7,63.267,0.00,1.6454,1.64547,7.000
7,63.400,0.04,1.7788,1.77890,7.000
7,63.533,0.13,1.9122,1.91230,7.000
7,63.667,0.36,2.0455,2.04560,7.000
7,63.800,0.71,2.1787,2.17880,7.000
7,63.933,1.18,2.3122,2.31233,7.000
7,64.067,1.76,2.4455,2.44557,7.000
7,64.200,2.47,2.5789,2.57900,7.000
7,64.333,3.32,2.7123,2.71243,7.000
7,64.467,4.33,2.8453,2.84540,7.000
7,64.667,5.22,2.9347,2.93477,7.000
7,64.800,3.79,2.8013,2.80140,7.000
7,64.933,2.73,2.6684,2.66850,7.000
7,65.067,1.90,2.5348,2.53493,7.000
7,65.200,1.25,2.4015,2.40160,7.000
7,65.333,0.75,2.2683,2.26840,7.000
7,65.467,0.39,2.1347,2.13483,7.000
7,65.600,0.15,2.0014,2.00150,7.000
7,65.733,0.04,1.8682,1.86830,7.000
7,65.867,0.00,1.7348,1.73490,7.000
7,66.000,0.00,1.6013,1.60140,7.000
7,66.133,0.00,1.4681,1.46820,7.000
7,66.267,0.00,1.3347,1.33483,7.000
7,66.400,-0.01,1.2015,1.20160,7.000
7,66.533,0.00,1.0682,1.06830,7.000
7,66.667,0.00,0.9347,0.93483,7.000
7,66.800,0.00,0.8014,0.80150,7.000
7,66.933,0.00,0.6681,0.66823,7.000
7,67.067,0.00,0.5347,0.53483,7.000
7,67.200,0.00,0.4013,0.40140,7.000
7,67.333,0.00,0.2681,0.26823,7.000
7,67.467,0.00,0.1347,0.13477,7.000
7,67.600,0.00,0.0013,0.00140,7.000
7,67.800,0.00,-0.0001,0.00000,7.000
7,67.933,0.00,-0.0002,-0.00010,7.000
7,68.067,0.00,-0.0002,-0.00010,7.000
7,68.200,0.00,-0.0002,-0.00010,7.000
7,68.333,0.00,-0.0002,-0.00010,7.000
7,68.467,0.00,-0.0002,-0.00010,7.000
7,68.600,0.00,-0.0002,-0.00010,7.000
7,68.733,0.00,-0.0002,-0.00010,7.000
7,68.867,0.00,-0.0002,-0.00010,7.000
7,69.000,0.00,-0.0002,-0.00010,7.000
7,69.133,0.00,-0.0002,-0.00010,7.000
7,69.267,0.00,-0.0002,-0.00010,7.000
7,69.400,0.00,-0.0002,-0.00010,7.000
7,69.533,0.00,-0.0002,-0.00010,7.000
7,69.667,-0.01,-0.0002,-0.00010,7.000
7,69.800,0.00,-0.0002,-0.00010,7.000
7,69.933,0.00,-0.0002,-0.00010,7.000
7,70.067,0.00,-0.0002,-0.00010,7.000
7,70.200,0.00,-0.0002,-0.00010,7.000
7,70.333,0.00,-0.0002,-0.00010,7.000
7,70.467,0.00,-0.0002,-0.00010,7.000
7,70.600,0.00,-0.0002,-0.00010,7.000
7,70.800,0.00,-0.0002,-0.00010,7.000
7,70.933,0.00,-0.0002,-0.00010,7.000
7,71.067,0.00,-0.0002,-0.00010,7.000
7,71.200,0.00,-0.0001,0.00000,7.000
7,71.333,0.00,-0.0001,0.00000,7.000
7,71.467,0.00,-0.0001,0.00000,7.000
7,71.600,0.00,-0.0001,0.00000,7.000
8,71.933,-0.01,0.0610,0.06097,8.000
8,72.067,0.00,0.1943,0.19427,8.000
8,72.200,0.00,0.3277,0.32770,8.000
8,72.333,0.00,0.4611,0.46113,8.000
8,72.467,0.00,0.5944,0.59437,8.000
8,72.600,0.00,0.7278,0.72780,8.000
8,72.733,0.00,0.8611,0.86113,8.000
8,72.867,0.00,0.9944,0.99443,8.000
8,73.000,0.00,1.1279,1.12790,8.000
8,73.133,0.00,1.2612,1.26117,8.000
8,73.267,0.00,1.3944,1.39440,8.000
8,73.400,0.00,1.5276,1.52760,8.000
8,73.533,0.00,1.6611,1.66113,8.000
8,73.667,0.05,1.7945,1.79450,8.000
8,73.800,0.15,1.9278,1.92780,8.000
8,73.933,0.39,2.0612,2.06120,8.000
8,74.067,0.76,2.1945,2.19453,8.000
8,74.200,1.24,2.3277,2.32770,8.000
8,74.333,1.84,2.4613,2.46127,8.000
8,74.467,2.57,2.5946,2.59460,8.000
8,74.600,3.43,2.7278,2.72780,8.000
8,74.733,4.46,2.8610,2.86103,8.000
8,74.933,5.19,2.9351,2.93513,8.000
8,75.067,3.78,2.8017,2.80173,8.000
8,75.200,2.72,2.6688,2.66880,8.000
8,75.333,1.90,2.5352,2.53523,8.000
8,75.467,1.24,2.4019,2.40193,8.000
8,75.600,0.75,2.2686,2.26860,8.000
8,75.733,0.39,2.1352,2.13517,8.000
8,75.867,0.15,2.0019,2.00187,8.000
8,76.000,0.04,1.8685,1.86850,8.000
8,76.133,0.00,1.7352,1.73517,8.000
8,76.267,0.00,1.6017,1.60170,8.000
8,76.400,0.00,1.4684,1.46840,8.000
8,76.533,0.00,1.3351,1.33507,8.000
8,76.667,0.00,1.2018,1.20177,8.000
8,76.800,0.00,1.0685,1.06850,8.000
8,76.933,0.00,0.9350,0.93503,8.000
8,77.067,0.00,0.8017,0.80170,8.000
8,77.200,0.00,0.6685,0.66850,8.000
8,77.333,0.00,0.5351,0.53510,8.000
8,77.467,0.00,0.4016,0.40163,8.000
8,77.600,0.00,0.2685,0.26850,8.000
8,77.733,0.00,0.1350,0.13500,8.000
8,77.867,0.00,0.0016,0.00163,8.000
8,78.067,0.00,-0.0002,-0.00020,8.000
8,78.200,0.00,-0.0002,-0.00020,8.000
8,78.333,0.00,-0.0002,-0.00020,8.000
8,78.467,0.00,-0.0002,-0.00020,8.000
8,78.600,-0.01,-0.0002,-0.00020,8.000
8,78.733,0.00,-0.0002,-0.00020,8.000
8,78.867,0.00,-0.0002,-0.00020,8.000
8,79.000,0.00,-0.0002,-0.00020,8.000
8,79.133,0.00,-0.0002,-0.00020,8.000
8,79.267,0.00,-0.0002,-0.00020,8.000
8,79.400,0.00,-0.0002,-0.00020,8.000
8,79.533,0.00,-0.0002,-0.00020,8.000
8,79.667,0.00,-0.0002,-0.00020,8.000
8,79.800,0.00,-0.0002,-0.00020,8.000
8,79.933,0.00,-0.0002,-0.00020,8.000
8,80.067,-0.01,-0.0002,-0.00020,8.000
8,80.200,0.00,-0.0002,-0.00020,8.000
8,80.333,0.00,-0.0002,-0.00020,8.000
8,80.467,0.00,-0.0002,-0.00020,8.000
8,80.600,0.00,-0.0002,-0.00020,8.000
8,80.733,0.00,-0.0002,-0.00020,8.000
8,80.867,0.00,-0.0002,-0.00020,8.000
8,81.067,0.00,-0.0002,-0.00020,8.000
8,81.200,0.00,-0.0002,-0.00020,8.000
8,81.333,0.00,-0.0002,-0.00020,8.000
8,81.467,0.00,-0.0001,-0.00010,8.000
8,81.600,0.00,-0.0001,-0.00010,8.000
8,81.733,0.00,-0.0001,-0.00010,8.000
8,81.867,-0.01,-0.0001,-0.00010,8.000
9,82.200,0.00,0.0667,0.06670,9.000
9,82.333,-0.01,0.1999,0.19987,9.000
9,82.467,-0.01,0.3334,0.33340,9.000
9,82.600,-0.01,0.4669,0.46690,9.000
9,82.733,-0.01,0.6000,0.60003,9.000
9,82.867,0.00,0.7334,0.73343,9.000
9,83.000,-0.01,0.8668,0.86680,9.000
9,83.133,-0.01,1.0001,1.00007,9.000
9,83.267,-0.01,1.1335,1.13353,9.000
9,83.400,0.00,1.2669,1.26690,9.000
9,83.533,-0.01,1.4000,1.40003,9.000
9,83.667,0.00,1.5333,1.53330,9.000
9,83.800,0.00,1.6670,1.66700,9.000
9,83.933,0.04,1.8000,1.80003,9.000
9,84.067,0.15,1.9334,1.93343,9.000
9,84.200,0.40,2.0669,2.06690,9.000
9,84.333,0.78,2.2002,2.20017,9.000
9,84.467,1.27,2.3334,2.33343,9.000
9,84.600,1.86,2.4670,2.46700,9.000
9,84.733,2.60,2.6002,2.60020,9.000
9,84.867,3.47,2.7335,2.73347,9.000
9,85.000,4.50,2.8668,2.86680,9.000
9,85.200,5.09,2.9272,2.92720,9.000
9,85.333,3.71,2.7942,2.79420,9.000
9,85.467,2.67,2.6610,2.66100,9.000
9,85.600,1.85,2.5275,2.52750,9.000
9,85.733,1.21,2.3943,2.39433,9.000
9,85.867,0.72,2.2608,2.26083,9.000
9,86.000,0.37,2.1274,2.12740,9.000
9,86.133,0.13,1.9942,1.99423,9.000
9,86.267,0.04,1.8609,1.86087,9.000
9,86.400,-0.01,1.7275,1.72750,9.000
9,86.533,-0.01,1.5941,1.59410,9.000
9,86.667,-0.01,1.4608,1.46080,9.000
9,86.800,0.00,1.3273,1.32730,9.000
9,86.933,0.00,1.1942,1.19423,9.000
9,87.067,0.00,1.0609,1.06090,9.000
9,87.200,0.00,0.9272,0.92720,9.000
9,87.333,-0.01,0.7941,0.79410,9.000
9,87.467,-0.01,0.6608,0.66080,9.000
9,87.600,0.00,0.5272,0.52720,9.000
9,87.733,0.00,0.3941,0.39413,9.000
9,87.867,0.00,0.2608,0.26083,9.000
9,88.000,-0.01,0.1272,0.12720,9.000
9,88.133,0.00,-0.0060,-0.00597,9.000
9,88.333,0.00,-0.0003,-0.00030,9.000
9,88.467,0.00,-0.0003,-0.00030,9.000
9,88.600,0.00,-0.0002,-0.00020,9.000
9,88.733,0.00,-0.0002,-0.00020,9.000
9,88.867,0.00,-0.0002,-0.00020,9.000
9,89.000,-0.01,-0.0002,-0.00020,9.000
9,89.133,0.00,-0.0002,-0.00020,9.000
9,89.267,0.00,-0.0002,-0.00020,9.000
9,89.400,0.00,-0.0002,-0.00020,9.000
9,89.533,0.00,-0.0002,-0.00020,9.000
9,89.667,-0.01,-0.0002,-0.00020,9.000
9,89.800,0.00,-0.0002,-0.00020,9.000
9,89.933,0.00,-0.0002,-0.00020,9.000
9,90.067,0.00,-0.0002,-0.00020,9.000
9,90.200,0.00,-0.0002,-0.00020,9.000
9,90.333,-0.01,-0.0002,-0.00020,9.000
9,90.467,0.00,-0.0002,-0.00020,9.000
9,90.600,0.00,-0.0002,-0.00020,9.000
9,90.733,-0.01,-0.0002,-0.00020,9.000
9,90.867,-0.01,-0.0002,-0.00020,9.000
9,91.000,0.00,-0.0002,-0.00020,9.000
9,91.133,-0.01,-0.0002,-0.00020,9.000
9,91.333,-0.01,-0.0002,-0.00020,9.000
9,91.467,-0.01,-0.0002,-0.00020,9.000
9,91.600,0.00,-0.0002,-0.00020,9.000
9,91.733,0.00,-0.0002,-0.00020,9.000
9,91.867,0.00,-0.0002,-0.00020,9.000
9,92.000,0.00,-0.0002,-0.00020,9.000
9,92.133,-0.01,-0.0002,-0.00020,9.000
10,92.467,0.00,0.0832,0.08327,10.000
10,92.600,0.00,0.2168,0.21690,10.000
10,92.733,0.00,0.3502,0.35027,10.000
10,92.867,0.01,0.4834,0.48347,10.000
10,93.000,0.00,0.6167,0.61680,10.000
10,93.133,0.01,0.7501,0.75023,10.000
10,93.267,0.00,0.8833,0.88340,10.000
10,93.400,0.01,1.0167,1.01680,10.000
10,93.533,0.00,1.1503,1.15040,10.000
10,93.667,0.00,1.2834,1.28353,10.000
10,93.800,0.00,1.4168,1.41690,10.000
10,93.933,0.00,1.5501,1.55017,10.000
10,94.067,0.01,1.6835,1.68360,10.000
10,94.200,0.07,1.8168,1.81690,10.000
10,94.333,0.18,1.9502,1.95030,10.000
10,94.467,0.45,2.0835,2.08363,10.000
10,94.600,0.84,2.2167,2.21680,10.000
10,94.733,1.34,2.3503,2.35040,10.000
10,94.867,1.96,2.4835,2.48363,10.000
10,95.000,2.71,2.6169,2.61700,10.000
10,95.133,3.60,2.7503,2.75043,10.000
10,95.267,4.65,2.8834,2.88350,10.000
10,95.533,4.20,2.8461,2.84617,10.000
10,95.667,3.05,2.7130,2.71310,10.000
10,95.800,2.16,2.5796,2.57970,10.000
10,95.933,1.45,2.4463,2.44637,10.000
10,96.067,0.90,2.3129,2.31303,10.000
10,96.200,0.49,2.1795,2.17960,10.000
10,96.333,0.21,2.0462,2.04630,10.000
10,96.467,0.06,1.9129,1.91300,10.000
10,96.600,0.01,1.7795,1.77960,10.000
10,96.733,0.00,1.6461,1.64617,10.000
10,96.867,0.00,1.5128,1.51287,10.000
10,97.000,0.00,1.3795,1.37960,10.000
10,97.133,0.00,1.2461,1.24620,10.000
10,97.267,0.00,1.1128,1.11293,10.000
10,97.400,0.00,0.9796,0.97970,10.000
10,97.533,0.00,0.8460,0.84610,10.000
10,97.667,0.00,0.7128,0.71287,10.000
10,97.800,0.00,0.5795,0.57960,10.000
10,97.933,0.00,0.4460,0.44610,10.000
10,98.067,0.00,0.3128,0.31290,10.000
10,98.200,0.00,0.1795,0.17960,10.000
10,98.333,0.01,0.0459,0.04597,10.000
10,98.533,0.00,-0.0007,-0.00060,10.000
10,98.667,0.00,-0.0003,-0.00020,10.000
10,98.800,0.00,-0.0003,-0.00020,10.000
10,98.933,0.00,-0.0003,-0.00020,10.000
10,99.067,0.00,-0.0003,-0.00020,10.000
10,99.200,0.00,-0.0003,-0.00020,10.000
10,99.333,0.01,-0.0002,-0.00010,10.000
10,99.467,0.01,-0.0002,-0.00010,10.000
10,99.600,0.01,-0.0002,-0.00010,10.000
10,99.733,0.01,-0.0002,-0.00010,10.000
10,99.867,0.00,-0.0002,-0.00010,10.000
10,100.000,0.00,-0.0002,-0.00010,10.000
10,100.133,0.00,-0.0002,-0.00010,10.000
10,100.267,0.00,-0.0002,-0.00010,10.000
10,100.400,0.00,-0.0002,-0.00010,10.000
10,100.533,0.00,-0.0002,-0.00010,10.000
10,100.667,0.00,-0.0002,-0.00010,10.000
10,100.800,0.00,-0.0002,-0.00010,10.000
10,100.933,0.00,-0.0002,-0.00010,10.000
10,101.067,0.00,-0.0002,-0.00010,10.000
10,101.200,0.00,-0.0002,-0.00010,10.000
10,101.333,0.00,-0.0002,-0.00010,10.000
10,101.467,0.00,-0.0002,-0.00010,10.000
10,101.667,0.00,-0.0002,-0.00010,10.000
10,101.800,0.00,-0.0002,-0.00010,10.000
10,101.933,0.01,-0.0002,-0.00010,10.000
10,102.067,0.00,-0.0002,-0.00010,10.000
10,102.200,0.00,-0.0001,0.00000,10.000
10,102.333,0.00,-0.0001,0.00000,10.000
10,102.467,0.00,-0.0001,0.00000,10.000