File: AIME_journal_files/AIME_data/calibDATA_loadcell/date_02:15:2018/Instron_02.15.2018/1_5N_4__1mm.s_0_0.txt
""
"Test Method","Radhen_Load_Cntrl_Cmprsn_250N_12-7.msm"
"Sample I. D.","Sample1.mss"
"Specimen Number","12"

"TheCycle_Output ()","_Time (s)","_Load (N)","_Extension (mm)","RealTimeDepth (mm)","CycleNumber ()"

1,0.267,0.00,0.0583,0.05833,1.000
1,0.400,0.00,0.1916,0.19160,1.000
1,0.533,0.00,0.3250,0.32503,1.000
1,0.667,0.00,0.4585,0.45853,1.000
1,0.800,0.00,0.5918,0.59180,1.000
1,0.933,0.00,0.7251,0.72507,1.000
1,1.067,0.00,0.8585,0.85850,1.000
1,1.200,0.00,0.9918,0.99180,1.000
1,1.333,0.00,1.1252,1.12517,1.000
1,1.467,0.00,1.2586,1.25860,1.000
1,1.600,0.01,1.3918,1.39180,1.000
1,1.733,0.01,1.5250,1.52500,1.000
1,1.867,0.00,1.6586,1.65857,1.000
1,2.000,0.00,1.7920,1.79200,1.000
1,2.133,0.01,1.9252,1.92517,1.000
1,2.267,0.06,2.0586,2.05860,1.000
1,2.400,0.20,2.1919,2.19190,1.000
1,2.533,0.47,2.3252,2.32520,1.000
1,2.667,0.86,2.4586,2.45860,1.000
1,2.800,1.37,2.5921,2.59210,1.000
1,2.933,2.03,2.7252,2.72520,1.000
1,3.067,2.83,2.8585,2.85847,1.000
1,3.200,3.81,2.9919,2.99190,1.000
1,3.333,4.96,3.1251,3.12513,1.000
1,3.533,4.22,3.0593,3.05927,1.000
1,3.667,2.99,2.9258,2.92583,1.000
1,3.800,2.06,2.7926,2.79260,1.000
1,3.933,1.36,2.6593,2.65933,1.000
1,4.067,0.82,2.5259,2.52590,1.000
1,4.200,0.44,2.3926,2.39260,1.000
1,4.333,0.17,2.2593,2.25930,1.000
1,4.467,0.04,2.1258,2.12577,1.000
1,4.600,0.00,1.9926,1.99260,1.000
1,4.733,0.00,1.8592,1.85923,1.000
1,4.867,0.00,1.7259,1.72590,1.000
1,5.000,0.00,1.5925,1.59250,1.000
1,5.133,0.00,1.4592,1.45923,1.000
1,5.267,0.00,1.3257,1.32570,1.000
1,5.400,-0.01,1.1926,1.19260,1.000
1,5.533,0.00,1.0593,1.05933,1.000
1,5.667,0.00,0.9257,0.92567,1.000
1,5.800,0.00,0.7924,0.79240,1.000
1,5.933,0.00,0.6592,0.65920,1.000
1,6.067,0.00,0.5257,0.52570,1.000
1,6.200,0.00,0.3925,0.39250,1.000
1,6.333,0.00,0.2591,0.25910,1.000
1,6.467,0.00,0.1256,0.12563,1.000
1,6.600,0.00,-0.0077,-0.00770,1.000
1,6.800,0.00,-0.0002,-0.00020,1.000
1,6.933,0.00,-0.0002,-0.00020,1.000
1,7.067,0.00,-0.0002,-0.00020,1.000
1,7.200,0.00,-0.0002,-0.00020,1.000
1,7.333,0.00,-0.0002,-0.00020,1.000
1,7.467,0.00,-0.0002,-0.00020,1.000
1,7.600,0.00,-0.0002,-0.00020,1.000
1,7.733,0.00,-0.0002,-0.00020,1.000
1,7.867,0.00,-0.0002,-0.00020,1.000
1,8.000,0.01,-0.0002,-0.00020,1.000
1,8.133,0.00,-0.0002,-0.00020,1.000
1,8.267,0.00,-0.0002,-0.00020,1.000
1,8.400,-0.01,-0.0002,-0.00020,1.000
1,8.533,0.00,-0.0002,-0.00020,1.000
1,8.667,0.00,-0.0002,-0.00020,1.000
1,8.800,0.00,-0.0002,-0.00020,1.000
1,8.933,0.00,-0.0002,-0.00020,1.000
1,9.067,0.00,-0.0002,-0.00020,1.000
1,9.200,0.00,-0.0001,-0.00010,1.000
1,9.333,0.00,-0.0001,-0.00010,1.000
1,9.467,0.00,-0.0001,-0.00010,1.000
1,9.600,0.00,-0.0001,-0.00010,1.000
1,9.800,0.00,-0.0001,-0.00010,1.000
1,9.933,0.00,-0.0001,-0.00010,1.000
1,10.067,0.00,-0.0001,-0.00010,1.000
1,10.200,0.00,-0.0001,-0.00010,1.000
1,10.333,0.00,-0.0001,-0.00010,1.000
1,10.467,0.00,-0.0001,-0.00010,1.000
1,10.600,0.00,-0.0001,-0.00010,1.000
2,10.933,0.00,0.1060,0.10597,2.000
2,11.067,0.01,0.2394,0.23937,2.000
2,11.200,0.00,0.3727,0.37270,2.000
2,11.333,0.00,0.5061,0.50607,2.000
2,11.467,0.00,0.6394,0.63940,2.000
2,11.600,0.00,0.7727,0.77270,2.000
2,11.733,0.01,0.9061,0.90607,2.000
2,11.867,0.00,1.0394,1.03940,2.000
2,12.000,0.00,1.1729,1.17290,2.000
2,12.133,0.00,1.3061,1.30610,2.000
2,12.267,0.00,1.4393,1.43933,2.000
2,12.400,0.01,1.5727,1.57270,2.000
2,12.533,0.00,1.7062,1.70620,2.000
2,12.667,0.01,1.8394,1.83940,2.000
2,12.800,0.02,1.9728,1.97280,2.000
2,12.933,0.09,2.1062,2.10617,2.000
2,13.067,0.27,2.2394,2.23943,2.000
2,13.200,0.58,2.3728,2.37280,2.000
2,13.333,1.00,2.5063,2.50633,2.000
2,13.467,1.57,2.6396,2.63957,2.000
2,13.600,2.28,2.7728,2.77280,2.000
2,13.733,3.15,2.9061,2.90610,2.000
2,13.867,4.20,3.0394,3.03943,2.000
2,14.067,5.32,3.1487,3.14870,2.000
2,14.200,3.78,3.0155,3.01550,2.000
2,14.333,2.66,2.8821,2.88210,2.000
2,14.467,1.82,2.7489,2.74893,2.000
2,14.600,1.17,2.6156,2.61560,2.000
2,14.733,0.69,2.4822,2.48220,2.000
2,14.867,0.34,2.3489,2.34893,2.000
2,15.000,0.12,2.2154,2.21540,2.000
2,15.133,0.03,2.0822,2.08217,2.000
2,15.267,0.00,1.9489,1.94893,2.000
2,15.400,0.01,1.8155,1.81550,2.000
2,15.533,0.00,1.6821,1.68210,2.000
2,15.667,0.00,1.5487,1.54873,2.000
2,15.800,0.00,1.4155,1.41550,2.000
2,15.933,0.00,1.2820,1.28203,2.000
2,16.067,0.01,1.1489,1.14890,2.000
2,16.200,0.00,1.0155,1.01550,2.000
2,16.333,0.01,0.8820,0.88203,2.000
2,16.467,0.00,0.7488,0.74883,2.000
2,16.600,0.00,0.6155,0.61550,2.000
2,16.733,0.00,0.4820,0.48200,2.000
2,16.867,0.00,0.3487,0.34873,2.000
2,17.000,0.00,0.2154,0.21540,2.000
2,17.133,0.00,0.0818,0.08180,2.000
2,17.333,0.00,-0.0359,-0.03593,2.000
2,17.467,0.00,-0.0002,-0.00020,2.000
2,17.600,0.00,-0.0002,-0.00020,2.000
2,17.733,0.00,-0.0002,-0.00020,2.000
2,17.867,0.01,-0.0002,-0.00020,2.000
2,18.000,0.00,-0.0002,-0.00020,2.000
2,18.133,0.00,-0.0002,-0.00020,2.000
2,18.267,0.00,-0.0002,-0.00020,2.000
2,18.400,0.00,-0.0002,-0.00020,2.000
2,18.533,0.00,-0.0002,-0.00020,2.000
2,18.667,0.00,-0.0002,-0.00020,2.000
2,18.800,0.00,-0.0002,-0.00020,2.000
2,18.933,0.00,-0.0002,-0.00020,2.000
2,19.067,0.00,-0.0002,-0.00020,2.000
2,19.200,0.00,-0.0002,-0.00020,2.000
2,19.333,0.00,-0.0002,-0.00020,2.000
2,19.467,0.00,-0.0002,-0.00020,2.000
2,19.600,0.00,-0.0002,-0.00020,2.000
2,19.733,0.00,-0.0002,-0.00020,2.000
2,19.867,0.00,-0.0002,-0.00020,2.000
2,20.000,0.00,-0.0002,-0.00020,2.000
2,20.133,0.00,-0.0002,-0.00020,2.000
2,20.267,0.00,-0.0002,-0.00020,2.000
2,20.467,0.00,-0.0002,-0.00020,2.000
2,20.600,0.00,-0.0001,-0.00010,2.000
2,20.733,0.00,-0.0001,-0.00010,2.000
2,20.867,0.00,-0.0001,-0.00010,2.000
2,21.000,0.01,-0.0001,-0.00010,2.000
2,21.133,0.00,-0.0001,-0.00010,2.000
2,21.267,0.00,-0.0001,-0.00010,2.000
3,21.533,0.00,0.0649,0.06500,3.000
3,21.667,0.00,0.1983,0.19837,3.000
3,21.800,0.00,0.3318,0.33190,3.000
3,21.933,0.00,0.4651,0.46520,3.000
3,22.067,0.00,0.5983,0.59840,3.000
3,22.200,0.00,0.7317,0.73180,3.000
3,22.333,0.00,0.8651,0.86523,3.000
3,22.467,0.00,0.9983,0.99843,3.000
3,22.600,0.00,1.1319,1.13200,3.000
3,22.733,0.00,1.2652,1.26527,3.000
3,22.867,0.00,1.3983,1.39843,3.000
3,23.000,0.00,1.5317,1.53180,3.000
3,23.133,0.00,1.6652,1.66533,3.000
3,23.267,0.00,1.7984,1.79847,3.000
3,23.400,0.00,1.9318,1.93190,3.000
3,23.533,0.05,2.0652,2.06530,3.000
3,23.667,0.19,2.1984,2.19850,3.000
3,23.800,0.47,2.3318,2.33190,3.000
3,23.933,0.86,2.4653,2.46537,3.000
3,24.067,1.39,2.5985,2.59863,3.000
3,24.200,2.06,2.7319,2.73200,3.000
3,24.333,2.88,2.8651,2.86520,3.000
3,24.467,3.89,2.9984,2.99853,3.000
3,24.600,5.06,3.1317,3.13180,3.000
3,24.800,4.37,3.0726,3.07270,3.000
3,24.933,3.11,2.9391,2.93923,3.000
3,25.067,2.15,2.8057,2.80583,3.000
3,25.200,1.43,2.6727,2.67280,3.000
3,25.333,0.87,2.5393,2.53940,3.000
3,25.467,0.47,2.4059,2.40600,3.000
3,25.600,0.19,2.2726,2.27270,3.000
3,25.733,0.04,2.1392,2.13927,3.000
3,25.867,0.00,2.0058,2.00593,3.000
3,26.000,0.00,1.8724,1.87250,3.000
3,26.133,0.00,1.7393,1.73940,3.000
3,26.267,0.00,1.6057,1.60577,3.000
3,26.400,0.00,1.4724,1.47250,3.000
3,26.533,-0.01,1.3391,1.33920,3.000
3,26.667,0.00,1.2058,1.20587,3.000
3,26.800,0.00,1.0725,1.07260,3.000
3,26.933,0.00,0.9391,0.93920,3.000
3,27.067,0.00,0.8056,0.80573,3.000
3,27.200,0.00,0.6723,0.67240,3.000
3,27.333,0.00,0.5391,0.53920,3.000
3,27.467,0.00,0.4057,0.40577,3.000
3,27.600,0.00,0.2724,0.27250,3.000
3,27.733,0.00,0.1390,0.13910,3.000
3,27.867,0.00,0.0057,0.00577,3.000
3,28.067,0.00,-0.0003,-0.00023,3.000
3,28.200,0.00,-0.0003,-0.00020,3.000
3,28.333,0.00,-0.0003,-0.00020,3.000
3,28.467,0.00,-0.0003,-0.00020,3.000
3,28.600,0.00,-0.0003,-0.00020,3.000
3,28.733,0.00,-0.0003,-0.00020,3.000
3,28.867,0.00,-0.0002,-0.00010,3.000
3,29.000,0.00,-0.0002,-0.00010,3.000
3,29.133,0.00,-0.0002,-0.00010,3.000
3,29.267,0.00,-0.0002,-0.00010,3.000
3,29.400,0.00,-0.0002,-0.00010,3.000
3,29.533,0.00,-0.0002,-0.00010,3.000
3,29.667,0.00,-0.0002,-0.00010,3.000
3,29.800,0.00,-0.0002,-0.00010,3.000
3,29.933,0.00,-0.0002,-0.00010,3.000
3,30.067,0.00,-0.0002,-0.00010,3.000
3,30.200,0.00,-0.0002,-0.00010,3.000
3,30.333,0.00,-0.0002,-0.00010,3.000
3,30.467,0.00,-0.0002,-0.00010,3.000
3,30.600,0.00,-0.0002,-0.00010,3.000
3,30.733,0.00,-0.0002,-0.00010,3.000
3,30.867,0.00,-0.0002,-0.00010,3.000
3,31.067,0.00,-0.0002,-0.00010,3.000
3,31.200,0.01,-0.0002,-0.00010,3.000
3,31.333,0.00,-0.0002,-0.00010,3.000
3,31.467,0.00,-0.0002,-0.00010,3.000
3,31.600,0.00,-0.0001,0.00000,3.000
3,31.733,0.00,-0.0001,0.00000,3.000
3,31.867,0.00,-0.0001,0.00000,3.000
3,32.000,0.00,-0.0001,0.00000,3.000
4,32.267,0.01,0.1383,0.13830,4.000
4,32.400,0.00,0.2717,0.27170,4.000
4,32.533,0.00,0.4050,0.40503,4.000
4,32.667,0.00,0.5384,0.53843,4.000
4,32.800,0.00,0.6717,0.67170,4.000
4,32.933,0.01,0.8051,0.80507,4.000
4,33.067,0.00,0.9385,0.93847,4.000
4,33.200,0.00,1.0719,1.07190,4.000
4,33.333,0.01,1.2051,1.20510,4.000
4,33.467,0.01,1.3384,1.33840,4.000
4,33.600,0.00,1.4718,1.47180,4.000
4,33.733,0.00,1.6050,1.60500,4.000
4,33.867,0.00,1.7385,1.73847,4.000
4,34.000,0.01,1.8719,1.87190,4.000
4,34.133,0.03,2.0052,2.00517,4.000
4,34.267,0.12,2.1384,2.13843,4.000
4,34.400,0.33,2.2718,2.27180,4.000
4,34.533,0.68,2.4051,2.40513,4.000
4,34.667,1.13,2.5386,2.53863,4.000
4,34.800,1.74,2.6721,2.67210,4.000
4,34.933,2.50,2.8050,2.80500,4.000
4,35.067,3.42,2.9384,2.93843,4.000
4,35.200,4.52,3.0718,3.07180,4.000
4,35.400,4.93,3.1166,3.11660,4.000
4,35.533,3.51,2.9832,2.98323,4.000
4,35.667,2.45,2.8497,2.84970,4.000
4,35.800,1.66,2.7167,2.71670,4.000
4,35.933,1.05,2.5833,2.58333,4.000
4,36.067,0.60,2.4499,2.44990,4.000
4,36.200,0.27,2.3166,2.31660,4.000
4,36.333,0.08,2.1832,2.18317,4.000
4,36.467,0.02,2.0498,2.04980,4.000
4,36.600,0.01,1.9166,1.91660,4.000
4,36.733,0.01,1.7832,1.78323,4.000
4,36.867,0.00,1.6497,1.64973,4.000
4,37.000,0.01,1.5164,1.51640,4.000
4,37.133,0.00,1.3830,1.38303,4.000
4,37.267,0.00,1.2497,1.24973,4.000
4,37.400,0.01,1.1164,1.11640,4.000
4,37.533,0.00,0.9832,0.98317,4.000
4,37.667,0.01,0.8497,0.84970,4.000
4,37.800,0.00,0.7164,0.71640,4.000
4,37.933,0.01,0.5831,0.58310,4.000
4,38.067,0.00,0.4497,0.44970,4.000
4,38.200,0.00,0.3164,0.31640,4.000
4,38.333,0.00,0.1831,0.18307,4.000
4,38.467,0.01,0.0496,0.04957,4.000
4,38.733,0.01,-0.0002,-0.00020,4.000
4,38.867,0.00,-0.0002,-0.00020,4.000
4,39.000,0.00,-0.0002,-0.00020,4.000
4,39.133,0.01,-0.0002,-0.00020,4.000
4,39.267,0.01,-0.0002,-0.00020,4.000
4,39.400,0.01,-0.0002,-0.00020,4.000
4,39.533,0.01,-0.0002,-0.00020,4.000
4,39.667,0.00,-0.0002,-0.00020,4.000
4,39.800,0.01,-0.0002,-0.00020,4.000
4,39.933,0.00,-0.0002,-0.00020,4.000
4,40.067,0.01,-0.0002,-0.00020,4.000
4,40.200,0.01,-0.0002,-0.00020,4.000
4,40.333,0.01,-0.0002,-0.00020,4.000
4,40.467,0.00,-0.0002,-0.00020,4.000
4,40.600,0.00,-0.0002,-0.00020,4.000
4,40.733,0.01,-0.0002,-0.00020,4.000
4,40.867,0.00,-0.0002,-0.00020,4.000
4,41.000,0.01,-0.0002,-0.00020,4.000
4,41.133,0.00,-0.0002,-0.00020,4.000
4,41.267,0.00,-0.0002,-0.00020,4.000
4,41.400,0.00,-0.0002,-0.00020,4.000
4,41.533,0.01,-0.0002,-0.00020,4.000
4,41.733,0.01,-0.0002,-0.00020,4.000
4,41.867,0.00,-0.0001,-0.00010,4.000
4,42.000,0.01,-0.0001,-0.00010,4.000
4,42.133,0.01,-0.0001,-0.00010,4.000
4,42.267,0.01,-0.0001,-0.00010,4.000
4,42.400,0.01,-0.0001,-0.00010,4.000
4,42.533,0.01,-0.0001,-0.00010,4.000
5,42.867,0.00,0.1082,0.10830,5.000
5,43.000,0.00,0.2416,0.24170,5.000
5,43.133,0.00,0.3751,0.37517,5.000
5,43.267,0.00,0.5084,0.50853,5.000
5,43.400,0.00,0.6417,0.64180,5.000
5,43.533,0.00,0.7751,0.77520,5.000
5,43.667,0.00,0.9084,0.90853,5.000
5,43.800,0.00,1.0418,1.04190,5.000
5,43.933,0.00,1.1752,1.17530,5.000
5,44.067,0.00,1.3085,1.30860,5.000
5,44.200,0.00,1.4416,1.44170,5.000
5,44.333,0.00,1.5750,1.57510,5.000
5,44.467,0.00,1.7085,1.70860,5.000
5,44.600,0.00,1.8417,1.84180,5.000
5,44.733,0.02,1.9751,1.97523,5.000
5,44.867,0.08,2.1085,2.10863,5.000
5,45.000,0.26,2.2418,2.24190,5.000
5,45.133,0.58,2.3751,2.37520,5.000
5,45.267,1.01,2.5086,2.50870,5.000
5,45.400,1.59,2.6419,2.64200,5.000
5,45.533,2.31,2.7751,2.77517,5.000
5,45.667,3.20,2.9084,2.90850,5.000
5,45.800,4.26,3.0418,3.04190,5.000
5,46.000,5.31,3.1422,3.14230,5.000
5,46.133,3.76,3.0092,3.00927,5.000
5,46.267,2.63,2.8757,2.87583,5.000
5,46.400,1.80,2.7426,2.74270,5.000
5,46.533,1.15,2.6092,2.60927,5.000
5,46.667,0.67,2.4759,2.47600,5.000
5,46.800,0.32,2.3426,2.34270,5.000
5,46.933,0.11,2.2090,2.20910,5.000
5,47.067,0.02,2.0759,2.07600,5.000
5,47.200,0.00,1.9426,1.94270,5.000
5,47.333,0.00,1.8090,1.80913,5.000
5,47.467,0.00,1.6758,1.67593,5.000
5,47.600,0.00,1.5426,1.54270,5.000
5,47.733,0.00,1.4090,1.40910,5.000
5,47.867,0.00,1.2757,1.27583,5.000
5,48.000,0.00,1.1426,1.14270,5.000
5,48.133,0.00,1.0091,1.00917,5.000
5,48.267,0.00,0.8757,0.87580,5.000
5,48.400,0.00,0.7425,0.74260,5.000
5,48.533,0.00,0.6090,0.60913,5.000
5,48.667,0.00,0.4757,0.47580,5.000
5,48.800,0.01,0.3424,0.34250,5.000
5,48.933,0.00,0.2090,0.20910,5.000
5,49.067,0.00,0.0755,0.07560,5.000
5,49.267,0.01,-0.0119,-0.01177,5.000
5,49.400,0.00,-0.0002,-0.00010,5.000
5,49.533,0.00,-0.0002,-0.00010,5.000
5,49.667,0.00,-0.0002,-0.00010,5.000
5,49.800,0.00,-0.0002,-0.00010,5.000
5,49.933,0.00,-0.0002,-0.00010,5.000
5,50.067,0.00,-0.0002,-0.00010,5.000
5,50.200,0.00,-0.0002,-0.00010,5.000
5,50.333,0.01,-0.0002,-0.00010,5.000
5,50.467,0.00,-0.0002,-0.00010,5.000
5,50.600,0.00,-0.0002,-0.00010,5.000
5,50.733,0.00,-0.0002,-0.00010,5.000
5,50.867,0.00,-0.0002,-0.00010,5.000
5,51.000,0.00,-0.0002,-0.00010,5.000
5,51.133,0.01,-0.0002,-0.00010,5.000
5,51.267,0.00,-0.0002,-0.00010,5.000
5,51.400,0.01,-0.0002,-0.00010,5.000
5,51.533,0.01,-0.0002,-0.00010,5.000
5,51.667,0.00,-0.0002,-0.00010,5.000
5,51.800,0.00,-0.0002,-0.00010,5.000
5,51.933,0.00,-0.0002,-0.00010,5.000
5,52.067,0.00,-0.0002,-0.00010,5.000
5,52.200,0.00,-0.0002,-0.00010,5.000
5,52.400,0.00,-0.0001,0.00000,5.000
5,52.533,0.00,-0.0001,0.00000,5.000
5,52.667,0.01,-0.0001,0.00000,5.000
5,52.800,0.01,-0.0001,0.00000,5.000
5,52.933,0.00,-0.0001,0.00000,5.000
5,53.067,0.00,-0.0001,0.00000,5.000
5,53.200,0.01,-0.0001,0.00000,5.000
6,53.533,0.00,0.1319,0.13187,6.000
6,53.667,-0.01,0.2654,0.26543,6.000
6,53.800,0.00,0.3986,0.39860,6.000
6,53.933,-0.01,0.5320,0.53203,6.000
6,54.067,0.00,0.6655,0.66550,6.000
6,54.200,0.01,0.7987,0.79870,6.000
6,54.333,0.00,0.9320,0.93203,6.000
6,54.467,-0.01,1.0655,1.06553,6.000
6,54.600,0.00,1.1988,1.19880,6.000
6,54.733,-0.01,1.3320,1.33203,6.000
6,54.867,0.00,1.4655,1.46547,6.000
6,55.000,0.00,1.5987,1.59870,6.000
6,55.133,-0.01,1.7321,1.73213,6.000
6,55.267,-0.01,1.8656,1.86557,6.000
6,55.400,0.02,1.9988,1.99880,6.000
6,55.533,0.10,2.1321,2.13207,6.000
6,55.667,0.31,2.2655,2.26553,6.000
6,55.800,0.65,2.3989,2.39890,6.000
6,55.933,1.10,2.5321,2.53213,6.000
6,56.067,1.70,2.6656,2.66563,6.000
6,56.200,2.45,2.7988,2.79880,6.000
6,56.333,3.36,2.9320,2.93203,6.000
6,56.467,4.45,3.0655,3.06550,6.000
6,56.667,4.89,3.1128,3.11283,6.000
6,56.800,3.47,2.9795,2.97950,6.000
6,56.933,2.42,2.8460,2.84603,6.000
6,57.067,1.64,2.7130,2.71297,6.000
6,57.200,1.03,2.5797,2.57970,6.000
6,57.333,0.58,2.4462,2.44617,6.000
6,57.467,0.26,2.3130,2.31297,6.000
6,57.600,0.08,2.1794,2.17940,6.000
6,57.733,0.01,2.0462,2.04617,6.000
6,57.867,0.00,1.9128,1.91283,6.000
6,58.000,0.00,1.7796,1.77960,6.000
6,58.133,0.00,1.6461,1.64607,6.000
6,58.267,-0.01,1.5127,1.51273,6.000
6,58.400,0.00,1.3795,1.37950,6.000
6,58.533,0.00,1.2461,1.24610,6.000
6,58.667,-0.01,1.1129,1.11287,6.000
6,58.800,0.00,0.9795,0.97950,6.000
6,58.933,0.00,0.8460,0.84597,6.000
6,59.067,-0.01,0.7127,0.71270,6.000
6,59.200,0.00,0.5795,0.57950,6.000
6,59.333,-0.01,0.4460,0.44597,6.000
6,59.467,0.00,0.3128,0.31277,6.000
6,59.600,0.00,0.1794,0.17940,6.000
6,59.733,0.00,0.0459,0.04587,6.000
6,60.000,0.00,-0.0002,-0.00020,6.000
6,60.133,0.00,-0.0002,-0.00020,6.000
6,60.267,0.00,-0.0002,-0.00020,6.000
6,60.400,0.00,-0.0002,-0.00020,6.000
6,60.533,0.00,-0.0002,-0.00020,6.000
6,60.667,0.00,-0.0002,-0.00020,6.000
6,60.800,0.00,-0.0002,-0.00020,6.000
6,60.933,0.00,-0.0002,-0.00020,6.000
6,61.067,0.00,-0.0002,-0.00020,6.000
6,61.200,0.00,-0.0002,-0.00020,6.000
6,61.333,0.00,-0.0002,-0.00020,6.000
6,61.467,0.00,-0.0002,-0.00020,6.000
6,61.600,-0.01,-0.0002,-0.00020,6.000
6,61.733,-0.01,-0.0002,-0.00020,6.000
6,61.867,0.00,-0.0002,-0.00020,6.000
6,62.000,-0.01,-0.0002,-0.00020,6.000
6,62.133,0.00,-0.0002,-0.00020,6.000
6,62.267,0.00,-0.0002,-0.00020,6.000
6,62.400,0.00,-0.0002,-0.00020,6.000
6,62.533,-0.01,-0.0002,-0.00020,6.000
6,62.667,0.00,-0.0002,-0.00020,6.000
6,62.800,0.00,-0.0002,-0.00020,6.000
6,63.067,0.00,-0.0002,-0.00020,6.000
6,63.200,-0.01,-0.0002,-0.00020,6.000
6,63.333,0.00,-0.0001,-0.00010,6.000
6,63.467,0.00,-0.0001,-0.00010,6.000
6,63.600,0.00,-0.0001,-0.00010,6.000
6,63.733,0.00,-0.0001,-0.00010,6.000
6,63.867,0.00,-0.0001,-0.00010,6.000
7,64.133,0.00,0.1218,0.12177,7.000
7,64.267,0.00,0.2554,0.25543,7.000
7,64.400,0.00,0.3888,0.38880,7.000
7,64.533,0.01,0.5220,0.52203,7.000
7,64.667,0.01,0.6554,0.65543,7.000
7,64.800,0.00,0.7889,0.78890,7.000
7,64.933,0.00,0.9219,0.92193,7.000
7,65.067,0.00,1.0554,1.05540,7.000
7,65.200,0.01,1.1890,1.18900,7.000
7,65.333,0.00,1.3220,1.32200,7.000
7,65.467,0.00,1.4554,1.45543,7.000
7,65.600,0.00,1.5888,1.58880,7.000
7,65.733,0.00,1.7222,1.72217,7.000
7,65.867,0.00,1.8554,1.85537,7.000
7,66.000,0.02,1.9889,1.98890,7.000
7,66.133,0.10,2.1221,2.12210,7.000
7,66.267,0.29,2.2554,2.25537,7.000
7,66.400,0.63,2.3890,2.38900,7.000
7,66.533,1.07,2.5222,2.52220,7.000
7,66.667,1.66,2.6556,2.65563,7.000
7,66.800,2.40,2.7888,2.78880,7.000
7,66.933,3.29,2.9221,2.92213,7.000
7,67.067,4.37,3.0554,3.05543,7.000
7,67.267,5.25,3.1428,3.14280,7.000
7,67.400,3.73,3.0095,3.00950,7.000
7,67.533,2.63,2.8761,2.87610,7.000
7,67.667,1.79,2.7430,2.74297,7.000
7,67.800,1.15,2.6096,2.60960,7.000
7,67.933,0.67,2.4763,2.47630,7.000
7,68.067,0.33,2.3429,2.34290,7.000
7,68.200,0.11,2.2093,2.20930,7.000
7,68.333,0.03,2.0762,2.07620,7.000
7,68.467,0.00,1.9429,1.94290,7.000
7,68.600,0.00,1.8093,1.80930,7.000
7,68.733,0.00,1.6762,1.67617,7.000
7,68.867,0.00,1.5428,1.54277,7.000
7,69.000,0.00,1.4093,1.40930,7.000
7,69.133,0.00,1.2761,1.27607,7.000
7,69.267,0.00,1.1429,1.14287,7.000
7,69.400,0.01,1.0093,1.00930,7.000
7,69.533,0.00,0.8760,0.87603,7.000
7,69.667,0.00,0.7428,0.74283,7.000
7,69.800,0.01,0.6093,0.60930,7.000
7,69.933,0.00,0.4761,0.47607,7.000
7,70.067,0.00,0.3428,0.34280,7.000
7,70.200,0.00,0.2093,0.20930,7.000
7,70.333,0.00,0.0759,0.07590,7.000
7,70.533,0.00,-0.0191,-0.01907,7.000
7,70.667,0.01,-0.0002,-0.00020,7.000
7,70.800,0.01,-0.0002,-0.00020,7.000
7,70.933,0.00,-0.0002,-0.00020,7.000
7,71.067,0.01,-0.0002,-0.00020,7.000
7,71.200,0.00,-0.0002,-0.00020,7.000
7,71.333,0.01,-0.0002,-0.00020,7.000
7,71.467,0.00,-0.0002,-0.00020,7.000
7,71.600,0.00,-0.0002,-0.00020,7.000
7,71.733,0.00,-0.0002,-0.00020,7.000
7,71.867,0.00,-0.0002,-0.00020,7.000
7,72.000,0.00,-0.0002,-0.00020,7.000
7,72.133,0.00,-0.0002,-0.00020,7.000
7,72.267,0.00,-0.0002,-0.00020,7.000
7,72.400,0.00,-0.0002,-0.00020,7.000
7,72.533,0.00,-0.0002,-0.00020,7.000
7,72.667,0.01,-0.0002,-0.00020,7.000
7,72.800,0.01,-0.0002,-0.00020,7.000
7,72.933,0.00,-0.0002,-0.00020,7.000
7,73.067,0.00,-0.0002,-0.00020,7.000
7,73.200,0.00,-0.0002,-0.00020,7.000
7,73.333,0.01,-0.0001,-0.00010,7.000
7,73.467,0.00,-0.0001,-0.00010,7.000
7,73.667,0.01,-0.0001,-0.00010,7.000
7,73.800,0.00,-0.0001,-0.00010,7.000
7,73.933,0.00,-0.0001,-0.00010,7.000
7,74.067,0.01,-0.0001,-0.00010,7.000
7,74.200,0.00,-0.0001,-0.00010,7.000
7,74.333,0.01,-0.0001,-0.00010,7.000
7,74.467,0.01,-0.0001,-0.00010,7.000
8,74.800,0.00,0.1215,0.12150,8.000
8,74.933,0.00,0.2550,0.25503,8.000
8,75.067,0.01,0.3884,0.38837,8.000
8,75.200,0.00,0.5216,0.52160,8.000
8,75.333,0.00,0.6551,0.65510,8.000
8,75.467,0.00,0.7885,0.78850,8.000
8,75.600,0.00,0.9216,0.92160,8.000
8,75.733,0.00,1.0551,1.05510,8.000
8,75.867,0.00,1.1886,1.18860,8.000
8,76.000,0.00,1.3216,1.32160,8.000
8,76.133,0.00,1.4551,1.45507,8.000
8,76.267,0.00,1.5884,1.58840,8.000
8,76.400,0.01,1.7218,1.72180,8.000
8,76.533,0.00,1.8551,1.85510,8.000
8,76.667,0.02,1.9885,1.98853,8.000
8,76.800,0.10,2.1217,2.12170,8.000
8,76.933,0.30,2.2551,2.25507,8.000
8,77.067,0.63,2.3886,2.38860,8.000
8,77.200,1.07,2.5219,2.52190,8.000
8,77.333,1.66,2.6552,2.65523,8.000
8,77.467,2.40,2.7885,2.78853,8.000
8,77.600,3.30,2.9218,2.92180,8.000
8,77.733,4.39,3.0551,3.05510,8.000
8,77.933,5.36,3.1490,3.14900,8.000
8,78.067,3.81,3.0158,3.01583,8.000
8,78.200,2.68,2.8824,2.88240,8.000
8,78.333,1.83,2.7493,2.74927,8.000
8,78.467,1.18,2.6159,2.61590,8.000
8,78.600,0.69,2.4826,2.48260,8.000
8,78.733,0.34,2.3493,2.34933,8.000
8,78.867,0.12,2.2157,2.21573,8.000
8,79.000,0.03,2.0825,2.08250,8.000
8,79.133,0.00,1.9493,1.94927,8.000
8,79.267,0.00,1.8158,1.81577,8.000
8,79.400,0.00,1.6824,1.68240,8.000
8,79.533,0.00,1.5490,1.54903,8.000
8,79.667,0.00,1.4157,1.41570,8.000
8,79.800,0.00,1.2824,1.28240,8.000
8,79.933,0.00,1.1493,1.14927,8.000
8,80.067,0.00,1.0157,1.01570,8.000
8,80.200,0.00,0.8823,0.88230,8.000
8,80.333,0.00,0.7492,0.74917,8.000
8,80.467,0.00,0.6157,0.61573,8.000
8,80.600,0.00,0.4823,0.48230,8.000
8,80.733,0.01,0.3491,0.34907,8.000
8,80.867,0.00,0.2157,0.21570,8.000
8,81.000,0.00,0.0820,0.08200,8.000
8,81.200,0.00,-0.0386,-0.03860,8.000
8,81.333,0.00,-0.0003,-0.00030,8.000
8,81.467,0.00,-0.0003,-0.00030,8.000
8,81.600,0.00,-0.0003,-0.00030,8.000
8,81.733,0.00,-0.0003,-0.00030,8.000
8,81.867,0.00,-0.0003,-0.00030,8.000
8,82.000,0.00,-0.0003,-0.00030,8.000
8,82.133,0.01,-0.0002,-0.00020,8.000
8,82.267,0.00,-0.0002,-0.00020,8.000
8,82.400,0.00,-0.0002,-0.00020,8.000
8,82.533,0.00,-0.0002,-0.00020,8.000
8,82.667,0.00,-0.0002,-0.00020,8.000
8,82.800,0.01,-0.0002,-0.00020,8.000
8,82.933,0.01,-0.0002,-0.00020,8.000
8,83.067,0.00,-0.0002,-0.00020,8.000
8,83.200,0.00,-0.0002,-0.00020,8.000
8,83.333,0.00,-0.0002,-0.00020,8.000
8,83.467,0.00,-0.0002,-0.00020,8.000
8,83.600,0.00,-0.0002,-0.00020,8.000
8,83.733,0.01,-0.0002,-0.00020,8.000
8,83.867,0.00,-0.0002,-0.00020,8.000
8,84.000,0.00,-0.0002,-0.00020,8.000
8,84.133,0.00,-0.0002,-0.00020,8.000
8,84.267,0.01,-0.0002,-0.00020,8.000
8,84.400,0.01,-0.0002,-0.00020,8.000
8,84.533,0.00,-0.0002,-0.00020,8.000
8,84.667,0.00,-0.0002,-0.00020,8.000
8,84.800,0.01,-0.0001,-0.00010,8.000
8,84.933,0.01,-0.0001,-0.00010,8.000
8,85.067,0.00,-0.0001,-0.00010,8.000
8,85.200,0.00,-0.0001,-0.00010,8.000
9,85.467,0.00,0.1393,0.13937,9.000
9,85.600,0.00,0.2728,0.27290,9.000
9,85.733,0.00,0.4060,0.40607,9.000
9,85.867,0.00,0.5394,0.53950,9.000
9,86.000,0.00,0.6728,0.67290,9.000
9,86.133,-0.01,0.8060,0.80613,9.000
9,86.267,0.00,0.9394,0.93953,9.000
9,86.400,0.00,1.0729,1.07300,9.000
9,86.533,0.00,1.2061,1.20623,9.000
9,86.667,0.00,1.3394,1.33953,9.000
9,86.800,0.00,1.4728,1.47290,9.000
9,86.933,0.00,1.6060,1.60613,9.000
9,87.067,0.00,1.7395,1.73957,9.000
9,87.200,0.00,1.8728,1.87290,9.000
9,87.333,0.02,2.0061,2.00623,9.000
9,87.467,0.11,2.1394,2.13950,9.000
9,87.600,0.33,2.2730,2.27310,9.000
9,87.733,0.67,2.4061,2.40623,9.000
9,87.867,1.14,2.5395,2.53963,9.000
9,88.000,1.75,2.6731,2.67320,9.000
9,88.133,2.52,2.8061,2.80617,9.000
9,88.267,3.44,2.9394,2.93953,9.000
9,88.400,4.54,3.0729,3.07300,9.000
9,88.600,4.92,3.1138,3.11390,9.000
9,88.733,3.50,2.9802,2.98030,9.000
9,88.867,2.44,2.8467,2.84683,9.000
9,89.000,1.66,2.7136,2.71370,9.000
9,89.133,1.03,2.5803,2.58037,9.000
9,89.267,0.58,2.4469,2.44700,9.000
9,89.400,0.26,2.3136,2.31370,9.000
9,89.533,0.08,2.1801,2.18020,9.000
9,89.667,0.01,2.0469,2.04700,9.000
9,89.800,-0.01,1.9136,1.91370,9.000
9,89.933,0.00,1.7802,1.78033,9.000
9,90.067,0.00,1.6467,1.64683,9.000
9,90.200,0.00,1.5134,1.51350,9.000
9,90.333,0.00,1.3800,1.38013,9.000
9,90.467,0.00,1.2467,1.24680,9.000
9,90.600,0.00,1.1136,1.11370,9.000
9,90.733,0.00,0.9801,0.98017,9.000
9,90.867,0.00,0.8467,0.84683,9.000
9,91.000,0.00,0.7133,0.71340,9.000
9,91.133,0.00,0.5802,0.58027,9.000
9,91.267,0.00,0.4467,0.44677,9.000
9,91.400,0.00,0.3134,0.31350,9.000
9,91.533,0.00,0.1801,0.18017,9.000
9,91.667,0.00,0.0465,0.04660,9.000
9,91.867,0.00,-0.0054,-0.00533,9.000
9,92.000,0.00,-0.0002,-0.00010,9.000
9,92.133,0.00,-0.0002,-0.00010,9.000
9,92.267,0.00,-0.0002,-0.00010,9.000
9,92.400,0.00,-0.0002,-0.00010,9.000
9,92.533,0.00,-0.0002,-0.00010,9.000
9,92.667,0.00,-0.0002,-0.00010,9.000
9,92.800,-0.01,-0.0002,-0.00010,9.000
9,92.933,0.00,-0.0002,-0.00010,9.000
9,93.067,0.00,-0.0002,-0.00010,9.000
9,93.200,0.00,-0.0002,-0.00010,9.000
9,93.333,0.00,-0.0002,-0.00010,9.000
9,93.467,0.00,-0.0002,-0.00010,9.000
9,93.600,0.00,-0.0002,-0.00010,9.000
9,93.733,0.00,-0.0002,-0.00010,9.000
9,93.867,0.00,-0.0002,-0.00010,9.000
9,94.000,-0.01,-0.0002,-0.00010,9.000
9,94.133,-0.01,-0.0002,-0.00010,9.000
9,94.267,0.00,-0.0002,-0.00010,9.000
9,94.400,0.00,-0.0002,-0.00010,9.000
9,94.533,0.00,-0.0002,-0.00010,9.000
9,94.667,0.00,-0.0002,-0.00010,9.000
9,94.800,0.00,-0.0002,-0.00010,9.000
9,95.000,0.00,-0.0002,-0.00010,9.000
9,95.133,0.00,-0.0002,-0.00010,9.000
9,95.267,0.00,-0.0002,-0.00010,9.000
9,95.400,0.00,-0.0001,0.00000,9.000
9,95.533,0.00,-0.0001,0.00000,9.000
9,95.667,0.00,-0.0001,0.00000,9.000
9,95.800,0.00,-0.0001,0.00000,9.000
10,96.133,0.00,0.1649,0.16497,10.000
10,96.267,0.00,0.2984,0.29850,10.000
10,96.400,-0.01,0.4318,0.43190,10.000
10,96.533,0.00,0.5650,0.56513,10.000
10,96.667,0.00,0.6984,0.69853,10.000
10,96.800,0.00,0.8318,0.83190,10.000
10,96.933,0.00,0.9650,0.96507,10.000
10,97.067,0.00,1.0985,1.09857,10.000
10,97.200,0.00,1.2319,1.23200,10.000
10,97.333,0.00,1.3649,1.36503,10.000
10,97.467,-0.01,1.4984,1.49850,10.000
10,97.600,0.00,1.6319,1.63200,10.000
10,97.733,0.00,1.7652,1.76527,10.000
10,97.867,0.00,1.8985,1.89860,10.000
10,98.000,0.04,2.0319,2.03200,10.000
10,98.133,0.15,2.1651,2.16520,10.000
10,98.267,0.39,2.2985,2.29860,10.000
10,98.400,0.76,2.4319,2.43200,10.000
10,98.533,1.25,2.5652,2.56530,10.000
10,98.667,1.89,2.6986,2.69867,10.000
10,98.800,2.67,2.8318,2.83190,10.000
10,98.933,3.64,2.9651,2.96520,10.000
10,99.067,4.78,3.0984,3.09853,10.000
10,99.267,4.79,3.1059,3.10603,10.000
10,99.400,3.41,2.9724,2.97250,10.000
10,99.533,2.37,2.8391,2.83920,10.000
10,99.667,1.60,2.7060,2.70613,10.000
10,99.800,1.00,2.5725,2.57260,10.000
10,99.933,0.56,2.4393,2.43943,10.000
10,100.067,0.25,2.3059,2.30603,10.000
10,100.200,0.07,2.1724,2.17250,10.000
10,100.333,0.00,2.0393,2.03937,10.000
10,100.467,0.00,1.9059,1.90600,10.000
10,100.600,0.00,1.7724,1.77250,10.000
10,100.733,0.00,1.6390,1.63913,10.000
10,100.867,0.00,1.5058,1.50587,10.000
10,101.000,0.00,1.3722,1.37230,10.000
10,101.133,0.00,1.2391,1.23923,10.000
10,101.267,0.00,1.1060,1.10607,10.000
10,101.400,0.00,0.9724,0.97250,10.000
10,101.533,0.00,0.8390,0.83910,10.000
10,101.667,0.00,0.7058,0.70593,10.000
10,101.800,0.00,0.5724,0.57250,10.000
10,101.933,0.00,0.4390,0.43907,10.000
10,102.067,0.00,0.3059,0.30597,10.000
10,102.200,0.00,0.1723,0.17240,10.000
10,102.333,0.00,0.0389,0.03900,10.000
10,102.533,0.00,-0.0021,-0.00200,10.000
10,102.667,0.00,-0.0002,-0.00013,10.000
10,102.800,0.00,-0.0002,-0.00010,10.000
10,102.933,0.00,-0.0002,-0.00010,10.000
10,103.067,0.00,-0.0002,-0.00010,10.000
10,103.200,0.00,-0.0002,-0.00010,10.000
10,103.333,0.00,-0.0002,-0.00010,10.000
10,103.467,0.00,-0.0002,-0.00010,10.000
10,103.600,0.00,-0.0002,-0.00010,10.000
10,103.733,0.00,-0.0002,-0.00010,10.000
10,103.867,0.00,-0.0002,-0.00010,10.000
10,104.000,0.00,-0.0002,-0.00010,10.000
10,104.133,0.00,-0.0002,-0.00010,10.000
10,104.267,0.00,-0.0002,-0.00010,10.000
10,104.400,0.00,-0.0002,-0.00010,10.000
10,104.533,0.00,-0.0002,-0.00010,10.000
10,104.667,0.00,-0.0002,-0.00010,10.000
10,104.800,0.00,-0.0002,-0.00010,10.000
10,104.933,-0.01,-0.0002,-0.00010,10.000
10,105.067,-0.01,-0.0002,-0.00010,10.000
10,105.200,-0.01,-0.0002,-0.00010,10.000
10,105.333,-0.01,-0.0002,-0.00010,10.000
10,105.467,-0.01,-0.0002,-0.00010,10.000
10,105.667,0.00,-0.0002,-0.00010,10.000
10,105.800,0.00,-0.0002,-0.00010,10.000
10,105.933,-0.01,-0.0002,-0.00010,10.000
10,106.067,0.00,-0.0001,0.00000,10.000
10,106.200,0.00,-0.0001,0.00000,10.000
10,106.333,-0.01,-0.0001,0.00000,10.000
10,106.467,0.00,-0.0001,0.00000,10.000