File: AIME_journal_files/AIME_data/calibDATA_loadcell/date_02:15:2018/Instron_02.15.2018/2_15N_0__1mm.s_0_0_hold.txt
""
"Test Method","Radhen_Load_Cntrl_Cmprsn_250N_12-7.msm"
"Sample I. D.","Sample1.mss"
"Specimen Number","33"

"TheCycle_Output ()","_Time (s)","_Load (N)","_Extension (mm)","RealTimeDepth (mm)","CycleNumber ()"

1,0.267,0.00,0.0560,0.05600,1.000
1,0.333,0.00,0.1226,0.12263,1.000
1,0.400,0.00,0.1894,0.18940,1.000
1,0.467,0.01,0.2561,0.25613,1.000
1,0.533,0.00,0.3228,0.32280,1.000
1,0.600,0.00,0.3896,0.38960,1.000
1,0.667,0.00,0.4562,0.45620,1.000
1,0.733,0.00,0.5228,0.52283,1.000
1,0.800,-0.01,0.5896,0.58960,1.000
1,0.867,0.00,0.6562,0.65620,1.000
1,0.933,0.00,0.7228,0.72283,1.000
1,1.000,0.00,0.7896,0.78960,1.000
1,1.067,0.00,0.8563,0.85627,1.000
1,1.133,0.00,0.9229,0.92287,1.000
1,1.200,0.00,0.9897,0.98970,1.000
1,1.267,0.00,1.0562,1.05617,1.000
1,1.333,0.00,1.1229,1.12293,1.000
1,1.400,-0.01,1.1898,1.18980,1.000
1,1.467,-0.01,1.2563,1.25630,1.000
1,1.533,0.00,1.3229,1.32290,1.000
1,1.600,0.00,1.3896,1.38960,1.000
1,1.667,0.00,1.4561,1.45613,1.000
1,1.733,-0.01,1.5228,1.52283,1.000
1,1.800,0.00,1.5896,1.58960,1.000
1,1.867,0.00,1.6562,1.65623,1.000
1,1.933,0.00,1.7230,1.72297,1.000
1,2.000,0.00,1.7898,1.78980,1.000
1,2.067,0.00,1.8562,1.85617,1.000
1,2.133,0.00,1.9230,1.92297,1.000
1,2.200,0.00,1.9898,1.98980,1.000
1,2.267,-0.01,2.0564,2.05637,1.000
1,2.333,0.00,2.1231,2.12307,1.000
1,2.400,0.00,2.1898,2.18980,1.000
1,2.467,0.00,2.2563,2.25627,1.000
1,2.533,0.00,2.3230,2.32297,1.000
1,2.600,-0.01,2.3898,2.38980,1.000
1,2.667,0.00,2.4564,2.45637,1.000
1,2.733,0.00,2.5230,2.52303,1.000
1,2.800,0.00,2.5897,2.58970,1.000
1,2.867,0.00,2.6562,2.65623,1.000
1,2.933,0.00,2.7230,2.72303,1.000
1,3.000,0.00,2.7898,2.78980,1.000
1,3.067,0.00,2.8564,2.85637,1.000
1,3.133,0.00,2.9230,2.92303,1.000
1,3.200,0.00,2.9898,2.98980,1.000
1,3.267,0.00,3.0564,3.05637,1.000
1,3.333,0.00,3.1231,3.12310,1.000
1,3.400,0.00,3.1898,3.18980,1.000
1,3.467,0.00,3.2564,3.25640,1.000
1,3.533,0.00,3.3231,3.32310,1.000
1,3.600,-0.01,3.3897,3.38970,1.000
1,3.667,0.00,3.4563,3.45633,1.000
1,3.733,0.00,3.5231,3.52307,1.000
1,3.800,0.00,3.5898,3.58980,1.000
1,3.867,0.00,3.6564,3.65643,1.000
1,3.933,0.00,3.7232,3.72320,1.000
1,4.000,0.00,3.7899,3.78990,1.000
1,4.067,0.00,3.8563,3.85633,1.000
1,4.133,0.00,3.9231,3.92307,1.000
1,4.200,0.00,3.9898,3.98980,1.000
1,4.267,0.01,4.0563,4.05630,1.000
1,4.333,0.01,4.1231,4.12307,1.000
1,4.400,0.01,4.1898,4.18980,1.000
1,4.467,0.01,4.2564,4.25637,1.000
1,4.533,0.01,4.3231,4.32313,1.000
1,4.600,0.02,4.3898,4.38980,1.000
1,4.667,0.04,4.4564,4.45640,1.000
1,4.733,0.06,4.5233,4.52327,1.000
1,4.800,0.12,4.5898,4.58980,1.000
1,4.867,0.18,4.6564,4.65643,1.000
1,4.933,0.28,4.7231,4.72310,1.000
1,5.000,0.40,4.7899,4.78990,1.000
1,5.067,0.54,4.8565,4.85647,1.000
1,5.133,0.72,4.9233,4.92327,1.000
1,5.200,0.92,4.9900,4.99000,1.000
1,5.267,1.16,5.0565,5.05650,1.000
1,5.333,1.42,5.1233,5.12330,1.000
1,5.400,1.71,5.1899,5.18990,1.000
1,5.467,2.03,5.2565,5.25650,1.000
1,5.533,2.38,5.3232,5.32320,1.000
1,5.600,2.77,5.3897,5.38970,1.000
1,5.667,3.18,5.4563,5.45633,1.000
1,5.733,3.63,5.5232,5.52317,1.000
1,5.800,4.11,5.5899,5.58990,1.000
1,5.867,4.62,5.6566,5.65663,1.000
1,5.933,5.17,5.7234,5.72337,1.000
1,6.000,5.76,5.7897,5.78970,1.000
1,6.067,6.38,5.8564,5.85637,1.000
1,6.133,7.05,5.9232,5.92320,1.000
1,6.200,7.75,5.9898,5.98980,1.000
1,6.267,8.50,6.0564,6.05640,1.000
1,6.333,9.30,6.1232,6.12320,1.000
1,6.400,10.15,6.1898,6.18980,1.000
1,6.467,11.06,6.2564,6.25643,1.000
1,6.533,12.02,6.3233,6.32327,1.000
1,6.600,13.03,6.3898,6.38980,1.000
1,6.667,14.10,6.4564,6.45643,1.000
1,6.867,15.42,6.5500,6.55000,1.000
1,6.933,15.21,6.5500,6.55000,1.000
1,7.000,15.06,6.5500,6.55000,1.000
1,7.067,14.95,6.5500,6.55000,1.000
1,7.133,14.86,6.5500,6.55000,1.000
1,7.200,14.78,6.5500,6.55000,1.000
1,7.267,14.71,6.5500,6.55000,1.000
1,7.333,14.66,6.5500,6.55000,1.000
1,7.400,14.61,6.5500,6.55000,1.000
1,7.467,14.55,6.5500,6.55000,1.000
1,7.533,14.52,6.5500,6.55000,1.000
1,7.600,14.48,6.5500,6.55000,1.000
1,7.667,14.44,6.5500,6.55000,1.000
1,7.733,14.41,6.5500,6.55000,1.000
1,7.800,14.38,6.5500,6.55000,1.000
1,7.867,14.35,6.5500,6.55000,1.000
1,7.933,14.33,6.5500,6.55000,1.000
1,8.000,14.30,6.5500,6.55000,1.000
1,8.067,14.28,6.5500,6.55000,1.000
1,8.133,14.26,6.5500,6.55000,1.000
1,8.200,14.24,6.5500,6.55000,1.000
1,8.267,14.22,6.5500,6.55000,1.000
1,8.333,14.20,6.5500,6.55000,1.000
1,8.400,14.18,6.5500,6.55000,1.000
1,8.467,14.17,6.5500,6.55000,1.000
1,8.533,14.15,6.5500,6.55000,1.000
1,8.600,14.14,6.5500,6.55000,1.000
1,8.667,14.13,6.5500,6.55000,1.000
1,8.733,14.11,6.5500,6.55000,1.000
1,8.800,14.10,6.5500,6.55000,1.000
1,8.867,14.08,6.5500,6.55000,1.000
1,8.933,14.07,6.5500,6.55000,1.000
1,9.000,14.07,6.5500,6.55000,1.000
1,9.067,14.05,6.5500,6.55000,1.000
1,9.133,14.04,6.5500,6.55000,1.000
1,9.200,14.03,6.5500,6.55000,1.000
1,9.267,14.02,6.5500,6.55000,1.000
1,9.333,14.01,6.5500,6.55000,1.000
1,9.400,14.00,6.5500,6.55000,1.000
1,9.467,13.99,6.5500,6.55000,1.000
1,9.533,13.98,6.5500,6.55000,1.000
1,9.600,13.98,6.5500,6.55000,1.000
1,9.667,13.96,6.5500,6.55000,1.000
1,9.733,13.95,6.5500,6.55000,1.000
1,9.800,13.95,6.5500,6.55000,1.000
1,9.867,13.94,6.5500,6.55000,1.000
1,9.933,13.93,6.5500,6.55000,1.000
1,10.000,13.93,6.5500,6.55000,1.000
1,10.067,13.91,6.5500,6.55000,1.000
1,10.133,13.91,6.5500,6.55000,1.000
1,10.200,13.90,6.5500,6.55000,1.000
1,10.267,13.90,6.5500,6.55000,1.000
1,10.333,13.89,6.5500,6.55000,1.000
1,10.400,13.88,6.5500,6.55000,1.000
1,10.467,13.87,6.5500,6.55000,1.000
1,10.533,13.87,6.5500,6.55000,1.000
1,10.600,13.86,6.5500,6.55000,1.000
1,10.667,13.85,6.5500,6.55000,1.000
1,10.733,13.85,6.5500,6.55000,1.000
1,10.800,13.84,6.5500,6.55000,1.000
1,10.867,13.84,6.5500,6.55000,1.000
1,10.933,13.83,6.5500,6.55000,1.000
1,11.000,13.83,6.5500,6.55000,1.000
1,11.067,13.82,6.5500,6.55000,1.000
1,11.133,13.82,6.5500,6.55000,1.000
1,11.200,13.81,6.5500,6.55000,1.000
1,11.267,13.81,6.5500,6.55000,1.000
1,11.333,13.80,6.5500,6.55000,1.000
1,11.400,13.80,6.5500,6.55000,1.000
1,11.467,13.79,6.5500,6.55000,1.000
1,11.533,13.79,6.5500,6.55000,1.000
1,11.600,13.78,6.5500,6.55000,1.000
1,11.667,13.78,6.5500,6.55000,1.000
1,11.733,13.78,6.5500,6.55000,1.000
1,11.800,13.77,6.5500,6.55000,1.000
1,11.867,13.77,6.5500,6.55000,1.000
1,11.933,13.76,6.5500,6.55000,1.000
1,12.000,13.76,6.5500,6.55000,1.000
1,12.067,13.75,6.5500,6.55000,1.000
1,12.133,13.75,6.5500,6.55000,1.000