File: AIME_journal_files/AIME_data/calibDATA_loadcell/date_02:15:2018/Instron_02.15.2018/2_1N_4__1mm.s_0_0.txt
""
"Test Method","Radhen_Load_Cntrl_Cmprsn_250N_12-7.msm"
"Sample I. D.","Sample1.mss"
"Specimen Number","14"

"TheCycle_Output ()","_Time (s)","_Load (N)","_Extension (mm)","RealTimeDepth (mm)","CycleNumber ()"

1,0.267,0.00,0.0611,0.06113,1.000
1,0.333,0.00,0.1278,0.12777,1.000
1,0.400,0.00,0.1946,0.19460,1.000
1,0.467,0.00,0.2614,0.26137,1.000
1,0.533,0.00,0.3279,0.32793,1.000
1,0.600,0.02,0.3948,0.39480,1.000
1,0.667,0.04,0.4614,0.46137,1.000
1,0.733,0.08,0.5280,0.52803,1.000
1,0.800,0.14,0.5948,0.59480,1.000
1,0.867,0.22,0.6614,0.66137,1.000
1,0.933,0.32,0.7280,0.72797,1.000
1,1.000,0.44,0.7948,0.79480,1.000
1,1.067,0.58,0.8613,0.86133,1.000
1,1.133,0.74,0.9279,0.92790,1.000
1,1.200,0.92,0.9947,0.99470,1.000
1,1.333,1.18,1.0615,1.06147,1.000
1,1.400,0.94,0.9955,0.99550,1.000
1,1.467,0.72,0.9287,0.92873,1.000
1,1.533,0.55,0.8622,0.86220,1.000
1,1.600,0.40,0.7955,0.79550,1.000
1,1.667,0.28,0.7288,0.72880,1.000
1,1.733,0.18,0.6622,0.66220,1.000
1,1.800,0.10,0.5956,0.59560,1.000
1,1.867,0.05,0.5287,0.52873,1.000
1,1.933,0.02,0.4622,0.46223,1.000
1,2.000,0.00,0.3955,0.39550,1.000
1,2.067,-0.01,0.3288,0.32883,1.000
1,2.133,-0.01,0.2621,0.26213,1.000
1,2.200,-0.01,0.1954,0.19540,1.000
1,2.267,-0.01,0.1285,0.12853,1.000
1,2.333,-0.01,0.0621,0.06207,1.000
1,2.400,-0.01,-0.0045,-0.00450,1.000
1,2.533,-0.01,-0.0016,-0.00160,1.000
1,2.600,-0.01,-0.0001,-0.00010,1.000
1,2.667,-0.01,-0.0001,-0.00010,1.000
1,2.733,-0.01,-0.0001,-0.00010,1.000
1,2.800,-0.01,-0.0001,-0.00010,1.000
1,2.867,-0.01,-0.0001,-0.00010,1.000
1,2.933,-0.01,-0.0001,-0.00010,1.000
1,3.000,-0.01,-0.0001,-0.00010,1.000
1,3.067,-0.01,-0.0001,-0.00010,1.000
1,3.133,-0.01,-0.0001,-0.00010,1.000
1,3.200,-0.01,-0.0001,-0.00010,1.000
1,3.267,-0.01,-0.0001,-0.00010,1.000
1,3.333,-0.01,-0.0001,-0.00010,1.000
1,3.400,-0.01,-0.0001,-0.00010,1.000
1,3.467,-0.01,-0.0001,-0.00010,1.000
1,3.533,-0.01,-0.0001,-0.00010,1.000
1,3.600,-0.01,-0.0001,-0.00010,1.000
1,3.667,-0.01,-0.0001,-0.00010,1.000
1,3.733,-0.01,-0.0001,-0.00010,1.000
1,3.800,-0.01,-0.0001,-0.00010,1.000
1,3.867,-0.01,-0.0001,-0.00010,1.000
1,3.933,-0.01,-0.0001,-0.00010,1.000
1,4.000,-0.01,-0.0001,-0.00010,1.000
1,4.067,-0.01,-0.0001,-0.00010,1.000
1,4.133,-0.01,-0.0001,-0.00010,1.000
1,4.200,-0.01,-0.0001,-0.00010,1.000
1,4.267,-0.01,-0.0001,-0.00010,1.000
1,4.333,-0.01,-0.0001,-0.00010,1.000
1,4.400,-0.01,-0.0001,-0.00010,1.000
1,4.467,-0.01,-0.0001,-0.00010,1.000
1,4.533,-0.01,-0.0001,-0.00010,1.000
1,4.600,-0.02,-0.0001,-0.00010,1.000
1,4.667,-0.01,-0.0001,-0.00010,1.000
1,4.733,-0.01,-0.0001,-0.00010,1.000
1,4.800,-0.01,-0.0001,-0.00010,1.000
1,4.867,-0.01,-0.0001,-0.00010,1.000
1,4.933,-0.01,-0.0001,-0.00010,1.000
1,5.000,-0.01,-0.0001,-0.00010,1.000
1,5.067,-0.01,-0.0001,-0.00010,1.000
1,5.133,-0.01,-0.0001,-0.00010,1.000
1,5.200,-0.01,-0.0001,-0.00010,1.000
1,5.267,-0.01,-0.0001,-0.00010,1.000
1,5.333,-0.01,-0.0001,-0.00010,1.000
1,5.400,-0.01,-0.0001,-0.00010,1.000
1,5.467,-0.01,-0.0001,-0.00010,1.000
1,5.600,0.00,-0.0001,-0.00010,1.000
1,5.667,-0.01,-0.0001,-0.00010,1.000
1,5.733,-0.01,-0.0001,-0.00010,1.000
1,5.800,-0.02,-0.0001,-0.00010,1.000
1,5.867,-0.01,-0.0001,-0.00010,1.000
1,5.933,-0.01,-0.0001,-0.00010,1.000
1,6.000,-0.01,-0.0001,-0.00010,1.000
1,6.067,-0.01,-0.0001,-0.00010,1.000
1,6.133,-0.01,-0.0001,-0.00010,1.000
1,6.200,-0.02,-0.0001,-0.00010,1.000
1,6.267,-0.01,-0.0001,-0.00010,1.000
1,6.333,-0.01,-0.0001,-0.00010,1.000
1,6.400,-0.01,-0.0001,-0.00010,1.000
1,6.467,-0.01,-0.0001,-0.00010,1.000
2,6.733,-0.01,0.0878,0.08783,2.000
2,6.800,-0.01,0.1546,0.15460,2.000
2,6.867,0.00,0.2214,0.22140,2.000
2,6.933,0.00,0.2881,0.28807,2.000
2,7.000,0.01,0.3548,0.35480,2.000
2,7.067,0.02,0.4215,0.42147,2.000
2,7.133,0.05,0.4881,0.48807,2.000
2,7.200,0.10,0.5549,0.55490,2.000
2,7.267,0.16,0.6215,0.62147,2.000
2,7.333,0.25,0.6881,0.68807,2.000
2,7.400,0.36,0.7549,0.75490,2.000
2,7.467,0.49,0.8214,0.82143,2.000
2,7.533,0.63,0.8880,0.88803,2.000
2,7.600,0.80,0.9549,0.95490,2.000
2,7.667,0.99,1.0215,1.02147,2.000
2,7.800,1.02,1.0153,1.01530,2.000
2,7.867,0.78,0.9488,0.94880,2.000
2,7.933,0.60,0.8822,0.88220,2.000
2,8.000,0.44,0.8155,0.81550,2.000
2,8.067,0.31,0.7490,0.74897,2.000
2,8.133,0.20,0.6821,0.68213,2.000
2,8.200,0.11,0.6154,0.61540,2.000
2,8.267,0.06,0.5490,0.54897,2.000
2,8.333,0.03,0.4822,0.48220,2.000
2,8.400,0.00,0.4155,0.41550,2.000
2,8.467,-0.01,0.3489,0.34890,2.000
2,8.533,-0.02,0.2821,0.28210,2.000
2,8.600,-0.01,0.2154,0.21540,2.000
2,8.667,-0.01,0.1488,0.14877,2.000
2,8.733,-0.01,0.0820,0.08197,2.000
2,8.800,-0.02,0.0154,0.01540,2.000
2,8.933,-0.02,-0.0121,-0.01210,2.000
2,9.000,-0.01,-0.0001,-0.00010,2.000
2,9.067,-0.01,-0.0001,-0.00010,2.000
2,9.133,-0.01,-0.0001,-0.00010,2.000
2,9.200,-0.02,-0.0001,-0.00010,2.000
2,9.267,-0.02,-0.0001,-0.00010,2.000
2,9.333,-0.02,-0.0001,-0.00010,2.000
2,9.400,-0.01,-0.0001,-0.00010,2.000
2,9.467,-0.01,-0.0001,-0.00010,2.000
2,9.533,-0.01,-0.0001,-0.00010,2.000
2,9.600,-0.01,-0.0001,-0.00010,2.000
2,9.667,-0.01,-0.0001,-0.00010,2.000
2,9.733,-0.01,-0.0001,-0.00010,2.000
2,9.800,-0.01,-0.0001,-0.00010,2.000
2,9.867,-0.02,-0.0001,-0.00010,2.000
2,9.933,-0.02,-0.0001,-0.00010,2.000
2,10.000,-0.01,-0.0001,-0.00010,2.000
2,10.067,-0.02,-0.0001,-0.00010,2.000
2,10.133,-0.02,-0.0001,-0.00010,2.000
2,10.200,-0.02,-0.0001,-0.00010,2.000
2,10.267,-0.01,-0.0001,-0.00010,2.000
2,10.333,-0.01,-0.0001,-0.00010,2.000
2,10.400,-0.02,-0.0001,-0.00010,2.000
2,10.467,-0.01,-0.0001,-0.00010,2.000
2,10.533,-0.02,-0.0001,-0.00010,2.000
2,10.600,-0.01,-0.0001,-0.00010,2.000
2,10.667,-0.01,-0.0001,-0.00010,2.000
2,10.733,-0.02,-0.0001,-0.00010,2.000
2,10.800,-0.01,-0.0001,-0.00010,2.000
2,10.867,-0.02,-0.0001,-0.00010,2.000
2,10.933,-0.01,-0.0001,-0.00010,2.000
2,11.000,-0.02,-0.0001,-0.00010,2.000
2,11.067,-0.01,-0.0001,-0.00010,2.000
2,11.133,-0.01,-0.0001,-0.00010,2.000
2,11.200,-0.02,-0.0001,-0.00010,2.000
2,11.267,-0.02,-0.0001,-0.00010,2.000
2,11.333,-0.01,-0.0001,-0.00010,2.000
2,11.400,-0.02,-0.0001,-0.00010,2.000
2,11.467,-0.02,-0.0001,-0.00010,2.000
2,11.533,-0.01,-0.0001,-0.00010,2.000
2,11.600,-0.01,0.0000,0.00000,2.000
2,11.667,-0.01,0.0000,0.00000,2.000
2,11.733,-0.02,0.0000,0.00000,2.000
2,11.800,-0.01,0.0000,0.00000,2.000
2,11.867,-0.01,0.0000,0.00000,2.000
2,12.000,-0.02,0.0000,0.00000,2.000
2,12.067,-0.01,0.0000,0.00000,2.000
2,12.133,-0.01,0.0000,0.00000,2.000
2,12.200,-0.01,0.0000,0.00000,2.000
2,12.267,-0.01,0.0000,0.00000,2.000
2,12.333,-0.01,0.0000,0.00000,2.000
2,12.400,-0.02,0.0000,0.00000,2.000
2,12.467,-0.01,0.0000,0.00000,2.000
2,12.533,-0.01,0.0000,0.00000,2.000
2,12.600,-0.02,0.0000,0.00000,2.000
2,12.667,-0.02,0.0000,0.00000,2.000
2,12.733,-0.01,0.0000,0.00000,2.000
2,12.800,-0.01,0.0000,0.00000,2.000
2,12.867,-0.01,0.0000,0.00000,2.000
3,13.133,0.00,0.0680,0.06800,3.000
3,13.200,0.00,0.1346,0.13460,3.000
3,13.267,0.01,0.2013,0.20133,3.000
3,13.333,0.02,0.2682,0.26820,3.000
3,13.400,0.02,0.3347,0.33470,3.000
3,13.467,0.03,0.4014,0.40137,3.000
3,13.533,0.05,0.4681,0.46813,3.000
3,13.600,0.09,0.5348,0.53480,3.000
3,13.667,0.15,0.6015,0.60150,3.000
3,13.733,0.23,0.6682,0.66820,3.000
3,13.800,0.33,0.7347,0.73470,3.000
3,13.867,0.46,0.8014,0.80143,3.000
3,13.933,0.60,0.8682,0.86820,3.000
3,14.000,0.76,0.9347,0.93470,3.000
3,14.067,0.95,1.0014,1.00143,3.000
3,14.200,1.10,1.0351,1.03510,3.000
3,14.267,0.86,0.9688,0.96880,3.000
3,14.333,0.66,0.9022,0.90217,3.000
3,14.400,0.49,0.8355,0.83550,3.000
3,14.467,0.36,0.7688,0.76880,3.000
3,14.533,0.24,0.7022,0.70220,3.000
3,14.600,0.15,0.6356,0.63560,3.000
3,14.667,0.08,0.5688,0.56877,3.000
3,14.733,0.04,0.5022,0.50223,3.000
3,14.800,0.01,0.4356,0.43560,3.000
3,14.867,0.00,0.3688,0.36880,3.000
3,14.933,0.00,0.3022,0.30223,3.000
3,15.000,0.00,0.2354,0.23540,3.000
3,15.067,-0.01,0.1687,0.16867,3.000
3,15.133,0.00,0.1020,0.10203,3.000
3,15.200,0.00,0.0354,0.03540,3.000
3,15.333,-0.01,-0.0311,-0.03107,3.000
3,15.400,-0.01,-0.0001,-0.00010,3.000
3,15.467,-0.01,-0.0001,-0.00010,3.000
3,15.533,-0.01,-0.0001,-0.00010,3.000
3,15.600,0.00,-0.0001,-0.00010,3.000
3,15.667,0.00,-0.0001,-0.00010,3.000
3,15.733,0.00,-0.0001,-0.00010,3.000
3,15.800,0.00,-0.0001,-0.00010,3.000
3,15.867,-0.01,-0.0001,-0.00010,3.000
3,15.933,-0.01,-0.0001,-0.00010,3.000
3,16.000,0.00,-0.0001,-0.00010,3.000
3,16.067,0.00,-0.0001,-0.00010,3.000
3,16.133,0.00,-0.0001,-0.00010,3.000
3,16.200,0.00,-0.0001,-0.00010,3.000
3,16.267,0.00,-0.0001,-0.00010,3.000
3,16.333,0.00,-0.0001,-0.00010,3.000
3,16.400,0.00,-0.0001,-0.00010,3.000
3,16.467,0.00,-0.0001,-0.00010,3.000
3,16.533,0.00,-0.0001,-0.00010,3.000
3,16.600,-0.01,-0.0001,-0.00010,3.000
3,16.667,0.00,-0.0001,-0.00010,3.000
3,16.733,0.00,-0.0001,-0.00010,3.000
3,16.800,0.00,-0.0001,-0.00010,3.000
3,16.867,-0.01,-0.0001,-0.00010,3.000
3,16.933,-0.01,-0.0001,-0.00010,3.000
3,17.000,-0.01,-0.0001,-0.00010,3.000
3,17.067,-0.01,-0.0001,-0.00010,3.000
3,17.133,-0.01,-0.0001,-0.00010,3.000
3,17.200,0.00,-0.0001,-0.00010,3.000
3,17.267,0.00,-0.0001,-0.00010,3.000
3,17.333,-0.01,-0.0001,-0.00010,3.000
3,17.400,0.00,-0.0001,-0.00010,3.000
3,17.467,0.00,-0.0001,-0.00010,3.000
3,17.533,0.00,-0.0001,-0.00010,3.000
3,17.600,0.00,-0.0001,-0.00010,3.000
3,17.667,0.00,-0.0001,-0.00010,3.000
3,17.733,0.00,-0.0001,-0.00010,3.000
3,17.800,0.00,-0.0001,-0.00010,3.000
3,17.867,0.00,-0.0001,-0.00010,3.000
3,17.933,0.00,-0.0001,-0.00010,3.000
3,18.000,-0.01,-0.0001,-0.00010,3.000
3,18.067,0.00,-0.0001,-0.00010,3.000
3,18.133,0.00,-0.0001,-0.00010,3.000
3,18.200,0.00,-0.0001,-0.00010,3.000
3,18.267,0.00,0.0000,0.00000,3.000
3,18.467,0.00,0.0000,0.00000,3.000
3,18.533,0.00,0.0000,0.00000,3.000
3,18.600,0.00,0.0000,0.00000,3.000
3,18.667,-0.01,0.0000,0.00000,3.000
3,18.733,0.00,0.0000,0.00000,3.000
3,18.800,0.00,0.0000,0.00000,3.000
3,18.867,0.00,0.0000,0.00000,3.000
3,18.933,0.00,0.0000,0.00000,3.000
3,19.000,0.00,0.0000,0.00000,3.000
3,19.067,-0.01,0.0000,0.00000,3.000
3,19.133,0.00,0.0000,0.00000,3.000
3,19.200,0.00,0.0000,0.00000,3.000
3,19.267,0.00,0.0000,0.00000,3.000
3,19.333,0.00,0.0000,0.00000,3.000
4,19.600,0.01,0.1137,0.11370,4.000
4,19.667,0.01,0.1804,0.18040,4.000
4,19.733,0.02,0.2470,0.24700,4.000
4,19.800,0.03,0.3139,0.31390,4.000
4,19.867,0.03,0.3804,0.38043,4.000
4,19.933,0.04,0.4471,0.44713,4.000
4,20.000,0.08,0.5138,0.51380,4.000
4,20.067,0.13,0.5804,0.58043,4.000
4,20.133,0.21,0.6471,0.64710,4.000
4,20.200,0.31,0.7139,0.71390,4.000
4,20.267,0.42,0.7804,0.78040,4.000
4,20.333,0.56,0.8471,0.84707,4.000
4,20.400,0.72,0.9139,0.91390,4.000
4,20.467,0.89,0.9804,0.98043,4.000
4,20.667,1.01,1.0097,1.00967,4.000
4,20.733,0.78,0.9432,0.94317,4.000
4,20.800,0.59,0.8765,0.87650,4.000
4,20.867,0.44,0.8098,0.80980,4.000
4,20.933,0.31,0.7432,0.74323,4.000
4,21.000,0.21,0.6765,0.67650,4.000
4,21.067,0.13,0.6098,0.60977,4.000
4,21.133,0.07,0.5432,0.54317,4.000
4,21.200,0.03,0.4765,0.47650,4.000
4,21.267,0.02,0.4098,0.40983,4.000
4,21.333,0.01,0.3432,0.34323,4.000
4,21.400,0.01,0.2766,0.27660,4.000
4,21.467,0.01,0.2097,0.20970,4.000
4,21.533,0.01,0.1431,0.14307,4.000
4,21.600,0.01,0.0763,0.07630,4.000
4,21.667,0.01,0.0096,0.00963,4.000
4,21.800,0.01,-0.0232,-0.02320,4.000
4,21.867,0.01,-0.0001,-0.00010,4.000
4,21.933,0.01,-0.0001,-0.00010,4.000
4,22.000,0.01,-0.0001,-0.00010,4.000
4,22.067,0.01,-0.0001,-0.00010,4.000
4,22.133,0.00,-0.0001,-0.00010,4.000
4,22.200,0.00,-0.0001,-0.00010,4.000
4,22.267,0.01,-0.0001,-0.00010,4.000
4,22.333,0.00,-0.0001,-0.00010,4.000
4,22.400,0.01,-0.0001,-0.00010,4.000
4,22.467,0.00,-0.0001,-0.00010,4.000
4,22.533,0.01,-0.0001,-0.00010,4.000
4,22.600,0.01,-0.0001,-0.00010,4.000
4,22.667,0.01,-0.0001,-0.00010,4.000
4,22.733,0.01,-0.0001,-0.00010,4.000
4,22.800,0.01,-0.0001,-0.00010,4.000
4,22.867,0.01,-0.0001,-0.00010,4.000
4,22.933,0.00,-0.0001,-0.00010,4.000
4,23.000,0.00,-0.0001,-0.00010,4.000
4,23.067,0.01,-0.0001,-0.00010,4.000
4,23.133,0.01,-0.0001,-0.00010,4.000
4,23.200,0.00,-0.0001,-0.00010,4.000
4,23.267,0.00,-0.0001,-0.00010,4.000
4,23.333,0.01,-0.0001,-0.00010,4.000
4,23.400,0.01,-0.0001,-0.00010,4.000
4,23.467,0.00,-0.0001,-0.00010,4.000
4,23.533,0.01,-0.0001,-0.00010,4.000
4,23.600,0.00,-0.0001,-0.00010,4.000
4,23.667,0.01,-0.0001,-0.00010,4.000
4,23.733,0.01,-0.0001,-0.00010,4.000
4,23.800,0.00,-0.0001,-0.00010,4.000
4,23.867,0.00,-0.0001,-0.00010,4.000
4,23.933,0.01,-0.0001,-0.00010,4.000
4,24.000,0.01,-0.0001,-0.00010,4.000
4,24.067,0.01,-0.0001,-0.00010,4.000
4,24.133,0.00,-0.0001,-0.00010,4.000
4,24.200,0.01,-0.0001,-0.00010,4.000
4,24.267,0.01,-0.0001,-0.00010,4.000
4,24.333,0.01,-0.0001,-0.00010,4.000
4,24.400,0.01,-0.0001,-0.00010,4.000
4,24.467,0.01,-0.0001,-0.00010,4.000
4,24.533,0.01,-0.0001,-0.00010,4.000
4,24.600,0.01,-0.0001,-0.00010,4.000
4,24.667,0.01,-0.0001,-0.00010,4.000
4,24.733,0.01,-0.0001,-0.00010,4.000
4,24.867,0.01,-0.0001,-0.00010,4.000
4,24.933,0.01,-0.0001,-0.00010,4.000
4,25.000,0.01,0.0000,0.00000,4.000
4,25.067,0.01,0.0000,0.00000,4.000
4,25.133,0.01,0.0000,0.00000,4.000
4,25.200,0.01,0.0000,0.00000,4.000
4,25.267,0.01,0.0000,0.00000,4.000
4,25.333,0.01,0.0000,0.00000,4.000
4,25.400,0.01,0.0000,0.00000,4.000
4,25.467,0.01,0.0000,0.00000,4.000
4,25.533,0.00,0.0000,0.00000,4.000
4,25.600,0.01,0.0000,0.00000,4.000
4,25.667,0.00,0.0000,0.00000,4.000
4,25.733,0.00,0.0000,0.00000,4.000
4,25.800,0.01,0.0000,0.00000,4.000
5,26.000,0.00,0.0536,0.05360,5.000
5,26.067,0.00,0.1202,0.12020,5.000
5,26.133,0.01,0.1870,0.18700,5.000
5,26.200,0.01,0.2538,0.25380,5.000
5,26.267,0.02,0.3205,0.32050,5.000
5,26.333,0.02,0.3871,0.38710,5.000
5,26.400,0.04,0.4538,0.45380,5.000
5,26.467,0.08,0.5205,0.52047,5.000
5,26.533,0.14,0.5871,0.58713,5.000
5,26.600,0.21,0.6538,0.65380,5.000
5,26.667,0.31,0.7204,0.72043,5.000
5,26.733,0.43,0.7872,0.78720,5.000
5,26.800,0.57,0.8537,0.85370,5.000
5,26.867,0.72,0.9204,0.92040,5.000
5,26.933,0.90,0.9872,0.98720,5.000
5,27.000,1.11,1.0537,1.05370,5.000
5,27.067,1.20,1.0655,1.06547,5.000
5,27.133,0.97,1.0012,1.00117,5.000
5,27.200,0.74,0.9344,0.93440,5.000
5,27.267,0.57,0.8678,0.86783,5.000
5,27.333,0.42,0.8011,0.80113,5.000
5,27.400,0.30,0.7345,0.73450,5.000
5,27.467,0.19,0.6679,0.66793,5.000
5,27.533,0.11,0.6012,0.60117,5.000
5,27.600,0.06,0.5344,0.53440,5.000
5,27.667,0.02,0.4679,0.46793,5.000
5,27.733,0.01,0.4012,0.40117,5.000
5,27.800,0.00,0.3344,0.33440,5.000
5,27.867,0.00,0.2679,0.26790,5.000
5,27.933,0.00,0.2010,0.20103,5.000
5,28.000,0.00,0.1344,0.13440,5.000
5,28.067,0.00,0.0677,0.06773,5.000
5,28.133,0.00,0.0011,0.00110,5.000
5,28.267,0.00,-0.0179,-0.01787,5.000
5,28.333,0.00,-0.0001,-0.00010,5.000
5,28.400,0.00,-0.0001,-0.00010,5.000
5,28.467,0.00,-0.0001,-0.00010,5.000
5,28.533,0.00,-0.0001,-0.00010,5.000
5,28.600,0.00,-0.0001,-0.00010,5.000
5,28.667,0.00,-0.0001,-0.00010,5.000
5,28.733,-0.01,-0.0001,-0.00010,5.000
5,28.800,0.00,-0.0001,-0.00010,5.000
5,28.867,0.00,-0.0001,-0.00010,5.000
5,28.933,0.00,-0.0001,-0.00010,5.000
5,29.000,0.00,-0.0001,-0.00010,5.000
5,29.067,0.00,-0.0001,-0.00010,5.000
5,29.133,0.00,-0.0001,-0.00010,5.000
5,29.200,0.00,-0.0001,-0.00010,5.000
5,29.267,0.00,-0.0001,-0.00010,5.000
5,29.333,0.00,-0.0001,-0.00010,5.000
5,29.400,0.00,-0.0001,-0.00010,5.000
5,29.467,0.00,-0.0001,-0.00010,5.000
5,29.533,0.00,-0.0001,-0.00010,5.000
5,29.600,0.00,-0.0001,-0.00010,5.000
5,29.667,0.00,-0.0001,-0.00010,5.000
5,29.733,0.00,-0.0001,-0.00010,5.000
5,29.800,0.00,-0.0001,-0.00010,5.000
5,29.867,0.00,-0.0001,-0.00010,5.000
5,29.933,0.00,-0.0001,-0.00010,5.000
5,30.000,0.00,-0.0001,-0.00010,5.000
5,30.067,0.00,-0.0001,-0.00010,5.000
5,30.133,0.00,-0.0001,-0.00010,5.000
5,30.200,0.00,-0.0001,-0.00010,5.000
5,30.267,0.00,-0.0001,-0.00010,5.000
5,30.333,0.00,-0.0001,-0.00010,5.000
5,30.400,0.00,-0.0001,-0.00010,5.000
5,30.467,0.00,-0.0001,-0.00010,5.000
5,30.533,0.00,-0.0001,-0.00010,5.000
5,30.600,0.00,-0.0001,-0.00010,5.000
5,30.667,0.00,-0.0001,-0.00010,5.000
5,30.733,0.00,-0.0001,-0.00010,5.000
5,30.800,0.00,-0.0001,-0.00010,5.000
5,30.867,0.00,-0.0001,-0.00010,5.000
5,30.933,0.00,-0.0001,-0.00010,5.000
5,31.000,0.00,-0.0001,-0.00010,5.000
5,31.067,0.00,-0.0001,-0.00010,5.000
5,31.133,0.00,-0.0001,-0.00010,5.000
5,31.200,-0.01,-0.0001,-0.00010,5.000
5,31.333,0.00,-0.0001,-0.00010,5.000
5,31.400,-0.01,-0.0001,-0.00010,5.000
5,31.467,0.00,-0.0001,-0.00010,5.000
5,31.533,0.00,0.0000,0.00000,5.000
5,31.600,-0.01,0.0000,0.00000,5.000
5,31.667,-0.01,0.0000,0.00000,5.000
5,31.733,0.00,0.0000,0.00000,5.000
5,31.800,0.00,0.0000,0.00000,5.000
5,31.867,0.00,0.0000,0.00000,5.000
5,31.933,0.00,0.0000,0.00000,5.000
5,32.000,0.00,0.0000,0.00000,5.000
5,32.067,0.00,0.0000,0.00000,5.000
5,32.133,0.00,0.0000,0.00000,5.000
5,32.200,0.00,0.0000,0.00000,5.000
6,32.533,0.01,0.0919,0.09187,6.000
6,32.600,0.02,0.1586,0.15860,6.000
6,32.667,0.02,0.2254,0.22540,6.000
6,32.733,0.02,0.2920,0.29203,6.000
6,32.800,0.03,0.3588,0.35880,6.000
6,32.867,0.04,0.4255,0.42553,6.000
6,32.933,0.06,0.4920,0.49203,6.000
6,33.000,0.11,0.5589,0.55890,6.000
6,33.067,0.18,0.6255,0.62553,6.000
6,33.133,0.27,0.6921,0.69207,6.000
6,33.200,0.38,0.7589,0.75890,6.000
6,33.267,0.51,0.8255,0.82550,6.000
6,33.333,0.66,0.8920,0.89200,6.000
6,33.400,0.83,0.9589,0.95890,6.000
6,33.467,1.02,1.0255,1.02550,6.000
6,33.600,1.05,1.0193,1.01930,6.000
6,33.667,0.81,0.9529,0.95290,6.000
6,33.733,0.62,0.8861,0.88610,6.000
6,33.800,0.46,0.8196,0.81960,6.000
6,33.867,0.33,0.7529,0.75290,6.000
6,33.933,0.22,0.6861,0.68613,6.000
6,34.000,0.14,0.6195,0.61950,6.000
6,34.067,0.08,0.5528,0.55283,6.000
6,34.133,0.03,0.4861,0.48613,6.000
6,34.200,0.02,0.4194,0.41940,6.000
6,34.267,0.01,0.3529,0.35287,6.000
6,34.333,0.01,0.2862,0.28617,6.000
6,34.400,0.01,0.2195,0.21950,6.000
6,34.467,0.01,0.1528,0.15277,6.000
6,34.533,0.01,0.0859,0.08593,6.000
6,34.600,0.01,0.0194,0.01940,6.000
6,34.733,0.01,-0.0092,-0.00917,6.000
6,34.800,0.00,0.0000,0.00000,6.000
6,34.867,0.00,0.0000,-0.00003,6.000
6,34.933,0.00,0.0000,0.00000,6.000
6,35.000,0.00,0.0000,0.00000,6.000
6,35.067,0.00,0.0000,0.00000,6.000
6,35.133,0.01,0.0000,0.00000,6.000
6,35.200,0.01,0.0000,0.00000,6.000
6,35.267,0.00,0.0000,0.00000,6.000
6,35.333,0.00,0.0000,0.00000,6.000
6,35.400,0.01,0.0000,0.00000,6.000
6,35.467,0.00,0.0000,0.00000,6.000
6,35.533,0.00,0.0000,0.00000,6.000
6,35.600,0.00,0.0000,0.00000,6.000
6,35.667,0.01,0.0000,0.00000,6.000
6,35.733,0.00,0.0000,0.00000,6.000
6,35.800,0.01,0.0000,0.00000,6.000
6,35.867,0.00,0.0000,0.00000,6.000
6,35.933,0.00,0.0000,0.00000,6.000
6,36.000,0.01,0.0000,0.00000,6.000
6,36.067,0.00,0.0000,0.00000,6.000
6,36.133,0.00,0.0000,0.00000,6.000
6,36.200,0.00,0.0000,0.00000,6.000
6,36.267,0.01,0.0000,0.00000,6.000
6,36.333,0.00,0.0000,0.00000,6.000
6,36.400,0.01,0.0000,0.00000,6.000
6,36.467,0.01,0.0000,0.00000,6.000
6,36.533,0.01,0.0000,0.00000,6.000
6,36.600,0.00,0.0000,0.00000,6.000
6,36.667,0.01,0.0000,0.00000,6.000
6,36.733,0.01,0.0000,0.00000,6.000
6,36.800,0.00,0.0000,0.00000,6.000
6,36.867,0.00,0.0000,0.00000,6.000
6,36.933,0.00,0.0000,0.00000,6.000
6,37.000,0.00,0.0000,0.00000,6.000
6,37.067,0.01,0.0000,0.00000,6.000
6,37.133,0.01,0.0000,0.00000,6.000
6,37.200,0.01,0.0000,0.00000,6.000
6,37.267,0.01,0.0000,0.00000,6.000
6,37.333,0.01,0.0000,0.00000,6.000
6,37.400,0.01,0.0000,0.00000,6.000
6,37.467,0.01,0.0000,0.00000,6.000
6,37.533,0.01,0.0000,0.00000,6.000
6,37.600,0.01,0.0000,0.00000,6.000
6,37.667,0.01,0.0000,0.00000,6.000
6,37.800,0.01,0.0000,0.00000,6.000
6,37.867,0.01,0.0000,0.00000,6.000
6,37.933,0.01,0.0000,0.00000,6.000
6,38.000,0.01,0.0000,0.00000,6.000
6,38.067,0.01,0.0000,0.00000,6.000
6,38.133,0.01,0.0000,0.00000,6.000
6,38.200,0.01,0.0000,0.00000,6.000
6,38.267,0.01,0.0000,0.00000,6.000
6,38.333,0.01,0.0000,0.00000,6.000
6,38.400,0.01,0.0000,0.00000,6.000
6,38.467,0.01,0.0000,0.00000,6.000
6,38.533,0.01,0.0000,0.00000,6.000
6,38.600,0.01,0.0000,0.00000,6.000
6,38.667,0.01,0.0000,0.00000,6.000
7,38.933,0.00,0.0569,0.05690,7.000
7,39.000,0.01,0.1234,0.12340,7.000
7,39.067,0.01,0.1904,0.19040,7.000
7,39.133,0.01,0.2571,0.25707,7.000
7,39.200,0.02,0.3237,0.32370,7.000
7,39.267,0.03,0.3905,0.39047,7.000
7,39.333,0.04,0.4571,0.45707,7.000
7,39.400,0.08,0.5238,0.52380,7.000
7,39.467,0.14,0.5905,0.59050,7.000
7,39.533,0.22,0.6570,0.65700,7.000
7,39.600,0.32,0.7237,0.72370,7.000
7,39.667,0.44,0.7905,0.79050,7.000
7,39.733,0.57,0.8570,0.85703,7.000
7,39.800,0.73,0.9238,0.92380,7.000
7,39.867,0.91,0.9905,0.99050,7.000
7,40.000,1.14,1.0447,1.04470,7.000
7,40.067,0.90,0.9777,0.97770,7.000
7,40.133,0.69,0.9112,0.91117,7.000
7,40.200,0.52,0.8444,0.84440,7.000
7,40.267,0.38,0.7778,0.77783,7.000
7,40.333,0.26,0.7112,0.71123,7.000
7,40.400,0.16,0.6443,0.64430,7.000
7,40.467,0.09,0.5778,0.57780,7.000
7,40.533,0.04,0.5112,0.51123,7.000
7,40.600,0.02,0.4444,0.44440,7.000
7,40.667,0.01,0.3778,0.37783,7.000
7,40.733,0.01,0.3112,0.31123,7.000
7,40.800,0.01,0.2444,0.24440,7.000
7,40.867,0.01,0.1777,0.17770,7.000
7,40.933,0.00,0.1109,0.11093,7.000
7,41.000,0.00,0.0442,0.04420,7.000
7,41.200,0.00,0.0004,0.00040,7.000
7,41.267,0.00,-0.0001,-0.00010,7.000
7,41.333,0.00,-0.0001,-0.00010,7.000
7,41.400,0.00,-0.0001,-0.00010,7.000
7,41.467,0.00,-0.0001,-0.00010,7.000
7,41.533,0.00,-0.0001,-0.00010,7.000
7,41.600,0.00,-0.0001,-0.00010,7.000
7,41.667,0.00,-0.0001,-0.00010,7.000
7,41.733,0.00,-0.0001,-0.00010,7.000
7,41.800,0.00,-0.0001,-0.00010,7.000
7,41.867,0.01,-0.0001,-0.00010,7.000
7,41.933,0.00,-0.0001,-0.00010,7.000
7,42.000,0.00,-0.0001,-0.00010,7.000
7,42.067,0.00,-0.0001,-0.00010,7.000
7,42.133,0.00,-0.0001,-0.00010,7.000
7,42.200,0.00,-0.0001,-0.00010,7.000
7,42.267,0.00,-0.0001,-0.00010,7.000
7,42.333,0.00,-0.0001,-0.00010,7.000
7,42.400,0.00,-0.0001,-0.00010,7.000
7,42.467,0.00,-0.0001,-0.00010,7.000
7,42.533,0.00,-0.0001,-0.00010,7.000
7,42.600,0.00,-0.0001,-0.00010,7.000
7,42.667,0.00,-0.0001,-0.00010,7.000
7,42.733,0.00,-0.0001,-0.00010,7.000
7,42.800,0.00,-0.0001,-0.00010,7.000
7,42.867,0.00,-0.0001,-0.00010,7.000
7,42.933,0.00,-0.0001,-0.00010,7.000
7,43.000,0.00,-0.0001,-0.00010,7.000
7,43.067,0.00,-0.0001,-0.00010,7.000
7,43.133,0.00,-0.0001,-0.00010,7.000
7,43.200,0.00,-0.0001,-0.00010,7.000
7,43.267,-0.01,-0.0001,-0.00010,7.000
7,43.333,0.00,-0.0001,-0.00010,7.000
7,43.400,0.00,-0.0001,-0.00010,7.000
7,43.467,0.00,-0.0001,-0.00010,7.000
7,43.533,0.00,-0.0001,-0.00010,7.000
7,43.600,0.00,-0.0001,-0.00010,7.000
7,43.667,0.00,-0.0001,-0.00010,7.000
7,43.733,0.00,-0.0001,-0.00010,7.000
7,43.800,0.00,-0.0001,-0.00010,7.000
7,43.867,0.00,-0.0001,-0.00010,7.000
7,43.933,0.00,-0.0001,-0.00010,7.000
7,44.000,0.00,-0.0001,-0.00010,7.000
7,44.067,0.00,-0.0001,-0.00010,7.000
7,44.267,0.00,-0.0001,-0.00010,7.000
7,44.333,0.00,-0.0001,-0.00010,7.000
7,44.400,0.01,-0.0001,-0.00010,7.000
7,44.467,0.00,-0.0001,-0.00010,7.000
7,44.533,0.00,-0.0001,-0.00010,7.000
7,44.600,0.00,-0.0001,-0.00010,7.000
7,44.667,0.00,0.0000,0.00000,7.000
7,44.733,0.00,0.0000,0.00000,7.000
7,44.800,0.00,0.0000,0.00000,7.000
7,44.867,0.00,0.0000,0.00000,7.000
7,44.933,0.00,0.0000,0.00000,7.000
7,45.000,0.00,0.0000,0.00000,7.000
7,45.067,0.00,0.0000,0.00000,7.000
7,45.133,0.00,0.0000,0.00000,7.000
8,45.400,0.01,0.0976,0.09760,8.000
8,45.467,0.00,0.1642,0.16423,8.000
8,45.533,0.01,0.2311,0.23110,8.000
8,45.600,0.01,0.2978,0.29780,8.000
8,45.667,0.02,0.3644,0.36437,8.000
8,45.733,0.04,0.4312,0.43120,8.000
8,45.800,0.06,0.4977,0.49770,8.000
8,45.867,0.11,0.5644,0.56440,8.000
8,45.933,0.17,0.6312,0.63123,8.000
8,46.000,0.27,0.6977,0.69770,8.000
8,46.067,0.38,0.7644,0.76443,8.000
8,46.133,0.52,0.8312,0.83117,8.000
8,46.200,0.66,0.8976,0.89760,8.000
8,46.267,0.84,0.9644,0.96440,8.000
8,46.333,1.03,1.0312,1.03120,8.000
8,46.467,1.01,1.0118,1.01177,8.000
8,46.533,0.78,0.9451,0.94510,8.000
8,46.600,0.60,0.8784,0.87840,8.000
8,46.667,0.44,0.8118,0.81183,8.000
8,46.733,0.31,0.7452,0.74523,8.000
8,46.800,0.21,0.6785,0.67850,8.000
8,46.867,0.12,0.6117,0.61170,8.000
8,46.933,0.05,0.5452,0.54523,8.000
8,47.000,0.03,0.4786,0.47860,8.000
8,47.067,0.01,0.4118,0.41180,8.000
8,47.133,0.01,0.3452,0.34520,8.000
8,47.200,0.01,0.2785,0.27850,8.000
8,47.267,0.00,0.2117,0.21173,8.000
8,47.333,0.00,0.1451,0.14507,8.000
8,47.400,0.00,0.0783,0.07830,8.000
8,47.467,0.00,0.0117,0.01167,8.000
8,47.600,0.00,-0.0069,-0.00690,8.000
8,47.667,0.00,-0.0001,-0.00010,8.000
8,47.733,0.00,-0.0001,-0.00010,8.000
8,47.800,0.01,-0.0001,-0.00010,8.000
8,47.867,0.00,-0.0001,-0.00010,8.000
8,47.933,-0.01,-0.0001,-0.00010,8.000
8,48.000,0.00,-0.0001,-0.00010,8.000
8,48.067,-0.01,-0.0001,-0.00010,8.000
8,48.133,0.01,-0.0001,-0.00010,8.000
8,48.200,-0.01,-0.0001,-0.00010,8.000
8,48.267,0.00,-0.0001,-0.00010,8.000
8,48.333,0.00,-0.0001,-0.00010,8.000
8,48.400,-0.01,-0.0001,-0.00010,8.000
8,48.467,0.00,-0.0001,-0.00010,8.000
8,48.533,0.00,-0.0001,-0.00010,8.000
8,48.600,-0.01,-0.0001,-0.00010,8.000
8,48.667,0.00,-0.0001,-0.00010,8.000
8,48.733,0.00,-0.0001,-0.00010,8.000
8,48.800,0.00,-0.0001,-0.00010,8.000
8,48.867,0.00,-0.0001,-0.00010,8.000
8,48.933,0.00,-0.0001,-0.00010,8.000
8,49.000,0.00,-0.0001,-0.00010,8.000
8,49.067,0.00,-0.0001,-0.00010,8.000
8,49.133,0.00,-0.0001,-0.00010,8.000
8,49.200,0.00,-0.0001,-0.00010,8.000
8,49.267,0.00,-0.0001,-0.00010,8.000
8,49.333,-0.01,-0.0001,-0.00010,8.000
8,49.400,0.00,-0.0001,-0.00010,8.000
8,49.467,0.00,-0.0001,-0.00010,8.000
8,49.533,-0.01,-0.0001,-0.00010,8.000
8,49.600,0.00,-0.0001,-0.00010,8.000
8,49.667,0.00,-0.0001,-0.00010,8.000
8,49.733,0.00,-0.0001,-0.00010,8.000
8,49.800,0.00,-0.0001,-0.00010,8.000
8,49.867,0.00,-0.0001,-0.00010,8.000
8,49.933,0.00,-0.0001,-0.00010,8.000
8,50.000,0.00,-0.0001,-0.00010,8.000
8,50.067,0.00,-0.0001,-0.00010,8.000
8,50.133,0.00,-0.0001,-0.00010,8.000
8,50.200,0.00,-0.0001,-0.00010,8.000
8,50.267,0.00,-0.0001,-0.00010,8.000
8,50.333,0.00,-0.0001,-0.00010,8.000
8,50.400,0.00,-0.0001,-0.00010,8.000
8,50.467,0.00,-0.0001,-0.00010,8.000
8,50.533,0.00,-0.0001,-0.00007,8.000
8,50.667,0.00,0.0000,0.00000,8.000
8,50.733,-0.01,0.0000,0.00000,8.000
8,50.800,0.00,0.0000,0.00000,8.000
8,50.867,0.01,0.0000,0.00000,8.000
8,50.933,0.00,0.0000,0.00000,8.000
8,51.000,0.00,0.0000,0.00000,8.000
8,51.067,0.00,0.0000,0.00000,8.000
8,51.133,0.00,0.0000,0.00000,8.000
8,51.200,0.00,0.0000,0.00000,8.000
8,51.267,0.00,0.0000,0.00000,8.000
8,51.333,0.01,0.0000,0.00000,8.000
8,51.400,0.00,0.0000,0.00000,8.000
8,51.467,0.00,0.0000,0.00000,8.000
8,51.533,0.00,0.0000,0.00000,8.000
9,51.800,0.01,0.0746,0.07460,9.000
9,51.867,0.01,0.1413,0.14130,9.000
9,51.933,0.01,0.2080,0.20797,9.000
9,52.000,0.02,0.2748,0.27480,9.000
9,52.067,0.02,0.3415,0.34153,9.000
9,52.133,0.03,0.4080,0.40800,9.000
9,52.200,0.05,0.4749,0.47490,9.000
9,52.267,0.09,0.5415,0.54150,9.000
9,52.333,0.16,0.6081,0.60807,9.000
9,52.400,0.24,0.6749,0.67490,9.000
9,52.467,0.35,0.7415,0.74147,9.000
9,52.533,0.47,0.8081,0.80813,9.000
9,52.600,0.61,0.8748,0.87480,9.000
9,52.667,0.78,0.9414,0.94137,9.000
9,52.733,0.97,1.0081,1.00807,9.000
9,52.867,1.08,1.0288,1.02883,9.000
9,52.933,0.84,0.9621,0.96210,9.000
9,53.000,0.65,0.8953,0.89530,9.000
9,53.067,0.48,0.8289,0.82890,9.000
9,53.133,0.35,0.7621,0.76213,9.000
9,53.200,0.23,0.6954,0.69540,9.000
9,53.267,0.15,0.6289,0.62887,9.000
9,53.333,0.08,0.5621,0.56213,9.000
9,53.400,0.03,0.4954,0.49540,9.000
9,53.467,0.01,0.4290,0.42897,9.000
9,53.533,0.01,0.3621,0.36210,9.000
9,53.600,0.01,0.2954,0.29540,9.000
9,53.667,0.01,0.2288,0.22883,9.000
9,53.733,0.00,0.1621,0.16207,9.000
9,53.800,0.00,0.0953,0.09530,9.000
9,53.867,0.00,0.0288,0.02877,9.000
9,54.000,0.00,-0.0254,-0.02540,9.000
9,54.067,-0.01,-0.0001,-0.00010,9.000
9,54.133,0.00,-0.0001,-0.00010,9.000
9,54.200,0.00,-0.0001,-0.00010,9.000
9,54.267,-0.01,-0.0001,-0.00010,9.000
9,54.333,0.00,-0.0001,-0.00010,9.000
9,54.400,0.00,-0.0001,-0.00010,9.000
9,54.467,0.00,-0.0001,-0.00010,9.000
9,54.533,0.00,-0.0001,-0.00010,9.000
9,54.600,0.01,-0.0001,-0.00010,9.000
9,54.667,0.00,-0.0001,-0.00010,9.000
9,54.733,0.00,-0.0001,-0.00010,9.000
9,54.800,0.00,-0.0001,-0.00010,9.000
9,54.867,0.00,-0.0001,-0.00010,9.000
9,54.933,0.00,-0.0001,-0.00010,9.000
9,55.000,0.00,-0.0001,-0.00010,9.000
9,55.067,0.00,-0.0001,-0.00010,9.000
9,55.133,0.00,-0.0001,-0.00010,9.000
9,55.200,0.00,-0.0001,-0.00010,9.000
9,55.267,0.00,-0.0001,-0.00010,9.000
9,55.333,0.00,-0.0001,-0.00010,9.000
9,55.400,0.00,-0.0001,-0.00010,9.000
9,55.467,0.00,-0.0001,-0.00010,9.000
9,55.533,0.00,-0.0001,-0.00010,9.000
9,55.600,0.00,-0.0001,-0.00010,9.000
9,55.667,0.00,-0.0001,-0.00010,9.000
9,55.733,0.00,-0.0001,-0.00010,9.000
9,55.800,0.00,-0.0001,-0.00010,9.000
9,55.867,0.00,-0.0001,-0.00010,9.000
9,55.933,0.00,-0.0001,-0.00010,9.000
9,56.000,0.00,-0.0001,-0.00010,9.000
9,56.067,0.00,-0.0001,-0.00010,9.000
9,56.133,0.00,-0.0001,-0.00010,9.000
9,56.200,0.00,-0.0001,-0.00010,9.000
9,56.267,0.00,-0.0001,-0.00010,9.000
9,56.333,0.01,-0.0001,-0.00010,9.000
9,56.400,0.00,-0.0001,-0.00010,9.000
9,56.467,0.00,-0.0001,-0.00010,9.000
9,56.533,0.00,-0.0001,-0.00010,9.000
9,56.600,0.00,-0.0001,-0.00010,9.000
9,56.667,0.00,-0.0001,-0.00010,9.000
9,56.733,0.00,-0.0001,-0.00010,9.000
9,56.800,0.01,-0.0001,-0.00010,9.000
9,56.867,0.00,-0.0001,-0.00010,9.000
9,56.933,0.00,-0.0001,-0.00010,9.000
9,57.067,0.00,0.0000,0.00000,9.000
9,57.133,0.00,0.0000,0.00000,9.000
9,57.200,0.00,0.0000,0.00000,9.000
9,57.267,0.00,0.0000,0.00000,9.000
9,57.333,0.00,0.0000,0.00000,9.000
9,57.400,0.00,0.0000,0.00000,9.000
9,57.467,0.00,0.0000,0.00000,9.000
9,57.533,0.00,0.0000,0.00000,9.000
9,57.600,0.00,0.0000,0.00000,9.000
9,57.667,0.00,0.0000,0.00000,9.000
9,57.733,0.00,0.0000,0.00000,9.000
9,57.800,0.00,0.0000,0.00000,9.000
9,57.867,0.00,0.0000,0.00000,9.000
9,57.933,0.00,0.0000,0.00000,9.000
10,58.267,0.01,0.0952,0.09523,10.000
10,58.333,0.01,0.1620,0.16197,10.000
10,58.400,0.01,0.2288,0.22880,10.000
10,58.467,0.02,0.2954,0.29537,10.000
10,58.533,0.03,0.3621,0.36213,10.000
10,58.600,0.04,0.4289,0.42890,10.000
10,58.667,0.07,0.4954,0.49543,10.000
10,58.733,0.12,0.5621,0.56210,10.000
10,58.800,0.18,0.6288,0.62880,10.000
10,58.867,0.28,0.6954,0.69543,10.000
10,58.933,0.38,0.7621,0.76213,10.000
10,59.000,0.52,0.8289,0.82890,10.000
10,59.067,0.67,0.8954,0.89540,10.000
10,59.133,0.84,0.9621,0.96210,10.000
10,59.333,0.96,0.9962,0.99617,10.000
10,59.400,0.75,0.9294,0.92940,10.000
10,59.467,0.57,0.8628,0.86280,10.000
10,59.533,0.42,0.7963,0.79627,10.000
10,59.600,0.29,0.7293,0.72930,10.000
10,59.667,0.19,0.6628,0.66283,10.000
10,59.733,0.11,0.5962,0.59623,10.000
10,59.800,0.06,0.5294,0.52940,10.000
10,59.867,0.03,0.4629,0.46287,10.000
10,59.933,0.01,0.3962,0.39620,10.000
10,60.000,0.00,0.3294,0.32940,10.000
10,60.067,0.01,0.2628,0.26283,10.000
10,60.133,0.00,0.1961,0.19613,10.000
10,60.200,0.01,0.1292,0.12920,10.000
10,60.267,0.00,0.0627,0.06273,10.000
10,60.333,0.00,-0.0038,-0.00383,10.000
10,60.467,0.00,-0.0002,-0.00020,10.000
10,60.533,0.00,-0.0001,-0.00010,10.000
10,60.600,0.00,0.0000,0.00000,10.000
10,60.667,0.00,0.0000,0.00000,10.000
10,60.733,0.00,0.0000,0.00000,10.000
10,60.800,0.00,0.0000,0.00000,10.000
10,60.867,0.00,0.0000,0.00000,10.000
10,60.933,0.00,0.0000,0.00000,10.000
10,61.000,0.00,0.0000,0.00000,10.000
10,61.067,0.00,0.0000,0.00000,10.000
10,61.133,0.00,0.0000,0.00000,10.000
10,61.200,0.00,0.0000,0.00000,10.000
10,61.267,0.01,0.0000,0.00000,10.000
10,61.333,0.00,0.0000,0.00000,10.000
10,61.400,0.00,0.0000,0.00000,10.000
10,61.467,0.00,0.0000,0.00000,10.000
10,61.533,0.01,0.0000,0.00000,10.000
10,61.600,0.00,0.0000,0.00000,10.000
10,61.667,0.01,0.0000,0.00000,10.000
10,61.733,0.00,0.0000,0.00000,10.000
10,61.800,0.00,0.0000,0.00000,10.000
10,61.867,0.00,0.0000,0.00000,10.000
10,61.933,0.00,0.0000,0.00000,10.000
10,62.000,0.01,0.0000,0.00000,10.000
10,62.067,0.00,0.0000,0.00000,10.000
10,62.133,0.00,0.0000,0.00000,10.000
10,62.200,0.00,0.0000,0.00000,10.000
10,62.267,0.00,0.0000,0.00000,10.000
10,62.333,0.01,0.0000,0.00000,10.000
10,62.400,0.00,0.0000,0.00000,10.000
10,62.467,0.00,0.0000,0.00000,10.000
10,62.533,0.00,0.0000,0.00000,10.000
10,62.600,0.00,0.0000,0.00000,10.000
10,62.667,0.00,0.0000,0.00000,10.000
10,62.733,0.00,0.0000,0.00000,10.000
10,62.800,0.01,0.0000,0.00000,10.000
10,62.867,0.00,0.0000,0.00000,10.000
10,62.933,0.00,0.0000,0.00000,10.000
10,63.000,0.01,0.0000,0.00000,10.000
10,63.067,0.00,0.0000,0.00000,10.000
10,63.133,0.00,0.0000,0.00000,10.000
10,63.200,0.01,0.0000,0.00000,10.000
10,63.267,0.00,0.0000,0.00000,10.000
10,63.333,0.00,0.0000,0.00000,10.000
10,63.400,0.01,0.0000,0.00000,10.000
10,63.533,0.00,0.0000,0.00000,10.000
10,63.600,0.01,0.0000,0.00000,10.000
10,63.667,0.00,0.0000,0.00000,10.000
10,63.733,0.00,0.0000,0.00000,10.000
10,63.800,0.00,0.0000,0.00000,10.000
10,63.867,0.01,0.0000,0.00000,10.000
10,63.933,0.00,0.0000,0.00000,10.000
10,64.000,0.01,0.0000,0.00000,10.000
10,64.067,0.00,0.0000,0.00000,10.000
10,64.133,0.00,0.0000,0.00000,10.000
10,64.200,0.00,0.0000,0.00000,10.000
10,64.267,0.00,0.0000,0.00000,10.000
10,64.333,0.01,0.0000,0.00000,10.000
10,64.400,0.00,0.0000,0.00000,10.000