File: AIME_journal_files/AIME_data/calibDATA_loadcell/date_02:15:2018/Instron_02.15.2018/2_20N_0__2mm.s_0_0.txt
""
"Test Method","Radhen_Load_Cntrl_Cmprsn_250N_12-7.msm"
"Sample I. D.","Sample1.mss"
"Specimen Number","18"

"TheCycle_Output ()","_Time (s)","_Load (N)","_Extension (mm)","RealTimeDepth (mm)","CycleNumber ()"

1,0.333,0.00,0.1443,0.14427,1.000
1,0.400,0.00,0.2775,0.27750,1.000
1,0.467,0.00,0.4110,0.41103,1.000
1,0.533,0.00,0.5444,0.54437,1.000
1,0.600,0.00,0.6776,0.67760,1.000
1,0.667,0.00,0.8111,0.81107,1.000
1,0.733,0.01,0.9445,0.94447,1.000
1,0.800,-0.01,1.0775,1.07750,1.000
1,0.867,0.00,1.2112,1.21117,1.000
1,0.933,0.00,1.3445,1.34450,1.000
1,1.000,0.00,1.4776,1.47760,1.000
1,1.067,0.00,1.6112,1.61117,1.000
1,1.133,0.01,1.7446,1.74457,1.000
1,1.200,0.01,1.8775,1.87750,1.000
1,1.267,0.02,2.0112,2.01123,1.000
1,1.333,0.04,2.1444,2.14440,1.000
1,1.400,0.09,2.2775,2.27750,1.000
1,1.467,0.20,2.4111,2.41110,1.000
1,1.533,0.38,2.5445,2.54450,1.000
1,1.600,0.68,2.6775,2.67750,1.000
1,1.667,1.06,2.8113,2.81127,1.000
1,1.733,1.58,2.9445,2.94450,1.000
1,1.800,2.21,3.0775,3.07750,1.000
1,1.867,2.96,3.2112,3.21123,1.000
1,1.933,3.86,3.3446,3.34457,1.000
1,2.000,4.94,3.4778,3.47780,1.000
1,2.067,6.18,3.6111,3.61113,1.000
1,2.133,7.61,3.7445,3.74453,1.000
1,2.200,9.24,3.8776,3.87760,1.000
1,2.267,11.11,4.0112,4.01120,1.000
1,2.333,13.23,4.1445,4.14453,1.000
1,2.400,15.66,4.2776,4.27760,1.000
1,2.467,18.45,4.4111,4.41110,1.000
1,2.600,24.01,4.6172,4.61720,1.000
1,2.667,22.64,4.5786,4.57860,1.000
1,2.733,18.32,4.4520,4.45197,1.000
1,2.800,14.60,4.3188,4.31880,1.000
1,2.867,11.71,4.1852,4.18523,1.000
1,2.933,9.40,4.0519,4.05187,1.000
1,3.000,7.49,3.9188,3.91880,1.000
1,3.067,5.95,3.7852,3.78520,1.000
1,3.133,4.69,3.6518,3.65177,1.000
1,3.200,3.65,3.5189,3.51890,1.000
1,3.267,2.82,3.3852,3.38523,1.000
1,3.333,2.12,3.2519,3.25193,1.000
1,3.400,1.54,3.1189,3.11890,1.000
1,3.467,1.07,2.9851,2.98510,1.000
1,3.533,0.70,2.8518,2.85180,1.000
1,3.600,0.42,2.7189,2.71890,1.000
1,3.667,0.22,2.5852,2.58517,1.000
1,3.733,0.10,2.4518,2.45183,1.000
1,3.800,0.04,2.3188,2.31880,1.000
1,3.867,0.01,2.1851,2.18507,1.000
1,3.933,0.00,2.0517,2.05170,1.000
1,4.000,-0.01,1.9189,1.91890,1.000
1,4.067,0.00,1.7851,1.78507,1.000
1,4.133,0.00,1.6517,1.65170,1.000
1,4.200,0.00,1.5189,1.51890,1.000
1,4.267,0.00,1.3851,1.38507,1.000
1,4.333,0.00,1.2518,1.25183,1.000
1,4.400,0.00,1.1187,1.11870,1.000
1,4.467,0.00,0.9851,0.98510,1.000
1,4.533,0.00,0.8517,0.85167,1.000
1,4.600,0.00,0.7188,0.71880,1.000
1,4.667,0.00,0.5851,0.58507,1.000
1,4.733,0.00,0.4517,0.45167,1.000
1,4.800,0.01,0.3189,0.31890,1.000
1,4.867,0.00,0.1850,0.18503,1.000
1,4.933,0.00,0.0517,0.05167,1.000
1,5.067,0.00,-0.1319,-0.13190,1.000
1,5.133,0.00,-0.0740,-0.07400,1.000
1,5.200,0.00,-0.0002,-0.00020,1.000
1,5.267,0.00,-0.0001,-0.00010,1.000
1,5.333,0.00,-0.0001,-0.00010,1.000
1,5.400,0.00,-0.0001,-0.00010,1.000
1,5.467,0.00,-0.0001,-0.00010,1.000
1,5.533,0.00,-0.0001,-0.00010,1.000
1,5.600,0.01,-0.0001,-0.00010,1.000
1,5.667,0.00,-0.0001,-0.00010,1.000
1,5.733,0.00,-0.0001,-0.00010,1.000
1,5.800,0.00,-0.0001,-0.00010,1.000
1,5.867,0.00,-0.0001,-0.00010,1.000
1,5.933,0.01,-0.0001,-0.00010,1.000
1,6.000,0.00,-0.0001,-0.00010,1.000
1,6.067,0.00,-0.0001,-0.00010,1.000
1,6.133,0.00,-0.0001,-0.00010,1.000
1,6.200,-0.01,-0.0001,-0.00010,1.000
1,6.267,-0.01,-0.0001,-0.00010,1.000
1,6.333,0.00,-0.0001,-0.00010,1.000
1,6.400,-0.01,-0.0001,-0.00010,1.000
1,6.467,0.00,-0.0001,-0.00010,1.000
1,6.533,0.00,-0.0001,-0.00010,1.000
1,6.600,0.01,-0.0001,-0.00010,1.000
1,6.667,0.00,-0.0001,-0.00010,1.000
1,6.733,0.00,-0.0001,-0.00010,1.000
1,6.800,0.00,-0.0001,-0.00010,1.000
1,6.867,-0.01,-0.0001,-0.00010,1.000
1,6.933,0.00,-0.0001,-0.00010,1.000
1,7.000,0.00,-0.0001,-0.00010,1.000
1,7.067,0.00,-0.0001,-0.00010,1.000
1,7.133,0.00,-0.0001,-0.00010,1.000
1,7.200,0.00,-0.0001,-0.00010,1.000
1,7.267,0.00,-0.0001,-0.00010,1.000
1,7.333,0.00,-0.0001,-0.00010,1.000
1,7.400,0.00,-0.0001,-0.00010,1.000
1,7.467,0.00,-0.0001,-0.00010,1.000
1,7.533,0.00,-0.0001,-0.00010,1.000
1,7.600,0.00,-0.0001,-0.00010,1.000
1,7.667,0.00,-0.0001,-0.00010,1.000
1,7.733,0.00,-0.0001,-0.00010,1.000
1,7.800,0.00,-0.0001,-0.00010,1.000
1,7.867,-0.01,-0.0001,-0.00010,1.000
1,7.933,0.00,-0.0001,-0.00010,1.000
1,8.000,-0.01,-0.0001,-0.00010,1.000
1,8.133,0.00,-0.0001,-0.00010,1.000
1,8.200,0.00,-0.0001,-0.00010,1.000
1,8.267,0.00,-0.0001,-0.00010,1.000
1,8.333,-0.01,-0.0001,-0.00010,1.000
1,8.400,0.00,-0.0001,-0.00010,1.000
1,8.467,-0.01,-0.0001,-0.00010,1.000
1,8.533,0.00,-0.0001,-0.00010,1.000
2,8.800,0.01,0.0810,0.08100,2.000
2,8.867,0.01,0.2150,0.21500,2.000
2,8.933,0.00,0.3484,0.34840,2.000
2,9.000,0.01,0.4816,0.48160,2.000
2,9.067,0.01,0.6150,0.61500,2.000
2,9.133,0.01,0.7483,0.74833,2.000
2,9.200,0.00,0.8814,0.88140,2.000
2,9.267,0.01,1.0151,1.01510,2.000
2,9.333,0.01,1.1484,1.14837,2.000
2,9.400,0.01,1.2815,1.28150,2.000
2,9.467,0.01,1.4151,1.41510,2.000
2,9.533,0.01,1.5484,1.54843,2.000
2,9.600,0.01,1.6816,1.68160,2.000
2,9.667,0.01,1.8151,1.81510,2.000
2,9.733,0.02,1.9486,1.94857,2.000
2,9.800,0.03,2.0813,2.08130,2.000
2,9.867,0.04,2.2151,2.21507,2.000
2,9.933,0.13,2.3483,2.34833,2.000
2,10.000,0.26,2.4815,2.48150,2.000
2,10.067,0.50,2.6151,2.61510,2.000
2,10.133,0.83,2.7486,2.74857,2.000
2,10.200,1.27,2.8814,2.88140,2.000
2,10.267,1.83,3.0151,3.01513,2.000
2,10.333,2.50,3.1486,3.14857,2.000
2,10.400,3.32,3.2815,3.28150,2.000
2,10.467,4.31,3.4152,3.41520,2.000
2,10.533,5.47,3.5485,3.54847,2.000
2,10.600,6.80,3.6814,3.68140,2.000
2,10.667,8.36,3.8151,3.81510,2.000
2,10.733,10.13,3.9485,3.94853,2.000
2,10.800,12.13,4.0815,4.08150,2.000
2,10.867,14.43,4.2151,4.21507,2.000
2,10.933,17.05,4.3484,4.34843,2.000
2,11.000,20.04,4.4816,4.48160,2.000
2,11.133,23.63,4.6077,4.60770,2.000
2,11.200,20.33,4.5102,4.51020,2.000
2,11.267,16.11,4.3773,4.37733,2.000
2,11.333,12.90,4.2439,4.24393,2.000
2,11.400,10.35,4.1104,4.11040,2.000
2,11.467,8.28,3.9773,3.97730,2.000
2,11.533,6.59,3.8439,3.84393,2.000
2,11.600,5.20,3.7103,3.71030,2.000
2,11.667,4.07,3.5772,3.57720,2.000
2,11.733,3.14,3.4439,3.44390,2.000
2,11.800,2.40,3.3105,3.31050,2.000
2,11.867,1.78,3.1773,3.17733,2.000
2,11.933,1.25,3.0438,3.04383,2.000
2,12.000,0.85,2.9103,2.91030,2.000
2,12.067,0.53,2.7773,2.77727,2.000
2,12.133,0.29,2.6439,2.64387,2.000
2,12.200,0.14,2.5105,2.51050,2.000
2,12.267,0.06,2.3771,2.37710,2.000
2,12.333,0.02,2.2438,2.24380,2.000
2,12.400,0.02,2.1105,2.11050,2.000
2,12.467,0.00,1.9772,1.97717,2.000
2,12.533,0.01,1.8438,1.84383,2.000
2,12.600,0.00,1.7105,1.71050,2.000
2,12.667,0.00,1.5772,1.57720,2.000
2,12.733,0.00,1.4438,1.44380,2.000
2,12.800,0.01,1.3106,1.31060,2.000
2,12.867,0.00,1.1771,1.17707,2.000
2,12.933,0.01,1.0438,1.04380,2.000
2,13.000,0.00,0.9105,0.91050,2.000
2,13.067,0.00,0.7770,0.77703,2.000
2,13.133,0.00,0.6438,0.64377,2.000
2,13.200,0.01,0.5106,0.51060,2.000
2,13.267,0.00,0.3770,0.37700,2.000
2,13.333,0.01,0.2438,0.24380,2.000
2,13.400,0.01,0.1105,0.11050,2.000
2,13.467,0.00,-0.0230,-0.02297,2.000
2,13.600,0.01,-0.1163,-0.11630,2.000
2,13.667,0.00,-0.0220,-0.02200,2.000
2,13.733,0.00,-0.0002,-0.00020,2.000
2,13.800,0.01,-0.0002,-0.00020,2.000
2,13.867,0.01,-0.0002,-0.00020,2.000
2,13.933,0.01,-0.0002,-0.00020,2.000
2,14.000,0.00,-0.0002,-0.00020,2.000
2,14.067,-0.01,-0.0002,-0.00020,2.000
2,14.133,0.01,-0.0002,-0.00020,2.000
2,14.200,0.01,-0.0002,-0.00020,2.000
2,14.267,0.00,-0.0002,-0.00020,2.000
2,14.333,0.00,-0.0002,-0.00020,2.000
2,14.400,-0.01,-0.0002,-0.00020,2.000
2,14.467,0.00,-0.0002,-0.00020,2.000
2,14.533,0.00,-0.0002,-0.00020,2.000
2,14.600,0.01,-0.0002,-0.00020,2.000
2,14.667,-0.01,-0.0002,-0.00020,2.000
2,14.733,0.01,-0.0002,-0.00020,2.000
2,14.800,0.01,-0.0002,-0.00020,2.000
2,14.867,0.02,-0.0002,-0.00020,2.000
2,14.933,0.00,-0.0002,-0.00020,2.000
2,15.000,-0.01,-0.0002,-0.00020,2.000
2,15.067,0.00,-0.0002,-0.00020,2.000
2,15.133,0.00,-0.0002,-0.00020,2.000
2,15.200,0.00,-0.0002,-0.00020,2.000
2,15.267,0.00,-0.0002,-0.00020,2.000
2,15.333,0.00,-0.0002,-0.00020,2.000
2,15.400,0.00,-0.0002,-0.00020,2.000
2,15.467,0.01,-0.0001,-0.00010,2.000
2,15.533,0.02,-0.0001,-0.00010,2.000
2,15.600,0.01,-0.0001,-0.00010,2.000
2,15.667,0.00,-0.0001,-0.00010,2.000
2,15.733,0.00,-0.0001,-0.00010,2.000
2,15.800,0.01,-0.0001,-0.00010,2.000
2,15.867,0.01,-0.0001,-0.00010,2.000
2,15.933,0.01,-0.0001,-0.00010,2.000
2,16.000,0.01,-0.0001,-0.00010,2.000
2,16.067,0.01,-0.0001,-0.00010,2.000
2,16.133,0.01,-0.0001,-0.00010,2.000
2,16.200,0.01,-0.0001,-0.00010,2.000
2,16.267,0.00,-0.0001,-0.00010,2.000
2,16.333,0.01,-0.0001,-0.00010,2.000
2,16.400,0.01,-0.0001,-0.00010,2.000
2,16.467,0.01,-0.0001,-0.00010,2.000
2,16.533,0.00,-0.0001,-0.00010,2.000
2,16.667,0.01,-0.0001,-0.00010,2.000
2,16.733,0.01,-0.0001,-0.00010,2.000
2,16.800,0.00,-0.0001,-0.00010,2.000
2,16.867,0.01,-0.0001,-0.00010,2.000
2,16.933,0.01,-0.0001,-0.00010,2.000
2,17.000,0.01,-0.0001,-0.00010,2.000
3,17.333,0.01,0.1443,0.14430,3.000
3,17.400,0.01,0.2775,0.27750,3.000
3,17.467,0.00,0.4110,0.41100,3.000
3,17.533,0.01,0.5443,0.54433,3.000
3,17.600,0.01,0.6775,0.67750,3.000
3,17.667,-0.01,0.8110,0.81097,3.000
3,17.733,0.00,0.9444,0.94440,3.000
3,17.800,0.01,1.0774,1.07740,3.000
3,17.867,0.01,1.2111,1.21113,3.000
3,17.933,0.01,1.3444,1.34443,3.000
3,18.000,0.01,1.4775,1.47750,3.000
3,18.067,0.01,1.6112,1.61117,3.000
3,18.133,0.01,1.7445,1.74450,3.000
3,18.200,0.03,1.8775,1.87750,3.000
3,18.267,0.03,2.0111,2.01113,3.000
3,18.333,0.03,2.1443,2.14433,3.000
3,18.400,0.09,2.2775,2.27750,3.000
3,18.467,0.19,2.4111,2.41110,3.000
3,18.533,0.36,2.5444,2.54440,3.000
3,18.600,0.63,2.6776,2.67760,3.000
3,18.667,1.01,2.8112,2.81120,3.000
3,18.733,1.51,2.9444,2.94443,3.000
3,18.800,2.12,3.0775,3.07750,3.000
3,18.867,2.86,3.2112,3.21120,3.000
3,18.933,3.76,3.3445,3.34450,3.000
3,19.000,4.83,3.4776,3.47760,3.000
3,19.067,6.07,3.6111,3.61107,3.000
3,19.133,7.50,3.7444,3.74440,3.000
3,19.200,9.17,3.8775,3.87750,3.000
3,19.267,11.05,4.0111,4.01113,3.000
3,19.333,13.17,4.1445,4.14450,3.000
3,19.400,15.61,4.2776,4.27760,3.000
3,19.467,18.40,4.4110,4.41103,3.000
3,19.667,23.59,4.6113,4.61133,3.000
3,19.733,19.39,4.4919,4.49187,3.000
3,19.800,15.45,4.3587,4.35870,3.000
3,19.867,12.39,4.2252,4.22520,3.000
3,19.933,9.96,4.0919,4.09190,3.000
3,20.000,7.97,3.9588,3.95880,3.000
3,20.067,6.34,3.8252,3.82523,3.000
3,20.133,5.01,3.6917,3.69170,3.000
3,20.200,3.91,3.5587,3.55870,3.000
3,20.267,3.01,3.4252,3.42517,3.000
3,20.333,2.28,3.2919,3.29187,3.000
3,20.400,1.68,3.1588,3.15880,3.000
3,20.467,1.20,3.0252,3.02517,3.000
3,20.533,0.78,2.8918,2.89183,3.000
3,20.600,0.49,2.7588,2.75880,3.000
3,20.667,0.28,2.6251,2.62507,3.000
3,20.733,0.11,2.4918,2.49177,3.000
3,20.800,0.05,2.3587,2.35870,3.000
3,20.867,0.01,2.2251,2.22507,3.000
3,20.933,0.01,2.0916,2.09163,3.000
3,21.000,0.01,1.9587,1.95870,3.000
3,21.067,0.00,1.8251,1.82507,3.000
3,21.133,0.00,1.6917,1.69167,3.000
3,21.200,0.01,1.5589,1.55890,3.000
3,21.267,0.01,1.4251,1.42507,3.000
3,21.333,0.01,1.2917,1.29173,3.000
3,21.400,0.01,1.1588,1.15880,3.000
3,21.467,0.01,1.0251,1.02510,3.000
3,21.533,0.01,0.8917,0.89170,3.000
3,21.600,0.00,0.7587,0.75870,3.000
3,21.667,0.00,0.6251,0.62507,3.000
3,21.733,0.00,0.4917,0.49167,3.000
3,21.800,0.01,0.3588,0.35880,3.000
3,21.867,0.00,0.2251,0.22507,3.000
3,21.933,0.01,0.0916,0.09157,3.000
3,22.000,0.00,-0.0413,-0.04130,3.000
3,22.133,0.01,-0.1188,-0.11877,3.000
3,22.200,0.01,-0.0207,-0.02070,3.000
3,22.267,0.01,-0.0002,-0.00020,3.000
3,22.333,0.02,-0.0002,-0.00020,3.000
3,22.400,0.00,-0.0002,-0.00020,3.000
3,22.467,0.01,-0.0002,-0.00020,3.000
3,22.533,0.01,-0.0002,-0.00020,3.000
3,22.600,0.00,-0.0002,-0.00020,3.000
3,22.667,0.01,-0.0002,-0.00020,3.000
3,22.733,0.01,-0.0002,-0.00020,3.000
3,22.800,0.00,-0.0002,-0.00020,3.000
3,22.867,0.01,-0.0002,-0.00020,3.000
3,22.933,0.01,-0.0002,-0.00020,3.000
3,23.000,0.00,-0.0002,-0.00020,3.000
3,23.067,0.01,-0.0002,-0.00020,3.000
3,23.133,0.01,-0.0002,-0.00020,3.000
3,23.200,0.02,-0.0002,-0.00020,3.000
3,23.267,0.01,-0.0002,-0.00020,3.000
3,23.333,0.00,-0.0002,-0.00020,3.000
3,23.400,0.01,-0.0002,-0.00020,3.000
3,23.467,0.01,-0.0002,-0.00020,3.000
3,23.533,0.00,-0.0002,-0.00020,3.000
3,23.600,0.00,-0.0002,-0.00020,3.000
3,23.667,0.00,-0.0002,-0.00020,3.000
3,23.733,0.02,-0.0002,-0.00020,3.000
3,23.800,0.01,-0.0002,-0.00020,3.000
3,23.867,0.01,-0.0002,-0.00020,3.000
3,23.933,0.02,-0.0002,-0.00020,3.000
3,24.000,0.00,-0.0002,-0.00020,3.000
3,24.067,0.01,-0.0002,-0.00020,3.000
3,24.133,0.01,-0.0002,-0.00020,3.000
3,24.200,0.00,-0.0001,-0.00010,3.000
3,24.267,0.01,-0.0001,-0.00010,3.000
3,24.333,0.01,-0.0001,-0.00010,3.000
3,24.400,0.00,-0.0001,-0.00010,3.000
3,24.467,0.01,-0.0001,-0.00010,3.000
3,24.533,0.01,-0.0001,-0.00010,3.000
3,24.600,0.01,-0.0001,-0.00010,3.000
3,24.667,0.01,-0.0001,-0.00010,3.000
3,24.733,0.01,-0.0001,-0.00010,3.000
3,24.800,0.01,-0.0001,-0.00010,3.000
3,24.867,0.01,-0.0001,-0.00010,3.000
3,24.933,0.00,-0.0001,-0.00010,3.000
3,25.000,0.00,-0.0001,-0.00010,3.000
3,25.067,0.01,-0.0001,-0.00010,3.000
3,25.200,0.01,-0.0001,-0.00010,3.000
3,25.267,0.01,-0.0001,-0.00010,3.000
3,25.333,0.01,-0.0001,-0.00010,3.000
3,25.400,0.01,-0.0001,-0.00010,3.000
3,25.467,0.00,-0.0001,-0.00010,3.000
3,25.533,0.01,-0.0001,-0.00010,3.000
3,25.600,0.01,-0.0001,-0.00010,3.000
4,25.867,-0.02,0.1548,0.15483,4.000
4,25.933,-0.01,0.2883,0.28830,4.000
4,26.000,-0.02,0.4218,0.42180,4.000
4,26.067,-0.02,0.5549,0.55490,4.000
4,26.133,-0.02,0.6884,0.68837,4.000
4,26.200,-0.02,0.8218,0.82180,4.000
4,26.267,-0.02,0.9549,0.95493,4.000
4,26.333,-0.01,1.0883,1.08833,4.000
4,26.400,-0.02,1.2220,1.22200,4.000
4,26.467,-0.02,1.3550,1.35497,4.000
4,26.533,-0.01,1.4884,1.48840,4.000
4,26.600,-0.02,1.6220,1.62200,4.000
4,26.667,-0.01,1.7550,1.75500,4.000
4,26.733,0.00,1.8884,1.88837,4.000
4,26.800,0.01,2.0221,2.02210,4.000
4,26.867,0.02,2.1548,2.15483,4.000
4,26.933,0.07,2.2882,2.28820,4.000
4,27.000,0.16,2.4219,2.42190,4.000
4,27.067,0.34,2.5550,2.55500,4.000
4,27.133,0.62,2.6884,2.68837,4.000
4,27.200,1.02,2.8220,2.82200,4.000
4,27.267,1.52,2.9550,2.95500,4.000
4,27.333,2.15,3.0884,3.08837,4.000
4,27.400,2.90,3.2221,3.22210,4.000
4,27.467,3.80,3.3551,3.35510,4.000
4,27.533,4.88,3.4884,3.48840,4.000
4,27.600,6.14,3.6219,3.62190,4.000
4,27.667,7.60,3.7550,3.75503,4.000
4,27.733,9.27,3.8883,3.88833,4.000
4,27.800,11.17,4.0220,4.02200,4.000
4,27.867,13.33,4.1550,4.15500,4.000
4,27.933,15.79,4.2883,4.28827,4.000
4,28.000,18.62,4.4218,4.42180,4.000
4,28.133,24.29,4.6302,4.63023,4.000
4,28.200,23.05,4.5949,4.59490,4.000
4,28.267,18.70,4.4693,4.46927,4.000
4,28.333,14.91,4.3358,4.33580,4.000
4,28.400,11.97,4.2027,4.20270,4.000
4,28.467,9.61,4.0692,4.06920,4.000
4,28.533,7.67,3.9358,3.93580,4.000
4,28.600,6.09,3.8028,3.80280,4.000
4,28.667,4.79,3.6691,3.66907,4.000
4,28.733,3.73,3.5358,3.53577,4.000
4,28.800,2.86,3.4029,3.40290,4.000
4,28.867,2.16,3.2692,3.26923,4.000
4,28.933,1.57,3.1359,3.13587,4.000
4,29.000,1.09,3.0027,3.00270,4.000
4,29.067,0.71,2.8691,2.86910,4.000
4,29.133,0.42,2.7358,2.73583,4.000
4,29.200,0.22,2.6029,2.60290,4.000
4,29.267,0.09,2.4691,2.46910,4.000
4,29.333,0.03,2.3356,2.33563,4.000
4,29.400,-0.01,2.2027,2.20270,4.000
4,29.467,-0.03,2.0690,2.06900,4.000
4,29.533,-0.01,1.9358,1.93580,4.000
4,29.600,-0.01,1.8027,1.80270,4.000
4,29.667,-0.02,1.6690,1.66903,4.000
4,29.733,-0.02,1.5358,1.53577,4.000
4,29.800,-0.02,1.4028,1.40280,4.000
4,29.867,-0.01,1.2691,1.26910,4.000
4,29.933,-0.01,1.1357,1.13570,4.000
4,30.000,-0.04,1.0026,1.00260,4.000
4,30.067,-0.01,0.8690,0.86897,4.000
4,30.133,-0.01,0.7357,0.73567,4.000
4,30.200,-0.01,0.6027,0.60270,4.000
4,30.267,-0.01,0.4690,0.46900,4.000
4,30.333,-0.01,0.3358,0.33580,4.000
4,30.400,-0.02,0.2026,0.20260,4.000
4,30.467,-0.01,0.0689,0.06893,4.000
4,30.667,-0.02,-0.1312,-0.13120,4.000
4,30.733,-0.02,-0.0261,-0.02607,4.000
4,30.800,-0.02,-0.0002,-0.00020,4.000
4,30.867,-0.02,-0.0002,-0.00020,4.000
4,30.933,-0.02,-0.0002,-0.00020,4.000
4,31.000,-0.01,-0.0002,-0.00020,4.000
4,31.067,-0.01,-0.0002,-0.00020,4.000
4,31.133,-0.02,-0.0002,-0.00020,4.000
4,31.200,-0.02,-0.0002,-0.00020,4.000
4,31.267,-0.02,-0.0002,-0.00020,4.000
4,31.333,-0.01,-0.0002,-0.00020,4.000
4,31.400,-0.02,-0.0002,-0.00020,4.000
4,31.467,-0.02,-0.0002,-0.00020,4.000
4,31.533,-0.02,-0.0002,-0.00020,4.000
4,31.600,-0.02,-0.0002,-0.00020,4.000
4,31.667,-0.01,-0.0002,-0.00020,4.000
4,31.733,-0.01,-0.0002,-0.00020,4.000
4,31.800,-0.01,-0.0002,-0.00020,4.000
4,31.867,-0.02,-0.0002,-0.00020,4.000
4,31.933,-0.01,-0.0002,-0.00020,4.000
4,32.000,-0.01,-0.0002,-0.00020,4.000
4,32.067,-0.02,-0.0002,-0.00020,4.000
4,32.133,-0.01,-0.0002,-0.00020,4.000
4,32.200,-0.02,-0.0002,-0.00020,4.000
4,32.267,-0.01,-0.0002,-0.00020,4.000
4,32.333,-0.02,-0.0002,-0.00020,4.000
4,32.400,-0.01,-0.0002,-0.00020,4.000
4,32.467,-0.01,-0.0002,-0.00020,4.000
4,32.533,-0.01,-0.0002,-0.00020,4.000
4,32.600,-0.02,-0.0002,-0.00020,4.000
4,32.667,-0.02,-0.0002,-0.00020,4.000
4,32.733,-0.02,-0.0002,-0.00020,4.000
4,32.800,-0.01,-0.0002,-0.00020,4.000
4,32.867,-0.01,-0.0002,-0.00020,4.000
4,32.933,-0.03,-0.0002,-0.00020,4.000
4,33.000,-0.02,-0.0002,-0.00020,4.000
4,33.067,-0.02,-0.0002,-0.00020,4.000
4,33.133,-0.01,-0.0002,-0.00020,4.000
4,33.200,-0.01,-0.0001,-0.00010,4.000
4,33.267,-0.01,-0.0001,-0.00010,4.000
4,33.333,-0.02,-0.0001,-0.00010,4.000
4,33.400,-0.02,-0.0001,-0.00010,4.000
4,33.467,-0.01,-0.0001,-0.00010,4.000
4,33.533,-0.02,-0.0001,-0.00010,4.000
4,33.600,-0.02,-0.0001,-0.00010,4.000
4,33.733,-0.02,-0.0001,-0.00010,4.000
4,33.800,-0.01,-0.0001,-0.00010,4.000
4,33.867,-0.02,-0.0001,-0.00010,4.000
4,33.933,-0.02,-0.0001,-0.00010,4.000
4,34.000,-0.02,-0.0001,-0.00010,4.000
4,34.067,-0.01,-0.0001,-0.00010,4.000
5,34.400,0.01,0.1418,0.14180,5.000
5,34.467,0.00,0.2750,0.27503,5.000
5,34.533,0.00,0.4082,0.40820,5.000
5,34.600,0.00,0.5417,0.54170,5.000
5,34.667,0.01,0.6750,0.67503,5.000
5,34.733,0.01,0.8082,0.80820,5.000
5,34.800,0.01,0.9419,0.94190,5.000
5,34.867,0.01,1.0749,1.07493,5.000
5,34.933,0.00,1.2083,1.20827,5.000
5,35.000,0.00,1.3420,1.34200,5.000
5,35.067,0.00,1.4750,1.47503,5.000
5,35.133,0.00,1.6083,1.60833,5.000
5,35.200,0.01,1.7419,1.74190,5.000
5,35.267,0.01,1.8750,1.87503,5.000
5,35.333,0.01,2.0084,2.00840,5.000
5,35.400,0.03,2.1419,2.14190,5.000
5,35.467,0.08,2.2749,2.27493,5.000
5,35.533,0.17,2.4083,2.40830,5.000
5,35.600,0.34,2.5419,2.54190,5.000
5,35.667,0.61,2.6750,2.67503,5.000
5,35.733,0.98,2.8084,2.80843,5.000
5,35.800,1.47,2.9419,2.94190,5.000
5,35.867,2.08,3.0750,3.07500,5.000
5,35.933,2.82,3.2084,3.20840,5.000
5,36.000,3.71,3.3420,3.34200,5.000
5,36.067,4.77,3.4751,3.47507,5.000
5,36.133,6.02,3.6083,3.60827,5.000
5,36.200,7.47,3.7419,3.74190,5.000
5,36.267,9.13,3.8750,3.87497,5.000
5,36.333,11.01,4.0083,4.00833,5.000
5,36.400,13.15,4.1420,4.14200,5.000
5,36.467,15.56,4.2750,4.27497,5.000
5,36.533,18.34,4.4084,4.40837,5.000
5,36.667,23.59,4.6037,4.60373,5.000
5,36.733,21.97,4.5560,4.55600,5.000
5,36.800,17.64,4.4263,4.42630,5.000
5,36.867,14.09,4.2933,4.29330,5.000
5,36.933,11.30,4.1600,4.16003,5.000
5,37.000,9.05,4.0263,4.02630,5.000
5,37.067,7.21,3.8934,3.89337,5.000
5,37.133,5.71,3.7599,3.75993,5.000
5,37.200,4.47,3.6261,3.62610,5.000
5,37.267,3.47,3.4934,3.49337,5.000
5,37.333,2.66,3.3601,3.36010,5.000
5,37.400,1.99,3.2264,3.22640,5.000
5,37.467,1.43,3.0934,3.09337,5.000
5,37.533,0.98,2.9599,2.95993,5.000
5,37.600,0.62,2.8262,2.82620,5.000
5,37.667,0.37,2.6933,2.69333,5.000
5,37.733,0.19,2.5599,2.55993,5.000
5,37.800,0.09,2.4262,2.42620,5.000
5,37.867,0.01,2.2932,2.29320,5.000
5,37.933,0.00,2.1598,2.15983,5.000
5,38.000,0.00,2.0262,2.02620,5.000
5,38.067,0.01,1.8933,1.89330,5.000
5,38.133,0.00,1.7599,1.75987,5.000
5,38.200,0.00,1.6262,1.62620,5.000
5,38.267,0.00,1.4933,1.49327,5.000
5,38.333,0.00,1.3599,1.35993,5.000
5,38.400,0.00,1.2264,1.22640,5.000
5,38.467,0.00,1.0932,1.09320,5.000
5,38.533,0.00,0.9598,0.95983,5.000
5,38.600,0.00,0.8262,0.82620,5.000
5,38.667,0.00,0.6933,0.69330,5.000
5,38.733,0.00,0.5598,0.55983,5.000
5,38.800,0.01,0.4263,0.42630,5.000
5,38.867,0.00,0.2931,0.29313,5.000
5,38.933,0.00,0.1597,0.15973,5.000
5,39.000,0.01,0.0264,0.02640,5.000
5,39.133,0.01,-0.1452,-0.14520,5.000
5,39.200,0.00,-0.0783,-0.07830,5.000
5,39.267,0.00,-0.0020,-0.00203,5.000
5,39.333,0.00,-0.0002,-0.00020,5.000
5,39.400,0.01,-0.0002,-0.00020,5.000
5,39.467,0.00,-0.0002,-0.00020,5.000
5,39.533,0.00,-0.0002,-0.00020,5.000
5,39.600,-0.01,-0.0002,-0.00020,5.000
5,39.667,0.00,-0.0002,-0.00020,5.000
5,39.733,0.00,-0.0002,-0.00020,5.000
5,39.800,-0.01,-0.0002,-0.00020,5.000
5,39.867,0.00,-0.0002,-0.00020,5.000
5,39.933,0.00,-0.0002,-0.00020,5.000
5,40.000,0.01,-0.0002,-0.00020,5.000
5,40.067,0.01,-0.0002,-0.00020,5.000
5,40.133,-0.01,-0.0002,-0.00020,5.000
5,40.200,0.00,-0.0002,-0.00020,5.000
5,40.267,0.00,-0.0002,-0.00020,5.000
5,40.333,0.00,-0.0002,-0.00020,5.000
5,40.400,0.00,-0.0002,-0.00020,5.000
5,40.467,0.00,-0.0002,-0.00020,5.000
5,40.533,0.01,-0.0002,-0.00020,5.000
5,40.600,0.00,-0.0002,-0.00020,5.000
5,40.667,0.01,-0.0002,-0.00020,5.000
5,40.733,0.01,-0.0002,-0.00020,5.000
5,40.800,0.00,-0.0002,-0.00020,5.000
5,40.867,0.01,-0.0002,-0.00020,5.000
5,40.933,0.01,-0.0002,-0.00020,5.000
5,41.000,0.00,-0.0002,-0.00020,5.000
5,41.067,0.01,-0.0002,-0.00020,5.000
5,41.133,0.02,-0.0002,-0.00020,5.000
5,41.200,0.01,-0.0002,-0.00020,5.000
5,41.267,0.01,-0.0002,-0.00020,5.000
5,41.333,0.00,-0.0002,-0.00020,5.000
5,41.400,0.01,-0.0002,-0.00020,5.000
5,41.467,0.01,-0.0002,-0.00020,5.000
5,41.533,0.00,-0.0002,-0.00020,5.000
5,41.600,0.00,-0.0001,-0.00010,5.000
5,41.667,0.00,-0.0001,-0.00010,5.000
5,41.733,0.01,-0.0001,-0.00010,5.000
5,41.800,-0.01,-0.0001,-0.00010,5.000
5,41.867,0.01,-0.0001,-0.00010,5.000
5,41.933,0.00,-0.0001,-0.00010,5.000
5,42.000,0.01,-0.0001,-0.00010,5.000
5,42.067,0.00,-0.0001,-0.00010,5.000
5,42.200,0.00,-0.0001,-0.00010,5.000
5,42.267,0.00,-0.0001,-0.00010,5.000
5,42.333,0.00,-0.0001,-0.00010,5.000
5,42.400,0.00,-0.0001,-0.00010,5.000
5,42.467,0.01,-0.0001,-0.00010,5.000
5,42.533,0.01,-0.0001,-0.00010,5.000
5,42.600,0.00,-0.0001,-0.00010,5.000
6,42.867,0.00,0.0949,0.09487,6.000
6,42.933,-0.01,0.2285,0.22847,6.000
6,43.000,0.00,0.3615,0.36150,6.000
6,43.067,-0.01,0.4950,0.49503,6.000
6,43.133,0.00,0.6284,0.62843,6.000
6,43.200,0.00,0.7614,0.76140,6.000
6,43.267,-0.01,0.8950,0.89503,6.000
6,43.333,-0.01,1.0285,1.02847,6.000
6,43.400,0.00,1.1614,1.16140,6.000
6,43.467,-0.01,1.2952,1.29517,6.000
6,43.533,0.00,1.4285,1.42847,6.000
6,43.600,-0.01,1.5615,1.56150,6.000
6,43.667,-0.01,1.6951,1.69510,6.000
6,43.733,0.00,1.8285,1.82847,6.000
6,43.800,-0.01,1.9615,1.96150,6.000
6,43.867,0.01,2.0951,2.09507,6.000
6,43.933,0.05,2.2284,2.22840,6.000
6,44.000,0.13,2.3616,2.36160,6.000
6,44.067,0.25,2.4951,2.49513,6.000
6,44.133,0.50,2.6284,2.62840,6.000
6,44.200,0.83,2.7616,2.76160,6.000
6,44.267,1.28,2.8952,2.89517,6.000
6,44.333,1.84,3.0285,3.02850,6.000
6,44.400,2.52,3.1616,3.16160,6.000
6,44.467,3.36,3.2952,3.29520,6.000
6,44.533,4.35,3.4286,3.42857,6.000
6,44.600,5.55,3.5616,3.56160,6.000
6,44.667,6.92,3.6951,3.69507,6.000
6,44.733,8.51,3.8284,3.82840,6.000
6,44.800,10.30,3.9616,3.96160,6.000
6,44.867,12.35,4.0951,4.09513,6.000
6,44.933,14.66,4.2285,4.22847,6.000
6,45.000,17.30,4.3617,4.36170,6.000
6,45.067,20.38,4.4951,4.49510,6.000
6,45.200,22.85,4.5828,4.58280,6.000
6,45.267,19.03,4.4692,4.46923,6.000
6,45.333,15.15,4.3358,4.33583,6.000
6,45.400,12.13,4.2027,4.20270,6.000
6,45.467,9.72,4.0693,4.06927,6.000
6,45.533,7.76,3.9359,3.93593,6.000
6,45.600,6.15,3.8028,3.80280,6.000
6,45.667,4.83,3.6690,3.66903,6.000
6,45.733,3.75,3.5358,3.53583,6.000
6,45.800,2.89,3.4028,3.40280,6.000
6,45.867,2.17,3.2692,3.26920,6.000
6,45.933,1.58,3.1359,3.13587,6.000
6,46.000,1.10,3.0027,3.00270,6.000
6,46.067,0.72,2.8691,2.86910,6.000
6,46.133,0.43,2.7358,2.73583,6.000
6,46.200,0.23,2.6029,2.60290,6.000
6,46.267,0.09,2.4692,2.46917,6.000
6,46.333,0.02,2.3356,2.33563,6.000
6,46.400,-0.01,2.2027,2.20270,6.000
6,46.467,-0.01,2.0690,2.06903,6.000
6,46.533,-0.01,1.9358,1.93580,6.000
6,46.600,0.00,1.8027,1.80270,6.000
6,46.667,0.00,1.6690,1.66903,6.000
6,46.733,-0.01,1.5358,1.53583,6.000
6,46.800,-0.01,1.4028,1.40280,6.000
6,46.867,-0.01,1.2691,1.26913,6.000
6,46.933,-0.01,1.1357,1.13570,6.000
6,47.000,-0.01,1.0027,1.00270,6.000
6,47.067,-0.01,0.8690,0.86900,6.000
6,47.133,-0.01,0.7357,0.73573,6.000
6,47.200,-0.01,0.6028,0.60280,6.000
6,47.267,-0.01,0.4690,0.46903,6.000
6,47.333,0.00,0.3358,0.33580,6.000
6,47.400,-0.01,0.2026,0.20260,6.000
6,47.467,-0.01,0.0689,0.06893,6.000
6,47.600,-0.01,-0.1453,-0.14530,6.000
6,47.667,-0.01,-0.1149,-0.11490,6.000
6,47.733,-0.01,-0.0160,-0.01597,6.000
6,47.800,-0.01,-0.0002,-0.00020,6.000
6,47.867,-0.01,-0.0002,-0.00020,6.000
6,47.933,-0.01,-0.0002,-0.00020,6.000
6,48.000,-0.01,-0.0002,-0.00020,6.000
6,48.067,-0.01,-0.0002,-0.00020,6.000
6,48.133,-0.01,-0.0002,-0.00020,6.000
6,48.200,-0.01,-0.0002,-0.00020,6.000
6,48.267,-0.01,-0.0002,-0.00020,6.000
6,48.333,-0.01,-0.0002,-0.00020,6.000
6,48.400,-0.01,-0.0002,-0.00020,6.000
6,48.467,-0.01,-0.0002,-0.00020,6.000
6,48.533,-0.01,-0.0002,-0.00020,6.000
6,48.600,-0.01,-0.0002,-0.00020,6.000
6,48.667,-0.01,-0.0002,-0.00020,6.000
6,48.733,0.00,-0.0002,-0.00020,6.000
6,48.800,-0.01,-0.0002,-0.00020,6.000
6,48.867,-0.01,-0.0002,-0.00020,6.000
6,48.933,-0.01,-0.0002,-0.00020,6.000
6,49.000,-0.01,-0.0002,-0.00020,6.000
6,49.067,-0.01,-0.0002,-0.00020,6.000
6,49.133,-0.01,-0.0002,-0.00020,6.000
6,49.200,-0.01,-0.0002,-0.00020,6.000
6,49.267,0.00,-0.0002,-0.00020,6.000
6,49.333,-0.01,-0.0002,-0.00020,6.000
6,49.400,-0.01,-0.0002,-0.00020,6.000
6,49.467,-0.01,-0.0002,-0.00020,6.000
6,49.533,-0.01,-0.0002,-0.00020,6.000
6,49.600,-0.01,-0.0002,-0.00020,6.000
6,49.667,-0.01,-0.0002,-0.00020,6.000
6,49.733,-0.01,-0.0002,-0.00020,6.000
6,49.800,-0.01,-0.0002,-0.00020,6.000
6,49.867,-0.01,-0.0002,-0.00020,6.000
6,49.933,-0.02,-0.0002,-0.00020,6.000
6,50.000,-0.01,-0.0002,-0.00020,6.000
6,50.067,0.00,-0.0001,-0.00010,6.000
6,50.133,-0.01,-0.0001,-0.00010,6.000
6,50.200,-0.01,-0.0001,-0.00010,6.000
6,50.267,-0.01,-0.0001,-0.00010,6.000
6,50.333,-0.01,-0.0001,-0.00010,6.000
6,50.400,-0.01,-0.0001,-0.00010,6.000
6,50.467,0.00,-0.0001,-0.00010,6.000
6,50.533,-0.01,-0.0001,-0.00010,6.000
6,50.600,0.00,-0.0001,-0.00010,6.000
6,50.667,0.00,-0.0001,-0.00010,6.000
6,50.733,-0.01,-0.0001,-0.00010,6.000
6,50.800,-0.01,-0.0001,-0.00010,6.000
6,50.867,-0.01,-0.0001,-0.00010,6.000
6,50.933,0.00,-0.0001,-0.00010,6.000
6,51.000,-0.01,-0.0001,-0.00010,6.000
6,51.067,-0.01,-0.0001,-0.00010,6.000
7,51.333,0.01,0.0480,0.04797,7.000
7,51.400,0.01,0.1779,0.17790,7.000
7,51.467,0.01,0.3110,0.31100,7.000
7,51.533,0.01,0.4442,0.44423,7.000
7,51.600,0.00,0.5779,0.57790,7.000
7,51.667,0.00,0.7110,0.71100,7.000
7,51.733,0.00,0.8442,0.84420,7.000
7,51.800,0.00,0.9779,0.97790,7.000
7,51.867,0.01,1.1110,1.11097,7.000
7,51.933,0.00,1.2443,1.24433,7.000
7,52.000,0.01,1.3779,1.37790,7.000
7,52.067,0.00,1.5110,1.51100,7.000
7,52.133,0.00,1.6444,1.64437,7.000
7,52.200,0.01,1.7779,1.77790,7.000
7,52.267,0.02,1.9111,1.91110,7.000
7,52.333,0.03,2.0444,2.04437,7.000
7,52.400,0.04,2.1779,2.17790,7.000
7,52.467,0.09,2.3109,2.31090,7.000
7,52.533,0.21,2.4444,2.44443,7.000
7,52.600,0.40,2.5778,2.57780,7.000
7,52.667,0.70,2.7111,2.71107,7.000
7,52.733,1.10,2.8444,2.84443,7.000
7,52.800,1.62,2.9777,2.97770,7.000
7,52.867,2.26,3.1111,3.11113,7.000
7,52.933,3.03,3.2445,3.24450,7.000
7,53.000,3.96,3.3778,3.37780,7.000
7,53.067,5.08,3.5112,3.51117,7.000
7,53.133,6.37,3.6444,3.64437,7.000
7,53.200,7.88,3.7778,3.77780,7.000
7,53.267,9.60,3.9111,3.91107,7.000
7,53.333,11.54,4.0445,4.04447,7.000
7,53.400,13.76,4.1776,4.17760,7.000
7,53.467,16.26,4.3110,4.31103,7.000
7,53.533,19.16,4.4445,4.44447,7.000
7,53.667,23.98,4.6175,4.61753,7.000
7,53.733,21.73,4.5514,4.55143,7.000
7,53.800,17.31,4.4187,4.41870,7.000
7,53.867,13.83,4.2852,4.28517,7.000
7,53.933,11.10,4.1520,4.15197,7.000
7,54.000,8.89,4.0187,4.01870,7.000
7,54.067,7.08,3.8852,3.88520,7.000
7,54.133,5.59,3.7519,3.75190,7.000
7,54.200,4.39,3.6184,3.61840,7.000
7,54.267,3.39,3.4853,3.48530,7.000
7,54.333,2.60,3.3520,3.35197,7.000
7,54.400,1.95,3.2187,3.21870,7.000
7,54.467,1.39,3.0852,3.08520,7.000
7,54.533,0.95,2.9518,2.95180,7.000
7,54.600,0.60,2.8186,2.81860,7.000
7,54.667,0.35,2.6852,2.68520,7.000
7,54.733,0.17,2.5519,2.55190,7.000
7,54.800,0.08,2.4183,2.41830,7.000
7,54.867,0.02,2.2852,2.28520,7.000
7,54.933,0.01,2.1518,2.15180,7.000
7,55.000,0.00,2.0184,2.01840,7.000
7,55.067,0.00,1.8853,1.88533,7.000
7,55.133,0.00,1.7519,1.75190,7.000
7,55.200,0.00,1.6183,1.61830,7.000
7,55.267,0.00,1.4853,1.48533,7.000
7,55.333,0.01,1.3519,1.35190,7.000
7,55.400,0.01,1.2183,1.21830,7.000
7,55.467,0.00,1.0852,1.08523,7.000
7,55.533,0.00,0.9518,0.95183,7.000
7,55.600,0.01,0.8182,0.81820,7.000
7,55.667,0.00,0.6853,0.68527,7.000
7,55.733,0.00,0.5518,0.55183,7.000
7,55.800,0.01,0.4181,0.41810,7.000
7,55.867,0.00,0.2853,0.28527,7.000
7,55.933,0.00,0.1518,0.15183,7.000
7,56.000,0.01,0.0182,0.01820,7.000
7,56.133,0.00,-0.1277,-0.12773,7.000
7,56.200,0.00,-0.0449,-0.04490,7.000
7,56.267,0.00,0.0007,0.00067,7.000
7,56.333,0.01,-0.0002,-0.00020,7.000
7,56.400,0.00,-0.0002,-0.00020,7.000
7,56.467,0.00,-0.0002,-0.00020,7.000
7,56.533,0.00,-0.0002,-0.00020,7.000
7,56.600,0.01,-0.0002,-0.00020,7.000
7,56.667,0.00,-0.0002,-0.00020,7.000
7,56.733,0.00,-0.0002,-0.00020,7.000
7,56.800,0.00,-0.0002,-0.00020,7.000
7,56.867,0.00,-0.0002,-0.00020,7.000
7,56.933,0.00,-0.0002,-0.00020,7.000
7,57.000,0.01,-0.0002,-0.00020,7.000
7,57.067,0.00,-0.0002,-0.00020,7.000
7,57.133,0.00,-0.0002,-0.00020,7.000
7,57.200,0.00,-0.0002,-0.00020,7.000
7,57.267,0.00,-0.0002,-0.00020,7.000
7,57.333,0.01,-0.0002,-0.00020,7.000
7,57.400,0.00,-0.0002,-0.00020,7.000
7,57.467,0.00,-0.0002,-0.00020,7.000
7,57.533,0.00,-0.0002,-0.00020,7.000
7,57.600,-0.01,-0.0002,-0.00020,7.000
7,57.667,0.01,-0.0002,-0.00020,7.000
7,57.733,0.01,-0.0002,-0.00020,7.000
7,57.800,0.01,-0.0001,-0.00010,7.000
7,57.867,0.00,-0.0001,-0.00010,7.000
7,57.933,0.01,-0.0001,-0.00010,7.000
7,58.000,0.01,-0.0001,-0.00010,7.000
7,58.067,0.01,-0.0001,-0.00010,7.000
7,58.133,0.00,-0.0001,-0.00010,7.000
7,58.200,0.00,-0.0001,-0.00010,7.000
7,58.267,0.00,-0.0001,-0.00010,7.000
7,58.333,0.00,-0.0001,-0.00010,7.000
7,58.400,0.00,-0.0001,-0.00010,7.000
7,58.467,0.00,-0.0001,-0.00010,7.000
7,58.533,0.00,-0.0001,-0.00010,7.000
7,58.600,0.01,-0.0001,-0.00010,7.000
7,58.667,0.00,-0.0001,-0.00010,7.000
7,58.733,0.01,-0.0001,-0.00010,7.000
7,58.800,0.00,-0.0001,-0.00010,7.000
7,58.867,0.01,-0.0001,-0.00010,7.000
7,58.933,0.01,-0.0001,-0.00010,7.000
7,59.000,0.01,-0.0001,-0.00010,7.000
7,59.067,0.01,-0.0001,-0.00010,7.000
7,59.200,0.01,-0.0001,-0.00010,7.000
7,59.267,0.01,-0.0001,-0.00010,7.000
7,59.333,0.00,-0.0001,-0.00010,7.000
7,59.400,0.01,-0.0001,-0.00010,7.000
7,59.467,0.01,-0.0001,-0.00010,7.000
7,59.533,0.00,-0.0001,-0.00010,7.000
8,59.867,0.01,0.1107,0.11067,8.000
8,59.933,0.00,0.2443,0.24430,8.000
8,60.000,0.01,0.3778,0.37780,8.000
8,60.067,0.01,0.5109,0.51090,8.000
8,60.133,0.01,0.6443,0.64430,8.000
8,60.200,0.01,0.7778,0.77780,8.000
8,60.267,0.01,0.9108,0.91083,8.000
8,60.333,0.01,1.0443,1.04427,8.000
8,60.400,0.01,1.1779,1.17790,8.000
8,60.467,0.01,1.3110,1.31097,8.000
8,60.533,0.01,1.4444,1.44437,8.000
8,60.600,0.01,1.5779,1.57790,8.000
8,60.667,0.01,1.7109,1.71093,8.000
8,60.733,0.02,1.8443,1.84433,8.000
8,60.800,0.02,1.9779,1.97790,8.000
8,60.867,0.03,2.1109,2.11087,8.000
8,60.933,0.06,2.2442,2.24423,8.000
8,61.000,0.15,2.3777,2.37770,8.000
8,61.067,0.30,2.5110,2.51103,8.000
8,61.133,0.54,2.6444,2.64437,8.000
8,61.200,0.88,2.7778,2.77780,8.000
8,61.267,1.35,2.9110,2.91100,8.000
8,61.333,1.93,3.0444,3.04440,8.000
8,61.400,2.63,3.1778,3.17780,8.000
8,61.467,3.47,3.3112,3.31120,8.000
8,61.533,4.49,3.4446,3.44457,8.000
8,61.600,5.70,3.5776,3.57760,8.000
8,61.667,7.08,3.7111,3.71107,8.000
8,61.733,8.69,3.8444,3.84443,8.000
8,61.800,10.52,3.9778,3.97780,8.000
8,61.867,12.60,4.1112,4.11117,8.000
8,61.933,14.95,4.2444,4.24443,8.000
8,62.000,17.66,4.3775,4.37750,8.000
8,62.067,20.77,4.5111,4.51110,8.000
8,62.200,23.30,4.5988,4.59880,8.000
8,62.267,19.38,4.4852,4.48517,8.000
8,62.333,15.42,4.3519,4.35187,8.000
8,62.400,12.36,4.2187,4.21870,8.000
8,62.467,9.93,4.0852,4.08523,8.000
8,62.533,7.93,3.9519,3.95190,8.000
8,62.600,6.30,3.8187,3.81870,8.000
8,62.667,4.96,3.6851,3.68510,8.000
8,62.733,3.87,3.5518,3.55183,8.000
8,62.800,2.98,3.4186,3.41860,8.000
8,62.867,2.25,3.2853,3.28527,8.000
8,62.933,1.66,3.1519,3.15190,8.000
8,63.000,1.17,3.0185,3.01850,8.000
8,63.067,0.77,2.8852,2.88520,8.000
8,63.133,0.48,2.7519,2.75193,8.000
8,63.200,0.25,2.6184,2.61840,8.000
8,63.267,0.12,2.4853,2.48527,8.000
8,63.333,0.05,2.3518,2.35177,8.000
8,63.400,0.02,2.2184,2.21840,8.000
8,63.467,0.01,2.0851,2.08507,8.000
8,63.533,0.01,1.9519,1.95193,8.000
8,63.600,0.00,1.8184,1.81840,8.000
8,63.667,0.01,1.6852,1.68517,8.000
8,63.733,0.01,1.5519,1.55187,8.000
8,63.800,0.01,1.4183,1.41830,8.000
8,63.867,0.01,1.2852,1.28523,8.000
8,63.933,0.01,1.1518,1.15183,8.000
8,64.000,0.01,1.0183,1.01830,8.000
8,64.067,0.01,0.8851,0.88513,8.000
8,64.133,0.01,0.7518,0.75183,8.000
8,64.200,0.02,0.6182,0.61820,8.000
8,64.267,0.01,0.4852,0.48517,8.000
8,64.333,0.00,0.3519,0.35190,8.000
8,64.400,0.00,0.2183,0.21830,8.000
8,64.467,0.02,0.0851,0.08510,8.000
8,64.600,0.01,-0.1294,-0.12940,8.000
8,64.667,0.02,-0.0990,-0.09900,8.000
8,64.733,0.01,-0.0087,-0.00870,8.000
8,64.800,0.02,-0.0003,-0.00030,8.000
8,64.867,0.01,-0.0002,-0.00020,8.000
8,64.933,0.01,-0.0002,-0.00020,8.000
8,65.000,0.01,-0.0002,-0.00020,8.000
8,65.067,0.02,-0.0002,-0.00020,8.000
8,65.133,0.01,-0.0002,-0.00020,8.000
8,65.200,0.02,-0.0002,-0.00020,8.000
8,65.267,0.01,-0.0002,-0.00020,8.000
8,65.333,0.01,-0.0002,-0.00020,8.000
8,65.400,0.01,-0.0002,-0.00020,8.000
8,65.467,0.01,-0.0002,-0.00020,8.000
8,65.533,0.01,-0.0002,-0.00020,8.000
8,65.600,0.01,-0.0002,-0.00020,8.000
8,65.667,0.01,-0.0002,-0.00020,8.000
8,65.733,0.01,-0.0002,-0.00020,8.000
8,65.800,0.01,-0.0002,-0.00020,8.000
8,65.867,0.01,-0.0002,-0.00020,8.000
8,65.933,0.01,-0.0002,-0.00020,8.000
8,66.000,0.01,-0.0002,-0.00020,8.000
8,66.067,0.01,-0.0002,-0.00020,8.000
8,66.133,0.00,-0.0002,-0.00020,8.000
8,66.200,0.01,-0.0002,-0.00020,8.000
8,66.267,0.02,-0.0002,-0.00020,8.000
8,66.333,0.01,-0.0002,-0.00020,8.000
8,66.400,0.01,-0.0002,-0.00020,8.000
8,66.467,0.01,-0.0002,-0.00020,8.000
8,66.533,0.01,-0.0002,-0.00020,8.000
8,66.600,0.01,-0.0002,-0.00020,8.000
8,66.667,0.01,-0.0002,-0.00020,8.000
8,66.733,0.01,-0.0002,-0.00020,8.000
8,66.800,0.02,-0.0001,-0.00010,8.000
8,66.867,0.01,-0.0001,-0.00010,8.000
8,66.933,0.00,-0.0001,-0.00010,8.000
8,67.000,0.01,-0.0001,-0.00010,8.000
8,67.067,0.01,-0.0001,-0.00010,8.000
8,67.133,0.01,-0.0001,-0.00010,8.000
8,67.200,0.01,-0.0001,-0.00010,8.000
8,67.267,0.01,-0.0001,-0.00010,8.000
8,67.333,0.01,-0.0001,-0.00010,8.000
8,67.400,0.01,-0.0001,-0.00010,8.000
8,67.467,0.01,-0.0001,-0.00010,8.000
8,67.533,0.01,-0.0001,-0.00010,8.000
8,67.600,0.01,-0.0001,-0.00010,8.000
8,67.733,0.01,-0.0001,-0.00010,8.000
8,67.800,0.01,-0.0001,-0.00010,8.000
8,67.867,0.01,-0.0001,-0.00010,8.000
8,67.933,0.01,-0.0001,-0.00010,8.000
8,68.000,0.02,-0.0001,-0.00010,8.000
8,68.067,0.01,-0.0001,-0.00010,8.000
9,68.400,-0.01,0.1212,0.12120,9.000
9,68.467,-0.01,0.2551,0.25513,9.000
9,68.533,-0.01,0.3884,0.38840,9.000
9,68.600,-0.01,0.5214,0.52140,9.000
9,68.667,-0.02,0.6552,0.65517,9.000
9,68.733,-0.01,0.7884,0.78840,9.000
9,68.800,-0.01,0.9214,0.92140,9.000
9,68.867,-0.01,1.0551,1.05510,9.000
9,68.933,-0.01,1.1885,1.18850,9.000
9,69.000,-0.01,1.3214,1.32140,9.000
9,69.067,-0.01,1.4552,1.45517,9.000
9,69.133,-0.01,1.5885,1.58850,9.000
9,69.200,-0.01,1.7214,1.72140,9.000
9,69.267,0.00,1.8552,1.85517,9.000
9,69.333,0.00,1.9885,1.98850,9.000
9,69.400,0.02,2.1214,2.12140,9.000
9,69.467,0.05,2.2551,2.25507,9.000
9,69.533,0.14,2.3884,2.38840,9.000
9,69.600,0.30,2.5216,2.52160,9.000
9,69.667,0.55,2.6551,2.65513,9.000
9,69.733,0.90,2.7885,2.78853,9.000
9,69.800,1.37,2.9215,2.92150,9.000
9,69.867,1.96,3.0551,3.05513,9.000
9,69.933,2.67,3.1886,3.18857,9.000
9,70.000,3.52,3.3217,3.32170,9.000
9,70.067,4.56,3.4552,3.45520,9.000
9,70.133,5.78,3.5884,3.58837,9.000
9,70.200,7.17,3.7216,3.72160,9.000
9,70.267,8.80,3.8551,3.85510,9.000
9,70.333,10.65,3.9885,3.98850,9.000
9,70.400,12.74,4.1217,4.12170,9.000
9,70.467,15.12,4.2550,4.25500,9.000
9,70.533,17.85,4.3884,4.38840,9.000
9,70.600,21.00,4.5218,4.52180,9.000
9,70.733,23.26,4.5990,4.59897,9.000
9,70.800,19.21,4.4825,4.48250,9.000
9,70.867,15.31,4.3492,4.34923,9.000
9,70.933,12.27,4.2159,4.21587,9.000
9,71.000,9.85,4.0827,4.08270,9.000
9,71.067,7.86,3.9493,3.94927,9.000
9,71.133,6.23,3.8159,3.81587,9.000
9,71.200,4.90,3.6826,3.68260,9.000
9,71.267,3.82,3.5491,3.54913,9.000
9,71.333,2.94,3.4159,3.41590,9.000
9,71.400,2.21,3.2827,3.28270,9.000
9,71.467,1.63,3.1492,3.14920,9.000
9,71.533,1.14,3.0158,3.01580,9.000
9,71.600,0.75,2.8828,2.88280,9.000
9,71.667,0.44,2.7492,2.74917,9.000
9,71.733,0.23,2.6158,2.61577,9.000
9,71.800,0.09,2.4829,2.48290,9.000
9,71.867,0.03,2.3491,2.34907,9.000
9,71.933,-0.01,2.2157,2.21573,9.000
9,72.000,-0.01,2.0827,2.08270,9.000
9,72.067,-0.01,1.9491,1.94913,9.000
9,72.133,-0.01,1.8157,1.81570,9.000
9,72.200,-0.02,1.6828,1.68280,9.000
9,72.267,-0.01,1.5491,1.54907,9.000
9,72.333,-0.01,1.4157,1.41570,9.000
9,72.400,-0.01,1.2828,1.28280,9.000
9,72.467,-0.01,1.1490,1.14903,9.000
9,72.533,-0.01,1.0158,1.01577,9.000
9,72.600,-0.02,0.8827,0.88270,9.000
9,72.667,-0.01,0.7490,0.74903,9.000
9,72.733,-0.01,0.6157,0.61573,9.000
9,72.800,-0.01,0.4827,0.48270,9.000
9,72.867,-0.01,0.3490,0.34903,9.000
9,72.933,-0.01,0.2157,0.21570,9.000
9,73.000,-0.01,0.0826,0.08260,9.000
9,73.067,-0.01,-0.0509,-0.05090,9.000
9,73.200,-0.01,-0.1385,-0.13850,9.000
9,73.267,-0.01,-0.0343,-0.03433,9.000
9,73.333,-0.01,-0.0004,-0.00037,9.000
9,73.400,-0.01,-0.0003,-0.00030,9.000
9,73.467,-0.01,-0.0003,-0.00030,9.000
9,73.533,-0.02,-0.0003,-0.00030,9.000
9,73.600,-0.02,-0.0003,-0.00030,9.000
9,73.667,-0.01,-0.0003,-0.00030,9.000
9,73.733,-0.01,-0.0003,-0.00030,9.000
9,73.800,-0.01,-0.0003,-0.00030,9.000
9,73.867,-0.01,-0.0003,-0.00030,9.000
9,73.933,-0.01,-0.0003,-0.00030,9.000
9,74.000,-0.01,-0.0002,-0.00020,9.000
9,74.067,-0.02,-0.0002,-0.00020,9.000
9,74.133,-0.01,-0.0002,-0.00020,9.000
9,74.200,-0.01,-0.0002,-0.00020,9.000
9,74.267,-0.01,-0.0002,-0.00020,9.000
9,74.333,-0.01,-0.0002,-0.00020,9.000
9,74.400,-0.01,-0.0002,-0.00020,9.000
9,74.467,-0.01,-0.0002,-0.00020,9.000
9,74.533,-0.01,-0.0002,-0.00020,9.000
9,74.600,-0.01,-0.0002,-0.00020,9.000
9,74.667,-0.01,-0.0002,-0.00020,9.000
9,74.733,0.00,-0.0002,-0.00020,9.000
9,74.800,-0.01,-0.0002,-0.00020,9.000
9,74.867,-0.02,-0.0002,-0.00020,9.000
9,74.933,-0.01,-0.0002,-0.00020,9.000
9,75.000,-0.02,-0.0002,-0.00020,9.000
9,75.067,-0.01,-0.0002,-0.00020,9.000
9,75.133,-0.01,-0.0002,-0.00020,9.000
9,75.200,-0.01,-0.0002,-0.00020,9.000
9,75.267,-0.02,-0.0002,-0.00020,9.000
9,75.333,-0.01,-0.0002,-0.00020,9.000
9,75.400,0.00,-0.0002,-0.00020,9.000
9,75.467,-0.01,-0.0002,-0.00020,9.000
9,75.533,-0.01,-0.0002,-0.00020,9.000
9,75.600,-0.01,-0.0002,-0.00020,9.000
9,75.667,-0.02,-0.0002,-0.00020,9.000
9,75.733,0.00,-0.0002,-0.00020,9.000
9,75.800,-0.02,-0.0002,-0.00020,9.000
9,75.867,-0.01,-0.0002,-0.00020,9.000
9,75.933,-0.01,-0.0002,-0.00020,9.000
9,76.000,-0.01,-0.0002,-0.00020,9.000
9,76.067,-0.01,-0.0002,-0.00020,9.000
9,76.133,-0.02,-0.0002,-0.00020,9.000
9,76.267,-0.01,-0.0002,-0.00020,9.000
9,76.333,-0.01,-0.0002,-0.00020,9.000
9,76.400,-0.01,-0.0002,-0.00020,9.000
9,76.467,-0.01,-0.0001,-0.00013,9.000
9,76.533,-0.01,-0.0001,-0.00010,9.000
9,76.600,-0.01,-0.0001,-0.00010,9.000
9,76.667,0.00,-0.0001,-0.00010,9.000
10,76.800,-0.01,-0.0001,-0.00010,10.000
10,76.933,0.00,0.1622,0.16230,10.000
10,77.000,0.00,0.2959,0.29600,10.000
10,77.067,0.00,0.4290,0.42913,10.000
10,77.133,-0.01,0.5623,0.56243,10.000
10,77.200,0.00,0.6958,0.69590,10.000
10,77.267,-0.01,0.8289,0.82903,10.000
10,77.333,0.00,0.9623,0.96237,10.000
10,77.400,0.00,1.0958,1.09590,10.000
10,77.467,0.00,1.2291,1.22920,10.000
10,77.533,-0.01,1.3624,1.36253,10.000
10,77.600,-0.01,1.4957,1.49580,10.000
10,77.667,0.00,1.6291,1.62917,10.000
10,77.733,0.00,1.7623,1.76243,10.000
10,77.800,0.01,1.8959,1.89600,10.000
10,77.867,0.01,2.0291,2.02920,10.000
10,77.933,0.03,2.1623,2.16243,10.000
10,78.000,0.09,2.2956,2.29570,10.000
10,78.067,0.18,2.4292,2.42927,10.000
10,78.133,0.36,2.5625,2.56257,10.000
10,78.200,0.66,2.6957,2.69580,10.000
10,78.267,1.05,2.8292,2.82930,10.000
10,78.333,1.55,2.9625,2.96257,10.000
10,78.400,2.16,3.0957,3.09580,10.000
10,78.467,2.92,3.2293,3.22940,10.000
10,78.533,3.83,3.3627,3.36277,10.000
10,78.600,4.92,3.4956,3.49570,10.000
10,78.667,6.20,3.6291,3.62920,10.000
10,78.733,7.66,3.7625,3.76257,10.000
10,78.800,9.36,3.8955,3.89560,10.000
10,78.867,11.28,4.0291,4.02923,10.000
10,78.933,13.45,4.1625,4.16263,10.000
10,79.000,15.92,4.2954,4.29550,10.000
10,79.067,18.78,4.4292,4.42930,10.000
10,79.200,24.66,4.6434,4.64350,10.000
10,79.267,23.59,4.6132,4.61330,10.000
10,79.333,19.24,4.4900,4.49013,10.000
10,79.400,15.34,4.3564,4.35650,10.000
10,79.467,12.32,4.2233,4.22343,10.000
10,79.533,9.88,4.0901,4.09017,10.000
10,79.600,7.90,3.9564,3.95650,10.000
10,79.667,6.27,3.8233,3.82343,10.000
10,79.733,4.94,3.6899,3.69000,10.000
10,79.800,3.85,3.5564,3.55650,10.000
10,79.867,2.96,3.4234,3.42347,10.000
10,79.933,2.24,3.2900,3.29007,10.000
10,80.000,1.65,3.1564,3.15650,10.000
10,80.067,1.15,3.0232,3.02333,10.000
10,80.133,0.76,2.8900,2.89010,10.000
10,80.200,0.47,2.7564,2.75650,10.000
10,80.267,0.24,2.6232,2.62333,10.000
10,80.333,0.11,2.4899,2.49003,10.000
10,80.400,0.04,2.3564,2.35650,10.000
10,80.467,0.01,2.2232,2.22327,10.000
10,80.533,0.00,2.0897,2.08980,10.000
10,80.600,0.00,1.9565,1.95660,10.000
10,80.667,-0.01,1.8232,1.82333,10.000
10,80.733,-0.01,1.6898,1.68987,10.000
10,80.800,-0.01,1.5566,1.55670,10.000
10,80.867,0.00,1.4231,1.42323,10.000
10,80.933,-0.01,1.2899,1.28997,10.000
10,81.000,-0.01,1.1566,1.15670,10.000
10,81.067,0.00,1.0232,1.02327,10.000
10,81.133,0.00,0.8897,0.88983,10.000
10,81.200,0.00,0.7566,0.75670,10.000
10,81.267,0.00,0.6231,0.62320,10.000
10,81.333,0.00,0.4897,0.48977,10.000
10,81.400,-0.01,0.3567,0.35680,10.000
10,81.467,0.00,0.2231,0.22320,10.000
10,81.533,-0.01,0.0896,0.08973,10.000
10,81.600,-0.01,-0.0433,-0.04320,10.000
10,81.733,-0.01,-0.1208,-0.12073,10.000
10,81.800,0.00,-0.0213,-0.02120,10.000
10,81.867,0.00,-0.0003,-0.00020,10.000
10,81.933,0.00,-0.0002,-0.00010,10.000
10,82.000,-0.01,-0.0002,-0.00010,10.000
10,82.067,-0.01,-0.0002,-0.00010,10.000
10,82.133,-0.01,-0.0002,-0.00010,10.000
10,82.200,-0.01,-0.0002,-0.00010,10.000
10,82.267,-0.01,-0.0002,-0.00010,10.000
10,82.333,-0.01,-0.0002,-0.00010,10.000
10,82.400,-0.01,-0.0002,-0.00010,10.000
10,82.467,-0.01,-0.0002,-0.00010,10.000
10,82.533,-0.01,-0.0002,-0.00010,10.000
10,82.600,0.00,-0.0002,-0.00010,10.000
10,82.667,-0.01,-0.0002,-0.00010,10.000
10,82.733,0.00,-0.0002,-0.00010,10.000
10,82.800,-0.01,-0.0002,-0.00010,10.000
10,82.867,0.00,-0.0002,-0.00010,10.000
10,82.933,-0.01,-0.0002,-0.00010,10.000
10,83.000,0.00,-0.0002,-0.00010,10.000
10,83.067,0.00,-0.0002,-0.00010,10.000
10,83.133,-0.01,-0.0002,-0.00010,10.000
10,83.200,0.00,-0.0002,-0.00010,10.000
10,83.267,0.00,-0.0002,-0.00010,10.000
10,83.333,0.00,-0.0002,-0.00010,10.000
10,83.400,-0.01,-0.0002,-0.00010,10.000
10,83.467,0.00,-0.0002,-0.00010,10.000
10,83.533,0.00,-0.0002,-0.00010,10.000
10,83.600,0.00,-0.0002,-0.00010,10.000
10,83.667,0.00,-0.0002,-0.00010,10.000
10,83.733,0.00,-0.0002,-0.00010,10.000
10,83.800,0.00,-0.0002,-0.00010,10.000
10,83.867,-0.01,-0.0002,-0.00010,10.000
10,83.933,-0.01,-0.0002,-0.00010,10.000
10,84.000,0.01,-0.0002,-0.00010,10.000
10,84.067,0.00,-0.0002,-0.00010,10.000
10,84.133,-0.01,-0.0002,-0.00010,10.000
10,84.200,-0.01,-0.0002,-0.00010,10.000
10,84.267,0.00,-0.0002,-0.00010,10.000
10,84.333,0.00,-0.0002,-0.00010,10.000
10,84.400,0.00,-0.0002,-0.00010,10.000
10,84.467,-0.01,-0.0002,-0.00010,10.000
10,84.533,-0.01,-0.0002,-0.00010,10.000
10,84.600,0.00,-0.0002,-0.00010,10.000
10,84.667,-0.01,-0.0002,-0.00010,10.000
10,84.800,-0.01,-0.0001,0.00000,10.000
10,84.867,0.00,-0.0001,0.00000,10.000
10,84.933,0.00,-0.0001,0.00000,10.000
10,85.000,0.00,-0.0001,0.00000,10.000
10,85.067,-0.01,-0.0001,0.00000,10.000
10,85.133,0.00,-0.0001,0.00000,10.000
10,85.200,0.00,-0.0001,0.00000,10.000