File: AIME_journal_files/AIME_data/calibDATA_loadcell/date_02:15:2018/Instron_02.15.2018/2_20N_0__7mm.s_0_0.txt
""
"Test Method","Radhen_Load_Cntrl_Cmprsn_250N_12-7.msm"
"Sample I. D.","Sample1.mss"
"Specimen Number","22"

"TheCycle_Output ()","_Time (s)","_Load (N)","_Extension (mm)","RealTimeDepth (mm)","CycleNumber ()"

1,0.333,-0.01,0.1567,0.15670,1.000
1,0.400,-0.01,0.3995,0.39950,1.000
1,0.467,0.00,0.7535,0.75350,1.000
1,0.533,-0.01,1.2058,1.20577,1.000
1,0.600,-0.01,1.6722,1.67220,1.000
1,0.667,-0.01,2.1390,2.13903,1.000
1,0.733,-0.01,2.6055,2.60550,1.000
1,0.800,0.00,3.0724,3.07240,1.000
1,0.867,-0.01,3.5390,3.53900,1.000
1,0.933,0.00,4.0056,4.00563,1.000
1,1.000,0.02,4.4724,4.47240,1.000
1,1.067,0.54,4.9391,4.93907,1.000
1,1.133,2.54,5.4056,5.40560,1.000
1,1.200,6.30,5.8724,5.87240,1.000
1,1.267,12.38,6.3391,6.33907,1.000
1,1.333,21.69,6.8057,6.80573,1.000
1,1.467,51.31,7.5970,7.59697,1.000
1,1.533,64.90,7.8305,7.83047,1.000
1,1.600,72.96,7.9529,7.95290,1.000
1,1.667,71.86,7.9643,7.96427,1.000
1,1.733,59.74,7.8647,7.86470,1.000
1,1.800,41.64,7.6539,7.65390,1.000
1,1.867,25.31,7.3314,7.33140,1.000
1,1.933,12.97,6.9002,6.90023,1.000
1,2.000,6.15,6.4337,6.43370,1.000
1,2.067,3.12,5.9669,5.96687,1.000
1,2.133,1.32,5.5002,5.50017,1.000
1,2.200,0.29,5.0334,5.03340,1.000
1,2.267,-0.01,4.5670,4.56700,1.000
1,2.333,0.00,4.1000,4.10003,1.000
1,2.400,-0.01,3.6336,3.63360,1.000
1,2.467,-0.01,3.1669,3.16687,1.000
1,2.533,-0.01,2.7001,2.70013,1.000
1,2.600,-0.02,2.2334,2.23340,1.000
1,2.667,-0.01,1.7668,1.76680,1.000
1,2.733,-0.01,1.3001,1.30013,1.000
1,2.800,-0.01,0.8336,0.83360,1.000
1,2.867,-0.01,0.3668,0.36680,1.000
1,3.067,-0.01,-0.8328,-0.83280,1.000
1,3.133,-0.01,-1.0330,-1.03303,1.000
1,3.200,-0.01,-1.1222,-1.12220,1.000
1,3.267,0.00,-1.1002,-1.10017,1.000
1,3.333,-0.01,-0.9672,-0.96723,1.000
1,3.400,-0.01,-0.7230,-0.72300,1.000
1,3.467,-0.01,-0.3964,-0.39643,1.000
1,3.533,0.00,-0.1553,-0.15530,1.000
1,3.600,0.00,-0.0250,-0.02500,1.000
1,3.667,0.00,-0.0003,-0.00030,1.000
1,3.733,-0.01,-0.0003,-0.00030,1.000
1,3.800,0.00,-0.0003,-0.00030,1.000
1,3.867,0.00,-0.0003,-0.00030,1.000
1,3.933,-0.01,-0.0003,-0.00030,1.000
1,4.000,-0.01,-0.0003,-0.00030,1.000
1,4.067,-0.01,-0.0003,-0.00030,1.000
1,4.133,0.00,-0.0003,-0.00030,1.000
1,4.200,-0.01,-0.0003,-0.00030,1.000
1,4.267,-0.01,-0.0003,-0.00030,1.000
1,4.333,-0.01,-0.0003,-0.00030,1.000
1,4.400,-0.01,-0.0003,-0.00030,1.000
1,4.467,-0.01,-0.0003,-0.00030,1.000
1,4.533,-0.01,-0.0003,-0.00027,1.000
1,4.600,-0.01,-0.0002,-0.00020,1.000
1,4.667,-0.01,-0.0002,-0.00020,1.000
1,4.733,-0.01,-0.0002,-0.00020,1.000
1,4.800,-0.01,-0.0002,-0.00020,1.000
1,4.867,-0.01,-0.0002,-0.00020,1.000
1,4.933,-0.01,-0.0002,-0.00020,1.000
1,5.000,-0.01,-0.0002,-0.00020,1.000
1,5.067,0.00,-0.0002,-0.00020,1.000
1,5.133,-0.01,-0.0002,-0.00020,1.000
1,5.200,-0.01,-0.0002,-0.00020,1.000
1,5.267,0.00,-0.0002,-0.00020,1.000
1,5.333,-0.01,-0.0002,-0.00020,1.000
1,5.400,0.00,-0.0002,-0.00020,1.000
1,5.467,-0.01,-0.0002,-0.00020,1.000
1,5.533,0.00,-0.0002,-0.00020,1.000
1,5.600,0.00,-0.0002,-0.00020,1.000
1,5.667,-0.01,-0.0002,-0.00020,1.000
1,5.733,0.00,-0.0002,-0.00020,1.000
1,5.800,0.00,-0.0002,-0.00020,1.000
1,5.867,-0.01,-0.0002,-0.00020,1.000
1,5.933,-0.01,-0.0002,-0.00020,1.000
1,6.000,-0.01,-0.0002,-0.00020,1.000
2,6.400,0.01,0.1912,0.19130,2.000
2,6.467,0.01,0.4538,0.45390,2.000
2,6.533,0.01,0.8272,0.82727,2.000
2,6.600,0.01,1.2874,1.28750,2.000
2,6.667,0.01,1.7541,1.75420,2.000
2,6.733,0.01,2.2208,2.22087,2.000
2,6.800,0.01,2.6874,2.68750,2.000
2,6.867,0.01,3.1542,3.15430,2.000
2,6.933,0.01,3.6209,3.62097,2.000
2,7.000,0.01,4.0875,4.08760,2.000
2,7.067,0.05,4.5543,4.55443,2.000
2,7.133,0.76,5.0210,5.02107,2.000
2,7.200,2.97,5.4876,5.48770,2.000
2,7.267,7.02,5.9542,5.95427,2.000
2,7.333,13.48,6.4209,6.42103,2.000
2,7.400,23.44,6.8876,6.88770,2.000
2,7.533,53.28,7.6370,7.63707,2.000
2,7.600,65.96,7.8463,7.84640,2.000
2,7.667,72.29,7.9438,7.94393,2.000
2,7.733,69.03,7.9310,7.93113,2.000
2,7.800,55.23,7.8071,7.80720,2.000
2,7.867,37.45,7.5714,7.57150,2.000
2,7.933,22.09,7.2247,7.22483,2.000
2,8.000,10.89,6.7765,6.77660,2.000
2,8.067,5.26,6.3100,6.31013,2.000
2,8.133,2.62,5.8432,5.84327,2.000
2,8.200,1.02,5.3766,5.37670,2.000
2,8.267,0.16,4.9100,4.91010,2.000
2,8.333,0.01,4.4433,4.44343,2.000
2,8.400,0.01,3.9767,3.97680,2.000
2,8.467,0.01,3.5100,3.51007,2.000
2,8.533,0.01,3.0434,3.04353,2.000
2,8.600,0.01,2.5765,2.57660,2.000
2,8.667,0.01,2.1100,2.11013,2.000
2,8.733,0.01,1.6433,1.64340,2.000
2,8.800,0.01,1.1767,1.17680,2.000
2,8.867,0.01,0.7098,0.70993,2.000
2,8.933,0.01,0.2432,0.24330,2.000
2,9.067,0.01,-0.6168,-0.61670,2.000
2,9.133,0.01,-0.9001,-0.90000,2.000
2,9.200,0.00,-1.0728,-1.07270,2.000
2,9.267,0.02,-1.1337,-1.13357,2.000
2,9.333,0.02,-1.0843,-1.08423,2.000
2,9.400,0.01,-0.9237,-0.92360,2.000
2,9.467,0.01,-0.6511,-0.65097,2.000
2,9.533,0.01,-0.3309,-0.33080,2.000
2,9.600,0.01,-0.1147,-0.11460,2.000
2,9.667,0.01,-0.0105,-0.01043,2.000
2,9.733,0.01,-0.0002,-0.00010,2.000
2,9.800,0.01,-0.0002,-0.00010,2.000
2,9.867,0.01,-0.0001,-0.00003,2.000
2,9.933,0.01,-0.0001,0.00000,2.000
2,10.000,0.01,-0.0001,0.00000,2.000
2,10.067,0.01,-0.0001,0.00000,2.000
2,10.133,0.01,-0.0001,0.00000,2.000
2,10.200,0.01,-0.0001,0.00000,2.000
2,10.267,0.01,-0.0001,0.00000,2.000
2,10.333,0.01,-0.0001,0.00000,2.000
2,10.400,0.01,-0.0001,0.00000,2.000
2,10.467,0.01,-0.0001,0.00000,2.000
2,10.533,0.01,-0.0001,0.00000,2.000
2,10.600,0.01,-0.0001,0.00000,2.000
2,10.667,0.01,-0.0001,0.00000,2.000
2,10.733,0.01,-0.0001,0.00000,2.000
2,10.800,0.01,-0.0001,0.00000,2.000
2,10.867,0.01,-0.0001,0.00000,2.000
2,10.933,0.01,-0.0001,0.00000,2.000
2,11.000,0.01,-0.0001,0.00000,2.000
2,11.067,0.01,-0.0001,0.00000,2.000
2,11.133,0.01,-0.0001,0.00000,2.000
2,11.200,0.01,-0.0001,0.00000,2.000
2,11.267,0.01,-0.0001,0.00000,2.000
2,11.333,0.01,-0.0001,0.00000,2.000
2,11.400,0.01,-0.0001,0.00000,2.000
2,11.467,0.01,-0.0001,0.00000,2.000
2,11.533,0.01,-0.0001,0.00000,2.000
2,11.600,0.01,-0.0001,0.00000,2.000
2,11.667,0.01,-0.0001,0.00000,2.000
2,11.733,0.01,-0.0001,0.00000,2.000
2,11.800,0.01,-0.0001,0.00000,2.000
2,11.867,0.01,-0.0001,0.00000,2.000
2,11.933,0.00,-0.0001,0.00000,2.000
2,12.000,0.01,-0.0001,0.00000,2.000
3,12.400,0.00,0.0676,0.06760,3.000
3,12.467,-0.01,0.2468,0.24680,3.000
3,12.533,-0.01,0.5368,0.53677,3.000
3,12.600,-0.01,0.9375,0.93750,3.000
3,12.667,-0.01,1.4042,1.40417,3.000
3,12.733,-0.01,1.8708,1.87077,3.000
3,12.800,-0.01,2.3375,2.33750,3.000
3,12.867,-0.01,2.8043,2.80433,3.000
3,12.933,-0.01,3.2708,3.27083,3.000
3,13.000,-0.01,3.7377,3.73770,3.000
3,13.067,-0.01,4.2042,4.20423,3.000
3,13.133,0.10,4.6709,4.67090,3.000
3,13.200,1.13,5.1377,5.13770,3.000
3,13.267,3.75,5.6044,5.60437,3.000
3,13.333,8.31,6.0708,6.07083,3.000
3,13.400,15.50,6.5375,6.53750,3.000
3,13.533,41.75,7.4075,7.40747,3.000
3,13.600,56.60,7.6999,7.69990,3.000
3,13.667,67.96,7.8809,7.88093,3.000
3,13.733,72.14,7.9509,7.95093,3.000
3,13.800,66.22,7.9108,7.91080,3.000
3,13.867,50.63,7.7586,7.75860,3.000
3,13.933,33.20,7.4952,7.49523,3.000
3,14.000,18.79,7.1210,7.12100,3.000
3,14.067,9.04,6.6600,6.66003,3.000
3,14.133,4.43,6.1934,6.19337,3.000
3,14.200,2.13,5.7266,5.72660,3.000
3,14.267,0.73,5.2600,5.26000,3.000
3,14.333,0.05,4.7934,4.79337,3.000
3,14.400,-0.01,4.3268,4.32680,3.000
3,14.467,-0.01,3.8598,3.85983,3.000
3,14.533,-0.01,3.3933,3.39330,3.000
3,14.600,-0.01,2.9265,2.92650,3.000
3,14.667,-0.01,2.4601,2.46007,3.000
3,14.733,-0.01,1.9933,1.99333,3.000
3,14.800,-0.02,1.5266,1.52660,3.000
3,14.867,-0.01,1.0599,1.05990,3.000
3,14.933,-0.01,0.5933,0.59327,3.000
3,15.000,-0.01,0.1266,0.12660,3.000
3,15.133,-0.01,-0.6980,-0.69797,3.000
3,15.200,-0.01,-0.9540,-0.95400,3.000
3,15.267,-0.01,-1.0982,-1.09817,3.000
3,15.333,-0.01,-1.1315,-1.13153,3.000
3,15.400,-0.01,-1.0548,-1.05480,3.000
3,15.467,-0.01,-0.8657,-0.86570,3.000
3,15.533,-0.01,-0.5657,-0.56573,3.000
3,15.600,-0.01,-0.2662,-0.26620,3.000
3,15.667,-0.01,-0.0785,-0.07847,3.000
3,15.733,-0.01,-0.0018,-0.00180,3.000
3,15.800,-0.01,-0.0002,-0.00020,3.000
3,15.867,-0.01,-0.0001,-0.00010,3.000
3,15.933,-0.02,-0.0001,-0.00010,3.000
3,16.000,-0.01,-0.0001,-0.00010,3.000
3,16.067,-0.01,-0.0001,-0.00010,3.000
3,16.133,-0.01,-0.0001,-0.00010,3.000
3,16.200,-0.02,-0.0001,-0.00010,3.000
3,16.267,-0.01,-0.0001,-0.00010,3.000
3,16.333,-0.01,-0.0001,-0.00010,3.000
3,16.400,-0.02,-0.0001,-0.00010,3.000
3,16.467,-0.01,-0.0001,-0.00010,3.000
3,16.533,-0.01,-0.0001,-0.00010,3.000
3,16.600,0.00,-0.0001,-0.00010,3.000
3,16.667,-0.01,-0.0001,-0.00010,3.000
3,16.733,-0.01,-0.0001,-0.00010,3.000
3,16.800,0.00,-0.0001,-0.00010,3.000
3,16.867,0.00,-0.0001,-0.00010,3.000
3,16.933,-0.01,-0.0001,-0.00010,3.000
3,17.000,-0.01,-0.0001,-0.00010,3.000
3,17.067,-0.01,-0.0001,-0.00010,3.000
3,17.133,-0.01,-0.0001,-0.00010,3.000
3,17.200,-0.02,-0.0001,-0.00010,3.000
3,17.267,-0.01,-0.0001,-0.00010,3.000
3,17.333,-0.01,-0.0001,-0.00010,3.000
3,17.400,0.00,-0.0001,-0.00010,3.000
3,17.467,-0.01,-0.0001,-0.00010,3.000
3,17.533,-0.01,-0.0001,-0.00010,3.000
3,17.600,-0.01,-0.0001,-0.00010,3.000
3,17.667,-0.02,-0.0001,-0.00010,3.000
3,17.733,-0.01,-0.0001,-0.00010,3.000
3,17.800,-0.01,-0.0001,-0.00010,3.000
3,17.867,0.00,-0.0001,-0.00010,3.000
3,17.933,-0.01,-0.0001,-0.00010,3.000
3,18.000,0.00,-0.0001,-0.00010,3.000
3,18.067,-0.01,-0.0001,-0.00010,3.000
3,18.200,-0.01,-0.0001,-0.00010,3.000
4,18.467,0.02,0.0516,0.05163,4.000
4,18.533,0.01,0.2150,0.21500,4.000
4,18.600,0.01,0.4893,0.48930,4.000
4,18.667,0.02,0.8751,0.87507,4.000
4,18.733,0.00,1.3389,1.33890,4.000
4,18.800,0.02,1.8054,1.80540,4.000
4,18.867,0.02,2.2722,2.27217,4.000
4,18.933,0.00,2.7388,2.73880,4.000
4,19.000,0.00,3.2057,3.20570,4.000
4,19.067,0.02,3.6723,3.67230,4.000
4,19.133,0.01,4.1389,4.13887,4.000
4,19.200,0.08,4.6055,4.60550,4.000
4,19.267,0.91,5.0724,5.07237,4.000
4,19.333,3.27,5.5390,5.53897,4.000
4,19.400,7.50,6.0055,6.00550,4.000
4,19.467,14.30,6.4722,6.47217,4.000
4,19.667,55.02,7.6719,7.67187,4.000
4,19.733,67.54,7.8720,7.87203,4.000
4,19.800,73.33,7.9612,7.96120,4.000
4,19.867,69.21,7.9392,7.93920,4.000
4,19.933,54.48,7.8062,7.80623,4.000
4,20.000,36.45,7.5620,7.56200,4.000
4,20.067,21.18,7.2062,7.20623,4.000
4,20.133,10.37,6.7533,6.75327,4.000
4,20.200,5.03,6.2868,6.28680,4.000
4,20.267,2.51,5.8198,5.81980,4.000
4,20.333,0.98,5.3533,5.35327,4.000
4,20.400,0.15,4.8866,4.88660,4.000
4,20.467,0.00,4.4200,4.41997,4.000
4,20.533,0.02,3.9533,3.95330,4.000
4,20.600,0.01,3.4865,3.48650,4.000
4,20.667,0.01,3.0200,3.02000,4.000
4,20.733,0.01,2.5532,2.55317,4.000
4,20.800,0.01,2.0868,2.08680,4.000
4,20.867,0.01,1.6198,1.61983,4.000
4,20.933,0.01,1.1534,1.15337,4.000
4,21.000,0.01,0.6866,0.68660,4.000
4,21.067,0.01,0.2199,0.21990,4.000
4,21.200,0.01,-0.6527,-0.65270,4.000
4,21.267,0.02,-0.9469,-0.94687,4.000
4,21.333,0.01,-1.1302,-1.13023,4.000
4,21.400,0.00,-1.2028,-1.20280,4.000
4,21.467,0.01,-1.1641,-1.16413,4.000
4,21.533,0.01,-1.0145,-1.01450,4.000
4,21.600,0.01,-0.7535,-0.75350,4.000
4,21.667,0.01,-0.4155,-0.41547,4.000
4,21.733,0.01,-0.1672,-0.16720,4.000
4,21.800,0.01,-0.0299,-0.02990,4.000
4,21.867,0.00,-0.0002,-0.00023,4.000
4,21.933,0.01,-0.0001,-0.00010,4.000
4,22.000,0.01,-0.0001,-0.00010,4.000
4,22.067,0.01,-0.0001,-0.00010,4.000
4,22.133,0.01,-0.0001,-0.00010,4.000
4,22.200,0.01,-0.0001,-0.00010,4.000
4,22.267,0.01,-0.0001,-0.00010,4.000
4,22.333,0.01,-0.0001,-0.00010,4.000
4,22.400,0.02,-0.0001,-0.00010,4.000
4,22.467,0.01,-0.0001,-0.00010,4.000
4,22.533,0.01,-0.0001,-0.00010,4.000
4,22.600,0.01,-0.0001,-0.00010,4.000
4,22.667,0.01,-0.0001,-0.00010,4.000
4,22.733,0.01,-0.0001,-0.00010,4.000
4,22.800,0.01,-0.0001,-0.00010,4.000
4,22.867,0.01,-0.0001,-0.00010,4.000
4,22.933,0.01,-0.0001,-0.00010,4.000
4,23.000,0.01,-0.0001,-0.00010,4.000
4,23.067,0.01,-0.0001,-0.00010,4.000
4,23.133,0.02,-0.0001,-0.00010,4.000
4,23.200,0.01,-0.0001,-0.00010,4.000
4,23.267,0.01,-0.0001,-0.00010,4.000
4,23.333,0.01,-0.0001,-0.00010,4.000
4,23.400,0.01,-0.0001,-0.00010,4.000
4,23.467,0.01,-0.0001,-0.00010,4.000
4,23.533,0.00,-0.0001,-0.00010,4.000
4,23.600,0.00,-0.0001,-0.00010,4.000
4,23.667,0.01,-0.0001,-0.00010,4.000
4,23.733,0.01,-0.0001,-0.00010,4.000
4,23.800,0.01,-0.0001,-0.00010,4.000
4,23.867,0.01,-0.0001,-0.00010,4.000
4,23.933,0.01,-0.0001,-0.00010,4.000
4,24.000,0.01,-0.0001,-0.00010,4.000
4,24.067,0.00,-0.0001,-0.00010,4.000
4,24.133,0.01,-0.0001,-0.00010,4.000
4,24.200,0.00,-0.0001,-0.00010,4.000
5,24.600,0.01,0.1474,0.14740,5.000
5,24.667,0.00,0.3852,0.38520,5.000
5,24.733,0.00,0.7334,0.73343,5.000
5,24.800,-0.01,1.1828,1.18280,5.000
5,24.867,0.00,1.6492,1.64920,5.000
5,24.933,0.00,2.1160,2.11597,5.000
5,25.000,0.00,2.5824,2.58240,5.000
5,25.067,0.00,3.0492,3.04923,5.000
5,25.133,0.00,3.5159,3.51593,5.000
5,25.200,0.00,3.9825,3.98250,5.000
5,25.267,0.02,4.4492,4.44923,5.000
5,25.333,0.46,4.9159,4.91593,5.000
5,25.400,2.26,5.3824,5.38240,5.000
5,25.467,5.83,5.8491,5.84913,5.000
5,25.533,11.63,6.3159,6.31587,5.000
5,25.600,20.63,6.7825,6.78250,5.000
5,25.733,49.94,7.5826,7.58260,5.000
5,25.800,63.83,7.8220,7.82200,5.000
5,25.867,72.39,7.9494,7.94940,5.000
5,25.933,72.03,7.9664,7.96643,5.000
5,26.000,60.56,7.8728,7.87280,5.000
5,26.067,42.67,7.6670,7.66700,5.000
5,26.133,26.14,7.3503,7.35027,5.000
5,26.200,13.55,6.9235,6.92350,5.000
5,26.267,6.47,6.4570,6.45703,5.000
5,26.333,3.25,5.9902,5.99023,5.000
5,26.400,1.46,5.5237,5.52370,5.000
5,26.467,0.35,5.0570,5.05700,5.000
5,26.533,-0.01,4.5904,4.59037,5.000
5,26.600,0.00,4.1235,4.12350,5.000
5,26.667,0.00,3.6570,3.65700,5.000
5,26.733,0.00,3.1903,3.19033,5.000
5,26.800,0.00,2.7237,2.72370,5.000
5,26.867,-0.01,2.2570,2.25700,5.000
5,26.933,0.00,1.7903,1.79027,5.000
5,27.000,-0.01,1.3235,1.32350,5.000
5,27.067,0.00,0.8569,0.85693,5.000
5,27.133,0.00,0.3903,0.39030,5.000
5,27.200,0.00,-0.0763,-0.07630,5.000
5,27.333,0.00,-0.8494,-0.84937,5.000
5,27.400,-0.01,-1.0720,-1.07200,5.000
5,27.467,0.00,-1.1829,-1.18287,5.000
5,27.533,0.00,-1.1832,-1.18323,5.000
5,27.600,0.00,-1.0727,-1.07270,5.000
5,27.667,0.01,-0.8503,-0.85033,5.000
5,27.733,-0.01,-0.5215,-0.52153,5.000
5,27.800,0.00,-0.2360,-0.23600,5.000
5,27.867,0.00,-0.0617,-0.06173,5.000
5,27.933,-0.01,0.0017,0.00170,5.000
5,28.000,0.00,-0.0001,-0.00010,5.000
5,28.067,0.00,-0.0001,-0.00010,5.000
5,28.133,0.00,-0.0001,-0.00010,5.000
5,28.200,-0.01,-0.0001,-0.00010,5.000
5,28.267,0.00,-0.0001,-0.00010,5.000
5,28.333,0.01,-0.0001,-0.00010,5.000
5,28.400,0.00,-0.0001,-0.00010,5.000
5,28.467,-0.01,-0.0001,-0.00010,5.000
5,28.533,0.00,-0.0001,-0.00010,5.000
5,28.600,-0.01,-0.0001,-0.00010,5.000
5,28.667,0.00,-0.0001,-0.00010,5.000
5,28.733,-0.01,-0.0001,-0.00010,5.000
5,28.800,0.01,-0.0001,-0.00010,5.000
5,28.867,0.00,-0.0001,-0.00010,5.000
5,28.933,0.00,-0.0001,-0.00010,5.000
5,29.000,0.00,-0.0001,-0.00010,5.000
5,29.067,0.00,-0.0001,-0.00010,5.000
5,29.133,-0.01,-0.0001,-0.00010,5.000
5,29.200,-0.01,-0.0001,-0.00010,5.000
5,29.267,0.00,-0.0001,-0.00010,5.000
5,29.333,-0.01,-0.0001,-0.00010,5.000
5,29.400,0.00,-0.0001,-0.00010,5.000
5,29.467,0.00,-0.0001,-0.00010,5.000
5,29.533,0.00,-0.0001,-0.00010,5.000
5,29.600,0.00,-0.0001,-0.00010,5.000
5,29.667,0.00,-0.0001,-0.00010,5.000
5,29.733,0.00,-0.0001,-0.00010,5.000
5,29.800,0.00,-0.0001,-0.00010,5.000
5,29.867,0.00,-0.0001,-0.00010,5.000
5,29.933,0.00,-0.0001,-0.00010,5.000
5,30.000,0.00,-0.0001,-0.00010,5.000
5,30.067,0.00,-0.0001,-0.00010,5.000
5,30.133,0.00,-0.0001,-0.00010,5.000
5,30.200,0.00,-0.0001,-0.00010,5.000
5,30.267,-0.01,-0.0001,-0.00010,5.000
5,30.400,-0.01,-0.0001,-0.00010,5.000
6,30.667,0.01,0.1261,0.12607,6.000
6,30.733,0.01,0.3495,0.34947,6.000
6,30.800,0.01,0.6835,0.68350,6.000
6,30.867,0.01,1.1243,1.12430,6.000
6,30.933,0.01,1.5908,1.59083,6.000
6,31.000,0.00,2.0577,2.05770,6.000
6,31.067,0.01,2.5241,2.52413,6.000
6,31.133,0.00,2.9908,2.99083,6.000
6,31.200,0.01,3.4575,3.45750,6.000
6,31.267,0.00,3.9241,3.92407,6.000
6,31.333,0.01,4.3909,4.39090,6.000
6,31.400,0.34,4.8576,4.85760,6.000
6,31.467,1.95,5.3243,5.32433,6.000
6,31.533,5.26,5.7909,5.79090,6.000
6,31.600,10.74,6.2576,6.25760,6.000
6,31.667,19.29,6.7242,6.72423,6.000
6,31.800,48.54,7.5569,7.55690,6.000
6,31.867,63.51,7.8178,7.81780,6.000
6,31.933,73.88,7.9677,7.96770,6.000
6,32.000,75.79,8.0070,8.00700,6.000
6,32.067,65.99,7.9352,7.93517,6.000
6,32.133,47.82,7.7520,7.75200,6.000
6,32.200,29.99,7.4579,7.45790,6.000
6,32.267,16.14,7.0521,7.05207,6.000
6,32.333,7.70,6.5854,6.58543,6.000
6,32.400,3.83,6.1186,6.11860,6.000
6,32.467,1.84,5.6522,5.65217,6.000
6,32.533,0.58,5.1854,5.18537,6.000
6,32.600,0.02,4.7186,4.71860,6.000
6,32.667,0.00,4.2520,4.25203,6.000
6,32.733,0.00,3.7853,3.78533,6.000
6,32.800,-0.01,3.3186,3.31860,6.000
6,32.867,0.01,2.8520,2.85203,6.000
6,32.933,0.00,2.3854,2.38540,6.000
6,33.000,0.00,1.9186,1.91860,6.000
6,33.067,0.00,1.4519,1.45190,6.000
6,33.133,0.00,0.9852,0.98523,6.000
6,33.200,0.00,0.5187,0.51870,6.000
6,33.267,0.01,0.0518,0.05180,6.000
6,33.400,0.00,-0.7568,-0.75680,6.000
6,33.467,0.00,-1.0012,-1.00120,6.000
6,33.533,0.01,-1.1344,-1.13443,6.000
6,33.600,0.01,-1.1573,-1.15730,6.000
6,33.667,0.00,-1.0688,-1.06877,6.000
6,33.733,0.01,-0.8687,-0.86867,6.000
6,33.800,-0.01,-0.5578,-0.55780,6.000
6,33.867,-0.01,-0.2599,-0.25993,6.000
6,33.933,0.00,-0.0731,-0.07310,6.000
6,34.000,0.00,0.0028,0.00280,6.000
6,34.067,0.00,0.0000,0.00000,6.000
6,34.133,0.00,0.0000,0.00000,6.000
6,34.200,0.00,0.0000,0.00000,6.000
6,34.267,0.01,0.0000,0.00000,6.000
6,34.333,0.01,0.0000,0.00000,6.000
6,34.400,-0.01,0.0000,0.00000,6.000
6,34.467,0.00,0.0000,0.00000,6.000
6,34.533,0.00,0.0000,0.00000,6.000
6,34.600,0.01,0.0000,0.00000,6.000
6,34.667,0.00,0.0000,0.00000,6.000
6,34.733,0.01,0.0000,0.00000,6.000
6,34.800,0.02,0.0000,0.00000,6.000
6,34.867,0.01,0.0000,0.00000,6.000
6,34.933,0.01,0.0000,0.00000,6.000
6,35.000,0.01,0.0000,0.00000,6.000
6,35.067,0.00,0.0000,0.00000,6.000
6,35.133,0.01,0.0000,0.00000,6.000
6,35.200,0.01,0.0000,0.00000,6.000
6,35.267,0.00,0.0000,0.00000,6.000
6,35.333,0.01,0.0000,0.00000,6.000
6,35.400,0.00,0.0000,0.00000,6.000
6,35.467,0.00,0.0000,0.00000,6.000
6,35.533,0.01,0.0000,0.00000,6.000
6,35.600,0.00,0.0000,0.00000,6.000
6,35.667,0.01,0.0000,0.00000,6.000
6,35.733,-0.01,0.0000,0.00000,6.000
6,35.800,0.01,0.0000,0.00000,6.000
6,35.867,0.01,0.0000,0.00000,6.000
6,35.933,0.01,0.0000,0.00000,6.000
6,36.000,0.00,0.0000,0.00000,6.000
6,36.067,0.01,0.0000,0.00000,6.000
6,36.133,0.01,0.0000,0.00000,6.000
6,36.200,0.01,0.0000,0.00000,6.000
6,36.267,0.01,0.0000,0.00000,6.000
6,36.333,0.01,0.0000,0.00000,6.000
6,36.467,0.01,0.0000,0.00000,6.000
7,36.733,-0.01,0.0647,0.06467,7.000
7,36.800,-0.02,0.2406,0.24060,7.000
7,36.867,-0.01,0.5281,0.52807,7.000
7,36.933,-0.01,0.9265,0.92647,7.000
7,37.000,-0.01,1.3924,1.39240,7.000
7,37.067,-0.01,1.8591,1.85907,7.000
7,37.133,-0.01,2.3258,2.32583,7.000
7,37.200,-0.01,2.7926,2.79260,7.000
7,37.267,-0.02,3.2592,3.25920,7.000
7,37.333,-0.01,3.7260,3.72597,7.000
7,37.400,-0.01,4.1925,4.19250,7.000
7,37.467,0.09,4.6592,4.65917,7.000
7,37.533,1.05,5.1260,5.12597,7.000
7,37.600,3.59,5.5926,5.59260,7.000
7,37.667,8.08,6.0591,6.05913,7.000
7,37.733,15.18,6.5258,6.52583,7.000
7,37.867,40.63,7.3859,7.38593,7.000
7,37.933,54.52,7.6693,7.66927,7.000
7,38.000,64.81,7.8418,7.84180,7.000
7,38.067,67.98,7.9029,7.90287,7.000
7,38.133,61.53,7.8535,7.85353,7.000
7,38.200,46.63,7.6929,7.69290,7.000
7,38.267,30.31,7.4204,7.42037,7.000
7,38.333,16.95,7.0370,7.03703,7.000
7,38.400,8.13,6.5737,6.57370,7.000
7,38.467,3.98,6.1069,6.10690,7.000
7,38.533,1.82,5.6405,5.64047,7.000
7,38.600,0.53,5.1736,5.17360,7.000
7,38.667,-0.01,4.7069,4.70693,7.000
7,38.733,-0.02,4.2404,4.24037,7.000
7,38.800,-0.01,3.7736,3.77360,7.000
7,38.867,-0.01,3.3070,3.30700,7.000
7,38.933,-0.01,2.8403,2.84027,7.000
7,39.000,-0.01,2.3736,2.37360,7.000
7,39.067,-0.01,1.9069,1.90690,7.000
7,39.133,-0.01,1.4402,1.44017,7.000
7,39.200,-0.01,0.9736,0.97360,7.000
7,39.267,-0.01,0.5068,0.50680,7.000
7,39.333,-0.01,0.0401,0.04007,7.000
7,39.467,-0.01,-0.7510,-0.75103,7.000
7,39.533,-0.01,-0.9846,-0.98460,7.000
7,39.600,-0.02,-1.1072,-1.10720,7.000
7,39.667,-0.01,-1.1182,-1.11823,7.000
7,39.733,-0.01,-1.0187,-1.01873,7.000
7,39.800,-0.01,-0.8079,-0.80790,7.000
7,39.867,-0.01,-0.4903,-0.49027,7.000
7,39.933,-0.02,-0.2158,-0.21583,7.000
7,40.000,-0.01,-0.0523,-0.05230,7.000
7,40.067,-0.01,0.0001,0.00007,7.000
7,40.133,-0.01,-0.0001,-0.00010,7.000
7,40.200,-0.01,-0.0001,-0.00010,7.000
7,40.267,-0.01,-0.0001,-0.00010,7.000
7,40.333,-0.01,-0.0001,-0.00010,7.000
7,40.400,-0.02,-0.0001,-0.00010,7.000
7,40.467,-0.01,-0.0001,-0.00010,7.000
7,40.533,-0.01,-0.0001,-0.00010,7.000
7,40.600,-0.01,-0.0001,-0.00010,7.000
7,40.667,-0.01,-0.0001,-0.00010,7.000
7,40.733,-0.01,-0.0001,-0.00010,7.000
7,40.800,-0.01,-0.0001,-0.00010,7.000
7,40.867,-0.02,-0.0001,-0.00010,7.000
7,40.933,-0.01,-0.0001,-0.00010,7.000
7,41.000,-0.01,-0.0001,-0.00010,7.000
7,41.067,-0.02,-0.0001,-0.00010,7.000
7,41.133,-0.01,-0.0001,-0.00010,7.000
7,41.200,-0.02,-0.0001,-0.00010,7.000
7,41.267,-0.01,-0.0001,-0.00010,7.000
7,41.333,-0.01,-0.0001,-0.00010,7.000
7,41.400,-0.01,-0.0001,-0.00010,7.000
7,41.467,-0.01,-0.0001,-0.00010,7.000
7,41.533,-0.01,-0.0001,-0.00010,7.000
7,41.600,-0.01,-0.0001,-0.00010,7.000
7,41.667,-0.01,-0.0001,-0.00010,7.000
7,41.733,-0.01,-0.0001,-0.00010,7.000
7,41.800,-0.01,-0.0001,-0.00010,7.000
7,41.867,-0.01,-0.0001,-0.00010,7.000
7,41.933,-0.01,-0.0001,-0.00010,7.000
7,42.000,-0.01,-0.0001,-0.00010,7.000
7,42.067,-0.01,-0.0001,-0.00010,7.000
7,42.133,-0.01,-0.0001,-0.00010,7.000
7,42.200,-0.01,-0.0001,-0.00010,7.000
7,42.267,-0.01,-0.0001,-0.00010,7.000
7,42.333,-0.03,-0.0001,-0.00010,7.000
7,42.400,-0.02,-0.0001,-0.00010,7.000
8,42.800,0.00,0.1217,0.12170,8.000
8,42.867,0.01,0.3424,0.34243,8.000
8,42.933,0.01,0.6741,0.67410,8.000
8,43.000,0.00,1.1124,1.11240,8.000
8,43.067,0.00,1.5792,1.57923,8.000
8,43.133,0.01,2.0459,2.04593,8.000
8,43.200,0.00,2.5125,2.51250,8.000
8,43.267,0.01,2.9792,2.97923,8.000
8,43.333,0.00,3.4459,3.44590,8.000
8,43.400,0.01,3.9124,3.91240,8.000
8,43.467,0.02,4.3792,4.37920,8.000
8,43.533,0.32,4.8459,4.84587,8.000
8,43.600,1.87,5.3127,5.31270,8.000
8,43.667,5.12,5.7792,5.77917,8.000
8,43.733,10.54,6.2459,6.24590,8.000
8,43.800,18.97,6.7125,6.71250,8.000
8,43.933,46.51,7.5152,7.51523,8.000
8,44.000,59.53,7.7562,7.75620,8.000
8,44.067,67.51,7.8854,7.88543,8.000
8,44.133,67.21,7.9039,7.90393,8.000
8,44.200,56.89,7.8121,7.81210,8.000
8,44.267,40.40,7.6079,7.60787,8.000
8,44.333,24.89,7.2929,7.29293,8.000
8,44.400,12.98,6.8677,6.86770,8.000
8,44.467,6.17,6.4011,6.40107,8.000
8,44.533,3.07,5.9343,5.93433,8.000
8,44.600,1.31,5.4675,5.46750,8.000
8,44.667,0.27,5.0010,5.00103,8.000
8,44.733,0.00,4.5344,4.53437,8.000
8,44.800,0.00,4.0676,4.06760,8.000
8,44.867,0.00,3.6010,3.60103,8.000
8,44.933,0.00,3.1343,3.13433,8.000
8,45.000,0.00,2.6675,2.66750,8.000
8,45.067,0.01,2.2009,2.20087,8.000
8,45.133,0.00,1.7343,1.73430,8.000
8,45.200,0.00,1.2677,1.26770,8.000
8,45.267,0.00,0.8009,0.80090,8.000
8,45.333,0.01,0.3342,0.33420,8.000
8,45.533,0.01,-0.8758,-0.87583,8.000
8,45.600,0.01,-1.0819,-1.08190,8.000
8,45.667,0.00,-1.1759,-1.17590,8.000
8,45.733,0.00,-1.1597,-1.15973,8.000
8,45.800,0.00,-1.0325,-1.03250,8.000
8,45.867,0.00,-0.7934,-0.79340,8.000
8,45.933,0.00,-0.4593,-0.45930,8.000
8,46.000,0.00,-0.1932,-0.19320,8.000
8,46.067,-0.01,-0.0390,-0.03897,8.000
8,46.133,0.00,0.0044,0.00440,8.000
8,46.200,-0.01,0.0000,0.00000,8.000
8,46.267,0.01,0.0000,0.00000,8.000
8,46.333,0.01,0.0000,0.00000,8.000
8,46.400,0.00,0.0000,0.00000,8.000
8,46.467,0.00,0.0000,0.00000,8.000
8,46.533,0.01,0.0000,0.00000,8.000
8,46.600,0.01,0.0000,0.00000,8.000
8,46.667,0.00,0.0000,0.00000,8.000
8,46.733,0.00,0.0000,0.00000,8.000
8,46.800,0.01,0.0000,0.00000,8.000
8,46.867,0.00,0.0000,0.00000,8.000
8,46.933,0.00,0.0000,0.00000,8.000
8,47.000,0.01,0.0000,0.00000,8.000
8,47.067,0.00,0.0000,0.00000,8.000
8,47.133,0.00,0.0000,0.00000,8.000
8,47.200,0.01,0.0000,0.00000,8.000
8,47.267,0.00,0.0000,0.00000,8.000
8,47.333,0.00,0.0000,0.00000,8.000
8,47.400,0.01,0.0000,0.00000,8.000
8,47.467,0.01,0.0000,0.00000,8.000
8,47.533,0.01,0.0000,0.00000,8.000
8,47.600,0.00,0.0000,0.00000,8.000
8,47.667,0.01,0.0000,0.00000,8.000
8,47.733,0.00,0.0000,0.00000,8.000
8,47.800,0.00,0.0000,0.00000,8.000
8,47.867,0.00,0.0000,0.00000,8.000
8,47.933,0.00,0.0000,0.00000,8.000
8,48.000,0.01,0.0000,0.00000,8.000
8,48.067,0.00,0.0000,0.00000,8.000
8,48.133,0.00,0.0000,0.00000,8.000
8,48.200,0.01,0.0000,0.00000,8.000
8,48.267,0.00,0.0000,0.00000,8.000
8,48.333,0.01,0.0000,0.00000,8.000
8,48.400,0.01,0.0000,0.00000,8.000
8,48.467,0.00,0.0000,0.00000,8.000
9,48.867,0.00,0.2128,0.21280,9.000
9,48.933,0.00,0.4862,0.48617,9.000
9,49.000,0.00,0.8703,0.87030,9.000
9,49.067,0.00,1.3342,1.33423,9.000
9,49.133,0.00,1.8007,1.80073,9.000
9,49.200,0.00,2.2675,2.26750,9.000
9,49.267,0.00,2.7341,2.73410,9.000
9,49.333,0.00,3.2009,3.20093,9.000
9,49.400,0.00,3.6676,3.66760,9.000
9,49.467,0.01,4.1341,4.13407,9.000
9,49.533,0.07,4.6009,4.60093,9.000
9,49.600,0.86,5.0675,5.06750,9.000
9,49.667,3.17,5.5343,5.53427,9.000
9,49.733,7.37,6.0009,6.00087,9.000
9,49.800,14.07,6.4675,6.46750,9.000
9,50.000,54.07,7.6632,7.66320,9.000
9,50.067,66.13,7.8609,7.86087,9.000
9,50.133,71.65,7.9475,7.94753,9.000
9,50.200,67.39,7.9240,7.92400,9.000
9,50.267,52.90,7.7884,7.78840,9.000
9,50.333,35.37,7.5418,7.54183,9.000
9,50.400,20.50,7.1841,7.18410,9.000
9,50.467,10.06,6.7300,6.72997,9.000
9,50.533,4.88,6.2634,6.26337,9.000
9,50.600,2.38,5.7965,5.79650,9.000
9,50.667,0.91,5.3299,5.32993,9.000
9,50.733,0.11,4.8633,4.86327,9.000
9,50.800,0.00,4.3966,4.39660,9.000
9,50.867,0.00,3.9298,3.92983,9.000
9,50.933,0.00,3.4632,3.46320,9.000
9,51.000,0.01,2.9967,2.99670,9.000
9,51.067,0.00,2.5299,2.52987,9.000
9,51.133,0.00,2.0634,2.06340,9.000
9,51.200,0.01,1.5965,1.59650,9.000
9,51.267,0.00,1.1300,1.13000,9.000
9,51.333,0.00,0.6633,0.66327,9.000
9,51.400,-0.01,0.1965,0.19650,9.000
9,51.533,0.00,-0.6502,-0.65017,9.000
9,51.600,0.00,-0.9227,-0.92270,9.000
9,51.667,-0.01,-1.0836,-1.08363,9.000
9,51.733,0.00,-1.1337,-1.13367,9.000
9,51.800,-0.01,-1.0735,-1.07350,9.000
9,51.867,0.01,-0.9012,-0.90117,9.000
9,51.933,-0.01,-0.6178,-0.61777,9.000
9,52.000,0.01,-0.3043,-0.30430,9.000
9,52.067,0.00,-0.0997,-0.09973,9.000
9,52.133,-0.01,-0.0063,-0.00630,9.000
9,52.200,0.00,-0.0001,-0.00010,9.000
9,52.267,0.00,-0.0001,-0.00010,9.000
9,52.333,0.00,-0.0001,-0.00010,9.000
9,52.400,0.00,-0.0001,-0.00010,9.000
9,52.467,-0.01,-0.0001,-0.00010,9.000
9,52.533,0.00,-0.0001,-0.00010,9.000
9,52.600,-0.01,-0.0001,-0.00010,9.000
9,52.667,0.00,-0.0001,-0.00010,9.000
9,52.733,0.00,-0.0001,-0.00010,9.000
9,52.800,0.00,-0.0001,-0.00010,9.000
9,52.867,-0.01,-0.0001,-0.00010,9.000
9,52.933,-0.01,-0.0001,-0.00010,9.000
9,53.000,0.00,-0.0001,-0.00010,9.000
9,53.067,0.00,-0.0001,-0.00010,9.000
9,53.133,0.00,-0.0001,-0.00010,9.000
9,53.200,0.01,-0.0001,-0.00010,9.000
9,53.267,0.00,-0.0001,-0.00010,9.000
9,53.333,0.00,-0.0001,-0.00010,9.000
9,53.400,0.00,-0.0001,-0.00010,9.000
9,53.467,0.00,-0.0001,-0.00010,9.000
9,53.533,0.00,-0.0001,-0.00010,9.000
9,53.600,0.01,-0.0001,-0.00010,9.000
9,53.667,0.00,-0.0001,-0.00010,9.000
9,53.733,0.00,-0.0001,-0.00010,9.000
9,53.800,-0.01,-0.0001,-0.00010,9.000
9,53.867,0.00,-0.0001,-0.00010,9.000
9,53.933,0.00,-0.0001,-0.00010,9.000
9,54.000,0.00,-0.0001,-0.00010,9.000
9,54.067,0.01,-0.0001,-0.00010,9.000
9,54.133,0.00,-0.0001,-0.00010,9.000
9,54.200,0.00,-0.0001,-0.00010,9.000
9,54.267,0.00,-0.0001,-0.00010,9.000
9,54.333,-0.01,-0.0001,-0.00010,9.000
9,54.400,-0.01,-0.0001,-0.00010,9.000
9,54.467,0.00,-0.0001,-0.00010,9.000
9,54.600,0.00,-0.0001,-0.00010,9.000
10,54.867,0.00,0.1020,0.10203,10.000
10,54.933,0.00,0.3088,0.30883,10.000
10,55.000,-0.01,0.6264,0.62640,10.000
10,55.067,0.01,1.0542,1.05417,10.000
10,55.133,0.00,1.5208,1.52077,10.000
10,55.200,0.00,1.9875,1.98750,10.000
10,55.267,0.00,2.4542,2.45423,10.000
10,55.333,-0.01,2.9208,2.92083,10.000
10,55.400,0.01,3.3876,3.38760,10.000
10,55.467,0.00,3.8542,3.85417,10.000
10,55.533,0.00,4.3209,4.32087,10.000
10,55.600,0.21,4.7875,4.78750,10.000
10,55.667,1.59,5.2543,5.25430,10.000
10,55.733,4.60,5.7210,5.72103,10.000
10,55.800,9.69,6.1876,6.18760,10.000
10,55.867,17.72,6.6543,6.65427,10.000
10,56.000,45.28,7.4912,7.49120,10.000
10,56.067,59.43,7.7555,7.75553,10.000
10,56.133,69.29,7.9090,7.90900,10.000
10,56.200,71.22,7.9514,7.95140,10.000
10,56.267,62.47,7.8829,7.88293,10.000
10,56.333,45.76,7.7031,7.70310,10.000
10,56.400,28.96,7.4122,7.41220,10.000
10,56.467,15.70,7.0098,7.00980,10.000
10,56.533,7.48,6.5434,6.54343,10.000
10,56.600,3.71,6.0765,6.07650,10.000
10,56.667,1.67,5.6101,5.61010,10.000
10,56.733,0.49,5.1433,5.14330,10.000
10,56.800,0.00,4.6766,4.67660,10.000
10,56.867,-0.01,4.2100,4.21003,10.000
10,56.933,0.00,3.7433,3.74333,10.000
10,57.000,0.01,3.2768,3.27680,10.000
10,57.067,0.00,2.8100,2.81000,10.000
10,57.133,0.00,2.3433,2.34327,10.000
10,57.200,-0.02,1.8765,1.87650,10.000
10,57.267,0.00,1.4098,1.40983,10.000
10,57.333,-0.01,0.9433,0.94327,10.000
10,57.400,-0.01,0.4765,0.47650,10.000
10,57.467,-0.01,0.0098,0.00983,10.000
10,57.600,-0.01,-0.7727,-0.77270,10.000
10,57.667,0.00,-1.0003,-1.00030,10.000
10,57.733,0.00,-1.1170,-1.11700,10.000
10,57.800,0.00,-1.1231,-1.12310,10.000
10,57.867,0.01,-1.0178,-1.01783,10.000
10,57.933,-0.02,-0.8011,-0.80107,10.000
10,58.000,-0.01,-0.4800,-0.48000,10.000
10,58.067,-0.01,-0.2092,-0.20917,10.000
10,58.133,0.00,-0.0491,-0.04907,10.000
10,58.200,-0.02,0.0004,0.00040,10.000
10,58.267,-0.01,-0.0001,-0.00010,10.000
10,58.333,-0.01,-0.0001,-0.00010,10.000
10,58.400,0.01,-0.0001,-0.00010,10.000
10,58.467,0.00,-0.0001,-0.00010,10.000
10,58.533,0.00,-0.0001,-0.00010,10.000
10,58.600,-0.01,-0.0001,-0.00010,10.000
10,58.667,-0.01,-0.0001,-0.00010,10.000
10,58.733,-0.01,-0.0001,-0.00010,10.000
10,58.800,0.01,-0.0001,-0.00010,10.000
10,58.867,-0.01,-0.0001,-0.00010,10.000
10,58.933,-0.01,-0.0001,-0.00010,10.000
10,59.000,-0.01,-0.0001,-0.00010,10.000
10,59.067,0.01,-0.0001,-0.00010,10.000
10,59.133,0.00,-0.0001,-0.00010,10.000
10,59.200,0.00,-0.0001,-0.00010,10.000
10,59.267,-0.01,-0.0001,-0.00010,10.000
10,59.333,0.00,-0.0001,-0.00010,10.000
10,59.400,-0.01,-0.0001,-0.00010,10.000
10,59.467,0.00,-0.0001,-0.00010,10.000
10,59.533,0.00,-0.0001,-0.00010,10.000
10,59.600,0.00,-0.0001,-0.00010,10.000
10,59.667,0.00,-0.0001,-0.00010,10.000
10,59.733,0.00,-0.0001,-0.00010,10.000
10,59.800,-0.01,-0.0001,-0.00010,10.000
10,59.867,0.00,-0.0001,-0.00010,10.000
10,59.933,0.00,-0.0001,-0.00010,10.000
10,60.000,0.00,-0.0001,-0.00010,10.000
10,60.067,0.00,-0.0001,-0.00010,10.000
10,60.133,-0.01,-0.0001,-0.00010,10.000
10,60.200,0.00,-0.0001,-0.00010,10.000
10,60.267,0.00,-0.0001,-0.00010,10.000
10,60.333,0.00,-0.0001,-0.00010,10.000
10,60.400,0.00,-0.0001,-0.00010,10.000
10,60.467,-0.01,-0.0001,-0.00010,10.000
10,60.533,0.00,-0.0001,-0.00010,10.000