File: AIME_journal_files/AIME_data/calibDATA_loadcell/date_02:15:2018/Instron_02.15.2018/2_20N_0__6mm.s_0_0.txt
""
"Test Method","Radhen_Load_Cntrl_Cmprsn_250N_12-7.msm"
"Sample I. D.","Sample1.mss"
"Specimen Number","25"

"TheCycle_Output ()","_Time (s)","_Load (N)","_Extension (mm)","RealTimeDepth (mm)","CycleNumber ()"

1,0.267,-0.01,0.0827,0.08267,1.000
1,0.333,0.00,0.2745,0.27450,1.000
1,0.400,0.00,0.5770,0.57700,1.000
1,0.467,0.00,0.9696,0.96957,1.000
1,0.533,0.00,1.3696,1.36963,1.000
1,0.600,-0.01,1.7696,1.76960,1.000
1,0.667,0.00,2.1696,2.16960,1.000
1,0.733,0.00,2.5696,2.56957,1.000
1,0.800,-0.01,2.9696,2.96960,1.000
1,0.867,0.00,3.3696,3.36963,1.000
1,0.933,0.00,3.7697,3.76973,1.000
1,1.000,0.00,4.1696,4.16960,1.000
1,1.067,0.05,4.5697,4.56967,1.000
1,1.133,0.67,4.9698,4.96980,1.000
1,1.200,2.36,5.3696,5.36960,1.000
1,1.267,5.30,5.7696,5.76957,1.000
1,1.333,9.77,6.1697,6.16970,1.000
1,1.400,16.29,6.5696,6.56960,1.000
1,1.533,37.45,7.3027,7.30267,1.000
1,1.600,47.26,7.5252,7.52520,1.000
1,1.667,52.46,7.6361,7.63613,1.000
1,1.733,51.00,7.6365,7.63653,1.000
1,1.800,42.32,7.5260,7.52600,1.000
1,1.867,29.83,7.3036,7.30363,1.000
1,1.933,17.98,6.9704,6.97037,1.000
1,2.000,9.45,6.5710,6.57100,1.000
1,2.067,4.99,6.1707,6.17070,1.000
1,2.133,2.60,5.7706,5.77060,1.000
1,2.200,1.10,5.3705,5.37050,1.000
1,2.267,0.24,4.9708,4.97080,1.000
1,2.333,-0.02,4.5708,4.57080,1.000
1,2.400,-0.01,4.1705,4.17050,1.000
1,2.467,0.00,3.7707,3.77067,1.000
1,2.533,-0.01,3.3707,3.37073,1.000
1,2.600,-0.01,2.9706,2.97060,1.000
1,2.667,0.00,2.5705,2.57053,1.000
1,2.733,-0.01,2.1706,2.17063,1.000
1,2.800,0.00,1.7707,1.77070,1.000
1,2.867,-0.01,1.3706,1.37057,1.000
1,2.933,-0.01,0.9706,0.97063,1.000
1,3.000,-0.01,0.5707,0.57070,1.000
1,3.067,-0.01,0.1705,0.17053,1.000
1,3.200,-0.01,-0.5498,-0.54980,1.000
1,3.267,-0.01,-0.7607,-0.76070,1.000
1,3.333,0.00,-0.8608,-0.86080,1.000
1,3.400,0.00,-0.8505,-0.85050,1.000
1,3.467,0.00,-0.7282,-0.72823,1.000
1,3.533,-0.01,-0.4950,-0.49500,1.000
1,3.600,0.00,-0.2203,-0.22030,1.000
1,3.667,0.00,-0.0525,-0.05247,1.000
1,3.733,0.00,0.0042,0.00423,1.000
1,3.800,0.00,-0.0001,-0.00010,1.000
1,3.867,0.00,-0.0001,-0.00010,1.000
1,3.933,-0.01,-0.0001,-0.00010,1.000
1,4.000,0.00,-0.0001,-0.00010,1.000
1,4.067,-0.01,-0.0001,-0.00010,1.000
1,4.133,0.00,-0.0001,-0.00010,1.000
1,4.200,0.00,-0.0001,-0.00010,1.000
1,4.267,0.00,-0.0001,-0.00010,1.000
1,4.333,0.00,-0.0001,-0.00010,1.000
1,4.400,-0.01,-0.0001,-0.00010,1.000
1,4.467,0.00,-0.0001,-0.00010,1.000
1,4.533,-0.01,-0.0001,-0.00010,1.000
1,4.600,-0.01,-0.0001,-0.00010,1.000
1,4.667,0.00,-0.0001,-0.00010,1.000
1,4.733,-0.01,-0.0001,-0.00010,1.000
1,4.800,0.00,-0.0001,-0.00010,1.000
1,4.867,0.00,-0.0001,-0.00010,1.000
1,4.933,0.00,-0.0001,-0.00010,1.000
1,5.000,0.00,-0.0001,-0.00010,1.000
1,5.067,0.00,-0.0001,-0.00010,1.000
1,5.133,0.00,-0.0001,-0.00010,1.000
1,5.200,-0.01,-0.0001,-0.00010,1.000
1,5.267,0.00,-0.0001,-0.00010,1.000
1,5.333,0.00,-0.0001,-0.00010,1.000
1,5.400,0.00,-0.0001,-0.00010,1.000
1,5.467,0.00,-0.0001,-0.00010,1.000
1,5.533,0.00,-0.0001,-0.00010,1.000
1,5.600,0.00,-0.0001,-0.00010,1.000
1,5.667,0.00,-0.0001,-0.00010,1.000
1,5.733,0.00,-0.0001,-0.00010,1.000
1,5.800,-0.01,-0.0001,-0.00010,1.000
1,5.867,0.00,-0.0001,-0.00010,1.000
1,5.933,-0.01,-0.0001,-0.00010,1.000
1,6.000,-0.01,-0.0001,-0.00010,1.000
1,6.067,0.00,-0.0001,-0.00010,1.000
1,6.133,-0.01,-0.0001,-0.00010,1.000
1,6.267,0.00,-0.0001,-0.00010,1.000
2,6.400,-0.01,0.0001,0.00010,2.000
2,6.467,0.00,0.0637,0.06367,2.000
2,6.533,-0.01,0.2386,0.23863,2.000
2,6.600,-0.01,0.5246,0.52460,2.000
2,6.667,-0.01,0.9097,0.90967,2.000
2,6.733,-0.01,1.3097,1.30967,2.000
2,6.800,0.00,1.7097,1.70970,2.000
2,6.867,-0.01,2.1097,2.10970,2.000
2,6.933,-0.01,2.5096,2.50957,2.000
2,7.000,-0.01,2.9097,2.90970,2.000
2,7.067,-0.01,3.3096,3.30963,2.000
2,7.133,-0.01,3.7098,3.70977,2.000
2,7.200,0.00,4.1096,4.10960,2.000
2,7.267,0.02,4.5097,4.50973,2.000
2,7.333,0.48,4.9096,4.90963,2.000
2,7.400,1.95,5.3097,5.30970,2.000
2,7.467,4.64,5.7099,5.70987,2.000
2,7.533,8.84,6.1096,6.10963,2.000
2,7.600,15.00,6.5096,6.50960,2.000
2,7.800,45.88,7.4989,7.49890,2.000
2,7.867,51.96,7.6264,7.62643,2.000
2,7.933,51.63,7.6435,7.64350,2.000
2,8.000,43.96,7.5499,7.54990,2.000
2,8.067,31.70,7.3440,7.34403,2.000
2,8.133,19.62,7.0274,7.02737,2.000
2,8.200,10.42,6.6307,6.63070,2.000
2,8.267,5.48,6.2307,6.23070,2.000
2,8.333,2.88,5.8305,5.83053,2.000
2,8.400,1.26,5.4306,5.43060,2.000
2,8.467,0.34,5.0307,5.03073,2.000
2,8.533,-0.02,4.6307,4.63070,2.000
2,8.600,-0.01,4.2308,4.23080,2.000
2,8.667,-0.01,3.8306,3.83057,2.000
2,8.733,-0.01,3.4306,3.43063,2.000
2,8.800,-0.01,3.0307,3.03070,2.000
2,8.867,0.00,2.6306,2.63057,2.000
2,8.933,-0.01,2.2306,2.23060,2.000
2,9.000,-0.01,1.8305,1.83050,2.000
2,9.067,-0.01,1.4305,1.43050,2.000
2,9.133,-0.01,1.0305,1.03053,2.000
2,9.200,-0.01,0.6306,0.63060,2.000
2,9.267,-0.01,0.2305,0.23053,2.000
2,9.400,0.00,-0.5086,-0.50860,2.000
2,9.467,-0.01,-0.7362,-0.73620,2.000
2,9.533,0.00,-0.8530,-0.85297,2.000
2,9.600,-0.01,-0.8591,-0.85910,2.000
2,9.667,0.00,-0.7537,-0.75367,2.000
2,9.733,-0.01,-0.5370,-0.53703,2.000
2,9.800,0.00,-0.2551,-0.25510,2.000
2,9.867,-0.01,-0.0706,-0.07060,2.000
2,9.933,-0.01,0.0027,0.00270,2.000
2,10.000,-0.01,-0.0001,-0.00010,2.000
2,10.067,-0.01,-0.0001,-0.00010,2.000
2,10.133,0.00,-0.0001,-0.00010,2.000
2,10.200,-0.01,-0.0001,-0.00010,2.000
2,10.267,-0.01,-0.0001,-0.00010,2.000
2,10.333,0.00,-0.0001,-0.00010,2.000
2,10.400,-0.01,-0.0001,-0.00010,2.000
2,10.467,-0.01,-0.0001,-0.00010,2.000
2,10.533,-0.01,-0.0001,-0.00010,2.000
2,10.600,0.00,-0.0001,-0.00010,2.000
2,10.667,-0.01,-0.0001,-0.00010,2.000
2,10.733,-0.01,-0.0001,-0.00010,2.000
2,10.800,-0.01,-0.0001,-0.00010,2.000
2,10.867,-0.01,-0.0001,-0.00010,2.000
2,10.933,-0.01,-0.0001,-0.00010,2.000
2,11.000,0.00,-0.0001,-0.00010,2.000
2,11.067,-0.01,-0.0001,-0.00010,2.000
2,11.133,-0.01,-0.0001,-0.00010,2.000
2,11.200,-0.01,-0.0001,-0.00010,2.000
2,11.267,-0.01,-0.0001,-0.00010,2.000
2,11.333,-0.01,-0.0001,-0.00010,2.000
2,11.400,-0.01,-0.0001,-0.00010,2.000
2,11.467,-0.01,-0.0001,-0.00010,2.000
2,11.533,0.00,-0.0001,-0.00010,2.000
2,11.600,-0.01,-0.0001,-0.00010,2.000
2,11.667,0.00,-0.0001,-0.00010,2.000
2,11.733,-0.01,-0.0001,-0.00010,2.000
2,11.800,-0.01,-0.0001,-0.00010,2.000
2,11.867,0.00,-0.0001,-0.00010,2.000
2,11.933,0.00,-0.0001,-0.00010,2.000
2,12.000,0.00,-0.0001,-0.00010,2.000
2,12.067,-0.01,-0.0001,-0.00010,2.000
2,12.133,0.00,-0.0001,-0.00010,2.000
2,12.200,-0.02,-0.0001,-0.00010,2.000
2,12.267,-0.01,-0.0001,-0.00010,2.000
2,12.333,0.00,-0.0001,-0.00010,2.000
2,12.400,0.00,-0.0001,-0.00010,2.000
3,12.600,-0.01,0.0000,0.00000,3.000
3,12.733,-0.02,0.1834,0.18340,3.000
3,12.800,-0.01,0.4410,0.44100,3.000
3,12.867,-0.01,0.8076,0.80757,3.000
3,12.933,-0.01,1.2077,1.20773,3.000
3,13.000,-0.03,1.6075,1.60750,3.000
3,13.067,-0.01,2.0076,2.00763,3.000
3,13.133,-0.01,2.4076,2.40763,3.000
3,13.200,-0.02,2.8077,2.80770,3.000
3,13.267,-0.01,3.2077,3.20767,3.000
3,13.333,-0.02,3.6076,3.60763,3.000
3,13.400,-0.02,4.0076,4.00760,3.000
3,13.467,0.00,4.4076,4.40760,3.000
3,13.533,0.25,4.8077,4.80767,3.000
3,13.600,1.44,5.2078,5.20780,3.000
3,13.667,3.79,5.6078,5.60777,3.000
3,13.733,7.55,6.0077,6.00767,3.000
3,13.800,13.18,6.4077,6.40770,3.000
3,13.867,21.30,6.8076,6.80760,3.000
3,14.000,42.72,7.4311,7.43110,3.000
3,14.067,49.43,7.5770,7.57697,3.000
3,14.133,50.25,7.6120,7.61203,3.000
3,14.200,44.03,7.5369,7.53690,3.000
3,14.267,32.67,7.3496,7.34957,3.000
3,14.333,20.76,7.0512,7.05120,3.000
3,14.400,11.21,6.6608,6.66080,3.000
3,14.467,5.87,6.2606,6.26063,3.000
3,14.533,3.06,5.8605,5.86053,3.000
3,14.600,1.36,5.4604,5.46040,3.000
3,14.667,0.37,5.0607,5.06070,3.000
3,14.733,-0.02,4.6607,4.66067,3.000
3,14.800,-0.03,4.2607,4.26070,3.000
3,14.867,-0.02,3.8605,3.86050,3.000
3,14.933,-0.02,3.4607,3.46067,3.000
3,15.000,-0.03,3.0607,3.06070,3.000
3,15.067,-0.01,2.6606,2.66057,3.000
3,15.133,-0.02,2.2606,2.26060,3.000
3,15.200,-0.01,1.8605,1.86050,3.000
3,15.267,-0.02,1.4605,1.46050,3.000
3,15.333,-0.02,1.0606,1.06057,3.000
3,15.400,-0.01,0.6606,0.66060,3.000
3,15.467,-0.01,0.2605,0.26050,3.000
3,15.667,-0.02,-0.7422,-0.74217,3.000
3,15.733,-0.01,-0.8773,-0.87730,3.000
3,15.800,-0.02,-0.9017,-0.90170,3.000
3,15.867,-0.01,-0.8146,-0.81463,3.000
3,15.933,-0.01,-0.6165,-0.61647,3.000
3,16.000,-0.01,-0.3267,-0.32670,3.000
3,16.067,-0.02,-0.1131,-0.11310,3.000
3,16.133,-0.01,-0.0102,-0.01017,3.000
3,16.200,-0.01,-0.0002,-0.00020,3.000
3,16.267,-0.01,-0.0002,-0.00020,3.000
3,16.333,-0.02,-0.0002,-0.00020,3.000
3,16.400,-0.01,-0.0002,-0.00020,3.000
3,16.467,-0.01,-0.0002,-0.00020,3.000
3,16.533,-0.02,-0.0002,-0.00020,3.000
3,16.600,-0.02,-0.0002,-0.00020,3.000
3,16.667,-0.03,-0.0002,-0.00020,3.000
3,16.733,-0.01,-0.0002,-0.00020,3.000
3,16.800,-0.02,-0.0002,-0.00020,3.000
3,16.867,-0.01,-0.0002,-0.00020,3.000
3,16.933,-0.01,-0.0002,-0.00020,3.000
3,17.000,-0.02,-0.0002,-0.00020,3.000
3,17.067,-0.01,-0.0002,-0.00020,3.000
3,17.133,0.00,-0.0002,-0.00020,3.000
3,17.200,-0.01,-0.0002,-0.00020,3.000
3,17.267,-0.01,-0.0002,-0.00020,3.000
3,17.333,-0.02,-0.0002,-0.00020,3.000
3,17.400,-0.01,-0.0002,-0.00020,3.000
3,17.467,-0.01,-0.0002,-0.00020,3.000
3,17.533,-0.01,-0.0002,-0.00020,3.000
3,17.600,-0.02,-0.0002,-0.00020,3.000
3,17.667,-0.01,-0.0002,-0.00020,3.000
3,17.733,-0.02,-0.0002,-0.00020,3.000
3,17.800,-0.02,-0.0002,-0.00020,3.000
3,17.867,-0.01,-0.0002,-0.00020,3.000
3,17.933,-0.01,-0.0002,-0.00020,3.000
3,18.000,-0.01,-0.0002,-0.00020,3.000
3,18.067,-0.01,-0.0002,-0.00020,3.000
3,18.133,-0.01,-0.0002,-0.00020,3.000
3,18.200,-0.02,-0.0002,-0.00020,3.000
3,18.267,-0.02,-0.0001,-0.00010,3.000
3,18.333,-0.02,-0.0001,-0.00010,3.000
3,18.400,-0.01,-0.0001,-0.00010,3.000
3,18.467,-0.01,-0.0001,-0.00010,3.000
3,18.533,-0.02,-0.0001,-0.00010,3.000
3,18.600,-0.02,-0.0001,-0.00010,3.000
4,18.933,-0.01,0.0841,0.08417,4.000
4,19.000,0.00,0.2767,0.27680,4.000
4,19.067,-0.01,0.5809,0.58100,4.000
4,19.133,-0.01,0.9736,0.97367,4.000
4,19.200,-0.01,1.3736,1.37370,4.000
4,19.267,-0.01,1.7735,1.77363,4.000
4,19.333,0.00,2.1736,2.17370,4.000
4,19.400,-0.01,2.5735,2.57360,4.000
4,19.467,-0.01,2.9736,2.97370,4.000
4,19.533,-0.01,3.3737,3.37377,4.000
4,19.600,-0.01,3.7737,3.77380,4.000
4,19.667,0.00,4.1736,4.17367,4.000
4,19.733,0.03,4.5738,4.57393,4.000
4,19.800,0.61,4.9737,4.97380,4.000
4,19.867,2.26,5.3736,5.37373,4.000
4,19.933,5.14,5.7737,5.77383,4.000
4,20.000,9.60,6.1737,6.17380,4.000
4,20.067,16.18,6.5736,6.57373,4.000
4,20.200,37.67,7.3129,7.31300,4.000
4,20.267,47.87,7.5404,7.54047,4.000
4,20.333,53.53,7.6571,7.65717,4.000
4,20.400,52.47,7.6633,7.66340,4.000
4,20.467,43.90,7.5580,7.55807,4.000
4,20.533,31.13,7.3413,7.34140,4.000
4,20.600,18.93,7.0139,7.01400,4.000
4,20.667,10.01,6.6148,6.61487,4.000
4,20.733,5.27,6.2147,6.21480,4.000
4,20.800,2.76,5.8145,5.81460,4.000
4,20.867,1.19,5.4145,5.41460,4.000
4,20.933,0.30,5.0148,5.01487,4.000
4,21.000,-0.02,4.6147,4.61480,4.000
4,21.067,-0.01,4.2147,4.21480,4.000
4,21.133,-0.01,3.8146,3.81473,4.000
4,21.200,-0.01,3.4147,3.41480,4.000
4,21.267,0.00,3.0147,3.01477,4.000
4,21.333,-0.01,2.6146,2.61470,4.000
4,21.400,0.00,2.2146,2.21470,4.000
4,21.467,-0.01,1.8146,1.81467,4.000
4,21.533,-0.01,1.4145,1.41457,4.000
4,21.600,0.00,1.0146,1.01470,4.000
4,21.667,-0.02,0.6145,0.61463,4.000
4,21.733,-0.01,0.2145,0.21460,4.000
4,21.800,-0.01,-0.1854,-0.18530,4.000
4,21.867,-0.01,-0.5301,-0.52997,4.000
4,21.933,-0.01,-0.7634,-0.76330,4.000
4,22.000,-0.01,-0.8862,-0.88610,4.000
4,22.067,-0.01,-0.8971,-0.89703,4.000
4,22.133,-0.01,-0.7976,-0.79747,4.000
4,22.200,0.00,-0.5868,-0.58670,4.000
4,22.267,-0.01,-0.2970,-0.29693,4.000
4,22.333,-0.02,-0.0956,-0.09553,4.000
4,22.400,-0.01,-0.0052,-0.00510,4.000
4,22.467,-0.01,-0.0002,-0.00010,4.000
4,22.533,-0.01,-0.0002,-0.00010,4.000
4,22.600,-0.02,-0.0002,-0.00010,4.000
4,22.667,-0.02,-0.0002,-0.00010,4.000
4,22.733,-0.01,-0.0002,-0.00010,4.000
4,22.800,-0.01,-0.0002,-0.00010,4.000
4,22.867,-0.01,-0.0002,-0.00010,4.000
4,22.933,-0.01,-0.0002,-0.00010,4.000
4,23.000,-0.01,-0.0002,-0.00010,4.000
4,23.067,-0.01,-0.0002,-0.00010,4.000
4,23.133,-0.01,-0.0002,-0.00010,4.000
4,23.200,-0.01,-0.0002,-0.00010,4.000
4,23.267,-0.01,-0.0002,-0.00010,4.000
4,23.333,-0.01,-0.0002,-0.00010,4.000
4,23.400,-0.01,-0.0002,-0.00010,4.000
4,23.467,-0.01,-0.0002,-0.00010,4.000
4,23.533,-0.01,-0.0002,-0.00010,4.000
4,23.600,0.00,-0.0002,-0.00010,4.000
4,23.667,-0.01,-0.0002,-0.00010,4.000
4,23.733,-0.01,-0.0002,-0.00010,4.000
4,23.800,-0.01,-0.0002,-0.00010,4.000
4,23.867,-0.01,-0.0002,-0.00010,4.000
4,23.933,-0.01,-0.0002,-0.00010,4.000
4,24.000,-0.01,-0.0002,-0.00010,4.000
4,24.067,-0.01,-0.0002,-0.00010,4.000
4,24.133,-0.01,-0.0002,-0.00010,4.000
4,24.200,-0.01,-0.0002,-0.00010,4.000
4,24.267,-0.01,-0.0001,0.00000,4.000
4,24.333,-0.02,-0.0001,0.00000,4.000
4,24.400,-0.02,-0.0001,0.00000,4.000
4,24.467,-0.01,-0.0001,0.00000,4.000
4,24.533,-0.01,-0.0001,0.00000,4.000
4,24.600,-0.01,-0.0001,0.00000,4.000
4,24.667,0.00,-0.0001,0.00000,4.000
4,24.733,-0.02,-0.0001,0.00000,4.000
4,24.800,0.00,-0.0001,0.00000,4.000
4,24.867,-0.01,-0.0001,0.00000,4.000
5,25.200,0.00,0.1120,0.11210,5.000
5,25.267,0.00,0.3262,0.32627,5.000
5,25.333,0.00,0.6511,0.65123,5.000
5,25.400,0.00,1.0496,1.04970,5.000
5,25.467,0.00,1.4496,1.44970,5.000
5,25.533,0.00,1.8495,1.84963,5.000
5,25.600,0.00,2.2495,2.24960,5.000
5,25.667,0.00,2.6496,2.64967,5.000
5,25.733,0.00,3.0496,3.04970,5.000
5,25.800,-0.01,3.4497,3.44980,5.000
5,25.867,0.00,3.8496,3.84970,5.000
5,25.933,0.01,4.2497,4.24980,5.000
5,26.000,0.08,4.6497,4.64980,5.000
5,26.067,0.85,5.0497,5.04983,5.000
5,26.133,2.70,5.4497,5.44977,5.000
5,26.200,5.85,5.8496,5.84970,5.000
5,26.267,10.69,6.2497,6.24980,5.000
5,26.333,17.72,6.6497,6.64983,5.000
5,26.467,40.25,7.3764,7.37647,5.000
5,26.533,50.46,7.5931,7.59317,5.000
5,26.600,55.76,7.6991,7.69920,5.000
5,26.667,53.86,7.6935,7.69363,5.000
5,26.733,44.22,7.5774,7.57750,5.000
5,26.800,30.80,7.3498,7.34990,5.000
5,26.867,18.44,7.0107,7.01080,5.000
5,26.933,9.71,6.6108,6.61090,5.000
5,27.000,5.14,6.2107,6.21080,5.000
5,27.067,2.71,5.8106,5.81067,5.000
5,27.133,1.17,5.4106,5.41067,5.000
5,27.200,0.28,5.0108,5.01090,5.000
5,27.267,-0.01,4.6107,4.61077,5.000
5,27.333,0.00,4.2106,4.21073,5.000
5,27.400,0.01,3.8106,3.81070,5.000
5,27.467,-0.01,3.4107,3.41083,5.000
5,27.533,-0.01,3.0107,3.01080,5.000
5,27.600,0.01,2.6106,2.61070,5.000
5,27.667,0.00,2.2106,2.21070,5.000
5,27.733,0.00,1.8106,1.81073,5.000
5,27.800,0.00,1.4104,1.41050,5.000
5,27.867,0.00,1.0105,1.01060,5.000
5,27.933,0.00,0.6106,0.61070,5.000
5,28.000,0.00,0.2105,0.21060,5.000
5,28.200,0.00,-0.7786,-0.77850,5.000
5,28.267,0.00,-0.9062,-0.90613,5.000
5,28.333,0.00,-0.9233,-0.92323,5.000
5,28.400,0.00,-0.8295,-0.82940,5.000
5,28.467,0.00,-0.6237,-0.62360,5.000
5,28.533,0.00,-0.3299,-0.32977,5.000
5,28.600,0.00,-0.1138,-0.11370,5.000
5,28.667,-0.01,-0.0096,-0.00953,5.000
5,28.733,0.00,-0.0003,-0.00020,5.000
5,28.800,0.00,-0.0001,0.00000,5.000
5,28.867,0.00,-0.0001,0.00000,5.000
5,28.933,-0.01,-0.0001,0.00000,5.000
5,29.000,0.00,-0.0001,0.00000,5.000
5,29.067,0.00,-0.0001,0.00000,5.000
5,29.133,-0.02,-0.0001,0.00000,5.000
5,29.200,-0.01,-0.0001,0.00000,5.000
5,29.267,0.00,-0.0001,0.00000,5.000
5,29.333,-0.01,-0.0001,0.00000,5.000
5,29.400,-0.01,-0.0001,0.00000,5.000
5,29.467,0.00,-0.0001,0.00000,5.000
5,29.533,-0.01,-0.0001,0.00000,5.000
5,29.600,-0.01,-0.0001,0.00000,5.000
5,29.667,0.00,-0.0001,0.00000,5.000
5,29.733,-0.01,-0.0001,0.00000,5.000
5,29.800,0.00,-0.0001,0.00000,5.000
5,29.867,0.00,-0.0001,0.00000,5.000
5,29.933,-0.01,-0.0001,0.00000,5.000
5,30.000,0.00,-0.0001,0.00000,5.000
5,30.067,0.00,-0.0001,0.00000,5.000
5,30.133,-0.01,-0.0001,0.00000,5.000
5,30.200,-0.01,-0.0001,0.00000,5.000
5,30.267,0.00,-0.0001,0.00000,5.000
5,30.333,0.01,-0.0001,0.00000,5.000
5,30.400,0.00,-0.0001,0.00000,5.000
5,30.467,0.00,-0.0001,0.00000,5.000
5,30.533,-0.01,-0.0001,0.00000,5.000
5,30.600,0.00,-0.0001,0.00000,5.000
5,30.667,0.00,-0.0001,0.00000,5.000
5,30.733,0.00,-0.0001,0.00000,5.000
5,30.800,0.01,-0.0001,0.00000,5.000
5,30.867,0.00,-0.0001,0.00000,5.000
5,30.933,0.00,-0.0001,0.00000,5.000
5,31.000,-0.01,-0.0001,0.00000,5.000
5,31.067,0.00,-0.0001,0.00000,5.000
5,31.133,0.00,-0.0001,0.00000,5.000
6,31.467,0.01,0.1021,0.10213,6.000
6,31.533,-0.01,0.3088,0.30883,6.000
6,31.600,0.01,0.6264,0.62640,6.000
6,31.667,0.01,1.0235,1.02353,6.000
6,31.733,0.00,1.4235,1.42350,6.000
6,31.800,0.00,1.8235,1.82350,6.000
6,31.867,0.00,2.2235,2.22353,6.000
6,31.933,0.01,2.6236,2.62360,6.000
6,32.000,0.01,3.0236,3.02360,6.000
6,32.067,0.00,3.4236,3.42357,6.000
6,32.133,0.01,3.8237,3.82367,6.000
6,32.200,0.01,4.2236,4.22360,6.000
6,32.267,0.07,4.6236,4.62357,6.000
6,32.333,0.78,5.0238,5.02377,6.000
6,32.400,2.55,5.4237,5.42370,6.000
6,32.467,5.62,5.8236,5.82360,6.000
6,32.533,10.29,6.2236,6.22360,6.000
6,32.600,17.18,6.6237,6.62370,6.000
6,32.733,38.98,7.3451,7.34513,6.000
6,32.800,48.63,7.5576,7.55760,6.000
6,32.867,53.44,7.6586,7.65860,6.000
6,32.933,51.30,7.6491,7.64907,6.000
6,33.000,41.89,7.5285,7.52850,6.000
6,33.067,29.08,7.2962,7.29617,6.000
6,33.133,17.29,6.9529,6.95293,6.000
6,33.200,9.07,6.5527,6.55270,6.000
6,33.267,4.79,6.1526,6.15260,6.000
6,33.333,2.48,5.7526,5.75260,6.000
6,33.400,1.02,5.3526,5.35260,6.000
6,33.467,0.21,4.9528,4.95277,6.000
6,33.533,0.01,4.5527,4.55270,6.000
6,33.600,0.00,4.1526,4.15260,6.000
6,33.667,0.00,3.7527,3.75273,6.000
6,33.733,0.01,3.3526,3.35263,6.000
6,33.800,0.01,2.9526,2.95260,6.000
6,33.867,0.01,2.5525,2.55253,6.000
6,33.933,0.00,2.1526,2.15263,6.000
6,34.000,0.01,1.7526,1.75260,6.000
6,34.067,0.00,1.3526,1.35257,6.000
6,34.133,0.00,0.9525,0.95253,6.000
6,34.200,0.01,0.5526,0.55260,6.000
6,34.267,0.01,0.1525,0.15250,6.000
6,34.400,0.00,-0.5679,-0.56790,6.000
6,34.467,0.01,-0.7787,-0.77873,6.000
6,34.533,0.01,-0.8790,-0.87897,6.000
6,34.600,0.01,-0.8685,-0.86850,6.000
6,34.667,0.01,-0.7463,-0.74630,6.000
6,34.733,0.01,-0.5129,-0.51293,6.000
6,34.800,0.01,-0.2343,-0.23430,6.000
6,34.867,0.01,-0.0617,-0.06173,6.000
6,34.933,0.00,-0.0003,-0.00030,6.000
6,35.000,0.01,-0.0002,-0.00020,6.000
6,35.067,0.00,-0.0002,-0.00020,6.000
6,35.133,0.01,-0.0002,-0.00020,6.000
6,35.200,0.00,-0.0002,-0.00020,6.000
6,35.267,0.00,-0.0002,-0.00020,6.000
6,35.333,0.00,-0.0002,-0.00020,6.000
6,35.400,0.00,-0.0002,-0.00020,6.000
6,35.467,0.00,-0.0002,-0.00020,6.000
6,35.533,0.01,-0.0002,-0.00020,6.000
6,35.600,0.00,-0.0002,-0.00020,6.000
6,35.667,0.01,-0.0002,-0.00020,6.000
6,35.733,0.01,-0.0002,-0.00020,6.000
6,35.800,0.01,-0.0002,-0.00020,6.000
6,35.867,0.01,-0.0002,-0.00020,6.000
6,35.933,0.01,-0.0002,-0.00020,6.000
6,36.000,0.01,-0.0002,-0.00020,6.000
6,36.067,0.00,-0.0002,-0.00020,6.000
6,36.133,0.01,-0.0002,-0.00020,6.000
6,36.200,0.01,-0.0002,-0.00020,6.000
6,36.267,0.00,-0.0002,-0.00020,6.000
6,36.333,0.01,-0.0002,-0.00020,6.000
6,36.400,0.01,-0.0002,-0.00020,6.000
6,36.467,0.01,-0.0002,-0.00020,6.000
6,36.533,0.01,-0.0002,-0.00020,6.000
6,36.600,0.00,-0.0002,-0.00020,6.000
6,36.667,0.01,-0.0002,-0.00020,6.000
6,36.733,0.02,-0.0002,-0.00020,6.000
6,36.800,0.00,-0.0002,-0.00020,6.000
6,36.867,0.01,-0.0002,-0.00020,6.000
6,36.933,0.01,-0.0002,-0.00017,6.000
6,37.000,0.01,-0.0001,-0.00010,6.000
6,37.067,0.00,-0.0001,-0.00010,6.000
6,37.133,0.00,-0.0001,-0.00010,6.000
6,37.200,0.01,-0.0001,-0.00010,6.000
6,37.267,0.01,-0.0001,-0.00010,6.000
6,37.333,0.00,-0.0001,-0.00010,6.000
6,37.467,0.01,-0.0001,-0.00010,6.000
7,37.600,0.00,0.0000,0.00000,7.000
7,37.733,0.00,0.1835,0.18347,7.000
7,37.800,0.00,0.4411,0.44110,7.000
7,37.867,0.00,0.8076,0.80760,7.000
7,37.933,-0.01,1.2077,1.20773,7.000
7,38.000,0.00,1.6076,1.60760,7.000
7,38.067,0.00,2.0076,2.00760,7.000
7,38.133,0.00,2.4076,2.40760,7.000
7,38.200,0.00,2.8078,2.80780,7.000
7,38.267,-0.01,3.2076,3.20763,7.000
7,38.333,0.00,3.6076,3.60760,7.000
7,38.400,0.00,4.0076,4.00760,7.000
7,38.467,0.02,4.4076,4.40757,7.000
7,38.533,0.26,4.8076,4.80763,7.000
7,38.600,1.44,5.2078,5.20780,7.000
7,38.667,3.76,5.6077,5.60773,7.000
7,38.733,7.52,6.0077,6.00770,7.000
7,38.800,13.13,6.4077,6.40770,7.000
7,38.867,21.27,6.8076,6.80760,7.000
7,39.000,43.09,7.4399,7.43990,7.000
7,39.067,50.14,7.5909,7.59087,7.000
7,39.133,51.29,7.6310,7.63103,7.000
7,39.200,45.21,7.5608,7.56080,7.000
7,39.267,33.71,7.3784,7.37840,7.000
7,39.333,21.57,7.0850,7.08503,7.000
7,39.400,11.72,6.6967,6.69670,7.000
7,39.467,6.14,6.2967,6.29670,7.000
7,39.533,3.23,5.8966,5.89660,7.000
7,39.600,1.48,5.4965,5.49650,7.000
7,39.667,0.43,5.0967,5.09667,7.000
7,39.733,0.00,4.6966,4.69663,7.000
7,39.800,0.00,4.2967,4.29670,7.000
7,39.867,0.00,3.8965,3.89650,7.000
7,39.933,0.00,3.4966,3.49660,7.000
7,40.000,0.00,3.0968,3.09680,7.000
7,40.067,0.00,2.6966,2.69657,7.000
7,40.133,0.00,2.2966,2.29660,7.000
7,40.200,0.00,1.8965,1.89650,7.000
7,40.267,0.00,1.4965,1.49650,7.000
7,40.333,0.00,1.0967,1.09670,7.000
7,40.400,0.00,0.6966,0.69660,7.000
7,40.467,0.00,0.2965,0.29650,7.000
7,40.667,0.00,-0.7061,-0.70610,7.000
7,40.733,0.00,-0.8413,-0.84133,7.000
7,40.800,0.00,-0.8656,-0.86560,7.000
7,40.867,0.00,-0.7786,-0.77860,7.000
7,40.933,0.00,-0.5804,-0.58037,7.000
7,41.000,0.00,-0.2961,-0.29610,7.000
7,41.067,-0.01,-0.0934,-0.09337,7.000
7,41.133,0.00,-0.0018,-0.00180,7.000
7,41.200,0.00,-0.0003,-0.00030,7.000
7,41.267,0.00,-0.0001,-0.00010,7.000
7,41.333,0.00,-0.0001,-0.00010,7.000
7,41.400,0.00,-0.0001,-0.00010,7.000
7,41.467,0.00,-0.0001,-0.00010,7.000
7,41.533,0.00,-0.0001,-0.00010,7.000
7,41.600,0.01,-0.0001,-0.00010,7.000
7,41.667,0.00,-0.0001,-0.00010,7.000
7,41.733,0.00,-0.0001,-0.00010,7.000
7,41.800,0.00,-0.0001,-0.00010,7.000
7,41.867,0.00,-0.0001,-0.00010,7.000
7,41.933,0.00,-0.0001,-0.00010,7.000
7,42.000,-0.01,-0.0001,-0.00010,7.000
7,42.067,0.00,-0.0001,-0.00010,7.000
7,42.133,0.00,-0.0001,-0.00010,7.000
7,42.200,0.00,-0.0001,-0.00010,7.000
7,42.267,0.00,-0.0001,-0.00010,7.000
7,42.333,0.00,-0.0001,-0.00010,7.000
7,42.400,0.00,-0.0001,-0.00010,7.000
7,42.467,0.00,-0.0001,-0.00010,7.000
7,42.533,0.00,-0.0001,-0.00010,7.000
7,42.600,0.00,-0.0001,-0.00010,7.000
7,42.667,0.00,-0.0001,-0.00010,7.000
7,42.733,0.00,-0.0001,-0.00010,7.000
7,42.800,0.00,-0.0001,-0.00010,7.000
7,42.867,0.00,-0.0001,-0.00010,7.000
7,42.933,0.00,-0.0001,-0.00010,7.000
7,43.000,0.00,-0.0001,-0.00010,7.000
7,43.067,0.00,-0.0001,-0.00010,7.000
7,43.133,0.00,-0.0001,-0.00010,7.000
7,43.200,-0.01,-0.0001,-0.00010,7.000
7,43.267,0.00,-0.0001,-0.00010,7.000
7,43.333,0.00,-0.0001,-0.00010,7.000
7,43.400,0.00,-0.0001,-0.00010,7.000
7,43.467,0.00,-0.0001,-0.00010,7.000
7,43.533,0.00,-0.0001,-0.00010,7.000
7,43.600,0.01,-0.0001,-0.00010,7.000
8,43.933,0.00,0.0841,0.08410,8.000
8,44.000,0.00,0.2767,0.27670,8.000
8,44.067,0.01,0.5809,0.58087,8.000
8,44.133,0.01,0.9735,0.97350,8.000
8,44.200,0.01,1.3736,1.37360,8.000
8,44.267,0.01,1.7735,1.77353,8.000
8,44.333,0.01,2.1736,2.17360,8.000
8,44.400,0.01,2.5735,2.57350,8.000
8,44.467,0.01,2.9736,2.97363,8.000
8,44.533,0.01,3.3736,3.37360,8.000
8,44.600,0.01,3.7737,3.77370,8.000
8,44.667,0.01,4.1736,4.17357,8.000
8,44.733,0.05,4.5737,4.57370,8.000
8,44.800,0.62,4.9737,4.97370,8.000
8,44.867,2.26,5.3736,5.37357,8.000
8,44.933,5.13,5.7737,5.77370,8.000
8,45.000,9.58,6.1736,6.17360,8.000
8,45.067,16.15,6.5736,6.57360,8.000
8,45.200,36.92,7.2941,7.29410,8.000
8,45.267,46.06,7.5050,7.50497,8.000
8,45.333,50.56,7.6050,7.60503,8.000
8,45.400,48.53,7.5948,7.59480,8.000
8,45.467,39.59,7.4726,7.47263,8.000
8,45.533,27.52,7.2392,7.23923,8.000
8,45.600,16.32,6.8952,6.89520,8.000
8,45.667,8.57,6.4947,6.49473,8.000
8,45.733,4.49,6.0946,6.09460,8.000
8,45.800,2.26,5.6948,5.69480,8.000
8,45.867,0.89,5.2947,5.29470,8.000
8,45.933,0.14,4.8947,4.89467,8.000
8,46.000,0.00,4.4947,4.49470,8.000
8,46.067,0.00,4.0946,4.09463,8.000
8,46.133,0.00,3.6947,3.69470,8.000
8,46.200,0.00,3.2947,3.29470,8.000
8,46.267,0.01,2.8946,2.89457,8.000
8,46.333,0.00,2.4946,2.49463,8.000
8,46.400,0.01,2.0948,2.09480,8.000
8,46.467,-0.01,1.6946,1.69463,8.000
8,46.533,0.01,1.2946,1.29463,8.000
8,46.600,0.01,0.8947,0.89470,8.000
8,46.667,0.01,0.4945,0.49453,8.000
8,46.733,0.00,0.0944,0.09443,8.000
8,46.867,0.01,-0.5888,-0.58880,8.000
8,46.933,0.01,-0.7722,-0.77220,8.000
8,47.000,0.00,-0.8448,-0.84480,8.000
8,47.067,0.01,-0.8063,-0.80627,8.000
8,47.133,0.01,-0.6564,-0.65637,8.000
8,47.200,0.00,-0.3957,-0.39570,8.000
8,47.267,0.01,-0.1548,-0.15477,8.000
8,47.333,0.01,-0.0247,-0.02470,8.000
8,47.400,0.01,0.0001,0.00010,8.000
8,47.467,0.01,-0.0002,-0.00020,8.000
8,47.533,0.01,-0.0002,-0.00020,8.000
8,47.600,0.01,-0.0002,-0.00020,8.000
8,47.667,0.00,-0.0002,-0.00020,8.000
8,47.733,0.01,-0.0002,-0.00020,8.000
8,47.800,0.01,-0.0002,-0.00020,8.000
8,47.867,0.01,-0.0002,-0.00020,8.000
8,47.933,0.01,-0.0002,-0.00020,8.000
8,48.000,0.00,-0.0002,-0.00020,8.000
8,48.067,0.01,-0.0002,-0.00020,8.000
8,48.133,0.01,-0.0002,-0.00020,8.000
8,48.200,0.01,-0.0002,-0.00020,8.000
8,48.267,0.01,-0.0002,-0.00020,8.000
8,48.333,0.01,-0.0002,-0.00020,8.000
8,48.400,0.01,-0.0002,-0.00020,8.000
8,48.467,0.01,-0.0002,-0.00020,8.000
8,48.533,0.01,-0.0002,-0.00020,8.000
8,48.600,0.01,-0.0002,-0.00020,8.000
8,48.667,0.01,-0.0002,-0.00020,8.000
8,48.733,0.01,-0.0002,-0.00020,8.000
8,48.800,0.01,-0.0002,-0.00020,8.000
8,48.867,0.01,-0.0002,-0.00020,8.000
8,48.933,0.01,-0.0001,-0.00010,8.000
8,49.000,0.01,-0.0001,-0.00010,8.000
8,49.067,0.01,-0.0001,-0.00010,8.000
8,49.133,0.01,-0.0001,-0.00010,8.000
8,49.200,0.01,-0.0001,-0.00010,8.000
8,49.267,0.01,-0.0001,-0.00010,8.000
8,49.333,0.01,-0.0001,-0.00010,8.000
8,49.400,0.01,-0.0001,-0.00010,8.000
8,49.467,0.01,-0.0001,-0.00010,8.000
8,49.533,0.01,-0.0001,-0.00010,8.000
8,49.600,0.01,-0.0001,-0.00010,8.000
8,49.667,0.01,-0.0001,-0.00010,8.000
8,49.733,0.01,-0.0001,-0.00010,8.000
8,49.800,0.01,-0.0001,-0.00010,8.000
8,49.933,0.01,-0.0001,-0.00010,8.000
9,50.133,0.00,0.0761,0.07623,9.000
9,50.200,0.01,0.2620,0.26210,9.000
9,50.267,0.00,0.5595,0.55960,9.000
9,50.333,0.00,0.9496,0.94973,9.000
9,50.400,0.00,1.3497,1.34980,9.000
9,50.467,0.00,1.7496,1.74970,9.000
9,50.533,0.00,2.1496,2.14967,9.000
9,50.600,0.00,2.5496,2.54970,9.000
9,50.667,0.00,2.9496,2.94973,9.000
9,50.733,0.00,3.3496,3.34970,9.000
9,50.800,0.00,3.7496,3.74970,9.000
9,50.867,0.01,4.1496,4.14967,9.000
9,50.933,0.03,4.5498,4.54990,9.000
9,51.000,0.55,4.9497,4.94980,9.000
9,51.067,2.11,5.3496,5.34973,9.000
9,51.133,4.90,5.7497,5.74980,9.000
9,51.200,9.25,6.1496,6.14970,9.000
9,51.267,15.67,6.5496,6.54973,9.000
9,51.400,36.90,7.2956,7.29570,9.000
9,51.467,47.24,7.5299,7.53000,9.000
9,51.533,53.30,7.6532,7.65333,9.000
9,51.600,52.68,7.6662,7.66630,9.000
9,51.667,44.48,7.5673,7.56743,9.000
9,51.733,31.83,7.3575,7.35757,9.000
9,51.800,19.54,7.0366,7.03670,9.000
9,51.867,10.38,6.6388,6.63887,9.000
9,51.933,5.47,6.2387,6.23877,9.000
9,52.000,2.87,5.8385,5.83860,9.000
9,52.067,1.27,5.4386,5.43873,9.000
9,52.133,0.32,5.0388,5.03887,9.000
9,52.200,0.00,4.6387,4.63880,9.000
9,52.267,0.00,4.2387,4.23877,9.000
9,52.333,0.00,3.8386,3.83870,9.000
9,52.400,-0.01,3.4387,3.43880,9.000
9,52.467,0.00,3.0387,3.03880,9.000
9,52.533,0.00,2.6385,2.63863,9.000
9,52.600,0.00,2.2386,2.23870,9.000
9,52.667,0.00,1.8386,1.83870,9.000
9,52.733,0.00,1.4385,1.43857,9.000
9,52.800,0.00,1.0386,1.03870,9.000
9,52.867,0.00,0.6385,0.63863,9.000
9,52.933,0.00,0.2385,0.23857,9.000
9,53.000,0.00,-0.1613,-0.16120,9.000
9,53.067,0.00,-0.5061,-0.50597,9.000
9,53.133,0.00,-0.7394,-0.73930,9.000
9,53.200,0.01,-0.8619,-0.86180,9.000
9,53.267,-0.01,-0.8732,-0.87310,9.000
9,53.333,0.00,-0.7735,-0.77340,9.000
9,53.400,0.01,-0.5627,-0.56260,9.000
9,53.467,0.00,-0.2775,-0.27737,9.000
9,53.533,0.00,-0.0840,-0.08387,9.000
9,53.600,-0.01,-0.0014,-0.00130,9.000
9,53.667,-0.01,-0.0002,-0.00007,9.000
9,53.733,0.00,-0.0001,0.00000,9.000
9,53.800,-0.01,-0.0001,0.00000,9.000
9,53.867,0.01,-0.0001,0.00000,9.000
9,53.933,-0.01,-0.0001,0.00000,9.000
9,54.000,0.00,-0.0001,0.00000,9.000
9,54.067,0.00,-0.0001,0.00000,9.000
9,54.133,0.00,-0.0001,0.00000,9.000
9,54.200,-0.01,-0.0001,0.00000,9.000
9,54.267,0.00,-0.0001,0.00000,9.000
9,54.333,0.00,-0.0001,0.00000,9.000
9,54.400,0.00,-0.0001,0.00000,9.000
9,54.467,0.00,-0.0001,0.00000,9.000
9,54.533,0.00,-0.0001,0.00000,9.000
9,54.600,-0.01,-0.0001,0.00000,9.000
9,54.667,0.00,-0.0001,0.00000,9.000
9,54.733,0.01,-0.0001,0.00000,9.000
9,54.800,0.00,-0.0001,0.00000,9.000
9,54.867,0.00,-0.0001,0.00000,9.000
9,54.933,0.01,-0.0001,0.00000,9.000
9,55.000,0.00,-0.0001,0.00000,9.000
9,55.067,0.00,-0.0001,0.00000,9.000
9,55.133,0.00,-0.0001,0.00000,9.000
9,55.200,0.00,-0.0001,0.00000,9.000
9,55.267,0.00,-0.0001,0.00000,9.000
9,55.333,0.00,-0.0001,0.00000,9.000
9,55.400,0.00,-0.0001,0.00000,9.000
9,55.467,0.01,-0.0001,0.00000,9.000
9,55.533,-0.01,-0.0001,0.00000,9.000
9,55.600,0.00,-0.0001,0.00000,9.000
9,55.667,0.00,-0.0001,0.00000,9.000
9,55.733,0.00,-0.0001,0.00000,9.000
9,55.800,0.00,-0.0001,0.00000,9.000
9,55.867,0.00,-0.0001,0.00000,9.000
9,55.933,0.00,-0.0001,0.00000,9.000
9,56.000,-0.01,-0.0001,0.00000,9.000
10,56.400,0.00,0.0980,0.09800,10.000
10,56.467,0.00,0.3023,0.30227,10.000
10,56.533,0.01,0.6174,0.61737,10.000
10,56.600,0.00,1.0137,1.01370,10.000
10,56.667,0.00,1.4135,1.41353,10.000
10,56.733,0.00,1.8135,1.81347,10.000
10,56.800,0.00,2.2136,2.21360,10.000
10,56.867,0.00,2.6135,2.61350,10.000
10,56.933,0.00,3.0136,3.01360,10.000
10,57.000,-0.01,3.4137,3.41370,10.000
10,57.067,0.00,3.8136,3.81363,10.000
10,57.133,0.00,4.2136,4.21360,10.000
10,57.200,0.06,4.6137,4.61370,10.000
10,57.267,0.72,5.0137,5.01370,10.000
10,57.333,2.47,5.4135,5.41353,10.000
10,57.400,5.47,5.8135,5.81350,10.000
10,57.467,10.12,6.2137,6.21370,10.000
10,57.533,16.93,6.6136,6.61363,10.000
10,57.667,37.97,7.3200,7.31997,10.000
10,57.733,46.75,7.5199,7.51993,10.000
10,57.800,50.69,7.6092,7.60920,10.000
10,57.867,47.87,7.5872,7.58723,10.000
10,57.933,38.43,7.4543,7.45430,10.000
10,58.000,26.29,7.2100,7.21000,10.000
10,58.067,15.33,6.8548,6.85477,10.000
10,58.133,8.02,6.4547,6.45467,10.000
10,58.200,4.20,6.0546,6.05460,10.000
10,58.267,2.09,5.6548,5.65483,10.000
10,58.333,0.78,5.2547,5.25467,10.000
10,58.400,0.10,4.8546,4.85460,10.000
10,58.467,-0.01,4.4547,4.45473,10.000
10,58.533,0.00,4.0546,4.05460,10.000
10,58.600,0.00,3.6547,3.65470,10.000
10,58.667,0.00,3.2547,3.25467,10.000
10,58.733,0.00,2.8546,2.85460,10.000
10,58.800,0.00,2.4547,2.45470,10.000
10,58.867,-0.01,2.0547,2.05473,10.000
10,58.933,0.00,1.6546,1.65457,10.000
10,59.000,0.00,1.2546,1.25460,10.000
10,59.067,0.00,0.8546,0.85460,10.000
10,59.133,0.00,0.4545,0.45453,10.000
10,59.200,-0.01,0.0545,0.05450,10.000
10,59.333,0.00,-0.6121,-0.61210,10.000
10,59.400,0.00,-0.7845,-0.78450,10.000
10,59.467,0.00,-0.8458,-0.84577,10.000
10,59.533,-0.01,-0.7963,-0.79633,10.000
10,59.600,-0.01,-0.6355,-0.63550,10.000
10,59.667,-0.01,-0.3668,-0.36683,10.000
10,59.733,0.00,-0.1367,-0.13667,10.000
10,59.800,0.00,-0.0172,-0.01720,10.000
10,59.867,0.00,-0.0002,-0.00017,10.000
10,59.933,0.00,-0.0002,-0.00020,10.000
10,60.000,0.01,-0.0002,-0.00020,10.000
10,60.067,0.00,-0.0002,-0.00020,10.000
10,60.133,0.00,-0.0002,-0.00020,10.000
10,60.200,-0.01,-0.0002,-0.00020,10.000
10,60.267,0.00,-0.0002,-0.00020,10.000
10,60.333,0.00,-0.0002,-0.00020,10.000
10,60.400,0.00,-0.0002,-0.00020,10.000
10,60.467,0.00,-0.0002,-0.00020,10.000
10,60.533,0.00,-0.0002,-0.00020,10.000
10,60.600,-0.01,-0.0002,-0.00020,10.000
10,60.667,0.00,-0.0002,-0.00020,10.000
10,60.733,-0.01,-0.0002,-0.00020,10.000
10,60.800,-0.01,-0.0002,-0.00020,10.000
10,60.867,0.00,-0.0002,-0.00020,10.000
10,60.933,0.00,-0.0002,-0.00020,10.000
10,61.000,0.00,-0.0002,-0.00020,10.000
10,61.067,0.00,-0.0002,-0.00020,10.000
10,61.133,0.00,-0.0002,-0.00020,10.000
10,61.200,0.00,-0.0002,-0.00020,10.000
10,61.267,0.00,-0.0002,-0.00020,10.000
10,61.333,0.00,-0.0002,-0.00020,10.000
10,61.400,0.00,-0.0001,-0.00010,10.000
10,61.467,0.00,-0.0001,-0.00010,10.000
10,61.533,0.00,-0.0001,-0.00010,10.000
10,61.600,0.00,-0.0001,-0.00010,10.000
10,61.667,0.00,-0.0001,-0.00010,10.000
10,61.733,0.00,-0.0001,-0.00010,10.000
10,61.800,0.00,-0.0001,-0.00010,10.000
10,61.867,0.00,-0.0001,-0.00010,10.000
10,61.933,0.00,-0.0001,-0.00010,10.000
10,62.000,0.00,-0.0001,-0.00010,10.000
10,62.067,0.00,-0.0001,-0.00010,10.000
10,62.133,0.00,-0.0001,-0.00010,10.000
10,62.200,0.00,-0.0001,-0.00010,10.000
10,62.267,0.00,-0.0001,-0.00010,10.000
10,62.400,0.00,-0.0001,-0.00010,10.000