File: AIME_journal_files/AIME_data/calibDATA_loadcell/date_02:15:2018/Instron_02.15.2018/2_30N_0__1mm.s_0_0_hold.txt
""
"Test Method","Radhen_Load_Cntrl_Cmprsn_250N_12-7.msm"
"Sample I. D.","Sample1.mss"
"Specimen Number","35"

"TheCycle_Output ()","_Time (s)","_Load (N)","_Extension (mm)","RealTimeDepth (mm)","CycleNumber ()"

1,0.333,0.00,0.0916,0.09160,1.000
1,0.400,0.00,0.1584,0.15840,1.000
1,0.467,0.00,0.2252,0.22520,1.000
1,0.533,0.00,0.2917,0.29173,1.000
1,0.600,0.00,0.3585,0.35850,1.000
1,0.667,0.00,0.4252,0.42520,1.000
1,0.733,0.00,0.4918,0.49180,1.000
1,0.800,0.00,0.5586,0.55860,1.000
1,0.867,0.00,0.6253,0.62527,1.000
1,0.933,0.00,0.6918,0.69177,1.000
1,1.000,0.00,0.7585,0.75850,1.000
1,1.067,0.00,0.8254,0.82537,1.000
1,1.133,0.00,0.8919,0.89187,1.000
1,1.200,0.00,0.9585,0.95850,1.000
1,1.267,0.00,1.0252,1.02523,1.000
1,1.333,0.00,1.0918,1.09180,1.000
1,1.400,0.00,1.1588,1.15880,1.000
1,1.467,0.00,1.2253,1.22533,1.000
1,1.533,0.00,1.2919,1.29190,1.000
1,1.600,0.00,1.3585,1.35850,1.000
1,1.667,0.00,1.4252,1.42520,1.000
1,1.733,0.00,1.4918,1.49180,1.000
1,1.800,0.00,1.5586,1.55860,1.000
1,1.867,0.00,1.6253,1.62533,1.000
1,1.933,0.00,1.6919,1.69193,1.000
1,2.000,0.00,1.7585,1.75850,1.000
1,2.067,0.00,1.8253,1.82530,1.000
1,2.133,0.00,1.8918,1.89180,1.000
1,2.200,0.00,1.9587,1.95870,1.000
1,2.267,0.00,2.0254,2.02543,1.000
1,2.333,0.00,2.0920,2.09197,1.000
1,2.400,0.00,2.1588,2.15880,1.000
1,2.467,0.00,2.2253,2.22533,1.000
1,2.533,0.00,2.2919,2.29187,1.000
1,2.600,0.00,2.3586,2.35860,1.000
1,2.667,0.00,2.4254,2.42540,1.000
1,2.733,0.00,2.4919,2.49193,1.000
1,2.800,0.00,2.5587,2.55870,1.000
1,2.867,0.00,2.6253,2.62533,1.000
1,2.933,0.00,2.6919,2.69187,1.000
1,3.000,0.00,2.7588,2.75880,1.000
1,3.067,0.00,2.8254,2.82543,1.000
1,3.133,0.00,2.8919,2.89193,1.000
1,3.200,0.00,2.9588,2.95880,1.000
1,3.267,0.00,3.0254,3.02537,1.000
1,3.333,0.00,3.0920,3.09203,1.000
1,3.400,0.00,3.1588,3.15880,1.000
1,3.467,0.00,3.2254,3.22537,1.000
1,3.533,0.00,3.2920,3.29200,1.000
1,3.600,-0.01,3.3588,3.35880,1.000
1,3.667,0.00,3.4254,3.42543,1.000
1,3.733,0.00,3.4920,3.49197,1.000
1,3.800,0.00,3.5588,3.55880,1.000
1,3.867,0.00,3.6255,3.62550,1.000
1,3.933,0.00,3.6921,3.69213,1.000
1,4.000,0.00,3.7590,3.75900,1.000
1,4.067,0.00,3.8254,3.82537,1.000
1,4.133,0.00,3.8919,3.89193,1.000
1,4.200,0.00,3.9588,3.95880,1.000
1,4.267,0.00,4.0253,4.02533,1.000
1,4.333,0.00,4.0920,4.09200,1.000
1,4.400,0.01,4.1588,4.15880,1.000
1,4.467,0.01,4.2254,4.22543,1.000
1,4.533,0.02,4.2921,4.29207,1.000
1,4.600,0.02,4.3589,4.35890,1.000
1,4.667,0.02,4.4254,4.42540,1.000
1,4.733,0.05,4.4922,4.49220,1.000
1,4.800,0.09,4.5588,4.55880,1.000
1,4.867,0.16,4.6254,4.62537,1.000
1,4.933,0.24,4.6920,4.69203,1.000
1,5.000,0.35,4.7588,4.75880,1.000
1,5.067,0.48,4.8254,4.82543,1.000
1,5.133,0.64,4.8922,4.89217,1.000
1,5.200,0.83,4.9590,4.95900,1.000
1,5.267,1.05,5.0255,5.02553,1.000
1,5.333,1.30,5.0922,5.09223,1.000
1,5.400,1.58,5.1589,5.15890,1.000
1,5.467,1.88,5.2255,5.22553,1.000
1,5.533,2.22,5.2922,5.29217,1.000
1,5.600,2.58,5.3588,5.35880,1.000
1,5.667,2.98,5.4254,5.42540,1.000
1,5.733,3.41,5.4921,5.49210,1.000
1,5.800,3.87,5.5589,5.55890,1.000
1,5.867,4.37,5.6257,5.62570,1.000
1,5.933,4.91,5.6922,5.69223,1.000
1,6.000,5.48,5.7588,5.75880,1.000
1,6.067,6.08,5.8253,5.82533,1.000
1,6.133,6.72,5.8921,5.89207,1.000
1,6.200,7.41,5.9589,5.95890,1.000
1,6.267,8.14,6.0254,6.02543,1.000
1,6.333,8.91,6.0921,6.09210,1.000
1,6.400,9.73,6.1589,6.15890,1.000
1,6.467,10.60,6.2254,6.22543,1.000
1,6.533,11.53,6.2922,6.29223,1.000
1,6.600,12.51,6.3589,6.35890,1.000
1,6.667,13.55,6.4255,6.42550,1.000
1,6.733,14.65,6.4922,6.49223,1.000
1,6.800,15.81,6.5589,6.55890,1.000
1,6.867,17.06,6.6255,6.62547,1.000
1,6.933,18.38,6.6922,6.69220,1.000
1,7.000,19.78,6.7588,6.75880,1.000
1,7.067,21.26,6.8255,6.82547,1.000
1,7.133,22.86,6.8923,6.89227,1.000
1,7.200,24.54,6.9591,6.95910,1.000
1,7.267,26.33,7.0255,7.02550,1.000
1,7.333,28.22,7.0922,7.09223,1.000
1,7.400,30.22,7.1588,7.15880,1.000
1,7.533,30.76,7.1990,7.19900,1.000
1,7.600,30.24,7.1990,7.19900,1.000
1,7.667,29.90,7.1990,7.19900,1.000
1,7.733,29.63,7.1990,7.19900,1.000
1,7.800,29.42,7.1990,7.19900,1.000
1,7.867,29.25,7.1990,7.19900,1.000
1,7.933,29.10,7.1990,7.19900,1.000
1,8.000,28.97,7.1990,7.19900,1.000
1,8.067,28.86,7.1990,7.19900,1.000
1,8.133,28.76,7.1990,7.19900,1.000
1,8.200,28.67,7.1990,7.19900,1.000
1,8.267,28.58,7.1990,7.19900,1.000
1,8.333,28.51,7.1990,7.19900,1.000
1,8.400,28.43,7.1990,7.19900,1.000
1,8.467,28.38,7.1990,7.19900,1.000
1,8.533,28.31,7.1990,7.19900,1.000
1,8.600,28.26,7.1990,7.19900,1.000
1,8.667,28.20,7.1990,7.19900,1.000
1,8.733,28.15,7.1990,7.19900,1.000
1,8.800,28.10,7.1990,7.19900,1.000
1,8.867,28.06,7.1990,7.19900,1.000
1,8.933,28.03,7.1990,7.19900,1.000
1,9.000,27.99,7.1990,7.19900,1.000
1,9.067,27.95,7.1990,7.19900,1.000
1,9.133,27.92,7.1990,7.19900,1.000
1,9.200,27.88,7.1990,7.19900,1.000
1,9.267,27.85,7.1990,7.19900,1.000
1,9.333,27.82,7.1990,7.19900,1.000
1,9.400,27.79,7.1990,7.19900,1.000
1,9.467,27.77,7.1990,7.19900,1.000
1,9.533,27.74,7.1990,7.19900,1.000
1,9.600,27.71,7.1990,7.19900,1.000
1,9.667,27.69,7.1990,7.19900,1.000
1,9.733,27.66,7.1990,7.19900,1.000
1,9.800,27.64,7.1990,7.19900,1.000
1,9.867,27.62,7.1990,7.19900,1.000
1,9.933,27.60,7.1990,7.19900,1.000
1,10.000,27.57,7.1990,7.19900,1.000
1,10.067,27.55,7.1990,7.19900,1.000
1,10.133,27.54,7.1990,7.19900,1.000
1,10.200,27.51,7.1990,7.19900,1.000
1,10.267,27.50,7.1990,7.19900,1.000
1,10.333,27.48,7.1990,7.19900,1.000
1,10.400,27.46,7.1990,7.19900,1.000
1,10.467,27.44,7.1990,7.19900,1.000
1,10.533,27.43,7.1990,7.19900,1.000
1,10.600,27.42,7.1990,7.19900,1.000
1,10.667,27.40,7.1990,7.19900,1.000
1,10.733,27.37,7.1990,7.19900,1.000
1,10.800,27.37,7.1990,7.19900,1.000
1,10.867,27.35,7.1990,7.19900,1.000
1,10.933,27.33,7.1990,7.19900,1.000
1,11.000,27.33,7.1990,7.19900,1.000
1,11.067,27.31,7.1990,7.19900,1.000
1,11.133,27.29,7.1990,7.19900,1.000
1,11.200,27.28,7.1990,7.19900,1.000
1,11.267,27.27,7.1990,7.19900,1.000
1,11.333,27.25,7.1990,7.19900,1.000
1,11.400,27.24,7.1990,7.19900,1.000
1,11.467,27.23,7.1990,7.19900,1.000
1,11.533,27.22,7.1990,7.19900,1.000
1,11.600,27.21,7.1990,7.19900,1.000
1,11.667,27.19,7.1990,7.19900,1.000
1,11.733,27.18,7.1990,7.19900,1.000
1,11.800,27.17,7.1990,7.19900,1.000
1,11.867,27.16,7.1990,7.19900,1.000
1,11.933,27.15,7.1990,7.19900,1.000
1,12.000,27.13,7.1990,7.19900,1.000
1,12.067,27.13,7.1990,7.19900,1.000
1,12.133,27.12,7.1990,7.19900,1.000
1,12.200,27.11,7.1990,7.19900,1.000
1,12.267,27.10,7.1990,7.19900,1.000
1,12.333,27.09,7.1990,7.19900,1.000
1,12.400,27.08,7.1990,7.19900,1.000
1,12.467,27.07,7.1990,7.19900,1.000
1,12.533,27.06,7.1990,7.19900,1.000
1,12.600,27.05,7.1990,7.19900,1.000
1,12.667,27.04,7.1990,7.19900,1.000
1,12.733,27.03,7.1990,7.19900,1.000
1,12.800,27.02,7.1990,7.19900,1.000
1,12.867,27.02,7.1990,7.19900,1.000
1,12.933,27.01,7.1990,7.19900,1.000
1,13.000,27.00,7.1990,7.19900,1.000
1,13.067,26.99,7.1990,7.19900,1.000
1,13.133,26.98,7.1990,7.19900,1.000
1,13.200,26.97,7.1990,7.19900,1.000
1,13.267,26.97,7.1990,7.19900,1.000
1,13.333,26.96,7.1990,7.19900,1.000
1,13.400,26.95,7.1990,7.19900,1.000
1,13.467,26.94,7.1990,7.19900,1.000
1,13.533,26.93,7.1990,7.19900,1.000