File: AIME_journal_files/AIME_data/calibDATA_loadcell/date_02:15:2018/Instron_02.15.2018/2_4N_0__1mm.s_0_0_hold.txt
""
"Test Method","Radhen_Load_Cntrl_Cmprsn_250N_12-7.msm"
"Sample I. D.","Sample1.mss"
"Specimen Number","30"

"TheCycle_Output ()","_Time (s)","_Load (N)","_Extension (mm)","RealTimeDepth (mm)","CycleNumber ()"

1,0.333,0.00,0.0917,0.09167,1.000
1,0.400,0.00,0.1584,0.15840,1.000
1,0.467,0.01,0.2253,0.22530,1.000
1,0.533,0.00,0.2918,0.29180,1.000
1,0.600,0.01,0.3585,0.35850,1.000
1,0.667,0.00,0.4253,0.42527,1.000
1,0.733,0.01,0.4918,0.49180,1.000
1,0.800,0.01,0.5585,0.55850,1.000
1,0.867,0.00,0.6253,0.62530,1.000
1,0.933,0.01,0.6918,0.69183,1.000
1,1.000,0.00,0.7585,0.75850,1.000
1,1.067,0.00,0.8253,0.82533,1.000
1,1.133,0.00,0.8919,0.89187,1.000
1,1.200,0.01,0.9585,0.95850,1.000
1,1.267,0.00,1.0253,1.02530,1.000
1,1.333,0.00,1.0919,1.09193,1.000
1,1.400,0.00,1.1586,1.15860,1.000
1,1.467,0.00,1.2254,1.22543,1.000
1,1.533,0.00,1.2920,1.29200,1.000
1,1.600,0.00,1.3586,1.35860,1.000
1,1.667,0.00,1.4253,1.42527,1.000
1,1.733,0.00,1.4919,1.49187,1.000
1,1.800,0.01,1.5586,1.55860,1.000
1,1.867,0.00,1.6253,1.62530,1.000
1,1.933,0.00,1.6920,1.69197,1.000
1,2.000,0.00,1.7586,1.75860,1.000
1,2.067,0.00,1.8253,1.82530,1.000
1,2.133,0.00,1.8919,1.89190,1.000
1,2.200,0.00,1.9587,1.95870,1.000
1,2.267,0.00,2.0255,2.02553,1.000
1,2.333,0.00,2.0921,2.09207,1.000
1,2.400,0.00,2.1588,2.15880,1.000
1,2.467,0.01,2.2254,2.22537,1.000
1,2.533,0.01,2.2919,2.29193,1.000
1,2.600,0.00,2.3587,2.35870,1.000
1,2.667,0.00,2.4254,2.42540,1.000
1,2.733,0.00,2.4920,2.49197,1.000
1,2.800,0.00,2.5587,2.55870,1.000
1,2.867,0.00,2.6253,2.62530,1.000
1,2.933,0.00,2.6919,2.69193,1.000
1,3.000,0.00,2.7587,2.75870,1.000
1,3.067,0.00,2.8255,2.82547,1.000
1,3.133,0.00,2.8919,2.89193,1.000
1,3.200,0.01,2.9588,2.95880,1.000
1,3.267,0.00,3.0255,3.02547,1.000
1,3.333,0.00,3.0920,3.09203,1.000
1,3.400,0.00,3.1589,3.15890,1.000
1,3.467,0.00,3.2255,3.22550,1.000
1,3.533,0.00,3.2920,3.29203,1.000
1,3.600,0.00,3.3589,3.35890,1.000
1,3.667,0.00,3.4254,3.42543,1.000
1,3.733,0.00,3.4920,3.49197,1.000
1,3.800,0.00,3.5588,3.55880,1.000
1,3.867,0.00,3.6255,3.62550,1.000
1,3.933,0.00,3.6921,3.69210,1.000
1,4.000,0.00,3.7590,3.75900,1.000
1,4.067,0.00,3.8254,3.82540,1.000
1,4.133,0.01,3.8919,3.89193,1.000
1,4.200,0.01,3.9589,3.95890,1.000
1,4.267,0.01,4.0254,4.02537,1.000
1,4.333,0.01,4.0920,4.09200,1.000
1,4.400,0.01,4.1589,4.15890,1.000
1,4.467,0.01,4.2255,4.22547,1.000
1,4.533,0.02,4.2921,4.29213,1.000
1,4.600,0.02,4.3588,4.35880,1.000
1,4.667,0.03,4.4254,4.42540,1.000
1,4.733,0.05,4.4921,4.49213,1.000
1,4.800,0.10,4.5590,4.55900,1.000
1,4.867,0.16,4.6255,4.62547,1.000
1,4.933,0.25,4.6921,4.69210,1.000
1,5.000,0.36,4.7588,4.75880,1.000
1,5.067,0.49,4.8255,4.82547,1.000
1,5.133,0.65,4.8921,4.89210,1.000
1,5.200,0.84,4.9590,4.95900,1.000
1,5.267,1.07,5.0256,5.02560,1.000
1,5.333,1.33,5.0922,5.09220,1.000
1,5.400,1.59,5.1590,5.15900,1.000
1,5.467,1.89,5.2255,5.22553,1.000
1,5.533,2.24,5.2922,5.29220,1.000
1,5.600,2.61,5.3589,5.35890,1.000
1,5.667,3.00,5.4254,5.42543,1.000
1,5.733,3.43,5.4921,5.49210,1.000
1,5.800,3.89,5.5590,5.55900,1.000
1,5.933,4.35,5.6191,5.61910,1.000
1,6.000,4.30,5.6191,5.61910,1.000
1,6.067,4.24,5.6191,5.61910,1.000
1,6.133,4.22,5.6191,5.61910,1.000
1,6.200,4.19,5.6191,5.61910,1.000
1,6.267,4.17,5.6191,5.61910,1.000
1,6.333,4.16,5.6191,5.61910,1.000
1,6.400,4.13,5.6191,5.61910,1.000
1,6.467,4.11,5.6191,5.61910,1.000
1,6.533,4.11,5.6191,5.61910,1.000
1,6.600,4.11,5.6191,5.61910,1.000
1,6.667,4.10,5.6191,5.61910,1.000
1,6.733,4.08,5.6191,5.61910,1.000
1,6.800,4.07,5.6191,5.61910,1.000
1,6.867,4.06,5.6191,5.61910,1.000
1,6.933,4.05,5.6191,5.61910,1.000
1,7.000,4.05,5.6191,5.61910,1.000
1,7.067,4.04,5.6191,5.61910,1.000
1,7.133,4.03,5.6191,5.61910,1.000
1,7.200,4.04,5.6191,5.61910,1.000
1,7.267,4.02,5.6191,5.61910,1.000
1,7.333,4.02,5.6191,5.61910,1.000
1,7.400,4.01,5.6191,5.61910,1.000
1,7.467,4.00,5.6191,5.61907,1.000
1,7.533,4.00,5.6191,5.61910,1.000
1,7.600,4.00,5.6191,5.61910,1.000
1,7.667,4.00,5.6191,5.61910,1.000
1,7.733,3.99,5.6191,5.61910,1.000
1,7.800,3.98,5.6191,5.61910,1.000
1,7.867,3.97,5.6191,5.61910,1.000
1,7.933,3.98,5.6191,5.61910,1.000
1,8.000,3.96,5.6191,5.61910,1.000
1,8.067,3.97,5.6191,5.61910,1.000
1,8.133,3.96,5.6191,5.61910,1.000
1,8.200,3.96,5.6191,5.61910,1.000
1,8.267,3.96,5.6191,5.61910,1.000
1,8.333,3.96,5.6191,5.61910,1.000
1,8.400,3.96,5.6191,5.61910,1.000
1,8.467,3.95,5.6191,5.61910,1.000
1,8.533,3.95,5.6191,5.61910,1.000
1,8.600,3.94,5.6191,5.61910,1.000
1,8.667,3.94,5.6191,5.61910,1.000
1,8.733,3.94,5.6191,5.61910,1.000
1,8.800,3.93,5.6191,5.61910,1.000
1,8.867,3.93,5.6191,5.61910,1.000
1,8.933,3.93,5.6191,5.61910,1.000
1,9.000,3.94,5.6191,5.61910,1.000
1,9.067,3.92,5.6191,5.61910,1.000
1,9.133,3.92,5.6191,5.61910,1.000
1,9.200,3.91,5.6191,5.61910,1.000
1,9.267,3.92,5.6191,5.61910,1.000
1,9.333,3.91,5.6191,5.61910,1.000
1,9.400,3.92,5.6191,5.61910,1.000
1,9.467,3.91,5.6191,5.61910,1.000
1,9.533,3.91,5.6191,5.61910,1.000
1,9.600,3.92,5.6191,5.61910,1.000
1,9.667,3.92,5.6191,5.61910,1.000
1,9.733,3.91,5.6191,5.61910,1.000
1,9.800,3.91,5.6191,5.61910,1.000
1,9.867,3.90,5.6191,5.61910,1.000
1,9.933,3.90,5.6191,5.61910,1.000
1,10.000,3.90,5.6191,5.61910,1.000
1,10.067,3.89,5.6191,5.61910,1.000
1,10.133,3.89,5.6191,5.61910,1.000
1,10.200,3.89,5.6191,5.61910,1.000
1,10.267,3.89,5.6191,5.61910,1.000
1,10.333,3.90,5.6191,5.61910,1.000