File: AIME_journal_files/AIME_data/calibDATA_loadcell/date_08:02:2018/MTS/0deg_30N_2.txt
""
"Test Method","Radhen_Load_Cntrl_Cmprsn_250N_12-7.msm"
"Sample I. D.","Sample1.mss"
"Specimen Number","2"

"TheCycle_Output ()","_Time (s)","_Load (N)","_Extension (mm)","RealTimeDepth (mm)","CycleNumber ()"

1,0.250,0.01,0.0278,0.02780,1.000
1,0.300,0.00,0.0776,0.07760,1.000
1,0.350,0.00,0.1277,0.12770,1.000
1,0.400,-0.01,0.1776,0.17760,1.000
1,0.450,0.00,0.2277,0.22770,1.000
1,0.500,-0.01,0.2777,0.27770,1.000
1,0.550,0.00,0.3277,0.32770,1.000
1,0.600,0.00,0.3777,0.37770,1.000
1,0.650,0.00,0.4279,0.42790,1.000
1,0.700,-0.01,0.4779,0.47790,1.000
1,0.750,0.00,0.5278,0.52780,1.000
1,0.800,-0.01,0.5776,0.57760,1.000
1,0.850,0.00,0.6277,0.62770,1.000
1,0.900,-0.01,0.6778,0.67780,1.000
1,0.950,0.00,0.7277,0.72770,1.000
1,1.000,0.00,0.7777,0.77770,1.000
1,1.050,0.00,0.8277,0.82770,1.000
1,1.100,0.00,0.8778,0.87780,1.000
1,1.150,0.00,0.9278,0.92780,1.000
1,1.200,0.00,0.9777,0.97770,1.000
1,1.250,0.00,1.0278,1.02780,1.000
1,1.300,0.00,1.0779,1.07790,1.000
1,1.350,0.00,1.1278,1.12780,1.000
1,1.400,0.00,1.1776,1.17760,1.000
1,1.450,-0.01,1.2277,1.22770,1.000
1,1.500,0.00,1.2778,1.27780,1.000
1,1.550,0.00,1.3277,1.32770,1.000
1,1.600,0.00,1.3777,1.37770,1.000
1,1.650,0.00,1.4278,1.42780,1.000
1,1.700,0.00,1.4778,1.47780,1.000
1,1.750,0.01,1.5278,1.52780,1.000
1,1.800,0.01,1.5778,1.57780,1.000
1,1.850,0.02,1.6277,1.62770,1.000
1,1.900,0.01,1.6779,1.67790,1.000
1,1.950,0.02,1.7279,1.72790,1.000
1,2.000,0.02,1.7778,1.77780,1.000
1,2.050,0.03,1.8279,1.82790,1.000
1,2.100,0.04,1.8779,1.87790,1.000
1,2.150,0.04,1.9280,1.92800,1.000
1,2.200,0.06,1.9777,1.97770,1.000
1,2.250,0.09,2.0277,2.02770,1.000
1,2.300,0.15,2.0779,2.07790,1.000
1,2.350,0.21,2.1280,2.12800,1.000
1,2.400,0.27,2.1778,2.17780,1.000
1,2.450,0.35,2.2278,2.22780,1.000
1,2.500,0.44,2.2779,2.27790,1.000
1,2.550,0.54,2.3279,2.32790,1.000
1,2.600,0.65,2.3778,2.37780,1.000
1,2.650,0.77,2.4279,2.42790,1.000
1,2.700,0.90,2.4779,2.47790,1.000
1,2.750,1.06,2.5279,2.52790,1.000
1,2.800,1.23,2.5778,2.57780,1.000
1,2.850,1.42,2.6278,2.62780,1.000
1,2.900,1.62,2.6779,2.67790,1.000
1,2.950,1.85,2.7280,2.72800,1.000
1,3.000,2.10,2.7777,2.77770,1.000
1,3.050,2.37,2.8277,2.82770,1.000
1,3.100,2.66,2.8779,2.87790,1.000
1,3.150,2.97,2.9278,2.92780,1.000
1,3.200,3.30,2.9777,2.97770,1.000
1,3.250,3.66,3.0278,3.02780,1.000
1,3.300,4.03,3.0780,3.07800,1.000
1,3.350,4.42,3.1280,3.12800,1.000
1,3.400,4.84,3.1778,3.17780,1.000
1,3.450,5.29,3.2279,3.22790,1.000
1,3.500,5.76,3.2779,3.27790,1.000
1,3.550,6.26,3.3278,3.32780,1.000
1,3.600,6.78,3.3777,3.37770,1.000
1,3.650,7.32,3.4278,3.42780,1.000
1,3.700,7.90,3.4779,3.47790,1.000
1,3.750,8.51,3.5279,3.52790,1.000
1,3.800,9.14,3.5777,3.57770,1.000
1,3.850,9.81,3.6277,3.62770,1.000
1,3.900,10.51,3.6779,3.67790,1.000
1,3.950,11.25,3.7280,3.72800,1.000
1,4.000,12.03,3.7778,3.77780,1.000
1,4.050,12.84,3.8278,3.82780,1.000
1,4.100,13.69,3.8779,3.87790,1.000
1,4.150,14.58,3.9280,3.92800,1.000
1,4.200,15.51,3.9778,3.97780,1.000
1,4.250,16.48,4.0279,4.02790,1.000
1,4.300,17.50,4.0779,4.07790,1.000
1,4.350,18.56,4.1279,4.12790,1.000
1,4.400,19.68,4.1778,4.17780,1.000
1,4.450,20.85,4.2279,4.22790,1.000
1,4.500,22.07,4.2779,4.27790,1.000
1,4.550,23.33,4.3281,4.32810,1.000
1,4.600,24.62,4.3778,4.37780,1.000
1,4.650,25.96,4.4278,4.42780,1.000
1,4.700,27.30,4.4778,4.47780,1.000
1,4.750,28.65,4.5280,4.52800,1.000
1,4.800,30.06,4.5777,4.57770,1.000
1,4.900,31.54,4.6175,4.61750,1.000
1,4.950,28.80,4.5687,4.56870,1.000
1,5.000,26.20,4.5187,4.51870,1.000
1,5.050,23.98,4.4686,4.46860,1.000
1,5.100,22.02,4.4186,4.41860,1.000
1,5.150,20.24,4.3687,4.36870,1.000
1,5.200,18.64,4.3188,4.31880,1.000
1,5.250,17.18,4.2688,4.26880,1.000
1,5.300,15.84,4.2186,4.21860,1.000
1,5.350,14.61,4.1687,4.16870,1.000
1,5.400,13.49,4.1187,4.11870,1.000
1,5.450,12.46,4.0687,4.06870,1.000
1,5.500,11.51,4.0187,4.01870,1.000
1,5.550,10.63,3.9687,3.96870,1.000
1,5.600,9.81,3.9189,3.91890,1.000
1,5.650,9.06,3.8687,3.86870,1.000
1,5.700,8.37,3.8186,3.81860,1.000
1,5.750,7.73,3.7687,3.76870,1.000
1,5.800,7.14,3.7188,3.71880,1.000
1,5.850,6.60,3.6687,3.66870,1.000
1,5.900,6.09,3.6185,3.61850,1.000
1,5.950,5.62,3.5685,3.56850,1.000
1,6.000,5.18,3.5187,3.51870,1.000
1,6.050,4.77,3.4685,3.46850,1.000
1,6.100,4.39,3.4186,3.41860,1.000
1,6.150,4.03,3.3686,3.36860,1.000
1,6.200,3.70,3.3186,3.31860,1.000
1,6.250,3.38,3.2685,3.26850,1.000
1,6.300,3.08,3.2185,3.21850,1.000
1,6.350,2.81,3.1687,3.16870,1.000
1,6.400,2.55,3.1188,3.11880,1.000
1,6.450,2.31,3.0686,3.06860,1.000
1,6.500,2.08,3.0185,3.01850,1.000
1,6.550,1.86,2.9686,2.96860,1.000
1,6.600,1.66,2.9185,2.91850,1.000
1,6.650,1.48,2.8684,2.86840,1.000
1,6.700,1.31,2.8184,2.81840,1.000
1,6.750,1.16,2.7686,2.76860,1.000
1,6.800,1.02,2.7185,2.71850,1.000
1,6.850,0.89,2.6684,2.66840,1.000
1,6.900,0.76,2.6184,2.61840,1.000
1,6.950,0.64,2.5685,2.56850,1.000
1,7.000,0.55,2.5187,2.51870,1.000
1,7.050,0.46,2.4685,2.46850,1.000
1,7.100,0.37,2.4184,2.41840,1.000
1,7.150,0.30,2.3685,2.36850,1.000
1,7.200,0.23,2.3186,2.31860,1.000
1,7.250,0.17,2.2684,2.26840,1.000
1,7.300,0.12,2.2184,2.21840,1.000
1,7.350,0.08,2.1685,2.16850,1.000
1,7.400,0.04,2.1185,2.11850,1.000
1,7.450,0.01,2.0684,2.06840,1.000
1,7.500,0.00,2.0183,2.01830,1.000
1,7.550,-0.01,1.9684,1.96840,1.000
1,7.600,0.00,1.9185,1.91850,1.000
1,7.650,0.00,1.8685,1.86850,1.000
1,7.700,0.00,1.8185,1.81850,1.000
1,7.750,0.00,1.7685,1.76850,1.000
1,7.800,0.01,1.7186,1.71860,1.000
1,7.850,0.00,1.6683,1.66830,1.000
1,7.900,0.00,1.6183,1.61830,1.000
1,7.950,0.00,1.5685,1.56850,1.000
1,8.000,0.00,1.5185,1.51850,1.000
1,8.050,0.00,1.4685,1.46850,1.000
1,8.100,0.00,1.4182,1.41820,1.000
1,8.150,0.00,1.3684,1.36840,1.000
1,8.200,0.00,1.3184,1.31840,1.000
1,8.250,0.00,1.2684,1.26840,1.000
1,8.300,0.00,1.2182,1.21820,1.000
1,8.350,0.00,1.1685,1.16850,1.000
1,8.400,0.00,1.1185,1.11850,1.000
1,8.450,0.00,1.0685,1.06850,1.000
1,8.500,0.00,1.0184,1.01840,1.000
1,8.550,0.00,0.9684,0.96840,1.000
1,8.600,0.00,0.9184,0.91840,1.000
1,8.650,0.00,0.8684,0.86840,1.000
1,8.700,0.00,0.8183,0.81830,1.000
1,8.750,0.00,0.7684,0.76840,1.000
1,8.800,0.00,0.7184,0.71840,1.000
1,8.850,0.00,0.6684,0.66840,1.000
1,8.900,0.00,0.6181,0.61810,1.000
1,8.950,0.00,0.5683,0.56830,1.000
1,9.000,0.00,0.5183,0.51830,1.000
1,9.050,0.00,0.4685,0.46850,1.000
1,9.100,0.00,0.4184,0.41840,1.000
1,9.150,0.00,0.3684,0.36840,1.000
1,9.200,0.00,0.3184,0.31840,1.000
1,9.250,0.01,0.2683,0.26830,1.000
1,9.300,0.01,0.2182,0.21820,1.000
1,9.350,0.00,0.1683,0.16830,1.000
1,9.400,0.00,0.1184,0.11840,1.000
1,9.450,0.00,0.0684,0.06840,1.000
1,9.500,0.00,0.0182,0.01820,1.000
1,9.600,0.00,-0.0343,-0.03430,1.000
1,9.650,0.00,-0.0004,-0.00040,1.000
1,9.700,0.00,-0.0002,-0.00020,1.000
1,9.750,0.00,-0.0002,-0.00020,1.000
1,9.800,0.00,-0.0002,-0.00020,1.000
1,9.850,0.01,-0.0002,-0.00020,1.000
1,9.900,0.01,-0.0002,-0.00020,1.000
1,9.950,0.00,-0.0002,-0.00020,1.000
1,10.000,0.01,-0.0002,-0.00020,1.000
1,10.050,0.00,-0.0002,-0.00020,1.000
1,10.100,0.00,-0.0002,-0.00020,1.000
1,10.150,0.00,-0.0002,-0.00020,1.000
1,10.200,0.00,-0.0002,-0.00020,1.000
1,10.250,0.00,-0.0002,-0.00020,1.000
1,10.300,0.01,-0.0002,-0.00020,1.000
1,10.350,0.01,-0.0002,-0.00020,1.000
1,10.400,0.01,-0.0002,-0.00020,1.000
1,10.450,0.01,-0.0002,-0.00020,1.000
1,10.500,0.00,-0.0002,-0.00020,1.000
1,10.550,0.01,-0.0002,-0.00020,1.000
1,10.600,0.00,-0.0002,-0.00020,1.000
1,10.650,0.00,-0.0002,-0.00020,1.000
1,10.700,0.00,-0.0002,-0.00020,1.000
1,10.750,0.00,-0.0002,-0.00020,1.000
1,10.800,0.00,-0.0002,-0.00020,1.000
1,10.850,0.00,-0.0002,-0.00020,1.000
1,10.900,0.00,-0.0002,-0.00020,1.000
1,10.950,0.00,-0.0002,-0.00020,1.000
1,11.000,0.01,-0.0002,-0.00020,1.000
1,11.050,0.00,-0.0002,-0.00020,1.000
1,11.100,0.00,-0.0002,-0.00020,1.000
1,11.150,0.00,-0.0002,-0.00020,1.000
1,11.200,0.01,-0.0002,-0.00020,1.000
1,11.250,0.01,-0.0002,-0.00020,1.000
1,11.300,0.00,-0.0002,-0.00020,1.000
1,11.350,0.00,-0.0002,-0.00020,1.000
1,11.400,0.00,-0.0002,-0.00020,1.000
1,11.450,0.00,-0.0002,-0.00020,1.000
1,11.500,0.00,-0.0002,-0.00020,1.000
1,11.550,0.00,-0.0002,-0.00020,1.000
1,11.600,0.00,-0.0002,-0.00020,1.000
1,11.650,0.01,-0.0002,-0.00020,1.000
1,11.700,0.00,-0.0002,-0.00020,1.000
1,11.750,0.00,-0.0002,-0.00020,1.000
1,11.800,0.00,-0.0002,-0.00020,1.000
1,11.850,-0.01,-0.0002,-0.00020,1.000
1,11.900,0.00,-0.0002,-0.00020,1.000
1,11.950,0.00,-0.0002,-0.00020,1.000
1,12.000,0.00,-0.0001,-0.00010,1.000
1,12.050,0.00,-0.0001,-0.00010,1.000
1,12.100,0.00,-0.0001,-0.00010,1.000
1,12.150,0.00,-0.0001,-0.00010,1.000
1,12.200,0.00,-0.0001,-0.00010,1.000
1,12.250,0.00,-0.0001,-0.00010,1.000
1,12.300,0.00,-0.0001,-0.00010,1.000
1,12.350,0.00,-0.0001,-0.00010,1.000
1,12.400,0.00,-0.0001,-0.00010,1.000
1,12.450,0.01,-0.0001,-0.00010,1.000
1,12.500,0.00,-0.0001,-0.00010,1.000
1,12.550,0.00,-0.0001,-0.00010,1.000
1,12.650,0.00,-0.0001,-0.00010,1.000
1,12.700,0.00,-0.0001,-0.00010,1.000
1,12.750,0.00,-0.0001,-0.00010,1.000
1,12.800,0.00,-0.0001,-0.00010,1.000
1,12.850,0.00,-0.0001,-0.00010,1.000
1,12.900,0.01,-0.0001,-0.00010,1.000
1,12.950,0.00,-0.0001,-0.00010,1.000
1,13.000,0.00,-0.0001,-0.00010,1.000
1,13.050,0.01,-0.0001,-0.00010,1.000
1,13.100,0.01,-0.0001,-0.00010,1.000
1,13.150,0.01,-0.0001,-0.00010,1.000
1,13.200,0.00,-0.0001,-0.00010,1.000
1,13.250,0.00,-0.0001,-0.00010,1.000
1,13.300,0.00,-0.0001,-0.00010,1.000
1,13.350,0.00,-0.0001,-0.00010,1.000
1,13.400,-0.01,-0.0001,-0.00010,1.000
1,13.450,0.00,-0.0001,-0.00010,1.000
1,13.500,0.00,-0.0001,-0.00010,1.000
1,13.550,0.00,-0.0001,-0.00010,1.000
1,13.600,0.00,-0.0001,-0.00010,1.000
2,13.850,-0.01,0.0506,0.05060,2.000
2,13.900,0.00,0.1004,0.10040,2.000
2,13.950,-0.01,0.1505,0.15050,2.000
2,14.000,0.00,0.2006,0.20060,2.000
2,14.050,-0.01,0.2506,0.25060,2.000
2,14.100,-0.01,0.3006,0.30060,2.000
2,14.150,-0.01,0.3507,0.35070,2.000
2,14.200,0.00,0.4008,0.40080,2.000
2,14.250,-0.01,0.4507,0.45070,2.000
2,14.300,-0.01,0.5005,0.50050,2.000
2,14.350,0.00,0.5506,0.55060,2.000
2,14.400,-0.01,0.6007,0.60070,2.000
2,14.450,0.00,0.6505,0.65050,2.000
2,14.500,-0.01,0.7006,0.70060,2.000
2,14.550,0.00,0.7506,0.75060,2.000
2,14.600,0.00,0.8006,0.80060,2.000
2,14.650,0.00,0.8506,0.85060,2.000
2,14.700,-0.02,0.9005,0.90050,2.000
2,14.750,0.00,0.9506,0.95060,2.000
2,14.800,-0.01,1.0007,1.00070,2.000
2,14.850,-0.01,1.0507,1.05070,2.000
2,14.900,-0.01,1.1007,1.10070,2.000
2,14.950,-0.01,1.1507,1.15070,2.000
2,15.000,0.00,1.2008,1.20080,2.000
2,15.050,0.00,1.2506,1.25060,2.000
2,15.100,-0.01,1.3006,1.30060,2.000
2,15.150,0.00,1.3506,1.35060,2.000
2,15.200,0.00,1.4007,1.40070,2.000
2,15.250,0.00,1.4507,1.45070,2.000
2,15.300,0.00,1.5007,1.50070,2.000
2,15.350,0.01,1.5507,1.55070,2.000
2,15.400,0.01,1.6007,1.60070,2.000
2,15.450,0.01,1.6507,1.65070,2.000
2,15.500,0.01,1.7006,1.70060,2.000
2,15.550,0.01,1.7507,1.75070,2.000
2,15.600,0.02,1.8008,1.80080,2.000
2,15.650,0.02,1.8508,1.85080,2.000
2,15.700,0.03,1.9008,1.90080,2.000
2,15.750,0.03,1.9508,1.95080,2.000
2,15.800,0.05,2.0007,2.00070,2.000
2,15.850,0.08,2.0508,2.05080,2.000
2,15.900,0.13,2.1007,2.10070,2.000
2,15.950,0.18,2.1508,2.15080,2.000
2,16.000,0.26,2.2008,2.20080,2.000
2,16.050,0.33,2.2507,2.25070,2.000
2,16.100,0.42,2.3007,2.30070,2.000
2,16.150,0.51,2.3508,2.35080,2.000
2,16.200,0.63,2.4009,2.40090,2.000
2,16.250,0.73,2.4509,2.45090,2.000
2,16.300,0.88,2.5008,2.50080,2.000
2,16.350,1.03,2.5508,2.55080,2.000
2,16.400,1.20,2.6007,2.60070,2.000
2,16.450,1.38,2.6508,2.65080,2.000
2,16.500,1.59,2.7008,2.70080,2.000
2,16.550,1.81,2.7507,2.75070,2.000
2,16.600,2.06,2.8007,2.80070,2.000
2,16.650,2.32,2.8508,2.85080,2.000
2,16.700,2.62,2.9006,2.90060,2.000
2,16.750,2.92,2.9507,2.95070,2.000
2,16.800,3.25,3.0009,3.00090,2.000
2,16.850,3.61,3.0509,3.05090,2.000
2,16.900,3.99,3.1007,3.10070,2.000
2,16.950,4.38,3.1509,3.15090,2.000
2,17.000,4.81,3.2009,3.20090,2.000
2,17.050,5.24,3.2509,3.25090,2.000
2,17.100,5.72,3.3007,3.30070,2.000
2,17.150,6.21,3.3506,3.35060,2.000
2,17.200,6.74,3.4008,3.40080,2.000
2,17.250,7.29,3.4508,3.45080,2.000
2,17.300,7.89,3.5007,3.50070,2.000
2,17.350,8.49,3.5507,3.55070,2.000
2,17.400,9.13,3.6008,3.60080,2.000
2,17.450,9.80,3.6508,3.65080,2.000
2,17.500,10.50,3.7007,3.70070,2.000
2,17.550,11.24,3.7508,3.75080,2.000
2,17.600,12.02,3.8008,3.80080,2.000
2,17.650,12.83,3.8509,3.85090,2.000
2,17.700,13.66,3.9008,3.90080,2.000
2,17.750,14.56,3.9508,3.95080,2.000
2,17.800,15.48,4.0008,4.00080,2.000
2,17.850,16.45,4.0509,4.05090,2.000
2,17.900,17.45,4.1007,4.10070,2.000
2,17.950,18.51,4.1508,4.15080,2.000
2,18.000,19.61,4.2008,4.20080,2.000
2,18.050,20.78,4.2509,4.25090,2.000
2,18.100,21.97,4.3008,4.30080,2.000
2,18.150,23.22,4.3508,4.35080,2.000
2,18.200,24.52,4.4009,4.40090,2.000
2,18.250,25.87,4.4508,4.45080,2.000
2,18.300,27.26,4.5007,4.50070,2.000
2,18.350,28.71,4.5508,4.55080,2.000
2,18.400,30.29,4.6009,4.60090,2.000
2,18.500,31.83,4.6386,4.63860,2.000
2,18.550,29.01,4.5896,4.58960,2.000
2,18.600,26.36,4.5395,4.53950,2.000
2,18.650,24.11,4.4895,4.48950,2.000
2,18.700,22.13,4.4397,4.43970,2.000
2,18.750,20.34,4.3896,4.38960,2.000
2,18.800,18.72,4.3396,4.33960,2.000
2,18.850,17.24,4.2898,4.28980,2.000
2,18.900,15.88,4.2396,4.23960,2.000
2,18.950,14.65,4.1895,4.18950,2.000
2,19.000,13.53,4.1396,4.13960,2.000
2,19.050,12.48,4.0897,4.08970,2.000
2,19.100,11.53,4.0397,4.03970,2.000
2,19.150,10.64,3.9896,3.98960,2.000
2,19.200,9.82,3.9397,3.93970,2.000
2,19.250,9.07,3.8896,3.88960,2.000
2,19.300,8.39,3.8397,3.83970,2.000
2,19.350,7.75,3.7895,3.78950,2.000
2,19.400,7.17,3.7396,3.73960,2.000
2,19.450,6.61,3.6896,3.68960,2.000
2,19.500,6.11,3.6397,3.63970,2.000
2,19.550,5.64,3.5895,3.58950,2.000
2,19.600,5.20,3.5394,3.53940,2.000
2,19.650,4.80,3.4896,3.48960,2.000
2,19.700,4.40,3.4396,3.43960,2.000
2,19.750,4.05,3.3894,3.38940,2.000
2,19.800,3.71,3.3394,3.33940,2.000
2,19.850,3.39,3.2895,3.28950,2.000
2,19.900,3.11,3.2396,3.23960,2.000
2,19.950,2.83,3.1895,3.18950,2.000
2,20.000,2.56,3.1395,3.13950,2.000
2,20.050,2.33,3.0895,3.08950,2.000
2,20.100,2.10,3.0397,3.03970,2.000
2,20.150,1.87,2.9895,2.98950,2.000
2,20.200,1.68,2.9394,2.93940,2.000
2,20.250,1.49,2.8895,2.88950,2.000
2,20.300,1.34,2.8394,2.83940,2.000
2,20.350,1.17,2.7895,2.78950,2.000
2,20.400,1.04,2.7393,2.73930,2.000
2,20.450,0.90,2.6894,2.68940,2.000
2,20.500,0.76,2.6395,2.63950,2.000
2,20.550,0.65,2.5894,2.58940,2.000
2,20.600,0.55,2.5395,2.53950,2.000
2,20.650,0.46,2.4895,2.48950,2.000
2,20.700,0.38,2.4395,2.43950,2.000
2,20.750,0.30,2.3895,2.38950,2.000
2,20.800,0.23,2.3394,2.33940,2.000
2,20.850,0.17,2.2896,2.28960,2.000
2,20.900,0.12,2.2395,2.23950,2.000
2,20.950,0.07,2.1895,2.18950,2.000
2,21.000,0.03,2.1392,2.13920,2.000
2,21.050,0.01,2.0895,2.08950,2.000
2,21.100,-0.01,2.0394,2.03940,2.000
2,21.150,-0.01,1.9893,1.98930,2.000
2,21.200,-0.01,1.9393,1.93930,2.000
2,21.250,0.00,1.8895,1.88950,2.000
2,21.300,-0.01,1.8395,1.83950,2.000
2,21.350,0.00,1.7895,1.78950,2.000
2,21.400,0.00,1.7394,1.73940,2.000
2,21.450,-0.01,1.6894,1.68940,2.000
2,21.500,0.00,1.6394,1.63940,2.000
2,21.550,0.00,1.5894,1.58940,2.000
2,21.600,0.00,1.5393,1.53930,2.000
2,21.650,-0.01,1.4894,1.48940,2.000
2,21.700,-0.02,1.4395,1.43950,2.000
2,21.750,0.01,1.3894,1.38940,2.000
2,21.800,-0.01,1.3392,1.33920,2.000
2,21.850,-0.01,1.2893,1.28930,2.000
2,21.900,-0.01,1.2394,1.23940,2.000
2,21.950,-0.01,1.1894,1.18940,2.000
2,22.000,0.00,1.1392,1.13920,2.000
2,22.050,-0.01,1.0893,1.08930,2.000
2,22.100,-0.01,1.0394,1.03940,2.000
2,22.150,-0.01,0.9894,0.98940,2.000
2,22.200,-0.01,0.9392,0.93920,2.000
2,22.250,-0.01,0.8893,0.88930,2.000
2,22.300,-0.01,0.8393,0.83930,2.000
2,22.350,-0.01,0.7893,0.78930,2.000
2,22.400,-0.01,0.7392,0.73920,2.000
2,22.450,0.00,0.6893,0.68930,2.000
2,22.500,0.00,0.6394,0.63940,2.000
2,22.550,-0.01,0.5893,0.58930,2.000
2,22.600,0.00,0.5392,0.53920,2.000
2,22.650,0.00,0.4893,0.48930,2.000
2,22.700,-0.01,0.4394,0.43940,2.000
2,22.750,-0.01,0.3893,0.38930,2.000
2,22.800,-0.01,0.3392,0.33920,2.000
2,22.850,0.00,0.2893,0.28930,2.000
2,22.900,0.00,0.2393,0.23930,2.000
2,22.950,-0.01,0.1894,0.18940,2.000
2,23.000,-0.01,0.1392,0.13920,2.000
2,23.050,-0.01,0.0892,0.08920,2.000
2,23.100,0.00,0.0394,0.03940,2.000
2,23.200,-0.01,-0.0402,-0.04020,2.000
2,23.250,0.00,-0.0098,-0.00980,2.000
2,23.300,0.00,-0.0002,-0.00020,2.000
2,23.350,-0.01,-0.0002,-0.00020,2.000
2,23.400,-0.01,-0.0002,-0.00020,2.000
2,23.450,-0.01,-0.0002,-0.00020,2.000
2,23.500,-0.01,-0.0002,-0.00020,2.000
2,23.550,-0.01,-0.0002,-0.00020,2.000
2,23.600,0.00,-0.0002,-0.00020,2.000
2,23.650,-0.01,-0.0002,-0.00020,2.000
2,23.700,-0.01,-0.0002,-0.00020,2.000
2,23.750,-0.01,-0.0002,-0.00020,2.000
2,23.800,-0.01,-0.0002,-0.00020,2.000
2,23.850,0.00,-0.0002,-0.00020,2.000
2,23.900,0.00,-0.0002,-0.00020,2.000
2,23.950,-0.01,-0.0002,-0.00020,2.000
2,24.000,-0.01,-0.0002,-0.00020,2.000
2,24.050,-0.01,-0.0002,-0.00020,2.000
2,24.100,-0.01,-0.0002,-0.00020,2.000
2,24.150,-0.01,-0.0002,-0.00020,2.000
2,24.200,-0.01,-0.0002,-0.00020,2.000
2,24.250,-0.01,-0.0002,-0.00020,2.000
2,24.300,-0.01,-0.0002,-0.00020,2.000
2,24.350,-0.01,-0.0002,-0.00020,2.000
2,24.400,0.00,-0.0002,-0.00020,2.000
2,24.450,-0.01,-0.0002,-0.00020,2.000
2,24.500,-0.02,-0.0002,-0.00020,2.000
2,24.550,-0.02,-0.0002,-0.00020,2.000
2,24.600,-0.01,-0.0002,-0.00020,2.000
2,24.650,-0.01,-0.0002,-0.00020,2.000
2,24.700,-0.01,-0.0002,-0.00020,2.000
2,24.750,0.00,-0.0002,-0.00020,2.000
2,24.800,-0.01,-0.0002,-0.00020,2.000
2,24.850,0.00,-0.0002,-0.00020,2.000
2,24.900,-0.01,-0.0002,-0.00020,2.000
2,24.950,-0.01,-0.0002,-0.00020,2.000
2,25.000,-0.02,-0.0002,-0.00020,2.000
2,25.050,-0.01,-0.0002,-0.00020,2.000
2,25.100,-0.01,-0.0002,-0.00020,2.000
2,25.150,-0.01,-0.0002,-0.00020,2.000
2,25.200,0.00,-0.0002,-0.00020,2.000
2,25.250,-0.01,-0.0002,-0.00020,2.000
2,25.300,-0.01,-0.0002,-0.00020,2.000
2,25.350,-0.01,-0.0002,-0.00020,2.000
2,25.400,-0.01,-0.0002,-0.00020,2.000
2,25.450,-0.01,-0.0002,-0.00020,2.000
2,25.500,-0.01,-0.0002,-0.00020,2.000
2,25.550,-0.01,-0.0002,-0.00020,2.000
2,25.600,0.00,-0.0002,-0.00020,2.000
2,25.650,-0.01,-0.0002,-0.00020,2.000
2,25.700,0.00,-0.0002,-0.00020,2.000
2,25.750,0.00,-0.0002,-0.00020,2.000
2,25.800,0.00,-0.0002,-0.00020,2.000
2,25.850,-0.01,-0.0002,-0.00020,2.000
2,25.900,-0.01,-0.0002,-0.00020,2.000
2,25.950,-0.01,-0.0002,-0.00020,2.000
2,26.000,0.00,-0.0001,-0.00010,2.000
2,26.050,-0.01,-0.0001,-0.00010,2.000
2,26.100,0.00,-0.0001,-0.00010,2.000
2,26.150,-0.01,-0.0001,-0.00010,2.000
2,26.200,-0.02,-0.0001,-0.00010,2.000
2,26.250,-0.01,-0.0001,-0.00010,2.000
2,26.300,0.00,-0.0001,-0.00010,2.000
2,26.350,-0.01,-0.0001,-0.00010,2.000
2,26.400,-0.01,-0.0001,-0.00010,2.000
2,26.450,-0.01,-0.0001,-0.00010,2.000
2,26.500,-0.01,-0.0001,-0.00010,2.000
2,26.550,-0.01,-0.0001,-0.00010,2.000
2,26.600,-0.01,-0.0001,-0.00010,2.000
2,26.650,-0.01,-0.0001,-0.00010,2.000
2,26.700,0.00,-0.0001,-0.00010,2.000
2,26.750,-0.01,-0.0001,-0.00010,2.000
2,26.800,0.00,-0.0001,-0.00010,2.000
2,26.850,-0.01,-0.0001,-0.00010,2.000
2,26.900,0.00,-0.0001,-0.00010,2.000
2,26.950,-0.01,-0.0001,-0.00010,2.000
2,27.000,-0.01,-0.0001,-0.00010,2.000
2,27.050,0.00,-0.0001,-0.00010,2.000
2,27.100,-0.01,-0.0001,-0.00010,2.000
2,27.150,-0.01,-0.0001,-0.00010,2.000
2,27.200,-0.01,-0.0001,-0.00010,2.000
3,27.400,0.00,0.0202,0.02030,3.000
3,27.450,0.00,0.0706,0.07070,3.000
3,27.500,0.00,0.1207,0.12080,3.000
3,27.550,0.01,0.1705,0.17060,3.000
3,27.600,0.00,0.2205,0.22060,3.000
3,27.650,0.01,0.2706,0.27070,3.000
3,27.700,0.00,0.3207,0.32080,3.000
3,27.750,0.00,0.3706,0.37070,3.000
3,27.800,0.00,0.4206,0.42070,3.000
3,27.850,0.00,0.4708,0.47090,3.000
3,27.900,0.00,0.5206,0.52070,3.000
3,27.950,0.00,0.5705,0.57060,3.000
3,28.000,0.00,0.6205,0.62060,3.000
3,28.050,0.00,0.6706,0.67070,3.000
3,28.100,0.00,0.7207,0.72080,3.000
3,28.150,0.00,0.7707,0.77080,3.000
3,28.200,0.00,0.8206,0.82070,3.000
3,28.250,0.00,0.8707,0.87080,3.000
3,28.300,0.00,0.9208,0.92090,3.000
3,28.350,0.00,0.9706,0.97070,3.000
3,28.400,0.00,1.0206,1.02070,3.000
3,28.450,0.00,1.0708,1.07090,3.000
3,28.500,0.00,1.1207,1.12080,3.000
3,28.550,0.00,1.1706,1.17070,3.000
3,28.600,0.00,1.2206,1.22070,3.000
3,28.650,0.00,1.2707,1.27080,3.000
3,28.700,0.00,1.3208,1.32090,3.000
3,28.750,0.00,1.3706,1.37070,3.000
3,28.800,0.00,1.4206,1.42070,3.000
3,28.850,0.01,1.4706,1.47070,3.000
3,28.900,0.01,1.5208,1.52090,3.000
3,28.950,0.01,1.5707,1.57080,3.000
3,29.000,0.01,1.6206,1.62070,3.000
3,29.050,0.01,1.6706,1.67070,3.000
3,29.100,0.02,1.7208,1.72090,3.000
3,29.150,0.02,1.7708,1.77090,3.000
3,29.200,0.02,1.8207,1.82080,3.000
3,29.250,0.03,1.8707,1.87080,3.000
3,29.300,0.04,1.9208,1.92090,3.000
3,29.350,0.04,1.9708,1.97090,3.000
3,29.400,0.06,2.0206,2.02070,3.000
3,29.450,0.09,2.0707,2.07080,3.000
3,29.500,0.14,2.1208,2.12090,3.000
3,29.550,0.21,2.1708,2.17090,3.000
3,29.600,0.28,2.2206,2.22070,3.000
3,29.650,0.37,2.2708,2.27090,3.000
3,29.700,0.45,2.3209,2.32100,3.000
3,29.750,0.55,2.3708,2.37090,3.000
3,29.800,0.66,2.4207,2.42080,3.000
3,29.850,0.78,2.4709,2.47100,3.000
3,29.900,0.92,2.5208,2.52090,3.000
3,29.950,1.08,2.5708,2.57090,3.000
3,30.000,1.26,2.6207,2.62080,3.000
3,30.050,1.44,2.6706,2.67070,3.000
3,30.100,1.65,2.7207,2.72080,3.000
3,30.150,1.89,2.7707,2.77080,3.000
3,30.200,2.15,2.8206,2.82070,3.000
3,30.250,2.42,2.8707,2.87080,3.000
3,30.300,2.72,2.9208,2.92090,3.000
3,30.350,3.02,2.9707,2.97080,3.000
3,30.400,3.37,3.0207,3.02080,3.000
3,30.450,3.72,3.0708,3.07090,3.000
3,30.500,4.10,3.1208,3.12090,3.000
3,30.550,4.52,3.1710,3.17110,3.000
3,30.600,4.95,3.2207,3.22080,3.000
3,30.650,5.40,3.2707,3.27080,3.000
3,30.700,5.87,3.3208,3.32090,3.000
3,30.750,6.38,3.3708,3.37090,3.000
3,30.800,6.92,3.4206,3.42070,3.000
3,30.850,7.47,3.4706,3.47070,3.000
3,30.900,8.06,3.5207,3.52080,3.000
3,30.950,8.67,3.5707,3.57080,3.000
3,31.000,9.32,3.6207,3.62080,3.000
3,31.050,10.00,3.6707,3.67080,3.000
3,31.100,10.71,3.7209,3.72100,3.000
3,31.150,11.46,3.7708,3.77090,3.000
3,31.200,12.25,3.8207,3.82080,3.000
3,31.250,13.07,3.8707,3.87080,3.000
3,31.300,13.93,3.9209,3.92100,3.000
3,31.350,14.82,3.9710,3.97110,3.000
3,31.400,15.75,4.0207,4.02080,3.000
3,31.450,16.72,4.0708,4.07090,3.000
3,31.500,17.73,4.1208,4.12090,3.000
3,31.550,18.80,4.1708,4.17090,3.000
3,31.600,19.91,4.2207,4.22080,3.000
3,31.650,21.07,4.2708,4.27090,3.000
3,31.700,22.27,4.3209,4.32100,3.000
3,31.750,23.53,4.3710,4.37110,3.000
3,31.800,24.84,4.4206,4.42070,3.000
3,31.850,26.21,4.4707,4.47080,3.000
3,31.900,27.61,4.5207,4.52080,3.000
3,31.950,29.11,4.5709,4.57100,3.000
3,32.050,31.74,4.6388,4.63890,3.000
3,32.100,29.69,4.5997,4.59980,3.000
3,32.150,26.85,4.5494,4.54950,3.000
3,32.200,24.52,4.4995,4.49960,3.000
3,32.250,22.46,4.4496,4.44970,3.000
3,32.300,20.64,4.3997,4.39980,3.000
3,32.350,18.99,4.3495,4.34960,3.000
3,32.400,17.49,4.2997,4.29980,3.000
3,32.450,16.09,4.2496,4.24970,3.000
3,32.500,14.84,4.1997,4.19980,3.000
3,32.550,13.69,4.1495,4.14960,3.000
3,32.600,12.63,4.0995,4.09960,3.000
3,32.650,11.66,4.0496,4.04970,3.000
3,32.700,10.77,3.9997,3.99980,3.000
3,32.750,9.94,3.9495,3.94960,3.000
3,32.800,9.18,3.8995,3.89960,3.000
3,32.850,8.48,3.8496,3.84970,3.000
3,32.900,7.83,3.7997,3.79980,3.000
3,32.950,7.25,3.7496,3.74970,3.000
3,33.000,6.69,3.6995,3.69960,3.000
3,33.050,6.18,3.6496,3.64970,3.000
3,33.100,5.70,3.5996,3.59970,3.000
3,33.150,5.26,3.5494,3.54950,3.000
3,33.200,4.85,3.4994,3.49950,3.000
3,33.250,4.46,3.4496,3.44970,3.000
3,33.300,4.09,3.3995,3.39960,3.000
3,33.350,3.75,3.3493,3.34940,3.000
3,33.400,3.44,3.2994,3.29950,3.000
3,33.450,3.14,3.2495,3.24960,3.000
3,33.500,2.86,3.1997,3.19980,3.000
3,33.550,2.61,3.1495,3.14960,3.000
3,33.600,2.36,3.0996,3.09970,3.000
3,33.650,2.13,3.0497,3.04980,3.000
3,33.700,1.91,2.9996,2.99970,3.000
3,33.750,1.70,2.9494,2.94950,3.000
3,33.800,1.54,2.8994,2.89950,3.000
3,33.850,1.35,2.8494,2.84950,3.000
3,33.900,1.20,2.7995,2.79960,3.000
3,33.950,1.05,2.7494,2.74950,3.000
3,34.000,0.91,2.6992,2.69930,3.000
3,34.050,0.80,2.6495,2.64960,3.000
3,34.100,0.67,2.5995,2.59960,3.000
3,34.150,0.57,2.5493,2.54940,3.000
3,34.200,0.48,2.4994,2.49950,3.000
3,34.250,0.39,2.4496,2.44970,3.000
3,34.300,0.32,2.3996,2.39970,3.000
3,34.350,0.25,2.3494,2.34950,3.000
3,34.400,0.19,2.2994,2.29950,3.000
3,34.450,0.13,2.2495,2.24960,3.000
3,34.500,0.08,2.1995,2.19960,3.000
3,34.550,0.05,2.1494,2.14950,3.000
3,34.600,0.02,2.0993,2.09940,3.000
3,34.650,-0.01,2.0493,2.04940,3.000
3,34.700,-0.01,1.9995,1.99960,3.000
3,34.750,-0.01,1.9493,1.94940,3.000
3,34.800,0.01,1.8994,1.89950,3.000
3,34.850,0.00,1.8495,1.84960,3.000
3,34.900,0.01,1.7995,1.79960,3.000
3,34.950,0.00,1.7495,1.74960,3.000
3,35.000,0.00,1.6992,1.69930,3.000
3,35.050,0.00,1.6494,1.64950,3.000
3,35.100,0.00,1.5995,1.59960,3.000
3,35.150,0.00,1.5493,1.54940,3.000
3,35.200,0.00,1.4993,1.49940,3.000
3,35.250,0.00,1.4494,1.44950,3.000
3,35.300,-0.01,1.3993,1.39940,3.000
3,35.350,0.00,1.3493,1.34940,3.000
3,35.400,0.00,1.2992,1.29930,3.000
3,35.450,0.00,1.2493,1.24940,3.000
3,35.500,0.00,1.1993,1.19940,3.000
3,35.550,0.00,1.1494,1.14950,3.000
3,35.600,0.00,1.0992,1.09930,3.000
3,35.650,0.00,1.0494,1.04950,3.000
3,35.700,0.01,0.9994,0.99950,3.000
3,35.750,0.00,0.9494,0.94950,3.000
3,35.800,0.00,0.8993,0.89940,3.000
3,35.850,0.00,0.8493,0.84940,3.000
3,35.900,0.00,0.7995,0.79960,3.000
3,35.950,0.00,0.7494,0.74950,3.000
3,36.000,0.00,0.6992,0.69930,3.000
3,36.050,0.00,0.6492,0.64930,3.000
3,36.100,0.00,0.5992,0.59930,3.000
3,36.150,0.00,0.5494,0.54950,3.000
3,36.200,0.01,0.4992,0.49930,3.000
3,36.250,0.00,0.4494,0.44950,3.000
3,36.300,0.00,0.3995,0.39960,3.000
3,36.350,0.01,0.3494,0.34950,3.000
3,36.400,0.01,0.2991,0.29920,3.000
3,36.450,0.01,0.2493,0.24940,3.000
3,36.500,0.00,0.1994,0.19950,3.000
3,36.550,0.00,0.1494,0.14950,3.000
3,36.600,0.00,0.0991,0.09920,3.000
3,36.650,0.00,0.0493,0.04940,3.000
3,36.700,0.01,-0.0008,-0.00070,3.000
3,36.800,0.00,-0.0384,-0.03830,3.000
3,36.850,0.00,-0.0003,-0.00020,3.000
3,36.900,0.00,-0.0001,0.00000,3.000
3,36.950,0.00,-0.0002,-0.00010,3.000
3,37.000,0.00,-0.0002,-0.00010,3.000
3,37.050,0.00,-0.0002,-0.00010,3.000
3,37.100,0.00,-0.0002,-0.00010,3.000
3,37.150,0.00,-0.0002,-0.00010,3.000
3,37.200,0.01,-0.0002,-0.00010,3.000
3,37.250,0.00,-0.0002,-0.00010,3.000
3,37.300,0.00,-0.0002,-0.00010,3.000
3,37.350,0.01,-0.0002,-0.00010,3.000
3,37.400,0.00,-0.0002,-0.00010,3.000
3,37.450,0.00,-0.0002,-0.00010,3.000
3,37.500,0.00,-0.0002,-0.00010,3.000
3,37.550,0.01,-0.0002,-0.00010,3.000
3,37.600,0.00,-0.0002,-0.00010,3.000
3,37.650,0.00,-0.0002,-0.00010,3.000
3,37.700,0.00,-0.0002,-0.00010,3.000
3,37.750,0.00,-0.0002,-0.00010,3.000
3,37.800,0.01,-0.0002,-0.00010,3.000
3,37.850,0.00,-0.0002,-0.00010,3.000
3,37.900,0.00,-0.0002,-0.00010,3.000
3,37.950,0.00,-0.0002,-0.00010,3.000
3,38.000,0.00,-0.0002,-0.00010,3.000
3,38.050,0.00,-0.0002,-0.00010,3.000
3,38.100,0.01,-0.0002,-0.00010,3.000
3,38.150,0.00,-0.0002,-0.00010,3.000
3,38.200,0.01,-0.0002,-0.00010,3.000
3,38.250,0.00,-0.0002,-0.00010,3.000
3,38.300,0.01,-0.0002,-0.00010,3.000
3,38.350,0.00,-0.0002,-0.00010,3.000
3,38.400,0.00,-0.0002,-0.00010,3.000
3,38.450,0.00,-0.0002,-0.00010,3.000
3,38.500,0.00,-0.0002,-0.00010,3.000
3,38.550,0.00,-0.0002,-0.00010,3.000
3,38.600,0.00,-0.0002,-0.00010,3.000
3,38.650,0.01,-0.0002,-0.00010,3.000
3,38.700,0.00,-0.0002,-0.00010,3.000
3,38.750,0.01,-0.0002,-0.00010,3.000
3,38.800,0.00,-0.0002,-0.00010,3.000
3,38.850,0.00,-0.0002,-0.00010,3.000
3,38.900,0.00,-0.0002,-0.00010,3.000
3,38.950,0.00,-0.0002,-0.00010,3.000
3,39.000,0.00,-0.0002,-0.00010,3.000
3,39.050,0.00,-0.0002,-0.00010,3.000
3,39.100,0.00,-0.0002,-0.00010,3.000
3,39.150,0.00,-0.0002,-0.00010,3.000
3,39.200,0.01,-0.0002,-0.00010,3.000
3,39.250,0.00,-0.0001,0.00000,3.000
3,39.300,0.01,-0.0001,0.00000,3.000
3,39.350,0.00,-0.0001,0.00000,3.000
3,39.400,0.00,-0.0001,0.00000,3.000
3,39.450,0.00,-0.0001,0.00000,3.000
3,39.500,0.01,-0.0001,0.00000,3.000
3,39.550,0.00,-0.0001,0.00000,3.000
3,39.600,0.00,-0.0001,0.00000,3.000
3,39.650,0.00,-0.0001,0.00000,3.000
3,39.700,0.00,-0.0001,0.00000,3.000
3,39.750,0.01,-0.0001,0.00000,3.000
3,39.850,-0.01,-0.0001,0.00000,3.000
3,39.900,0.00,-0.0001,0.00000,3.000
3,39.950,0.00,-0.0001,0.00000,3.000
3,40.000,0.00,-0.0001,0.00000,3.000
3,40.050,0.01,-0.0001,0.00000,3.000
3,40.100,0.00,-0.0001,0.00000,3.000
3,40.150,0.00,-0.0001,0.00000,3.000
3,40.200,0.00,-0.0001,0.00000,3.000
3,40.250,0.00,-0.0001,0.00000,3.000
3,40.300,0.01,-0.0001,0.00000,3.000
3,40.350,0.00,-0.0001,0.00000,3.000
3,40.400,0.00,-0.0001,0.00000,3.000
3,40.450,0.00,-0.0001,0.00000,3.000
3,40.500,0.00,-0.0001,0.00000,3.000
3,40.550,0.00,-0.0001,0.00000,3.000
3,40.600,0.00,-0.0001,0.00000,3.000
3,40.650,0.01,-0.0001,0.00000,3.000
3,40.700,0.00,-0.0001,0.00000,3.000
3,40.750,0.00,-0.0001,0.00000,3.000
3,40.800,0.01,-0.0001,0.00000,3.000
4,41.000,0.00,0.0298,0.02990,4.000
4,41.050,0.00,0.0796,0.07970,4.000
4,41.100,0.00,0.1295,0.12960,4.000
4,41.150,0.00,0.1795,0.17960,4.000
4,41.200,0.00,0.2295,0.22960,4.000
4,41.250,0.00,0.2798,0.27990,4.000
4,41.300,0.00,0.3295,0.32960,4.000
4,41.350,0.00,0.3797,0.37980,4.000
4,41.400,0.01,0.4297,0.42980,4.000
4,41.450,0.00,0.4798,0.47990,4.000
4,41.500,0.00,0.5295,0.52960,4.000
4,41.550,0.00,0.5794,0.57950,4.000
4,41.600,0.00,0.6295,0.62960,4.000
4,41.650,0.00,0.6797,0.67980,4.000
4,41.700,0.00,0.7297,0.72980,4.000
4,41.750,0.00,0.7796,0.77970,4.000
4,41.800,0.00,0.8296,0.82970,4.000
4,41.850,0.00,0.8797,0.87980,4.000
4,41.900,0.00,0.9296,0.92970,4.000
4,41.950,0.00,0.9795,0.97960,4.000
4,42.000,0.00,1.0297,1.02980,4.000
4,42.050,0.00,1.0798,1.07990,4.000
4,42.100,0.00,1.1296,1.12970,4.000
4,42.150,0.01,1.1795,1.17960,4.000
4,42.200,0.00,1.2296,1.22970,4.000
4,42.250,0.00,1.2797,1.27980,4.000
4,42.300,0.00,1.3297,1.32980,4.000
4,42.350,0.00,1.3795,1.37960,4.000
4,42.400,0.01,1.4297,1.42980,4.000
4,42.450,0.01,1.4798,1.47990,4.000
4,42.500,0.01,1.5297,1.52980,4.000
4,42.550,0.01,1.5796,1.57970,4.000
4,42.600,0.02,1.6296,1.62970,4.000
4,42.650,0.01,1.6798,1.67990,4.000
4,42.700,0.01,1.7297,1.72980,4.000
4,42.750,0.02,1.7797,1.77980,4.000
4,42.800,0.03,1.8297,1.82980,4.000
4,42.850,0.02,1.8799,1.88000,4.000
4,42.900,0.03,1.9298,1.92990,4.000
4,42.950,0.04,1.9796,1.97970,4.000
4,43.000,0.05,2.0297,2.02980,4.000
4,43.050,0.10,2.0797,2.07980,4.000
4,43.100,0.15,2.1298,2.12990,4.000
4,43.150,0.21,2.1796,2.17970,4.000
4,43.200,0.28,2.2297,2.22980,4.000
4,43.250,0.37,2.2797,2.27980,4.000
4,43.300,0.46,2.3298,2.32990,4.000
4,43.350,0.56,2.3797,2.37980,4.000
4,43.400,0.67,2.4298,2.42990,4.000
4,43.450,0.79,2.4799,2.48000,4.000
4,43.500,0.94,2.5298,2.52990,4.000
4,43.550,1.09,2.5797,2.57980,4.000
4,43.600,1.27,2.6297,2.62980,4.000
4,43.650,1.46,2.6798,2.67990,4.000
4,43.700,1.68,2.7298,2.72990,4.000
4,43.750,1.92,2.7796,2.77970,4.000
4,43.800,2.17,2.8298,2.82990,4.000
4,43.850,2.45,2.8798,2.87990,4.000
4,43.900,2.75,2.9298,2.92990,4.000
4,43.950,3.06,2.9797,2.97980,4.000
4,44.000,3.41,3.0298,3.02990,4.000
4,44.050,3.77,3.0799,3.08000,4.000
4,44.100,4.15,3.1299,3.13000,4.000
4,44.150,4.57,3.1797,3.17980,4.000
4,44.200,5.00,3.2297,3.22980,4.000
4,44.250,5.45,3.2797,3.27980,4.000
4,44.300,5.93,3.3298,3.32990,4.000
4,44.350,6.45,3.3797,3.37980,4.000
4,44.400,6.98,3.4297,3.42980,4.000
4,44.450,7.55,3.4798,3.47990,4.000
4,44.500,8.15,3.5297,3.52980,4.000
4,44.550,8.78,3.5797,3.57980,4.000
4,44.600,9.42,3.6297,3.62980,4.000
4,44.650,10.10,3.6798,3.67990,4.000
4,44.700,10.82,3.7298,3.72990,4.000
4,44.750,11.58,3.7797,3.77980,4.000
4,44.800,12.36,3.8297,3.82980,4.000
4,44.850,13.20,3.8798,3.87990,4.000
4,44.900,14.05,3.9300,3.93010,4.000
4,44.950,14.94,3.9798,3.97990,4.000
4,45.000,15.87,4.0298,4.02990,4.000
4,45.050,16.85,4.0798,4.07990,4.000
4,45.100,17.86,4.1299,4.13000,4.000
4,45.150,18.93,4.1797,4.17980,4.000
4,45.200,20.04,4.2298,4.22990,4.000
4,45.250,21.19,4.2798,4.27990,4.000
4,45.300,22.41,4.3300,4.33010,4.000
4,45.350,23.67,4.3797,4.37980,4.000
4,45.400,24.99,4.4298,4.42990,4.000
4,45.450,26.35,4.4798,4.47990,4.000
4,45.500,27.77,4.5298,4.52990,4.000
4,45.550,29.29,4.5797,4.57980,4.000
4,45.650,31.97,4.6478,4.64790,4.000
4,45.700,29.88,4.6087,4.60880,4.000
4,45.750,27.01,4.5585,4.55860,4.000
4,45.800,24.67,4.5085,4.50860,4.000
4,45.850,22.60,4.4586,4.45870,4.000
4,45.900,20.74,4.4087,4.40880,4.000
4,45.950,19.09,4.3586,4.35870,4.000
4,46.000,17.56,4.3085,4.30860,4.000
4,46.050,16.18,4.2586,4.25870,4.000
4,46.100,14.90,4.2086,4.20870,4.000
4,46.150,13.75,4.1586,4.15870,4.000
4,46.200,12.70,4.1085,4.10860,4.000
4,46.250,11.73,4.0586,4.05870,4.000
4,46.300,10.83,4.0087,4.00880,4.000
4,46.350,10.00,3.9587,3.95880,4.000
4,46.400,9.23,3.9085,3.90860,4.000
4,46.450,8.53,3.8586,3.85870,4.000
4,46.500,7.88,3.8087,3.80880,4.000
4,46.550,7.29,3.7587,3.75880,4.000
4,46.600,6.73,3.7086,3.70870,4.000
4,46.650,6.21,3.6586,3.65870,4.000
4,46.700,5.74,3.6085,3.60860,4.000
4,46.750,5.29,3.5586,3.55870,4.000
4,46.800,4.87,3.5084,3.50850,4.000
4,46.850,4.48,3.4584,3.45850,4.000
4,46.900,4.12,3.4085,3.40860,4.000
4,46.950,3.78,3.3585,3.35860,4.000
4,47.000,3.46,3.3083,3.30840,4.000
4,47.050,3.16,3.2584,3.25850,4.000
4,47.100,2.88,3.2086,3.20870,4.000
4,47.150,2.62,3.1586,3.15870,4.000
4,47.200,2.38,3.1086,3.10870,4.000
4,47.250,2.14,3.0585,3.05860,4.000
4,47.300,1.92,3.0086,3.00870,4.000
4,47.350,1.72,2.9585,2.95860,4.000
4,47.400,1.54,2.9084,2.90850,4.000
4,47.450,1.37,2.8584,2.85850,4.000
4,47.500,1.21,2.8084,2.80850,4.000
4,47.550,1.06,2.7585,2.75860,4.000
4,47.600,0.92,2.7083,2.70840,4.000
4,47.650,0.80,2.6584,2.65850,4.000
4,47.700,0.67,2.6085,2.60860,4.000
4,47.750,0.57,2.5585,2.55860,4.000
4,47.800,0.48,2.5084,2.50850,4.000
4,47.850,0.39,2.4584,2.45850,4.000
4,47.900,0.32,2.4086,2.40870,4.000
4,47.950,0.24,2.3585,2.35860,4.000
4,48.000,0.19,2.3084,2.30850,4.000
4,48.050,0.13,2.2583,2.25840,4.000
4,48.100,0.09,2.2085,2.20860,4.000
4,48.150,0.04,2.1585,2.15860,4.000
4,48.200,0.02,2.1083,2.10840,4.000
4,48.250,0.00,2.0582,2.05830,4.000
4,48.300,-0.02,2.0083,2.00840,4.000
4,48.350,-0.01,1.9585,1.95860,4.000
4,48.400,0.00,1.9084,1.90850,4.000
4,48.450,0.00,1.8584,1.85850,4.000
4,48.500,0.00,1.8085,1.80860,4.000
4,48.550,0.00,1.7585,1.75860,4.000
4,48.600,0.00,1.7083,1.70840,4.000
4,48.650,0.00,1.6583,1.65840,4.000
4,48.700,0.00,1.6083,1.60840,4.000
4,48.750,0.00,1.5584,1.55850,4.000
4,48.800,0.00,1.5083,1.50840,4.000
4,48.850,0.00,1.4582,1.45830,4.000
4,48.900,0.00,1.4083,1.40840,4.000
4,48.950,0.00,1.3584,1.35850,4.000
4,49.000,0.00,1.3082,1.30830,4.000
4,49.050,0.00,1.2582,1.25830,4.000
4,49.100,0.00,1.2084,1.20850,4.000
4,49.150,0.00,1.1583,1.15840,4.000
4,49.200,0.00,1.1084,1.10850,4.000
4,49.250,0.00,1.0582,1.05830,4.000
4,49.300,0.00,1.0083,1.00840,4.000
4,49.350,0.00,0.9585,0.95860,4.000
4,49.400,0.00,0.9083,0.90840,4.000
4,49.450,0.00,0.8582,0.85830,4.000
4,49.500,0.00,0.8082,0.80830,4.000
4,49.550,0.00,0.7584,0.75850,4.000
4,49.600,0.00,0.7084,0.70850,4.000
4,49.650,0.00,0.6581,0.65820,4.000
4,49.700,0.00,0.6083,0.60840,4.000
4,49.750,0.00,0.5583,0.55840,4.000
4,49.800,0.00,0.5083,0.50840,4.000
4,49.850,0.00,0.4583,0.45840,4.000
4,49.900,0.00,0.4084,0.40850,4.000
4,49.950,0.00,0.3585,0.35860,4.000
4,50.000,0.00,0.3083,0.30840,4.000
4,50.050,0.00,0.2581,0.25820,4.000
4,50.100,0.00,0.2082,0.20830,4.000
4,50.150,0.00,0.1585,0.15860,4.000
4,50.200,0.00,0.1083,0.10840,4.000
4,50.250,0.00,0.0582,0.05830,4.000
4,50.300,0.00,0.0083,0.00840,4.000
4,50.400,0.00,-0.0459,-0.04580,4.000
4,50.450,0.00,-0.0045,-0.00440,4.000
4,50.500,0.00,-0.0003,-0.00020,4.000
4,50.550,0.00,-0.0002,-0.00010,4.000
4,50.600,0.00,-0.0002,-0.00010,4.000
4,50.650,0.00,-0.0002,-0.00010,4.000
4,50.700,0.00,-0.0002,-0.00010,4.000
4,50.750,-0.01,-0.0002,-0.00010,4.000
4,50.800,-0.01,-0.0002,-0.00010,4.000
4,50.850,0.00,-0.0002,-0.00010,4.000
4,50.900,-0.01,-0.0002,-0.00010,4.000
4,50.950,0.00,-0.0002,-0.00010,4.000
4,51.000,0.00,-0.0002,-0.00010,4.000
4,51.050,0.00,-0.0002,-0.00010,4.000
4,51.100,0.00,-0.0002,-0.00010,4.000
4,51.150,0.00,-0.0002,-0.00010,4.000
4,51.200,0.00,-0.0002,-0.00010,4.000
4,51.250,-0.01,-0.0002,-0.00010,4.000
4,51.300,0.00,-0.0002,-0.00010,4.000
4,51.350,0.00,-0.0002,-0.00010,4.000
4,51.400,0.00,-0.0002,-0.00010,4.000
4,51.450,0.00,-0.0002,-0.00010,4.000
4,51.500,-0.01,-0.0002,-0.00010,4.000
4,51.550,-0.01,-0.0002,-0.00010,4.000
4,51.600,0.00,-0.0002,-0.00010,4.000
4,51.650,0.00,-0.0002,-0.00010,4.000
4,51.700,0.00,-0.0002,-0.00010,4.000
4,51.750,-0.01,-0.0002,-0.00010,4.000
4,51.800,-0.01,-0.0002,-0.00010,4.000
4,51.850,0.00,-0.0002,-0.00010,4.000
4,51.900,0.00,-0.0002,-0.00010,4.000
4,51.950,0.00,-0.0002,-0.00010,4.000
4,52.000,0.00,-0.0002,-0.00010,4.000
4,52.050,-0.01,-0.0002,-0.00010,4.000
4,52.100,0.00,-0.0002,-0.00010,4.000
4,52.150,0.00,-0.0002,-0.00010,4.000
4,52.200,0.00,-0.0002,-0.00010,4.000
4,52.250,0.00,-0.0002,-0.00010,4.000
4,52.300,0.00,-0.0002,-0.00010,4.000
4,52.350,0.00,-0.0002,-0.00010,4.000
4,52.400,0.00,-0.0002,-0.00010,4.000
4,52.450,0.00,-0.0002,-0.00010,4.000
4,52.500,-0.01,-0.0002,-0.00010,4.000
4,52.550,0.00,-0.0002,-0.00010,4.000
4,52.600,0.00,-0.0002,-0.00010,4.000
4,52.650,0.00,-0.0002,-0.00010,4.000
4,52.700,0.00,-0.0002,-0.00010,4.000
4,52.750,0.00,-0.0002,-0.00010,4.000
4,52.800,0.00,-0.0002,-0.00010,4.000
4,52.850,0.00,-0.0002,-0.00010,4.000
4,52.900,0.00,-0.0002,-0.00010,4.000
4,52.950,0.00,-0.0002,-0.00010,4.000
4,53.000,0.00,-0.0002,-0.00010,4.000
4,53.050,0.00,-0.0002,-0.00010,4.000
4,53.100,0.00,-0.0002,-0.00010,4.000
4,53.150,0.00,-0.0002,-0.00010,4.000
4,53.200,0.00,-0.0002,-0.00010,4.000
4,53.250,0.00,-0.0002,-0.00010,4.000
4,53.300,0.00,-0.0002,-0.00010,4.000
4,53.350,0.00,-0.0002,-0.00010,4.000
4,53.450,0.00,-0.0002,-0.00010,4.000
4,53.500,0.00,-0.0001,0.00000,4.000
4,53.550,0.00,-0.0001,0.00000,4.000
4,53.600,0.00,-0.0001,0.00000,4.000
4,53.650,0.00,-0.0001,0.00000,4.000
4,53.700,0.00,-0.0001,0.00000,4.000
4,53.750,0.00,-0.0001,0.00000,4.000
4,53.800,0.00,-0.0001,0.00000,4.000
4,53.850,0.00,-0.0001,0.00000,4.000
4,53.900,0.00,-0.0001,0.00000,4.000
4,53.950,0.00,-0.0001,0.00000,4.000
4,54.000,0.00,-0.0001,0.00000,4.000
4,54.050,0.00,-0.0001,0.00000,4.000
4,54.100,-0.01,-0.0001,0.00000,4.000
4,54.150,0.00,-0.0001,0.00000,4.000
4,54.200,0.00,-0.0001,0.00000,4.000
4,54.250,0.00,-0.0001,0.00000,4.000
4,54.300,0.00,-0.0001,0.00000,4.000
4,54.350,0.00,-0.0001,0.00000,4.000
4,54.400,0.00,-0.0001,0.00000,4.000
5,54.600,0.01,0.0298,0.02980,5.000
5,54.650,0.01,0.0795,0.07950,5.000
5,54.700,0.00,0.1295,0.12950,5.000
5,54.750,0.00,0.1795,0.17950,5.000
5,54.800,0.00,0.2295,0.22950,5.000
5,54.850,0.00,0.2797,0.27970,5.000
5,54.900,0.00,0.3297,0.32970,5.000
5,54.950,0.00,0.3796,0.37960,5.000
5,55.000,0.00,0.4297,0.42970,5.000
5,55.050,0.00,0.4798,0.47980,5.000
5,55.100,0.00,0.5296,0.52960,5.000
5,55.150,0.00,0.5795,0.57950,5.000
5,55.200,0.00,0.6295,0.62950,5.000
5,55.250,0.00,0.6796,0.67960,5.000
5,55.300,0.00,0.7297,0.72970,5.000
5,55.350,0.00,0.7795,0.77950,5.000
5,55.400,0.00,0.8297,0.82970,5.000
5,55.450,0.01,0.8798,0.87980,5.000
5,55.500,0.00,0.9296,0.92960,5.000
5,55.550,0.00,0.9795,0.97950,5.000
5,55.600,0.00,1.0297,1.02970,5.000
5,55.650,0.00,1.0798,1.07980,5.000
5,55.700,0.00,1.1296,1.12960,5.000
5,55.750,0.00,1.1796,1.17960,5.000
5,55.800,0.00,1.2295,1.22950,5.000
5,55.850,0.00,1.2796,1.27960,5.000
5,55.900,0.00,1.3297,1.32970,5.000
5,55.950,0.00,1.3795,1.37950,5.000
5,56.000,0.01,1.4296,1.42960,5.000
5,56.050,0.01,1.4797,1.47970,5.000
5,56.100,0.01,1.5297,1.52970,5.000
5,56.150,0.01,1.5796,1.57960,5.000
5,56.200,0.02,1.6297,1.62970,5.000
5,56.250,0.02,1.6797,1.67970,5.000
5,56.300,0.02,1.7298,1.72980,5.000
5,56.350,0.02,1.7797,1.77970,5.000
5,56.400,0.02,1.8298,1.82980,5.000
5,56.450,0.03,1.8798,1.87980,5.000
5,56.500,0.04,1.9298,1.92980,5.000
5,56.550,0.05,1.9796,1.97960,5.000
5,56.600,0.07,2.0296,2.02960,5.000
5,56.650,0.09,2.0797,2.07970,5.000
5,56.700,0.16,2.1299,2.12990,5.000
5,56.750,0.21,2.1797,2.17970,5.000
5,56.800,0.28,2.2297,2.22970,5.000
5,56.850,0.36,2.2798,2.27980,5.000
5,56.900,0.45,2.3298,2.32980,5.000
5,56.950,0.55,2.3797,2.37970,5.000
5,57.000,0.66,2.4297,2.42970,5.000
5,57.050,0.79,2.4798,2.47980,5.000
5,57.100,0.92,2.5299,2.52990,5.000
5,57.150,1.09,2.5797,2.57970,5.000
5,57.200,1.26,2.6297,2.62970,5.000
5,57.250,1.45,2.6798,2.67980,5.000
5,57.300,1.66,2.7298,2.72980,5.000
5,57.350,1.89,2.7796,2.77960,5.000
5,57.400,2.14,2.8297,2.82970,5.000
5,57.450,2.42,2.8797,2.87970,5.000
5,57.500,2.71,2.9297,2.92970,5.000
5,57.550,3.03,2.9797,2.97970,5.000
5,57.600,3.37,3.0297,3.02970,5.000
5,57.650,3.73,3.0799,3.07990,5.000
5,57.700,4.12,3.1300,3.13000,5.000
5,57.750,4.53,3.1797,3.17970,5.000
5,57.800,4.96,3.2298,3.22980,5.000
5,57.850,5.42,3.2797,3.27970,5.000
5,57.900,5.90,3.3298,3.32980,5.000
5,57.950,6.41,3.3796,3.37960,5.000
5,58.000,6.94,3.4298,3.42980,5.000
5,58.050,7.50,3.4797,3.47970,5.000
5,58.100,8.10,3.5299,3.52990,5.000
5,58.150,8.72,3.5796,3.57960,5.000
5,58.200,9.37,3.6297,3.62970,5.000
5,58.250,10.05,3.6798,3.67980,5.000
5,58.300,10.77,3.7299,3.72990,5.000
5,58.350,11.51,3.7797,3.77970,5.000
5,58.400,12.30,3.8297,3.82970,5.000
5,58.450,13.11,3.8798,3.87980,5.000
5,58.500,13.97,3.9300,3.93000,5.000
5,58.550,14.87,3.9797,3.97970,5.000
5,58.600,15.80,4.0298,4.02980,5.000
5,58.650,16.75,4.0797,4.07970,5.000
5,58.700,17.76,4.1298,4.12980,5.000
5,58.750,18.82,4.1797,4.17970,5.000
5,58.800,19.93,4.2298,4.22980,5.000
5,58.850,21.07,4.2798,4.27980,5.000
5,58.900,22.28,4.3300,4.33000,5.000
5,58.950,23.53,4.3798,4.37980,5.000
5,59.000,24.84,4.4297,4.42970,5.000
5,59.050,26.20,4.4798,4.47980,5.000
5,59.100,27.62,4.5299,4.52990,5.000
5,59.150,29.13,4.5797,4.57970,5.000
5,59.250,31.73,4.6465,4.64650,5.000
5,59.300,29.59,4.6067,4.60670,5.000
5,59.350,26.76,4.5565,4.55650,5.000
5,59.400,24.45,4.5065,4.50650,5.000
5,59.450,22.40,4.4566,4.45660,5.000
5,59.500,20.56,4.4066,4.40660,5.000
5,59.550,18.92,4.3566,4.35660,5.000
5,59.600,17.41,4.3066,4.30660,5.000
5,59.650,16.04,4.2566,4.25660,5.000
5,59.700,14.78,4.2066,4.20660,5.000
5,59.750,13.64,4.1565,4.15650,5.000
5,59.800,12.59,4.1065,4.10650,5.000
5,59.850,11.62,4.0566,4.05660,5.000
5,59.900,10.73,4.0067,4.00670,5.000
5,59.950,9.91,3.9566,3.95660,5.000
5,60.000,9.15,3.9065,3.90650,5.000
5,60.050,8.46,3.8566,3.85660,5.000
5,60.100,7.81,3.8066,3.80660,5.000
5,60.150,7.22,3.7567,3.75670,5.000
5,60.200,6.67,3.7065,3.70650,5.000
5,60.250,6.16,3.6566,3.65660,5.000
5,60.300,5.68,3.6066,3.60660,5.000
5,60.350,5.25,3.5566,3.55660,5.000
5,60.400,4.84,3.5064,3.50640,5.000
5,60.450,4.44,3.4565,3.45650,5.000
5,60.500,4.08,3.4065,3.40650,5.000
5,60.550,3.74,3.3565,3.35650,5.000
5,60.600,3.43,3.3063,3.30630,5.000
5,60.650,3.13,3.2564,3.25640,5.000
5,60.700,2.85,3.2067,3.20670,5.000
5,60.750,2.59,3.1566,3.15660,5.000
5,60.800,2.35,3.1064,3.10640,5.000
5,60.850,2.12,3.0565,3.05650,5.000
5,60.900,1.90,3.0065,3.00650,5.000
5,60.950,1.71,2.9565,2.95650,5.000
5,61.000,1.52,2.9064,2.90640,5.000
5,61.050,1.35,2.8564,2.85640,5.000
5,61.100,1.20,2.8065,2.80650,5.000
5,61.150,1.05,2.7566,2.75660,5.000
5,61.200,0.91,2.7063,2.70630,5.000
5,61.250,0.79,2.6564,2.65640,5.000
5,61.300,0.67,2.6065,2.60650,5.000
5,61.350,0.57,2.5565,2.55650,5.000
5,61.400,0.48,2.5065,2.50650,5.000
5,61.450,0.39,2.4564,2.45640,5.000
5,61.500,0.31,2.4066,2.40660,5.000
5,61.550,0.24,2.3565,2.35650,5.000
5,61.600,0.18,2.3063,2.30630,5.000
5,61.650,0.13,2.2564,2.25640,5.000
5,61.700,0.08,2.2065,2.20650,5.000
5,61.750,0.05,2.1565,2.15650,5.000
5,61.800,0.02,2.1064,2.10640,5.000
5,61.850,0.00,2.0563,2.05630,5.000
5,61.900,-0.01,2.0064,2.00640,5.000
5,61.950,-0.01,1.9564,1.95640,5.000
5,62.000,0.00,1.9063,1.90630,5.000
5,62.050,0.00,1.8565,1.85650,5.000
5,62.100,0.00,1.8065,1.80650,5.000
5,62.150,0.00,1.7565,1.75650,5.000
5,62.200,0.00,1.7064,1.70640,5.000
5,62.250,0.00,1.6563,1.65630,5.000
5,62.300,0.00,1.6063,1.60630,5.000
5,62.350,0.00,1.5564,1.55640,5.000
5,62.400,0.00,1.5063,1.50630,5.000
5,62.450,0.00,1.4563,1.45630,5.000
5,62.500,0.00,1.4064,1.40640,5.000
5,62.550,0.00,1.3564,1.35640,5.000
5,62.600,0.00,1.3062,1.30620,5.000
5,62.650,0.00,1.2562,1.25620,5.000
5,62.700,0.00,1.2063,1.20630,5.000
5,62.750,0.00,1.1565,1.15650,5.000
5,62.800,0.00,1.1063,1.10630,5.000
5,62.850,0.00,1.0563,1.05630,5.000
5,62.900,0.00,1.0063,1.00630,5.000
5,62.950,0.00,0.9564,0.95640,5.000
5,63.000,0.00,0.9063,0.90630,5.000
5,63.050,0.00,0.8562,0.85620,5.000
5,63.100,0.00,0.8063,0.80630,5.000
5,63.150,0.00,0.7564,0.75640,5.000
5,63.200,0.00,0.7063,0.70630,5.000
5,63.250,0.00,0.6561,0.65610,5.000
5,63.300,0.00,0.6063,0.60630,5.000
5,63.350,0.00,0.5564,0.55640,5.000
5,63.400,0.00,0.5063,0.50630,5.000
5,63.450,0.00,0.4563,0.45630,5.000
5,63.500,0.00,0.4064,0.40640,5.000
5,63.550,0.00,0.3563,0.35630,5.000
5,63.600,-0.01,0.3063,0.30630,5.000
5,63.650,0.00,0.2562,0.25620,5.000
5,63.700,0.00,0.2063,0.20630,5.000
5,63.750,0.00,0.1565,0.15650,5.000
5,63.800,0.00,0.1063,0.10630,5.000
5,63.850,0.00,0.0561,0.05610,5.000
5,63.900,0.00,0.0064,0.00640,5.000
5,64.000,0.00,-0.0479,-0.04790,5.000
5,64.050,0.00,-0.0055,-0.00550,5.000
5,64.100,0.00,-0.0003,-0.00030,5.000
5,64.150,0.00,-0.0002,-0.00020,5.000
5,64.200,0.00,-0.0002,-0.00020,5.000
5,64.250,0.00,-0.0002,-0.00020,5.000
5,64.300,0.00,-0.0002,-0.00020,5.000
5,64.350,0.00,-0.0002,-0.00020,5.000
5,64.400,0.00,-0.0002,-0.00020,5.000
5,64.450,0.00,-0.0002,-0.00020,5.000
5,64.500,0.00,-0.0002,-0.00020,5.000
5,64.550,0.00,-0.0002,-0.00020,5.000
5,64.600,-0.01,-0.0002,-0.00020,5.000
5,64.650,0.00,-0.0002,-0.00020,5.000
5,64.700,0.00,-0.0002,-0.00020,5.000
5,64.750,0.00,-0.0002,-0.00020,5.000
5,64.800,0.00,-0.0002,-0.00020,5.000
5,64.850,0.00,-0.0002,-0.00020,5.000
5,64.900,0.00,-0.0002,-0.00020,5.000
5,64.950,0.00,-0.0002,-0.00020,5.000
5,65.000,0.00,-0.0002,-0.00020,5.000
5,65.050,0.00,-0.0002,-0.00020,5.000
5,65.100,0.00,-0.0002,-0.00020,5.000
5,65.150,0.00,-0.0002,-0.00020,5.000
5,65.200,0.00,-0.0002,-0.00020,5.000
5,65.250,0.00,-0.0002,-0.00020,5.000
5,65.300,0.00,-0.0002,-0.00020,5.000
5,65.350,0.00,-0.0002,-0.00020,5.000
5,65.400,0.00,-0.0002,-0.00020,5.000
5,65.450,0.00,-0.0002,-0.00020,5.000
5,65.500,0.00,-0.0002,-0.00020,5.000
5,65.550,0.00,-0.0002,-0.00020,5.000
5,65.600,0.00,-0.0002,-0.00020,5.000
5,65.650,0.00,-0.0002,-0.00020,5.000
5,65.700,0.00,-0.0002,-0.00020,5.000
5,65.750,0.00,-0.0002,-0.00020,5.000
5,65.800,0.00,-0.0002,-0.00020,5.000
5,65.850,0.00,-0.0002,-0.00020,5.000
5,65.900,0.00,-0.0002,-0.00020,5.000
5,65.950,0.00,-0.0002,-0.00020,5.000
5,66.000,0.00,-0.0002,-0.00020,5.000
5,66.050,0.00,-0.0002,-0.00020,5.000
5,66.100,0.00,-0.0002,-0.00020,5.000
5,66.150,0.00,-0.0002,-0.00020,5.000
5,66.200,0.00,-0.0002,-0.00020,5.000
5,66.250,0.00,-0.0002,-0.00020,5.000
5,66.300,0.00,-0.0002,-0.00020,5.000
5,66.350,0.00,-0.0002,-0.00020,5.000
5,66.400,0.00,-0.0002,-0.00020,5.000
5,66.450,0.00,-0.0002,-0.00020,5.000
5,66.500,0.00,-0.0002,-0.00020,5.000
5,66.550,0.00,-0.0002,-0.00020,5.000
5,66.600,0.00,-0.0002,-0.00020,5.000
5,66.650,0.00,-0.0002,-0.00020,5.000
5,66.700,0.00,-0.0002,-0.00020,5.000
5,66.750,0.00,-0.0002,-0.00020,5.000
5,66.800,0.00,-0.0002,-0.00020,5.000
5,66.850,0.00,-0.0002,-0.00020,5.000
5,66.900,0.00,-0.0002,-0.00020,5.000
5,66.950,0.00,-0.0002,-0.00020,5.000
5,67.050,0.01,-0.0002,-0.00020,5.000
5,67.100,0.00,-0.0002,-0.00020,5.000
5,67.150,0.00,-0.0001,-0.00010,5.000
5,67.200,0.00,-0.0001,-0.00010,5.000
5,67.250,0.00,-0.0001,-0.00010,5.000
5,67.300,0.00,-0.0001,-0.00010,5.000
5,67.350,0.00,-0.0001,-0.00010,5.000
5,67.400,0.00,-0.0001,-0.00010,5.000
5,67.450,0.00,-0.0001,-0.00010,5.000
5,67.500,0.00,-0.0001,-0.00010,5.000
5,67.550,0.00,-0.0001,-0.00010,5.000
5,67.600,0.00,-0.0001,-0.00010,5.000
5,67.650,0.00,-0.0001,-0.00010,5.000
5,67.700,0.00,-0.0001,-0.00010,5.000
5,67.750,0.00,-0.0001,-0.00010,5.000
5,67.800,0.00,-0.0001,-0.00010,5.000
5,67.850,0.00,-0.0001,-0.00010,5.000
5,67.900,0.00,-0.0001,-0.00010,5.000
5,67.950,0.01,-0.0001,-0.00010,5.000