File: AIME_journal_files/AIME_data/calibDATA_loadcell/date_08:02:2018/MTS/20deg_30N_1.txt
""
"Test Method","Radhen_Load_Cntrl_Cmprsn_250N_12-7.msm"
"Sample I. D.","Sample1.mss"
"Specimen Number","4"

"TheCycle_Output ()","_Time (s)","_Load (N)","_Extension (mm)","RealTimeDepth (mm)","CycleNumber ()"

1,0.250,0.00,0.0157,0.01570,1.000
1,0.350,-0.01,0.1156,0.11560,1.000
1,0.450,0.00,0.2157,0.21570,1.000
1,0.550,-0.01,0.3158,0.31580,1.000
1,0.650,-0.01,0.4158,0.41580,1.000
1,0.750,-0.01,0.5158,0.51580,1.000
1,0.850,0.00,0.6158,0.61580,1.000
1,0.950,0.00,0.7158,0.71580,1.000
1,1.050,0.00,0.8157,0.81570,1.000
1,1.150,0.00,0.9157,0.91570,1.000
1,1.250,0.00,1.0158,1.01580,1.000
1,1.350,-0.01,1.1158,1.11580,1.000
1,1.450,0.00,1.2159,1.21590,1.000
1,1.550,0.00,1.3159,1.31590,1.000
1,1.650,0.00,1.4157,1.41570,1.000
1,1.750,0.00,1.5158,1.51580,1.000
1,1.850,-0.01,1.6158,1.61580,1.000
1,1.950,0.00,1.7159,1.71590,1.000
1,2.050,-0.01,1.8158,1.81580,1.000
1,2.150,0.00,1.9159,1.91590,1.000
1,2.250,0.00,2.0157,2.01570,1.000
1,2.350,-0.01,2.1160,2.11600,1.000
1,2.450,0.00,2.2157,2.21570,1.000
1,2.550,0.00,2.3160,2.31600,1.000
1,2.650,-0.01,2.4159,2.41590,1.000
1,2.750,-0.01,2.5160,2.51600,1.000
1,2.850,0.00,2.6159,2.61590,1.000
1,2.950,-0.01,2.7160,2.71600,1.000
1,3.050,0.00,2.8158,2.81580,1.000
1,3.150,-0.01,2.9159,2.91590,1.000
1,3.250,0.00,3.0158,3.01580,1.000
1,3.350,0.00,3.1159,3.11590,1.000
1,3.450,0.00,3.2158,3.21580,1.000
1,3.550,-0.01,3.3161,3.31610,1.000
1,3.650,-0.01,3.4158,3.41580,1.000
1,3.750,-0.01,3.5160,3.51600,1.000
1,3.850,0.00,3.6158,3.61580,1.000
1,3.950,-0.01,3.7159,3.71590,1.000
1,4.050,-0.01,3.8158,3.81580,1.000
1,4.150,-0.01,3.9161,3.91610,1.000
1,4.250,-0.01,4.0159,4.01590,1.000
1,4.350,-0.01,4.1161,4.11610,1.000
1,4.450,-0.01,4.2159,4.21590,1.000
1,4.550,-0.01,4.3160,4.31600,1.000
1,4.650,0.02,4.4158,4.41580,1.000
1,4.750,0.08,4.5161,4.51610,1.000
1,4.850,0.20,4.6158,4.61580,1.000
1,4.950,0.43,4.7160,4.71600,1.000
1,5.050,0.74,4.8159,4.81590,1.000
1,5.150,1.16,4.9160,4.91600,1.000
1,5.250,1.70,5.0158,5.01580,1.000
1,5.350,2.35,5.1160,5.11600,1.000
1,5.450,3.12,5.2159,5.21590,1.000
1,5.550,4.02,5.3160,5.31600,1.000
1,5.650,5.08,5.4159,5.41590,1.000
1,5.750,6.30,5.5161,5.51610,1.000
1,5.850,7.71,5.6159,5.61590,1.000
1,5.950,9.30,5.7160,5.71600,1.000
1,6.050,11.13,5.8158,5.81580,1.000
1,6.150,13.20,5.9160,5.91600,1.000
1,6.250,15.54,6.0159,6.01590,1.000
1,6.350,18.16,6.1161,6.11610,1.000
1,6.450,21.14,6.2159,6.21590,1.000
1,6.550,24.45,6.3160,6.31600,1.000
1,6.650,28.13,6.4159,6.41590,1.000
1,6.800,30.56,6.4945,6.49450,1.000
1,6.900,23.06,6.3949,6.39490,1.000
1,7.000,17.89,6.2945,6.29450,1.000
1,7.100,14.04,6.1948,6.19480,1.000
1,7.200,11.07,6.0946,6.09460,1.000
1,7.300,8.76,5.9948,5.99480,1.000
1,7.400,6.94,5.8944,5.89440,1.000
1,7.500,5.48,5.7947,5.79470,1.000
1,7.600,4.33,5.6945,5.69450,1.000
1,7.700,3.40,5.5946,5.59460,1.000
1,7.800,2.66,5.4946,5.49460,1.000
1,7.900,2.09,5.3947,5.39470,1.000
1,8.000,1.63,5.2946,5.29460,1.000
1,8.100,1.25,5.1946,5.19460,1.000
1,8.200,0.93,5.0944,5.09440,1.000
1,8.300,0.65,4.9946,4.99460,1.000
1,8.400,0.43,4.8944,4.89440,1.000
1,8.500,0.23,4.7945,4.79450,1.000
1,8.600,0.09,4.6943,4.69430,1.000
1,8.700,0.00,4.5946,4.59460,1.000
1,8.800,-0.02,4.4945,4.49450,1.000
1,8.900,-0.01,4.3945,4.39450,1.000
1,9.000,0.00,4.2944,4.29440,1.000
1,9.100,0.00,4.1946,4.19460,1.000
1,9.200,-0.01,4.0944,4.09440,1.000
1,9.300,0.00,3.9946,3.99460,1.000
1,9.400,-0.01,3.8945,3.89450,1.000
1,9.500,0.00,3.7944,3.79440,1.000
1,9.600,0.00,3.6943,3.69430,1.000
1,9.700,0.00,3.5945,3.59450,1.000
1,9.800,0.00,3.4943,3.49430,1.000
1,9.900,0.00,3.3945,3.39450,1.000
1,10.000,0.00,3.2943,3.29430,1.000
1,10.100,0.00,3.1945,3.19450,1.000
1,10.200,0.00,3.0942,3.09420,1.000
1,10.300,0.00,2.9945,2.99450,1.000
1,10.400,0.00,2.8943,2.89430,1.000
1,10.500,0.00,2.7945,2.79450,1.000
1,10.600,0.00,2.6942,2.69420,1.000
1,10.700,-0.01,2.5944,2.59440,1.000
1,10.800,-0.01,2.4943,2.49430,1.000
1,10.900,0.00,2.3944,2.39440,1.000
1,11.000,0.00,2.2943,2.29430,1.000
1,11.100,0.00,2.1945,2.19450,1.000
1,11.200,0.00,2.0944,2.09440,1.000
1,11.300,0.00,1.9945,1.99450,1.000
1,11.400,0.00,1.8942,1.89420,1.000
1,11.500,0.00,1.7944,1.79440,1.000
1,11.600,0.00,1.6942,1.69420,1.000
1,11.700,0.00,1.5944,1.59440,1.000
1,11.800,0.00,1.4942,1.49420,1.000
1,11.900,-0.01,1.3942,1.39420,1.000
1,12.000,0.00,1.2943,1.29430,1.000
1,12.100,0.00,1.1942,1.19420,1.000
1,12.200,0.00,1.0943,1.09430,1.000
1,12.300,-0.01,0.9941,0.99410,1.000
1,12.400,0.00,0.8942,0.89420,1.000
1,12.500,0.00,0.7942,0.79420,1.000
1,12.600,0.00,0.6944,0.69440,1.000
1,12.700,0.00,0.5943,0.59430,1.000
1,12.800,0.00,0.4942,0.49420,1.000
1,12.900,0.00,0.3943,0.39430,1.000
1,13.000,0.00,0.2943,0.29430,1.000
1,13.100,0.00,0.1942,0.19420,1.000
1,13.200,0.00,0.0942,0.09420,1.000
1,13.400,0.00,-0.0124,-0.01240,1.000
1,13.500,0.00,-0.0003,-0.00030,1.000
1,13.600,0.01,-0.0003,-0.00030,1.000
1,13.700,0.00,-0.0003,-0.00030,1.000
1,13.800,0.00,-0.0003,-0.00030,1.000
1,13.900,0.00,-0.0003,-0.00030,1.000
1,14.000,-0.01,-0.0003,-0.00030,1.000
1,14.100,-0.01,-0.0003,-0.00030,1.000
1,14.200,0.00,-0.0003,-0.00030,1.000
1,14.300,0.00,-0.0003,-0.00030,1.000
1,14.400,0.00,-0.0003,-0.00030,1.000
1,14.500,-0.01,-0.0003,-0.00030,1.000
1,14.600,-0.01,-0.0003,-0.00030,1.000
1,14.700,-0.01,-0.0003,-0.00030,1.000
1,14.800,0.00,-0.0003,-0.00030,1.000
1,14.900,0.00,-0.0003,-0.00030,1.000
1,15.000,0.00,-0.0003,-0.00030,1.000
1,15.100,-0.01,-0.0003,-0.00030,1.000
1,15.200,0.00,-0.0003,-0.00030,1.000
1,15.300,0.00,-0.0003,-0.00030,1.000
1,15.400,0.00,-0.0003,-0.00030,1.000
1,15.500,0.00,-0.0003,-0.00030,1.000
1,15.600,0.00,-0.0003,-0.00030,1.000
1,15.700,0.00,-0.0003,-0.00030,1.000
1,15.800,0.00,-0.0003,-0.00030,1.000
1,15.900,0.00,-0.0003,-0.00030,1.000
1,16.000,0.00,-0.0003,-0.00030,1.000
1,16.100,-0.01,-0.0002,-0.00020,1.000
1,16.200,0.00,-0.0002,-0.00020,1.000
1,16.300,0.00,-0.0002,-0.00020,1.000
1,16.450,0.00,-0.0002,-0.00020,1.000
1,16.550,0.00,-0.0002,-0.00020,1.000
1,16.650,-0.01,-0.0002,-0.00020,1.000
1,16.750,0.00,-0.0002,-0.00020,1.000
1,16.850,0.00,-0.0002,-0.00020,1.000
1,16.950,0.00,-0.0002,-0.00020,1.000
1,17.050,0.00,-0.0002,-0.00020,1.000
1,17.150,0.00,-0.0002,-0.00020,1.000
1,17.250,0.00,-0.0002,-0.00020,1.000
1,17.350,0.00,-0.0002,-0.00020,1.000
2,17.650,0.00,0.0945,0.09460,2.000
2,17.750,-0.01,0.1947,0.19480,2.000
2,17.850,0.00,0.2947,0.29480,2.000
2,17.950,0.00,0.3948,0.39490,2.000
2,18.050,0.00,0.4947,0.49480,2.000
2,18.150,0.00,0.5947,0.59480,2.000
2,18.250,-0.01,0.6947,0.69480,2.000
2,18.350,0.00,0.7946,0.79470,2.000
2,18.450,-0.01,0.8947,0.89480,2.000
2,18.550,-0.01,0.9947,0.99480,2.000
2,18.650,-0.01,1.0947,1.09480,2.000
2,18.750,0.00,1.1947,1.19480,2.000
2,18.850,0.00,1.2948,1.29490,2.000
2,18.950,0.00,1.3947,1.39480,2.000
2,19.050,0.00,1.4947,1.49480,2.000
2,19.150,0.00,1.5947,1.59480,2.000
2,19.250,0.00,1.6947,1.69480,2.000
2,19.350,0.00,1.7948,1.79490,2.000
2,19.450,-0.01,1.8948,1.89490,2.000
2,19.550,0.00,1.9948,1.99490,2.000
2,19.650,0.00,2.0948,2.09490,2.000
2,19.750,0.00,2.1948,2.19490,2.000
2,19.850,0.00,2.2947,2.29480,2.000
2,19.950,0.00,2.3949,2.39500,2.000
2,20.050,0.00,2.4947,2.49480,2.000
2,20.150,-0.01,2.5950,2.59510,2.000
2,20.250,0.00,2.6947,2.69480,2.000
2,20.350,0.00,2.7949,2.79500,2.000
2,20.450,0.00,2.8947,2.89480,2.000
2,20.550,0.00,2.9948,2.99490,2.000
2,20.650,0.00,3.0947,3.09480,2.000
2,20.750,0.00,3.1949,3.19500,2.000
2,20.850,0.00,3.2948,3.29490,2.000
2,20.950,-0.01,3.3950,3.39510,2.000
2,21.050,0.00,3.4948,3.49490,2.000
2,21.150,0.00,3.5949,3.59500,2.000
2,21.250,0.00,3.6946,3.69470,2.000
2,21.350,0.00,3.7948,3.79490,2.000
2,21.450,0.00,3.8948,3.89490,2.000
2,21.550,-0.01,3.9949,3.99500,2.000
2,21.650,-0.01,4.0947,4.09480,2.000
2,21.750,0.00,4.1949,4.19500,2.000
2,21.850,-0.01,4.2948,4.29490,2.000
2,21.950,-0.01,4.3948,4.39490,2.000
2,22.050,0.03,4.4949,4.49500,2.000
2,22.150,0.10,4.5949,4.59500,2.000
2,22.250,0.27,4.6947,4.69480,2.000
2,22.350,0.50,4.7949,4.79500,2.000
2,22.450,0.82,4.8948,4.89490,2.000
2,22.550,1.21,4.9949,4.99500,2.000
2,22.650,1.70,5.0947,5.09480,2.000
2,22.750,2.34,5.1949,5.19500,2.000
2,22.850,3.15,5.2948,5.29490,2.000
2,22.950,4.09,5.3949,5.39500,2.000
2,23.050,5.19,5.4948,5.49490,2.000
2,23.150,6.47,5.5950,5.59510,2.000
2,23.250,7.96,5.6948,5.69490,2.000
2,23.350,9.64,5.7949,5.79500,2.000
2,23.450,11.56,5.8947,5.89480,2.000
2,23.550,13.71,5.9949,5.99500,2.000
2,23.650,16.17,6.0949,6.09500,2.000
2,23.750,18.92,6.1949,6.19500,2.000
2,23.850,22.08,6.2947,6.29480,2.000
2,23.950,25.72,6.3950,6.39510,2.000
2,24.050,29.94,6.4947,6.49480,2.000
2,24.200,26.85,6.4717,6.47180,2.000
2,24.300,20.57,6.3717,6.37180,2.000
2,24.400,16.01,6.2717,6.27180,2.000
2,24.500,12.58,6.1717,6.17180,2.000
2,24.600,9.91,6.0717,6.07180,2.000
2,24.700,7.82,5.9716,5.97170,2.000
2,24.800,6.16,5.8716,5.87170,2.000
2,24.900,4.85,5.7715,5.77160,2.000
2,25.000,3.81,5.6715,5.67160,2.000
2,25.100,3.04,5.5715,5.57160,2.000
2,25.200,2.47,5.4717,5.47180,2.000
2,25.300,1.98,5.3715,5.37160,2.000
2,25.400,1.55,5.2717,5.27180,2.000
2,25.500,1.17,5.1715,5.17160,2.000
2,25.600,0.85,5.0716,5.07170,2.000
2,25.700,0.55,4.9713,4.97140,2.000
2,25.800,0.33,4.8716,4.87170,2.000
2,25.900,0.15,4.7713,4.77140,2.000
2,26.000,0.04,4.6715,4.67160,2.000
2,26.100,-0.02,4.5714,4.57150,2.000
2,26.200,-0.01,4.4716,4.47170,2.000
2,26.300,-0.01,4.3713,4.37140,2.000
2,26.400,0.00,4.2716,4.27170,2.000
2,26.500,0.00,4.1714,4.17150,2.000
2,26.600,0.00,4.0716,4.07170,2.000
2,26.700,-0.01,3.9713,3.97140,2.000
2,26.800,-0.01,3.8716,3.87170,2.000
2,26.900,-0.01,3.7713,3.77140,2.000
2,27.000,0.00,3.6715,3.67160,2.000
2,27.100,0.00,3.5712,3.57130,2.000
2,27.200,0.00,3.4715,3.47160,2.000
2,27.300,0.00,3.3714,3.37150,2.000
2,27.400,-0.01,3.2715,3.27160,2.000
2,27.500,0.00,3.1712,3.17130,2.000
2,27.600,0.00,3.0714,3.07150,2.000
2,27.700,0.00,2.9712,2.97130,2.000
2,27.800,-0.01,2.8713,2.87140,2.000
2,27.900,0.00,2.7712,2.77130,2.000
2,28.000,0.00,2.6715,2.67160,2.000
2,28.100,-0.01,2.5713,2.57140,2.000
2,28.200,0.00,2.4714,2.47150,2.000
2,28.300,0.00,2.3711,2.37120,2.000
2,28.400,0.00,2.2714,2.27150,2.000
2,28.500,-0.01,2.1712,2.17130,2.000
2,28.600,0.00,2.0714,2.07150,2.000
2,28.700,0.00,1.9713,1.97140,2.000
2,28.800,0.00,1.8713,1.87140,2.000
2,28.900,0.00,1.7712,1.77130,2.000
2,29.000,0.00,1.6713,1.67140,2.000
2,29.100,0.00,1.5711,1.57120,2.000
2,29.200,0.00,1.4713,1.47140,2.000
2,29.300,0.00,1.3712,1.37130,2.000
2,29.400,0.00,1.2714,1.27150,2.000
2,29.500,0.00,1.1712,1.17130,2.000
2,29.600,-0.01,1.0713,1.07140,2.000
2,29.700,0.00,0.9711,0.97120,2.000
2,29.800,0.00,0.8712,0.87130,2.000
2,29.900,0.00,0.7710,0.77110,2.000
2,30.000,0.00,0.6714,0.67150,2.000
2,30.100,0.00,0.5712,0.57130,2.000
2,30.200,0.00,0.4712,0.47130,2.000
2,30.300,0.00,0.3712,0.37130,2.000
2,30.400,0.00,0.2713,0.27140,2.000
2,30.500,0.00,0.1711,0.17120,2.000
2,30.600,0.00,0.0712,0.07130,2.000
2,30.750,0.00,-0.0388,-0.03870,2.000
2,30.850,0.00,-0.0004,-0.00030,2.000
2,30.950,0.00,-0.0004,-0.00030,2.000
2,31.050,0.00,-0.0004,-0.00030,2.000
2,31.150,0.00,-0.0004,-0.00030,2.000
2,31.250,0.00,-0.0004,-0.00030,2.000
2,31.350,0.00,-0.0004,-0.00030,2.000
2,31.450,-0.01,-0.0004,-0.00030,2.000
2,31.550,-0.01,-0.0004,-0.00030,2.000
2,31.650,0.00,-0.0003,-0.00020,2.000
2,31.750,0.00,-0.0003,-0.00020,2.000
2,31.850,-0.01,-0.0003,-0.00020,2.000
2,31.950,0.00,-0.0003,-0.00020,2.000
2,32.050,0.00,-0.0003,-0.00020,2.000
2,32.150,-0.01,-0.0003,-0.00020,2.000
2,32.250,0.00,-0.0003,-0.00020,2.000
2,32.350,0.00,-0.0003,-0.00020,2.000
2,32.450,-0.01,-0.0003,-0.00020,2.000
2,32.550,-0.01,-0.0003,-0.00020,2.000
2,32.650,0.00,-0.0003,-0.00020,2.000
2,32.750,0.00,-0.0003,-0.00020,2.000
2,32.850,0.00,-0.0003,-0.00020,2.000
2,32.950,0.00,-0.0003,-0.00020,2.000
2,33.050,-0.01,-0.0003,-0.00020,2.000
2,33.150,0.00,-0.0003,-0.00020,2.000
2,33.250,0.00,-0.0003,-0.00020,2.000
2,33.350,-0.01,-0.0003,-0.00020,2.000
2,33.450,0.00,-0.0003,-0.00020,2.000
2,33.550,-0.01,-0.0002,-0.00010,2.000
2,33.650,0.00,-0.0002,-0.00010,2.000
2,33.800,-0.01,-0.0002,-0.00010,2.000
2,33.900,0.00,-0.0002,-0.00010,2.000
2,34.000,0.00,-0.0002,-0.00010,2.000
2,34.100,0.00,-0.0002,-0.00010,2.000
2,34.200,0.00,-0.0002,-0.00010,2.000
2,34.300,0.00,-0.0002,-0.00010,2.000
2,34.400,-0.01,-0.0002,-0.00010,2.000
2,34.500,0.00,-0.0002,-0.00010,2.000
2,34.600,0.00,-0.0002,-0.00010,2.000
2,34.700,0.00,-0.0002,-0.00010,2.000
3,35.000,0.01,0.0454,0.04550,3.000
3,35.100,0.01,0.1456,0.14570,3.000
3,35.200,0.02,0.2455,0.24560,3.000
3,35.300,0.01,0.3457,0.34580,3.000
3,35.400,0.02,0.4456,0.44570,3.000
3,35.500,0.01,0.5457,0.54580,3.000
3,35.600,0.01,0.6457,0.64580,3.000
3,35.700,0.02,0.7458,0.74590,3.000
3,35.800,0.01,0.8455,0.84560,3.000
3,35.900,0.01,0.9457,0.94580,3.000
3,36.000,0.01,1.0455,1.04560,3.000
3,36.100,0.01,1.1457,1.14580,3.000
3,36.200,0.01,1.2457,1.24580,3.000
3,36.300,0.01,1.3458,1.34590,3.000
3,36.400,0.02,1.4455,1.44560,3.000
3,36.500,0.01,1.5457,1.54580,3.000
3,36.600,0.02,1.6456,1.64570,3.000
3,36.700,0.01,1.7458,1.74590,3.000
3,36.800,0.01,1.8456,1.84570,3.000
3,36.900,0.02,1.9457,1.94580,3.000
3,37.000,0.01,2.0457,2.04580,3.000
3,37.100,0.01,2.1459,2.14600,3.000
3,37.200,0.01,2.2456,2.24570,3.000
3,37.300,0.02,2.3457,2.34580,3.000
3,37.400,0.02,2.4457,2.44580,3.000
3,37.500,0.02,2.5458,2.54590,3.000
3,37.600,0.01,2.6458,2.64590,3.000
3,37.700,0.01,2.7458,2.74590,3.000
3,37.800,0.02,2.8457,2.84580,3.000
3,37.900,0.01,2.9459,2.94600,3.000
3,38.000,0.01,3.0457,3.04580,3.000
3,38.100,0.01,3.1457,3.14580,3.000
3,38.200,0.02,3.2459,3.24600,3.000
3,38.300,0.01,3.3459,3.34600,3.000
3,38.400,0.01,3.4459,3.44600,3.000
3,38.500,0.02,3.5458,3.54590,3.000
3,38.600,0.01,3.6458,3.64590,3.000
3,38.700,0.02,3.7459,3.74600,3.000
3,38.800,0.01,3.8458,3.84590,3.000
3,38.900,0.01,3.9459,3.94600,3.000
3,39.000,0.01,4.0459,4.04600,3.000
3,39.100,0.02,4.1459,4.14600,3.000
3,39.200,0.02,4.2460,4.24610,3.000
3,39.300,0.01,4.3457,4.34580,3.000
3,39.400,0.02,4.4459,4.44600,3.000
3,39.500,0.09,4.5459,4.54600,3.000
3,39.600,0.18,4.6459,4.64600,3.000
3,39.700,0.39,4.7459,4.74600,3.000
3,39.800,0.65,4.8459,4.84600,3.000
3,39.900,1.00,4.9458,4.94590,3.000
3,40.000,1.44,5.0458,5.04590,3.000
3,40.100,1.99,5.1459,5.14600,3.000
3,40.200,2.72,5.2459,5.24600,3.000
3,40.300,3.59,5.3459,5.34600,3.000
3,40.400,4.60,5.4460,5.44610,3.000
3,40.500,5.81,5.5460,5.54610,3.000
3,40.600,7.18,5.6459,5.64600,3.000
3,40.700,8.75,5.7459,5.74600,3.000
3,40.800,10.54,5.8458,5.84590,3.000
3,40.900,12.55,5.9458,5.94590,3.000
3,41.000,14.83,6.0459,6.04600,3.000
3,41.100,17.39,6.1459,6.14600,3.000
3,41.200,20.29,6.2460,6.24610,3.000
3,41.300,23.63,6.3459,6.34600,3.000
3,41.400,27.48,6.4460,6.44610,3.000
3,41.550,32.08,6.5420,6.54210,3.000
3,41.650,24.32,6.4448,6.44490,3.000
3,41.750,18.77,6.3446,6.34470,3.000
3,41.850,14.64,6.2447,6.24480,3.000
3,41.950,11.52,6.1446,6.14470,3.000
3,42.050,9.08,6.0447,6.04480,3.000
3,42.150,7.18,5.9445,5.94460,3.000
3,42.250,5.65,5.8446,5.84470,3.000
3,42.350,4.46,5.7445,5.74460,3.000
3,42.450,3.52,5.6446,5.64470,3.000
3,42.550,2.87,5.5446,5.54470,3.000
3,42.650,2.33,5.4445,5.44460,3.000
3,42.750,1.86,5.3446,5.34470,3.000
3,42.850,1.45,5.2447,5.24480,3.000
3,42.950,1.09,5.1445,5.14460,3.000
3,43.050,0.77,5.0445,5.04460,3.000
3,43.150,0.49,4.9445,4.94460,3.000
3,43.250,0.28,4.8445,4.84460,3.000
3,43.350,0.13,4.7443,4.74440,3.000
3,43.450,0.03,4.6444,4.64450,3.000
3,43.550,0.00,4.5445,4.54460,3.000
3,43.650,0.01,4.4444,4.44450,3.000
3,43.750,0.01,4.3443,4.34440,3.000
3,43.850,0.01,4.2445,4.24460,3.000
3,43.950,0.01,4.1445,4.14460,3.000
3,44.050,0.01,4.0445,4.04460,3.000
3,44.150,0.01,3.9444,3.94450,3.000
3,44.250,0.01,3.8445,3.84460,3.000
3,44.350,0.01,3.7444,3.74450,3.000
3,44.450,0.02,3.6443,3.64440,3.000
3,44.550,0.01,3.5443,3.54440,3.000
3,44.650,0.01,3.4444,3.44450,3.000
3,44.750,0.01,3.3445,3.34460,3.000
3,44.850,0.02,3.2445,3.24460,3.000
3,44.950,0.02,3.1443,3.14440,3.000
3,45.050,0.01,3.0443,3.04440,3.000
3,45.150,0.01,2.9443,2.94440,3.000
3,45.250,0.02,2.8442,2.84430,3.000
3,45.350,0.01,2.7444,2.74450,3.000
3,45.450,0.02,2.6444,2.64450,3.000
3,45.550,0.02,2.5444,2.54450,3.000
3,45.650,0.02,2.4443,2.44440,3.000
3,45.750,0.01,2.3444,2.34450,3.000
3,45.850,0.02,2.2442,2.24430,3.000
3,45.950,0.02,2.1444,2.14450,3.000
3,46.050,0.02,2.0444,2.04450,3.000
3,46.150,0.01,1.9444,1.94450,3.000
3,46.250,0.01,1.8443,1.84440,3.000
3,46.350,0.02,1.7444,1.74450,3.000
3,46.450,0.01,1.6442,1.64430,3.000
3,46.550,0.02,1.5443,1.54440,3.000
3,46.650,0.01,1.4441,1.44420,3.000
3,46.750,0.02,1.3445,1.34460,3.000
3,46.850,0.01,1.2443,1.24440,3.000
3,46.950,0.01,1.1444,1.14450,3.000
3,47.050,0.02,1.0441,1.04420,3.000
3,47.150,0.02,0.9443,0.94440,3.000
3,47.250,0.02,0.8440,0.84410,3.000
3,47.350,0.01,0.7443,0.74440,3.000
3,47.450,0.02,0.6442,0.64430,3.000
3,47.550,0.01,0.5442,0.54430,3.000
3,47.650,0.02,0.4442,0.44430,3.000
3,47.750,0.01,0.3443,0.34440,3.000
3,47.850,0.01,0.2440,0.24410,3.000
3,47.950,0.01,0.1441,0.14420,3.000
3,48.050,0.02,0.0440,0.04410,3.000
3,48.200,0.02,-0.0345,-0.03440,3.000
3,48.300,0.01,-0.0003,-0.00020,3.000
3,48.400,0.01,-0.0003,-0.00020,3.000
3,48.500,0.02,-0.0003,-0.00020,3.000
3,48.600,0.02,-0.0003,-0.00020,3.000
3,48.700,0.01,-0.0003,-0.00020,3.000
3,48.800,0.02,-0.0003,-0.00020,3.000
3,48.900,0.02,-0.0003,-0.00020,3.000
3,49.000,0.01,-0.0003,-0.00020,3.000
3,49.100,0.02,-0.0003,-0.00020,3.000
3,49.200,0.02,-0.0003,-0.00020,3.000
3,49.300,0.02,-0.0003,-0.00020,3.000
3,49.400,0.01,-0.0003,-0.00020,3.000
3,49.500,0.02,-0.0003,-0.00020,3.000
3,49.600,0.01,-0.0003,-0.00020,3.000
3,49.700,0.01,-0.0003,-0.00020,3.000
3,49.800,0.01,-0.0003,-0.00020,3.000
3,49.900,0.01,-0.0003,-0.00020,3.000
3,50.000,0.02,-0.0003,-0.00020,3.000
3,50.100,0.01,-0.0003,-0.00020,3.000
3,50.200,0.02,-0.0003,-0.00020,3.000
3,50.300,0.01,-0.0003,-0.00020,3.000
3,50.400,0.01,-0.0003,-0.00020,3.000
3,50.500,0.02,-0.0003,-0.00020,3.000
3,50.600,0.01,-0.0003,-0.00020,3.000
3,50.700,0.01,-0.0003,-0.00020,3.000
3,50.800,0.01,-0.0002,-0.00010,3.000
3,50.900,0.01,-0.0002,-0.00010,3.000
3,51.000,0.01,-0.0002,-0.00010,3.000
3,51.100,0.02,-0.0002,-0.00010,3.000
3,51.250,0.02,-0.0002,-0.00010,3.000
3,51.350,0.01,-0.0002,-0.00010,3.000
3,51.450,0.02,-0.0002,-0.00010,3.000
3,51.550,0.01,-0.0002,-0.00010,3.000
3,51.650,0.01,-0.0002,-0.00010,3.000
3,51.750,0.02,-0.0002,-0.00010,3.000
3,51.850,0.01,-0.0002,-0.00010,3.000
3,51.950,0.01,-0.0002,-0.00010,3.000
3,52.050,0.01,-0.0002,-0.00010,3.000
3,52.150,0.02,-0.0002,-0.00010,3.000
4,52.400,0.00,0.0145,0.01460,4.000
4,52.500,0.00,0.1145,0.11460,4.000
4,52.600,0.00,0.2145,0.21460,4.000
4,52.700,0.00,0.3147,0.31480,4.000
4,52.800,-0.01,0.4147,0.41480,4.000
4,52.900,0.00,0.5147,0.51480,4.000
4,53.000,0.00,0.6147,0.61480,4.000
4,53.100,0.00,0.7147,0.71480,4.000
4,53.200,-0.01,0.8146,0.81470,4.000
4,53.300,-0.01,0.9146,0.91470,4.000
4,53.400,0.00,1.0146,1.01470,4.000
4,53.500,0.00,1.1148,1.11490,4.000
4,53.600,0.00,1.2147,1.21480,4.000
4,53.700,-0.01,1.3148,1.31490,4.000
4,53.800,-0.01,1.4145,1.41460,4.000
4,53.900,-0.01,1.5147,1.51480,4.000
4,54.000,0.00,1.6146,1.61470,4.000
4,54.100,0.00,1.7147,1.71480,4.000
4,54.200,-0.01,1.8147,1.81480,4.000
4,54.300,0.00,1.9149,1.91500,4.000
4,54.400,-0.01,2.0147,2.01480,4.000
4,54.500,0.00,2.1149,2.11500,4.000
4,54.600,-0.01,2.2148,2.21490,4.000
4,54.700,-0.01,2.3149,2.31500,4.000
4,54.800,0.00,2.4146,2.41470,4.000
4,54.900,0.00,2.5149,2.51500,4.000
4,55.000,-0.01,2.6147,2.61480,4.000
4,55.100,-0.01,2.7149,2.71500,4.000
4,55.200,0.00,2.8148,2.81490,4.000
4,55.300,-0.01,2.9149,2.91500,4.000
4,55.400,-0.01,3.0148,3.01490,4.000
4,55.500,0.00,3.1149,3.11500,4.000
4,55.600,0.00,3.2147,3.21480,4.000
4,55.700,0.00,3.3149,3.31500,4.000
4,55.800,-0.01,3.4147,3.41480,4.000
4,55.900,-0.01,3.5148,3.51490,4.000
4,56.000,-0.01,3.6147,3.61480,4.000
4,56.100,-0.01,3.7148,3.71490,4.000
4,56.200,-0.01,3.8147,3.81480,4.000
4,56.300,0.00,3.9150,3.91510,4.000
4,56.400,-0.01,4.0148,4.01490,4.000
4,56.500,0.00,4.1150,4.11510,4.000
4,56.600,-0.01,4.2147,4.21480,4.000
4,56.700,-0.01,4.3148,4.31490,4.000
4,56.800,0.00,4.4148,4.41490,4.000
4,56.900,0.04,4.5150,4.51510,4.000
4,57.000,0.11,4.6148,4.61490,4.000
4,57.100,0.28,4.7149,4.71500,4.000
4,57.200,0.53,4.8147,4.81480,4.000
4,57.300,0.85,4.9148,4.91490,4.000
4,57.400,1.26,5.0147,5.01480,4.000
4,57.500,1.80,5.1149,5.11500,4.000
4,57.600,2.49,5.2148,5.21490,4.000
4,57.700,3.33,5.3150,5.31510,4.000
4,57.800,4.29,5.4148,5.41490,4.000
4,57.900,5.43,5.5148,5.51490,4.000
4,58.000,6.77,5.6148,5.61490,4.000
4,58.100,8.28,5.7148,5.71490,4.000
4,58.200,10.00,5.8147,5.81480,4.000
4,58.300,11.93,5.9149,5.91500,4.000
4,58.400,14.13,6.0148,6.01490,4.000
4,58.500,16.57,6.1150,6.11510,4.000
4,58.600,19.36,6.2148,6.21490,4.000
4,58.700,22.54,6.3149,6.31500,4.000
4,58.800,26.22,6.4150,6.41510,4.000
4,58.950,32.01,6.5377,6.53780,4.000
4,59.050,25.14,6.4517,6.45180,4.000
4,59.150,19.32,6.3517,6.35180,4.000
4,59.250,15.04,6.2517,6.25180,4.000
4,59.350,11.81,6.1517,6.15180,4.000
4,59.450,9.30,6.0517,6.05180,4.000
4,59.550,7.34,5.9517,5.95180,4.000
4,59.650,5.78,5.8516,5.85170,4.000
4,59.750,4.55,5.7516,5.75170,4.000
4,59.850,3.57,5.6516,5.65170,4.000
4,59.950,2.88,5.5517,5.55180,4.000
4,60.050,2.34,5.4515,5.45160,4.000
4,60.150,1.85,5.3517,5.35180,4.000
4,60.250,1.45,5.2516,5.25170,4.000
4,60.350,1.08,5.1516,5.15170,4.000
4,60.450,0.78,5.0515,5.05160,4.000
4,60.550,0.49,4.9516,4.95170,4.000
4,60.650,0.28,4.8515,4.85160,4.000
4,60.750,0.12,4.7515,4.75160,4.000
4,60.850,0.02,4.6514,4.65150,4.000
4,60.950,-0.03,4.5516,4.55170,4.000
4,61.050,-0.01,4.4515,4.45160,4.000
4,61.150,0.00,4.3515,4.35160,4.000
4,61.250,-0.01,4.2515,4.25160,4.000
4,61.350,-0.01,4.1516,4.15170,4.000
4,61.450,-0.01,4.0515,4.05160,4.000
4,61.550,-0.01,3.9515,3.95160,4.000
4,61.650,0.00,3.8514,3.85150,4.000
4,61.750,0.00,3.7515,3.75160,4.000
4,61.850,0.00,3.6513,3.65140,4.000
4,61.950,-0.01,3.5514,3.55150,4.000
4,62.050,-0.01,3.4513,3.45140,4.000
4,62.150,-0.01,3.3515,3.35160,4.000
4,62.250,0.00,3.2514,3.25150,4.000
4,62.350,0.00,3.1515,3.15160,4.000
4,62.450,0.00,3.0512,3.05130,4.000
4,62.550,0.00,2.9514,2.95150,4.000
4,62.650,-0.01,2.8512,2.85130,4.000
4,62.750,-0.01,2.7515,2.75160,4.000
4,62.850,-0.01,2.6513,2.65140,4.000
4,62.950,0.00,2.5515,2.55160,4.000
4,63.050,-0.01,2.4512,2.45130,4.000
4,63.150,0.00,2.3515,2.35160,4.000
4,63.250,0.00,2.2512,2.25130,4.000
4,63.350,0.00,2.1514,2.15150,4.000
4,63.450,-0.01,2.0513,2.05140,4.000
4,63.550,-0.01,1.9515,1.95160,4.000
4,63.650,-0.01,1.8512,1.85130,4.000
4,63.750,-0.01,1.7514,1.75150,4.000
4,63.850,-0.01,1.6511,1.65120,4.000
4,63.950,0.00,1.5513,1.55140,4.000
4,64.050,0.00,1.4512,1.45130,4.000
4,64.150,-0.01,1.3514,1.35150,4.000
4,64.250,-0.01,1.2512,1.25130,4.000
4,64.350,-0.01,1.1514,1.15150,4.000
4,64.450,-0.01,1.0511,1.05120,4.000
4,64.550,0.00,0.9513,0.95140,4.000
4,64.650,-0.01,0.8510,0.85110,4.000
4,64.750,0.00,0.7512,0.75130,4.000
4,64.850,0.00,0.6512,0.65130,4.000
4,64.950,-0.01,0.5513,0.55140,4.000
4,65.050,-0.01,0.4510,0.45110,4.000
4,65.150,0.00,0.3513,0.35140,4.000
4,65.250,0.00,0.2511,0.25120,4.000
4,65.350,0.00,0.1512,0.15130,4.000
4,65.450,0.00,0.0511,0.05120,4.000
4,65.600,-0.01,-0.0255,-0.02540,4.000
4,65.700,-0.01,-0.0004,-0.00030,4.000
4,65.800,0.00,-0.0003,-0.00020,4.000
4,65.900,0.00,-0.0003,-0.00020,4.000
4,66.000,0.00,-0.0003,-0.00020,4.000
4,66.100,-0.01,-0.0003,-0.00020,4.000
4,66.200,-0.01,-0.0003,-0.00020,4.000
4,66.300,0.00,-0.0003,-0.00020,4.000
4,66.400,0.00,-0.0003,-0.00020,4.000
4,66.500,0.00,-0.0003,-0.00020,4.000
4,66.600,0.00,-0.0003,-0.00020,4.000
4,66.700,-0.01,-0.0003,-0.00020,4.000
4,66.800,0.00,-0.0003,-0.00020,4.000
4,66.900,-0.01,-0.0003,-0.00020,4.000
4,67.000,0.00,-0.0003,-0.00020,4.000
4,67.100,0.00,-0.0003,-0.00020,4.000
4,67.200,0.00,-0.0003,-0.00020,4.000
4,67.300,-0.01,-0.0003,-0.00020,4.000
4,67.400,-0.01,-0.0003,-0.00020,4.000
4,67.500,0.00,-0.0003,-0.00020,4.000
4,67.600,-0.01,-0.0003,-0.00020,4.000
4,67.700,-0.01,-0.0003,-0.00020,4.000
4,67.800,-0.01,-0.0003,-0.00020,4.000
4,67.900,0.00,-0.0003,-0.00020,4.000
4,68.000,0.00,-0.0003,-0.00020,4.000
4,68.100,-0.01,-0.0003,-0.00020,4.000
4,68.200,0.00,-0.0002,-0.00010,4.000
4,68.300,0.00,-0.0002,-0.00010,4.000
4,68.400,-0.01,-0.0002,-0.00010,4.000
4,68.500,0.00,-0.0002,-0.00010,4.000
4,68.650,-0.01,-0.0002,-0.00010,4.000
4,68.750,-0.01,-0.0002,-0.00010,4.000
4,68.850,0.00,-0.0002,-0.00010,4.000
4,68.950,0.00,-0.0002,-0.00010,4.000
4,69.050,0.00,-0.0002,-0.00010,4.000
4,69.150,0.00,-0.0002,-0.00010,4.000
4,69.250,-0.01,-0.0002,-0.00010,4.000
4,69.350,-0.01,-0.0002,-0.00010,4.000
4,69.450,-0.01,-0.0002,-0.00010,4.000
4,69.550,0.00,-0.0002,-0.00010,4.000
5,69.850,-0.01,0.0746,0.07470,5.000
5,69.950,-0.01,0.1745,0.17460,5.000
5,70.050,-0.01,0.2747,0.27480,5.000
5,70.150,-0.01,0.3746,0.37470,5.000
5,70.250,0.00,0.4747,0.47480,5.000
5,70.350,-0.01,0.5746,0.57470,5.000
5,70.450,-0.01,0.6749,0.67500,5.000
5,70.550,-0.01,0.7745,0.77460,5.000
5,70.650,-0.01,0.8747,0.87480,5.000
5,70.750,-0.01,0.9746,0.97470,5.000
5,70.850,0.00,1.0748,1.07490,5.000
5,70.950,0.00,1.1747,1.17480,5.000
5,71.050,0.00,1.2749,1.27500,5.000
5,71.150,-0.01,1.3746,1.37470,5.000
5,71.250,-0.01,1.4748,1.47490,5.000
5,71.350,0.00,1.5746,1.57470,5.000
5,71.450,0.00,1.6748,1.67490,5.000
5,71.550,-0.01,1.7747,1.77480,5.000
5,71.650,-0.01,1.8747,1.87480,5.000
5,71.750,-0.01,1.9747,1.97480,5.000
5,71.850,0.00,2.0749,2.07500,5.000
5,71.950,-0.01,2.1746,2.17470,5.000
5,72.050,-0.01,2.2747,2.27480,5.000
5,72.150,0.00,2.3747,2.37480,5.000
5,72.250,-0.01,2.4749,2.47500,5.000
5,72.350,0.00,2.5747,2.57480,5.000
5,72.450,-0.01,2.6749,2.67500,5.000
5,72.550,0.00,2.7747,2.77480,5.000
5,72.650,-0.01,2.8748,2.87490,5.000
5,72.750,-0.01,2.9747,2.97480,5.000
5,72.850,0.00,3.0747,3.07480,5.000
5,72.950,0.00,3.1747,3.17480,5.000
5,73.050,0.00,3.2748,3.27490,5.000
5,73.150,0.00,3.3748,3.37490,5.000
5,73.250,-0.01,3.4750,3.47510,5.000
5,73.350,0.00,3.5747,3.57480,5.000
5,73.450,0.00,3.6749,3.67500,5.000
5,73.550,-0.01,3.7748,3.77490,5.000
5,73.650,0.00,3.8748,3.87490,5.000
5,73.750,-0.01,3.9748,3.97490,5.000
5,73.850,-0.01,4.0749,4.07500,5.000
5,73.950,-0.01,4.1748,4.17490,5.000
5,74.050,-0.01,4.2749,4.27500,5.000
5,74.150,0.00,4.3748,4.37490,5.000
5,74.250,0.01,4.4750,4.47510,5.000
5,74.350,0.07,4.5748,4.57490,5.000
5,74.450,0.20,4.6748,4.67490,5.000
5,74.550,0.41,4.7747,4.77480,5.000
5,74.650,0.70,4.8749,4.87500,5.000
5,74.750,1.07,4.9747,4.97480,5.000
5,74.850,1.56,5.0749,5.07500,5.000
5,74.950,2.20,5.1747,5.17480,5.000
5,75.050,2.97,5.2750,5.27510,5.000
5,75.150,3.89,5.3749,5.37500,5.000
5,75.250,4.96,5.4750,5.47510,5.000
5,75.350,6.21,5.5748,5.57490,5.000
5,75.450,7.64,5.6748,5.67490,5.000
5,75.550,9.28,5.7747,5.77480,5.000
5,75.650,11.11,5.8748,5.87490,5.000
5,75.750,13.20,5.9748,5.97490,5.000
5,75.850,15.52,6.0749,6.07500,5.000
5,75.950,18.16,6.1749,6.17500,5.000
5,76.050,21.14,6.2749,6.27500,5.000
5,76.150,24.57,6.3748,6.37490,5.000
5,76.250,28.53,6.4748,6.47490,5.000
5,76.400,29.63,6.5135,6.51360,5.000
5,76.500,22.27,6.4137,6.41380,5.000
5,76.600,17.26,6.3138,6.31390,5.000
5,76.700,13.50,6.2136,6.21370,5.000
5,76.800,10.60,6.1137,6.11380,5.000
5,76.900,8.37,6.0136,6.01370,5.000
5,77.000,6.61,5.9136,5.91370,5.000
5,77.100,5.21,5.8135,5.81360,5.000
5,77.200,4.09,5.7136,5.71370,5.000
5,77.300,3.24,5.6135,5.61360,5.000
5,77.400,2.64,5.5137,5.51380,5.000
5,77.500,2.14,5.4136,5.41370,5.000
5,77.600,1.68,5.3138,5.31390,5.000
5,77.700,1.29,5.2136,5.21370,5.000
5,77.800,0.96,5.1136,5.11370,5.000
5,77.900,0.65,5.0135,5.01360,5.000
5,78.000,0.39,4.9136,4.91370,5.000
5,78.100,0.20,4.8135,4.81360,5.000
5,78.200,0.07,4.7136,4.71370,5.000
5,78.300,0.00,4.6135,4.61360,5.000
5,78.400,-0.02,4.5137,4.51380,5.000
5,78.500,-0.01,4.4134,4.41350,5.000
5,78.600,0.00,4.3135,4.31360,5.000
5,78.700,-0.01,4.2135,4.21360,5.000
5,78.800,-0.01,4.1135,4.11360,5.000
5,78.900,-0.01,4.0134,4.01350,5.000
5,79.000,-0.01,3.9135,3.91360,5.000
5,79.100,-0.01,3.8134,3.81350,5.000
5,79.200,-0.01,3.7135,3.71360,5.000
5,79.300,-0.01,3.6133,3.61340,5.000
5,79.400,-0.01,3.5134,3.51350,5.000
5,79.500,-0.01,3.4134,3.41350,5.000
5,79.600,0.00,3.3135,3.31360,5.000
5,79.700,0.00,3.2134,3.21350,5.000
5,79.800,-0.01,3.1134,3.11350,5.000
5,79.900,-0.01,3.0132,3.01330,5.000
5,80.000,-0.01,2.9134,2.91350,5.000
5,80.100,0.00,2.8131,2.81320,5.000
5,80.200,0.00,2.7135,2.71360,5.000
5,80.300,-0.01,2.6134,2.61350,5.000
5,80.400,0.00,2.5134,2.51350,5.000
5,80.500,0.00,2.4132,2.41330,5.000
5,80.600,0.00,2.3134,2.31350,5.000
5,80.700,0.00,2.2133,2.21340,5.000
5,80.800,-0.01,2.1135,2.11360,5.000
5,80.900,0.00,2.0133,2.01340,5.000
5,81.000,-0.01,1.9134,1.91350,5.000
5,81.100,-0.01,1.8132,1.81330,5.000
5,81.200,0.00,1.7134,1.71350,5.000
5,81.300,-0.01,1.6131,1.61320,5.000
5,81.400,0.00,1.5133,1.51340,5.000
5,81.500,-0.01,1.4131,1.41320,5.000
5,81.600,0.00,1.3133,1.31340,5.000
5,81.700,0.00,1.2131,1.21320,5.000
5,81.800,-0.01,1.1132,1.11330,5.000
5,81.900,-0.01,1.0132,1.01330,5.000
5,82.000,0.00,0.9133,0.91340,5.000
5,82.100,0.00,0.8130,0.81310,5.000
5,82.200,0.00,0.7133,0.71340,5.000
5,82.300,0.00,0.6133,0.61340,5.000
5,82.400,-0.01,0.5132,0.51330,5.000
5,82.500,0.00,0.4131,0.41320,5.000
5,82.600,-0.01,0.3133,0.31340,5.000
5,82.700,-0.01,0.2131,0.21320,5.000
5,82.800,0.00,0.1132,0.11330,5.000
5,82.900,-0.01,0.0131,0.01320,5.000
5,83.050,-0.01,-0.0002,-0.00010,5.000
5,83.150,0.00,-0.0003,-0.00020,5.000
5,83.250,-0.01,-0.0003,-0.00020,5.000
5,83.350,-0.01,-0.0003,-0.00020,5.000
5,83.450,-0.01,-0.0003,-0.00020,5.000
5,83.550,-0.01,-0.0003,-0.00020,5.000
5,83.650,-0.01,-0.0003,-0.00020,5.000
5,83.750,-0.01,-0.0003,-0.00020,5.000
5,83.850,0.00,-0.0003,-0.00020,5.000
5,83.950,-0.01,-0.0003,-0.00020,5.000
5,84.050,0.00,-0.0003,-0.00020,5.000
5,84.150,0.00,-0.0003,-0.00020,5.000
5,84.250,-0.01,-0.0003,-0.00020,5.000
5,84.350,0.00,-0.0003,-0.00020,5.000
5,84.450,0.00,-0.0003,-0.00020,5.000
5,84.550,-0.01,-0.0003,-0.00020,5.000
5,84.650,-0.01,-0.0003,-0.00020,5.000
5,84.750,0.00,-0.0003,-0.00020,5.000
5,84.850,-0.01,-0.0003,-0.00020,5.000
5,84.950,-0.01,-0.0003,-0.00020,5.000
5,85.050,-0.01,-0.0003,-0.00020,5.000
5,85.150,0.00,-0.0003,-0.00020,5.000
5,85.250,0.00,-0.0003,-0.00020,5.000
5,85.350,-0.01,-0.0002,-0.00010,5.000
5,85.450,-0.01,-0.0002,-0.00010,5.000
5,85.550,0.00,-0.0002,-0.00010,5.000
5,85.650,0.00,-0.0002,-0.00010,5.000
5,85.750,-0.01,-0.0002,-0.00010,5.000
5,85.850,0.00,-0.0002,-0.00010,5.000
5,85.950,0.00,-0.0002,-0.00010,5.000
5,86.100,-0.01,-0.0002,-0.00010,5.000
5,86.200,0.00,-0.0002,-0.00010,5.000
5,86.300,-0.01,-0.0002,-0.00010,5.000
5,86.400,0.00,-0.0002,-0.00010,5.000
5,86.500,-0.01,-0.0002,-0.00010,5.000
5,86.600,0.00,-0.0002,-0.00010,5.000
5,86.700,0.00,-0.0002,-0.00010,5.000
5,86.800,0.00,-0.0002,-0.00010,5.000
5,86.900,-0.01,-0.0002,-0.00010,5.000
5,86.950,-0.01,-0.0002,-0.00010,5.000