File: calibDATA_loadcell/data/date_30:1:2018/MTSdata_date_1.30/radhen_10cyc_black_-20deg_1mms_5N.txt
""
"Test Method","Radhen_Load_Cntrl_Cmprsn_250N_12-7.msm"
"Sample I. D.","Sample1.mss"
"Specimen Number","13"

"TheCycle_Output ()","_Time (s)","_Load (N)","_Extension (mm)","RealTimeDepth (mm)","CycleNumber ()"

1,0.150,-0.01,0.0000,0.00000,1.000
1,0.280,0.01,0.1064,0.10640,1.000
1,0.400,0.01,0.2265,0.22650,1.000
1,0.520,0.01,0.3466,0.34660,1.000
1,0.640,0.01,0.4665,0.46650,1.000
1,0.760,0.01,0.5866,0.58660,1.000
1,0.880,0.01,0.7065,0.70650,1.000
1,1.000,0.01,0.8267,0.82670,1.000
1,1.120,0.01,0.9466,0.94660,1.000
1,1.240,0.01,1.0668,1.06680,1.000
1,1.360,0.01,1.1867,1.18670,1.000
1,1.480,0.00,1.3066,1.30660,1.000
1,1.600,0.00,1.4267,1.42670,1.000
1,1.720,0.00,1.5467,1.54670,1.000
1,1.840,0.00,1.6666,1.66660,1.000
1,1.960,0.01,1.7867,1.78670,1.000
1,2.080,0.01,1.9067,1.90670,1.000
1,2.200,0.00,2.0266,2.02660,1.000
1,2.320,0.00,2.1468,2.14680,1.000
1,2.440,0.01,2.2668,2.26680,1.000
1,2.560,0.01,2.3868,2.38680,1.000
1,2.680,0.00,2.5068,2.50680,1.000
1,2.800,0.01,2.6268,2.62680,1.000
1,2.920,0.00,2.7468,2.74680,1.000
1,3.040,0.01,2.8667,2.86670,1.000
1,3.160,0.01,2.9868,2.98680,1.000
1,3.280,0.01,3.1068,3.10680,1.000
1,3.400,0.01,3.2269,3.22690,1.000
1,3.520,0.01,3.3466,3.34660,1.000
1,3.640,0.01,3.4667,3.46670,1.000
1,3.760,0.01,3.5868,3.58680,1.000
1,3.880,0.00,3.7068,3.70680,1.000
1,4.000,0.01,3.8267,3.82670,1.000
1,4.120,0.01,3.9467,3.94670,1.000
1,4.240,0.07,4.0667,4.06670,1.000
1,4.360,0.24,4.1867,4.18670,1.000
1,4.480,0.54,4.3068,4.30680,1.000
1,4.600,0.97,4.4267,4.42670,1.000
1,4.720,1.56,4.5467,4.54670,1.000
1,4.840,2.32,4.6667,4.66670,1.000
1,4.960,3.29,4.7867,4.78670,1.000
1,5.080,4.44,4.9067,4.90670,1.000
1,5.210,5.57,4.9939,4.99390,1.000
1,5.330,3.90,4.8796,4.87960,1.000
1,5.450,2.65,4.7597,4.75970,1.000
1,5.570,1.74,4.6397,4.63970,1.000
1,5.690,1.09,4.5198,4.51980,1.000
1,5.810,0.63,4.3998,4.39980,1.000
1,5.930,0.30,4.2798,4.27980,1.000
1,6.050,0.10,4.1596,4.15960,1.000
1,6.170,0.01,4.0396,4.03960,1.000
1,6.290,0.01,3.9196,3.91960,1.000
1,6.410,0.01,3.7996,3.79960,1.000
1,6.530,0.01,3.6796,3.67960,1.000
1,6.650,0.01,3.5596,3.55960,1.000
1,6.770,0.01,3.4396,3.43960,1.000
1,6.890,0.01,3.3195,3.31950,1.000
1,7.010,0.01,3.1997,3.19970,1.000
1,7.130,0.01,3.0796,3.07960,1.000
1,7.250,0.01,2.9596,2.95960,1.000
1,7.370,0.01,2.8395,2.83950,1.000
1,7.490,0.00,2.7195,2.71950,1.000
1,7.610,0.01,2.5995,2.59950,1.000
1,7.730,0.00,2.4794,2.47940,1.000
1,7.850,0.01,2.3596,2.35960,1.000
1,7.970,0.01,2.2395,2.23950,1.000
1,8.090,0.01,2.1194,2.11940,1.000
1,8.210,0.01,1.9994,1.99940,1.000
1,8.330,0.01,1.8795,1.87950,1.000
1,8.450,0.01,1.7595,1.75950,1.000
1,8.570,0.01,1.6395,1.63950,1.000
1,8.690,0.01,1.5195,1.51950,1.000
1,8.810,0.01,1.3995,1.39950,1.000
1,8.930,0.01,1.2793,1.27930,1.000
1,9.050,0.01,1.1594,1.15940,1.000
1,9.170,0.01,1.0395,1.03950,1.000
1,9.290,0.01,0.9194,0.91940,1.000
1,9.410,0.01,0.7995,0.79950,1.000
1,9.530,0.01,0.6793,0.67930,1.000
1,9.650,0.01,0.5594,0.55940,1.000
1,9.770,0.01,0.4394,0.43940,1.000
1,9.890,0.01,0.3194,0.31940,1.000
1,10.010,0.01,0.1993,0.19930,1.000
1,10.130,0.00,0.0792,0.07920,1.000
1,10.260,0.01,-0.0400,-0.04000,1.000
1,10.380,0.01,-0.0002,-0.00020,1.000
1,10.500,0.01,-0.0002,-0.00020,1.000
1,10.620,0.01,-0.0002,-0.00020,1.000
1,10.740,0.01,-0.0002,-0.00020,1.000
1,10.860,0.01,-0.0002,-0.00020,1.000
1,10.980,0.01,-0.0002,-0.00020,1.000
1,11.100,0.00,-0.0002,-0.00020,1.000
1,11.220,0.00,-0.0002,-0.00020,1.000
1,11.340,0.01,-0.0002,-0.00020,1.000
1,11.460,0.01,-0.0002,-0.00020,1.000
1,11.580,0.01,-0.0002,-0.00020,1.000
1,11.700,0.01,-0.0002,-0.00020,1.000
1,11.820,0.01,-0.0002,-0.00020,1.000
1,11.940,0.01,-0.0002,-0.00020,1.000
1,12.060,0.00,-0.0002,-0.00020,1.000
1,12.180,0.01,-0.0002,-0.00020,1.000
1,12.300,0.01,-0.0002,-0.00020,1.000
1,12.420,0.00,-0.0002,-0.00020,1.000
1,12.540,0.01,-0.0002,-0.00020,1.000
1,12.660,0.00,-0.0002,-0.00020,1.000
1,12.780,0.01,-0.0002,-0.00020,1.000
1,12.900,0.01,-0.0002,-0.00020,1.000
1,13.020,0.00,-0.0002,-0.00020,1.000
1,13.140,0.01,-0.0002,-0.00020,1.000
1,13.260,0.01,-0.0002,-0.00020,1.000
1,13.390,0.00,-0.0002,-0.00020,1.000
1,13.510,0.01,-0.0002,-0.00020,1.000
1,13.630,0.01,-0.0002,-0.00020,1.000
1,13.750,0.01,-0.0002,-0.00020,1.000
1,13.870,0.01,-0.0001,-0.00010,1.000
1,13.990,0.00,-0.0001,-0.00010,1.000
1,14.110,0.00,-0.0001,-0.00010,1.000
1,14.230,0.01,-0.0001,-0.00010,1.000
1,14.350,0.00,-0.0001,-0.00010,1.000
1,14.470,0.01,-0.0001,-0.00010,1.000
1,14.590,0.01,-0.0001,-0.00010,1.000
1,14.710,0.00,-0.0001,-0.00010,1.000
1,14.830,0.00,-0.0001,-0.00010,1.000
1,14.950,0.00,-0.0001,-0.00010,1.000
1,15.070,0.00,-0.0001,-0.00010,1.000
1,15.190,0.01,-0.0001,-0.00010,1.000
1,15.310,0.01,-0.0001,-0.00010,1.000
1,15.430,0.00,-0.0001,-0.00010,1.000
1,15.550,0.00,-0.0001,-0.00010,1.000
1,15.670,0.01,-0.0001,-0.00010,1.000
1,15.790,0.01,-0.0001,-0.00010,1.000
1,15.910,0.01,-0.0001,-0.00010,1.000
1,16.030,0.01,-0.0001,-0.00010,1.000
1,16.150,0.00,-0.0001,-0.00010,1.000
1,16.270,0.01,-0.0001,-0.00010,1.000
2,16.480,0.00,0.0004,0.00040,2.000
2,16.600,0.00,0.1085,0.10850,2.000
2,16.720,0.00,0.2287,0.22870,2.000
2,16.840,0.00,0.3487,0.34870,2.000
2,16.960,0.00,0.4687,0.46870,2.000
2,17.080,0.01,0.5887,0.58870,2.000
2,17.200,0.00,0.7087,0.70870,2.000
2,17.320,0.00,0.8286,0.82860,2.000
2,17.440,0.00,0.9487,0.94870,2.000
2,17.560,0.01,1.0688,1.06880,2.000
2,17.680,0.00,1.1887,1.18870,2.000
2,17.800,0.00,1.3086,1.30860,2.000
2,17.920,0.01,1.4287,1.42870,2.000
2,18.040,0.00,1.5488,1.54880,2.000
2,18.160,0.00,1.6687,1.66870,2.000
2,18.280,0.01,1.7887,1.78870,2.000
2,18.400,0.01,1.9087,1.90870,2.000
2,18.520,0.00,2.0286,2.02860,2.000
2,18.640,0.00,2.1487,2.14870,2.000
2,18.760,0.00,2.2687,2.26870,2.000
2,18.880,0.00,2.3888,2.38880,2.000
2,19.000,0.00,2.5087,2.50870,2.000
2,19.120,0.00,2.6287,2.62870,2.000
2,19.240,0.00,2.7488,2.74880,2.000
2,19.360,0.00,2.8688,2.86880,2.000
2,19.480,0.01,2.9888,2.98880,2.000
2,19.600,0.01,3.1089,3.10890,2.000
2,19.720,0.01,3.2288,3.22880,2.000
2,19.840,0.00,3.3486,3.34860,2.000
2,19.960,0.00,3.4688,3.46880,2.000
2,20.080,0.00,3.5888,3.58880,2.000
2,20.200,0.00,3.7087,3.70870,2.000
2,20.320,0.01,3.8287,3.82870,2.000
2,20.440,0.00,3.9486,3.94860,2.000
2,20.560,0.06,4.0688,4.06880,2.000
2,20.680,0.23,4.1886,4.18860,2.000
2,20.800,0.53,4.3088,4.30880,2.000
2,20.920,0.97,4.4288,4.42880,2.000
2,21.040,1.56,4.5487,4.54870,2.000
2,21.160,2.33,4.6687,4.66870,2.000
2,21.280,3.30,4.7888,4.78880,2.000
2,21.400,4.45,4.9087,4.90870,2.000
2,21.520,5.72,5.0093,5.00930,2.000
2,21.640,4.25,4.9094,4.90940,2.000
2,21.760,2.89,4.7896,4.78960,2.000
2,21.880,1.91,4.6694,4.66940,2.000
2,22.000,1.21,4.5495,4.54950,2.000
2,22.120,0.72,4.4295,4.42950,2.000
2,22.240,0.37,4.3095,4.30950,2.000
2,22.360,0.13,4.1896,4.18960,2.000
2,22.480,0.01,4.0694,4.06940,2.000
2,22.600,0.00,3.9493,3.94930,2.000
2,22.720,0.01,3.8294,3.82940,2.000
2,22.840,0.00,3.7093,3.70930,2.000
2,22.960,0.01,3.5893,3.58930,2.000
2,23.080,0.01,3.4694,3.46940,2.000
2,23.200,0.00,3.3492,3.34920,2.000
2,23.320,0.01,3.2295,3.22950,2.000
2,23.440,0.01,3.1095,3.10950,2.000
2,23.560,0.01,2.9893,2.98930,2.000
2,23.680,0.01,2.8693,2.86930,2.000
2,23.800,0.00,2.7493,2.74930,2.000
2,23.920,0.01,2.6292,2.62920,2.000
2,24.040,0.01,2.5093,2.50930,2.000
2,24.160,0.00,2.3894,2.38940,2.000
2,24.280,0.00,2.2694,2.26940,2.000
2,24.400,0.01,2.1494,2.14940,2.000
2,24.520,0.00,2.0292,2.02920,2.000
2,24.640,0.00,1.9093,1.90930,2.000
2,24.760,0.01,1.7893,1.78930,2.000
2,24.880,0.01,1.6694,1.66940,2.000
2,25.000,0.00,1.5493,1.54930,2.000
2,25.120,0.01,1.4293,1.42930,2.000
2,25.240,0.01,1.3093,1.30930,2.000
2,25.360,0.01,1.1894,1.18940,2.000
2,25.480,0.00,1.0693,1.06930,2.000
2,25.600,0.00,0.9494,0.94940,2.000
2,25.720,0.01,0.8294,0.82940,2.000
2,25.840,0.00,0.7092,0.70920,2.000
2,25.960,0.00,0.5892,0.58920,2.000
2,26.080,0.01,0.4693,0.46930,2.000
2,26.200,0.01,0.3492,0.34920,2.000
2,26.320,0.00,0.2294,0.22940,2.000
2,26.440,0.00,0.1091,0.10910,2.000
2,26.560,0.01,-0.0106,-0.01060,2.000
2,26.680,0.01,-0.0113,-0.01130,2.000
2,26.800,0.00,-0.0002,-0.00020,2.000
2,26.920,0.00,-0.0002,-0.00020,2.000
2,27.040,0.01,-0.0002,-0.00020,2.000
2,27.160,0.01,-0.0002,-0.00020,2.000
2,27.280,0.01,-0.0002,-0.00020,2.000
2,27.400,0.00,-0.0002,-0.00020,2.000
2,27.520,0.00,-0.0002,-0.00020,2.000
2,27.640,0.00,-0.0002,-0.00020,2.000
2,27.760,0.01,-0.0002,-0.00020,2.000
2,27.880,0.01,-0.0002,-0.00020,2.000
2,28.000,0.00,-0.0002,-0.00020,2.000
2,28.120,0.01,-0.0002,-0.00020,2.000
2,28.240,0.00,-0.0002,-0.00020,2.000
2,28.360,0.01,-0.0002,-0.00020,2.000
2,28.480,0.00,-0.0002,-0.00020,2.000
2,28.600,0.00,-0.0002,-0.00020,2.000
2,28.720,0.00,-0.0002,-0.00020,2.000
2,28.840,0.00,-0.0002,-0.00020,2.000
2,28.960,0.01,-0.0002,-0.00020,2.000
2,29.080,0.01,-0.0002,-0.00020,2.000
2,29.200,0.00,-0.0002,-0.00020,2.000
2,29.320,0.00,-0.0002,-0.00020,2.000
2,29.440,0.01,-0.0002,-0.00020,2.000
2,29.560,0.01,-0.0002,-0.00020,2.000
2,29.700,0.01,-0.0002,-0.00020,2.000
2,29.820,0.01,-0.0002,-0.00020,2.000
2,29.940,0.00,-0.0002,-0.00020,2.000
2,30.060,0.00,-0.0002,-0.00020,2.000
2,30.180,0.01,-0.0002,-0.00020,2.000
2,30.300,0.01,-0.0002,-0.00020,2.000
2,30.420,0.00,-0.0001,-0.00010,2.000
2,30.540,0.01,-0.0001,-0.00010,2.000
2,30.660,0.01,-0.0001,-0.00010,2.000
2,30.780,0.01,-0.0001,-0.00010,2.000
2,30.900,0.01,-0.0001,-0.00010,2.000
2,31.020,0.00,-0.0001,-0.00010,2.000
2,31.140,0.00,-0.0001,-0.00010,2.000
2,31.260,0.01,-0.0001,-0.00010,2.000
2,31.380,0.00,-0.0001,-0.00010,2.000
2,31.500,0.01,-0.0001,-0.00010,2.000
2,31.620,0.01,-0.0001,-0.00010,2.000
2,31.740,0.01,-0.0001,-0.00010,2.000
2,31.860,0.00,-0.0001,-0.00010,2.000
2,31.980,0.01,-0.0001,-0.00010,2.000
2,32.100,0.00,-0.0001,-0.00010,2.000
2,32.220,0.00,-0.0001,-0.00010,2.000
2,32.340,0.00,-0.0001,-0.00010,2.000
2,32.460,0.01,-0.0001,-0.00010,2.000
2,32.580,0.00,-0.0001,-0.00010,2.000
3,32.830,0.00,0.0153,0.01530,3.000
3,32.950,0.00,0.1353,0.13530,3.000
3,33.070,0.00,0.2556,0.25560,3.000
3,33.190,0.00,0.3755,0.37550,3.000
3,33.310,0.00,0.4955,0.49550,3.000
3,33.430,-0.01,0.6156,0.61560,3.000
3,33.550,0.00,0.7355,0.73550,3.000
3,33.670,0.00,0.8556,0.85560,3.000
3,33.790,0.00,0.9756,0.97560,3.000
3,33.910,-0.01,1.0957,1.09570,3.000
3,34.030,0.00,1.2157,1.21570,3.000
3,34.150,0.00,1.3357,1.33570,3.000
3,34.270,0.00,1.4557,1.45570,3.000
3,34.390,0.00,1.5758,1.57580,3.000
3,34.510,0.00,1.6957,1.69570,3.000
3,34.630,0.00,1.8157,1.81570,3.000
3,34.750,0.00,1.9358,1.93580,3.000
3,34.870,0.00,2.0557,2.05570,3.000
3,34.990,0.00,2.1757,2.17570,3.000
3,35.110,0.00,2.2958,2.29580,3.000
3,35.230,0.00,2.4159,2.41590,3.000
3,35.350,0.00,2.5358,2.53580,3.000
3,35.470,0.00,2.6558,2.65580,3.000
3,35.590,0.00,2.7759,2.77590,3.000
3,35.710,0.00,2.8960,2.89600,3.000
3,35.830,0.00,3.0160,3.01600,3.000
3,35.950,0.00,3.1361,3.13610,3.000
3,36.070,0.00,3.2560,3.25600,3.000
3,36.190,0.00,3.3758,3.37580,3.000
3,36.310,0.00,3.4960,3.49600,3.000
3,36.430,0.00,3.6159,3.61590,3.000
3,36.550,0.00,3.7358,3.73580,3.000
3,36.670,0.00,3.8560,3.85600,3.000
3,36.790,0.00,3.9759,3.97590,3.000
3,36.910,0.08,4.0959,4.09590,3.000
3,37.030,0.28,4.2159,4.21590,3.000
3,37.150,0.62,4.3359,4.33590,3.000
3,37.270,1.08,4.4559,4.45590,3.000
3,37.390,1.70,4.5758,4.57580,3.000
3,37.510,2.53,4.6959,4.69590,3.000
3,37.630,3.54,4.8159,4.81590,3.000
3,37.750,4.74,4.9359,4.93590,3.000
3,37.880,5.24,4.9683,4.96830,3.000
3,38.000,3.51,4.8486,4.84860,3.000
3,38.120,2.37,4.7288,4.72880,3.000
3,38.240,1.53,4.6086,4.60860,3.000
3,38.360,0.93,4.4887,4.48870,3.000
3,38.480,0.52,4.3688,4.36880,3.000
3,38.600,0.23,4.2487,4.24870,3.000
3,38.720,0.07,4.1286,4.12860,3.000
3,38.840,-0.01,4.0086,4.00860,3.000
3,38.960,0.00,3.8886,3.88860,3.000
3,39.080,0.00,3.7685,3.76850,3.000
3,39.200,0.00,3.6485,3.64850,3.000
3,39.320,0.00,3.5286,3.52860,3.000
3,39.440,-0.01,3.4084,3.40840,3.000
3,39.560,0.00,3.2884,3.28840,3.000
3,39.680,0.00,3.1687,3.16870,3.000
3,39.800,0.00,3.0486,3.04860,3.000
3,39.920,0.00,2.9286,2.92860,3.000
3,40.040,0.00,2.8085,2.80850,3.000
3,40.160,0.00,2.6884,2.68840,3.000
3,40.280,0.00,2.5685,2.56850,3.000
3,40.400,0.00,2.4485,2.44850,3.000
3,40.520,0.00,2.3285,2.32850,3.000
3,40.640,0.00,2.2086,2.20860,3.000
3,40.760,0.00,2.0884,2.08840,3.000
3,40.880,0.00,1.9684,1.96840,3.000
3,41.000,0.00,1.8484,1.84840,3.000
3,41.120,0.00,1.7285,1.72850,3.000
3,41.240,0.00,1.6085,1.60850,3.000
3,41.360,0.00,1.4884,1.48840,3.000
3,41.480,0.00,1.3683,1.36830,3.000
3,41.600,0.00,1.2483,1.24830,3.000
3,41.720,0.00,1.1285,1.12850,3.000
3,41.840,0.00,1.0085,1.00850,3.000
3,41.960,0.00,0.8885,0.88850,3.000
3,42.080,0.00,0.7683,0.76830,3.000
3,42.200,0.00,0.6483,0.64830,3.000
3,42.320,0.00,0.5283,0.52830,3.000
3,42.440,0.00,0.4084,0.40840,3.000
3,42.560,0.00,0.2884,0.28840,3.000
3,42.680,0.00,0.1683,0.16830,3.000
3,42.800,0.00,0.0481,0.04810,3.000
3,42.920,0.00,-0.0408,-0.04080,3.000
3,43.040,0.00,-0.0002,-0.00020,3.000
3,43.160,0.00,-0.0002,-0.00020,3.000
3,43.280,0.01,-0.0002,-0.00020,3.000
3,43.400,0.00,-0.0002,-0.00020,3.000
3,43.520,0.00,-0.0002,-0.00020,3.000
3,43.640,0.00,-0.0002,-0.00020,3.000
3,43.760,0.00,-0.0002,-0.00020,3.000
3,43.880,0.00,-0.0002,-0.00020,3.000
3,44.000,0.00,-0.0002,-0.00020,3.000
3,44.120,0.00,-0.0002,-0.00020,3.000
3,44.240,0.00,-0.0002,-0.00020,3.000
3,44.360,0.01,-0.0002,-0.00020,3.000
3,44.480,0.00,-0.0002,-0.00020,3.000
3,44.600,0.00,-0.0002,-0.00020,3.000
3,44.720,0.00,-0.0002,-0.00020,3.000
3,44.840,0.00,-0.0002,-0.00020,3.000
3,44.960,0.00,-0.0002,-0.00020,3.000
3,45.080,0.00,-0.0002,-0.00020,3.000
3,45.200,0.00,-0.0002,-0.00020,3.000
3,45.320,0.00,-0.0002,-0.00020,3.000
3,45.440,0.00,-0.0002,-0.00020,3.000
3,45.560,0.00,-0.0002,-0.00020,3.000
3,45.680,0.00,-0.0002,-0.00020,3.000
3,45.800,0.00,-0.0002,-0.00020,3.000
3,45.920,-0.01,-0.0002,-0.00020,3.000
3,46.050,0.00,-0.0002,-0.00020,3.000
3,46.170,0.00,-0.0002,-0.00020,3.000
3,46.290,0.00,-0.0001,-0.00010,3.000
3,46.410,0.00,-0.0001,-0.00010,3.000
3,46.530,0.00,-0.0001,-0.00010,3.000
3,46.650,0.00,-0.0001,-0.00010,3.000
3,46.770,0.00,-0.0001,-0.00010,3.000
3,46.890,0.00,-0.0001,-0.00010,3.000
3,47.010,0.00,-0.0001,-0.00010,3.000
3,47.130,0.00,-0.0001,-0.00010,3.000
3,47.250,0.00,-0.0001,-0.00010,3.000
3,47.370,0.00,-0.0001,-0.00010,3.000
3,47.490,0.00,-0.0001,-0.00010,3.000
3,47.610,0.00,-0.0001,-0.00010,3.000
3,47.730,-0.01,-0.0001,-0.00010,3.000
3,47.850,0.00,-0.0001,-0.00010,3.000
3,47.970,0.00,-0.0001,-0.00010,3.000
3,48.090,0.00,-0.0001,-0.00010,3.000
3,48.210,0.00,-0.0001,-0.00010,3.000
3,48.330,-0.01,-0.0001,-0.00010,3.000
3,48.450,0.00,-0.0001,-0.00010,3.000
3,48.570,0.00,-0.0001,-0.00010,3.000
3,48.690,0.00,-0.0001,-0.00010,3.000
3,48.810,0.00,-0.0001,-0.00010,3.000
3,48.930,0.00,-0.0001,-0.00010,3.000
4,49.160,0.00,0.0477,0.04770,4.000
4,49.280,0.00,0.1676,0.16760,4.000
4,49.400,0.01,0.2877,0.28770,4.000
4,49.520,0.00,0.4078,0.40780,4.000
4,49.640,0.00,0.5278,0.52780,4.000
4,49.760,0.00,0.6477,0.64770,4.000
4,49.880,0.00,0.7678,0.76780,4.000
4,50.000,0.01,0.8877,0.88770,4.000
4,50.120,0.00,1.0078,1.00780,4.000
4,50.240,0.00,1.1278,1.12780,4.000
4,50.360,0.00,1.2477,1.24770,4.000
4,50.480,0.00,1.3677,1.36770,4.000
4,50.600,0.00,1.4879,1.48790,4.000
4,50.720,0.00,1.6079,1.60790,4.000
4,50.840,0.00,1.7279,1.72790,4.000
4,50.960,0.00,1.8479,1.84790,4.000
4,51.080,0.00,1.9677,1.96770,4.000
4,51.200,0.00,2.0878,2.08780,4.000
4,51.320,0.01,2.2079,2.20790,4.000
4,51.440,0.01,2.3278,2.32780,4.000
4,51.560,0.00,2.4479,2.44790,4.000
4,51.680,0.00,2.5678,2.56780,4.000
4,51.800,0.00,2.6878,2.68780,4.000
4,51.920,0.00,2.8079,2.80790,4.000
4,52.040,0.01,2.9280,2.92800,4.000
4,52.160,0.00,3.0479,3.04790,4.000
4,52.280,0.01,3.1680,3.16800,4.000
4,52.400,0.00,3.2879,3.28790,4.000
4,52.520,0.00,3.4079,3.40790,4.000
4,52.640,0.00,3.5280,3.52800,4.000
4,52.760,0.00,3.6479,3.64790,4.000
4,52.880,0.00,3.7679,3.76790,4.000
4,53.000,0.00,3.8879,3.88790,4.000
4,53.120,0.01,4.0078,4.00780,4.000
4,53.240,0.12,4.1279,4.12790,4.000
4,53.360,0.36,4.2479,4.24790,4.000
4,53.480,0.73,4.3680,4.36800,4.000
4,53.600,1.22,4.4879,4.48790,4.000
4,53.720,1.90,4.6078,4.60780,4.000
4,53.840,2.78,4.7278,4.72780,4.000
4,53.960,3.84,4.8478,4.84780,4.000
4,54.080,5.09,4.9679,4.96790,4.000
4,54.210,4.98,4.9583,4.95830,4.000
4,54.330,3.37,4.8386,4.83860,4.000
4,54.450,2.27,4.7187,4.71870,4.000
4,54.570,1.47,4.5985,4.59850,4.000
4,54.690,0.89,4.4786,4.47860,4.000
4,54.810,0.49,4.3587,4.35870,4.000
4,54.930,0.21,4.2387,4.23870,4.000
4,55.050,0.06,4.1186,4.11860,4.000
4,55.170,0.00,3.9986,3.99860,4.000
4,55.290,0.00,3.8785,3.87850,4.000
4,55.410,0.00,3.7584,3.75840,4.000
4,55.530,0.00,3.6385,3.63850,4.000
4,55.650,0.00,3.5185,3.51850,4.000
4,55.770,0.01,3.3984,3.39840,4.000
4,55.890,0.00,3.2785,3.27850,4.000
4,56.010,0.00,3.1586,3.15860,4.000
4,56.130,0.01,3.0384,3.03840,4.000
4,56.250,0.00,2.9184,2.91840,4.000
4,56.370,0.00,2.7985,2.79850,4.000
4,56.490,0.00,2.6784,2.67840,4.000
4,56.610,0.00,2.5584,2.55840,4.000
4,56.730,0.00,2.4385,2.43850,4.000
4,56.850,0.00,2.3185,2.31850,4.000
4,56.970,0.00,2.1984,2.19840,4.000
4,57.090,0.00,2.0783,2.07830,4.000
4,57.210,0.00,1.9583,1.95830,4.000
4,57.330,0.00,1.8385,1.83850,4.000
4,57.450,0.00,1.7184,1.71840,4.000
4,57.570,0.00,1.5984,1.59840,4.000
4,57.690,0.00,1.4784,1.47840,4.000
4,57.810,0.01,1.3585,1.35850,4.000
4,57.930,0.00,1.2383,1.23830,4.000
4,58.050,0.00,1.1185,1.11850,4.000
4,58.170,0.00,0.9984,0.99840,4.000
4,58.290,0.00,0.8784,0.87840,4.000
4,58.410,0.00,0.7583,0.75830,4.000
4,58.530,0.00,0.6384,0.63840,4.000
4,58.650,0.00,0.5184,0.51840,4.000
4,58.770,0.00,0.3983,0.39830,4.000
4,58.890,0.00,0.2784,0.27840,4.000
4,59.010,0.00,0.1583,0.15830,4.000
4,59.130,0.00,0.0383,0.03830,4.000
4,59.260,0.00,-0.0312,-0.03120,4.000
4,59.380,0.00,-0.0002,-0.00020,4.000
4,59.500,0.00,-0.0002,-0.00020,4.000
4,59.620,0.00,-0.0002,-0.00020,4.000
4,59.740,0.00,-0.0002,-0.00020,4.000
4,59.860,0.01,-0.0002,-0.00020,4.000
4,59.980,0.00,-0.0002,-0.00020,4.000
4,60.100,0.00,-0.0002,-0.00020,4.000
4,60.220,0.00,-0.0002,-0.00020,4.000
4,60.340,0.00,-0.0002,-0.00020,4.000
4,60.460,0.00,-0.0002,-0.00020,4.000
4,60.580,0.00,-0.0002,-0.00020,4.000
4,60.700,0.00,-0.0002,-0.00020,4.000
4,60.820,0.00,-0.0002,-0.00020,4.000
4,60.940,0.00,-0.0002,-0.00020,4.000
4,61.060,0.00,-0.0002,-0.00020,4.000
4,61.180,0.00,-0.0002,-0.00020,4.000
4,61.300,0.00,-0.0002,-0.00020,4.000
4,61.420,0.00,-0.0002,-0.00020,4.000
4,61.540,0.00,-0.0002,-0.00020,4.000
4,61.660,0.00,-0.0002,-0.00020,4.000
4,61.780,0.00,-0.0002,-0.00020,4.000
4,61.900,0.00,-0.0002,-0.00020,4.000
4,62.020,0.00,-0.0002,-0.00020,4.000
4,62.140,0.00,-0.0002,-0.00020,4.000
4,62.260,0.00,-0.0002,-0.00020,4.000
4,62.390,0.00,-0.0002,-0.00020,4.000
4,62.510,0.00,-0.0002,-0.00020,4.000
4,62.630,0.00,-0.0002,-0.00020,4.000
4,62.750,0.00,-0.0001,-0.00010,4.000
4,62.870,0.00,-0.0001,-0.00010,4.000
4,62.990,0.00,-0.0001,-0.00010,4.000
4,63.110,0.00,-0.0001,-0.00010,4.000
4,63.230,0.00,-0.0001,-0.00010,4.000
4,63.350,0.00,-0.0001,-0.00010,4.000
4,63.470,0.00,-0.0001,-0.00010,4.000
4,63.590,0.00,-0.0001,-0.00010,4.000
4,63.710,0.00,-0.0001,-0.00010,4.000
4,63.830,0.00,-0.0001,-0.00010,4.000
4,63.950,0.00,-0.0001,-0.00010,4.000
4,64.070,0.00,-0.0001,-0.00010,4.000
4,64.190,0.00,-0.0001,-0.00010,4.000
4,64.310,0.00,-0.0001,-0.00010,4.000
4,64.430,0.00,-0.0001,-0.00010,4.000
4,64.550,0.00,-0.0001,-0.00010,4.000
4,64.670,0.00,-0.0001,-0.00010,4.000
4,64.790,0.00,-0.0001,-0.00010,4.000
4,64.910,0.00,-0.0001,-0.00010,4.000
4,65.030,0.00,-0.0001,-0.00010,4.000
4,65.150,0.00,-0.0001,-0.00010,4.000
4,65.270,0.00,-0.0001,-0.00010,4.000
5,65.480,-0.01,0.0476,0.04760,5.000
5,65.600,-0.01,0.1675,0.16750,5.000
5,65.720,0.00,0.2878,0.28780,5.000
5,65.840,-0.01,0.4077,0.40770,5.000
5,65.960,0.00,0.5277,0.52770,5.000
5,66.080,0.00,0.6478,0.64780,5.000
5,66.200,-0.01,0.7677,0.76770,5.000
5,66.320,-0.01,0.8878,0.88780,5.000
5,66.440,-0.01,1.0077,1.00770,5.000
5,66.560,0.00,1.1278,1.12780,5.000
5,66.680,0.00,1.2477,1.24770,5.000
5,66.800,-0.01,1.3677,1.36770,5.000
5,66.920,0.00,1.4878,1.48780,5.000
5,67.040,0.00,1.6078,1.60780,5.000
5,67.160,-0.01,1.7279,1.72790,5.000
5,67.280,-0.01,1.8478,1.84780,5.000
5,67.400,-0.01,1.9679,1.96790,5.000
5,67.520,0.00,2.0878,2.08780,5.000
5,67.640,0.00,2.2079,2.20790,5.000
5,67.760,-0.01,2.3279,2.32790,5.000
5,67.880,-0.01,2.4478,2.44780,5.000
5,68.000,-0.01,2.5677,2.56770,5.000
5,68.120,0.00,2.6878,2.68780,5.000
5,68.240,-0.01,2.8078,2.80780,5.000
5,68.360,-0.01,2.9278,2.92780,5.000
5,68.480,-0.01,3.0479,3.04790,5.000
5,68.600,-0.01,3.1680,3.16800,5.000
5,68.720,-0.01,3.2879,3.28790,5.000
5,68.840,-0.01,3.4078,3.40780,5.000
5,68.960,-0.01,3.5278,3.52780,5.000
5,69.080,0.00,3.6479,3.64790,5.000
5,69.200,0.00,3.7679,3.76790,5.000
5,69.320,-0.01,3.8878,3.88780,5.000
5,69.440,0.00,4.0078,4.00780,5.000
5,69.560,0.11,4.1279,4.12790,5.000
5,69.680,0.35,4.2479,4.24790,5.000
5,69.800,0.72,4.3679,4.36790,5.000
5,69.920,1.22,4.4880,4.48800,5.000
5,70.040,1.90,4.6079,4.60790,5.000
5,70.160,2.77,4.7279,4.72790,5.000
5,70.280,3.83,4.8478,4.84780,5.000
5,70.400,5.09,4.9679,4.96790,5.000
5,70.540,5.08,4.9684,4.96840,5.000
5,70.660,3.45,4.8486,4.84860,5.000
5,70.780,2.32,4.7288,4.72880,5.000
5,70.900,1.50,4.6086,4.60860,5.000
5,71.020,0.92,4.4886,4.48860,5.000
5,71.140,0.51,4.3687,4.36870,5.000
5,71.260,0.22,4.2488,4.24880,5.000
5,71.380,0.06,4.1287,4.12870,5.000
5,71.500,-0.01,4.0086,4.00860,5.000
5,71.620,0.00,3.8886,3.88860,5.000
5,71.740,0.00,3.7685,3.76850,5.000
5,71.860,-0.01,3.6485,3.64850,5.000
5,71.980,0.00,3.5286,3.52860,5.000
5,72.100,-0.01,3.4085,3.40850,5.000
5,72.220,-0.01,3.2884,3.28840,5.000
5,72.340,0.00,3.1688,3.16880,5.000
5,72.460,-0.01,3.0486,3.04860,5.000
5,72.580,-0.01,2.9285,2.92850,5.000
5,72.700,-0.01,2.8085,2.80850,5.000
5,72.820,0.00,2.6885,2.68850,5.000
5,72.940,-0.01,2.5684,2.56840,5.000
5,73.060,-0.01,2.4485,2.44850,5.000
5,73.180,-0.01,2.3285,2.32850,5.000
5,73.300,0.00,2.2085,2.20850,5.000
5,73.420,0.00,2.0883,2.08830,5.000
5,73.540,-0.01,1.9683,1.96830,5.000
5,73.660,-0.01,1.8483,1.84830,5.000
5,73.780,-0.01,1.7284,1.72840,5.000
5,73.900,0.00,1.6085,1.60850,5.000
5,74.020,-0.01,1.4885,1.48850,5.000
5,74.140,-0.01,1.3685,1.36850,5.000
5,74.260,-0.01,1.2483,1.24830,5.000
5,74.380,0.00,1.1285,1.12850,5.000
5,74.500,-0.01,1.0085,1.00850,5.000
5,74.620,-0.01,0.8884,0.88840,5.000
5,74.740,0.00,0.7684,0.76840,5.000
5,74.860,0.00,0.6483,0.64830,5.000
5,74.980,0.00,0.5283,0.52830,5.000
5,75.100,0.00,0.4083,0.40830,5.000
5,75.220,0.00,0.2884,0.28840,5.000
5,75.340,-0.01,0.1683,0.16830,5.000
5,75.460,0.00,0.0482,0.04820,5.000
5,75.590,-0.01,-0.0264,-0.02640,5.000
5,75.710,-0.01,-0.0002,-0.00020,5.000
5,75.830,0.00,-0.0002,-0.00020,5.000
5,75.950,-0.01,-0.0002,-0.00020,5.000
5,76.070,-0.01,-0.0002,-0.00020,5.000
5,76.190,0.00,-0.0002,-0.00020,5.000
5,76.310,-0.01,-0.0002,-0.00020,5.000
5,76.430,-0.01,-0.0002,-0.00020,5.000
5,76.550,-0.01,-0.0002,-0.00020,5.000
5,76.670,-0.01,-0.0002,-0.00020,5.000
5,76.790,-0.01,-0.0002,-0.00020,5.000
5,76.910,-0.01,-0.0002,-0.00020,5.000
5,77.030,-0.01,-0.0002,-0.00020,5.000
5,77.150,-0.01,-0.0002,-0.00020,5.000
5,77.270,0.00,-0.0002,-0.00020,5.000
5,77.390,-0.01,-0.0002,-0.00020,5.000
5,77.510,0.00,-0.0002,-0.00020,5.000
5,77.630,0.00,-0.0002,-0.00020,5.000
5,77.750,0.00,-0.0002,-0.00020,5.000
5,77.870,-0.01,-0.0002,-0.00020,5.000
5,77.990,-0.01,-0.0002,-0.00020,5.000
5,78.110,0.00,-0.0002,-0.00020,5.000
5,78.230,0.00,-0.0002,-0.00020,5.000
5,78.350,0.00,-0.0002,-0.00020,5.000
5,78.470,0.00,-0.0002,-0.00020,5.000
5,78.610,0.00,-0.0001,-0.00010,5.000
5,78.730,0.00,-0.0001,-0.00010,5.000
5,78.850,0.00,-0.0001,-0.00010,5.000
5,78.970,-0.01,-0.0001,-0.00010,5.000
5,79.090,0.00,-0.0001,-0.00010,5.000
5,79.210,-0.01,-0.0001,-0.00010,5.000
5,79.330,0.00,-0.0001,-0.00010,5.000
5,79.450,0.00,-0.0001,-0.00010,5.000
5,79.570,0.00,-0.0001,-0.00010,5.000
5,79.690,0.00,-0.0001,-0.00010,5.000
5,79.810,0.00,-0.0001,-0.00010,5.000
5,79.930,0.00,-0.0001,-0.00010,5.000
5,80.050,0.00,-0.0001,-0.00010,5.000
5,80.170,0.00,-0.0001,-0.00010,5.000
5,80.290,0.00,-0.0001,-0.00010,5.000
5,80.410,0.00,-0.0001,-0.00010,5.000
5,80.530,0.00,-0.0001,-0.00010,5.000
5,80.650,0.00,-0.0001,-0.00010,5.000
5,80.770,0.00,-0.0001,-0.00010,5.000
5,80.890,0.00,-0.0001,-0.00010,5.000
5,81.010,0.00,-0.0001,-0.00010,5.000
5,81.130,0.00,-0.0001,-0.00010,5.000
5,81.250,0.00,-0.0001,-0.00010,5.000
5,81.370,0.00,-0.0001,-0.00010,5.000
5,81.490,0.00,-0.0001,-0.00010,5.000
6,81.720,0.00,0.0000,0.00000,6.000
6,81.850,0.00,0.1064,0.10640,6.000
6,81.970,0.00,0.2266,0.22660,6.000
6,82.090,-0.01,0.3466,0.34660,6.000
6,82.210,0.00,0.4665,0.46650,6.000
6,82.330,0.00,0.5866,0.58660,6.000
6,82.450,0.00,0.7066,0.70660,6.000
6,82.570,0.00,0.8266,0.82660,6.000
6,82.690,0.00,0.9466,0.94660,6.000
6,82.810,0.00,1.0667,1.06670,6.000
6,82.930,0.00,1.1867,1.18670,6.000
6,83.050,-0.01,1.3067,1.30670,6.000
6,83.170,-0.01,1.4267,1.42670,6.000
6,83.290,0.00,1.5467,1.54670,6.000
6,83.410,0.00,1.6666,1.66660,6.000
6,83.530,0.00,1.7866,1.78660,6.000
6,83.650,0.00,1.9068,1.90680,6.000
6,83.770,0.00,2.0266,2.02660,6.000
6,83.890,0.00,2.1466,2.14660,6.000
6,84.010,0.00,2.2667,2.26670,6.000
6,84.130,0.00,2.3867,2.38670,6.000
6,84.250,0.00,2.5067,2.50670,6.000
6,84.370,0.00,2.6266,2.62660,6.000
6,84.490,-0.01,2.7468,2.74680,6.000
6,84.610,0.00,2.8667,2.86670,6.000
6,84.730,-0.01,2.9867,2.98670,6.000
6,84.850,0.00,3.1069,3.10690,6.000
6,84.970,-0.01,3.2268,3.22680,6.000
6,85.090,0.00,3.3466,3.34660,6.000
6,85.210,0.00,3.4667,3.46670,6.000
6,85.330,0.00,3.5869,3.58690,6.000
6,85.450,0.00,3.7067,3.70670,6.000
6,85.570,0.00,3.8267,3.82670,6.000
6,85.690,0.00,3.9468,3.94680,6.000
6,85.810,0.05,4.0668,4.06680,6.000
6,85.930,0.22,4.1867,4.18670,6.000
6,86.050,0.52,4.3068,4.30680,6.000
6,86.170,0.96,4.4270,4.42700,6.000
6,86.290,1.54,4.5467,4.54670,6.000
6,86.410,2.31,4.6668,4.66680,6.000
6,86.530,3.28,4.7867,4.78670,6.000
6,86.650,4.44,4.9068,4.90680,6.000
6,86.790,5.67,5.0025,5.00250,6.000
6,86.910,3.96,4.8876,4.88760,6.000
6,87.030,2.69,4.7677,4.76770,6.000
6,87.150,1.77,4.6476,4.64760,6.000
6,87.270,1.10,4.5277,4.52770,6.000
6,87.390,0.64,4.4078,4.40780,6.000
6,87.510,0.31,4.2877,4.28770,6.000
6,87.630,0.10,4.1677,4.16770,6.000
6,87.750,0.00,4.0476,4.04760,6.000
6,87.870,0.00,3.9275,3.92750,6.000
6,87.990,0.00,3.8075,3.80750,6.000
6,88.110,0.00,3.6876,3.68760,6.000
6,88.230,0.00,3.5676,3.56760,6.000
6,88.350,-0.01,3.4475,3.44750,6.000
6,88.470,0.00,3.3274,3.32740,6.000
6,88.590,0.00,3.2077,3.20770,6.000
6,88.710,0.00,3.0877,3.08770,6.000
6,88.830,0.00,2.9675,2.96750,6.000
6,88.950,-0.01,2.8476,2.84760,6.000
6,89.070,0.00,2.7275,2.72750,6.000
6,89.190,0.00,2.6075,2.60750,6.000
6,89.310,0.00,2.4875,2.48750,6.000
6,89.430,0.00,2.3675,2.36750,6.000
6,89.550,0.00,2.2476,2.24760,6.000
6,89.670,-0.01,2.1274,2.12740,6.000
6,89.790,0.00,2.0074,2.00740,6.000
6,89.910,0.00,1.8874,1.88740,6.000
6,90.030,0.00,1.7675,1.76750,6.000
6,90.150,0.00,1.6475,1.64750,6.000
6,90.270,-0.01,1.5276,1.52760,6.000
6,90.390,-0.01,1.4074,1.40740,6.000
6,90.510,0.00,1.2874,1.28740,6.000
6,90.630,0.00,1.1674,1.16740,6.000
6,90.750,0.00,1.0474,1.04740,6.000
6,90.870,0.00,0.9274,0.92740,6.000
6,90.990,-0.01,0.8074,0.80740,6.000
6,91.110,-0.01,0.6874,0.68740,6.000
6,91.230,-0.01,0.5674,0.56740,6.000
6,91.350,0.00,0.4472,0.44720,6.000
6,91.470,0.00,0.3274,0.32740,6.000
6,91.590,0.00,0.2072,0.20720,6.000
6,91.710,0.00,0.0872,0.08720,6.000
6,91.840,0.00,-0.0334,-0.03340,6.000
6,91.960,0.00,-0.0001,-0.00010,6.000
6,92.080,0.00,-0.0002,-0.00020,6.000
6,92.200,0.00,-0.0002,-0.00020,6.000
6,92.320,0.00,-0.0002,-0.00020,6.000
6,92.440,-0.01,-0.0002,-0.00020,6.000
6,92.560,0.00,-0.0002,-0.00020,6.000
6,92.680,-0.01,-0.0002,-0.00020,6.000
6,92.800,0.00,-0.0002,-0.00020,6.000
6,92.920,-0.01,-0.0002,-0.00020,6.000
6,93.040,-0.01,-0.0002,-0.00020,6.000
6,93.160,0.00,-0.0002,-0.00020,6.000
6,93.280,0.00,-0.0002,-0.00020,6.000
6,93.400,0.00,-0.0002,-0.00020,6.000
6,93.520,0.00,-0.0002,-0.00020,6.000
6,93.640,0.00,-0.0002,-0.00020,6.000
6,93.760,0.00,-0.0002,-0.00020,6.000
6,93.880,0.00,-0.0002,-0.00020,6.000
6,94.000,0.00,-0.0002,-0.00020,6.000
6,94.120,0.00,-0.0002,-0.00020,6.000
6,94.240,0.00,-0.0002,-0.00020,6.000
6,94.360,-0.01,-0.0002,-0.00020,6.000
6,94.480,0.00,-0.0002,-0.00020,6.000
6,94.600,-0.01,-0.0002,-0.00020,6.000
6,94.720,0.00,-0.0001,-0.00010,6.000
6,94.840,-0.01,-0.0001,-0.00010,6.000
6,94.970,0.00,-0.0001,-0.00010,6.000
6,95.090,0.00,-0.0001,-0.00010,6.000
6,95.210,-0.01,-0.0001,-0.00010,6.000
6,95.330,0.00,-0.0001,-0.00010,6.000
6,95.450,0.00,-0.0001,-0.00010,6.000
6,95.570,0.00,-0.0001,-0.00010,6.000
6,95.690,0.00,-0.0001,-0.00010,6.000
6,95.810,-0.01,-0.0001,-0.00010,6.000
6,95.930,0.00,-0.0001,-0.00010,6.000
6,96.050,0.00,-0.0001,-0.00010,6.000
6,96.170,0.00,-0.0001,-0.00010,6.000
6,96.290,-0.01,-0.0001,-0.00010,6.000
6,96.410,0.00,-0.0001,-0.00010,6.000
6,96.530,0.00,-0.0001,-0.00010,6.000
6,96.650,0.00,-0.0001,-0.00010,6.000
6,96.770,-0.01,-0.0001,-0.00010,6.000
6,96.890,0.00,-0.0001,-0.00010,6.000
6,97.010,0.00,-0.0001,-0.00010,6.000
6,97.130,-0.01,-0.0001,-0.00010,6.000
6,97.250,0.00,-0.0001,-0.00010,6.000
6,97.370,0.00,-0.0001,-0.00010,6.000
6,97.490,0.00,-0.0001,-0.00010,6.000
6,97.610,0.00,-0.0001,-0.00010,6.000
6,97.730,0.00,-0.0001,-0.00010,6.000
6,97.850,0.00,-0.0001,-0.00010,6.000
7,98.090,0.00,0.0276,0.02760,7.000
7,98.210,0.00,0.1474,0.14740,7.000
7,98.330,0.00,0.2676,0.26760,7.000
7,98.450,0.00,0.3875,0.38750,7.000
7,98.570,0.00,0.5075,0.50750,7.000
7,98.690,0.00,0.6276,0.62760,7.000
7,98.810,0.00,0.7475,0.74750,7.000
7,98.930,0.00,0.8675,0.86750,7.000
7,99.050,0.00,0.9875,0.98750,7.000
7,99.170,0.00,1.1077,1.10770,7.000
7,99.290,0.00,1.2277,1.22770,7.000
7,99.410,0.00,1.3477,1.34770,7.000
7,99.530,0.00,1.4676,1.46760,7.000
7,99.650,0.00,1.5877,1.58770,7.000
7,99.770,0.00,1.7076,1.70760,7.000
7,99.890,0.00,1.8276,1.82760,7.000
7,100.010,0.00,1.9478,1.94780,7.000
7,100.130,0.00,2.0677,2.06770,7.000
7,100.250,0.00,2.1876,2.18760,7.000
7,100.370,0.00,2.3078,2.30780,7.000
7,100.490,0.00,2.4277,2.42770,7.000
7,100.610,0.00,2.5477,2.54770,7.000
7,100.730,0.00,2.6677,2.66770,7.000
7,100.850,0.00,2.7878,2.78780,7.000
7,100.970,0.00,2.9077,2.90770,7.000
7,101.090,0.00,3.0278,3.02780,7.000
7,101.210,0.00,3.1478,3.14780,7.000
7,101.330,0.00,3.2679,3.26790,7.000
7,101.450,0.00,3.3877,3.38770,7.000
7,101.570,0.00,3.5078,3.50780,7.000
7,101.690,0.00,3.6278,3.62780,7.000
7,101.810,0.00,3.7477,3.74770,7.000
7,101.930,0.00,3.8677,3.86770,7.000
7,102.050,0.00,3.9877,3.98770,7.000
7,102.170,0.09,4.1077,4.10770,7.000
7,102.290,0.31,4.2278,4.22780,7.000
7,102.410,0.66,4.3478,4.34780,7.000
7,102.530,1.13,4.4678,4.46780,7.000
7,102.650,1.78,4.5877,4.58770,7.000
7,102.770,2.62,4.7078,4.70780,7.000
7,102.890,3.65,4.8278,4.82780,7.000
7,103.010,4.88,4.9477,4.94770,7.000
7,103.150,5.49,4.9901,4.99010,7.000
7,103.270,3.71,4.8704,4.87040,7.000
7,103.390,2.51,4.7507,4.75070,7.000
7,103.510,1.64,4.6305,4.63050,7.000
7,103.630,1.01,4.5106,4.51060,7.000
7,103.750,0.58,4.3906,4.39060,7.000
7,103.870,0.27,4.2705,4.27050,7.000
7,103.990,0.08,4.1505,4.15050,7.000
7,104.110,-0.01,4.0305,4.03050,7.000
7,104.230,0.00,3.9104,3.91040,7.000
7,104.350,0.00,3.7904,3.79040,7.000
7,104.470,0.00,3.6703,3.67030,7.000
7,104.590,0.00,3.5505,3.55050,7.000
7,104.710,0.00,3.4303,3.43030,7.000
7,104.830,0.00,3.3102,3.31020,7.000
7,104.950,0.00,3.1906,3.19060,7.000
7,105.070,0.00,3.0705,3.07050,7.000
7,105.190,0.00,2.9503,2.95030,7.000
7,105.310,0.00,2.8303,2.83030,7.000
7,105.430,0.00,2.7102,2.71020,7.000
7,105.550,0.00,2.5903,2.59030,7.000
7,105.670,0.00,2.4702,2.47020,7.000
7,105.790,0.00,2.3504,2.35040,7.000
7,105.910,0.00,2.2304,2.23040,7.000
7,106.030,0.00,2.1102,2.11020,7.000
7,106.150,0.00,1.9902,1.99020,7.000
7,106.270,0.00,1.8703,1.87030,7.000
7,106.390,0.00,1.7503,1.75030,7.000
7,106.510,0.00,1.6302,1.63020,7.000
7,106.630,0.00,1.5104,1.51040,7.000
7,106.750,0.00,1.3903,1.39030,7.000
7,106.870,0.00,1.2703,1.27030,7.000
7,106.990,0.00,1.1503,1.15030,7.000
7,107.110,0.00,1.0302,1.03020,7.000
7,107.230,0.00,0.9102,0.91020,7.000
7,107.350,0.00,0.7902,0.79020,7.000
7,107.470,0.00,0.6703,0.67030,7.000
7,107.590,0.00,0.5501,0.55010,7.000
7,107.710,0.00,0.4301,0.43010,7.000
7,107.830,0.00,0.3103,0.31030,7.000
7,107.950,0.00,0.1902,0.19020,7.000
7,108.070,0.00,0.0700,0.07000,7.000
7,108.210,0.00,-0.0598,-0.05980,7.000
7,108.330,0.00,-0.0004,-0.00040,7.000
7,108.450,0.00,-0.0003,-0.00030,7.000
7,108.570,0.00,-0.0003,-0.00030,7.000
7,108.690,0.00,-0.0003,-0.00030,7.000
7,108.810,0.00,-0.0003,-0.00030,7.000
7,108.930,0.00,-0.0003,-0.00030,7.000
7,109.050,0.00,-0.0003,-0.00030,7.000
7,109.170,0.00,-0.0003,-0.00030,7.000
7,109.290,0.00,-0.0003,-0.00030,7.000
7,109.410,0.00,-0.0003,-0.00030,7.000
7,109.530,0.00,-0.0002,-0.00020,7.000
7,109.650,0.00,-0.0002,-0.00020,7.000
7,109.770,0.00,-0.0002,-0.00020,7.000
7,109.890,0.00,-0.0002,-0.00020,7.000
7,110.010,0.00,-0.0002,-0.00020,7.000
7,110.130,0.00,-0.0002,-0.00020,7.000
7,110.250,0.00,-0.0002,-0.00020,7.000
7,110.370,0.00,-0.0002,-0.00020,7.000
7,110.490,0.00,-0.0002,-0.00020,7.000
7,110.610,0.00,-0.0002,-0.00020,7.000
7,110.730,0.00,-0.0002,-0.00020,7.000
7,110.850,0.00,-0.0002,-0.00020,7.000
7,110.970,0.00,-0.0002,-0.00020,7.000
7,111.090,0.00,-0.0002,-0.00020,7.000
7,111.210,0.00,-0.0002,-0.00020,7.000
7,111.350,0.00,-0.0002,-0.00020,7.000
7,111.470,0.00,-0.0002,-0.00020,7.000
7,111.590,0.00,-0.0002,-0.00020,7.000
7,111.710,0.00,-0.0002,-0.00020,7.000
7,111.830,0.00,-0.0002,-0.00020,7.000
7,111.950,0.00,-0.0002,-0.00020,7.000
7,112.070,0.00,-0.0002,-0.00020,7.000
7,112.190,0.00,-0.0001,-0.00010,7.000
7,112.310,0.00,-0.0001,-0.00010,7.000
7,112.430,0.00,-0.0001,-0.00010,7.000
7,112.550,0.00,-0.0001,-0.00010,7.000
7,112.670,0.00,-0.0001,-0.00010,7.000
7,112.790,0.00,-0.0001,-0.00010,7.000
7,112.910,0.00,-0.0001,-0.00010,7.000
7,113.030,0.00,-0.0001,-0.00010,7.000
7,113.150,0.00,-0.0001,-0.00010,7.000
7,113.270,0.00,-0.0001,-0.00010,7.000
7,113.390,0.00,-0.0001,-0.00010,7.000
7,113.510,0.00,-0.0001,-0.00010,7.000
7,113.630,0.00,-0.0001,-0.00010,7.000
7,113.750,0.00,-0.0001,-0.00010,7.000
7,113.870,0.00,-0.0001,-0.00010,7.000
7,113.990,0.00,-0.0001,-0.00010,7.000
7,114.110,0.00,-0.0001,-0.00010,7.000
7,114.230,-0.01,-0.0001,-0.00010,7.000
8,114.450,0.01,0.0173,0.01730,8.000
8,114.570,0.00,0.1375,0.13750,8.000
8,114.690,0.01,0.2577,0.25770,8.000
8,114.810,0.00,0.3777,0.37770,8.000
8,114.930,0.00,0.4976,0.49760,8.000
8,115.050,0.00,0.6177,0.61770,8.000
8,115.170,0.01,0.7376,0.73760,8.000
8,115.290,0.00,0.8578,0.85780,8.000
8,115.410,0.00,0.9777,0.97770,8.000
8,115.530,0.01,1.0979,1.09790,8.000
8,115.650,0.01,1.2178,1.21780,8.000
8,115.770,0.01,1.3378,1.33780,8.000
8,115.890,0.00,1.4577,1.45770,8.000
8,116.010,0.01,1.5780,1.57800,8.000
8,116.130,0.00,1.6979,1.69790,8.000
8,116.250,0.00,1.8179,1.81790,8.000
8,116.370,0.00,1.9378,1.93780,8.000
8,116.490,0.01,2.0578,2.05780,8.000
8,116.610,0.01,2.1778,2.17780,8.000
8,116.730,0.00,2.2979,2.29790,8.000
8,116.850,0.01,2.4180,2.41800,8.000
8,116.970,0.00,2.5378,2.53780,8.000
8,117.090,0.00,2.6578,2.65780,8.000
8,117.210,0.00,2.7779,2.77790,8.000
8,117.330,0.00,2.8978,2.89780,8.000
8,117.450,0.00,3.0180,3.01800,8.000
8,117.570,0.01,3.1380,3.13800,8.000
8,117.690,0.00,3.2581,3.25810,8.000
8,117.810,0.01,3.3778,3.37780,8.000
8,117.930,0.00,3.4980,3.49800,8.000
8,118.050,0.01,3.6179,3.61790,8.000
8,118.170,0.01,3.7379,3.73790,8.000
8,118.290,0.01,3.8579,3.85790,8.000
8,118.410,0.01,3.9779,3.97790,8.000
8,118.530,0.09,4.0979,4.09790,8.000
8,118.650,0.29,4.2178,4.21780,8.000
8,118.770,0.63,4.3379,4.33790,8.000
8,118.890,1.09,4.4579,4.45790,8.000
8,119.010,1.73,4.5779,4.57790,8.000
8,119.130,2.55,4.6980,4.69800,8.000
8,119.250,3.56,4.8178,4.81780,8.000
8,119.370,4.77,4.9379,4.93790,8.000
8,119.500,5.29,4.9723,4.97230,8.000
8,119.620,3.55,4.8527,4.85270,8.000
8,119.740,2.40,4.7327,4.73270,8.000
8,119.860,1.56,4.6127,4.61270,8.000
8,119.980,0.96,4.4927,4.49270,8.000
8,120.100,0.54,4.3727,4.37270,8.000
8,120.220,0.25,4.2528,4.25280,8.000
8,120.340,0.08,4.1327,4.13270,8.000
8,120.460,0.00,4.0126,4.01260,8.000
8,120.580,0.00,3.8926,3.89260,8.000
8,120.700,0.01,3.7725,3.77250,8.000
8,120.820,0.01,3.6526,3.65260,8.000
8,120.940,0.01,3.5326,3.53260,8.000
8,121.060,0.01,3.4124,3.41240,8.000
8,121.180,0.01,3.2924,3.29240,8.000
8,121.300,0.01,3.1727,3.17270,8.000
8,121.420,0.00,3.0525,3.05250,8.000
8,121.540,0.01,2.9325,2.93250,8.000
8,121.660,0.00,2.8125,2.81250,8.000
8,121.780,0.00,2.6924,2.69240,8.000
8,121.900,0.00,2.5724,2.57240,8.000
8,122.020,0.00,2.4525,2.45250,8.000
8,122.140,0.00,2.3325,2.33250,8.000
8,122.260,0.01,2.2124,2.21240,8.000
8,122.380,0.00,2.0923,2.09230,8.000
8,122.500,0.00,1.9724,1.97240,8.000
8,122.620,0.01,1.8524,1.85240,8.000
8,122.740,0.01,1.7324,1.73240,8.000
8,122.860,0.01,1.6124,1.61240,8.000
8,122.980,0.00,1.4925,1.49250,8.000
8,123.100,0.00,1.3723,1.37230,8.000
8,123.220,0.00,1.2523,1.25230,8.000
8,123.340,0.00,1.1326,1.13260,8.000
8,123.460,0.01,1.0124,1.01240,8.000
8,123.580,0.01,0.8924,0.89240,8.000
8,123.700,0.01,0.7724,0.77240,8.000
8,123.820,0.01,0.6523,0.65230,8.000
8,123.940,0.00,0.5323,0.53230,8.000
8,124.060,0.00,0.4124,0.41240,8.000
8,124.180,0.01,0.2924,0.29240,8.000
8,124.300,0.01,0.1722,0.17220,8.000
8,124.420,0.00,0.0523,0.05230,8.000
8,124.550,0.00,-0.0362,-0.03620,8.000
8,124.670,0.00,-0.0002,-0.00020,8.000
8,124.790,0.01,-0.0002,-0.00020,8.000
8,124.910,0.01,-0.0002,-0.00020,8.000
8,125.030,0.01,-0.0002,-0.00020,8.000
8,125.150,0.00,-0.0002,-0.00020,8.000
8,125.270,0.00,-0.0002,-0.00020,8.000
8,125.390,0.00,-0.0002,-0.00020,8.000
8,125.510,0.01,-0.0002,-0.00020,8.000
8,125.630,0.00,-0.0002,-0.00020,8.000
8,125.750,0.01,-0.0002,-0.00020,8.000
8,125.870,0.01,-0.0002,-0.00020,8.000
8,125.990,0.01,-0.0002,-0.00020,8.000
8,126.110,0.00,-0.0002,-0.00020,8.000
8,126.230,0.00,-0.0002,-0.00020,8.000
8,126.350,0.01,-0.0002,-0.00020,8.000
8,126.470,0.01,-0.0002,-0.00020,8.000
8,126.590,0.01,-0.0002,-0.00020,8.000
8,126.710,0.00,-0.0002,-0.00020,8.000
8,126.830,0.01,-0.0002,-0.00020,8.000
8,126.950,0.00,-0.0002,-0.00020,8.000
8,127.070,0.01,-0.0002,-0.00020,8.000
8,127.190,0.00,-0.0002,-0.00020,8.000
8,127.310,0.01,-0.0002,-0.00020,8.000
8,127.430,0.00,-0.0002,-0.00020,8.000
8,127.560,0.01,-0.0002,-0.00020,8.000
8,127.680,0.00,-0.0002,-0.00020,8.000
8,127.800,0.00,-0.0002,-0.00020,8.000
8,127.920,0.00,-0.0002,-0.00020,8.000
8,128.040,0.01,-0.0002,-0.00020,8.000
8,128.160,0.00,-0.0001,-0.00010,8.000
8,128.280,0.00,-0.0001,-0.00010,8.000
8,128.400,0.01,-0.0001,-0.00010,8.000
8,128.520,0.00,-0.0001,-0.00010,8.000
8,128.640,0.01,-0.0001,-0.00010,8.000
8,128.760,0.00,-0.0001,-0.00010,8.000
8,128.880,0.00,-0.0001,-0.00010,8.000
8,129.000,0.01,-0.0001,-0.00010,8.000
8,129.120,0.00,-0.0001,-0.00010,8.000
8,129.240,0.01,-0.0001,-0.00010,8.000
8,129.360,0.01,-0.0001,-0.00010,8.000
8,129.480,0.00,-0.0001,-0.00010,8.000
8,129.600,0.01,-0.0001,-0.00010,8.000
8,129.720,0.01,-0.0001,-0.00010,8.000
8,129.840,0.01,-0.0001,-0.00010,8.000
8,129.960,0.01,-0.0001,-0.00010,8.000
8,130.080,0.00,-0.0001,-0.00010,8.000
8,130.200,0.00,-0.0001,-0.00010,8.000
8,130.320,0.00,-0.0001,-0.00010,8.000
8,130.440,0.00,-0.0001,-0.00010,8.000
8,130.560,0.00,-0.0001,-0.00010,8.000
9,130.780,0.00,0.0764,0.07640,9.000
9,130.900,0.00,0.1965,0.19650,9.000
9,131.020,0.00,0.3166,0.31660,9.000
9,131.140,0.00,0.4367,0.43670,9.000
9,131.260,0.01,0.5566,0.55660,9.000
9,131.380,0.00,0.6766,0.67660,9.000
9,131.500,0.00,0.7966,0.79660,9.000
9,131.620,0.00,0.9167,0.91670,9.000
9,131.740,0.00,1.0368,1.03680,9.000
9,131.860,0.00,1.1568,1.15680,9.000
9,131.980,0.00,1.2766,1.27660,9.000
9,132.100,0.00,1.3967,1.39670,9.000
9,132.220,0.00,1.5167,1.51670,9.000
9,132.340,0.00,1.6366,1.63660,9.000
9,132.460,0.00,1.7568,1.75680,9.000
9,132.580,0.00,1.8768,1.87680,9.000
9,132.700,0.00,1.9968,1.99680,9.000
9,132.820,0.00,2.1167,2.11670,9.000
9,132.940,0.00,2.2367,2.23670,9.000
9,133.060,0.00,2.3568,2.35680,9.000
9,133.180,0.00,2.4767,2.47670,9.000
9,133.300,0.00,2.5968,2.59680,9.000
9,133.420,0.00,2.7168,2.71680,9.000
9,133.540,0.00,2.8368,2.83680,9.000
9,133.660,0.00,2.9568,2.95680,9.000
9,133.780,0.00,3.0768,3.07680,9.000
9,133.900,0.00,3.1970,3.19700,9.000
9,134.020,0.00,3.3166,3.31660,9.000
9,134.140,0.00,3.4367,3.43670,9.000
9,134.260,0.00,3.5568,3.55680,9.000
9,134.380,0.00,3.6767,3.67670,9.000
9,134.500,0.00,3.7968,3.79680,9.000
9,134.620,0.01,3.9167,3.91670,9.000
9,134.740,0.02,4.0367,4.03670,9.000
9,134.860,0.17,4.1568,4.15680,9.000
9,134.980,0.44,4.2768,4.27680,9.000
9,135.100,0.84,4.3969,4.39690,9.000
9,135.220,1.37,4.5167,4.51670,9.000
9,135.340,2.10,4.6367,4.63670,9.000
9,135.460,3.02,4.7567,4.75670,9.000
9,135.580,4.13,4.8768,4.87680,9.000
9,135.710,5.56,5.0026,5.00260,9.000
9,135.830,4.54,4.9297,4.92970,9.000
9,135.950,3.08,4.8098,4.80980,9.000
9,136.070,2.05,4.6896,4.68960,9.000
9,136.190,1.31,4.5696,4.56960,9.000
9,136.310,0.79,4.4497,4.44970,9.000
9,136.430,0.41,4.3296,4.32960,9.000
9,136.550,0.16,4.2096,4.20960,9.000
9,136.670,0.03,4.0895,4.08950,9.000
9,136.790,0.00,3.9696,3.96960,9.000
9,136.910,0.00,3.8496,3.84960,9.000
9,137.030,0.00,3.7295,3.72950,9.000
9,137.150,0.00,3.6095,3.60950,9.000
9,137.270,0.00,3.4896,3.48960,9.000
9,137.390,0.00,3.3693,3.36930,9.000
9,137.510,0.00,3.2496,3.24960,9.000
9,137.630,0.01,3.1297,3.12970,9.000
9,137.750,0.01,3.0095,3.00950,9.000
9,137.870,0.00,2.8895,2.88950,9.000
9,137.990,0.00,2.7695,2.76950,9.000
9,138.110,0.00,2.6494,2.64940,9.000
9,138.230,0.00,2.5295,2.52950,9.000
9,138.350,0.00,2.4095,2.40950,9.000
9,138.470,0.00,2.2895,2.28950,9.000
9,138.590,0.00,2.1695,2.16950,9.000
9,138.710,0.00,2.0493,2.04930,9.000
9,138.830,0.00,1.9294,1.92940,9.000
9,138.950,0.00,1.8095,1.80950,9.000
9,139.070,0.00,1.6895,1.68950,9.000
9,139.190,0.00,1.5695,1.56950,9.000
9,139.310,0.00,1.4494,1.44940,9.000
9,139.430,0.00,1.3293,1.32930,9.000
9,139.550,0.00,1.2094,1.20940,9.000
9,139.670,0.00,1.0894,1.08940,9.000
9,139.790,0.00,0.9694,0.96940,9.000
9,139.910,0.00,0.8493,0.84930,9.000
9,140.030,0.01,0.7293,0.72930,9.000
9,140.150,0.00,0.6094,0.60940,9.000
9,140.270,0.00,0.4893,0.48930,9.000
9,140.390,0.00,0.3694,0.36940,9.000
9,140.510,0.00,0.2493,0.24930,9.000
9,140.630,0.00,0.1292,0.12920,9.000
9,140.750,0.00,0.0093,0.00930,9.000
9,140.890,0.00,-0.0011,-0.00110,9.000
9,141.010,0.00,-0.0002,-0.00020,9.000
9,141.130,0.00,-0.0002,-0.00020,9.000
9,141.250,0.00,-0.0002,-0.00020,9.000
9,141.370,0.00,-0.0002,-0.00020,9.000
9,141.490,0.00,-0.0002,-0.00020,9.000
9,141.610,0.00,-0.0002,-0.00020,9.000
9,141.730,0.00,-0.0002,-0.00020,9.000
9,141.850,0.00,-0.0002,-0.00020,9.000
9,141.970,0.00,-0.0002,-0.00020,9.000
9,142.090,0.00,-0.0002,-0.00020,9.000
9,142.210,0.00,-0.0002,-0.00020,9.000
9,142.330,0.00,-0.0002,-0.00020,9.000
9,142.450,0.00,-0.0002,-0.00020,9.000
9,142.570,0.00,-0.0002,-0.00020,9.000
9,142.690,0.00,-0.0002,-0.00020,9.000
9,142.810,0.00,-0.0002,-0.00020,9.000
9,142.930,0.00,-0.0002,-0.00020,9.000
9,143.050,0.00,-0.0002,-0.00020,9.000
9,143.170,0.00,-0.0002,-0.00020,9.000
9,143.290,0.00,-0.0002,-0.00020,9.000
9,143.410,0.01,-0.0002,-0.00020,9.000
9,143.530,0.00,-0.0002,-0.00020,9.000
9,143.650,0.00,-0.0002,-0.00020,9.000
9,143.770,0.00,-0.0002,-0.00020,9.000
9,143.900,0.00,-0.0002,-0.00020,9.000
9,144.020,0.00,-0.0002,-0.00020,9.000
9,144.140,0.00,-0.0002,-0.00020,9.000
9,144.260,0.00,-0.0002,-0.00020,9.000
9,144.380,0.01,-0.0002,-0.00020,9.000
9,144.500,0.00,-0.0002,-0.00020,9.000
9,144.620,0.01,-0.0002,-0.00020,9.000
9,144.740,0.00,-0.0002,-0.00020,9.000
9,144.860,0.00,-0.0002,-0.00020,9.000
9,144.980,0.01,-0.0001,-0.00010,9.000
9,145.100,0.00,-0.0001,-0.00010,9.000
9,145.220,0.00,-0.0001,-0.00010,9.000
9,145.340,0.00,-0.0001,-0.00010,9.000
9,145.460,0.00,-0.0001,-0.00010,9.000
9,145.580,0.00,-0.0001,-0.00010,9.000
9,145.700,0.00,-0.0001,-0.00010,9.000
9,145.820,0.00,-0.0001,-0.00010,9.000
9,145.940,0.00,-0.0001,-0.00010,9.000
9,146.060,0.00,-0.0001,-0.00010,9.000
9,146.180,0.00,-0.0001,-0.00010,9.000
9,146.300,0.00,-0.0001,-0.00010,9.000
9,146.420,0.00,-0.0001,-0.00010,9.000
9,146.540,0.00,-0.0001,-0.00010,9.000
9,146.660,0.00,-0.0001,-0.00010,9.000
9,146.780,0.00,-0.0001,-0.00010,9.000
9,146.900,0.01,-0.0001,-0.00010,9.000
10,147.100,-0.01,0.0674,0.06740,10.000
10,147.220,0.00,0.1875,0.18750,10.000
10,147.340,0.00,0.3075,0.30750,10.000
10,147.460,-0.01,0.4275,0.42750,10.000
10,147.580,0.00,0.5476,0.54760,10.000
10,147.700,0.00,0.6675,0.66750,10.000
10,147.820,0.00,0.7876,0.78760,10.000
10,147.940,-0.01,0.9076,0.90760,10.000
10,148.060,-0.01,1.0278,1.02780,10.000
10,148.180,-0.01,1.1477,1.14770,10.000
10,148.300,0.00,1.2676,1.26760,10.000
10,148.420,-0.01,1.3876,1.38760,10.000
10,148.540,-0.01,1.5078,1.50780,10.000
10,148.660,-0.01,1.6277,1.62770,10.000
10,148.780,0.00,1.7477,1.74770,10.000
10,148.900,-0.01,1.8677,1.86770,10.000
10,149.020,0.00,1.9876,1.98760,10.000
10,149.140,0.00,2.1076,2.10760,10.000
10,149.260,-0.01,2.2279,2.22790,10.000
10,149.380,-0.01,2.3478,2.34780,10.000
10,149.500,-0.01,2.4677,2.46770,10.000
10,149.620,0.00,2.5877,2.58770,10.000
10,149.740,0.00,2.7077,2.70770,10.000
10,149.860,0.00,2.8277,2.82770,10.000
10,149.980,0.00,2.9479,2.94790,10.000
10,150.100,0.00,3.0679,3.06790,10.000
10,150.220,-0.01,3.1880,3.18800,10.000
10,150.340,0.00,3.3077,3.30770,10.000
10,150.460,0.00,3.4278,3.42780,10.000
10,150.580,0.00,3.5479,3.54790,10.000
10,150.700,0.00,3.6678,3.66780,10.000
10,150.820,-0.01,3.7878,3.78780,10.000
10,150.940,0.00,3.9078,3.90780,10.000
10,151.060,0.02,4.0277,4.02770,10.000
10,151.180,0.15,4.1478,4.14780,10.000
10,151.300,0.41,4.2678,4.26780,10.000
10,151.420,0.80,4.3879,4.38790,10.000
10,151.540,1.33,4.5079,4.50790,10.000
10,151.660,2.04,4.6277,4.62770,10.000
10,151.780,2.95,4.7479,4.74790,10.000
10,151.900,4.04,4.8678,4.86780,10.000
10,152.040,5.58,5.0014,5.00140,10.000
10,152.160,4.45,4.9226,4.92260,10.000
10,152.280,3.02,4.8025,4.80250,10.000
10,152.400,2.01,4.6825,4.68250,10.000
10,152.520,1.27,4.5625,4.56250,10.000
10,152.640,0.76,4.4426,4.44260,10.000
10,152.760,0.39,4.3226,4.32260,10.000
10,152.880,0.16,4.2025,4.20250,10.000
10,153.000,0.02,4.0825,4.08250,10.000
10,153.120,0.00,3.9624,3.96240,10.000
10,153.240,-0.01,3.8425,3.84250,10.000
10,153.360,0.00,3.7223,3.72230,10.000
10,153.480,-0.01,3.6025,3.60250,10.000
10,153.600,0.00,3.4824,3.48240,10.000
10,153.720,0.00,3.3623,3.36230,10.000
10,153.840,-0.01,3.2426,3.24260,10.000
10,153.960,0.00,3.1225,3.12250,10.000
10,154.080,0.00,3.0024,3.00240,10.000
10,154.200,0.00,2.8825,2.88250,10.000
10,154.320,-0.01,2.7623,2.76230,10.000
10,154.440,0.00,2.6423,2.64230,10.000
10,154.560,-0.01,2.5224,2.52240,10.000
10,154.680,0.00,2.4025,2.40250,10.000
10,154.800,0.00,2.2825,2.28250,10.000
10,154.920,0.00,2.1623,2.16230,10.000
10,155.040,0.00,2.0423,2.04230,10.000
10,155.160,0.00,1.9224,1.92240,10.000
10,155.280,0.00,1.8023,1.80230,10.000
10,155.400,-0.01,1.6824,1.68240,10.000
10,155.520,0.00,1.5624,1.56240,10.000
10,155.640,-0.01,1.4425,1.44250,10.000
10,155.760,0.00,1.3224,1.32240,10.000
10,155.880,0.00,1.2023,1.20230,10.000
10,156.000,0.00,1.0824,1.08240,10.000
10,156.120,0.00,0.9624,0.96240,10.000
10,156.240,0.00,0.8424,0.84240,10.000
10,156.360,0.00,0.7224,0.72240,10.000
10,156.480,0.00,0.6023,0.60230,10.000
10,156.600,-0.01,0.4824,0.48240,10.000
10,156.720,0.00,0.3623,0.36230,10.000
10,156.840,0.00,0.2425,0.24250,10.000
10,156.960,0.00,0.1223,0.12230,10.000
10,157.080,0.00,0.0022,0.00220,10.000
10,157.220,0.00,-0.0049,-0.00490,10.000
10,157.340,0.00,-0.0002,-0.00020,10.000
10,157.460,-0.01,-0.0002,-0.00020,10.000
10,157.580,0.00,-0.0002,-0.00020,10.000
10,157.700,-0.01,-0.0002,-0.00020,10.000
10,157.820,0.00,-0.0002,-0.00020,10.000
10,157.940,0.00,-0.0002,-0.00020,10.000
10,158.060,0.00,-0.0002,-0.00020,10.000
10,158.180,0.00,-0.0002,-0.00020,10.000
10,158.300,0.00,-0.0002,-0.00020,10.000
10,158.420,0.00,-0.0002,-0.00020,10.000
10,158.540,0.00,-0.0002,-0.00020,10.000
10,158.660,-0.01,-0.0002,-0.00020,10.000
10,158.780,0.00,-0.0002,-0.00020,10.000
10,158.900,-0.01,-0.0002,-0.00020,10.000
10,159.020,0.00,-0.0002,-0.00020,10.000
10,159.140,0.00,-0.0002,-0.00020,10.000
10,159.260,-0.01,-0.0002,-0.00020,10.000
10,159.380,0.00,-0.0002,-0.00020,10.000
10,159.500,0.00,-0.0002,-0.00020,10.000
10,159.620,0.00,-0.0002,-0.00020,10.000
10,159.740,0.00,-0.0002,-0.00020,10.000
10,159.860,-0.01,-0.0002,-0.00020,10.000
10,159.980,-0.01,-0.0002,-0.00020,10.000
10,160.100,0.00,-0.0002,-0.00020,10.000
10,160.230,-0.01,-0.0002,-0.00020,10.000
10,160.350,0.00,-0.0002,-0.00020,10.000
10,160.470,0.00,-0.0002,-0.00020,10.000
10,160.590,0.00,-0.0002,-0.00020,10.000
10,160.710,0.00,-0.0002,-0.00020,10.000
10,160.830,0.00,-0.0002,-0.00020,10.000
10,160.950,0.00,-0.0002,-0.00020,10.000
10,161.070,0.00,-0.0002,-0.00020,10.000
10,161.190,0.00,-0.0002,-0.00020,10.000
10,161.310,0.00,-0.0002,-0.00020,10.000
10,161.430,0.00,-0.0002,-0.00020,10.000
10,161.550,-0.01,-0.0002,-0.00020,10.000
10,161.670,0.00,-0.0002,-0.00020,10.000
10,161.790,0.00,-0.0002,-0.00020,10.000
10,161.910,0.00,-0.0001,-0.00010,10.000
10,162.030,-0.01,-0.0001,-0.00010,10.000
10,162.150,-0.01,-0.0001,-0.00010,10.000
10,162.270,0.00,-0.0001,-0.00010,10.000
10,162.390,0.00,-0.0001,-0.00010,10.000
10,162.510,0.00,-0.0001,-0.00010,10.000
10,162.630,0.00,-0.0001,-0.00010,10.000
10,162.750,-0.01,-0.0001,-0.00010,10.000
10,162.870,0.00,-0.0001,-0.00010,10.000
10,162.990,0.00,-0.0001,-0.00010,10.000
10,163.110,0.00,-0.0001,-0.00010,10.000
10,163.220,0.00,-0.0001,-0.00010,10.000