File: AIME_journal_files/AIME_data/calibDATA_deadWeights/calibTest/calibTest_2_13-4/InstronData13-4/Test1_Al_April13th.is_comp_RawData/Specimen_RawData_1.csv
Maximum Load : Compressive strain (Extension) at Maximum Load,"0.10861",mm/mm
Maximum Load : Compressive stress at Maximum Load,"0.23738",MPa
Maximum Load : Maximum Load,"40.00145",N
Maximum Load : Compressive extension at Maximum Load,"1.40113",mm
Maximum Load : Time at Maximum Load,"42.06400",s
Modulus (Automatic) : Modulus (Automatic),"5.66856",MPa

Time,Extension,Load,Compressive strain (Extension),Compressive stress
(s),(mm),(N),(mm/mm),(MPa)
"0.00000","0.00000","-0.03393","0.00000","-0.00020"
"0.07700","-0.00089","-0.03430","-0.00007","-0.00020"
"0.15400","-0.00029","-0.03472","-0.00002","-0.00021"
"0.23100","0.00066","-0.03368","0.00005","-0.00020"
"0.30800","0.00443","-0.00857","0.00034","-0.00005"
"0.38500","0.01153","0.04256","0.00089","0.00025"
"0.46200","0.01493","0.06511","0.00116","0.00039"
"0.53900","0.01707","0.07905","0.00132","0.00047"
"0.61600","0.01946","0.09568","0.00151","0.00057"
"0.69300","0.02207","0.11316","0.00171","0.00067"
"0.77000","0.02462","0.12979","0.00191","0.00077"
"0.84700","0.02710","0.14741","0.00210","0.00087"
"0.92400","0.02950","0.16473","0.00229","0.00098"
"1.00100","0.03202","0.18322","0.00248","0.00109"
"1.07800","0.03447","0.20079","0.00267","0.00119"
"1.15500","0.03733","0.22139","0.00289","0.00131"
"1.23200","0.04020","0.24262","0.00312","0.00144"
"1.30900","0.04287","0.26308","0.00332","0.00156"
"1.38600","0.04533","0.28155","0.00351","0.00167"
"1.46300","0.04760","0.29863","0.00369","0.00177"
"1.54000","0.05009","0.31725","0.00388","0.00188"
"1.61700","0.05266","0.33690","0.00408","0.00200"
"1.69400","0.05516","0.35596","0.00428","0.00211"
"1.77100","0.05763","0.37584","0.00447","0.00223"
"1.84800","0.06025","0.39739","0.00467","0.00236"
"1.92500","0.06283","0.41797","0.00487","0.00248"
"2.00200","0.06538","0.43781","0.00507","0.00260"
"2.07900","0.06806","0.45892","0.00528","0.00272"
"2.15600","0.07087","0.48151","0.00549","0.00286"
"2.23300","0.07372","0.50501","0.00571","0.00300"
"2.31000","0.07633","0.52553","0.00592","0.00312"
"2.38700","0.07878","0.54446","0.00611","0.00323"
"2.46400","0.08123","0.56375","0.00630","0.00335"
"2.54100","0.08376","0.58356","0.00649","0.00346"
"2.61800","0.08629","0.60375","0.00669","0.00358"
"2.69500","0.08878","0.62401","0.00688","0.00370"
"2.77200","0.09115","0.64291","0.00707","0.00382"
"2.84900","0.09358","0.66212","0.00725","0.00393"
"2.92600","0.09607","0.68116","0.00745","0.00404"
"3.00300","0.09888","0.70379","0.00766","0.00418"
"3.08000","0.10179","0.72714","0.00789","0.00432"
"3.15700","0.10453","0.74868","0.00810","0.00444"
"3.23400","0.10701","0.76706","0.00830","0.00455"
"3.31100","0.10930","0.78349","0.00847","0.00465"
"3.38800","0.11169","0.80135","0.00866","0.00476"
"3.46500","0.11426","0.82065","0.00886","0.00487"
"3.54200","0.11679","0.83715","0.00905","0.00497"
"3.61900","0.11928","0.84565","0.00925","0.00502"
"3.69600","0.12187","0.85116","0.00945","0.00505"
"3.77300","0.12442","0.85936","0.00965","0.00510"
"3.85000","0.12698","0.87048","0.00984","0.00517"
"3.92700","0.12970","0.88564","0.01005","0.00526"
"4.00400","0.13257","0.90188","0.01028","0.00535"
"4.08100","0.13531","0.91716","0.01049","0.00544"
"4.15800","0.13783","0.93068","0.01068","0.00552"
"4.23500","0.14032","0.94467","0.01088","0.00561"
"4.31200","0.14285","0.95913","0.01107","0.00569"
"4.38900","0.14535","0.97361","0.01127","0.00578"
"4.46600","0.14788","0.98837","0.01146","0.00587"
"4.54300","0.15035","1.00183","0.01166","0.00595"
"4.62000","0.15275","1.01540","0.01184","0.00603"
"4.69700","0.15525","1.03096","0.01204","0.00612"
"4.77400","0.15777","1.04607","0.01223","0.00621"
"4.85100","0.16049","1.06313","0.01244","0.00631"
"4.92800","0.16343","1.08110","0.01267","0.00642"
"5.00500","0.16619","1.09647","0.01288","0.00651"
"5.08200","0.16865","1.10981","0.01307","0.00659"
"5.15900","0.17090","1.12194","0.01325","0.00666"
"5.23600","0.17331","1.13685","0.01343","0.00675"
"5.31300","0.17587","1.15304","0.01363","0.00684"
"5.39000","0.17836","1.16808","0.01383","0.00693"
"5.46700","0.18088","1.18325","0.01402","0.00702"
"5.54400","0.18346","1.19912","0.01422","0.00712"
"5.62100","0.18602","1.21458","0.01442","0.00721"
"5.69800","0.18861","1.23019","0.01462","0.00730"
"5.77500","0.19134","1.24181","0.01483","0.00737"
"5.85200","0.19417","1.23540","0.01505","0.00733"
"5.92900","0.19693","1.25222","0.01527","0.00743"
"6.00600","0.19949","1.26822","0.01546","0.00753"
"6.08300","0.20195","1.28424","0.01566","0.00762"
"6.16000","0.20445","1.30025","0.01585","0.00772"
"6.23700","0.20697","1.31695","0.01604","0.00782"
"6.31400","0.20951","1.33453","0.01624","0.00792"
"6.39100","0.21200","1.35066","0.01643","0.00802"
"6.46800","0.21440","1.36638","0.01662","0.00811"
"6.54500","0.21681","1.38223","0.01681","0.00820"
"6.62200","0.21935","1.39979","0.01700","0.00831"
"6.69900","0.22199","1.41839","0.01721","0.00842"
"6.77600","0.22492","1.43947","0.01744","0.00854"
"6.85300","0.22774","1.45788","0.01765","0.00865"
"6.93000","0.23027","1.47377","0.01785","0.00875"
"7.00700","0.23257","1.48761","0.01803","0.00883"
"7.08400","0.23488","1.50257","0.01821","0.00892"
"7.16100","0.23749","1.52104","0.01841","0.00903"
"7.23800","0.23998","1.53772","0.01860","0.00913"
"7.31500","0.24248","1.55350","0.01880","0.00922"
"7.39200","0.24507","1.56947","0.01900","0.00931"
"7.46900","0.24771","1.58422","0.01920","0.00940"
"7.54600","0.25025","1.59527","0.01940","0.00947"
"7.62300","0.25291","1.60552","0.01961","0.00953"
"7.70000","0.25572","1.61720","0.01982","0.00960"
"7.77700","0.25852","1.62925","0.02004","0.00967"
"7.85400","0.26109","1.64346","0.02024","0.00975"
"7.93100","0.26351","1.65699","0.02043","0.00983"
"8.00800","0.26599","1.67158","0.02062","0.00992"
"8.08500","0.26862","1.60765","0.02082","0.00954"
"8.16200","0.27110","1.52985","0.02102","0.00908"
"8.23900","0.27356","1.56222","0.02121","0.00927"
"8.31600","0.27596","1.58450","0.02139","0.00940"
"8.39300","0.27842","1.60527","0.02158","0.00953"
"8.47000","0.28099","1.62539","0.02178","0.00965"
"8.54700","0.28360","1.64514","0.02198","0.00976"
"8.62400","0.28650","1.66661","0.02221","0.00989"
"8.70100","0.28937","1.68592","0.02243","0.01000"
"8.77800","0.29189","1.70209","0.02263","0.01010"
"8.85500","0.29421","1.71701","0.02281","0.01019"
"8.93200","0.29640","1.73128","0.02298","0.01027"
"9.00900","0.29907","1.75141","0.02318","0.01039"
"9.08600","0.30162","1.76847","0.02338","0.01049"
"9.16300","0.30404","1.78650","0.02357","0.01060"
"9.24000","0.30664","1.80249","0.02377","0.01070"
"9.31700","0.30930","1.82341","0.02398","0.01082"
"9.39400","0.31189","1.84166","0.02418","0.01093"
"9.47100","0.31450","1.86293","0.02438","0.01106"
"9.54800","0.31728","1.88360","0.02460","0.01118"
"9.62500","0.32009","1.90144","0.02481","0.01128"
"9.70200","0.32268","1.91885","0.02501","0.01139"
"9.77900","0.32519","1.93565","0.02521","0.01149"
"9.85600","0.32766","1.95507","0.02540","0.01160"
"9.93300","0.33014","1.97297","0.02559","0.01171"
"10.01000","0.33268","1.99119","0.02579","0.01182"
"10.08700","0.33515","2.00837","0.02598","0.01192"
"10.16400","0.33757","2.02542","0.02617","0.01202"
"10.24100","0.34004","2.04432","0.02636","0.01213"
"10.31800","0.34263","2.06442","0.02656","0.01225"
"10.39500","0.34515","2.08257","0.02676","0.01236"
"10.47200","0.34798","2.10420","0.02698","0.01249"
"10.54900","0.35081","2.12417","0.02719","0.01261"
"10.62600","0.35344","2.14300","0.02740","0.01272"
"10.70300","0.35583","2.15957","0.02758","0.01282"
"10.78000","0.35804","2.17472","0.02776","0.01291"
"10.85700","0.36073","2.19630","0.02796","0.01303"
"10.93400","0.36330","2.21405","0.02816","0.01314"
"11.01100","0.36570","2.23123","0.02835","0.01324"
"11.08800","0.36819","2.25081","0.02854","0.01336"
"11.16500","0.37087","2.27124","0.02875","0.01348"
"11.24200","0.37347","2.29052","0.02895","0.01359"
"11.31900","0.37606","2.30912","0.02915","0.01370"
"11.39600","0.37875","2.32941","0.02936","0.01382"
"11.47300","0.38157","2.35151","0.02958","0.01395"
"11.55000","0.38428","2.37120","0.02979","0.01407"
"11.62700","0.38679","2.38872","0.02998","0.01418"
"11.70400","0.38924","2.28098","0.03017","0.01354"
"11.78100","0.39180","2.24341","0.03037","0.01331"
"11.85800","0.39432","2.27480","0.03057","0.01350"
"11.93500","0.39682","2.30031","0.03076","0.01365"
"12.01200","0.39929","2.32356","0.03095","0.01379"
"12.08900","0.40170","2.34476","0.03114","0.01391"
"12.16600","0.40422","2.36707","0.03133","0.01405"
"12.24300","0.40677","2.38925","0.03153","0.01418"
"12.32000","0.40954","2.41426","0.03175","0.01433"
"12.39700","0.41241","2.43948","0.03197","0.01448"
"12.47400","0.41509","2.46124","0.03218","0.01461"
"12.55100","0.41753","2.48013","0.03237","0.01472"
"12.62800","0.41972","2.49658","0.03254","0.01482"
"12.70500","0.42231","2.51960","0.03274","0.01495"
"12.78200","0.42489","2.54068","0.03294","0.01508"
"12.85900","0.42733","2.55958","0.03313","0.01519"
"12.93600","0.42985","2.58055","0.03332","0.01531"
"13.01300","0.43250","2.60272","0.03353","0.01545"
"13.09000","0.43505","2.62330","0.03373","0.01557"
"13.16700","0.43765","2.64537","0.03393","0.01570"
"13.24400","0.44037","2.66866","0.03414","0.01584"
"13.32100","0.44322","2.69381","0.03436","0.01599"
"13.39800","0.44591","2.71529","0.03457","0.01611"
"13.47500","0.44838","2.73451","0.03476","0.01623"
"13.55200","0.45087","2.75539","0.03495","0.01635"
"13.62900","0.45339","2.77654","0.03515","0.01648"
"13.70600","0.45594","2.79773","0.03534","0.01660"
"13.78300","0.45849","2.81902","0.03554","0.01673"
"13.86000","0.46093","2.83928","0.03573","0.01685"
"13.93700","0.46327","2.85907","0.03591","0.01697"
"14.01400","0.46571","2.88023","0.03610","0.01709"
"14.09100","0.46828","2.90247","0.03630","0.01722"
"14.16800","0.47105","2.92808","0.03652","0.01738"
"14.24500","0.47394","2.95420","0.03674","0.01753"
"14.32200","0.47670","2.97826","0.03695","0.01767"
"14.39900","0.47919","2.99846","0.03715","0.01779"
"14.47600","0.48137","3.01477","0.03732","0.01789"
"14.55300","0.48386","3.03783","0.03751","0.01803"
"14.63000","0.48653","3.06298","0.03772","0.01818"
"14.70700","0.48903","3.08494","0.03791","0.01831"
"14.78400","0.49145","3.10638","0.03810","0.01843"
"14.86100","0.49405","3.13116","0.03830","0.01858"
"14.93800","0.49659","3.15410","0.03850","0.01872"
"15.01500","0.49917","3.17786","0.03869","0.01886"
"15.09200","0.50191","3.20401","0.03891","0.01901"
"15.16900","0.50474","3.23098","0.03913","0.01917"
"15.24600","0.50751","3.25590","0.03934","0.01932"
"15.32300","0.51003","3.27742","0.03954","0.01945"
"15.40000","0.51252","3.29987","0.03973","0.01958"
"15.47700","0.51505","3.32411","0.03993","0.01973"
"15.55400","0.51753","3.34752","0.04012","0.01987"
"15.63100","0.52010","3.37194","0.04032","0.02001"
"15.70800","0.52258","3.39434","0.04051","0.02014"
"15.78500","0.52499","3.41656","0.04070","0.02028"
"15.86200","0.52739","3.43903","0.04088","0.02041"
"15.93900","0.52995","3.46448","0.04108","0.02056"
"16.01600","0.53269","3.49191","0.04129","0.02072"
"16.09300","0.53556","3.52139","0.04152","0.02090"
"16.17000","0.53830","3.54724","0.04173","0.02105"
"16.24700","0.54081","3.57017","0.04192","0.02119"
"16.32400","0.54305","3.58899","0.04210","0.02130"
"16.40100","0.54542","3.31494","0.04228","0.01967"
"16.47800","0.54807","3.36072","0.04249","0.01994"
"16.55500","0.55054","3.39934","0.04268","0.02017"
"16.63200","0.55302","3.43360","0.04287","0.02038"
"16.70900","0.55560","3.46711","0.04307","0.02058"
"16.78600","0.55819","3.49934","0.04327","0.02077"
"16.86300","0.56079","3.53033","0.04347","0.02095"
"16.94000","0.56349","3.56321","0.04368","0.02115"
"17.01700","0.56628","3.59677","0.04390","0.02134"
"17.09400","0.56903","3.62939","0.04411","0.02154"
"17.17100","0.57162","3.65894","0.04431","0.02171"
"17.24800","0.57414","3.68690","0.04451","0.02188"
"17.32500","0.57661","3.71356","0.04470","0.02204"
"17.40200","0.57910","3.74095","0.04489","0.02220"
"17.47900","0.58165","3.76985","0.04509","0.02237"
"17.55600","0.58412","3.79673","0.04528","0.02253"
"17.63300","0.58651","3.82328","0.04547","0.02269"
"17.71000","0.58896","3.85194","0.04566","0.02286"
"17.78700","0.59156","3.88374","0.04586","0.02305"
"17.86400","0.59424","3.91629","0.04607","0.02324"
"17.94100","0.59717","3.95270","0.04629","0.02346"
"18.01800","0.59993","3.98560","0.04651","0.02365"
"18.09500","0.60243","4.01378","0.04670","0.02382"
"18.17200","0.60472","4.03972","0.04688","0.02397"
"18.24900","0.60699","4.06702","0.04705","0.02414"
"18.32600","0.60964","4.10214","0.04726","0.02434"
"18.40300","0.61217","4.13374","0.04745","0.02453"
"18.48000","0.61464","4.16452","0.04765","0.02471"
"18.55700","0.61722","4.19783","0.04785","0.02491"
"18.63400","0.61983","4.23161","0.04805","0.02511"
"18.71100","0.62240","4.26395","0.04825","0.02530"
"18.78800","0.62507","4.29887","0.04846","0.02551"
"18.86500","0.62791","4.33711","0.04868","0.02574"
"18.94200","0.63074","4.37480","0.04889","0.02596"
"19.01900","0.63328","4.40727","0.04909","0.02615"
"19.09600","0.63578","4.43949","0.04928","0.02635"
"19.17300","0.63828","4.47260","0.04948","0.02654"
"19.25000","0.64073","4.50499","0.04967","0.02673"
"19.32700","0.64325","4.53959","0.04986","0.02694"
"19.40400","0.64573","4.57271","0.05006","0.02714"
"19.48100","0.64812","4.60418","0.05024","0.02732"
"19.55800","0.65057","4.63779","0.05043","0.02752"
"19.63500","0.65317","4.67473","0.05063","0.02774"
"19.71200","0.65581","4.71265","0.05084","0.02797"
"19.78900","0.65867","4.75477","0.05106","0.02822"
"19.86600","0.66148","4.79472","0.05128","0.02845"
"19.94300","0.66401","4.82950","0.05147","0.02866"
"20.02000","0.66639","4.86145","0.05166","0.02885"
"20.09700","0.66863","4.89178","0.05183","0.02903"
"20.17400","0.67126","4.93196","0.05204","0.02927"
"20.25100","0.67376","4.96784","0.05223","0.02948"
"20.32800","0.67623","5.00306","0.05242","0.02969"
"20.40500","0.67879","5.04077","0.05262","0.02991"
"20.48200","0.68139","5.07929","0.05282","0.03014"
"20.55900","0.68398","5.11784","0.05302","0.03037"
"20.63600","0.68666","5.15874","0.05323","0.03061"
"20.71300","0.68942","5.20037","0.05344","0.03086"
"20.79000","0.69225","5.24371","0.05366","0.03112"
"20.86700","0.69484","5.28243","0.05386","0.03135"
"20.94400","0.69733","5.32151","0.05406","0.03158"
"21.02100","0.69980","5.36071","0.05425","0.03181"
"21.09800","0.70229","5.39850","0.05444","0.03204"
"21.17500","0.70479","5.44303","0.05463","0.03230"
"21.25200","0.70727","5.48647","0.05483","0.03256"
"21.32900","0.70971","5.52757","0.05502","0.03280"
"21.40600","0.71224","5.57188","0.05521","0.03307"
"21.48300","0.71482","5.61742","0.05541","0.03334"
"21.56000","0.71741","5.66197","0.05561","0.03360"
"21.63700","0.72025","5.37264","0.05583","0.03188"
"21.71400","0.72314","5.45535","0.05606","0.03237"
"21.79100","0.72567","5.52039","0.05625","0.03276"
"21.86800","0.72800","5.57562","0.05643","0.03309"
"21.94500","0.73028","5.62667","0.05661","0.03339"
"22.02200","0.73276","5.68049","0.05680","0.03371"
"22.09900","0.73541","5.73659","0.05701","0.03404"
"22.17600","0.73789","5.78494","0.05720","0.03433"
"22.25300","0.74045","5.83544","0.05740","0.03463"
"22.33000","0.74299","5.88529","0.05760","0.03493"
"22.40700","0.74554","5.93519","0.05779","0.03522"
"22.48400","0.74822","5.98829","0.05800","0.03554"
"22.56100","0.75106","6.04435","0.05822","0.03587"
"22.63800","0.75388","6.09846","0.05844","0.03619"
"22.71500","0.75645","6.14576","0.05864","0.03647"
"22.79200","0.75890","6.19211","0.05883","0.03675"
"22.86900","0.76140","6.24157","0.05902","0.03704"
"22.94600","0.76395","6.29365","0.05922","0.03735"
"23.02300","0.76649","6.34507","0.05942","0.03765"
"23.10000","0.76898","6.39593","0.05961","0.03796"
"23.17700","0.77138","6.44472","0.05980","0.03825"
"23.25400","0.77379","6.49479","0.05998","0.03854"
"23.33100","0.77639","6.55229","0.06019","0.03888"
"23.40800","0.77901","6.61031","0.06039","0.03923"
"23.48500","0.78179","6.67499","0.06060","0.03961"
"23.56200","0.78465","6.74148","0.06083","0.04001"
"23.63900","0.78724","6.80043","0.06103","0.04036"
"23.71600","0.78965","6.85626","0.06121","0.04069"
"23.79300","0.79184","6.90573","0.06138","0.04098"
"23.87000","0.79444","6.97078","0.06158","0.04137"
"23.94700","0.79706","7.03584","0.06179","0.04175"
"24.02400","0.79950","7.09568","0.06198","0.04211"
"24.10100","0.80207","7.16223","0.06218","0.04250"
"24.17800","0.80462","7.22749","0.06237","0.04289"
"24.25500","0.80722","7.29452","0.06257","0.04329"
"24.33200","0.80985","7.36420","0.06278","0.04370"
"24.40900","0.81254","7.43619","0.06299","0.04413"
"24.48600","0.81530","7.51135","0.06320","0.04458"
"24.56300","0.81799","7.58437","0.06341","0.04501"
"24.64000","0.82053","7.65294","0.06361","0.04542"
"24.71700","0.82298","7.72018","0.06380","0.04581"
"24.79400","0.82556","7.79338","0.06400","0.04625"
"24.87100","0.82812","7.86610","0.06420","0.04668"
"24.94800","0.83060","7.93733","0.06439","0.04710"
"25.02500","0.83304","8.00852","0.06458","0.04753"
"25.10200","0.83540","8.07637","0.06476","0.04793"
"25.17900","0.83792","8.15168","0.06496","0.04838"
"25.25600","0.84056","8.23223","0.06516","0.04885"
"25.33300","0.84335","8.31986","0.06538","0.04937"
"25.41000","0.84624","8.41249","0.06560","0.04992"
"25.48700","0.84890","8.49362","0.06581","0.05040"
"25.56400","0.85127","8.56523","0.06599","0.05083"
"25.64100","0.85347","8.63112","0.06616","0.05122"
"25.71800","0.85597","8.71147","0.06635","0.05170"
"25.79500","0.85861","8.79633","0.06656","0.05220"
"25.87200","0.86111","8.60079","0.06675","0.05104"
"25.94900","0.86370","8.67646","0.06695","0.05149"
"26.02600","0.86620","8.77615","0.06715","0.05208"
"26.10300","0.86879","8.87407","0.06735","0.05266"
"26.18000","0.87138","8.96860","0.06755","0.05322"
"26.25700","0.87407","9.06642","0.06776","0.05380"
"26.33400","0.87684","9.16754","0.06797","0.05440"
"26.41100","0.87964","9.26875","0.06819","0.05500"
"26.48800","0.88220","9.35834","0.06839","0.05554"
"26.56500","0.88467","9.44495","0.06858","0.05605"
"26.64200","0.88718","9.53469","0.06877","0.05658"
"26.71900","0.88973","9.62768","0.06897","0.05713"
"26.79600","0.89226","9.71891","0.06917","0.05768"
"26.87300","0.89473","9.80768","0.06936","0.05820"
"26.95000","0.89709","9.89286","0.06954","0.05871"
"27.02700","0.89954","9.98225","0.06973","0.05924"
"27.10400","0.90214","10.08025","0.06993","0.05982"
"27.18100","0.90490","10.18602","0.07015","0.06045"
"27.25800","0.90780","10.29869","0.07037","0.06112"
"27.33500","0.91049","10.39968","0.07058","0.06172"
"27.41200","0.91290","10.48814","0.07077","0.06224"
"27.48900","0.91515","10.56984","0.07094","0.06273"
"27.56600","0.91757","10.66249","0.07113","0.06328"
"27.64300","0.92019","10.76521","0.07133","0.06388"
"27.72000","0.92272","10.86271","0.07153","0.06446"
"27.79700","0.92524","10.96135","0.07172","0.06505"
"27.87400","0.92778","11.06148","0.07192","0.06564"
"27.95100","0.93037","11.16467","0.07212","0.06626"
"28.02800","0.93297","11.26884","0.07232","0.06687"
"28.10500","0.93567","11.37835","0.07253","0.06752"
"28.18200","0.93848","11.49452","0.07275","0.06821"
"28.25900","0.94131","11.61236","0.07297","0.06891"
"28.33600","0.94385","11.71396","0.07317","0.06951"
"28.41300","0.94630","11.81279","0.07336","0.07010"
"28.49000","0.94873","11.91155","0.07354","0.07069"
"28.56700","0.95129","12.01906","0.07374","0.07133"
"28.64400","0.95386","12.12808","0.07394","0.07197"
"28.72100","0.95631","12.22948","0.07413","0.07257"
"28.79800","0.95863","12.32532","0.07431","0.07314"
"28.87500","0.96108","12.42884","0.07450","0.07376"
"28.95200","0.96370","12.54287","0.07471","0.07443"
"29.02900","0.96640","12.66122","0.07491","0.07514"
"29.10600","0.96930","12.79149","0.07514","0.07591"
"29.18300","0.97210","12.91468","0.07536","0.07664"
"29.26000","0.97459","13.01988","0.07555","0.07726"
"29.33700","0.97691","13.11502","0.07573","0.07783"
"29.41400","0.97932","12.97106","0.07592","0.07698"
"29.49100","0.98177","13.01983","0.07611","0.07726"
"29.56800","0.98434","13.14748","0.07631","0.07802"
"29.64500","0.98684","13.26705","0.07650","0.07873"
"29.72200","0.98938","13.38874","0.07670","0.07945"
"29.79900","0.99192","13.51000","0.07689","0.08017"
"29.87600","0.99449","13.63204","0.07709","0.08090"
"29.95300","0.99722","13.76378","0.07730","0.08168"
"30.03000","1.00006","13.90092","0.07752","0.08249"
"30.10700","1.00293","14.04196","0.07775","0.08333"
"30.18400","1.00550","14.16510","0.07795","0.08406"
"30.26100","1.00790","14.27763","0.07813","0.08473"
"30.33800","1.01042","14.38849","0.07833","0.08539"
"30.41500","1.01287","14.50724","0.07852","0.08609"
"30.49200","1.01541","14.63330","0.07871","0.08684"
"30.56900","1.01788","14.75478","0.07891","0.08756"
"30.64600","1.02022","14.86890","0.07909","0.08824"
"30.72300","1.02271","14.99360","0.07928","0.08898"
"30.80000","1.02538","15.13139","0.07949","0.08980"
"30.87700","1.02804","15.26730","0.07969","0.09060"
"30.95400","1.03082","15.41203","0.07991","0.09146"
"31.03100","1.03365","15.56033","0.08013","0.09234"
"31.10800","1.03621","15.69076","0.08033","0.09311"
"31.18500","1.03850","15.80536","0.08050","0.09379"
"31.26200","1.04080","15.92166","0.08068","0.09448"
"31.33900","1.04337","16.05908","0.08088","0.09530"
"31.41600","1.04594","16.19549","0.08108","0.09611"
"31.49300","1.04845","16.32777","0.08128","0.09689"
"31.57000","1.05100","16.46463","0.08147","0.09771"
"31.64700","1.05356","16.60279","0.08167","0.09853"
"31.72400","1.05614","16.74257","0.08187","0.09936"
"31.80100","1.05890","16.89489","0.08208","0.10026"
"31.87800","1.06178","17.05642","0.08231","0.10122"
"31.95500","1.06453","17.20810","0.08252","0.10212"
"32.03200","1.06700","17.34021","0.08271","0.10290"
"32.10900","1.06940","17.46936","0.08290","0.10367"
"32.18600","1.07196","17.60952","0.08310","0.10450"
"32.26300","1.07453","17.75280","0.08330","0.10535"
"32.34000","1.07703","17.89133","0.08349","0.10617"
"32.41700","1.07954","18.03185","0.08369","0.10701"
"32.49400","1.08191","18.16235","0.08387","0.10778"
"32.57100","1.08430","18.29484","0.08405","0.10857"
"32.64800","1.08692","18.44405","0.08426","0.10945"
"32.72500","1.08955","18.59315","0.08446","0.11034"
"32.80200","1.09239","18.75938","0.08468","0.11133"
"32.87900","1.09524","18.92654","0.08490","0.11232"
"32.95600","1.09783","19.07500","0.08510","0.11320"
"33.03300","1.10019","19.20626","0.08529","0.11398"
"33.11000","1.10254","19.33938","0.08547","0.11477"
"33.18700","1.10500","19.48175","0.08566","0.11561"
"33.26400","1.10751","19.62876","0.08585","0.11648"
"33.34100","1.11003","19.77688","0.08605","0.11736"
"33.41800","1.11257","19.92529","0.08625","0.11824"
"33.49500","1.11513","20.07656","0.08644","0.11914"
"33.57200","1.11774","20.23117","0.08665","0.12006"
"33.64900","1.12042","20.39196","0.08685","0.12101"
"33.72600","1.12321","20.56107","0.08707","0.12202"
"33.80300","1.12607","20.73462","0.08729","0.12305"
"33.88000","1.12865","20.88702","0.08749","0.12395"
"33.95700","1.13104","21.02573","0.08768","0.12477"
"34.03400","1.13356","21.17770","0.08787","0.12568"
"34.11100","1.13613","21.33375","0.08807","0.12660"
"34.18800","1.13864","21.48367","0.08827","0.12749"
"34.26500","1.14114","21.62767","0.08846","0.12835"
"34.34200","1.14349","21.76342","0.08864","0.12915"
"34.41900","1.14590","21.90730","0.08883","0.13001"
"34.49600","1.14853","22.06811","0.08903","0.13096"
"34.57300","1.15113","22.22144","0.08924","0.13187"
"34.65000","1.15399","22.29855","0.08946","0.13233"
"34.72700","1.15684","22.24776","0.08968","0.13203"
"34.80400","1.15937","22.40620","0.08987","0.13297"
"34.88100","1.16167","22.54748","0.09005","0.13380"
"34.95800","1.16403","22.69614","0.09023","0.13469"
"35.03500","1.16658","22.86161","0.09043","0.13567"
"35.11200","1.16914","23.02670","0.09063","0.13665"
"35.18900","1.17165","23.18731","0.09083","0.13760"
"35.26600","1.17414","23.34652","0.09102","0.13855"
"35.34300","1.17676","23.51785","0.09122","0.13956"
"35.42000","1.17937","23.68787","0.09142","0.14057"
"35.49700","1.18202","23.86267","0.09163","0.14161"
"35.57400","1.18482","24.04912","0.09185","0.14272"
"35.65100","1.18772","24.24334","0.09207","0.14387"
"35.72800","1.19030","24.41085","0.09227","0.14486"
"35.80500","1.19266","24.55999","0.09245","0.14575"
"35.88200","1.19514","24.72220","0.09265","0.14671"
"35.95900","1.19774","24.89507","0.09285","0.14774"
"36.03600","1.20021","25.05597","0.09304","0.14869"
"36.11300","1.20269","25.22040","0.09323","0.14967"
"36.19000","1.20509","25.37780","0.09342","0.15060"
"36.26700","1.20752","25.54001","0.09361","0.15156"
"36.34400","1.21001","25.70837","0.09380","0.15256"
"36.42100","1.21264","25.88885","0.09400","0.15363"
"36.49800","1.21567","26.10644","0.09424","0.15493"
"36.57500","1.21861","26.31417","0.09447","0.15616"
"36.65200","1.22108","26.48064","0.09466","0.15715"
"36.72900","1.22339","26.63639","0.09484","0.15807"
"36.80600","1.22571","26.79389","0.09502","0.15900"
"36.88300","1.22819","26.96587","0.09521","0.16003"
"36.96000","1.23072","27.14352","0.09540","0.16108"
"37.03700","1.23324","27.32008","0.09560","0.16213"
"37.11400","1.23575","27.49695","0.09579","0.16318"
"37.19100","1.23832","27.68063","0.09599","0.16427"
"37.26800","1.24094","27.86814","0.09620","0.16538"
"37.34500","1.24365","28.06512","0.09641","0.16655"
"37.42200","1.24636","28.26161","0.09662","0.16771"
"37.49900","1.24918","28.46991","0.09684","0.16895"
"37.57600","1.25192","28.66751","0.09705","0.17012"
"37.65300","1.25434","28.83665","0.09724","0.17113"
"37.73000","1.25677","29.00881","0.09742","0.17215"
"37.80700","1.25930","29.19234","0.09762","0.17324"
"37.88400","1.26187","29.38208","0.09782","0.17436"
"37.96100","1.26441","29.56644","0.09802","0.17546"
"38.03800","1.26687","29.74375","0.09821","0.17651"
"38.11500","1.26923","29.91400","0.09839","0.17752"
"38.19200","1.27173","30.10008","0.09858","0.17862"
"38.26900","1.27435","30.30059","0.09879","0.17981"
"38.34600","1.27717","30.51777","0.09901","0.18110"
"38.42300","1.27998","30.73441","0.09922","0.18239"
"38.50000","1.28254","30.92585","0.09942","0.18353"
"38.57700","1.28495","31.10377","0.09961","0.18458"
"38.65400","1.28729","31.27791","0.09979","0.18561"
"38.73100","1.28979","31.46604","0.09998","0.18673"
"38.80800","1.29235","31.66463","0.10018","0.18791"
"38.88500","1.29487","31.85636","0.10038","0.18905"
"38.96200","1.29737","32.04731","0.10057","0.19018"
"39.03900","1.29997","32.25351","0.10077","0.19140"
"39.11600","1.30252","32.45044","0.10097","0.19257"
"39.19300","1.30515","32.65768","0.10117","0.19380"
"39.27000","1.30786","32.87248","0.10138","0.19508"
"39.34700","1.31064","33.09414","0.10160","0.19639"
"39.42400","1.31347","33.32149","0.10182","0.19774"
"39.50100","1.31605","33.52438","0.10202","0.19895"
"39.57800","1.31849","33.71403","0.10221","0.20007"
"39.65500","1.32096","33.90820","0.10240","0.20122"
"39.73200","1.32347","34.10712","0.10259","0.20240"
"39.80900","1.32600","34.30714","0.10279","0.20359"
"39.88600","1.32843","34.49825","0.10298","0.20473"
"39.96300","1.33073","34.67766","0.10316","0.20579"
"40.04000","1.33322","34.87724","0.10335","0.20697"
"40.11700","1.33578","35.08726","0.10355","0.20822"
"40.19400","1.33874","35.33793","0.10378","0.20971"
"40.27100","1.34171","35.59003","0.10401","0.21120"
"40.34800","1.34422","35.78867","0.10420","0.21238"
"40.42500","1.34657","35.97033","0.10438","0.21346"
"40.50200","1.34888","36.15561","0.10456","0.21456"
"40.57900","1.35139","36.36015","0.10476","0.21577"
"40.65600","1.35397","36.57109","0.10496","0.21703"
"40.73300","1.35650","36.77157","0.10516","0.21822"
"40.81000","1.35896","36.96220","0.10535","0.21935"
"40.88700","1.36150","37.05774","0.10554","0.21991"
"40.96400","1.36413","36.75922","0.10575","0.21814"
"41.04100","1.36670","36.98375","0.10595","0.21948"
"41.11800","1.36944","37.22666","0.10616","0.22092"
"41.19500","1.37222","37.46991","0.10637","0.22236"
"41.27200","1.37508","37.72416","0.10660","0.22387"
"41.34900","1.37769","37.94939","0.10680","0.22521"
"41.42600","1.38015","38.15705","0.10699","0.22644"
"41.50300","1.38255","38.36198","0.10717","0.22765"
"41.58000","1.38505","38.57981","0.10737","0.22895"
"41.65700","1.38762","38.80516","0.10757","0.23028"
"41.73400","1.39010","39.02097","0.10776","0.23156"
"41.81100","1.39246","39.22514","0.10794","0.23278"
"41.88800","1.39489","39.43762","0.10813","0.23404"
"41.96500","1.39739","39.65764","0.10832","0.23534"
"42.04200","1.40025","39.91899","0.10855","0.23689"
"42.06400","1.40113","40.00145","0.10861","0.23738"